File: raw data/testID_0254.csv
Time(sec),Force(kN),Jaw(mm),PowAngle(deg),Power(W),Pram,PTemp,Strain,Stress(MPa),Stroke(mm),TC1(C),wedge(mm)
0.0,1.5828167,0.12617169,0.0,0,10.594783,0.00097874238,0.0084582763,19.994255,10.595138,12.816403,-9.1218166
2.2,1.4920312,0.0055955271,0.0,0,10.594783,6.5161748,0.00037517553,18.974733,10.594477,12.747918,-9.4862833
4.4,1.4458828,0.0058467356,0.0,0,10.594783,13.116177,0.00040153143,18.414085,10.59514,12.665792,-9.4830027
6.6,1.4277967,0.005472763,30.462036,0,10.594783,19.716175,0.00036943483,18.164948,10.595078,14.538491,-9.4789324
8.8,1.4106476,0.0024129653,36.304943,0,10.594783,26.316177,0.00016340041,17.955078,10.595423,22.131903,-9.4746561
11.0,1.4024684,-0.00021039991,37.742626,0,10.594783,32.916164,-1.2204548e-05,17.857046,10.594247,30.623022,-9.4711952
13.2,1.3936237,-0.0013315903,37.836914,0,10.594783,39.516174,-7.7256125e-05,17.738224,10.595276,38.418297,-9.4676352
15.4,1.3778189,-0.0031151664,38.529106,0,10.594783,46.11618,-0.00019078227,17.545837,10.594496,45.433743,-9.4637966
17.6,1.3866057,-0.0038379682,38.839764,0,10.594783,52.716194,-0.00025366704,17.655262,10.5945,52.148289,-9.4603577
19.8,1.3655078,-0.0055522751,39.24316,0,10.594783,59.316189,-0.00034912574,17.405882,10.594473,58.773151,-9.4570417
22.0,1.3704634,-0.006997067,39.702545,0,10.594783,65.916176,-0.00046396311,17.467829,10.594843,65.615494,-9.4533024
24.2,1.3503374,-0.0089498619,39.923576,0,10.594783,72.516182,-0.00056025846,17.204824,10.594515,72.293892,-9.4490662
26.4,1.3546104,-0.0098778335,40.326187,0,10.594783,79.116173,-0.00066941499,17.26638,10.595568,78.741386,-9.445075
28.6,1.3461803,-0.011974539,40.572433,0,10.594783,85.716194,-0.00076534186,17.156321,10.59445,85.540955,-9.4418106
30.8,1.3462977,-0.012993097,40.572506,0,10.594783,92.316185,-0.00087841111,17.166897,10.594055,92.120171,-9.4379473
33.0,1.331764,-0.015304276,41.107819,0,10.594783,98.916176,-0.00099236646,16.983448,10.594266,98.586754,-9.4339075
35.2,1.3396449,-0.016615812,41.195187,0,10.594783,105.51618,-0.0011178363,17.076294,10.594751,105.25928,-9.4303665
37.4,1.3290113,-0.01903899,41.198727,0,10.594783,112.11618,-0.0012486394,16.942671,10.595583,111.81863,-9.4261875
39.6,1.3320433,-0.020546446,41.802582,0,10.594783,118.71618,-0.0013867493,16.987274,10.594487,118.49261,-9.4224434
41.8,1.3305757,-0.023221733,41.802975,0,10.594783,125.31617,-0.0015190514,16.955446,10.595428,125.09945,-9.4191399
44.0,1.3367949,-0.025453681,42.309597,0,10.594783,131.91618,-0.001711262,17.057386,10.594655,131.61801,-9.415535
46.2,1.3290207,-0.027732505,42.395702,0,10.594783,138.51617,-0.0018242507,16.949247,10.595044,138.3614,-9.4113636
48.4,1.3348887,-0.030554898,42.582554,0,10.594783,145.1162,-0.0020538229,17.043184,10.594362,144.76881,-9.4076624
50.6,1.3248186,-0.034241505,42.396946,0,10.594783,151.71619,-0.0022654443,16.914244,10.594023,151.6927,-9.4040461
52.8,1.3422112,-0.037028536,42.396244,0,10.594783,158.31619,-0.0024867181,17.132929,10.595003,158.41261,-9.4004507
55.0,1.318418,-0.040065553,42.396236,0,10.594783,164.91618,-0.0026604859,16.840166,10.594546,164.86131,-9.3966312
57.2,1.333513,-0.043020841,42.396236,0,10.594783,171.51617,-0.0028890884,17.019444,10.594082,171.57054,-9.3926697
59.4,1.3229383,-0.046338998,42.97784,0,10.594783,178.11618,-0.0030807809,16.903427,10.595529,177.83365,-9.3894739
61.6,1.3170031,-0.049835753,42.545586,0,10.594783,184.71619,-0.0033355665,16.821106,10.595322,184.59616,-9.3851213
63.8,1.3279574,-0.052588779,42.925755,0,10.594783,191.31621,-0.0035041617,16.963146,10.595008,191.17722,-9.3818607
66.0,1.3194468,-0.056454252,42.977669,0,10.594783,197.91621,-0.0037672741,16.877825,10.594734,197.74507,-9.3778992
68.2,1.3430088,-0.061043441,43.379276,0,10.594783,204.5162,-0.0040661735,17.172077,10.59504,204.23277,-9.374299
70.4,1.3297389,-0.064065017,43.180088,0,10.594783,211.11621,-0.0042661829,16.995224,10.595036,211.04562,-9.370945
72.6,1.3178737,-0.067942932,43.503899,0,10.594783,217.7162,-0.0045086779,16.844812,10.595008,217.52504,-9.3670988
74.8,1.3371729,-0.071953118,43.400646,0,10.594783,224.31619,-0.0047968384,17.125097,10.594971,224.21059,-9.363553
77.0,1.3223916,-0.07611943,43.45089,0,10.594783,230.91618,-0.0050541582,16.921185,10.594381,230.94518,-9.3589869
79.2,1.3630023,-0.080600314,43.527828,0,10.594783,237.51619,-0.0053584045,17.440058,10.594897,237.35814,-9.3558741
81.4,1.3509253,-0.084200926,43.792908,0,10.594783,244.11618,-0.0055902447,17.290686,10.594706,243.93619,-9.3524122
83.6,1.3514166,-0.088704877,43.861832,0,10.594783,250.7162,-0.0058864751,17.317001,10.594568,250.65637,-9.3485909
85.8,1.3553263,-0.092805102,43.971844,0,10.594783,257.31647,-0.0061572576,17.361084,10.594498,257.24149,-9.3450537
88.0,1.3710256,-0.097917244,44.077145,0,10.594783,263.9162,-0.0065052877,17.572634,10.594102,263.77646,-9.3412018
90.2,1.355128,-0.10183802,44.041428,0,10.594783,270.51617,-0.0067532873,17.37945,10.594362,270.60056,-9.337244
92.4,1.3512765,-0.10656023,44.076061,0,10.594783,277.11618,-0.0070632123,17.325541,10.594692,276.99661,-9.3334637
94.6,1.3715428,-0.11164498,43.933544,0,10.594783,283.71616,-0.007403126,17.580421,10.594079,283.77029,-9.3300047
96.8,1.3850375,-0.11507487,44.339413,0,10.594783,290.31616,-0.0076145516,17.770544,10.593969,290.0253,-9.3262386
99.0,1.3706597,-0.11977898,44.31192,0,10.594783,296.91617,-0.0079574613,17.587786,10.594605,296.82855,-9.322361
101.2,1.3749025,-0.12413717,44.489033,0,10.594783,303.51617,-0.0082153603,17.640957,10.594709,303.41995,-9.318943
103.4,1.3985953,-0.12914138,44.57188,0,10.594783,310.11618,-0.0085772648,17.945557,10.594256,310.0574,-9.3158226
105.6,1.4095861,-0.13285239,44.603798,0,10.594783,316.71619,-0.0087964535,18.112049,10.594168,316.6998,-9.3121424
107.8,1.3925552,-0.13666092,44.849792,0,10.594783,323.31622,-0.0090930127,17.885887,10.595122,322.991,-9.3086071
110.0,1.3876723,-0.14136256,44.87793,0,10.594783,329.9162,-0.0093617868,17.830921,10.594381,329.78256,-9.3041277
112.2,1.4010736,-0.14629188,44.801842,0,10.594783,336.51617,-0.0097313598,18.020578,10.594203,336.46558,-9.3005695
114.4,1.3805724,-0.14896294,44.786396,0,10.594783,343.11618,-0.0098639904,17.764053,10.595059,343.07828,-9.2969999
116.6,1.3604796,-0.15235202,44.653049,0,10.594783,349.71619,-0.01013303,17.49972,10.594319,349.7486,-9.2930727
118.8,1.3820943,-0.15594432,44.604496,0,10.594783,356.31619,-0.010343452,17.780767,10.593787,356.4761,-9.2896318
121.0,1.35452,-0.15843755,44.54974,0,10.594783,362.9162,-0.010529408,17.441505,10.593784,363.05334,-9.2860136
123.2,1.3533059,-0.16168571,44.604488,0,10.594783,369.5162,-0.010711833,17.418783,10.595125,369.40182,-9.2829008
125.4,1.3352513,-0.16304401,44.625679,0,10.594783,376.11621,-0.010825052,17.185154,10.594926,376.02884,-9.2788687
127.6,1.3085283,-0.16516925,44.937393,0,10.594783,382.71622,-0.010950659,16.855608,10.594285,382.55743,-9.2752333
129.8,1.3193539,-0.16768143,44.741028,0,10.594783,389.31619,-0.011129883,16.981211,10.594472,389.28677,-9.2718058
132.0,1.3071107,-0.16559023,44.604488,0,10.594783,395.91617,-0.010974467,16.817747,10.594391,396.00735,-9.2682362
134.2,1.2886717,-0.16541973,44.306389,0,10.594783,402.51617,-0.010967146,16.578276,10.595294,402.70029,-9.264677
136.4,1.3032707,-0.16448744,44.711403,0,10.594783,409.11618,-0.010901658,16.780426,10.594494,408.92355,-9.2606945
138.6,1.2790493,-0.16000187,44.604496,0,10.594783,415.71619,-0.010593403,16.463276,10.594926,415.78149,-9.2569561
140.8,1.2700721,-0.15418191,44.366325,0,10.594783,422.31616,-0.010222911,16.3311,10.594058,422.50461,-9.2532377
143.0,1.2782402,-0.14819254,44.077152,0,10.594783,428.9162,-0.0097949253,16.417761,10.594393,429.02313,-9.2494326
145.2,1.2772511,-0.13652922,44.228027,0,10.594783,435.51624,-0.0090689221,16.426332,10.594998,435.52805,-9.2456026
147.4,1.2674541,-0.12484696,44.200424,0,10.594783,442.11621,-0.0082641784,16.279253,10.59425,442.08939,-9.2415123
149.6,0.32082924,-0.13187431,45.12072,0,10.594783,448.71622,-0.0087751253,4.1384993,10.594584,447.9938,-9.2381105
151.8,0.32294843,-0.13446768,43.754627,0,10.594783,449.9989,-0.0089019351,4.1614113,10.594706,450.52917,-9.2374496
154.0,0.31525841,-0.13603219,43.744644,0,10.594783,449.9989,-0.0090531344,4.0604153,10.594093,450.22787,-9.2368565
156.2,0.3366558,-0.13747822,43.070492,0,10.594783,449.9989,-0.0091211293,4.3078899,10.595366,450.43854,-9.2374964
158.4,0.33906642,-0.13990152,42.461765,0,10.594783,449.9989,-0.0092970924,4.3622079,10.594934,450.55276,-9.237237
160.6,0.342902,-0.13943695,42.834625,0,10.594783,449.9989,-0.009263901,4.4107985,10.593657,450.16797,-9.2368298
162.8,0.34390286,-0.14059584,42.773182,0,10.594783,449.9989,-0.0093531217,4.4092212,10.594881,450.03922,-9.2369633
165.0,0.34801522,-0.14236873,42.396244,0,10.594783,449.9989,-0.0094392523,4.4732857,10.594692,450.18292,-9.2372532
167.2,0.34349111,-0.14381115,41.819672,0,10.594783,449.9989,-0.0095380368,4.4146848,10.595591,450.31851,-9.2371988
169.4,0.34494352,-0.14451322,41.802982,0,10.594783,449.9989,-0.0095790168,4.432951,10.59418,450.2298,-9.2369356
171.6,0.35408869,-0.14771761,41.623055,0,10.594783,449.9989,-0.0097920559,4.541316,10.593945,450.26282,-9.2367878
173.8,0.36666763,-0.14638844,41.677334,0,10.594783,449.9989,-0.0097168563,4.6989675,10.594652,450.06219,-9.2371311
176.0,0.36221516,-0.14758001,41.286331,0,10.594783,449.9989,-0.0097559569,4.6590996,10.594862,450.12589,-9.236927
178.2,0.35835779,-0.1485194,41.198734,0,10.594783,449.9989,-0.0098749651,4.6018214,10.594495,450.12192,-9.2369652
180.4,0.35586751,-0.1494562,40.931004,0,10.594783,449.9989,-0.0099049127,4.5848212,10.595369,450.21359,-9.236907
182.6,0.35961115,-0.15028355,41.084934,0,10.594783,449.9989,-0.0099940561,4.631536,10.59483,450.07938,-9.2371731
184.8,0.37033311,-0.1517749,40.957855,0,10.594783,449.9989,-0.010062257,4.7599163,10.594591,450.01804,-9.2370176
187.0,0.36723951,-0.15200025,40.719391,0,10.594783,449.9989,-0.010094164,4.7310243,10.595076,450.03757,-9.2368088
189.2,0.36978298,-0.15210368,40.594543,0,10.594783,449.9989,-0.010077818,4.7590494,10.593833,450.05588,-9.2366333
191.4,0.36617607,-0.15314753,40.572514,0,10.594783,449.9989,-0.010151216,4.7068086,10.594397,450.03235,-9.2366962
193.6,0.36200309,-0.15393981,40.572514,0,10.594783,449.9989,-0.010200122,4.6550889,10.595033,450.17218,-9.2364321
195.2809,0.62389976,0.013140911,40.57251,0,10.5948,0.0060100802,0.0011003371,7.930006,10.593179,450.22702,-9.2355547
195.2853,0.59232652,0.013992609,33.269436,0,10.5948,5.9954178999999996e-33,0.0011102553,7.4693036,10.594405,450.2348,-9.2363043
195.2897,0.61280239,0.012981565,15.417532,0,10.5948,0.0,0.0011344411,7.8233757,10.595767,450.2348,-9.2381916
195.2941,0.59192312,0.013582642,0.0,0,10.5948,0.0,0.0010850491,7.5157266,10.594538,450.27972,-9.2385368
195.2985,0.59720522,0.014680794,0.0,0,10.5948,0.0,0.0012489735,7.668395,10.595632,450.60907,-9.236865
195.3029,0.60547739,0.012267627,0.0,0,10.5948,0.0,0.0010399615,7.7444935,10.595133,450.93842,-9.2367659
195.3073,0.61069632,0.013272131,0.0,0,10.5948,0.0,0.0011702863,7.7651935,10.593541,450.85818,-9.2359915
195.3117,0.60964423,0.013372655,0.0,0,10.5948,0.0,0.0010974169,7.688231,10.595782,450.71329,-9.2351522
195.3161,0.62539142,0.014292745,0.0,0,10.5948,0.0,0.0011982578,7.9199705,10.593601,450.60727,-9.2369442
195.3205,0.62123626,0.014405592,0.0,0,10.5948,0.0,0.0012207512,7.9115849,10.596238,450.52823,-9.2359486
195.3249,0.6308189,0.013961152,0.0,0,10.5948,0.0,0.0011956861,7.9097333,10.593819,450.45337,-9.2359686
195.3293,0.62707078,0.014176887,0.0,0,10.5948,0.0,0.0011654206,8.0367136,10.593601,450.38751,-9.2363176
195.3337,0.62924182,0.015648713,0.0,0,10.542864,0.0,0.001269468,8.0216608,10.594667,450.32101,-9.2358551
195.3381,0.63691014,0.015229205,0.0,0,10.476864,0.0,0.0012015501,8.1143169,10.592017,450.24197,-9.2360821
195.3425,0.6523875,0.014948466,0.0,0,10.410864,0.0,0.001241698,8.2985897,10.559658,450.16293,-9.237464
195.3469,0.63607115,0.015216011,0.0,0,10.344864,0.0,0.0012081886,8.1801167,10.482916,450.06351,-9.2363691
195.3513,0.65279496,0.013777963,0.0,0,10.278863,0.0,0.0011465733,8.2741299,10.379008,449.95813,-9.2362118
195.3557,0.66285789,0.015313402,0.0,0,10.212864,0.0,0.0011693435,8.4590139,10.294847,449.85272,-9.2366333
195.3601,0.66168559,0.014836598,0.0,0,10.146863,0.0,0.0012642007,8.3716364,10.225357,449.74734,-9.2372084
195.3645,0.66038519,0.015095063,0.0,0,10.080864,0.0,0.0012025586,8.3801622,10.175296,449.64194,-9.2365417
195.3689,0.67345089,0.016402259,0.0,0,10.014863,0.0,0.0012789408,8.4115448,10.115013,449.53653,-9.2357521
195.3733,0.67742187,0.01626417,0.0,0,9.948863,0.0,0.0012195229,8.5110207,10.05027,449.43112,-9.2371025
195.3777,0.6710068,0.014332366,0.0,0,9.882863,0.0,0.0011828294,8.5342159,9.9757776,449.32571,-9.2356768
195.3821,0.66900313,0.01710753,0.0,0,9.8168631,0.0,0.001280764,8.5473394,9.9016399,449.22034,-9.2374954
195.3865,0.70094091,0.01581485,0.0,0,9.7508631,0.0,0.0012738261,8.8747244,9.8373823,449.1329,-9.236125
195.3909,1.8909291,0.032375567,0.0,0,9.6848631,0.0,0.0023024424,23.888655,9.7822676,449.05386,-9.2361135
195.3953,3.0454371,0.043825265,0.0,0,9.6188631,0.0,0.0030967293,38.550888,9.716753,448.98019,-9.2340355
195.3997,3.5723972,0.11694965,0.0,0,9.5528631,0.0,0.0078792488,45.181637,9.6458101,448.91431,-9.2345181
195.4041,3.8556437,0.18333292,0.0,0,9.4868631,0.0,0.012459693,48.422703,9.5727797,448.84305,-9.2336292
195.4085,4.0110941,0.25534081,0.0,0,9.4223585,0.0,0.017290495,50.194157,9.5002604,448.73767,-9.2331467
195.4129,4.0755587,0.31949735,0.0,0,9.3579779,0.0,0.021609986,50.77499,9.4333849,448.63229,-9.2338209
195.4173,4.0993929,0.38154888,0.0,0,9.2935972,0.0,0.025868308,50.881641,9.3719196,448.58377,-9.2345619
195.4217,4.1377521,0.43944395,0.0,0,9.2292166,0.0,0.029787764,51.086838,9.3055735,448.54425,-9.2353306
195.4261,4.2099161,0.50468922,0.0,0,9.164835,0.0,0.034267064,51.873505,9.2438555,448.49695,-9.2336521
195.4305,4.2862935,0.57221425,0.0,0,9.1004553,0.0,0.038943749,52.398937,9.1733894,448.44424,-9.2341681
195.4349,4.2981825,0.63952202,0.0,0,9.0360737,0.0,0.043657977,52.343155,9.1080761,448.39154,-9.2346716
195.4393,4.2958779,0.70446265,0.0,0,8.971693,0.0,0.048146393,52.14756,9.0372124,448.33884,-9.2346125
195.4437,4.3467083,0.76898569,0.0,0,8.9073124,0.0,0.052632779,52.478935,8.9761686,448.28076,-9.2353067
195.4481,4.380549,0.83028924,0.0,0,8.8429308,0.0,0.056976918,52.634525,8.9101973,448.1095,-9.2335234
195.4525,4.3998218,0.89430845,0.0,0,8.7785501,0.0,0.061486848,52.767727,8.8495255,447.9382,-9.2346945
195.4569,4.4057708,0.95370907,0.0,0,8.7159328,0.0,0.065696232,52.46666,8.7853069,447.65497,-9.234272
195.4613,4.4590344,1.0182383,0.0,0,8.6547022,0.0,0.070396453,52.904411,8.7205973,447.33878,-9.2350864
195.4657,4.4807105,1.0807767,0.0,0,8.5934715,0.0,0.074794419,53.078461,8.6539984,446.9501,-9.2345562
195.4701,4.5177865,1.1429554,0.0,0,8.5322428,0.0,0.079298556,53.018517,8.5963907,446.48901,-9.235898
195.4745,4.5202723,1.2051543,0.0,0,8.4710112,0.0,0.083692484,52.784664,8.5292501,445.99197,-9.2340412
195.4789,4.5528555,1.2694033,0.0,0,8.4097815,0.0,0.088407099,53.057163,8.4671106,445.37274,-9.2337809
195.4833,4.6163301,1.3321031,0.0,0,8.3485498,0.0,0.092937931,53.48196,8.4023581,444.75354,-9.2351885
195.4877,4.6231995,1.3893299,0.0,0,8.2873201,0.0,0.097230814,53.463467,8.34342,443.90738,-9.2343407
195.4921,4.639215,1.4481128,0.0,0,8.2260895,0.0,0.10142347,53.362804,8.281455,443.05038,-9.233922
195.4965,4.7047014,1.511287,0.0,0,8.1648588,0.0,0.1061383,53.877308,8.2241812,442.31906,-9.2351894
195.5009,4.7706213,1.5723385,0.0,0,8.1036291,0.0,0.11065914,54.356209,8.156229,441.64633,-9.2349377
195.5053,4.8061476,1.6399854,0.0,0,8.0429821,0.0,0.11566349,54.511536,8.0910864,441.01132,-9.234189
195.5097,4.8142514,1.6979493,0.0,0,7.984726,0.0,0.12004995,54.375298,8.0305767,440.43073,-9.2334995
195.5141,4.7856069,1.7570847,0.0,0,7.9264693,0.0,0.12453116,53.884056,7.9719772,439.85196,-9.2337065
195.5185,4.8389101,1.8067417,0.0,0,7.8682137,0.0,0.12830214,54.215816,7.917613,439.28455,-9.2335825
195.5229,4.9058909,1.865266,0.0,0,7.8099575,0.0,0.13264666,54.756905,7.8606629,438.71716,-9.2356672
195.5273,4.9509349,1.9248667,0.0,0,7.7517014,0.0,0.13716035,55.035603,7.79913,438.59421,-9.2339354
195.5317,4.9676666,1.9839588,0.0,0,7.6934457,0.0,0.14166696,54.856308,7.7420568,438.54144,-9.2338314
195.5361,5.0125656,2.0407057,0.0,0,7.6351895,0.0,0.14610039,55.102821,7.6808863,438.66797,-9.2350798
195.5405,5.0538797,2.1007318,0.0,0,7.5769334,0.0,0.15068333,55.37299,7.621758,438.9187,-9.2340622
195.5449,5.0655975,2.1544633,0.0,0,7.5186772,0.0,0.15492472,55.305836,7.5649309,439.2114,-9.2343102
195.5493,5.1119356,2.2149282,0.0,0,7.4604211,0.0,0.15952906,55.481258,7.5096803,439.59402,-9.2346344
195.5537,5.1618552,2.2717676,0.0,0,7.4021654,0.0,0.1641055,55.725113,7.445087,439.96588,-9.2352934
195.5581,5.2255526,2.333864,0.0,0,7.346283,0.0,0.16885932,56.260498,7.3923888,440.11105,-9.2351952
195.5625,5.257329,2.3903463,0.0,0,7.2908783,0.0,0.17335059,56.255558,7.3264518,440.2562,-9.2352228
195.5669,5.2452698,2.4493756,0.0,0,7.2354732,0.0,0.17803125,55.91795,7.2714396,440.12607,-9.2350616
195.5713,5.272367,2.5026939,0.0,0,7.1800685,0.0,0.18223466,55.968594,7.2138295,439.91495,-9.2347641
195.5757,5.3594193,2.5614772,0.0,0,7.1246629,0.0,0.18695538,56.635815,7.1572838,439.63785,-9.2348452
195.5801,5.3752041,2.6135345,0.0,0,7.0692587,0.0,0.19122458,56.593437,7.0995708,439.29477,-9.2345276
195.5845,5.3664813,2.6718447,0.0,0,7.0138535,0.0,0.19591598,56.171146,7.0440135,438.90372,-9.233901
195.5889,5.3997293,2.7214971,0.0,0,6.9584489,0.0,0.19992645,56.277489,6.989686,438.34952,-9.2333221
195.5933,5.4501247,2.7753153,0.0,0,6.9030442,0.0,0.20425062,56.531132,6.9418783,437.79532,-9.2338839
195.5977,5.5374107,2.8287189,0.0,0,6.8476396,0.0,0.2086478,57.171154,6.8819304,437.2789,-9.2336349
195.6021,5.5510459,2.8874736,0.0,0,6.7922344,0.0,0.21343835,57.134312,6.8289528,436.76428,-9.2349958
195.6065,5.5776763,2.9429064,0.0,0,6.7380919,0.0,0.21808046,57.123104,6.7685523,435.8898,-9.2332983
195.6109,5.6196828,2.9993227,0.0,0,6.68538,0.0,0.22275026,57.274303,6.7119155,434.84738,-9.2346249
195.6153,5.6839557,3.0505228,0.0,0,6.632668,0.0,0.22701761,57.557301,6.6600604,433.79956,-9.233676
195.6197,5.6681218,3.1083181,0.0,0,6.5799561,0.0,0.23179843,57.31683,6.6059251,432.74396,-9.2338839
195.6241,5.6904516,3.1556144,0.0,0,6.5272441,0.0,0.23597954,57.264481,6.5521679,431.83047,-9.2334108
195.6285,5.7330222,3.2097442,0.0,0,6.4745321,0.0,0.240421,57.365479,6.5010505,431.81729,-9.2342091
195.6329,5.7864285,3.2578628,0.0,0,6.4218202,0.0,0.24452646,57.705173,6.4488959,431.80411,-9.2338381
195.6373,5.8345814,3.3122249,0.0,0,6.3691082,0.0,0.24902943,57.889023,6.3989224,432.07581,-9.2344818
195.6417,5.8807244,3.3639734,0.0,0,6.3163962,0.0,0.25360045,58.051083,6.3412857,432.39249,-9.2333059
195.6461,5.9380631,3.4218938,0.0,0,6.2636843,0.0,0.25842479,58.363056,6.2886515,432.63898,-9.2344894
195.6505,5.9818735,3.4753375,0.0,0,6.2109723,0.0,0.26319787,58.487106,6.2298713,432.83691,-9.2351246
195.6549,5.9918089,3.5295475,0.0,0,6.1585317,0.0,0.26770887,58.4021,6.1818051,432.99704,-9.233139
195.6593,5.9746704,3.5761967,0.0,0,6.1083975,0.0,0.27201703,58.00243,6.1315079,433.07623,-9.234457
195.6637,6.0538831,3.6292195,0.0,0,6.0582643,0.0,0.27643269,58.548882,6.0790291,433.1506,-9.2327471
195.6681,6.1078987,3.6792195,0.0,0,6.0081306,0.0,0.28107542,58.704453,6.0215292,433.12421,-9.2338266
195.6725,6.1334662,3.7312138,0.0,0,5.9579968,0.0,0.28545877,58.726814,5.9812107,433.09781,-9.2343454
195.6769,6.1411314,3.7764859,0.0,0,5.9078636,0.0,0.28966314,58.558273,5.9270506,432.95926,-9.2333431
195.6813,6.1720819,3.8257363,0.0,0,5.8577299,0.0,0.29389763,58.586056,5.8790464,432.78772,-9.2343645
195.6857,6.2481232,3.8728888,0.0,0,5.8075962,0.0,0.29837266,58.981659,5.8298836,432.68878,-9.2341356
195.6901,6.2985678,3.927753,0.0,0,5.7574625,0.0,0.30307353,59.271751,5.7807012,432.66238,-9.2350683
195.6945,6.3455734,3.9724407,0.0,0,5.7073288,0.0,0.30733776,59.414112,5.7289238,432.64801,-9.233531
195.6989,6.3520322,4.0249629,0.0,0,5.6571956,0.0,0.31191763,59.225651,5.6778703,432.67438,-9.2329254
195.7033,6.4366307,4.0737553,0.0,0,5.6070614,0.0,0.31661025,59.652924,5.6286469,432.70078,-9.2329416
195.7077,6.5159488,4.1301861,0.0,0,5.5587354,0.0,0.32157525,60.104866,5.5765295,432.73975,-9.233182
195.7121,6.5585012,4.1790915,0.0,0,5.5110397,0.0,0.32629636,60.31076,5.5209708,432.77933,-9.2342119
195.7165,6.5356755,4.2324147,0.0,0,5.4633436,0.0,0.33099973,59.757298,5.4743471,432.77393,-9.2343378
195.7209,6.5562162,4.2743502,0.0,0,5.4156475,0.0,0.3350617,59.707115,5.4284372,432.74756,-9.2332325
195.7253,6.6053414,4.325943,0.0,0,5.3679519,0.0,0.33967093,59.877235,5.3794079,432.651,-9.2341356
195.7297,6.6680951,4.3662515,0.0,0,5.3202558,0.0,0.34373406,60.201862,5.3376393,432.45306,-9.2348213
195.7341,6.7054644,4.4184718,0.0,0,5.2725596,0.0,0.3483682,60.303875,5.2821159,432.23892,-9.2335587
195.7385,6.7188001,4.461731,0.0,0,5.224864,0.0,0.35270503,60.061733,5.2384872,431.92224,-9.2338762
195.7429,6.8240609,4.513555,0.0,0,5.1771674,0.0,0.35744399,60.765423,5.1905389,431.60556,-9.2340326
195.7473,6.8855729,4.5570388,0.0,0,5.1294718,0.0,0.36189136,61.117821,5.1422992,431.32306,-9.233222
195.7517,6.8921294,4.6102228,0.0,0,5.0817757,0.0,0.36676681,60.883469,5.0962682,431.04596,-9.2337141
195.7561,6.9117694,4.6527286,0.0,0,5.0349607,0.0,0.37111506,60.723354,5.0439715,430.83905,-9.233325
195.7605,6.9748106,4.7040157,0.0,0,4.9895968,0.0,0.37585846,60.920998,5.0015564,430.68073,-9.233263
195.7649,7.0248127,4.7461581,0.0,0,4.9442329,0.0,0.38013157,61.222454,4.9538345,430.49298,-9.2343607
195.7693,7.0372024,4.7926011,0.0,0,4.898869,0.0,0.38458428,61.011826,4.9104896,430.24228,-9.2326241
195.7737,7.0771084,4.8348131,0.0,0,4.8535047,0.0,0.38888991,61.133179,4.8677778,429.99216,-9.2336502
195.7781,7.1702304,4.8849578,0.0,0,4.8081408,0.0,0.39370412,61.483303,4.8181877,429.75467,-9.2334394
195.7825,7.2111812,4.9281311,0.0,0,4.7627769,0.0,0.39809111,61.661655,4.7732558,429.51715,-9.2335138
195.7869,7.2196302,4.9776378,0.0,0,4.7174129,0.0,0.40299463,61.447147,4.7259793,429.34082,-9.2323847
195.7913,7.2358932,5.0142756,0.0,0,4.6720486,0.0,0.40668181,61.342911,4.6852093,429.18246,-9.233428
195.7957,7.2842941,5.0617986,0.0,0,4.6266847,0.0,0.41129848,61.448986,4.6427402,428.99774,-9.2332373
195.8001,7.4165101,5.1027193,0.0,0,4.5813208,0.0,0.41555297,62.290878,4.5957742,428.78662,-9.2340174
195.8045,7.4648066,5.1529441,0.0,0,4.5359983,0.0,0.4206439,62.364143,4.5490541,428.54544,-9.2338448
195.8089,7.5248837,5.1972866,0.0,0,4.4928331,0.0,0.42531127,62.605453,4.5013757,428.20215,-9.2330885
195.8133,7.5418367,5.2470241,0.0,0,4.4496775,0.0,0.43024462,62.514736,4.4515214,427.85883,-9.233633
195.8177,7.5500522,5.2907801,0.0,0,4.4065223,0.0,0.43482035,62.16275,4.4100943,424.80252,-9.2346725
195.8221,7.5712175,5.3331113,0.0,0,4.3633671,0.0,0.43908337,62.119122,4.371613,421.61703,-9.2334442
195.8265,7.6419697,5.369216,0.0,0,4.3202119,0.0,0.44306809,62.438541,4.3310404,417.91684,-9.2337923
195.8309,7.703485,5.4195466,0.0,0,4.2770567,0.0,0.44813827,62.629894,4.2849483,413.97644,-9.2346478
195.8353,7.7724466,5.4586458,0.0,0,4.2339015,0.0,0.45247066,62.960537,4.2429361,411.17145,-9.2333794
195.8397,7.8331461,5.5058556,0.0,0,4.1907463,0.0,0.45732817,63.155548,4.198801,410.0065,-9.2338266
195.8441,7.8604007,5.5455203,0.0,0,4.1475911,0.0,0.46156919,63.100349,4.152925,408.98779,-9.2345543
195.8485,7.9114342,5.5924306,0.0,0,4.1044359,0.0,0.46648848,63.162609,4.1119523,408.89508,-9.2337942
195.8529,7.9774156,5.6321249,0.0,0,4.0612807,0.0,0.47079819,63.427906,4.0683379,408.80237,-9.2337952
195.8573,8.0572033,5.6793056,0.0,0,4.0194993,0.0,0.47584558,63.732101,4.0223823,409.65881,-9.2323923
195.8617,8.0605774,5.7211676,0.0,0,3.9784563,0.0,0.48041871,63.479557,3.9839678,410.6651,-9.233223
195.8661,8.1066637,5.7622452,0.0,0,3.9374132,0.0,0.48486549,63.511982,3.9407673,411.7338,-9.2344742
195.8705,8.1728277,5.8027191,0.0,0,3.8963699,0.0,0.48929122,63.804817,3.8954802,412.84567,-9.2331104
195.8749,8.2178822,5.8474784,0.0,0,3.8553267,0.0,0.4941242,63.871643,3.8555768,413.61218,-9.2330551
195.8793,8.2405548,5.8863268,0.0,0,3.8142834,0.0,0.49831039,63.797882,3.8158109,413.63858,-9.2351522
195.8837,8.2829485,5.9271264,0.0,0,3.7732403,0.0,0.50298029,63.76606,3.7787719,413.66083,-9.2331772
195.8881,8.3889303,5.9687161,0.0,0,3.732197,0.0,0.50753474,64.273323,3.7330668,413.59473,-9.2323942
195.8925,8.4612656,6.013905,0.0,0,3.6911538,0.0,0.51253802,64.503883,3.6876769,413.52863,-9.2324009
195.8969,8.503602,6.0537267,0.0,0,3.6501107,0.0,0.51704264,64.588982,3.6501002,413.41147,-9.2346039
195.9013,8.5108356,6.0950999,0.0,0,3.6090674,0.0,0.52171999,64.356628,3.6106138,413.2793,-9.2337675
195.9057,8.5370102,6.1340327,0.0,0,3.5685976,0.0,0.52610439,64.191574,3.5691016,413.06116,-9.2340851
195.9101,8.5999031,6.1734672,0.0,0,3.5295517,0.0,0.53058922,64.429817,3.5309253,412.75708,-9.2337675
195.9145,8.7020149,6.208251,0.0,0,3.4905062,0.0,0.5344668,64.957085,3.4906445,412.44986,-9.233099
195.9189,8.7531967,6.2542434,0.0,0,3.4514608,0.0,0.54001409,64.948601,3.4501195,412.13202,-9.2338037
195.9233,8.8001127,6.2923613,0.0,0,3.412415,0.0,0.54409581,65.050682,3.4100258,411.81418,-9.2333527
195.9277,8.8621759,6.3344173,0.0,0,3.3733692,0.0,0.54909945,65.158546,3.3701839,410.94009,-9.2330256
195.9321,8.8873348,6.371129,0.0,0,3.3343236,0.0,0.55329758,65.072662,3.3318901,410.03949,-9.2343178
195.9365,8.9130144,6.4103866,0.0,0,3.2952783,0.0,0.55790585,64.975601,3.2955916,409.13889,-9.2338533
195.9409,8.9443102,6.4432507,0.0,0,3.2562327,0.0,0.56173509,64.908913,3.2569396,408.23828,-9.2351761
195.9453,9.0482416,6.4863515,0.0,0,3.2171869,0.0,0.56686199,65.310921,3.2208734,407.79822,-9.233902
195.9497,9.1559334,6.5240135,0.0,0,3.1781414,0.0,0.57123774,65.809731,3.1822793,408.02338,-9.2319059
195.9541,9.2151136,6.565661,0.0,0,3.1390958,0.0,0.57615894,65.96653,3.1435394,408.22864,-9.2338104
195.9585,9.2764273,6.6053395,0.0,0,3.101805,0.0,0.58084738,66.09449,3.1001871,408.30811,-9.2332163
195.9629,9.3726749,6.6456494,0.0,0,3.0646603,0.0,0.58588076,66.488243,3.0607252,408.38757,-9.2326193
195.9673,9.4082479,6.6889057,0.0,0,3.0275152,0.0,0.59100395,66.326927,3.0189581,408.02094,-9.2332411
195.9717,9.4034271,6.7260165,0.0,0,2.9903708,0.0,0.5955683,65.999329,2.9824214,407.58389,-9.2326298
195.9761,9.3529148,6.760057,0.0,0,2.9532259,0.0,0.5995031,65.399307,2.9467945,406.73206,-9.2336645
195.9805,9.4166641,6.793334,0.0,0,2.916081,0.0,0.60371029,65.505333,2.9141557,405.59305,-9.2337551
195.9849,9.5112581,6.8271914,0.0,0,2.8789363,0.0,0.60776156,65.923576,2.8783073,404.77853,-9.2330217
195.9893,9.6117001,6.8636575,0.0,0,2.8417914,0.0,0.61236799,66.385208,2.8453469,404.65936,-9.2327967
195.9937,9.7085695,6.9031167,0.0,0,2.8046467,0.0,0.61710614,66.73175,2.8006084,404.54379,-9.2337656
195.9981,9.760601,6.9413166,0.0,0,2.7675018,0.0,0.62212336,66.729691,2.7652488,404.50403,-9.2330866
196.0025,9.8283453,6.9800148,0.0,0,2.7303569,0.0,0.62668157,66.822571,2.7283146,404.46429,-9.2336035
196.0069,9.8851662,7.0174193,0.0,0,2.694227,0.0,0.63145101,66.966614,2.6888664,403.63654,-9.2332411
196.0113,9.9262409,7.0522375,0.0,0,2.658895,0.0,0.6357668,66.864372,2.6556914,402.577,-9.2339001
196.0157,9.9867706,7.0911121,0.0,0,2.6235628,0.0,0.64075589,67.024414,2.6215312,401.20563,-9.2339172
196.0201,10.076683,7.1272473,0.0,0,2.5882308,0.0,0.64513725,67.302162,2.5779498,399.52237,-9.2328825
196.0245,10.088541,7.1624289,0.0,0,2.5528989,0.0,0.64981627,67.050453,2.54882,397.71243,-9.2335854
196.0289,10.132465,7.1980591,0.0,0,2.5175667,0.0,0.65427768,67.086861,2.5132866,395.47168,-9.2339697
196.0333,10.185389,7.2329855,0.0,0,2.482235,0.0,0.65894526,67.094086,2.4775925,393.23093,-9.2339106
196.0377,10.251344,7.2654285,0.0,0,2.4469028,0.0,0.66298515,67.248489,2.4428108,393.06573,-9.2327652
196.0421,10.34587,7.3007975,0.0,0,2.4115708,0.0,0.66761619,67.517372,2.4088416,392.99939,-9.2332706
196.0465,10.421701,7.3389392,0.0,0,2.3762388,0.0,0.67254627,67.733673,2.371294,393.57553,-9.2342548
196.0509,10.499387,7.3738241,0.0,0,2.3409069,0.0,0.67722458,67.945351,2.3330038,394.45148,-9.2323494
196.0553,10.576333,7.4137211,0.0,0,2.3059127,0.0,0.68225276,68.089897,2.2982204,395.02881,-9.234561
196.0597,10.614758,7.4484949,0.0,0,2.2723055,0.0,0.68702823,68.014511,2.2618074,395.1748,-9.2352457
196.0641,10.639813,7.4799924,0.0,0,2.2386985,0.0,0.69096732,67.869164,2.227598,395.35156,-9.2323437
196.0685,10.645961,7.5181193,0.0,0,2.2050912,0.0,0.69629127,67.602516,2.1966796,395.72302,-9.2338686
196.0729,10.705442,7.5483098,0.0,0,2.171484,0.0,0.70015907,67.594467,2.1667209,396.09448,-9.2329121
196.0773,10.778207,7.5773039,0.0,0,2.1378767,0.0,0.70426118,67.856155,2.1320541,396.85526,-9.2337637
196.0817,10.883533,7.6131706,0.0,0,2.1042697,0.0,0.70889926,68.201088,2.0983613,397.67746,-9.2340269
196.0861,10.934076,7.6463356,0.0,0,2.0706627,0.0,0.71354216,68.215897,2.0667081,397.88843,-9.2328844
196.0905,11.003107,7.6825838,0.0,0,2.0370555,0.0,0.71827066,68.318138,2.0347149,397.67621,-9.2330074
196.0949,11.116567,7.7146397,0.0,0,2.0034482,0.0,0.72292376,68.678459,2.0007656,397.32059,-9.2332563
196.0993,11.208406,7.7544837,0.0,0,1.969841,0.0,0.72813493,68.919914,1.9651939,396.65762,-9.2340775
196.1037,11.213528,7.7853117,0.0,0,1.9362339,0.0,0.732517,68.622627,1.9292071,396.02176,-9.2337914
196.1081,11.260335,7.8197165,0.0,0,1.9039891,0.0,0.73718792,68.574509,1.9002322,395.95541,-9.2339735
196.1125,11.316923,7.8510118,0.0,0,1.8720186,0.0,0.74159706,68.622116,1.8656559,395.88904,-9.2333784
196.1169,11.410551,7.8860321,0.0,0,1.8400483,0.0,0.74620783,68.958984,1.8374561,396.30438,-9.2330265
196.1213,11.476727,7.9198651,0.0,0,1.8080778,0.0,0.75119823,68.996002,1.8003335,396.86139,-9.2339506
196.1257,11.534844,7.9497457,0.0,0,1.7761074,0.0,0.75535244,68.981041,1.7711438,397.45135,-9.2350826
196.1301,11.599524,7.9830775,0.0,0,1.744137,0.0,0.76024002,69.061913,1.73476,398.07428,-9.234149
196.1345,11.657738,8.0152063,0.0,0,1.7121667,0.0,0.76472753,69.092133,1.7050481,398.50143,-9.2335634
196.1389,11.677747,8.0471172,0.0,0,1.6801963,0.0,0.76924413,68.930634,1.6711677,398.26297,-9.233099
196.1433,11.708733,8.0754128,0.0,0,1.6482258,0.0,0.77338845,68.815857,1.6425631,398.02448,-9.234107
196.1477,11.834535,8.108861,0.0,0,1.6162554,0.0,0.77803057,69.185684,1.6098728,396.62091,-9.2322474
196.1521,11.942316,8.1409702,0.0,0,1.5842849,0.0,0.7827273,69.496254,1.5777878,395.16187,-9.2331839
196.1565,12.048492,8.1721306,0.0,0,1.5530447,0.0,0.78724104,69.774826,1.5480081,394.26328,-9.2337046
196.1609,12.049994,8.2062006,0.0,0,1.5226319,0.0,0.79223543,69.4702,1.5197552,393.62619,-9.2332468
196.1653,12.118591,8.2368202,0.0,0,1.4922191,0.0,0.79664302,69.534447,1.4824778,393.44522,-9.2328224
196.1697,12.209736,8.2698336,0.0,0,1.4618063,0.0,0.80145615,69.774147,1.4597495,393.923,-9.2328749
196.1741,12.342427,8.3001461,0.0,0,1.4313934,0.0,0.80609173,70.141678,1.4226956,393.93378,-9.234333
196.1785,12.351285,8.334796,0.0,0,1.4009807,0.0,0.81121343,69.90551,1.3904692,390.98691,-9.2338524
196.1829,12.382967,8.3657045,0.0,0,1.3705679,0.0,0.8158536,69.713776,1.3598069,388.04004,-9.2325592
196.1873,12.424006,8.3945341,0.0,0,1.3401551,0.0,0.82001239,69.686745,1.331575,384.97849,-9.2327461
196.1917,12.505802,8.4215765,0.0,0,1.3097425,0.0,0.82420838,69.856651,1.3008583,381.8988,-9.2341604
196.1961,12.573488,8.451026,0.0,0,1.2793295,0.0,0.82864726,69.921127,1.2738161,380.20663,-9.2337885
196.2005,12.660674,8.4786921,0.0,0,1.2489167,0.0,0.83291417,70.085243,1.2458168,379.47501,-9.2326727
196.2049,12.795728,8.5111332,0.0,0,1.2186602,0.0,0.83772963,70.477173,1.2135125,378.89578,-9.2336044
196.2093,12.914409,8.5420904,0.0,0,1.1897346,0.0,0.8425923,70.789101,1.179885,378.64304,-9.2337914
196.2137,12.916496,8.57652,0.0,0,1.160809,0.0,0.84790218,70.453293,1.1496078,378.41147,-9.2337341
196.2181,12.898405,8.6019726,0.0,0,1.1318834,0.0,0.85169494,70.075981,1.1195178,378.6243,-9.2325993
196.2225,12.978456,8.6314764,0.0,0,1.1029578,0.0,0.85644156,70.155502,1.0944498,378.83713,-9.2325964
196.2269,13.030951,8.6561604,0.0,0,1.0740322,0.0,0.86025691,70.206619,1.0689723,378.69022,-9.233819
196.2313,13.127508,8.6839333,0.0,0,1.0451066,0.0,0.86460012,70.382515,1.0418205,378.43747,-9.2327738
196.2357,13.235196,8.7117605,0.0,0,1.016181,0.0,0.8691448,70.664391,1.011631,378.73001,-9.23248
196.2401,13.365877,8.7435865,0.0,0,0.98725533,0.0,0.87403226,71.00663,0.97836304,379.56781,-9.2322865
196.2445,13.473073,8.7710648,0.0,0,0.95832974,0.0,0.87852699,71.284698,0.95051104,380.22427,-9.2330437
196.2489,13.492402,8.8036985,0.0,0,0.92940414,0.0,0.88344538,71.014786,0.92146903,380.26419,-9.2334938
196.2533,13.534635,8.8263779,0.0,0,0.90047848,0.0,0.88729507,70.96656,0.89516568,380.30411,-9.2322206
196.2577,13.64837,8.8598051,0.0,0,0.87260348,0.0,0.89252168,71.190849,0.86663198,380.21722,-9.2337799
196.2621,13.837712,8.8869534,0.0,0,0.84509462,0.0,0.8970961,71.781082,0.84034008,380.12436,-9.2324715
196.2665,13.897135,8.9208527,0.0,0,0.81758583,0.0,0.90250504,71.790329,0.80815655,381.03073,-9.2319422
196.2709,13.937237,8.9445944,0.0,0,0.79007703,0.0,0.90631914,71.696808,0.78174043,382.40347,-9.2317791
196.2753,13.948485,8.9773703,0.0,0,0.76256824,0.0,0.91178858,71.376877,0.74825734,383.63422,-9.2317162
196.2797,14.037157,9.0006447,0.0,0,0.73505944,0.0,0.91574639,71.481239,0.72040027,384.7756,-9.2332115
196.2841,14.094382,9.0315752,0.0,0,0.70755064,0.0,0.92076826,71.43409,0.69762981,385.84009,-9.2322206
196.2885,14.123909,9.0527754,0.0,0,0.68004185,0.0,0.92423636,71.416367,0.67357934,386.75586,-9.2343483
196.2929,14.195067,9.0805969,0.0,0,0.65253305,0.0,0.92910844,71.34584,0.64613324,387.64087,-9.2334461
196.2973,14.288822,9.1044521,0.0,0,0.62502426,0.0,0.93317366,71.532845,0.62207127,388.10538,-9.2327127
196.3017,14.498952,9.1342258,0.0,0,0.59751546,0.0,0.93792617,72.250275,0.59289092,388.56989,-9.233325
196.3061,14.610026,9.1574783,0.0,0,0.57050872,0.0,0.94217569,72.540413,0.56798005,388.66492,-9.2336893
196.3105,14.619495,9.1888895,0.0,0,0.54432869,0.0,0.94744617,72.197632,0.53649408,388.66492,-9.2324905
196.3149,13.711081,9.1927824,0.0,0,0.51814872,0.0,0.94819576,67.680542,0.51867223,388.69266,-9.2340755
196.3193,13.28219,9.201314,0.0,0,0.49196872,0.0,0.94948757,65.408524,0.50430554,388.74576,-9.2340641
196.3237,13.005775,9.2074347,0.0,0,0.46578872,0.0,0.95059752,64.000916,0.48986802,388.87848,-9.2331228
196.3281,12.788419,9.2170467,0.0,0,0.43960872,0.0,0.95218748,62.857944,0.47292027,389.25009,-9.2347689
196.3325,12.449235,9.2165003,0.0,0,0.41342869,0.0,0.95221382,61.199577,0.45509982,389.62167,-9.2345982
196.3369,12.119824,9.2233524,0.0,0,0.38724869,0.0,0.95314884,59.493382,0.43612641,389.69498,-9.2350187
196.3413,11.78637,9.2200689,0.0,0,0.36106867,0.0,0.95281845,57.911938,0.43352172,389.76135,-9.2347841
196.3457,11.504379,9.225276,0.0,0,0.33488867,0.0,0.95357084,56.470383,0.42541936,389.72485,-9.2343073
196.3501,11.418599,9.2227125,0.0,0,0.3087087,0.0,0.9532547,56.086617,0.4143804,389.64523,-9.236311
196.3545,11.500471,9.2295551,0.0,0,0.28255266,0.0,0.95416605,56.373569,0.39179659,389.60571,-9.2358551
196.3589,11.756529,9.228653,0.0,0,0.25765175,0.0,0.95433056,57.628693,0.35973355,389.61896,-9.2339954
196.3633,11.955013,9.2356977,0.0,0,0.23275654,0.0,0.95513785,58.561253,0.32317099,389.62378,-9.2349787
196.3677,12.059238,9.2361174,0.0,0,0.20786138,0.0,0.95546925,59.090195,0.28921652,389.58398,-9.234623
196.3721,12.09975,9.2414093,0.0,0,0.18296619,0.0,0.95622754,59.230404,0.26111248,389.54416,-9.2345181
196.3765,12.111418,9.2423534,0.0,0,0.15807098,0.0,0.95674682,59.252316,0.23207974,389.43378,-9.2331181
196.3809,12.093085,9.2477293,0.0,0,0.13317578,0.0,0.95718491,59.132824,0.20395494,389.31433,-9.2352276
196.3853,12.008957,9.2479763,0.0,0,0.10828056,0.0,0.95760274,58.736874,0.18361485,389.18674,-9.2353048
196.3897,11.95392,9.252121,0.0,0,0.083385363,0.0,0.95794535,58.363968,0.15296495,389.05402,-9.2337532
196.3941,11.886081,9.2511454,0.0,0,0.058490161,0.0,0.95824569,58.071911,0.13380691,388.93939,-9.2341509
196.3985,11.836006,9.2561026,0.0,0,0.033594958,0.0,0.95864588,57.799152,0.11465295,388.85977,-9.2330027
196.4029,11.761067,9.257144,0.0,0,0.0086997608,0.0,0.9594959,57.398891,0.09485554,388.78012,-9.2344475
196.4073,11.689598,9.262578,0.0,0,-0.01580043,0.0,0.95970231,57.004372,0.077317283,388.70047,-9.2344809
196.4117,11.618515,9.2614326,0.0,0,-0.040088434,0.0,0.95998192,56.63702,0.059539489,388.62085,-9.2339563
196.4161,11.550061,9.2664938,0.0,0,-0.064376429,0.0,0.96030837,56.293457,0.046424255,388.53067,-9.2344809
196.4205,11.436143,9.2614365,0.0,0,-0.088664427,0.0,0.95993477,55.808899,0.035820436,388.43777,-9.2346897
196.4249,11.302818,9.2680206,15.721955,0,-0.044744857,449.55496,0.96070474,55.06337,0.024809906,388.32407,-9.2334719
196.4293,11.172287,9.2644186,45.799007,0,0.75208735,450.0,0.96067566,54.428669,0.022552086,388.19135,-9.2343845
196.4337,9.4488859,9.2654743,68.356934,0,1.5489455,450.0,0.96039808,46.197128,0.09143091,388.02213,-9.2334499
196.4381,5.2698612,9.2124348,68.356934,0,2.3458037,450.0,0.95157635,26.08453,0.32808051,387.74341,-9.2385225
196.4425,0.93320352,9.2050381,68.356934,0,3.1426611,450.0,0.94993794,4.3783679,0.93763196,387.46472,-9.2424507
196.4469,0.75240356,9.1925945,68.423073,0,3.9395185,450.0,0.94856656,3.6038461,2.2856748,387.51025,-9.2414894
196.4513,0.56570774,9.2198658,68.490746,0,4.7363758,450.0,0.95283502,2.7311623,3.3197441,387.56332,-9.241643
196.4557,0.65959364,9.2036486,68.51075,0,5.5332332,450.0,0.95021904,3.3434813,4.0895061,387.63513,-9.2403097
196.4601,0.67447859,9.2160511,68.51075,0,6.3300915,450.0,0.95223284,3.3127353,4.8481245,387.71475,-9.2388077
196.4645,0.55131352,9.2025166,68.51075,0,7.1269488,450.0,0.95006061,2.6965272,5.6099677,387.77719,-9.2388401
196.4689,0.50602651,9.2060976,68.51075,0,7.9238062,450.0,0.95023,2.5235155,6.3980813,387.81702,-9.2379408
196.4733,0.47757539,9.2019501,68.51075,0,8.720664,450.0,0.94989067,2.327302,7.2346387,387.88007,-9.2384853
196.4777,0.48779935,9.1826735,68.51075,0,9.5175228,450.0,0.94661671,2.3799825,8.0727282,388.06586,-9.2375822
196.4821,0.519063,9.2006912,68.51075,0,10.314381,450.0,0.94979256,2.4858313,8.8891773,388.25165,-9.2361078
196.4865,0.71029091,9.2034798,68.38649,0,11.111238,450.0,0.950216,3.5091209,9.7196569,388.40216,-9.2353935
196.4909,0.42447886,9.2067308,68.2463,0,11.908095,450.0,0.95102531,2.1270504,10.518483,388.54819,-9.2359838
196.4953,0.49356154,9.2007465,68.192139,0,12.704953,450.0,0.94965929,2.361362,11.313481,388.68604,-9.2363043
196.4997,0.62302196,9.2107553,68.192139,0,13.501811,450.0,0.95150077,3.045747,12.087865,388.81876,-9.235467
196.5041,0.47577628,9.2032909,68.169067,0,14.298668,450.0,0.95017761,2.3557103,12.858096,388.96503,-9.2361498
196.5085,0.52654612,9.1877356,68.101395,0,15.095526,450.0,0.94777822,2.657464,13.650998,389.13757,-9.2370405
196.5129,0.47450241,9.201766,68.03833,0,15.892384,450.0,0.95005482,2.3231008,14.455739,389.3092,-9.2372446
196.5173,0.48327735,9.1783075,68.03833,0,16.689241,450.0,0.94647008,2.3634868,15.27352,389.46848,-9.2355318
196.5217,0.54289258,9.2032118,68.03833,0,17.486099,450.0,0.95043516,2.6519723,16.068129,389.62772,-9.2355061
196.5261,0.74503243,9.2012129,67.980652,0,18.0,450.0,0.95016932,3.6061089,16.866491,389.74475,-9.2354555
196.5305,0.5181998,9.2100353,67.908142,0,18.0,450.0,0.95167243,2.5493362,17.639112,389.85095,-9.2362213
196.5349,0.74856877,9.1978683,67.873535,0,18.0,450.0,0.94977218,3.6603105,18.239491,389.94324,-9.2390947
196.5393,1.2897749,9.213315,67.873535,0,18.0,450.0,0.95227695,6.2676315,18.510612,390.02286,-9.243928
196.5437,1.3092622,9.2155886,67.855408,0,18.0,450.0,0.95292026,6.4388142,18.373606,390.13235,-9.2587948
196.5481,1.330448,9.2087708,67.782898,0,18.0,450.0,0.95156401,6.603076,18.138292,390.33142,-9.2857151
196.5525,1.1974531,9.2179899,67.710388,0,18.0,450.0,0.95348358,5.9017191,18.036869,390.53052,-9.3218546
196.5569,1.0472636,9.206193,67.70874,0,18.0,450.0,0.95140737,5.1543536,18.051531,390.65176,-9.360589
196.5613,1.2860417,9.2133312,67.70874,0,18.0,450.0,0.95274794,6.2842603,18.094547,390.77124,-9.3970757
196.5657,1.2961768,9.2171011,67.70874,0,18.0,450.0,0.95318907,6.197257,18.145563,390.87198,-9.4312296
196.5701,1.143425,9.2263556,67.70874,0,18.0,450.0,0.95498341,5.6010284,18.144247,390.96487,-9.4638186
196.5745,1.2159963,9.2127028,67.70874,0,18.0,450.0,0.95272255,5.9727139,18.148258,391.0578,-9.496316
196.5789,1.32493,9.2068472,67.70874,0,18.0,450.0,0.95150918,6.4552026,18.140724,391.1507,-9.5273714
196.5833,1.3209534,9.2149515,67.70874,0,18.0,450.0,0.95303708,6.4947491,18.133373,391.24149,-9.5615244
196.5877,1.3307707,9.1941023,67.70874,0,18.0,450.0,0.94944352,6.6163707,18.127892,391.32111,-9.5952644
196.5921,1.2060205,9.2157345,67.70874,0,18.0,450.0,0.95345378,5.9563408,18.123062,391.40073,-9.6262026
196.5965,1.0918144,9.2038679,67.70874,0,18.0,450.0,0.9513821,5.334506,18.122824,391.48038,-9.6597767
196.6009,1.3645513,9.2164879,67.70874,0,18.0,450.0,0.95359141,6.6994314,18.119867,391.56,-9.6920042
196.6053,1.240157,9.208436,67.753235,0,18.0,450.0,0.95218629,6.1913247,18.112469,391.60706,-9.726841
196.6097,1.1113518,9.2274323,67.825745,0,18.0,450.0,0.95547014,5.4494419,18.11161,391.63361,-9.7597809
196.6141,1.2455139,9.2084293,67.873535,0,18.0,450.0,0.95229203,6.0973587,18.112448,391.64658,-9.7908392
196.6185,1.3186735,9.1980667,67.873535,0,18.0,450.0,0.95040941,6.4432006,18.109613,391.63327,-9.8243046
196.6229,1.2998283,9.209569,67.878479,0,18.0,450.0,0.95243543,6.4325967,18.111294,391.62543,-9.8578138
196.6273,1.3530892,9.1971292,67.950989,0,18.0,450.0,0.95066333,6.7069488,18.104103,391.6918,-9.8895493
196.6317,1.2159567,9.2094374,68.023499,0,18.0,450.0,0.95252627,5.9403825,18.103844,391.75815,-9.9243135
196.6361,1.1210316,9.2115316,68.03833,0,18.0,450.0,0.95299518,5.4910479,18.100315,391.84564,-9.9565954
196.6405,1.3857287,9.2170382,68.03833,0,18.0,450.0,0.95389426,6.8328085,18.095104,391.93857,-9.9889107
196.6449,1.245608,9.2105837,68.03833,0,18.0,450.0,0.95295268,6.1419516,18.097363,391.97598,-10.022408
196.6493,1.1346406,9.2180023,68.03833,0,18.0,450.0,0.95402944,5.5479207,18.09543,391.96268,-10.054881
196.6537,1.2920018,9.2084351,68.03833,0,18.0,450.0,0.95249134,6.3012958,18.094357,391.96268,-10.088984
196.6581,1.286078,9.1915846,68.03833,0,18.0,450.0,0.94917613,6.3061185,18.094198,392.0025,-10.120459
196.6625,1.2760413,9.2108183,68.03833,0,18.0,450.0,0.95291775,6.286788,18.089453,392.0423,-10.153401
196.6669,1.4219195,9.2003193,68.03833,0,18.0,450.0,0.95126814,7.0493717,18.089211,392.14697,-10.188234
196.6713,1.2722713,9.2147598,68.03833,0,18.0,450.0,0.95392877,6.2183065,18.087,392.25317,-10.219011
196.6757,1.2325081,9.206358,68.03833,0,18.0,450.0,0.95208222,6.2573571,18.085951,392.3313,-10.251454
196.6801,1.3718309,9.2180309,68.03833,0,18.0,450.0,0.95440763,6.7650161,18.081814,392.39764,-10.286705
196.6845,1.2361521,9.2065125,68.067558,0,18.0,450.0,0.95232415,6.1048179,18.081873,392.44681,-10.318956
196.6889,1.1705599,9.2143984,68.135231,0,18.0,450.0,0.95348513,5.7152653,18.0776,392.47336,-10.350421
196.6933,1.3265848,9.2044373,68.192139,0,18.0,450.0,0.95186865,6.5126972,18.082947,392.49988,-10.385011
196.6977,1.2130749,9.1859312,68.192139,0,18.0,450.0,0.9487192,5.9910307,18.078861,392.52643,-10.41686
196.7021,1.2499083,9.2044392,68.192139,0,18.0,450.0,0.95211112,6.1538968,18.083004,392.55298,-10.450636
196.7065,1.4997355,9.2056074,68.192139,0,18.0,450.0,0.95245206,7.3635931,18.080723,392.59128,-10.482118
196.7109,1.2969275,9.2111378,68.192139,0,18.0,450.0,0.95324278,6.3363895,18.07626,392.6311,-10.514854
196.7153,1.4190099,9.2050629,68.192139,0,18.0,450.0,0.95223707,6.9070077,18.074511,392.65463,-10.549933
196.7197,1.3835725,9.2183199,68.192139,0,18.0,450.0,0.95432556,6.7900362,18.074965,392.66788,-10.581924
196.7241,1.2559756,9.2061892,68.216858,0,18.0,450.0,0.95239252,6.1633286,18.073862,392.69925,-10.615183
196.7285,1.2661798,9.2019062,68.289368,0,18.0,450.0,0.95132422,6.2001786,18.071304,392.76563,-10.646239
196.7329,1.3300917,9.2081299,68.356934,0,18.0,450.0,0.95272595,6.5770864,18.0693,392.82925,-10.680963
196.7373,1.1441959,9.1836081,68.356934,0,18.0,450.0,0.94850546,5.6431651,18.068316,392.85583,-10.713255
196.7417,1.2831432,9.2063808,68.356934,0,18.0,450.0,0.95231324,6.2908425,18.062181,392.88239,-10.746481
196.7461,1.5947365,9.2101107,68.356934,0,18.0,450.0,0.95289034,7.7867975,18.068478,392.93005,-10.781244
196.7505,1.3060129,9.217206,68.356934,0,18.0,450.0,0.9542318,6.4062157,18.059481,392.98312,-10.813022
196.7549,1.2893145,9.2021675,68.356934,0,18.0,450.0,0.95155543,6.3997631,18.066017,393.03619,-10.846344
196.7593,1.35455,9.2107859,68.356934,0,18.0,450.0,0.95303571,6.6606927,18.065964,393.08929,-10.879636
196.7637,1.3277916,9.2033424,68.373856,0,18.0,450.0,0.95161784,6.5066218,18.061058,393.12909,-10.910709
196.7681,1.3215948,9.1912527,68.441528,0,18.0,450.0,0.94951433,6.5244546,18.061007,393.12909,-10.944659
196.7725,1.2970501,9.2051096,68.509209,0,18.0,450.0,0.95202142,6.4391456,18.056503,393.12909,-10.977222
196.7769,1.1293973,9.1856165,68.51075,0,18.0,450.0,0.94887489,5.5688953,18.056984,393.19394,-11.008606
196.7813,1.3305013,9.2054834,68.51075,0,18.0,450.0,0.95206487,6.5537243,18.057446,393.26031,-11.043581
196.7857,1.5856837,9.2082052,68.51075,0,18.0,450.0,0.95249903,7.6640568,18.058567,393.31732,-11.074414
196.7901,1.2603517,9.2169485,68.51075,0,18.0,450.0,0.9540596,6.1769743,18.055786,393.37039,-11.109953
196.7945,1.2824776,9.1991577,68.51075,0,18.0,450.0,0.95104057,6.317297,18.053503,393.39484,-11.143946
196.7989,1.3610363,9.2024412,68.51075,0,18.0,450.0,0.95138389,6.6402364,18.052423,393.38159,-11.175307
196.8033,1.378674,9.2015457,68.521507,0,18.0,450.0,0.95121413,6.7376609,18.051256,393.37042,-11.208506
196.8077,1.3830861,9.1854782,68.589188,0,18.0,450.0,0.94824469,6.8940854,18.051443,393.37042,-11.240568
196.8121,1.278026,9.2043705,68.65686,0,18.0,450.0,0.95183933,6.3248906,18.048592,393.37042,-11.2729
196.8165,1.1380496,9.1903324,68.664551,0,18.0,450.0,0.94939631,5.5586743,18.049538,393.41748,-11.304011
196.8209,1.4109896,9.2011595,68.664551,0,18.0,450.0,0.95112783,6.9293556,18.047876,393.47058,-11.337465
197.2244,1.1975176,9.2113218,0.0,0,18.0,0.001595666,0.95206106,5.8817658,18.012613,380.45288,-11.481761
199.4244,1.0009756,9.2238693,0.0,0,18.0,1.5917635e-33,0.95431036,4.9027357,18.000282,329.83911,-11.481361
201.6244,0.9712593,9.2341366,0.0,0,18.0,1.4012985e-45,0.95600915,4.7498999,17.999258,298.49893,-11.481667
203.8244,0.9810726,9.2441912,0.0,0,18.0,1.4012985e-45,0.9578253,4.7927165,18.000105,275.75769,-11.481318
206.0244,0.99495423,9.2544928,0.0,0,18.0,1.4012985e-45,0.95958924,4.8506393,17.999228,255.90279,-11.481321
208.2244,1.0072006,9.26336,0.0,0,18.0,1.4012985e-45,0.96122497,4.9056149,17.999577,238.57346,-11.481733
210.4244,1.0160288,9.2713337,0.0,0,18.0,1.4012985e-45,0.96264112,4.9460764,17.999895,222.64262,-11.481591
212.6244,1.0085754,9.2790127,0.0,0,18.0,1.4012985e-45,0.96392745,4.90207,18.000799,208.39337,-11.481417
214.8244,1.0252701,9.2856064,0.0,0,18.0,1.4012985e-45,0.96513557,4.9776635,17.999779,195.17276,-11.481524
217.0244,1.0252599,9.2926426,0.0,0,18.0,1.4012985e-45,0.96622574,4.9706154,17.99951,182.98996,-11.481629
219.2244,1.0352038,9.2987823,0.0,0,18.0,1.4012985e-45,0.96734387,5.0104194,17.999102,171.86449,-11.48197
221.4244,1.0252509,9.3047676,0.0,0,18.0,1.4012985e-45,0.9683544,4.9595742,18.000013,161.44449,-11.481304
223.6244,1.0133257,9.3101082,0.0,0,18.0,1.4012985e-45,0.9693467,4.8924336,18.000002,152.10725,-11.481157
225.8244,1.0288624,9.3149481,0.0,0,18.0,1.4012985e-45,0.97019911,4.9550385,18.000608,143.48441,-11.481019
228.0244,1.0488483,9.3205929,0.0,0,18.0,1.4012985e-45,0.97127092,5.0474186,17.999708,135.41907,-11.481773
230.2244,1.0333812,9.3250084,0.0,0,18.0,1.4012985e-45,0.97208697,4.9666095,18.000193,127.85171,-11.481064
232.4244,1.0377637,9.3298101,0.0,0,18.0,1.4012985e-45,0.9727993,4.9893918,17.998972,120.83357,-11.481659
234.6244,1.030811,9.3339739,0.0,0,18.0,1.4012985e-45,0.97359151,4.9594069,18.000807,114.38421,-11.480628
236.8244,1.0497137,9.3378668,0.0,0,18.0,1.4012985e-45,0.97413194,5.0443201,18.000425,108.08189,-11.480381
239.0244,1.0439708,9.3411713,0.0,0,18.0,1.4012985e-45,0.97480381,5.0153275,17.99905,102.33075,-11.48044
241.2244,1.066853,9.3456764,0.0,0,18.0,1.4012985e-45,0.97560388,5.1267066,17.999556,96.886429,-11.481343
243.4244,1.0546917,9.3485279,0.0,0,18.0,1.4012985e-45,0.97620559,5.0678654,18.00009,91.852539,-11.481371
245.6244,1.056996,9.3517656,0.0,0,18.0,1.4012985e-45,0.9767434,5.0675402,17.999508,87.267105,-11.4815
247.8244,1.037604,9.3550596,0.0,0,18.0,1.4012985e-45,0.97733033,4.9748788,17.999483,82.895264,-11.480892
250.0244,1.0373579,9.3576641,0.0,0,18.0,1.4012985e-45,0.97784233,4.9795227,18.000683,78.794098,-11.480249
252.2244,1.053934,9.3608112,0.0,0,18.0,1.4012985e-45,0.9782604,5.0437121,17.999857,75.025223,-11.480265
254.4244,1.0576404,9.3633156,0.0,0,18.0,1.4012985e-45,0.97877318,5.0605922,18.000593,71.384727,-11.480648
256.6244,1.0647019,9.3659916,0.0,0,18.0,1.4012985e-45,0.97915256,5.0876713,18.00001,68.140099,-11.481193
256.8244,1.0749161,9.3663158,0.0,0,18.0,1.4012985e-45,0.97918493,5.1448312,17.999107,67.785141,-11.480979