File: raw data/testID_0252.csv
Time(sec),Force(kN),Jaw(mm),PowAngle(deg),Power(W),Pram,PTemp,Strain,Stress(MPa),Stroke(mm),TC1(C),wedge(mm)
0.0,1.5330845,0.53966397,0.0,0,10.594783,0.0012583095,0.03665477,18.834166,10.594805,13.04723,-9.1135635
2.2,1.4452875,-0.0032918144,0.0,0,10.594783,6.5158744,-0.00019567041,18.394897,10.594727,12.977545,-9.4791994
4.4,1.3953555,-0.0033743086,0.0,0,10.594783,13.115874,-0.00020087637,17.77611,10.594769,13.028536,-9.4764271
6.6,1.3735482,-0.003837835,31.340778,0,10.594783,19.715878,-0.00022784444,17.507521,10.59485,13.984473,-9.4723368
8.8,1.3904382,-0.0077542793,41.19207,0,10.594783,26.315876,-0.00048961834,17.705673,10.595276,19.992716,-9.4680853
11.0,1.3897256,-0.01198619,42.176865,0,10.594783,32.915894,-0.00078459707,17.70331,10.594569,29.853785,-9.4652939
13.2,1.3507247,-0.013827202,40.793716,0,10.594783,39.515884,-0.00091038545,17.2321,10.594811,38.982746,-9.4618425
15.4,1.3399991,-0.0144471,39.95647,0,10.594783,46.115883,-0.00097205618,17.073513,10.59544,46.207935,-9.4586639
17.6,1.3284636,-0.015433215,40.572506,0,10.594783,52.715881,-0.0010413146,16.940474,10.595246,52.525177,-9.454874
19.8,1.3213385,-0.016154433,41.198727,0,10.594783,59.315876,-0.0010914819,16.829498,10.594742,58.792934,-9.451148
22.0,1.3099566,-0.017508345,41.802975,0,10.594783,65.915886,-0.0011765385,16.690659,10.595132,65.495819,-9.4482164
24.2,1.3047317,-0.018617319,42.318066,0,10.594783,72.515877,-0.0012715592,16.634155,10.594424,72.054573,-9.4444695
26.4,1.2901659,-0.020058075,42.396236,0,10.594783,79.115868,-0.001363731,16.447889,10.594173,78.794861,-9.4401789
28.6,1.298012,-0.021147273,42.671833,0,10.594783,85.715874,-0.0014324925,16.550249,10.595044,85.466812,-9.4366589
30.8,1.2938734,-0.022994578,42.689209,0,10.594783,92.31588,-0.0015462163,16.49332,10.595076,92.194351,-9.4332781
33.0,1.2811115,-0.023439942,42.976589,0,10.594783,98.915878,-0.001560676,16.333269,10.594633,98.833473,-9.4297285
35.2,1.2730261,-0.024439478,42.978512,0,10.594783,105.5159,-0.0016171384,16.253046,10.594887,105.30759,-9.4263582
37.4,1.2758815,-0.025831556,43.527828,0,10.594783,112.11588,-0.0017064684,16.281197,10.5952,111.8578,-9.4224358
39.6,1.2770966,-0.027686505,43.527828,0,10.594783,118.71589,-0.0018428522,16.289865,10.594535,118.59207,-9.4189587
41.8,1.2677704,-0.028875791,43.688656,0,10.594783,125.3159,-0.0019213348,16.177565,10.595095,125.0575,-9.4147043
44.0,1.2613851,-0.0307246,44.019714,0,10.594783,131.91588,-0.0020449522,16.099356,10.59482,131.77113,-9.411437
46.2,1.2698032,-0.03251243,44.077145,0,10.594783,138.51588,-0.0021695201,16.204908,10.594959,138.3602,-9.4080858
48.4,1.2682062,-0.035457466,44.311073,0,10.594783,145.11588,-0.0023560885,16.188112,10.594594,144.88586,-9.4044781
50.6,1.2633173,-0.036737088,44.363815,0,10.594783,151.71587,-0.0024381338,16.128443,10.594841,151.62796,-9.4009085
52.8,1.2613822,-0.039080717,44.604488,0,10.594783,158.31587,-0.002585643,16.10804,10.595675,158.12538,-9.3970222
55.0,1.2697269,-0.042234529,44.931602,0,10.594783,164.91589,-0.0027892466,16.207582,10.593875,164.65747,-9.3935375
57.2,1.2512269,-0.044800539,44.982231,0,10.594783,171.51591,-0.0029527103,15.976382,10.595057,171.40515,-9.3897133
59.4,1.2586346,-0.047698181,44.790226,0,10.594783,178.11589,-0.0031424314,16.063046,10.595106,178.10646,-9.3861837
61.6,1.2595437,-0.050397355,44.887638,0,10.594783,184.71588,-0.0033232167,16.10412,10.594995,184.69296,-9.3829613
63.8,1.2709428,-0.05452178,45.410942,0,10.594783,191.31589,-0.0036030335,16.239357,10.594744,191.03493,-9.3790636
66.0,1.2484252,-0.057048507,45.588284,0,10.594783,197.91589,-0.003783395,15.945284,10.595165,197.757,-9.3753862
68.2,1.2547857,-0.060347531,45.471779,0,10.594783,204.51588,-0.0040061292,16.039709,10.59436,204.39604,-9.3718081
70.4,1.2656376,-0.063524596,45.615231,0,10.594783,211.11588,-0.0042288741,16.181259,10.594904,211.00261,-9.3684235
72.6,1.2674856,-0.067335248,45.615231,0,10.594783,217.71588,-0.0044831834,16.222532,10.594554,217.61833,-9.3648653
74.8,1.2662197,-0.070800707,45.615238,0,10.594783,224.31589,-0.0047213519,16.205698,10.595599,224.20638,-9.3613815
77.0,1.2713614,-0.074709378,45.615238,0,10.594783,230.91591,-0.0049852943,16.276054,10.59561,230.96024,-9.357583
79.2,1.2809329,-0.078953959,45.814445,0,10.594783,237.5159,-0.0052706064,16.404015,10.595243,237.45935,-9.3537836
81.4,1.2917466,-0.08329045,45.615238,0,10.594783,244.11589,-0.0055594225,16.557474,10.594038,244.22754,-9.3502159
83.6,1.290527,-0.087750308,45.194599,0,10.594783,250.7159,-0.0058633005,16.517303,10.594921,250.98186,-9.3461733
85.8,1.3089995,-0.091495223,45.614044,0,10.594783,257.31616,-0.0061103161,16.769913,10.594523,257.34818,-9.3429871
88.0,1.3034731,-0.096600011,45.292591,0,10.594783,263.91586,-0.0064562047,16.705442,10.59446,264.07474,-9.339098
90.2,1.3185687,-0.10147905,45.454792,0,10.594783,270.51587,-0.0067673246,16.900827,10.594755,270.50531,-9.3357372
92.4,1.3217623,-0.10604514,45.322094,0,10.594783,277.11584,-0.0070671118,16.943554,10.594343,277.10965,-9.3319817
94.6,1.3266238,-0.11042137,45.325211,0,10.594783,283.71585,-0.0073478222,17.012232,10.594621,283.72809,-9.3286104
96.8,1.3269354,-0.11448132,45.443947,0,10.594783,290.31592,-0.0076045473,17.01392,10.595019,290.32043,-9.3245459
99.0,1.3259064,-0.11853613,45.25272,0,10.594783,296.91592,-0.0078764651,16.990879,10.595289,296.95563,-9.3208361
101.2,1.3319846,-0.1233688,45.133942,0,10.594783,303.51593,-0.0081903217,17.096327,10.595583,303.55716,-9.3174591
103.4,1.3262616,-0.12771139,45.214233,0,10.594783,310.11591,-0.008481551,17.022322,10.594491,310.14838,-9.3137312
105.6,1.3335241,-0.13199693,45.123257,0,10.594783,316.71591,-0.008760401,17.141333,10.594988,316.78229,-9.3102407
107.8,1.3323005,-0.13585944,45.127178,0,10.594783,323.31589,-0.009000794,17.12533,10.595655,323.28763,-9.3068428
110.0,1.3444543,-0.13973702,45.493977,0,10.594783,329.91586,-0.009266031,17.27701,10.595495,329.85831,-9.3033438
112.2,1.3291937,-0.14355007,45.468346,0,10.594783,336.51587,-0.0095082438,17.078217,10.594658,336.4794,-9.2994442
114.4,1.3323345,-0.14642625,45.405891,0,10.594783,343.11588,-0.0096954415,17.142467,10.595707,343.12006,-9.2959805
116.6,1.3161184,-0.14980748,45.269432,0,10.594783,349.71591,-0.0099268658,16.92264,10.594896,349.74277,-9.2919083
118.8,1.3001629,-0.15400265,45.568893,0,10.594783,356.31592,-0.010205898,16.730106,10.594472,356.25809,-9.2885513
121.0,1.2724037,-0.15419005,45.126778,0,10.594783,362.91589,-0.010206313,16.36171,10.594341,362.98615,-9.2847891
123.2,1.2430346,-0.15562323,45.389927,0,10.594783,369.5159,-0.010308075,15.988766,10.594834,369.52936,-9.2809191
125.4,1.24286,-0.15587239,45.568813,0,10.594783,376.11588,-0.010324323,15.990396,10.595423,376.13403,-9.2773552
127.6,1.2416772,-0.15512642,45.615231,0,10.594783,382.71588,-0.010279393,15.990451,10.595602,382.69388,-9.2737169
129.8,1.2352098,-0.15473153,45.615231,0,10.594783,389.31589,-0.010258408,15.884892,10.595692,389.22,-9.2701063
132.0,1.2145112,-0.14883593,45.676182,0,10.594783,395.91589,-0.0098746251,15.631284,10.594954,395.77438,-9.2667007
134.2,1.2158495,-0.14178506,45.612419,0,10.594783,402.5159,-0.0094067426,15.619514,10.59457,402.6781,-9.262949
136.4,1.2321451,-0.1318264,45.304073,0,10.594783,409.11594,-0.0087737208,15.832858,10.595018,409.22537,-9.2591362
138.6,1.2125375,-0.11586679,45.182747,0,10.594783,415.71594,-0.0077030403,15.559837,10.595046,415.7186,-9.2556133
140.8,1.2196064,-0.095854081,45.120853,0,10.594783,422.31592,-0.006392248,15.631329,10.595828,422.43594,-9.2518282
143.0,0.34734371,-0.11686438,46.109619,0,10.594783,428.91589,-0.0077700969,4.45363,10.595354,428.2196,-9.2480431
145.2,0.33981401,-0.12261987,46.429672,0,10.594783,435.5159,-0.0081594614,4.3654165,10.595051,435.14816,-9.2446699
147.4,0.35091022,-0.13000616,46.109741,0,10.594783,442.11588,-0.0086555127,4.4994502,10.595051,442.11914,-9.2408361
149.6,0.35379621,-0.13312005,46.127121,0,10.594783,448.71588,-0.0088620335,4.5434737,10.595146,448.61771,-9.2375412
151.8,0.33901408,-0.13498685,43.014416,0,10.594783,449.9989,-0.0089871129,4.3615685,10.594892,451.80576,-9.2364731
154.0,0.33002147,-0.13351674,43.527828,0,10.594783,449.9989,-0.00888272,4.2439051,10.594448,450.46243,-9.2366304
156.2,0.36298728,-0.1354429,43.527836,0,10.594783,449.9989,-0.0090147816,4.6604276,10.595433,450.33377,-9.2366495
158.4,0.35168216,-0.13487339,43.00491,0,10.594783,449.9989,-0.0089698844,4.5158343,10.595243,450.47113,-9.2365217
160.6,0.36518615,-0.13712753,43.142788,0,10.594783,449.9989,-0.0091145663,4.6885362,10.594949,450.14462,-9.2363358
162.8,0.36191586,-0.1367974,42.983292,0,10.594783,449.9989,-0.0090984972,4.6476588,10.595119,450.04077,-9.2362671
165.0,0.36095625,-0.1382452,42.954155,0,10.594783,449.9989,-0.0091894325,4.6388469,10.594783,450.27124,-9.23594
167.2,0.37040341,-0.13825282,42.714935,0,10.594783,449.9989,-0.0091922274,4.7549233,10.594171,450.14456,-9.2361908
169.4,0.36521068,-0.13885762,42.429138,0,10.594783,449.9989,-0.0092219701,4.6910114,10.594665,450.09378,-9.2360687
171.6,0.37228966,-0.13961491,42.396244,0,10.594783,449.9989,-0.0092700925,4.8051839,10.594747,450.13507,-9.236289
173.8,0.35668421,-0.14100215,41.890244,0,10.594783,449.9989,-0.0093548056,4.5791554,10.595277,450.25409,-9.2361355
176.0,0.36375278,-0.14107001,41.803032,0,10.594783,449.9989,-0.0093444185,4.6722884,10.594866,450.20746,-9.2359686
178.2,0.36420617,-0.14172593,41.802982,0,10.594783,449.9989,-0.0093807103,4.6781001,10.594526,450.09317,-9.2356482
180.4,0.37798971,-0.14237364,41.802982,0,10.594783,449.9989,-0.0094289565,4.8449292,10.595429,450.13776,-9.2356777
182.6,0.37373143,-0.14269967,41.802799,0,10.594783,449.9989,-0.0094421124,4.8080945,10.596009,450.08051,-9.2355623
184.8,0.37840089,-0.14331478,41.520271,0,10.594783,449.9989,-0.0094926227,4.8576388,10.594408,450.09769,-9.2355213
187.0,0.37056911,-0.14336288,41.781754,0,10.594783,449.9989,-0.0094879912,4.7567649,10.595729,450.01031,-9.2356367
189.2,0.38291037,-0.14504853,41.283752,0,10.594783,449.9989,-0.0096096573,4.9125223,10.593892,450.0787,-9.236083
191.4,0.37967968,-0.14410262,41.198734,0,10.594783,449.9989,-0.0095569575,4.8796015,10.594281,450.06274,-9.2362537
193.6,0.38116604,-0.14409721,41.030735,0,10.594783,449.9989,-0.0095581468,4.880167,10.595397,450.22415,-9.2364664
195.2938,0.55749696,0.020497337,40.57251,0,10.5948,0.0060101803,0.0011317951,7.1807203,10.591743,450.28336,-9.237606
195.2982,0.5540027,0.018123176,35.38958,0,10.5948,5.9955178e-33,0.0010526258,7.0811982,10.597223,450.25323,-9.2357969
195.3026,0.59700978,0.025274493,17.573311,0,10.5948,0.0,0.0014590312,7.6084032,10.595771,450.21381,-9.2349577
195.307,0.55596477,0.019998679,0.0,0,10.5948,0.0,0.0012366615,7.0861588,10.596774,450.17578,-9.2356224
195.3114,0.56677723,0.022897556,0.0,0,10.5948,0.0,0.0012918169,7.219677,10.594227,450.24155,-9.2360296
195.3158,0.57895243,0.018647766,0.0,0,10.5948,0.0,0.0011233916,7.3606458,10.595455,450.30728,-9.2354717
195.3202,0.5703091,0.023617595,0.0,0,10.5948,0.0,0.0013176233,7.1659136,10.594913,450.29556,-9.235424
195.3246,0.57319856,0.01981945,0.0,0,10.5948,0.0,0.0012038182,7.2862639,10.597223,450.25613,-9.2355833
195.329,0.57968587,0.023818083,0.0,0,10.5948,0.0,0.0013326769,7.3612785,10.594007,450.21667,-9.2360783
195.3334,0.5840897,0.020881923,0.0,0,10.5948,0.0,0.0013133825,7.4474907,10.599037,450.17725,-9.2352743
195.3378,0.58601785,0.023744009,0.0,0,10.5948,0.0,0.0013749866,7.4312325,10.595978,450.14258,-9.2361031
195.3422,0.58234686,0.020740781,0.0,0,10.5948,0.0,0.0012809149,7.4653525,10.596995,450.12943,-9.2372742
195.3466,0.59057844,0.024510367,0.0,0,10.542864,0.0,0.0014314149,7.5862813,10.596202,450.11627,-9.2355442
195.351,0.60159117,0.020266211,0.0,0,10.476864,0.0,0.001231485,7.6571884,10.594095,450.13879,-9.236867
195.3554,0.61255056,0.024638969,0.0,0,10.410864,0.0,0.0013861973,7.7513189,10.561143,450.1651,-9.2360277
195.3598,0.58637738,0.021018758,0.0,0,10.344864,0.0,0.0013063817,7.5635748,10.483892,450.16666,-9.2353783
195.3642,0.60684896,0.025703015,0.0,0,10.278863,0.0,0.0014832104,7.6338863,10.374328,450.1535,-9.2349949
195.3686,0.6117993,0.021441491,0.0,0,10.212864,0.0,0.0013231522,7.8797545,10.289313,450.13574,-9.235281
195.373,0.61395001,0.027337587,0.0,0,10.146863,0.0,0.0015697679,7.8210936,10.226404,450.10947,-9.2358141
195.3774,0.61630428,0.022790678,0.0,0,10.080864,0.0,0.0014365067,7.8972278,10.180291,450.08127,-9.235815
195.3818,0.62668467,0.026017236,0.0,0,10.014863,0.0,0.0015566674,7.8119526,10.116304,450.02869,-9.2359419
195.3862,0.63457042,0.022658445,0.0,0,9.948863,0.0,0.0014212714,8.0499706,10.048595,449.97607,-9.2357121
195.3906,0.64156055,0.027421383,0.0,0,9.882863,0.0,0.0015795759,8.2330933,9.9701986,449.93396,-9.2361403
195.395,0.63459402,0.022735016,0.0,0,9.8168631,0.0,0.0013767584,8.0240746,9.9076233,449.8945,-9.2352409
195.3994,0.63380927,0.027788805,0.0,0,9.7508631,0.0,0.0015945004,8.0245113,9.8352232,449.87549,-9.2362223
195.4038,1.1217765,0.031465039,0.0,0,9.6848631,0.0,0.0020127709,14.130235,9.7755871,449.87549,-9.2359591
195.4082,1.748456,0.039724443,0.0,0,9.6188631,0.0,0.0024248508,22.170019,9.7152977,449.91666,-9.2350807
195.4126,3.0446873,0.077282421,0.0,0,9.5528631,0.0,0.0050607072,38.531517,9.6489286,450.08759,-9.2344065
195.417,3.3704352,0.15458149,0.0,0,9.4868631,0.0,0.010069554,42.467449,9.5753736,450.25851,-9.234622
195.4214,3.5945811,0.22028469,0.0,0,9.4223585,0.0,0.014652147,45.087933,9.5010433,451.40506,-9.2330179
195.4258,3.6775434,0.29206365,0.0,0,9.3579779,0.0,0.019373279,45.812473,9.4305906,452.58841,-9.2338209
195.4302,3.6923082,0.35024688,0.0,0,9.2935972,0.0,0.023427088,45.934597,9.3704329,454.04248,-9.2339964
195.4346,3.6992362,0.41481122,0.0,0,9.2292166,0.0,0.027751312,45.832912,9.3055267,455.6203,-9.2352657
195.439,3.7082636,0.47262108,0.0,0,9.164835,0.0,0.031830881,45.712864,9.2425022,456.97742,-9.2351837
195.4434,3.759963,0.54023242,0.0,0,9.1004553,0.0,0.036414567,46.192905,9.1786346,458.01578,-9.2341318
195.4478,3.7693386,0.60411519,0.0,0,9.0360737,0.0,0.040976908,45.994915,9.1086864,459.03323,-9.2326984
195.4522,3.7267985,0.67248154,0.0,0,8.971693,0.0,0.045629796,45.429501,9.0394669,459.91321,-9.234417
195.4566,3.7712455,0.73329687,0.0,0,8.9073124,0.0,0.049969956,45.693275,8.9778347,460.79321,-9.2343416
195.461,3.8223393,0.8019554,0.0,0,8.8429308,0.0,0.054625601,46.049923,8.9088078,461.49347,-9.2338305
195.4654,3.8418171,0.8633185,0.0,0,8.7785501,0.0,0.059074517,46.145061,8.8443537,462.16315,-9.2347622
195.4698,3.8503253,0.93202722,0.0,0,8.7159328,0.0,0.063850001,46.071846,8.7770987,462.68121,-9.2348423
195.4742,3.8446808,0.99156916,0.0,0,8.6547022,0.0,0.068236247,45.719604,8.7134514,463.08826,-9.2348795
195.4786,3.8949506,1.054684,0.0,0,8.5934715,0.0,0.072601572,46.074009,8.6540899,463.43622,-9.2347422
195.483,3.9273272,1.1098007,0.0,0,8.5322428,0.0,0.076676488,46.414536,8.5927782,463.6463,-9.2333202
195.4874,3.9340582,1.1755131,0.0,0,8.4710112,0.0,0.081221417,46.221779,8.5348263,463.854,-9.2343102
195.4918,3.9606128,1.2295746,0.0,0,8.4097815,0.0,0.085388891,46.360416,8.4746056,463.95908,-9.2341709
195.4962,4.030961,1.297296,0.0,0,8.3485498,0.0,0.090145692,46.771339,8.4080992,464.06415,-9.2347488
195.5006,4.0902181,1.3555522,0.0,0,8.2873201,0.0,0.094493926,47.469212,8.3481283,464.20834,-9.233572
195.505,4.1084199,1.4234394,0.0,0,8.2260895,0.0,0.099413522,47.264336,8.280652,464.36591,-9.2347107
195.5094,4.1177454,1.4815829,0.0,0,8.1648588,0.0,0.10379008,47.295261,8.2155228,464.52347,-9.2339363
195.5138,4.1398897,1.5465487,0.0,0,8.1036291,0.0,0.10843078,47.304073,8.1529751,464.68106,-9.2339764
195.5182,4.2059069,1.6020828,0.0,0,8.0429821,0.0,0.11274325,47.84412,8.0938625,464.81857,-9.2360563
195.5226,4.2343798,1.6664165,0.0,0,7.984726,0.0,0.11742727,47.972576,8.0298262,464.87106,-9.2348299
195.527,4.2323952,1.7219034,0.0,0,7.9264693,0.0,0.12171239,47.771347,7.9703999,464.92358,-9.2343082
195.5314,4.2429838,1.7810652,0.0,0,7.8682137,0.0,0.1260834,47.593239,7.917521,464.96411,-9.2341871
195.5358,4.3244796,1.834492,0.0,0,7.8099575,0.0,0.13022476,48.239456,7.8563743,465.00351,-9.2357693
195.5402,4.3421478,1.8979446,0.0,0,7.7517014,0.0,0.1348868,48.338734,7.7975798,464.98441,-9.2343082
195.5446,4.3474803,1.9508606,0.0,0,7.6934457,0.0,0.13908757,48.143356,7.7407675,464.93188,-9.2335358
195.549,4.3944054,2.0113623,0.0,0,7.6351895,0.0,0.14361291,48.414814,7.6814642,464.82751,-9.2345781
195.5534,4.45086,2.0654225,0.0,0,7.5769334,0.0,0.14788103,48.843391,7.6235352,464.63055,-9.2345209
195.5578,4.4816241,2.1281183,0.0,0,7.5186772,0.0,0.15261565,49.006016,7.5624056,464.4379,-9.2342033
195.5622,4.4955635,2.1842387,0.0,0,7.4604211,0.0,0.15715294,48.940662,7.5037284,464.29346,-9.2343311
195.5666,4.5279927,2.2431717,0.0,0,7.4021654,0.0,0.16167289,49.034004,7.4463978,464.14902,-9.2345667
195.571,4.5946035,2.2997208,0.0,0,7.346283,0.0,0.16623427,49.538483,7.3866329,464.09967,-9.2344198
195.5754,4.6091657,2.363349,0.0,0,7.2908783,0.0,0.17103833,49.486237,7.3304205,464.07339,-9.2347565
195.5798,4.5982356,2.4115171,0.0,0,7.2354732,0.0,0.17510712,49.17448,7.273006,463.88788,-9.233882
195.5842,4.6264353,2.4713206,0.0,0,7.1800685,0.0,0.17963566,49.225719,7.2191319,463.5596,-9.2340355
195.5886,4.681066,2.5196812,0.0,0,7.1246629,0.0,0.1837015,49.58831,7.1618643,463.12955,-9.2347355
195.593,4.71946,2.580142,0.0,0,7.0692587,0.0,0.18840495,49.869129,7.1050029,462.39423,-9.2347803
195.5974,4.7728114,2.6319025,0.0,0,7.0138535,0.0,0.19267094,50.137703,7.0536141,461.65891,-9.2338676
195.6018,4.7833438,2.6914666,0.0,0,6.9584489,0.0,0.19738354,50.009308,6.9924817,461.28122,-9.2351751
195.6062,4.8368368,2.7427285,0.0,0,6.9030442,0.0,0.20173082,50.249615,6.9369249,460.91354,-9.2345514
195.6106,4.8782363,2.8032722,0.0,0,6.8476396,0.0,0.20650694,50.514313,6.8784308,460.81985,-9.2340298
195.615,4.9292192,2.8551009,0.0,0,6.7922344,0.0,0.21090075,50.848179,6.8229427,460.8461,-9.2329674
195.6194,4.9104266,2.9144278,0.0,0,6.7380919,0.0,0.21564743,50.394253,6.7644386,460.88336,-9.2339115
195.6238,4.9393253,2.9624631,0.0,0,6.68538,0.0,0.21973644,50.50639,6.7162333,460.93588,-9.2339029
195.6282,4.9837127,3.0169148,0.0,0,6.632668,0.0,0.22419226,50.702171,6.6647344,460.66614,-9.2338629
195.6326,5.0349545,3.065495,0.0,0,6.5799561,0.0,0.22841114,51.005749,6.608922,458.43158,-9.2342739
195.637,5.0717964,3.1231499,0.0,0,6.5272441,0.0,0.23299617,51.117985,6.5556746,456.19699,-9.2327614
195.6414,5.0974069,3.1726692,0.0,0,6.4745321,0.0,0.23738538,51.209652,6.5005541,454.33722,-9.2338085
195.6458,5.1323051,3.2300475,0.0,0,6.4218202,0.0,0.24210139,51.286396,6.4484138,452.53659,-9.2345686
195.6502,5.174365,3.2742393,0.0,0,6.3691082,0.0,0.24601738,51.505302,6.4003634,451.89975,-9.2345695
195.6546,5.2282352,3.3330703,0.0,0,6.3163962,0.0,0.25095063,51.819164,6.3444576,452.08383,-9.233489
195.659,5.2451887,3.3826971,0.0,0,6.2636843,0.0,0.25526291,51.751408,6.2889223,451.8046,-9.2339764
195.6634,5.3107185,3.4408605,0.0,0,6.2109723,0.0,0.26013809,52.062145,6.2337704,450.48975,-9.2345648
195.6678,5.3488398,3.4883716,0.0,0,6.1585317,0.0,0.26436481,52.30648,6.1805558,449.15857,-9.2343245
195.6722,5.3636155,3.5449028,0.0,0,6.1083975,0.0,0.26921803,52.191479,6.1283884,447.33093,-9.2335777
195.6766,5.3417096,3.5917349,0.0,0,6.0582643,0.0,0.27353173,51.73616,6.0798926,445.50327,-9.2334843
195.681,5.3988514,3.6450524,0.0,0,6.0081306,0.0,0.27797002,52.015446,6.0275364,444.70743,-9.2339125
195.6854,5.4423952,3.6871021,0.0,0,5.9579968,0.0,0.28187948,52.279808,5.9821033,444.24722,-9.2333565
195.6898,5.5024347,3.7412164,0.0,0,5.9078636,0.0,0.28647447,52.590405,5.9312296,444.27023,-9.2328167
195.6942,5.5495987,3.7895043,0.0,0,5.8577299,0.0,0.29097199,52.814278,5.87848,444.82251,-9.2338142
195.6986,5.6219358,3.8462367,0.0,0,5.8075962,0.0,0.29585949,53.230835,5.8246045,445.35638,-9.2340899
195.703,5.6642408,3.896003,0.0,0,5.7574625,0.0,0.30048126,53.399139,5.7719955,445.81656,-9.2338428
195.7074,5.6616678,3.9518707,0.0,0,5.7073288,0.0,0.30531007,53.140656,5.7180748,446.27676,-9.2342768
195.7118,5.672576,3.994988,0.0,0,5.6571956,0.0,0.30938217,53.051109,5.6708293,446.71271,-9.2340965
195.7162,5.6894751,4.0442839,0.0,0,5.6070614,0.0,0.31378806,52.897411,5.6228881,447.14661,-9.2324247
195.7206,5.7781467,4.0876369,0.0,0,5.5587354,0.0,0.31789824,53.444794,5.5773611,447.53806,-9.2332153
195.725,5.8044825,4.139699,0.0,0,5.5110397,0.0,0.32246733,53.553719,5.5305681,447.90622,-9.2335405
195.7294,5.8545928,4.1850319,0.0,0,5.4633436,0.0,0.32691708,53.741051,5.4812799,448.24533,-9.2330341
195.7338,5.8852372,4.2365608,0.0,0,5.4156475,0.0,0.33140591,53.842937,5.4290333,448.53458,-9.2330675
195.7382,5.9561963,4.2852564,0.0,0,5.3679519,0.0,0.33613569,54.115288,5.3812323,448.8071,-9.2330923
195.7426,5.9870038,4.334228,0.0,0,5.3202558,0.0,0.34060112,54.223881,5.3331556,448.91229,-9.232852
195.747,5.999784,4.3770928,0.0,0,5.2725596,0.0,0.34485343,54.140648,5.2858658,449.01752,-9.2335224
195.7514,6.0552258,4.4314275,0.0,0,5.224864,0.0,0.34966347,54.348843,5.2366805,449.005,-9.2336187
195.7558,6.1440191,4.4750414,0.0,0,5.1771674,0.0,0.35408553,54.832932,5.1880498,448.96555,-9.2344828
195.7602,6.1747465,4.5279803,0.0,0,5.1294718,0.0,0.35893863,54.9613,5.1413727,448.89084,-9.2341776
195.7646,6.172049,4.5718045,0.0,0,5.0817757,0.0,0.36325887,54.682106,5.0914583,448.78564,-9.2328205
195.769,6.1920104,4.6196885,0.0,0,5.0349607,0.0,0.3676627,54.576962,5.0494285,448.55099,-9.2339373
195.7734,6.2610068,4.6627321,0.0,0,4.9895968,0.0,0.37200308,54.928463,5.0038538,447.9462,-9.2328911
195.7778,6.354105,4.7124028,0.0,0,4.9442329,0.0,0.37667498,55.505486,4.9574156,447.34137,-9.2326431
195.7822,6.3477721,4.754962,0.0,0,4.898869,0.0,0.38089666,55.204823,4.9072742,446.42673,-9.2345209
195.7866,6.3857131,4.8056355,0.0,0,4.8535047,0.0,0.38566473,55.316807,4.8615937,445.50635,-9.2328176
195.791,6.4093933,4.844768,0.0,0,4.8081408,0.0,0.38979861,55.244179,4.8177023,444.08459,-9.2329493
195.7954,6.4717131,4.8949509,0.0,0,4.7627769,0.0,0.39457381,55.498032,4.7759118,442.45261,-9.2341795
195.7998,6.5353961,4.9330139,0.0,0,4.7174129,0.0,0.39847115,55.842396,4.7301478,440.93289,-9.2328444
195.8042,6.5623431,4.9839501,0.0,0,4.6720486,0.0,0.40343383,55.812767,4.6870165,439.56372,-9.2331619
195.8086,6.6198716,5.0251021,0.0,0,4.6266847,0.0,0.40776181,56.009274,4.6384435,438.37421,-9.2340755
195.813,6.7181158,5.0749602,0.0,0,4.5813208,0.0,0.41257486,56.647163,4.5918503,438.203,-9.2334757
195.8174,6.7718344,5.1190729,0.0,0,4.5359983,0.0,0.4170782,56.826401,4.5440803,438.0318,-9.2349491
195.8218,6.7494421,5.1712518,0.0,0,4.4928331,0.0,0.42218781,56.368065,4.498559,438.44675,-9.2327166
195.8262,6.7685361,5.2093744,0.0,0,4.4496775,0.0,0.4262462,56.188709,4.4541583,438.94714,-9.2336979
195.8306,6.8107615,5.252707,0.0,0,4.4065223,0.0,0.43057668,56.379395,4.4137268,439.31427,-9.233614
195.835,6.8901429,5.2913709,0.0,0,4.3633671,0.0,0.43473712,56.788414,4.3705859,439.59082,-9.2324419
195.8394,6.9215727,5.3375249,0.0,0,4.3202119,0.0,0.43932202,56.800056,4.3281446,439.62018,-9.2321339
195.8438,6.9893188,5.3781562,0.0,0,4.2770567,0.0,0.44366479,57.058102,4.2827682,439.11975,-9.2330132
195.8482,7.0538735,5.4284191,0.0,0,4.2339015,0.0,0.44873431,57.343113,4.2382264,438.62579,-9.2334986
195.8526,7.1113687,5.4692202,0.0,0,4.1907463,0.0,0.45326108,57.589397,4.1997342,438.28339,-9.233222
195.857,7.1373992,5.5142584,0.0,0,4.1475911,0.0,0.45773211,57.49548,4.1527824,437.94101,-9.2318439
195.8614,7.1818366,5.5558958,0.0,0,4.1044359,0.0,0.46234208,57.594158,4.1128712,437.59863,-9.2323561
195.8658,7.2718897,5.6025491,0.0,0,4.0612807,0.0,0.46714187,58.090527,4.0653782,437.25626,-9.23283
195.8702,7.3257632,5.6455221,0.0,0,4.0194993,0.0,0.47179919,58.207611,4.0189815,436.60641,-9.2337608
195.8746,7.3049226,5.6905217,0.0,0,3.9784563,0.0,0.47642469,57.786091,3.9774833,435.63193,-9.2345047
195.879,7.3191237,5.7254486,0.0,0,3.9374132,0.0,0.48050982,57.591824,3.9392247,434.56934,-9.2331705
195.8834,7.3529296,5.767014,0.0,0,3.8963699,0.0,0.48478159,57.608898,3.9028864,433.17343,-9.2327089
195.8878,7.4676147,5.8052382,0.0,0,3.8553267,0.0,0.48901942,58.332012,3.8567357,431.77756,-9.2330122
195.8922,7.5375681,5.8499532,0.0,0,3.8142834,0.0,0.49375731,58.583103,3.8215222,430.9093,-9.2324476
195.8966,7.5880604,5.88837,0.0,0,3.7732403,0.0,0.49811888,58.710629,3.7758446,430.07965,-9.2331381
195.901,7.6770496,5.9369674,0.0,0,3.732197,0.0,0.50335747,59.064739,3.7317626,429.68097,-9.2316513
195.9054,7.7503738,5.9801049,0.0,0,3.6911538,0.0,0.50825745,59.34877,3.6854391,429.5098,-9.2333298
195.9098,7.7568884,6.0259032,0.0,0,3.6501107,0.0,0.51319152,59.139751,3.6481175,429.47772,-9.2323809
195.9142,7.758913,6.0614433,0.0,0,3.6090674,0.0,0.51737076,58.837463,3.6068525,429.67526,-9.2321768
195.9186,7.7623062,6.1031919,0.0,0,3.5685976,0.0,0.52177072,58.644161,3.5711966,429.828,-9.2330208
195.923,7.8451929,6.1366544,0.0,0,3.5295517,0.0,0.52573973,58.993855,3.527854,429.57779,-9.2329493
195.9274,7.9271579,6.1825476,0.0,0,3.4905062,0.0,0.5307169,59.404564,3.4929063,429.32758,-9.2335052
195.9318,7.9925294,6.2133322,0.0,0,3.4514608,0.0,0.53441191,59.66441,3.4516845,428.67618,-9.2316513
195.9362,8.0238142,6.2586017,0.0,0,3.412415,0.0,0.53941989,59.594959,3.4081991,427.93829,-9.2324209
195.9406,8.1203976,6.295475,0.0,0,3.3733692,0.0,0.54379153,59.971943,3.3715575,427.21442,-9.2320585
195.945,8.1857729,6.3417606,0.0,0,3.3343236,0.0,0.54898149,60.214561,3.3316379,426.5022,-9.2331657
195.9494,8.2005196,6.374743,0.0,0,3.2952783,0.0,0.55294991,60.073959,3.2931514,425.82529,-9.2323666
195.9538,8.1998234,6.4162583,0.0,0,3.2562327,0.0,0.55763555,59.777115,3.2537076,425.24484,-9.2342606
195.9582,8.2726173,6.4503536,0.0,0,3.2171869,0.0,0.56191486,59.994518,3.2174532,424.6644,-9.2344618
195.9626,8.3744946,6.4920421,0.0,0,3.1781414,0.0,0.56649506,60.539135,3.1801093,424.25388,-9.2338085
195.967,8.4696131,6.5294452,0.0,0,3.1390958,0.0,0.57107705,60.913601,3.1410458,423.84491,-9.2329502
195.9714,8.5395899,6.575357,0.0,0,3.101805,0.0,0.57627404,61.087101,3.1021795,423.3136,-9.2327785
195.9758,8.5560713,6.6124144,0.0,0,3.0646603,0.0,0.58091092,60.934692,3.0612888,422.73312,-9.2320108
195.9802,8.6494503,6.6541572,0.0,0,3.0275152,0.0,0.58570212,61.218773,3.0204954,422.31964,-9.2327967
195.9846,8.6303654,6.6877875,0.0,0,2.9903708,0.0,0.58998513,60.917969,2.984067,422.12177,-9.2331028
195.989,8.6630449,6.7245584,0.0,0,2.9532259,0.0,0.59413832,60.912781,2.948143,422.00363,-9.2323465
195.9934,8.7030973,6.757648,0.0,0,2.916081,0.0,0.59826297,60.941811,2.9153373,422.30704,-9.2332754
195.9978,8.8474588,6.8002658,0.0,0,2.8789363,0.0,0.60328358,61.589546,2.8798816,422.61044,-9.2333288
196.0022,8.9539814,6.8354053,0.0,0,2.8417914,0.0,0.6078552,62.021751,2.8355439,422.0065,-9.2318668
196.0066,8.9774218,6.8776751,0.0,0,2.8046467,0.0,0.61284578,61.982655,2.7977238,421.28094,-9.2323713
196.011,9.0084581,6.9126325,0.0,0,2.7675018,0.0,0.61748028,61.796329,2.7579238,418.99902,-9.2330418
196.0154,9.0002813,6.9531436,0.0,0,2.7303569,0.0,0.62203795,61.576092,2.7266254,415.69907,-9.2335711
196.0198,9.087429,6.9811215,0.0,0,2.694227,0.0,0.62583256,61.916965,2.6921778,412.79651,-9.2324905
196.0242,9.1920404,7.0218616,0.0,0,2.658895,0.0,0.63080633,62.278934,2.6562157,410.71085,-9.2334986
196.0286,9.279048,7.0578451,0.0,0,2.6235631,0.0,0.63543427,62.577221,2.6169326,408.76913,-9.2335472
196.033,9.306097,7.0988455,0.0,0,2.5882311,0.0,0.64043587,62.400517,2.5809264,409.56223,-9.2332783
196.0374,9.3830976,7.128046,0.0,0,2.5528989,0.0,0.64441329,62.697197,2.5475709,410.35529,-9.232316
196.0418,9.3961964,7.1703153,0.0,0,2.5175669,0.0,0.64950979,62.51231,2.5153115,410.88278,-9.2336979
196.0462,9.438653,7.1972394,0.0,0,2.482235,0.0,0.65320086,62.53299,2.4780011,411.33218,-9.2323503
196.0506,9.5128078,7.2369556,0.0,0,2.446903,0.0,0.65807027,62.681068,2.444047,411.55237,-9.2308607
196.055,9.6233597,7.2652392,0.0,0,2.411571,0.0,0.66189456,63.172703,2.4107063,411.53915,-9.2312775
196.0594,9.7042494,7.303411,0.0,0,2.3762391,0.0,0.6666674,63.437164,2.3753796,411.58646,-9.2329617
196.0638,9.7752457,7.3378162,0.0,0,2.3409069,0.0,0.67137283,63.571419,2.3352907,411.85074,-9.2324572
196.0682,9.8850956,7.3817706,0.0,0,2.3059127,0.0,0.67677879,63.944614,2.2990551,412.11502,-9.2320414
196.0726,9.9403677,7.4123616,0.0,0,2.2723055,0.0,0.68107778,64.022682,2.265224,411.96896,-9.2308817
196.077,9.9833679,7.4515362,0.0,0,2.2386985,0.0,0.68610293,64.047615,2.230099,411.79715,-9.2325239
196.0814,9.9677467,7.4833884,0.0,0,2.2050912,0.0,0.69044429,63.70015,2.1978049,410.82715,-9.2316494
196.0858,10.008007,7.5164757,0.0,0,2.171484,0.0,0.69464946,63.658794,2.1666234,409.45258,-9.2323456
196.0902,10.139907,7.5456123,0.0,0,2.1378767,0.0,0.69892544,64.173805,2.1349537,408.26184,-9.2317629
196.0946,10.241269,7.5830302,0.0,0,2.1042697,0.0,0.70368034,64.502213,2.0993555,407.36304,-9.2329969
196.099,10.308165,7.6136861,0.0,0,2.0706627,0.0,0.70803636,64.671242,2.0655437,406.65167,-9.2322206
196.1034,10.360546,7.6546373,0.0,0,2.0370555,0.0,0.71329272,64.650734,2.0285544,407.47119,-9.2336855
196.1078,10.447315,7.6814928,0.0,0,2.0034482,0.0,0.71721435,64.948273,1.9985915,408.29071,-9.2327814
196.1122,10.553805,7.7225676,0.0,0,1.969841,0.0,0.72254133,65.238853,1.9642363,409.13217,-9.2321711
196.1166,10.604791,7.750351,0.0,0,1.9362339,0.0,0.72656935,65.272881,1.9323561,409.97809,-9.2314587
196.121,10.656104,7.7898493,0.0,0,1.9039891,0.0,0.73189306,65.281052,1.899778,410.30362,-9.2323656
196.1254,10.756314,7.8182783,0.0,0,1.8720186,0.0,0.73599678,65.548683,1.8676033,410.21109,-9.2327719
196.1298,10.816912,7.8558908,0.0,0,1.8400483,0.0,0.74111098,65.631485,1.8323435,410.0636,-9.2316456
196.1342,10.883476,7.8830228,0.0,0,1.8080778,0.0,0.7451129,65.780457,1.8007922,409.7728,-9.2312717
196.1386,10.924104,7.91991,0.0,0,1.7761074,0.0,0.75001967,65.69381,1.7696129,409.48199,-9.2312994
196.143,11.013683,7.9475851,0.0,0,1.744137,0.0,0.75424749,65.923401,1.7394052,408.74182,-9.2324028
196.1474,11.120338,7.9838462,0.0,0,1.7121667,0.0,0.75919676,66.233429,1.7022086,408.00162,-9.2324257
196.1518,11.21317,8.0110979,0.0,0,1.6801963,0.0,0.76322097,66.544327,1.671894,407.07037,-9.2316122
196.1562,11.247098,8.0486879,0.0,0,1.6482258,0.0,0.76843899,66.443344,1.6391799,406.06586,-9.2316513
196.1606,11.292952,8.0753832,0.0,0,1.6162554,0.0,0.77253175,66.390533,1.609908,405.42047,-9.2315121
196.165,11.39537,8.1101942,0.0,0,1.5842849,0.0,0.77735674,66.644371,1.5791545,405.2222,-9.2325459
196.1694,11.527335,8.1384144,0.0,0,1.5530447,0.0,0.78171498,67.176445,1.5461946,405.09952,-9.2324791
196.1738,11.637177,8.177002,0.0,0,1.5226319,0.0,0.78690356,67.443565,1.5145711,405.35065,-9.2321863
196.1782,11.664415,8.2043371,0.0,0,1.4922191,0.0,0.79122591,67.305206,1.4820143,405.60178,-9.2318583
196.1826,11.727098,8.2391434,0.0,0,1.4618063,0.0,0.796143,67.338478,1.4506868,405.67627,-9.2316227
196.187,11.722585,8.2653103,0.0,0,1.4313934,0.0,0.80025429,67.030342,1.4249382,405.72916,-9.2320728
196.1914,11.779061,8.2955332,0.0,0,1.4009807,0.0,0.80447203,67.076363,1.3964168,405.77393,-9.2324953
196.1958,11.85812,8.3187141,0.0,0,1.3705679,0.0,0.80818421,67.262733,1.3689801,405.81357,-9.2327461
196.2002,12.066225,8.3560658,0.0,0,1.3401551,0.0,0.81353158,68.079712,1.3364435,405.92883,-9.2314711
196.2046,12.211252,8.3849068,0.0,0,1.3097425,0.0,0.8181445,68.572922,1.3053793,406.19318,-9.2314777
196.209,12.291837,8.417366,0.0,0,1.2793295,0.0,0.82301486,68.721718,1.2736478,406.42471,-9.2323151
196.2134,12.36529,8.4474859,0.0,0,1.2489167,0.0,0.82765263,68.84285,1.2382519,406.13391,-9.2319269
196.2178,12.448773,8.4832039,0.0,0,1.2186602,0.0,0.83291394,68.892838,1.2058687,405.84314,-9.2313223
196.2222,12.518538,8.5069284,0.0,0,1.1897346,0.0,0.83688599,69.020119,1.1772892,405.24234,-9.2311735
196.2266,12.558587,8.5448456,0.0,0,1.160809,0.0,0.84243268,68.877419,1.1459016,404.55502,-9.2314787
196.231,12.537034,8.5634346,0.0,0,1.1318834,0.0,0.8455798,68.58651,1.1207154,404.02921,-9.231288
196.2354,12.622766,8.597024,0.0,0,1.1029578,0.0,0.85058397,68.63459,1.0957836,403.66199,-9.2331352
196.2398,12.834642,8.6204987,0.0,0,1.0740322,0.0,0.85432279,69.536407,1.063832,403.27963,-9.2313929
196.2442,12.913193,8.6526108,0.0,0,1.0451066,0.0,0.85921627,69.603394,1.0353445,402.5791,-9.2317219
196.2486,12.959525,8.6786976,0.0,0,1.016181,0.0,0.86365628,69.610405,1.0042143,401.87857,-9.2316523
196.253,13.016451,8.7112713,0.0,0,0.98725533,0.0,0.86847258,69.534828,0.98038822,400.80234,-9.2314882
196.2574,13.100679,8.7312918,0.0,0,0.95832974,0.0,0.8719241,69.725563,0.95321655,399.61276,-9.2317085
196.2618,13.242014,8.7655602,0.0,0,0.9294042,0.0,0.87715518,70.126907,0.92513174,398.76059,-9.2313213
196.2662,13.355358,8.7887468,0.0,0,0.90047854,0.0,0.88116676,70.472374,0.8974582,398.2583,-9.2312069
196.2706,13.471692,8.8243685,0.0,0,0.87260348,0.0,0.8865397,70.698067,0.86516577,397.87463,-9.2320156
196.275,13.584807,8.8466444,0.0,0,0.84509468,0.0,0.89046597,70.98246,0.83852637,397.92749,-9.2304754
196.2794,13.695767,8.8824062,0.0,0,0.81758583,0.0,0.89608264,71.166817,0.81030047,397.98038,-9.2320642
196.2838,13.77267,8.9042511,0.0,0,0.79007703,0.0,0.89998847,71.29493,0.78105706,397.10367,-9.2338705
196.2882,13.835053,8.9407568,0.0,0,0.76256824,0.0,0.90555602,71.213493,0.75187021,396.16379,-9.2314472
196.2926,13.900622,8.9609985,0.0,0,0.73505944,0.0,0.90925884,71.249954,0.72633618,396.03503,-9.2295961
196.297,14.02667,8.9917202,0.0,0,0.70755064,0.0,0.91420221,71.578697,0.69729537,396.32584,-9.2299366
196.3014,14.090451,9.0172157,0.0,0,0.68004191,0.0,0.91860384,71.615738,0.67162573,396.97546,-9.2307663
196.3058,14.157409,9.0438881,0.0,0,0.65253305,0.0,0.92285854,71.650909,0.6466741,398.20612,-9.2309198
196.3102,14.295852,9.0692987,0.0,0,0.62502432,0.0,0.92736381,71.989319,0.61902893,399.3551,-9.2314711
196.3146,14.468451,9.0997076,0.0,0,0.59751546,0.0,0.9322331,72.48951,0.5881111,399.8045,-9.2312231
196.319,14.591864,9.1239595,0.0,0,0.57050872,0.0,0.93657875,72.825432,0.56304288,400.25391,-9.2298927
196.3234,14.635631,9.1564274,0.0,0,0.54432875,0.0,0.94172716,72.68364,0.53645575,400.82358,-9.2306442
196.3278,14.72416,9.1792707,0.0,0,0.51814872,0.0,0.9460389,72.789917,0.50601244,401.41837,-9.2312851
196.3322,14.058526,9.1920462,0.0,0,0.49196875,0.0,0.94802135,69.41713,0.48642114,401.91867,-9.2314625
196.3366,13.478739,9.2008829,0.0,0,0.46578872,0.0,0.94984096,66.405075,0.47251713,402.34164,-9.2328463
196.341,13.13827,9.2077417,0.0,0,0.43960872,0.0,0.95082331,64.67749,0.45728031,402.6781,-9.2316437
196.3454,12.875908,9.2124481,0.0,0,0.41342872,0.0,0.95186496,63.315601,0.44335106,402.78384,-9.2331009
196.3498,12.608626,9.2214413,0.0,0,0.38724869,0.0,0.95312667,61.918858,0.42611286,402.88959,-9.2345715
196.3542,12.299783,9.2172337,0.0,0,0.3610687,0.0,0.95258003,60.404339,0.4072209,402.73218,-9.2334604
196.3586,11.907013,9.2261992,0.0,0,0.3348887,0.0,0.95401132,58.429214,0.39571986,402.57358,-9.2339182
196.363,11.555746,9.2206135,0.0,0,0.3087087,0.0,0.95309871,56.73925,0.39181796,402.30106,-9.2338219
196.3674,11.372761,9.2270117,0.0,0,0.28255266,0.0,0.95416921,55.757587,0.38518316,401.98383,-9.2329121
196.3718,11.356322,9.2240658,0.0,0,0.25765175,0.0,0.95380741,55.663921,0.36628881,401.7132,-9.2342825
196.3762,11.510213,9.2324314,0.0,0,0.23275654,0.0,0.95499939,56.369644,0.34095857,401.50171,-9.2316761
196.3806,11.774786,9.2304993,0.0,0,0.20786138,0.0,0.95483893,57.689831,0.30508742,401.29456,-9.2330637
196.385,11.965729,9.2372608,0.0,0,0.18296619,0.0,0.95592219,58.573174,0.26789305,401.1095,-9.2338562
196.3894,12.06603,9.2359228,0.0,0,0.158071,0.0,0.9557156,59.045712,0.23515165,400.92447,-9.2325115
196.3938,12.084663,9.2441502,0.0,0,0.13317578,0.0,0.95714211,59.07518,0.20741972,400.78629,-9.2325249
196.3982,12.055651,9.2436056,0.0,0,0.10828058,0.0,0.95719177,58.954235,0.18110353,400.65411,-9.2322493
196.4026,12.006104,9.2503042,0.0,0,0.083385371,0.0,0.95801032,58.615841,0.15647006,400.44949,-9.2317209
196.407,11.973492,9.2479286,0.0,0,0.058490172,0.0,0.95787621,58.477814,0.13133186,400.19836,-9.2322483
196.4114,11.921198,9.2551155,0.0,0,0.03359497,0.0,0.9588905,58.214714,0.10970815,399.94284,-9.2324572
196.4158,11.842828,9.2536526,0.0,0,0.008699771,0.0,0.9589774,57.849075,0.090789221,399.67847,-9.2329779
196.4202,11.777306,9.2583847,0.0,0,-0.01580042,0.0,0.95954865,57.460411,0.072386965,399.41483,-9.2313547
196.4246,11.718234,9.2576027,0.0,0,-0.040088423,0.0,0.95955348,57.170193,0.051105548,399.1637,-9.2321367
196.429,11.668202,9.260272,0.0,0,-0.064376414,0.0,0.95994216,56.872437,0.032891493,398.91257,-9.2317257
196.4334,11.583004,9.2601976,0.0,0,-0.088664412,0.0,0.96011335,56.463493,0.019286817,398.53815,-9.2335291
196.4378,11.467921,9.2639885,0.0,0,-0.044745184,449.55496,0.96033978,55.89859,0.0032910544,398.12839,-9.2313862
196.4422,11.316109,9.2600965,14.417367,0,0.752087,450.0,0.95995992,55.18214,-0.0025761432,397.69199,-9.232378
196.4466,9.3411827,9.2594538,43.252419,0,1.5489452,450.0,0.95980805,45.755589,0.076281421,397.22894,-9.2334185
196.451,5.126905,9.2378426,65.665283,0,2.3458035,450.0,0.95624614,25.303165,0.31462726,396.87491,-9.2362509
196.4554,0.66856074,9.1845999,65.665283,0,3.1426606,450.0,0.94665569,2.9958527,0.93932575,396.90134,-9.2411146
196.4598,0.90559834,9.1957312,65.665283,0,3.939518,450.0,0.9489432,4.5445561,2.3300829,396.92776,-9.2393875
196.4642,0.98300523,9.2137337,66.030182,0,4.7363758,450.0,0.95195323,4.8005109,3.3381705,395.86475,-9.2392759
196.4686,0.67778075,9.2181168,66.416122,0,5.5332332,450.0,0.95289475,3.3403361,4.1038914,394.73889,-9.2376785
196.473,0.69327873,9.2078409,66.544189,0,6.3300915,450.0,0.95083863,3.3923354,4.8411703,395.66357,-9.2380104
196.4774,0.84217173,9.2111979,66.544189,0,7.1269484,450.0,0.95146203,4.1644421,5.6018157,397.60657,-9.2364902
196.4818,0.66167867,9.2075338,66.331093,0,7.9238062,450.0,0.95082581,3.2396832,6.4024529,398.70718,-9.236145
196.4862,0.73555803,9.1881666,65.785934,0,8.720664,450.0,0.94758302,3.6707578,7.2371235,398.49527,-9.2361765
196.4906,0.63811296,9.2092285,65.302734,0,9.5175219,450.0,0.95102328,3.1321898,8.0713854,398.32996,-9.235219
196.495,0.48786286,9.1856346,65.302734,0,10.31438,450.0,0.94734877,2.3885775,8.8897963,398.52823,-9.2356558
196.4994,0.69995481,9.2060614,65.302734,0,11.111238,450.0,0.95066756,3.4841466,9.7032566,398.72647,-9.2349787
196.5038,0.62538838,9.1984806,65.234138,0,11.908094,450.0,0.94938731,2.9619405,10.513408,398.92508,-9.2340384
196.5082,0.53808051,9.2180376,65.152122,0,12.704952,450.0,0.95261067,2.6235871,11.305423,399.12375,-9.2357225
196.5126,0.66560119,9.1997576,65.115967,0,13.50181,450.0,0.94968373,3.3078144,12.080695,399.27048,-9.2338037
196.517,0.77362072,9.2012329,65.115967,0,14.298667,450.0,0.9495635,3.8413498,12.857792,399.37622,-9.2341433
196.5214,0.60297048,9.2021742,65.09285,0,15.095525,450.0,0.94994986,2.9535022,13.65168,399.54922,-9.234458
196.5258,0.82330853,9.1905565,65.010841,0,15.892383,450.0,0.94790763,4.1090913,14.459713,399.89362,-9.2325478
196.5302,0.61336356,9.2022476,64.929199,0,16.689241,450.0,0.95016253,2.9983752,15.269513,400.23547,-9.2343597
196.5346,0.50334525,9.2032967,64.929199,0,17.486099,450.0,0.9500463,2.4307232,16.07872,400.02399,-9.2329941
196.539,0.70564008,9.2066412,64.929199,0,18.0,450.0,0.95084959,3.4236355,16.856636,399.8125,-9.2345381
196.5434,0.69925362,9.202569,64.988846,0,18.0,450.0,0.94985282,3.4190605,17.621342,399.89932,-9.2344084
196.5478,0.81448334,9.2155476,65.070854,0,18.0,450.0,0.95236951,3.9889848,18.222795,400.09799,-9.2359762
196.5522,1.2483714,9.2104349,65.115967,0,18.0,450.0,0.951208,6.0845237,18.484297,399.7374,-9.2424021
196.5566,1.2563008,9.1958094,65.115967,0,18.0,450.0,0.94865274,6.2321801,18.358686,398.69318,-9.2578764
196.561,1.2950431,9.2188721,65.157631,0,18.0,450.0,0.952564,6.3510251,18.143589,397.92087,-9.2848845
196.5654,1.3782756,9.2036839,65.398842,0,18.0,450.0,0.95042396,6.8620195,18.052359,398.45068,-9.3204422
196.5698,1.1652683,9.2179909,65.640068,0,18.0,450.0,0.95255226,5.6966777,18.05834,398.9805,-9.3591814
196.5742,1.0830686,9.2038021,65.665283,0,18.0,450.0,0.95036262,5.4368296,18.097191,399.23709,-9.394578
196.5786,1.3399996,9.2200985,65.665283,0,18.0,450.0,0.95291817,6.6102672,18.127045,399.46182,-9.429018
196.583,1.2205156,9.2071848,65.665283,0,18.0,450.0,0.95092714,6.0254407,18.140917,399.48212,-9.4623499
196.5874,1.0993203,9.2177992,65.665283,0,18.0,450.0,0.95232439,5.4276476,18.138948,399.37613,-9.4941387
196.5918,1.2106388,9.2070894,65.665283,0,18.0,450.0,0.95091933,5.937789,18.134687,399.43698,-9.5266809
196.5962,1.1660475,9.1862249,65.665283,0,18.0,450.0,0.9471184,5.7461405,18.132133,399.82028,-9.559207
196.6006,1.2547413,9.2085361,65.660065,0,18.0,450.0,0.95114028,6.1798496,18.125187,400.18256,-9.5931864
196.605,1.4372267,9.2104731,65.578056,0,18.0,450.0,0.95150065,7.1300564,18.12092,400.23557,-9.6256504
196.6094,1.1761379,9.2110729,65.49604,0,18.0,450.0,0.95172864,5.7499781,18.114489,400.28854,-9.6584902
196.6138,1.3302493,9.2071962,65.478516,0,18.0,450.0,0.95079136,6.4231114,18.114788,400.3934,-9.6918201
196.6182,1.3694488,9.2171478,65.478516,0,18.0,450.0,0.95261979,6.7377868,18.109688,400.51236,-9.7241735
196.6226,1.1955028,9.2121019,65.478516,0,18.0,450.0,0.95154518,5.9318991,18.107594,400.59775,-9.7584906
196.627,1.1292793,9.2004938,65.478516,0,18.0,450.0,0.94958019,5.560864,18.106861,400.65073,-9.7911167
196.6314,1.245898,9.2096796,65.478516,0,18.0,450.0,0.95107895,6.11028,18.106529,400.73123,-9.8230333
196.6358,1.1094189,9.1897755,65.478516,0,18.0,450.0,0.94800669,5.4681168,18.104443,400.90308,-9.8570404
196.6402,1.2360497,9.2113972,65.478516,0,18.0,450.0,0.95139247,6.0758266,18.104992,401.07489,-9.8885641
196.6446,1.4361229,9.2095041,65.478516,0,18.0,450.0,0.95120233,7.0201592,18.104212,401.07007,-9.9211159
196.649,1.1823241,9.2202587,65.478516,0,18.0,450.0,0.95291364,5.7870421,18.099607,401.05682,-9.9552183
196.6534,1.2677432,9.2040625,65.478516,0,18.0,450.0,0.95043117,6.2055273,18.092999,401.15997,-9.9886026
196.6578,1.2988533,9.2144213,65.478516,0,18.0,450.0,0.95189494,6.3845129,18.091671,401.31857,-10.022574
196.6622,1.205696,9.2044458,65.478516,0,18.0,450.0,0.95045853,5.9084349,18.090071,401.43497,-10.053464
196.6666,1.2461185,9.1947803,65.478516,0,18.0,450.0,0.94852436,6.1690297,18.091087,401.48795,-10.086826
196.671,1.2648243,9.2086315,65.478516,0,18.0,450.0,0.95128888,6.2313428,18.091469,401.55875,-10.119086
196.6754,1.0915645,9.2004118,65.478516,0,18.0,450.0,0.94965464,5.393784,18.090298,401.75702,-10.152774
196.6798,1.2472568,9.2109947,65.478516,0,18.0,450.0,0.95156151,6.1950364,18.090515,401.95526,-10.183918
196.6842,1.146549,9.2077799,65.413254,0,18.0,450.0,0.95081216,5.60814,18.088165,402.0419,-10.218058
196.6886,1.1849704,9.2193146,65.336067,0,18.0,450.0,0.95331228,5.7916427,18.08576,402.10812,-10.252102
196.693,1.2515237,9.2102795,65.302734,0,18.0,450.0,0.95128763,6.1671066,18.084652,402.08414,-10.285198
196.6974,1.2467693,9.2007418,65.302734,0,18.0,450.0,0.94966376,6.1407094,18.086557,401.99164,-10.316364
196.7018,1.2356195,9.2092667,65.325195,0,18.0,450.0,0.95116109,6.0776439,18.073988,401.953,-10.349416
196.7062,1.3901767,9.1902008,65.402382,0,18.0,450.0,0.94805527,6.8720932,18.080652,402.04572,-10.382828
196.7106,1.2536024,9.214797,65.478516,0,18.0,450.0,0.95197535,6.1718216,18.075148,402.13824,-10.417371
196.715,1.0439918,9.2038012,65.478516,0,18.0,450.0,0.95036125,5.1112633,18.07317,402.21756,-10.450812
196.7194,1.2837987,9.2152128,65.478516,0,18.0,450.0,0.95216846,6.3324084,18.073551,402.29688,-10.481282
196.7238,1.2896605,9.2044277,65.53891,0,18.0,450.0,0.95044589,6.3181963,18.072058,402.30801,-10.513737
196.7282,1.1873533,9.2253504,65.620918,0,18.0,450.0,0.95384222,5.8515067,18.072481,402.29477,-10.547215
196.7326,1.2307683,9.206172,65.665283,0,18.0,450.0,0.95085818,6.0488749,18.070288,402.39075,-10.58109
196.737,1.1922568,9.1891775,65.665283,0,18.0,450.0,0.947537,5.8482161,18.073868,402.61548,-10.614172
196.7414,1.2843486,9.2084761,65.665283,0,18.0,450.0,0.95121968,6.306901,18.07094,402.78967,-10.646575
196.7458,1.4983193,9.2042475,65.665283,0,18.0,450.0,0.95027184,7.3838263,18.073055,402.73669,-10.679725
196.7502,1.2254287,9.2115278,65.665283,0,18.0,450.0,0.95164877,6.0523429,18.06739,402.68372,-10.713554
196.7546,1.1801981,9.2071953,65.665283,0,18.0,450.0,0.95058417,5.9589448,18.072191,402.76233,-10.745364
196.759,1.3705242,9.213707,65.665283,0,18.0,450.0,0.95223713,6.7252336,18.065704,402.85486,-10.778294
196.7634,1.3115362,9.2114315,65.665283,0,18.0,450.0,0.95143825,6.4613485,18.066353,402.90598,-10.811601
196.7678,1.1618954,9.2093735,65.665283,0,18.0,450.0,0.9512015,5.7296767,18.057451,402.93246,-10.845071
196.7722,1.2276551,9.2082882,65.665283,0,18.0,450.0,0.95095915,6.0202947,18.058521,402.97748,-10.876676
196.7766,1.1504357,9.1818676,65.665283,0,18.0,450.0,0.94664848,5.6550775,18.055243,403.05676,-10.909137
196.781,1.3179673,9.2103529,65.665283,0,18.0,450.0,0.95130104,6.4526768,18.055454,403.12646,-10.942482
196.7854,1.5268847,9.2102175,65.665283,0,18.0,450.0,0.9516108,7.530488,18.056311,403.07346,-10.975259
196.7898,1.1856718,9.2175426,65.665283,0,18.0,450.0,0.95257372,5.8392167,18.058598,403.02048,-11.010313
196.7942,1.2728801,9.20016,65.665283,0,18.0,450.0,0.9499712,6.2013912,18.055149,403.07272,-11.04306
196.7986,1.4206613,9.2151146,65.665283,0,18.0,450.0,0.95208848,6.9451551,18.055256,403.15204,-11.075015
196.803,1.2963861,9.2083759,65.705276,0,18.0,450.0,0.95113367,6.4022341,18.054926,403.20398,-11.106825
196.8074,1.1857364,9.1994247,65.782471,0,18.0,450.0,0.94930774,5.9102254,18.054359,403.23044,-11.141452
196.8118,1.2411407,9.2054272,65.841064,0,18.0,450.0,0.95076454,6.036068,18.053862,403.28238,-11.173723
196.8162,1.1565329,9.1888218,65.841064,0,18.0,450.0,0.94772071,5.6670494,18.050938,403.41458,-11.207559
196.8206,1.3315256,9.2079229,65.841064,0,18.0,450.0,0.95110679,6.5644093,18.054886,403.54675,-11.240253
196.825,1.4769433,9.2117395,65.766685,0,18.0,450.0,0.9516238,7.1918306,18.048332,403.62814,-11.274513
196.8294,1.1876516,9.2162876,65.689499,0,18.0,450.0,0.95269448,5.7934704,18.050995,403.70761,-11.305355
196.8338,1.2933532,9.2061367,65.665283,0,18.0,450.0,0.9504444,6.38379,18.049311,403.74161,-11.33777
197.2373,1.1630888,9.2106228,0.00026391153,0,18.0,0.0015956662,0.95209354,5.7131934,18.011709,391.63599,-11.48073
199.4373,0.95630544,9.223361,2.8009454e-34,0,18.0,1.5917635e-33,0.95422703,4.6842895,18.000515,335.23645,-11.480039
201.6373,0.93273777,9.2337523,7.9874012e-44,0,18.0,1.4012985e-45,0.95600969,4.5664248,17.999826,301.00897,-11.481064
203.8373,0.94326234,9.2447166,7.9874012e-44,0,18.0,1.4012985e-45,0.95791,4.609365,17.999849,275.70294,-11.480353
206.0373,0.95200849,9.2546329,7.9874012e-44,0,18.0,1.4012985e-45,0.95964295,4.6430168,17.999958,255.14311,-11.480362
208.2373,0.95499206,9.262558,7.9874012e-44,0,18.0,1.4012985e-45,0.96105933,4.6539612,17.999699,237.56276,-11.48138
210.4373,0.96703696,9.2708092,7.9874012e-44,0,18.0,1.4012985e-45,0.96251673,4.7056789,18.000999,222.07124,-11.480947
212.6373,0.97688246,9.2786789,7.9874012e-44,0,18.0,1.4012985e-45,0.96391112,4.742022,18.000135,208.09712,-11.480917
214.8373,0.98232383,9.2850876,7.9874012e-44,0,18.0,1.4012985e-45,0.96501154,4.7645378,18.000164,193.63222,-11.480689
217.0373,0.99546301,9.2923908,7.9874012e-44,0,18.0,1.4012985e-45,0.96627611,4.8235908,18.000927,181.58366,-11.480711
219.2373,1.0002979,9.2982998,7.9874012e-44,0,18.0,1.4012985e-45,0.96722209,4.8497224,18.00036,170.92163,-11.481113
221.4373,0.99813241,9.3043289,7.9874012e-44,0,18.0,1.4012985e-45,0.96824181,4.8289762,18.00062,160.79921,-11.481282
223.6373,1.0072081,9.3101616,7.9874012e-44,0,18.0,1.4012985e-45,0.96927184,4.874598,17.999557,151.25546,-11.481341
225.8373,1.0099834,9.3159389,7.9874012e-44,0,18.0,1.4012985e-45,0.97030181,4.8738465,18.000254,142.70998,-11.480557
228.0373,1.0238477,9.320159,7.9874012e-44,0,18.0,1.4012985e-45,0.97107267,4.9319358,18.000578,134.64847,-11.480525
230.2373,1.0315887,9.3250875,7.9874012e-44,0,18.0,1.4012985e-45,0.97199011,4.9603162,18.000139,127.11334,-11.480505
232.4373,1.0377862,9.3294029,7.9874012e-44,0,18.0,1.4012985e-45,0.97279119,4.9909997,17.999395,119.91463,-11.481331
234.6373,1.0442961,9.3338528,7.9874012e-44,0,18.0,1.4012985e-45,0.97362959,5.0240669,18.000744,113.41395,-11.481413
236.8373,1.0397526,9.3385782,7.9874012e-44,0,18.0,1.4012985e-45,0.97449219,4.9999008,17.99962,107.17646,-11.481176
239.0373,1.0334674,9.3426886,7.9874012e-44,0,18.0,1.4012985e-45,0.97519809,4.962707,18.000702,101.41953,-11.480493
241.2373,1.0317079,9.3461914,7.9874012e-44,0,18.0,1.4012985e-45,0.97577602,4.9491277,18.001095,96.06311,-11.480247
243.4373,1.0385211,9.3500271,7.9874012e-44,0,18.0,1.4012985e-45,0.97638142,4.9782729,18.00013,90.913643,-11.480485
245.6373,1.0460782,9.3531799,7.9874012e-44,0,18.0,1.4012985e-45,0.9769026,5.0029268,18.000368,86.385254,-11.481136
247.8373,1.0499482,9.3562956,7.9874012e-44,0,18.0,1.4012985e-45,0.97752106,5.0308566,18.000362,82.036781,-11.481452
250.0373,1.050173,9.3594933,7.9874012e-44,0,18.0,1.4012985e-45,0.97809327,5.0310836,18.000406,77.882462,-11.481671
252.2373,1.0532771,9.3620138,7.9874012e-44,0,18.0,1.4012985e-45,0.97858292,5.0438929,17.999958,74.12767,-11.481975
254.4373,1.0508454,9.3651228,7.9874012e-44,0,18.0,1.4012985e-45,0.97912127,5.0277271,18.000185,70.470779,-11.48095
256.6373,1.0438128,9.3673897,7.9874012e-44,0,18.0,1.4012985e-45,0.97947598,4.992023,17.999683,67.164665,-11.481111
256.8373,1.0535903,9.3678112,7.9874012e-44,0,18.0,1.4012985e-45,0.97960341,5.0410495,17.999853,66.857315,-11.480763