File: raw data/testID_0246.csv
Time(sec),Force(kN),Jaw(mm),PowAngle(deg),Power(W),Pram,PTemp,Strain,Stress(MPa),Stroke(mm),TC1(C),wedge(mm)
0.0,1.5138868,-8.3236036,0.0,0,10.594783,0.0013609888,-0.44141531,29.976233,10.594733,12.468451,-9.1206284
2.2,1.4207237,-0.0050806045,0.0,0,10.594783,6.515903,-0.00032713453,18.099648,10.595517,12.490113,-9.4863758
4.4,1.3768867,-0.0054707141,0.0,0,10.594783,13.115904,-0.00036193943,17.530603,10.595492,12.444817,-9.4830952
6.6,1.3837856,-0.0063190744,33.354893,0,10.594783,19.715906,-0.00042500571,17.630207,10.59424,13.436203,-9.4790735
8.8,1.4130284,-0.014278942,39.924313,0,10.594783,26.315907,-0.00093265157,18.002172,10.59407,21.357927,-9.4745998
11.0,1.4002676,-0.019123843,33.782299,0,10.594783,32.915913,-0.0012537085,17.833199,10.594334,33.735695,-9.4715452
13.2,1.3494648,-0.018530885,26.857428,0,10.594783,39.515903,-0.0012084502,17.203915,10.594577,41.783676,-9.4677773
15.4,1.3354309,-0.019368865,32.596619,0,10.594783,46.11591,-0.0012935831,17.02722,10.595066,45.209095,-9.4636869
17.6,1.3695303,-0.024530528,37.567158,0,10.594783,52.715904,-0.0016449792,17.458836,10.594584,50.463928,-9.4599705
19.8,1.368266,-0.02910896,36.818539,0,10.594783,59.315922,-0.0019628028,17.459463,10.594712,58.823906,-9.4563723
22.0,1.3393124,-0.030992718,34.432972,0,10.594783,65.915909,-0.0020865479,17.096399,10.594341,66.647217,-9.4529448
24.2,1.3275238,-0.033001572,34.650875,0,10.594783,72.515907,-0.0022100401,16.926012,10.593965,72.493401,-9.4487486
26.4,1.3383362,-0.036230534,36.65044,0,10.594783,79.115913,-0.0024189281,17.081411,10.595041,78.452774,-9.4451418
28.6,1.3352276,-0.039551441,36.309818,0,10.594783,85.715927,-0.0026262887,17.042692,10.595704,85.612846,-9.4408607
30.8,1.3288288,-0.042659815,36.230854,0,10.594783,92.315941,-0.0028348861,16.963833,10.594142,92.457336,-9.4372435
33.0,1.3307815,-0.045350749,36.298115,0,10.594783,98.915932,-0.0030230419,16.999187,10.594673,98.931023,-9.4335489
35.2,1.3265157,-0.048316717,36.309811,0,10.594783,105.51594,-0.0032042845,16.937593,10.594865,105.32893,-9.4299374
37.4,1.3340921,-0.051796138,37.06942,0,10.594783,112.11593,-0.0034260994,17.030323,10.594278,111.89051,-9.4260845
39.6,1.3288873,-0.055886745,37.08984,0,10.594783,118.71593,-0.0036944016,16.98387,10.594403,118.55896,-9.4225502
41.8,1.3292212,-0.059350606,37.08984,0,10.594783,125.31593,-0.0039461176,16.993431,10.59521,125.25642,-9.4186316
44.0,1.3088152,-0.0630152,37.05077,0,10.594783,131.91591,-0.004201333,16.743286,10.594565,131.99796,-9.4143238
46.2,1.3238612,-0.066694088,37.463123,0,10.594783,138.51595,-0.0044588693,16.920292,10.595013,138.22954,-9.4108849
48.4,1.3333973,-0.070413195,37.836914,0,10.594783,145.11595,-0.0047060605,17.053907,10.595787,144.94098,-9.4073305
50.6,1.3358675,-0.074134789,38.124851,0,10.594783,151.71596,-0.0049480698,17.073404,10.594816,151.46983,-9.4031868
52.8,1.3389441,-0.078438565,38.307152,0,10.594783,158.31595,-0.0052200276,17.145935,10.595352,158.16266,-9.3997793
55.0,1.3406315,-0.081926554,37.84774,0,10.594783,164.91595,-0.0054328991,17.168591,10.594502,164.85956,-9.3962326
57.2,1.3513018,-0.086077891,38.433952,0,10.594783,171.51595,-0.0057147518,17.302538,10.594202,171.46985,-9.3926182
59.4,1.3448423,-0.090220705,38.079391,0,10.594783,178.11594,-0.0059960405,17.228195,10.594729,178.12231,-9.3885422
61.6,1.3508843,-0.094017938,38.551022,0,10.594783,184.71594,-0.0062419367,17.31813,10.595486,184.5598,-9.3847408
63.8,1.347073,-0.097861387,38.963165,0,10.594783,191.31595,-0.0064880513,17.283785,10.59427,191.04466,-9.3808165
66.0,1.3365928,-0.10238624,38.551819,0,10.594783,197.91595,-0.0067821024,17.133568,10.594158,197.86464,-9.3772717
68.2,1.3554447,-0.10633209,39.213017,0,10.594783,204.51598,-0.0070585171,17.377783,10.593645,204.45091,-9.3740416
70.4,1.3657978,-0.110988,39.24316,0,10.594783,211.11595,-0.0073733544,17.515863,10.593959,211.03876,-9.370326
72.6,1.3756138,-0.11552022,38.874886,0,10.594783,217.71596,-0.0076923124,17.650024,10.595009,217.75797,-9.36693
74.8,1.3840361,-0.11899823,39.24316,0,10.594783,224.31595,-0.0079318546,17.748692,10.594394,224.26147,-9.362855
77.0,1.3795315,-0.12260278,39.243156,0,10.594783,230.91594,-0.0081582069,17.713848,10.594083,230.92128,-9.3588734
79.2,1.3780725,-0.12670855,39.24316,0,10.594783,237.51595,-0.0084219631,17.6912,10.59474,237.3373,-9.3553543
81.4,1.3778025,-0.1307503,39.713894,0,10.594783,244.11595,-0.0086742248,17.703907,10.59423,243.9754,-9.3516665
83.6,1.3859451,-0.13492383,39.349026,0,10.594783,250.71596,-0.0089420667,17.816111,10.594345,250.70004,-9.3483505
85.8,1.3770463,-0.13952485,39.327518,0,10.594783,257.31625,-0.0092550647,17.695833,10.594984,257.29108,-9.3445234
88.0,1.3846931,-0.14358386,39.291653,0,10.594783,263.91599,-0.0095327999,17.798782,10.594796,263.93527,-9.340683
90.2,1.3883336,-0.14823039,39.321728,0,10.594783,270.51596,-0.0098277153,17.851871,10.59528,270.54233,-9.3372192
92.4,1.3894109,-0.15235063,39.244541,0,10.594783,277.11597,-0.010081719,17.875006,10.59414,277.17426,-9.3331766
94.6,1.3990849,-0.15669541,39.780113,0,10.594783,283.71597,-0.010369797,18.009298,10.59475,283.62683,-9.3302641
96.8,1.389774,-0.16118243,39.401344,0,10.594783,290.31598,-0.010671563,17.879116,10.594872,290.35031,-9.3261709
99.0,1.4033204,-0.16523358,39.711128,0,10.594783,296.91595,-0.010948344,18.055937,10.595037,296.8891,-9.3226433
101.2,1.427168,-0.17020656,39.690739,0,10.594783,303.51596,-0.011279645,18.380198,10.594495,303.49567,-9.319294
103.4,1.4049062,-0.17458044,39.56377,0,10.594783,310.116,-0.011591017,18.093727,10.594522,310.09937,-9.3153124
105.6,1.4127897,-0.17739424,39.599922,0,10.594783,316.716,-0.011779388,18.195108,10.595027,316.68381,-9.3118048
107.8,1.4072751,-0.18156499,39.680981,0,10.594783,323.31601,-0.012056472,18.141184,10.594687,323.29681,-9.3080368
110.0,1.3965669,-0.18540959,39.493816,0,10.594783,329.91599,-0.012304852,18.003262,10.594489,329.9519,-9.3044472
112.2,1.37578,-0.1895559,39.437679,0,10.594783,336.51599,-0.012566351,17.74065,10.594708,336.57657,-9.3005457
114.4,1.3615117,-0.19245856,39.260666,0,10.594783,343.116,-0.012744428,17.558441,10.595478,343.15286,-9.2972107
116.6,1.3575474,-0.19716521,39.428917,0,10.594783,349.71597,-0.013042176,17.511833,10.594585,349.68161,-9.2932711
118.8,1.3562888,-0.19809477,39.282154,0,10.594783,356.31601,-0.013122853,17.507603,10.594035,356.34735,-9.2901106
121.0,1.3308797,-0.19917402,39.677376,0,10.594783,362.91602,-0.013184475,17.171223,10.594715,362.89825,-9.2864847
123.2,1.3047956,-0.20029277,39.394905,0,10.594783,369.51605,-0.013256973,16.845097,10.594629,369.56662,-9.2831564
125.4,1.2847872,-0.20009725,39.360252,0,10.594783,376.11603,-0.013242167,16.570614,10.594879,376.09595,-9.2794151
127.6,1.2662661,-0.19919278,39.374794,0,10.594783,382.716,-0.013166972,16.338581,10.594816,382.76071,-9.2751284
129.8,1.2457383,-0.19684994,39.738857,0,10.594783,389.31604,-0.013007846,16.068039,10.594536,389.28284,-9.2717381
132.0,1.2272834,-0.19325794,39.404732,0,10.594783,395.91599,-0.012780352,15.834507,10.594187,396.00131,-9.267642
134.2,0.31666324,-0.2035296,37.090221,0,10.594783,399.99893,-0.013471056,4.0848699,10.594837,401.5943,-9.265851
136.4,0.33060598,-0.20214084,37.836914,0,10.594783,399.99893,-0.013391188,4.2655802,10.594746,400.25571,-9.2660103
138.6,0.34303311,-0.20500614,37.431725,0,10.594783,399.99893,-0.013585399,4.4387574,10.593958,400.31107,-9.2658195
140.8,0.34734514,-0.20571153,36.675365,0,10.594783,399.99893,-0.013638944,4.4809394,10.594423,400.41394,-9.2658319
143.0,0.34108424,-0.20586807,36.451302,0,10.594783,399.99893,-0.013659907,4.4045906,10.595307,400.19226,-9.2658758
145.2,0.34436333,-0.20640568,36.446411,0,10.594783,399.99893,-0.013690887,4.4464846,10.594578,400.07535,-9.2664747
147.4,0.34933865,-0.20768183,36.309818,0,10.594783,399.99893,-0.013763902,4.5028,10.594492,400.20905,-9.2660284
149.6,0.34712476,-0.20901334,35.68919,0,10.594783,399.99893,-0.013846748,4.4838758,10.595565,400.26651,-9.2660961
151.8,0.35318899,-0.20945217,35.5457,0,10.594783,399.99893,-0.013871326,4.563735,10.595729,400.19879,-9.2658453
154.0,0.34814146,-0.21064298,36.03933,0,10.594783,399.99893,-0.013939789,4.486424,10.595023,400.01901,-9.26513
156.2,0.35920173,-0.21155438,35.514023,0,10.594783,399.99893,-0.013990467,4.6364675,10.59395,400.11792,-9.2653875
158.4,0.36097953,-0.21199512,35.49683,0,10.594783,399.99893,-0.014042882,4.6649356,10.594316,400.16299,-9.2650671
160.6,0.35057569,-0.21269311,35.328316,0,10.594783,399.99893,-0.014076896,4.5304375,10.594814,400.13943,-9.2650042
162.8,0.35154086,-0.21343905,35.285553,0,10.594783,399.99893,-0.01411944,4.5358324,10.59393,400.02927,-9.2649012
165.0,0.35913742,-0.21507819,35.228088,0,10.594783,399.99893,-0.014210993,4.6301489,10.594885,400.05307,-9.2652016
167.2,0.36599725,-0.21457203,35.092628,0,10.594783,399.99893,-0.014180294,4.7244725,10.594311,400.04074,-9.2651329
169.4,0.35926905,-0.21539102,34.671436,0,10.594783,399.99893,-0.01423893,4.6402111,10.594593,400.09613,-9.2656202
171.6,0.3703436,-0.21719459,34.959015,0,10.594783,399.99893,-0.014367019,4.7786798,10.594186,399.99994,-9.2653885
173.8,0.36904278,-0.21606387,34.666996,0,10.594783,399.99893,-0.014306786,4.7543979,10.593814,400.10675,-9.2651949
176.0,0.35702592,-0.21711518,34.650883,0,10.594783,399.99893,-0.014382172,4.6204896,10.595366,400.10315,-9.265172
178.2,0.35814989,-0.21706134,34.352814,0,10.594783,399.99893,-0.014382607,4.6246123,10.59488,400.13916,-9.2653255
178.6174,0.61272502,0.02216582,0.0,0,10.5948,9.9962087e-21,0.0014575695,7.8051815,10.594075,400.11948,-9.2658911
178.6218,0.60657662,0.024303282,0.0,0,10.5948,0.0,0.001568838,7.6723981,10.595945,400.10617,-9.2651806
178.6262,0.60876906,0.022349963,0.0,0,10.5948,0.0,0.0014446069,7.7605166,10.59623,400.0929,-9.264719
178.6306,0.60821003,0.024147764,0.0,0,10.5948,0.0,0.0015063564,7.7362008,10.595101,400.05743,-9.2658396
178.635,0.62973869,0.021978304,0.0,0,10.5948,0.0,0.0014193038,8.0307636,10.597398,400.01761,-9.2642221
178.6394,0.62992048,0.025100578,0.0,0,10.5948,0.0,0.0015433806,8.035121,10.595075,400.00797,-9.264596
178.6438,0.6282829,0.022278154,0.0,0,10.5948,0.0,0.0014088546,7.9543676,10.59509,400.02124,-9.2651939
178.6482,0.6301505,0.026571611,0.0,0,10.5948,0.0,0.0016306613,7.9537497,10.59398,400.03052,-9.2635431
178.6526,0.65425497,0.02314776,0.0,0,10.5948,0.0,0.0014323534,8.2275314,10.594919,400.03052,-9.2653484
178.657,0.64084309,0.027371109,0.0,0,10.5948,0.0,0.0016663773,8.1738939,10.594685,400.03094,-9.2653437
178.6614,0.64200687,0.023464939,0.0,0,10.5948,0.0,0.0014094855,8.1613426,10.593308,400.04422,-9.2644796
178.6658,0.63674128,0.026831668,0.0,0,10.569863,0.0,0.0015914391,7.9921031,10.595203,400.0575,-9.2654095
178.6702,0.65149117,0.024596881,0.0,0,10.503863,0.0,0.0014611111,8.2239771,10.595475,400.0809,-9.2653246
178.6746,0.66173816,0.026383162,0.0,0,10.437863,0.0,0.0015681766,8.3707285,10.576879,400.10745,-9.2655773
178.679,0.66125697,0.025488853,0.0,0,10.371863,0.0,0.0015485645,8.487114,10.521682,400.12741,-9.2653799
178.6834,0.65871793,0.028440801,0.0,0,10.305863,0.0,0.0016497438,8.3439407,10.423092,400.14069,-9.265871
178.6878,0.6593802,0.025388524,0.0,0,10.239863,0.0,0.0015336809,8.3527479,10.327869,400.14792,-9.2652988
178.6922,0.67485023,0.028261654,0.0,0,10.173863,0.0,0.0016442974,8.7311707,10.254814,400.13464,-9.264679
178.6966,0.67213023,0.026733018,0.0,0,10.107863,0.0,0.0015900793,8.5826111,10.20006,400.1214,-9.2654638
178.701,0.67013383,0.029811975,0.0,0,10.041863,0.0,0.0016827305,8.5827103,10.139328,400.12085,-9.2666721
178.7054,0.68206835,0.026553163,0.0,0,9.9758635,0.0,0.0015306833,8.5810223,10.076723,400.12085,-9.2653933
178.7098,0.69250417,0.030541267,0.0,0,9.9098635,0.0,0.0017833428,8.870326,10.004436,400.10251,-9.2651033
178.7142,0.69211787,0.02602529,0.0,0,9.8438625,0.0,0.001581635,8.8157463,9.9354076,400.07596,-9.264163
178.7186,1.9671586,0.047546532,0.0,0,9.7778635,0.0,0.0028810266,24.955975,9.8695927,400.03821,-9.2642269
178.723,3.3192737,0.059100814,0.0,0,9.7118626,0.0,0.0037876761,41.836269,9.8119354,399.98511,-9.2642317
178.7274,4.1318479,0.12885715,0.0,0,9.6458635,0.0,0.0082827825,52.040417,9.7456341,400.07971,-9.2629671
178.7318,4.4778805,0.19178122,0.0,0,9.5798635,0.0,0.012659119,56.378258,9.6697273,400.98212,-9.2623186
178.7362,4.6593218,0.26935965,0.0,0,9.5138636,0.0,0.017784581,58.248009,9.5954275,401.88452,-9.263669
178.7406,4.7704372,0.33480346,0.0,0,9.4486961,0.0,0.022351563,59.32922,9.5235233,403.18686,-9.2620935
178.745,4.8571053,0.40285578,0.0,0,9.3843155,0.0,0.026972361,60.193333,9.4580669,404.54047,-9.2630806
178.7494,4.8824096,0.46596029,0.0,0,9.3199348,0.0,0.031424548,60.322914,9.3911848,404.92603,-9.2617435
178.7538,4.9004679,0.53047413,0.0,0,9.2555542,0.0,0.035725217,60.269707,9.3268814,404.71368,-9.2627039
178.7582,4.9694304,0.58803236,0.0,0,9.1911736,0.0,0.039816834,60.694824,9.26262,404.31558,-9.2638292
178.7626,5.0271478,0.65663022,0.0,0,9.126792,0.0,0.044512708,61.16832,9.2002859,403.57242,-9.2637215
178.767,5.0796084,0.71605313,0.0,0,9.0624113,0.0,0.048744444,61.558739,9.1363268,402.89441,-9.2641382
178.7714,5.1054249,0.78401905,0.0,0,8.9980307,0.0,0.053424042,61.635303,9.0689964,402.94751,-9.2631226
178.7758,5.1547127,0.84547746,0.0,0,8.93365,0.0,0.057959065,61.941669,9.0021563,403.00058,-9.2640095
178.7802,5.2067795,0.91140604,0.0,0,8.8692694,0.0,0.062527999,62.299236,8.9385376,403.07526,-9.2633524
178.7846,5.260819,0.97326416,0.0,0,8.8048878,0.0,0.067072771,62.6273,8.8750839,403.15488,-9.2629061
178.789,5.2764435,1.0374371,0.0,0,8.7409821,0.0,0.071538366,62.600739,8.8079615,403.35031,-9.2622967
178.7934,5.3152986,1.0973521,0.0,0,8.6797504,0.0,0.075969204,62.683945,8.7448874,403.64227,-9.2636518
178.7978,5.3726206,1.1634144,0.0,0,8.6185207,0.0,0.080690876,63.136108,8.6857004,403.97839,-9.2624865
178.8022,5.417614,1.2219828,0.0,0,8.5572901,0.0,0.084968373,63.378849,8.616271,404.42957,-9.2624903
178.8066,5.4674997,1.2889444,0.0,0,8.4960604,0.0,0.089867897,63.57909,8.5546494,404.87717,-9.2630949
178.811,5.4619193,1.3482592,0.0,0,8.4348297,0.0,0.094175488,63.370739,8.4913177,404.93024,-9.2630339
178.8154,5.5234056,1.4109422,0.0,0,8.3735991,0.0,0.098862283,63.690483,8.4286318,404.98331,-9.2623806
178.8198,5.5787439,1.4708037,0.0,0,8.3123684,0.0,0.1032225,64.099525,8.3659496,405.24289,-9.2636881
178.8242,5.5965233,1.5332711,0.0,0,8.2511396,0.0,0.10795397,64.035301,8.3042593,405.57465,-9.2630119
178.8286,5.6063504,1.5909911,0.0,0,8.189908,0.0,0.11216521,63.846825,8.2428312,405.97543,-9.2635536
178.833,5.6635003,1.6524144,0.0,0,8.1286783,0.0,0.1168966,64.122459,8.186305,406.45316,-9.2623777
178.8374,5.7228951,1.7100719,0.0,0,8.0674477,0.0,0.12115368,64.531731,8.1192169,406.89563,-9.2636538
178.8418,5.7528424,1.7726725,0.0,0,8.0085573,0.0,0.12596875,64.645836,8.0590286,407.20087,-9.2631397
178.8462,5.7837224,1.8318465,0.0,0,7.9503016,0.0,0.13042954,64.656708,7.9949484,407.5061,-9.2627506
178.8506,5.8266106,1.8943115,0.0,0,7.892046,0.0,0.13521384,64.763985,7.9362702,407.92316,-9.2632122
178.855,5.8655806,1.9509929,0.0,0,7.8337893,0.0,0.13954575,64.962891,7.8750434,408.34781,-9.263216
178.8594,5.8723006,2.0059316,0.0,0,7.7755337,0.0,0.14380476,64.834351,7.8178415,408.88773,-9.261591
178.8638,5.9253831,2.0612514,0.0,0,7.7172771,0.0,0.14804274,65.104591,7.7619362,409.48489,-9.2637539
178.8682,5.9688697,2.1219759,0.0,0,7.6590214,0.0,0.1527545,65.281639,7.7029791,410.04492,-9.2629557
178.8726,6.0349956,2.1802967,0.0,0,7.6007657,0.0,0.1572454,65.616081,7.6459041,410.54922,-9.2632074
178.877,6.0652647,2.2361777,0.0,0,7.5425091,0.0,0.16181464,65.727463,7.5912352,411.00104,-9.2633772
178.8814,6.0953665,2.2932329,0.0,0,7.4842534,0.0,0.16618887,65.730492,7.5295625,411.10721,-9.2632713
178.8858,6.1367221,2.35112,0.0,0,7.4259973,0.0,0.17079945,65.900063,7.4724712,411.21338,-9.263587
178.8902,6.199862,2.4092751,0.0,0,7.3689485,0.0,0.17541473,66.161942,7.407908,411.25076,-9.2630901
178.8946,6.2404122,2.4691257,0.0,0,7.3135438,0.0,0.18023701,66.364563,7.3537946,411.27728,-9.2623539
178.899,6.2509551,2.5233426,0.0,0,7.2581387,0.0,0.18445309,66.182411,7.2963958,411.38284,-9.2628584
178.9034,6.2557664,2.5779674,0.0,0,7.202734,0.0,0.18886286,65.983604,7.2423797,411.54211,-9.2631254
178.9078,6.2833815,2.6304069,0.0,0,7.1473289,0.0,0.1930697,65.981674,7.1870766,411.69702,-9.2627888
178.9122,6.3862896,2.6853974,0.0,0,7.0919242,0.0,0.19761507,66.721306,7.1314425,411.84299,-9.262888
178.9166,6.4222775,2.7417219,0.0,0,7.0365191,0.0,0.20206413,66.878349,7.0724854,411.9819,-9.2621651
178.921,6.4657559,2.7982521,0.0,0,6.9811144,0.0,0.20680475,66.951416,7.0179577,412.00845,-9.2634525
178.9254,6.4859543,2.8549271,0.0,0,6.9257097,0.0,0.21139711,66.819885,6.957458,412.03497,-9.2631531
178.9298,6.571373,2.9104395,0.0,0,6.8703055,0.0,0.215978,67.442963,6.9033132,412.06152,-9.2638988
178.9342,6.6001906,2.9660692,0.0,0,6.8148999,0.0,0.2204778,67.435181,6.8450308,412.08804,-9.2630577
178.9386,6.6269112,3.0203326,0.0,0,6.759656,0.0,0.22505459,67.390991,6.7894902,412.09378,-9.2620049
178.943,6.6544719,3.0759842,0.0,0,6.706944,0.0,0.22966616,67.325455,6.7365699,412.08051,-9.2608862
178.9474,6.7226982,3.1304092,0.0,0,6.654232,0.0,0.23426545,67.703377,6.6825137,412.01996,-9.2611065
178.9518,6.7551522,3.1836395,0.0,0,6.6015201,0.0,0.23864806,67.767365,6.6264448,411.82089,-9.2627439
178.9562,6.7377782,3.2335975,0.0,0,6.5488081,0.0,0.24287546,67.278893,6.5743742,411.62186,-9.2633009
178.9606,6.7700911,3.2823229,0.0,0,6.4960961,0.0,0.24698693,67.281784,6.521873,411.46207,-9.2608147
178.965,6.8226585,3.3317711,0.0,0,6.4433842,0.0,0.25124189,67.620621,6.4777803,411.30283,-9.2628813
178.9694,6.9412723,3.385736,0.0,0,6.3906722,0.0,0.25586513,68.407997,6.4251456,411.21982,-9.2617331
178.9738,6.9883928,3.4407227,0.0,0,6.3379602,0.0,0.26055768,68.526276,6.3688674,411.16672,-9.262949
178.9782,7.0174041,3.4997089,0.0,0,6.2852483,0.0,0.26559284,68.553581,6.3107305,410.88669,-9.2628469
178.9826,7.0289669,3.5515654,0.0,0,6.2325363,0.0,0.2701723,68.295822,6.2558637,410.32932,-9.2623205
178.987,7.0932422,3.6025174,0.0,0,6.1798244,0.0,0.27458045,68.651215,6.2030516,409.73816,-9.2630596
178.9914,7.1487312,3.6545527,0.0,0,6.1289067,0.0,0.27915138,68.890556,6.1535001,408.99503,-9.2621708
178.9958,7.1633816,3.7103374,0.0,0,6.0787735,0.0,0.2840178,68.630379,6.0963392,408.25186,-9.2621794
179.0002,7.1858673,3.7573478,0.0,0,6.0286398,0.0,0.28823483,68.618851,6.0499058,407.94519,-9.2617331
179.0046,7.2446942,3.8078122,0.0,0,5.9785061,0.0,0.29264125,68.786751,5.9965982,407.67978,-9.2622766
179.009,7.2842007,3.8548167,0.0,0,5.9283724,0.0,0.29686707,68.895233,5.9490242,407.61996,-9.2630339
179.0134,7.3153563,3.9082832,0.0,0,5.8782392,0.0,0.30153662,68.858673,5.8979015,407.67307,-9.2620564
179.0178,7.3752656,3.9545994,0.0,0,5.8281054,0.0,0.3058033,69.134033,5.851088,407.73615,-9.2622414
179.0222,7.4203463,4.0067716,0.0,0,5.7779713,0.0,0.31047711,69.210045,5.7984862,407.81577,-9.2624998
179.0266,7.4951744,4.054462,0.0,0,5.7278385,0.0,0.31489903,69.667526,5.7513733,407.84326,-9.2605915
179.031,7.5348978,4.1114016,0.0,0,5.6777043,0.0,0.31994501,69.638107,5.6967077,407.44516,-9.2625561
179.0354,7.5664105,4.157012,0.0,0,5.6275706,0.0,0.32418114,69.667488,5.6469531,407.04703,-9.2630148
179.0398,7.6351228,4.2094193,0.0,0,5.5782475,0.0,0.32899919,69.899467,5.5943179,406.69357,-9.2618513
179.0442,7.6837769,4.2574711,0.0,0,5.5305514,0.0,0.33343729,70.144295,5.5486732,406.34854,-9.2624626
179.0486,7.6890221,4.3090882,0.0,0,5.4828553,0.0,0.33825386,69.823753,5.4974837,406.2771,-9.2615824
179.053,7.69662,4.3529167,0.0,0,5.4351597,0.0,0.34235328,69.602074,5.4497681,406.40979,-9.2621155
179.0574,7.7993798,4.4011469,0.0,0,5.3874636,0.0,0.3468295,70.183624,5.4062767,406.52634,-9.2616434
179.0618,7.8679285,4.4493394,0.0,0,5.3397679,0.0,0.35145211,70.543709,5.3562684,406.60596,-9.2619371
179.0662,7.9043293,4.5018158,0.0,0,5.2920718,0.0,0.35624626,70.467682,5.3058176,406.67786,-9.2629128
179.0706,7.9497924,4.5475988,0.0,0,5.2443757,0.0,0.36079511,70.580215,5.2561326,406.54514,-9.2620955
179.075,8.0089827,4.6021624,0.0,0,5.1966796,0.0,0.36583734,70.595261,5.2043524,406.41245,-9.2620134
179.0794,8.0214148,4.6429939,0.0,0,5.148984,0.0,0.36991417,70.550171,5.1604671,406.27975,-9.2610712
179.0838,8.0694017,4.6930013,0.0,0,5.1012874,0.0,0.37462816,70.582855,5.1150832,406.14703,-9.2618771
179.0882,8.1032877,4.7355804,0.0,0,5.0535922,0.0,0.3789275,70.577042,5.0700569,405.79538,-9.2637453
179.0926,8.2112236,4.7878852,0.0,0,5.0081549,0.0,0.38385954,71.164276,5.020215,405.22473,-9.2619505
179.097,8.2672329,4.8325276,0.0,0,4.962791,0.0,0.38848537,71.330185,4.970263,404.58026,-9.2607698
179.1014,8.2678547,4.8849168,0.0,0,4.9174271,0.0,0.39333275,71.012634,4.9267726,403.69113,-9.2622881
179.1058,8.2871361,4.921771,0.0,0,4.8720627,0.0,0.39725155,70.936073,4.8841534,402.80197,-9.2612324
179.1102,8.3311157,4.9725032,0.0,0,4.8266988,0.0,0.40219325,70.941765,4.8357496,402.60342,-9.2615252
179.1146,8.4049025,5.0104532,0.0,0,4.7813349,0.0,0.40614045,71.317673,4.7936454,402.43091,-9.2624912
179.119,8.4842777,5.065011,0.0,0,4.735971,0.0,0.41145557,71.603371,4.7479048,402.49832,-9.2607946
179.1234,8.5217257,5.1047063,0.0,0,4.6906066,0.0,0.41569623,71.584373,4.7029161,402.67084,-9.2620687
179.1278,8.5789948,5.1538711,0.0,0,4.6452427,0.0,0.42056999,71.757057,4.6543756,402.74698,-9.2612886
179.1322,8.6333895,5.1985269,0.0,0,4.5998788,0.0,0.42528898,71.828156,4.6070247,402.69391,-9.2619114
179.1366,8.6621809,5.2448215,0.0,0,4.5545149,0.0,0.42982465,71.778351,4.5591607,402.62183,-9.2612076
179.141,8.7103539,5.2863317,0.0,0,4.5104871,0.0,0.43430474,71.821075,4.51968,402.44931,-9.2615252
179.1454,8.7573166,5.3336048,0.0,0,4.4673314,0.0,0.43903208,71.862526,4.4751859,402.27679,-9.2636108
179.1498,8.8345861,5.3738737,0.0,0,4.4241767,0.0,0.4433805,72.173088,4.4303832,401.71411,-9.2612162
179.1542,8.9014521,5.4221892,0.0,0,4.3810215,0.0,0.44834778,72.388809,4.385828,401.10367,-9.2620354
179.1586,8.9188814,5.4637737,0.0,0,4.3378663,0.0,0.45280194,72.200005,4.3439746,400.26181,-9.2616968
179.163,8.9605417,5.5098372,0.0,0,4.2947111,0.0,0.45759344,72.146301,4.2965317,399.27979,-9.2619762
179.1674,9.0018158,5.5469337,0.0,0,4.2515559,0.0,0.46163648,72.217903,4.2560449,398.27859,-9.2615471
179.1718,9.1100407,5.5949216,0.0,0,4.2084007,0.0,0.46673542,72.674301,4.2154851,397.24246,-9.2607965
179.1762,9.1615257,5.6336989,0.0,0,4.1652455,0.0,0.47099248,72.83252,4.1701522,396.22348,-9.2622948
179.1806,9.2215567,5.6846561,0.0,0,4.1220903,0.0,0.47652093,72.908676,4.1252971,395.38586,-9.2622776
179.185,9.2246132,5.7241292,0.0,0,4.0789351,0.0,0.4807955,72.628235,4.0803461,394.54825,-9.2608471
179.1894,9.2808809,5.7679648,0.0,0,4.0362897,0.0,0.48546842,72.688278,4.0397677,393.6452,-9.2615242
179.1938,9.3555202,5.8058538,0.0,0,3.9952466,0.0,0.48961887,72.996193,3.9986012,392.7276,-9.25982
179.1982,9.4331036,5.8530388,0.0,0,3.9542036,0.0,0.49481151,73.240448,3.9561276,391.86121,-9.2615805
179.2026,9.4173813,5.8911219,0.0,0,3.9131603,0.0,0.49900341,72.827583,3.9154186,391.03668,-9.2623682
179.207,9.4552402,5.9340091,0.0,0,3.872117,0.0,0.5038045,72.710793,3.8764799,390.4483,-9.2618694
179.2114,9.5526667,5.9686241,0.0,0,3.831074,0.0,0.507514,73.255371,3.8365109,390.46161,-9.2625704
179.2158,9.6047621,6.0135326,0.0,0,3.7900305,0.0,0.51268911,73.291313,3.796433,390.4809,-9.2621269
179.2202,9.6891441,6.0530853,0.0,0,3.7489874,0.0,0.51709646,73.543434,3.7511926,390.93304,-9.2611628
179.2246,9.767765,6.0982904,0.0,0,3.7079442,0.0,0.52222383,73.733589,3.710459,391.38519,-9.2618723
179.229,9.8474903,6.1372313,0.0,0,3.6669011,0.0,0.52654815,74.043861,3.6686873,391.5994,-9.2600079
179.2334,9.8571215,6.1787305,0.0,0,3.6258578,0.0,0.5313375,73.802505,3.627563,391.73239,-9.2602148
179.2378,9.8561296,6.2183671,0.0,0,3.5848145,0.0,0.5357582,73.447128,3.5869594,391.37665,-9.2625237
179.2422,9.9750652,6.2598243,0.0,0,3.5455253,0.0,0.54068893,73.980179,3.5453997,390.48566,-9.2615051
179.2466,10.079173,6.2983856,0.0,0,3.5064795,0.0,0.54512841,74.4133,3.5033681,389.65582,-9.2616692
179.251,10.104751,6.3412943,0.0,0,3.4674337,0.0,0.55011415,74.258232,3.464916,389.05737,-9.2607975
179.2554,10.109246,6.380455,0.0,0,3.4283881,0.0,0.55462742,73.929245,3.4266865,388.45895,-9.2616434
179.2598,10.131804,6.4152412,0.0,0,3.3893428,0.0,0.5586229,73.773872,3.3886082,388.9241,-9.2603321
179.2642,10.235381,6.4560733,0.0,0,3.3502972,0.0,0.56335127,74.187019,3.3510966,389.45605,-9.2626486
179.2686,10.301455,6.4921775,0.0,0,3.3112512,0.0,0.56770366,74.369888,3.3144259,389.91641,-9.2627134
179.273,10.3719,6.5318532,0.0,0,3.2722056,0.0,0.57236689,74.506882,3.2781935,390.34198,-9.2607498
179.2774,10.461804,6.5722404,0.0,0,3.2331603,0.0,0.57715166,74.773293,3.2385402,390.66534,-9.2622023
179.2818,10.55473,6.6115408,0.0,0,3.1941147,0.0,0.58173507,75.070374,3.192858,390.8382,-9.2619762
179.2862,10.627197,6.6552491,0.0,0,3.1550689,0.0,0.5870406,75.2314,3.1518693,391.01889,-9.2609339
179.2906,10.658031,6.6930852,0.0,0,3.1170006,0.0,0.59146655,75.098381,3.1150653,391.24911,-9.2609997
179.295,10.670451,6.7317319,0.0,0,3.0798559,0.0,0.59625518,74.868546,3.077045,391.47934,-9.261219
179.2994,10.753871,6.7704654,0.0,0,3.042711,0.0,0.60068971,75.010078,3.0404902,391.50027,-9.261261
179.3038,10.812322,6.8060226,0.0,0,3.0055661,0.0,0.60516793,75.171638,3.0035434,391.50027,-9.2604666
179.3082,10.895514,6.8465199,0.0,0,2.9684215,0.0,0.61006016,75.338615,2.9651151,391.53436,-9.259656
179.3126,10.944549,6.881423,0.0,0,2.9312766,0.0,0.61432934,75.355385,2.9286208,391.58755,-9.2610912
179.317,11.025259,6.9182458,0.0,0,2.8941319,0.0,0.61879861,75.608345,2.8915379,391.69031,-9.2619858
179.3214,11.103879,6.9593053,0.0,0,2.8569868,0.0,0.62384766,75.72213,2.8534005,391.8765,-9.2609539
179.3258,11.138741,6.9951696,0.0,0,2.8198423,0.0,0.62827528,75.664528,2.8174722,392.04599,-9.2617846
179.3302,11.164353,7.0314097,0.0,0,2.7826974,0.0,0.63272983,75.495659,2.7791803,392.0726,-9.2616482
179.3346,11.277206,7.0690441,0.0,0,2.7455528,0.0,0.63738465,75.871704,2.7435889,392.09918,-9.2605686
179.339,11.365907,7.1080709,0.0,0,2.7086811,0.0,0.64228982,76.113098,2.7067196,392.0813,-9.2630796
179.3434,11.462218,7.1437888,0.0,0,2.6733489,0.0,0.64688319,76.399544,2.6672444,392.05469,-9.2611742
179.3478,11.458052,7.181119,0.0,0,2.6380169,0.0,0.65154397,76.069038,2.6318355,391.99789,-9.2608414
179.3522,11.505138,7.2168903,0.0,0,2.602685,0.0,0.65617096,75.995903,2.5966504,391.91809,-9.2601871
179.3566,11.589668,7.253139,0.0,0,2.567353,0.0,0.66076988,76.233856,2.5620399,391.83032,-9.2614021
179.361,11.693053,7.2868295,0.0,0,2.532021,0.0,0.6650601,76.576263,2.5271895,391.72394,-9.2623739
179.3654,11.749324,7.3251872,0.0,0,2.4966891,0.0,0.66998166,76.5494,2.4926178,391.61752,-9.2614202
179.3698,11.83005,7.3617382,0.0,0,2.4613569,0.0,0.67458647,76.683113,2.453213,391.51114,-9.2603378
179.3742,11.918513,7.3972654,0.0,0,2.4260249,0.0,0.67930633,76.920273,2.4196205,391.40479,-9.2609739
179.3786,11.971283,7.4346452,0.0,0,2.3906929,0.0,0.68412346,76.9179,2.3850808,391.15622,-9.261713
179.383,11.992499,7.4651237,0.0,0,2.355361,0.0,0.68822181,76.736481,2.3530149,390.86365,-9.262311
179.3874,12.028838,7.5024629,0.0,0,2.3200288,0.0,0.69304419,76.577072,2.3162334,390.45908,-9.2598734
179.3918,12.154974,7.5340533,0.0,0,2.2860541,0.0,0.69730347,77.052719,2.2804372,389.94043,-9.2601385
179.3962,12.29374,7.5746503,0.0,0,2.2524469,0.0,0.70258611,77.483078,2.2488868,389.31903,-9.261034
179.4006,12.355843,7.6056685,0.0,0,2.2188396,0.0,0.706801,77.590614,2.2068272,388.34824,-9.2613029
179.405,12.341958,7.6438088,0.0,0,2.1852326,0.0,0.71184778,77.112511,2.1780634,387.37741,-9.2614555
179.4094,12.389023,7.6760411,0.0,0,2.1516254,0.0,0.71641487,77.034981,2.1473117,386.96783,-9.2609386
179.4138,12.501949,7.7086458,0.0,0,2.1180182,0.0,0.72067171,77.416885,2.1123667,386.58215,-9.2607317
179.4182,12.581534,7.7396607,0.0,0,2.0844109,0.0,0.72495973,77.571487,2.0781872,386.73859,-9.2607298
179.4226,12.651718,7.7790227,0.0,0,2.0508039,0.0,0.73025012,77.596474,2.0463519,387.13754,-9.2597399
179.427,12.755413,7.8092175,0.0,0,2.0171967,0.0,0.73456061,77.911026,2.0168653,387.41284,-9.2609243
179.4314,12.906824,7.8499823,0.0,0,1.9835894,0.0,0.7400822,78.335091,1.9818573,387.51923,-9.2612562
179.4358,12.96702,7.8826113,0.0,0,1.9499823,0.0,0.74478745,78.390587,1.9456143,387.56192,-9.2619972
179.4402,13.007382,7.9184637,0.0,0,1.9170679,0.0,0.74950814,78.280334,1.9105201,387.25604,-9.2615891
179.4446,13.108163,7.9525595,0.0,0,1.8850974,0.0,0.75467914,78.486382,1.8741648,386.95016,-9.2609501
179.449,13.182,7.9892516,0.0,0,1.853127,0.0,0.75957423,78.502609,1.8397233,386.38498,-9.2606726
179.4534,13.135813,8.0161629,0.0,0,1.8211566,0.0,0.76370901,77.90963,1.8109368,385.78653,-9.2606735
179.4578,13.150726,8.0504923,0.0,0,1.7891862,0.0,0.76826769,77.63839,1.779681,385.45117,-9.2594385
179.4622,13.226736,8.0754318,0.0,0,1.7572159,0.0,0.77234763,77.766426,1.7534529,385.27832,-9.2618475
179.4666,13.361676,8.1087027,0.0,0,1.7252455,0.0,0.77675492,78.156181,1.7217019,385.30093,-9.2610054
179.471,13.511312,8.1375265,0.0,0,1.693275,0.0,0.78129649,78.784248,1.6883096,385.68658,-9.2606573
179.4754,13.603244,8.1774788,0.0,0,1.6613046,0.0,0.78676683,78.920929,1.6599716,385.98627,-9.2623587
179.4798,13.713311,8.2035475,0.0,0,1.6293342,0.0,0.79106444,79.145988,1.6198854,385.32135,-9.2622747
179.4842,13.776411,8.2455473,0.0,0,1.5973638,0.0,0.79679418,79.049721,1.5880382,384.65643,-9.2600603
179.4886,13.868028,8.2732239,0.0,0,1.5654866,0.0,0.80125159,79.248154,1.5557507,384.15381,-9.2599201
179.493,13.868263,8.3083963,0.0,0,1.5350735,0.0,0.80648559,78.83181,1.5224762,383.68835,-9.2608156
179.4974,13.884483,8.3338003,0.0,0,1.5046606,0.0,0.8104648,78.606712,1.4985015,383.96277,-9.2616405
179.5018,13.969095,8.3651495,0.0,0,1.4742478,0.0,0.81498289,78.693932,1.4655464,384.85379,-9.2610626
179.5062,14.10003,8.3930387,0.0,0,1.4438351,0.0,0.81932724,79.10273,1.4421932,385.58624,-9.2604189
179.5106,14.232752,8.4274187,0.0,0,1.4134222,0.0,0.82458615,79.4785,1.4067634,385.9054,-9.2601156
179.515,14.302813,8.4592638,0.0,0,1.3830094,0.0,0.82957745,79.41291,1.3725071,386.21503,-9.261241
179.5194,14.373652,8.4925404,0.0,0,1.3525968,0.0,0.83455592,79.422745,1.3441154,385.48361,-9.2608862
179.5238,14.454243,8.5183134,0.0,0,1.322184,0.0,0.83881646,79.494858,1.313651,384.7522,-9.2608776
179.5282,14.509298,8.5529108,0.0,0,1.2917712,0.0,0.84396291,79.440331,1.2809585,383.70511,-9.2602949
179.5326,14.508023,8.5753736,0.0,0,1.2613584,0.0,0.84767801,79.152626,1.25419,382.54764,-9.2603645
179.537,14.663028,8.6082478,0.0,0,1.2309455,0.0,0.85279578,79.586136,1.2220838,381.76755,-9.2599058
179.5414,14.834128,8.6356678,0.0,0,1.2015678,0.0,0.85731512,80.104462,1.1935556,381.40839,-9.2615376
179.5458,14.961298,8.6698904,0.0,0,1.1726422,0.0,0.86272007,80.389076,1.1596961,380.81461,-9.2595968
179.5502,14.981368,8.697917,0.0,0,1.1437165,0.0,0.86730874,80.166519,1.1310687,379.30847,-9.2607794
179.5546,14.953538,8.729641,0.0,0,1.114791,0.0,0.87237924,79.624016,1.1017858,377.80234,-9.2614975
179.559,15.057419,8.7538195,0.0,0,1.0858653,0.0,0.8760848,79.818443,1.0717673,376.44595,-9.2600489
179.5634,15.09532,8.7806854,0.0,0,1.0569397,0.0,0.88061732,79.657166,1.0512725,375.09973,-9.2615995
179.5678,15.191933,8.8052387,0.0,0,1.0280141,0.0,0.88466132,79.887215,1.024544,375.1785,-9.2620354
179.5722,15.331504,8.835227,0.0,0,0.99908859,0.0,0.88966274,80.203407,0.99493337,375.96487,-9.2606688
179.5766,15.428961,8.8597727,0.0,0,0.97016299,0.0,0.89350963,80.384712,0.96721184,376.67664,-9.2607088
179.581,15.551708,8.8880196,0.0,0,0.94123739,0.0,0.89854753,80.619957,0.93717325,377.27643,-9.2594175
179.5854,15.695456,8.9194117,0.0,0,0.91231167,0.0,0.90353948,80.941315,0.90537822,377.8569,-9.2607708
179.5898,15.838573,8.950016,0.0,0,0.88385707,0.0,0.90867823,81.274551,0.87805563,378.31009,-9.2601805
179.5942,15.99463,8.9800043,0.0,0,0.85634828,0.0,0.91359371,81.676727,0.84681678,378.76324,-9.2605667
179.5986,16.017433,9.0114689,0.0,0,0.82883948,0.0,0.91907221,81.311104,0.8177675,379.15887,-9.2612133
179.603,16.006567,9.037118,0.0,0,0.80133069,0.0,0.92345333,80.92804,0.78800195,379.54541,-9.2602043
179.6074,16.016121,9.0650568,0.0,0,0.77382189,0.0,0.92798769,80.643936,0.76236606,379.80496,-9.2621593
179.6118,16.094971,9.0865507,0.0,0,0.74631304,0.0,0.93168908,80.698166,0.73520118,379.97821,-9.2609835
179.6162,16.23328,9.1156702,0.0,0,0.7188043,0.0,0.93688816,81.016495,0.71120238,380.05988,-9.2593269
179.6206,16.3925,9.1417742,0.0,0,0.69129544,0.0,0.94122756,81.446571,0.68219435,379.95325,-9.2614594
179.625,16.494541,9.1674852,0.0,0,0.66378671,0.0,0.94556105,81.617393,0.65444642,379.80487,-9.2617807
179.6294,16.602699,9.1982584,0.0,0,0.63627785,0.0,0.95082474,81.70369,0.62406337,378.99182,-9.2595301
179.6338,16.724398,9.2227468,0.0,0,0.60876906,0.0,0.95535588,81.90596,0.60136449,378.1788,-9.2601357
179.6382,16.770044,9.2508926,0.0,0,0.58126026,0.0,0.96008557,81.779587,0.56671381,377.60822,-9.2606897
179.6426,16.769585,9.2770109,0.0,0,0.55503875,0.0,0.96459383,81.402573,0.5460279,377.10172,-9.2611818
179.647,16.295359,9.2941179,0.0,0,0.52885872,0.0,0.96753764,78.847908,0.52068907,377.82758,-9.260787
179.6514,15.717335,9.303484,0.0,0,0.50267869,0.0,0.96939898,75.939278,0.50797981,379.67859,-9.262042
179.6558,15.397109,9.3137989,0.0,0,0.47649872,0.0,0.97094303,74.2341,0.49321792,381.44153,-9.262332
179.6602,15.164158,9.3203697,0.0,0,0.45031872,0.0,0.97215039,73.054909,0.47759071,382.94659,-9.2620811
179.6646,14.762004,9.3221693,0.0,0,0.4241387,0.0,0.97242016,71.11364,0.45745671,384.45163,-9.2621899
179.669,14.329747,9.3281279,0.0,0,0.3979587,0.0,0.9736498,68.957031,0.44390815,384.23605,-9.2620087
179.6734,13.898121,9.3262081,0.0,0,0.3717787,0.0,0.97304273,66.917587,0.43593842,383.9967,-9.2623606
179.6778,13.569714,9.328742,0.0,0,0.3455987,0.0,0.97372007,65.250221,0.43285754,383.75732,-9.2626181
179.6822,13.409253,9.333931,0.0,0,0.3194187,0.0,0.97423202,64.497063,0.41681001,383.51794,-9.2626877
179.6866,13.370795,9.3335123,0.0,0,0.29323873,0.0,0.97419232,64.282654,0.40658996,383.00293,-9.2633457
179.691,13.578458,9.3353338,0.0,0,0.26783612,0.0,0.97430569,65.204826,0.37424964,382.151,-9.2629213
179.6954,13.817728,9.339922,0.0,0,0.24294093,0.0,0.97523415,66.374603,0.33932891,381.3208,-9.2621164
179.6998,13.959459,9.3430319,0.0,0,0.21804574,0.0,0.97569007,66.982529,0.30396235,380.58826,-9.2620249
179.7042,14.021399,9.3466682,0.0,0,0.19315059,0.0,0.97629601,67.272263,0.27346534,379.85574,-9.260766
179.7086,14.048844,9.3513107,0.0,0,0.16825537,0.0,0.97690761,67.320023,0.24230617,379.75595,-9.2624331
179.713,14.042966,9.3516665,0.0,0,0.14336018,0.0,0.97699183,67.294807,0.21691762,379.71597,-9.2619972
179.7174,13.995687,9.3532915,0.0,0,0.11846498,0.0,0.9773885,67.069466,0.18914406,379.73618,-9.2607431
179.7218,13.907163,9.3579006,0.0,0,0.093569778,0.0,0.97785902,66.622551,0.16906185,379.78949,-9.2621393
179.7262,13.837947,9.3608522,0.0,0,0.068674572,0.0,0.97831726,66.231865,0.14455687,379.80762,-9.260891
179.7306,13.778241,9.3599939,0.0,0,0.043779373,0.0,0.97817618,65.971703,0.12471104,379.76761,-9.2619171
179.735,13.703712,9.3632402,0.0,0,0.018884173,0.0,0.97861707,65.570854,0.10028533,379.73053,-9.2630119
179.7394,13.59459,9.3669415,0.0,0,-0.00586442,0.0,0.97933954,65.026497,0.087288409,379.71722,-9.2615671
179.7438,13.497506,9.367506,0.0,0,-0.03015242,0.0,0.97922587,64.537422,0.070002839,379.70389,-9.2623348
179.7482,13.410597,9.3704109,0.0,0,-0.05444042,0.0,0.97975677,64.073318,0.056910783,379.64572,-9.260766
179.7526,13.314994,9.3718815,0.0,0,-0.078728423,0.0,0.97980171,63.647202,0.038872346,379.57907,-9.260808
179.757,13.195982,9.3727579,0.0,0,-0.10301641,0.0,0.98005342,63.078083,0.029842056,379.49716,-9.2626228
179.7614,13.055232,9.3766937,0.0,0,0.4260999,400.0,0.98057085,62.349705,0.020640178,379.40387,-9.262188
179.7658,12.417149,9.3708763,6.4388509,0,1.222958,400.0,0.97959137,59.461975,0.036873829,379.31058,-9.262351
179.7702,8.8530397,9.3610563,27.581478,0,2.0198162,400.0,0.97766608,42.604851,0.2221251,379.21729,-9.2640095
179.7746,1.1174561,9.3130159,47.955322,0,2.8166733,400.0,0.96953607,6.1860189,0.55274421,379.11865,-9.2704744
179.779,0.90161216,9.2982302,47.955322,0,3.6135306,400.0,0.96677119,4.5490775,1.7638426,378.87872,-9.272851
179.7834,1.1065602,9.3135042,47.955322,0,4.4103885,400.0,0.96904749,5.3358674,2.9868314,378.63882,-9.2708473
179.7878,1.0708355,9.3236189,48.100433,0,5.2072458,400.0,0.97085845,5.1399751,3.7802508,378.54224,-9.2695684
179.7922,0.94962561,9.3268423,48.289337,0,6.0041041,400.0,0.97152227,4.5912766,4.5428252,378.48892,-9.2691374
179.7966,1.0388756,9.3178415,48.383789,0,6.8009615,400.0,0.96970356,4.9645991,5.2911334,378.4223,-9.2684669
179.801,1.0275534,9.3076181,48.383789,0,7.5978193,400.0,0.9677884,4.9188862,6.083982,378.34232,-9.2671118
179.8054,1.0498691,9.319993,48.427582,0,8.3946772,400.0,0.97001892,5.0782843,6.9117522,378.26852,-9.266345
179.8098,1.1534129,9.3117971,48.616486,0,9.191534,400.0,0.96885008,5.585331,7.7483263,378.21518,-9.2664242
179.8142,0.99775273,9.3185005,48.805382,0,9.9883928,400.0,0.96972901,4.7943115,8.5710678,378.16187,-9.2663412
179.8186,1.029363,9.3107166,48.812256,0,10.785251,400.0,0.96860564,5.024436,9.3774195,378.18561,-9.2659397
179.823,1.0534493,9.3203259,48.812256,0,11.582107,400.0,0.96985912,5.1092906,10.207515,378.21228,-9.2651663
179.8274,1.0010035,9.3143978,48.812256,0,12.378964,400.0,0.96917671,4.84798,11.011829,378.25748,-9.2642126
179.8318,0.90787506,9.3268414,48.812256,0,13.175823,400.0,0.97095871,4.394412,11.800647,378.31079,-9.2654171
179.8362,1.024116,9.3146534,48.812256,0,13.97268,400.0,0.9694351,4.9385319,12.562199,378.31854,-9.2661028
179.8406,1.0359894,9.3037081,48.812256,0,14.769538,400.0,0.96694231,4.9988775,13.338592,378.26523,-9.2638588
179.845,1.0157186,9.3148842,48.841537,0,15.566396,400.0,0.96935171,4.891541,14.137458,378.2204,-9.2639551
179.8494,1.1663405,9.3191748,49.025597,0,16.363255,400.0,0.96984559,5.6466818,14.952826,378.2204,-9.2636919
179.8538,0.99979061,9.316328,49.209656,0,17.16011,400.0,0.96973598,4.8045864,15.754017,378.2204,-9.2643433
179.8582,1.0000592,9.3170614,49.229736,0,17.95697,400.0,0.96952415,4.7549844,16.559032,378.27979,-9.2646685
179.8626,1.0778962,9.3168535,49.229736,0,18.0,400.0,0.96994692,5.2175269,17.354292,378.34644,-9.2637587
179.867,1.088927,9.3186312,49.229736,0,18.0,400.0,0.96986067,5.2820868,18.042358,378.37158,-9.2644167
179.8714,1.045469,9.3196163,49.229736,0,18.0,400.0,0.97059172,5.0493879,18.457279,378.37158,-9.2709417
179.8758,1.2359675,9.3202801,49.229736,0,18.0,400.0,0.97020102,5.9255719,18.457121,378.37631,-9.2809963
179.8802,1.1810927,9.2972746,49.229736,0,18.0,400.0,0.96656924,5.7038469,18.222034,378.38962,-9.3016214
179.8846,1.2049921,9.3193521,49.229736,0,18.0,400.0,0.97029543,5.8494086,18.057705,378.40179,-9.3330584
179.889,1.3359169,9.3093328,49.229736,0,18.0,400.0,0.96883571,6.4207091,18.038654,378.40179,-9.3717556
179.8934,1.1215816,9.3137703,49.229736,0,18.0,400.0,0.9694308,5.4188781,18.082369,378.40179,-9.4088297
179.8978,1.1950524,9.3044157,49.229736,0,18.0,400.0,0.96807247,5.7362971,18.12401,378.37997,-9.4417324
179.9022,1.2142549,9.312109,49.229736,0,18.0,400.0,0.96921068,5.9256277,18.147892,378.35333,-9.478159
179.9066,1.1621305,9.3090019,49.328308,0,18.0,400.0,0.96898031,5.5942488,18.148207,378.31934,-9.5055113
179.911,1.089111,9.3125181,49.507519,0,18.0,400.0,0.96948588,5.2927814,18.145699,378.27936,-9.5370331
179.9154,1.1938266,9.3061171,49.63623,0,18.0,400.0,0.96871185,5.7435017,18.136719,378.24313,-9.57024
179.9198,1.1072118,9.2944136,49.63623,0,18.0,400.0,0.96666008,5.34865,18.132692,378.21646,-9.6043921
179.9242,1.1627432,9.3066483,49.63623,0,18.0,400.0,0.96898329,5.6558509,18.124634,378.19037,-9.6371593
179.9286,1.339759,9.3106308,49.63623,0,18.0,400.0,0.96969002,6.3400955,18.118202,378.20367,-9.669817
179.933,1.1843108,9.3065958,49.63623,0,18.0,400.0,0.96898979,5.6803246,18.11087,378.21701,-9.7009869
179.9374,1.2029397,9.3069067,49.63623,0,18.0,400.0,0.96914876,5.8161407,18.111973,378.2204,-9.7349482
179.9418,1.2405354,9.3094101,49.63623,0,18.0,400.0,0.96957684,5.9871788,18.10766,378.2204,-9.765377
179.9462,1.1698906,9.3053513,49.721767,0,18.0,400.0,0.96893573,5.6563606,18.102934,378.20767,-9.7978592
179.9506,1.1432755,9.3000975,49.900982,0,18.0,400.0,0.96793538,5.546937,18.108496,378.181,-9.8291111
179.955,1.2129033,9.3061905,50.042725,0,18.0,400.0,0.96928,5.8443513,18.103172,378.16827,-9.8633881
179.9594,1.0551379,9.2926741,50.042725,0,18.0,400.0,0.96717447,5.1451755,18.102106,378.20825,-9.8980217
179.9638,1.1784495,9.3034277,50.042725,0,18.0,400.0,0.96900058,5.6914611,18.098013,378.24826,-9.9301243
179.9682,1.1458464,9.3068476,50.042725,0,18.0,400.0,0.96941406,5.4456892,18.104286,378.26318,-9.9616051
179.9726,1.1874881,9.3083372,50.042725,0,18.0,400.0,0.96997881,5.7386546,18.096439,378.27652,-9.9949675
179.977,1.2025584,9.3013229,50.042725,0,18.0,400.0,0.96872431,5.8845654,18.096132,378.254,-10.027211
179.9814,1.2493594,9.3049774,50.042725,0,18.0,400.0,0.96946937,6.0172024,18.094515,378.21399,-10.059969
179.9858,1.1928233,9.3028383,50.042725,0,18.0,400.0,0.96912032,5.7280941,18.094126,378.17938,-10.090272
179.9902,1.2047313,9.2989311,50.042725,0,18.0,400.0,0.96829599,5.8650117,18.093695,378.15274,-10.122359
179.9946,1.2075236,9.3002949,50.042725,0,18.0,400.0,0.96866292,5.8573895,18.092634,378.12244,-10.155078
179.999,1.0488977,9.2970629,50.042725,0,18.0,400.0,0.96827245,5.0567036,18.0865,378.06912,-10.188687
180.0034,1.2111862,9.3007975,50.042725,0,18.0,400.0,0.96878171,5.8413215,18.088131,378.01581,-10.22156
180.0078,1.2162639,9.2995415,50.194111,0,18.0,400.0,0.96867949,5.8792644,18.086058,378.00879,-10.253732
180.0122,1.1995356,9.3066502,50.368484,0,18.0,400.0,0.96980435,5.7708521,18.086403,378.00879,-10.287827
180.0166,1.1787256,9.3030796,50.438232,0,18.0,400.0,0.96919191,5.6752353,18.083881,378.02478,-10.319742
180.021,1.2243656,9.2998276,50.438232,0,18.0,400.0,0.96844667,5.9034309,18.082029,378.05142,-10.351563
180.0254,1.2232203,9.2990971,50.438232,0,18.0,400.0,0.96861392,5.8784399,18.080027,378.06039,-10.38312
180.0298,1.2614275,9.2933912,50.438232,0,18.0,400.0,0.96737367,6.1361141,18.080711,378.03375,-10.416422
180.0342,1.1829103,9.3009977,50.438232,0,18.0,400.0,0.96894568,5.7426324,18.076437,378.00793,-10.448929
180.0386,1.0259916,9.2957001,50.438232,0,18.0,400.0,0.96773672,4.9203591,18.076504,377.9946,-10.483098
180.043,1.2478645,9.29807,50.438232,0,18.0,400.0,0.96835399,5.9751377,18.076395,377.98126,-10.51358
180.0474,1.2385491,9.3020926,50.573086,0,18.0,400.0,0.9687686,5.9690771,18.078928,377.93613,-10.547346
180.0518,1.1593193,9.3074808,50.742615,0,18.0,400.0,0.96992898,5.5883889,18.075314,377.88281,-10.579788
180.0562,1.1824967,9.2984371,50.822754,0,18.0,400.0,0.96808922,5.7296357,18.075264,377.82248,-10.610892
180.0606,1.2272604,9.2929173,50.822754,0,18.0,400.0,0.96714461,5.8786316,18.075529,377.75586,-10.643681
180.065,1.2420492,9.3018789,50.822754,0,18.0,400.0,0.96866632,6.0345039,18.073891,377.70993,-10.675886
180.0694,1.3137896,9.2962437,50.822754,0,18.0,400.0,0.96750295,6.4213943,18.066898,377.72327,-10.709537
180.0738,1.1770977,9.3006983,50.822754,0,18.0,400.0,0.96823668,5.6971059,18.064415,377.73657,-10.743667
180.0782,1.0617925,9.2970152,50.822754,0,18.0,400.0,0.9675194,5.2083669,18.057119,377.76312,-10.775763
180.0826,1.2848351,9.305068,50.822754,0,18.0,400.0,0.9690336,6.2161746,18.062456,377.78979,-10.80687
180.087,1.2276555,9.3007126,50.941776,0,18.0,400.0,0.96797997,5.9551249,18.058653,377.79718,-10.838907
180.0914,1.1128507,9.3096018,51.106461,0,18.0,400.0,0.96963221,5.3450127,18.058422,377.79718,-10.871187
180.0958,1.1979817,9.3002405,51.196289,0,18.0,400.0,0.96778941,5.7845941,18.059355,377.78506,-10.904185
180.1002,1.2344751,9.290801,51.196289,0,18.0,400.0,0.96609968,5.9512043,18.058559,377.75839,-10.935267
180.1046,1.2389674,9.2992792,51.196289,0,18.0,400.0,0.96755379,5.9908323,18.059265,377.73669,-10.969214
180.109,1.3467237,9.3013325,51.196289,0,18.0,400.0,0.96773678,6.5387816,18.06135,377.73669,-11.001584
180.1134,1.1959319,9.301465,51.196289,0,18.0,400.0,0.96765935,5.7583537,18.057734,377.73669,-11.033083
180.1178,1.2806309,9.298274,51.196289,0,18.0,400.0,0.96687311,6.2319756,18.058256,377.73669,-11.067382
180.1222,1.3068973,9.3063745,51.196289,0,18.0,400.0,0.96839142,6.3292913,18.058624,377.73669,-11.100195
180.1266,1.214087,9.3041868,51.303333,0,18.0,400.0,0.96805394,5.8949866,18.057161,377.71936,-11.132583
180.131,1.1061882,9.3108139,51.468021,0,18.0,400.0,0.96914256,5.3600211,18.055925,377.69269,-11.165132
180.1354,1.2407041,9.3041325,51.569824,0,18.0,400.0,0.9678309,5.9988914,18.053408,377.67621,-11.197039
180.1398,1.227679,9.2880821,51.569824,0,18.0,400.0,0.96478337,5.9326587,18.055607,377.67621,-11.229264
180.1442,1.2320238,9.3077679,51.569824,0,18.0,400.0,0.96833926,5.9820199,18.05512,377.67923,-11.261654
180.1486,1.3950568,9.3025322,51.569824,0,18.0,400.0,0.96741593,6.8155236,18.050589,377.7059,-11.294058
180.153,1.2078727,9.3072786,51.569824,0,18.0,400.0,0.96808273,5.8237758,18.051998,377.73257,-11.327022
180.1574,1.2942007,9.3017683,51.569824,0,18.0,400.0,0.96712339,6.2095537,18.049004,377.70288,-11.359271
181.8583,0.97983813,9.3120461,3.9626255000000004e-22,0,18.0,2.6539226e-21,0.96967798,4.7238984,18.000269,345.40033,-11.48114
184.0583,0.87539351,9.3156281,7.9874012e-44,0,18.0,1.4012985e-45,0.97033352,4.2277541,17.999716,311.94196,-11.481637
186.2583,0.89615941,9.3252048,7.9874012e-44,0,18.0,1.4012985e-45,0.97206467,4.3112736,18.000401,288.39832,-11.48173
188.4583,0.90464085,9.3334751,7.9874012e-44,0,18.0,1.4012985e-45,0.97355616,4.3505607,17.998755,269.65826,-11.48136
190.6583,0.91687864,9.3405027,7.9874012e-44,0,18.0,1.4012985e-45,0.97479826,4.4064255,17.999586,253.42754,-11.481488
192.8583,0.9208163,9.3475027,7.9874012e-44,0,18.0,1.4012985e-45,0.97595859,4.4182105,18.000046,239.63498,-11.482045
195.0583,0.92682421,9.353755,7.9874012e-44,0,18.0,1.4012985e-45,0.97703308,4.4467154,17.99955,225.66183,-11.481989
197.2583,0.93738073,9.3601894,7.9874012e-44,0,18.0,1.4012985e-45,0.97815466,4.4856639,18.000362,215.03941,-11.481884
199.4583,0.94395214,9.3660221,7.9874012e-44,0,18.0,1.4012985e-45,0.9791615,4.5110788,18.000027,199.2312,-11.481986
201.6583,0.9527306,9.3718758,7.9874012e-44,0,18.0,1.4012985e-45,0.98022252,4.5497255,18.000277,191.77338,-11.482213
203.8583,0.96065283,9.3767071,7.9874012e-44,0,18.0,1.4012985e-45,0.98106956,4.5875826,17.999306,182.09106,-11.482349
206.0583,0.96952987,9.3817787,7.9874012e-44,0,18.0,1.4012985e-45,0.98202926,4.6148229,17.999746,172.94887,-11.482357
208.2583,0.98116767,9.3865566,7.9874012e-44,0,18.0,1.4012985e-45,0.98292291,4.6779652,17.999889,164.65179,-11.482222
210.4583,0.98377436,9.3906393,7.9874012e-44,0,18.0,1.4012985e-45,0.98367071,4.6829915,18.000496,161.97078,-11.481926
212.6583,0.98444653,9.3953733,7.9874012e-44,0,18.0,1.4012985e-45,0.98449153,4.6808996,17.999672,154.49973,-11.48175
214.8583,0.99132341,9.3998146,7.9874012e-44,0,18.0,1.4012985e-45,0.98524046,4.7088771,18.000751,147.41,-11.482189
217.0583,0.99321371,9.4039793,7.9874012e-44,0,18.0,1.4012985e-45,0.98595989,4.7214489,17.999361,141.00056,-11.481894
219.2583,0.99473554,9.4072342,7.9874012e-44,0,18.0,1.4012985e-45,0.98654437,4.7181406,17.999636,134.85599,-11.482304
221.4583,1.0007708,9.4113188,7.9874012e-44,0,18.0,1.4012985e-45,0.98729962,4.741293,17.99967,128.70824,-11.482215
223.6583,1.0079057,9.4146919,7.9874012e-44,0,18.0,1.4012985e-45,0.98794132,4.7752728,17.99996,122.97935,-11.482308
225.8583,1.0083858,9.4177332,7.9874012e-44,0,18.0,1.4012985e-45,0.98853403,4.7801981,18.000351,117.68865,-11.482461
228.0583,1.0135185,9.4211807,7.9874012e-44,0,18.0,1.4012985e-45,0.98916239,4.7971935,18.000376,112.91389,-11.482463
230.2583,1.0116056,9.4244862,7.9874012e-44,0,18.0,1.4012985e-45,0.98970789,4.7844315,17.999317,107.99548,-11.48194
232.4583,1.0178529,9.4273806,7.9874012e-44,0,18.0,1.4012985e-45,0.99017429,4.8140922,18.000566,103.54517,-11.481831
234.6583,1.0145539,9.4304504,7.9874012e-44,0,18.0,1.4012985e-45,0.99067897,4.8001251,17.999626,99.131653,-11.481882
236.8583,1.0175772,9.4333248,7.9874012e-44,0,18.0,1.4012985e-45,0.99119198,4.8061633,17.999853,94.883125,-11.481457
239.0583,1.0118836,9.4357901,7.9874012e-44,0,18.0,1.4012985e-45,0.99161685,4.7826905,18.001425,90.936615,-11.481645
240.1583,1.0219737,9.4363785,7.9874012e-44,0,18.0,1.4012985e-45,0.99179864,4.826334,17.999485,89.017899,-11.481315