File: raw data/testID_0236.csv
Time(sec),Force(kN),Jaw(mm),PowAngle(deg),Power(W),Pram,PTemp,Strain,Stress(MPa),Stroke(mm),TC1(C),wedge(mm)
0.0,1.5039455,-0.10881311,0.0,0,11.076097,0.00068862399,-0.0072072591,19.302454,11.076301,22.448359,-9.1223717
1.3,1.4412088,-0.0023453701,0.0,0,11.076097,3.815918,-0.00014654275,18.353235,11.076371,22.328228,-9.4884415
2.6,1.4067984,-0.0023112115,0.0,0,11.076097,7.7159162,-0.00017638768,17.902994,11.076785,22.415451,-9.4853954
3.9,1.3794082,-0.0021803135,0.0,0,11.076097,11.615913,-0.00013701392,17.574541,11.075706,22.458614,-9.4837465
5.2,1.3484182,-0.0020610881,0.0,0,11.076097,15.515914,-0.00014201006,17.175045,11.076319,22.421761,-9.4810209
6.5,1.3329515,-0.0025147172,0.0,0,11.076097,19.415915,-0.00016523541,16.966341,11.076345,22.456818,-9.4784746
7.8,1.3140808,-0.0024265463,2.0028007,0,11.076097,23.315916,-0.00016127303,16.721111,11.076453,22.394201,-9.4760342
9.1,1.2993193,-0.0021852895,26.063316,0,11.076097,27.215914,-0.00017069372,16.549242,11.0761,22.495234,-9.4734735
10.4,1.3089896,-0.0023827178,38.53141,0,11.076097,31.115911,-0.00014045574,16.668972,11.075994,23.112347,-9.4715662
11.7,1.2994109,-0.0039299796,46.307339,0,11.076097,35.015907,-0.00026577836,16.547743,11.075815,24.95013,-9.4696274
13.0,1.2985086,-0.0057388339,51.181232,0,11.076097,38.915909,-0.00040415648,16.541294,11.075451,28.326265,-9.4673319
14.3,1.3046314,-0.0079775527,54.31115,0,11.076097,42.815914,-0.00050630816,16.614315,11.076371,32.960026,-9.4652185
15.6,1.3067806,-0.010358997,56.251251,0,11.076097,46.715919,-0.00068225473,16.637129,11.075956,38.436764,-9.4632273
16.9,1.293666,-0.012514232,57.141415,0,11.076097,50.615917,-0.00085722125,16.495481,11.075753,44.50177,-9.4604387
18.2,1.2936283,-0.014109937,57.112797,0,11.076097,54.515907,-0.00091160508,16.485275,11.076074,50.865833,-9.458744
19.5,1.2886537,-0.014913679,56.71143,0,11.076097,58.415901,-0.00098876457,16.430679,11.075929,56.944649,-9.4562883
20.8,1.2841643,-0.015983244,55.843525,0,11.076097,62.315895,-0.0010856366,16.3659,11.076507,62.622948,-9.4541998
22.1,1.2747264,-0.016569374,54.624832,0,11.076097,66.215912,-0.0010873885,16.253706,11.076571,67.761192,-9.4519405
23.4,1.2674708,-0.017134713,53.657715,0,11.076097,70.115913,-0.001138108,16.154259,11.075792,72.216743,-9.4500761
24.7,1.2674751,-0.017455433,52.976078,0,11.076097,74.015907,-0.0011691403,16.151125,11.0761,76.223328,-9.4476223
26.0,1.2642425,-0.017536109,52.284523,0,11.076097,77.915901,-0.0011701883,16.120337,11.076362,79.774521,-9.4451075
27.3,1.2516835,-0.017344682,52.283939,0,11.076097,81.815887,-0.0011742214,15.959653,11.07587,83.054062,-9.4426565
28.6,1.2536123,-0.017754629,52.635479,0,11.076097,85.715897,-0.0011761457,15.965521,11.075714,86.104332,-9.4403219
29.9,1.2591397,-0.017686781,52.999355,0,11.076097,89.615898,-0.0011749268,16.054909,11.075964,89.281914,-9.4381161
31.2,1.2497452,-0.018672664,53.657223,0,11.076097,93.5159,-0.0012725675,15.928889,11.076795,92.557594,-9.4356604
32.5,1.2500199,-0.019620409,54.305416,0,11.076097,97.415901,-0.0012859396,15.935353,11.075885,96.074913,-9.4337378
33.8,1.2436384,-0.020480381,54.662331,0,11.076097,101.3159,-0.0013647941,15.861266,11.076641,99.976608,-9.4311476
35.1,1.246881,-0.021163268,55.2388,0,11.076097,105.2159,-0.001437123,15.902435,11.075458,103.96178,-9.4292459
36.4,1.2351158,-0.022907846,55.239254,0,11.076097,109.11588,-0.001498032,15.744116,11.075589,108.10433,-9.4267921
37.7,1.234924,-0.024082411,55.535885,0,11.076097,113.0159,-0.0015986974,15.748857,11.075366,112.22119,-9.4242105
39.0,1.2362972,-0.024878394,55.535885,0,11.076097,116.91589,-0.0016741478,15.754517,11.075393,116.37513,-9.4221468
40.3,1.2307882,-0.026098795,55.535885,0,11.076097,120.8159,-0.001718183,15.691435,11.075664,120.57526,-9.4198971
41.6,1.2309806,-0.026834166,55.362404,0,11.076097,124.7159,-0.0017813133,15.68848,11.075946,124.66644,-9.4180117
42.9,1.2292362,-0.027988795,55.489349,0,11.076097,128.61601,-0.0018742427,15.671016,11.076248,128.56667,-9.4153805
44.2,1.231833,-0.029157111,55.505646,0,11.076097,132.51588,-0.0019366702,15.708405,11.075662,132.47646,-9.413249
45.5,1.2233709,-0.030177811,55.535885,0,11.076097,136.41589,-0.0020230426,15.602108,11.076009,136.35971,-9.4104528
46.8,1.2233468,-0.031470243,55.535885,0,11.076097,140.31587,-0.0020931517,15.597794,11.076433,140.19048,-9.4083071
48.1,1.2192452,-0.032773476,55.624901,0,11.076097,144.21588,-0.0021839195,15.564821,11.076555,143.96809,-9.4057951
49.4,1.2185748,-0.033985719,55.837833,0,11.076097,148.11588,-0.0022859708,15.558878,11.075527,147.85995,-9.4036379
50.7,1.2187324,-0.035654798,55.843506,0,11.076097,152.0159,-0.0023570685,15.548214,11.076834,151.78192,-9.4015369
52.0,1.2183506,-0.03715441,55.843513,0,11.076097,155.91589,-0.0024665608,15.547233,11.075933,155.62151,-9.3992109
53.3,1.2195882,-0.038990371,56.129147,0,11.076097,159.8159,-0.0026197764,15.565185,11.076215,159.43301,-9.3969555
54.6,1.2189598,-0.040555961,56.129147,0,11.076097,163.7159,-0.0026728883,15.560671,11.07614,163.37701,-9.3943796
55.9,1.2215202,-0.041574929,56.289501,0,11.076097,167.61589,-0.0027634054,15.601354,11.075503,167.254,-9.392374
57.2,1.218109,-0.043182891,56.425777,0,11.076097,171.51588,-0.0028951704,15.562418,11.07561,171.13342,-9.3900709
58.5,1.2127135,-0.04514705,56.425785,0,11.076097,175.41588,-0.0029778446,15.481997,11.076094,175.03183,-9.3881025
59.8,1.2057204,-0.046750374,56.711422,0,11.076097,179.31586,-0.0030946427,15.404325,11.076134,178.92441,-9.3855391
61.1,1.2149466,-0.048230715,56.711422,0,11.076097,183.21587,-0.0032275226,15.521443,11.075835,182.87251,-9.3835201
62.4,1.2143364,-0.049932621,56.711422,0,11.076097,187.11588,-0.003312361,15.511532,11.07583,186.78598,-9.3812857
63.7,1.2215865,-0.051871192,56.860306,0,11.076097,191.01587,-0.0034455883,15.61372,11.075892,190.73576,-9.3792257
65.0,1.2192707,-0.053527981,56.986084,0,11.076097,194.91586,-0.0035635962,15.584096,11.075162,194.5128,-9.3772335
66.3,1.2069457,-0.055412967,57.220951,0,11.076097,198.81587,-0.0036886828,15.435209,11.076144,198.38403,-9.3746357
67.6,1.2095475,-0.057464186,57.259827,0,11.076097,202.71587,-0.0038312189,15.459087,11.076241,202.40187,-9.3725681
68.9,1.203334,-0.059642028,57.259151,0,11.076097,206.61586,-0.003966047,15.386933,11.076671,206.4357,-9.370245
70.2,1.205076,-0.061508868,57.174713,0,11.076097,210.51587,-0.0040864758,15.403134,11.075533,210.42068,-9.3680248
71.5,1.2121742,-0.063220963,57.260738,0,11.076097,214.41588,-0.0042183478,15.502454,11.07596,214.24847,-9.3659372
72.8,1.2144916,-0.065141998,57.260738,0,11.076097,218.31587,-0.0043220362,15.521451,11.075958,218.21407,-9.3638515
74.1,1.2161795,-0.067132965,57.260738,0,11.076097,222.21587,-0.0044681858,15.534945,11.076072,222.1431,-9.3617201
75.4,1.2103807,-0.069798909,57.260738,0,11.076097,226.11588,-0.0046667098,15.483223,11.076284,225.9543,-9.3590984
76.7,1.2108432,-0.072067633,57.265656,0,11.076097,230.01588,-0.0047604782,15.494028,11.076085,229.88708,-9.3568792
78.0,1.2186422,-0.074022852,57.265568,0,11.076097,233.91588,-0.0049218265,15.591644,11.075913,233.83121,-9.354845
79.3,1.2193979,-0.075969748,57.37326,0,11.076097,237.81586,-0.0050708582,15.593471,11.076963,237.66832,-9.3523388
80.6,1.2269378,-0.078129269,57.263958,0,11.076097,241.71585,-0.0051714708,15.698639,11.076921,241.76157,-9.3504105
81.9,1.2289948,-0.079997286,57.260746,0,11.076097,245.61586,-0.0053136386,15.732307,11.075093,245.73894,-9.3485069
83.2,1.2175672,-0.082975812,57.25938,0,11.076097,249.51585,-0.0055271196,15.595864,11.075749,249.65262,-9.3461676
84.5,1.2277794,-0.084949397,57.001553,0,11.076097,253.41585,-0.0056342995,15.727467,11.07575,253.6447,-9.3441057
85.8,1.226019,-0.087102182,57.434216,0,11.076097,257.31613,-0.0058027417,15.711136,11.076079,256.93527,-9.341959
87.1,1.2353243,-0.08952757,57.535397,0,11.076097,261.21613,-0.0059499806,15.836761,11.076267,260.93167,-9.3397207
88.4,1.2320584,-0.092152178,57.260746,0,11.076097,265.11584,-0.0061299312,15.785075,11.075991,265.23224,-9.3374424
89.7,1.2409402,-0.094844602,57.125107,0,11.076097,269.01584,-0.006320511,15.895969,11.076385,269.37442,-9.3353424
91.0,1.25081,-0.097781487,56.721867,0,11.076097,272.91586,-0.0064769979,16.035109,11.076233,273.56863,-9.3330822
92.3,1.2512233,-0.099204838,56.652569,0,11.076097,276.81586,-0.006591497,16.044683,11.075868,277.49847,-9.3310375
93.6,1.2532414,-0.10131291,56.425785,0,11.076097,280.71588,-0.0067502735,16.065517,11.07632,281.46472,-9.3287525
94.9,1.254482,-0.10378178,55.852695,0,11.076097,284.61588,-0.0068702484,16.084129,11.075294,285.56665,-9.3266497
96.2,1.2440085,-0.10622676,55.603329,0,11.076097,288.51587,-0.0070446962,15.957124,11.074773,289.47205,-9.3241825
97.5,1.240939,-0.10854139,55.535919,0,11.076097,292.41583,-0.0072290068,15.904622,11.075848,293.08167,-9.3221369
98.8,1.2465391,-0.1112029,55.611206,0,11.076097,296.31583,-0.0073719383,15.984046,11.075457,296.58527,-9.3199377
100.1,1.257004,-0.11327849,55.678234,0,11.076097,300.21582,-0.0075228941,16.130413,11.076027,300.38193,-9.3180809
101.4,1.2530726,-0.11653808,55.535892,0,11.076097,304.11584,-0.0077412329,16.076557,11.075962,304.28079,-9.3157759
102.7,1.2554768,-0.11886604,55.535892,0,11.076097,308.01587,-0.0079043917,16.109287,11.075201,308.26541,-9.3137274
104.0,1.262478,-0.12128675,55.405758,0,11.076097,311.91583,-0.008085453,16.201986,11.076128,312.19498,-9.3117437
105.3,1.2581156,-0.12407432,55.308804,0,11.076097,315.81586,-0.0082128961,16.139166,11.075798,316.04044,-9.3095913
106.6,1.258769,-0.12642604,55.388264,0,11.076097,319.71585,-0.0083851917,16.157488,11.075736,319.84808,-9.3072882
107.9,1.2474363,-0.12905586,55.450466,0,11.076097,323.61588,-0.0085903909,16.008585,11.076292,323.6456,-9.3049898
109.2,1.2647579,-0.13152641,55.374607,0,11.076097,327.51587,-0.0087042358,16.229563,11.075495,327.53201,-9.3030348
110.5,1.2626942,-0.13380289,55.239262,0,11.076097,331.41583,-0.0088702096,16.207689,11.076862,331.59781,-9.3008204
111.8,1.2581246,-0.13664272,54.93227,0,11.076097,335.31586,-0.0090814717,16.167311,11.076944,335.78152,-9.2984467
113.1,1.2666928,-0.13898395,54.669601,0,11.076097,339.21585,-0.0092104459,16.281488,11.075672,339.78415,-9.2965527
114.4,1.2503915,-0.14147481,54.624161,0,11.076097,343.11584,-0.0093969405,16.069744,11.076074,343.53339,-9.2943201
115.7,1.2464629,-0.14361754,54.931583,0,11.076097,347.01587,-0.00953699,16.026024,11.076356,347.08023,-9.292079
117.0,1.2475721,-0.14578928,54.931637,0,11.076097,350.91586,-0.0096716443,16.043545,11.076035,350.85477,-9.2898598
118.3,1.2460371,-0.14791262,55.173981,0,11.076097,354.81586,-0.0098366318,16.031075,11.07632,354.57996,-9.2877064
119.6,1.2461998,-0.14998941,55.153156,0,11.076097,358.71585,-0.0099406037,16.029234,11.075579,358.56183,-9.2857952
120.9,1.2421091,-0.15236901,54.942749,0,11.076097,362.61584,-0.010101856,15.978077,11.075924,362.58508,-9.2839212
122.2,1.2327635,-0.15430672,54.932571,0,11.076097,366.51584,-0.010258734,15.854696,11.075602,366.6409,-9.2813015
123.5,1.2248321,-0.15639079,54.624027,0,11.076097,370.41583,-0.010335728,15.759356,11.075555,370.89645,-9.279274
124.8,1.21962,-0.15802245,54.310997,0,11.076097,374.31586,-0.010474375,15.695965,11.076467,374.87207,-9.2769833
126.1,1.2136408,-0.15927294,54.55555,0,11.076097,378.21585,-0.010578503,15.611723,11.076277,378.49518,-9.2749424
127.4,1.2008051,-0.1611291,54.532055,0,11.076097,382.11584,-0.010662265,15.446328,11.075379,382.30167,-9.2723675
128.7,1.205079,-0.16237862,54.601364,0,11.076097,386.01584,-0.010760958,15.508214,11.075987,386.11841,-9.2706356
130.0,1.1886199,-0.16379222,54.624023,0,11.076097,389.91586,-0.010863554,15.299612,11.075269,389.87466,-9.2681742
131.3,1.1848763,-0.16487142,54.624023,0,11.076097,393.81583,-0.010927087,15.255896,11.07542,393.82089,-9.2662287
132.6,1.1828389,-0.16552822,54.339165,0,11.076097,397.71582,-0.010988425,15.234006,11.076766,397.89453,-9.2640343
133.9,1.1798483,-0.16596614,54.559231,0,11.076097,401.61584,-0.011004421,15.198965,11.076039,401.70377,-9.2621603
135.2,1.1749918,-0.16625012,54.454533,0,11.076097,405.51584,-0.011021446,15.130526,11.076417,405.573,-9.2598886
136.5,1.1710811,-0.16622168,54.356705,0,11.076097,409.41583,-0.011040443,15.081906,11.076612,409.48318,-9.2577391
137.8,1.1663511,-0.1664075,54.305508,0,11.076097,413.31586,-0.011010703,15.01414,11.076838,413.38516,-9.2556009
139.1,1.1661768,-0.16584359,54.305424,0,11.076097,417.21585,-0.010985409,15.014657,11.076644,417.37433,-9.2534933
140.4,1.1627935,-0.16491005,54.164021,0,11.076097,421.11581,-0.010958667,14.963496,11.075047,421.38837,-9.2507429
141.7,1.1630301,-0.16380429,54.212425,0,11.076097,425.01584,-0.010833148,14.962016,11.076652,425.21823,-9.2487574
143.0,1.1594995,-0.16179211,54.200901,0,11.076097,428.91583,-0.010727231,14.923841,11.075772,428.98203,-9.2465487
144.3,1.1609108,-0.15944327,54.026283,0,11.076097,432.81583,-0.010578986,14.932487,11.075994,432.93329,-9.2443514
145.6,1.1602341,-0.15645137,53.975834,0,11.076097,436.71582,-0.010379167,14.934716,11.075854,436.89005,-9.2425489
146.9,1.1613377,-0.15251845,53.975834,0,11.076097,440.61584,-0.010139246,14.934594,11.075476,440.68936,-9.2404518
148.2,1.1564716,-0.14798212,54.007427,0,11.076097,444.51584,-0.009804233,14.864275,11.076207,444.52524,-9.2382746
149.5,1.1586809,-0.14229566,53.975834,0,11.076097,448.41583,-0.0094441902,14.882637,11.075764,448.54248,-9.235836
150.8,1.1560838,-0.13532765,53.763733,0,11.076097,452.31583,-0.0090037901,14.860928,11.075692,452.65839,-9.2338848
152.1,1.1549523,-0.12727883,53.657372,0,11.076097,456.21582,-0.008423117,14.840226,11.075949,456.5769,-9.2316771
153.4,1.1564345,-0.11659669,53.65723,0,11.076097,460.11581,-0.0077344095,14.841295,11.076467,460.51776,-9.2295256
154.7,1.1567432,-0.10420526,53.316654,0,11.076097,464.01581,-0.0069377664,14.826138,11.074978,464.42639,-9.2270546
156.0,0.42370528,-0.10964891,53.316654,0,11.076097,467.91583,-0.00727743,5.4419703,11.076084,468.19058,-9.22509
157.3,0.25742161,-0.11877716,54.623974,0,11.076097,471.81583,-0.0079127001,3.2812331,11.075926,470.60049,-9.2228899
158.6,0.26165986,-0.12215184,54.773403,0,11.076097,475.71582,-0.0081035532,3.3481236,11.075735,474.73639,-9.2210445
159.9,0.2624962,-0.12564763,54.624352,0,11.076097,479.61581,-0.0083423452,3.3629284,11.075162,479.10562,-9.2189436
161.2,0.26158056,-0.1289456,54.638325,0,11.076097,483.51584,-0.0085833408,3.3553834,11.075128,483.25055,-9.2164698
162.5,0.27071917,-0.13264406,54.624027,0,11.076097,487.4158,-0.0087804114,3.4731596,11.07596,487.39874,-9.2142992
163.8,0.27452263,-0.13537262,54.305424,0,11.076097,491.3158,-0.0089709722,3.5409024,11.075558,491.61761,-9.2124653
165.1,0.27321887,-0.13833983,54.250248,0,11.076097,495.21579,-0.0092000216,3.5154188,11.075979,495.6427,-9.2099571
166.4,0.27682328,-0.14140953,54.104679,0,11.076097,499.11581,-0.009371195,3.5680454,11.076612,499.40335,-9.2082453
167.7,0.27864516,-0.14373875,52.285809,0,11.076097,499.99884,-0.0095440065,3.5856433,11.075879,502.43066,-9.2073517
169.0,0.27668807,-0.14466858,50.939331,0,11.076097,499.99884,-0.0095954407,3.5607171,11.076229,502.69196,-9.2070904
170.3,0.26916349,-0.1456648,50.438236,0,11.076097,499.99884,-0.0096709263,3.4611518,11.075412,502.22443,-9.207099
171.6,0.27608776,-0.14604683,50.042728,0,11.076097,499.99884,-0.009720589,3.530998,11.075844,501.81546,-9.2072239
172.9,0.27447921,-0.1469598,49.606365,0,11.076097,499.99884,-0.0097217401,3.5244,11.075965,501.40936,-9.2073593
174.2,0.27125362,-0.14728308,49.22974,0,11.076097,499.99884,-0.0097629763,3.4915507,11.075521,501.0033,-9.2074223
175.5,0.27137825,-0.14780854,49.228477,0,11.076097,499.99884,-0.0098347384,3.4900546,11.076062,500.90857,-9.2072592
176.8,0.2783657,-0.14838687,48.917217,0,11.076097,499.99884,-0.0098241726,3.5723064,11.076411,500.63065,-9.2073679
178.1,0.28164256,-0.14851244,48.81226,0,11.076097,499.99884,-0.0098432768,3.6265144,11.075532,500.55069,-9.2071896
179.4,0.27939558,-0.14904752,48.483772,0,11.076097,499.99884,-0.0098866569,3.5914433,11.076598,500.55981,-9.2072744
180.7,0.2800664,-0.14974199,48.592594,0,11.076097,499.99884,-0.0099367341,3.5954072,11.075865,500.32886,-9.2076807
182.0,0.28036883,-0.14929208,48.384117,0,11.076097,499.99884,-0.0099390596,3.611382,11.076472,500.30505,-9.2073298
183.3,0.28372878,-0.14970995,48.383793,0,11.076097,499.99884,-0.009909099,3.63603,11.07623,500.36072,-9.2072744
184.6,0.27193102,-0.14985082,47.959858,0,11.076097,499.99884,-0.0099311508,3.5050797,11.075741,500.38229,-9.2071447
185.9,0.28349909,-0.14998843,47.955326,0,11.076097,499.99884,-0.0099652428,3.645829,11.076271,500.43338,-9.207303
187.2,0.27690569,-0.15091324,47.504887,0,11.076097,499.99884,-0.0099784844,3.5707922,11.076942,500.51358,-9.2069731
188.5,0.27797332,-0.15090619,47.290665,0,11.076097,499.99884,-0.010004729,3.5783148,11.076271,500.53079,-9.2072334
189.8,0.28155228,-0.15180823,47.09565,0,11.076097,499.99884,-0.010086806,3.6276402,11.07589,500.40985,-9.2072306
191.1,0.28699669,-0.15123285,47.054462,0,11.076097,499.99884,-0.010029538,3.6927633,11.076056,500.34573,-9.20718
192.4,0.28018075,-0.15170714,47.054447,0,11.076097,499.99884,-0.010086796,3.6240349,11.076373,500.36411,-9.2071028
193.7,0.27811685,-0.15186028,47.048992,0,11.076097,499.99884,-0.010045959,3.5682311,11.074801,500.26758,-9.2070398
195.0,0.28381172,-0.15202482,46.959599,0,11.076097,499.99884,-0.010086238,3.645119,11.076131,500.13638,-9.2072515
196.3,0.29196066,-0.15251735,46.595024,0,11.076097,499.99884,-0.01014192,3.7538023,11.076339,500.17343,-9.2072401
197.6,0.28503641,-0.1525642,46.583202,0,11.076097,499.99884,-0.010096313,3.6603403,11.075493,500.18423,-9.2073288
198.9,0.27639133,-0.15279038,46.444893,0,11.076097,499.99884,-0.010130778,3.5514553,11.076437,500.36917,-9.2070904
200.2,0.28577986,-0.15302989,46.110683,0,11.076097,499.99884,-0.010148738,3.6695089,11.076303,500.3006,-9.2069511
201.5,0.28315297,-0.15392298,46.414341,0,11.076097,499.99884,-0.010207775,3.6669767,11.075861,500.13226,-9.2070436
202.8,0.28558409,-0.15356119,46.341217,0,11.076097,499.99884,-0.010207511,3.6835024,11.076234,500.07816,-9.2073765
204.1,0.28269929,-0.15376306,46.109623,0,11.076097,499.99884,-0.010173654,3.6445408,11.076955,500.07944,-9.2072325
205.4,0.2793757,-0.15426503,46.109623,0,11.076097,499.99884,-0.010225501,3.5955474,11.076278,500.0918,-9.2068529
206.7,0.28889567,-0.15432303,46.109623,0,11.076097,499.99884,-0.010250778,3.725734,11.076104,500.26425,-9.2071695
208.0,0.28575152,-0.1544787,45.717999,0,11.076097,499.99884,-0.010244362,3.6729045,11.075831,500.29913,-9.2073431
209.3,0.28866294,-0.15435395,45.844158,0,11.076097,499.99884,-0.010246608,3.7275333,11.076591,500.12503,-9.2071772
210.6,0.2843723,-0.15520257,45.886787,0,11.076097,499.99884,-0.010288909,3.662843,11.076784,500.05719,-9.2072535
211.8967,0.43533269,0.0047028717,45.616333,0,11.076097,499.99884,0.00031286414,5.5405917,11.075778,500.20056,-9.2070189
211.9492,0.50378209,0.0089882072,31.080219,0,11.076099,8.222714e-14,0.00038540884,6.4117122,11.075888,500.12637,-9.2079544
211.9518,0.54553366,0.0051381392,19.196491,0,11.076099,1.538564e-31,0.00030825794,6.9353762,11.072464,500.11081,-9.2069368
211.9544,0.50619859,0.0063799177,7.3127599,0,11.076099,0.0,0.00051743706,6.5156708,11.074458,500.09528,-9.2080669
211.957,0.52049738,0.0053287386,0.0,0,11.076099,0.0,0.00061871472,6.6397181,11.07322,500.12756,-9.2078552
211.9596,0.53847229,0.0063157519,0.0,0,11.076099,0.0,0.00047739569,6.8459659,11.075743,500.23642,-9.2066927
211.9622,0.51512599,0.0097790724,0.0,0,11.076099,0.0,0.00062493986,6.6040759,11.073452,500.34528,-9.2070627
211.9648,0.53347206,0.007317523,0.0,0,11.076099,0.0,0.00042641081,6.7452416,11.074533,500.45413,-9.2067127
211.9674,0.54189157,0.010880049,0.0,0,11.076099,0.0,0.00043220411,6.7869549,11.074192,500.48654,-9.2060413
211.97,0.52734053,0.0057497644,0.0,0,11.076099,0.0,0.00028346869,6.727881,11.075952,500.45544,-9.2067909
211.9726,0.52982432,0.007209029,0.0,0,11.076099,0.0,0.00052491663,6.7163463,11.075492,500.42435,-9.2065363
211.9752,0.55040073,0.0046890355,0.0,0,11.076099,0.0,0.00057345349,6.9726887,11.074818,500.39325,-9.2064009
211.9778,0.53411609,0.0061864341,0.0,0,11.076099,0.0,0.00058479438,6.8702679,11.073758,500.35666,-9.2067242
211.9804,0.53609055,0.010205981,0.0,0,11.076099,0.0,0.00079327915,6.8767457,11.075982,500.31778,-9.2077475
211.983,0.54944754,0.0092211012,0.0,0,11.076099,0.0,0.00055553066,7.0354953,11.076916,500.2789,-9.2076283
211.9856,0.54872876,0.013519895,0.0,0,11.076099,0.0,0.00059447979,6.9823155,11.073094,500.24005,-9.2065668
211.9882,0.54549342,0.008216572,0.0,0,11.076099,0.0,0.00042385497,6.9679751,11.074464,500.22144,-9.2067471
211.9908,0.55450827,0.0088550188,0.0,0,11.076099,0.0,0.00059848896,7.045763,11.075596,500.20587,-9.2070713
211.9934,0.55473489,0.0066395313,0.0,0,11.076099,0.0,0.00055257394,7.0395894,11.075876,500.19034,-9.2081594
211.996,0.54513675,0.0065632556,0.0,0,11.076099,0.0,0.00061005715,6.912168,11.075418,500.17575,-9.2068615
211.9986,0.57107067,0.0092242882,0.0,0,10.826056,0.0,0.00072837964,7.183919,11.074473,500.19128,-9.2064495
212.0012,0.55312186,0.0077661993,0.0,0,10.435001,0.0,0.00056016084,7.0732179,11.07445,500.20685,-9.2060719
212.0038,0.56744033,0.01373513,0.0,0,10.043947,0.0,0.00068308675,7.1413679,11.000441,500.22238,-9.2061882
212.0064,0.59894395,0.0091830669,0.0,0,9.6528921,0.0,0.00048264404,7.6904612,10.758369,500.30673,-9.205452
212.009,0.57870543,0.011169881,0.0,0,9.2678127,0.0,0.00060663657,7.3124137,10.369075,500.67993,-9.205348
212.0116,0.53221458,0.0077109556,0.0,0,8.8873806,0.0,0.00051392196,6.8285146,9.8524494,501.05316,-9.2067108
212.0142,3.9518137,0.54422194,0.0,0,8.5188513,0.0,0.036405038,48.18055,9.2853775,501.42636,-9.2051878
212.0168,4.266427,0.9489491,0.0,0,8.1570358,0.0,0.065069877,51.037079,8.8229828,501.72253,-9.2036152
212.0194,4.5945773,1.3382673,0.0,0,7.8078103,0.0,0.093020916,53.221397,8.4138327,501.87805,-9.2046776
212.022,4.5347452,1.6772426,0.0,0,7.4635701,0.0,0.11811861,51.157665,8.0547934,502.03354,-9.2043943
212.0246,4.7614875,1.9955289,0.0,0,7.1326947,0.0,0.14210683,52.690853,7.7345209,502.18906,-9.2035913
212.0272,4.883523,2.299907,0.0,0,6.8053026,0.0,0.16588572,52.609409,7.4334126,501.89172,-9.2041197
212.0298,5.0775523,2.6003699,0.0,0,6.4917574,0.0,0.18989179,53.492802,7.1198654,501.16861,-9.2037878
212.0324,5.3416886,2.906956,0.0,0,6.1802773,0.0,0.21527225,54.775341,6.8059888,500.44553,-9.2009258
212.035,5.4589558,3.2243125,0.0,0,5.8832278,0.0,0.24197005,54.551064,6.4907494,499.72244,-9.2033119
212.0376,5.6769152,3.5406508,0.0,0,5.5874376,0.0,0.26906192,55.139568,6.1691017,499.10458,-9.2038355
212.0402,5.8984818,3.8626831,0.0,0,5.3054895,0.0,0.29719919,55.760727,5.8559489,498.53699,-9.2041311
212.0428,6.0678773,4.1605539,0.0,0,5.0250449,0.0,0.32421073,55.866325,5.5488496,497.96939,-9.2020588
212.0454,6.2649002,4.4560103,0.0,0,4.7569804,0.0,0.35162863,56.136776,5.2534652,497.40179,-9.2021027
212.048,6.4651566,4.7370009,0.0,0,4.4912419,0.0,0.37899143,56.335373,4.9664011,497.73389,-9.2030325
212.0506,6.6557899,5.0134935,0.0,0,4.2362337,0.0,0.40658394,56.416622,4.687499,498.23929,-9.2028341
212.0532,6.8525944,5.2816548,0.0,0,3.9844058,0.0,0.43415123,56.465363,4.420064,498.74469,-9.201993
212.0558,7.0825629,5.5424385,0.0,0,3.7418776,0.0,0.46125504,56.788631,4.1575422,499.25006,-9.2036819
212.0584,7.262526,5.8029881,0.0,0,3.5032654,0.0,0.48868281,56.678528,3.9038858,499.81766,-9.2028418
212.061,7.4532609,6.0501356,0.0,0,3.2725413,0.0,0.51581633,56.661446,3.6596091,500.38525,-9.2021084
212.0636,7.7084093,6.2945585,0.0,0,3.0464072,0.0,0.54285526,56.997025,3.4171958,500.95285,-9.2028036
212.0662,7.9104223,6.5218887,0.0,0,2.826915,0.0,0.5698095,57.001442,3.1823657,501.29559,-9.202817
212.0688,8.1317234,6.7524047,0.0,0,2.6126244,0.0,0.59773904,56.84782,2.9575379,500.47141,-9.2026386
212.0714,8.4150333,6.9784193,0.0,0,2.4038444,0.0,0.62600309,57.188034,2.7299192,499.64722,-9.2024145
212.074,8.6359129,7.2012424,0.0,0,2.2007973,0.0,0.65430295,57.14463,2.5122135,498.82306,-9.2020369
212.0766,8.8612137,7.4231057,0.0,0,2.0022092,0.0,0.68291831,56.983936,2.2929122,497.4585,-9.2012768
212.0792,9.1524734,7.6322603,0.0,0,1.8098055,0.0,0.71023983,57.246159,2.086283,494.96191,-9.2019091
212.0818,9.4149122,7.8424983,0.0,0,1.6208895,0.0,0.7386325,57.204319,1.884527,492.4653,-9.2020388
212.0844,9.6471424,8.0354719,0.0,0,1.4385666,0.0,0.76616031,57.079113,1.6865908,489.96872,-9.202117
212.087,9.9585161,8.2276449,0.0,0,1.2588546,0.0,0.79447567,57.279419,1.4956852,487.69806,-9.2010069
212.0896,10.257632,8.4092569,0.0,0,1.0861139,0.0,0.82238948,57.366997,1.3082106,485.66763,-9.2004299
212.0922,10.534019,8.5935478,0.0,0,0.91518986,0.0,0.85107285,57.229649,1.1253737,483.63724,-9.2012768
212.0948,10.859126,8.7733421,0.0,0,0.75155091,0.0,0.87958694,57.31654,0.94729561,481.60681,-9.2022142
212.0974,11.173114,8.9480219,0.0,0,0.58899897,0.0,0.90720803,57.439625,0.77888685,481.10464,-9.2005453
212.1,11.478447,9.1175089,0.0,0,0.43388361,0.0,0.93491852,57.384548,0.61141205,481.43927,-9.2003794
212.1026,9.6260738,9.1712255,0.0,0,0.27942321,0.0,0.94449538,47.767479,0.49781743,481.7739,-9.2029381
212.1052,8.4610472,9.1862326,0.0,0,0.13225797,0.0,0.94697964,41.806152,0.44549838,482.10852,-9.2039642
212.1078,7.8765264,9.1875792,0.0,0,-0.014481357,0.0,0.94809824,38.895084,0.40663892,483.22879,-9.2037392
212.1104,7.5813622,9.1928358,0.0,0,-0.15795054,0.0,0.94970572,37.342854,0.37393293,484.53607,-9.2035074
212.113,7.5206451,9.1945696,0.0,0,-0.30141854,0.0,0.95049846,36.958717,0.33067876,485.84338,-9.2036266
212.1156,7.8011918,9.2056932,0.0,0,-0.44488654,0.0,0.95158893,38.323467,0.26863709,487.15067,-9.2044067
212.1182,7.9382324,9.2186489,0.0,0,-0.58835453,0.0,0.95275134,38.989494,0.1910768,487.99768,-9.2044373
212.1208,7.9004545,9.2223434,0.0,0,-0.73182249,0.0,0.95330751,38.780582,0.12169975,488.83014,-9.2047186
212.1234,7.7549896,9.2303476,0.0,0,-0.87529051,0.0,0.95441765,38.023563,0.065609865,489.66257,-9.2037477
212.126,7.5034804,9.227931,1.0519469,0,-1.0187585,0.0,0.95486104,36.779716,0.026617303,490.4278,-9.2043705
212.1286,7.1273851,9.2282476,9.0946436,0,-0.91973537,499.99997,0.95554858,34.947853,0.013958809,490.74658,-9.2053671
212.1312,6.7201443,9.2274551,17.137341,0,-0.42304215,500.0,0.95607156,32.938618,0.015392231,491.06537,-9.2049322
212.1338,6.3496566,9.229022,25.180037,0,0.073651433,500.0,0.95584428,31.117355,0.017760625,491.38416,-9.2038574
212.1364,6.0847154,9.2359095,30.871582,0,0.57034528,500.0,0.95637447,29.812,0.022294216,491.63474,-9.2066345
212.139,5.9059157,9.2329693,30.871582,0,1.0670385,500.0,0.95531148,28.964018,0.022214359,491.72028,-9.2074471
212.1416,5.5155573,9.2313757,30.871582,0,1.5637323,500.0,0.95440525,27.040047,0.033016793,491.80579,-9.2054787
212.1442,4.3794618,9.2242346,30.871582,0,2.0604262,500.0,0.95386159,21.597691,0.1047695,491.89133,-9.2052956
212.1468,2.2410738,9.2105064,30.744274,0,2.5571194,500.0,0.95228547,11.229555,0.26724577,491.96271,-9.2070093
212.1494,-0.16669846,9.1742811,30.463781,0,3.0538132,500.0,0.94708699,-0.63281989,0.53267294,492.01715,-9.2111111
212.152,0.23637895,9.175642,30.183289,0,3.5505066,500.0,0.94691747,0.92019182,1.1155679,492.07159,-9.2114077
212.1546,0.064352579,9.1733065,29.902798,0,4.0472002,500.0,0.94602162,0.42376074,1.9791228,492.12601,-9.2097836
212.1572,0.051550485,9.1733313,29.794922,0,4.5438938,500.0,0.94521248,0.24578243,2.810575,492.16129,-9.2098379
212.1598,-0.19171819,9.184638,29.794922,0,5.0405879,500.0,0.94634432,-0.9238888,3.4360378,492.18463,-9.2083836
212.1624,-0.0018573231,9.1642599,29.794922,0,5.537281,500.0,0.94320011,-0.0025525864,3.9198289,492.20795,-9.2095938
212.165,-0.077553794,9.1690254,29.794922,0,6.0339746,500.0,0.94476187,-0.39153272,4.3706303,492.23129,-9.2082548
212.1676,-0.031463213,9.1653872,29.794922,0,6.5306687,500.0,0.94497102,-0.12164942,4.8213863,492.24252,-9.2083216
212.1702,-0.074000321,9.1638327,29.794922,0,7.0273619,500.0,0.94500792,-0.30819374,5.2857165,492.25031,-9.2079344
212.1728,-0.10292337,9.1695271,29.794922,0,7.524056,500.0,0.94584191,-0.58651257,5.7899427,492.25809,-9.2082071
212.1754,-0.077107124,9.1694279,29.794922,0,8.0207491,500.0,0.9447208,-0.38767359,6.3205395,492.26584,-9.207757
212.178,-0.096701354,9.1725731,29.794922,0,8.5174427,500.0,0.94443947,-0.48135513,6.8354139,492.28821,-9.2073812
212.1806,-0.0088191247,9.1676226,29.794922,0,9.0141363,500.0,0.94374734,-0.031805966,7.3720498,492.31155,-9.2068825
212.1832,-0.19853897,9.1688194,29.794922,0,9.5108299,500.0,0.94428962,-0.95037144,7.8840151,492.33487,-9.2076778
212.1858,-0.00046258108,9.162509,29.794922,0,10.007524,500.0,0.94411784,0.041785121,8.4019203,492.35587,-9.2076588
212.1884,-0.14946207,9.1635733,29.794922,0,10.504217,500.0,0.94487858,-0.79572767,8.9058342,492.35587,-9.2067232
212.191,0.018027961,9.1648512,29.794922,0,11.000911,500.0,0.94500905,0.031253844,9.4228525,492.35587,-9.2067509
212.1936,-0.20177214,9.1690092,29.794922,0,11.497604,500.0,0.94511181,-0.91805112,9.9223747,492.35587,-9.2073345
212.1962,-0.0070719183,9.172554,29.794922,0,11.994298,500.0,0.94471192,-0.078600034,10.438961,492.36807,-9.206089
212.1988,-0.21583934,9.1724586,29.794922,0,12.490992,500.0,0.94454706,-1.0347745,10.944852,492.41473,-9.2069826
212.2014,-0.087985337,9.1649523,29.794922,0,12.987685,500.0,0.94334114,-0.51032126,11.45337,492.46136,-9.206665
212.204,-0.09718816,9.1625614,29.794922,0,13.484379,500.0,0.9436875,-0.39258537,11.95696,492.50803,-9.2057133
212.2066,-0.11496329,9.1636,29.794922,0,13.981072,500.0,0.94463283,-0.61384976,12.448622,492.55469,-9.2067766
212.2092,-0.033940505,9.1628428,29.794922,0,14.477766,500.0,0.94487339,-0.16002013,12.954045,492.60132,-9.2055712
212.2118,-0.16214405,9.1678715,29.794922,0,14.97446,500.0,0.94507688,-0.80210507,13.45763,492.64798,-9.2053881
212.2144,-0.045041341,9.1715517,29.794922,0,15.471153,500.0,0.94488788,-0.30186787,13.97527,492.69461,-9.2065897
212.217,-0.13248879,9.1653481,29.794922,0,15.967847,500.0,0.94352579,-0.57703906,14.49094,492.71854,-9.2052145
212.2196,-0.054750565,9.1681538,29.794922,0,16.46454,500.0,0.94368434,-0.30337048,14.998803,492.72632,-9.2053566
212.2222,-0.22037059,9.1601896,29.794922,0,16.961235,500.0,0.94283557,-1.1086749,15.490271,492.7341,-9.206377
212.2248,-0.066824324,9.1616011,29.794922,0,17.457928,500.0,0.94412029,-0.28170654,15.989645,492.74185,-9.2053738
212.2274,-0.14554317,9.1633158,29.794922,0,17.95462,500.0,0.94493806,-0.68464446,16.479488,492.73224,-9.2044563
212.23,-0.16148086,9.1640453,29.794922,0,18.0,500.0,0.94485462,-0.80931824,16.979084,492.71667,-9.2045059
212.2326,-0.13215153,9.1696892,29.794922,0,18.0,500.0,0.9451037,-0.62298155,17.450596,492.70114,-9.2036848
212.2352,-0.089808531,9.169116,29.794922,0,18.0,500.0,0.94427752,-0.47836003,17.866156,492.68558,-9.2046585
212.2378,0.0011381742,9.1714764,29.794922,0,18.0,500.0,0.94416714,0.023099462,18.20859,492.67004,-9.207056
212.2404,0.10000864,9.1650047,29.794922,0,18.0,500.0,0.94360697,0.48836949,18.440376,492.65448,-9.2117214
212.243,0.34793678,9.1712618,29.794922,0,18.0,500.0,0.94536471,1.7736408,18.534161,492.63895,-9.2179489
212.2456,0.56424439,9.1818666,29.794922,0,18.0,500.0,0.94803101,2.6683264,18.47267,492.6218,-9.2267256
212.2482,0.85961443,9.1934137,29.794922,0,18.0,500.0,0.95010382,4.2494125,18.325634,492.58292,-9.2381363
212.2508,0.853508,9.2045431,29.794922,0,18.0,500.0,0.95145059,4.1810031,18.181276,492.54404,-9.255599
212.2534,0.79456329,9.2153254,29.794922,0,18.0,500.0,0.95246053,3.8517859,18.070581,492.50516,-9.2758017
212.256,0.73071903,9.2180634,29.794922,0,18.0,500.0,0.95219648,3.5640922,18.029821,492.44833,-9.299078
212.2586,0.81709361,9.2101593,29.794922,0,18.0,500.0,0.95099765,3.9993978,18.024967,492.3317,-9.3217487
212.2612,0.68998682,9.2064009,29.794922,0,18.0,500.0,0.9509837,3.4120882,18.058193,492.21509,-9.3456135
212.2638,0.75650507,9.2042999,29.794922,0,18.0,500.0,0.95149159,3.7005272,18.088364,492.09845,-9.3685627
212.2664,0.78874111,9.2021923,30.00828,0,18.0,500.0,0.95153505,3.8858135,18.115904,491.98184,-9.3878965
212.269,0.7918542,9.2077217,30.552092,0,18.0,500.0,0.95227218,3.8854725,18.140015,491.8652,-9.4059486
212.2716,0.79149276,9.2118654,31.095905,0,18.0,500.0,0.95235538,3.9314303,18.15078,491.74857,-9.42659
212.2742,0.82987344,9.2138014,31.639717,0,18.0,500.0,0.95167357,4.0395584,18.153936,491.63193,-9.4470921
212.2768,0.7937116,9.208024,31.882326,0,18.0,500.0,0.95069861,3.9017894,18.157898,491.5239,-9.4660425
212.2794,0.78716964,9.2090845,31.882326,0,18.0,500.0,0.95110655,3.8624589,18.150154,491.42282,-9.4857416
212.282,0.81621432,9.1968498,31.882326,0,18.0,500.0,0.94979382,4.0271301,18.146439,491.32175,-9.502677
212.2846,0.81721091,9.2027521,31.882326,0,18.0,500.0,0.95145899,4.0237708,18.143188,491.22067,-9.5227861
212.2872,0.78702641,9.208025,32.23452,0,18.0,500.0,0.9525649,3.8466289,18.138969,491.12515,-9.5439501
212.2898,0.83614123,9.2058973,32.72681,0,18.0,500.0,0.95155799,4.1087818,18.134706,491.03186,-9.5631943
212.2924,0.82464701,9.2161179,33.219105,0,18.0,500.0,0.95230275,4.0718031,18.130308,490.93854,-9.5814075
212.295,0.791991,9.2128897,33.711395,0,18.0,500.0,0.951648,3.8870168,18.130894,490.84525,-9.60186
212.2976,0.83958292,9.2098703,33.771973,0,18.0,500.0,0.95105618,4.1184464,18.125183,490.74515,-9.6216021
212.3002,0.85208452,9.202239,33.771973,0,18.0,500.0,0.95050734,4.1663551,18.117865,490.64407,-9.6400204
212.3028,0.83347398,9.2059059,33.771973,0,18.0,500.0,0.95166415,4.1426387,18.115828,490.543,-9.6602535
212.3054,0.83393639,9.2073269,33.780857,0,18.0,500.0,0.95255899,4.0507908,18.114552,490.44278,-9.6795855
212.308,0.8420794,9.2084513,34.011677,0,18.0,500.0,0.95226073,4.1619067,18.114937,490.36441,-9.7008333
212.3106,0.87219471,9.2169085,34.2425,0,18.0,500.0,0.95285159,4.2114186,18.114603,490.28601,-9.7210951
212.3132,0.80876809,9.212677,34.473324,0,18.0,500.0,0.95172167,3.96067,18.112123,490.20764,-9.7399158
212.3158,0.86918151,9.2116137,34.650879,0,18.0,500.0,0.95104545,4.2313662,18.111975,490.133,-9.7585831
212.3184,0.81902504,9.2055616,34.650879,0,18.0,500.0,0.95067036,4.0287986,18.11112,490.07077,-9.7786922
212.321,0.78237361,9.2003908,34.650879,0,18.0,500.0,0.95063329,3.8326609,18.112068,490.00858,-9.7991428
212.3236,0.86579627,9.2040501,34.650879,0,18.0,500.0,0.95205319,4.274508,18.111557,489.94638,-9.8179922
212.3262,0.83441365,9.2067041,34.820435,0,18.0,500.0,0.95226038,4.0732722,18.107996,489.875,-9.8383265
212.3288,0.82449734,9.2124548,35.252621,0,18.0,500.0,0.95254678,4.012486,18.108156,489.78949,-9.8591661
212.3314,0.88699126,9.2127237,35.684811,0,18.0,500.0,0.95200539,4.3817325,18.104891,489.70395,-9.8795338
212.334,0.83149529,9.2171783,36.117001,0,18.0,500.0,0.95189315,4.0830045,18.106831,489.61841,-9.8991661
212.3366,0.8419987,9.209568,36.309814,0,18.0,500.0,0.95117623,4.1253958,18.101517,489.52426,-9.918149
212.3392,0.8664313,9.2053118,36.309814,0,18.0,500.0,0.95112681,4.2891903,18.099697,489.42316,-9.936512
212.3418,0.85190403,9.1992064,36.309814,0,18.0,500.0,0.95077723,4.1995878,18.103601,489.32202,-9.9566507
212.3444,0.83914036,9.2078295,36.309814,0,18.0,500.0,0.95258963,4.1072078,18.098225,489.22092,-9.9771929
212.347,0.88139981,9.210783,36.455193,0,18.0,500.0,0.95280212,4.3134995,18.096579,489.14206,-9.9960785
212.3496,0.87375349,9.2130203,36.658409,0,18.0,500.0,0.95229453,4.3153253,18.101559,489.07205,-10.016746
212.3522,0.83900964,9.2206354,36.861622,0,18.0,500.0,0.95282912,4.0961442,18.096861,489.00201,-10.036462
212.3548,0.88432944,9.2118416,37.064835,0,18.0,500.0,0.95139605,4.3397636,18.095455,488.93201,-10.054581
212.3574,0.88318801,9.2124395,37.089844,0,18.0,500.0,0.95194286,4.3883977,18.094614,488.862,-10.073994
212.36,0.89063072,9.2085876,37.089844,0,18.0,500.0,0.95217657,4.3958755,18.093735,488.79196,-10.095048
212.3626,0.92294395,9.2029953,37.089844,0,18.0,500.0,0.95150322,4.5228915,18.093868,488.72192,-10.113208
212.3652,0.90267926,9.2108173,37.104492,0,18.0,500.0,0.9528802,4.4638076,18.094418,488.65012,-10.134576
212.3678,0.87280709,9.2118168,37.485157,0,18.0,500.0,0.95247376,4.255178,18.093801,488.53339,-10.155764
212.3704,0.98513228,9.2168694,37.865829,0,18.0,500.0,0.95225555,4.8245034,18.087893,488.41666,-10.175651
212.373,0.88580108,9.2159319,38.246494,0,18.0,500.0,0.9520151,4.3595958,18.087671,488.29993,-10.192818
212.3756,0.86622524,9.2159901,38.551025,0,18.0,500.0,0.95220602,4.2734723,18.092306,488.18475,-10.214439
212.3782,0.90322077,9.2085552,38.551025,0,18.0,500.0,0.95170397,4.3973093,18.087444,488.07581,-10.233967
212.3808,0.85582834,9.2004442,38.551025,0,18.0,500.0,0.95110995,4.187428,18.08741,487.96686,-10.253382
212.3834,0.90658915,9.2113771,38.551025,0,18.0,500.0,0.95320493,4.4159579,18.087252,487.85791,-10.273785
212.386,0.89126897,9.2113552,38.680378,0,18.0,500.0,0.95251191,4.4062672,18.087452,487.75742,-10.294815
212.3886,0.91639441,9.2155228,39.038151,0,18.0,500.0,0.95243448,4.4986939,18.081665,487.67181,-10.314153
212.3912,0.90943152,9.2167053,39.39592,0,18.0,500.0,0.95225579,4.5064392,18.081924,487.58621,-10.331891
212.3938,0.88835561,9.2175674,39.753693,0,18.0,500.0,0.95229495,4.3565135,18.083374,487.50061,-10.350845
212.3964,0.93514222,9.2090654,39.924316,0,18.0,500.0,0.95141858,4.6048431,18.084455,487.4028,-10.37035
212.399,0.89332587,9.2105293,39.924316,0,18.0,500.0,0.95247394,4.4118409,18.079153,487.29385,-10.389804
212.4016,0.90060955,9.200346,39.924316,0,18.0,500.0,0.95120734,4.4003673,18.085358,487.18491,-10.411112
212.4042,0.94163233,9.2083473,39.924316,0,18.0,500.0,0.95236224,4.6321573,18.078827,487.07599,-10.428342
212.4068,0.9264037,9.2185698,40.039928,0,18.0,500.0,0.95337689,4.5501528,18.078503,486.97769,-10.449896
212.4094,0.90939438,9.2151728,40.208797,0,18.0,500.0,0.95234007,4.4308228,18.082371,486.88431,-10.472062
212.412,0.90348911,9.2205687,40.377663,0,18.0,500.0,0.95249611,4.485148,18.078405,486.79092,-10.489493
212.4146,0.93256718,9.2148476,40.546532,0,18.0,500.0,0.95206195,4.5606647,18.076241,486.69754,-10.508902
212.4172,0.91056526,9.211297,40.57251,0,18.0,500.0,0.95237875,4.4469981,18.076122,486.59756,-10.530343
212.4198,0.94888306,9.2065353,40.57251,0,18.0,500.0,0.95228213,4.7163105,18.076675,486.4964,-10.549911
212.4224,0.96084273,9.2088509,40.57251,0,18.0,500.0,0.9525196,4.7482615,18.075676,486.39523,-10.570058
212.425,0.9226414,9.2149057,40.574978,0,18.0,500.0,0.95330739,4.5020347,18.076506,486.29419,-10.588921
212.4276,0.95721287,9.2130423,40.895542,0,18.0,500.0,0.95213228,4.7014718,18.072224,486.20862,-10.607183
212.4302,1.0488989,9.2211924,41.216103,0,18.0,500.0,0.95252085,5.142139,18.073812,486.12302,-10.627345
212.4328,0.90989989,9.2187777,41.536671,0,18.0,500.0,0.95265883,4.4542189,18.070385,486.03741,-10.647879
212.4354,0.95373374,9.212409,41.802979,0,18.0,500.0,0.95222694,4.7079124,18.071682,485.9505,-10.666579
212.438,0.97043788,9.2112761,41.802979,0,18.0,500.0,0.95278537,4.7762203,18.068907,485.85712,-10.685844
212.4406,0.86930162,9.2045574,41.802979,0,18.0,500.0,0.95195538,4.2842264,18.06822,485.76373,-10.706965
212.4432,0.97791219,9.2127981,41.802979,0,18.0,500.0,0.95310259,4.7528629,18.07053,485.67035,-10.725755
212.4458,0.96706933,9.2145567,41.904282,0,18.0,500.0,0.95257682,4.7799158,18.068792,485.57697,-10.744557
212.4484,0.94091523,9.2211599,42.210533,0,18.0,500.0,0.95290041,4.606173,18.068106,485.48358,-10.764856
212.451,0.98752892,9.2148113,42.516785,0,18.0,500.0,0.95206052,4.8220325,18.063787,485.39023,-10.784421
212.4536,0.9659276,9.2191305,42.823036,0,18.0,500.0,0.95281404,4.7430539,18.066402,485.29684,-10.805012
212.4562,0.95577592,9.2126741,42.978516,0,18.0,500.0,0.95250231,4.7020025,18.063705,485.20346,-10.823802
212.4588,0.96359825,9.2099791,42.978516,0,18.0,500.0,0.95289713,4.6938334,18.06547,485.11008,-10.843809
212.4614,0.97530919,9.2061272,42.978516,0,18.0,500.0,0.95213056,4.7983146,18.066832,485.01669,-10.862259
212.464,0.96730477,9.2155495,42.978516,0,18.0,500.0,0.95316958,4.7765384,18.060709,484.92331,-10.883788
212.4666,0.95948422,9.2189922,43.07209,0,18.0,500.0,0.9528507,4.7158718,18.061144,484.82993,-10.903927
212.4692,0.9946869,9.2155972,43.215199,0,18.0,500.0,0.9520458,4.86128,18.062901,484.73654,-10.923314
212.4718,0.94339615,9.2224913,43.358303,0,18.0,500.0,0.95314556,4.6231799,18.060776,484.64316,-10.944656
212.4744,0.96206427,9.2138882,43.501415,0,18.0,500.0,0.95243931,4.7268109,18.060698,484.54977,-10.963903
212.477,1.0001358,9.2098408,43.527832,0,18.0,500.0,0.95253301,4.8725572,18.062901,484.46274,-10.982557
212.4796,0.95155609,9.2101364,43.527832,0,18.0,500.0,0.95298839,4.7645273,18.059649,484.37714,-11.002195
212.4822,0.99446601,9.2117672,43.527832,0,18.0,500.0,0.95292288,4.8794756,18.060671,484.29153,-11.021847
212.4848,1.0038972,9.2170839,43.527832,0,18.0,500.0,0.95295274,4.9019475,18.059513,484.20596,-11.041425
212.4874,0.99350733,9.217597,43.801857,0,18.0,500.0,0.95259291,4.8851347,18.059629,484.13556,-11.062424
212.49,1.0734528,9.2220373,44.082348,0,18.0,500.0,0.95303172,5.313149,18.060398,484.06552,-11.080706
212.4926,0.96612352,9.2164316,44.362843,0,18.0,500.0,0.95265651,4.7053123,18.058184,483.99548,-11.099734
212.4952,1.000433,9.2136116,44.604492,0,18.0,500.0,0.95294356,4.9307656,18.056133,483.92114,-11.120688
212.4978,0.9823041,9.2121611,44.604492,0,18.0,500.0,0.95333284,4.842752,18.059004,483.81998,-11.1406
212.5004,0.94961244,9.2068443,44.604492,0,18.0,500.0,0.95232278,4.6905789,18.059059,483.71881,-11.159801
212.503,1.0345638,9.2232523,44.604492,0,18.0,500.0,0.95441234,5.0652237,18.055918,483.61765,-11.180519
212.5056,0.99089175,9.2201462,44.683491,0,18.0,500.0,0.95319396,4.8674774,18.056759,483.50714,-11.200694
212.5082,1.0136958,9.2215147,44.946812,0,18.0,500.0,0.95262271,4.9738908,18.054749,483.37488,-11.218687
212.5108,1.0391994,9.2171297,45.210133,0,18.0,500.0,0.95232201,5.1533442,18.05773,483.24258,-11.2394
212.5134,0.97917718,9.2199316,45.47345,0,18.0,500.0,0.95353597,4.7668266,18.053123,483.11029,-11.260814
212.516,0.99885511,9.2127171,45.615234,0,18.0,500.0,0.95334172,4.9369745,18.053524,482.99597,-11.278398
212.5186,1.0283213,9.2139921,45.615234,0,18.0,500.0,0.95357364,5.0516834,18.051693,482.90259,-11.297232
212.5212,0.9959392,9.2131472,45.615234,0,18.0,500.0,0.95307279,4.899837,18.049416,482.8092,-11.32021
212.5238,1.0243028,9.217721,45.615234,0,18.0,500.0,0.95315427,5.0275035,18.050858,482.71582,-11.338922
212.5264,1.0253886,9.2229433,38.210598,0,18.0,500.0,0.95310247,5.0453582,18.050598,482.61276,-11.35652
213.2275,0.99182063,9.22365,0.0,0,18.0,1.442716e-07,0.95432365,4.8642693,18.003817,463.70111,-11.481314
214.5275,0.93844354,9.2285061,0.0,0,18.0,2.6994773e-25,0.95510203,4.5978575,17.999174,433.73245,-11.48092
215.8275,0.87891203,9.2295609,0.0,0,18.0,5.0446745e-43,0.95526677,4.3049374,18.000475,409.43765,-11.481606
217.1275,0.86651653,9.2345648,0.0,0,18.0,1.4012985e-45,0.95611632,4.2402458,17.999701,389.38455,-11.481562
218.4275,0.87694585,9.2398024,0.0,0,18.0,1.4012985e-45,0.95713955,4.2857423,17.999861,371.69193,-11.48214
219.7275,0.87897539,9.2455311,0.0,0,18.0,1.4012985e-45,0.95807713,4.2935209,17.999943,355.86084,-11.481355
221.0275,0.88707304,9.2512283,0.0,0,18.0,1.4012985e-45,0.95897216,4.3286629,18.00062,341.12436,-11.481685
222.3275,0.88964844,9.2558136,0.0,0,18.0,1.4012985e-45,0.95993048,4.3347716,17.99921,327.8248,-11.481474
223.6275,0.89217722,9.2600088,0.0,0,18.0,1.4012985e-45,0.96064097,4.3447814,18.000303,315.52997,-11.481079
224.9275,0.89905208,9.2652884,0.0,0,18.0,1.4012985e-45,0.96150017,4.3732605,18.000656,304.02277,-11.481457
226.2275,0.90693259,9.269578,0.0,0,18.0,1.4012985e-45,0.96223241,4.4071426,18.000116,293.3353,-11.481459
227.5275,0.90691483,9.2736845,0.0,0,18.0,1.4012985e-45,0.96291274,4.4074917,18.000216,283.04755,-11.481611
228.8275,0.91309744,9.2775793,0.0,0,18.0,1.4012985e-45,0.96375006,4.4340448,18.000109,273.90167,-11.481251
230.1275,0.91966248,9.2818956,0.0,0,18.0,1.4012985e-45,0.96445751,4.4608412,18.000578,265.09085,-11.48138
231.4275,0.92334044,9.2857046,0.0,0,18.0,1.4012985e-45,0.96499735,4.4776821,17.999722,256.44318,-11.481191
232.7275,0.92025369,9.2894049,0.0,0,18.0,1.4012985e-45,0.96574658,4.4566631,17.999786,248.45633,-11.481134
234.0275,0.92282021,9.2929697,0.0,0,18.0,1.4012985e-45,0.96635771,4.4702592,18.000969,241.0634,-11.481495
235.3275,0.92911369,9.2970037,0.0,0,18.0,1.4012985e-45,0.96708447,4.498446,18.000124,233.98109,-11.481857
236.6275,0.92535257,9.2996178,0.0,0,18.0,1.4012985e-45,0.96750033,4.4791875,17.999598,227.12294,-11.481234
237.9275,0.93218803,9.303731,0.0,0,18.0,1.4012985e-45,0.96815187,4.5032864,18.000046,220.60861,-11.481627
239.2275,0.93491834,9.3061094,0.0,0,18.0,1.4012985e-45,0.96872288,4.512691,17.998156,214.42863,-11.481934
240.5275,0.93493831,9.3094873,0.0,0,18.0,1.4012985e-45,0.96931636,4.5137405,17.999432,208.40193,-11.481585
241.8275,0.93270707,9.3127689,0.0,0,18.0,1.4012985e-45,0.9697901,4.5063596,17.999926,202.57564,-11.481288
243.1275,0.94345504,9.3160782,0.0,0,18.0,1.4012985e-45,0.97037464,4.5483398,17.998896,197.02316,-11.481481
244.4275,0.94875574,9.3188238,0.0,0,18.0,1.4012985e-45,0.97083497,4.5741167,18.000366,191.7561,-11.4815
245.7275,0.9382596,9.3215265,0.0,0,18.0,1.4012985e-45,0.97145575,4.5221305,17.999464,186.71927,-11.481342
247.0275,0.94386774,9.3241377,0.0,0,18.0,1.4012985e-45,0.9718315,4.5466466,18.00091,181.91862,-11.481791
248.3275,0.94385117,9.3269091,0.0,0,18.0,1.4012985e-45,0.97221243,4.5462141,18.000248,177.16313,-11.4816
249.6275,0.94461238,9.3294582,0.0,0,18.0,1.4012985e-45,0.97280002,4.5509553,18.001028,172.66765,-11.481535
250.9275,0.94136024,9.3318777,0.0,0,18.0,1.4012985e-45,0.97322339,4.5290213,17.999762,168.24245,-11.481531
252.2275,0.9484719,9.3347645,0.0,0,18.0,1.4012985e-45,0.97372651,4.5576563,17.99979,164.19125,-11.481881
253.5275,0.9474346,9.3362961,0.0,0,18.0,1.4012985e-45,0.97395122,4.5560813,17.999956,160.08916,-11.481938
254.8275,0.95364708,9.3393326,0.0,0,18.0,1.4012985e-45,0.97441107,4.5814958,17.99962,156.0825,-11.481833
256.1275,0.94624597,9.3412466,0.0,0,18.0,1.4012985e-45,0.97491205,4.5412245,17.999207,152.33388,-11.481716
257.4275,0.95112228,9.3437557,0.0,0,18.0,1.4012985e-45,0.97534829,4.5646515,17.999739,148.73929,-11.481665
258.7275,0.95203549,9.3457346,0.0,0,18.0,1.4012985e-45,0.97560155,4.5733495,17.999014,145.16829,-11.481621
260.0275,0.9494037,9.3479977,0.0,0,18.0,1.4012985e-45,0.97599864,4.5553737,17.998789,141.63652,-11.481817
261.3275,0.95533061,9.3503284,0.0,0,18.0,1.4012985e-45,0.97636873,4.5812993,18.000038,138.20358,-11.481844
262.6275,0.95395553,9.3516865,0.0,0,18.0,1.4012985e-45,0.97677928,4.5753388,18.000761,134.8569,-11.481628
263.9275,0.9574362,9.3539982,0.0,0,18.0,1.4012985e-45,0.97714585,4.5898547,17.999718,131.67101,-11.481925
265.2275,0.95568013,9.3558331,0.0,0,18.0,1.4012985e-45,0.97736973,4.5815849,17.99964,128.62823,-11.4818
266.5275,0.95715505,9.3572836,0.0,0,18.0,1.4012985e-45,0.97765285,4.5773587,18.000542,125.58892,-11.481885
267.8275,0.9614296,9.3594627,0.0,0,18.0,1.4012985e-45,0.97799325,4.6030598,17.999798,122.65711,-11.481791
269.1275,0.95990038,9.3612509,0.0,0,18.0,1.4012985e-45,0.97847414,4.5902996,18.000698,119.81894,-11.48187
270.4275,0.96266294,9.3630438,0.0,0,18.0,1.4012985e-45,0.97877353,4.6060853,17.999783,117.17365,-11.481649
271.7275,0.96470988,9.365202,0.0,0,18.0,1.4012985e-45,0.97904122,4.6136355,18.000605,114.37975,-11.481677
272.5275,0.96358651,9.3658876,0.0,0,18.0,1.4012985e-45,0.97913307,4.6044064,18.000242,112.69659,-11.481877