File: raw data/testID_0249.csv
Time(sec),Force(kN),Jaw(mm),PowAngle(deg),Power(W),Pram,PTemp,Strain,Stress(MPa),Stroke(mm),TC1(C),wedge(mm)
0.0,1.5047984,-0.34569669,0.0,0,10.594783,0.0015172546,-0.022790456,19.597183,10.594868,12.838732,-9.1199837
2.2,1.4149741,0.001759004,0.0,0,10.594783,6.5159025,0.00013853575,18.010012,10.595177,12.815166,-9.4856796
4.4,1.3697525,0.002040941,0.0,0,10.594783,13.115906,0.00014633256,17.424795,10.594243,12.841078,-9.4825659
6.6,1.3459116,0.0013431148,31.318661,0,10.594783,19.715906,9.3884024e-05,17.133369,10.595057,14.124554,-9.4788227
8.8,1.3506616,-0.0015493082,37.83691,0,10.594783,26.315907,-0.00011405442,17.184877,10.594945,21.66152,-9.4748001
11.0,1.3454506,-0.0045941165,39.243114,0,10.594783,32.915901,-0.00032802275,17.150352,10.594591,30.433645,-9.4715014
13.2,1.3223256,-0.0069919722,39.924072,0,10.594783,39.515907,-0.00046409009,16.868587,10.595573,38.25351,-9.4675779
15.4,1.3082012,-0.0088239247,40.089241,0,10.594783,46.11591,-0.0005677361,16.672161,10.594369,45.300114,-9.4637432
17.6,1.3095255,-0.010031757,40.572506,0,10.594783,52.715923,-0.00066840026,16.681498,10.594119,52.136787,-9.4599876
19.8,1.2970634,-0.011672377,41.198727,0,10.594783,59.315926,-0.00076717063,16.535847,10.594396,58.764862,-9.4566755
22.0,1.2923366,-0.013114032,41.80283,0,10.594783,65.915916,-0.00088996388,16.470018,10.594894,65.461166,-9.4532938
24.2,1.2847111,-0.014380389,42.001385,0,10.594783,72.515915,-0.00098682707,16.362915,10.594826,72.040237,-9.449399
26.4,1.2856762,-0.015767323,42.396236,0,10.594783,79.115921,-0.0010427115,16.383127,10.593859,78.806557,-9.4453335
28.6,1.2689867,-0.01723236,42.467495,0,10.594783,85.715927,-0.001123919,16.176901,10.593968,85.401466,-9.441329
30.8,1.2688245,-0.018416155,42.703476,0,10.594783,92.315933,-0.0012269628,16.174685,10.59549,92.176254,-9.4374113
33.0,1.2621962,-0.019823547,43.020321,0,10.594783,98.915939,-0.0013109527,16.083296,10.595229,98.587502,-9.433424
35.2,1.2561127,-0.021668391,43.527794,0,10.594783,105.51591,-0.0014619392,16.007385,10.59489,105.23318,-9.4298811
37.4,1.2551509,-0.023114178,43.527378,0,10.594783,112.11592,-0.0015504693,16.007032,10.595476,112.00619,-9.4264507
39.6,1.2494107,-0.024755513,43.527828,0,10.594783,118.71592,-0.0016390539,15.943058,10.595,118.56551,-9.4228258
41.8,1.2435437,-0.026917685,43.859352,0,10.594783,125.31593,-0.0017677376,15.854784,10.594926,125.08582,-9.4190187
44.0,1.24436,-0.02859045,44.077145,0,10.594783,131.91594,-0.0019054612,15.873972,10.595417,131.83157,-9.4154339
46.2,1.2511585,-0.030491296,43.615986,0,10.594783,138.51596,-0.0020273379,15.960582,10.594888,138.56358,-9.4117775
48.4,1.241868,-0.031927992,44.077145,0,10.594783,145.11594,-0.0021476909,15.853997,10.594702,144.88892,-9.4075937
50.6,1.2390579,-0.034681264,44.499531,0,10.594783,151.71594,-0.0023219378,15.819463,10.594682,151.55513,-9.4037628
52.8,1.228889,-0.03723276,44.495258,0,10.594783,158.31593,-0.002462815,15.694927,10.594894,158.2619,-9.4000092
55.0,1.2428218,-0.039851494,44.569332,0,10.594783,164.91592,-0.0026406725,15.874672,10.594382,164.84894,-9.3959837
57.2,1.2350419,-0.041877765,44.604488,0,10.594783,171.51593,-0.0027881542,15.767335,10.595466,171.45526,-9.3920231
59.4,1.2285225,-0.044284765,44.604488,0,10.594783,178.11595,-0.0029430576,15.695875,10.594783,178.09019,-9.3886414
61.6,1.2253718,-0.046994533,44.906311,0,10.594783,184.71596,-0.0031428211,15.653829,10.593575,184.50609,-9.3846779
63.8,1.22684,-0.049893826,45.005116,0,10.594783,191.31596,-0.0033393649,15.668603,10.595095,191.1825,-9.3809099
66.0,1.2384864,-0.053911958,44.968475,0,10.594783,197.91595,-0.003573691,15.820396,10.594144,197.86102,-9.3777027
68.2,1.2341698,-0.055884324,45.118931,0,10.594783,204.51596,-0.003705882,15.778622,10.59426,204.43051,-9.3739424
70.4,1.2245473,-0.058919519,45.12085,0,10.594783,211.11597,-0.0039212331,15.659604,10.594346,210.94737,-9.3703413
72.6,1.2189627,-0.062663846,45.12085,0,10.594783,217.71596,-0.0041675032,15.594775,10.595379,217.67921,-9.3669949
74.8,1.2328581,-0.066530086,45.20211,0,10.594783,224.31595,-0.0044413293,15.77778,10.594485,224.18562,-9.3633127
77.0,1.2425903,-0.069300853,45.120853,0,10.594783,230.91595,-0.0046223323,15.890056,10.594399,231.00038,-9.3594112
79.2,1.228761,-0.073562346,44.827702,0,10.594783,237.51596,-0.0048745074,15.731561,10.594626,237.67026,-9.3558826
81.4,1.2291111,-0.077452473,44.914455,0,10.594783,244.11598,-0.0051312144,15.747609,10.594588,244.16655,-9.3522282
83.6,1.2456717,-0.08138027,44.749565,0,10.594783,250.71599,-0.0054113232,15.935434,10.595188,250.743,-9.3486481
85.8,1.2637219,-0.085238919,44.693054,0,10.594783,257.31625,-0.0056627612,16.176161,10.594728,257.3761,-9.3448181
88.0,1.2487764,-0.088600844,44.696125,0,10.594783,263.91595,-0.0059141465,15.993124,10.594889,263.89035,-9.3411484
90.2,1.262645,-0.092639238,44.639259,0,10.594783,270.51599,-0.0061731529,16.187311,10.594097,270.49149,-9.3376112
92.4,1.2608147,-0.096961752,44.604496,0,10.594783,277.11597,-0.0064278524,16.167263,10.594034,277.23969,-9.3336945
94.6,1.2593782,-0.10094958,44.604496,0,10.594783,283.71594,-0.0066986918,16.14896,10.594265,283.7323,-9.3298874
96.8,1.2670525,-0.10522092,44.320641,0,10.594783,290.31601,-0.0069893533,16.245562,10.595078,290.62613,-9.3264551
99.0,1.2668862,-0.1095479,44.170479,0,10.594783,296.91602,-0.0072792089,16.245926,10.593386,297.10074,-9.3228226
101.2,1.2737979,-0.11373536,44.162777,0,10.594783,303.51599,-0.0075749489,16.349218,10.594702,303.68289,-9.3189669
103.4,1.2748915,-0.11821913,44.077427,0,10.594783,310.116,-0.0078631742,16.369373,10.595868,310.28708,-9.3153362
105.6,1.2834183,-0.12263013,44.077152,0,10.594783,316.71597,-0.0081203086,16.48641,10.594079,316.86096,-9.3118029
107.8,1.2831928,-0.1264872,44.033478,0,10.594783,323.31598,-0.0083963191,16.475775,10.595198,323.51816,-9.3080578
110.0,1.2842109,-0.13058998,44.077145,0,10.594783,329.91599,-0.0086695487,16.487059,10.594808,329.83844,-9.3043375
112.2,1.2816608,-0.13499758,43.839733,0,10.594783,336.51599,-0.0089725386,16.473982,10.595047,336.66486,-9.3006315
114.4,1.2929612,-0.13852261,43.752914,0,10.594783,343.116,-0.0092126597,16.611488,10.595182,343.20267,-9.2971907
116.6,1.2991489,-0.14262953,44.077145,0,10.594783,349.716,-0.0094582923,16.703709,10.59385,349.70273,-9.2935686
118.8,1.2805897,-0.14647864,44.047573,0,10.594783,356.31601,-0.0096928403,16.468658,10.595101,356.32327,-9.289587
121.0,1.2730014,-0.15003599,44.021164,0,10.594783,362.91602,-0.0099645108,16.361309,10.594696,362.89645,-9.2861481
123.2,1.2639753,-0.15359043,44.069199,0,10.594783,369.51599,-0.010177211,16.268024,10.595723,369.46432,-9.282505
125.4,1.2499107,-0.15751138,44.074867,0,10.594783,376.116,-0.010458521,16.075136,10.594933,376.02646,-9.2789001
127.6,1.2394226,-0.15881725,43.818138,0,10.594783,382.716,-0.010546215,15.935765,10.594316,382.76187,-9.2754517
129.8,1.2175839,-0.16083948,44.077145,0,10.594783,389.31598,-0.010646068,15.667909,10.594915,389.30576,-9.2717113
132.0,1.2020028,-0.162131,43.600979,0,10.594783,395.91602,-0.01073208,15.481148,10.594228,395.9946,-9.2682629
134.2,0.33481577,-0.18231353,43.404842,0,10.594783,399.99893,-0.012078428,4.3138118,10.594877,400.26544,-9.2659492
136.4,0.34481448,-0.18367901,42.978519,0,10.594783,399.99893,-0.012166652,4.444912,10.595096,400.4592,-9.2660904
138.6,0.34968182,-0.18492582,42.223179,0,10.594783,399.99893,-0.012265514,4.5155225,10.595274,400.63452,-9.2656403
140.8,0.34530133,-0.18710501,41.803234,0,10.594783,399.99893,-0.012407047,4.4514642,10.59511,400.38602,-9.2655849
143.0,0.34349114,-0.18766606,41.327572,0,10.594783,399.99893,-0.012417598,4.4218807,10.594964,400.37405,-9.2658634
145.2,0.3379187,-0.18859129,41.198734,0,10.594783,399.99893,-0.012491084,4.3649497,10.595086,400.31137,-9.2656851
147.4,0.34254125,-0.18960312,41.046204,0,10.594783,399.99893,-0.012546501,4.4266686,10.595093,400.25137,-9.2656689
149.6,0.35555738,-0.19119616,40.999428,0,10.594783,399.99893,-0.012676965,4.5760164,10.594539,400.13696,-9.26581
151.8,0.34811085,-0.19178542,40.699764,0,10.594783,399.99893,-0.012723074,4.4830599,10.595324,400.09531,-9.265707
154.0,0.35590154,-0.19265479,40.342506,0,10.594783,399.99893,-0.01276024,4.5916409,10.594844,400.20578,-9.2657194
156.2,0.35683632,-0.19364482,40.062153,0,10.594783,399.99893,-0.012805914,4.6056528,10.594354,400.17236,-9.2655067
158.4,0.35935381,-0.19493471,39.903587,0,10.594783,399.99893,-0.012911087,4.6358514,10.593808,400.26602,-9.2651682
160.6,0.35773119,-0.19491735,39.67057,0,10.594783,399.99893,-0.012906514,4.6041374,10.594957,400.13748,-9.2652798
162.8,0.35921133,-0.195648,39.578484,0,10.594783,399.99893,-0.012985673,4.6319604,10.595673,400.06595,-9.2651596
165.0,0.35663518,-0.19659822,39.243168,0,10.594783,399.99893,-0.013029103,4.589571,10.594281,400.11505,-9.2655678
167.2,0.35990378,-0.19751728,39.243168,0,10.594783,399.99893,-0.01305997,4.6417975,10.595164,400.13058,-9.2654495
169.4,0.36013976,-0.19829103,39.199215,0,10.594783,399.99893,-0.013119448,4.6377993,10.594333,400.19864,-9.2656059
171.6,0.36294752,-0.19862835,39.036911,0,10.594783,399.99893,-0.013151629,4.695816,10.594977,400.11401,-9.2652197
173.8,0.36386815,-0.19983347,38.886375,0,10.594783,399.99893,-0.013228727,4.6950359,10.594589,400.0632,-9.2650232
176.0,0.36525413,-0.19966166,38.986889,0,10.594783,399.99893,-0.013246789,4.7131824,10.595422,399.99973,-9.2653704
178.2,0.36601287,-0.20058361,38.619179,0,10.594783,399.99893,-0.013292213,4.7222309,10.594914,400.07047,-9.2652435
178.6211,0.49142593,0.0098670851,34.151707,0,10.5948,9.9962087e-21,0.00062279176,6.2133946,10.597989,399.89175,-9.2651939
178.6255,0.53060836,0.014271317,16.91918,0,10.5948,0.0,0.00086006202,6.7599759,10.596407,399.9314,-9.2652845
178.6299,0.49559775,0.010617301,0.0,0,10.5948,0.0,0.00063009292,6.2860274,10.592804,399.97299,-9.2639017
178.6343,0.50032872,0.012869298,0.0,0,10.5948,0.0,0.00072430307,6.3481851,10.594942,400.11838,-9.2644558
178.6387,0.50531834,0.011270819,0.0,0,10.5948,0.0,0.0006460697,6.4495549,10.594954,400.26379,-9.2632923
178.6431,0.5005089,0.015374461,0.0,0,10.5948,0.0,0.00083274051,6.3747101,10.593048,400.24271,-9.2660437
178.6475,0.5053888,0.012050304,0.0,0,10.5948,0.0,0.00063883769,6.3930292,10.600609,400.16339,-9.2666111
178.6519,0.52759498,0.015044874,0.0,0,10.5948,0.0,0.000811751,6.5929313,10.592343,400.09634,-9.2657032
178.6563,0.52147663,0.012818079,0.0,0,10.5948,0.0,0.00071042648,6.6301284,10.595342,400.04346,-9.2651224
178.6607,0.52220386,0.015396784,0.0,0,10.5948,0.0,0.000839171,6.6708012,10.593177,399.99796,-9.264245
178.6651,0.52245587,0.012708859,0.0,0,10.5948,0.0,0.00068709214,6.6133604,10.598858,399.98474,-9.263237
178.6695,0.54116434,0.016376682,0.0,0,10.569863,0.0,0.00085646962,6.8777618,10.597646,399.97153,-9.2649965
178.6739,0.55359638,0.013818335,0.0,0,10.503863,0.0,0.00075304497,6.982935,10.592135,399.94632,-9.264679
178.6783,0.53856391,0.018030657,0.0,0,10.437863,0.0,0.00090599002,6.7994294,10.580104,399.91989,-9.2648659
178.6827,0.54427475,0.012451421,0.0,0,10.371863,0.0,0.00071666349,6.770802,10.521912,399.91016,-9.2647057
178.6871,0.54043138,0.019062055,0.0,0,10.305863,0.0,0.00094293768,6.9311528,10.423373,399.91016,-9.2648945
178.6915,0.5509249,0.014516202,0.0,0,10.239863,0.0,0.00087775523,7.0794945,10.327959,399.91953,-9.2660971
178.6959,0.55083567,0.019502562,0.0,0,10.173863,0.0,0.0010466739,7.0334253,10.251341,399.94595,-9.2645912
178.7003,0.55345058,0.01406567,0.0,0,10.107863,0.0,0.00081815431,6.975101,10.190102,399.97134,-9.2647305
178.7047,0.56347257,0.019216873,0.0,0,10.041863,0.0,0.0010333856,7.0708251,10.138277,399.98456,-9.2654133
178.7091,0.58255851,0.01486164,0.0,0,9.9758635,0.0,0.00090577005,7.3628922,10.076159,399.99777,-9.2639322
178.7135,0.57889521,0.019236716,0.0,0,9.9098635,0.0,0.0010379781,7.439136,10.006626,400.00043,-9.2649288
178.7179,0.57550848,0.016264193,0.0,0,9.8438625,0.0,0.00096612313,7.3004017,9.9324055,400.00043,-9.2638292
178.7223,1.4174926,0.034232784,0.0,0,9.7778635,0.0,0.0020369324,17.810869,9.8669424,400.00043,-9.2644377
178.7267,2.1507435,0.033707552,0.0,0,9.7118626,0.0,0.0021689374,27.091898,9.808814,400.00043,-9.2634735
178.7311,3.5553105,0.098248318,0.0,0,9.6458635,0.0,0.0062935492,44.98241,9.7407084,400.05557,-9.2610846
178.7355,4.0760999,0.16241388,0.0,0,9.5798635,0.0,0.010678927,51.352512,9.6714621,400.2803,-9.2627249
178.7399,4.3817339,0.24184664,0.0,0,9.5138636,0.0,0.016094413,54.878597,9.5933075,400.505,-9.2615595
178.7443,4.2591052,0.3096461,0.0,0,9.4486961,0.0,0.02073743,53.143353,9.5181522,401.04962,-9.2608957
178.7487,4.1594377,0.37543795,0.0,0,9.3843155,0.0,0.02519276,51.695911,9.4577522,401.60477,-9.2641964
178.7531,4.1562996,0.43229884,0.0,0,9.3199348,0.0,0.029181954,51.37672,9.3917675,401.99554,-9.2624445
178.7575,4.347249,0.49217892,0.0,0,9.2555542,0.0,0.033243071,53.611755,9.335659,402.31274,-9.2632284
178.7619,4.5612864,0.55024439,0.0,0,9.1911736,0.0,0.037367441,55.854008,9.2697783,402.50967,-9.2640028
178.7663,4.5524936,0.622522,0.0,0,9.126792,0.0,0.042304687,55.606983,9.2022152,402.53613,-9.2630348
178.7707,4.4060354,0.68602496,0.0,0,9.0624113,0.0,0.046822581,53.496124,9.1330137,402.5788,-9.2633781
178.7751,4.5840893,0.74941969,0.0,0,8.9980307,0.0,0.051247995,55.435509,9.0680676,402.72418,-9.262269
178.7795,4.7233872,0.80896825,0.0,0,8.93365,0.0,0.055402197,56.79509,9.0050755,402.8696,-9.265234
178.7839,4.9056687,0.87594479,0.0,0,8.8692694,0.0,0.060229983,58.760269,8.9390936,403.00363,-9.2636042
178.7883,5.0107837,0.93727088,0.0,0,8.8048878,0.0,0.064490579,59.853737,8.8687458,403.1358,-9.2628899
178.7927,5.0794125,1.0052619,0.0,0,8.7409821,0.0,0.069437012,60.283466,8.8042994,403.19107,-9.262804
178.7971,5.1583247,1.0645057,0.0,0,8.6797504,0.0,0.073661916,60.959503,8.7382364,403.19107,-9.2620192
178.8015,5.2362761,1.1269556,0.0,0,8.6185207,0.0,0.078187078,61.604675,8.6822529,402.9415,-9.262372
178.8059,5.3183303,1.1863481,0.0,0,8.5572901,0.0,0.082484178,62.417267,8.6224566,402.12201,-9.2631712
178.8103,5.3693633,1.2508385,0.0,0,8.4960604,0.0,0.087262087,62.671032,8.5529156,401.30682,-9.2630501
178.8147,5.4136662,1.311902,0.0,0,8.4348297,0.0,0.091617987,62.939926,8.4930401,400.64594,-9.262886
178.8191,5.493722,1.3734736,0.0,0,8.3735991,0.0,0.09625937,63.531578,8.4262857,399.98505,-9.2638245
178.8235,5.5628338,1.4354019,0.0,0,8.3123684,0.0,0.1007112,64.005981,8.3679667,399.93878,-9.2626534
178.8279,5.5764203,1.4981436,0.0,0,8.2511396,0.0,0.10543422,63.952446,8.3040142,400.09741,-9.2618942
178.8323,5.6291642,1.5586535,0.0,0,8.189908,0.0,0.10990758,64.206306,8.2388868,400.24976,-9.261322
178.8367,5.681459,1.6220641,0.0,0,8.1286783,0.0,0.1147152,64.41481,8.1743755,400.39517,-9.261342
178.8411,5.7239566,1.6785665,0.0,0,8.0674477,0.0,0.11893722,64.643677,8.1179047,400.47079,-9.2619982
178.8455,5.7435908,1.7370158,0.0,0,8.0085573,0.0,0.12329501,64.705917,8.0558052,400.25931,-9.2622929
178.8499,5.7796102,1.7965509,0.0,0,7.9503016,0.0,0.12780987,64.777962,8.0009708,400.04782,-9.2629881
178.8543,5.8418269,1.8534962,0.0,0,7.892046,0.0,0.13216823,65.074455,7.9392376,399.50867,-9.2613068
178.8587,5.8792467,1.9095484,0.0,0,7.8337893,0.0,0.13635318,65.221413,7.8835931,398.94031,-9.2619686
178.8631,5.9265881,1.9673303,0.0,0,7.7755337,0.0,0.14089389,65.504013,7.8219862,398.49054,-9.2627354
178.8675,5.9622941,2.0280836,0.0,0,7.7172771,0.0,0.1454794,65.709282,7.765049,398.10727,-9.2599306
178.8719,6.0065417,2.0882266,0.0,0,7.6590214,0.0,0.15015213,65.875465,7.7009206,397.83929,-9.2620354
178.8763,6.0530763,2.1448674,0.0,0,7.6007657,0.0,0.15450141,66.024254,7.644114,397.77322,-9.2613325
178.8807,6.0821018,2.2005281,0.0,0,7.5425091,0.0,0.15883583,66.007439,7.5857153,397.73337,-9.2604647
178.8851,6.0916872,2.2568929,0.0,0,7.4842534,0.0,0.16324843,65.885674,7.5328364,397.97128,-9.2616243
178.8895,6.1849461,2.3131437,0.0,0,7.4259973,0.0,0.16767411,66.475578,7.4696732,398.20923,-9.2617645
178.8939,6.2683258,2.3741696,0.0,0,7.3689485,0.0,0.17244855,67.075401,7.415513,398.41504,-9.2621975
178.8983,6.313395,2.4350245,0.0,0,7.3135438,0.0,0.17736973,67.212852,7.3506737,398.61331,-9.2616024
178.9027,6.3110304,2.4960513,0.0,0,7.2581387,0.0,0.18213515,67.001663,7.29074,398.80453,-9.2623434
178.9071,6.2952352,2.547482,0.0,0,7.202734,0.0,0.18624444,66.488579,7.2367897,398.98959,-9.2623835
178.9115,6.3636265,2.6012287,0.0,0,7.1473289,0.0,0.19051558,66.923386,7.1841707,399.17465,-9.2610807
178.9159,6.4039392,2.653892,0.0,0,7.0919242,0.0,0.19478953,67.113892,7.1308427,399.35968,-9.261591
178.9203,6.4720201,2.7084246,0.0,0,7.0365191,0.0,0.1991694,67.486389,7.0731711,399.54474,-9.2625475
178.9247,6.4949775,2.7624955,0.0,0,6.9811144,0.0,0.20363632,67.487503,7.0187216,399.61356,-9.2619209
178.9291,6.5748982,2.8195605,0.0,0,6.9257097,0.0,0.20826155,67.916389,6.9597821,399.67963,-9.2626143
178.9335,6.6381497,2.8760617,0.0,0,6.8703055,0.0,0.21288443,68.321205,6.9027996,399.71796,-9.2614832
178.9379,6.6573138,2.9337025,0.0,0,6.8148999,0.0,0.21760613,68.176613,6.841445,399.74438,-9.2623587
178.9423,6.6593733,2.9866292,0.0,0,6.759656,0.0,0.22187831,67.965294,6.7942934,399.72052,-9.2625484
178.9467,6.7331514,3.0421405,0.0,0,6.706944,0.0,0.22657363,68.335739,6.7373114,399.62802,-9.2615795
178.9511,6.7744188,3.0951622,0.0,0,6.654232,0.0,0.23101087,68.506882,6.6835208,399.42197,-9.2630415
178.9555,6.7910848,3.1486201,0.0,0,6.6015201,0.0,0.23544297,68.273605,6.6315389,398.54892,-9.2633686
178.9599,6.8525949,3.1999195,0.0,0,6.5488081,0.0,0.23980726,68.595154,6.5779891,397.67587,-9.261857
178.9643,6.9068747,3.2589395,0.0,0,6.4960961,0.0,0.24474841,68.860779,6.5190063,396.63022,-9.2621269
178.9687,6.991168,3.3090403,0.0,0,6.4433842,0.0,0.24905664,69.4151,6.4692717,395.55838,-9.2608471
178.9731,6.9939036,3.3658059,0.0,0,6.3906722,0.0,0.25380862,69.13839,6.4149842,394.93988,-9.2621021
178.9775,7.0078659,3.4140007,0.0,0,6.3379602,0.0,0.25808153,68.941597,6.3638539,394.63525,-9.2589169
178.9819,7.0354733,3.4646606,0.0,0,6.2852483,0.0,0.26238975,68.883606,6.3112621,394.39706,-9.2605944
178.9863,7.1356626,3.5131924,0.0,0,6.2325363,0.0,0.26657704,69.565361,6.2600522,394.30435,-9.2613611
178.9907,7.1948824,3.5689244,0.0,0,6.1798244,0.0,0.27137718,69.89283,6.205379,394.21402,-9.2621946
178.9951,7.2454495,3.6230428,0.0,0,6.1289067,0.0,0.27614671,69.988235,6.1533675,394.18753,-9.2615471
178.9995,7.2747293,3.6804218,0.0,0,6.0787735,0.0,0.2810832,69.978546,6.0971828,394.16104,-9.2613134
179.0039,7.3005314,3.7283652,0.0,0,6.0286398,0.0,0.2854321,69.895714,6.0441103,394.14462,-9.2618294
179.0083,7.3175354,3.7792528,0.0,0,5.9785061,0.0,0.28981242,69.736366,5.9987645,394.13138,-9.2617941
179.0127,7.3478646,3.824141,0.0,0,5.9283724,0.0,0.29392791,69.793228,5.9521313,394.09354,-9.2621002
179.0171,7.3860788,3.8735049,0.0,0,5.8782392,0.0,0.29825938,69.773315,5.9028034,394.02924,-9.2626276
179.0215,7.478909,3.9186509,0.0,0,5.8281054,0.0,0.30245832,70.348343,5.8544073,393.96646,-9.2615709
179.0259,7.5775986,3.9737861,0.0,0,5.7779713,0.0,0.30724022,70.947701,5.8012009,393.91348,-9.2612228
179.0303,7.6068316,4.0228186,0.0,0,5.7278385,0.0,0.31194744,70.916389,5.7492342,393.8605,-9.2615004
179.0347,7.6615992,4.0806975,0.0,0,5.6777043,0.0,0.31688806,71.051666,5.6983776,393.67096,-9.2620077
179.0391,7.6880388,4.1253042,0.0,0,5.6275706,0.0,0.32127923,70.954071,5.6429944,393.45905,-9.2597723
179.0435,7.7493443,4.1805167,0.0,0,5.5782475,0.0,0.32614627,71.237274,5.596817,393.26254,-9.2611618
179.0479,7.7953467,4.226685,0.0,0,5.5305514,0.0,0.33074182,71.37606,5.5445471,393.07709,-9.2599382
179.0523,7.8098617,4.2775879,0.0,0,5.4828553,0.0,0.33522075,71.081528,5.4970345,392.936,-9.2617626
179.0567,7.8373137,4.3229833,0.0,0,5.4351597,0.0,0.33957925,71.058968,5.4506283,392.89627,-9.2611609
179.0611,7.9151311,4.3722358,0.0,0,5.3874636,0.0,0.34408674,71.451477,5.4041963,392.8533,-9.2613201
179.0655,7.9668183,4.4147344,0.0,0,5.3397679,0.0,0.34835055,71.618088,5.3602285,392.69437,-9.2620478
179.0699,8.0094004,4.4678245,0.0,0,5.2920718,0.0,0.35313582,71.736099,5.312717,392.5354,-9.2613077
179.0743,8.0723991,4.5107965,0.0,0,5.2443757,0.0,0.35738829,71.859055,5.2599316,392.38638,-9.2615967
179.0787,8.164794,4.5640082,0.0,0,5.1966796,0.0,0.36241984,72.342163,5.2121644,392.24069,-9.2614975
179.0831,8.2509689,4.6146874,0.0,0,5.148984,0.0,0.36744243,72.743446,5.1581326,392.06995,-9.2613153
179.0875,8.2501249,4.6674652,0.0,0,5.1012874,0.0,0.3724317,72.422585,5.107532,391.87128,-9.2618961
179.0919,8.251564,4.7098017,0.0,0,5.0535922,0.0,0.3766275,72.089981,5.061502,391.65189,-9.2613163
179.0963,8.2736626,4.7546239,0.0,0,5.0081549,0.0,0.38093242,71.899223,5.0190005,391.34723,-9.2620173
179.1007,8.3754778,4.7951813,0.0,0,4.962791,0.0,0.38503346,72.551872,4.9795794,391.0426,-9.2605438
179.1051,8.4340696,4.8453503,0.0,0,4.9174271,0.0,0.38987401,72.687737,4.9299359,390.82309,-9.2610455
179.1095,8.4857044,4.8904333,0.0,0,4.8720627,0.0,0.39446524,72.772301,4.8828306,390.61115,-9.2610312
179.1139,8.5523977,4.9397569,0.0,0,4.8266988,0.0,0.39933065,73.013214,4.835506,390.43317,-9.2593288
179.1183,8.5828218,4.9800167,0.0,0,4.7813349,0.0,0.40350369,72.958374,4.7917905,390.27423,-9.2618446
179.1227,8.6352272,5.0277281,0.0,0,4.735971,0.0,0.40825582,73.060493,4.7429852,390.06714,-9.2615919
179.1271,8.6533298,5.0685687,0.0,0,4.6906066,0.0,0.41239643,72.994133,4.6999378,389.7757,-9.2610874
179.1315,8.7478075,5.1184483,0.0,0,4.6452427,0.0,0.41742155,73.307541,4.6563702,389.48315,-9.2605963
179.1359,8.8134937,5.1589932,0.0,0,4.5998788,0.0,0.42169872,73.650215,4.6095772,389.17853,-9.2603655
179.1403,8.8893948,5.2095952,0.0,0,4.5545149,0.0,0.42670184,73.933708,4.5605879,388.8739,-9.2591858
179.1447,8.8855896,5.2512817,0.0,0,4.5104871,0.0,0.43097046,73.594421,4.5168538,388.64426,-9.2605314
179.1491,8.9614935,5.2977333,0.0,0,4.4673314,0.0,0.43588594,73.752312,4.4746876,388.43234,-9.2600803
179.1535,9.021925,5.3387666,0.0,0,4.4241767,0.0,0.4401401,73.930305,4.430737,388.19226,-9.2609711
179.1579,9.0485296,5.3840923,0.0,0,4.3810215,0.0,0.44493991,73.814659,4.387682,387.92734,-9.2613525
179.1623,9.1245565,5.42378,0.0,0,4.3378663,0.0,0.44907725,74.161682,4.3471441,387.62198,-9.2610826
179.1667,9.1936789,5.470891,0.0,0,4.2947111,0.0,0.45400596,74.280273,4.2970781,387.19809,-9.2622509
179.1711,9.2490702,5.5149789,0.0,0,4.2515559,0.0,0.45866176,74.378494,4.2545009,386.77423,-9.2603683
179.1755,9.283329,5.5574617,0.0,0,4.2084007,0.0,0.46325904,74.378792,4.2149544,386.38922,-9.2617397
179.1799,9.3531036,5.6004233,0.0,0,4.1652455,0.0,0.46781099,74.61647,4.1701512,386.0051,-9.2614822
179.1843,9.3840723,5.6441908,0.0,0,4.1220903,0.0,0.4724392,74.40313,4.1286111,385.79715,-9.2609367
179.1887,9.5135498,5.6862745,0.0,0,4.0789351,0.0,0.4770723,75.16404,4.0849113,385.6647,-9.2600374
179.1931,9.6005707,5.731668,0.0,0,4.0362897,0.0,0.48194408,75.461205,4.0359292,385.52103,-9.2586193
179.1975,9.6109514,5.7782798,0.0,0,3.9952466,0.0,0.48701453,75.280571,3.992384,385.36209,-9.2602806
179.2019,9.6017075,5.8188066,0.0,0,3.9542036,0.0,0.49150327,74.798241,3.9514868,385.19159,-9.259758
179.2063,9.6407194,5.8556399,0.0,0,3.9131603,0.0,0.49542671,74.742294,3.9162223,384.95316,-9.2591591
179.2107,9.7219305,5.8944478,0.0,0,3.872117,0.0,0.49980214,75.114677,3.8750548,384.71475,-9.260911
179.2151,9.820507,5.9344707,0.0,0,3.831074,0.0,0.50398886,75.519203,3.8332303,384.54532,-9.2604675
179.2195,9.8715687,5.9761219,0.0,0,3.7900305,0.0,0.50873965,75.594337,3.7954624,384.38638,-9.2601423
179.2239,9.9224567,6.0197601,0.0,0,3.7489874,0.0,0.51346523,75.57486,3.7531431,384.19614,-9.2599926
179.2283,10.022635,6.0620408,0.0,0,3.7079442,0.0,0.51825011,75.999062,3.7102935,383.98419,-9.2585096
179.2327,10.1123,6.1048536,0.0,0,3.6669011,0.0,0.52294886,76.324539,3.666019,383.7515,-9.2595482
179.2371,10.149444,6.1473131,0.0,0,3.6258578,0.0,0.5278936,76.254242,3.623301,383.47336,-9.2593174
179.2415,10.170491,6.1896381,0.0,0,3.5848145,0.0,0.5325942,75.983612,3.5818639,383.19666,-9.2612762
179.2459,10.227804,6.2282128,0.0,0,3.5455253,0.0,0.5369339,76.070786,3.5463996,382.95822,-9.261055
179.2503,10.272675,6.2676325,0.0,0,3.5064795,0.0,0.54141706,76.12693,3.5044658,382.71979,-9.2596884
179.2547,10.329966,6.3023834,0.0,0,3.4674337,0.0,0.54525638,76.276146,3.46701,382.49142,-9.2613077
179.2591,10.388785,6.3448844,0.0,0,3.4283881,0.0,0.55009556,76.270866,3.427402,382.26627,-9.2608395
179.2635,10.460002,6.3811021,0.0,0,3.3893428,0.0,0.55424011,76.530853,3.3867698,382.00266,-9.261261
179.2679,10.546533,6.4214711,0.0,0,3.3502972,0.0,0.55894351,76.773079,3.3532341,381.69763,-9.2617321
179.2723,10.617298,6.4621992,0.0,0,3.3112512,0.0,0.56374061,76.916298,3.3123262,381.38986,-9.2608528
179.2767,10.666443,6.5034919,0.0,0,3.2722056,0.0,0.56851012,76.957138,3.2702787,381.07135,-9.2603216
179.2811,10.726454,6.5411892,0.0,0,3.2331603,0.0,0.57289875,76.980476,3.2333622,380.75281,-9.2599449
179.2855,10.788411,6.5814734,0.0,0,3.1941147,0.0,0.57767183,77.049347,3.1935298,380.2988,-9.2597036
179.2899,10.864577,6.6178408,0.0,0,3.1550689,0.0,0.58184373,77.273369,3.15801,379.83414,-9.260457
179.2943,10.94117,6.6604228,0.0,0,3.1170006,0.0,0.58696234,77.434334,3.1187704,379.29184,-9.2599897
179.2987,11.006104,6.6987176,0.0,0,3.0798559,0.0,0.5915392,77.576096,3.0782013,378.7077,-9.2599554
179.3031,11.057917,6.7379913,0.0,0,3.042711,0.0,0.59624034,77.580963,3.0386693,378.22256,-9.2610121
179.3075,11.105924,6.7737288,0.0,0,3.0055661,0.0,0.60053062,77.557007,3.0024304,377.90396,-9.25986
179.3119,11.151062,6.8154192,0.0,0,2.9684215,0.0,0.60539579,77.509911,2.9644735,377.59171,-9.2604589
179.3163,11.225463,6.8501906,0.0,0,2.9312766,0.0,0.60979772,77.690933,2.9267118,377.33948,-9.2591591
179.3207,11.323319,6.8899412,0.0,0,2.8941319,0.0,0.61448181,78.013084,2.8934882,377.08725,-9.2599277
179.3251,11.421806,6.9267669,0.0,0,2.8569868,0.0,0.61914033,78.297272,2.8551955,376.25934,-9.260705
179.3295,11.445059,6.967113,0.0,0,2.8198423,0.0,0.62404174,78.106323,2.8143632,375.3035,-9.2624893
179.3339,11.508546,7.003499,0.0,0,2.7826974,0.0,0.62856412,78.134361,2.7795582,374.26151,-9.2599201
179.3383,11.581591,7.0419326,0.0,0,2.7455528,0.0,0.63328904,78.283142,2.7468586,373.14636,-9.2605848
179.3427,11.683227,7.0760126,0.0,0,2.7086811,0.0,0.63762933,78.63929,2.7060559,372.06619,-9.259944
179.3471,11.760085,7.1176572,0.0,0,2.6733489,0.0,0.64275426,78.746803,2.6688433,371.08383,-9.2609224
179.3515,11.816162,7.1538363,0.0,0,2.6380169,0.0,0.64733666,78.730278,2.6302018,370.10144,-9.2600527
179.3559,11.883971,7.1939683,0.0,0,2.602685,0.0,0.65250957,78.80661,2.5972962,369.30237,-9.2593594
179.3603,11.945313,7.2263303,0.0,0,2.567353,0.0,0.6565401,78.859955,2.5582304,368.50586,-9.2606468
179.3647,11.963874,7.2647309,0.0,0,2.532021,0.0,0.66144651,78.658958,2.5256758,368.19882,-9.2604055
179.3691,12.003286,7.2936382,0.0,0,2.4966891,0.0,0.66534871,78.574081,2.4923415,368.09262,-9.2608995
179.3735,12.113528,7.3315997,0.0,0,2.4613569,0.0,0.67007846,78.920906,2.4595215,368.06094,-9.2593813
179.3779,12.222789,7.36409,0.0,0,2.4260249,0.0,0.67443836,79.260971,2.4233396,368.12732,-9.2599859
179.3823,12.308311,7.4045053,0.0,0,2.3906929,0.0,0.67963636,79.474976,2.3872645,368.17725,-9.2607765
179.3867,12.360625,7.4375892,0.0,0,2.355361,0.0,0.68434823,79.349785,2.3483667,368.13745,-9.2583313
179.3911,12.481966,7.4766798,0.0,0,2.3200288,0.0,0.68925661,79.709351,2.3132708,368.09763,-9.2596197
179.3955,12.581583,7.511281,0.0,0,2.2860541,0.0,0.69409418,80.01503,2.2763784,368.02286,-9.2597551
179.3999,12.609426,7.5506229,0.0,0,2.2524469,0.0,0.69895697,79.802109,2.2443967,367.94321,-9.259675
179.4043,12.574532,7.5806146,0.0,0,2.2188396,0.0,0.70341194,79.271141,2.2090423,367.71222,-9.2604303
179.4087,12.624689,7.6162281,0.0,0,2.1852326,0.0,0.70786113,79.22541,2.1777713,367.38034,-9.2604132
179.4131,12.750094,7.6437373,0.0,0,2.1516254,0.0,0.7120648,79.667183,2.1446857,366.91531,-9.2599468
179.4175,12.816406,7.6794252,0.0,0,2.1180182,0.0,0.71656424,79.760536,2.1166539,366.17096,-9.2603531
179.4219,12.915498,7.7093616,0.0,0,2.0844109,0.0,0.72096652,79.974159,2.0817375,365.41208,-9.2600927
179.4263,13.006734,7.7461123,0.0,0,2.0508039,0.0,0.72593921,80.091446,2.0503268,364.34753,-9.2610455
179.4307,13.152951,7.7816777,0.0,0,2.0171967,0.0,0.73093581,80.589088,2.0157108,363.28299,-9.2595253
179.4351,13.255867,7.8197646,0.0,0,1.9835894,0.0,0.73603451,80.860664,1.9794655,362.22861,-9.259407
179.4395,13.306444,7.854948,0.0,0,1.9499823,0.0,0.74115711,80.728165,1.9437032,361.17731,-9.2608929
179.4439,13.326221,7.8907466,0.0,0,1.9170679,0.0,0.74612397,80.480194,1.9069171,360.17825,-9.25986
179.4483,13.426033,7.91995,0.0,0,1.8850974,0.0,0.75048542,80.706352,1.8731045,359.2334,-9.2587318
179.4527,13.470863,7.9562922,0.0,0,1.853127,0.0,0.75559676,80.611679,1.8423666,358.32834,-9.259203
179.4571,13.501268,7.9840593,0.0,0,1.8211566,0.0,0.75970978,80.396294,1.8132126,357.56979,-9.2612581
179.4615,13.59049,8.0180464,0.0,0,1.7891862,0.0,0.76449251,80.550766,1.7837945,356.81125,-9.2610712
179.4659,13.716311,8.0462589,0.0,0,1.7572159,0.0,0.76876575,80.981895,1.7515244,356.73804,-9.2592173
179.4703,13.808549,8.0817881,0.0,0,1.7252455,0.0,0.77385545,81.106331,1.7167982,356.71143,-9.2592735
179.4747,13.85172,8.1098757,0.0,0,1.693275,0.0,0.77801031,81.032494,1.6841635,356.55325,-9.2612267
179.4791,13.905761,8.1439495,0.0,0,1.6613046,0.0,0.78309888,80.926285,1.6525302,356.32703,-9.2604733
179.4835,13.992418,8.1723003,0.0,0,1.6293342,0.0,0.78723711,81.071602,1.6257514,355.90265,-9.2601938
179.4879,14.140268,8.2076769,0.0,0,1.5973638,0.0,0.79252571,81.493813,1.5906513,355.15738,-9.2604837
179.4923,14.197134,8.2359562,0.0,0,1.5654866,0.0,0.79658526,81.509949,1.5575163,354.36478,-9.2599316
179.4967,14.245356,8.2691307,0.0,0,1.5350735,0.0,0.80181599,81.357788,1.5303355,353.16653,-9.2597628
179.5011,14.336509,8.2989292,0.0,0,1.5046606,0.0,0.80615884,81.527695,1.4967171,351.96826,-9.2596741
179.5055,14.459657,8.3320265,0.0,0,1.4742478,0.0,0.81111938,81.795326,1.4641716,350.63684,-9.2601156
179.5099,14.545481,8.3609791,0.0,0,1.4438351,0.0,0.81558079,81.948669,1.4368708,349.27759,-9.2590437
179.5143,14.603437,8.3941422,0.0,0,1.4134222,0.0,0.82076895,81.812828,1.4039147,348.10083,-9.2602291
179.5187,14.623444,8.4245558,0.0,0,1.3830094,0.0,0.82532263,81.55616,1.3760669,347.07343,-9.2594719
179.5231,14.745307,8.4517155,0.0,0,1.3525968,0.0,0.82966095,81.876961,1.3461546,346.08603,-9.260457
179.5275,14.86683,8.4824896,0.0,0,1.322184,0.0,0.83422226,82.207466,1.3116089,345.20538,-9.260973
179.5319,14.909346,8.5114174,0.0,0,1.2917712,0.0,0.8388738,82.094543,1.2848735,344.32474,-9.2598782
179.5363,14.924525,8.5400295,0.0,0,1.2613584,0.0,0.84329224,81.771698,1.2569855,343.88242,-9.2604132
179.5407,15.050542,8.5704451,0.0,0,1.2309455,0.0,0.84788483,82.026093,1.22662,343.44208,-9.2597361
179.5451,15.192988,8.5975027,0.0,0,1.2015678,0.0,0.85208082,82.456093,1.1953617,343.15509,-9.2590218
179.5495,15.275291,8.6309099,0.0,0,1.1726422,0.0,0.85739386,82.500435,1.1618389,342.92828,-9.259922
179.5539,15.385375,8.6583023,0.0,0,1.1437165,0.0,0.86186671,82.748428,1.1326123,342.58966,-9.2599335
179.5583,15.453811,8.6907854,0.0,0,1.114791,0.0,0.8670429,82.685318,1.1008525,342.10928,-9.2598228
179.5627,15.489825,8.7166805,0.0,0,1.0858653,0.0,0.87105066,82.497414,1.0773822,341.64856,-9.2601643
179.5671,15.527125,8.7457857,0.0,0,1.0569397,0.0,0.87575221,82.373596,1.0485332,341.2883,-9.2599983
179.5715,15.608902,8.7705183,0.0,0,1.0280141,0.0,0.87957549,82.468437,1.0216019,340.92807,-9.259676
179.5759,15.768954,8.8000984,0.0,0,0.99908859,0.0,0.88442993,82.906723,0.99136013,340.44952,-9.2597513
179.5803,15.884476,8.8310823,0.0,0,0.97016299,0.0,0.88930273,83.121994,0.96142602,339.95581,-9.2597046
179.5847,15.941082,8.8596821,0.0,0,0.94123739,0.0,0.89404303,83.027954,0.93289775,339.43774,-9.2604227
179.5891,15.964971,8.8849277,0.0,0,0.91231167,0.0,0.89803791,82.794731,0.90269834,338.90402,-9.2597332
179.5935,16.092119,8.9133749,0.0,0,0.88385707,0.0,0.9028759,83.033966,0.87871003,338.62711,-9.2594843
179.5979,16.260633,8.9461184,0.0,0,0.85634828,0.0,0.90788227,83.504173,0.84535426,338.86728,-9.2597742
179.6023,16.341845,8.9736042,0.0,0,0.82883948,0.0,0.91252881,83.557922,0.82063949,339.11475,-9.2594452
179.6067,16.362366,9.0031309,0.0,0,0.80133069,0.0,0.91737324,83.260216,0.78792781,339.48834,-9.2604103
179.6111,16.386187,9.027236,0.0,0,0.77382189,0.0,0.92129701,83.013306,0.7656408,339.86194,-9.2595491
179.6155,16.507046,9.0542278,0.0,0,0.74631304,0.0,0.9257496,83.246536,0.73895621,339.79996,-9.2607059
179.6199,16.659435,9.0812387,0.0,0,0.7188043,0.0,0.93034482,83.664963,0.71196693,339.61316,-9.2599249
179.6243,16.726835,9.1083403,0.0,0,0.69129544,0.0,0.9347946,83.654373,0.6845634,339.15952,-9.2591276
179.6287,16.771976,9.135354,0.0,0,0.66378671,0.0,0.93926519,83.500671,0.65656209,338.43896,-9.2598915
179.6331,16.886642,9.1624374,0.0,0,0.63627785,0.0,0.94390935,83.63269,0.63164896,337.82541,-9.2597647
179.6375,17.003443,9.1871481,0.0,0,0.60876906,0.0,0.94788277,83.867401,0.60192955,337.58524,-9.2584934
179.6419,17.11841,9.2145548,0.0,0,0.58126026,0.0,0.95258635,84.078865,0.57801718,337.34506,-9.2584934
179.6463,17.220312,9.2428341,0.0,0,0.55503875,0.0,0.95747238,84.152679,0.54389644,337.6095,-9.2591887
179.6507,17.281408,9.2697763,0.0,0,0.52885872,0.0,0.96207064,84.139008,0.51925755,337.90305,-9.2591124
179.6551,16.488804,9.2749834,0.0,0,0.50267869,0.0,0.96305484,80.193451,0.5018149,338.06287,-9.2600756
179.6595,16.058666,9.2899714,0.0,0,0.47649872,0.0,0.96554381,77.909546,0.4865649,338.15628,-9.2602959
179.6639,15.823456,9.2900543,0.0,0,0.45031872,0.0,0.96560943,76.726707,0.47123757,338.18185,-9.2606068
179.6683,15.585222,9.301939,0.0,0,0.4241387,0.0,0.96734804,75.468994,0.45463133,338.10181,-9.261364
179.6727,15.161544,9.3012934,0.0,0,0.3979587,0.0,0.96736789,73.405823,0.43820781,338.0202,-9.2618999
179.6771,14.730186,9.3061333,0.0,0,0.3717787,0.0,0.96791726,71.275146,0.43005404,337.92682,-9.2616644
179.6815,14.372106,9.3062201,0.0,0,0.3455987,0.0,0.96801138,69.524445,0.42473972,337.8334,-9.2607555
179.6859,14.176974,9.3086882,0.0,0,0.3194187,0.0,0.96839631,68.545898,0.41494292,337.79581,-9.2614679
179.6903,14.140013,9.3086319,0.0,0,0.29323873,0.0,0.96829712,68.342537,0.3989315,337.76913,-9.2622881
179.6947,14.288098,9.3158846,0.0,0,0.26783612,0.0,0.9695428,68.96669,0.37374777,337.72009,-9.2618408
179.6991,14.536067,9.3149004,0.0,0,0.24294093,0.0,0.96942699,70.181755,0.33793214,337.65335,-9.2606316
179.7035,14.684608,9.3229036,0.0,0,0.21804574,0.0,0.97057939,70.81868,0.30773059,337.57535,-9.2609663
179.7079,14.765425,9.3213577,0.0,0,0.19315059,0.0,0.97030312,71.201347,0.27032444,337.46863,-9.2610397
179.7123,14.784518,9.3264008,0.0,0,0.16825537,0.0,0.97114825,71.279839,0.24111767,337.36218,-9.2591772
179.7167,14.770854,9.3286543,0.0,0,0.14336018,0.0,0.97189432,71.162125,0.21324863,337.32214,-9.259572
179.7211,14.704483,9.3353081,0.0,0,0.11846498,0.0,0.97250408,70.79985,0.18960719,337.2821,-9.260541
179.7255,14.637125,9.3326397,0.0,0,0.093569778,0.0,0.97262859,70.439178,0.16521204,337.26147,-9.2602062
179.7299,14.586586,9.3392534,0.0,0,0.068674572,0.0,0.97330731,70.173882,0.14409789,337.24814,-9.2602587
179.7343,14.531074,9.3376026,0.0,0,0.043779373,0.0,0.97334093,69.876549,0.12447414,337.21075,-9.2606735
179.7387,14.441994,9.3437376,0.0,0,0.018884173,0.0,0.97401917,69.482605,0.10245,337.14404,-9.2612696
179.7431,14.383026,9.3414268,0.0,0,-0.0058644204,0.0,0.97398996,69.12989,0.084624469,337.07965,-9.2607679
179.7475,14.33273,9.3451405,0.0,0,-0.03015242,0.0,0.97432125,68.884766,0.070034809,337.02628,-9.2609692
179.7519,14.272854,9.3423872,0.0,0,-0.05444042,0.0,0.97442883,68.571381,0.051415976,336.97293,-9.2611742
179.7563,14.200603,9.3502674,0.0,0,-0.078728423,0.0,0.97543436,68.177345,0.03871683,336.89566,-9.2597685
179.7607,14.075783,9.3496523,0.0,0,-0.10301641,0.0,0.97559774,67.563667,0.024405137,336.81561,-9.2596626
179.7651,13.949363,9.3516693,18.722841,0,0.4260999,400.0,0.97577924,66.92379,0.015640821,336.65305,-9.2603064
179.7695,13.302095,9.3489237,49.010021,0,1.222958,400.0,0.97555441,63.97789,0.029438719,336.43954,-9.2589769
179.7739,9.7101526,9.3384285,68.972168,0,2.0198162,400.0,0.97329426,46.908211,0.21414684,336.23969,-9.2634706
179.7783,0.80413151,9.2636061,68.972168,0,2.8166733,400.0,0.96092165,4.8991075,0.55772656,336.06622,-9.268919
179.7827,1.2066622,9.2662048,68.989052,0,3.6135306,400.0,0.96128845,6.0117421,1.7405202,335.85532,-9.270752
179.7871,1.1124308,9.2884254,69.254387,0,4.4103885,400.0,0.96517682,5.3634973,2.9568901,335.09302,-9.2709227
179.7915,1.0234686,9.3087311,69.51973,0,5.2072458,400.0,0.9684726,4.9263902,3.7635942,334.33072,-9.2696714
179.7959,1.0858369,9.2918272,69.576416,0,6.0041041,400.0,0.96601802,5.2535443,4.5212288,338.22449,-9.2663469
179.8003,1.1144474,9.3001661,69.576416,0,6.8009615,400.0,0.96727657,5.3946595,5.279665,343.38327,-9.2668486
179.8047,0.98324609,9.2869673,68.819969,0,7.5978193,400.0,0.96509135,4.7657733,6.0704818,345.70459,-9.2673569
179.8091,0.9505468,9.2902603,67.334076,0,8.3946772,400.0,0.9655413,4.6030869,6.8896632,345.28973,-9.2669382
179.8135,0.97949511,9.2874203,66.192627,0,9.191534,400.0,0.96542251,4.8050799,7.7267933,344.87231,-9.2663031
179.8179,0.91865927,9.2707224,66.192627,0,9.9883928,400.0,0.96236241,4.3991265,8.5520678,344.44647,-9.2647982
179.8223,1.0282831,9.2866192,66.192627,0,10.785251,400.0,0.96542042,5.0004573,9.3837633,344.02063,-9.2651443
179.8267,1.2076601,9.2926846,66.409065,0,11.582107,400.0,0.96648449,5.8562322,10.201719,343.96295,-9.2658281
179.8311,0.94721276,9.2912779,66.635803,0,12.378964,400.0,0.96649355,4.6299038,10.994348,343.92282,-9.2641726
179.8355,0.94402039,9.287405,66.708984,0,13.175823,400.0,0.96577585,4.5706515,11.762917,343.94589,-9.2652769
179.8399,1.0787486,9.2874756,66.708984,0,13.97268,400.0,0.96558839,5.2482181,12.532598,343.99911,-9.264102
179.8443,0.99957246,9.2870474,66.708984,0,14.769538,400.0,0.96579647,4.8682399,13.31389,344.09531,-9.2641401
179.8487,1.0332884,9.2693796,66.708984,0,15.566396,400.0,0.96277851,5.0030928,14.132515,344.25589,-9.2636909
179.8531,0.99430418,9.2866249,66.708984,0,16.363255,400.0,0.9659161,4.8238974,14.949804,344.39679,-9.262557
179.8575,0.88495302,9.2720909,66.708984,0,17.16011,400.0,0.96352953,4.2941132,15.749723,344.39679,-9.2629099
179.8619,1.0716074,9.2846861,66.708984,0,17.95697,400.0,0.96561623,5.2256112,16.546103,344.39679,-9.2634954
179.8663,1.0109668,9.2796116,66.774246,0,18.0,400.0,0.96497691,4.8270998,17.334229,344.47598,-9.2622871
179.8707,0.95349103,9.2961302,66.851433,0,18.0,400.0,0.96768159,4.6077256,18.013998,344.56967,-9.2644062
179.8751,1.1352844,9.2795925,66.884766,0,18.0,400.0,0.96484113,5.4986649,18.430574,344.59497,-9.2695885
179.8795,1.2284894,9.277751,66.884766,0,18.0,400.0,0.96452248,5.9449377,18.435337,344.56836,-9.2800035
179.8839,1.2363381,9.2777758,66.862305,0,18.0,400.0,0.96470135,5.9672046,18.221329,344.63904,-9.3017941
179.8883,1.1915773,9.2671986,66.785118,0,18.0,400.0,0.96310282,5.8294005,18.07403,344.94684,-9.3317442
179.8927,1.1111499,9.2746449,66.708984,0,18.0,400.0,0.96430236,5.3877649,18.050795,345.24969,-9.3695593
179.8971,1.0126632,9.2717361,66.708984,0,18.0,400.0,0.96361506,4.9073424,18.075428,345.19647,-9.4071245
179.9015,1.2280918,9.2733479,66.708984,0,18.0,400.0,0.9639535,5.9720531,18.113842,345.14325,-9.4415398
179.9059,1.1412891,9.2726545,66.765823,0,18.0,400.0,0.96386528,5.5292201,18.142569,345.12921,-9.4744034
179.9103,1.0511794,9.2802334,66.84301,0,18.0,400.0,0.96517044,5.0867162,18.13658,345.12921,-9.5033731
179.9147,1.1563486,9.2703075,66.884766,0,18.0,400.0,0.96341825,5.6321702,18.140465,345.10477,-9.5365839
179.9191,1.1685535,9.2569027,66.884766,0,18.0,400.0,0.96094906,5.6348834,18.131832,345.05154,-9.5699387
179.9235,1.152856,9.2699347,66.897919,0,18.0,400.0,0.96349657,5.6272793,18.126001,345.02258,-9.6026821
179.9279,1.278736,9.2633371,66.970284,0,18.0,400.0,0.96222872,6.2627859,18.119678,345.10291,-9.6352882
179.9323,1.1430397,9.2730227,67.042656,0,18.0,400.0,0.96383762,5.5436316,18.119545,345.1832,-9.6668043
179.9367,1.0585434,9.2692423,67.049561,0,18.0,400.0,0.96307296,5.2674298,18.10491,345.1066,-9.6986532
179.9411,1.2509488,9.2763824,67.049561,0,18.0,400.0,0.96431112,6.1211667,18.111664,345.01346,-9.7321987
179.9455,1.1423079,9.2688675,67.097984,0,18.0,400.0,0.96291989,5.5333052,18.107944,345.0123,-9.7631054
179.9499,1.0676174,9.2740574,67.175171,0,18.0,400.0,0.96358079,5.1621661,18.104452,345.06586,-9.7959614
179.9543,1.1813129,9.2690315,67.225342,0,18.0,400.0,0.962708,5.7549081,18.102638,345.08667,-9.8292742
179.9587,1.0842497,9.2492399,67.225342,0,18.0,400.0,0.95927471,5.3023853,18.105635,345.04672,-9.8635445
179.9631,1.1608148,9.2697573,67.230606,0,18.0,400.0,0.96261692,5.6520514,18.099897,345.01166,-9.8962936
179.9675,1.3599608,9.2662678,67.302971,0,18.0,400.0,0.96222937,6.6515899,18.1038,345.03842,-9.9269409
179.9719,1.1737334,9.2770891,67.375336,0,18.0,400.0,0.96387035,5.651032,18.099333,345.06522,-9.9604254
179.9763,1.2541838,9.2622166,67.390137,0,18.0,400.0,0.96127385,6.0190802,18.100769,345.11301,-9.993309
179.9807,1.2664391,9.2757368,67.390137,0,18.0,400.0,0.963413,6.1255803,18.095186,345.16626,-10.026617
179.9851,1.15966,9.2702112,67.390137,0,18.0,400.0,0.96267051,5.632813,18.093908,345.23349,-10.05724
179.9895,1.1112634,9.2650518,67.390137,0,18.0,400.0,0.96135515,5.4169927,18.092506,345.31381,-10.088623
179.9939,1.2112349,9.2704391,67.390137,0,18.0,400.0,0.96249622,5.8979721,18.091799,345.38116,-10.120989
179.9983,1.0629659,9.2534552,67.390137,0,18.0,400.0,0.95943969,5.2211661,18.092236,345.40778,-10.153956
180.0027,1.1786915,9.2666845,67.390137,0,18.0,400.0,0.9615894,5.7654767,18.089926,345.43439,-10.189069
180.0071,1.4409527,9.2744646,67.459869,0,18.0,400.0,0.96275496,6.9551325,18.089436,345.53851,-10.221221
180.0115,1.185922,9.2799749,67.532234,0,18.0,400.0,0.96368778,5.7480378,18.087645,345.64557,-10.253585
180.0159,1.1844071,9.2703695,67.554932,0,18.0,400.0,0.96196157,5.7634821,18.084606,345.74942,-10.28611
180.0203,1.2217642,9.2715397,67.554932,0,18.0,400.0,0.96214849,5.9407406,18.084549,345.85181,-10.318212
180.0247,1.1885558,9.2706108,67.554932,0,18.0,400.0,0.96176565,5.7617517,18.084444,345.93863,-10.348765
180.0291,1.177996,9.2574472,67.554932,0,18.0,400.0,0.95956987,5.7957463,18.075821,345.99216,-10.382315
180.0335,1.1753509,9.2764769,67.554932,0,18.0,400.0,0.96265674,5.7489676,18.079021,346.04352,-10.417531
180.0379,1.0386937,9.2553854,67.554932,0,18.0,400.0,0.95906144,5.0863481,18.076021,346.04352,-10.449124
180.0423,1.2190176,9.2743874,67.554932,0,18.0,400.0,0.96237826,5.9252696,18.075277,346.04352,-10.479931
180.0467,1.1959029,9.2708817,67.554932,0,18.0,400.0,0.96145886,5.7076378,18.07213,346.07419,-10.512265
180.0511,1.1271052,9.2855406,67.554932,0,18.0,400.0,0.96408248,5.4976373,18.070438,346.11432,-10.545796
180.0555,1.1581802,9.2719202,67.554932,0,18.0,400.0,0.96185249,5.6400032,18.070049,346.14142,-10.579089
180.0599,1.1957793,9.2658339,67.554932,0,18.0,400.0,0.96053189,5.790832,18.071421,346.15469,-10.610847
180.0643,1.2301016,9.2724237,67.569054,0,18.0,400.0,0.96186513,5.9508438,18.068066,346.1792,-10.643871
180.0687,1.2646751,9.2627001,67.636589,0,18.0,400.0,0.95981532,6.2186046,18.069239,346.24603,-10.675859
180.0731,1.1550391,9.2732372,67.704132,0,18.0,400.0,0.96206796,5.6347451,18.066998,346.3129,-10.707014
180.0775,1.0331451,9.2725878,67.70874,0,18.0,400.0,0.96156287,4.9905753,18.065388,346.35464,-10.740409
180.0819,1.2895918,9.2729387,67.70874,0,18.0,400.0,0.96194106,6.2521667,18.06728,346.39456,-10.773572
180.0863,1.232504,9.2741852,67.70874,0,18.0,400.0,0.96189064,5.9835567,18.064264,346.47821,-10.806686
180.0907,1.0942066,9.2794647,67.70874,0,18.0,400.0,0.96323985,5.3212786,18.06765,346.58496,-10.838392
180.0951,1.1609583,9.2746239,67.70874,0,18.0,400.0,0.96193665,5.6543064,18.062366,346.68155,-10.870903
180.0995,1.1837088,9.2551289,67.70874,0,18.0,400.0,0.95885974,5.7254653,18.064573,346.76141,-10.90134
180.1039,1.235441,9.2749319,67.70874,0,18.0,400.0,0.96196938,6.0438323,18.062309,346.83862,-10.934954
180.1083,1.3377295,9.2652588,67.70874,0,18.0,400.0,0.96094954,6.6001668,18.059547,346.892,-10.967318
180.1127,1.1597668,9.2801819,67.70874,0,18.0,400.0,0.96308285,5.6441584,18.058685,346.94537,-10.99971
180.1171,1.076619,9.2655277,67.70874,0,18.0,400.0,0.96093649,5.3369899,18.055582,346.93295,-11.033944
180.1215,1.3434812,9.2827501,67.70874,0,18.0,400.0,0.9635675,6.5277996,18.057339,346.90631,-11.066902
180.1259,1.2209417,9.2697115,67.748207,0,18.0,400.0,0.96171814,5.9173999,18.053904,346.92334,-11.098554
180.1303,1.0975574,9.2793989,67.82058,0,18.0,400.0,0.96312165,5.3436127,18.052185,346.97668,-11.132609
180.1347,1.1930324,9.2693357,67.873535,0,18.0,400.0,0.96187192,5.7907729,18.052595,347.01575,-11.163819
180.1391,1.1600134,9.25212,67.873535,0,18.0,400.0,0.95863169,5.6263838,18.052374,347.01575,-11.195176
180.1435,1.2353758,9.2697172,67.873535,0,18.0,400.0,0.96195811,6.0291653,18.051914,347.01575,-11.227683
180.1479,1.4201519,9.2745047,67.873535,0,18.0,400.0,0.96288896,6.9448538,18.053093,347.12152,-11.26149
180.1523,1.1816452,9.2731934,67.873535,0,18.0,400.0,0.96285379,5.7067037,18.049503,347.22827,-11.292114
180.1567,1.3105363,9.2696724,67.873535,0,18.0,400.0,0.96196198,6.2930694,18.049011,347.27783,-11.324718
180.1611,1.3348968,9.2770109,67.873535,0,18.0,400.0,0.96335649,6.5017457,18.053698,347.30444,-11.359649
181.862,0.95971841,9.2820301,4.801110500000003e-22,0,18.0,2.6539226e-21,0.96440881,4.6603837,18.000858,285.68698,-11.480598
184.062,0.86050379,9.2865429,7.9874012e-44,0,18.0,1.4012985e-45,0.96514255,4.1738763,17.999889,248.39923,-11.481312
186.262,0.8763752,9.2949781,7.9874012e-44,0,18.0,1.4012985e-45,0.9667064,4.2463765,17.99996,229.79604,-11.480706
188.462,0.88832241,9.302845,7.9874012e-44,0,18.0,1.4012985e-45,0.96815228,4.3012366,17.999285,216.19742,-11.480653
190.662,0.89292765,9.3102741,7.9874012e-44,0,18.0,1.4012985e-45,0.9693709,4.3137231,17.99987,204.26784,-11.481883
192.862,0.89764321,9.3162594,7.9874012e-44,0,18.0,1.4012985e-45,0.97046334,4.3296905,18.00012,194.49472,-11.481903
195.062,0.90820313,9.3222599,7.9874012e-44,0,18.0,1.4012985e-45,0.97149652,4.375587,17.999596,184.91614,-11.481202
197.262,0.91360664,9.3287439,7.9874012e-44,0,18.0,1.4012985e-45,0.97255892,4.3964906,18.000162,176.51968,-11.481568
199.462,0.93108124,9.3338442,7.9874012e-44,0,18.0,1.4012985e-45,0.973526,4.4770789,17.998997,168.46851,-11.481949
201.662,0.9345035,9.3385983,7.9874012e-44,0,18.0,1.4012985e-45,0.97447085,4.4894838,18.001024,160.72166,-11.482346
203.862,0.94126588,9.343873,7.9874012e-44,0,18.0,1.4012985e-45,0.97529632,4.5207191,18.000078,154.02164,-11.482322
206.062,0.94582784,9.3483419,7.9874012e-44,0,18.0,1.4012985e-45,0.97613186,4.5410461,17.999331,147.28716,-11.481482
208.262,0.95652825,9.353322,7.9874012e-44,0,18.0,1.4012985e-45,0.97697765,4.586576,17.999907,140.86447,-11.481194
210.462,0.95829016,9.3573771,7.9874012e-44,0,18.0,1.4012985e-45,0.97762203,4.5940928,17.999973,134.84628,-11.481686
212.662,0.96301973,9.3610506,7.9874012e-44,0,18.0,1.4012985e-45,0.97833234,4.6048346,18.000242,129.17007,-11.481493
214.862,0.9735561,9.3651381,7.9874012e-44,0,18.0,1.4012985e-45,0.97915089,4.6558051,17.999607,123.49208,-11.482103
217.062,0.99051338,9.3683004,7.9874012e-44,0,18.0,1.4012985e-45,0.97964495,4.7297721,17.999519,118.40717,-11.481948
219.262,0.98914546,9.3721209,7.9874012e-44,0,18.0,1.4012985e-45,0.98033166,4.7254305,18.000057,113.4566,-11.4816
221.462,0.99023557,9.3759193,7.9874012e-44,0,18.0,1.4012985e-45,0.98100102,4.7256799,17.999985,108.60242,-11.480447
223.662,0.99223149,9.3788671,7.9874012e-44,0,18.0,1.4012985e-45,0.98143935,4.7363863,17.999884,103.92676,-11.480605
225.862,0.98954892,9.3819504,7.9874012e-44,0,18.0,1.4012985e-45,0.98208594,4.7257209,17.99967,99.573586,-11.481042
228.062,0.98951423,9.3849487,7.9874012e-44,0,18.0,1.4012985e-45,0.98266482,4.7197237,17.999641,95.444412,-11.481508
230.262,0.99428171,9.3881855,7.9874012e-44,0,18.0,1.4012985e-45,0.98313326,4.7355604,17.999567,91.458466,-11.481317
232.462,1.0004991,9.3904381,7.9874012e-44,0,18.0,1.4012985e-45,0.98364431,4.7627988,18.001356,87.787163,-11.481842
234.662,1.002303,9.3928738,7.9874012e-44,0,18.0,1.4012985e-45,0.98395818,4.7660594,18.00028,84.280281,-11.481456
236.862,1.0048226,9.3953848,7.9874012e-44,0,18.0,1.4012985e-45,0.98439682,4.7797031,17.998804,80.898407,-11.480589
239.062,1.0093435,9.3978653,7.9874012e-44,0,18.0,1.4012985e-45,0.98495322,4.7985926,17.999971,77.614677,-11.480873
240.162,1.0056772,9.3988829,7.9874012e-44,0,18.0,1.4012985e-45,0.98506373,4.7822075,17.999498,76.138359,-11.480681