File: raw data/testID_0189.csv
Time(sec),Force(kN),Jaw(mm),PowAngle(deg),Power(W),Pram,PTemp,Strain,Stress(MPa),Stroke(mm),TC1(C),wedge(mm)
0.0,0.93992245,0.80896538,0.0,0,11.076097,0.001588269,0.055718437,11.335608,11.076672,22.496986,-9.122633
1.1,0.89741117,0.00076834776,0.0,0,11.076097,3.2158828,5.3599379e-05,11.434281,11.075912,22.536949,-9.4844971
2.2,0.83530569,0.00052657793,0.0,0,11.076097,6.515883,2.3038441e-05,10.630045,11.076152,22.47887,-9.4788208
3.3,0.8735255,0.0010135463,0.0,0,11.076097,9.8158808,3.8312657e-05,11.109911,11.076835,22.522526,-9.4827013
4.4,0.85706568,0.00066840509,0.0,0,11.076097,13.115884,8.189548e-05,10.897335,11.076513,22.556934,-9.4812841
5.5,0.80472565,0.00019302889,0.0,0,11.076097,16.415882,1.8138751e-05,10.241899,11.076649,22.581629,-9.4769068
6.6,0.7991969,0.00041831471,0.0,0,11.076097,19.715881,2.1763106e-05,10.169714,11.076447,22.561203,-9.4748011
7.7,0.80057198,0.00050772104,0.0,0,11.076097,23.015882,2.6737744e-05,10.188996,11.075759,22.490351,-9.4740343
8.8,0.79013014,0.00070435717,21.133978,0,11.076097,26.315886,1.8275448e-05,10.055359,11.076509,22.697079,-9.4722996
9.9,0.80267459,-0.00085195468,30.826973,0,11.076097,29.615885,-2.7182026e-05,10.221931,11.076565,24.402048,-9.4701738
11.0,0.8201921,-0.0038438886,35.012669,0,11.076097,32.915874,-0.00025334724,10.437431,11.076405,27.649069,-9.4688501
12.1,0.83026916,-0.0068561439,36.309811,0,11.076097,36.215878,-0.000476043,10.582467,11.076056,32.281239,-9.4666958
13.2,0.83732033,-0.010257441,35.49712,0,11.076097,39.515881,-0.00068250438,10.671933,11.076204,37.292717,-9.4648151
14.3,0.84121799,-0.012615757,34.650883,0,11.076097,42.815887,-0.00086030486,10.712406,11.07612,41.868954,-9.4634724
15.4,0.83768606,-0.015238946,33.771976,0,11.076097,46.115894,-0.00098661857,10.668505,11.075756,45.802082,-9.4618225
16.5,0.84433717,-0.017521858,33.771976,0,11.076097,49.415894,-0.001161061,10.769745,11.076211,49.40234,-9.4602156
17.6,0.83643436,-0.019768758,33.771976,0,11.076097,52.715893,-0.001340011,10.662053,11.076243,52.538204,-9.4582739
18.7,0.83666331,-0.022416446,34.64949,0,11.076097,56.015892,-0.0014730243,10.670671,11.076139,55.607922,-9.4563913
19.8,0.83766592,-0.024546832,34.650875,0,11.076097,59.315895,-0.0016489141,10.677207,11.075985,58.891926,-9.4543276
20.9,0.83420503,-0.027320812,35.477928,0,11.076097,62.615894,-0.0018074559,10.6365,11.076303,62.158161,-9.4523573
22.0,0.84120798,-0.029614629,35.129272,0,11.076097,65.915878,-0.0019782463,10.739132,11.075871,65.626266,-9.4508667
23.1,0.85082287,-0.031439599,35.496826,0,11.076097,69.215889,-0.0021260788,10.852799,11.075841,68.910378,-9.4491539
24.2,0.85744613,-0.034103073,35.496826,0,11.076097,72.515884,-0.0022476721,10.945964,11.076377,72.36821,-9.4477816
25.3,0.85985857,-0.036337178,35.496826,0,11.076097,75.815887,-0.0024309985,10.966518,11.07618,75.594818,-9.4459953
26.4,0.85886979,-0.038916338,35.520042,0,11.076097,79.115891,-0.0025737581,10.958851,11.076196,78.863365,-9.4440441
27.5,0.86326307,-0.04200327,36.309811,0,11.076097,82.415901,-0.0027924478,11.033713,11.076563,82.118706,-9.4420729
28.6,0.87450832,-0.043807775,36.309811,0,11.076097,85.715904,-0.0029466965,11.17004,11.075997,85.444099,-9.44065
29.7,0.86655003,-0.045996904,36.309811,0,11.076097,89.015892,-0.0030375989,11.066548,11.07604,88.819817,-9.4391041
30.8,0.86612302,-0.047726516,36.323437,0,11.076097,92.315895,-0.0031928374,11.058485,11.076214,92.070679,-9.4367008
31.9,0.84614873,-0.051271167,37.038712,0,11.076097,95.615891,-0.0033951621,10.80146,11.076675,95.303185,-9.4335661
33.0,0.8645137,-0.053252991,37.08984,0,11.076097,98.915894,-0.0035418626,11.042289,11.076602,98.586143,-9.4323483
34.1,0.87108964,-0.056007601,37.08984,0,11.076097,102.21588,-0.0037555622,11.126662,11.076508,101.90394,-9.4305401
35.2,0.87973762,-0.058840156,37.523273,0,11.076097,105.51588,-0.003903131,11.235789,11.075677,105.1322,-9.4287205
36.3,0.86819184,-0.061037771,37.5051,0,11.076097,108.81588,-0.004078126,11.080664,11.077038,108.63751,-9.4269476
37.4,0.88754982,-0.065036297,37.826706,0,11.076097,112.11588,-0.0043058549,11.346373,11.075985,111.95698,-9.4250374
38.5,0.89828438,-0.065779075,37.256481,0,11.076097,115.41589,-0.0043763439,11.495703,11.076538,115.35596,-9.4238281
39.6,0.89903319,-0.06850718,37.548466,0,11.076097,118.71588,-0.0045810044,11.502769,11.076031,118.63526,-9.4226437
40.7,0.89378548,-0.071473084,37.836914,0,11.076097,122.01589,-0.004729134,11.441419,11.07591,121.86098,-9.4209166
41.8,0.88796204,-0.074198343,37.86763,0,11.076097,125.31588,-0.0049453927,11.368897,11.076372,125.02253,-9.4191141
42.9,0.89724517,-0.076961346,38.551022,0,11.076097,128.616,-0.0050954041,11.481831,11.075871,128.28912,-9.4170265
44.0,0.90842372,-0.079369307,38.551022,0,11.076097,131.91591,-0.0052770618,11.628671,11.076454,131.62213,-9.4148951
45.1,0.91057605,-0.083128639,38.551022,0,11.076097,135.2159,-0.0055672405,11.654795,11.076127,135.04262,-9.4126511
46.2,0.91491824,-0.08430218,38.551022,0,11.076097,138.5159,-0.0055906414,11.714561,11.075518,138.31924,-9.4105616
47.3,0.90620476,-0.087257572,39.24316,0,11.076097,141.81589,-0.0058014137,11.593347,11.076811,141.29881,-9.4082251
48.4,0.91974968,-0.09055417,39.263943,0,11.076097,145.11591,-0.0059992876,11.787215,11.076131,144.6962,-9.40732
49.5,0.92623419,-0.093512252,39.246044,0,11.076097,148.41589,-0.0062137595,11.878871,11.076549,148.18935,-9.4057055
50.6,0.93527859,-0.097091019,39.243572,0,11.076097,151.71588,-0.0064774207,11.989019,11.076161,151.58463,-9.4038715
51.7,0.93849719,-0.098433204,39.710602,0,11.076097,155.0159,-0.0065206941,12.026777,11.075992,154.82758,-9.4025087
52.8,0.9342249,-0.10178287,39.617718,0,11.076097,158.31589,-0.0067758821,11.977864,11.076253,158.22298,-9.4004965
53.9,0.93711883,-0.10464235,39.5121,0,11.076097,161.61589,-0.0069240518,12.017096,11.076394,161.59207,-9.3985806
55.0,0.94316584,-0.10722146,39.918072,0,11.076097,164.91588,-0.0071049249,12.096904,11.076327,164.80038,-9.3965349
56.1,0.95175183,-0.11007009,39.916649,0,11.076097,168.21588,-0.0073375916,12.221683,11.077008,168.17212,-9.3944073
57.2,0.95030254,-0.11292425,39.913731,0,11.076097,171.51588,-0.0074851937,12.199395,11.076129,171.4709,-9.3924093
58.3,0.94512582,-0.11604267,39.924313,0,11.076097,174.81589,-0.007728999,12.132044,11.076134,174.6524,-9.3902197
59.4,0.955001,-0.11867283,39.924313,0,11.076097,178.11588,-0.0078629702,12.241501,11.077008,177.94112,-9.3890209
60.5,0.97298783,-0.12182906,40.369915,0,11.076097,181.41588,-0.0080798855,12.488396,11.076655,181.14102,-9.3877039
61.6,0.97150403,-0.12401512,39.243168,0,11.076097,184.7159,-0.0082421973,12.471801,11.076064,185.20679,-9.3858919
62.7,0.9675259,-0.12694217,39.923603,0,11.076097,188.0159,-0.0084342435,12.41992,11.076104,187.94444,-9.3840771
63.8,0.9725998,-0.12963876,40.572491,0,11.076097,191.3159,-0.0086365687,12.480761,11.076737,190.7789,-9.382618
64.9,0.981112,-0.13329265,41.194706,0,11.076097,194.61591,-0.0088179568,12.602237,11.076437,193.95334,-9.3802586
66.0,0.9818303,-0.13627756,41.198727,0,11.076097,197.91591,-0.0090288119,12.61177,11.076131,197.38171,-9.3787813
67.1,0.97361535,-0.13948791,40.900417,0,11.076097,201.2159,-0.0092639895,12.514501,11.075686,201.04546,-9.3763723
68.2,0.99157274,-0.14216936,41.189724,0,11.076097,204.51588,-0.0094399694,12.721928,11.076699,204.35886,-9.3744831
69.3,0.99948788,-0.14474148,41.19635,0,11.076097,207.8159,-0.0096376222,12.849538,11.07495,207.67476,-9.3723707
70.4,0.98352855,-0.14864522,41.198727,0,11.076097,211.11589,-0.0098288013,12.648859,11.075782,210.89317,-9.3704309
71.5,0.99085021,-0.15188758,41.338593,0,11.076097,214.41591,-0.010055001,12.74836,11.076744,214.06287,-9.3692932
72.6,1.0023078,-0.15591425,40.572624,0,11.076097,217.7159,-0.01035595,12.905079,11.077049,218.11099,-9.3674316
73.7,1.0054308,-0.15715578,40.988148,0,11.076097,221.0159,-0.010436645,12.933051,11.07565,221.14096,-9.3665504
74.8,0.96958441,-0.16073066,41.198727,0,11.076097,224.31589,-0.010688254,12.470425,11.07635,224.09563,-9.3634958
75.9,0.96337295,-0.16548036,41.802975,0,11.076097,227.61591,-0.010930746,12.4036,11.076151,227.22142,-9.3557644
77.0,0.97262537,-0.166684,41.802975,0,11.076097,230.91589,-0.011042786,12.521846,11.076488,230.58401,-9.353611
78.1,0.97961485,-0.17048776,41.802975,0,11.076097,234.2159,-0.011290743,12.619376,11.075964,233.99612,-9.3523378
79.2,0.99694645,-0.1731219,41.802982,0,11.076097,237.5159,-0.011475542,12.834743,11.0764,237.32858,-9.3508139
80.3,0.9990837,-0.17571327,42.086929,0,11.076097,240.8159,-0.011675929,12.883043,11.076156,240.60907,-9.3487434
81.4,1.0022458,-0.17980114,41.991055,0,11.076097,244.11591,-0.011890487,12.917102,11.076459,243.96326,-9.3465118
82.5,1.0100533,-0.18254413,41.970943,0,11.076097,247.41591,-0.01210736,13.009957,11.07705,247.35992,-9.3450212
83.6,1.0294141,-0.18543799,42.031509,0,11.076097,250.7159,-0.012272329,13.27511,11.076549,250.6774,-9.3434267
84.7,1.0207487,-0.18951364,41.980408,0,11.076097,254.0159,-0.012548874,13.154802,11.076122,253.97099,-9.3415098
85.8,1.013638,-0.19285093,42.307007,0,11.076097,257.31616,-0.012807408,13.058719,11.076193,257.24591,-9.3402424
86.9,1.0391324,-0.19543213,42.396236,0,11.076097,260.61618,-0.012934606,13.403246,11.075878,260.40103,-9.3388119
88.0,1.0236093,-0.19818611,42.644264,0,11.076097,263.91589,-0.013142441,13.215637,11.076153,263.62772,-9.3366623
89.1,1.0239534,-0.20259231,42.973877,0,11.076097,267.21591,-0.013380034,13.224349,11.076674,266.91367,-9.3354149
90.2,1.0420208,-0.20492685,42.926708,0,11.076097,270.5159,-0.013562127,13.454912,11.076292,270.345,-9.3332453
91.3,1.0390652,-0.2084423,42.906277,0,11.076097,273.81589,-0.013811003,13.411365,11.076578,273.69803,-9.3314247
92.4,1.0351883,-0.21192107,42.978512,0,11.076097,277.11591,-0.014050752,13.352273,11.076719,276.90588,-9.3293619
93.5,1.0514574,-0.21405874,42.978512,0,11.076097,280.41592,-0.01420881,13.592937,11.076427,280.13156,-9.3280058
94.6,1.0473974,-0.21871288,43.021652,0,11.076097,283.71591,-0.014441492,13.545771,11.075936,283.49072,-9.3265915
95.7,1.0587742,-0.22155866,42.98658,0,11.076097,287.0159,-0.014637564,13.674613,11.076974,286.85147,-9.3248854
96.8,1.0635753,-0.22426522,43.221989,0,11.076097,290.31589,-0.014844288,13.739438,11.076353,290.17773,-9.32302
97.9,1.0519843,-0.22876304,43.49065,0,11.076097,293.61588,-0.015145484,13.606043,11.076362,293.43619,-9.321476
99.0,1.0691345,-0.23346034,43.478443,0,11.076097,296.91589,-0.015477674,13.817966,11.076423,296.83612,-9.3201752
100.1,1.0508591,-0.23521057,42.993099,0,11.076097,299.99539,-0.0155246,13.605007,11.076443,300.146,-9.3180838
101.2,0.093985014,-0.25167188,38.371841,0,11.076097,299.99905,-0.016636232,1.2136626,11.076482,303.19962,-9.3180475
102.3,0.077245884,-0.25081894,35.212219,0,11.076097,299.99905,-0.016575878,1.0082273,11.075617,303.56042,-9.3183289
103.4,0.064646967,-0.2490015,38.48629,0,11.076097,299.99905,-0.016466415,0.83337981,11.076429,300.60266,-9.3181581
104.5,0.065322898,-0.2482668,42.32901,0,11.076097,299.99905,-0.016442662,0.83332705,11.076844,297.95047,-9.3179398
105.6,0.077952996,-0.24773298,44.604355,0,11.076097,299.99905,-0.016358245,1.0043447,11.075942,296.90875,-9.3181524
106.7,0.096163072,-0.24847242,45.535736,0,11.076097,299.99905,-0.016447499,1.2443386,11.076828,297.41159,-9.3183489
107.8,0.10936338,-0.24988507,44.620964,0,11.076097,299.99905,-0.016491909,1.4081886,11.075966,298.99142,-9.318593
108.9,0.11532635,-0.25016353,43.009216,0,11.076097,299.99905,-0.016534079,1.4930049,11.075772,300.51202,-9.3188953
110.0,0.10726032,-0.25108111,41.204723,0,11.076097,299.99905,-0.01660917,1.3767221,11.076715,301.55823,-9.3190641
111.1,0.10548729,-0.25093552,40.279102,0,11.076097,299.99905,-0.016605807,1.368718,11.076836,301.64883,-9.3188105
112.2,0.10265041,-0.25044927,39.92432,0,11.076097,299.99905,-0.01659368,1.3462583,11.076447,301.14859,-9.3192053
113.3,0.093711242,-0.25142017,40.572506,0,11.076097,299.99905,-0.016584275,1.2319545,11.076337,300.54529,-9.3191347
114.4,0.092748865,-0.25095931,41.086681,0,11.076097,299.99905,-0.016586253,1.1898416,11.077253,300.04111,-9.3190298
115.5,0.086962104,-0.25102746,41.390965,0,11.076097,299.99905,-0.0166017,1.1118772,11.076592,299.69379,-9.318902
116.6,0.091074876,-0.25172624,42.057976,0,11.076097,299.99905,-0.016652493,1.1907291,11.076164,299.42801,-9.3191338
117.7,0.10181148,-0.25177351,42.396236,0,11.076097,299.99905,-0.016675161,1.3184398,11.076054,299.5018,-9.3192301
118.8,0.11528708,-0.25226441,42.212563,0,11.076097,299.99905,-0.016650293,1.5111063,11.075902,299.7977,-9.3192987
119.9,0.10695883,-0.2524417,41.802982,0,11.076097,299.99905,-0.016685411,1.3792245,11.076755,300.08878,-9.3193588
121.0,0.11105066,-0.25311896,41.218651,0,11.076097,299.99905,-0.016718766,1.4442039,11.07622,300.30759,-9.320138
122.1,0.11696066,-0.2541227,41.198734,0,11.076097,299.99905,-0.01680279,1.5260472,11.076787,300.42166,-9.3201923
123.2,0.11206819,-0.25335389,41.01339,0,11.076097,299.99905,-0.016772319,1.4577415,11.076145,300.39246,-9.3201113
124.3,0.10905366,-0.25369546,40.598976,0,11.076097,299.99905,-0.016760729,1.4066415,11.077231,300.30618,-9.320179
125.4,0.11143526,-0.25374761,40.993771,0,11.076097,299.99905,-0.016798746,1.4276137,11.076992,300.18192,-9.3202791
126.5,0.115063,-0.25444019,40.728661,0,11.076097,299.99905,-0.016787471,1.495662,11.076699,300.15399,-9.3202438
127.6,0.10598532,-0.25426662,41.060112,0,11.076097,299.99905,-0.016798295,1.3854002,11.07634,300.03595,-9.3198614
128.7,0.11465293,-0.25477463,41.165146,0,11.076097,299.99905,-0.016853236,1.4928597,11.075964,300.00024,-9.3199148
129.8,0.11287936,-0.25496432,40.901062,0,11.076097,299.99905,-0.01686598,1.4481195,11.076971,300.04605,-9.3201427
130.9,0.12431911,-0.25531045,41.033569,0,11.076097,299.99905,-0.016908849,1.6198699,11.076325,299.98047,-9.3202868
132.0,0.11369324,-0.2553921,40.807949,0,11.076097,299.99905,-0.016849583,1.4597881,11.076338,300.02643,-9.3206348
133.1,0.11751746,-0.25584522,40.859528,0,11.076097,299.99905,-0.016906241,1.5224838,11.075347,300.0228,-9.3208714
134.2,0.1171462,-0.25656629,40.682377,0,11.076097,299.99905,-0.016952367,1.5205566,11.07582,300.06235,-9.3209553
135.3,0.11504463,-0.25674692,40.882847,0,11.076097,299.99905,-0.016986618,1.4828961,11.076383,299.99042,-9.3208828
136.4,0.11752703,-0.2579107,40.660675,0,11.076097,299.99905,-0.017076811,1.5212427,11.07608,300.08362,-9.3207846
137.5,0.11717363,-0.25701573,40.574261,0,11.076097,299.99905,-0.016972331,1.5125157,11.076025,300.00574,-9.3208046
138.6,0.1211098,-0.25717834,41.024147,0,11.076097,299.99905,-0.017020322,1.5854703,11.07602,299.94653,-9.3210573
139.7,0.11664972,-0.25836328,40.927319,0,11.076097,299.99905,-0.017053818,1.512859,11.076615,299.94919,-9.320941
140.8,0.11955871,-0.25814581,40.656338,0,11.076097,299.99905,-0.017051179,1.5558383,11.075959,300.01779,-9.3211689
141.9,0.11879001,-0.25858048,40.573959,0,11.076097,299.99905,-0.017100912,1.5313987,11.07573,300.09061,-9.3215322
143.0,0.11290943,-0.25906703,40.844128,0,11.076097,299.99905,-0.017121725,1.4604467,11.076276,299.92911,-9.3217249
144.1,0.11119912,-0.25929686,40.86013,0,11.076097,299.99905,-0.017169904,1.4428716,11.076932,299.93161,-9.3212423
145.13,0.13667583,-0.0059108618,40.579067,0,11.076097,299.99905,-0.00039501736,1.7345223,11.076617,300.05161,-9.3213444
145.2819,0.24461588,0.012957709,40.57251,0,11.076099,6.0844296e-10,0.00063280953,3.1674678,11.074596,300.12762,-9.3208733
145.2841,0.2309293,0.0046175276,40.57251,0,11.076099,6.0770028e-25,0.00049007079,2.8803418,11.077984,300.12088,-9.3208809
145.2863,0.25924277,0.0074021341,40.57251,0,11.076099,6.0695841999999995e-40,0.000466317,3.3808947,11.074595,300.11414,-9.3217163
145.2885,0.24568602,0.005671131,40.57251,0,11.076099,0.0,0.00062821759,3.2114708,11.078588,300.10736,-9.3208895
145.2907,0.23828082,0.012593749,33.269218,0,11.076099,0.0,0.000608765,2.9913065,11.076989,300.11166,-9.3210945
145.2929,0.2228429,0.0081438227,24.343262,0,11.076099,0.0,0.00077948952,2.863224,11.074698,300.11841,-9.3205681
145.2951,0.23742263,0.0095281787,15.417312,0,11.076099,0.0,0.00049078761,3.0806367,11.07448,300.12518,-9.3221798
145.2973,0.24426188,0.007724579,6.4913611,0,11.076099,0.0,0.000759558,3.1532879,11.07585,300.13193,-9.3219099
145.2995,0.25669077,0.013277431,0.0,0,11.076099,0.0,0.00052471075,3.1536651,11.074542,300.13315,-9.3214598
145.3017,0.26081476,0.0068481779,0.0,0,11.076099,0.0,0.00062087254,3.376929,11.075047,300.11966,-9.3208475
145.3039,0.25379577,0.0088106748,0.0,0,11.076099,0.0,0.00040117503,3.2643611,11.075126,300.10614,-9.3208694
145.3061,0.25470519,0.0068086381,0.0,0,11.076099,0.0,0.00068819558,3.313781,11.073053,300.09262,-9.3201284
145.3083,0.24913654,0.012013714,0.0,0,11.076099,0.0,0.00048131376,3.2551558,11.074419,300.07913,-9.3210773
145.3105,0.24623734,0.0071465163,0.0,0,11.076099,0.0,0.00067839096,3.1207695,11.075207,300.0607,-9.3212385
145.3127,0.25182644,0.0084179584,0.0,0,11.076099,0.0,0.00041418226,3.2472935,11.076221,300.04044,-9.3209009
145.3149,0.25605801,0.0070713623,0.0,0,11.076099,0.0,0.00074525876,3.229495,11.076893,300.02017,-9.3214588
145.3171,0.24597256,0.012580882,0.0,0,11.076099,0.0,0.00057702773,3.2060428,11.074736,299.99991,-9.3207169
145.3193,0.26406172,0.0073482064,0.0,0,11.076099,0.0,0.00073406147,3.3592932,11.07734,299.98578,-9.3207932
145.3215,0.26404464,0.0086728269,0.0,0,11.076099,0.0,0.00041565171,3.3762321,11.078088,299.9993,-9.3214464
145.3237,0.26169184,0.0071353065,0.0,0,11.076099,0.0,0.00070045696,3.2887137,11.080185,300.01282,-9.320878
145.3259,0.2586984,0.011003375,0.0,0,11.076099,0.0,0.00046042394,3.3058357,11.074891,300.02631,-9.3205862
145.3281,0.25955635,0.0071061957,0.0,0,11.076099,0.0,0.00065995811,3.2889369,11.082469,300.03983,-9.322053
145.3303,0.25152722,0.0098007312,0.0,0,11.063758,0.0,0.00046994412,3.2340569,11.077506,300.05334,-9.3214359
145.3325,0.2524586,0.008718323,0.0,0,10.735813,0.0,0.00083540863,3.3772097,11.077849,300.06683,-9.3208437
145.3347,0.27100655,0.012010209,0.0,0,10.404921,0.0,0.00056047388,3.4311068,11.072821,300.08035,-9.3210936
145.3369,0.28258479,0.0085658366,0.0,0,10.074029,0.0,0.00069755234,3.6237061,11.012209,300.09387,-9.3212576
145.3391,0.28640813,0.0089623565,0.0,0,9.7431355,0.0,0.00044890889,3.665765,10.830532,300.17728,-9.3218565
145.3413,0.29430017,0.0095123369,0.0,0,9.4141331,0.0,0.00082960288,3.8308301,10.523261,300.95938,-9.3214521
145.3435,0.26206321,0.013099018,0.0,0,9.0922289,0.0,0.00070369511,3.2910094,10.137486,301.74149,-9.3201685
145.3457,7.9552903,0.38378575,0.0,0,8.7703247,0.0,0.025480263,98.21769,9.7082071,302.52362,-9.3162384
145.3479,10.327063,0.75331414,0.0,0,8.4631872,0.0,0.051159173,124.54551,9.2296925,303.30573,-9.3153038
145.3501,11.081012,1.141266,0.0,0,8.1570358,0.0,0.079075366,129.71675,8.8145065,303.85284,-9.3127594
145.3523,11.344615,1.485266,0.0,0,7.8607702,0.0,0.10362391,130.40819,8.4851828,304.2041,-9.3134899
145.3545,11.956963,1.7452784,0.0,0,7.56949,0.0,0.12340464,134.20415,8.1931343,304.55539,-9.3127337
145.3567,12.189178,2.0302484,0.0,0,7.2837992,0.0,0.14473429,134.36201,7.9006,304.90665,-9.3129053
145.3589,12.502664,2.3009522,0.0,0,7.0067744,0.0,0.16644599,134.60753,7.6316719,305.25787,-9.3126945
145.3611,12.891481,2.5545075,0.0,0,6.7313623,0.0,0.1861209,136.18964,7.3712196,304.69193,-9.3137617
145.3633,13.174329,2.8078859,0.0,0,6.4677978,0.0,0.20707116,136.35324,7.111979,304.12598,-9.3134813
145.3655,13.526464,3.0681944,0.0,0,6.2042375,0.0,0.22834329,136.97954,6.8456826,303.56003,-9.3138809
145.3677,13.910324,3.3348258,0.0,0,5.951591,0.0,0.25123504,137.72691,6.5733457,302.99408,-9.3129864
145.3699,14.274396,3.6014972,0.0,0,5.7009234,0.0,0.27388486,138.13519,6.3079634,302.6731,-9.3132544
145.3721,14.685282,3.8646371,0.0,0,5.4572492,0.0,0.29756284,138.72581,6.0403924,302.64609,-9.3133106
145.3743,15.070601,4.1228948,0.0,0,5.2187696,0.0,0.32082167,139.13403,5.7731633,302.61905,-9.3133793
145.3765,15.4505,4.3829689,0.0,0,4.9838004,0.0,0.34533793,139.11058,5.5154891,302.59204,-9.3131294
145.3787,15.827971,4.6301837,0.0,0,4.7569804,0.0,0.3686032,139.29723,5.2583838,302.565,-9.3122683
145.3809,16.190128,4.872242,0.0,0,4.5305719,0.0,0.39242849,139.15329,5.0149312,300.30444,-9.3129759
145.3831,16.545191,5.1082082,0.0,0,4.3146982,0.0,0.41577074,138.93257,4.7798076,297.82062,-9.312562
145.3853,16.920904,5.3414917,0.0,0,4.0989218,0.0,0.43985692,138.75491,4.5485578,295.33676,-9.3127031
145.3875,17.315458,5.5598745,0.0,0,3.8911257,0.0,0.46255365,138.80334,4.3234601,292.85294,-9.3123341
145.3897,17.730003,5.7755551,0.0,0,3.6859097,0.0,0.48583895,138.8324,4.1057382,291.12988,-9.3125658
145.3919,18.150291,5.9853783,0.0,0,3.4855173,0.0,0.50877059,138.85474,3.8954439,290.7381,-9.3136816
145.3941,18.584517,6.1983743,0.0,0,3.2902894,0.0,0.53270453,138.86772,3.6920598,290.34628,-9.3130302
145.3963,19.030437,6.397356,0.0,0,3.0970592,0.0,0.55556548,139.00243,3.4844415,289.95447,-9.3122044
145.3985,19.487484,6.6020684,0.0,0,2.911335,0.0,0.57973653,138.91504,3.2838714,289.56268,-9.3123655
145.4007,19.979166,6.7979808,0.0,0,2.7256112,0.0,0.6032061,139.09181,3.0867925,290.08023,-9.3108912
145.4029,20.451586,6.9991689,0.0,0,2.5483842,0.0,0.62794715,138.85519,2.8926752,290.7998,-9.3115587
145.4051,20.953396,7.1831751,0.0,0,2.3717244,0.0,0.65153211,138.99319,2.6999595,291.51938,-9.3115292
145.4073,21.47274,7.3715463,0.0,0,2.2007973,0.0,0.67566496,139.07899,2.5192184,292.23895,-9.3112364
145.4095,22.021152,7.5488753,0.0,0,2.0327616,0.0,0.69932044,139.2567,2.3391433,292.27325,-9.3122253
145.4117,22.560255,7.7320404,0.0,0,1.8679335,0.0,0.72379345,139.24849,2.1584256,290.48044,-9.3101015
145.4139,23.126564,7.8965635,0.0,0,1.7080816,0.0,0.74715269,139.42757,1.9906484,288.68762,-9.3096333
145.4161,23.679344,8.0680838,0.0,0,1.5491617,0.0,0.77114379,139.36456,1.8238199,286.89481,-9.3101912
145.4183,24.268501,8.2306843,0.0,0,1.3970947,0.0,0.7955147,139.41602,1.6614318,285.10199,-9.3098946
145.4205,24.857243,8.4018545,0.0,0,1.2450306,0.0,0.82025564,139.30438,1.4975274,283.90213,-9.3098383
145.4227,25.458963,8.5488377,0.0,0,1.0992619,0.0,0.84379417,139.30145,1.3417869,282.92459,-9.3087788
145.4249,26.121325,8.7042627,0.0,0,0.95463383,0.0,0.86743593,139.64333,1.1878988,281.94705,-9.3085318
145.4271,26.808542,8.846796,0.0,0,0.81407094,0.0,0.89113992,139.9384,1.0397797,280.96951,-9.3076324
145.4293,27.538029,8.997426,0.0,0,0.67652696,0.0,0.91479099,140.3647,0.89358062,280.2894,-9.3079338
145.4315,28.267342,9.127429,0.0,0,0.54098368,0.0,0.9379521,140.8606,0.75734389,280.94733,-9.3072157
145.4337,29.078873,9.265811,0.0,0,0.41008362,0.0,0.9607957,141.57622,0.62191778,281.60529,-9.3065577
145.4359,29.600107,9.3874454,0.0,0,0.27942321,0.0,0.9834488,141.30898,0.48569369,282.26321,-9.3061275
145.4381,27.314646,9.4118032,0.0,0,0.15488999,0.0,0.98645669,129.74872,0.42515621,282.92117,-9.3081379
145.4403,26.330559,9.4023151,0.0,0,0.030413972,0.0,0.98653793,125.04504,0.3923094,284.74191,-9.3106508
145.4425,25.814877,9.4106817,0.0,0,-0.091734543,0.0,0.98637962,122.62365,0.36339605,287.22702,-9.312088
145.4447,25.670656,9.4083023,0.0,0,-0.21313053,0.0,0.98773664,121.7589,0.32811698,289.71213,-9.3117571
145.4469,25.845945,9.4220238,0.0,0,-0.33452654,0.0,0.98822546,122.47864,0.2733596,292.19724,-9.3120136
145.4491,25.950926,9.4207754,0.0,0,-0.45592254,0.0,0.98976445,122.77261,0.21362215,294.62827,-9.3104105
145.4513,25.99497,9.4296045,0.0,0,-0.57731855,0.0,0.98997414,122.95641,0.15592815,296.51862,-9.3119078
145.4535,25.921322,9.4314251,0.0,0,-0.69871449,0.0,0.99205035,122.3857,0.10418986,298.40897,-9.310894
145.4557,25.779713,9.4472971,0.0,0,-0.8201105,0.0,0.9925133,121.68673,0.057574484,300.29932,-9.3119888
145.4579,25.535128,9.4390268,0.0,0,-0.94150651,0.0,0.99306142,120.43166,0.023544462,302.18967,-9.3120413
145.4601,25.19729,9.4458513,0.0,0,-1.0629026,0.0,0.99289781,118.87767,0.0042685792,303.72409,-9.3125563
145.4623,24.713171,9.4427071,0.0,0,-0.8433212,300.0,0.9940151,116.50739,-0.0024793185,304.96198,-9.3132915
145.4645,24.172647,9.4543056,0.0,0,-0.42304215,300.0,0.9937548,113.9556,-0.00121541,306.19986,-9.3140593
145.4667,23.731285,9.4428301,0.0,0,-0.0027626567,300.0,0.99401528,111.87787,0.0049358364,307.43774,-9.3135672
145.4689,23.388262,9.4482841,0.0,0,0.4175162,300.0,0.99310863,110.31735,0.0075640236,308.48236,-9.3156433
145.4711,23.149155,9.4452972,0.0,0,0.83779532,300.0,0.99458927,109.01432,0.0061617638,309.18875,-9.3155775
145.4733,22.924919,9.4559612,0.0,0,1.2580752,300.0,0.99389368,108.06097,0.006614231,309.89517,-9.3156548
145.4755,22.162373,9.4429941,0.0,0,1.6783539,300.0,0.99394429,104.54431,0.021195911,310.60156,-9.3156967
145.4777,20.32502,9.4429369,0.0,0,2.0986328,300.0,0.99220657,96.164139,0.10375471,311.30798,-9.3166246
145.4799,16.979439,9.4301157,0.0,0,2.5189123,300.0,0.99196905,80.579124,0.2361411,312.0419,-9.3187256
145.4821,11.112382,9.4190674,0.0,0,2.9391916,300.0,0.98747391,53.690609,0.45686877,312.78195,-9.322648
145.4843,0.69365501,9.1842232,0.0,0,3.3594708,300.0,0.94907933,3.3685706,0.88854164,313.522,-9.3314123
145.4865,-0.33776811,8.9965811,0.0,0,3.7797496,300.0,0.91503805,-1.3499159,1.4995576,314.26205,-9.3305893
145.4887,-0.28508899,8.8156328,0.0,0,4.2000294,300.0,0.88775432,-1.6914927,2.219702,314.6553,-9.3317938
145.4909,0.20559585,8.6541958,0.0,0,4.6203084,300.0,0.85957778,0.98073775,2.8858163,314.12381,-9.3318462
145.4931,0.028961625,8.5536766,0.0,0,5.0405879,300.0,0.8455494,0.2671575,3.4129636,313.59232,-9.3308258
145.4953,-0.13127215,8.4807892,0.0,0,5.4608669,300.0,0.83285433,-0.62143874,3.8244636,313.06082,-9.3306913
145.4975,-0.067223728,8.4370127,0.0,0,5.8811464,300.0,0.82745981,-0.31654075,4.2068343,312.52933,-9.3301697
145.4997,-0.0089532658,8.4386902,0.0,0,6.3014255,300.0,0.82595086,-0.082276851,4.5885525,311.77768,-9.3271484
145.5019,0.05504882,8.4594507,0.0,0,6.721704,300.0,0.83081216,0.29887661,4.9808064,310.94342,-9.3269634
145.5041,0.030216195,8.5102301,0.0,0,7.141984,300.0,0.83686489,0.24355642,5.3856368,310.10919,-9.3247766
145.5063,-0.050711516,8.5762062,0.0,0,7.562263,300.0,0.84862334,-0.2236824,5.812098,309.27496,-9.325345
145.5085,-0.050878976,8.6705818,0.0,0,7.9825425,300.0,0.86179233,-0.25206807,6.2508445,308.51657,-9.3242264
145.5107,0.09883853,8.7709932,0.0,0,8.4028215,300.0,0.8794409,0.47637784,6.7036481,308.09943,-9.3243971
145.5129,0.011335446,8.9084816,0.0,0,8.8231001,300.0,0.90002882,0.13051811,7.1570926,307.68231,-9.3237286
145.5151,-0.046100732,9.0514393,0.0,0,9.2433796,300.0,0.92534053,-0.24604157,7.594192,307.2652,-9.3227549
145.5173,-0.059175134,9.2160683,0.0,0,9.6636591,300.0,0.95158046,-0.3511436,8.0212822,306.84808,-9.321557
145.5195,0.024349967,9.3854618,0.0,0,10.083939,300.0,0.98289967,0.07036037,8.45714,306.64932,-9.3211021
145.5217,0.11793978,9.3930569,0.0,0,10.504217,300.0,0.98426449,0.39917618,8.8863535,306.57532,-9.3217421
145.5239,-0.12477947,9.366498,0.0,0,10.924497,300.0,0.98132277,-0.48243719,9.3202848,306.50131,-9.3221769
145.5261,0.03455798,9.3640375,0.0,0,11.344775,300.0,0.97837102,0.082511455,9.7529821,306.42731,-9.3228331
145.5283,0.018567832,9.3956985,0.0,0,11.765055,300.0,0.98480445,0.10537492,10.185757,306.51663,-9.3219671
145.5305,0.040062699,9.415163,0.0,0,12.185334,300.0,0.98694187,0.21709505,10.622167,308.23883,-9.3212948
145.5327,-0.0018318059,9.4297361,0.0,0,12.605614,300.0,0.99107707,0.043518327,11.050349,309.96103,-9.3209476
145.5349,-0.098989777,9.4305859,0.0,0,13.025892,300.0,0.99020869,-0.48251429,11.478305,311.68323,-9.3216019
145.5371,-0.015187297,9.4143887,0.0,0,13.446172,300.0,0.98872381,-0.08926297,11.901699,313.40546,-9.3229446
145.5393,0.059370909,9.4128399,0.0,0,13.86645,300.0,0.98703456,0.28297263,12.319892,314.76437,-9.3235044
145.5415,0.064398706,9.4144487,0.0,0,14.286731,300.0,0.9885475,0.37249339,12.743073,315.82062,-9.3216372
145.5437,-0.051014356,9.4159069,0.0,0,14.707009,300.0,0.98754579,-0.19225809,13.168347,316.87686,-9.3195381
145.5459,-0.026440749,9.4141655,0.0,0,15.127289,300.0,0.98818791,-0.15959118,13.610058,317.93314,-9.3204851
145.5481,0.045339856,9.4104166,0.0,0,15.547567,300.0,0.98673064,0.2205281,14.053902,318.98935,-9.3208761
145.5503,0.024531813,9.419136,0.0,0,15.967847,300.0,0.98914325,0.16233979,14.486886,319.25754,-9.320837
145.5525,-0.013214774,9.4133711,0.0,0,16.388126,300.0,0.98733503,-0.062347788,14.915229,319.52573,-9.3208523
145.5547,-0.066919461,9.4143744,0.0,0,16.808407,300.0,0.98828018,-0.28611183,15.334665,319.79391,-9.3213654
145.5569,-0.010473772,9.411974,0.0,0,17.228685,300.0,0.98716068,-0.14091051,15.752422,320.0621,-9.3224201
145.5591,0.053713653,9.4166842,0.0,0,17.648966,300.0,0.9885996,0.27508307,16.164633,320.39148,-9.32055
145.5613,0.078582302,9.4138918,0.0,0,17.999975,300.0,0.98741794,0.40921557,16.584656,320.79431,-9.3192396
145.5635,-0.10622244,9.4159222,0.0,0,18.0,300.0,0.98826683,-0.45231587,16.999615,321.19711,-9.3194914
145.5657,-0.001608792,9.4128227,0.0,0,18.0,300.0,0.9874776,-0.024012338,17.403252,321.59995,-9.3208065
145.5679,0.020957215,9.4198723,0.0,0,18.0,300.0,0.98885816,0.066415571,17.765833,322.00275,-9.3209848
145.5701,-0.01287521,9.4131556,0.0,0,18.0,300.0,0.98768842,0.040589079,18.086796,320.77423,-9.3222771
145.5723,-0.02761253,9.4181528,0.0,0,18.0,300.0,0.98864233,-0.13495681,18.33285,319.3826,-9.3252602
145.5745,0.0069153234,9.4196768,0.0,0,18.0,300.0,0.98889321,0.033037513,18.496346,317.991,-9.3268309
145.5767,0.011791021,9.4318018,0.0,0,18.0,300.0,0.99068671,0.01780301,18.538992,316.59937,-9.3329716
145.5789,0.063382126,9.4315186,0.0,0,18.0,300.0,0.99108875,0.19241419,18.484329,315.44501,-9.339982
145.5811,0.1251705,9.4457111,0.0,0,18.0,300.0,0.99334985,0.6092447,18.36659,314.70581,-9.3515558
145.5833,0.052290127,9.4545231,0.0,0,18.0,300.0,0.99514234,0.28377378,18.233175,313.96661,-9.3652077
145.5855,-0.027713956,9.4789524,0.0,0,18.0,300.0,0.99907959,-0.050425187,18.123861,313.22742,-9.3792486
145.5877,-0.056263968,9.4907007,0.0,0,18.0,300.0,1.0017039,-0.25634071,18.060143,312.48822,-9.3970499
145.5899,-0.10949446,9.5134468,0.0,0,18.0,300.0,1.0053412,-0.44605821,18.045877,312.64005,-9.4158211
145.5921,-0.10081787,9.5268383,0.0,0,18.0,300.0,1.0085506,-0.50788558,18.048828,312.9899,-9.4355974
145.5943,-0.010117684,9.5513268,0.0,0,18.0,300.0,1.01205,-0.12334618,18.069342,313.33975,-9.4527473
145.5965,0.067411043,9.5577927,0.0,0,18.0,300.0,1.0142196,0.29142037,18.090836,313.68958,-9.4708738
145.5987,0.073831506,9.5773087,0.0,0,18.0,300.0,1.0170604,0.34025356,18.117756,314.25717,-9.4875536
145.6009,0.05936471,9.5898952,0.0,0,18.0,300.0,1.020305,0.30944538,18.139545,315.40533,-9.5047197
145.6031,0.026965387,9.6164589,0.0,0,18.0,300.0,1.0240356,0.16962317,18.149696,316.55353,-9.5193663
145.6053,-0.031545687,9.6254129,0.0,0,18.0,300.0,1.0268327,-0.063777253,18.161016,317.70172,-9.5336294
145.6075,-0.10446957,9.6449366,0.0,0,18.0,300.0,1.0293353,-0.44594118,18.159586,318.84991,-9.5508194
145.6097,-0.10951903,9.651247,0.0,0,18.0,300.0,1.0318666,-0.48719758,18.160543,319.80853,-9.5669374
145.6119,-0.024679875,9.6739521,0.0,0,18.0,300.0,1.0344299,-0.19213527,18.157434,320.69611,-9.5806293
145.6141,0.061958995,9.6795931,0.0,0,18.0,300.0,1.0373143,0.23371457,18.154181,321.58368,-9.5952501
145.6163,0.09954302,9.7033262,0.0,0,18.0,300.0,1.0401634,0.43374738,18.145975,322.47125,-9.6110201
145.6185,0.092066675,9.7126369,0.0,0,18.0,300.0,1.0436686,0.44345188,18.148266,323.00824,-9.6251192
145.6207,0.05503596,9.7410364,0.0,0,18.0,300.0,1.0468493,0.29421294,18.141075,321.96771,-9.641449
145.6229,-0.027253732,9.7440271,0.0,0,18.0,300.0,1.0493971,-0.04741947,18.143301,320.92715,-9.6572771
145.6251,-0.078108661,9.7663794,0.0,0,18.0,300.0,1.0520582,-0.30618459,18.136217,319.88663,-9.6734667
145.6273,-0.11052616,9.7769566,0.0,0,18.0,300.0,1.0559939,-0.48330477,18.129805,318.84607,-9.6880445
145.6295,-0.065869905,9.8022423,0.0,0,18.0,300.0,1.0584399,-0.33064193,18.126476,318.79199,-9.7040062
145.6317,0.027049901,9.8068256,0.0,0,18.0,300.0,1.0617019,0.029933516,18.122562,319.30154,-9.7210579
145.6339,0.10729524,9.8278761,0.0,0,18.0,300.0,1.0638115,0.42843476,18.124805,319.8111,-9.7362709
145.6361,0.11705064,9.8374109,0.0,0,18.0,300.0,1.0677803,0.50339198,18.124641,320.32065,-9.7530813
145.6383,0.077078655,9.8660803,0.0,0,18.0,300.0,1.0707718,0.34485331,18.116735,320.81998,-9.769207
145.6405,0.0086140102,9.8714809,0.0,0,18.0,300.0,1.0743182,0.09442801,18.117767,321.21686,-9.7860136
145.6427,-0.063404717,9.8940964,0.0,0,18.0,300.0,1.0765189,-0.25730857,18.117516,321.61377,-9.8012953
145.6449,-0.1114342,9.9048338,0.0,0,18.0,300.0,1.0810989,-0.4443289,18.119282,322.01065,-9.8164711
145.6471,-0.086714499,9.9312506,0.0,0,18.0,300.0,1.0834517,-0.4042843,18.11204,322.40756,-9.8307714
145.6493,-0.0049232189,9.9374266,0.0,0,18.0,300.0,1.0872808,-0.11761188,18.111494,322.23685,-9.8475647
145.6515,0.078360327,9.9544935,0.0,0,18.0,300.0,1.0887419,0.29089007,18.112562,321.5932,-9.8638659
145.6537,0.1130243,9.9647045,0.0,0,18.0,300.0,1.092924,0.4735198,18.109791,320.94952,-9.8794613
145.6559,0.082042873,9.9893208,0.0,0,18.0,300.0,1.094833,0.37710446,18.108868,320.30588,-9.895793
145.6581,0.016295193,9.9971428,0.0,0,18.0,300.0,1.099187,0.13994093,18.113968,319.66223,-9.9102316
145.6603,-0.044752929,10.021795,0.0,0,18.0,300.0,1.1019481,-0.12415198,18.110859,319.86337,-9.9253311
145.6625,-0.10047617,10.032504,0.0,0,18.0,300.0,1.1064515,-0.38043919,18.109764,320.06451,-9.9412251
145.6647,-0.10372682,10.055198,0.0,0,18.0,300.0,1.1081172,-0.47813326,18.108995,320.26566,-9.9591513
145.6669,-0.0495838,10.062531,0.0,0,18.0,300.0,1.1124076,-0.28975445,18.108402,320.4668,-9.9747734
145.6691,0.042626843,10.082376,0.0,0,18.0,300.0,1.1142212,0.11460146,18.107296,320.94223,-9.9895563
145.6713,0.10472672,10.094616,0.0,0,18.0,300.0,1.1188147,0.40326005,18.110241,321.7468,-10.00602
145.6735,0.11353902,10.113759,0.0,0,18.0,300.0,1.1202179,0.45904714,18.107555,322.55136,-10.021667
145.6757,0.041693624,10.123997,0.0,0,18.0,300.0,1.1249595,0.21357109,18.108198,323.35596,-10.037452
145.6779,-0.027620675,10.147022,0.0,0,18.0,300.0,1.1273245,-0.042110465,18.106936,324.16052,-10.052863
145.6801,-0.074624315,10.163363,0.0,0,18.0,300.0,1.1329802,-0.29241976,18.105623,324.94681,-10.069292
145.6823,-0.097442515,10.180078,0.0,0,18.0,300.0,1.1339552,-0.40395826,18.099794,325.73126,-10.085077
145.6845,-0.080920823,10.189452,0.0,0,18.0,300.0,1.1383537,-0.36496797,18.102972,326.51572,-10.101423
145.6867,-0.0038399219,10.205591,0.0,0,18.0,300.0,1.1396513,-0.080002308,18.101257,327.30017,-10.118379
145.6889,0.093886733,10.220462,0.0,0,18.0,300.0,1.1448201,0.35343599,18.10215,327.90662,-10.133554
145.6911,0.11058436,10.241388,0.0,0,18.0,300.0,1.1469547,0.45284185,18.095406,328.20163,-10.149247
145.6933,0.078814074,10.25512,0.0,0,18.0,300.0,1.1519595,0.34577921,18.097927,328.49664,-10.1647
145.6955,0.00082002627,10.272108,0.0,0,18.0,300.0,1.153358,0.04426739,18.100201,328.79166,-10.180791
145.6977,-0.075780421,10.287006,0.0,0,18.0,300.0,1.1587939,-0.23486264,18.097229,329.08667,-10.195962
145.6999,-0.087475792,10.303794,0.0,0,18.0,300.0,1.1602095,-0.36096594,18.091862,328.66302,-10.210916
145.7021,-0.093003899,10.316234,0.0,0,18.0,300.0,1.1649088,-0.37238613,18.094246,328.07971,-10.226586
145.7043,-0.022815581,10.334378,0.0,0,18.0,300.0,1.1668297,-0.13978195,18.091532,327.4964,-10.243432
145.7065,0.073675036,10.349919,0.0,0,18.0,300.0,1.1719803,0.23424764,18.091686,326.91309,-10.257916
145.7087,0.12166563,10.364465,0.0,0,18.0,300.0,1.1732761,0.449619,18.089205,326.51813,-10.274796
145.7109,0.1119805,10.378149,0.0,0,18.0,300.0,1.1778727,0.44667628,18.091974,326.6254,-10.289842
145.7131,0.037676048,10.394626,0.0,0,18.0,300.0,1.1802449,0.21456964,18.091768,326.7327,-10.305456
145.7153,-0.047332965,10.41719,0.0,0,18.0,300.0,1.1864709,-0.14124878,18.091576,326.83997,-10.322423
145.7175,-0.090280287,10.432034,0.0,0,18.0,300.0,1.188128,-0.35382015,18.091438,326.94724,-10.339198
145.7197,-0.081095718,10.444325,0.0,0,18.0,300.0,1.1920674,-0.32620895,18.087904,327.02527,-10.355535
145.7219,-0.052449662,10.458819,0.0,0,18.0,300.0,1.1944473,-0.24927583,18.090448,327.09232,-10.370509
145.7241,0.030595206,10.481252,0.0,0,18.0,300.0,1.2003169,0.052377321,18.086407,327.15936,-10.384905
145.7263,0.10794301,10.491056,0.0,0,18.0,300.0,1.2013113,0.3788726,18.086069,327.22641,-10.400998
145.7285,0.11592697,10.503613,0.0,0,18.0,300.0,1.205169,0.44945529,18.084915,327.0874,-10.417108
145.7307,0.062439501,10.519927,0.0,0,18.0,300.0,1.2077973,0.30994356,18.084112,326.02136,-10.43327
145.7329,-0.010957017,10.54596,0.0,0,18.0,300.0,1.2144998,-0.0021573957,18.087757,324.95529,-10.449861
145.7351,-0.085239761,10.558118,0.0,0,18.0,300.0,1.216735,-0.28264794,18.08589,323.88925,-10.465141
145.7373,-0.096845709,10.574792,0.0,0,18.0,300.0,1.2209179,-0.39436609,18.081964,322.82318,-10.482405
145.7395,-0.070427053,10.583574,0.0,0,18.0,300.0,1.2225432,-0.30765954,18.08379,322.28622,-10.498633
145.7417,0.0078193964,10.605438,0.0,0,18.0,300.0,1.2274953,-0.025454717,18.083973,322.05154,-10.512668
145.7439,0.070731103,10.613873,0.0,0,18.0,300.0,1.2293957,0.21740948,18.080751,321.81689,-10.527272
145.7461,0.12793854,10.633272,0.0,0,18.0,300.0,1.2340957,0.44164583,18.084192,321.58221,-10.543634
145.7483,0.092042319,10.645343,0.0,0,18.0,300.0,1.2369119,0.38534153,18.082256,321.36096,-10.559579
145.7505,0.009131344,10.668432,0.0,0,18.0,300.0,1.2417458,0.092719369,18.081682,321.2738,-10.576155
145.7527,-0.058351032,10.68082,0.0,0,18.0,300.0,1.2451866,-0.18215804,18.079388,321.18665,-10.593208
145.7549,-0.11143531,10.701912,0.0,0,18.0,300.0,1.2496068,-0.38371602,18.077728,321.09949,-10.609604
145.7571,-0.084555924,10.712104,0.0,0,18.0,300.0,1.2525966,-0.34220657,18.073334,321.01233,-10.625017
145.7593,-0.016817857,10.734571,0.0,0,18.0,300.0,1.2571206,-0.11263339,18.073908,320.96906,-10.641507
145.7615,0.055971004,10.742466,0.0,0,18.0,300.0,1.2597148,0.13997777,18.074774,320.96234,-10.656817
145.7637,0.10107421,10.760245,0.0,0,18.0,300.0,1.2631607,0.33715427,18.077068,320.95566,-10.672009
145.7659,0.10761324,10.769378,0.0,0,18.0,300.0,1.2660469,0.41132694,18.071266,320.94894,-10.686137
145.7681,0.04989069,10.795967,0.0,0,18.0,300.0,1.2712364,0.25143039,18.073389,320.94223,-10.702133
145.7703,-0.039246902,10.806476,0.0,0,18.0,300.0,1.2749326,-0.12417901,18.072336,321.06293,-10.717884
145.7725,-0.092984803,10.830509,0.0,0,18.0,300.0,1.2795066,-0.3237122,18.074018,321.18359,-10.733889
145.7747,-0.10511762,10.838081,0.0,0,18.0,300.0,1.2827921,-0.34914806,18.07542,321.30429,-10.74872
145.7769,-0.046472736,10.862184,0.0,0,18.0,300.0,1.2867577,-0.20019916,18.072287,321.42496,-10.764874
145.7791,0.026153862,10.865906,0.0,0,18.0,300.0,1.289559,0.054524846,18.071346,321.56393,-10.781199
145.7813,0.095221914,10.889344,0.0,0,18.0,300.0,1.2935309,0.31526381,18.069248,321.72485,-10.796768
145.7835,0.11432678,10.898717,0.0,0,18.0,300.0,1.2977531,0.39224058,18.069168,321.88577,-10.813067
145.7857,0.090647511,10.924256,0.0,0,18.0,300.0,1.3015555,0.32383776,18.071304,322.04669,-10.829041
145.7879,0.0013550367,10.931666,0.0,0,18.0,300.0,1.3057953,0.041103985,18.071033,322.20761,-10.844671
145.7901,-0.085080706,10.955968,0.0,0,18.0,300.0,1.3097212,-0.23513088,18.067724,322.58795,-10.860436
145.7923,-0.11369848,10.966787,0.0,0,18.0,300.0,1.3147658,-0.38007396,18.067387,322.99023,-10.876972
145.7945,-0.077004984,10.990355,0.0,0,18.0,300.0,1.317721,-0.29601178,18.070791,323.39252,-10.893345
145.7967,0.011601132,10.992973,0.0,0,18.0,300.0,1.3212442,-0.015995018,18.065945,323.7948,-10.91067
145.7989,0.07836464,11.013188,0.0,0,18.0,300.0,1.3239956,0.22558282,18.064754,324.19708,-10.925753
145.8011,0.11811895,11.024347,0.0,0,18.0,300.0,1.3294923,0.36643746,18.067362,324.59937,-10.940374
145.8033,0.10158887,11.050556,0.0,0,18.0,300.0,1.3326296,0.3525711,18.065365,325.00165,-10.957425
145.8055,0.031194394,11.05365,0.0,0,18.0,300.0,1.3367635,0.13777053,18.064713,325.40393,-10.971505
145.8077,-0.066902749,11.080035,0.0,0,18.0,300.0,1.3405573,-0.17612952,18.059349,325.80618,-10.987514
145.8099,-0.12192311,11.090508,0.0,0,18.0,300.0,1.3463426,-0.37708974,18.06374,326.00003,-11.003384
145.8121,-0.097357497,11.115287,0.0,0,18.0,300.0,1.3487784,-0.35167968,18.067041,326.14752,-11.019503
145.8143,-0.01045592,11.118338,0.0,0,18.0,300.0,1.3533894,-0.08655145,18.060854,326.29504,-11.036056
145.8165,0.056138154,11.141457,0.0,0,18.0,300.0,1.3563287,0.14700219,18.057735,326.44257,-11.05197
145.8187,0.11246669,11.152516,0.0,0,18.0,300.0,1.3623556,0.349868,18.061058,326.55899,-11.067613
145.8209,0.10861915,11.17402,0.0,0,18.0,300.0,1.3639514,0.35720211,18.058496,326.5925,-11.082625
145.8231,0.061243325,11.180142,0.0,0,18.0,300.0,1.3691602,0.2189635,18.06003,326.62604,-11.097703
145.8253,-0.029446585,11.202046,0.0,0,18.0,300.0,1.3720322,-0.027909074,18.057243,326.65955,-11.112251
145.8275,-0.096337661,11.217885,0.0,0,18.0,300.0,1.3794752,-0.26928025,18.057058,326.69305,-11.129067
145.8297,-0.11536754,11.244605,0.0,0,18.0,300.0,1.3827372,-0.37450379,18.063499,326.77536,-11.145229
145.8319,-0.05792309,11.247835,0.0,0,18.0,300.0,1.3873311,-0.23035574,18.059328,326.87592,-11.162333
145.8341,0.041272078,11.268233,0.0,0,18.0,300.0,1.3897054,0.06969244,18.055613,326.9765,-11.177907
145.8363,0.096485324,11.274071,0.0,0,18.0,300.0,1.3949382,0.27976432,18.057476,327.07709,-11.194337
145.8385,0.11051639,11.299262,0.0,0,18.0,300.0,1.3975474,0.34738135,18.05891,327.16913,-11.210315
145.8407,0.088234425,11.309805,0.0,0,18.0,300.0,1.4041377,0.2841574,18.056332,327.22275,-11.225092
145.8429,0.0031404565,11.330544,0.0,0,18.0,300.0,1.4062742,0.061376516,18.056679,327.27637,-11.240997
145.8451,-0.081106395,11.343907,0.0,0,18.0,300.0,1.4133067,-0.20539458,18.053589,327.33002,-11.255686
145.8473,-0.11119325,11.36628,0.0,0,18.0,300.0,1.4159355,-0.32462868,18.05588,327.38364,-11.272563
145.8495,-0.092192329,11.375033,0.0,0,18.0,300.0,1.4219459,-0.29238799,18.055941,327.45862,-11.29121
145.8517,0.011197787,11.393989,0.0,0,18.0,300.0,1.4239336,-0.029513244,18.051882,327.54578,-11.307029
145.8539,0.078729577,11.40552,0.0,0,18.0,300.0,1.430542,0.22756073,18.056108,327.63293,-11.320762
145.8561,0.10748138,11.425034,0.0,0,18.0,300.0,1.4320518,0.33086076,18.05431,327.72009,-11.335106
145.8583,0.094056495,11.436697,0.0,0,18.0,300.0,1.4388469,0.28659484,18.051758,327.82312,-11.349857
145.8605,0.041185278,11.456398,0.0,0,18.0,300.0,1.4414769,0.1475818,18.053093,328.08459,-11.366769
146.7608,0.010585108,11.562676,0.0,0,18.0,1.6216721e-10,1.4733975,0.034514055,18.002062,323.573,-11.480334
147.8608,0.011834571,11.562438,0.0,0,18.0,1.6196875e-25,1.473248,0.032560013,18.000412,314.18497,-11.479807
148.9608,0.0080570308,11.562379,0.0,0,18.0,1.617701e-40,1.4730445,0.020866489,18.000309,307.09625,-11.479778
150.0608,0.0054942854,11.561716,0.0,0,18.0,1.4012985e-45,1.4731345,0.014859589,17.999434,299.67148,-11.480701
151.1608,0.006377067,11.563338,0.0,0,18.0,1.4012985e-45,1.4735093,0.021786336,18.000025,293.29172,-11.481186
152.2608,0.0096180914,11.562601,0.0,0,18.0,1.4012985e-45,1.4735484,0.028330944,18.000774,286.61093,-11.480826
153.3608,0.010723696,11.563029,0.0,0,18.0,1.4012985e-45,1.4735863,0.033172462,18.000185,280.84341,-11.480826
154.4608,0.0056850719,11.562925,0.0,0,18.0,1.4012985e-45,1.4733399,0.011707481,18.000517,274.70816,-11.480404
155.5608,0.0033279608,11.563081,0.0,0,18.0,1.4012985e-45,1.4733689,0.011587744,18.000416,269.01062,-11.480548
156.6608,0.0036099092,11.56332,0.0,0,18.0,1.4012985e-45,1.4733331,0.012799376,17.999876,262.55609,-11.480359
157.7608,0.0096160695,11.563251,0.0,0,18.0,1.4012985e-45,1.4736837,0.029813396,18.000059,256.83194,-11.48068
158.8608,0.0082045859,11.56374,0.0,0,18.0,1.4012985e-45,1.4737033,0.023687083,17.999634,251.57689,-11.481003
159.9608,0.0050510918,11.563482,0.0,0,18.0,1.4012985e-45,1.4737555,0.014608992,18.00046,246.89601,-11.480817
161.0608,0.0031311617,11.563726,0.0,0,18.0,1.4012985e-45,1.4737313,0.0091346754,18.000803,241.17075,-11.480746
162.1608,0.0055265063,11.5637,0.0,0,18.0,1.4012985e-45,1.4735417,0.015842641,18.000381,236.54958,-11.480531
163.2608,0.0036095157,11.563365,0.0,0,18.0,1.4012985e-45,1.4734118,0.010796713,18.000341,230.87614,-11.480748
164.3608,0.0055281315,11.563664,0.0,0,18.0,1.4012985e-45,1.4734559,0.016458059,17.999977,225.88564,-11.480812
165.4608,0.0038009998,11.563339,0.0,0,18.0,1.4012985e-45,1.4737393,0.0077352873,17.999937,221.26413,-11.480464
166.5608,0.0010045507,11.564162,0.0,0,18.0,1.4012985e-45,1.4738791,0.0037850898,17.999876,216.65874,-11.481258
167.6608,0.0041010855,11.564444,0.0,0,18.0,1.4012985e-45,1.4740095,0.012573618,17.99905,212.48947,-11.481331
168.7608,0.0089744097,11.564782,0.0,0,18.0,1.4012985e-45,1.4739991,0.027247326,18.000151,208.26292,-11.481259
169.8608,0.0079978257,11.565228,0.0,0,18.0,1.4012985e-45,1.4739667,0.02010251,18.000771,203.73474,-11.481371
170.9608,0.0046336451,11.565211,0.0,0,18.0,1.4012985e-45,1.4739934,0.013558233,18.000229,199.53922,-11.481264
172.0608,0.0035362593,11.565764,0.0,0,18.0,1.4012985e-45,1.4740514,0.01425588,17.999981,195.52646,-11.481361
173.1608,0.0036442145,11.565117,0.0,0,18.0,1.4012985e-45,1.4742217,0.011617849,18.000093,191.32822,-11.48099
174.2608,0.0088712508,11.56522,0.0,0,18.0,1.4012985e-45,1.4741637,0.024994573,18.000551,187.51196,-11.481282
175.3608,0.0076912404,11.564784,0.0,0,18.0,1.4012985e-45,1.4741678,0.019782545,18.000563,183.35632,-11.481439
176.4608,0.0031644544,11.565596,0.0,0,18.0,1.4012985e-45,1.4743005,0.010606103,18.000723,179.55629,-11.481138
177.5608,0.0022934945,11.565872,0.0,0,18.0,1.4012985e-45,1.474214,0.0078810072,18.000357,175.79785,-11.481112
178.6608,0.004376424,11.566417,0.0,0,18.0,1.4012985e-45,1.4743136,0.014342695,18.000395,172.04607,-11.481441
179.7608,0.0061803656,11.566104,0.0,0,18.0,1.4012985e-45,1.474146,0.018629905,17.999811,168.46352,-11.481262
180.8608,0.0019379293,11.566907,0.0,0,18.0,1.4012985e-45,1.4747282,0.0034220843,17.99966,165.16905,-11.480949
181.9608,0.00082156225,11.566396,0.0,0,18.0,1.4012985e-45,1.4744236,0.0030145494,17.999821,161.90511,-11.48139
183.0608,0.00079071772,11.566969,0.0,0,18.0,1.4012985e-45,1.4747962,0.0065499321,18.000259,158.49051,-11.481333
184.1608,0.0042308928,11.5667,0.0,0,18.0,1.4012985e-45,1.4746574,0.014091494,18.000582,155.1264,-11.481587
185.2608,0.0041044257,11.567643,0.0,0,18.0,1.4012985e-45,1.4747559,0.010252842,17.999146,151.98486,-11.481498
186.3608,0.00078962586,11.56697,0.0,0,18.0,1.4012985e-45,1.4745153,0.00023940553,18.000706,149.10429,-11.481662
187.4608,-0.0015317819,11.567634,0.0,0,18.0,1.4012985e-45,1.4745609,-0.0040288046,18.00029,146.03943,-11.481875
188.5608,-0.00023649441,11.567873,0.0,0,18.0,1.4012985e-45,1.4748963,0.0038522878,17.999998,143.06804,-11.481663
189.6608,0.0038085703,11.567975,0.0,0,18.0,1.4012985e-45,1.4747893,0.011241089,18.000319,140.07249,-11.481782
190.7608,0.0035254341,11.568085,0.0,0,18.0,1.4012985e-45,1.475181,0.0096662007,17.999968,137.17209,-11.481807
191.8608,-0.0015262779,11.567961,0.0,0,18.0,1.4012985e-45,1.4750662,-0.003831658,17.999928,134.42616,-11.48187
192.9608,-0.00074211106,11.568747,0.0,0,18.0,1.4012985e-45,1.4752229,-0.0012055079,17.999842,131.65132,-11.481976
194.0608,0.001845076,11.568998,0.0,0,18.0,1.4012985e-45,1.4751937,0.0091527831,18.000275,128.92171,-11.481984
195.1608,0.0044686636,11.568858,0.0,0,18.0,1.4012985e-45,1.4750192,0.011637329,17.998951,126.76472,-11.48187
196.2608,0.0034021763,11.568941,0.0,0,18.0,1.4012985e-45,1.4751152,0.0083781639,17.999561,124.32011,-11.481951
197.3608,-0.0013154483,11.5697,0.0,0,18.0,1.4012985e-45,1.4751984,-0.0015421223,18.00013,121.85266,-11.481987
198.4608,-0.0024015475,11.568595,0.0,0,18.0,1.4012985e-45,1.4752429,-0.0060133971,17.999981,119.31422,-11.482143
199.5608,0.0017983899,11.569322,0.0,0,18.0,1.4012985e-45,1.4753467,0.0042397841,18.000467,116.94167,-11.481942
200.6608,0.0032747176,11.569651,0.0,0,18.0,1.4012985e-45,1.475545,0.0098328348,18.000387,114.7946,-11.482238
201.7608,0.00051715778,11.569619,0.0,0,18.0,1.4012985e-45,1.4754974,0.0012813446,17.999456,112.50569,-11.48233
202.8608,-0.002616267,11.570397,0.0,0,18.0,1.4012985e-45,1.4755375,-0.0082680099,18.000067,110.27654,-11.482171
203.9608,-0.0012321067,11.569983,0.0,0,18.0,1.4012985e-45,1.4753903,-0.0035916872,17.999853,108.29707,-11.482569
205.0608,0.0014298772,11.570846,0.0,0,18.0,1.4012985e-45,1.4754895,0.0070910025,17.999924,106.27654,-11.482154
205.8608,-1.0212711e-05,11.570616,0.0,0,18.0,1.4012985e-45,1.4755692,0.0020248438,18.000305,104.75116,-11.482359