File: raw data/testID_0216.csv
Time(sec),Force(kN),Jaw(mm),PowAngle(deg),Power(W),Pram,PTemp,Strain,Stress(MPa),Stroke(mm),TC1(C),wedge(mm)
0.0,0.95597833,-0.060997631,0.0,0,11.076097,0.0007772597,-0.0040724361,12.232128,11.075812,23.44495,-9.1156788
1.2,0.89476961,-0.0019907078,0.0,0,11.076097,3.5158999,-0.00012898039,11.394973,11.074892,23.417526,-9.4758692
2.4,0.86871821,-0.0022979355,0.0,0,11.076097,7.1159005,-0.00014023957,11.074496,11.076015,23.357967,-9.4738922
3.6,0.85334879,-0.0024025473,0.0,0,11.076097,10.715901,-0.00014951442,10.869752,11.075908,23.387281,-9.4727087
4.8,0.83153182,-0.0023628257,0.0,0,11.076097,14.315905,-0.00017054976,10.600112,11.075817,23.340433,-9.4705276
6.0,0.81620389,-0.0025738156,0.0,0,11.076097,17.915903,-0.00015202384,10.400017,11.076478,23.308537,-9.4686689
7.2,0.79794753,-0.0023633263,0.0,0,11.076097,21.515902,-0.00015862193,10.1655,11.075808,23.314222,-9.4661732
8.4,0.79477149,-0.0020854985,13.539942,0,11.076097,25.115904,-0.00015020654,10.115144,11.075134,23.253765,-9.4641361
9.6,0.78568983,-0.0022207317,31.742571,0,11.076097,28.715906,-0.00014233614,10.018297,11.076162,23.3253,-9.4621725
10.8,0.81778157,-0.0039341501,41.269192,0,11.076097,32.315907,-0.00025302739,10.408946,11.075537,23.869225,-9.4609957
12.0,0.82782131,-0.00746876,47.443661,0,11.076097,35.915905,-0.0004850252,10.549228,11.077125,25.330463,-9.4589949
13.2,0.84240878,-0.011879311,51.419109,0,11.076097,39.515903,-0.00081455108,10.745026,11.076608,27.650652,-9.4574156
14.4,0.86189753,-0.017808339,54.301723,0,11.076097,43.115906,-0.0011622531,10.97989,11.07607,30.756481,-9.4556274
15.6,0.87406343,-0.023926478,56.349422,0,11.076097,46.715908,-0.001592727,11.138512,11.076233,34.455898,-9.4531603
16.8,0.88864428,-0.029507052,57.624763,0,11.076097,50.31591,-0.0019741284,11.349442,11.076267,38.687778,-9.45117
18.0,0.91494524,-0.035277616,58.589317,0,11.076097,53.915909,-0.0023501671,11.683322,11.076474,43.337906,-9.449234
19.2,0.92199618,-0.040652677,59.05196,0,11.076097,57.515911,-0.0026956336,11.784434,11.075908,48.310581,-9.4473934
20.4,0.93782586,-0.046430383,59.106438,0,11.076097,61.11591,-0.0030761051,11.967754,11.076075,53.448284,-9.4455023
21.6,0.93764251,-0.052505419,59.069035,0,11.076097,64.715935,-0.0035135527,11.970076,11.076222,58.578762,-9.4437809
22.8,0.92958605,-0.05845046,58.595715,0,11.076097,68.315926,-0.0038724809,11.871858,11.075672,63.792305,-9.4415979
24.0,0.9252153,-0.063877054,58.303329,0,11.076097,71.915916,-0.0042457636,11.829948,11.077059,68.66629,-9.4398365
25.2,0.92293286,-0.068474658,57.581261,0,11.076097,75.51593,-0.0045697568,11.811806,11.07671,73.595047,-9.4379635
26.4,0.93419635,-0.073181063,56.987179,0,11.076097,79.115921,-0.0048714611,11.944646,11.07678,78.329437,-9.4357338
27.6,0.93151271,-0.077824719,56.426685,0,11.076097,82.715935,-0.0051676468,11.93149,11.076641,82.705727,-9.4342976
28.8,0.9314748,-0.081945382,56.01664,0,11.076097,86.315926,-0.0054385047,11.925658,11.076489,86.847275,-9.4324055
30.0,0.92719764,-0.085637942,55.535892,0,11.076097,89.915932,-0.0057117669,11.867995,11.076097,90.877563,-9.4307289
31.2,0.93497276,-0.089719705,55.239262,0,11.076097,93.515915,-0.005942231,11.988878,11.075297,94.544968,-9.4288244
32.4,0.9361614,-0.093469024,55.197308,0,11.076097,97.115936,-0.0062087001,12.001934,11.076847,98.05159,-9.426836
33.6,0.93289542,-0.097462051,55.239254,0,11.076097,100.71593,-0.0064905859,11.959806,11.07541,101.31052,-9.4246817
34.8,0.94109714,-0.10150992,55.535866,0,11.076097,104.31593,-0.0067326203,12.06168,11.075525,104.54273,-9.422513
36.0,0.93563122,-0.10527704,55.843506,0,11.076097,107.91593,-0.0070027453,11.976927,11.076312,107.66793,-9.4204741
37.2,0.94216824,-0.10897911,56.425713,0,11.076097,111.51592,-0.0072422852,12.088985,11.076159,110.73742,-9.418642
38.4,0.94489366,-0.11312194,57.026867,0,11.076097,115.11593,-0.0075255455,12.121602,11.076573,113.78707,-9.4165754
39.6,0.93879235,-0.11747614,57.746853,0,11.076097,118.71593,-0.0077908635,12.053797,11.076538,116.87996,-9.4146252
40.8,0.94452572,-0.12208629,58.337288,0,11.076097,122.31593,-0.0080900416,12.129156,11.075358,120.00321,-9.4126759
42.0,0.94467723,-0.12673031,59.034138,0,11.076097,125.91592,-0.0084316237,12.136609,11.075871,123.23548,-9.4109325
43.2,0.95168287,-0.13160847,59.589199,0,11.076097,129.51604,-0.0087196529,12.250565,11.077267,126.60788,-9.4092989
44.4,0.94806838,-0.13729693,60.084156,0,11.076097,133.11592,-0.009113797,12.18769,11.075188,129.96791,-9.4072886
45.6,0.9516812,-0.14342035,60.555454,0,11.076097,136.71593,-0.0095276516,12.237517,11.07675,133.63399,-9.4054565
46.8,0.94653249,-0.15011303,60.787346,0,11.076097,140.31592,-0.0099654468,12.17231,11.075986,137.28601,-9.4039221
48.0,0.94510531,-0.15551265,61.018063,0,11.076097,143.91592,-0.01029978,12.172088,11.075912,141.16043,-9.4018192
49.2,0.94796377,-0.15950602,61.234772,0,11.076097,147.51593,-0.010569899,12.209679,11.076217,145.09331,-9.4003658
50.4,0.94508493,-0.16379432,61.237843,0,11.076097,151.11592,-0.010879931,12.16068,11.07757,149.00153,-9.3982649
51.6,0.93960625,-0.16968584,61.333195,0,11.076097,154.71594,-0.011227112,12.106871,11.076061,152.87105,-9.3964319
52.8,0.94186378,-0.17473423,61.404438,0,11.076097,158.31593,-0.011572982,12.153356,11.076234,156.80328,-9.3944569
54.0,0.94292468,-0.17955314,61.468498,0,11.076097,161.91594,-0.011920813,12.143794,11.076392,160.49045,-9.3921318
55.2,0.95399046,-0.18460958,61.468498,0,11.076097,165.51595,-0.012215867,12.308556,11.076604,164.34543,-9.3905172
56.4,0.94261724,-0.18937947,61.468498,0,11.076097,169.11595,-0.012540209,12.145734,11.076442,168.22455,-9.3882351
57.6,0.95269626,-0.19330058,61.425598,0,11.076097,172.71594,-0.012807777,12.303144,11.075037,172.08522,-9.3863592
58.8,0.95111722,-0.19799791,61.269932,0,11.076097,176.31595,-0.013114022,12.270749,11.076234,175.86317,-9.3844204
60.0,0.95901048,-0.20455368,61.322472,0,11.076097,179.91594,-0.013539469,12.399763,11.075956,179.55142,-9.382205
61.2,0.95528662,-0.21071015,61.254559,0,11.076097,183.51596,-0.013928524,12.340646,11.076729,183.24748,-9.380393
62.4,0.95413262,-0.21378112,61.324955,0,11.076097,187.11595,-0.014161538,12.319794,11.076307,186.86702,-9.3785744
63.6,0.94946814,-0.21872172,61.47686,0,11.076097,190.71596,-0.014453581,12.26346,11.07644,190.23291,-9.3776445
64.8,0.9446013,-0.2233928,61.692947,0,11.076097,194.31595,-0.014768851,12.204273,11.075955,193.59535,-9.3754473
66.0,0.950831,-0.22761132,62.081223,0,11.076097,197.91597,-0.015081728,12.314467,11.07584,196.82843,-9.3735161
67.2,0.96091509,-0.23201871,62.336418,0,11.076097,201.51595,-0.015334229,12.412433,11.076882,200.28198,-9.3715439
68.4,0.95852292,-0.23716892,62.545162,0,11.076097,205.11597,-0.01569433,12.393028,11.076615,203.66792,-9.3695374
69.6,0.95589924,-0.24473895,62.861973,0,11.076097,208.71594,-0.016189562,12.356988,11.077116,207.16013,-9.3674135
70.8,0.95294565,-0.24864201,63.087254,0,11.076097,212.31598,-0.016448686,12.33291,11.0764,210.61061,-9.3657742
72.0,0.94967031,-0.25371328,63.356453,0,11.076097,215.91595,-0.016765591,12.297009,11.075166,214.16586,-9.3639498
73.2,0.94865656,-0.25838682,63.52475,0,11.076097,219.51596,-0.017071031,12.290447,11.075398,217.8092,-9.3621321
74.4,0.95301741,-0.26309463,63.577873,0,11.076097,223.11595,-0.017400587,12.362342,11.076643,221.53513,-9.3604183
75.6,0.95146644,-0.26793787,63.775627,0,11.076097,226.71597,-0.01768503,12.342801,11.076012,225.23451,-9.3581572
76.8,0.95990211,-0.27236873,63.917866,0,11.076097,230.31595,-0.017981054,12.442405,11.07656,228.89722,-9.3561764
78.0,0.96209162,-0.27873331,63.973385,0,11.076097,233.91599,-0.018438879,12.472219,11.075464,232.52763,-9.3538818
79.2,0.96263611,-0.28666478,63.976021,0,11.076097,237.51596,-0.018918291,12.483157,11.076043,236.33334,-9.3519869
80.4,0.96513134,-0.29006234,64.171127,0,11.076097,241.11597,-0.019151481,12.521095,11.077681,239.99867,-9.3500624
81.6,0.95282227,-0.29494879,64.171135,0,11.076097,244.71596,-0.019475004,12.362059,11.075581,243.71954,-9.3483067
82.8,0.95625281,-0.29970804,64.280533,0,11.076097,248.31596,-0.019788226,12.428407,11.076712,247.28925,-9.3465624
84.0,0.95079356,-0.30486387,64.462776,0,11.076097,251.91597,-0.020113906,12.349692,11.075652,250.83856,-9.3444004
85.2,0.95623469,-0.30951703,64.552292,0,11.076097,255.51598,-0.020406554,12.428921,11.077168,254.49512,-9.342886
86.4,0.9693346,-0.31624413,64.555656,0,11.076097,259.11621,-0.020884475,12.598948,11.075676,258.20844,-9.3411522
87.6,0.9612757,-0.32293594,64.672142,0,11.076097,262.716,-0.021271916,12.507436,11.076565,261.77267,-9.3392315
88.8,0.94684201,-0.32710165,64.742432,0,11.076097,266.31595,-0.021563185,12.325454,11.076425,265.45798,-9.3370991
90.0,0.96189767,-0.331801,64.80162,0,11.076097,269.91592,-0.021886753,12.521539,11.075896,269.07196,-9.3353033
91.2,0.96501404,-0.3366361,64.929192,0,11.076097,273.51596,-0.022177292,12.567843,11.075964,272.6962,-9.333477
92.4,0.96430629,-0.34197229,64.929192,0,11.076097,277.11594,-0.022551874,12.549497,11.076871,276.43033,-9.3309908
93.6,0.96499163,-0.35140541,64.929207,0,11.076097,280.71594,-0.023146953,12.595053,11.076006,280.0455,-9.3290224
94.8,0.96179974,-0.35402137,65.034538,0,11.076097,284.31598,-0.023342052,12.527813,11.075273,283.67117,-9.3275394
96.0,0.95978183,-0.3603313,65.109001,0,11.076097,287.91595,-0.023721734,12.518723,11.076468,287.33911,-9.3252077
97.2,0.96877885,-0.36511067,65.063683,0,11.076097,291.51596,-0.024037637,12.641433,11.075992,290.98087,-9.3228655
98.4,0.97405487,-0.37000442,65.115959,0,11.076097,295.11597,-0.02439284,12.723212,11.076957,294.58136,-9.321229
99.6,0.96902555,-0.37982801,65.115959,0,11.076097,298.71597,-0.024982821,12.648902,11.076444,298.33487,-9.3193045
100.8,0.95909876,-0.38356528,65.040466,0,11.076097,302.31598,-0.025235143,12.529683,11.076559,302.11819,-9.3175697
102.0,0.96173924,-0.38891721,64.969597,0,11.076097,305.91599,-0.025605343,12.577491,11.076036,305.84274,-9.3157749
103.2,0.96354133,-0.39304027,64.929237,0,11.076097,309.51599,-0.025871953,12.585799,11.076382,309.53104,-9.3135033
104.4,0.97565472,-0.40340686,65.009369,0,11.076097,313.11597,-0.026527761,12.749323,11.076609,313.09518,-9.3118353
105.6,0.95877355,-0.40654281,64.829353,0,11.076097,316.71597,-0.026742605,12.552417,11.076956,316.90143,-9.3099947
106.8,0.96544755,-0.41183621,64.742851,0,11.076097,320.31598,-0.027091656,12.638192,11.077032,320.59824,-9.3084297
108.0,0.97417432,-0.41651732,64.669975,0,11.076097,323.91599,-0.027363859,12.749397,11.07625,324.3602,-9.306325
109.2,0.97443652,-0.42761558,64.424667,0,11.076097,327.51596,-0.028098287,12.762551,11.075635,328.28638,-9.304328
110.4,0.9570961,-0.43035242,64.354828,0,11.076097,331.116,-0.028306635,12.543084,11.076382,331.97971,-9.3023062
111.6,0.9656986,-0.43612105,64.17115,0,11.076097,334.71597,-0.02864005,12.663262,11.076117,335.64957,-9.3003435
112.8,0.97203797,-0.43985313,63.974979,0,11.076097,338.31601,-0.028890662,12.748929,11.076796,339.28949,-9.2982454
114.0,0.98522168,-0.44761637,63.973553,0,11.076097,341.91599,-0.029432718,12.914189,11.076726,342.71439,-9.2962103
115.2,0.98154223,-0.4541705,64.020172,0,11.076097,345.51602,-0.029799715,12.878339,11.076513,346.14063,-9.2938013
116.4,0.9627918,-0.45973688,63.944778,0,11.076097,349.116,-0.030179862,12.647158,11.076299,349.80109,-9.2916708
117.6,0.96752012,-0.46456969,63.775642,0,11.076097,352.716,-0.030510807,12.711531,11.076344,353.62036,-9.2900591
118.8,0.97674406,-0.46966293,63.606644,0,11.076097,356.31601,-0.030834354,12.830444,11.076414,357.17148,-9.2875519
120.0,0.98214787,-0.47366673,63.577888,0,11.076097,359.91602,-0.031074418,12.914246,11.076075,360.72852,-9.2857485
121.2,0.98777765,-0.47818881,63.369152,0,11.076097,363.51599,-0.031383701,12.984046,11.076984,364.44632,-9.2841759
122.4,0.99390185,-0.485796,63.265053,0,11.076097,367.116,-0.031909782,13.067143,11.076137,368.0867,-9.2821684
123.6,0.98607266,-0.49391356,63.557308,0,11.076097,370.716,-0.032396805,12.955991,11.076217,371.01047,-9.2798338
124.8,0.98012233,-0.50114292,64.550735,0,11.076097,374.31601,-0.032864485,12.881844,11.076244,372.92123,-9.2776995
126.0,0.98881322,-0.509179,66.672195,0,11.076097,377.91602,-0.033401705,13.003763,11.0764,372.79935,-9.275856
127.2,0.98664987,-0.51915085,68.825226,0,11.076097,381.51605,-0.034021627,12.994378,11.077819,373.08884,-9.273922
128.4,0.99101406,-0.52649689,69.57637,0,11.076097,385.116,-0.034512851,13.041097,11.075974,376.83362,-9.2720089
129.6,0.96891099,-0.52535641,68.613022,0,11.076097,388.716,-0.03447761,12.764263,11.075815,384.04489,-9.2703171
130.8,0.9155587,-0.51727235,65.55323,0,11.076097,392.31601,-0.033908524,12.065078,11.075469,394.45111,-9.2680759
132.0,0.84670693,-0.50695819,60.513454,0,11.076097,395.91599,-0.033230394,11.148458,11.076956,405.61774,-9.2664881
133.2,0.8053779,-0.49377194,53.892342,0,11.076097,399.51599,-0.032399297,10.610055,11.075796,415.14984,-9.264761
134.4,0.015476197,-0.50075072,44.180477,0,11.076097,399.99893,-0.032822203,0.21600689,11.076972,420.37054,-9.2641668
135.6,0.00064165384,-0.49374914,39.250771,0,11.076097,399.99893,-0.032389987,0.0090943556,11.076019,419.25137,-9.2639627
136.8,-0.0074600466,-0.48814023,40.506809,0,11.076097,399.99893,-0.032033361,-0.078213021,11.075704,415.06842,-9.2633829
138.0,-0.012177992,-0.48486885,44.633484,0,11.076097,399.99893,-0.031810295,-0.16975036,11.074813,409.95071,-9.2637577
139.2,-0.017887294,-0.48119885,49.578606,0,11.076097,399.99893,-0.031574409,-0.22323133,11.076859,404.73407,-9.2634983
140.4,-0.01586045,-0.47868717,54.337666,0,11.076097,399.99893,-0.03142843,-0.21309406,11.076255,399.40695,-9.2635345
141.6,-0.023689181,-0.47683948,59.028252,0,11.076097,399.99893,-0.031293504,-0.30569094,11.077668,394.30453,-9.2639332
142.8,-0.017726013,-0.47582254,63.07563,0,11.076097,399.99893,-0.031224411,-0.21420403,11.077369,389.41818,-9.2639122
144.0,-0.022626143,-0.47471547,66.841301,0,11.076097,399.99893,-0.031156352,-0.30349943,11.076645,384.91119,-9.2641163
145.2,-0.017434968,-0.47421131,70.238083,0,11.076097,399.99893,-0.03112717,-0.2153641,11.075937,380.54929,-9.2637529
146.4,-0.016659036,-0.47345302,73.355896,0,11.076097,399.99893,-0.031070115,-0.21808732,11.077324,376.46765,-9.2639332
147.6,-0.021276889,-0.47325337,76.198845,0,11.076097,399.99893,-0.031068057,-0.27286214,11.074851,372.69513,-9.26369
148.8,-0.016515085,-0.47299471,78.810127,0,11.076097,399.99893,-0.03105003,-0.22133172,11.076735,369.06909,-9.2635612
150.0,-0.023189235,-0.47276622,81.307388,0,11.076097,399.99893,-0.031024385,-0.30116484,11.076441,365.48984,-9.263463
151.2,-0.019250371,-0.47233182,83.616463,0,11.076097,399.99893,-0.030998746,-0.26014009,11.076209,362.026,-9.2633123
152.4,-0.022692638,-0.471825,85.844109,0,11.076097,399.99893,-0.030979693,-0.30326399,11.076185,358.43701,-9.2634859
153.6,-0.023202132,-0.47110477,87.943771,0,11.076097,399.99893,-0.030917786,-0.29510808,11.077133,354.96716,-9.2638426
154.8,-0.019521335,-0.47089726,89.97451,0,11.076097,399.99893,-0.030906903,-0.26691145,11.076203,351.32922,-9.2637234
156.0,-0.027072951,-0.47048181,91.475067,0,11.076097,399.99893,-0.030894591,-0.36306709,11.076412,347.70728,-9.2638445
157.2,-0.021047536,-0.4698934,91.92067,0,11.076097,399.99893,-0.0308278,-0.26488051,11.076341,344.35913,-9.2641544
158.4,-0.026901376,-0.46955022,92.38961,0,11.076097,399.99893,-0.030813292,-0.34353521,11.077006,340.99585,-9.2639017
159.6,0.58254027,-0.3264522,74.681938,0,11.076097,399.99893,-0.021541465,7.5926824,11.076194,338.93741,-9.2639465
160.8,0.67908102,-0.359005,75.304581,0,11.076097,399.99893,-0.023636257,8.8468561,11.076915,343.14389,-9.2636528
162.0,0.74978393,-0.39268759,75.656395,0,11.076097,399.99893,-0.025812319,9.7969494,11.076744,352.55698,-9.2641325
163.2,0.7693662,-0.42314568,74.542679,0,11.076097,399.99893,-0.027835896,10.066122,11.076104,364.4494,-9.2635851
164.4,0.77733058,-0.43974712,72.172325,0,11.076097,399.99893,-0.028908044,10.188697,11.075799,377.22415,-9.2638798
165.6,0.77812976,-0.44968793,68.751808,0,11.076097,399.99893,-0.029544851,10.199888,11.076642,389.13974,-9.263586
166.8,0.77388608,-0.45612511,64.326309,0,11.076097,399.99893,-0.02997018,10.163631,11.076705,399.53677,-9.2636671
168.0,0.75011963,-0.45870504,58.652851,0,11.076097,399.99893,-0.030098075,9.85044,11.075919,407.81219,-9.2636299
169.2,0.71203536,-0.45628837,51.724804,0,11.076097,399.99893,-0.029953146,9.3500156,11.076726,413.71671,-9.2637539
170.4,0.66942728,-0.44874224,44.697788,0,11.076097,399.99893,-0.029483955,8.7848873,11.075934,416.45023,-9.2637281
171.6,0.64471334,-0.43915567,39.947174,0,11.076097,399.99893,-0.028834224,8.4483671,11.076021,416.09323,-9.2632933
172.8,0.63353229,-0.42935154,38.551029,0,11.076097,399.99893,-0.028199436,8.2952271,11.077019,413.73798,-9.2630148
174.0,0.62885773,-0.4221088,40.572365,0,11.076097,399.99893,-0.027773567,8.2265673,11.076107,410.23334,-9.2632513
175.2,0.6289342,-0.41799751,43.863323,0,11.076097,399.99893,-0.027462868,8.2207632,11.076437,406.61276,-9.2634211
176.4,0.63436145,-0.41581964,46.799095,0,11.076097,399.99893,-0.027337085,8.2942181,11.076332,403.54086,-9.2636557
177.6,0.63951844,-0.41512886,48.811649,0,11.076097,399.99893,-0.027316188,8.3661747,11.075539,401.40417,-9.2634764
178.614,0.53391546,0.014452427,50.438232,0,11.076099,65.880898,0.0012016911,6.7735085,11.072174,400.06064,-9.2646646
178.6164,0.71229368,0.011598714,50.438232,0,11.076099,2.8482205e-15,0.0010692148,9.0544758,11.076248,400.06064,-9.2639904
178.6188,0.66364312,0.0098919421,50.438232,0,11.076099,1.2312851e-31,0.00074355159,8.4517269,11.072993,400.06064,-9.2644272
178.6212,0.65444106,0.011619883,41.863628,0,11.076099,0.0,0.0006264369,8.2454977,11.071457,400.06064,-9.2643061
178.6236,0.74138826,0.015413253,29.758455,0,11.076099,0.0,0.0007989342,9.1720057,11.080873,400.06064,-9.2636538
178.626,0.62158334,0.012037477,17.653278,0,11.076099,0.0,0.00087720738,7.9017463,11.071532,400.06064,-9.2642822
178.6284,0.64614838,0.011045606,5.5481009,0,11.076099,0.0,0.0010043158,8.2159624,11.076121,400.06064,-9.2636137
178.6308,0.65112489,0.010154902,0.0,0,11.076099,0.0,0.00073524303,8.3266201,11.076441,400.05283,-9.2635422
178.6332,0.64003402,0.014030267,0.0,0,11.076099,0.0,0.00061928894,8.2525454,11.071875,400.03836,-9.263938
178.6356,0.63805407,0.016030395,0.0,0,11.076099,0.0,0.00081216829,8.0851316,11.073154,400.0239,-9.2638769
178.638,0.63787502,0.014132507,0.0,0,11.076099,0.0,0.00094363879,8.0801048,11.075831,400.00946,-9.2636795
178.6404,0.63458079,0.0098821083,0.0,0,11.076099,0.0,0.00098599168,8.0494375,11.071417,399.99503,-9.2645426
178.6428,0.63904011,0.010000554,0.0,0,11.076099,0.0,0.00072910415,8.1280775,11.075742,399.98056,-9.2641945
178.6452,0.63875932,0.011488356,0.0,0,11.076099,0.0,0.00056915573,8.0149422,11.077563,399.96613,-9.2641697
178.6476,0.63092911,0.012261487,0.0,0,11.076099,0.0,0.00069503154,8.0104523,11.075589,399.95169,-9.263629
178.65,0.62700212,0.011342033,0.0,0,11.076099,0.0,0.00076711376,8.0234127,11.074576,399.94327,-9.2628546
178.6524,0.62908596,0.0083991671,0.0,0,11.076099,0.0,0.00081968709,8.0159073,11.075917,399.9577,-9.263649
178.6548,0.61236453,0.0095348759,0.0,0,11.076099,0.0,0.00071644475,7.815784,11.0792,399.97214,-9.2632132
178.6572,0.61847168,0.014603273,0.0,0,11.076099,0.0,0.00073984696,7.7737136,11.076187,399.98657,-9.2640581
178.6596,0.62164778,0.017660826,0.0,0,11.076099,0.0,0.00080160605,7.8936491,11.076688,400.00134,-9.2642336
178.662,0.6272229,0.015141393,0.0,0,11.076099,0.0,0.0010848223,7.943954,11.081163,400.02301,-9.2639303
178.6644,0.63368511,0.011478117,0.0,0,11.006544,0.0,0.0010601026,8.0092068,11.07563,400.04468,-9.2643147
178.6668,0.62177193,0.0085136127,0.0,0,10.645576,0.0,0.00065937848,7.9002914,11.078068,400.06638,-9.2646828
178.6692,0.61806029,0.0092570055,0.0,0,10.284603,0.0,0.00045037962,7.9482484,11.063355,400.08804,-9.2629137
178.6716,0.65340543,0.011395003,0.0,0,9.9236288,0.0,0.00062741514,8.1762228,10.940957,397.78482,-9.2628622
178.674,0.61551809,0.012622959,0.0,0,9.5626554,0.0,0.00087369949,7.8302603,10.666748,395.14948,-9.2633848
178.6764,0.65710396,0.0098603675,0.0,0,9.2092905,0.0,0.00087865011,8.3636608,10.289003,392.51413,-9.263917
178.6788,3.7021449,0.2773028,0.0,0,8.8581219,0.0,0.017807528,46.889599,9.8657923,389.87878,-9.260582
178.6812,4.0878639,0.72843379,0.0,0,8.518857,0.0,0.049477305,49.185032,9.3566132,398.61914,-9.2617149
178.6836,4.2205925,1.179498,0.0,0,8.1848736,0.0,0.081137724,49.485237,8.9025793,412.04346,-9.2606363
178.686,4.1865664,1.5762941,0.0,0,7.8607755,0.0,0.11042086,47.735855,8.5249786,425.46774,-9.2609167
178.6884,4.4160671,1.8905821,0.0,0,7.543015,0.0,0.13462082,49.117844,8.1726189,438.89203,-9.259407
178.6908,4.3920751,2.1968956,0.0,0,7.2334356,0.0,0.15824403,47.603519,7.8414516,455.51166,-9.2608452
178.6932,4.5335393,2.5083544,0.0,0,6.9312277,0.0,0.18239002,48.15229,7.5385017,474.83493,-9.2593994
178.6956,4.602828,2.8001647,0.0,0,6.6355219,0.0,0.20597431,47.582176,7.2492647,494.15823,-9.2603674
178.698,4.7551255,3.0853033,0.0,0,6.3480015,0.0,0.22979303,48.041245,6.9541521,513.48151,-9.2603569
178.7004,4.8169894,3.3742149,0.0,0,6.065536,0.0,0.25472039,47.542915,6.6591887,526.9165,-9.2610073
178.7028,5.0025983,3.6695189,0.0,0,5.792079,0.0,0.28038284,48.078018,6.3653388,530.53796,-9.2600365
178.7052,5.1156659,3.9640424,0.0,0,5.5222936,0.0,0.3062914,47.857681,6.0733972,534.15948,-9.2590752
178.7076,5.2240338,4.2563858,0.0,0,5.2621331,0.0,0.33275446,47.635571,5.7833548,537.78094,-9.261076
178.71,5.3272443,4.5367007,0.0,0,5.0044241,0.0,0.35957268,47.354008,5.4998999,540.7926,-9.2603397
178.7124,5.4515128,4.8012085,0.0,0,4.7569842,0.0,0.38581908,47.169163,5.2269874,541.48694,-9.2604723
178.7148,5.5684657,5.0631166,0.0,0,4.5108657,0.0,0.41169775,46.971649,4.9650273,542.18127,-9.2603416
178.7172,5.719769,5.3191471,0.0,0,4.2754698,0.0,0.43723246,47.039627,4.7090268,542.87555,-9.2602062
178.7196,5.7995486,5.5714226,0.0,0,4.0404716,0.0,0.46334067,46.469116,4.460813,543.54095,-9.2590637
178.722,5.9499502,5.8104267,0.0,0,3.8165054,0.0,0.4894118,46.453224,4.2201638,543.54095,-9.2603836
178.7244,6.1289883,6.0431585,0.0,0,3.5926332,0.0,0.51577079,46.533718,3.9847071,543.54095,-9.2613831
178.7268,6.2889333,6.2722158,0.0,0,3.3790326,0.0,0.5415321,46.590248,3.7564936,543.54095,-9.2603188
178.7292,6.4598536,6.5005612,0.0,0,3.1660566,0.0,0.56731546,46.644497,3.5295348,543.54095,-9.2591934
178.7316,6.6185007,6.7306285,0.0,0,2.9619906,0.0,0.59422576,46.51173,3.3095369,543.00232,-9.2597551
178.734,6.8252573,6.9492087,0.0,0,2.7593822,0.0,0.62134206,46.648338,3.0913441,542.38672,-9.2596483
178.7364,7.0614142,7.1550412,0.0,0,2.5644474,0.0,0.64832091,46.968246,2.8775139,541.77112,-9.2600298
178.7388,7.2849956,7.3578439,0.0,0,2.3717272,0.0,0.67473364,47.216915,2.673723,541.15558,-9.2598257
178.7412,7.4866643,7.5610113,0.0,0,2.1855242,0.0,0.70071113,47.246521,2.4682028,537.94928,-9.2588129
178.7436,7.7368288,7.7585211,0.0,0,2.0022123,0.0,0.72699326,47.613758,2.2793674,533.67633,-9.2589302
178.746,7.9899726,7.9482751,0.0,0,1.8243403,0.0,0.75406533,47.854321,2.0904586,529.40338,-9.2590132
178.7484,8.2914066,8.127491,0.0,0,1.6499563,0.0,0.78070587,48.281986,1.9040329,525.13043,-9.2572584
178.7508,8.5600815,8.3019018,0.0,0,1.4800413,0.0,0.80652374,48.654335,1.731061,519.94562,-9.2580757
178.7532,8.8674631,8.4802036,0.0,0,1.3141534,0.0,0.8324911,49.063839,1.5623887,513.98938,-9.2587004
178.7556,9.1972752,8.6541166,0.0,0,1.1518564,0.0,0.85861081,49.581959,1.3923901,508.03308,-9.2574224
178.758,9.6250057,8.8223038,0.0,0,0.99408036,0.0,0.88596874,50.456791,1.2185527,502.07681,-9.2577953
178.7604,10.024717,8.9839602,0.0,0,0.83908135,0.0,0.91407859,51.144249,1.0571415,497.55646,-9.2573128
178.7628,10.430053,9.1433735,0.0,0,0.68903339,0.0,0.94116402,51.788803,0.88783354,495.42917,-9.2573462
178.7652,10.888169,9.3029976,0.0,0,0.54098594,0.0,0.96763182,52.647724,0.72872633,493.30191,-9.2577419
178.7676,11.375666,9.4638605,0.0,0,0.39818591,0.0,0.99519187,53.490669,0.57398826,491.17465,-9.257618
178.77,9.1457996,9.5033102,0.0,0,0.25673628,0.0,1.0030944,42.806824,0.48403913,489.88004,-9.2583189
178.7724,7.9230666,9.5134354,0.0,0,0.12094415,0.0,1.006319,36.939682,0.43729287,491.74945,-9.2604885
178.7748,7.3928566,9.5120935,0.0,0,-0.014479235,0.0,1.0066141,34.43261,0.40712827,493.61887,-9.2609358
178.7772,7.1585693,9.5222263,0.0,0,-0.14691243,0.0,1.0071977,33.294567,0.38161257,495.48828,-9.2626123
178.7796,7.17694,9.5312347,0.0,0,-0.27934441,0.0,1.0076722,33.331284,0.34003773,497.43079,-9.2612457
178.782,7.5142422,9.5372753,0.0,0,-0.41177642,0.0,1.0092142,34.85862,0.27433896,501.05429,-9.2613611
178.7844,7.6651015,9.5425444,0.0,0,-0.54420841,0.0,1.0117315,35.49276,0.20473023,504.6778,-9.2603302
178.7868,7.6517696,9.5420732,0.0,0,-0.67664039,0.0,1.0123149,35.42844,0.14198665,508.30127,-9.2597446
178.7892,7.5100722,9.5495243,0.0,0,-0.80907238,0.0,1.0124084,34.773701,0.085843995,511.92477,-9.2606335
178.7916,7.3232498,9.5570984,0.0,0,-0.94150436,0.0,1.0129148,33.853027,0.042493157,514.43835,-9.2616882
178.794,7.0617838,9.5631943,0.0,0,-1.0739365,0.0,1.0141132,32.625118,0.014682936,516.79333,-9.2609549
178.7964,6.703814,9.560709,0.0,0,-0.76691425,400.0,1.0149038,30.961348,-0.0015204606,519.14838,-9.2604675
178.7988,6.2880664,9.5569363,0.0,0,-0.3084279,400.0,1.014935,29.00238,0.00096974528,521.50336,-9.2615986
178.8012,5.9327559,9.5582113,0.0,0,0.15005845,400.0,1.0142744,27.411489,0.012354261,523.2547,-9.2615576
178.8036,5.7020268,9.565218,0.0,0,0.60854483,400.0,1.0140959,26.327269,0.014374241,524.75745,-9.2617035
178.806,5.5502014,9.5681906,0.0,0,1.0670311,400.0,1.0148798,25.615608,0.013283918,526.26019,-9.2601986
178.8084,5.25635,9.564127,0.0,0,1.5255175,400.0,1.01566,24.270191,0.016634788,527.76294,-9.2611418
178.8108,4.3699389,9.5551701,0.0,0,1.9840039,400.0,1.0148635,20.279079,0.072227903,529.19592,-9.2624903
178.8132,2.501905,9.5427637,0.0,0,2.4424908,400.0,1.0115147,11.799169,0.19370206,530.56989,-9.2641096
178.8156,0.34127903,9.5229759,0.0,0,2.9009769,400.0,1.0065953,1.7196951,0.41277564,531.94385,-9.2649164
178.818,0.20917985,9.4673519,0.0,0,3.3594635,400.0,0.99663144,1.1218166,0.79922044,533.31781,-9.2659073
178.8204,-0.10267385,9.5067511,0.0,0,3.8179498,400.0,1.0046256,-0.2988269,1.5037628,534.56567,-9.2654247
178.8228,-0.099938393,9.4937239,0.0,0,4.2764363,400.0,1.0036333,-0.57974595,2.3274839,535.60345,-9.2660933
178.8252,0.13682291,9.4840517,0.0,0,4.7349229,400.0,1.0008187,0.62898839,3.0550776,536.64124,-9.2651987
178.8276,0.0089676278,9.4941473,0.0,0,5.1934094,400.0,1.0013915,0.13604468,3.5881112,537.67902,-9.2636786
178.83,-0.052681319,9.5014076,0.0,0,5.651895,400.0,1.0023706,-0.30384842,4.0129061,538.64673,-9.2637424
178.8324,0.045865677,9.4977474,0.0,0,6.1103816,400.0,1.0032152,0.14886189,4.435029,539.34827,-9.263319
178.8348,0.0083307195,9.4929609,0.0,0,6.5688682,400.0,1.0032895,0.051568877,4.8582296,540.04974,-9.2634468
178.8372,-0.010533365,9.4931765,0.0,0,7.0273547,400.0,1.0024377,-0.097326167,5.2870426,540.75122,-9.264761
178.8396,0.10452285,9.4923325,0.0,0,7.4858413,400.0,1.0012441,0.40578416,5.7546339,541.44769,-9.2634602
178.842,-0.10983676,9.4940434,0.0,0,7.9443278,400.0,1.0011795,-0.45935145,6.2332358,542.0293,-9.2633791
178.8444,-0.0008140076,9.4919252,0.0,0,8.4028139,400.0,1.0021757,-0.096940242,6.720511,542.61084,-9.2641182
178.8468,0.12723073,9.4875011,0.0,0,8.8612995,400.0,1.0021436,0.55749923,7.2118063,543.19244,-9.2623758
178.8492,-0.031024169,9.4875727,0.0,0,9.3197861,400.0,1.001577,-0.092860766,7.689249,543.76855,-9.2615662
178.8516,-0.029252604,9.4955397,0.0,0,9.7782726,400.0,1.0017779,-0.14852673,8.1645432,544.21948,-9.2621698
178.854,0.085439816,9.498683,0.0,0,10.236759,400.0,1.0017803,0.43224475,8.6344051,544.67041,-9.2620268
178.8564,-0.11252245,9.495945,0.0,0,10.695246,400.0,1.0024843,-0.4965536,9.0923481,545.12134,-9.2626772
178.8588,0.13044076,9.4883633,0.0,0,11.153732,400.0,1.0023994,0.52216125,9.5631981,545.57227,-9.2622795
178.8612,-0.017510064,9.484664,0.0,0,11.612218,400.0,1.0011675,0.036004893,10.044971,545.92932,-9.2624302
178.8636,-0.094451636,9.4874277,0.0,0,12.070705,400.0,1.0003579,-0.49845737,10.509273,546.27289,-9.2631426
178.866,0.049889933,9.4917002,0.0,0,12.529191,400.0,1.0009872,0.15449059,10.978668,546.61652,-9.2634401
178.8684,0.071414068,9.490243,0.0,0,12.987678,400.0,1.0016426,0.36154354,11.445983,546.96008,-9.2624989
178.8708,-0.066393226,9.4868345,0.0,0,13.446164,400.0,1.0020962,-0.28127888,11.897621,547.27325,-9.2620907
178.8732,-0.017115012,9.4860392,0.0,0,13.904651,400.0,1.0013329,-0.11453241,12.356916,547.57385,-9.261919
178.8756,0.056904316,9.4899483,0.0,0,14.363137,400.0,1.0008299,0.33233231,12.831517,547.87451,-9.2613144
178.878,-0.048482239,9.4952154,0.0,0,14.821624,400.0,1.0010657,-0.17282164,13.308315,548.17511,-9.2619724
178.8804,0.0046909619,9.4969654,0.0,0,15.28011,400.0,1.0022246,-0.038027171,13.792346,548.42926,-9.2610378
178.8828,0.053402171,9.4873476,0.0,0,15.738596,400.0,1.0020921,0.25467378,14.278416,548.64398,-9.2608862
178.8852,-0.050604936,9.4838905,0.0,0,16.197083,400.0,1.0013813,-0.27857319,14.740086,548.8587,-9.2620478
178.8876,0.032202192,9.4833698,0.0,0,16.655569,400.0,0.99991208,0.12925035,15.198521,549.07343,-9.2621584
178.89,0.028780684,9.4870815,0.0,0,17.114056,400.0,0.99996442,0.13582158,15.653209,549.26666,-9.2619448
178.8924,-0.055483144,9.4909096,0.0,0,17.572542,400.0,1.0014982,-0.22777997,16.103546,549.42413,-9.2622795
178.8948,0.018255295,9.4874649,0.0,0,17.999401,400.0,1.0021304,0.055533011,16.55607,549.5816,-9.2618618
178.8972,-0.0092467824,9.4853888,0.0,0,18.0,400.0,1.001458,-0.0076865214,17.008806,549.73907,-9.2616367
178.8996,-0.01796343,9.4876232,0.0,0,18.0,400.0,1.0005945,-0.083985612,17.442301,549.90253,-9.2626057
178.902,0.040332299,9.4946547,0.0,0,18.0,400.0,1.0007958,0.16806519,17.82604,550.08868,-9.2630968
178.9044,0.0068994537,9.4951248,0.0,0,18.0,400.0,1.0019339,0.03015409,18.151222,550.27484,-9.2649527
178.9068,0.059863392,9.492238,0.0,0,18.0,400.0,1.0029391,0.29359418,18.384947,550.46094,-9.2688923
178.9092,0.031380873,9.4907675,0.0,0,18.0,400.0,1.0027993,0.19864289,18.503145,550.6441,-9.2720127
178.9116,0.18885197,9.5011606,0.0,0,18.0,400.0,1.0031987,0.87174439,18.498632,550.75867,-9.2790642
178.914,0.084762469,9.5166378,0.0,0,18.0,400.0,1.0052085,0.52229333,18.383829,550.87323,-9.2867584
178.9164,0.45230079,9.5296497,0.0,0,18.0,400.0,1.0082794,2.029608,18.239199,550.98779,-9.299552
178.9188,0.70230931,9.5308638,0.0,0,18.0,400.0,1.0097808,3.3533568,18.128439,551.10236,-9.3149481
178.9212,0.644934,9.5293894,0.0,0,18.0,400.0,1.0096205,2.9354241,18.074694,551.1731,-9.3342819
178.9236,0.63869351,9.5295372,0.0,0,18.0,400.0,1.0083246,2.9652507,18.06176,551.23749,-9.354023
178.926,0.61336213,9.5364685,0.0,0,18.0,400.0,1.0084852,2.8768964,18.058634,551.30194,-9.3749704
178.9284,0.59252572,9.5381498,0.0,0,18.0,400.0,1.0095987,2.7682912,18.070524,551.36633,-9.3953762
178.9308,0.60188729,9.5339546,0.0,0,18.0,400.0,1.0104195,2.8006561,18.089537,551.44598,-9.4133434
178.9332,0.61380559,9.5295725,0.0,0,18.0,400.0,1.009918,2.8344612,18.102957,551.53192,-9.432744
178.9356,0.637851,9.5274115,0.0,0,18.0,400.0,1.0082039,2.9447045,18.112013,551.61786,-9.4508791
178.938,0.62846994,9.5334196,0.0,0,18.0,400.0,1.008328,2.9159105,18.127439,551.7038,-9.4705029
178.9404,0.60289109,9.5356073,0.0,0,18.0,400.0,1.0093716,2.8163521,18.131397,551.78192,-9.4867134
178.9428,0.61683041,9.5318813,0.0,0,18.0,400.0,1.0098312,2.8487921,18.128592,551.85358,-9.5024071
178.9452,0.64389217,9.5258427,0.0,0,18.0,400.0,1.0093222,2.9921029,18.129322,551.92517,-9.5193768
178.9476,0.65527946,9.5298233,0.0,0,18.0,400.0,1.0086217,3.0662279,18.130764,551.99677,-9.5370245
178.95,0.63375294,9.5363636,0.0,0,18.0,400.0,1.0086331,2.9633,18.127697,552.04956,-9.5554848
178.9524,0.6102252,9.5376062,0.0,0,18.0,400.0,1.0092549,2.8255453,18.123625,552.07104,-9.5732069
178.9548,0.6244508,9.5335283,0.0,0,18.0,400.0,1.0101919,2.8820939,18.1222,552.09253,-9.5900049
178.9572,0.65301263,9.5274363,0.0,0,18.0,400.0,1.0095791,3.0338349,18.122065,552.11395,-9.6073036
178.9596,0.64740175,9.530839,0.0,0,18.0,400.0,1.0088861,3.0193787,18.117887,552.12653,-9.6249008
178.962,0.62455273,9.5342245,0.0,0,18.0,400.0,1.008407,2.9321051,18.115021,552.10504,-9.6441746
178.9644,0.62609863,9.5328665,0.0,0,18.0,400.0,1.0087533,2.9001672,18.110744,552.08356,-9.6618452
178.9668,0.65366971,9.5290413,0.0,0,18.0,400.0,1.0091569,3.0074158,18.110178,552.06207,-9.677968
178.9692,0.65749508,9.5263844,0.0,0,18.0,400.0,1.0092615,3.0222437,18.109221,552.04297,-9.6959629
178.9716,0.64439511,9.530261,0.0,0,18.0,400.0,1.0090871,3.0162396,18.110502,552.0788,-9.7149668
178.974,0.60490435,9.5387392,0.0,0,18.0,400.0,1.0092221,2.8061633,18.106899,552.11462,-9.7320166
178.9764,0.63413006,9.5374775,0.0,0,18.0,400.0,1.0089949,2.9198568,18.106365,552.15039,-9.7512865
178.9788,0.65269452,9.5334301,0.0,0,18.0,400.0,1.0100042,2.9794276,18.109156,552.18622,-9.7692747
178.9812,0.63696665,9.529171,0.0,0,18.0,400.0,1.0099168,2.974524,18.104746,552.22198,-9.7864628
178.9836,0.62605077,9.5292921,0.0,0,18.0,400.0,1.0090319,2.9568484,18.104614,552.25781,-9.8057842
178.986,0.61930335,9.5332909,0.0,0,18.0,400.0,1.0083815,2.8427532,18.102066,552.29358,-9.8237228
178.9884,0.64666051,9.5329428,0.0,0,18.0,400.0,1.0085424,2.9830456,18.106564,552.32941,-9.8416777
178.9908,0.64650488,9.5313263,0.0,0,18.0,400.0,1.0094649,3.0147054,18.102276,552.32971,-9.8589859
178.9932,0.63303846,9.5297832,0.0,0,18.0,400.0,1.0098964,2.9473755,18.101343,552.31537,-9.8750429
178.9956,0.61497486,9.5300341,0.0,0,18.0,400.0,1.0091354,2.86289,18.100096,552.30103,-9.8924942
178.998,0.63528687,9.5355692,0.0,0,18.0,400.0,1.0089792,2.9392688,18.100899,552.28674,-9.9098463
179.0004,0.65083021,9.5390129,0.0,0,18.0,400.0,1.0091432,2.9894929,18.096365,552.27625,-9.9269381
179.0028,0.64939111,9.5353804,0.0,0,18.0,400.0,1.010201,3.0084343,18.098993,552.2691,-9.9465475
179.0052,0.62978441,9.5325499,0.0,0,18.0,400.0,1.0104697,2.898082,18.095205,552.26196,-9.9649267
179.0076,0.62891197,9.5299349,0.0,0,18.0,400.0,1.0092301,2.9167421,18.093441,552.25476,-9.980999
179.01,0.63691354,9.5329866,0.0,0,18.0,400.0,1.0084777,2.9810863,18.092554,552.26105,-9.9980373
179.0124,0.66754037,9.5365734,0.0,0,18.0,400.0,1.0091534,3.0988829,18.092581,552.28967,-10.017442
179.0148,0.6527034,9.5368719,0.0,0,18.0,400.0,1.010407,3.0343344,18.092722,552.3183,-10.035961
179.0172,0.63010693,9.5328417,0.0,0,18.0,400.0,1.010628,2.9357452,18.090643,552.34698,-10.054197
179.0196,0.64467919,9.5292377,0.0,0,18.0,400.0,1.0091946,2.9757583,18.091599,552.36963,-10.071382
179.022,0.6669454,9.5344601,0.0,0,18.0,400.0,1.008669,3.1070466,18.090212,552.36963,-10.087612
179.0244,0.67834395,9.5403652,0.0,0,18.0,400.0,1.0093204,3.1244228,18.090174,552.36963,-10.105187
179.0268,0.64410901,9.5394831,0.0,0,18.0,400.0,1.0107396,2.9984145,18.089697,552.36963,-10.12293
179.0292,0.64078587,9.5326509,0.0,0,18.0,400.0,1.0105293,2.9727819,18.091002,552.36755,-10.142116
179.0316,0.65973705,9.5310116,0.0,0,18.0,400.0,1.0094949,3.0666208,18.087322,552.31744,-10.158525
179.034,0.68441021,9.5340242,0.0,0,18.0,400.0,1.0087471,3.1366422,18.084761,552.26727,-10.175821
179.0364,0.66805601,9.5349302,0.0,0,18.0,400.0,1.008852,3.1070473,18.081787,552.21716,-10.194261
179.0388,0.63954842,9.5351353,0.0,0,18.0,400.0,1.0098488,2.9757907,18.082455,552.16705,-10.211803
179.0412,0.63994068,9.5324697,0.0,0,18.0,400.0,1.0104159,2.9614782,18.07852,552.13574,-10.229073
179.0436,0.68593937,9.5328436,0.0,0,18.0,400.0,1.0099759,3.1652923,18.076134,552.10712,-10.247464
179.046,0.68260789,9.5376415,0.0,0,18.0,400.0,1.009431,3.1815815,18.079853,552.07849,-10.264887
179.0484,0.65446681,9.5434322,0.0,0,18.0,400.0,1.0098221,3.0175827,18.079565,552.04987,-10.283258
179.0508,0.64509231,9.5418854,0.0,0,18.0,400.0,1.0108289,3.0217991,18.076536,552.0415,-10.300065
179.0532,0.64837736,9.5355291,0.0,0,18.0,400.0,1.0109607,3.0349007,18.075373,552.0415,-10.317931
179.0556,0.68603307,9.5315952,0.0,0,18.0,400.0,1.009882,3.1688066,18.076687,552.0415,-10.335324
179.058,0.67970741,9.5349979,0.0,0,18.0,400.0,1.0090448,3.1402588,18.075544,552.0415,-10.353161
179.0604,0.62893748,9.5373631,0.0,0,18.0,400.0,1.0091146,2.9578128,18.080584,552.0415,-10.371853
179.0628,0.64460462,9.5371485,0.0,0,18.0,400.0,1.0098801,3.0122089,18.075516,552.0415,-10.389089
179.0652,0.67721707,9.5314388,0.0,0,18.0,400.0,1.0099436,3.1317141,18.075245,552.0415,-10.405531
179.0676,0.68716198,9.5316668,0.0,0,18.0,400.0,1.0098631,3.192667,18.074711,552.0415,-10.4248
179.07,0.66455102,9.5369978,0.0,0,18.0,400.0,1.0095971,3.0668442,18.075216,552.02539,-10.443868
179.0724,0.64124852,9.5406485,0.0,0,18.0,400.0,1.0093744,2.9941745,18.073334,551.98242,-10.461522
179.0748,0.66095233,9.5401249,0.0,0,18.0,400.0,1.0102766,3.0274665,18.07468,551.93945,-10.477981
179.0772,0.69141591,9.5367384,0.0,0,18.0,400.0,1.0109255,3.2059002,18.071611,551.89648,-10.495834
179.0796,0.68046445,9.5325661,0.0,0,18.0,400.0,1.0102749,3.189327,18.074911,551.85651,-10.513795
179.082,0.65270174,9.5338383,0.0,0,18.0,400.0,1.0091573,3.0326667,18.070927,551.82788,-10.532049
179.0844,0.66616654,9.5382032,0.0,0,18.0,400.0,1.0092744,3.0894616,18.072069,551.79926,-10.550011
179.0868,0.68890965,9.5377283,0.0,0,18.0,400.0,1.0098455,3.1685991,18.070198,551.77063,-10.566299
179.0892,0.69910133,9.5329037,0.0,0,18.0,400.0,1.010327,3.2247193,18.072273,551.74286,-10.585361
179.0916,0.67724013,9.5326624,0.0,0,18.0,400.0,1.0102528,3.1483145,18.06637,551.73572,-10.603119
179.094,0.65361387,9.535553,0.0,0,18.0,400.0,1.0096982,3.0409427,18.068089,551.72852,-10.621346
179.0964,0.66970366,9.5417776,0.0,0,18.0,400.0,1.0095401,3.0988553,18.068422,551.72131,-10.638751
179.0988,0.70940197,9.5434189,0.0,0,18.0,400.0,1.0105996,3.2693276,18.06398,551.71417,-10.655777
179.1012,0.69974285,9.539731,0.0,0,18.0,400.0,1.0115486,3.2160769,18.064627,551.70074,-10.674792
179.1036,0.66793734,9.534771,0.0,0,18.0,400.0,1.0109953,3.0970771,18.067633,551.6864,-10.693185
179.106,0.66429704,9.5360956,0.0,0,18.0,400.0,1.00966,3.0835283,18.065773,551.67212,-10.710708
179.1084,0.68847775,9.537734,0.0,0,18.0,400.0,1.0089986,3.1727724,18.061893,551.65778,-10.726877
179.1108,0.71597135,9.5396681,0.0,0,18.0,400.0,1.0100449,3.2788322,18.058229,551.62317,-10.744449
179.1132,0.67855269,9.5356359,0.0,0,18.0,400.0,1.0107075,3.174736,18.058569,551.5802,-10.762181
179.1156,0.65727717,9.5341444,0.0,0,18.0,400.0,1.0106398,3.0566175,18.059437,551.53729,-10.779694
179.118,0.67899251,9.537406,0.0,0,18.0,400.0,1.0101297,3.1190755,18.061995,551.49432,-10.795968
179.1204,0.70772064,9.5436697,0.0,0,18.0,400.0,1.0099684,3.268548,18.061491,551.45135,-10.814706
179.1228,0.69816691,9.5465107,0.0,0,18.0,400.0,1.0110215,3.2412608,18.056849,551.40839,-10.83371
179.1252,0.66478282,9.5412321,0.0,0,18.0,400.0,1.0114893,3.0837173,18.057571,551.36542,-10.852275
179.1276,0.67206985,9.5339975,0.0,0,18.0,400.0,1.0107422,3.109998,18.057888,551.32251,-10.86936
179.13,0.68296582,9.5332327,0.0,0,18.0,400.0,1.009402,3.1558113,18.057823,551.29028,-10.886874
179.1324,0.71873236,9.5373278,0.0,0,18.0,400.0,1.0090584,3.3353858,18.059597,551.27594,-10.90405
179.1348,0.68487412,9.5392857,0.0,0,18.0,400.0,1.0098842,3.1786361,18.057314,551.26166,-10.922496
179.1372,0.6642375,9.5351839,0.0,0,18.0,400.0,1.0103742,3.087359,18.057665,551.24731,-10.941688
179.1396,0.6757772,9.5309067,0.0,0,18.0,400.0,1.0101939,3.1126261,18.058393,551.23297,-10.957913
179.142,0.7066977,9.5351858,0.0,0,18.0,400.0,1.0099238,3.2595491,18.058502,551.21869,-10.975568
179.1444,0.71260935,9.5427418,0.0,0,18.0,400.0,1.0098497,3.3150125,18.059668,551.20435,-10.99249
179.1468,0.67763269,9.5450487,0.0,0,18.0,400.0,1.0104674,3.1448457,18.057558,551.19006,-11.010994
179.1492,0.6668511,9.5390358,0.0,0,18.0,400.0,1.0110558,3.0931416,18.057468,551.17542,-11.029932
179.1516,0.69924736,9.5339355,0.0,0,18.0,400.0,1.0108256,3.206861,18.056662,551.15393,-11.046955
179.154,0.71575016,9.5337257,0.0,0,18.0,400.0,1.0096689,3.3229771,18.056427,551.13245,-11.063673
179.1564,0.6969071,9.5391064,0.0,0,18.0,400.0,1.0094172,3.2522595,18.054976,551.11096,-11.081189
179.1588,0.66969436,9.5424442,0.0,0,18.0,400.0,1.0103109,3.1214955,18.054573,551.08948,-11.099409
179.1612,0.68050778,9.5389891,0.0,0,18.0,400.0,1.0108489,3.1478875,18.053429,551.04919,-11.117422
179.1636,0.72497469,9.5331135,0.0,0,18.0,400.0,1.010636,3.3141053,18.050093,551.00629,-11.133891
179.166,0.71404493,9.5346756,0.0,0,18.0,400.0,1.0099889,3.3299053,18.049366,550.96332,-11.152995
179.1684,0.68607706,9.5438185,0.0,0,18.0,400.0,1.0103292,3.2160394,18.054981,550.92035,-11.170301
179.1708,0.67881012,9.5478992,0.0,0,18.0,400.0,1.011021,3.1268678,18.050266,550.88251,-11.186854
179.1732,0.70110929,9.5426798,0.0,0,18.0,400.0,1.0114813,3.2457759,18.052675,550.84668,-11.202629
179.1756,0.73173052,9.5367804,0.0,0,18.0,400.0,1.0113024,3.3785627,18.049444,550.81085,-11.222625
179.178,0.71323568,9.5372896,0.0,0,18.0,400.0,1.0105488,3.311811,18.050697,550.77509,-11.241281
179.1804,0.68006337,9.5422382,0.0,0,18.0,400.0,1.0101414,3.1514506,18.049459,550.75092,-11.257177
179.1828,0.69656545,9.5427876,0.0,0,18.0,400.0,1.0103328,3.2052934,18.045101,550.73657,-11.276217
179.1852,0.72726589,9.5405254,0.0,0,18.0,400.0,1.010891,3.3606036,18.048759,550.72223,-11.294917
179.1876,0.72434747,9.5344677,0.0,0,18.0,400.0,1.0108296,3.3879008,18.046427,550.70795,-11.313437
179.19,0.69195759,9.5341978,0.0,0,18.0,400.0,1.010226,3.2299416,18.047976,550.6936,-11.331803
179.1924,0.69081825,9.5437231,0.0,0,18.0,400.0,1.0104673,3.1917336,18.047571,550.67926,-11.348572
179.2945,0.69690156,9.5407257,0.0,0,18.0,17.344156,1.0108353,3.2289555,18.035959,547.90613,-11.467356
180.4945,0.67472965,9.5587749,0.0,0,18.0,7.5886285e-16,1.0139936,3.1174066,17.999912,524.99005,-11.479877
181.6945,0.69182587,9.5717278,0.0,0,18.0,3.2805517000000004e-32,1.0164895,3.1903217,17.99996,509.78818,-11.479903
182.8945,0.70162797,9.5832367,0.0,0,18.0,1.4012985e-45,1.0185946,3.2163198,17.999876,496.00977,-11.480389
184.0945,0.70075279,9.5937538,0.0,0,18.0,1.4012985e-45,1.0204048,3.2196696,18.000584,482.99286,-11.480811
185.2945,0.71071082,9.6029682,0.0,0,18.0,1.4012985e-45,1.0222694,3.2586174,18.000061,470.32693,-11.480466
186.4945,0.71134108,9.612627,0.0,0,18.0,1.4012985e-45,1.0240399,3.250236,17.999733,457.73883,-11.480207
187.6945,0.71748203,9.6215458,0.0,0,18.0,1.4012985e-45,1.025576,3.2764103,18.000183,445.31506,-11.480279
188.8945,0.72050494,9.6291132,0.0,0,18.0,1.4012985e-45,1.0271493,3.2833023,17.999166,432.73685,-11.479718
190.0945,0.72466511,9.6379519,0.0,0,18.0,1.4012985e-45,1.0287406,3.3001804,18.000355,420.04303,-11.480307
191.2945,0.73332846,9.6450624,0.0,0,18.0,1.4012985e-45,1.0299734,3.3295839,18.000305,407.65582,-11.480632
192.4945,0.73038298,9.6525526,0.0,0,18.0,1.4012985e-45,1.0314777,3.3148987,18.000032,395.86292,-11.481069
193.6945,0.74270403,9.6602402,0.0,0,18.0,1.4012985e-45,1.0328832,3.3701398,18.00001,384.60214,-11.481084
194.8945,0.7400893,9.6674623,0.0,0,18.0,1.4012985e-45,1.0341576,3.3505507,17.999937,373.86752,-11.481227
196.0945,0.74806696,9.674161,0.0,0,18.0,1.4012985e-45,1.0355402,3.3825612,18.000893,363.32434,-11.481169
197.2945,0.75355041,9.6808538,0.0,0,18.0,1.4012985e-45,1.0367645,3.4019628,18.000372,353.12372,-11.480949
198.4945,0.75253946,9.6873817,0.0,0,18.0,1.4012985e-45,1.0378953,3.3963842,17.999422,343.23611,-11.480395
199.6945,0.76081473,9.6934805,0.0,0,18.0,1.4012985e-45,1.0391915,3.4278247,18.000538,333.54526,-11.480422
200.8945,0.75812352,9.6994467,0.0,0,18.0,1.4012985e-45,1.0402545,3.4100249,18.00024,324.41364,-11.480155
202.0945,0.76977718,9.7054014,0.0,0,18.0,1.4012985e-45,1.0413125,3.461395,17.999807,315.41644,-11.480251
203.2945,0.77083832,9.7118359,0.0,0,18.0,1.4012985e-45,1.042645,3.4535246,18.00008,306.47052,-11.479981
204.4945,0.77168447,9.7174559,0.0,0,18.0,1.4012985e-45,1.0436572,3.4685452,17.99987,297.98752,-11.480529
205.6945,0.77941424,9.7231808,0.0,0,18.0,1.4012985e-45,1.0446727,3.4895866,17.999762,289.48651,-11.481116
206.8945,0.77921796,9.7282743,0.0,0,18.0,1.4012985e-45,1.0457315,3.4920092,17.999798,281.42035,-11.480897
208.0945,0.79055548,9.7334146,0.0,0,18.0,1.4012985e-45,1.0466542,3.5259635,18.000286,273.77994,-11.481271
209.2945,0.78583115,9.7387819,0.0,0,18.0,1.4012985e-45,1.0476313,3.510875,17.999315,266.2912,-11.481352
210.4945,0.79343921,9.7440014,0.0,0,18.0,1.4012985e-45,1.0487121,3.5422173,18.00009,259.0062,-11.481387
211.6945,0.79322213,9.7489471,0.0,0,18.0,1.4012985e-45,1.0495975,3.5313706,17.999109,251.8199,-11.48104
212.8945,0.79686373,9.7541151,0.0,0,18.0,1.4012985e-45,1.0505511,3.5553548,18.000498,245.05084,-11.481335
214.0945,0.80368692,9.7580347,0.0,0,18.0,1.4012985e-45,1.051402,3.5694027,18.000959,238.3176,-11.481215
215.2945,0.80015391,9.7624903,0.0,0,18.0,1.4012985e-45,1.0522155,3.5595071,18.000732,231.93614,-11.481107
216.4945,0.81273347,9.7673283,0.0,0,18.0,1.4012985e-45,1.0530927,3.6070499,18.001072,225.80122,-11.481495
217.6945,0.80229747,9.7713013,0.0,0,18.0,1.4012985e-45,1.0539556,3.5588562,17.999161,219.8815,-11.481776
218.8945,0.8105762,9.7763081,0.0,0,18.0,1.4012985e-45,1.0548472,3.5955141,18.000673,214.15343,-11.481876
220.0945,0.80785853,9.7800465,0.0,0,18.0,1.4012985e-45,1.0554873,3.5797126,18.000319,208.62494,-11.481784
221.2945,0.8050673,9.7847776,0.0,0,18.0,1.4012985e-45,1.0565417,3.5726337,18.000256,202.98811,-11.481836
222.4945,0.81640309,9.7881784,0.0,0,18.0,1.4012985e-45,1.0571239,3.6064155,17.999828,197.88008,-11.481632
223.6945,0.80771977,9.7925234,0.0,0,18.0,1.4012985e-45,1.0578748,3.570266,17.999823,192.69328,-11.481955
224.8945,0.81772101,9.796072,0.0,0,18.0,1.4012985e-45,1.0587035,3.6175125,18.000486,187.81708,-11.481896
226.0945,0.80934054,9.7996645,0.0,0,18.0,1.4012985e-45,1.0593662,3.5704987,18.000105,182.90991,-11.481737
227.2945,0.81487441,9.8035707,0.0,0,18.0,1.4012985e-45,1.0599811,3.6006658,18.000557,178.3015,-11.48175
228.4945,0.81448859,9.8070488,0.0,0,18.0,1.4012985e-45,1.0608189,3.5846465,18.000202,173.84062,-11.481518
229.6945,0.81205815,9.8105249,0.0,0,18.0,1.4012985e-45,1.0614603,3.5776088,17.999853,169.5079,-11.481877
230.8945,0.81802577,9.813405,0.0,0,18.0,1.4012985e-45,1.0618932,3.5966415,17.99929,165.2182,-11.481833
232.0945,0.81205064,9.8165321,0.0,0,18.0,1.4012985e-45,1.0626696,3.575551,18.000645,161.05693,-11.481735
233.2945,0.82374471,9.8198757,0.0,0,18.0,1.4012985e-45,1.063261,3.6198199,18.000031,157.15543,-11.481914
234.4945,0.81575823,9.8233938,0.0,0,18.0,1.4012985e-45,1.0638331,3.582155,17.999174,153.23976,-11.481632
235.6945,0.82536638,9.8260765,0.0,0,18.0,1.4012985e-45,1.0644937,3.6254551,17.999502,149.40385,-11.481839
236.8945,0.8165561,9.8288727,0.0,0,18.0,1.4012985e-45,1.0649995,3.5814977,17.999943,145.91226,-11.482076
238.0945,0.81593257,9.8317051,0.0,0,18.0,1.4012985e-45,1.0654234,3.5828762,17.999842,142.38071,-11.481672
239.1945,0.82647002,9.8339052,0.0,0,18.0,1.4012985e-45,1.0659496,3.6216311,17.999907,139.2486,-11.481482