File: raw data/testID_0224.csv
Time(sec),Force(kN),Jaw(mm),PowAngle(deg),Power(W),Pram,PTemp,Strain,Stress(MPa),Stroke(mm),TC1(C),wedge(mm)
0.0,1.1665529,0.50458753,0.0,0,11.076097,0.0014212866,0.034207672,14.363219,11.077255,22.362825,-9.1358557
1.2,1.1071827,0.0039878264,0.0,0,11.076097,3.5155752,0.0002562179,14.096246,11.075776,22.396418,-9.4878798
2.4,1.0695001,0.0036963704,0.0,0,11.076097,7.1155748,0.00024008092,13.615309,11.076472,22.431194,-9.4848719
3.6,1.0472786,0.0035740642,0.0,0,11.076097,10.715573,0.00023596591,13.341814,11.077115,22.39039,-9.484211
4.8,1.0256864,0.0031850382,0.0,0,11.076097,14.315575,0.00020306176,13.054665,11.076344,22.375597,-9.4814329
6.0,1.01018,0.0034715927,0.0,0,11.076097,17.915577,0.00022366886,12.849196,11.076278,22.433018,-9.4793596
7.2,0.99503076,0.0031629109,0.0,0,11.076097,21.515579,0.00021134298,12.665339,11.076239,22.370924,-9.4771223
8.4,0.98611194,0.0036973949,15.752809,0,11.076097,25.115578,0.00023759912,12.543909,11.076643,22.367393,-9.4742937
9.6,0.98833442,0.0040560169,31.806904,0,11.076097,28.715578,0.00026623986,12.57981,11.075536,22.515688,-9.4724617
10.8,1.0069798,0.001613387,41.543396,0,11.076097,32.315578,9.4028372e-05,12.821057,11.076561,23.54085,-9.4708691
12.0,1.0267749,-0.0032576316,47.465183,0,11.076097,35.915573,-0.00022395034,13.077355,11.074885,25.759354,-9.4694223
13.2,1.0431652,-0.0071802442,51.56353,0,11.076097,39.515575,-0.00048575524,13.291217,11.076629,29.238743,-9.4671907
14.4,1.0580902,-0.01332865,54.242973,0,11.076097,43.115574,-0.00089742173,13.486129,11.076379,33.722984,-9.4650002
15.6,1.0833317,-0.020062167,55.718807,0,11.076097,46.715572,-0.0013373288,13.807198,11.07476,38.913288,-9.4623795
16.8,1.1001265,-0.026479831,56.425674,0,11.076097,50.315578,-0.0017616389,14.028649,11.075914,44.586159,-9.4606781
18.0,1.1159273,-0.033143021,56.425785,0,11.076097,53.915577,-0.0022001991,14.238653,11.076452,50.324787,-9.4583387
19.2,1.1240933,-0.039206166,55.845627,0,11.076097,57.515579,-0.0026148076,14.334992,11.076389,56.01329,-9.4562483
20.4,1.1344215,-0.046441182,54.93169,0,11.076097,61.115585,-0.0030767343,14.483299,11.077306,61.569141,-9.4548759
21.6,1.1242571,-0.051071744,53.657276,0,11.076097,64.715584,-0.003388179,14.361121,11.076291,66.5802,-9.4523363
22.8,1.1353757,-0.054007255,51.936665,0,11.076097,68.315575,-0.003584245,14.51372,11.076952,71.334831,-9.450798
24.0,1.1322598,-0.057446957,50.438286,0,11.076097,71.915573,-0.0038061179,14.475494,11.076522,75.494011,-9.4485159
25.2,1.1249262,-0.060383148,48.813763,0,11.076097,75.515579,-0.0040048631,14.389378,11.075764,79.215622,-9.4462376
26.4,1.1220138,-0.062902763,47.682888,0,11.076097,79.115562,-0.004170855,14.352441,11.07574,82.447739,-9.4438639
27.6,1.1211889,-0.065207317,47.069748,0,11.076097,82.715576,-0.0043226248,14.3416,11.076193,85.267616,-9.4420004
28.8,1.1154214,-0.06768968,47.337185,0,11.076097,86.315567,-0.0044973833,14.267605,11.076815,87.765488,-9.4396439
30.0,1.125353,-0.070080608,47.955318,0,11.076097,89.915573,-0.0046599112,14.392704,11.076249,90.109749,-9.4378891
31.2,1.1331211,-0.073081091,49.229683,0,11.076097,93.515579,-0.0048639625,14.496373,11.074774,92.508293,-9.4357815
32.4,1.1320816,-0.076216415,50.821609,0,11.076097,97.115578,-0.0050783353,14.493601,11.076183,94.949623,-9.4340019
33.6,1.1332459,-0.080168881,52.552624,0,11.076097,100.71558,-0.0053519909,14.515908,11.075546,97.555122,-9.4320364
34.8,1.133316,-0.084403671,53.974117,0,11.076097,104.31558,-0.0056317924,14.506799,11.076283,100.52445,-9.4296885
36.0,1.1420162,-0.089002728,55.238796,0,11.076097,107.91557,-0.0059427503,14.621477,11.075715,103.91315,-9.4275751
37.2,1.1417071,-0.094542176,56.424828,0,11.076097,111.51559,-0.0062974393,14.635378,11.076002,107.56465,-9.4255247
38.4,1.1439257,-0.10061229,57.260555,0,11.076097,115.11558,-0.0067074443,14.663618,11.07686,111.46771,-9.4236403
39.6,1.1445603,-0.10615373,57.81004,0,11.076097,118.71558,-0.0070764362,14.67903,11.076269,115.52618,-9.4214315
40.8,1.1387533,-0.11040703,58.073727,0,11.076097,122.31558,-0.0073632188,14.619699,11.075318,119.84699,-9.4196434
42.0,1.1404909,-0.11437436,58.337399,0,11.076097,125.91559,-0.0076169237,14.622653,11.076316,124.04916,-9.4172716
43.2,1.1420484,-0.11975938,58.470512,0,11.076097,129.51572,-0.0079684788,14.65715,11.075481,128.20792,-9.4155054
44.4,1.1407571,-0.12481914,58.346741,0,11.076097,133.11557,-0.0082967561,14.647226,11.075756,132.41142,-9.4134007
45.6,1.1411778,-0.12997082,58.33741,0,11.076097,136.71559,-0.0086285956,14.655923,11.075415,136.43513,-9.4116802
46.8,1.1389529,-0.13504802,58.073738,0,11.076097,140.31558,-0.0089507755,14.630673,11.076603,140.48778,-9.4092607
48.0,1.1348859,-0.1398091,57.810066,0,11.076097,143.9156,-0.0092666671,14.587437,11.076126,144.5116,-9.4074879
49.2,1.1414382,-0.14401376,57.351742,0,11.076097,147.51559,-0.009528799,14.663046,11.076022,148.43973,-9.4054852
50.4,1.1437743,-0.14987305,57.026707,0,11.076097,151.1156,-0.0099147921,14.70456,11.076092,152.12346,-9.403513
51.6,1.1435742,-0.15166612,56.986088,0,11.076097,154.71559,-0.010039142,14.713105,11.075599,155.60504,-9.4015532
52.8,1.1457582,-0.15516184,56.886734,0,11.076097,158.3156,-0.010269759,14.73437,11.076619,158.88345,-9.3998547
54.0,1.1482705,-0.15971346,56.986084,0,11.076097,161.91559,-0.010580363,14.771178,11.075569,162.15953,-9.3977013
55.2,1.1400139,-0.16366075,57.260681,0,11.076097,165.51559,-0.010842904,14.678913,11.075707,165.36136,-9.3952026
56.4,1.1386851,-0.16835397,57.535397,0,11.076097,169.1156,-0.01115889,14.663515,11.075928,168.51675,-9.3933392
57.6,1.1547174,-0.17273292,57.997028,0,11.076097,172.71559,-0.011441973,14.867816,11.076388,171.70764,-9.391242
58.8,1.1547836,-0.17768456,58.337227,0,11.076097,176.3156,-0.011782458,14.857028,11.076232,175.0524,-9.3890276
60.0,1.1492854,-0.18015707,58.680614,0,11.076097,179.91559,-0.011930279,14.830831,11.075991,178.56071,-9.3872004
61.2,1.1523662,-0.18510248,59.106155,0,11.076097,183.51558,-0.012252479,14.866871,11.0767,182.06161,-9.385416
62.4,1.1417845,-0.19044863,59.348137,0,11.076097,187.1156,-0.012600215,14.71296,11.075739,185.71046,-9.3835163
63.6,1.143569,-0.19520545,59.842506,0,11.076097,190.71559,-0.012927161,14.763807,11.076949,189.26855,-9.381835
64.8,1.1448972,-0.20048188,60.083801,0,11.076097,194.31558,-0.013291218,14.770805,11.075549,192.98407,-9.3796806
66.0,1.1551814,-0.20560119,60.313515,0,11.076097,197.91559,-0.013625525,14.891222,11.076682,196.61307,-9.3782387
67.2,1.1609991,-0.21110334,60.556637,0,11.076097,201.51556,-0.014006219,14.991237,11.076544,200.40858,-9.3763924
68.4,1.1564428,-0.21363568,60.556648,0,11.076097,205.11559,-0.014165893,14.944306,11.075874,204.23274,-9.3739634
69.6,1.15343,-0.21851818,60.78376,0,11.076097,208.71558,-0.014480517,14.903637,11.075465,207.99738,-9.3718405
70.8,1.1463429,-0.2237677,60.787346,0,11.076097,212.31557,-0.014832592,14.821875,11.076788,211.73253,-9.3697615
72.0,1.1504676,-0.22846375,60.787346,0,11.076097,215.91559,-0.015123385,14.867179,11.07679,215.52298,-9.367753
73.2,1.1457866,-0.23322958,60.787346,0,11.076097,219.51558,-0.015425298,14.806801,11.075335,219.22527,-9.3654919
74.4,1.1575248,-0.23781574,60.787346,0,11.076097,223.11557,-0.015706949,14.976103,11.075587,222.86145,-9.3635445
75.6,1.1543353,-0.24464841,60.825996,0,11.076097,226.71559,-0.016150407,14.938744,11.075761,226.483,-9.3613338
76.8,1.1605748,-0.24697407,61.018063,0,11.076097,230.31558,-0.016304107,15.022538,11.074972,230.06444,-9.3593674
78.0,1.1553924,-0.25110066,61.086426,0,11.076097,233.91559,-0.016562765,14.974926,11.075939,233.44316,-9.3572626
79.2,1.1556889,-0.25652343,61.237789,0,11.076097,237.51558,-0.016932696,14.976063,11.076312,237.02937,-9.3552189
80.4,1.1505115,-0.26153252,61.468472,0,11.076097,241.1156,-0.017279532,14.904452,11.077178,240.56018,-9.3530693
81.6,1.1444924,-0.26628807,61.674908,0,11.076097,244.71559,-0.017602276,14.825765,11.07571,243.96298,-9.3511238
82.8,1.1455319,-0.27072427,61.779751,0,11.076097,248.3156,-0.017898142,14.851871,11.076644,247.51787,-9.3495111
84.0,1.1640596,-0.27631778,62.054565,0,11.076097,251.9156,-0.018237542,15.101687,11.07545,250.99225,-9.3473473
85.2,1.1617653,-0.28248739,62.116692,0,11.076097,255.51559,-0.018646393,15.074637,11.075425,254.64502,-9.3453903
86.4,1.1643466,-0.28460461,62.336418,0,11.076097,259.11588,-0.018787306,15.107832,11.076038,258.32904,-9.3440418
87.6,1.1625479,-0.28890732,62.497604,0,11.076097,262.71561,-0.019067379,15.106231,11.075419,261.94971,-9.3419333
88.8,1.1562012,-0.2942377,62.572247,0,11.076097,266.31558,-0.019439179,15.020741,11.075341,265.55838,-9.3402071
90.0,1.1581613,-0.29909059,62.753899,0,11.076097,269.91562,-0.019769626,15.049961,11.075747,269.23071,-9.3379707
91.2,1.1509682,-0.30373105,62.913494,0,11.076097,273.51559,-0.020073341,14.944799,11.075089,272.8913,-9.3360615
92.4,1.1553921,-0.30813244,62.962639,0,11.076097,277.11563,-0.020360662,15.017127,11.076385,276.36517,-9.3342028
93.6,1.1627651,-0.31400669,63.171383,0,11.076097,280.71558,-0.020717893,15.121463,11.075825,280.03586,-9.3315811
94.8,1.1652158,-0.31928113,63.171383,0,11.076097,284.31558,-0.021078333,15.154095,11.07624,283.71503,-9.3296127
96.0,1.1641467,-0.3215616,63.348278,0,11.076097,287.91562,-0.021205641,15.155717,11.075731,287.42099,-9.3280602
97.2,1.1555154,-0.32563841,63.369137,0,11.076097,291.51556,-0.021444835,15.042069,11.076771,291.09732,-9.3260508
98.4,1.1585464,-0.33036718,63.369137,0,11.076097,295.1156,-0.021763705,15.090293,11.075907,294.89133,-9.3239307
99.6,1.1564218,-0.33480579,63.369137,0,11.076097,298.71561,-0.022051968,15.051293,11.076626,298.4317,-9.3221273
100.8,1.1513395,-0.33919916,63.392006,0,11.076097,302.31561,-0.022363631,15.000261,11.075245,301.98373,-9.3196115
102.0,1.1508934,-0.34364557,63.576488,0,11.076097,305.91562,-0.022655455,14.998462,11.076349,305.5686,-9.3179159
103.2,1.1573418,-0.34708542,63.577873,0,11.076097,309.51556,-0.022872355,15.061666,11.076384,309.25574,-9.3159008
104.4,1.1637321,-0.35321027,63.632626,0,11.076097,313.11557,-0.023244739,15.156895,11.075735,312.7117,-9.3138609
105.6,1.1672261,-0.35740134,63.863972,0,11.076097,316.71561,-0.023539763,15.228529,11.075837,316.13846,-9.3117065
106.8,1.1700474,-0.35874453,63.973385,0,11.076097,320.31558,-0.023653278,15.259821,11.076257,319.65292,-9.3097525
108.0,1.1661267,-0.3624858,64.171135,0,11.076097,323.91559,-0.023893494,15.216945,11.074888,323.22189,-9.3074808
109.2,1.1599752,-0.36740193,64.357903,0,11.076097,327.51556,-0.02422432,15.13603,11.075886,326.72205,-9.3058472
110.4,1.1631176,-0.37186512,64.555656,0,11.076097,331.1156,-0.024495156,15.174198,11.075654,330.14127,-9.3035936
111.6,1.157397,-0.37627524,64.818489,0,11.076097,334.71558,-0.024767602,15.118994,11.076938,333.56018,-9.3016586
112.8,1.1573917,-0.3809427,64.932388,0,11.076097,338.31558,-0.025065929,15.119143,11.076401,337.18188,-9.2996883
114.0,1.170701,-0.3845281,65.301659,0,11.076097,341.91556,-0.025283715,15.272086,11.075835,340.64243,-9.2973213
115.2,1.1749705,-0.39171445,65.664589,0,11.076097,345.51556,-0.025752682,15.349692,11.075658,343.76685,-9.2954483
116.4,1.1709766,-0.39464152,65.823883,0,11.076097,349.1156,-0.025982684,15.317126,11.07654,347.67529,-9.2937183
117.6,1.1696813,-0.39643517,65.841057,0,11.076097,352.71558,-0.026086742,15.283817,11.075363,351.68066,-9.2914352
118.8,1.1621671,-0.40157929,65.841057,0,11.076097,356.31561,-0.026402598,15.196411,11.075666,355.6178,-9.2892342
120.0,1.1669815,-0.40562248,65.841263,0,11.076097,359.91559,-0.026673861,15.261577,11.075986,359.59869,-9.2874765
121.2,1.1579309,-0.40923554,65.665291,0,11.076097,363.51563,-0.026930923,15.146109,11.075324,363.68887,-9.2851019
122.4,1.1538857,-0.41256845,65.490875,0,11.076097,367.1156,-0.027159622,15.098873,11.07544,367.50565,-9.2834682
123.6,1.1612165,-0.41501576,65.483177,0,11.076097,370.71561,-0.027299402,15.187141,11.07745,371.02209,-9.2815628
124.8,1.1796768,-0.41993335,65.255241,0,11.076097,374.31561,-0.027616171,15.443677,11.075768,375.1713,-9.2795258
126.0,1.1623652,-0.41848287,65.111534,0,11.076097,377.91559,-0.027506107,15.21547,11.07638,378.79529,-9.277771
127.2,1.1471676,-0.41961429,64.892418,0,11.076097,381.51563,-0.027563302,15.028381,11.076447,382.53699,-9.275423
128.4,1.1374068,-0.42186457,64.742439,0,11.076097,385.1156,-0.02772489,14.89168,11.076043,386.03928,-9.2734804
129.6,1.1262687,-0.42395666,64.766617,0,11.076097,388.71564,-0.027872004,14.746668,11.076116,389.14084,-9.2714043
130.8,1.1116389,-0.42569458,64.769775,0,11.076097,392.31561,-0.027977807,14.558501,11.076616,392.50623,-9.2696323
132.0,1.1189706,-0.42579493,64.929192,0,11.076097,395.91562,-0.027987819,14.631377,11.076282,395.84467,-9.2674685
133.2,1.1131934,-0.4302519,64.742706,0,11.076097,399.51563,-0.028286144,14.564778,11.076255,399.91721,-9.2655087
134.4,1.1079867,-0.4293901,64.929192,0,11.076097,403.11563,-0.028260138,14.513363,11.076321,402.83832,-9.2633877
135.6,1.0967807,-0.42742917,65.115959,0,11.076097,406.71564,-0.028118987,14.38184,11.076062,406.12985,-9.2614498
136.8,1.0872725,-0.42878452,65.467377,0,11.076097,410.31561,-0.028187156,14.226565,11.077113,409.25797,-9.2594566
138.0,1.0700272,-0.43097541,65.681046,0,11.076097,413.91559,-0.028304411,14.028106,11.075426,412.74661,-9.2576809
139.2,1.0479709,-0.4322125,66.016777,0,11.076097,417.51559,-0.028383827,13.734592,11.075174,416.21793,-9.2553339
140.4,1.0326849,-0.43263909,65.320045,0,11.076097,421.1156,-0.028438767,13.532388,11.075586,421.89954,-9.2533083
141.6,1.0217009,-0.43183884,64.666862,0,11.076097,424.71561,-0.028391678,13.377178,11.076268,426.61322,-9.2512188
142.8,1.0277334,-0.43248892,63.835468,0,11.076097,428.31561,-0.02839762,13.451461,11.07635,431.18265,-9.2496185
144.0,1.0207232,-0.43023524,62.261616,0,11.076097,431.91562,-0.028296258,13.373001,11.075807,437.05298,-9.2471323
145.2,1.0070394,-0.42409754,60.915096,0,11.076097,435.51559,-0.027907675,13.188859,11.075806,440.98419,-9.2455463
146.4,0.99109471,-0.42139325,59.602238,0,11.076097,439.1156,-0.027731797,12.975657,11.076818,444.68713,-9.243331
147.6,0.97324324,-0.41815847,57.701225,0,11.076097,442.71561,-0.027497539,12.737579,11.074821,449.21851,-9.2410583
148.8,0.96852791,-0.41408777,56.712593,0,11.076097,446.31558,-0.027207103,12.673944,11.075946,451.64163,-9.2393942
150.0,0.960464,-0.41089761,56.985771,0,11.076097,449.91409,-0.027003815,12.567376,11.075422,452.75162,-9.2370491
151.2,0.9498468,-0.40816653,55.949299,0,11.076097,449.9989,-0.026835132,12.422772,11.076418,453.28125,-9.236846
152.4,0.8319847,-0.40781724,54.82254,0,11.076097,449.9989,-0.02683202,10.883661,11.075779,453.48834,-9.2369366
153.6,0.70930952,-0.40489182,54.305424,0,11.076097,449.9989,-0.026625922,9.2707062,11.075843,452.96365,-9.2370968
154.8,0.6013577,-0.40476879,53.975815,0,11.076097,449.9989,-0.026633758,7.868196,11.075285,452.18796,-9.2366095
156.0,0.49550551,-0.40450463,53.952831,0,11.076097,449.9989,-0.026642226,6.4699335,11.076375,451.28479,-9.2369375
157.2,0.40904596,-0.40426278,54.623928,0,11.076097,449.9989,-0.026607903,5.3517113,11.075903,449.95599,-9.236702
158.4,0.31202915,-0.40408453,54.692974,0,11.076097,449.9989,-0.026578998,4.0732131,11.075361,449.72015,-9.2365122
159.6,0.23599657,-0.40401971,55.695751,0,11.076097,449.9989,-0.026532164,3.0859442,11.075411,448.7106,-9.236805
160.8,0.1820084,-0.40347415,57.259151,0,11.076097,449.9989,-0.026530419,2.3784163,11.076076,446.79117,-9.2367706
162.0,0.14853255,-0.40090969,59.103321,0,11.076097,449.9989,-0.026379066,1.9457533,11.075911,445.37134,-9.2366371
163.2,0.121863,-0.40026942,60.777367,0,11.076097,449.9989,-0.026321042,1.591953,11.07596,444.31323,-9.2364111
164.4,0.1079018,-0.39971063,62.333931,0,11.076097,449.9989,-0.026294259,1.4018086,11.075041,443.44034,-9.2368116
165.6,0.093465045,-0.3997618,64.081017,0,11.076097,449.9989,-0.026325652,1.2196686,11.075414,442.60278,-9.2366467
166.8,0.091746204,-0.39967778,65.729301,0,11.076097,449.9989,-0.026319675,1.1953403,11.075715,441.88196,-9.2364836
168.0,0.10599221,-0.40039387,67.543579,0,11.076097,449.9989,-0.0263367,1.3732307,11.076659,440.58807,-9.236455
169.2,0.11662839,-0.40326935,68.663063,0,11.076097,449.9989,-0.026498111,1.5254637,11.076645,441.27045,-9.2362804
170.4,0.11653938,-0.40518963,69.576294,0,11.076097,449.9989,-0.026644664,1.5273919,11.074606,442.18405,-9.2361937
171.6,0.11519497,-0.40642381,70.015862,0,11.076097,449.9989,-0.026748313,1.512151,11.076208,443.96838,-9.2363605
172.8,0.11886147,-0.40894642,70.301506,0,11.076097,449.9989,-0.026890067,1.5693691,11.07689,445.69833,-9.2361946
174.0,0.11784945,-0.41196647,70.015968,0,11.076097,449.9989,-0.027112648,1.5459485,11.076598,448.00296,-9.2360353
175.2,0.11963291,-0.41490778,69.576515,0,11.076097,449.9989,-0.027308123,1.5700883,11.075793,450.08472,-9.2361774
176.4,0.12102527,-0.41779554,68.820862,0,11.076097,449.9989,-0.027481174,1.5888036,11.076049,451.99814,-9.2359734
177.6,0.11996228,-0.42018759,67.711334,0,11.076097,449.9989,-0.027609566,1.5695745,11.075706,454.19839,-9.2357702
178.8,0.1181193,-0.42099038,66.256035,0,11.076097,449.9989,-0.02766026,1.541321,11.076563,455.96994,-9.2358065
180.0,0.1189599,-0.42154038,64.808418,0,11.076097,449.9989,-0.027724998,1.5619278,11.075366,456.95786,-9.2356281
181.2,0.12570249,-0.42111546,63.208649,0,11.076097,449.9989,-0.02768429,1.6464767,11.075124,457.57056,-9.2359562
182.4,0.1329684,-0.42004699,61.691498,0,11.076097,449.9989,-0.027624678,1.7336506,11.075912,457.72516,-9.235878
183.6,0.12867726,-0.41773957,60.192417,0,11.076097,449.9989,-0.027491909,1.6950375,11.076636,457.33179,-9.2356491
184.8,0.12729242,-0.41538671,59.603161,0,11.076097,449.9989,-0.027320163,1.6681612,11.074986,455.58557,-9.2358589
186.0,0.12780406,-0.41255811,59.348148,0,11.076097,449.9989,-0.027113993,1.6719017,11.076509,453.92535,-9.2358856
187.2,0.12988688,-0.41003227,59.600826,0,11.076097,449.9989,-0.026938565,1.7011189,11.075966,451.92288,-9.2358313
188.4,0.13107345,-0.4085969,60.545025,0,11.076097,449.9989,-0.026879223,1.7114317,11.075607,449.6908,-9.2354765
189.6,0.13323307,-0.40677589,61.842392,0,11.076097,449.9989,-0.026752321,1.7251561,11.076189,447.44904,-9.2356634
190.8,0.13509442,-0.40500274,63.359959,0,11.076097,449.9989,-0.026656918,1.7679595,11.076313,445.36856,-9.235466
192.0,0.13633533,-0.40382731,64.917557,0,11.076097,449.9989,-0.026588548,1.7888712,11.075906,443.87485,-9.2352753
193.2,0.16919009,-0.40377969,66.367783,0,11.076097,449.9989,-0.026567802,2.2193184,11.075768,442.98337,-9.2357807
194.4,0.18203211,-0.40525326,67.395393,0,11.076097,449.9989,-0.02663224,2.3914003,11.076555,443.16861,-9.2354984
195.282,0.24850333,0.017370541,43.54446,0,11.076099,3.208111,0.0010264029,3.1292844,11.076649,443.60907,-9.2349195
195.2844,0.18986468,0.013636511,27.21526,0,11.076099,1.3868656000000002e-16,0.00095210457,2.3812709,11.080287,443.62344,-9.235199
195.2868,0.17904583,0.013048409,10.886063,0,11.076099,5.9954172e-33,0.0011072973,2.2402239,11.081853,443.63782,-9.2343292
195.2892,0.1725609,0.012989407,0.0,0,11.076099,0.0,0.00093473739,2.1637633,11.082035,443.66656,-9.2344151
195.2916,0.17746495,0.015922897,0.0,0,11.076099,0.0,0.00084516261,2.1504271,11.07501,443.72406,-9.2360048
195.294,0.17639574,0.018262906,0.0,0,11.076099,0.0,0.00087084848,2.1854117,11.081382,443.78159,-9.2352934
195.2964,0.16217907,0.016689155,0.0,0,11.076099,0.0,0.0010296181,2.1393092,11.078396,443.83908,-9.2356358
195.2988,0.15101866,0.012719963,0.0,0,11.076099,0.0,0.0010901417,1.8760734,11.078825,443.87741,-9.2358665
195.3012,0.15374281,0.010153706,0.0,0,11.076099,0.0,0.00088783941,1.835115,11.074956,443.81992,-9.2357817
195.3036,0.16090183,0.011229959,0.0,0,11.076099,0.0,0.00070320448,1.9539258,11.075344,443.76245,-9.2352896
195.306,0.1560623,0.014736793,0.0,0,11.076099,0.0,0.00082176982,2.0008261,11.076565,443.70496,-9.2355309
195.3084,0.15082018,0.014697839,0.0,0,11.076099,0.0,0.00088046258,1.9540278,11.079211,443.64746,-9.2352438
195.3108,0.14041945,0.013834407,0.0,0,11.076099,0.0,0.0010097089,1.7493972,11.075016,443.64746,-9.2348042
195.3132,0.13860883,0.012439722,0.0,0,11.076099,0.0,0.0010426219,1.7600075,11.07473,443.64746,-9.2352371
195.3156,0.15506469,0.012641821,0.0,0,11.076099,0.0,0.00091798883,2.0530713,11.070339,443.64746,-9.2357359
195.318,0.14535236,0.015536391,0.0,0,11.076099,0.0,0.00087224355,1.8505083,11.077037,443.64746,-9.2358999
195.3204,0.13363959,0.01859205,0.0,0,11.076099,0.0,0.00090244517,1.7666332,11.074924,443.67142,-9.2358656
195.3228,0.1482475,0.016679961,0.0,0,11.076099,0.0,0.0010934388,1.8443658,11.073527,443.70016,-9.2340841
195.3252,0.1501029,0.012731586,0.0,0,11.076099,0.0,0.0011027483,1.9325517,11.074783,443.72888,-9.2337742
195.3276,0.14898707,0.0098931426,0.0,0,11.076099,0.0,0.00083863252,1.950191,11.076287,443.75763,-9.2349129
195.33,0.14383744,0.011822169,0.0,0,11.076099,0.0,0.00073076156,1.7580076,11.075001,443.75284,-9.2350216
195.3324,0.13385007,0.014354235,0.0,0,10.976468,0.0,0.00079898635,1.6730003,11.075748,443.73126,-9.2352533
195.3348,0.14120574,0.014961709,0.0,0,10.615494,0.0,0.00094866205,1.7386477,11.072921,443.70972,-9.2351713
195.3372,0.14739752,0.013453294,0.0,0,10.254521,0.0,0.00099152129,1.799245,11.058815,443.68814,-9.2354908
195.3396,0.17478916,0.01066115,0.0,0,9.8935471,0.0,0.00094150827,2.156949,10.93046,446.75208,-9.2362957
195.342,0.11809836,0.011845519,0.0,0,9.5325737,0.0,0.00083892746,1.5149722,10.646555,452.90146,-9.2359734
195.3444,0.16005471,0.015474746,0.0,0,9.1800261,0.0,0.00079846353,2.0607779,10.257648,459.05081,-9.2363672
195.3468,4.5438614,0.29010549,0.0,0,8.8288574,0.0,0.018283878,56.833447,9.8177128,465.2002,-9.2311811
195.3492,4.8413,0.73425931,0.0,0,8.491025,0.0,0.049951378,58.375381,9.3063059,471.48569,-9.2307882
195.3516,4.9982581,1.170821,0.0,0,8.1570406,0.0,0.081248336,58.839516,8.851943,478.04343,-9.2332201
195.354,4.988421,1.5774201,0.0,0,7.8342953,0.0,0.1107885,56.790115,8.4750013,484.60117,-9.2317476
195.3564,5.2710466,1.875797,0.0,0,7.5165353,0.0,0.13298413,58.61726,8.1457443,491.15894,-9.2303391
195.3588,5.2949119,2.1815221,0.0,0,7.2082515,0.0,0.15654562,57.495228,7.8196373,496.75262,-9.2312536
195.3612,5.4118161,2.4867461,0.0,0,6.9060431,0.0,0.18081383,57.595089,7.5212431,497.52621,-9.2308407
195.3636,5.5262985,2.7722249,0.0,0,6.6115613,0.0,0.20425557,57.397476,7.2312512,498.2998,-9.230896
195.366,5.7148304,3.0545692,0.0,0,6.3240414,0.0,0.2276046,57.927002,6.9414606,499.07336,-9.2323551
195.3684,5.8208079,3.3428791,0.0,0,6.042748,0.0,0.25165084,57.53661,6.6470976,499.84695,-9.2326784
195.3708,5.997016,3.6398025,0.0,0,5.7692914,0.0,0.27707627,57.927071,6.3577428,496.51392,-9.2323484
195.3732,6.1083574,3.9315803,0.0,0,5.5006132,0.0,0.30315298,57.43988,6.0679722,493.18085,-9.2323313
195.3756,6.2524972,4.2099333,0.0,0,5.2404532,0.0,0.32919133,57.215645,5.7852101,489.84781,-9.2326145
195.378,6.3964348,4.485858,0.0,0,4.9838037,0.0,0.35543045,57.079231,5.502049,486.51477,-9.2323503
195.3804,6.5733848,4.7582383,0.0,0,4.7363639,0.0,0.38129643,57.120754,5.2301126,484.20993,-9.2311354
195.3828,6.7235446,5.0269289,0.0,0,4.4912457,0.0,0.40735629,56.953541,4.960072,482.11072,-9.2306156
195.3852,6.8655877,5.2903056,0.0,0,4.2558532,0.0,0.43406394,56.609264,4.6990709,480.01147,-9.2312975
195.3876,6.9944348,5.5411921,0.0,0,4.0217257,0.0,0.46074098,56.172802,4.4504147,477.91226,-9.2317562
195.39,7.1822481,5.7833018,0.0,0,3.7978492,0.0,0.48710683,56.115051,4.1987824,478.27859,-9.2310495
195.3924,7.3787374,6.0223823,0.0,0,3.5743496,0.0,0.51341259,56.209579,3.9605262,479.87769,-9.2301121
195.3948,7.5354104,6.2565718,0.0,0,3.3612847,0.0,0.5391171,55.943237,3.7311635,481.47678,-9.230875
195.3972,7.7321076,6.4840264,0.0,0,3.1483085,0.0,0.5649035,55.939972,3.5067885,483.0759,-9.2312918
195.3996,7.9208417,6.7033162,0.0,0,2.9451063,0.0,0.59136778,55.82058,3.2906852,484.29114,-9.2312002
195.402,8.1722193,6.910615,0.0,0,2.7424982,0.0,0.61753404,56.062881,3.0779719,485.12256,-9.230113
195.4044,8.4283924,7.1106467,0.0,0,2.5483871,0.0,0.64296103,56.354916,2.8724651,485.95395,-9.2301254
195.4068,8.6482344,7.312676,0.0,0,2.3556671,0.0,0.66818297,56.464279,2.6698489,486.78537,-9.2300472
195.4092,8.9080009,7.5132413,0.0,0,2.170248,0.0,0.69394469,56.670338,2.4786193,487.7099,-9.2303391
195.4116,9.2247219,7.7109241,0.0,0,1.986936,0.0,0.72064447,57.095806,2.2846231,488.82068,-9.2305927
195.414,9.5522337,7.9010406,0.0,0,1.8098083,0.0,0.74782962,57.55257,2.0900428,489.93146,-9.2303972
195.4164,9.8760376,8.087738,0.0,0,1.6354243,0.0,0.77505898,57.912262,1.900999,491.04224,-9.228857
195.4188,10.2079,8.269393,0.0,0,1.4662172,0.0,0.80145025,58.248615,1.7191319,491.83887,-9.228756
195.4212,10.57541,8.4565315,0.0,0,1.3003292,0.0,0.82858771,58.751675,1.5400195,491.06482,-9.2287893
195.4236,10.995521,8.6352825,0.0,0,1.1387082,0.0,0.85562634,59.420338,1.3660182,490.29074,-9.2287779
195.426,11.41827,8.8010836,0.0,0,0.98093224,0.0,0.88273019,60.084522,1.1958083,489.51669,-9.2284813
195.4284,11.854427,8.9621372,0.0,0,0.82657719,0.0,0.91042084,60.707737,1.0309782,488.74261,-9.227972
195.4308,12.302234,9.1228561,0.0,0,0.67652929,0.0,0.93766087,61.309834,0.86867285,489.595,-9.2272682
195.4332,12.796047,9.2765026,0.0,0,0.52908581,0.0,0.96302599,62.142845,0.71001405,490.44739,-9.2277946
195.4356,13.356611,9.4298334,0.0,0,0.38628578,0.0,0.98918039,63.17424,0.55750817,491.29974,-9.2281027
195.438,10.883459,9.4676857,0.0,0,0.24542005,0.0,0.99634451,51.283218,0.47030488,492.15213,-9.2296104
195.4404,9.5567245,9.4761238,0.0,0,0.10962804,0.0,0.99921924,44.869862,0.43009132,494.81323,-9.2302828
195.4428,8.9579048,9.4722013,0.0,0,-0.025516471,0.0,0.99938023,42.040493,0.39891246,497.83609,-9.2326365
195.4452,8.6863108,9.4791813,0.0,0,-0.15794852,0.0,0.99999434,40.703255,0.37288338,500.85895,-9.2327881
195.4476,8.7222672,9.4896441,0.0,0,-0.29038054,0.0,1.0006549,40.813126,0.33016461,503.88181,-9.2313118
195.45,9.0683136,9.499321,0.0,0,-0.42281252,0.0,1.0017573,42.416756,0.26517045,505.79642,-9.2316818
195.4524,9.1952057,9.5047836,0.0,0,-0.55524451,0.0,1.0039215,42.882717,0.19727236,507.15689,-9.2324724
195.4548,9.1676197,9.5060987,0.0,0,-0.68767649,0.0,1.0054336,42.693905,0.13426931,508.51736,-9.2334776
195.4572,9.0282803,9.5069542,0.0,0,-0.82010847,0.0,1.0056162,42.03167,0.080344938,509.87787,-9.2323742
195.4596,8.8126574,9.5140066,0.0,0,-0.95254052,0.0,1.0057461,41.059223,0.0400238,510.55453,-9.2320337
195.462,8.5203114,9.5207253,0.0,0,-1.0849725,0.0,1.0059402,39.69463,0.0121191,510.54736,-9.2311926
195.4644,8.1069756,9.5215874,0.0,0,-0.72870666,450.0,1.0064458,37.732166,0.0012960283,510.54022,-9.2327032
195.4668,7.6542258,9.517127,0.0,0,-0.27022031,450.0,1.0070316,35.648865,0.005581087,510.53305,-9.2338543
195.4692,7.2945147,9.5159245,0.0,0,0.18826602,450.0,1.0073789,33.941868,0.008760944,510.48294,-9.2325926
195.4716,7.0514975,9.5185633,0.0,0,0.64675242,450.0,1.0069907,32.819794,0.013845263,510.34692,-9.2327032
195.474,6.8551488,9.5238857,0.0,0,1.105239,450.0,1.0067247,31.920334,0.01369968,510.21091,-9.2335386
195.4764,6.4941115,9.5272331,0.0,0,1.5637254,450.0,1.0069745,30.245678,0.025779063,510.07489,-9.2342024
195.4788,5.4434156,9.5248165,0.0,0,2.0222118,450.0,1.0077797,25.44422,0.076243341,509.99615,-9.2348309
195.4812,3.3478816,9.5053635,0.0,0,2.4806983,450.0,1.0055053,15.785613,0.2075894,510.20377,-9.2367592
195.4836,0.58853602,9.4782066,0.0,0,2.9391847,450.0,1.0002172,2.9247739,0.43455774,510.41138,-9.2380753
195.486,-0.037072297,9.3981686,0.0,0,3.3976712,450.0,0.98438579,-0.015279545,0.89509559,510.61899,-9.2385502
195.4884,-0.26057032,9.3619604,0.0,0,3.8561575,450.0,0.97766668,-1.2612487,1.6206306,510.8266,-9.2375355
195.4908,0.0059478045,9.3242817,0.0,0,4.3146439,450.0,0.97161347,0.066772602,2.4401846,511.07715,-9.2366047
195.4932,0.022645403,9.3199644,0.0,0,4.7731299,450.0,0.97188342,0.091086142,3.1384077,511.32773,-9.2362928
195.4956,-0.042323388,9.3344126,0.0,0,5.2316165,450.0,0.97447783,-0.12235151,3.6508894,511.57828,-9.236659
195.498,-0.065023191,9.3535728,0.0,0,5.6901031,450.0,0.97732323,-0.34570864,4.0783277,511.82886,-9.2374058
195.5004,0.091005541,9.3730669,0.0,0,6.1485891,450.0,0.97930306,0.40250051,4.49859,512.06152,-9.2378826
195.5028,0.038148526,9.3883257,0.0,0,6.6070752,450.0,0.98192382,0.22142039,4.9169598,512.29059,-9.2368269
195.5052,-0.046073914,9.399971,0.0,0,7.0655622,450.0,0.98549825,-0.30770493,5.3408904,512.51971,-9.2366524
195.5076,0.050693616,9.4025927,0.0,0,7.5240488,450.0,0.9870078,0.14909364,5.8058643,512.74878,-9.2363586
195.51,0.081519566,9.4104052,0.0,0,7.9825354,450.0,0.98775423,0.45743868,6.2906332,512.96356,-9.2369461
195.5124,-0.092682213,9.4266405,0.0,0,8.441021,450.0,0.98946595,-0.51942074,6.7707214,513.17114,-9.2358904
195.5148,0.1513502,9.437047,0.0,0,8.8995075,450.0,0.99094176,0.65847135,7.2600069,513.37878,-9.2356386
195.5172,-0.040934183,9.4430866,0.0,0,9.3579931,450.0,0.9927085,-0.078069903,7.737772,513.58636,-9.2344332
195.5196,-0.078036301,9.4430723,0.0,0,9.8164806,450.0,0.99404258,-0.3912538,8.2036037,513.77612,-9.234973
195.522,0.13171063,9.4415493,0.0,0,10.274966,450.0,0.99357355,0.53727895,8.6813059,513.94794,-9.2356548
195.5244,-0.024008382,9.4447622,0.0,0,10.733453,450.0,0.99323052,0.025106231,9.152422,514.11975,-9.233901
195.5268,-0.059546739,9.4523468,0.0,0,11.191939,450.0,0.99358726,-0.37909278,9.6152115,514.29156,-9.2338037
195.5292,0.12362747,9.4534292,0.0,0,11.650426,450.0,0.99383706,0.60855645,10.094629,514.44672,-9.2343025
195.5316,-0.037996415,9.4510803,0.0,0,12.108912,450.0,0.99497443,-0.10075744,10.570305,514.56842,-9.2348537
195.534,-0.024469025,9.450963,0.0,0,12.567399,450.0,0.99569988,-0.23521616,11.038013,514.69006,-9.2351313
195.5364,0.16546085,9.4487524,0.0,0,13.025885,450.0,0.99460286,0.85018325,11.507024,514.81177,-9.2344418
195.5388,-0.15363012,9.4568644,0.0,0,13.484371,450.0,0.9945358,-0.62141079,11.948205,514.93109,-9.2331123
195.5412,0.031730194,9.4552946,0.0,0,13.942858,450.0,0.99449587,0.06785991,12.410632,515.03845,-9.2331057
195.5436,0.092341185,9.4518213,0.0,0,14.401344,450.0,0.99473727,0.46495783,12.885084,515.14587,-9.2344837
195.546,-0.0025843135,9.4503908,0.0,0,14.859831,450.0,0.99535346,0.026857046,13.361528,515.25323,-9.2342958
195.5484,-0.11998498,9.451992,0.0,0,15.318317,450.0,0.99560338,-0.58878791,13.842532,515.3606,-9.2336044
195.5508,0.13960542,9.4535122,0.0,0,15.776803,450.0,0.9944483,0.64661092,14.326882,515.47516,-9.2325487
195.5532,-0.10963341,9.4609499,0.0,0,16.235291,450.0,0.99494505,-0.49399841,14.794155,515.58972,-9.2331581
195.5556,0.029992756,9.4605703,0.0,0,16.693775,450.0,0.99545389,0.05483878,15.247379,515.70422,-9.2333879
195.558,0.12587707,9.4501657,0.0,0,17.152262,450.0,0.99499446,0.65213275,15.71088,515.81879,-9.2336464
195.5604,-0.12022267,9.4495916,0.0,0,17.61075,450.0,0.99550378,-0.51377648,16.155495,515.92737,-9.2324247
195.5628,0.068092398,9.4485445,0.0,0,17.999975,450.0,0.99431932,0.27348936,16.612446,516.03479,-9.2320881
195.5652,0.088348135,9.4512053,0.0,0,18.0,450.0,0.99354285,0.47830638,17.075247,516.14215,-9.2312059
195.5676,-0.10083726,9.4541969,0.0,0,18.0,450.0,0.99413759,-0.43869013,17.496462,516.24957,-9.2328014
195.57,0.049882788,9.4527931,0.0,0,18.0,450.0,0.99493861,0.24728855,17.87742,516.31396,-9.2340946
195.5724,-0.011059823,9.451685,0.0,0,18.0,450.0,0.99587297,-0.028478894,18.191311,516.35693,-9.2349329
195.5748,0.030072656,9.4552879,0.0,0,18.0,450.0,0.99591851,0.11368505,18.408926,516.39984,-9.2383184
195.5772,0.090718858,9.4637299,0.0,0,18.0,450.0,0.99617344,0.38762408,18.517942,516.44281,-9.2442474
195.5796,0.014086327,9.4791765,0.0,0,18.0,450.0,0.99790895,0.14948843,18.489656,516.48578,-9.2520914
195.582,-0.0019583616,9.4891472,0.0,0,18.0,450.0,1.0006523,-0.078021504,18.362244,516.52875,-9.260498
195.5844,0.25308791,9.4894733,0.0,0,18.0,450.0,1.002254,1.1964102,18.226715,516.57172,-9.2739573
195.5868,0.13826935,9.4817524,0.0,0,18.0,450.0,1.0012397,0.64070326,18.112453,516.61469,-9.2899551
195.5892,0.20606138,9.4824495,0.0,0,18.0,450.0,1.0002441,0.98269212,18.060696,516.66956,-9.3084974
195.5916,0.15442182,9.4843979,0.0,0,18.0,450.0,0.99941725,0.73638719,18.053198,516.74829,-9.3302803
195.594,0.054885373,9.4848843,0.0,0,18.0,450.0,0.99977982,0.30003005,18.055971,516.82709,-9.3516874
195.5964,0.11926123,9.480547,0.0,0,18.0,450.0,1.0000443,0.53676808,18.071867,516.90582,-9.3714199
195.5988,0.18463635,9.4755621,0.0,0,18.0,450.0,0.99990058,0.88102829,18.096394,516.97742,-9.3916302
195.6012,0.16408193,9.4766245,0.0,0,18.0,450.0,0.99965483,0.72844732,18.117559,517.01318,-9.4112272
195.6036,0.11711156,9.4839249,0.0,0,18.0,450.0,0.99953377,0.57363451,18.134516,517.04895,-9.4298592
195.606,0.098467574,9.487772,0.0,0,18.0,450.0,0.99965101,0.43041712,18.14167,517.08478,-9.4462986
195.6084,0.17189731,9.4845781,0.0,0,18.0,450.0,1.0000452,0.78750098,18.143255,517.12054,-9.462698
195.6108,0.2075666,9.478611,0.0,0,18.0,450.0,1.0004535,0.95798361,18.138628,517.14917,-9.4808931
195.6132,0.13816172,9.4767408,0.0,0,18.0,450.0,1.0001328,0.67094481,18.139362,517.1778,-9.4974155
195.6156,0.10940264,9.4795313,0.0,0,18.0,450.0,0.99941301,0.53013992,18.133703,517.20648,-9.5162935
195.618,0.13725252,9.4812164,0.0,0,18.0,450.0,0.99887413,0.6152755,18.131504,517.23511,-9.5349827
195.6204,0.19388489,9.4812574,0.0,0,18.0,450.0,0.99925023,0.89628989,18.132658,517.25775,-9.5514345
195.6228,0.18901964,9.4796247,0.0,0,18.0,450.0,1.0001714,0.86702377,18.128767,517.27924,-9.5690727
195.6252,0.13771403,9.4793978,0.0,0,18.0,450.0,1.0007539,0.64069563,18.126993,517.30072,-9.5881968
195.6276,0.11985031,9.479867,0.0,0,18.0,450.0,1.0002477,0.54127496,18.121815,517.3222,-9.6061287
195.63,0.1741529,9.4861069,0.0,0,18.0,450.0,0.99984527,0.82110769,18.119501,517.34845,-9.6244612
195.6324,0.20390357,9.4899387,0.0,0,18.0,450.0,1.0000428,0.96814948,18.11817,517.37708,-9.6411257
195.6348,0.15314971,9.4882603,0.0,0,18.0,450.0,1.000957,0.75481176,18.114956,517.4057,-9.6592655
195.6372,0.10042821,9.4817495,0.0,0,18.0,450.0,1.0011749,0.50017101,18.113667,517.43433,-9.6780958
195.6396,0.15138806,9.4789724,0.0,0,18.0,450.0,1.0005083,0.68210363,18.112701,517.45941,-9.6957159
195.642,0.19932124,9.4807911,0.0,0,18.0,450.0,0.99948674,0.90716356,18.111778,517.4809,-9.7139597
195.6444,0.19472182,9.4856443,0.0,0,18.0,450.0,0.99960351,0.91704899,18.110348,517.50238,-9.7322044
195.6468,0.12620084,9.4846611,0.0,0,18.0,450.0,1.0000329,0.63759339,18.11499,517.52386,-9.7494383
195.6492,0.10883609,9.4797773,0.0,0,18.0,450.0,1.0002937,0.52568614,18.108618,517.53821,-9.7680693
195.6516,0.18034968,9.4753284,0.0,0,18.0,450.0,0.99996704,0.83767414,18.106964,517.53821,-9.7861223
195.654,0.19714645,9.4766483,0.0,0,18.0,450.0,0.99929976,0.91600543,18.107019,517.53821,-9.803051
195.6564,0.15339059,9.4837704,0.0,0,18.0,450.0,0.99921703,0.75761521,18.107704,517.53821,-9.8212013
195.6588,0.10416597,9.4893179,0.0,0,18.0,450.0,1.0002272,0.47572237,18.107969,517.54059,-9.8402567
195.6612,0.14313571,9.4865761,0.0,0,18.0,450.0,1.0012755,0.6361081,18.107719,517.55493,-9.8571243
195.6636,0.20120783,9.4777651,0.0,0,18.0,450.0,1.0006571,0.94127232,18.103468,517.56921,-9.8744688
195.666,0.18785898,9.4738626,0.0,0,18.0,450.0,0.9991855,0.8945291,18.103296,517.58356,-9.8939543
195.6684,0.12943052,9.4778528,0.0,0,18.0,450.0,0.9987731,0.61199003,18.104471,517.59784,-9.9125185
195.6708,0.11177222,9.4844675,0.0,0,18.0,450.0,0.99941486,0.49839363,18.102987,517.59784,-9.9305897
195.6732,0.17971934,9.4834776,0.0,0,18.0,450.0,1.0001756,0.78624642,18.099213,517.59784,-9.9471827
195.6756,0.20581354,9.4787893,0.0,0,18.0,450.0,1.0001659,0.96520692,18.099131,517.59784,-9.9644918
195.678,0.15549396,9.4771729,0.0,0,18.0,450.0,1.0001091,0.75035071,18.096388,517.59784,-9.983326
195.6804,0.11140544,9.4805269,0.0,0,18.0,450.0,0.9996776,0.52810735,18.095814,517.59784,-10.002489
195.6828,0.16089462,9.4872713,0.0,0,18.0,450.0,0.99982417,0.72754914,18.09885,517.59784,-10.020626
195.6852,0.1987845,9.490365,0.0,0,18.0,450.0,1.0006251,0.9120298,18.095734,517.59784,-10.039136
195.6876,0.21237384,9.4855919,0.0,0,18.0,450.0,1.0011002,1.0142542,18.092419,517.59784,-10.054081
195.69,0.14478849,9.4804211,0.0,0,18.0,450.0,1.0009582,0.6973663,18.096458,517.58832,-10.074668
195.6924,0.1325148,9.4801426,0.0,0,18.0,450.0,1.0000151,0.62723261,18.094809,517.57397,-10.093224
195.6948,0.18557538,9.4829826,0.0,0,18.0,450.0,0.99953699,0.84794199,18.091242,517.55969,-10.109286
195.6972,0.21940781,9.4861937,0.0,0,18.0,450.0,0.9999299,1.025156,18.091026,517.54535,-10.126987
195.6996,0.17658034,9.4869347,0.0,0,18.0,450.0,1.0009084,0.86267483,18.093523,517.53107,-10.144383
195.702,0.14225252,9.4851208,0.0,0,18.0,450.0,1.0015179,0.66136044,18.091507,517.51672,-10.163131
195.7044,0.15959793,9.4801102,0.0,0,18.0,450.0,1.0005548,0.74898875,18.086815,517.50238,-10.181722
195.7068,0.2140094,9.4811363,0.0,0,18.0,450.0,0.99964935,0.99079174,18.083158,517.48804,-10.198746
195.7092,0.21642381,9.487051,0.0,0,18.0,450.0,0.99957454,1.0252934,18.087442,517.48804,-10.216839
195.7116,0.15716702,9.4903774,0.0,0,18.0,450.0,1.0005798,0.7928977,18.081581,517.51666,-10.235555
195.714,0.12318277,9.4882288,0.0,0,18.0,450.0,1.0019124,0.56166625,18.0842,517.54529,-10.255122
195.7164,0.19575882,9.47927,0.0,0,18.0,450.0,1.0009226,0.88037175,18.084158,517.57391,-10.273746
195.7188,0.21122628,9.4799185,0.0,0,18.0,450.0,0.99985808,0.98932749,18.081373,517.5954,-10.290357
195.7212,0.18142575,9.4841728,0.0,0,18.0,450.0,0.99937224,0.86802608,18.080891,517.58105,-10.307229
195.7236,0.14286041,9.4873018,0.0,0,18.0,450.0,0.99998987,0.65881848,18.083141,517.56677,-10.327346
195.726,0.15464598,9.4844666,0.0,0,18.0,450.0,1.0006334,0.70573694,18.079039,517.55243,-10.344061
195.7284,0.20292589,9.4794397,0.0,0,18.0,450.0,1.0007472,0.93277395,18.078281,517.53815,-10.360917
195.7308,0.2128593,9.4787674,0.0,0,18.0,450.0,1.0002663,1.047793,18.078287,517.50238,-10.377768
195.7332,0.15458055,9.4853191,0.0,0,18.0,450.0,1.0000439,0.74547422,18.076571,517.46655,-10.397313
195.7356,0.13041733,9.4913359,0.0,0,18.0,450.0,1.0002829,0.59810483,18.078634,517.43079,-10.415649
195.738,0.19091137,9.4910173,0.0,0,18.0,450.0,1.0011395,0.88411009,18.07778,517.39502,-10.433383
195.7404,0.20638978,9.484602,0.0,0,18.0,450.0,1.0014918,0.93526775,18.076815,517.37708,-10.450264
195.7428,0.19238806,9.4794331,0.0,0,18.0,450.0,1.0008303,0.95125252,18.076488,517.36279,-10.46745
195.7452,0.16045716,9.4829702,0.0,0,18.0,450.0,1.0002667,0.7292887,18.073933,517.34845,-10.486829
195.7476,0.1531425,9.4860315,0.0,0,18.0,450.0,0.99999601,0.67186052,18.074905,517.33411,-10.505234
195.75,0.21654373,9.4872131,0.0,0,18.0,450.0,1.0001456,0.9997856,18.075172,517.315,-10.523104
195.7524,0.22582267,9.4849634,0.0,0,18.0,450.0,1.0009204,1.1065862,18.077961,517.29358,-10.54181
195.7548,0.17139375,9.4804859,0.0,0,18.0,450.0,1.001042,0.81974655,18.07542,517.27209,-10.558409
195.7572,0.15037909,9.479846,0.0,0,18.0,450.0,1.0000888,0.67429048,18.074835,517.25061,-10.57782
195.7596,0.19105218,9.4843111,0.0,0,18.0,450.0,0.99982327,0.8863799,18.07254,517.23627,-10.595731
195.762,0.22109817,9.4918098,0.0,0,18.0,450.0,1.0003684,1.0657707,18.074907,517.22913,-10.614561
195.7644,0.21127799,9.4908066,0.0,0,18.0,450.0,1.0011523,0.99276823,18.069283,517.22198,-10.63203
195.7668,0.15947182,9.484333,0.0,0,18.0,450.0,1.0014278,0.73730087,18.070126,517.21478,-10.650322
195.7692,0.16381811,9.4800072,0.0,0,18.0,450.0,1.0007557,0.7363525,18.069498,517.20288,-10.668192
195.7716,0.2153617,9.4816036,0.0,0,18.0,450.0,0.99980873,0.99443072,18.06764,517.1814,-10.685603
195.774,0.2289643,9.4856157,0.0,0,18.0,450.0,0.99968421,1.0625299,18.066149,517.15991,-10.702548
195.7764,0.18160221,9.485899,0.0,0,18.0,450.0,1.0001092,0.86058086,18.066996,517.13843,-10.720286
195.7788,0.1502824,9.4862003,0.0,0,18.0,450.0,1.0013344,0.7068578,18.067755,517.11816,-10.738706
195.7812,0.19494089,9.4824905,0.0,0,18.0,450.0,1.0012031,0.86450648,18.06591,517.10382,-10.755859
195.7836,0.23720089,9.4813395,0.0,0,18.0,450.0,1.0003008,1.0817851,18.063208,517.08954,-10.774906
195.786,0.20802522,9.4874773,0.0,0,18.0,450.0,0.99997222,1.0132124,18.062689,517.0752,-10.791499
195.7884,0.16422243,9.4925461,0.0,0,18.0,450.0,1.0006901,0.77315933,18.061769,517.06091,-10.810622
195.7908,0.16606271,9.4896183,0.0,0,18.0,450.0,1.0014303,0.72840995,18.061125,517.0824,-10.828768
195.7932,0.21396297,9.4822741,0.0,0,18.0,450.0,1.0015111,0.98727292,18.061752,517.10388,-10.848303
195.7956,0.22087388,9.4815197,0.0,0,18.0,450.0,1.0008692,1.0191288,18.064474,517.12537,-10.864036
195.798,0.1790776,9.4855127,0.0,0,18.0,450.0,1.0003343,0.86333245,18.061472,517.14679,-10.882675
195.8004,0.15540285,9.4882231,0.0,0,18.0,450.0,1.0000086,0.71840757,18.060658,517.14441,-10.900054
195.8028,0.19508789,9.4869232,0.0,0,18.0,450.0,1.0003639,0.87239051,18.061613,517.13727,-10.919461
195.8052,0.22736405,9.4812603,0.0,0,18.0,450.0,1.0006645,1.0748675,18.059172,517.13007,-10.935656
195.8076,0.21286473,9.4805994,0.0,0,18.0,450.0,1.0008339,1.0275135,18.0597,517.12292,-10.952905
195.81,0.17482018,9.4847937,0.0,0,18.0,450.0,1.0005386,0.83277959,18.059729,517.08716,-10.970624
195.8124,0.16624448,9.4929199,0.0,0,18.0,450.0,1.0007509,0.713337,18.057573,517.03705,-10.99107
195.8148,0.22655094,9.4918633,0.0,0,18.0,450.0,1.0006084,1.0165986,18.058754,516.98694,-11.008653
195.8172,0.23039012,9.4866438,0.0,0,18.0,450.0,1.0009711,1.0642323,18.057842,516.93683,-11.025359
195.8196,0.19158483,9.4845695,0.0,0,18.0,450.0,1.0017618,0.90902054,18.054125,516.9046,-11.04317
195.822,0.16381134,9.4834566,0.0,0,18.0,450.0,1.0010709,0.80858904,18.054571,516.89026,-11.061583
195.8244,0.20752792,9.4851265,0.0,0,18.0,450.0,0.99992377,0.93088704,18.055923,516.87592,-11.079456
195.8268,0.24523546,9.4868994,0.0,0,18.0,450.0,1.0000513,1.1351689,18.057165,516.86157,-11.097596
195.8292,0.22048037,9.4876862,0.0,0,18.0,450.0,1.000721,1.0510688,18.05352,516.84967,-11.116313
195.8316,0.18688205,9.4873819,0.0,0,18.0,450.0,1.0016967,0.88199335,18.053442,516.84253,-11.13506
195.834,0.17135417,9.4845352,0.0,0,18.0,450.0,1.001585,0.76852673,18.053375,516.83539,-11.153496
195.8364,0.23129967,9.4871387,0.0,0,18.0,450.0,1.0007993,1.0694394,18.053818,516.82825,-11.170577
195.8388,0.22241654,9.4905729,0.0,0,18.0,450.0,1.0003754,1.0402464,18.054697,516.81989,-11.188005
195.8412,0.19696765,9.4946146,0.0,0,18.0,450.0,1.0014,0.95051855,18.052521,516.80554,-11.206163
195.8436,0.18595143,9.491437,0.0,0,18.0,450.0,1.0021844,0.85130644,18.045994,516.7912,-11.225286
195.846,0.20405923,9.4845648,0.0,0,18.0,450.0,1.0018383,0.94135225,18.049555,516.77692,-11.242204
195.8484,0.23635697,9.4810467,0.0,0,18.0,450.0,1.0003881,1.1024244,18.051085,516.76257,-11.25793
195.8508,0.23303409,9.4842415,0.0,0,18.0,450.0,0.99975383,1.095286,18.045506,516.75543,-11.276858
195.8532,0.17452088,9.4904995,0.0,0,18.0,450.0,1.0005547,0.81542969,18.048674,516.74829,-11.295507
195.8556,0.17765811,9.4893713,0.0,0,18.0,450.0,1.0014491,0.79995131,18.051579,516.74115,-11.31393
195.858,0.2351902,9.484849,0.0,0,18.0,450.0,1.0015208,1.0947387,18.047823,516.73401,-11.330471
195.8604,0.23881046,9.4827948,0.0,0,18.0,450.0,1.0011131,1.0948789,18.044262,516.72083,-11.349443
196.0623,0.1893817,9.4893646,0.0,0,18.0,0.85476655,1.0013599,0.88210934,18.025772,511.80457,-11.478881
197.2623,0.18027115,9.5014906,0.0,0,18.0,3.6951402e-17,1.0035779,0.84151208,18.00012,494.28827,-11.480824
198.4623,0.19835122,9.5113811,0.0,0,18.0,1.5974026e-33,1.0054147,0.92276096,17.999535,481.46768,-11.480227
199.6623,0.20327699,9.5202503,0.0,0,18.0,1.4012985e-45,1.0069108,0.95058197,18.000164,469.62781,-11.481482
200.8623,0.21053013,9.5288916,0.0,0,18.0,1.4012985e-45,1.0084876,0.97956002,17.999992,458.3833,-11.48162
202.0623,0.21687776,9.5361528,0.0,0,18.0,1.4012985e-45,1.0099287,1.0057106,17.99954,447.49673,-11.480949
203.2623,0.2192872,9.5433807,0.0,0,18.0,1.4012985e-45,1.0113262,1.0138484,17.999386,436.6474,-11.480965
204.4623,0.22695617,9.5508375,0.0,0,18.0,1.4012985e-45,1.0125595,1.0486534,17.999891,426.11282,-11.480801
205.6623,0.22833367,9.5576611,0.0,0,18.0,1.4012985e-45,1.0138811,1.052117,18.000437,415.5928,-11.48136
206.8623,0.23433539,9.5645323,0.0,0,18.0,1.4012985e-45,1.0151037,1.0835553,17.999947,405.33127,-11.481246
208.0623,0.23574644,9.5710564,0.0,0,18.0,1.4012985e-45,1.0161866,1.0946323,18.000374,395.31296,-11.481471
209.2623,0.24210781,9.5780821,0.0,0,18.0,1.4012985e-45,1.0175896,1.1128166,17.999876,385.33115,-11.481384
210.4623,0.24696115,9.5844126,0.0,0,18.0,1.4012985e-45,1.018883,1.1372099,17.999722,375.73669,-11.481157
211.6623,0.24946231,9.5906601,0.0,0,18.0,1.4012985e-45,1.01994,1.1506001,18.00025,366.20105,-11.481064
212.8623,0.25135764,9.5970545,0.0,0,18.0,1.4012985e-45,1.0211107,1.1553063,17.999298,356.80466,-11.481236
214.0623,0.25876939,9.6026869,0.0,0,18.0,1.4012985e-45,1.0221962,1.1892868,17.998953,347.73004,-11.481347
215.2623,0.25950202,9.6090479,0.0,0,18.0,1.4012985e-45,1.0232282,1.1826901,18.001011,338.88727,-11.480933
216.4623,0.26704738,9.614666,0.0,0,18.0,1.4012985e-45,1.0243285,1.2232823,18.000013,330.28525,-11.481495
217.6623,0.26870045,9.6197433,0.0,0,18.0,1.4012985e-45,1.025409,1.2301911,17.999285,321.97971,-11.481586
218.8623,0.27460083,9.6263876,0.0,0,18.0,1.4012985e-45,1.0265975,1.2515739,17.999975,313.74438,-11.481712
220.0623,0.28009459,9.6315231,0.0,0,18.0,1.4012985e-45,1.0275106,1.2719415,18.000433,305.93542,-11.48151
221.2623,0.28239381,9.6368437,0.0,0,18.0,1.4012985e-45,1.0285316,1.2862446,17.999695,298.36795,-11.48228
222.4623,0.29058,9.6421003,0.0,0,18.0,1.4012985e-45,1.0293888,1.3236016,18.00094,290.81635,-11.481506
223.6623,0.29119277,9.6472855,0.0,0,18.0,1.4012985e-45,1.0303991,1.3237563,18.000317,283.31659,-11.481456
224.8623,0.29206842,9.6517591,0.0,0,18.0,1.4012985e-45,1.031368,1.328949,17.999546,276.36255,-11.481366
226.0623,0.30129352,9.6566458,0.0,0,18.0,1.4012985e-45,1.0322453,1.3669192,17.999836,269.38464,-11.480995
227.2623,0.30252132,9.6608648,0.0,0,18.0,1.4012985e-45,1.0329905,1.3722349,17.999525,262.61383,-11.480882
228.4623,0.30589795,9.6657896,0.0,0,18.0,1.4012985e-45,1.0339328,1.3850849,17.999819,256.02298,-11.481355
229.6623,0.31036258,9.6707811,0.0,0,18.0,1.4012985e-45,1.0347621,1.406294,17.999586,249.65842,-11.481071
230.8623,0.3104631,9.6743202,0.0,0,18.0,1.4012985e-45,1.0354654,1.3991994,18.000084,243.30867,-11.4816
232.0623,0.31367308,9.6783724,0.0,0,18.0,1.4012985e-45,1.0363746,1.4174703,18.000404,237.11876,-11.481438
233.2623,0.3123005,9.6826229,0.0,0,18.0,1.4012985e-45,1.0370762,1.4036618,18.000481,231.17023,-11.481668
234.4623,0.31185454,9.6870441,0.0,0,18.0,1.4012985e-45,1.0379183,1.4113519,17.99894,225.42487,-11.481559
235.6623,0.31275958,9.6913776,0.0,0,18.0,1.4012985e-45,1.0387199,1.4122227,17.999557,219.82988,-11.480989
236.8623,0.31714571,9.6951361,0.0,0,18.0,1.4012985e-45,1.0393397,1.4257458,17.999743,214.31543,-11.481471
238.0623,0.31670976,9.6989012,0.0,0,18.0,1.4012985e-45,1.0401636,1.4242837,17.999866,209.11894,-11.481787
239.2623,0.31826693,9.7025938,0.0,0,18.0,1.4012985e-45,1.0409408,1.4334185,17.99987,203.8105,-11.481981
240.4623,0.32075322,9.7061024,0.0,0,18.0,1.4012985e-45,1.0414507,1.4438175,18.000061,198.84175,-11.481682
241.6623,0.31664681,9.7098093,0.0,0,18.0,1.4012985e-45,1.042271,1.4203923,17.999861,193.95743,-11.481444
242.8623,0.32246986,9.7134457,0.0,0,18.0,1.4012985e-45,1.0428264,1.449156,17.999969,189.18344,-11.481672
244.0623,0.32269901,9.7162266,0.0,0,18.0,1.4012985e-45,1.0433578,1.4443645,17.999748,184.7049,-11.48129
245.2623,0.3245317,9.7197008,0.0,0,18.0,1.4012985e-45,1.0441738,1.4571726,17.999712,180.11601,-11.481651
246.4623,0.32492909,9.7229137,0.0,0,18.0,1.4012985e-45,1.0446881,1.4545527,18.001318,175.85336,-11.481627
247.6623,0.32498962,9.7259865,0.0,0,18.0,1.4012985e-45,1.0452768,1.4573808,18.000565,171.54994,-11.481118
248.8623,0.32397607,9.7294731,0.0,0,18.0,1.4012985e-45,1.0459501,1.4470965,17.999634,167.53931,-11.481275
250.0623,0.32657981,9.7322683,0.0,0,18.0,1.4012985e-45,1.0463259,1.4670496,17.999651,163.63197,-11.481294
251.2623,0.32409316,9.7350245,0.0,0,18.0,1.4012985e-45,1.0469755,1.4432875,18.000473,159.80217,-11.481621
252.4623,0.3215358,9.7382965,0.0,0,18.0,1.4012985e-45,1.0476938,1.4367893,18.000027,156.04379,-11.481155
253.6623,0.32739738,9.7411222,0.0,0,18.0,1.4012985e-45,1.0481055,1.4612321,17.999702,152.45758,-11.481442
254.8623,0.33028227,9.7433672,0.0,0,18.0,1.4012985e-45,1.0486327,1.4765576,17.998959,148.91144,-11.481491
255.8623,0.32447022,9.7462263,0.0,0,18.0,1.4012985e-45,1.0490894,1.4484134,18.000916,145.9673,-11.481783