File: raw data/testID_0229.csv
Time(sec),Force(kN),Jaw(mm),PowAngle(deg),Power(W),Pram,PTemp,Strain,Stress(MPa),Stroke(mm),TC1(C),wedge(mm)
0.0,1.0471957,0.16045763,0.0,0,11.076097,0.0011005693,0.010786728,13.206076,11.075941,12.844309,-9.1564217
1.2,0.99746263,-2.1063458e-06,0.0,0,11.076097,3.5158761,-6.1557221e-06,12.69051,11.077269,12.830015,-9.4932632
2.4,0.95411408,-6.9973466e-05,0.0,0,11.076097,7.1158752,-3.4256432e-06,12.154899,11.075979,12.847435,-9.4881353
3.6,0.96571666,7.16676e-05,0.0,0,11.076097,10.715875,-1.6766542e-05,12.300992,11.076632,12.76976,-9.4894114
4.8,0.93319452,-3.3516928e-05,7.7926893,0,11.076097,14.315874,-2.1378646e-05,11.878338,11.076759,12.788417,-9.486475
6.0,0.9252407,-0.00036889937,27.631016,0,11.076097,17.915878,9.3953913e-06,11.784324,11.075872,12.752386,-9.4842043
7.2,0.92778695,-0.00078310585,39.060253,0,11.076097,21.515879,-3.6459733e-05,11.798499,11.0762,13.398345,-9.4827175
8.4,0.94746673,-0.0030099086,45.428757,0,11.076097,25.115879,-0.00019706492,12.080913,11.076326,15.738631,-9.4808798
9.6,0.95899373,-0.0057837302,48.382519,0,11.076097,28.715878,-0.00040596953,12.220373,11.075979,20.314817,-9.4784193
10.8,0.96094871,-0.0095885852,49.229733,0,11.076097,32.315876,-0.00066408218,12.230751,11.076221,26.487032,-9.4762859
12.0,0.96107858,-0.012454621,47.760761,0,11.076097,35.915886,-0.00081543648,12.238459,11.076776,33.621887,-9.4742899
13.2,0.92932063,-0.013759974,45.16975,0,11.076097,39.515888,-0.00089821592,11.832396,11.076959,40.293739,-9.472229
14.4,0.8987639,-0.013596011,42.451694,0,11.076097,43.115891,-0.00089303456,11.466155,11.077306,45.408966,-9.4696655
15.6,0.88932902,-0.013391844,41.198734,0,11.076097,46.715885,-0.00091247389,11.327574,11.076525,49.04443,-9.4670649
16.8,0.87711996,-0.013075071,41.794918,0,11.076097,50.315876,-0.00089580368,11.175532,11.076708,51.367527,-9.4648905
18.0,0.87423307,-0.013774231,43.70528,0,11.076097,53.915874,-0.00090510177,11.153095,11.076499,53.204002,-9.4626455
19.2,0.87724149,-0.014839297,45.615158,0,11.076097,57.515877,-0.00095995358,11.188612,11.076158,55.526253,-9.4605217
20.4,0.8779729,-0.016162971,47.289154,0,11.076097,61.115871,-0.0010836928,11.199612,11.07566,58.635559,-9.4589262
21.6,0.891123,-0.018413557,47.539589,0,11.076097,64.715889,-0.0012350378,11.365566,11.075922,62.773056,-9.4569454
22.8,0.87798035,-0.019687369,47.504887,0,11.076097,68.31588,-0.0013402737,11.183311,11.076432,67.379303,-9.4551897
24.0,0.862831,-0.021016005,46.582062,0,11.076097,71.915886,-0.0013965127,10.993554,11.075908,72.035103,-9.4527884
25.2,0.85640717,-0.02128469,45.915108,0,11.076097,75.515892,-0.0013873916,10.920225,11.076046,76.138596,-9.4509611
26.4,0.85940087,-0.021660792,45.615238,0,11.076097,79.115891,-0.0014556143,10.962315,11.076177,79.672363,-9.4489985
27.6,0.84716564,-0.02227515,45.999405,0,11.076097,82.715889,-0.001480283,10.80773,11.076198,82.791252,-9.4466953
28.8,0.850362,-0.023096841,46.932961,0,11.076097,86.315887,-0.0015650569,10.838907,11.076531,85.641586,-9.4446583
30.0,0.8446973,-0.024595963,47.504883,0,11.076097,89.915901,-0.0016388751,10.777475,11.076528,88.858803,-9.4424076
31.2,0.84722185,-0.025825825,47.955318,0,11.076097,93.515892,-0.0016908093,10.809914,11.076432,92.478989,-9.4400921
32.4,0.84711599,-0.026993247,47.955318,0,11.076097,97.115906,-0.0018137315,10.800181,11.075992,96.469986,-9.4380493
33.6,0.84678704,-0.028088709,47.531685,0,11.076097,100.71589,-0.0018599156,10.805028,11.075777,100.57027,-9.4363298
34.8,0.83950543,-0.02930906,47.353905,0,11.076097,104.3159,-0.001983563,10.716116,11.076053,104.54625,-9.4341631
36.0,0.84117204,-0.03051151,47.054447,0,11.076097,107.91587,-0.0020297396,10.737857,11.075869,108.12695,-9.4318972
37.2,0.84308904,-0.031342763,47.394154,0,11.076097,111.5159,-0.0020481611,10.748052,11.076162,111.45723,-9.4299088
38.4,0.83627403,-0.032701727,47.536381,0,11.076097,115.11588,-0.0021946265,10.674524,11.076011,114.84801,-9.4276657
39.6,0.83242017,-0.034007054,47.955318,0,11.076097,118.71589,-0.0022599951,10.627625,11.076257,118.27883,-9.4256773
40.8,0.84714431,-0.035553705,47.955318,0,11.076097,122.31589,-0.0024030583,10.797391,11.076454,122.07517,-9.4240236
42.0,0.82895273,-0.037343279,47.955318,0,11.076097,125.91588,-0.0024720319,10.583197,11.076635,125.85613,-9.4217119
43.2,0.83085972,-0.038857419,47.826393,0,11.076097,129.51599,-0.0025519349,10.608228,11.076359,129.51816,-9.4196739
44.4,0.83300436,-0.040045135,47.504887,0,11.076097,133.11588,-0.0026694152,10.645556,11.075846,133.27867,-9.4179955
45.6,0.83386475,-0.041639846,47.704346,0,11.076097,136.71588,-0.0027852692,10.640675,11.076083,136.63911,-9.4159088
46.8,0.82730854,-0.042900812,47.955307,0,11.076097,140.31587,-0.002875725,10.562558,11.076931,140.21193,-9.4135599
48.0,0.8269769,-0.044778015,47.955318,0,11.076097,143.91586,-0.0029492136,10.566272,11.076423,143.69948,-9.411767
49.2,0.81986856,-0.046367772,47.955318,0,11.076097,147.51588,-0.0030862156,10.469462,11.076396,147.40857,-9.4097919
50.4,0.82520151,-0.047600161,47.955318,0,11.076097,151.11589,-0.0031488738,10.537734,11.07646,151.09717,-9.4075222
51.6,0.82486528,-0.049085185,47.955318,0,11.076097,154.71588,-0.0032977108,10.545787,11.075788,154.65623,-9.405468
52.8,0.82607824,-0.050693195,47.955318,0,11.076097,158.31587,-0.0033884314,10.565413,11.076478,158.25612,-9.4032831
54.0,0.80928403,-0.053004414,47.955318,0,11.076097,161.91589,-0.0034818773,10.345179,11.076214,161.80978,-9.4012346
55.2,0.81710565,-0.054358579,47.955318,0,11.076097,165.51588,-0.0036376584,10.440407,11.075632,165.44585,-9.3990927
56.4,0.82358986,-0.055750541,48.22826,0,11.076097,169.11591,-0.0037031514,10.5177,11.076401,168.9512,-9.3970623
57.6,0.82274741,-0.057489764,48.142399,0,11.076097,172.71588,-0.0038544589,10.521944,11.076447,172.60965,-9.3954678
58.8,0.82932758,-0.059528764,48.383209,0,11.076097,176.31589,-0.0039452147,10.587331,11.076571,176.19807,-9.3932467
60.0,0.82903868,-0.061459247,48.052029,0,11.076097,179.91588,-0.0040643932,10.59283,11.077132,179.94295,-9.391078
61.2,0.82423127,-0.06314458,47.955326,0,11.076097,183.5159,-0.0041985032,10.535053,11.07722,183.76459,-9.3889513
62.4,0.82306743,-0.0649672,47.928997,0,11.076097,187.11589,-0.0043415683,10.51389,11.075974,187.30246,-9.3869314
63.6,0.82608694,-0.066821963,47.955318,0,11.076097,190.71591,-0.0044505345,10.563354,11.076174,190.64015,-9.3847742
64.8,0.83622038,-0.068767063,48.383785,0,11.076097,194.31589,-0.0045309905,10.689194,11.076479,193.94931,-9.3827667
66.0,0.83461297,-0.070905507,48.788025,0,11.076097,197.91591,-0.0047240225,10.666707,11.076733,197.36794,-9.3808641
67.2,0.83728445,-0.073398955,48.788246,0,11.076097,201.51588,-0.0048755785,10.719691,11.076987,201.16737,-9.3783741
68.4,0.84385252,-0.075031571,48.390503,0,11.076097,205.11591,-0.005018902,10.798109,11.076303,205.11566,-9.3764648
69.6,0.8384164,-0.077668928,48.480236,0,11.076097,208.7159,-0.0051551559,10.73509,11.075944,208.62888,-9.3743439
70.8,0.84783298,-0.079157151,48.812252,0,11.076097,212.31592,-0.0052463985,10.870216,11.076066,212.00383,-9.3724623
72.0,0.85198808,-0.081178546,48.812252,0,11.076097,215.91591,-0.0053867493,10.911978,11.07606,215.81059,-9.3705587
73.2,0.83263505,-0.083013877,48.786419,0,11.076097,219.51591,-0.0055511161,10.657675,11.076003,219.54024,-9.3683109
74.4,0.83315939,-0.085414603,48.812252,0,11.076097,223.11589,-0.0056915767,10.671367,11.07602,222.86728,-9.3658915
75.6,0.85142505,-0.087906919,49.229733,0,11.076097,226.71591,-0.0058032516,10.911885,11.076004,226.25365,-9.3640842
76.8,0.84701216,-0.090009913,49.229733,0,11.076097,230.31589,-0.0059978073,10.8591,11.076284,230.05804,-9.3620415
78.0,0.85454297,-0.092903689,48.924622,0,11.076097,233.91592,-0.006167307,10.935128,11.076264,233.98741,-9.3599281
79.2,0.8659789,-0.095814608,48.81226,0,11.076097,237.51588,-0.0064020557,11.086946,11.07614,237.72925,-9.358161
80.4,0.86569595,-0.097383603,48.776989,0,11.076097,241.11589,-0.0064519113,11.092561,11.075764,241.37979,-9.3560581
81.6,0.86194003,-0.099442504,48.56678,0,11.076097,244.71588,-0.0065902434,11.063278,11.075933,244.88269,-9.3540945
82.8,0.85525078,-0.10198292,48.811928,0,11.076097,248.3159,-0.0067569353,10.966605,11.075825,248.34424,-9.3520718
84.0,0.877038,-0.10451704,48.726292,0,11.076097,251.91589,-0.0069723795,11.23908,11.075936,251.96886,-9.349926
85.2,0.85968012,-0.10690382,48.50724,0,11.076097,255.51588,-0.007109113,11.028881,11.076119,255.62184,-9.3478584
86.4,0.87282497,-0.10930097,48.812248,0,11.076097,259.11615,-0.0072205109,11.198526,11.076125,259.01318,-9.3457718
87.6,0.8609634,-0.11144884,48.812252,0,11.076097,262.71588,-0.0074133226,11.046943,11.075902,262.65057,-9.3439646
88.8,0.88548315,-0.11469039,48.812252,0,11.076097,266.31589,-0.0076356381,11.363825,11.076436,266.26147,-9.3417645
90.0,0.8847217,-0.11617453,48.840618,0,11.076097,269.91589,-0.0077395625,11.36365,11.077224,269.77487,-9.3397865
91.2,0.88011438,-0.1192508,48.81226,0,11.076097,273.51587,-0.0078788325,11.289615,11.076057,273.34686,-9.3374882
92.4,0.8931846,-0.12197478,48.81226,0,11.076097,277.11584,-0.0081100278,11.468607,11.076406,277.16766,-9.3353453
93.6,0.87984633,-0.12447611,48.385216,0,11.076097,280.71588,-0.0082539702,11.301086,11.076582,281.02774,-9.3333035
94.8,0.88865155,-0.12667112,48.383793,0,11.076097,284.31589,-0.008430372,11.397048,11.075779,284.7178,-9.3315678
96.0,0.89404416,-0.12896489,48.213146,0,11.076097,287.91589,-0.0085424902,11.481621,11.076924,288.28171,-9.3293619
97.2,0.89324969,-0.13137408,48.379807,0,11.076097,291.5159,-0.008716329,11.476606,11.076495,291.65982,-9.3275003
98.4,0.91233701,-0.13468696,48.383507,0,11.076097,295.11591,-0.0089322235,11.713573,11.076164,295.26352,-9.3255768
99.6,0.90921122,-0.13656707,47.955326,0,11.076097,298.71591,-0.0090932893,11.698752,11.076123,299.09348,-9.3233128
100.8,0.88934076,-0.13970745,47.504887,0,11.076097,302.31589,-0.0092756823,11.416621,11.076049,302.90222,-9.3212471
102.0,0.91633278,-0.14233863,47.453407,0,11.076097,305.91589,-0.0094099594,11.76779,11.076324,306.4451,-9.3194313
103.2,0.91135675,-0.14351946,47.504883,0,11.076097,309.5159,-0.0095235165,11.719096,11.076543,309.68646,-9.3171654
104.4,0.90264195,-0.14631967,47.532127,0,11.076097,313.11591,-0.009726556,11.608774,11.075913,313.06125,-9.3152227
105.6,0.92448258,-0.1495488,47.506577,0,11.076097,316.71591,-0.0099295899,11.883021,11.075665,316.72128,-9.3133221
106.8,0.9248696,-0.15146182,47.504887,0,11.076097,320.31592,-0.010003231,11.911237,11.076047,320.41141,-9.311121
108.0,0.91592628,-0.1540903,47.358311,0,11.076097,323.91592,-0.010233003,11.783524,11.07652,324.16815,-9.3091764
109.2,0.90844065,-0.15614958,47.060165,0,11.076097,327.5159,-0.010345614,11.693782,11.076291,327.81763,-9.307126
110.4,0.922517,-0.15900022,47.504883,0,11.076097,331.11594,-0.010559714,11.86174,11.076611,331.17337,-9.3051281
111.6,0.93032175,-0.16132954,47.487545,0,11.076097,334.71591,-0.010685684,11.976161,11.076251,334.83759,-9.3032799
112.8,0.91098607,-0.16320421,47.055984,0,11.076097,338.31595,-0.010828667,11.730644,11.076299,338.45816,-9.301055
114.0,0.91336823,-0.16524759,47.504696,0,11.076097,341.91592,-0.010943908,11.755565,11.076277,341.79575,-9.2989998
115.2,0.91041994,-0.16713525,47.504883,0,11.076097,345.5159,-0.011114524,11.725746,11.077127,345.23392,-9.2968941
116.4,0.93677783,-0.17063588,47.846802,0,11.076097,349.11591,-0.011299954,12.054319,11.075646,348.87698,-9.2946568
117.6,0.93155944,-0.17197315,47.504887,0,11.076097,352.71591,-0.011376166,11.997276,11.075767,352.8847,-9.2926636
118.8,0.91825241,-0.1740367,47.054447,0,11.076097,356.31592,-0.011523983,11.827664,11.076719,356.60199,-9.2907467
120.0,0.91936111,-0.1758872,47.504883,0,11.076097,359.91589,-0.011696802,11.852142,11.07605,359.85236,-9.288579
121.2,0.91854638,-0.17833798,47.504883,0,11.076097,363.5159,-0.011821319,11.832682,11.07573,363.54907,-9.286706
122.4,0.92567456,-0.18180023,47.25296,0,11.076097,367.11591,-0.012010224,11.931212,11.077073,367.31604,-9.2847004
123.6,0.92125404,-0.18290238,47.054447,0,11.076097,370.71588,-0.012114966,11.878806,11.075927,370.92941,-9.2826395
124.8,0.90392929,-0.18423453,47.333168,0,11.076097,374.31589,-0.012235878,11.653132,11.07625,374.22684,-9.2803955
126.0,0.90574515,-0.18662006,47.504883,0,11.076097,377.91589,-0.012368188,11.688918,11.076335,377.84683,-9.2784691
127.2,0.89064115,-0.18872179,47.054474,0,11.076097,381.51593,-0.012465125,11.472417,11.076147,381.61243,-9.2762871
128.4,0.88854474,-0.19027886,47.054447,0,11.076097,385.11591,-0.012605812,11.461309,11.075938,385.20145,-9.2742939
129.6,0.88995546,-0.19223319,47.504848,0,11.076097,388.71588,-0.012757198,11.48436,11.076029,388.62439,-9.272253
130.8,0.88427055,-0.19463368,47.054447,0,11.076097,392.31589,-0.012905869,11.385188,11.076072,392.52277,-9.2702274
132.0,0.88127166,-0.19671007,46.932537,0,11.076097,395.91589,-0.012985975,11.363692,11.076603,396.23117,-9.2683992
133.2,0.88436002,-0.19845189,47.044392,0,11.076097,399.5159,-0.013142224,11.40467,11.07616,399.60641,-9.2666073
134.4,0.8831749,-0.19975224,47.05444,0,11.076097,403.11588,-0.013257825,11.392675,11.076071,403.11807,-9.2643528
135.6,0.87013203,-0.20164357,47.050522,0,11.076097,406.71588,-0.013359438,11.226066,11.076028,406.81305,-9.262085
136.8,0.86360031,-0.20245565,46.582649,0,11.076097,410.31592,-0.013382757,11.14727,11.076588,410.47446,-9.2601547
138.0,0.85677493,-0.20369641,46.679291,0,11.076097,413.91589,-0.013488133,11.048522,11.076106,414.01257,-9.2583666
139.2,0.84650606,-0.20507826,47.014214,0,11.076097,417.51593,-0.013608129,10.940624,11.077159,417.48883,-9.2562752
140.4,0.84233016,-0.20612688,46.656517,0,11.076097,421.11591,-0.013649737,10.874558,11.076096,421.2514,-9.2542772
141.6,0.82801545,-0.20630223,46.682068,0,11.076097,424.71591,-0.013623393,10.684041,11.076024,424.75668,-9.2522898
142.8,0.81999844,-0.20644313,47.05444,0,11.076097,428.31592,-0.013662848,10.57145,11.076402,428.13489,-9.250124
144.0,0.80050379,-0.20720848,47.05444,0,11.076097,431.91589,-0.0137639,10.302845,11.076759,431.78726,-9.2477999
145.2,0.78809804,-0.20829293,47.05444,0,11.076097,435.51593,-0.013795759,10.163119,11.076522,435.56201,-9.2462101
146.4,0.77645153,-0.20830993,46.834274,0,11.076097,439.11591,-0.01375809,10.0065,11.076817,439.26996,-9.2440844
147.6,0.7736209,-0.20854038,47.001003,0,11.076097,442.71594,-0.013788676,9.9911232,11.075874,442.70181,-9.2418547
148.8,0.77511609,-0.20782997,46.629837,0,11.076097,446.31589,-0.013802018,10.017995,11.076185,446.44617,-9.2399473
150.0,0.77328616,-0.20754704,46.816391,0,11.076097,449.91476,-0.01373927,9.9763651,11.075999,449.96332,-9.2379608
151.2,0.26051828,-0.22038838,43.54446,0,11.076097,449.9989,-0.014564075,3.3719592,11.076287,452.43692,-9.2377481
152.4,0.25030369,-0.2192087,44.105598,0,11.076097,449.9989,-0.014504948,3.2266126,11.075876,450.97214,-9.2379723
153.6,0.28402618,-0.21931553,45.615231,0,11.076097,449.9989,-0.014556553,3.6502275,11.076229,449.5112,-9.2380352
154.8,0.29266471,-0.2227179,45.377983,0,11.076097,449.9989,-0.014732244,3.7820334,11.076369,450.04636,-9.2375202
156.0,0.28096774,-0.2222539,44.084785,0,11.076097,449.9989,-0.014693148,3.6113238,11.076354,450.8815,-9.237463
157.2,0.27872068,-0.22245099,44.077152,0,11.076097,449.9989,-0.014702614,3.6076014,11.076393,450.73944,-9.2375574
158.4,0.28280205,-0.22249977,44.077145,0,11.076097,449.9989,-0.01474882,3.6456273,11.076296,450.33301,-9.237628
159.6,0.29910499,-0.22337382,44.488293,0,11.076097,449.9989,-0.014768536,3.8687365,11.076409,450.01334,-9.2377748
160.8,0.29871714,-0.22453867,44.077152,0,11.076097,449.9989,-0.014848094,3.8573897,11.076201,450.22128,-9.2376251
162.0,0.29624206,-0.22614662,43.73077,0,11.076097,449.9989,-0.014953732,3.8265071,11.075531,450.41486,-9.2374258
163.2,0.28441951,-0.22564188,43.742336,0,11.076097,449.9989,-0.014951755,3.6772702,11.07617,450.25467,-9.2370815
164.4,0.29777649,-0.22633311,43.717468,0,11.076097,449.9989,-0.014945103,3.8600221,11.075941,450.11221,-9.2371407
165.6,0.30474505,-0.22665685,43.527836,0,11.076097,449.9989,-0.01499558,3.9432456,11.075606,450.19858,-9.2374182
166.8,0.30228758,-0.22748064,43.527836,0,11.076097,449.9989,-0.015046765,3.903193,11.075646,450.33026,-9.2372255
168.0,0.29628983,-0.229407,42.983723,0,11.076097,449.9989,-0.015208862,3.8235638,11.076287,450.37347,-9.2370577
169.2,0.30228648,-0.22864644,43.301929,0,11.076097,449.9989,-0.015090724,3.9227974,11.076436,450.13455,-9.2374887
170.4,0.29927558,-0.22953403,42.980797,0,11.076097,449.9989,-0.015202244,3.8831546,11.075763,450.18341,-9.2374687
171.6,0.30099732,-0.22981378,42.97884,0,11.076097,449.9989,-0.015205739,3.9008126,11.07627,450.11203,-9.2372589
172.8,0.30737013,-0.23027551,42.978519,0,11.076097,449.9989,-0.015249327,3.9836485,11.076713,450.09802,-9.2375107
174.0,0.31466722,-0.23062295,42.978519,0,11.076097,449.9989,-0.015215861,4.0687547,11.076616,450.14542,-9.2369909
175.2,0.30749741,-0.23227726,42.482643,0,11.076097,449.9989,-0.015373029,3.9816344,11.076287,450.37512,-9.2370081
176.4,0.30994675,-0.23143478,42.653286,0,11.076097,449.9989,-0.015332299,3.9956863,11.076077,450.18686,-9.2371569
177.6,0.30460075,-0.23246245,42.747044,0,11.076097,449.9989,-0.015385692,3.9352481,11.076077,450.08676,-9.2366781
178.8,0.30921009,-0.23290724,42.532974,0,11.076097,449.9989,-0.015368205,4.0032454,11.076465,450.16364,-9.2368965
180.0,0.30911076,-0.23308715,42.966286,0,11.076097,449.9989,-0.015418909,4.0188494,11.076234,450.00381,-9.2367239
181.2,0.30858094,-0.23347414,42.645935,0,11.076097,449.9989,-0.015469505,3.9953806,11.076096,450.0553,-9.2365751
182.4,0.31163719,-0.23404561,42.399307,0,11.076097,449.9989,-0.015490654,4.0323572,11.075656,450.0892,-9.2366838
183.6,0.2461931,-0.2358281,42.406025,0,11.076097,449.9989,-0.015567334,3.1889675,11.07541,450.06485,-9.2301741
184.8,0.26214305,-0.23605034,42.468872,0,11.076097,449.9989,-0.015616585,3.384582,11.075513,450.05334,-9.2303314
186.0,0.27326396,-0.23586175,42.396244,0,11.076097,449.9989,-0.015628852,3.5540648,11.076038,450.15302,-9.2304363
187.2,0.28726164,-0.23632714,42.396244,0,11.076097,449.9989,-0.015638994,3.7190838,11.076672,450.27625,-9.230608
188.4,0.29005876,-0.23663938,41.802982,0,11.076097,449.9989,-0.015618132,3.7495651,11.076719,450.42795,-9.2306004
189.6,0.28723112,-0.23678191,41.802982,0,11.076097,449.9989,-0.015656825,3.7209692,11.076341,450.29086,-9.230732
190.8,0.30063814,-0.23706266,41.802982,0,11.076097,449.9989,-0.015703198,3.8844011,11.07615,450.10599,-9.2311049
192.0,0.3002488,-0.23751527,41.802982,0,11.076097,449.9989,-0.015717266,3.8897488,11.076032,450.07785,-9.230999
193.2,0.30424663,-0.23802696,41.802982,0,11.076097,449.9989,-0.015714681,3.9258885,11.076176,450.09161,-9.2308874
194.4,0.30670798,-0.23847674,41.499641,0,11.076097,449.9989,-0.015763419,3.9718945,11.076623,450.29358,-9.2310066
195.2805,0.34949708,0.031367458,29.25104,0,11.076099,3.2081115,0.0018494138,4.4530516,11.074512,450.25217,-9.2300692
195.2829,0.40744901,0.03196089,19.363346,0,11.076099,1.3868658000000002e-16,0.0021451768,5.207243,11.077598,450.26654,-9.2312059
195.2853,0.35370499,0.029650254,9.4756517,0,11.076099,5.9954178999999996e-33,0.0021346407,4.4840631,11.077672,450.28091,-9.2305889
195.2877,0.36316571,0.024916647,0.0,0,11.076099,0.0,0.0018515956,4.650424,11.075216,450.29678,-9.2313442
195.2901,0.35866353,0.02526883,0.0,0,11.076099,0.0,0.0016493697,4.5897217,11.0785,450.34708,-9.2306671
195.2925,0.33919156,0.026924318,0.0,0,11.076099,0.0,0.0016301584,4.3887773,11.078255,450.39737,-9.2304945
195.2949,0.3542617,0.026898591,0.0,0,11.076099,0.0,0.0016905635,4.4893565,11.075457,450.44769,-9.2303762
195.2973,0.37597495,0.026553113,0.0,0,11.076099,0.0,0.0018154122,4.6999502,11.075339,450.49799,-9.2314072
195.2997,0.35785666,0.026527297,0.0,0,11.076099,0.0,0.001961452,4.5629773,11.075449,450.4917,-9.2313118
195.3021,0.36176088,0.0276688,0.0,0,11.076099,0.0,0.0019247093,4.5161099,11.080517,450.47733,-9.2312031
195.3045,0.36511606,0.030598281,0.0,0,11.076099,0.0,0.0018826236,4.6879244,11.074364,450.46295,-9.230732
195.3069,0.35884175,0.031586885,0.0,0,11.076099,0.0,0.0018263287,4.5923414,11.075228,450.44858,-9.2316227
195.3093,0.37359837,0.031806,0.0,0,11.076099,0.0,0.0020083082,4.6808891,11.078781,450.4342,-9.2312603
195.3117,0.36711386,0.029714394,0.0,0,11.076099,0.0,0.002120276,4.6536155,11.078662,450.41986,-9.2311001
195.3141,0.35791349,0.026384767,0.0,0,11.076099,0.0,0.0020368071,4.5477557,11.076326,450.40549,-9.2310858
195.3165,0.36122569,0.026859077,0.0,0,11.076099,0.0,0.0018560371,4.5748062,11.075233,450.39111,-9.2298803
195.3189,0.38251048,0.026174797,0.0,0,11.076099,0.0,0.0016656331,4.8593349,11.081764,450.36896,-9.2311745
195.3213,0.37588233,0.027295999,0.0,0,11.076099,0.0,0.0017320992,4.7149496,11.074421,450.34018,-9.2306128
195.3237,0.37224087,0.029198958,0.0,0,11.076099,0.0,0.0018538865,4.735723,11.075232,450.31143,-9.2305031
195.3261,0.37198219,0.028312121,0.0,0,11.076099,0.0,0.0019675165,4.7410326,11.074397,450.28268,-9.2296343
195.3285,0.38096973,0.026989687,0.0,0,11.076099,0.0,0.0019532586,4.7117186,11.078469,450.2674,-9.2301855
195.3309,0.38960934,0.028068127,0.0,0,10.976468,0.0,0.0018954007,4.9297767,11.075522,450.2746,-9.2304974
195.3333,0.36956251,0.029538292,0.0,0,10.615494,0.0,0.0018242651,4.7644339,11.078059,450.2818,-9.2312126
195.3357,0.35776049,0.033040397,0.0,0,10.254521,0.0,0.001946057,4.652442,11.060877,450.28897,-9.2297573
195.3381,0.39323458,0.030770777,0.0,0,9.8935471,0.0,0.0020082381,5.0837603,10.932146,450.28421,-9.230092
195.3405,0.3837035,0.029475305,0.0,0,9.5325737,0.0,0.0021725486,4.8117056,10.647993,450.23389,-9.2307072
195.3429,0.42360958,0.027500493,0.0,0,9.1800261,0.0,0.0020143711,5.371048,10.261626,450.18359,-9.2317142
195.3453,3.794302,0.15447818,0.0,0,8.8288574,0.0,0.009985528,46.149448,9.7844667,450.1333,-9.2301216
195.3477,4.2184448,0.72184873,0.0,0,8.491025,0.0,0.048858788,51.928303,9.1814671,450.05273,-9.2278709
195.3501,4.4054246,1.1643093,0.0,0,8.1570406,0.0,0.080039851,51.728317,8.7361317,449.27664,-9.2274065
195.3525,4.7777348,1.5090504,0.0,0,7.8342953,0.0,0.10563518,55.093025,8.3864288,448.50052,-9.2274294
195.3549,4.7857833,1.7753844,0.0,0,7.5165353,0.0,0.12601814,53.53651,8.0751553,447.7244,-9.2276726
195.3573,4.8970804,2.0532045,0.0,0,7.2082515,0.0,0.14697056,53.817173,7.7982836,446.9483,-9.227931
195.3597,5.0205145,2.3210163,0.0,0,6.9060431,0.0,0.16769603,53.927105,7.5392933,446.66895,-9.2280531
195.3621,5.2798047,2.580786,0.0,0,6.6115613,0.0,0.18810809,55.739208,7.2711315,446.46054,-9.22789
195.3645,5.4431515,2.8601429,0.0,0,6.3240414,0.0,0.21078135,56.000828,6.9868107,446.25214,-9.2265015
195.3669,5.6361351,3.1495025,0.0,0,6.042748,0.0,0.2354546,56.706219,6.6968637,446.04376,-9.2257957
195.3693,5.806951,3.4483643,0.0,0,5.7692914,0.0,0.26118246,56.961197,6.3956571,445.97787,-9.2267265
195.3717,6.056704,3.7479773,0.0,0,5.5006132,0.0,0.28720659,57.76886,6.0932636,445.97067,-9.2269535
195.3741,6.2493877,4.0478559,0.0,0,5.2404532,0.0,0.31384012,58.207058,5.7876902,445.9635,-9.2259359
195.3765,6.4559536,4.336235,0.0,0,4.9838037,0.0,0.3404144,58.471741,5.4984126,445.9563,-9.2264862
195.3789,6.6001139,4.6130447,0.0,0,4.7363639,0.0,0.36690801,58.2444,5.2219992,444.77222,-9.2265358
195.3813,6.824914,4.8751335,0.0,0,4.4912457,0.0,0.39285532,58.624321,4.9536719,442.59229,-9.2264395
195.3837,7.0071316,5.1313915,0.0,0,4.2558532,0.0,0.41869819,58.670643,4.6958399,440.41238,-9.2263575
195.3861,7.2120485,5.3770499,0.0,0,4.0217257,0.0,0.44363955,58.907665,4.4485784,438.23245,-9.2252674
195.3885,7.3976026,5.6173401,0.0,0,3.7978492,0.0,0.46842298,58.901009,4.2129827,436.69461,-9.2265263
195.3909,7.5887051,5.8518229,0.0,0,3.5743496,0.0,0.49344784,59.010517,3.9782169,436.2269,-9.226717
195.3933,7.8005323,6.0781708,0.0,0,3.3612847,0.0,0.51895988,59.074757,3.7524836,435.75916,-9.2260113
195.3957,8.060276,6.2976799,0.0,0,3.1483085,0.0,0.54449403,59.467506,3.5297599,435.29141,-9.2265501
195.3981,8.2482166,6.5160723,0.0,0,2.9451063,0.0,0.57005435,59.383736,3.3087187,434.70493,-9.2253199
195.4005,8.4603148,6.7319989,0.0,0,2.7424982,0.0,0.59534746,59.405895,3.100759,433.66708,-9.2266665
195.4029,8.7091465,6.9443088,0.0,0,2.5483871,0.0,0.62078369,59.596275,2.8879411,432.62927,-9.2263479
195.4053,8.9469175,7.157084,0.0,0,2.3556671,0.0,0.64750695,59.522675,2.6800292,431.59143,-9.2250519
195.4077,9.2132902,7.3593583,0.0,0,2.170248,0.0,0.67421055,59.716816,2.475688,430.53629,-9.225441
195.4101,9.4454918,7.553349,0.0,0,1.986936,0.0,0.70030576,59.704983,2.2800972,429.08237,-9.2249727
195.4125,9.6791935,7.7457371,0.0,0,1.8098083,0.0,0.72664237,59.541256,2.0864866,427.62848,-9.2257967
195.4149,9.9613943,7.9377131,0.0,0,1.6354243,0.0,0.75266194,59.731945,1.9042624,426.17456,-9.224988
195.4173,10.265937,8.1256599,0.0,0,1.4662172,0.0,0.77901626,59.923759,1.7173884,424.72067,-9.2245846
195.4197,10.536143,8.3080072,0.0,0,1.3003292,0.0,0.80598658,59.861771,1.5402132,423.97745,-9.2242327
195.4221,10.798409,8.4776421,0.0,0,1.1387082,0.0,0.83271664,59.807709,1.3682795,423.33575,-9.2249365
195.4245,11.112556,8.6404228,0.0,0,0.98093224,0.0,0.85861462,59.955296,1.1973748,422.69409,-9.2253733
195.4269,11.427858,8.8034353,0.0,0,0.82657719,0.0,0.88420361,60.036221,1.0321447,422.0524,-9.224987
195.4293,11.767424,8.9634924,0.0,0,0.67652929,0.0,0.90949893,60.309948,0.87098819,419.85162,-9.2244043
195.4317,12.078568,9.1239691,0.0,0,0.52908581,0.0,0.93594545,60.314869,0.71669555,417.00891,-9.223485
195.4341,12.421644,9.2772713,0.0,0,0.38628578,0.0,0.96274489,60.347145,0.55904341,414.1662,-9.2242336
195.4365,10.542576,9.3111305,0.0,0,0.24542007,0.0,0.96981114,50.91087,0.46995455,411.32349,-9.2265425
195.4389,9.3890877,9.3228273,0.0,0,0.10962805,0.0,0.97255427,45.227535,0.42032403,409.90344,-9.2272148
195.4413,8.8487253,9.3286619,0.0,0,-0.025516469,0.0,0.97300625,42.628956,0.38082308,409.68713,-9.2267714
195.4437,8.5531969,9.338273,0.0,0,-0.15794852,0.0,0.97363651,41.135803,0.35397804,409.47083,-9.2279558
195.4461,8.4840059,9.3451309,0.0,0,-0.29038054,0.0,0.97452247,40.765198,0.31864697,409.25452,-9.2287264
195.4485,8.6935911,9.3487396,0.0,0,-0.42281252,0.0,0.97567922,41.690552,0.26541516,409.85278,-9.2280626
195.4509,8.9358358,9.3535299,0.0,0,-0.55524451,0.0,0.97777963,42.799919,0.19596431,411.80869,-9.227232
195.4533,9.0086155,9.3567429,0.0,0,-0.68767649,0.0,0.97854829,43.11726,0.13116285,413.76456,-9.2268238
195.4557,8.9271688,9.3633366,0.0,0,-0.82010847,0.0,0.97893506,42.738354,0.072799221,415.72046,-9.2282257
195.4581,8.7324953,9.3682709,2.6988664,0,-0.95254052,0.0,0.97886795,41.797207,0.027003603,417.45813,-9.2273741
195.4605,8.4534178,9.3690901,15.653066,0,-1.0849725,0.0,0.97904551,40.464008,0.00042256538,418.36658,-9.2273502
195.4629,8.0501318,9.3713541,28.607265,0,-0.72870666,450.0,0.98004323,38.498581,-0.013547616,419.27505,-9.2273521
195.4653,7.6436419,9.3697815,41.561462,0,-0.27022031,450.0,0.98077738,36.534828,-0.0059229974,420.1835,-9.228157
195.4677,7.3185425,9.3687744,53.97583,0,0.18826602,450.0,0.98053873,34.958611,-0.0040371921,421.05621,-9.2297735
195.4701,7.0681901,9.3710384,53.97583,0,0.64675242,450.0,0.98012662,33.78204,0.0031262033,421.10669,-9.2303782
195.4725,6.7223954,9.3737946,53.97583,0,1.105239,450.0,0.97972304,32.156044,0.0036521696,421.15717,-9.2296495
195.4749,6.6746693,9.3828325,53.97583,0,1.5637254,450.0,0.98117518,31.888687,0.012375738,421.20761,-9.2286224
195.4773,5.3210411,9.367938,53.97583,0,2.0222118,450.0,0.97985804,25.516668,0.083411135,421.25809,-9.2310562
195.4797,3.2077627,9.3521156,54.045044,0,2.4806983,450.0,0.9777962,15.637412,0.21805237,421.16977,-9.2319956
195.4821,0.8084681,9.3265676,54.124149,0,2.9391847,450.0,0.97305369,4.1233492,0.45965943,421.06161,-9.234231
195.4845,-0.50293058,9.2995415,54.203247,0,3.3976712,450.0,0.96706426,-2.2883904,0.9270398,420.95346,-9.2343779
195.4869,-0.21495323,9.3171806,54.282349,0,3.8561575,450.0,0.97000104,-1.0745087,1.6304524,420.84534,-9.2354107
195.4893,-0.061421037,9.306283,54.30542,0,4.3146439,450.0,0.96795875,-0.24219456,2.4179981,420.92615,-9.2342749
195.4917,-0.1945775,9.3142366,54.30542,0,4.7731299,450.0,0.97048432,-0.81940645,3.1110425,421.08475,-9.2338314
195.4941,-0.22496097,9.3174076,54.30542,0,5.2316165,450.0,0.97144663,-1.0991021,3.6085186,421.24338,-9.2332001
195.4965,-0.13924655,9.3183737,54.30542,0,5.6901031,450.0,0.97132033,-0.70559525,4.0305829,421.40201,-9.2334824
195.4989,-0.19118986,9.3220892,54.262573,0,6.1485891,450.0,0.97087508,-0.8508634,4.4458847,421.49033,-9.233305
195.5013,-0.20463893,9.3251133,54.183472,0,6.6070752,450.0,0.97087944,-0.97564858,4.8661265,421.51917,-9.2330685
195.5037,-0.18608131,9.3197489,54.10437,0,7.0655622,450.0,0.97032905,-0.89205021,5.3007331,421.548,-9.2328472
195.5061,-0.058512386,9.3202515,54.025269,0,7.5240488,450.0,0.9718191,-0.30832347,5.7690187,421.57681,-9.2320442
195.5085,-0.25657845,9.3144875,53.97583,0,7.9825354,450.0,0.97116429,-1.2318585,6.2478223,421.64893,-9.2319841
195.5109,-0.16263631,9.3148127,53.97583,0,8.441021,450.0,0.97050411,-0.84207779,6.7356586,421.79312,-9.2342739
195.5133,-0.22429316,9.3063965,53.97583,0,8.8995075,450.0,0.96788526,-1.0370319,7.22856,421.93732,-9.2330732
195.5157,-0.15849087,9.3199425,53.97583,0,9.3579931,450.0,0.97038144,-0.74560642,7.7079129,422.08151,-9.2328148
195.5181,-0.20236209,9.3168221,53.942871,0,9.8164806,450.0,0.97042924,-0.98973858,8.1765881,422.22272,-9.2322226
195.5205,-0.11491655,9.313035,53.784668,0,10.274966,450.0,0.97045016,-0.52564961,8.6468964,422.35251,-9.23207
195.5229,-0.20891473,9.3099318,53.626465,0,10.733453,450.0,0.97014683,-0.97197014,9.1104603,422.4823,-9.2323217
195.5253,-0.14571688,9.3192577,53.468262,0,11.191939,450.0,0.97104174,-0.78606486,9.5791798,422.61206,-9.2333603
195.5277,-0.1760515,9.3199177,53.31665,0,11.650426,450.0,0.97010088,-0.75650418,10.054357,422.74097,-9.2320309
195.5301,-0.31989431,9.3227186,53.31665,0,12.108912,450.0,0.97047371,-1.5424533,10.524163,422.84912,-9.2311707
195.5325,-0.23374736,9.3145971,53.31665,0,12.567399,450.0,0.97024596,-1.166042,11.008564,422.95724,-9.232007
195.5349,-0.11408439,9.3172226,53.31665,0,13.025885,450.0,0.97146106,-0.54138488,11.483595,423.0654,-9.2323475
195.5373,-0.27303782,9.3125544,53.31665,0,13.484371,450.0,0.9707799,-1.3215485,11.931459,423.17355,-9.2314386
195.5397,-0.16443987,9.3141146,53.245129,0,13.942858,450.0,0.96995735,-0.84947777,12.395171,423.23123,-9.2312336
195.5421,-0.06778302,9.3189974,53.163391,0,14.401344,450.0,0.96980053,-0.23001966,12.855079,423.28171,-9.2297049
195.5445,-0.31335875,9.3217745,53.081654,0,14.859831,450.0,0.97088981,-1.5136559,13.317039,423.33218,-9.2304478
195.5469,-0.15887433,9.3169708,52.999916,0,15.318317,450.0,0.97091657,-0.79232979,13.796839,423.38266,-9.2302217
195.5493,-0.20731518,9.310976,52.976074,0,15.776803,450.0,0.97065246,-0.99242479,14.271785,423.41779,-9.2304258
195.5517,-0.33614209,9.3102312,52.976074,0,16.235291,450.0,0.97003847,-1.5283703,14.741032,423.44662,-9.2298698
195.5541,-0.12355067,9.3118286,52.976074,0,16.693775,450.0,0.96914923,-0.57097661,15.207803,423.47546,-9.2303247
195.5565,-0.23944698,9.3215036,52.976074,0,17.152262,450.0,0.97015053,-1.1619484,15.666462,423.5043,-9.2308435
195.5589,-0.2082793,9.3194761,52.976074,0,17.61075,450.0,0.97033495,-0.98360038,16.126213,423.51361,-9.2306852
195.5613,-0.1953662,9.3123398,52.976074,0,17.999975,450.0,0.97051942,-0.86158645,16.584826,423.50641,-9.2305593
195.5637,-0.22456804,9.3091717,52.976074,0,18.0,450.0,0.97034204,-1.0242001,17.030926,423.49921,-9.2294617
195.5661,-0.21998407,9.3183174,52.976074,0,18.0,450.0,0.97121418,-1.0791738,17.455832,423.492,-9.2296267
195.5685,-0.1983012,9.315135,52.976074,0,18.0,450.0,0.96968931,-0.88858533,17.841391,423.49561,-9.2299213
195.5709,-0.12537161,9.3163939,52.976074,0,18.0,450.0,0.96970135,-0.64633816,18.165787,423.51724,-9.2325163
195.5733,-0.051433176,9.3096781,52.976074,0,18.0,450.0,0.96900809,-0.27139774,18.405125,423.53888,-9.2349606
195.5757,0.18174212,9.3252735,52.976074,0,18.0,450.0,0.97270083,0.84548479,18.529264,423.56052,-9.2399082
195.5781,0.42964622,9.3278923,52.976074,0,18.0,450.0,0.97347569,2.1149385,18.51944,423.59717,-9.2459316
195.5805,0.63810664,9.3380566,52.976074,0,18.0,450.0,0.97448266,3.0633318,18.407482,423.69089,-9.2568569
195.5829,0.66423315,9.3384295,52.976074,0,18.0,450.0,0.97364008,3.279412,18.273973,423.78461,-9.2710876
195.5853,0.48061264,9.3565283,52.976074,0,18.0,450.0,0.97638118,2.271822,18.145021,423.87833,-9.2873287
195.5877,0.51569843,9.3473015,52.976074,0,18.0,450.0,0.97583377,2.540818,18.062101,423.96875,-9.3085232
195.5901,0.50674963,9.3399181,52.976074,0,18.0,450.0,0.97547877,2.3745997,18.048315,423.98318,-9.3301992
195.5925,0.4282952,9.3293848,52.976074,0,18.0,450.0,0.97384566,2.0306356,18.055542,423.99759,-9.3513412
195.5949,0.56004792,9.3396549,52.976074,0,18.0,450.0,0.97436041,2.6556802,18.07535,424.01202,-9.3739319
195.5973,0.52672607,9.3396292,52.976074,0,18.0,450.0,0.9736715,2.5620098,18.102636,424.02646,-9.3939466
195.5997,0.4877528,9.3399267,52.976074,0,18.0,450.0,0.97410601,2.3205667,18.127066,424.03458,-9.4129944
195.6021,0.70742452,9.3413792,52.976074,0,18.0,450.0,0.97501904,3.3874795,18.146141,424.04178,-9.4308605
195.6045,0.48189732,9.3387442,52.976074,0,18.0,450.0,0.97534019,2.3017802,18.147764,424.04898,-9.4478149
195.6069,0.54490393,9.3384371,52.976074,0,18.0,450.0,0.9750669,2.6129241,18.147013,424.05618,-9.4654255
195.6093,0.52168465,9.3391638,52.976074,0,18.0,450.0,0.97409874,2.5056288,18.146881,424.03787,-9.4828463
195.6117,0.48800281,9.3424406,52.976074,0,18.0,450.0,0.97385103,2.5006995,18.145954,424.009,-9.5001974
195.6141,0.56420302,9.3368082,52.976074,0,18.0,450.0,0.97327453,2.704869,18.139673,423.98016,-9.5158787
195.6165,0.58818138,9.340786,52.976074,0,18.0,450.0,0.97520143,2.8017447,18.143356,423.95132,-9.5330267
195.6189,0.52907771,9.3368893,53.020351,0,18.0,450.0,0.975128,2.5619051,18.139441,423.91077,-9.5523281
195.6213,0.51255292,9.3344526,53.102089,0,18.0,450.0,0.97430873,2.4898934,18.130457,423.86032,-9.5708151
195.6237,0.53954375,9.3317986,53.18383,0,18.0,450.0,0.97290635,2.6493528,18.128531,423.80984,-9.588789
195.6261,0.54998744,9.344348,53.265564,0,18.0,450.0,0.97464418,2.6139293,18.128479,423.75937,-9.6080723
195.6285,0.55114496,9.3411112,53.31665,0,18.0,450.0,0.97431493,2.6529093,18.12439,423.71704,-9.624649
195.6309,0.54974788,9.3374338,53.31665,0,18.0,450.0,0.9746539,2.653831,18.124889,423.68817,-9.6435966
195.6333,0.48600143,9.3238707,53.31665,0,18.0,450.0,0.97282749,2.3146765,18.122793,423.65933,-9.6611671
195.6357,0.60940492,9.3397102,53.31665,0,18.0,450.0,0.97489113,2.9052055,18.123098,423.63049,-9.6791182
195.6381,0.57003284,9.3403254,53.333679,0,18.0,450.0,0.97398555,2.7343106,18.119329,423.60617,-9.6977835
195.6405,0.55085397,9.346529,53.415421,0,18.0,450.0,0.97461218,2.6742632,18.113489,423.59897,-9.7152538
195.6429,0.65484703,9.3416243,53.497158,0,18.0,450.0,0.97451019,3.1626136,18.116947,423.59174,-9.7340727
195.6453,0.49798453,9.3484097,53.578892,0,18.0,450.0,0.97661901,2.3548615,18.113512,423.58453,-9.7504568
195.6477,0.56330985,9.3349409,53.657227,0,18.0,450.0,0.97478127,2.7131681,18.111855,423.57584,-9.7686329
195.6501,0.56971657,9.3353214,53.657227,0,18.0,450.0,0.97379231,2.7290931,18.111692,423.53256,-9.7874184
195.6525,0.43984428,9.3324566,53.657227,0,18.0,450.0,0.97265816,2.1369631,18.114033,423.48932,-9.8057604
195.6549,0.60199106,9.3436108,53.657227,0,18.0,450.0,0.97467673,2.8241105,18.110485,423.44604,-9.8228064
195.6573,0.60121173,9.3388577,53.657227,0,18.0,450.0,0.97471529,2.8911304,18.109758,423.40277,-9.8398466
195.6597,0.57512861,9.3382807,53.724133,0,18.0,450.0,0.97517437,2.780267,18.110409,423.37845,-9.8577976
195.6621,0.74014014,9.34132,53.800598,0,18.0,450.0,0.97553223,3.5535653,18.110861,423.35681,-9.8764219
195.6645,0.47093362,9.3445673,53.877064,0,18.0,450.0,0.97510475,2.2763665,18.104366,423.33517,-9.8954906
195.6669,0.57040513,9.3450518,53.953529,0,18.0,450.0,0.97452265,2.7573957,18.106773,423.31357,-9.9118204
195.6693,0.57577562,9.3425426,53.97583,0,18.0,450.0,0.97421819,2.769228,18.102976,423.27661,-9.9310131
195.6717,0.5074802,9.3376675,53.97583,0,18.0,450.0,0.97444284,2.5518022,18.104818,423.23334,-9.9492731
195.6741,0.55609673,9.3337097,53.97583,0,18.0,450.0,0.97447258,2.6788526,18.106056,423.19006,-9.967761
195.6765,0.59562159,9.3369646,53.97583,0,18.0,450.0,0.974765,2.8327026,18.103395,423.14682,-9.9853716
195.6789,0.58046484,9.3364496,54.018677,0,18.0,450.0,0.97369885,2.7952988,18.099722,423.10745,-10.001906
195.6813,0.56812966,9.3454494,54.097778,0,18.0,450.0,0.97458297,2.7660606,18.097607,423.07141,-10.019969
195.6837,0.55465817,9.3387098,54.17688,0,18.0,450.0,0.97375005,2.6863813,18.097294,423.03537,-10.038559
195.6861,0.57110882,9.3421288,54.255985,0,18.0,450.0,0.97564244,2.7171166,18.098722,422.9993,-10.055659
195.6885,0.58401394,9.334486,54.30542,0,18.0,450.0,0.97474599,2.7335906,18.095823,422.95786,-10.073988
195.6909,0.61051124,9.3320684,54.30542,0,18.0,450.0,0.97374117,2.9410043,18.093376,422.90738,-10.090451
195.6933,0.55376917,9.3286047,54.30542,0,18.0,450.0,0.97200143,2.7217162,18.096628,422.8569,-10.108306
195.6957,0.63308811,9.3495646,54.30542,0,18.0,450.0,0.97512788,3.0823739,18.096228,422.80643,-10.127379
195.6981,0.5838564,9.3448277,54.321354,0,18.0,450.0,0.9750092,2.8501754,18.095791,422.75146,-10.145317
195.7005,0.61579496,9.3385363,54.397816,0,18.0,450.0,0.97509331,2.9605916,18.092756,422.67935,-10.162539
195.7029,0.72616714,9.3290195,54.474281,0,18.0,450.0,0.97389096,3.4956191,18.093952,422.60727,-10.181159
195.7053,0.53566992,9.344903,54.550747,0,18.0,450.0,0.97565091,2.5722518,18.091503,422.53516,-10.199468
195.7077,0.59052879,9.3381901,54.624023,0,18.0,450.0,0.97365165,2.8338013,18.092575,422.46457,-10.218374
195.7101,0.59506702,9.3383999,54.624023,0,18.0,450.0,0.97356355,2.8217471,18.092649,422.4285,-10.237039
195.7125,0.52110881,9.3318138,54.624023,0,18.0,450.0,0.97320843,2.5018306,18.091524,422.39246,-10.254529
195.7149,0.66674751,9.3402719,54.624023,0,18.0,450.0,0.97534269,3.2085671,18.090721,422.35641,-10.272535
195.7173,0.62546688,9.3359289,54.624023,0,18.0,450.0,0.97463447,3.0093815,18.090687,422.32037,-10.292225
195.7197,0.58940756,9.3392296,54.688625,0,18.0,450.0,0.97451842,2.8221231,18.084368,422.2717,-10.309676
195.7221,0.78780413,9.3450279,54.762451,0,18.0,450.0,0.97471279,3.7748389,18.088644,422.22122,-10.327172
195.7245,0.54605651,9.350174,54.836281,0,18.0,450.0,0.975362,2.6287355,18.081612,422.17075,-10.344149
195.7269,0.61684668,9.3455153,54.910107,0,18.0,450.0,0.97575057,2.939934,18.082842,422.12027,-10.36168
195.7293,0.57996726,9.3377409,54.931641,0,18.0,450.0,0.97533208,2.8268516,18.080921,422.06982,-10.380292
195.7317,0.49358574,9.333169,54.931641,0,18.0,450.0,0.97433484,2.4105146,18.086094,422.01935,-10.397329
195.7341,0.64236671,9.3330202,54.931641,0,18.0,450.0,0.97298634,3.0789902,18.076878,421.96887,-10.413836
195.7365,0.66926944,9.3430395,54.931641,0,18.0,450.0,0.97421694,3.1967068,18.080576,421.9184,-10.431288
195.7389,0.61385459,9.3451071,55.010193,0,18.0,450.0,0.97493017,2.9851749,18.082844,421.8562,-10.452312
195.7413,0.54199558,9.3440275,55.155212,0,18.0,450.0,0.97571206,2.6106045,18.075014,421.78412,-10.471842
195.7437,0.59445262,9.3323059,55.300236,0,18.0,450.0,0.97417819,2.9031191,18.076456,421.71201,-10.489292
195.7461,0.6229676,9.3406725,55.445251,0,18.0,450.0,0.97517699,2.9727356,18.075121,421.63992,-10.504439
195.7485,0.62198049,9.3398027,55.535889,0,18.0,450.0,0.97400063,2.9546616,18.080042,421.56781,-10.523669
195.7509,0.62105185,9.3454123,55.535889,0,18.0,450.0,0.97438771,2.9808207,18.075922,421.4957,-10.5411
195.7533,0.5631308,9.3333883,55.535889,0,18.0,450.0,0.97283411,2.7116625,18.075855,421.42361,-10.560347
195.7557,0.69331676,9.3440361,55.535889,0,18.0,450.0,0.97593296,3.3579166,18.075089,421.3515,-10.577046
195.7581,0.64557856,9.336462,55.55127,0,18.0,450.0,0.97486615,3.0978398,18.074535,421.28543,-10.593998
195.7605,0.64004987,9.3370838,55.625099,0,18.0,450.0,0.97436142,3.078048,18.071726,421.24216,-10.612138
195.7629,0.7259981,9.3318138,55.698925,0,18.0,450.0,0.97267199,3.4735563,18.073709,421.19891,-10.632819
195.7653,0.5876413,9.3482523,55.772758,0,18.0,450.0,0.97549093,2.7717543,18.074423,421.15564,-10.649117
195.7677,0.64949822,9.3406324,55.84351,0,18.0,450.0,0.97454584,3.1553032,18.070681,421.1127,-10.666248
195.7701,0.66394579,9.3375511,55.84351,0,18.0,450.0,0.97474551,3.1672363,18.073757,421.07663,-10.684363
195.7725,0.52345872,9.3280754,55.84351,0,18.0,450.0,0.97366601,2.4998925,18.071411,421.04059,-10.702044
195.7749,0.70268691,9.3432093,55.84351,0,18.0,450.0,0.97549659,3.3418758,18.073118,421.00455,-10.720926
195.7773,0.67174351,9.3414907,55.84351,0,18.0,450.0,0.97420543,3.2105479,18.069649,420.96851,-10.738576
195.7797,0.6630733,9.3461084,55.903496,0,18.0,450.0,0.97454143,3.1829851,18.071112,420.93243,-10.756362
195.7821,0.82490706,9.3475904,55.97205,0,18.0,450.0,0.97590417,3.9436986,18.069321,420.89639,-10.775088
195.7845,0.55418122,9.3473549,56.0406,0,18.0,450.0,0.97679979,2.652586,18.066309,420.86035,-10.79403
195.7869,0.65178442,9.3386765,56.109154,0,18.0,450.0,0.97552383,3.1198239,18.062656,420.82431,-10.811726
195.7893,0.6539458,9.3363237,56.12915,0,18.0,450.0,0.97390276,3.1650722,18.066092,420.76782,-10.82965
195.7917,0.52536941,9.3405333,56.12915,0,18.0,450.0,0.9738512,2.5843143,18.067955,420.70291,-10.84826
195.7941,0.65137684,9.3416491,56.12915,0,18.0,450.0,0.9740141,3.1154892,18.062216,420.63803,-10.866124
195.7965,0.67991394,9.3410053,56.12915,0,18.0,450.0,0.97511369,3.2978022,18.066055,420.57315,-10.88433
195.7989,0.65830839,9.3353901,56.204845,0,18.0,450.0,0.97479606,3.1849148,18.064493,420.4809,-10.901731
195.8013,0.61656302,9.3334122,56.344593,0,18.0,450.0,0.97394592,2.9345605,18.058527,420.36554,-10.918324
195.8037,0.62225217,9.3363104,56.484341,0,18.0,450.0,0.97348666,3.0423827,18.058321,420.25018,-10.936152
195.8061,0.63623989,9.35145,56.624084,0,18.0,450.0,0.97551835,3.062993,18.059628,420.13483,-10.954776
195.8085,0.65197235,9.3449764,56.711426,0,18.0,450.0,0.97464997,3.123883,18.059425,420.0303,-10.97236
195.8109,0.67668849,9.3388538,56.711426,0,18.0,450.0,0.97498643,3.2420497,18.057863,419.94376,-10.990095
195.8133,0.60836309,9.3246422,56.711426,0,18.0,450.0,0.97279537,2.9265647,18.058609,419.85724,-11.008545
195.8157,0.73221171,9.3405724,56.711426,0,18.0,450.0,0.97515619,3.5041969,18.056784,419.77072,-11.025862
195.8181,0.65458351,9.3372374,56.725159,0,18.0,450.0,0.97367346,3.1290922,18.059486,419.70221,-11.044066
195.8205,0.6852383,9.3410587,56.791077,0,18.0,450.0,0.97381848,3.2795839,18.056992,419.70221,-11.062839
195.8229,0.7697106,9.3364744,56.856995,0,18.0,450.0,0.97376204,3.764138,18.058794,419.70221,-11.079966
195.8253,0.61677289,9.3500757,56.922913,0,18.0,450.0,0.97689849,2.9293983,18.058689,419.70221,-11.097173
195.8277,0.64523506,9.3376741,56.986084,0,18.0,450.0,0.97522765,3.1242602,18.057842,419.70071,-11.116971
195.8301,0.67687249,9.3360138,56.986084,0,18.0,450.0,0.97425574,3.2424695,18.060301,419.66464,-11.135224
195.8325,0.58698809,9.3321695,56.986084,0,18.0,450.0,0.97249287,2.8181679,18.05986,419.6286,-11.152728
195.8349,0.75372976,9.3498583,56.986084,0,18.0,450.0,0.97528338,3.6508827,18.057388,419.59256,-11.171265
195.8373,0.68981713,9.3469944,56.986084,0,18.0,450.0,0.97560292,3.3701212,18.055597,419.55652,-11.189575
195.8397,0.67349118,9.3401842,57.101444,0,18.0,450.0,0.97552598,3.2307563,18.058105,419.49524,-11.207667
195.8421,0.87064773,9.3392982,57.23328,0,18.0,450.0,0.97562504,4.2100735,18.056648,419.43033,-11.224203
195.8445,0.61797744,9.3457384,57.365112,0,18.0,450.0,0.97550887,2.9452224,18.05257,419.36545,-11.241176
195.8469,0.70912528,9.3440323,57.496948,0,18.0,450.0,0.97452736,3.3716984,18.053738,419.30057,-11.259082
195.8493,0.6615361,9.3407745,57.535404,0,18.0,450.0,0.97406757,3.1962743,18.052492,419.25101,-11.278418
195.8517,0.53905219,9.3380775,57.535404,0,18.0,450.0,0.97453368,2.5861862,18.055847,419.20773,-11.295415
195.8541,0.70771718,9.334672,57.535404,0,18.0,450.0,0.97452599,3.3415103,18.053366,419.16446,-11.313022
195.8565,0.74361777,9.3377781,57.535404,0,18.0,450.0,0.97495306,3.619241,18.051655,419.12122,-11.332379
195.8589,0.68084133,9.3418932,49.903099,0,18.0,450.0,0.97477382,3.2606058,18.049156,419.0416,-11.350297
196.0608,0.66480005,9.343976,0.0,0,18.0,0.85476655,0.97529179,3.1902411,18.027231,414.21878,-11.474862
197.2608,0.60713726,9.354003,0.0,0,18.0,3.6951402e-17,0.97722495,2.907515,18.000223,358.25095,-11.476499
198.4608,0.54021299,9.3574324,0.0,0,18.0,1.5974026e-33,0.97770739,2.588403,18.00054,328.60721,-11.476819
199.6608,0.49079996,9.3593636,0.0,0,18.0,1.4012985e-45,0.97799259,2.3515615,18.000196,307.85287,-11.477066
200.8608,0.50069219,9.3651409,0.0,0,18.0,1.4012985e-45,0.9790442,2.3998318,17.99955,292.68988,-11.47709
202.0608,0.5121116,9.3703384,0.0,0,18.0,1.4012985e-45,0.98009038,2.4464598,17.999676,280.05078,-11.476837
203.2608,0.51757294,9.3754177,0.0,0,18.0,1.4012985e-45,0.98095846,2.4749932,18.000015,268.76221,-11.477009
204.4608,0.52325523,9.3807669,0.0,0,18.0,1.4012985e-45,0.9817608,2.4958515,18.00045,258.87433,-11.477137
205.6608,0.5281539,9.3848658,0.0,0,18.0,1.4012985e-45,0.98260415,2.5198591,17.999453,249.88562,-11.477592
206.8608,0.53008443,9.3895473,0.0,0,18.0,1.4012985e-45,0.98345107,2.5227149,17.999479,241.47444,-11.477166
208.0608,0.53775936,9.39394,0.0,0,18.0,1.4012985e-45,0.98426795,2.5575571,18.000088,233.46973,-11.477105
209.2608,0.54125482,9.3976307,0.0,0,18.0,1.4012985e-45,0.98474193,2.578233,18.000259,226.21802,-11.477324
210.4608,0.54687667,9.401391,0.0,0,18.0,1.4012985e-45,0.9855665,2.5961504,18.000448,219.07689,-11.477443
211.6608,0.54810923,9.4054852,0.0,0,18.0,1.4012985e-45,0.98626119,2.605526,18.000601,212.48126,-11.4778
212.8608,0.55600536,9.4086866,0.0,0,18.0,1.4012985e-45,0.98690414,2.6373837,17.999863,206.17921,-11.477747
214.0608,0.55605978,9.4126616,0.0,0,18.0,1.4012985e-45,0.98741138,2.6351821,17.999807,200.36993,-11.477291
215.2608,0.56052977,9.4160547,0.0,0,18.0,1.4012985e-45,0.9882499,2.6571131,17.999794,194.31009,-11.477165
216.4608,0.56162763,9.4195032,0.0,0,18.0,1.4012985e-45,0.98870111,2.6609914,17.999437,188.72745,-11.477515
217.6608,0.56834823,9.4227848,0.0,0,18.0,1.4012985e-45,0.98942703,2.6936698,17.999594,183.45576,-11.477577
218.8608,0.57119477,9.426075,0.0,0,18.0,1.4012985e-45,0.98984075,2.7024326,18.000101,178.34996,-11.477397
220.0608,0.57880801,9.4289732,0.0,0,18.0,1.4012985e-45,0.99062067,2.7357476,17.999733,173.53101,-11.477888
221.2608,0.5800783,9.4323273,0.0,0,18.0,1.4012985e-45,0.99100363,2.743499,18.000036,168.68474,-11.477947
222.4608,0.58693242,9.4354525,0.0,0,18.0,1.4012985e-45,0.99161148,2.772644,17.999865,164.18748,-11.477766
223.6608,0.58534342,9.4382534,0.0,0,18.0,1.4012985e-45,0.99209559,2.7630632,18.000299,159.74532,-11.47777
224.8608,0.59630018,9.4407358,0.0,0,18.0,1.4012985e-45,0.99266565,2.8105509,18.000206,155.55743,-11.478335
226.0608,0.60148144,9.4439831,0.0,0,18.0,1.4012985e-45,0.99321592,2.8359489,18.000168,151.4474,-11.478243
227.2608,0.59635139,9.4466476,0.0,0,18.0,1.4012985e-45,0.99352396,2.810811,17.999887,147.56955,-11.478398
228.4608,0.60251564,9.4487524,0.0,0,18.0,1.4012985e-45,0.9940843,2.8351364,18.0,143.79097,-11.478394
229.6608,0.60201603,9.4517403,0.0,0,18.0,1.4012985e-45,0.99456215,2.834676,18.000519,140.20679,-11.478487
230.8608,0.61407834,9.4542027,0.0,0,18.0,1.4012985e-45,0.99510354,2.8901291,17.999468,136.60429,-11.478231
232.0608,0.61142701,9.4569635,0.0,0,18.0,1.4012985e-45,0.99538463,2.8821733,18.000547,133.20439,-11.47824
233.2608,0.62023878,9.4592571,0.0,0,18.0,1.4012985e-45,0.99605083,2.9129553,18.000017,129.76927,-11.478331
234.4608,0.62298173,9.461813,0.0,0,18.0,1.4012985e-45,0.99628752,2.9282846,18.000048,126.58384,-11.478653
235.6608,0.62077361,9.4640932,0.0,0,18.0,1.4012985e-45,0.9968105,2.9225192,17.999346,123.43121,-11.478524
236.8608,0.6292876,9.4665022,0.0,0,18.0,1.4012985e-45,0.99715459,2.9528849,18.000521,120.31017,-11.478711
238.0608,0.62312877,9.467824,0.0,0,18.0,1.4012985e-45,0.99760193,2.9268949,18.00054,117.32655,-11.478657
239.2608,0.63095951,9.4702654,0.0,0,18.0,1.4012985e-45,0.99791282,2.9610493,18.000006,114.51351,-11.47898
240.4608,0.63000214,9.4720993,0.0,0,18.0,1.4012985e-45,0.99816328,2.9600818,17.999899,111.59578,-11.478632
241.6608,0.62982142,9.4741554,0.0,0,18.0,1.4012985e-45,0.99861735,2.9522216,18.000101,108.84757,-11.47876
242.8608,0.6356045,9.4762373,0.0,0,18.0,1.4012985e-45,0.99901342,2.9807308,18.000059,106.18359,-11.478647
244.0608,0.63413739,9.478056,0.0,0,18.0,1.4012985e-45,0.99938214,2.9704103,18.000181,103.44007,-11.479007
245.2608,0.64079905,9.4799614,0.0,0,18.0,1.4012985e-45,0.99955493,3.0001044,17.999571,100.89848,-11.478726
246.4608,0.64120221,9.4816198,0.0,0,18.0,1.4012985e-45,1.0000932,3.0032642,17.999662,98.502144,-11.47872
247.6608,0.63541806,9.4832487,0.0,0,18.0,1.4012985e-45,1.0001734,2.9699035,17.999857,95.966301,-11.479092
248.8608,0.64395767,9.4855604,0.0,0,18.0,1.4012985e-45,1.0007011,3.0195851,17.999962,93.661522,-11.478971
250.0608,0.63609928,9.486763,0.0,0,18.0,1.4012985e-45,1.0008029,2.9709971,18.000137,91.374054,-11.478901
251.2608,0.64669901,9.4880781,0.0,0,18.0,1.4012985e-45,1.0012645,3.0237448,18.000065,89.175201,-11.479295
252.4608,0.6380924,9.4898529,0.0,0,18.0,1.4012985e-45,1.0014335,2.9869487,18.000216,87.031731,-11.479284
253.6608,0.64412618,9.4913368,0.0,0,18.0,1.4012985e-45,1.0016611,3.0098286,18.000303,84.981796,-11.479095
254.8608,0.64294195,9.4928589,0.0,0,18.0,1.4012985e-45,1.0020032,3.0082181,18.000153,83.145241,-11.479217
255.8608,0.64926374,9.4942608,0.0,0,18.0,1.4012985e-45,1.002197,3.0336792,18.000158,81.374603,-11.479674