File: raw data/testID_0192.csv
Time(sec),Force(kN),Jaw(mm),PowAngle(deg),Power(W),Pram,PTemp,Strain,Stress(MPa),Stroke(mm),TC1(C),wedge(mm)
0.0,7.2952642,0.80228317,0.0,0,11.076097,0.001662507,0.054996409,87.91217,11.076509,23.574142,-9.1204863
1.1,6.8910899,-0.0035301268,0.0,0,11.076097,3.2158816,-0.00023830088,87.759155,11.075901,23.652231,-9.4902782
2.2,6.6780925,-0.0035944013,0.0,0,11.076097,6.515883,-0.00025175861,85.06073,11.075849,23.537102,-9.4913454
3.3,6.5406919,-0.0040002489,0.0,0,11.076097,9.8158817,-0.0002698176,83.313072,11.076615,23.462337,-9.4895201
4.4,6.473824,-0.0044305888,0.0,0,11.076097,13.115881,-0.00026274013,82.441887,11.075951,23.498009,-9.4878225
5.5,6.4370022,-0.0041415077,0.0,0,11.076097,16.41588,-0.0002946585,82.007446,11.076723,23.498604,-9.4863348
6.6,6.4342265,-0.0041157235,0.0,0,11.076097,19.715883,-0.00026279644,81.94043,11.076194,23.529501,-9.4848986
7.7,6.4215059,-0.0041027451,0.0,0,11.076097,23.015888,-0.00027108306,81.780289,11.076918,23.529217,-9.4823093
8.8,6.4286222,-0.0033466916,15.999557,0,11.076097,26.315884,-0.00021286987,81.875282,11.075801,23.493727,-9.4804564
9.9,6.4484963,-0.0035285177,31.257524,0,11.076097,29.615883,-0.00026661376,82.116173,11.076077,23.633528,-9.4782457
11.0,6.463232,-0.0065881829,39.865341,0,11.076097,32.915894,-0.00043777662,82.30909,11.076599,24.749281,-9.4765415
12.1,6.486516,-0.012132114,44.613407,0,11.076097,36.215885,-0.00078074617,82.675194,11.076118,27.561417,-9.4749498
13.2,6.5270939,-0.014763374,46.582027,0,11.076097,39.515884,-0.0010019033,83.18856,11.076047,32.284607,-9.4733086
14.3,6.5499225,-0.020255463,47.05444,0,11.076097,42.815884,-0.0013524994,83.491989,11.075961,37.99522,-9.4710541
15.4,6.5625954,-0.024979975,45.168297,0,11.076097,46.115883,-0.0016711255,83.69973,11.075721,44.406342,-9.4688997
16.5,6.5564575,-0.028904656,42.057281,0,11.076097,49.415882,-0.0019023945,83.629967,11.076209,50.662735,-9.4670191
17.6,6.5321302,-0.031429797,37.920403,0,11.076097,52.715878,-0.0021181616,83.335335,11.076667,56.032921,-9.4649706
18.7,6.5282893,-0.032094713,33.783226,0,11.076097,56.015877,-0.0021271231,83.312714,11.076048,60.247395,-9.4628048
19.8,6.5103545,-0.033833362,30.874046,0,11.076097,59.31588,-0.0022417663,83.080368,11.076228,63.149799,-9.4606829
20.9,6.4888315,-0.035163365,30.871584,0,11.076097,62.615879,-0.0023398155,82.802139,11.076923,65.041962,-9.4584827
22.0,6.4862733,-0.035844248,33.76778,0,11.076097,65.915886,-0.0024073727,82.795135,11.076438,66.388702,-9.4571047
23.1,6.4917216,-0.037091441,37.760059,0,11.076097,69.215881,-0.0024729131,82.850433,11.076222,67.599823,-9.4549685
24.2,6.4960027,-0.039597921,41.155857,0,11.076097,72.515884,-0.0026080071,82.908051,11.07569,69.376312,-9.45327
25.3,6.5013976,-0.042340588,43.552876,0,11.076097,75.81588,-0.0028468831,83.021599,11.077279,71.957329,-9.4514017
26.4,6.5294485,-0.046218917,45.12085,0,11.076097,79.115875,-0.0030551194,83.392029,11.076815,75.487389,-9.4493523
27.5,6.5478649,-0.050176475,45.615231,0,11.076097,82.415878,-0.0033363923,83.642242,11.076643,79.951126,-9.4473295
28.6,6.5613117,-0.054218423,45.120853,0,11.076097,85.715889,-0.003615133,83.85508,11.076277,84.510017,-9.445528
29.7,6.5642734,-0.056770559,43.693569,0,11.076097,89.015884,-0.0037977942,83.892525,11.075965,89.194687,-9.4433327
30.8,6.5405173,-0.059648614,42.396481,0,11.076097,92.315887,-0.0039717145,83.604057,11.075982,93.530174,-9.4412146
31.9,6.53332,-0.062252697,41.198734,0,11.076097,95.615898,-0.0041188598,83.533401,11.076361,97.183929,-9.4393673
33.0,6.5154848,-0.06453944,40.572514,0,11.076097,98.915894,-0.0043212171,83.315697,11.075901,100.30605,-9.4375324
34.1,6.4977822,-0.065608636,40.572487,0,11.076097,102.2159,-0.0043522501,83.092346,11.076562,103.09542,-9.4359865
35.2,6.4953322,-0.067359641,41.198727,0,11.076097,105.51589,-0.0044614403,83.086243,11.075737,105.4079,-9.4333115
36.3,6.5078993,-0.07015577,42.978157,0,11.076097,108.8159,-0.0046716258,83.240982,11.075359,107.67001,-9.4315329
37.4,6.4972696,-0.072865166,44.380821,0,11.076097,112.11589,-0.0048657181,83.141548,11.076566,110.31905,-9.4296675
38.5,6.5292234,-0.076113321,45.315807,0,11.076097,115.4159,-0.0050710747,83.557175,11.076358,113.51246,-9.4278984
39.6,6.5360551,-0.079397663,45.925419,0,11.076097,118.7159,-0.0052539231,83.654724,11.076046,117.04791,-9.4257097
40.7,6.5459204,-0.081774719,46.582027,0,11.076097,122.01589,-0.0054665352,83.789787,11.07725,120.17078,-9.4239817
41.8,6.5622787,-0.085628219,46.627327,0,11.076097,125.31589,-0.0056744227,84.045265,11.077527,124.15781,-9.4223347
42.9,6.5766511,-0.089057021,46.582035,0,11.076097,128.61601,-0.0058984905,84.235161,11.076457,127.98405,-9.4203758
44.0,6.5848389,-0.093217455,46.133366,0,11.076097,131.91589,-0.0062102205,84.351738,11.075663,131.7457,-9.4184647
45.1,6.5996699,-0.094195485,45.615238,0,11.076097,135.21588,-0.0062592616,84.577133,11.076201,135.68797,-9.4170389
46.2,6.5990534,-0.097570367,45.120853,0,11.076097,138.51588,-0.006490666,84.567871,11.077716,139.33572,-9.415143
47.3,6.5813193,-0.10014642,44.604496,0,11.076097,141.81587,-0.0066431062,84.349037,11.075843,142.70036,-9.4130392
48.4,6.5915475,-0.10306449,44.596783,0,11.076097,145.11589,-0.0068667717,84.498962,11.077312,145.68037,-9.4111385
49.5,6.5845056,-0.10456578,44.604488,0,11.076097,148.41589,-0.0069346926,84.422668,11.076097,148.65237,-9.4092999
50.6,6.5716195,-0.10721459,45.12085,0,11.076097,151.71588,-0.0070818155,84.267128,11.077321,151.39819,-9.407198
51.7,6.5907397,-0.10967846,45.952648,0,11.076097,155.0159,-0.0073136259,84.539955,11.076325,154.28595,-9.4054966
52.8,6.5974679,-0.11276502,46.581959,0,11.076097,158.31589,-0.0074677649,84.62159,11.076339,157.25241,-9.403739
53.9,6.6083117,-0.11677289,47.477989,0,11.076097,161.61591,-0.0077279303,84.795265,11.07711,160.26176,-9.4022217
55.0,6.6210175,-0.11843321,47.63229,0,11.076097,164.91589,-0.0078708613,84.973297,11.076219,163.70496,-9.400157
56.1,6.6228156,-0.12114868,47.600117,0,11.076097,168.2159,-0.0080460543,84.997932,11.076143,167.47618,-9.3982553
57.2,6.6284204,-0.12438741,47.504887,0,11.076097,171.5159,-0.0082596764,85.102203,11.077223,171.05664,-9.3968248
58.3,6.6285462,-0.12735416,47.504887,0,11.076097,174.8159,-0.0084456196,85.133949,11.076715,174.68069,-9.3951445
59.4,6.6253204,-0.12970369,47.504887,0,11.076097,178.11591,-0.0086318506,85.06665,11.075601,177.88091,-9.3928909
60.5,6.6308479,-0.13381051,47.662308,0,11.076097,181.41591,-0.0088859303,85.18058,11.076012,181.15997,-9.3911467
61.6,6.6297326,-0.13458626,47.940834,0,11.076097,184.7159,-0.0088957231,85.176132,11.076612,184.51436,-9.3894129
62.7,6.627049,-0.13716474,47.551441,0,11.076097,188.0159,-0.0091310656,85.144737,11.076695,188.03294,-9.3877897
63.8,6.610085,-0.13941334,47.944828,0,11.076097,191.3159,-0.0092391558,84.953987,11.076353,191.15453,-9.3855104
64.9,6.6100678,-0.14160393,47.955318,0,11.076097,194.61589,-0.0093694758,84.96714,11.076602,194.22491,-9.3837309
66.0,6.5854969,-0.14375421,48.383785,0,11.076097,197.91589,-0.0095567554,84.641701,11.076535,197.37181,-9.3816662
67.1,6.5685692,-0.14549489,48.624699,0,11.076097,201.2159,-0.0096290652,84.443314,11.076112,200.74046,-9.3802443
68.2,6.5488358,-0.14726235,48.383793,0,11.076097,204.5159,-0.0097609833,84.202652,11.076504,204.37099,-9.3782616
69.3,6.5115647,-0.14670283,48.38335,0,11.076097,207.81589,-0.0097393291,83.706299,11.076292,207.76863,-9.3763552
70.4,6.4833493,-0.14733095,48.812077,0,11.076097,211.11591,-0.0097787827,83.362846,11.077058,210.69073,-9.3745918
71.5,6.4800882,-0.1474556,49.001804,0,11.076097,214.41589,-0.0097848782,83.325714,11.076007,213.87318,-9.3728476
72.6,6.4663496,-0.14632998,47.504894,0,11.076097,217.7159,-0.0096928924,83.137024,11.076137,218.8535,-9.3711967
73.7,6.4503207,-0.14403266,47.952705,0,11.076097,221.0159,-0.0095759528,82.93779,11.076189,221.26784,-9.3698015
74.8,6.4557014,-0.14004938,47.504887,0,11.076097,224.3159,-0.0092934826,82.96994,11.075639,224.85674,-9.3679867
75.9,6.4385719,-0.13547622,46.583008,0,11.076097,227.61591,-0.008970784,82.715027,11.075644,228.75452,-9.3665247
77.0,6.4250193,-0.1273015,46.595684,0,11.076097,230.91589,-0.0084803486,82.500237,11.076442,231.70059,-9.3642921
78.1,6.4250374,-0.12041673,47.739979,0,11.076097,234.21591,-0.0079947254,82.466255,11.075799,233.74828,-9.3624058
79.2,6.41436,-0.11300271,49.064034,0,11.076097,237.5159,-0.0074707917,82.276886,11.076362,235.9222,-9.3609219
80.3,6.4036074,-0.10301647,48.369316,0,11.076097,240.8159,-0.0068759141,82.103981,11.077171,240.34047,-9.3585186
81.4,6.4115853,-0.090446331,48.013969,0,11.076097,244.11591,-0.0059933066,82.134392,11.076326,244.14577,-9.3565893
82.5,6.410007,-0.074752331,47.504658,0,11.076097,247.41589,-0.0049391356,82.005981,11.075656,247.99361,-9.3545694
83.6,6.4098272,-0.05727214,44.879498,0,11.076097,250.7159,-0.0038336061,81.939827,11.076452,253.32065,-9.3526468
84.7,6.418324,-0.036400516,44.098541,0,11.076097,254.0159,-0.0024156498,81.925102,11.076858,256.27255,-9.3509045
85.8,6.4108787,-0.016918536,44.659576,0,11.076097,257.31616,-0.0011034297,81.713753,11.076682,258.14648,-9.3490095
86.9,6.4066811,0.00091457256,47.504478,0,11.076097,260.61615,4.5265002e-05,81.572052,11.076799,258.68494,-9.3472862
88.0,6.4114199,0.020228215,49.632118,0,11.076097,263.91589,0.0013590306,81.529953,11.076698,260.64627,-9.345458
89.1,6.4040766,0.043854259,50.438217,0,11.076097,267.21588,0.0029439242,81.30069,11.077283,264.32773,-9.3435364
90.2,6.4063916,0.072719403,51.18848,0,11.076097,270.5159,0.0048546409,81.174759,11.076664,268.00217,-9.341856
91.3,6.4094467,0.10624634,50.309784,0,11.076097,273.81589,0.0071058618,81.035065,11.076066,273.06171,-9.3400908
92.4,6.3976851,0.15079905,49.22974,0,11.076097,277.11591,0.010105001,80.62735,11.076452,277.65674,-9.3384933
93.5,6.3908324,0.19992766,50.4557,0,11.076097,280.41592,0.013414852,80.293518,11.076114,279.49918,-9.3366451
94.6,6.3894296,0.25564158,50.043198,0,11.076097,283.71591,0.017194394,79.962189,11.076085,283.74725,-9.3349819
95.7,6.3802662,0.31840378,50.441238,0,11.076097,287.01593,0.021457428,79.514496,11.075938,286.71869,-9.3327789
96.8,6.3769031,0.38991624,48.206093,0,11.076097,290.31592,0.026343506,79.094398,11.076691,292.33591,-9.3312778
97.9,6.3766913,0.46747282,47.467342,0,11.076097,293.61591,0.03165175,78.661713,11.07646,295.6593,-9.3295584
99.0,6.3718204,0.5451591,47.955318,0,11.076097,296.91589,0.037023284,78.172371,11.076076,297.59241,-9.3279953
100.1,6.3763089,0.62543362,48.388412,0,11.076097,299.99542,0.042593215,77.808342,11.076859,299.99133,-9.3265524
101.2,0.017512169,0.56935608,44.159393,0,11.076097,299.99905,0.038692597,0.22242051,11.076563,303.90164,-9.3275251
102.3,0.0018762408,0.56897557,39.932034,0,11.076097,299.99905,0.038668856,0.021709487,11.076593,305.18954,-9.3272076
103.4,-0.020990994,0.56880367,39.924313,0,11.076097,299.99905,0.038651206,-0.26369849,11.076574,303.29022,-9.3271942
104.5,-0.028924543,0.568856,41.940659,0,11.076097,299.99905,0.038657133,-0.34289387,11.076472,300.83807,-9.3267593
105.6,-0.028793341,0.56878406,45.04845,0,11.076097,299.99905,0.038662858,-0.35720557,11.076643,298.36667,-9.3268394
106.7,-0.036731828,0.56968945,48.794846,0,11.076097,299.99905,0.038722813,-0.44972503,11.075874,295.5137,-9.3265343
107.8,-0.037116427,0.57020468,52.663124,0,11.076097,299.99905,0.038750455,-0.44871789,11.077196,292.93839,-9.3266706
108.9,-0.034064613,0.57067925,56.277149,0,11.076097,299.99905,0.038783219,-0.41503727,11.076231,290.90421,-9.3273745
110.0,-0.041402977,0.57057744,59.315216,0,11.076097,299.99905,0.038778841,-0.50694823,11.076012,289.495,-9.327239
111.1,-0.038253263,0.57064807,61.9258,0,11.076097,299.99905,0.038785074,-0.47031134,11.07592,288.45514,-9.3270712
112.2,-0.036135353,0.57008529,64.16375,0,11.076097,299.99905,0.038747504,-0.44215402,11.07544,288.12439,-9.3268595
113.3,-0.038453713,0.57014918,66.010376,0,11.076097,299.99905,0.038744401,-0.45568433,11.076092,288.263,-9.326952
114.4,-0.032217309,0.56978136,67.575104,0,11.076097,299.99905,0.038724411,-0.40071201,11.075995,288.6445,-9.3265877
115.5,-0.025156494,0.56972122,68.813087,0,11.076097,299.99905,0.038732715,-0.31414542,11.075943,289.45728,-9.3264008
116.6,-0.021324206,0.56923729,69.718521,0,11.076097,299.99905,0.038685858,-0.25513434,11.075964,290.59622,-9.3266249
117.7,-0.0070666489,0.56875294,70.437866,0,11.076097,299.99905,0.03867127,-0.075401433,11.076118,292.10324,-9.326479
118.8,0.0011744257,0.56875396,70.662857,0,11.076097,299.99905,0.038672477,0.010175835,11.076179,294.12128,-9.3265181
119.9,0.0047563231,0.56901938,70.569702,0,11.076097,299.99905,0.038650122,0.077528715,11.076106,296.67404,-9.3266973
121.0,0.021444732,0.5684064,69.917679,0,11.076097,299.99905,0.038647953,0.27111012,11.076896,299.54523,-9.326581
122.1,0.021036951,0.56546491,68.672951,0,11.076097,299.99905,0.038462624,0.26771456,11.076238,303.21323,-9.3261738
123.2,0.021097932,0.56316477,66.742538,0,11.076097,299.99905,0.038238961,0.27543345,11.076031,306.87418,-9.3261967
124.3,0.023850428,0.56143177,64.243973,0,11.076097,299.99905,0.038170431,0.29354471,11.076012,310.06558,-9.3259382
125.4,0.022263266,0.55989635,61.067753,0,11.076097,299.99905,0.038075622,0.26613468,11.076117,312.77673,-9.3260612
126.5,0.011563223,0.55950826,57.287384,0,11.076097,299.99905,0.037982553,0.14023156,11.076333,314.41824,-9.325551
127.6,0.0041009295,0.55958939,53.844151,0,11.076097,299.99905,0.038027138,0.044342682,11.0751,313.9476,-9.3254442
128.7,-0.010606736,0.55958831,50.881824,0,11.076097,299.99905,0.03805339,-0.1514852,11.075974,312.39847,-9.3254786
129.8,-0.026796993,0.55968463,49.229786,0,11.076097,299.99905,0.03799019,-0.31453785,11.076316,309.91394,-9.3256168
130.9,-0.034632556,0.56014621,48.506992,0,11.076097,299.99905,0.038059518,-0.41407824,11.076999,306.91592,-9.3254156
132.0,-0.041633565,0.56102329,49.229733,0,11.076097,299.99905,0.038150672,-0.51428252,11.075685,303.71738,-9.3256397
133.1,-0.0474604,0.56161046,51.315117,0,11.076097,299.99905,0.038127441,-0.57778352,11.075674,300.34848,-9.3254337
134.2,-0.046548851,0.5623498,53.893055,0,11.076097,299.99905,0.03820686,-0.56377321,11.076011,297.28204,-9.3256388
135.3,-0.053323578,0.56266677,56.69088,0,11.076097,299.99905,0.038240787,-0.66956717,11.075368,294.45599,-9.325779
136.4,-0.054728907,0.56340557,59.47998,0,11.076097,299.99905,0.038270812,-0.66283238,11.075768,292.12994,-9.3256559
137.5,-0.048085473,0.56333715,61.944611,0,11.076097,299.99905,0.038269162,-0.58970469,11.077359,290.42062,-9.3252974
138.6,-0.052359886,0.56341726,64.335693,0,11.076097,299.99905,0.038272955,-0.66912144,11.075446,289.06418,-9.3256083
139.7,-0.054203864,0.56311363,66.523376,0,11.076097,299.99905,0.038274884,-0.65570033,11.076307,288.09326,-9.325489
140.8,-0.049320295,0.56294292,68.338211,0,11.076097,299.99905,0.038257919,-0.60749555,11.076292,287.79816,-9.325264
141.9,-0.055756897,0.56333601,69.999084,0,11.076097,299.99905,0.038265046,-0.69133151,11.076641,287.6814,-9.3248358
143.0,-0.051761955,0.56328052,71.361717,0,11.076097,299.99905,0.038287587,-0.63013059,11.076375,287.95663,-9.3250513
144.1,-0.045225967,0.56290656,72.503815,0,11.076097,299.99905,0.038285282,-0.56985778,11.075648,288.59103,-9.324707
145.1302,0.06831637,0.031939458,73.453331,0,11.076097,299.99905,0.0021867992,0.87920296,11.07603,289.16141,-9.3247166
145.2821,1.8150691,0.036046304,73.575439,0,11.076099,6.0864735e-10,0.0025422494,23.014565,11.075971,289.62897,-9.3223782
145.2843,1.8345543,0.035152484,61.337341,0,11.076099,6.0790445e-25,0.0022541503,23.332581,11.074826,289.66116,-9.3228989
145.2865,1.9486995,0.036647066,45.118309,0,11.076099,6.0716300999999994e-40,0.0025126892,24.740843,11.076182,289.69501,-9.323596
145.2887,1.9056884,0.03203401,28.899271,0,11.076099,0.0,0.0021255121,24.296642,11.076001,289.72885,-9.3237009
145.2909,1.9087018,0.040977191,12.680234,0,11.076099,0.0,0.002802175,24.197453,11.076497,289.7627,-9.3236752
145.2931,1.9181151,0.034936715,0.0,0,11.076099,0.0,0.0022705847,24.446146,11.075308,289.78619,-9.3236332
145.2953,1.9377335,0.033580538,0.0,0,11.076099,0.0,0.0023072425,24.615328,11.074941,289.77264,-9.322937
145.2975,1.9390535,0.033747453,0.0,0,11.076099,0.0,0.0022051625,24.675793,11.077049,289.75912,-9.3242722
145.2997,1.9597987,0.03980273,0.0,0,11.076099,0.0,0.0027093114,24.889595,11.075058,289.74557,-9.3244429
145.3019,1.9876714,0.03553921,0.0,0,11.076099,0.0,0.0022868577,25.186989,11.075441,289.73203,-9.3235464
145.3041,2.0231509,0.033680193,0.0,0,11.076099,0.0,0.0023224072,25.630697,11.07513,289.74158,-9.3234396
145.3063,2.0450485,0.033884078,0.0,0,11.076099,0.0,0.0022382494,26.088345,11.074511,289.76187,-9.3236923
145.3085,2.0733483,0.038795926,0.0,0,11.076099,0.0,0.0026286643,26.293409,11.076038,289.7822,-9.3238907
145.3107,2.0737615,0.036192171,0.0,0,11.076099,0.0,0.0023731268,26.379976,11.07559,289.80249,-9.3250494
145.3129,2.0864768,0.037334532,0.0,0,11.076099,0.0,0.0025424045,26.515816,11.076029,289.82379,-9.3241911
145.3151,2.0982952,0.034503039,0.0,0,11.076099,0.0,0.0023156013,26.675594,11.075474,289.85086,-9.3237867
145.3173,2.11724,0.040322743,0.0,0,11.076099,0.0,0.0027745336,26.818167,11.074275,289.87796,-9.3233767
145.3195,2.1293826,0.036898203,0.0,0,11.076099,0.0,0.0023934511,27.079908,11.074867,289.90503,-9.3233948
145.3217,2.1634667,0.037139256,0.0,0,11.076099,0.0,0.0025621476,27.480915,11.077769,289.9321,-9.323823
145.3239,2.1937108,0.035792351,0.0,0,11.076099,0.0,0.0023504836,27.818432,11.077885,289.94681,-9.3251762
145.3261,2.2246635,0.042755812,0.0,0,11.076099,0.0,0.0028877244,28.218971,11.075953,289.95358,-9.3243122
145.3283,2.2435765,0.038575806,0.0,0,11.076099,0.0,0.0025315194,28.418505,11.074541,289.96036,-9.3246307
145.3305,2.2463806,0.037107769,0.0,0,11.063763,0.0,0.0025276155,28.495825,11.077374,289.9671,-9.3246279
145.3327,2.2489045,0.036871321,0.0,0,10.735819,0.0,0.0023897011,28.537212,11.075073,289.97388,-9.3249435
145.3349,2.2675281,0.042209081,0.0,0,10.404926,0.0,0.0027969345,28.89827,11.074696,289.98065,-9.3245611
145.3371,2.3116267,0.036712304,0.0,0,10.074035,0.0,0.002419034,29.354734,11.014174,289.98743,-9.3235016
145.3393,2.3151879,0.039137151,0.0,0,9.7431412,0.0,0.0026805359,29.473526,10.828446,289.99417,-9.3238297
145.3415,2.3629432,0.037697852,0.0,0,9.4141388,0.0,0.0024407012,29.905396,10.528056,290.00095,-9.3238783
145.3437,2.3748055,0.043686517,0.0,0,9.0922337,0.0,0.002903006,30.126099,10.145328,290.12027,-9.324131
145.3459,2.3946979,0.039878529,0.0,0,8.7703295,0.0,0.0026575017,30.383322,9.6903467,290.33685,-9.3249636
145.3481,2.4350631,0.040133066,0.0,0,8.4631929,0.0,0.0026659218,30.954523,9.2389841,290.55344,-9.3243179
145.3503,6.3624277,0.081516437,0.0,0,8.1570406,0.0,0.0051583806,76.86425,8.8457565,290.77005,-9.3236027
145.3525,10.138099,0.42947137,0.0,0,7.860775,0.0,0.028700104,124.60214,8.49473,290.98663,-9.3182564
145.3547,10.992069,0.6677292,0.0,0,7.5694952,0.0,0.04521966,133.99521,8.2114897,291.43338,-9.3167048
145.3569,11.724466,0.95491844,0.0,0,7.2838035,0.0,0.065676115,139.36139,7.9157972,291.88013,-9.3174629
145.3591,12.398967,1.2067077,0.0,0,7.0067787,0.0,0.083535723,145.20442,7.6507311,292.32687,-9.3149052
145.3613,12.641831,1.4853636,0.0,0,6.7313666,0.0,0.10382832,145.10838,7.374814,292.77359,-9.3159685
145.3635,13.094968,1.7388039,0.0,0,6.467802,0.0,0.12293939,147.21848,7.1101294,292.95044,-9.3155966
145.3657,13.485689,2.0050585,0.0,0,6.2042418,0.0,0.14306401,148.84554,6.841794,292.81506,-9.3165722
145.3679,13.832566,2.2663476,0.0,0,5.9515953,0.0,0.16341583,149.47066,6.5734019,292.67969,-9.3153124
145.3701,14.303789,2.5376434,0.0,0,5.7009273,0.0,0.18488513,151.26941,6.3053813,292.54434,-9.3150806
145.3723,14.675653,2.7917089,0.0,0,5.457253,0.0,0.20560654,152.09613,6.0377402,292.40897,-9.3135929
145.3745,15.076071,3.0598576,0.0,0,5.2187734,0.0,0.2277192,152.72708,5.7750697,292.38657,-9.3136473
145.3767,15.477252,3.3119111,0.0,0,4.9838037,0.0,0.24912606,153.56206,5.5153608,292.37302,-9.3140078
145.3789,15.850226,3.5746112,0.0,0,4.7569838,0.0,0.27172878,153.72385,5.257411,292.3595,-9.3150949
145.3811,16.244104,3.8135662,0.0,0,4.5305758,0.0,0.29300335,154.25487,5.004838,292.34595,-9.3170023
145.3833,16.625883,4.055553,0.0,0,4.3147016,0.0,0.31481057,154.39063,4.7688909,292.36682,-9.3152494
145.3855,17.042311,4.2831631,0.0,0,4.0989256,0.0,0.33589002,154.95085,4.5365653,292.44128,-9.3142519
145.3877,17.460852,4.5125599,0.0,0,3.8911293,0.0,0.35733595,155.43794,4.309906,292.51572,-9.3156118
145.3899,17.903778,4.7224598,0.0,0,3.6859133,0.0,0.37778556,156.13333,4.0899997,292.59018,-9.3156672
145.3921,18.338614,4.9343357,0.0,0,3.4855206,0.0,0.39853445,156.69266,3.8809938,292.66464,-9.3143368
145.3943,18.818741,5.1365857,0.0,0,3.2902927,0.0,0.41891277,157.50548,3.6764376,292.50772,-9.3145523
145.3965,19.305563,5.3469477,0.0,0,3.0970623,0.0,0.4402214,158.20711,3.4712899,292.31143,-9.3144436
145.3987,19.802795,5.5402513,0.0,0,2.9113381,0.0,0.46081719,158.97218,3.2738681,292.11514,-9.3143101
145.4009,20.341015,5.7386079,0.0,0,2.7256143,0.0,0.48169494,159.94606,3.0748742,291.91885,-9.3135586
145.4031,20.920706,5.9265251,0.0,0,2.5483871,0.0,0.50251395,161.04845,2.8803346,291.90778,-9.3133717
145.4053,21.500225,6.1244326,0.0,0,2.3717272,0.0,0.52415389,162.00383,2.6936679,292.29358,-9.3145161
145.4075,22.143494,6.2985377,0.0,0,2.2008002,0.0,0.54436964,163.47375,2.5107512,292.67941,-9.3134909
145.4097,22.794044,6.4773026,0.0,0,2.0327642,0.0,0.56484133,164.89398,2.3302031,293.06522,-9.3140507
145.4119,23.469328,6.6417799,0.0,0,1.8679363,0.0,0.58450526,166.43033,2.1581604,293.45105,-9.3134022
145.4141,24.176147,6.818234,0.0,0,1.7080842,0.0,0.60555387,167.8405,1.9911385,292.56906,-9.3128204
145.4163,24.911606,6.9773355,0.0,0,1.5491643,0.0,0.62558562,169.62511,1.8206577,291.33328,-9.3118839
145.4185,25.675388,7.1418695,0.0,0,1.3970972,0.0,0.6459465,171.25439,1.6601274,290.09747,-9.3118677
145.4207,26.487076,7.289639,0.0,0,1.2450333,0.0,0.66527832,173.32581,1.5028187,288.86169,-9.309103
145.4229,27.323248,7.4480591,0.0,0,1.0992643,0.0,0.68552697,175.14517,1.3493208,287.19308,-9.3103685
145.4251,28.230684,7.5901632,0.0,0,0.95463622,0.0,0.70504624,177.48907,1.2006863,284.19388,-9.3110027
145.4273,29.168402,7.7352939,0.0,0,0.8140732,0.0,0.72445333,179.87917,1.0562927,281.1947,-9.30933
145.4295,30.126099,7.8699222,0.0,0,0.67652929,0.0,0.74370021,182.22675,0.90997654,278.19553,-9.3079357
145.4317,31.111082,8.0124578,0.0,0,0.54098582,0.0,0.76304114,184.58549,0.77605963,275.19632,-9.3075542
145.4339,32.131805,8.1347246,0.0,0,0.4100858,0.0,0.78149503,187.14815,0.64165568,273.57095,-9.3067503
145.4361,33.206917,8.2633429,0.0,0,0.27942529,0.0,0.79973716,189.91081,0.51021516,272.50919,-9.3077888
145.4383,32.177959,8.3536587,0.0,0,0.15489206,0.0,0.81417209,181.66557,0.39817652,271.44742,-9.3082218
145.4405,31.441238,8.3854904,0.0,0,0.030416043,0.0,0.81800282,176.66808,0.35154045,270.38562,-9.3098831
145.4427,30.695557,8.3784161,0.0,0,-0.091732524,0.0,0.81796688,172.53885,0.3218101,269.7757,-9.310544
145.4449,30.405426,8.3924084,0.0,0,-0.21312852,0.0,0.81948042,170.5988,0.28450349,271.32965,-9.3119106
145.4471,30.413755,8.3893099,0.0,0,-0.33452454,0.0,0.81961286,170.62209,0.23015189,272.88361,-9.312665
145.4493,30.408899,8.4065914,0.0,0,-0.45592052,0.0,0.82157129,170.29372,0.17262794,274.43756,-9.3113899
145.4515,30.407846,8.4015026,0.0,0,-0.57731652,0.0,0.8215313,170.23143,0.11698277,275.99152,-9.3115044
145.4537,30.323492,8.4115276,0.0,0,-0.69871247,0.0,0.82244676,169.67699,0.064156346,277.65646,-9.3111963
145.4559,30.207159,8.4106121,0.0,0,-0.82010847,0.0,0.82290423,168.90253,0.018519485,279.38483,-9.3132687
145.4581,29.987833,8.4248075,0.0,0,-0.94150448,0.0,0.82430571,167.50038,-0.013369702,281.11319,-9.3134212
145.4603,29.70153,8.4204874,0.0,0,-1.0629005,0.0,0.8246302,165.85553,-0.046918917,282.84158,-9.3145399
145.4625,29.311649,8.425189,0.80047393,0,-0.84332824,300.0,0.8245185,163.69003,-0.063772202,284.49832,-9.3146019
145.4647,28.819956,8.4203253,8.8046417,0,-0.42304912,300.0,0.82445484,160.96948,-0.06688676,285.51035,-9.3131065
145.4669,28.352003,8.4302654,16.808811,0,-0.0027696523,300.0,0.82500684,158.24252,-0.058711927,286.5224,-9.3154526
145.4691,27.935333,8.4203768,24.812979,0,0.4175092,300.0,0.82460302,155.96297,-0.052918091,287.53445,-9.3143663
145.4713,27.632427,8.4265051,32.817146,0,0.83778834,300.0,0.82458395,154.27429,-0.050897162,288.54648,-9.3158617
145.4735,27.367908,8.4230795,36.309814,0,1.2580682,300.0,0.82480729,152.76698,-0.049514756,289.52637,-9.3166857
145.4757,26.514759,8.4317503,36.309814,0,1.6783469,300.0,0.82514334,148.05898,-0.026424441,290.48135,-9.3167715
145.4779,24.792349,8.4174652,36.309814,0,2.0986257,300.0,0.82399356,138.74303,0.048053116,291.43634,-9.3180256
145.4801,21.311607,8.4146795,36.309814,0,2.5189054,300.0,0.8227039,119.72211,0.18555574,292.39133,-9.3221045
145.4823,13.056445,8.3751135,36.174046,0,2.9391847,300.0,0.81806457,75.801102,0.42402548,293.34482,-9.325264
145.4845,0.33781943,8.26682,31.197172,0,3.3594637,300.0,0.79979002,2.2507486,0.8813616,294.24506,-9.336792
145.4867,6.9426937,8.3700714,26.220301,0,3.7797427,300.0,0.81666672,40.635242,1.5507593,295.14529,-9.3323193
145.4889,2.3946419,8.340188,21.243427,0,4.2000222,300.0,0.81132954,12.584594,2.2953441,296.04553,-9.3368959
145.4911,2.8103223,8.3276768,16.266556,0,4.6203012,300.0,0.81082928,16.329329,2.9647076,296.94577,-9.334815
145.4933,3.8976481,8.3461571,13.73291,0,5.0405807,300.0,0.81229889,21.848112,3.487664,297.71307,-9.3346424
145.4955,3.0539296,8.3291798,13.73291,0,5.4608598,300.0,0.81081283,17.145332,3.887465,298.34259,-9.3324842
145.4977,2.9616704,8.3374271,13.73291,0,5.8811393,300.0,0.81105393,16.802219,4.2697477,298.97208,-9.3329058
145.4999,3.2166529,8.3355207,13.73291,0,6.3014183,300.0,0.81173933,18.236179,4.6481423,299.60156,-9.3317652
145.5021,3.2212555,8.3496075,13.73291,0,6.7216969,300.0,0.81266934,18.183062,5.0290127,300.23108,-9.3314266
145.5043,3.1969047,8.3360863,10.843197,0,7.1419768,300.0,0.8119629,18.013058,5.4255166,300.66672,-9.3289595
145.5065,3.1178417,8.3414516,7.8159027,0,7.5622559,300.0,0.81159347,17.615318,5.844399,301.09314,-9.3288774
145.5087,3.1794822,8.3328333,4.7886076,0,7.9825354,300.0,0.81145281,18.001726,6.2878237,301.51956,-9.328476
145.5109,3.2294617,8.3432369,1.7613126,0,8.4028139,300.0,0.81163543,18.24872,6.7391996,301.94598,-9.3282824
145.5131,3.2484815,8.3360662,0.0,0,8.8230925,300.0,0.81191283,18.384005,7.1849103,302.34116,-9.3276901
145.5153,3.3196006,8.3402863,0.0,0,9.243372,300.0,0.81141579,18.726866,7.619885,302.69278,-9.3271208
145.5175,3.1909688,8.334527,0.0,0,9.6636515,300.0,0.81178886,18.123959,8.0577478,303.04443,-9.3267937
145.5197,3.2117205,8.3449469,0.0,0,10.083931,300.0,0.81196702,18.087875,8.4834042,303.39609,-9.3260326
145.5219,3.2441747,8.3357706,0.0,0,10.50421,300.0,0.81187546,18.290592,8.916544,303.74771,-9.3254805
145.5241,3.3495204,8.3405437,0.0,0,10.924489,300.0,0.81137991,18.912912,9.3523817,304.06906,-9.3247814
145.5263,3.2740381,8.332839,0.0,0,11.344769,300.0,0.81149703,18.491194,9.7917337,304.38635,-9.324338
145.5285,3.3242433,8.3474321,0.0,0,11.765047,300.0,0.81223357,18.804005,10.21939,304.70361,-9.3241463
145.5307,3.3884571,8.33564,0.0,0,12.185327,300.0,0.8118636,19.097425,10.652213,305.0209,-9.3254271
145.5329,3.3881319,8.3402824,0.0,0,12.605606,300.0,0.81136477,19.157763,11.081326,305.31708,-9.3239899
145.5351,3.3483837,8.3359423,0.0,0,13.025885,300.0,0.81212515,18.937407,11.50081,305.57324,-9.3255663
145.5373,3.3180287,8.3465443,0.0,0,13.446164,300.0,0.81208497,18.771835,11.921414,305.82941,-9.3245277
145.5395,3.3395646,8.3385315,0.0,0,13.866444,300.0,0.81237465,18.894531,12.340096,306.08557,-9.3233442
145.5417,3.4075372,8.3415985,0.0,0,14.286723,300.0,0.81162632,19.188951,12.771924,306.34174,-9.3224154
145.5439,3.5090797,8.3363142,0.0,0,14.707002,300.0,0.81216985,19.849836,13.203352,306.5488,-9.3222418
145.5461,3.394067,8.348197,0.0,0,15.127281,300.0,0.81222844,19.182159,13.645388,306.74429,-9.3239746
145.5483,3.5118673,8.3346376,0.0,0,15.547561,300.0,0.81173629,19.873831,14.086673,306.93979,-9.3234568
145.5505,3.4866374,8.3460016,0.0,0,15.967839,300.0,0.81220418,19.710121,14.526281,307.13528,-9.3223982
145.5527,3.5235031,8.3374815,0.0,0,16.388119,300.0,0.81226349,19.945658,14.947116,307.31241,-9.3214254
145.5549,3.4734795,8.3492279,0.0,0,16.808399,300.0,0.81248105,19.669271,15.36151,307.44046,-9.3214846
145.5571,3.4469552,8.3376827,0.0,0,17.228678,300.0,0.81233072,19.456553,15.771513,307.56854,-9.322608
145.5593,3.4634116,8.3426657,0.0,0,17.648958,300.0,0.81176054,19.594334,16.191282,307.69662,-9.3217278
145.5615,3.6138015,8.3363552,0.0,0,17.999975,300.0,0.81216866,20.400526,16.605865,307.82471,-9.3226976
145.5637,3.6065409,8.3513107,0.0,0,18.0,300.0,0.81271392,20.427282,17.022173,307.94781,-9.3218956
145.5659,3.6031885,8.3365479,0.0,0,18.0,300.0,0.8121717,20.330797,17.42831,308.06915,-9.3219032
145.5681,3.6597915,8.343255,0.0,0,18.0,300.0,0.81178939,20.7344,17.79269,308.19052,-9.3227282
145.5703,3.6457734,8.337079,0.0,0,18.0,300.0,0.81239522,20.60882,18.097967,308.31186,-9.3239851
145.5725,3.6709559,8.347559,0.0,0,18.0,300.0,0.81222647,20.766512,18.338373,308.4332,-9.3262348
145.5747,3.6814878,8.3388863,0.0,0,18.0,300.0,0.81267971,20.75882,18.484554,308.55453,-9.3296289
145.5769,3.7204075,8.3450069,0.0,0,18.0,300.0,0.81211579,21.044439,18.525875,308.67587,-9.3341484
145.5791,3.8090255,8.3386202,0.0,0,18.0,300.0,0.81259233,21.512798,18.45974,308.79724,-9.3394299
145.5813,3.89241,8.3479891,0.0,0,18.0,300.0,0.81214356,21.996321,18.341698,308.91858,-9.3482466
145.5835,3.9443293,8.3378801,0.0,0,18.0,300.0,0.81229013,22.247791,18.216341,309.022,-9.3605413
145.5857,3.9561272,8.3453512,0.0,0,18.0,300.0,0.81193501,22.331522,18.122221,309.11639,-9.3755713
145.5879,3.9690528,8.3409729,0.0,0,18.0,300.0,0.81296039,22.466936,18.05912,309.21075,-9.3925714
145.5901,3.9108694,8.3487062,0.0,0,18.0,300.0,0.81227636,22.137106,18.03751,309.30515,-9.4109955
145.5923,3.8336387,8.3345423,0.0,0,18.0,300.0,0.81202072,21.71257,18.042057,309.39093,-9.4302464
145.5945,3.7964139,8.340064,0.0,0,18.0,300.0,0.81123102,21.424492,18.051094,309.41791,-9.4482145
145.5967,3.8710971,8.3335323,0.0,0,18.0,300.0,0.81190568,21.813459,18.076477,309.44489,-9.467761
145.5989,3.935504,8.3456755,0.0,0,18.0,300.0,0.81166756,22.15917,18.096523,309.47183,-9.4838591
145.6011,4.042552,8.3345079,0.0,0,18.0,300.0,0.81195682,22.752968,18.116261,309.49881,-9.500308
145.6033,4.0743518,8.3398466,0.0,0,18.0,300.0,0.811279,23.058434,18.130707,309.52179,-9.517067
145.6055,4.0945845,8.3346224,0.0,0,18.0,300.0,0.81202251,23.196129,18.137144,309.54199,-9.5334206
145.6077,4.0536065,8.3474121,0.0,0,18.0,300.0,0.81199294,22.97485,18.142,309.56223,-9.5472116
145.6099,3.9784474,8.3351011,0.0,0,18.0,300.0,0.81210637,22.597492,18.141741,309.58246,-9.5621738
145.6121,3.9394016,8.3397188,0.0,0,18.0,300.0,0.81120533,22.356991,18.137228,309.60303,-9.5779705
145.6143,3.9698977,8.3328228,0.0,0,18.0,300.0,0.81193614,22.434547,18.137039,309.63,-9.5941629
145.6165,4.0511165,8.3449354,0.0,0,18.0,300.0,0.81156898,22.844334,18.137341,309.65695,-9.6098604
145.6187,4.1385636,8.3362398,0.0,0,18.0,300.0,0.81226194,23.371708,18.133842,309.68393,-9.625186
145.6209,4.2102294,8.3443766,0.0,0,18.0,300.0,0.81174105,23.778339,18.130163,309.71088,-9.6395817
145.6231,4.2342033,8.3372221,0.0,0,18.0,300.0,0.81249112,23.934946,18.128603,309.73087,-9.656683
145.6253,4.2168484,8.3465958,0.0,0,18.0,300.0,0.81187338,23.839329,18.126429,309.74435,-9.6708755
145.6275,4.1599865,8.3350277,0.0,0,18.0,300.0,0.81204951,23.609549,18.123032,309.75781,-9.6879807
145.6297,4.0745621,8.3422737,0.0,0,18.0,300.0,0.81166935,23.098694,18.123487,309.7713,-9.7044249
145.6319,4.0844517,8.3361025,0.0,0,18.0,300.0,0.81253338,23.077475,18.120615,309.78479,-9.7196875
145.6341,4.1362834,8.3439913,0.0,0,18.0,300.0,0.81143743,23.344873,18.117918,309.79828,-9.7348146
145.6363,4.2510629,8.3341665,0.0,0,18.0,300.0,0.81189358,23.944838,18.115896,309.81177,-9.7496576
145.6385,4.3137031,8.342207,0.0,0,18.0,300.0,0.81146169,24.348787,18.116531,309.82526,-9.766449
145.6407,4.3541985,8.3382521,0.0,0,18.0,300.0,0.81257272,24.585819,18.115662,309.83875,-9.783042
145.6429,4.3394365,8.3484507,0.0,0,18.0,300.0,0.8120684,24.569271,18.111637,309.83121,-9.7991467
145.6451,4.2901015,8.3392105,0.0,0,18.0,300.0,0.81265283,24.30493,18.108765,309.79749,-9.8152275
145.6473,4.2205405,8.3438978,0.0,0,18.0,300.0,0.81175876,23.925062,18.10305,309.76379,-9.8308039
145.6495,4.1886668,8.3360062,0.0,0,18.0,300.0,0.81231004,23.720497,18.103664,309.73007,-9.8475609
145.6517,4.2164192,8.3471375,0.0,0,18.0,300.0,0.81176269,23.786585,18.10277,309.69635,-9.8637266
145.6539,4.3159423,8.3373184,0.0,0,18.0,300.0,0.81240028,24.314924,18.102911,309.65039,-9.8784113
145.6561,4.4215698,8.344141,0.0,0,18.0,300.0,0.81172341,24.922861,18.100456,309.60321,-9.8944368
145.6583,4.4620924,8.3351068,0.0,0,18.0,300.0,0.81226957,25.166077,18.095181,309.55603,-9.9104595
145.6605,4.4554272,8.3478746,0.0,0,18.0,300.0,0.81193793,25.174152,18.097778,309.50885,-9.9261265
145.6627,4.4039998,8.3400297,0.0,0,18.0,300.0,0.8127591,24.935072,18.099434,309.47675,-9.9418983
145.6649,4.3547559,8.3446608,0.0,0,18.0,300.0,0.81187934,24.701864,18.1012,309.47,-9.9572563
145.6671,4.3150406,8.3382835,0.0,0,18.0,300.0,0.81277001,24.39049,18.096912,309.46326,-9.9738932
145.6693,4.3151269,8.3472128,0.0,0,18.0,300.0,0.81190282,24.363668,18.093292,309.45651,-9.9881907
145.6715,4.3809018,8.3354063,0.0,0,18.0,300.0,0.81212205,24.673439,18.098124,309.44977,-10.004474
145.6737,4.5005174,8.3423414,0.0,0,18.0,300.0,0.81150621,25.301867,18.097073,309.42612,-10.021579
145.6759,4.5680947,8.3386364,0.0,0,18.0,300.0,0.81266034,25.776968,18.096249,309.39917,-10.038397
145.6781,4.5817971,8.3506088,0.0,0,18.0,300.0,0.81220126,25.920021,18.094484,309.37219,-10.05271
145.6803,4.546731,8.3375931,0.0,0,18.0,300.0,0.8125304,25.751978,18.094408,309.34521,-10.068624
145.6825,4.4901156,8.343235,0.0,0,18.0,300.0,0.81168377,25.488338,18.096292,309.31625,-10.08578
145.6847,4.4455628,8.3393221,0.0,0,18.0,300.0,0.81290531,25.154051,18.095188,309.28253,-10.100749
145.6869,4.4368258,8.3488083,0.0,0,18.0,300.0,0.81199062,25.101587,18.087168,309.24881,-10.116703
145.6891,4.4777889,8.333827,0.0,0,18.0,300.0,0.81202555,25.23558,18.089939,309.21512,-10.132053
145.6913,4.575624,8.3414268,0.0,0,18.0,300.0,0.81131297,25.767559,18.088303,309.1814,-10.147535
145.6935,4.6714878,8.3381977,0.0,0,18.0,300.0,0.81275022,26.34568,18.086817,309.16315,-10.16395
145.6957,4.7149916,8.3485613,0.0,0,18.0,300.0,0.81191367,26.645226,18.088087,309.14966,-10.179914
145.6979,4.6854253,8.3387156,0.0,0,18.0,300.0,0.81274909,26.486,18.086287,309.13617,-10.195576
145.7001,4.6385565,8.3451653,0.0,0,18.0,300.0,0.8119719,26.282946,18.085773,309.12268,-10.210439
145.7023,4.5742669,8.3411903,0.0,0,18.0,300.0,0.81313616,25.915951,18.085619,309.11075,-10.225253
145.7045,4.5644565,8.3473988,0.0,0,18.0,300.0,0.81174695,25.816725,18.086142,309.104,-10.242371
145.7067,4.570004,8.335556,0.0,0,18.0,300.0,0.81230819,25.815577,18.086229,309.09726,-10.25946
145.7089,4.6491013,8.3436384,0.0,0,18.0,300.0,0.81161839,26.234148,18.08576,309.09052,-10.275285
145.7111,4.7544789,8.3400936,0.0,0,18.0,300.0,0.8129949,26.760174,18.084194,309.08377,-10.288192
145.7133,4.8239455,8.3507795,0.0,0,18.0,300.0,0.81234914,27.205727,18.082973,309.04443,-10.305788
145.7155,4.8119278,8.3386021,0.0,0,18.0,300.0,0.8126139,27.215176,18.081554,308.99051,-10.321998
145.7177,4.7491593,8.3462172,0.0,0,18.0,300.0,0.81206691,26.968353,18.081068,308.93655,-10.339697
145.7199,4.6880612,8.341012,0.0,0,18.0,300.0,0.81319487,26.504065,18.081528,308.88263,-10.355624
145.7221,4.6705203,8.3499031,0.0,0,18.0,300.0,0.8122707,26.428978,18.079496,308.82663,-10.370664
145.7243,4.6642814,8.3376484,0.0,0,18.0,300.0,0.81254894,26.359419,18.077995,308.75922,-10.38528
145.7265,4.7200556,8.3427353,0.0,0,18.0,300.0,0.81157166,26.658407,18.074783,308.6918,-10.400835
145.7287,4.8217764,8.3388157,0.0,0,18.0,300.0,0.81280363,27.119762,18.080221,308.62439,-10.418148
145.7309,4.8941317,8.3489046,0.0,0,18.0,300.0,0.81192845,27.571743,18.075951,308.55698,-10.434244
145.7331,4.9295015,8.337575,0.0,0,18.0,300.0,0.81249332,27.83029,18.074188,308.51459,-10.449
145.7353,4.8972878,8.3439617,0.0,0,18.0,300.0,0.81157017,27.739958,18.072565,308.48761,-10.465475
145.7375,4.8126531,8.3414764,0.0,0,18.0,300.0,0.81316578,27.250788,18.072712,308.46066,-10.480408
145.7397,4.7667718,8.3499584,0.0,0,18.0,300.0,0.81217664,27.002634,18.074394,308.43369,-10.49694
145.7419,4.7722902,8.3387728,0.0,0,18.0,300.0,0.81276429,26.958439,18.076254,308.40451,-10.513017
145.7441,4.7997704,8.3438807,0.0,0,18.0,300.0,0.81171286,27.097708,18.069675,308.35059,-10.529033
145.7463,4.8788342,8.3411379,0.0,0,18.0,300.0,0.81314415,27.497761,18.07338,308.29666,-10.544195
145.7485,4.9748511,8.3500032,0.0,0,18.0,300.0,0.81218439,28.053305,18.073843,308.24274,-10.559318
145.7507,5.0277228,8.3398495,0.0,0,18.0,300.0,0.81277627,28.407015,18.070225,308.18881,-10.575134
145.7529,5.0306015,8.3448439,0.0,0,18.0,300.0,0.81179959,28.477547,18.073729,308.13489,-10.591918
145.7551,4.9592342,8.3439369,0.0,0,18.0,300.0,0.81354749,28.105122,18.074158,308.08096,-10.609304
145.7573,4.8821545,8.3511229,0.0,0,18.0,300.0,0.81252086,27.673304,18.069811,308.02701,-10.623172
145.7595,4.8737807,8.3393793,0.0,0,18.0,300.0,0.81286323,27.539415,18.069099,307.97308,-10.639258
145.7617,4.9051757,8.343606,0.0,0,18.0,300.0,0.81168348,27.699224,18.069494,307.91922,-10.654915
145.7639,4.9653392,8.3395929,0.0,0,18.0,300.0,0.81294006,27.971321,18.068378,307.87204,-10.671423
145.7661,5.0433502,8.3480844,0.0,0,18.0,300.0,0.81209642,28.421934,18.068398,307.82483,-10.686741
145.7683,5.121551,8.3400784,0.0,0,18.0,300.0,0.81289184,28.862026,18.069715,307.77765,-10.701841
145.7705,5.1460495,8.3478823,0.0,0,18.0,300.0,0.81215352,29.118933,18.066015,307.73044,-10.718456
145.7727,5.108386,8.3416471,0.0,0,18.0,300.0,0.8132984,28.892763,18.064342,307.68008,-10.735007
145.7749,5.0272646,8.3499985,0.0,0,18.0,300.0,0.81245744,28.444708,18.066135,307.62616,-10.751967
145.7771,4.9645557,8.3428841,0.0,0,18.0,300.0,0.81333613,28.046125,18.066816,307.57224,-10.765451
145.7793,4.9761028,8.3442965,0.0,0,18.0,300.0,0.81173348,28.127077,18.064758,307.51828,-10.781293
145.7815,5.0453982,8.3381348,0.0,0,18.0,300.0,0.81271839,28.48233,18.063133,307.46436,-10.797411
145.7837,5.1230769,8.3486567,0.0,0,18.0,300.0,0.8121357,28.856598,18.061268,307.42307,-10.814136
145.7859,5.1902623,8.3433104,0.0,0,18.0,300.0,0.81345743,29.241302,18.063406,307.38263,-10.830507
145.7881,5.2249651,8.347681,0.0,0,18.0,300.0,0.81214666,29.550123,18.066822,307.34216,-10.846008
145.7903,5.2200818,8.3412704,0.0,0,18.0,300.0,0.81302708,29.521177,18.063,307.30173,-10.859991
145.7925,5.1556435,8.3476315,0.0,0,18.0,300.0,0.81214809,29.215443,18.063158,307.26129,-10.876923
145.7947,5.0814557,8.3428631,0.0,0,18.0,300.0,0.81336206,28.741879,18.061626,307.22086,-10.893137
145.7969,5.050508,8.3447475,0.0,0,18.0,300.0,0.81181073,28.562487,18.059887,307.18039,-10.909014
145.7991,5.1101804,8.3394823,0.0,0,18.0,300.0,0.812922,28.850033,18.065048,307.13995,-10.924006
145.8013,5.1921964,8.34688,0.0,0,18.0,300.0,0.81189054,29.267246,18.057428,307.09952,-10.939421
145.8035,5.2653923,8.3438616,0.0,0,18.0,300.0,0.81342071,29.648659,18.055237,307.05322,-10.954415
145.8057,5.3025203,8.3451033,0.0,0,18.0,300.0,0.81187141,29.97489,18.056704,307.00604,-10.970647
145.8079,5.3169136,8.3414402,0.0,0,18.0,300.0,0.81320924,30.057476,18.054373,306.95886,-10.988399
145.8101,5.2717957,8.3486576,0.0,0,18.0,300.0,0.81223387,29.842541,18.062067,306.91165,-11.003458
145.8123,5.2027941,8.34373,0.0,0,18.0,300.0,0.81351668,29.433916,18.056993,306.86447,-11.019091
145.8145,5.1604519,8.3490858,0.0,0,18.0,300.0,0.81243747,29.204662,18.054533,306.81729,-11.034781
145.8167,5.1797051,8.344017,0.0,0,18.0,300.0,0.81352234,29.202007,18.055285,306.77008,-11.050345
145.8189,5.2475061,8.345808,0.0,0,18.0,300.0,0.81174523,29.572397,18.052271,306.7229,-11.067646
145.8211,5.3271203,8.341012,0.0,0,18.0,300.0,0.81296331,30.004364,18.057949,306.67569,-11.084553
145.8233,5.3899636,8.3460712,0.0,0,18.0,300.0,0.81203717,30.431263,18.055151,306.62317,-11.099476
145.8255,5.3993325,8.3463831,0.0,0,18.0,300.0,0.81388772,30.528454,18.055801,306.56924,-11.114347
145.8277,5.3834286,8.3498363,0.0,0,18.0,300.0,0.81244028,30.457035,18.049688,306.51532,-11.129163
145.8299,5.3277273,8.3416176,0.0,0,18.0,300.0,0.81312954,30.186581,18.052723,306.4614,-11.145225
145.8321,5.2762909,8.3470402,0.0,0,18.0,300.0,0.81221592,29.877468,18.052969,306.41434,-11.160868
145.8343,5.2633276,8.343955,0.0,0,18.0,300.0,0.81351161,29.685923,18.054678,306.38739,-11.177574
145.8365,5.3013172,8.3473825,0.0,0,18.0,300.0,0.81200832,29.892948,18.05401,306.36041,-11.192821
145.8387,5.3949656,8.3412848,0.0,0,18.0,300.0,0.81310517,30.381289,18.05233,306.33347,-11.208213
145.8409,5.4691858,8.3464365,0.0,0,18.0,300.0,0.8120749,30.858398,18.049253,306.30649,-11.225206
145.8431,5.4909153,8.3430967,0.0,0,18.0,300.0,0.81335634,31.00861,18.052143,306.27951,-11.24217
145.8453,5.4761224,8.3472652,0.0,0,18.0,300.0,0.81215274,31.009665,18.050226,306.25256,-11.256494
145.8475,5.4516945,8.3430386,0.0,0,18.0,300.0,0.81327695,30.817728,18.050344,306.22559,-11.27185
145.8497,5.3853574,8.3464937,0.0,0,18.0,300.0,0.81201565,30.526104,18.051247,306.19864,-11.288708
145.8519,5.3401003,8.3424511,0.0,0,18.0,300.0,0.81330895,30.172092,18.04623,306.16553,-11.305269
145.8541,5.3649273,8.347105,0.0,0,18.0,300.0,0.81202132,30.27787,18.048971,306.10486,-11.321061
145.8563,5.4314756,8.3431892,0.0,0,18.0,300.0,0.81330562,30.600803,18.047958,306.04419,-11.335845
145.8585,5.5242043,8.3476734,0.0,0,18.0,300.0,0.81234413,31.166136,18.049107,305.98352,-11.348976
145.8607,5.5739217,8.3457527,0.0,0,18.0,300.0,0.81374192,31.417049,18.047152,305.92285,-11.366658
146.761,5.4721818,8.35285,0.0,0,18.0,1.621674e-10,0.81378412,30.872526,18.001087,278.64896,-11.483126
147.861,5.227262,8.3565283,0.0,0,18.0,1.6196895e-25,0.81438774,29.486116,18.000465,265.69861,-11.482835
148.961,5.1453896,8.3600264,0.0,0,18.0,1.6177150000000001e-40,0.81498694,29.002649,17.999601,256.02255,-11.483309
150.061,5.0461917,8.3628426,0.0,0,18.0,1.4012985e-45,0.81534994,28.417475,18.000067,247.49136,-11.482997
151.161,4.9822006,8.3658733,0.0,0,18.0,1.4012985e-45,0.81579995,28.068956,18.00045,239.88617,-11.483856
152.261,4.9349737,8.3688059,0.0,0,18.0,1.4012985e-45,0.81622231,27.783831,17.999895,232.66365,-11.483714
153.361,4.8379612,8.371315,0.0,0,18.0,1.4012985e-45,0.81670374,27.211996,18.000437,226.05438,-11.483479
154.461,4.7649527,8.3735838,0.0,0,18.0,1.4012985e-45,0.8170768,26.815845,18.000019,219.62273,-11.483424
155.561,4.707067,8.3762007,0.0,0,18.0,1.4012985e-45,0.81729585,26.467318,17.999872,213.72607,-11.483454
156.661,4.6383171,8.378809,0.0,0,18.0,1.4012985e-45,0.81780529,26.063896,17.999008,207.8853,-11.483208
157.761,4.5707593,8.3812599,0.0,0,18.0,1.4012985e-45,0.81824017,25.684757,18.000284,202.48114,-11.483171
158.861,4.5352411,8.3840036,0.0,0,18.0,1.4012985e-45,0.81849241,25.465368,18.000914,197.18466,-11.483124
159.961,4.4565921,8.3860283,0.0,0,18.0,1.4012985e-45,0.81882143,25.009342,18.00075,192.20668,-11.483375
161.061,4.4111023,8.3886003,0.0,0,18.0,1.4012985e-45,0.81925219,24.763052,17.999815,187.2719,-11.483327
162.161,4.3799043,8.3908482,0.0,0,18.0,1.4012985e-45,0.81965613,24.565451,17.999607,182.74141,-11.483562
163.261,4.3084621,8.393157,0.0,0,18.0,1.4012985e-45,0.81999213,24.154879,17.999964,178.22778,-11.483657
164.361,4.2591567,8.3956051,0.0,0,18.0,1.4012985e-45,0.82023668,23.888914,18.000618,174.01605,-11.484118
165.461,4.221427,8.3975306,0.0,0,18.0,1.4012985e-45,0.82065612,23.652166,17.999746,169.71024,-11.483885
166.561,4.1590109,8.3997488,0.0,0,18.0,1.4012985e-45,0.82103336,23.296495,17.998625,165.91064,-11.483763
167.661,4.1425438,8.4016361,0.0,0,18.0,1.4012985e-45,0.82114828,23.214008,17.999056,162.02487,-11.483708
168.761,4.125175,8.4036236,0.0,0,18.0,1.4012985e-45,0.82149774,23.09024,17.999853,158.14746,-11.48372
169.861,4.0808754,8.4055901,0.0,0,18.0,1.4012985e-45,0.82184058,22.838362,17.999737,154.64885,-11.483471
170.961,4.0644045,8.4080372,0.0,0,18.0,1.4012985e-45,0.82221949,22.754131,17.99983,151.14378,-11.483484
172.061,4.0548301,8.4100084,0.0,0,18.0,1.4012985e-45,0.8225199,22.673426,17.999786,147.69691,-11.483407
173.161,4.0189915,8.4121561,0.0,0,18.0,1.4012985e-45,0.82275259,22.481018,17.999949,144.3177,-11.483168
174.261,4.0205302,8.4138536,0.0,0,18.0,1.4012985e-45,0.82311547,22.485357,18.000025,141.02167,-11.483242
175.361,3.9955616,8.4153461,0.0,0,18.0,1.4012985e-45,0.82340509,22.320051,17.999722,137.88443,-11.48325
176.461,3.954972,8.4167919,0.0,0,18.0,1.4012985e-45,0.82345688,22.10351,18.000137,134.87257,-11.483433
177.561,3.9541054,8.4191322,0.0,0,18.0,1.4012985e-45,0.82384235,22.095722,18.000084,131.69881,-11.48353
178.661,3.9388249,8.4211178,0.0,0,18.0,1.4012985e-45,0.82418013,21.984062,17.99959,128.89117,-11.483598
179.761,3.9109182,8.4223347,0.0,0,18.0,1.4012985e-45,0.8244099,21.840582,17.999989,126.16381,-11.483769
180.861,3.9107306,8.4242897,0.0,0,18.0,1.4012985e-45,0.82472914,21.83687,17.99896,123.33278,-11.483751
181.961,3.8790996,8.4264288,0.0,0,18.0,1.4012985e-45,0.82489216,21.637096,18.000879,120.68066,-11.483642
183.061,3.8555603,8.4277287,0.0,0,18.0,1.4012985e-45,0.82521027,21.512226,18.000948,118.11074,-11.483852
184.161,3.8585408,8.4290075,0.0,0,18.0,1.4012985e-45,0.82546169,21.523991,18.000484,115.62438,-11.483618
185.261,3.8285928,8.4305468,0.0,0,18.0,1.4012985e-45,0.82557845,21.338627,18.000143,113.09367,-11.483471
186.361,3.8055987,8.4324083,0.0,0,18.0,1.4012985e-45,0.82588851,21.22508,18.00061,110.84372,-11.483593
187.461,3.8001285,8.4335442,0.0,0,18.0,1.4012985e-45,0.82604837,21.180145,17.999559,108.47153,-11.483232
188.561,3.7759123,8.4345798,0.0,0,18.0,1.4012985e-45,0.82629275,21.032888,18.000071,106.17713,-11.483359
189.661,3.7492332,8.4361534,0.0,0,18.0,1.4012985e-45,0.82657135,20.894936,18.00009,103.95092,-11.483099
190.761,3.7595153,8.4374256,0.0,0,18.0,1.4012985e-45,0.82660383,20.940702,17.999765,101.87057,-11.48326
191.861,3.7147479,8.4391165,0.0,0,18.0,1.4012985e-45,0.82688314,20.680771,18.000378,99.80426,-11.482792
192.961,3.7024465,8.4398727,0.0,0,18.0,1.4012985e-45,0.82702833,20.632381,18.000553,97.760757,-11.482796
194.061,3.6942978,8.4414387,0.0,0,18.0,1.4012985e-45,0.82733774,20.5655,17.999132,95.843132,-11.482566
195.161,3.6663754,8.4425964,0.0,0,18.0,1.4012985e-45,0.82753152,20.400633,17.999842,94.00016,-11.482669
196.261,3.6689765,8.4443836,0.0,0,18.0,1.4012985e-45,0.82762736,20.430372,18.000467,92.157623,-11.482443
197.361,3.6648452,8.4445171,0.0,0,18.0,1.4012985e-45,0.82773304,20.38933,18.000793,90.416405,-11.482706
198.461,3.6425884,8.4461422,0.0,0,18.0,1.4012985e-45,0.82802969,20.260206,18.00005,88.619896,-11.483112
199.561,3.6322787,8.4470606,0.0,0,18.0,1.4012985e-45,0.82816297,20.213821,17.999514,86.918343,-11.482405
200.661,3.6250739,8.4481039,0.0,0,18.0,1.4012985e-45,0.82833552,20.146662,17.999657,85.275642,-11.482898
201.761,3.6024535,8.4492149,0.0,0,18.0,1.4012985e-45,0.82836455,20.031137,18.000072,83.66539,-11.483209
202.861,3.6007104,8.4503956,0.0,0,18.0,1.4012985e-45,0.82863122,20.029808,18.000671,82.122612,-11.482912
203.961,3.5741606,8.4511509,0.0,0,18.0,1.4012985e-45,0.82879215,19.864183,18.000565,80.609062,-11.482777
205.061,3.545763,8.451746,0.0,0,18.0,1.4012985e-45,0.82887363,19.712347,17.999645,79.143044,-11.482757
205.861,3.5266683,8.4527388,0.0,0,18.0,1.4012985e-45,0.82900494,19.600197,17.998749,78.099388,-11.482178