File: raw data/testID_0238.csv
Time(sec),Force(kN),Jaw(mm),PowAngle(deg),Power(W),Pram,PTemp,Strain,Stress(MPa),Stroke(mm),TC1(C),wedge(mm)
0.0,1.0312725,33.652531,0.0,0,11.076097,0.00074825424,9.6158056,0.00087472814,11.076232,22.49999,-9.1286716
1.3,0.9819476,-0.002066426,0.0,0,11.076097,3.8159177,-9.1898379e-05,12.506516,11.075982,22.527664,-9.4893646
2.6,0.95770538,-0.0015159582,0.0,0,11.076097,7.7159162,-0.00011586697,12.194129,11.07579,22.497231,-9.4876938
3.9,0.92914009,-0.0015921779,0.0,0,11.076097,11.615913,-9.4276671e-05,11.844643,11.075814,22.478334,-9.4858541
5.2,0.9126792,-0.0013344071,0.0,0,11.076097,15.515914,-0.00012354089,11.617801,11.075873,22.4839,-9.4842854
6.5,0.88910615,-0.0016524382,0.0,0,11.076097,19.415915,-0.00010911827,11.328114,11.07624,22.544741,-9.480588
7.8,0.87905061,-0.0017540496,0.0,0,11.076097,23.315916,-7.8116864e-05,11.197595,11.075926,22.542936,-9.4785337
9.1,0.86778593,-0.0014075034,24.941761,0,11.076097,27.215914,-0.00011161478,11.047526,11.076504,22.733299,-9.4766083
10.4,0.86788553,-0.0019471123,36.293198,0,11.076097,31.115911,-0.00012052018,11.042461,11.076133,24.252886,-9.4742422
11.7,0.86810094,-0.002745908,42.193993,0,11.076097,35.015907,-0.00022312743,11.046411,11.075835,27.567146,-9.4722099
13.0,0.87079763,-0.0047361413,45.353977,0,11.076097,38.915909,-0.00029652205,11.094478,11.076169,32.197468,-9.4703741
14.3,0.86172521,-0.0069804965,47.254742,0,11.076097,42.815914,-0.00044565654,10.985686,11.075837,37.210598,-9.4679804
15.6,0.85849196,-0.0087858588,48.383175,0,11.076097,46.715919,-0.0005847977,10.938506,11.075887,42.367069,-9.4651909
16.9,0.85797268,-0.010160699,48.812252,0,11.076097,50.615917,-0.00069450017,10.942378,11.07615,47.549866,-9.4625788
18.2,0.86032623,-0.01184689,49.229733,0,11.076097,54.515907,-0.00080924272,10.959915,11.076267,52.411377,-9.4603872
19.5,0.85586363,-0.013374279,49.371017,0,11.076097,58.415901,-0.00085945259,10.908653,11.07625,56.950638,-9.458024
20.8,0.84939247,-0.014243641,49.636227,0,11.076097,62.315895,-0.00094471331,10.838144,11.075973,61.259754,-9.4556332
22.1,0.84457147,-0.015116619,49.636227,0,11.076097,66.215912,-0.0009963183,10.761083,11.075744,65.429771,-9.4533806
23.4,0.83921993,-0.016143706,50.042713,0,11.076097,70.115913,-0.0011127098,10.694297,11.075855,69.398994,-9.4514418
24.7,0.83957475,-0.016817471,50.042721,0,11.076097,74.015907,-0.0011342283,10.702307,11.076378,73.572487,-9.4489927
26.0,0.82686478,-0.018177347,50.042721,0,11.076097,77.915901,-0.0011667922,10.539735,11.07625,77.617226,-9.4465694
27.3,0.83399141,-0.018448018,50.209423,0,11.076097,81.815887,-0.0012392697,10.615107,11.075913,81.439209,-9.4445305
28.6,0.82948333,-0.01983973,50.438187,0,11.076097,85.715897,-0.0013026113,10.576292,11.07592,85.310905,-9.4423161
29.9,0.82735461,-0.020309713,50.438229,0,11.076097,89.615898,-0.0013883924,10.540231,11.076283,89.278694,-9.4400101
31.2,0.81835353,-0.021484932,50.514645,0,11.076097,93.5159,-0.0014327385,10.419023,11.07608,93.206787,-9.4375868
32.5,0.81785309,-0.022530673,50.578285,0,11.076097,97.415901,-0.0014704331,10.428836,11.076215,97.195877,-9.4357624
33.8,0.81100976,-0.023682535,50.810146,0,11.076097,101.3159,-0.001589334,10.340845,11.076076,101.09647,-9.4332466
35.1,0.80985928,-0.024668952,50.448128,0,11.076097,105.2159,-0.0016373134,10.336393,11.076033,105.21227,-9.4308815
36.4,0.81000555,-0.025595246,50.698215,0,11.076097,109.11588,-0.001734913,10.321629,11.075569,109.01521,-9.4288054
37.7,0.80746555,-0.026977682,50.819393,0,11.076097,113.0159,-0.0017749354,10.288991,11.075491,112.94714,-9.4264107
39.0,0.81215811,-0.028357059,50.56715,0,11.076097,116.91589,-0.0018635101,10.367613,11.0759,116.92649,-9.4244709
40.3,0.80730373,-0.029560197,50.817398,0,11.076097,120.8159,-0.0019656615,10.299308,11.075786,120.72177,-9.4217787
41.6,0.81009978,-0.030813176,50.455807,0,11.076097,124.7159,-0.0020813099,10.336997,11.075953,124.78284,-9.4197702
42.9,0.80188864,-0.032134019,50.648754,0,11.076097,128.61601,-0.0021540285,10.240048,11.075741,128.61942,-9.4172258
44.2,0.80292928,-0.033750504,50.442623,0,11.076097,132.51588,-0.0022109102,10.24306,11.075974,132.52896,-9.4148884
45.5,0.79718095,-0.034930691,50.438244,0,11.076097,136.41589,-0.0023361098,10.167657,11.075904,136.51936,-9.4128389
46.8,0.79532439,-0.036198638,50.438236,0,11.076097,140.31587,-0.0023929093,10.150419,11.076117,140.36282,-9.4104805
48.1,0.79962921,-0.037162777,50.444901,0,11.076097,144.21588,-0.0025041588,10.213324,11.076175,144.2366,-9.4083948
49.4,0.78864032,-0.038902774,50.489353,0,11.076097,148.11588,-0.0025923003,10.09035,11.076388,148.08577,-9.4061756
50.7,0.78731638,-0.040568307,50.438236,0,11.076097,152.0159,-0.0026628103,10.05733,11.076111,152.04213,-9.403841
52.0,0.79011822,-0.04156667,50.438236,0,11.076097,155.91589,-0.0027838049,10.104583,11.076134,156.06015,-9.4012594
53.3,0.78833747,-0.043623038,50.411255,0,11.076097,159.8159,-0.0029004174,10.077526,11.076231,159.98598,-9.3993149
54.6,0.78358459,-0.044949081,50.045616,0,11.076097,163.7159,-0.0030180356,9.9998007,11.075864,163.92896,-9.3966961
55.9,0.79007989,-0.046643991,50.042912,0,11.076097,167.61589,-0.0030996231,10.094904,11.075529,167.83276,-9.394825
57.2,0.7823956,-0.048565786,50.069172,0,11.076097,171.51588,-0.003203785,9.9894724,11.075307,171.59143,-9.3928013
58.5,0.77633214,-0.050101236,50.149174,0,11.076097,175.41588,-0.0033344463,9.9220371,11.075563,175.4758,-9.3904257
59.8,0.77823377,-0.051717393,50.042728,0,11.076097,179.31586,-0.0034500046,9.9351587,11.075966,179.46712,-9.387887
61.1,0.77508241,-0.053747632,49.636234,0,11.076097,183.21587,-0.0036028107,9.9033833,11.075919,183.6236,-9.3855591
62.4,0.77944475,-0.055490389,49.658154,0,11.076097,187.11588,-0.0036651404,9.9597607,11.076062,187.37808,-9.3835135
63.7,0.77476192,-0.057102323,49.636234,0,11.076097,191.01587,-0.0037945616,9.905447,11.076171,191.29913,-9.381464
65.0,0.7828514,-0.058695238,49.636234,0,11.076097,194.91586,-0.0038885819,10.010248,11.075747,195.18152,-9.3792706
66.3,0.77924138,-0.06050121,49.636227,0,11.076097,198.81587,-0.0040562646,9.9660835,11.076056,198.88327,-9.3766747
67.6,0.77898592,-0.062513202,49.55476,0,11.076097,202.71587,-0.004164401,9.9699392,11.076267,202.91299,-9.3745718
68.9,0.78031594,-0.064654075,49.22974,0,11.076097,206.61586,-0.0042556338,9.9858303,11.076116,206.79575,-9.3721104
70.2,0.77223271,-0.066633873,49.537079,0,11.076097,210.51587,-0.0044394657,9.8743963,11.076113,210.52867,-9.369668
71.5,0.77880293,-0.068688162,49.619545,0,11.076097,214.41588,-0.0045558512,9.9792461,11.075786,214.33932,-9.3672104
72.8,0.78018302,-0.070372716,49.229733,0,11.076097,218.31587,-0.0047134152,9.979022,11.075909,218.63045,-9.3648376
74.1,0.79543078,-0.073126592,49.220127,0,11.076097,222.21587,-0.0048669493,10.183153,11.076594,222.35106,-9.3631096
75.4,0.8048442,-0.075303353,49.229733,0,11.076097,226.11588,-0.0049770121,10.297173,11.075988,226.21516,-9.3610239
76.7,0.807621,-0.076874644,49.113338,0,11.076097,230.01588,-0.0051199785,10.338454,11.07551,230.22255,-9.3592119
78.0,0.79167223,-0.078947112,48.812504,0,11.076097,233.91588,-0.0052368687,10.12509,11.0762,234.06502,-9.3570557
79.3,0.7864114,-0.081036523,49.150696,0,11.076097,237.81586,-0.0054158922,10.068944,11.076088,237.83871,-9.3548098
80.6,0.78000534,-0.084031768,48.97282,0,11.076097,241.71585,-0.0055712913,10.004315,11.076029,241.75183,-9.3516245
81.9,0.7796312,-0.086465567,48.81226,0,11.076097,245.61586,-0.0057102419,9.9957781,11.075344,245.71275,-9.3492489
83.2,0.79656047,-0.08857625,49.036289,0,11.076097,249.51585,-0.0058918931,10.193792,11.076454,249.45961,-9.347249
84.5,0.81771857,-0.09022744,48.81226,0,11.076097,253.41585,-0.0060075796,10.47602,11.076746,253.55693,-9.3459158
85.8,0.82605028,-0.092531778,48.727955,0,11.076097,257.31613,-0.0061779087,10.577353,11.076612,257.5871,-9.3438015
87.1,0.81049502,-0.0958983,48.702732,0,11.076097,261.21613,-0.0063625537,10.383219,11.076271,261.38272,-9.3413734
88.4,0.80061847,-0.098956883,48.803814,0,11.076097,265.11584,-0.0065488941,10.263705,11.076398,265.12924,-9.3386469
89.7,0.80546373,-0.1011619,48.385563,0,11.076097,269.01584,-0.006727295,10.322653,11.075687,269.14032,-9.3360434
91.0,0.79642081,-0.10331534,48.383793,0,11.076097,272.91586,-0.0068660304,10.201376,11.076059,273.1041,-9.3337984
92.3,0.81533986,-0.10557432,47.974052,0,11.076097,276.81586,-0.0070480364,10.468305,11.076185,277.23306,-9.332056
93.6,0.81167054,-0.10858706,47.970753,0,11.076097,280.71588,-0.0071887425,10.414801,11.076448,281.03668,-9.3300409
94.9,0.82063305,-0.11116572,47.955326,0,11.076097,284.61588,-0.0073754974,10.526423,11.0762,284.92487,-9.3284788
96.2,0.8208071,-0.11363236,47.505287,0,11.076097,288.51587,-0.0075386837,10.532384,11.07551,288.97214,-9.3257742
97.5,0.81911272,-0.11616932,47.633701,0,11.076097,292.41583,-0.0077323401,10.514964,11.076418,292.65607,-9.3232994
98.8,0.81345284,-0.11908062,47.5051,0,11.076097,296.31583,-0.0079228738,10.44922,11.076338,296.45343,-9.3205595
100.1,0.82407886,-0.12183253,47.504887,0,11.076097,300.21582,-0.0080509074,10.575955,11.075768,300.50012,-9.3183298
101.4,0.8316142,-0.12414256,47.47094,0,11.076097,304.11584,-0.00824848,10.680228,11.076286,304.33908,-9.3160028
102.7,0.83551186,-0.1264129,47.054688,0,11.076097,308.01587,-0.008376671,10.732581,11.075668,308.26819,-9.3147707
104.0,0.8331582,-0.12917686,47.267696,0,11.076097,311.91583,-0.0086108614,10.702767,11.07557,311.99307,-9.3124266
105.3,0.84535521,-0.13167909,47.061661,0,11.076097,315.81586,-0.0087434892,10.860227,11.075738,315.91669,-9.3102846
106.6,0.84645718,-0.13476598,47.054447,0,11.076097,319.71585,-0.0089072557,10.878872,11.076573,319.83411,-9.3080835
107.9,0.84857333,-0.13769795,46.896534,0,11.076097,323.61588,-0.0091475034,10.897385,11.076,323.9241,-9.3058605
109.2,0.83105242,-0.14082959,46.949211,0,11.076097,327.51587,-0.0093278866,10.684811,11.076574,327.71695,-9.3030701
110.5,0.8405742,-0.14270739,46.698212,0,11.076097,331.41583,-0.0094915479,10.789025,11.07581,331.56348,-9.3007984
111.8,0.8460719,-0.14457732,47.000252,0,11.076097,335.31586,-0.0095943343,10.873851,11.076088,335.37289,-9.2984829
113.1,0.84683567,-0.14753957,46.891304,0,11.076097,339.21585,-0.0097504286,10.896678,11.075765,339.23724,-9.296896
114.4,0.83885872,-0.14989372,46.760426,0,11.076097,343.11584,-0.0099530453,10.794492,11.076344,343.1485,-9.2946692
115.7,0.85131681,-0.15207091,47.048191,0,11.076097,347.01587,-0.010090147,10.958901,11.075939,346.91116,-9.2923594
117.0,0.855546,-0.15478666,46.583893,0,11.076097,350.91586,-0.010285742,11.009147,11.076526,351.04694,-9.2905254
118.3,0.84967422,-0.15761207,46.59296,0,11.076097,354.81586,-0.010431075,10.921934,11.076053,354.90692,-9.2881985
119.6,0.85623437,-0.16001698,46.628708,0,11.076097,358.71585,-0.010594156,11.020073,11.076527,358.7522,-9.2856827
120.9,0.84609073,-0.16243857,46.799026,0,11.076097,362.61584,-0.010771275,10.896907,11.075909,362.60751,-9.2830629
122.2,0.85462826,-0.16492066,46.684654,0,11.076097,366.51584,-0.010958491,11.017213,11.075929,366.54608,-9.2807016
123.5,0.86062825,-0.16733493,46.582035,0,11.076097,370.41583,-0.011096645,11.08063,11.075891,370.52435,-9.2786589
124.8,0.864555,-0.16996002,46.46735,0,11.076097,374.31586,-0.011223685,11.139161,11.075973,374.55646,-9.2766466
126.1,0.87191045,-0.17202011,46.58091,0,11.076097,378.21585,-0.011412538,11.230774,11.075912,378.23618,-9.2749577
127.4,0.86539042,-0.17483602,46.346066,0,11.076097,382.11584,-0.011572857,11.158037,11.07608,382.2182,-9.2725086
128.7,0.87223357,-0.1769844,46.138241,0,11.076097,386.01584,-0.01176451,11.253471,11.076881,386.15237,-9.2708406
130.0,0.87327456,-0.17988938,46.292469,0,11.076097,389.91586,-0.01191003,11.255758,11.075641,389.97839,-9.2686167
131.3,0.85613364,-0.1825425,46.319,0,11.076097,393.81583,-0.012061585,11.034844,11.07589,393.85638,-9.2659111
132.6,0.8561992,-0.18484658,46.111588,0,11.076097,397.71582,-0.01224901,11.034472,11.076144,397.81833,-9.2633867
133.9,0.84921134,-0.18737572,46.109707,0,11.076097,401.61584,-0.012425363,10.944662,11.075951,401.80038,-9.2607107
135.2,0.85329717,-0.18973976,46.109623,0,11.076097,405.51584,-0.012596194,11.014951,11.075624,405.68118,-9.2589874
136.5,0.86902964,-0.19202693,46.022896,0,11.076097,409.41583,-0.012696107,11.203491,11.076764,409.56326,-9.2573528
137.8,0.8590225,-0.19436423,46.109486,0,11.076097,413.31586,-0.012859746,11.08334,11.075562,413.40253,-9.2552032
139.1,0.86003107,-0.19647904,45.664917,0,11.076097,417.21585,-0.013005277,11.092399,11.076022,417.39905,-9.2530279
140.4,0.85604179,-0.19835453,45.639565,0,11.076097,421.11581,-0.013162715,11.032697,11.076259,421.27029,-9.2510071
141.7,0.83605647,-0.20095538,45.724571,0,11.076097,425.01584,-0.013315852,10.790337,11.076258,425.07333,-9.2485981
143.0,0.82815665,-0.20353645,45.771908,0,11.076097,428.91583,-0.013426,10.675595,11.075487,428.90048,-9.2455549
144.3,0.82342345,-0.2054061,45.773335,0,11.076097,432.81583,-0.013603174,10.622928,11.076059,432.80063,-9.2432423
145.6,0.82548028,-0.20723607,46.065357,0,11.076097,436.71582,-0.013705421,10.644837,11.075816,436.66327,-9.2413101
146.9,0.8245042,-0.20916408,45.77504,0,11.076097,440.61584,-0.013883212,10.640656,11.076734,440.62552,-9.2395639
148.2,0.81722778,-0.21091925,45.622021,0,11.076097,444.51584,-0.013968886,10.552717,11.076218,444.5791,-9.2375479
149.5,0.81559449,-0.2127969,45.615524,0,11.076097,448.41583,-0.014047263,10.515743,11.075742,448.53461,-9.2357359
150.8,0.80937743,-0.21398811,45.234962,0,11.076097,452.31583,-0.014190091,10.440048,11.075994,452.64301,-9.2336388
152.1,0.80265826,-0.21570833,45.28875,0,11.076097,456.21582,-0.014268477,10.380137,11.076486,456.43954,-9.2313833
153.4,0.78567457,-0.21722306,45.232903,0,11.076097,460.11581,-0.014413225,10.143808,11.076663,460.32959,-9.2283583
154.7,0.77589494,-0.21831927,45.127003,0,11.076097,464.01581,-0.014440075,10.028747,11.07548,464.13141,-9.22579
156.0,0.77781802,-0.21931012,45.280773,0,11.076097,467.91583,-0.014483141,10.041398,11.07658,467.96304,-9.2237549
157.3,0.75922132,-0.22018044,45.120853,0,11.076097,471.81583,-0.014572121,9.8120842,11.075603,471.87555,-9.2221537
158.6,0.75241613,-0.22075683,45.254105,0,11.076097,475.71582,-0.014617885,9.7229147,11.076159,475.70639,-9.2199621
159.9,0.74975145,-0.22155286,45.121025,0,11.076097,479.61581,-0.014690048,9.6894855,11.076146,479.6814,-9.2178621
161.2,0.7381289,-0.22197713,45.41534,0,11.076097,483.51584,-0.014668862,9.5405302,11.076273,483.46652,-9.2158442
162.5,0.73834813,-0.22170231,45.13126,0,11.076097,487.4158,-0.014647825,9.5531387,11.07534,487.45602,-9.2136698
163.8,0.73676515,-0.22229889,45.322056,0,11.076097,491.3158,-0.014706795,9.5123119,11.075592,491.29797,-9.2111835
165.1,0.73345208,-0.22070095,45.481487,0,11.076097,495.21579,-0.014623025,9.4629259,11.075793,495.11105,-9.2087927
166.4,0.71235025,-0.21933182,45.146698,0,11.076097,499.11581,-0.014535189,9.2113037,11.076711,499.11301,-9.2066565
167.7,0.24408376,-0.23243299,44.604488,0,11.076097,499.99884,-0.015348393,3.1586316,11.076403,500.42386,-9.2060318
169.0,0.25346121,-0.2330395,44.604496,0,11.076097,499.99884,-0.015411174,3.2791383,11.076846,500.40741,-9.2065668
170.3,0.25536281,-0.2337576,44.371284,0,11.076097,499.99884,-0.015453774,3.3180256,11.076012,500.29849,-9.2061825
171.6,0.25968045,-0.23490389,44.077152,0,11.076097,499.99884,-0.015577239,3.3623848,11.075991,500.53992,-9.2066898
172.9,0.25885764,-0.23655081,43.614853,0,11.076097,499.99884,-0.015662393,3.346972,11.076313,500.39044,-9.2065153
174.2,0.25769806,-0.23721364,43.479191,0,11.076097,499.99884,-0.015640067,3.3173001,11.076307,500.50177,-9.206008
175.5,0.25293669,-0.23771018,42.997429,0,11.076097,499.99884,-0.015727295,3.2741735,11.075772,500.50366,-9.2056637
176.8,0.25677606,-0.23831223,42.978519,0,11.076097,499.99884,-0.015748037,3.3195581,11.076196,500.38712,-9.2054272
178.1,0.26097813,-0.23873475,42.545078,0,11.076097,499.99884,-0.015830012,3.3817356,11.075955,500.4903,-9.2056293
179.4,0.27555811,-0.23945796,42.470375,0,11.076097,499.99884,-0.015836168,3.5710447,11.0766,500.35498,-9.206399
180.7,0.27932346,-0.23996338,42.396366,0,11.076097,499.99884,-0.015834471,3.6262002,11.075728,500.34207,-9.2061701
182.0,0.27688286,-0.24173279,42.325893,0,11.076097,499.99884,-0.015994083,3.5989349,11.075445,500.38412,-9.2064219
183.3,0.27040794,-0.24180888,41.91946,0,11.076097,499.99884,-0.015987141,3.493331,11.075667,500.35468,-9.2062578
184.6,0.26220667,-0.24233234,41.847721,0,11.076097,499.99884,-0.01605558,3.3978562,11.074952,500.20483,-9.2061768
185.9,0.27245784,-0.24303074,41.802982,0,11.076097,499.99884,-0.016061991,3.5362034,11.076383,500.25974,-9.206563
187.2,0.27664539,-0.24336793,41.802982,0,11.076097,499.99884,-0.016062021,3.5810342,11.076098,500.11386,-9.2060423
188.5,0.2821143,-0.24518538,41.802982,0,11.076097,499.99884,-0.016222365,3.6513929,11.074991,500.1658,-9.2055635
189.8,0.27583727,-0.24469839,41.78566,0,11.076097,499.99884,-0.016197115,3.578877,11.075943,500.16101,-9.2059317
191.1,0.27737057,-0.24505883,41.485954,0,11.076097,499.99884,-0.016222117,3.5981696,11.076106,500.21588,-9.206172
192.4,0.27587736,-0.2458511,41.611134,0,11.076097,499.99884,-0.016224561,3.5655947,11.075709,500.09964,-9.2058458
193.7,0.28236797,-0.24600194,41.449116,0,11.076097,499.99884,-0.016256265,3.6652739,11.075994,500.0614,-9.2058458
195.0,0.28307056,-0.24761768,41.198734,0,11.076097,499.99884,-0.016360097,3.6758106,11.075798,500.15018,-9.2054901
196.3,0.27593431,-0.24743406,41.156929,0,11.076097,499.99884,-0.016381117,3.5700498,11.075995,500.29443,-9.2061939
197.6,0.28643319,-0.24749422,40.572731,0,11.076097,499.99884,-0.016380226,3.7044308,11.075859,500.2504,-9.2064791
198.9,0.28948522,-0.24805494,40.727955,0,11.076097,499.99884,-0.016367104,3.7562833,11.075898,500.16873,-9.2062979
200.2,0.27929801,-0.24941474,41.041267,0,11.076097,499.99884,-0.016497806,3.6093934,11.075732,500.04538,-9.2060242
201.5,0.26701134,-0.24925753,40.677914,0,11.076097,499.99884,-0.016470119,3.4475949,11.07541,500.04431,-9.2051382
202.8,0.27489576,-0.24947724,40.606213,0,11.076097,499.99884,-0.016531769,3.5630016,11.076407,500.03943,-9.2051888
204.1,0.29137143,-0.24940622,40.572514,0,11.076097,499.99884,-0.016500274,3.7679074,11.075197,500.13641,-9.2054987
205.4,0.29073632,-0.2502664,40.666702,0,11.076097,499.99884,-0.016514435,3.7641332,11.076686,500.03094,-9.2058716
206.7,0.29132405,-0.25054574,40.572514,0,11.076097,499.99884,-0.01658603,3.7461233,11.076198,500.13925,-9.2057991
208.0,0.29132533,-0.25051123,40.572514,0,11.076097,499.99884,-0.016547032,3.7652097,11.075615,500.202,-9.2062502
209.3,0.28557405,-0.25079343,40.215164,0,11.076097,499.99884,-0.016616985,3.7171185,11.074753,500.25156,-9.2060986
210.6,0.29790184,-0.2525335,40.41684,0,11.076097,499.99884,-0.016702639,3.8596053,11.075215,500.12262,-9.2067823
211.8967,0.33092916,0.008561831,40.31469,0,11.076097,499.99884,0.00061053853,4.1961932,11.075958,500.06143,-9.2107248
211.9492,0.37393045,0.011714999,34.346039,0,11.076099,8.225476e-14,0.00079019181,4.7010098,11.075184,500.02185,-9.2114859
211.9518,0.36657387,0.016750455,23.986439,0,11.076099,1.5390809e-31,0.00084047479,4.6194739,11.074961,500.01413,-9.2096577
211.9544,0.38664174,0.011944599,13.626836,0,11.076099,0.0,0.00062925724,4.9330463,11.075009,500.00638,-9.21138
211.957,0.36968368,0.013058285,3.2672338,0,11.076099,0.0,0.00082364713,4.6003213,11.075679,499.99863,-9.2104549
211.9596,0.36964285,0.0095994091,0.0,0,11.076099,0.0,0.00076617266,4.780798,11.075187,500.03329,-9.2118702
211.9622,0.38171074,0.010563178,0.0,0,11.076099,0.0,0.00085445959,4.8611135,11.075122,500.08752,-9.2088146
211.9648,0.36375648,0.012965725,0.0,0,11.076099,0.0,0.0010346239,4.630239,11.075159,500.14172,-9.2091122
211.9674,0.37902936,0.011539713,0.0,0,11.076099,0.0,0.00075693912,4.8585405,11.076672,500.19592,-9.2098894
211.97,0.39018366,0.015407653,0.0,0,11.076099,0.0,0.00074700551,4.8917041,11.077358,500.19223,-9.2104092
211.9726,0.38712257,0.010552245,0.0,0,11.076099,0.0,0.00055615767,4.8637624,11.076748,500.17676,-9.2115707
211.9752,0.38491476,0.011532621,0.0,0,11.076099,0.0,0.00078653067,4.8758979,11.077236,500.16125,-9.2107744
211.9778,0.39805791,0.0088982014,0.0,0,11.076099,0.0,0.00080910878,5.0210185,11.075322,500.14578,-9.2102547
211.9804,0.3861872,0.010479049,0.0,0,11.076099,0.0,0.00090905331,4.9482846,11.07515,500.15298,-9.2095928
211.983,0.37965995,0.014196162,0.0,0,11.076099,0.0,0.0010266324,4.8181057,11.074898,500.16074,-9.2115259
211.9856,0.38325897,0.011746438,0.0,0,11.076099,0.0,0.00071208604,4.8937721,11.078182,500.16846,-9.2107878
211.9882,0.39005351,0.016879626,0.0,0,11.076099,0.0,0.000822092,4.9919262,11.074088,500.17337,-9.2115612
211.9908,0.38242659,0.010615196,0.0,0,11.076099,0.0,0.0006213786,4.885241,11.074769,500.15787,-9.2118778
211.9934,0.40672708,0.011747237,0.0,0,11.076099,0.0,0.00083766336,5.182076,11.078401,500.14236,-9.2108765
211.996,0.39287719,0.0091666039,0.0,0,11.076099,0.0,0.00088048517,4.9259834,11.075451,500.12689,-9.210207
211.9986,0.3939659,0.011546609,0.0,0,10.826062,0.0,0.00088585267,4.9585748,11.077371,500.11557,-9.2115822
212.0012,0.4161281,0.014242856,0.0,0,10.435007,0.0,0.0010542925,5.261138,11.074155,500.11557,-9.2108803
212.0038,0.39916295,0.013561153,0.0,0,10.043953,0.0,0.00081372767,5.0532303,10.999119,500.11557,-9.2109461
212.0064,0.39391416,0.016738364,0.0,0,9.6528978,0.0,0.00085981446,5.0779519,10.757249,500.11557,-9.2109585
212.009,0.42980266,0.01179166,0.0,0,9.2678175,0.0,0.00067913043,5.5215573,10.367911,500.13486,-9.2103596
212.0116,1.7593372,0.059847001,0.0,0,8.8873854,0.0,0.0035562951,20.021589,9.8674698,500.18134,-9.2106867
212.0142,4.2575178,0.70355505,0.0,0,8.518857,0.0,0.048117731,51.768105,9.219841,500.22778,-9.208375
212.0168,4.1756592,1.1839589,0.0,0,8.1570406,0.0,0.081755057,48.908333,8.7059259,500.27426,-9.2085257
212.0194,4.418581,1.5535452,0.0,0,7.8078156,0.0,0.10895883,50.577549,8.3200073,500.2207,-9.2069597
212.022,4.4656763,1.8355862,0.0,0,7.4635754,0.0,0.13009144,49.82814,7.9907956,500.08905,-9.2070045
212.0246,4.4871373,2.1206756,0.0,0,7.132699,0.0,0.15182376,49.079685,7.7117167,499.9574,-9.208457
212.0272,4.7449956,2.3918617,0.0,0,6.8053074,0.0,0.17318511,50.847759,7.4442091,499.82574,-9.2076874
212.0298,4.8925433,2.6695883,0.0,0,6.4917617,0.0,0.19572486,51.132957,7.160233,499.22824,-9.2083502
212.0324,5.1229267,2.9800353,0.0,0,6.1802816,0.0,0.22143242,52.278515,6.8500133,498.43832,-9.2079544
212.035,5.3718514,3.2984831,0.0,0,5.8832316,0.0,0.24808198,53.347412,6.5250783,497.64844,-9.2077303
212.0376,5.519712,3.633194,0.0,0,5.5874414,0.0,0.27683455,53.213345,6.1947641,496.85852,-9.2075233
212.0402,5.7541909,3.9560406,0.0,0,5.3054934,0.0,0.30544713,53.981964,5.8649769,495.7446,-9.2069902
212.0428,5.9637084,4.2769232,0.0,0,5.0250483,0.0,0.33474699,54.24155,5.5466075,494.57523,-9.2070494
212.0454,6.1242151,4.5741029,0.0,0,4.7569838,0.0,0.36328956,54.196404,5.2402434,493.40585,-9.2068577
212.048,6.3329768,4.8624063,0.0,0,4.4912457,0.0,0.3915678,54.485126,4.9456487,492.23648,-9.2070045
212.0506,6.5067496,5.1412253,0.0,0,4.236237,0.0,0.41972625,54.393768,4.6709929,491.08994,-9.2083721
212.0532,6.6850166,5.4064755,0.0,0,3.9844091,0.0,0.4467687,54.426243,4.4033909,489.94336,-9.2084827
212.0558,6.8639174,5.6625423,0.0,0,3.7418811,0.0,0.47332433,54.421001,4.1524711,488.79681,-9.2072744
212.0584,7.0722647,5.9051232,0.0,0,3.5032687,0.0,0.49952164,54.616081,3.9052658,487.61734,-9.2075367
212.061,7.2568388,6.1511931,0.0,0,3.2725446,0.0,0.52682835,54.542934,3.6611686,486.24557,-9.2069855
212.0636,7.4506531,6.384129,0.0,0,3.0464103,0.0,0.55393153,54.47665,3.4250309,484.87384,-9.2070246
212.0662,7.6987333,6.6170988,0.0,0,2.8269181,0.0,0.58183306,54.782421,3.1902044,483.50208,-9.206871
212.0688,7.9232411,6.852994,0.0,0,2.6126273,0.0,0.61054772,54.742443,2.9584916,481.25903,-9.2057104
212.0714,8.1561356,7.084188,0.0,0,2.4038472,0.0,0.63902301,54.79916,2.7343006,476.90662,-9.2068005
212.074,8.4415531,7.3128886,0.0,0,2.2008002,0.0,0.66757965,55.058025,2.5101686,472.5542,-9.2068062
212.0766,8.6829557,7.5266495,0.0,0,2.002212,0.0,0.6956107,55.148598,2.2918832,468.20178,-9.2069826
212.0792,8.9267359,7.7379251,0.0,0,1.8098083,0.0,0.72443336,55.050297,2.0843229,465.16614,-9.205431
212.0818,9.2339087,7.9334803,0.0,0,1.6208922,0.0,0.7523253,55.367233,1.8879938,463.81686,-9.2067881
212.0844,9.4885311,8.1268826,0.0,0,1.4385692,0.0,0.78055745,55.309883,1.6940615,462.46759,-9.2069244
212.087,9.7864237,8.3220119,0.0,0,1.2588573,0.0,0.80961162,55.444431,1.5059959,461.11832,-9.2056103
212.0896,10.121801,8.5115652,0.0,0,1.0861163,0.0,0.83777606,55.74464,1.3170025,459.89923,-9.2048426
212.0922,10.466822,8.6985903,0.0,0,0.91519231,0.0,0.86613464,56.04137,1.1323127,458.77261,-9.2060137
212.0948,10.762729,8.8735971,0.0,0,0.75155324,0.0,0.89406735,56.033329,0.95002109,457.64603,-9.205472
212.0974,11.151227,9.0486031,0.0,0,0.58900124,0.0,0.92327625,56.361797,0.77952754,456.51941,-9.2060156
212.1,11.491815,9.2146378,0.0,0,0.43388578,0.0,0.9525705,56.457848,0.60639828,456.03464,-9.2052431
212.1026,9.7317934,9.2782574,0.0,0,0.27942529,0.0,0.9649604,47.356487,0.48579955,455.78635,-9.2063894
212.1052,8.5981684,9.29531,0.0,0,0.13226004,0.0,0.96747565,41.603874,0.43287456,455.53806,-9.2084522
212.1078,8.0354509,9.3016109,0.0,0,-0.014479335,0.0,0.96792859,38.905926,0.39220092,455.28976,-9.2082033
212.1104,7.7732339,9.3118649,0.0,0,-0.15794852,0.0,0.96868968,37.585461,0.35701984,458.60242,-9.2091045
212.113,7.7246151,9.3109932,0.0,0,-0.30141655,0.0,0.96859074,37.315022,0.31791854,462.41486,-9.2094021
212.1156,7.9902992,9.3178635,0.0,0,-0.44488451,0.0,0.97018707,38.551357,0.25143698,466.22726,-9.2104034
212.1182,8.1913719,9.3220224,0.0,0,-0.5883525,0.0,0.97177327,39.453804,0.17661807,469.96301,-9.2087364
212.1208,8.1710253,9.3264418,0.0,0,-0.73182052,0.0,0.97314221,39.307617,0.10902872,470.45181,-9.2073946
212.1234,8.0083437,9.336977,0.0,0,-0.87528849,0.0,0.97487146,38.457359,0.050815184,470.94064,-9.2073526
212.126,7.7723384,9.3431664,0.0,0,-1.0187565,0.0,0.97514725,37.362537,0.012238334,471.42947,-9.2084274
212.1286,7.3673186,9.3516264,2.3562253,0,-0.91974235,499.99997,0.97557187,35.414135,-0.0053007402,471.81851,-9.2092733
212.1312,6.9020653,9.3439617,16.279257,0,-0.42304912,500.0,0.97447848,33.188137,-0.0010804984,471.71762,-9.2089481
212.1338,6.561933,9.3413134,30.202291,0,0.073644437,500.0,0.97477883,31.492889,0.0011629108,471.61676,-9.2081575
212.1364,6.2924676,9.3378582,44.12532,0,0.57033831,500.0,0.97495717,30.249125,0.0043994598,471.5159,-9.2084637
212.139,6.0973687,9.3392706,53.657227,0,1.0670315,500.0,0.9754144,29.29937,0.006279204,471.46887,-9.2086716
212.1416,5.7665815,9.3436308,53.657227,0,1.5637254,500.0,0.97604793,27.686049,0.013576527,471.5387,-9.209341
212.1442,4.4354215,9.320672,53.657227,0,2.0604191,500.0,0.97113413,21.471252,0.08838284,471.60852,-9.2102375
212.1468,2.4187274,9.3305044,53.657227,0,2.5571125,500.0,0.97184116,11.868031,0.2431262,471.67834,-9.2114668
212.1494,-0.15973304,9.2840414,53.657227,0,3.0538061,500.0,0.96420133,-0.53112239,0.51463801,471.69446,-9.2131958
212.152,-0.33808106,9.2573128,53.657227,0,3.5504997,500.0,0.96027368,-1.9483849,1.1447659,471.64792,-9.2149792
212.1546,-0.099573135,9.2631636,53.657227,0,4.0471931,500.0,0.96187931,-0.23174889,1.9702852,471.60138,-9.2125139
212.1572,-0.18033929,9.2853537,53.657227,0,4.5438867,500.0,0.96633911,-1.1262484,2.759903,471.55481,-9.213995
212.1598,-0.07077425,9.2951231,53.657227,0,5.0405807,500.0,0.9671852,-0.24763224,3.3873868,471.62613,-9.2124338
212.1624,-0.10240486,9.2862101,53.657227,0,5.5372739,500.0,0.96476597,-0.46784726,3.8688605,471.77356,-9.2133303
212.165,-0.032359675,9.2906075,53.657227,0,6.0339675,500.0,0.96472651,-0.1312072,4.3127484,471.92096,-9.2122459
212.1676,-0.19093446,9.2881565,53.657227,0,6.5306616,500.0,0.96483576,-0.91255963,4.7648849,472.06839,-9.2117176
212.1702,-0.034178909,9.282939,53.590607,0,7.0273547,500.0,0.96475136,-0.16733958,5.2506256,472.12222,-9.2114477
212.1728,-0.033871707,9.2821989,53.502235,0,7.5240488,500.0,0.96536219,-0.14771043,5.7553377,472.14551,-9.2112226
212.1754,-0.11912931,9.2872,53.413864,0,8.0207424,500.0,0.96627867,-0.57473481,6.2817707,472.16879,-9.2120094
212.178,-0.18196724,9.2913704,53.325489,0,8.5174351,500.0,0.96632797,-0.8585912,6.8131618,472.19208,-9.2110224
212.1806,-0.10325932,9.2878551,53.31665,0,9.0141287,500.0,0.96488285,-0.48479611,7.3381724,472.22931,-9.2100525
212.1832,-0.29430863,9.285923,53.31665,0,9.5108232,500.0,0.96379572,-1.3802149,7.8501372,472.26813,-9.2098103
212.1858,-0.078763515,9.2858496,53.31665,0,10.007517,500.0,0.96447664,-0.45081985,8.355834,472.30692,-9.211297
212.1884,-0.063751645,9.283227,53.31665,0,10.50421,500.0,0.96494859,-0.24713726,8.8724318,472.34644,-9.2107811
212.191,-0.2441012,9.2833643,53.31665,0,11.000903,500.0,0.96570832,-1.203968,9.3802691,472.40076,-9.2112608
212.1936,0.023387169,9.2784843,53.31665,0,11.497598,500.0,0.96465141,0.14502411,9.8977728,472.45505,-9.2121716
212.1962,-0.25034183,9.2966881,53.31665,0,11.99429,500.0,0.96706593,-1.22111,10.397614,472.50937,-9.2108364
212.1988,-0.12220995,9.2864256,53.31665,0,12.490984,500.0,0.96455091,-0.64443737,10.915097,472.56516,-9.2109289
212.2014,-0.22465166,9.2887087,53.31665,0,12.987678,500.0,0.96434051,-1.081733,11.424063,472.62723,-9.2115135
212.204,-0.14380373,9.2681885,53.31665,0,13.484371,500.0,0.96181226,-0.76091444,11.924886,472.6893,-9.2117519
212.2066,-0.16789412,9.2826004,53.31665,0,13.981066,500.0,0.96491969,-0.75657213,12.419528,472.75137,-9.2107725
212.2092,-0.17229703,9.2803001,53.31665,0,14.477758,500.0,0.96524328,-0.85692638,12.917561,472.81345,-9.2109909
212.2118,-0.11263172,9.2807989,53.31665,0,14.974452,500.0,0.9648996,-0.56067282,13.434661,472.87555,-9.2101345
212.2144,-0.16030595,9.2847519,53.31665,0,15.471146,500.0,0.96461308,-0.79813075,13.945579,472.93762,-9.2096491
212.217,-0.16169325,9.2901096,53.31665,0,15.967839,500.0,0.9651792,-0.72630501,14.455826,472.99969,-9.2102652
212.2196,-0.16836232,9.2892141,53.31665,0,16.464533,500.0,0.96474928,-0.82949716,14.956765,473.04297,-9.2101898
212.2222,-0.12599979,9.2781324,53.31665,0,16.961227,500.0,0.96376777,-0.58289474,15.460423,473.06625,-9.2090425
212.2248,-0.19517183,9.2736063,53.31665,0,17.45792,500.0,0.9635464,-0.94159484,15.951748,473.08951,-9.2093687
212.2274,-0.094342597,9.2825632,53.31665,0,17.954613,500.0,0.96563423,-0.46904323,16.445642,473.11279,-9.2087145
212.23,-0.22428817,9.2842264,53.260906,0,18.0,500.0,0.96532786,-1.031193,16.938841,473.15564,-9.2092981
212.2326,-0.12050721,9.2890282,53.172535,0,18.0,500.0,0.96509898,-0.70508021,17.419689,473.20996,-9.2100267
212.2352,-0.18092202,9.2885742,53.084164,0,18.0,500.0,0.96470684,-0.89191222,17.8297,473.26428,-9.2099953
212.2378,-0.041928325,9.2925911,52.995789,0,18.0,500.0,0.96543086,-0.19691168,18.185286,473.31857,-9.2111712
212.2404,-0.0097313169,9.2866449,52.976074,0,18.0,500.0,0.96514273,-0.089451671,18.427343,473.32465,-9.2140169
212.243,0.043122984,9.2875452,52.976074,0,18.0,500.0,0.96627593,0.17438494,18.526026,473.31689,-9.2198992
212.2456,0.51186293,9.3005075,52.976074,0,18.0,500.0,0.96884,2.4565046,18.484293,473.30914,-9.2270956
212.2482,0.65831071,9.3080845,52.976074,0,18.0,500.0,0.96926194,3.1593251,18.349089,473.30139,-9.241024
212.2508,0.51578432,9.3163671,53.057652,0,18.0,500.0,0.96967453,2.4709215,18.205549,473.27216,-9.2599802
212.2534,0.72523558,9.3144302,53.146023,0,18.0,500.0,0.96934992,3.4916022,18.100935,473.24112,-9.2810564
212.256,0.41709295,9.3218651,53.234394,0,18.0,500.0,0.97053385,2.0181434,18.05669,473.21008,-9.3059816
212.2586,0.48390234,9.3109226,53.31665,0,18.0,500.0,0.9696697,2.3182561,18.055975,473.18228,-9.3311672
212.2612,0.50424391,9.3035069,53.31665,0,18.0,500.0,0.96931612,2.4387722,18.071857,473.19781,-9.3543224
212.2638,0.41404569,9.2985477,53.31665,0,18.0,500.0,0.9684099,2.0482607,18.097046,473.21332,-9.3767233
212.2664,0.53645056,9.311058,53.31665,0,18.0,500.0,0.96990764,2.5557613,18.126728,473.22882,-9.3977709
212.269,0.53826499,9.3140688,53.31665,0,18.0,500.0,0.96908224,2.6005969,18.140507,473.24432,-9.4138947
212.2716,0.51732069,9.310792,53.31665,0,18.0,500.0,0.96851903,2.5164566,18.14616,473.25986,-9.4346056
212.2742,0.6000067,9.3052015,53.31665,0,18.0,500.0,0.96797514,2.9403377,18.145998,473.27536,-9.4532728
212.2768,0.51013756,9.312315,53.31665,0,18.0,500.0,0.97011679,2.4159794,18.143354,473.29086,-9.4720726
212.2794,0.51813859,9.3044701,53.31665,0,18.0,500.0,0.96930248,2.5550139,18.143379,473.28397,-9.4923077
212.282,0.52340847,9.3078461,53.31665,0,18.0,500.0,0.96985549,2.5252047,18.140585,473.2374,-9.5119057
212.2846,0.51219141,9.2962151,53.31665,0,18.0,500.0,0.96697921,2.4422011,18.138216,473.19086,-9.5316782
212.2872,0.58268857,9.3160667,53.31665,0,18.0,500.0,0.96957242,2.8055985,18.135801,473.14432,-9.550437
212.2898,0.51638162,9.3117437,53.403492,0,18.0,500.0,0.96873784,2.5400796,18.133801,473.08594,-9.5714655
212.2924,0.53791356,9.3124027,53.574532,0,18.0,500.0,0.96936399,2.6792672,18.12763,473.01611,-9.5894203
212.295,0.52118087,9.3019753,53.745579,0,18.0,500.0,0.96823221,2.5721233,18.126738,472.94626,-9.608861
212.2976,0.51974893,9.3110533,53.916622,0,18.0,500.0,0.97058374,2.4897633,18.125586,472.87643,-9.6311331
212.3002,0.55037785,9.3108177,53.97583,0,18.0,500.0,0.97015858,2.6494994,18.122808,472.81674,-9.6517143
212.3028,0.52202356,9.3061657,53.97583,0,18.0,500.0,0.96841037,2.6644287,18.122061,472.76245,-9.6690912
212.3054,0.53612441,9.310565,53.97583,0,18.0,500.0,0.96821779,2.6051023,18.12159,472.70813,-9.6898918
212.308,0.59409004,9.3059101,53.97583,0,18.0,500.0,0.96784639,2.8402071,18.117775,472.65381,-9.7095919
212.3106,0.55356193,9.3061123,54.044247,0,18.0,500.0,0.96853346,2.7109854,18.114582,472.5871,-9.7296057
212.3132,0.71460611,9.308897,54.129772,0,18.0,500.0,0.96982384,3.4334648,18.113016,472.51724,-9.7488108
212.3158,0.47514269,9.3096733,54.215294,0,18.0,500.0,0.97025263,2.2875714,18.11236,472.44742,-9.7695208
212.3184,0.57180637,9.3097467,54.300816,0,18.0,500.0,0.96989852,2.7828033,18.109711,472.37759,-9.7887039
212.321,0.52304149,9.3082724,54.30542,0,18.0,500.0,0.96864742,2.5622928,18.109974,472.26373,-9.8085871
212.3236,0.44183469,9.3055754,54.30542,0,18.0,500.0,0.96749294,2.1338837,18.118134,472.14734,-9.8286896
212.3262,0.62077016,9.3084135,54.30542,0,18.0,500.0,0.96817857,2.99106,18.110569,472.03094,-9.8476458
212.3288,0.56397194,9.305932,54.320419,0,18.0,500.0,0.96873695,2.7783761,18.109552,471.91812,-9.8681517
212.3314,0.55361509,9.3031321,54.482914,0,18.0,500.0,0.96905333,2.6559119,18.109707,471.84055,-9.8873634
212.334,0.70076609,9.302372,54.645405,0,18.0,500.0,0.96902221,3.3835847,18.109011,471.76297,-9.9072351
212.3366,0.48125911,9.3227787,54.807896,0,18.0,500.0,0.97197288,2.3474739,18.105288,471.68536,-9.9265137
212.3392,0.54945314,9.3124781,54.931641,0,18.0,500.0,0.96938723,2.6254463,18.102325,471.61517,-9.9469709
212.3418,0.58372265,9.3130207,54.931641,0,18.0,500.0,0.96854931,2.81529,18.105747,471.5686,-9.9667454
212.3444,0.49306816,9.2952156,54.931641,0,18.0,500.0,0.96603364,2.3971632,18.103254,471.52206,-9.9865913
212.347,0.61465573,9.3093328,54.931641,0,18.0,500.0,0.96956134,2.9523113,18.107512,471.47549,-10.005458
212.3496,0.57904845,9.3032379,54.991943,0,18.0,500.0,0.9690904,2.8313947,18.103361,471.41104,-10.023045
212.3522,0.5894469,9.3062162,55.148735,0,18.0,500.0,0.96967411,2.8750138,18.096918,471.31793,-10.044465
212.3548,0.56326628,9.3069315,55.305527,0,18.0,500.0,0.96897781,2.7268806,18.096766,471.22482,-10.06516
212.3574,0.58236223,9.3165789,55.462318,0,18.0,500.0,0.96992999,2.8008647,18.097679,471.13171,-10.084276
212.36,0.57004803,9.3165512,55.535889,0,18.0,500.0,0.96925485,2.7566471,18.095772,471.03036,-10.103088
212.3626,0.64551073,9.3064938,55.535889,0,18.0,500.0,0.96834809,3.0922329,18.093647,470.92172,-10.124583
212.3652,0.60237628,9.2984943,55.535889,0,18.0,500.0,0.96756637,2.8675942,18.094631,470.81311,-10.143558
212.3678,0.64208424,9.3070402,55.535889,0,18.0,500.0,0.96985799,3.096091,18.092449,470.70447,-10.16499
212.3704,0.55709136,9.3067322,55.589924,0,18.0,500.0,0.96954006,2.7103543,18.091839,470.6116,-10.183531
212.373,0.75073302,9.3131104,55.669743,0,18.0,500.0,0.96980721,3.5064647,18.091709,470.52625,-10.201741
212.3756,0.53433591,9.313303,55.749565,0,18.0,500.0,0.96912378,2.612484,18.090479,470.44089,-10.221032
212.3782,0.5841893,9.3172007,55.829388,0,18.0,500.0,0.96945536,2.8001015,18.08939,470.35556,-10.242113
212.3808,0.59815741,9.3048859,55.84351,0,18.0,500.0,0.96808684,2.8734181,18.090467,470.26382,-10.260785
212.3834,0.47130087,9.300292,55.84351,0,18.0,500.0,0.96826971,2.3083191,18.090658,470.17072,-10.279795
212.386,0.61981499,9.3081312,55.84351,0,18.0,500.0,0.97016978,2.9828284,18.091778,470.07761,-10.299103
212.3886,0.6291278,9.3076057,55.84351,0,18.0,500.0,0.96945953,2.9916837,18.086767,469.9845,-10.319265
212.3912,0.60630667,9.3121662,55.989948,0,18.0,500.0,0.96922332,2.941509,18.087584,469.88385,-10.339647
212.3938,0.73468941,9.3108959,56.141037,0,18.0,500.0,0.96868813,3.5683048,18.084995,469.78299,-10.360693
212.3964,0.51413018,9.3221235,56.292126,0,18.0,500.0,0.97068286,2.4381087,18.084101,469.68213,-10.380948
212.399,0.60926777,9.3092604,56.425781,0,18.0,500.0,0.96903205,2.9575682,18.088558,469.58395,-10.39922
212.4016,0.58527756,9.3075628,56.425781,0,18.0,500.0,0.9697293,2.8408237,18.082632,469.50635,-10.419168
212.4042,0.52412927,9.2981987,56.425781,0,18.0,500.0,0.9684909,2.5277843,18.080717,469.42877,-10.44035
212.4068,0.67344213,9.314311,56.425781,0,18.0,500.0,0.97027117,3.2543285,18.082701,469.35117,-10.458282
212.4094,0.61136854,9.315093,56.463806,0,18.0,500.0,0.96972793,2.9586699,18.07984,469.26953,-10.478609
212.412,0.61257946,9.3120499,56.609196,0,18.0,500.0,0.96898454,2.9423721,18.075697,469.17642,-10.499489
212.4146,0.68384659,9.3039656,56.754581,0,18.0,500.0,0.96741635,3.3512621,18.074869,469.08331,-10.518229
212.4172,0.57436752,9.3153448,56.899971,0,18.0,500.0,0.97015983,2.828902,18.080372,468.9902,-10.538784
212.4198,0.60706747,9.3056717,56.986084,0,18.0,500.0,0.96938813,2.9185741,18.076059,468.88129,-10.558786
212.4224,0.63414085,9.3028975,56.986084,0,18.0,500.0,0.96929735,3.052937,18.074633,468.74936,-10.578129
212.425,0.58292526,9.2971153,56.986084,0,18.0,500.0,0.96729511,2.8470416,18.077557,468.61746,-10.596272
212.4276,0.6791631,9.3170471,56.986084,0,18.0,500.0,0.97005308,3.2571769,18.075459,468.48553,-10.615424
212.4302,0.6267091,9.3100185,57.1045,0,18.0,500.0,0.96860355,3.0499203,18.072517,468.36655,-10.635878
212.4328,0.62274933,9.3135014,57.318306,0,18.0,500.0,0.9691934,2.9703557,18.075899,468.2579,-10.654958
212.4354,0.55495143,9.3076649,57.532112,0,18.0,500.0,0.96895349,2.7183926,18.073675,468.14926,-10.676327
212.438,0.64992923,9.311265,57.745918,0,18.0,500.0,0.97037727,3.1476471,18.074579,468.04065,-10.695015
212.4406,0.62082851,9.3103132,57.810059,0,18.0,500.0,0.97028989,2.9850492,18.07193,467.95917,-10.715039
212.4432,0.46723202,9.3095894,57.810059,0,18.0,500.0,0.96950841,2.270757,18.0746,467.88934,-10.735763
212.4458,0.66745961,9.313591,57.810059,0,18.0,500.0,0.96899629,3.1999199,18.073166,467.81952,-10.755403
212.4484,0.67933559,9.3109426,57.810059,0,18.0,500.0,0.96863246,3.3011179,18.069775,467.74969,-10.774487
212.451,0.61505175,9.3117695,57.86795,0,18.0,500.0,0.96911329,2.9619658,18.071817,467.66675,-10.795005
212.4536,0.8359589,9.3069105,57.936371,0,18.0,500.0,0.96923405,4.0178766,18.066116,467.58139,-10.813514
212.4562,0.55477393,9.3125334,58.004787,0,18.0,500.0,0.9706986,2.6924281,18.066971,467.49603,-10.832341
212.4588,0.62782109,9.3130083,58.073208,0,18.0,500.0,0.97081137,3.0570307,18.069214,467.41071,-10.85303
212.4614,0.63578969,9.3084526,58.07373,0,18.0,500.0,0.96911997,3.0789213,18.069147,467.28683,-10.873172
212.464,0.55494773,9.3057518,58.07373,0,18.0,500.0,0.96754032,2.669693,18.063814,467.16269,-10.890761
212.4666,0.70580262,9.3165846,58.07373,0,18.0,500.0,0.9695214,3.3902173,18.065928,467.03854,-10.911662
212.4692,0.65694815,9.3075953,58.101757,0,18.0,500.0,0.96868843,3.2107334,18.063255,466.9144,-10.931816
212.4718,0.66258812,9.3056202,58.304161,0,18.0,500.0,0.96909928,3.192884,18.065819,466.79025,-10.951396
212.4744,0.7361294,9.3002024,58.506561,0,18.0,500.0,0.96873248,3.5954208,18.063492,466.66608,-10.972105
212.477,0.59117335,9.3202143,58.708965,0,18.0,500.0,0.97176325,2.8035939,18.060322,466.54193,-10.992271
212.4796,0.65357751,9.3097725,58.85376,0,18.0,500.0,0.96903992,3.1648483,18.060299,466.42001,-11.011133
212.4822,0.64589465,9.3156023,58.85376,0,18.0,500.0,0.96897763,3.1279137,18.059214,466.30362,-11.030916
212.4848,0.59311438,9.2937927,58.85376,0,18.0,500.0,0.96583849,2.8642943,18.06163,466.18723,-11.052193
212.4874,0.73239094,9.3099051,58.85376,0,18.0,500.0,0.96921229,3.543191,18.057011,466.07086,-11.0706
212.49,0.64874834,9.3047247,58.909023,0,18.0,500.0,0.96922511,3.1419804,18.057467,465.96115,-11.09112
212.4926,0.61180687,9.3032045,59.0373,0,18.0,500.0,0.96930814,3.0243163,18.060867,465.86029,-11.109529
212.4952,0.65005112,9.3045187,59.165585,0,18.0,500.0,0.96889889,3.1464281,18.05673,465.75943,-11.128023
212.4978,0.65181565,9.3184643,59.293869,0,18.0,500.0,0.97042751,3.1434083,18.056684,465.65854,-11.148898
212.5004,0.64463931,9.3162165,59.348145,0,18.0,500.0,0.96937698,3.1084602,18.060202,465.55768,-11.168996
212.503,0.59519404,9.3088102,59.348145,0,18.0,500.0,0.96847367,3.014641,18.055723,465.45682,-11.188975
212.5056,0.66338015,9.3054323,59.348145,0,18.0,500.0,0.96852094,3.2044771,18.055099,465.35596,-11.206802
212.5082,0.7154187,9.3072729,59.348145,0,18.0,500.0,0.96984214,3.4685445,18.05578,465.25507,-11.227162
212.5108,0.66639662,9.3060188,59.440903,0,18.0,500.0,0.96954525,3.2140479,18.054932,465.14859,-11.247688
212.5134,0.88529533,9.3164577,59.569187,0,18.0,500.0,0.97079736,4.2757874,18.056271,465.03998,-11.265813
212.516,0.560637,9.3170567,59.697472,0,18.0,500.0,0.97007143,2.6884387,18.053436,464.93137,-11.287334
212.5186,0.69300109,9.3174887,59.825756,0,18.0,500.0,0.96950895,3.3306193,18.053719,464.82272,-11.30659
212.5212,0.67301762,9.3089008,59.842533,0,18.0,500.0,0.96837711,3.2520549,18.054338,464.7276,-11.325851
212.5238,0.55254138,9.3011236,59.842533,0,18.0,500.0,0.96809208,2.6356511,18.052452,464.63449,-11.345634
212.5264,0.73222339,9.3077631,59.842533,0,18.0,500.0,0.97003919,3.4741547,18.054649,464.54138,-11.365047
213.2275,0.61549777,9.3194828,1.8137927e-08,0,18.0,1.4427177e-07,0.97115594,2.9707026,18.002975,433.91165,-11.48493
214.5275,0.55811185,9.3257685,3.418118e-26,0,18.0,2.6994805e-25,0.97205085,2.6928759,18.000412,387.75009,-11.485955
215.8275,0.48844159,9.3263712,7.9874012e-44,0,18.0,5.0446745e-43,0.97229797,2.3547244,17.999861,357.56665,-11.484257
217.1275,0.47780746,9.3325853,7.9874012e-44,0,18.0,1.4012985e-45,0.97321039,2.2985878,18.000189,336.04504,-11.486857
218.4275,0.48366645,9.3387518,7.9874012e-44,0,18.0,1.4012985e-45,0.97437453,2.3237519,18.000015,319.42361,-11.485655
219.7275,0.4944309,9.3443756,7.9874012e-44,0,18.0,1.4012985e-45,0.97552603,2.3737261,18.000008,305.80347,-11.484524
221.0275,0.5064919,9.3503141,7.9874012e-44,0,18.0,1.4012985e-45,0.97636956,2.4282973,17.999838,293.21527,-11.484114
222.3275,0.50699395,9.3554211,7.9874012e-44,0,18.0,1.4012985e-45,0.97742343,2.4264863,17.999769,282.20654,-11.484892
223.6275,0.50757277,9.3610907,7.9874012e-44,0,18.0,1.4012985e-45,0.97823727,2.4276702,17.99995,272.12518,-11.485847
224.9275,0.51205844,9.3655195,7.9874012e-44,0,18.0,1.4012985e-45,0.97921681,2.4432414,18.000151,262.23004,-11.485266
226.2275,0.51980925,9.3702812,7.9874012e-44,0,18.0,1.4012985e-45,0.98004395,2.4774098,17.999907,253.59326,-11.485019
227.5275,0.52159202,9.37465,7.9874012e-44,0,18.0,1.4012985e-45,0.98078221,2.4968946,18.000647,245.10429,-11.485335
228.8275,0.52640253,9.3790159,7.9874012e-44,0,18.0,1.4012985e-45,0.98151022,2.5100152,17.999722,237.34726,-11.485704
230.1275,0.5357396,9.3837919,7.9874012e-44,0,18.0,1.4012985e-45,0.98232138,2.5517623,18.000147,230.00578,-11.485352
231.4275,0.53365928,9.3868074,7.9874012e-44,0,18.0,1.4012985e-45,0.98308355,2.5439045,18.000153,222.97684,-11.485042
232.7275,0.5390054,9.3915977,7.9874012e-44,0,18.0,1.4012985e-45,0.98373175,2.5686574,18.000076,216.32288,-11.484914
234.0275,0.55320108,9.3951483,7.9874012e-44,0,18.0,1.4012985e-45,0.98450452,2.6327479,17.999769,210.00934,-11.485326
235.3275,0.54813546,9.3993959,7.9874012e-44,0,18.0,1.4012985e-45,0.98506367,2.6048248,18.000238,203.62129,-11.484278
236.6275,0.55541956,9.403017,7.9874012e-44,0,18.0,1.4012985e-45,0.98584741,2.6399815,18.000168,197.59285,-11.484311
237.9275,0.55486351,9.4069757,7.9874012e-44,0,18.0,1.4012985e-45,0.98660636,2.6405869,17.999809,191.9678,-11.484014
239.2275,0.56073648,9.4100389,7.9874012e-44,0,18.0,1.4012985e-45,0.98707616,2.6658692,18.000143,186.43593,-11.484004
240.5275,0.56663048,9.4143238,7.9874012e-44,0,18.0,1.4012985e-45,0.98781866,2.6853645,18.000376,181.28493,-11.48437
241.8275,0.57105356,9.4171486,7.9874012e-44,0,18.0,1.4012985e-45,0.98827839,2.7062159,18.000292,176.30107,-11.484268
243.1275,0.57193816,9.4206228,7.9874012e-44,0,18.0,1.4012985e-45,0.98909879,2.7084777,18.000364,171.40558,-11.48489
244.4275,0.57824814,9.4232187,7.9874012e-44,0,18.0,1.4012985e-45,0.98935455,2.7400227,18.000257,166.54916,-11.484752
245.7275,0.58393925,9.4272823,7.9874012e-44,0,18.0,1.4012985e-45,0.99026668,2.7650454,17.999071,162.01636,-11.484812
247.0275,0.58749282,9.429635,7.9874012e-44,0,18.0,1.4012985e-45,0.99045658,2.7827904,17.999773,157.49841,-11.484874
248.3275,0.59157723,9.4324799,7.9874012e-44,0,18.0,1.4012985e-45,0.99116462,2.7966716,18.00028,153.39,-11.485008
249.6275,0.59473896,9.4354992,7.9874012e-44,0,18.0,1.4012985e-45,0.99169266,2.8109014,17.999733,149.18019,-11.484861
250.9275,0.59873033,9.4383211,7.9874012e-44,0,18.0,1.4012985e-45,0.99217486,2.8272674,17.999281,145.3636,-11.484194
252.2275,0.60053295,9.440836,7.9874012e-44,0,18.0,1.4012985e-45,0.99254227,2.8344641,17.999548,141.66299,-11.483905
253.5275,0.60363501,9.4432344,7.9874012e-44,0,18.0,1.4012985e-45,0.99296325,2.848783,18.000502,138.00963,-11.483485
254.8275,0.6059944,9.4459324,7.9874012e-44,0,18.0,1.4012985e-45,0.99367326,2.8548989,17.999493,134.59012,-11.482992
256.1275,0.61056083,9.4485931,7.9874012e-44,0,18.0,1.4012985e-45,0.99391818,2.8759472,17.999569,131.02464,-11.482988
257.4275,0.60778767,9.4509764,7.9874012e-44,0,18.0,1.4012985e-45,0.99448717,2.8621302,17.999832,127.67776,-11.482534
258.7275,0.61636901,9.4533558,7.9874012e-44,0,18.0,1.4012985e-45,0.9947058,2.9002018,18.000593,124.39072,-11.482796
260.0275,0.62080884,9.4548397,7.9874012e-44,0,18.0,1.4012985e-45,0.99520665,2.9260449,17.999931,121.28961,-11.482961
261.3275,0.61351621,9.4572325,7.9874012e-44,0,18.0,1.4012985e-45,0.99558544,2.8871841,18.000265,118.17259,-11.482754
262.6275,0.61929303,9.4594202,7.9874012e-44,0,18.0,1.4012985e-45,0.99600136,2.9121037,18.000473,115.22569,-11.483323
263.9275,0.62113303,9.4615545,7.9874012e-44,0,18.0,1.4012985e-45,0.99623871,2.9161575,18.00053,112.39856,-11.483242
265.2275,0.6176489,9.4635992,7.9874012e-44,0,18.0,1.4012985e-45,0.99667698,2.9016235,17.999701,109.72432,-11.483696
266.5275,0.61836445,9.4652348,7.9874012e-44,0,18.0,1.4012985e-45,0.99710482,2.9014792,18.00041,107.00104,-11.48342
267.8275,0.62039042,9.4672937,7.9874012e-44,0,18.0,1.4012985e-45,0.99736261,2.9127986,18.000275,104.29408,-11.483634
269.1275,0.62615192,9.4690447,7.9874012e-44,0,18.0,1.4012985e-45,0.99766064,2.9396834,17.999895,101.83318,-11.483508
270.4275,0.62112743,9.4709721,7.9874012e-44,0,18.0,1.4012985e-45,0.99795997,2.9126215,17.999392,99.506134,-11.483528
271.7275,0.62326491,9.4721746,7.9874012e-44,0,18.0,1.4012985e-45,0.99840999,2.9258947,17.999563,97.037155,-11.482986
272.5275,0.62396955,9.4735413,7.9874012e-44,0,18.0,1.4012985e-45,0.99862903,2.9224834,18.000151,95.564667,-11.482781