File: raw data/testID_0134.csv
Time(sec),Force(kN),Jaw(mm),PowAngle(deg),Power(W),Pram,PTemp,Strain,Stress(MPa),Stroke(mm),TC1(C),wedge(mm)
0.0,0.78345543,0.26042727,0.0,0,11.076097,0.00069119054,0.017507449,9.7987766,11.076318,29.151262,-9.1306162
1.1,0.73687178,-0.00053073879,0.0,0,11.076097,3.2158809,-3.2432974e-05,9.369525,11.075786,29.141432,-9.4994307
2.2,0.70730144,-0.00067659817,0.0,0,11.076097,6.5158811,-5.9640159e-05,9.0141354,11.075234,29.10528,-9.496357
3.3,0.69079107,-0.00090068282,0.0,0,11.076097,9.8158817,-5.7915368e-05,8.7900362,11.075564,29.09379,-9.4949532
4.4,0.67240703,-0.00082061259,0.0,0,11.076097,13.115882,-5.9767761e-05,8.5575752,11.076144,28.967422,-9.4925842
5.5,0.66657263,-0.00056112697,0.0,0,11.076097,16.415886,-5.4341377e-05,8.4798269,11.076071,28.911045,-9.4910517
6.6,0.64704293,-0.00099021872,0.0,0,11.076097,19.715883,-5.8796115e-05,8.2396793,11.076343,28.891171,-9.4886618
7.7,0.63827896,-0.0011985106,0.0,0,11.076097,23.015881,-8.6512046e-05,8.1240416,11.076321,28.727253,-9.4863605
8.8,0.62355155,-0.00082292903,0.0,0,11.076097,26.315887,-8.303309e-05,7.939126,11.076939,28.743536,-9.4841337
9.9,0.6170662,-0.0012321477,2.7585132,0,11.076097,29.615885,-5.6937886e-05,7.8637438,11.076146,28.591162,-9.4820461
11.0,0.62244076,-0.0001610481,24.461973,0,11.076097,32.915894,-4.5992792e-06,7.9283152,11.076937,28.599981,-9.4803782
12.1,0.62050968,-0.00086749706,35.459602,0,11.076097,36.215897,-7.6173674e-05,7.8918233,11.076714,29.16321,-9.478756
13.2,0.6264348,-0.0028399366,42.624317,0,11.076097,39.515892,-0.00016056995,7.9642911,11.075521,30.638552,-9.4770145
14.3,0.62938297,-0.0062860451,47.198078,0,11.076097,42.815895,-0.00041235826,8.0067883,11.075931,33.422989,-9.4748077
15.4,0.64893925,-0.0090925284,50.425045,0,11.076097,46.115891,-0.0006346266,8.2649851,11.076859,36.956226,-9.4731083
16.5,0.66730261,-0.014271753,52.254543,0,11.076097,49.415894,-0.00092862593,8.5039454,11.075887,41.528893,-9.4712076
17.6,0.67065579,-0.017728182,52.976028,0,11.076097,52.715889,-0.0011706144,8.5590172,11.076994,46.596043,-9.4692183
18.7,0.69039428,-0.022627169,52.976086,0,11.076097,56.015881,-0.001526561,8.8005066,11.075969,52.136387,-9.4668903
19.8,0.69193721,-0.025711337,52.284019,0,11.076097,59.315884,-0.0016878399,8.8199863,11.077021,57.636906,-9.4647665
20.9,0.69511437,-0.029038845,50.826485,0,11.076097,62.615879,-0.0019305472,8.8640995,11.076582,63.069546,-9.4626522
22.0,0.69737029,-0.032303844,49.230103,0,11.076097,65.915894,-0.0021632742,8.8962708,11.075411,67.981316,-9.4602776
23.1,0.7060762,-0.034809936,47.060184,0,11.076097,69.215881,-0.0023090467,9.0138779,11.076064,72.360779,-9.4589052
24.2,0.70039064,-0.037090797,45.187527,0,11.076097,72.515877,-0.0024862643,8.9482851,11.07645,76.17321,-9.457057
25.3,0.68468523,-0.038666598,43.915874,0,11.076097,75.815887,-0.0025732575,8.7503967,11.075402,79.303925,-9.4546709
26.4,0.67728478,-0.039739318,42.979229,0,11.076097,79.115891,-0.0026445671,8.6463089,11.075156,81.859428,-9.4525566
27.5,0.67879701,-0.041803699,43.527031,0,11.076097,82.415894,-0.0028112091,8.6733208,11.07653,84.011238,-9.4505873
28.6,0.66933054,-0.042935684,44.59082,0,11.076097,85.715889,-0.0028403362,8.5574312,11.07614,85.92205,-9.4483662
29.7,0.67820925,-0.044692773,46.108673,0,11.076097,89.015884,-0.0029691197,8.6685667,11.075219,87.886955,-9.4466743
30.8,0.68937474,-0.047203857,47.876438,0,11.076097,92.31588,-0.0031734863,8.8092804,11.076483,90.070572,-9.4446001
31.9,0.69068795,-0.04935905,49.629932,0,11.076097,95.615875,-0.0032574488,8.8289804,11.075806,92.465889,-9.4427652
33.0,0.69315058,-0.051889848,50.82267,0,11.076097,98.915871,-0.0034457608,8.8525009,11.075831,95.406593,-9.4409103
34.1,0.70438379,-0.054672796,52.232494,0,11.076097,102.21589,-0.0036537813,8.9993782,11.075318,98.6035,-9.4395199
35.2,0.71282476,-0.058512617,52.976028,0,11.076097,105.51589,-0.0038801997,9.1139812,11.077337,102.31125,-9.437645
36.3,0.71794266,-0.060941502,53.31665,0,11.076097,108.8159,-0.0040627043,9.1791058,11.075936,106.17814,-9.4353905
37.4,0.71568447,-0.064613119,53.643738,0,11.076097,112.11591,-0.0042980146,9.1612492,11.07581,110.26376,-9.4331322
38.5,0.72903335,-0.06805981,53.316654,0,11.076097,115.41591,-0.0045391656,9.3325338,11.076425,114.42859,-9.4313631
39.6,0.72974628,-0.07123208,52.976078,0,11.076097,118.71592,-0.0047624758,9.3460789,11.075978,118.57897,-9.4291058
40.7,0.7318868,-0.07392478,52.453987,0,11.076097,122.0159,-0.0048958752,9.3763504,11.075449,122.48538,-9.4270782
41.8,0.73138851,-0.076550417,51.932377,0,11.076097,125.3159,-0.0050779395,9.3495522,11.075628,126.25848,-9.4249744
42.9,0.72385943,-0.079430446,51.569828,0,11.076097,128.61603,-0.0053087464,9.2774687,11.076175,129.56703,-9.4229774
44.0,0.73754144,-0.082311161,51.200657,0,11.076097,131.91588,-0.0054427208,9.4520569,11.076541,132.79947,-9.421134
45.1,0.74176234,-0.085204139,51.274471,0,11.076097,135.2159,-0.0056523765,9.5028048,11.075783,135.76599,-9.4193916
46.2,0.73706275,-0.087024637,51.56982,0,11.076097,138.51588,-0.0057998504,9.42871,11.076065,138.53459,-9.417347
47.3,0.73573816,-0.089554757,52.130913,0,11.076097,141.81589,-0.0059466679,9.4215136,11.075405,141.31006,-9.4157581
48.4,0.73944372,-0.092331938,52.635494,0,11.076097,145.11589,-0.0061484263,9.4771833,11.076669,144.18723,-9.413806
49.5,0.73487473,-0.094740719,53.316624,0,11.076097,148.41589,-0.0062768506,9.4173956,11.076628,147.07274,-9.411849
50.6,0.75038016,-0.097422019,53.972916,0,11.076097,151.7159,-0.0064732605,9.6358957,11.076678,150.04131,-9.4101
51.7,0.75157338,-0.1006438,54.305416,0,11.076097,155.0159,-0.0067167082,9.6299658,11.076753,153.298,-9.4086323
52.8,0.7598232,-0.10424308,54.805824,0,11.076097,158.31589,-0.0069015138,9.739706,11.075727,156.74799,-9.4059258
53.9,0.76528066,-0.10793582,55.035984,0,11.076097,161.61588,-0.0071622692,9.8046427,11.075562,160.22545,-9.4037762
55.0,0.76950878,-0.11167483,55.239254,0,11.076097,164.91589,-0.007429014,9.8625278,11.077391,163.88899,-9.4016733
56.1,0.76723641,-0.11510135,55.239254,0,11.076097,168.2159,-0.0076349429,9.8303585,11.075614,167.5231,-9.3997498
57.2,0.76517534,-0.11782128,55.196991,0,11.076097,171.5159,-0.007835621,9.8113203,11.076332,171.14372,-9.3986177
58.3,0.76417208,-0.12062021,54.932274,0,11.076097,174.8159,-0.0079919212,9.8115091,11.075778,174.71112,-9.3966541
59.4,0.75851196,-0.12378576,54.931644,0,11.076097,178.11591,-0.0082139801,9.7349186,11.075899,178.31392,-9.3944311
60.5,0.76287371,-0.12619056,54.720947,0,11.076097,181.41589,-0.0084110862,9.7927637,11.076468,181.64728,-9.3923931
61.6,0.76339871,-0.12999532,54.624027,0,11.076097,184.7159,-0.008602351,9.7928762,11.076026,184.96387,-9.390521
62.7,0.76518661,-0.13266718,54.624027,0,11.076097,188.0159,-0.0087941894,9.8343811,11.076099,188.19424,-9.3885803
63.8,0.76910776,-0.13568515,54.816761,0,11.076097,191.3159,-0.0090083238,9.8818855,11.075957,191.22206,-9.3869514
64.9,0.76365417,-0.13876304,54.931637,0,11.076097,194.61589,-0.0092108762,9.8135099,11.075577,194.40057,-9.3850288
66.0,0.76831466,-0.14143528,55.08556,0,11.076097,197.91589,-0.0094050784,9.8854342,11.076015,197.55742,-9.3833294
67.1,0.77508235,-0.14506014,55.239254,0,11.076097,201.2159,-0.0096030319,9.943284,11.077523,200.88664,-9.381712
68.2,0.77179754,-0.14836967,55.239254,0,11.076097,204.5159,-0.0098347813,9.9024076,11.075588,204.19394,-9.3796015
69.3,0.78000259,-0.15183908,55.239254,0,11.076097,207.81589,-0.010084268,10.024844,11.075883,207.51993,-9.3776054
70.4,0.78572458,-0.15505442,55.488621,0,11.076097,211.11589,-0.010266996,10.105482,11.075644,210.78555,-9.3759527
71.5,0.78511763,-0.15760365,55.535885,0,11.076097,214.41589,-0.010452062,10.109663,11.076198,214.03632,-9.3733845
72.6,0.7818476,-0.16006775,55.814331,0,11.076097,217.71588,-0.010612636,10.066513,11.075897,217.19473,-9.3714018
73.7,0.77287799,-0.16322845,55.846992,0,11.076097,221.0159,-0.010816212,9.948122,11.076267,220.35689,-9.3693953
74.8,0.78034699,-0.1663049,56.129147,0,11.076097,224.31589,-0.011053183,10.04601,11.076331,223.72226,-9.368062
75.9,0.77980614,-0.16943571,56.129147,0,11.076097,227.61591,-0.011197375,10.049834,11.075685,227.20677,-9.366662
77.0,0.78083104,-0.17255807,56.129147,0,11.076097,230.91589,-0.01142024,10.066385,11.075828,230.60275,-9.3646679
78.1,0.77511168,-0.17606084,56.129147,0,11.076097,234.2159,-0.011681141,9.9793186,11.076202,233.98723,-9.3629818
79.2,0.77785248,-0.17936864,56.129147,0,11.076097,237.5159,-0.011885399,10.016204,11.075701,237.29695,-9.3610849
80.3,0.77367657,-0.18277077,56.129154,0,11.076097,240.8159,-0.012131709,9.9489689,11.074803,240.68147,-9.3589306
81.4,0.79388177,-0.18653558,56.129154,0,11.076097,244.11591,-0.012334558,10.225418,11.076667,244.05614,-9.3571796
82.5,0.79006243,-0.19101407,56.129154,0,11.076097,247.41589,-0.012638896,10.185428,11.076602,247.41496,-9.3554783
83.6,0.78906274,-0.19308241,56.129154,0,11.076097,250.71591,-0.01280903,10.182854,11.075586,250.56815,-9.3531694
84.7,0.79011083,-0.1957126,56.389717,0,11.076097,254.0159,-0.012955276,10.193265,11.075329,253.76671,-9.3512392
85.8,0.79019123,-0.19888611,56.425777,0,11.076097,257.31616,-0.013183364,10.191603,11.076105,257.11542,-9.3493834
86.9,0.78736353,-0.20246665,56.425777,0,11.076097,260.61618,-0.013390247,10.157139,11.076145,260.34726,-9.3475914
88.0,0.77914697,-0.2060342,56.576519,0,11.076097,263.91589,-0.013634478,10.066648,11.076142,263.6394,-9.3456802
89.1,0.78238416,-0.20941596,56.711414,0,11.076097,267.21588,-0.013880013,10.109588,11.076277,266.93991,-9.3438101
90.2,0.78701991,-0.21296763,56.711422,0,11.076097,270.5159,-0.014069655,10.180243,11.075454,270.27002,-9.3424339
91.3,0.77959186,-0.21607634,56.711422,0,11.076097,273.81589,-0.014310003,10.070851,11.077442,273.67871,-9.3403492
92.4,0.77657646,-0.21949691,56.711422,0,11.076097,277.11588,-0.014517098,10.043228,11.076385,276.9733,-9.3384523
93.5,0.7725603,-0.22300492,56.711422,0,11.076097,280.41589,-0.014753148,9.9904737,11.075868,280.16821,-9.3368998
94.6,0.7825855,-0.22638375,56.969749,0,11.076097,283.71588,-0.015002791,10.132951,11.076109,283.39478,-9.3353224
95.7,0.77420515,-0.2297288,56.986084,0,11.076097,287.0159,-0.015174456,9.9987507,11.07563,286.68161,-9.3325958
96.8,0.78964424,-0.2330763,56.986084,0,11.076097,290.31586,-0.015416458,10.20827,11.076696,290.03952,-9.331008
97.9,0.78825563,-0.23709653,57.189594,0,11.076097,293.61591,-0.015663983,10.190214,11.076656,293.24771,-9.3285418
99.0,0.79683071,-0.24117023,57.260738,0,11.076097,296.91589,-0.015940597,10.315268,11.075169,296.49869,-9.3268471
100.1,0.79730892,-0.24465315,57.260738,0,11.076097,300.21591,-0.016204005,10.313406,11.076325,299.80447,-9.3256903
101.2,0.79648805,-0.24845599,57.535397,0,11.076097,303.51593,-0.016399371,10.303993,11.074892,303.10263,-9.324192
102.3,0.79251885,-0.25197744,57.535397,0,11.076097,306.81592,-0.016654845,10.261895,11.075157,306.41159,-9.321888
103.4,0.79327303,-0.2554763,57.537323,0,11.076097,310.11591,-0.016892744,10.269034,11.075837,309.74008,-9.3198528
104.5,0.80149019,-0.25878873,57.810051,0,11.076097,313.41589,-0.017110927,10.374227,11.07658,312.99762,-9.3180857
105.6,0.80078274,-0.2623969,57.810051,0,11.076097,316.71588,-0.017362539,10.38196,11.075172,316.34171,-9.3160076
106.7,0.8031618,-0.26603493,57.810051,0,11.076097,320.0159,-0.017557988,10.401034,11.076704,319.74014,-9.314393
107.8,0.79677206,-0.26935408,57.945049,0,11.076097,323.31589,-0.017794438,10.334425,11.07558,323.03171,-9.3125858
108.9,0.79511416,-0.27248576,57.98336,0,11.076097,326.61588,-0.017995033,10.304528,11.075383,326.36847,-9.3111076
110.0,0.79022837,-0.27480823,57.813732,0,11.076097,329.91522,-0.018152146,10.235151,11.075594,329.81094,-9.3097191
111.1,0.042684298,-0.28739822,56.037693,0,11.076097,329.99976,-0.01900919,0.55049294,11.075787,332.68607,-9.3094654
112.2,0.020731723,-0.28790593,53.978649,0,11.076097,329.99976,-0.018990269,0.26811802,11.075768,334.48563,-9.3085709
113.3,0.019394461,-0.28667957,52.284187,0,11.076097,329.99976,-0.018934237,0.25314242,11.076517,334.98865,-9.308816
114.4,0.015294217,-0.28496468,51.196293,0,11.076097,329.99976,-0.018811839,0.21577054,11.07636,334.47635,-9.3083858
115.5,0.010028761,-0.28380662,50.822758,0,11.076097,329.99976,-0.01874375,0.13526152,11.075969,333.05539,-9.3082237
116.6,0.0054270038,-0.2826415,51.56982,0,11.076097,329.99976,-0.018697789,0.075952478,11.07556,331.11572,-9.3081007
117.7,0.002344575,-0.28167462,53.348801,0,11.076097,329.99976,-0.018585443,0.029951036,11.075448,328.72205,-9.3080587
118.8,-0.0055579818,-0.27976197,55.503822,0,11.076097,329.99976,-0.018480109,-0.071264878,11.076561,326.44162,-9.3083992
119.9,-0.0063251364,-0.27933067,57.767384,0,11.076097,329.99976,-0.018447295,-0.06863261,11.075876,324.423,-9.308424
121.0,-0.0076084654,-0.27906224,59.942307,0,11.076097,329.99976,-0.018434407,-0.10303187,11.076441,322.8768,-9.3084764
122.1,-0.00043647876,-0.27893391,61.890133,0,11.076097,329.99976,-0.018450657,0.017522804,11.076163,321.80173,-9.3087311
123.2,0.0071473261,-0.2800321,63.738167,0,11.076097,329.99976,-0.018480413,0.087771557,11.075315,321.20221,-9.308279
124.3,0.026259359,-0.27952638,65.108002,0,11.076097,329.99976,-0.018466141,0.33476761,11.076283,321.33484,-9.3089323
125.4,0.032737274,-0.28196168,65.884911,0,11.076097,329.99976,-0.018614657,0.43059784,11.076134,322.59152,-9.307642
126.5,0.043446455,-0.28489658,66.085411,0,11.076097,329.99976,-0.018806044,0.57241184,11.076074,324.77844,-9.3074198
127.6,0.054394554,-0.28859776,65.666153,0,11.076097,329.99976,-0.019082511,0.72347802,11.076242,327.68066,-9.3068781
128.7,0.059004303,-0.29077795,64.582314,0,11.076097,329.99976,-0.019192344,0.75858682,11.075319,330.78964,-9.3073778
129.8,0.050999988,-0.29298696,63.077175,0,11.076097,329.99976,-0.019353528,0.67827946,11.07622,333.69998,-9.3076744
130.9,0.05447267,-0.29499367,61.028786,0,11.076097,329.99976,-0.019453481,0.69820273,11.075859,336.29776,-9.3080292
132.0,0.054756053,-0.29622996,58.523815,0,11.076097,329.99976,-0.019548258,0.72049183,11.075544,338.28677,-9.3082495
133.1,0.039648399,-0.29642594,55.851849,0,11.076097,329.99976,-0.019578163,0.5143258,11.075975,339.37579,-9.3079891
134.2,0.017471822,-0.29568851,53.046825,0,11.076097,329.99976,-0.019519394,0.22579728,11.076511,339.53491,-9.3074913
135.3,0.0059264628,-0.29458717,51.071693,0,11.076097,329.99976,-0.019468082,0.082454972,11.075656,338.58475,-9.3071337
136.4,-0.0057466691,-0.29376689,49.859497,0,11.076097,329.99976,-0.019361014,-0.055707358,11.075433,336.70273,-9.3072414
137.5,-0.014574386,-0.29246509,50.042683,0,11.076097,329.99976,-0.019296315,-0.18929206,11.07521,334.15576,-9.3070049
138.6,-0.023219749,-0.29066703,51.536823,0,11.076097,329.99976,-0.019199867,-0.28022122,11.076249,331.02185,-9.3074713
139.7,-0.028491089,-0.28925335,53.927074,0,11.076097,329.99976,-0.019097604,-0.36850113,11.076359,327.87015,-9.3074074
140.8,-0.029554781,-0.28820956,56.703747,0,11.076097,329.99976,-0.019056519,-0.38189673,11.075497,324.82272,-9.3076096
141.9,-0.032719985,-0.28827518,59.587383,0,11.076097,329.99976,-0.019008311,-0.42547625,11.076242,322.17334,-9.3076429
143.0,-0.033386782,-0.28805336,62.323689,0,11.076097,329.99976,-0.019033171,-0.41402543,11.07576,320.06235,-9.307601
144.1,-0.036574144,-0.28783956,64.888336,0,11.076097,329.99976,-0.018991802,-0.46096882,11.075921,318.33051,-9.3073845
145.2,-0.031030457,-0.28704488,67.148087,0,11.076097,329.99976,-0.018948004,-0.3839789,11.07697,317.26846,-9.3072567
146.3,-0.030298654,-0.28738245,69.086945,0,11.076097,329.99976,-0.01899592,-0.38695505,11.075792,316.7341,-9.3071451
147.4,-0.020158935,-0.28881267,70.589394,0,11.076097,329.99976,-0.019070284,-0.2624951,11.076689,317.04556,-9.3065891
148.5,-0.016316717,-0.28848168,71.80368,0,11.076097,329.99976,-0.019075321,-0.22020017,11.076107,318.04816,-9.3064651
149.6,0.017981069,-0.29096326,72.454643,0,11.076097,329.99976,-0.019174879,0.22578749,11.075773,320.35803,-9.3063059
150.7,0.049707036,-0.29601893,72.323296,0,11.076097,329.99976,-0.01952647,0.65345693,11.07617,324.24405,-9.3058882
151.8,0.065204613,-0.30322757,71.283127,0,11.076097,329.99976,-0.020018322,0.82602644,11.076996,329.54022,-9.3067484
152.9,0.048060615,-0.30646756,69.387695,0,11.076097,329.99976,-0.020224772,0.63837641,11.075349,335.14902,-9.3071051
154.0,0.051347982,-0.31017923,66.624176,0,11.076097,329.99976,-0.020482559,0.68204021,11.075419,340.32703,-9.3068676
155.1,0.057133667,-0.049713988,63.020512,0,11.076097,329.99976,-0.0032609501,0.71970487,11.075836,344.62241,-9.3073483
155.2817,0.099374443,0.0059055653,15.552133,0,11.076099,1.5450173e-08,0.00031110711,1.2606865,11.070795,345.24753,-9.3078356
155.2839,0.096254081,0.0053613889,1.8654919,0,11.076099,1.5431313999999998e-23,0.0004098865,1.1881474,11.074857,345.26086,-9.3077955
155.2861,0.096764594,0.0016987493,0.0,0,11.076099,1.5412479999999996e-38,0.00013079894,1.2169635,11.074735,345.28,-9.3067932
155.2883,0.11523498,0.0051343404,0.0,0,11.076099,0.0,0.00042394444,1.3556476,11.07478,345.30002,-9.308238
155.2905,0.1097873,0.0038058271,0.0,0,11.076099,0.0,0.0002244377,1.4711696,11.074764,345.32004,-9.3074903
155.2927,0.097541079,0.0061594881,0.0,0,11.076099,0.0,0.00046943966,1.3430516,11.074691,345.34006,-9.307045
155.2949,0.10837216,0.0034694229,0.0,0,11.076099,0.0,0.0002080827,1.3095801,11.074748,345.34976,-9.3078184
155.2971,0.097189739,0.007410421,0.0,0,11.076099,0.0,0.00053908979,1.229365,11.075829,345.3364,-9.3069906
155.2993,0.10397047,0.005077499,0.0,0,11.076099,0.0,0.00023537604,1.316292,11.07551,345.32306,-9.3073692
155.3015,0.09744063,0.003997379,0.0,0,11.076099,0.0,0.00042279344,1.2553195,11.074564,345.30972,-9.3077688
155.3037,0.099045038,0.0039597242,0.0,0,11.076099,0.0,0.00024607917,1.2392306,11.074955,345.29636,-9.3089809
155.3059,0.1160697,0.0069843442,0.0,0,11.076099,0.0,0.00057378242,1.4146825,11.07531,345.28806,-9.3078747
155.3081,0.12222094,0.005856711,0.0,0,11.076099,0.0,0.00032593947,1.5632956,11.076822,345.28137,-9.306716
155.3103,0.11965303,0.0055578626,0.0,0,11.076099,0.0,0.00045620583,1.5661229,11.076459,345.27472,-9.3066015
155.3125,0.10776918,0.0051079635,0.0,0,11.076099,0.0,0.00028769646,1.3798728,11.07458,345.26804,-9.3064699
155.3147,0.11299931,0.0092736688,0.0,0,11.076099,0.0,0.00068485813,1.3645083,11.075154,345.26669,-9.3070583
155.3169,0.10789032,0.0065070931,0.0,0,11.076099,0.0,0.00037683774,1.3961316,11.077531,345.28671,-9.3076096
155.3191,0.11226027,0.0053157974,0.0,0,11.076099,0.0,0.00045640933,1.4363931,11.074824,345.30673,-9.3072681
155.3213,0.10650856,0.0056875879,0.0,0,11.076099,0.0,0.00033353834,1.4296104,11.074821,345.32675,-9.306673
155.3235,0.10765804,0.009527225,0.0,0,11.076099,0.0,0.00071171997,1.3551869,11.073901,345.34677,-9.3066149
155.3257,0.14036708,0.006257785,0.0,0,11.076099,0.0,0.00033085831,1.7476907,11.075904,345.36249,-9.3066759
155.3279,0.14117971,0.0053219488,0.0,0,11.076099,0.0,0.0004582433,1.7784503,11.0784,345.37582,-9.3068666
155.3301,0.13470154,0.0061999145,0.0,0,11.076099,0.0,0.00033606478,1.7041187,11.072593,345.38916,-9.3078566
155.3323,0.12508351,0.0082916589,0.0,0,10.765881,0.0,0.00067628862,1.723197,11.077091,345.4025,-9.3075342
155.3345,0.13162862,0.0072997394,0.0,0,10.434988,0.0,0.00037049304,1.6796436,11.074531,345.45892,-9.3076954
155.3367,0.13851632,0.0054406938,0.0,0,10.104096,0.0,0.00044320483,1.8463542,11.026346,345.94595,-9.3075552
155.3389,0.11029888,0.0057460442,0.0,0,9.7732038,0.0,0.00029330954,1.3873436,10.84856,346.43298,-9.3077955
155.3411,0.15068215,0.0092479801,0.0,0,9.443388,0.0,0.0007119035,1.8461615,10.548554,346.92001,-9.307765
155.3433,0.13086744,0.0089787999,0.0,0,9.121479,0.0,0.00044390681,1.7429425,10.15909,347.40704,-9.3082142
155.3455,6.7828269,0.35103941,0.0,0,8.7995749,0.0,0.023344455,84.033096,9.7594633,349.23889,-9.3016901
155.3477,8.2996664,0.67958927,0.0,0,8.4910078,0.0,0.046128415,100.61575,9.3440847,352.23297,-9.3016806
155.3499,8.6617937,1.0728308,0.0,0,8.1848555,0.0,0.074033022,102.00022,8.9434843,355.22702,-9.300869
155.3521,8.8072681,1.4421847,0.0,0,7.8872385,0.0,0.10047031,101.5595,8.586524,358.2211,-9.3006659
155.3543,9.2237406,1.7325747,0.0,0,7.5959582,0.0,0.1223065,103.72979,8.2654066,361.21515,-9.2992268
155.3565,9.3815222,2.046371,0.0,0,7.3089714,0.0,0.14608563,103.27277,7.9456143,362.68741,-9.2990046
155.3587,9.5600395,2.3443806,0.0,0,7.0319471,0.0,0.16970685,102.63342,7.64922,364.13156,-9.2994547
155.3609,9.8871307,2.6139007,0.0,0,6.7554259,0.0,0.19085518,104.03223,7.3734908,365.57571,-9.2999916
155.3631,10.056562,2.8778577,0.0,0,6.4917464,0.0,0.21275346,103.45084,7.0975876,367.01987,-9.2993183
155.3653,10.304748,3.1413243,0.0,0,6.2281866,0.0,0.23435427,103.74194,6.8256726,367.4325,-9.3003817
155.3675,10.550849,3.4021745,0.0,0,5.9743686,0.0,0.25708905,103.87881,6.5673404,366.46274,-9.2997742
155.3697,10.735974,3.6579549,0.0,0,5.7237005,0.0,0.27885449,103.45327,6.3063011,365.49301,-9.3000803
155.3719,10.964675,3.9103415,0.0,0,5.4789195,0.0,0.30181527,103.14758,6.0482759,364.52328,-9.3000813
155.3741,11.212812,4.1614261,0.0,0,5.2404394,0.0,0.32429725,103.20992,5.7959185,363.55353,-9.2998047
155.3763,11.438231,4.4174056,0.0,0,5.0044107,0.0,0.34865403,102.7534,5.537991,362.47195,-9.301136
155.3785,11.685349,4.6641083,0.0,0,4.7775908,0.0,0.37169573,102.5582,5.2951546,361.37405,-9.3001614
155.3807,11.97122,4.9027667,0.0,0,4.5507708,0.0,0.39555472,102.61478,5.049675,360.27615,-9.2984343
155.3829,12.242179,5.1413026,0.0,0,4.3343053,0.0,0.41901675,102.43949,4.8101039,359.17828,-9.298789
155.3851,12.50485,5.3794079,0.0,0,4.1185288,0.0,0.44401804,102.0873,4.5713811,358.00204,-9.298584
155.3873,12.775477,5.6085939,0.0,0,3.9097731,0.0,0.46747878,101.90026,4.344707,356.65796,-9.299305
155.3895,13.047029,5.8274918,0.0,0,3.7045572,0.0,0.49172401,101.51428,4.1219029,355.31384,-9.299819
155.3917,13.349173,6.0427289,0.0,0,3.5032573,0.0,0.51481068,101.47566,3.9027224,353.96976,-9.3006907
155.3939,13.677896,6.2549906,0.0,0,3.3080292,0.0,0.53959042,101.49309,3.6941102,352.62567,-9.3005648
155.3961,14.015156,6.4635844,0.0,0,3.113939,0.0,0.56282532,101.55431,3.4876626,350.37112,-9.2986145
155.3983,14.363691,6.6587586,0.0,0,2.9282112,0.0,0.58686656,101.65366,3.288238,347.83487,-9.2985287
155.4005,14.763642,6.8539515,0.0,0,2.7424874,0.0,0.60980028,102.10651,3.0921841,345.29858,-9.2987175
155.4027,15.17334,7.0495543,0.0,0,2.5644369,0.0,0.6348877,102.33409,2.8993664,342.76233,-9.2984819
155.4049,15.563874,7.2393117,0.0,0,2.3877769,0.0,0.6580925,102.53963,2.7134411,340.23569,-9.2971029
155.4071,15.983721,7.4217505,0.0,0,2.2160664,0.0,0.68283778,102.74025,2.5255866,337.74545,-9.2968626
155.4093,16.417871,7.6003456,0.0,0,2.0480304,0.0,0.70568365,103.17994,2.3443565,335.25519,-9.296401
155.4115,16.912287,7.7773247,0.0,0,1.8824589,0.0,0.73091894,103.61502,2.1683228,332.76495,-9.2967091
155.4137,17.442535,7.954771,0.0,0,1.7226069,0.0,0.75461501,104.386,1.9985758,330.27469,-9.2955046
155.4159,17.988979,8.1172295,0.0,0,1.5630457,0.0,0.77913135,104.97984,1.8313489,326.95337,-9.297122
155.4181,18.571142,8.2823877,0.0,0,1.4109124,0.0,0.80217665,105.95112,1.662631,323.19354,-9.2976189
155.4203,19.211308,8.4415226,0.0,0,1.2588483,0.0,0.82754499,106.82488,1.5020739,319.43372,-9.2965212
155.4225,19.83218,8.60357,0.0,0,1.1124039,0.0,0.85117584,107.77523,1.34606,315.67389,-9.294795
155.4247,20.485605,8.7522163,0.0,0,0.96777582,0.0,0.87614226,108.55294,1.1884307,312.0571,-9.2951946
155.4269,21.184662,8.9020014,0.0,0,0.8265692,0.0,0.89894265,109.70087,1.0349853,309.72668,-9.2958622
155.4291,21.888935,9.0450583,0.0,0,0.68902522,0.0,0.92421573,110.55297,0.88985354,307.3963,-9.2951269
155.4313,22.670712,9.1879721,0.0,0,0.55287826,0.0,0.94690871,111.89424,0.7491551,305.06589,-9.2945156
155.4335,23.43841,9.3187895,0.0,0,0.42197818,0.0,0.97112727,112.92664,0.61065364,302.7355,-9.2928839
155.4357,21.690287,9.4036198,0.0,0,0.29107815,0.0,0.98512524,103.29826,0.48883274,303.02557,-9.2948046
155.4379,20.334532,9.4167967,0.0,0,0.1662008,0.0,0.98913354,96.329277,0.43981883,307.09988,-9.2978039
155.4401,19.365477,9.4250488,0.0,0,0.041724794,0.0,0.98890185,91.769829,0.41348472,311.17419,-9.2997627
155.4423,18.807106,9.430212,0.0,0,-0.080703594,0.0,0.99148279,88.862663,0.38368115,315.24854,-9.2994471
155.4445,18.684628,9.4373245,0.0,0,-0.20209959,0.0,0.99112463,88.261513,0.3449308,319.32285,-9.2988148
155.4467,18.910387,9.4421425,0.0,0,-0.3234956,0.0,0.99372834,89.098602,0.28905204,322.94882,-9.2996778
155.4489,19.052048,9.4483814,0.0,0,-0.44489157,0.0,0.99299526,89.840897,0.23002061,326.49854,-9.2991276
155.4511,19.053762,9.4492254,0.0,0,-0.56628758,0.0,0.99495286,89.708618,0.17103173,330.04822,-9.2994862
155.4533,18.972694,9.4564056,0.0,0,-0.68768358,0.0,0.99458593,89.34053,0.11311281,333.59793,-9.2997952
155.4555,18.78299,9.4616861,0.0,0,-0.80907953,0.0,0.99734163,88.234657,0.062977664,336.72122,-9.3000593
155.4577,18.540049,9.4708576,0.0,0,-0.93047559,0.0,0.9968828,87.142853,0.026445856,338.84985,-9.2997293
155.4599,18.207813,9.4684124,0.0,0,-1.0518717,0.0,0.99855,85.451401,0.0034733859,340.97845,-9.3001328
155.4621,17.798861,9.4730721,0.0,0,-0.88151103,330.0,0.99755448,83.62619,-0.014539866,343.10709,-9.299819
155.4643,17.303104,9.470397,0.0,0,-0.4612315,330.0,0.9990117,81.184898,-0.013482106,345.23569,-9.3002901
155.4665,16.837439,9.4740343,0.0,0,-0.04095266,330.0,0.99746644,79.118889,-0.0112045,347.53589,-9.3016462
155.4687,16.415627,9.4696636,0.0,0,0.37932643,330.0,0.99894053,76.999367,-0.0044733761,349.89465,-9.3011169
155.4709,16.091648,9.477376,0.0,0,0.79960597,330.0,0.9983272,75.531136,-0.0016987064,352.25342,-9.3021479
155.4731,15.826273,9.4754133,0.0,0,1.2198851,330.0,0.99984211,74.180634,-0.0019259363,354.61218,-9.3025112
155.4753,15.096255,9.4766312,0.0,0,1.6401638,330.0,0.99784762,70.974174,0.018707091,356.83939,-9.3028927
155.4775,13.320807,9.4651394,0.0,0,2.0604436,330.0,0.99803066,62.746529,0.092141107,358.50925,-9.303195
155.4797,10.590364,9.4592314,0.0,0,2.4807229,330.0,0.99500364,50.113544,0.22528191,360.17908,-9.3040981
155.4819,6.7578201,9.441699,0.0,0,2.9010019,330.0,0.99394071,32.189957,0.43590328,361.84894,-9.309432
155.4841,0.029187584,9.3432398,0.0,0,3.321281,330.0,0.97471231,0.090450235,0.76668167,363.51877,-9.3164396
155.4863,0.21163927,9.2229967,0.0,0,3.7415602,330.0,0.95564753,1.0814953,1.4414009,365.25894,-9.3149147
155.4885,-0.17866699,9.143384,0.0,0,4.1618395,330.0,0.93967497,-0.84143341,2.1983175,367.03928,-9.3147669
155.4907,-0.090811618,9.0580502,0.0,0,4.5821185,330.0,0.92725307,-0.64123017,2.9067538,368.81961,-9.3153839
155.4929,0.10332696,9.0135412,0.0,0,5.002398,330.0,0.91764265,0.46854722,3.4540787,370.59995,-9.3148203
155.4951,0.054299176,8.9905605,0.0,0,5.4226766,330.0,0.91554195,0.35116413,3.8589547,372.23611,-9.3120613
155.4973,-0.098802775,8.988389,0.0,0,5.8429565,330.0,0.91362345,-0.49660373,4.2364783,372.25604,-9.3110285
155.4995,-0.038131829,9.0022888,0.0,0,6.2632351,330.0,0.91766459,-0.18716162,4.6106014,372.27594,-9.3114872
155.5017,-0.082591593,9.0304375,0.0,0,6.6835146,330.0,0.92026603,-0.40580684,4.9979906,372.29587,-9.311739
155.5039,-0.062006935,9.060729,0.0,0,7.1037941,330.0,0.92740887,-0.35369584,5.4023647,372.3158,-9.3122997
155.5061,-0.02596185,9.1136379,0.0,0,7.5240731,330.0,0.93424976,-0.1027182,5.8213644,371.61444,-9.3096685
155.5083,-0.14180458,9.1663055,0.0,0,7.9443526,330.0,0.94522494,-0.6863842,6.260191,370.26663,-9.3088007
155.5105,-0.047942892,9.2367163,0.0,0,8.3646317,330.0,0.95530832,-0.32794377,6.7089524,368.91879,-9.3087626
155.5127,0.049943808,9.3064337,0.0,0,8.7849102,330.0,0.96945196,0.26559734,7.1542506,367.57095,-9.3075333
155.5149,-0.096420027,9.39715,0.0,0,9.2051897,330.0,0.98346192,-0.36966482,7.5947323,366.22314,-9.306736
155.5171,-0.09142179,9.422204,0.0,0,9.6254692,330.0,0.99033731,-0.48355386,8.0234203,365.8049,-9.3063402
155.5193,-0.07874278,9.4145689,0.0,0,10.045749,330.0,0.98661655,-0.40215915,8.4537048,365.41266,-9.3057079
155.5215,0.031981282,9.4074392,0.0,0,10.466027,330.0,0.98755366,0.12738872,8.8836527,365.02042,-9.3066835
155.5237,-0.06791085,9.4305372,0.0,0,10.886307,330.0,0.98963642,-0.30005136,9.3162355,364.62814,-9.3078651
155.5259,-0.077019058,9.4287434,0.0,0,11.306585,330.0,0.99159479,-0.30237794,9.7524242,364.43335,-9.3077106
155.5281,-0.16949385,9.4386597,0.0,0,11.726865,330.0,0.99094248,-0.79919362,10.190551,364.51321,-9.3055496
155.5303,-0.068699948,9.4256716,0.0,0,12.147144,330.0,0.99095494,-0.40252411,10.639059,364.59305,-9.305315
155.5325,0.12166577,9.4272747,0.0,0,12.567424,330.0,0.98928815,0.53253067,11.079647,364.67288,-9.3048868
155.5347,-0.1380254,9.4303865,0.0,0,12.987702,330.0,0.99192065,-0.52110457,11.500907,364.75272,-9.3051577
155.5369,-0.16287655,9.4333048,0.0,0,13.407982,330.0,0.99007356,-0.77981955,11.908811,365.06799,-9.305953
155.5391,-0.031666473,9.4250402,0.0,0,13.82826,330.0,0.99085706,-0.19494447,12.324048,365.42041,-9.3054008
155.5413,-0.045870371,9.430603,0.0,0,14.248541,330.0,0.98998296,-0.1732264,12.745362,365.77283,-9.3056536
155.5435,-0.072198376,9.4258318,0.0,0,14.668819,330.0,0.99122941,-0.24674404,13.175954,366.12524,-9.3047237
155.5457,-0.11147042,9.4365902,0.0,0,15.089099,330.0,0.9907133,-0.49702409,13.613007,365.99844,-9.3047705
155.5479,-0.083984092,9.4281588,0.0,0,15.509378,330.0,0.99144113,-0.4432784,14.055065,364.80075,-9.304781
155.5501,0.068807751,9.4272738,0.0,0,15.929657,330.0,0.98915958,0.28024146,14.495541,363.60303,-9.3047256
155.5523,-0.031355303,9.4235582,0.0,0,16.349936,330.0,0.99061978,-0.017992113,14.928636,362.40533,-9.3045406
155.5545,-0.14111772,9.4296579,0.0,0,16.770216,330.0,0.98935431,-0.62839001,15.343654,361.20764,-9.3038454
155.5567,-0.06557633,9.4267159,0.0,0,17.190495,330.0,0.99124002,-0.37085131,15.75056,360.42184,-9.3043346
155.5589,-0.022248449,9.4308767,0.0,0,17.610775,330.0,0.98983419,-0.16849546,16.173388,359.76999,-9.304718
155.5611,-0.011043039,9.4225063,0.0,0,17.999401,330.0,0.99048227,-0.051833186,16.589546,359.11816,-9.3042011
155.5633,-0.11025144,9.4334087,0.0,0,18.0,330.0,0.99009395,-0.43035504,17.007879,358.46631,-9.3037891
155.5655,-0.10384095,9.4242525,0.0,0,18.0,330.0,0.99076486,-0.52433002,17.409939,357.90762,-9.3039665
155.5677,0.0045522181,9.4282894,0.0,0,18.0,330.0,0.98940951,-0.023614353,17.773317,357.72131,-9.3046322
155.5699,-0.094197944,9.4285927,0.0,0,18.0,330.0,0.9916504,-0.41841123,18.083639,357.535,-9.3071175
155.5721,-0.036533341,9.4369078,0.0,0,18.0,330.0,0.99055415,-0.16112156,18.319872,357.34869,-9.3090887
155.5743,-0.10288222,9.4312201,0.0,0,18.0,330.0,0.9919256,-0.42060384,18.46468,357.16238,-9.311202
155.5765,-0.10831024,9.4424658,0.0,0,18.0,330.0,0.99182248,-0.50887185,18.501968,356.1767,-9.3157949
155.5787,-0.021778012,9.4436703,0.0,0,18.0,330.0,0.99428219,-0.11869004,18.438948,354.75204,-9.3219366
155.5809,-0.048726868,9.4636307,0.0,0,18.0,330.0,0.99533415,-0.1955381,18.327822,353.32739,-9.3319874
155.5831,-0.01940868,9.4645233,0.0,0,18.0,330.0,0.99786562,-0.15048102,18.211958,351.90274,-9.3442001
155.5853,0.049204584,9.4823332,0.0,0,18.0,330.0,0.99911153,0.19673771,18.118984,350.4639,-9.3591557
155.5875,0.062634148,9.4942999,0.0,0,18.0,330.0,1.0033094,0.30725729,18.058928,348.88339,-9.3747921
155.5897,-0.0097564328,9.5186653,0.0,0,18.0,330.0,1.0053084,-0.011144148,18.041185,347.30289,-9.3918171
155.5919,-0.07988672,9.5284414,0.0,0,18.0,330.0,1.00963,-0.31945306,18.039015,345.72238,-9.4111414
155.5941,-0.15263513,9.5518694,0.0,0,18.0,330.0,1.0118747,-0.67126518,18.056108,344.14188,-9.427804
155.5963,-0.17960832,9.5647974,0.0,0,18.0,330.0,1.0164309,-0.78109747,18.079273,342.7113,-9.444911
155.5985,-0.14400347,9.5922098,0.0,0,18.0,330.0,1.0187675,-0.73056704,18.104815,341.41034,-9.4629259
155.6007,-0.056254823,9.5955677,0.0,0,18.0,330.0,1.0220253,-0.29974875,18.124763,340.10941,-9.4788799
155.6029,0.021014404,9.617897,0.0,0,18.0,330.0,1.0240351,0.061017483,18.142202,338.80844,-9.4967365
155.6051,0.058617365,9.6273241,0.0,0,18.0,330.0,1.0278022,0.26741469,18.148651,337.50748,-9.513196
155.6073,0.040535521,9.6521349,0.0,0,18.0,330.0,1.0296767,0.21568564,18.148153,337.22842,-9.5291376
155.6095,-0.04460673,9.6598864,0.0,0,18.0,330.0,1.0337359,-0.15300795,18.148211,336.96823,-9.5442934
155.6117,-0.13331516,9.6814518,0.0,0,18.0,330.0,1.0358114,-0.5013743,18.146233,336.70804,-9.5591459
155.6139,-0.16158755,9.6916952,0.0,0,18.0,330.0,1.0401237,-0.68821108,18.144617,336.44785,-9.5742235
155.6161,-0.1359643,9.7184391,0.0,0,18.0,330.0,1.0422617,-0.66217345,18.135756,336.22464,-9.5924644
155.6183,-0.088852391,9.7231331,0.0,0,18.0,330.0,1.0457982,-0.44665024,18.131649,336.05106,-9.6080265
155.6205,0.011947894,9.7467203,0.0,0,18.0,330.0,1.0482901,-0.01584724,18.133959,335.87747,-9.6245613
155.6227,0.065379746,9.7554379,0.0,0,18.0,330.0,1.0521078,0.28359416,18.129553,335.70392,-9.6393967
155.6249,0.062938377,9.7787981,0.0,0,18.0,330.0,1.0538397,0.27472681,18.127012,335.53033,-9.655282
155.6271,-0.012763383,9.7855854,0.0,0,18.0,330.0,1.0576599,-0.001765387,18.126184,334.6442,-9.671176
155.6293,-0.10877112,9.8086796,0.0,0,18.0,330.0,1.0600758,-0.4211852,18.119898,333.65421,-9.6858711
155.6315,-0.1563355,9.819026,0.0,0,18.0,330.0,1.0642192,-0.6581074,18.122072,332.66425,-9.7023296
155.6337,-0.14785793,9.847105,0.0,0,18.0,330.0,1.0669175,-0.67656302,18.113958,331.67426,-9.7181044
155.6359,-0.10550533,9.8501158,0.95955694,0,18.0,330.0,1.0701154,-0.51362526,18.112745,330.74805,-9.73386
155.6381,-0.024441473,9.870204,3.9747667,0,18.0,330.0,1.0718896,-0.1716696,18.113941,329.95847,-9.7507782
155.6403,0.064849444,9.8806849,6.9899764,0,18.0,330.0,1.0763395,0.23511508,18.111914,329.16888,-9.7677374
155.6425,0.078933492,9.9086246,10.005186,0,18.0,330.0,1.0789453,0.33345988,18.107124,328.3793,-9.7829447
155.6447,0.028073849,9.9154892,13.020396,0,18.0,330.0,1.082974,0.17028593,18.106165,327.58972,-9.799221
155.6469,-0.072654121,9.9368782,13.73291,0,18.0,330.0,1.085034,-0.23829508,18.110317,326.99945,-9.8155632
155.6491,-0.15443036,9.9476919,13.73291,0,18.0,330.0,1.0893904,-0.60364693,18.105,326.47083,-9.8314924
155.6513,-0.17374703,9.972167,13.73291,0,18.0,330.0,1.0915797,-0.75192231,18.106617,325.9422,-9.846735
155.6535,-0.11582766,9.9778223,13.73291,0,18.0,330.0,1.0952393,-0.50792187,18.104719,325.4136,-9.8624525
155.6557,-0.045969114,9.998601,14.519929,0,18.0,330.0,1.0973954,-0.24199432,18.103504,324.85001,-9.8791704
155.6579,0.012007714,10.006899,18.282911,0,18.0,330.0,1.101244,-0.0026325518,18.100496,324.15411,-9.894269
155.6601,0.074366421,10.031719,22.045893,0,18.0,330.0,1.1035722,0.2978296,18.103903,323.45819,-9.908968
155.6623,0.045506116,10.038661,25.808874,0,18.0,330.0,1.1073809,0.22435743,18.100836,322.7623,-9.9261656
155.6645,-0.033549704,10.060899,29.571854,0,18.0,330.0,1.109876,-0.068378769,18.103312,322.06641,-9.9424849
155.6667,-0.14408021,10.072568,30.871582,0,18.0,330.0,1.1144903,-0.5295791,18.09927,321.49271,-9.9582767
155.6689,-0.18208887,10.10108,30.871582,0,18.0,330.0,1.1174759,-0.74106342,18.098505,320.98346,-9.975625
155.6711,-0.14125775,10.10371,30.871582,0,18.0,330.0,1.1206993,-0.65221155,18.094414,320.47424,-9.9920216
155.6733,-0.061474349,10.127102,30.871582,0,18.0,330.0,1.1235256,-0.32465973,18.099304,319.965,-10.008425
155.6755,0.0095848078,10.134649,31.040287,0,18.0,330.0,1.127321,-0.042805277,18.097923,319.46512,-10.02293
155.6777,0.047134914,10.16115,32.726395,0,18.0,330.0,1.129908,0.18324879,18.093,319.04947,-10.039424
155.6799,0.054784764,10.168396,34.412498,0,18.0,330.0,1.1338944,0.22162771,18.094995,318.63385,-10.054913
155.6821,0.0010824404,10.189287,36.098606,0,18.0,330.0,1.1362494,0.049342394,18.097948,318.2182,-10.06974
155.6843,-0.10711318,10.201442,37.78471,0,18.0,330.0,1.1409441,-0.35974354,18.098728,317.80255,-10.086905
155.6865,-0.17261258,10.229119,38.551025,0,18.0,330.0,1.1439716,-0.66287589,18.095284,317.39023,-10.10247
155.6887,-0.15798977,10.233943,38.551025,0,18.0,330.0,1.1474519,-0.65316772,18.094246,316.98065,-10.11842
155.6909,-0.092633396,10.255501,38.551025,0,18.0,330.0,1.1501347,-0.43587124,18.095959,316.57108,-10.13592
155.6931,0.0024073464,10.262843,38.551025,0,18.0,330.0,1.1538019,-0.033469729,18.09231,316.1615,-10.151895
155.6953,0.040120352,10.288015,38.551025,0,18.0,330.0,1.1564697,0.11525584,18.093475,315.75192,-10.167855
155.6975,0.052778799,10.291706,39.980473,0,18.0,330.0,1.1597466,0.22742508,18.092108,314.92984,-10.182233
155.6997,0.026167687,10.315353,41.422947,0,18.0,330.0,1.1625985,0.16494615,18.091208,314.10397,-10.198023
155.7019,-0.048482217,10.326718,42.865425,0,18.0,330.0,1.1676731,-0.13041979,18.089952,313.27814,-10.214029
155.7041,-0.1557143,10.35836,44.307903,0,18.0,330.0,1.1714256,-0.54010302,18.088041,312.45227,-10.229795
155.7063,-0.18108892,10.360985,45.120853,0,18.0,330.0,1.1744148,-0.71940124,18.088339,311.59128,-10.246952
155.7085,-0.12258961,10.382908,45.120853,0,18.0,330.0,1.1772865,-0.5232833,18.086418,310.68484,-10.263099
155.7107,-0.023224697,10.388481,45.120853,0,18.0,330.0,1.1807359,-0.14015694,18.084497,309.77841,-10.279116
155.7129,0.044308156,10.415096,45.120853,0,18.0,330.0,1.1837543,0.12209885,18.081564,308.87198,-10.294579
155.7151,0.0481962,10.421391,45.120853,0,18.0,330.0,1.1876768,0.17937061,18.08329,307.96558,-10.309411
155.7173,0.028757123,10.44488,46.297207,0,18.0,330.0,1.1909012,0.15271293,18.082952,307.31375,-10.324152
155.7195,-0.023109742,10.454962,47.631138,0,18.0,330.0,1.1950694,-0.020228855,18.079754,306.69604,-10.339948
155.7217,-0.11805744,10.48155,48.965065,0,18.0,330.0,1.1984777,-0.38567403,18.081778,306.07834,-10.35831
155.7239,-0.18013634,10.488482,50.298992,0,18.0,330.0,1.2023406,-0.65849566,18.081783,305.46063,-10.374805
155.7261,-0.15974367,10.510992,51.196289,0,18.0,330.0,1.205387,-0.63890147,18.08049,304.98578,-10.391651
155.7283,-0.059233107,10.516834,51.196289,0,18.0,330.0,1.2088251,-0.29112291,18.079273,304.80447,-10.4079
155.7305,0.03216894,10.542563,51.196289,0,18.0,330.0,1.212055,0.07159432,18.075741,304.6232,-10.423193
155.7327,0.063128479,10.549461,51.196289,0,18.0,330.0,1.2160963,0.25230926,18.076263,304.44189,-10.437447
155.7349,0.039287206,10.571985,51.196289,0,18.0,330.0,1.219275,0.20003535,18.076515,304.26062,-10.452314
155.7371,-0.0042429613,10.580945,51.440483,0,18.0,330.0,1.2231232,0.010382504,18.077627,304.06326,-10.468253
155.7393,-0.09236636,10.609125,51.756477,0,18.0,330.0,1.2271054,-0.27454859,18.077944,303.86121,-10.485475
155.7415,-0.16430613,10.614801,52.072472,0,18.0,330.0,1.2308314,-0.55506974,18.078142,303.65915,-10.501627
155.7437,-0.18960829,10.638229,52.388466,0,18.0,330.0,1.2342422,-0.69106829,18.078476,303.45709,-10.517659
155.7459,-0.10102081,10.644865,52.635498,0,18.0,330.0,1.2379438,-0.43876266,18.075237,303.2153,-10.534151
155.7481,0.000291926,10.670274,52.635498,0,18.0,330.0,1.241239,-0.039911784,18.073668,302.83109,-10.54826
155.7503,0.067181066,10.674191,52.635498,0,18.0,330.0,1.2442354,0.19402641,18.078669,302.4469,-10.562289
155.7525,0.059191097,10.696559,52.635498,0,18.0,330.0,1.2476408,0.21671815,18.073292,302.06271,-10.580564
155.7547,0.012539108,10.707211,52.635498,0,18.0,330.0,1.2519958,0.068415992,18.073633,301.67853,-10.596659
155.7569,-0.057595573,10.733806,53.144596,0,18.0,330.0,1.2561067,-0.14243428,18.073664,301.07504,-10.612457
155.7591,-0.13445419,10.740799,53.911663,0,18.0,330.0,1.2598028,-0.45400316,18.073599,300.36041,-10.629398
155.7613,-0.18317166,10.762868,54.678734,0,18.0,330.0,1.263339,-0.63302165,18.067123,299.64578,-10.644617
155.7635,-0.1382587,10.771323,55.445805,0,18.0,330.0,1.2670434,-0.56254685,18.066772,298.93118,-10.661633
155.7657,-0.031913675,10.797503,56.12915,0,18.0,330.0,1.2712876,-0.1788014,18.069597,298.24304,-10.677061
155.7679,0.062514938,10.803056,56.12915,0,18.0,330.0,1.274387,0.20527567,18.06675,297.77112,-10.693673
155.7701,0.072727263,10.823674,56.12915,0,18.0,330.0,1.2778435,0.26220942,18.065788,297.29919,-10.709677
155.7723,0.038168069,10.835373,56.12915,0,18.0,330.0,1.2822739,0.15865964,18.063831,296.82727,-10.72539
155.7745,-0.030852184,10.862551,56.12915,0,18.0,330.0,1.2867532,-0.054710858,18.061071,296.35535,-10.74163
155.7767,-0.11621971,10.868274,56.300385,0,18.0,330.0,1.290254,-0.34191054,18.063066,296.11899,-10.758248
155.7789,-0.16936623,10.892003,56.609146,0,18.0,330.0,1.2942501,-0.55114192,18.061913,296.07178,-10.773078
155.7811,-0.14894071,10.899999,56.917904,0,18.0,330.0,1.2980472,-0.54937661,18.062511,296.0246,-10.790237
155.7833,-0.072833806,10.923514,57.226662,0,18.0,330.0,1.3017324,-0.34755215,18.06657,295.97742,-10.80556
155.7855,0.032665376,10.930122,57.535404,0,18.0,330.0,1.3051227,0.070160531,18.059938,295.93024,-10.819649
155.7877,0.073444448,10.952504,57.535404,0,18.0,330.0,1.3090302,0.26247698,18.063702,295.66055,-10.835591
155.7899,0.059824441,10.960546,57.535404,0,18.0,330.0,1.3125969,0.24278653,18.062309,295.3909,-10.851524
155.7921,-0.012490146,10.986293,57.535404,0,18.0,330.0,1.3168831,-0.0043547982,18.062805,295.12122,-10.868091
155.7943,-0.08156836,10.99329,57.535404,0,18.0,330.0,1.3208889,-0.25572592,18.060698,294.85156,-10.884241
155.7965,-0.15593681,11.017914,57.712723,0,18.0,330.0,1.3256453,-0.49459463,18.065245,294.50681,-10.899954
155.7987,-0.16922966,11.027302,58.110725,0,18.0,330.0,1.3292075,-0.57355571,18.064079,294.0686,-10.915453
155.8009,-0.092870884,11.050609,58.508732,0,18.0,330.0,1.3333688,-0.3672049,18.062681,293.63037,-10.930912
155.8031,-0.00087403005,11.053984,58.906742,0,18.0,330.0,1.3360374,-0.091775052,18.057812,293.19217,-10.947892
155.8053,0.071690857,11.073497,59.304745,0,18.0,330.0,1.3394542,0.20587738,18.064531,292.75397,-10.964905
155.8075,0.07563749,11.085824,59.348145,0,18.0,330.0,1.34396,0.26382267,18.058813,292.33377,-10.980156
155.8097,0.030927846,11.114174,59.348145,0,18.0,330.0,1.3496563,0.12548697,18.057985,291.91577,-10.994907
155.8119,-0.067952268,11.120149,59.348145,0,18.0,330.0,1.352972,-0.148812,18.05686,291.49777,-11.012028
155.8141,-0.14188476,11.145103,59.348145,0,18.0,330.0,1.3580818,-0.4308354,18.058828,291.0798,-11.028454
155.8163,-0.16209616,11.154872,59.471489,0,18.0,330.0,1.3616598,-0.55871874,18.057278,290.70264,-11.045998
155.8185,-0.1298787,11.176497,59.838142,0,18.0,330.0,1.3659223,-0.47329602,18.056072,290.40601,-11.060678
155.8207,-0.022818662,11.185053,60.204792,0,18.0,330.0,1.3698478,-0.15352793,18.053179,290.10938,-11.07703
155.8229,0.051011577,11.207519,60.571442,0,18.0,330.0,1.3743501,0.12970428,18.053244,289.81271,-11.092872
155.8251,0.077413082,11.215359,60.938095,0,18.0,330.0,1.3776156,0.25744975,18.055996,289.51608,-11.108764
155.8273,0.048682917,11.23954,61.01807,0,18.0,330.0,1.3823229,0.17401159,18.056097,289.10785,-11.124611
155.8295,-0.034198821,11.249143,61.01807,0,18.0,330.0,1.3866115,-0.051174305,18.051619,288.66849,-11.141574
155.8317,-0.12230582,11.269987,61.01807,0,18.0,330.0,1.3908597,-0.34337646,18.053055,288.22913,-11.157163
155.8339,-0.16531999,11.281581,61.01807,0,18.0,330.0,1.3951755,-0.51422805,18.05319,287.78973,-11.174486
155.8361,-0.1421037,11.307066,61.115128,0,18.0,330.0,1.4005775,-0.4743847,18.053452,287.35638,-11.189987
155.8383,-0.072098233,11.309505,61.54208,0,18.0,330.0,1.4028167,-0.27891839,18.055676,286.94348,-11.20635
155.8405,0.03651844,11.331271,61.969028,0,18.0,330.0,1.4077929,0.045228168,18.055462,286.53058,-11.220499
155.8427,0.081124246,11.342463,62.395985,0,18.0,330.0,1.4118987,0.2350319,18.054262,286.11768,-11.236616
155.8449,0.069324031,11.368139,62.822941,0,18.0,330.0,1.4175429,0.23738632,18.049713,285.70474,-11.251575
155.8471,-0.0052404483,11.373508,62.962646,0,18.0,330.0,1.4202062,0.026694568,18.05456,285.3782,-11.267516
155.8493,-0.094342485,11.397711,62.962646,0,18.0,330.0,1.4258308,-0.23373525,18.051146,285.09366,-11.283197
155.8515,-0.16184597,11.407899,62.962646,0,18.0,330.0,1.4295411,-0.46055904,18.051424,284.80911,-11.300311
155.8537,-0.16577777,11.433284,62.962646,0,18.0,330.0,1.4357743,-0.49841079,18.050905,284.52457,-11.316297
155.8559,-0.085601576,11.437936,61.328117,0,18.0,330.0,1.4380717,-0.30113924,18.050291,284.22562,-11.333571
155.8581,-0.0052642017,11.459266,47.503986,0,18.0,330.0,1.443153,-0.062686056,18.050079,283.81912,-11.349049
155.8603,0.073477566,11.466892,33.679855,0,18.0,330.0,1.4460605,0.17136393,18.047731,283.41263,-11.364756
156.6608,-0.050544411,11.58764,0.0,0,18.0,4.1213424e-09,1.4805952,-0.142831,18.001629,85.977905,-11.483314
157.7608,-0.051339198,11.586204,0.0,0,18.0,4.1162991e-24,1.4800563,-0.14457197,17.998816,27.957264,-11.482396
158.8608,-0.051970121,11.586867,0.0,0,18.0,4.1112612e-39,1.4805118,-0.15183122,17.999435,25.158319,-11.483094
159.9608,-0.053599067,11.586321,0.0,0,18.0,1.4012985e-45,1.4802716,-0.15374047,18.001043,24.961536,-11.483386
161.0608,-0.057156745,11.586042,0.0,0,18.0,1.4012985e-45,1.4803036,-0.16394697,17.999615,24.968279,-11.482653
162.1608,-0.056150999,11.586171,0.0,0,18.0,1.4012985e-45,1.4803101,-0.16073468,17.999849,25.126719,-11.482594
163.2608,-0.055042244,11.586716,0.0,0,18.0,1.4012985e-45,1.4802969,-0.15686436,18.000111,24.986979,-11.482724
164.3608,-0.052950729,11.586313,0.0,0,18.0,1.4012985e-45,1.4802098,-0.15486261,18.000408,24.87459,-11.482609
165.4608,-0.054475188,11.586394,0.0,0,18.0,1.4012985e-45,1.4801462,-0.16122104,17.999622,24.602049,-11.482828
166.5608,-0.057472061,11.586143,0.0,0,18.0,1.4012985e-45,1.4803238,-0.16485287,17.999424,24.468563,-11.483232
167.6608,-0.055503387,11.58665,0.0,0,18.0,1.4012985e-45,1.4804009,-0.15742932,17.999619,24.696795,-11.483447
168.7608,-0.054636884,11.586972,0.0,0,18.0,1.4012985e-45,1.4805576,-0.15674183,17.99943,24.456738,-11.483713
169.8608,-0.05638859,11.586849,0.0,0,18.0,1.4012985e-45,1.4804592,-0.1599227,18.00091,24.611753,-11.483995
170.9608,-0.059424795,11.587195,0.0,0,18.0,1.4012985e-45,1.4803759,-0.17131801,18.000393,24.483057,-11.483076
172.0608,-0.05599314,11.58742,0.0,0,18.0,1.4012985e-45,1.4805532,-0.16045001,18.000597,24.417944,-11.483436
173.1608,-0.058353338,11.587996,0.0,0,18.0,1.4012985e-45,1.480592,-0.16961607,18.000492,24.410969,-11.483496
174.2608,-0.055179957,11.587662,0.0,0,18.0,1.4012985e-45,1.4807898,-0.16173205,17.999361,24.543928,-11.483055
175.3608,-0.057681296,11.587282,0.0,0,18.0,1.4012985e-45,1.4805828,-0.16695754,17.999702,24.421581,-11.482457
176.4608,-0.061332367,11.586513,0.0,0,18.0,1.4012985e-45,1.480394,-0.17891751,17.999327,24.465521,-11.481594
177.5608,-0.058181144,11.586812,0.0,0,18.0,1.4012985e-45,1.4805197,-0.16686875,18.000431,24.41758,-11.482102
178.6608,-0.056178812,11.587237,0.0,0,18.0,1.4012985e-45,1.4804581,-0.16188996,17.999706,24.375593,-11.482264
179.7608,-0.055699375,11.587705,0.0,0,18.0,1.4012985e-45,1.4805984,-0.16306213,17.999397,24.339348,-11.48249
180.8608,-0.053193111,11.58774,0.0,0,18.0,1.4012985e-45,1.4805136,-0.15586014,17.998808,24.303787,-11.483143
181.9608,-0.058233771,11.58834,0.0,0,18.0,1.4012985e-45,1.4809555,-0.17344658,18.000433,24.063118,-11.483683
183.0608,-0.055267166,11.588626,0.0,0,18.0,1.4012985e-45,1.480971,-0.16236155,18.000086,23.97374,-11.483578
184.1608,-0.052656226,11.588643,0.0,0,18.0,1.4012985e-45,1.4810733,-0.1533305,17.998793,24.09446,-11.483639
185.2608,-0.05647397,11.58897,0.0,0,18.0,1.4012985e-45,1.4811467,-0.1654257,18.000416,24.016993,-11.484232
186.3608,-0.057047766,11.588644,0.0,0,18.0,1.4012985e-45,1.4809239,-0.16748314,18.00074,24.139036,-11.483824
187.4608,-0.057294816,11.588564,0.0,0,18.0,1.4012985e-45,1.4808782,-0.16589355,18.000671,24.050661,-11.483016
188.5608,-0.055813067,11.588908,0.0,0,18.0,1.4012985e-45,1.4808278,-0.16182715,18.000011,24.271193,-11.483165
189.6608,-0.057429582,11.588439,0.0,0,18.0,1.4012985e-45,1.4809475,-0.16710742,18.000809,24.137688,-11.482312
190.7608,-0.055773016,11.588772,0.0,0,18.0,1.4012985e-45,1.480886,-0.1640559,18.000149,23.929899,-11.482386
191.8608,-0.051638622,11.588263,0.0,0,18.0,1.4012985e-45,1.4809669,-0.15240775,18.000088,24.085611,-11.482531
192.9608,-0.056686997,11.588564,0.0,0,18.0,1.4012985e-45,1.4810628,-0.16490397,17.999643,24.033642,-11.482135
194.0608,-0.052378874,11.588995,0.0,0,18.0,1.4012985e-45,1.4810647,-0.15327874,17.999485,23.946424,-11.482631
195.1608,-0.052821305,11.589218,0.0,0,18.0,1.4012985e-45,1.4810951,-0.1542092,17.99935,24.023512,-11.482593
196.2608,-0.049914259,11.589628,0.0,0,18.0,1.4012985e-45,1.4810207,-0.14777757,17.999825,23.942932,-11.482507
197.3608,-0.051133957,11.589406,0.0,0,18.0,1.4012985e-45,1.4811242,-0.15239307,18.000343,23.725422,-11.482543
198.4608,-0.053431671,11.589355,0.0,0,18.0,1.4012985e-45,1.4809948,-0.1531612,17.99964,23.857092,-11.482768
199.5608,-0.053158373,11.589808,0.0,0,18.0,1.4012985e-45,1.4814326,-0.1560553,17.999489,23.906187,-11.482596
200.6608,-0.055343676,11.589724,0.0,0,18.0,1.4012985e-45,1.4812868,-0.16147839,18.000055,23.907915,-11.482047
201.7608,-0.050312888,11.58992,0.0,0,18.0,1.4012985e-45,1.4814068,-0.14778028,17.998859,23.799454,-11.482769
202.8608,-0.050393291,11.590497,0.0,0,18.0,1.4012985e-45,1.4815234,-0.14689155,18.000357,23.968502,-11.483188
203.9608,-0.047664739,11.591068,0.0,0,18.0,1.4012985e-45,1.481568,-0.14173666,17.999493,24.028236,-11.483285
205.0608,-0.050288368,11.591766,0.0,0,18.0,1.4012985e-45,1.4817966,-0.14665756,18.000067,23.775415,-11.483303
206.1608,-0.050990544,11.591778,0.0,0,18.0,1.4012985e-45,1.4816583,-0.14754607,18.000769,23.842026,-11.483505
207.2608,-0.048747953,11.591571,0.0,0,18.0,1.4012985e-45,1.4818337,-0.14198577,17.999588,23.856791,-11.483584
208.3608,-0.058681738,11.591884,0.0,0,18.0,1.4012985e-45,1.4818294,-0.17118937,17.999741,24.043808,-11.483623
209.4608,-0.050214816,11.592152,0.0,0,18.0,1.4012985e-45,1.4821399,-0.14710908,18.00004,23.93755,-11.483951
210.5608,-0.054775778,11.591902,0.0,0,18.0,1.4012985e-45,1.4820031,-0.15685365,17.999687,24.024637,-11.483424
211.6608,-0.055517577,11.592275,0.0,0,18.0,1.4012985e-45,1.4820986,-0.16003862,17.999403,24.079411,-11.483144
212.7608,-0.054179668,11.592266,0.0,0,18.0,1.4012985e-45,1.4820002,-0.15336585,17.999454,23.772848,-11.48309
213.8608,-0.056805886,11.592372,0.0,0,18.0,1.4012985e-45,1.4818842,-0.16298263,18.000278,23.919859,-11.483049
214.9608,-0.05594385,11.59213,0.0,0,18.0,1.4012985e-45,1.4819155,-0.16132383,18.000076,23.861401,-11.482552
215.8608,-0.058873478,11.592836,0.0,0,18.0,1.4012985e-45,1.4819974,-0.17097852,17.999496,23.805449,-11.482907