File: raw data/testID_0230.csv
Time(sec),Force(kN),Jaw(mm),PowAngle(deg),Power(W),Pram,PTemp,Strain,Stress(MPa),Stroke(mm),TC1(C),wedge(mm)
0.0,1.0641956,0.36180076,0.0,0,11.076097,0.0016614936,0.024430994,13.234362,11.075963,12.35861,-9.115819
1.2,1.0204768,-0.0044858516,0.0,0,11.076097,3.5158749,-0.00026170435,13.003837,11.075994,12.337968,-9.4822206
2.4,0.99529934,-0.0042657196,0.0,0,11.076097,7.1158752,-0.00031144335,12.667633,11.076686,12.371554,-9.4798098
3.6,0.97414637,-0.0042055058,0.0,0,11.076097,10.715878,-0.00028658047,12.393689,11.07667,12.365328,-9.4783573
4.8,0.95476544,-0.0042412993,10.839746,0,11.076097,14.315876,-0.00028854707,12.158423,11.076443,12.416805,-9.476182
6.0,0.94546837,-0.0037716071,28.895361,0,11.076097,17.915876,-0.00023702555,12.02933,11.075869,12.470061,-9.4746065
7.2,0.96301198,-0.0052465755,38.235271,0,11.076097,21.515875,-0.00031764456,12.275909,11.076291,14.185237,-9.4721937
8.4,0.97463286,-0.0083233044,41.198727,0,11.076097,25.115879,-0.00057711697,12.406919,11.076647,18.862959,-9.4700346
9.6,0.98117578,-0.010493779,40.728642,0,11.076097,28.715879,-0.00068983645,12.506458,11.075799,25.086443,-9.4678898
10.8,0.9628619,-0.012250986,39.24604,0,11.076097,32.315876,-0.00083219196,12.265513,11.075556,30.941605,-9.466424
12.0,0.94487172,-0.013212171,38.551029,0,11.076097,35.915882,-0.00087971287,12.0536,11.076513,35.610352,-9.4648609
13.2,0.93268257,-0.014073977,38.551022,0,11.076097,39.515884,-0.00092248648,11.884093,11.076235,39.236282,-9.4628592
14.4,0.92529809,-0.014684273,39.792599,0,11.076097,43.115887,-0.00099772529,11.780122,11.075845,42.196426,-9.4607544
15.6,0.92246431,-0.015735477,41.194637,0,11.076097,46.715889,-0.0010300245,11.767881,11.076298,45.396923,-9.4589682
16.8,0.91734546,-0.016844913,41.802975,0,11.076097,50.315887,-0.0011496175,11.695196,11.076217,48.916332,-9.45681
18.0,0.91983074,-0.018229378,42.396236,0,11.076097,53.915886,-0.0012175797,11.724879,11.076151,52.716,-9.4550066
19.2,0.90987295,-0.019561123,42.396236,0,11.076097,57.515892,-0.0012890345,11.612046,11.076719,56.699669,-9.4531689
20.4,0.90172458,-0.02020932,42.446129,0,11.076097,61.115891,-0.0013643501,11.506242,11.076408,60.519421,-9.4515181
21.6,0.90039635,-0.021581523,42.978512,0,11.076097,64.715881,-0.0014171761,11.485362,11.076823,64.228256,-9.449585
22.8,0.90442812,-0.022415103,42.978512,0,11.076097,68.315872,-0.0015149979,11.538158,11.076794,67.874031,-9.4473991
24.0,0.89081591,-0.023297666,43.278534,0,11.076097,71.915871,-0.0015463267,11.35328,11.077201,71.469589,-9.4456882
25.2,0.88642961,-0.024512302,43.544052,0,11.076097,75.515877,-0.0016188199,11.2953,11.075999,74.986969,-9.4435225
26.4,0.88871843,-0.025623931,43.927586,0,11.076097,79.115883,-0.0017266229,11.334412,11.076095,78.562927,-9.441411
27.6,0.88014305,-0.026554996,44.077145,0,11.076097,82.715874,-0.0017547976,11.218144,11.076161,82.354347,-9.4393148
28.8,0.87487638,-0.027266514,44.077145,0,11.076097,86.31588,-0.0018355501,11.165601,11.076203,85.944145,-9.437007
30.0,0.87349445,-0.028462308,44.601269,0,11.076097,89.915878,-0.0018894428,11.143825,11.076876,89.447617,-9.4351845
31.2,0.87963641,-0.030011443,44.604488,0,11.076097,93.515892,-0.0019759925,11.221222,11.076106,93.166138,-9.4333801
32.4,0.87868243,-0.030169671,44.604488,0,11.076097,97.115883,-0.0020347859,11.211182,11.076718,96.774734,-9.4313536
33.6,0.87116188,-0.031531189,44.786442,0,11.076097,100.7159,-0.0020847484,11.112952,11.075916,100.39696,-9.4295216
34.8,0.86264724,-0.032573506,45.009766,0,11.076097,104.31589,-0.0021922505,10.999728,11.076628,104.06303,-9.4271793
36.0,0.86972648,-0.033877213,44.87941,0,11.076097,107.91589,-0.002245235,11.084449,11.076351,107.78088,-9.4255733
37.2,0.86206627,-0.035811145,45.109062,0,11.076097,111.51589,-0.0023599467,11.011779,11.076487,111.39889,-9.4232244
38.4,0.86192584,-0.036142316,45.12085,0,11.076097,115.11589,-0.0024340178,10.99584,11.075989,114.91634,-9.4211702
39.6,0.8559081,-0.037464775,45.615231,0,11.076097,118.7159,-0.0024860189,10.918911,11.075706,118.28395,-9.4191704
40.8,0.85189575,-0.038308933,45.861237,0,11.076097,122.3159,-0.0025704014,10.876753,11.075978,121.78534,-9.4175968
42.0,0.85203928,-0.04020144,46.109619,0,11.076097,125.91589,-0.0026681377,10.874252,11.076122,125.3187,-9.4152288
43.2,0.85024858,-0.041517943,46.138012,0,11.076097,129.51601,-0.002741779,10.861852,11.076556,129.06317,-9.4132433
44.4,0.85503191,-0.042854451,46.404823,0,11.076097,133.11589,-0.0028818308,10.909813,11.07579,132.73445,-9.4111776
45.6,0.85316235,-0.044534154,46.565308,0,11.076097,136.71588,-0.0029635911,10.906893,11.076582,136.46864,-9.4090919
46.8,0.85479766,-0.045175914,46.581924,0,11.076097,140.31587,-0.0030193373,10.915174,11.076572,140.04556,-9.4074039
48.0,0.84592867,-0.047099788,46.581837,0,11.076097,143.91589,-0.0031204449,10.798075,11.075723,143.75972,-9.4051847
49.2,0.84439862,-0.048330471,46.959011,0,11.076097,147.51588,-0.0031933521,10.77944,11.076463,147.11942,-9.4032421
50.4,0.84309793,-0.049705014,47.05444,0,11.076097,151.11588,-0.0033261119,10.761578,11.076889,150.54001,-9.4013376
51.6,0.84802389,-0.051524263,47.504883,0,11.076097,154.71588,-0.00341681,10.834768,11.076661,154.21939,-9.3993664
52.8,0.84949744,-0.053297989,47.359417,0,11.076097,158.31589,-0.0035667005,10.850364,11.076294,158.08551,-9.3972321
54.0,0.84087771,-0.054659121,47.208717,0,11.076097,161.91589,-0.0036318013,10.739784,11.076556,161.84227,-9.3952856
55.2,0.83265215,-0.056239169,47.054596,0,11.076097,165.51588,-0.0037153305,10.651261,11.075829,165.53484,-9.393322
56.4,0.84091216,-0.05740973,47.279423,0,11.076097,169.11589,-0.0038413194,10.749167,11.076588,169.02034,-9.3913393
57.6,0.8380059,-0.059389722,47.504883,0,11.076097,172.71588,-0.0039333301,10.708642,11.076544,172.53987,-9.3892565
58.8,0.84205323,-0.061235961,47.342407,0,11.076097,176.31589,-0.0040868204,10.752551,11.076213,176.32368,-9.3871727
60.0,0.83867919,-0.062664039,47.504883,0,11.076097,179.91588,-0.0041586813,10.726206,11.076094,179.85414,-9.3852816
61.2,0.84279096,-0.064571664,47.504883,0,11.076097,183.51588,-0.0042549302,10.769132,11.076269,183.38751,-9.3832903
62.4,0.83872414,-0.066193938,47.504883,0,11.076097,187.11589,-0.0044240914,10.734801,11.076069,186.93498,-9.3813276
63.6,0.84797382,-0.068888761,47.586102,0,11.076097,190.71588,-0.0045883753,10.846374,11.076031,190.50874,-9.3793507
64.8,0.85008854,-0.07007762,47.606552,0,11.076097,194.31589,-0.0046810424,10.878368,11.075596,194.18695,-9.3771315
66.0,0.84554291,-0.072314382,47.542313,0,11.076097,197.91588,-0.0047931504,10.812521,11.076022,197.90817,-9.375452
67.2,0.83982539,-0.074134216,47.516647,0,11.076097,201.51588,-0.0048888819,10.73921,11.076534,201.46931,-9.3734026
68.4,0.84620947,-0.076392859,47.684143,0,11.076097,205.11589,-0.0051134159,10.827955,11.077089,205.10033,-9.3711958
69.6,0.85116577,-0.078938976,47.504887,0,11.076097,208.71588,-0.0052572004,10.890474,11.076128,208.70929,-9.369153
70.8,0.84945691,-0.080266275,47.954651,0,11.076097,212.31589,-0.0053460533,10.885478,11.076002,212.10164,-9.3673868
72.0,0.83743995,-0.082317032,47.14817,0,11.076097,215.91589,-0.0054623019,10.722564,11.076257,216.32486,-9.3654327
73.2,0.83380675,-0.083958715,47.504883,0,11.076097,219.51588,-0.0055451617,10.68195,11.076714,219.4794,-9.3635159
74.4,0.85819322,-0.086082354,47.955318,0,11.076097,223.11589,-0.0057516452,10.984824,11.074586,222.62932,-9.3613558
75.6,0.86423618,-0.088078521,48.168545,0,11.076097,226.7159,-0.0058677634,11.076875,11.075993,226.26563,-9.3593254
76.8,0.86657196,-0.090353251,48.0867,0,11.076097,230.31589,-0.0059931092,11.095829,11.075838,230.09999,-9.3573465
78.0,0.86703819,-0.092682071,47.960529,0,11.076097,233.91589,-0.0061678686,11.113163,11.075791,233.86555,-9.3554811
79.2,0.8710655,-0.094780765,48.203186,0,11.076097,237.51591,-0.0062727123,11.165653,11.075934,237.39807,-9.3533707
80.4,0.87867051,-0.097738631,48.011154,0,11.076097,241.11589,-0.0065107504,11.264601,11.07597,241.11301,-9.3513708
81.6,0.88098693,-0.099180199,48.007801,0,11.076097,244.7159,-0.0065881968,11.295268,11.076934,244.72647,-9.3493662
82.8,0.8783834,-0.10186007,47.955326,0,11.076097,248.31589,-0.0067363461,11.262657,11.076069,248.38229,-9.3476152
84.0,0.87418711,-0.10444913,47.955326,0,11.076097,251.91591,-0.0069659152,11.222096,11.076495,252.11528,-9.3453779
85.2,0.87563646,-0.10645685,47.94149,0,11.076097,255.51588,-0.0070713018,11.23261,11.076605,255.76212,-9.3435583
86.4,0.88458151,-0.10946737,47.681946,0,11.076097,259.11615,-0.0072735236,11.331758,11.075943,259.32541,-9.3414736
87.6,0.89407992,-0.11179131,47.955318,0,11.076097,262.71594,-0.007408421,11.466817,11.076424,262.66556,-9.3396034
88.8,0.88822925,-0.11400633,47.955318,0,11.076097,266.31592,-0.0075285039,11.391187,11.076331,266.19275,-9.3373795
90.0,0.88066757,-0.1163913,47.955326,0,11.076097,269.91589,-0.0077558206,11.299412,11.076449,269.77875,-9.3351946
91.2,0.89442772,-0.1191387,48.13644,0,11.076097,273.51587,-0.0079282811,11.486644,11.076958,273.35791,-9.3337622
92.4,0.89272916,-0.12191162,47.982769,0,11.076097,277.11588,-0.0080893971,11.457432,11.075787,277.1546,-9.3317242
93.6,0.90004683,-0.12408859,47.955326,0,11.076097,280.71585,-0.0082375379,11.535354,11.075989,280.76889,-9.3296824
94.8,0.90942055,-0.12730321,47.955326,0,11.076097,284.31589,-0.0084159588,11.679378,11.075488,284.34796,-9.327405
96.0,0.91027623,-0.12838158,48.014172,0,11.076097,287.91589,-0.0085583907,11.695141,11.075488,287.8432,-9.3257475
97.2,0.91276932,-0.13121569,48.100609,0,11.076097,291.5159,-0.0087118428,11.727554,11.075838,291.47131,-9.3235254
98.4,0.90888339,-0.13370045,47.957397,0,11.076097,295.11588,-0.0088561745,11.681119,11.076244,295.18051,-9.321681
99.6,0.90969384,-0.13616915,48.05817,0,11.076097,298.71591,-0.0090481555,11.680211,11.076372,298.7063,-9.3198967
100.8,0.92114067,-0.13886319,48.072414,0,11.076097,302.31589,-0.0091987737,11.828848,11.07676,302.30203,-9.3177643
102.0,0.91918141,-0.14178312,47.955326,0,11.076097,305.91586,-0.0094269207,11.796929,11.076283,306.02097,-9.3155909
103.2,0.9242363,-0.14339006,47.955326,0,11.076097,309.5159,-0.0095048081,11.877667,11.076237,309.76132,-9.313817
104.4,0.92219877,-0.14606623,47.894764,0,11.076097,313.11588,-0.0096553313,11.851197,11.076546,313.32297,-9.3118582
105.6,0.92821461,-0.14822054,47.569115,0,11.076097,316.71591,-0.0098630115,11.951969,11.07542,316.87906,-9.310008
106.8,0.92696053,-0.15082616,47.729034,0,11.076097,320.31592,-0.010012765,11.923017,11.076571,320.40228,-9.3080273
108.0,0.93988186,-0.15405726,47.955246,0,11.076097,323.91592,-0.010227071,12.087204,11.076128,323.88171,-9.3057785
109.2,0.93128932,-0.15533943,47.955318,0,11.076097,327.5159,-0.0102868,11.980466,11.076899,327.49545,-9.3038645
110.4,0.93568778,-0.15832295,47.955318,0,11.076097,331.11591,-0.010464814,12.034923,11.076021,331.02634,-9.3018255
111.6,0.92190564,-0.16006085,47.959042,0,11.076097,334.71588,-0.010641269,11.868378,11.076442,334.53214,-9.2997036
112.8,0.93988985,-0.16256444,48.232872,0,11.076097,338.31589,-0.010782327,12.080444,11.076162,338.11365,-9.297822
114.0,0.94854504,-0.1648351,47.955326,0,11.076097,341.91592,-0.010927551,12.21268,11.076105,341.89685,-9.2959709
115.2,0.93969089,-0.16714498,47.955326,0,11.076097,345.5159,-0.011074459,12.09462,11.076204,345.57623,-9.2936401
116.4,0.9369365,-0.16994438,47.737019,0,11.076097,349.11591,-0.011234239,12.07015,11.075849,349.39746,-9.2916832
117.6,0.93933666,-0.17246792,47.729771,0,11.076097,352.71591,-0.011456466,12.086219,11.07671,352.85464,-9.2897348
118.8,0.95451945,-0.17396277,47.627357,0,11.076097,356.31592,-0.011525593,12.294484,11.076964,356.4733,-9.2874918
120.0,0.93849719,-0.17671056,47.504887,0,11.076097,359.91592,-0.01168458,12.091586,11.076423,360.10364,-9.2857122
121.2,0.93822598,-0.17873105,47.504887,0,11.076097,363.51593,-0.011870261,12.086126,11.076719,363.56897,-9.2837591
122.4,0.95675278,-0.18205634,47.504887,0,11.076097,367.11594,-0.012065813,12.323344,11.076053,367.25977,-9.2818689
123.6,0.94722372,-0.18311121,47.504887,0,11.076097,370.71594,-0.012143265,12.191889,11.075984,370.76715,-9.2798157
124.8,0.94901299,-0.18514696,47.504887,0,11.076097,374.31592,-0.012252293,12.233183,11.076772,374.45755,-9.2777901
126.0,0.93059987,-0.18785498,47.054447,0,11.076097,377.91592,-0.012405233,12.004715,11.076829,378.25165,-9.2757683
127.2,0.94796884,-0.19027528,47.504883,0,11.076097,381.51593,-0.012639896,12.230321,11.076406,381.51688,-9.2739906
128.4,0.93739814,-0.19179425,47.496628,0,11.076097,385.11594,-0.012710639,12.092075,11.076193,385.12393,-9.27178
129.6,0.92168766,-0.19375099,47.054447,0,11.076097,388.71594,-0.012826611,11.886056,11.076303,388.87775,-9.2696466
130.8,0.91569364,-0.195307,47.441578,0,11.076097,392.31595,-0.012933271,11.820951,11.075673,392.27838,-9.2678423
132.0,0.92129862,-0.19898623,47.058094,0,11.076097,395.91589,-0.013162346,11.880319,11.076456,396.01605,-9.2656403
133.2,0.91790479,-0.19875093,47.195271,0,11.076097,399.51593,-0.01318782,11.854004,11.076154,399.54016,-9.2638111
134.4,0.90405029,-0.20094225,47.308933,0,11.076097,403.11591,-0.013309154,11.67036,11.075753,403.10498,-9.2618599
135.6,0.89754903,-0.20271438,47.072723,0,11.076097,406.71591,-0.01339695,11.583144,11.076282,406.80463,-9.2599354
136.8,0.8951354,-0.20462167,47.165249,0,11.076097,410.31592,-0.013569911,11.545563,11.075806,410.31458,-9.257843
138.0,0.89515144,-0.20498966,47.056854,0,11.076097,413.91589,-0.013572865,11.548263,11.075546,414.02945,-9.2558441
139.2,0.87907654,-0.20627736,47.054447,0,11.076097,417.5159,-0.013670838,11.344106,11.076044,417.62082,-9.2539988
140.4,0.87327898,-0.20732184,47.169483,0,11.076097,421.11591,-0.01371331,11.273649,11.075904,421.04944,-9.2521696
141.6,0.86299133,-0.2084758,47.075016,0,11.076097,424.71591,-0.013773016,11.128804,11.077235,424.68948,-9.2502508
142.8,0.8654511,-0.21024399,47.054447,0,11.076097,428.31592,-0.013951361,11.169232,11.077186,428.5242,-9.2479887
144.0,0.84537315,-0.20969467,46.582035,0,11.076097,431.91589,-0.013899719,10.920483,11.075964,432.32599,-9.245656
145.2,0.83054405,-0.21042433,46.838287,0,11.076097,435.5159,-0.013935777,10.725677,11.076788,435.59796,-9.2438354
146.4,0.81683248,-0.21068941,46.582062,0,11.076097,439.11591,-0.013941694,10.548508,11.076128,439.24762,-9.2419863
147.6,0.79992682,-0.21125901,46.582458,0,11.076097,442.71591,-0.013952659,10.318989,11.076183,442.88129,-9.239954
148.8,0.80471039,-0.21193182,46.803562,0,11.076097,446.31592,-0.014051184,10.38551,11.076183,446.2785,-9.2380295
150.0,0.80024135,-0.21120569,46.582035,0,11.076097,449.91412,-0.01398503,10.33568,11.076912,450.04407,-9.2358551
151.2,0.29133508,-0.22380766,44.077168,0,11.076097,449.9989,-0.014790102,3.7616241,11.076318,452.05875,-9.2360573
152.4,0.29166323,-0.22295377,45.120785,0,11.076097,449.9989,-0.014775376,3.7734067,11.076612,450.35342,-9.2361231
153.6,0.3061468,-0.22382078,45.615288,0,11.076097,449.9989,-0.014812491,3.9614506,11.076044,449.84045,-9.2356901
154.8,0.3177543,-0.22520524,45.001118,0,11.076097,449.9989,-0.014913146,4.1101255,11.076876,450.60925,-9.2360449
156.0,0.30883342,-0.22590543,44.604496,0,11.076097,449.9989,-0.014932743,3.9863949,11.076991,450.61728,-9.23559
157.2,0.33120885,-0.227283,44.604496,0,11.076097,449.9989,-0.015006925,4.2762718,11.076877,450.44998,-9.2357416
158.4,0.32214305,-0.22657792,44.259518,0,11.076097,449.9989,-0.015021122,4.1697254,11.075774,450.35776,-9.2355442
159.6,0.32744369,-0.22732462,44.077171,0,11.076097,449.9989,-0.015054537,4.2314491,11.075381,450.33371,-9.2353249
160.8,0.32771322,-0.22866444,43.540134,0,11.076097,449.9989,-0.015112896,4.2477689,11.075786,450.5795,-9.2356415
162.0,0.32843158,-0.22869964,43.527836,0,11.076097,449.9989,-0.015142525,4.2466879,11.076385,450.5484,-9.2357025
163.2,0.3258166,-0.22946148,43.527836,0,11.076097,449.9989,-0.015166746,4.2134829,11.075845,450.39856,-9.2355175
164.4,0.32484293,-0.22995475,42.978592,0,11.076097,449.9989,-0.015225607,4.2001667,11.075994,450.45667,-9.2355862
165.6,0.3313939,-0.23050104,42.978519,0,11.076097,449.9989,-0.0152447,4.2785921,11.075329,450.22009,-9.2353354
166.8,0.33106318,-0.23181228,42.978535,0,11.076097,449.9989,-0.015298682,4.2831926,11.076888,450.23929,-9.2356062
168.0,0.34008375,-0.23283422,42.978519,0,11.076097,449.9989,-0.015431826,4.3952031,11.076093,450.20227,-9.2352705
169.2,0.33724448,-0.23320337,42.978519,0,11.076097,449.9989,-0.015438152,4.3698716,11.075981,450.20828,-9.2352161
170.4,0.34483108,-0.23296617,42.68631,0,11.076097,449.9989,-0.015410917,4.4576559,11.076429,450.28104,-9.2355585
171.6,0.34667554,-0.23312874,42.75753,0,11.076097,449.9989,-0.015436423,4.5001783,11.075971,450.09134,-9.2355165
172.8,0.33815199,-0.23382814,42.396492,0,11.076097,449.9989,-0.015458547,4.3686299,11.076461,450.18799,-9.2355003
174.0,0.33960286,-0.23413855,42.396244,0,11.076097,449.9989,-0.015497142,4.3982377,11.076749,450.11948,-9.2354555
175.2,0.3388752,-0.23484485,42.396244,0,11.076097,449.9989,-0.015523278,4.3932161,11.075951,450.29807,-9.2352457
176.4,0.34353906,-0.23552044,42.27515,0,11.076097,449.9989,-0.015535815,4.4447355,11.076197,450.27029,-9.2353773
177.6,0.33908284,-0.23548536,41.889282,0,11.076097,449.9989,-0.015610492,4.3902698,11.076362,450.21603,-9.2353086
178.8,0.33819988,-0.23619492,42.15443,0,11.076097,449.9989,-0.015627027,4.3757458,11.076627,450.09512,-9.2352629
180.0,0.33967397,-0.23663478,41.924706,0,11.076097,449.9989,-0.015629537,4.3945565,11.075949,450.1402,-9.2351789
181.2,0.34259039,-0.23671526,41.802982,0,11.076097,449.9989,-0.015676146,4.4236374,11.076352,450.21994,-9.2353954
182.4,0.33557713,-0.23761493,41.201942,0,11.076097,449.9989,-0.01571336,4.3344059,11.076159,450.33557,-9.2350931
183.6,0.34370741,-0.23782073,41.39922,0,11.076097,449.9989,-0.015734628,4.4434376,11.076529,450.2092,-9.2353754
184.8,0.34243312,-0.23839085,41.608612,0,11.076097,449.9989,-0.015764907,4.4302373,11.077266,450.09534,-9.2352962
186.0,0.34917644,-0.23877551,41.370937,0,11.076097,449.9989,-0.015762575,4.5111575,11.076646,450.12363,-9.2353535
187.2,0.35026157,-0.23882027,41.74342,0,11.076097,449.9989,-0.015821885,4.5081315,11.07722,450.0162,-9.2355003
188.4,0.33788189,-0.23970298,41.198734,0,11.076097,449.9989,-0.015853481,4.3725266,11.075686,450.15521,-9.234992
189.6,0.34448242,-0.24014582,41.408909,0,11.076097,449.9989,-0.015842093,4.4401865,11.076878,449.98541,-9.2353172
190.8,0.35442224,-0.24027781,41.198883,0,11.076097,449.9989,-0.015918629,4.5789003,11.076083,450.06604,-9.235157
192.0,0.35110986,-0.24084508,41.198734,0,11.076097,449.9989,-0.01593275,4.5444951,11.076171,450.07376,-9.2349291
193.2,0.35912678,-0.24148321,41.198734,0,11.076097,449.9989,-0.015952324,4.6512952,11.076295,450.27014,-9.2349262
194.4,0.33951342,-0.24199702,40.798958,0,11.076097,449.9989,-0.016016107,4.4017239,11.07587,450.24481,-9.2347183
195.2849,0.3896912,-0.00071102666,41.19873,0,11.076099,3.2081649,-6.6432629e-05,4.9868879,11.076874,450.16174,-9.2347565
195.2873,0.41548678,0.0034560072,41.19873,0,11.076099,1.3868889000000002e-16,3.2956821e-05,5.3794641,11.078838,450.16895,-9.2351027
195.2897,0.4172748,0.0041815359,39.550755,0,11.076099,5.9955178e-33,0.00013853291,5.3355989,11.076982,450.17252,-9.2344322
195.2921,0.42085871,0.0034957952,29.663057,0,11.076099,0.0,0.00032134782,5.3931413,11.076912,450.15814,-9.2344065
195.2945,0.48342597,0.004245806,19.775364,0,11.076099,0.0,0.00046895881,6.1834908,11.078113,450.14377,-9.2337894
195.2969,0.40962267,0.0040424918,9.8876667,0,11.076099,0.0,0.00040094735,5.2181001,11.077278,450.12939,-9.2337513
195.2993,0.4108012,0.0040784301,0.0,0,11.076099,0.0,0.00019370748,5.2235084,11.080291,450.11502,-9.2343969
195.3017,0.41813996,0.0066781165,0.0,0,11.076099,0.0,0.00018351487,5.3770037,11.076888,450.15094,-9.2343254
195.3041,0.43488696,0.0069259377,0.0,0,11.076099,0.0,0.00032164835,5.5617056,11.072914,450.18686,-9.233654
195.3065,0.42491448,0.0048086238,0.0,0,11.076099,0.0,0.00046752265,5.3346844,11.077199,450.22281,-9.2337484
195.3089,0.41360304,0.0027934597,0.0,0,11.076099,0.0,0.00041178256,5.2765403,11.073461,450.25873,-9.2332954
195.3113,0.41739249,0.0010605245,0.0,0,11.076099,0.0,0.00010879986,5.3207693,11.075022,450.26471,-9.2341337
195.3137,0.43765458,0.0028978311,0.0,0,11.076099,0.0,7.0753369e-05,5.4650507,11.073667,450.26471,-9.234539
195.3161,0.43393806,0.0042189206,0.0,0,11.076099,0.0,0.0001454848,5.5089841,11.074766,450.26471,-9.2345858
195.3185,0.4266167,0.0038856803,0.0,0,11.076099,0.0,0.00027708145,5.5153646,11.074263,450.26471,-9.2349653
195.3209,0.41149229,0.0037694024,0.0,0,11.076099,0.0,0.00040063812,5.3012295,11.076819,450.25513,-9.2355175
195.3233,0.42049545,0.0028324365,0.0,0,11.076099,0.0,0.00035358008,5.3372903,11.076817,450.24075,-9.2343416
195.3257,0.44953096,0.003850397,0.0,0,11.076099,0.0,0.00025414056,5.6412282,11.074739,450.22638,-9.2361679
195.3281,0.43738377,0.0072647226,0.0,0,11.076099,0.0,0.00025484798,5.5548387,11.076675,450.21201,-9.2350512
195.3305,0.43227017,0.0093765901,0.0,0,11.076099,0.0,0.0004156082,5.4933906,11.078038,450.20123,-9.2346697
195.3329,0.43191704,0.0071471846,0.0,0,11.076099,0.0,0.00052117178,5.539959,11.076576,450.19406,-9.2351151
195.3353,0.44186503,0.0046071396,0.0,0,10.976469,0.0,0.00053336087,5.6422319,11.076973,450.18686,-9.23522
195.3377,0.45308948,0.0023261667,0.0,0,10.615495,0.0,0.00035266104,5.7333655,11.078745,450.17969,-9.2351446
195.3401,0.43833104,0.004086717,0.0,0,10.254521,0.0,0.00026723213,5.6296396,11.058862,450.16052,-9.2357197
195.3425,0.45644465,0.005011322,0.0,0,9.893548,0.0,0.00023602704,5.8584666,10.930665,450.1174,-9.2355862
195.3449,0.42809796,0.0060161399,0.0,0,9.5325737,0.0,0.00032134546,5.3494716,10.654846,450.07428,-9.2350588
195.3473,0.48688179,0.0039415476,0.0,0,9.1800261,0.0,0.00035551135,6.2179084,10.257473,450.03116,-9.2347479
195.3497,3.6373641,0.1130466,0.0,0,8.8288584,0.0,0.0074659991,43.927387,9.7822952,449.95093,-9.2337713
195.3521,4.525476,0.62668955,0.0,0,8.4910259,0.0,0.042550426,56.099079,9.2135849,449.68503,-9.2312813
195.3545,4.5769348,1.0857284,0.0,0,8.1570415,0.0,0.074210756,54.086292,8.7789354,449.41916,-9.2315531
195.3569,5.0314779,1.4410067,0.0,0,7.8342957,0.0,0.10015541,58.141483,8.4171362,449.15326,-9.2304802
195.3593,5.0556526,1.7173405,0.0,0,7.5165353,0.0,0.12125641,56.696259,8.0940075,448.88739,-9.2296419
195.3617,5.1894011,2.0085442,0.0,0,7.2082515,0.0,0.1435363,57.421825,7.8011379,448.57837,-9.2304964
195.3641,5.2492585,2.2826409,0.0,0,6.9060431,0.0,0.16512387,56.62439,7.5335355,448.26938,-9.2298822
195.3665,5.5257564,2.5398901,0.0,0,6.6115613,0.0,0.18519473,58.317642,7.2630324,447.96036,-9.2302437
195.3689,5.7271314,2.8152919,0.0,0,6.3240418,0.0,0.2072227,59.165184,6.9816518,447.65137,-9.2300568
195.3713,5.9195495,3.1061163,0.0,0,6.042748,0.0,0.23144417,59.913216,6.6927047,447.67172,-9.2300129
195.3737,6.1048937,3.4037271,0.0,0,5.7692914,0.0,0.256984,60.087936,6.3972988,447.75797,-9.2297516
195.3761,6.31247,3.6966529,0.0,0,5.5006137,0.0,0.2827282,60.521881,6.0982418,447.84418,-9.2303534
195.3785,6.5354266,3.9900777,0.0,0,5.2404532,0.0,0.30913782,61.053482,5.800467,447.93042,-9.2312469
195.3809,6.7735877,4.2815742,0.0,0,4.9838042,0.0,0.33566028,61.603542,5.5093246,447.31668,-9.2296896
195.3833,6.9640727,4.5704813,0.0,0,4.7363639,0.0,0.36255565,61.705353,5.2197738,446.353,-9.2294512
195.3857,7.1398091,4.845809,0.0,0,4.4912457,0.0,0.38927427,61.58633,4.9485006,445.38928,-9.2306566
195.3881,7.34236,5.1025195,0.0,0,4.2558532,0.0,0.41549248,61.644302,4.6852002,444.42557,-9.2313976
195.3905,7.5536098,5.3453231,0.0,0,4.0217257,0.0,0.44074431,61.874416,4.4395275,443.1705,-9.2318115
195.3929,7.7480893,5.5786295,0.0,0,3.7978494,0.0,0.46509233,61.99118,4.2008142,441.62405,-9.2297468
195.3953,7.9570379,5.8118095,0.0,0,3.5743496,0.0,0.48956424,62.098339,3.9657381,440.07764,-9.2299871
195.3977,8.1403856,6.0403891,0.0,0,3.3612847,0.0,0.51427829,61.95623,3.7425702,438.53119,-9.2291174
195.4001,8.3695335,6.2568979,0.0,0,3.1483088,0.0,0.53919929,62.020321,3.5242336,436.80887,-9.2302685
195.4025,8.6192007,6.4715071,0.0,0,2.9451065,0.0,0.56455851,62.338161,3.3089738,434.73474,-9.2294302
195.4049,8.8271418,6.6831508,0.0,0,2.7424984,0.0,0.58992434,62.310692,3.1014271,432.66064,-9.2282257
195.4073,9.0406685,6.8932242,0.0,0,2.5483873,0.0,0.61518949,62.220325,2.8908522,430.58652,-9.2296762
195.4097,9.3059788,7.1050839,0.0,0,2.3556671,0.0,0.64097142,62.344482,2.6821361,428.46301,-9.2309589
195.4121,9.5698633,7.3145676,0.0,0,2.1702483,0.0,0.66743618,62.489101,2.4819458,426.09256,-9.2299662
195.4145,9.8424177,7.5116673,0.0,0,1.9869361,0.0,0.6939522,62.54641,2.2823861,423.72211,-9.229394
195.4169,10.093596,7.7035508,0.0,0,1.8098084,0.0,0.72078836,62.535603,2.0898466,421.35168,-9.2282581
195.4193,10.354984,7.8867426,0.0,0,1.6354244,0.0,0.74641752,62.4706,1.9046453,418.98123,-9.2286406
195.4217,10.647913,8.0676146,0.0,0,1.4662173,0.0,0.77149874,62.642654,1.7255508,418.39722,-9.2289801
195.4241,10.966763,8.2507687,0.0,0,1.3003293,0.0,0.79766273,62.879059,1.542892,417.8132,-9.2281885
195.4265,11.266918,8.4272165,0.0,0,1.1387084,0.0,0.82409406,62.893921,1.3685133,417.22919,-9.2288485
195.4289,11.570518,8.5967636,0.0,0,0.98093235,0.0,0.85084581,62.899078,1.196968,416.64517,-9.2280264
195.4313,11.914982,8.7604971,0.0,0,0.82657731,0.0,0.87750334,63.044285,1.0295079,413.84378,-9.2280903
195.4337,12.276456,8.9190149,0.0,0,0.67652941,0.0,0.90328187,63.301479,0.86757803,410.59894,-9.2282696
195.4361,12.628984,9.075161,0.0,0,0.52908593,0.0,0.9283486,63.490513,0.71325016,407.35406,-9.2266026
195.4385,12.996169,9.230238,0.0,0,0.3862859,0.0,0.95405519,63.689007,0.56076396,404.10919,-9.2267551
195.4409,11.308537,9.3138943,0.0,0,0.24542016,0.0,0.96915376,54.548233,0.45134163,401.91095,-9.2291508
195.4433,10.069838,9.3232641,0.0,0,0.10962815,0.0,0.97228956,48.587669,0.39640194,400.23602,-9.2294464
195.4457,9.5097361,9.3180494,0.0,0,-0.025516368,0.0,0.97182661,45.800514,0.36093727,398.5611,-9.2305231
195.4481,9.1071596,9.3209944,0.0,0,-0.15794842,0.0,0.97190082,43.881592,0.33351028,396.88617,-9.2311659
195.4505,8.9934244,9.3254261,0.0,0,-0.29038045,0.0,0.97151464,43.334476,0.29579893,397.332,-9.2301149
195.4529,9.2017488,9.3360977,0.0,0,-0.42281243,0.0,0.9729709,44.264286,0.24786294,399.89862,-9.2325916
195.4553,9.4480839,9.3409348,0.0,0,-0.55524439,0.0,0.97453368,45.33392,0.17973121,402.46521,-9.2311325
195.4577,9.5042963,9.3450785,0.0,0,-0.68767637,0.0,0.9759981,45.626129,0.11145414,405.03183,-9.231348
195.4601,9.4393635,9.3488598,0.0,0,-0.82010835,0.0,0.97713524,45.225262,0.04742875,407.20508,-9.2318439
195.4625,9.2730103,9.3528128,0.0,0,-0.9525404,0.0,0.97724903,44.465816,0.0017040607,408.59158,-9.2320852
195.4649,8.9838886,9.3614283,0.0,0,-1.0849724,0.0,0.97760528,43.084183,-0.028628122,409.97812,-9.2320814
195.4673,8.6131229,9.3688908,0.0,0,-0.72870702,450.0,0.9785378,41.269917,-0.042003527,411.36465,-9.2314291
195.4697,8.1959524,9.3694382,2.3014545,0,-0.27022067,450.0,0.9793207,39.182175,-0.040711712,412.6235,-9.2326288
195.4721,7.8339663,9.3631334,16.109951,0,0.18826568,450.0,0.97961533,37.514297,-0.037674706,413.24408,-9.2317648
195.4745,7.5469966,9.3588314,29.918449,0,0.64675206,450.0,0.97902262,36.140072,-0.030369408,413.86469,-9.2328281
195.4769,7.3320322,9.3576584,43.726944,0,1.1052387,450.0,0.97779489,35.168427,-0.03000815,414.48526,-9.2321358
195.4793,6.8774915,9.3626099,57.535404,0,1.563725,450.0,0.97773337,32.996475,-0.014345589,415.10583,-9.2318707
195.4817,5.5262232,9.3591375,57.535404,0,2.0222113,450.0,0.97735137,26.643024,0.058774997,415.50961,-9.2335653
195.4841,3.1707981,9.3417559,57.535404,0,2.4806981,450.0,0.97517544,15.386481,0.20753111,415.91336,-9.2350435
195.4865,0.84062904,9.3234901,57.535404,0,2.9391842,450.0,0.97250837,4.3387961,0.42690668,416.31711,-9.2378168
195.4889,-0.4720926,9.2730093,57.535404,0,3.3976707,450.0,0.96337724,-2.2111411,0.89590061,416.72089,-9.2390757
195.4913,0.12768948,9.2928381,57.313477,0,3.8561573,450.0,0.96637738,0.56582826,1.6499938,416.89032,-9.2396441
195.4937,0.27429295,9.2955942,57.047169,0,4.3146434,450.0,0.96573102,1.4382254,2.4583745,417.01288,-9.2373581
195.4961,-0.16220362,9.3205643,56.780861,0,4.7731299,450.0,0.97026551,-0.80561393,3.1326425,417.13547,-9.2368984
195.4985,0.011935375,9.3140297,56.514549,0,5.2316165,450.0,0.9704169,0.10571215,3.6508968,417.25803,-9.236227
195.5009,-0.18213828,9.3085155,56.425781,0,5.6901026,450.0,0.97018844,-0.82438993,4.074841,417.3085,-9.2375383
195.5033,-0.061239317,9.2995281,56.425781,0,6.1485891,450.0,0.96815979,-0.23162314,4.4888682,417.32294,-9.237525
195.5057,0.027823046,9.3017874,56.425781,0,6.6070752,450.0,0.96737999,0.088591509,4.9119177,417.33734,-9.2360668
195.5081,-0.045574013,9.3116999,56.425781,0,7.0655618,450.0,0.96879762,-0.14853384,5.335083,417.35178,-9.2357521
195.5105,-0.1022471,9.3098211,56.390186,0,7.5240483,450.0,0.96898282,-0.51683259,5.7808461,417.42026,-9.2349405
195.5129,0.0075187478,9.309104,56.318996,0,7.9825354,450.0,0.96972442,0.05235941,6.260366,417.54285,-9.235466
195.5153,-0.057906989,9.2984476,56.247803,0,8.441021,450.0,0.96811295,-0.23668218,6.7464652,417.66541,-9.2346506
195.5177,-0.11236737,9.3101845,56.176609,0,8.8995075,450.0,0.96970731,-0.58764911,7.2371216,417.78796,-9.2355452
195.5201,-0.020835426,9.3095131,56.12915,0,9.3579931,450.0,0.96843797,-0.12944087,7.722908,417.92496,-9.2351074
195.5225,-0.13502413,9.3108492,56.12915,0,9.8164806,450.0,0.96831959,-0.646065,8.1945477,418.09079,-9.2351236
195.5249,-0.11872158,9.2982931,56.12915,0,10.274966,450.0,0.96702319,-0.57729059,8.6645651,418.25665,-9.2358589
195.5273,0.018988239,9.3055553,56.12915,0,10.733453,450.0,0.96949035,0.1095221,9.1336279,418.42249,-9.2341614
195.5297,-0.13240814,9.3002148,56.117722,0,11.191939,450.0,0.96867394,-0.64150774,9.6000757,418.5787,-9.2342644
195.5321,-0.076573037,9.3021898,56.049168,0,11.650426,450.0,0.96802062,-0.45781371,10.068778,418.68683,-9.2340708
195.5345,0.075177804,9.3010683,55.980618,0,12.108912,450.0,0.9669264,0.42811233,10.548184,418.79498,-9.233284
195.5369,-0.23603976,9.3165808,55.912064,0,12.567399,450.0,0.9698357,-1.1490769,11.016598,418.90314,-9.2330999
195.5393,-0.10788186,9.3072548,55.84351,0,13.025885,450.0,0.96895677,-0.57451987,11.486306,419.01129,-9.2328358
195.5417,-0.054692648,9.2999878,55.84351,0,13.484371,450.0,0.96868432,-0.26489753,11.948213,419.13385,-9.2328405
195.5441,-0.25956589,9.2958965,55.84351,0,13.942858,450.0,0.96753371,-1.2884213,12.404664,419.25641,-9.2336397
195.5465,0.0013177888,9.3038797,55.84351,0,14.401344,450.0,0.96799827,0.018329296,12.866962,419.37897,-9.2330332
195.5489,-0.081078812,9.307682,55.84351,0,14.859831,450.0,0.96780491,-0.33213663,13.341005,419.50156,-9.2341852
195.5513,-0.16329132,9.3099251,55.722656,0,15.318317,450.0,0.968593,-0.79131782,13.813672,419.6181,-9.2333889
195.5537,0.11331035,9.3077888,55.577637,0,15.776803,450.0,0.96948826,0.48105949,14.29518,419.73346,-9.2327328
195.5561,-0.091960646,9.3047199,55.432617,0,16.235291,450.0,0.96940964,-0.39055473,14.764992,419.84885,-9.2328186
195.5585,-0.10813789,9.3036337,55.287598,0,16.693775,450.0,0.96865541,-0.51120323,15.228234,419.9642,-9.2327366
195.5609,-0.13469659,9.3025131,55.239258,0,17.152262,450.0,0.96743083,-0.64882904,15.684956,420.03632,-9.231905
195.5633,-0.035534728,9.2982483,55.239258,0,17.61075,450.0,0.96651006,-0.12700918,16.141872,420.08676,-9.2325106
195.5657,-0.11270556,9.2995281,55.239258,0,17.999975,450.0,0.96701926,-0.57209873,16.591358,420.13724,-9.2321157
195.5681,-0.055798694,9.3010883,55.239258,0,18.0,450.0,0.96858639,-0.28263944,17.054802,420.18771,-9.2333117
195.5705,-0.13055342,9.2997713,55.239258,0,18.0,450.0,0.96841395,-0.65666211,17.479174,420.23819,-9.2325583
195.5729,0.00233178,9.3022461,55.239258,0,18.0,450.0,0.96809089,0.0016223199,17.86569,420.28864,-9.2340174
195.5753,0.072261207,9.3012238,55.239258,0,18.0,450.0,0.9669742,0.37311265,18.195253,420.33911,-9.2359638
195.5777,0.11070208,9.3205862,55.239258,0,18.0,450.0,0.97009027,0.53676414,18.428318,420.38959,-9.2386398
195.5801,0.27885583,9.3196392,55.239258,0,18.0,450.0,0.9707967,1.3932642,18.545513,420.42804,-9.2437658
195.5825,0.60202426,9.3210573,55.239258,0,18.0,450.0,0.97213352,2.8304727,18.535238,420.44244,-9.2498417
195.5849,0.49372384,9.3093119,55.239258,0,18.0,450.0,0.97027469,2.4323807,18.413113,420.45688,-9.259841
195.5873,0.6646167,9.325923,55.239258,0,18.0,450.0,0.97214705,3.1279457,18.261833,420.47131,-9.2730579
195.5897,0.62398469,9.3245249,55.239258,0,18.0,450.0,0.97112125,3.0903187,18.125795,420.48334,-9.290494
195.5921,0.55963832,9.3275404,55.239258,0,18.0,450.0,0.97173822,2.6621914,18.056814,420.48334,-9.3105917
195.5945,0.66348392,9.323844,55.239258,0,18.0,450.0,0.97198039,3.2215915,18.040956,420.48334,-9.3319273
195.5969,0.46534947,9.3306932,55.239258,0,18.0,450.0,0.97410011,2.2015197,18.040695,420.48334,-9.3534203
195.5993,0.5488292,9.3228645,55.239258,0,18.0,450.0,0.97208089,2.6285322,18.060764,420.48334,-9.3719368
195.6017,0.56928283,9.3223267,55.239258,0,18.0,450.0,0.97115368,2.7355707,18.091661,420.48334,-9.3927784
195.6041,0.39658046,9.3242683,55.239258,0,18.0,450.0,0.97068417,1.9133025,18.119055,420.48334,-9.4105167
195.6065,0.57387853,9.3308144,55.239258,0,18.0,450.0,0.97235203,2.7331295,18.136957,420.48334,-9.4290895
195.6089,0.60466743,9.3242207,55.239258,0,18.0,450.0,0.97244573,2.9091835,18.143473,420.48334,-9.4468327
195.6113,0.58282167,9.3178959,55.298584,0,18.0,450.0,0.97185314,2.7953107,18.148571,420.45929,-9.4637842
195.6137,0.74375856,9.3227921,55.369778,0,18.0,450.0,0.97192442,3.5564344,18.146139,420.43045,-9.4825726
195.6161,0.49485475,9.3258152,55.440968,0,18.0,450.0,0.9713642,2.4080126,18.144854,420.40161,-9.4998655
195.6185,0.56975967,9.328702,55.512157,0,18.0,450.0,0.97186351,2.7348862,18.144125,420.37277,-9.5176573
195.6209,0.58904541,9.3216887,55.535889,0,18.0,450.0,0.9712519,2.8316092,18.141115,420.33911,-9.5340281
195.6233,0.65215558,9.3163185,55.535889,0,18.0,450.0,0.97114658,3.1733079,18.134464,420.30307,-9.5538397
195.6257,0.54043365,9.3122587,55.535889,0,18.0,450.0,0.97065502,2.6314032,18.132582,420.26703,-9.572031
195.6281,0.61688936,9.3233957,55.535889,0,18.0,450.0,0.97191298,2.9635334,18.131731,420.23099,-9.5880852
195.6305,0.59009796,9.3268661,55.535889,0,18.0,450.0,0.97136241,2.8726664,18.126944,420.22015,-9.6058035
195.6329,0.62532735,9.3314848,55.535889,0,18.0,450.0,0.97189486,3.0183568,18.124586,420.23456,-9.6233168
195.6353,0.60871965,9.3218727,55.535889,0,18.0,450.0,0.97142333,2.948781,18.122593,420.24899,-9.6433573
195.6377,0.53585643,9.3311567,55.535889,0,18.0,450.0,0.97416925,2.5973458,18.120098,420.2634,-9.6616163
195.6401,0.58945364,9.3218508,55.535889,0,18.0,450.0,0.97225338,2.8112831,18.118471,420.25861,-9.6791487
195.6425,0.61576229,9.3193617,55.535889,0,18.0,450.0,0.9708674,2.9777961,18.1157,420.21533,-9.696105
195.6449,0.52524263,9.311758,55.535889,0,18.0,450.0,0.9687897,2.5445678,18.118456,420.17209,-9.7139587
195.6473,0.63121408,9.3289566,55.535889,0,18.0,450.0,0.97192091,3.0690823,18.115694,420.12881,-9.7329321
195.6497,0.58034182,9.3238544,55.55962,0,18.0,450.0,0.97212392,2.7891572,18.115412,420.08557,-9.7516441
195.6521,0.6067,9.3203573,55.702003,0,18.0,450.0,0.97217458,2.9082918,18.11286,420.0423,-9.7690926
195.6545,0.74669504,9.3172712,55.844387,0,18.0,450.0,0.97128123,3.5952775,18.113031,419.99905,-9.7864962
195.6569,0.50877333,9.3330908,55.986767,0,18.0,450.0,0.97268921,2.4547548,18.108072,419.95578,-9.8060417
195.6593,0.56699181,9.329917,56.12915,0,18.0,450.0,0.9716059,2.7504356,18.114004,419.91254,-9.8238859
195.6617,0.58822364,9.3271866,56.12915,0,18.0,450.0,0.97168422,2.8076644,18.110943,419.85486,-9.8414288
195.6641,0.50399286,9.3174047,56.12915,0,18.0,450.0,0.97140944,2.3821018,18.109846,419.79718,-9.8582649
195.6665,0.64846271,9.318326,56.12915,0,18.0,450.0,0.97174436,3.1125605,18.105156,419.73947,-9.8768101
195.6689,0.62338704,9.3192968,56.12915,0,18.0,450.0,0.97141719,3.0160131,18.10478,419.68179,-9.895999
195.6713,0.57214123,9.3238926,56.188477,0,18.0,450.0,0.97111076,2.7954638,18.101156,419.61209,-9.9154911
195.6737,0.80857259,9.3286095,56.259666,0,18.0,450.0,0.97171259,3.8211296,18.10639,419.54001,-9.9324694
195.6761,0.5442071,9.3252726,56.33086,0,18.0,450.0,0.97179782,2.6041627,18.099928,419.4679,-9.9486275
195.6785,0.62544113,9.3236847,56.40205,0,18.0,450.0,0.97252822,3.0459521,18.100632,419.39581,-9.9663925
195.6809,0.57869315,9.3202705,56.425781,0,18.0,450.0,0.9720276,2.7620151,18.100534,419.32849,-9.985981
195.6833,0.64067787,9.3197613,56.425781,0,18.0,450.0,0.97100461,3.194731,18.101654,419.26361,-10.002906
195.6857,0.62738824,9.3191948,56.425781,0,18.0,450.0,0.96982372,2.9831109,18.098478,419.19873,-10.020262
195.6881,0.68363744,9.3306551,56.425781,0,18.0,450.0,0.97202939,3.2960024,18.098253,419.13382,-10.037631
195.6905,0.61307633,9.3274193,56.46006,0,18.0,450.0,0.97245532,2.9805956,18.098078,419.08698,-10.056783
195.6929,0.60403901,9.3250494,56.528614,0,18.0,450.0,0.97303665,2.9436772,18.098167,419.05814,-10.076038
195.6953,0.65834439,9.3117647,56.597168,0,18.0,450.0,0.97047353,3.2073846,18.095284,419.0293,-10.09441
195.6977,0.61921579,9.3262825,56.665722,0,18.0,450.0,0.97193623,2.9654543,18.09815,419.00046,-10.109916
195.7001,0.63834858,9.3253536,56.711426,0,18.0,450.0,0.97111422,3.0807004,18.094051,418.96921,-10.128186
195.7025,0.6120218,9.3279285,56.711426,0,18.0,450.0,0.97185296,2.9747984,18.095865,418.93317,-10.145794
195.7049,0.5491519,9.3115568,56.711426,0,18.0,450.0,0.97015804,2.6546485,18.094608,418.89713,-10.164921
195.7073,0.72053075,9.324667,56.711426,0,18.0,450.0,0.97291636,3.4468734,18.093161,418.86105,-10.182168
195.7097,0.66196585,9.3195829,56.722412,0,18.0,450.0,0.97163445,3.1766839,18.088573,418.82382,-10.199259
195.7121,0.62960225,9.325696,56.78833,0,18.0,450.0,0.97151107,3.0070691,18.088821,418.78055,-10.218018
195.7145,0.76260537,9.3287067,56.854248,0,18.0,450.0,0.971542,3.7298889,18.088299,418.73727,-10.237624
195.7169,0.55564368,9.3401623,56.920166,0,18.0,450.0,0.97399467,2.6101615,18.084419,418.69403,-10.254571
195.7193,0.66482365,9.3250389,56.986084,0,18.0,450.0,0.97258025,3.1711922,18.079004,418.65076,-10.271317
195.7217,0.6517157,9.3182755,56.986084,0,18.0,450.0,0.9718616,3.1781135,18.086485,418.57864,-10.289416
195.7241,0.49727359,9.3154888,56.986084,0,18.0,450.0,0.97053874,2.3731194,18.084438,418.50656,-10.308744
195.7265,0.65144449,9.323946,56.986084,0,18.0,450.0,0.97111905,3.1274107,18.082335,418.43445,-10.327173
195.7289,0.67875659,9.3229399,56.986084,0,18.0,450.0,0.97090697,3.2796872,18.082361,418.36237,-10.344071
195.7313,0.65746719,9.3239994,57.150883,0,18.0,450.0,0.97167259,3.1787665,18.082155,418.25421,-10.362471
195.7337,0.82899487,9.3275585,57.348633,0,18.0,450.0,0.97332662,3.9820993,18.086592,418.13885,-10.3803
195.7361,0.54742998,9.3228045,57.546387,0,18.0,450.0,0.97229892,2.6556852,18.08106,418.0235,-10.398726
195.7385,0.65159106,9.3244419,57.744141,0,18.0,450.0,0.97174758,3.1164188,18.080532,417.90814,-10.416881
195.7409,0.64873117,9.3277874,57.810059,0,18.0,450.0,0.97140944,3.1292267,18.08042,417.83603,-10.433212
195.7433,0.64951962,9.3295012,57.810059,0,18.0,450.0,0.97165108,3.2565193,18.081268,417.78558,-10.450638
195.7457,0.62353128,9.3206797,57.810059,0,18.0,450.0,0.97139776,2.9805269,18.079868,417.73511,-10.470275
195.7481,0.68774676,9.3233643,57.810059,0,18.0,450.0,0.9727959,3.3049414,18.080269,417.68463,-10.488703
195.7505,0.66630232,9.316659,57.841705,0,18.0,450.0,0.97133416,3.2123413,18.080217,417.65579,-10.506968
195.7529,0.64109665,9.3175211,57.90498,0,18.0,450.0,0.97047156,3.1576993,18.079275,417.64856,-10.524955
195.7553,0.6772207,9.3179865,57.968262,0,18.0,450.0,0.96968013,3.3487563,18.075434,417.64136,-10.543246
195.7577,0.61541551,9.3348312,58.031544,0,18.0,450.0,0.97327721,2.9696832,18.074745,417.63416,-10.56215
195.7601,0.65485781,9.3254232,58.07373,0,18.0,450.0,0.97253251,3.1403434,18.077564,417.60529,-10.580105
195.7625,0.68456775,9.319952,58.07373,0,18.0,450.0,0.97212046,3.2956526,18.075373,417.5332,-10.596991
195.7649,0.60354757,9.3087425,58.07373,0,18.0,450.0,0.96951616,2.9494832,18.077126,417.46109,-10.612973
195.7673,0.72509819,9.3313198,58.07373,0,18.0,450.0,0.97242481,3.4753737,18.072754,417.38901,-10.633116
195.7697,0.67891926,9.3299446,58.084278,0,18.0,450.0,0.97165048,3.2661316,18.071827,417.31931,-10.650514
195.7721,0.69081998,9.3281946,58.14756,0,18.0,450.0,0.9720844,3.3261759,18.070457,417.26163,-10.669481
195.7745,0.82266378,9.3178577,58.210842,0,18.0,450.0,0.9716903,3.9673319,18.072454,417.20398,-10.686417
195.7769,0.58250332,9.330267,58.274124,0,18.0,450.0,0.97393292,2.8429251,18.072035,417.1463,-10.705079
195.7793,0.65668088,9.323308,58.337406,0,18.0,450.0,0.97179586,3.1667612,18.067282,417.08862,-10.722712
195.7817,0.68049127,9.3218737,58.337406,0,18.0,450.0,0.97080833,3.2821877,18.069376,417.04535,-10.741023
195.7841,0.56422728,9.316844,58.337406,0,18.0,450.0,0.97002095,2.7057571,18.068275,417.00211,-10.757052
195.7865,0.73215169,9.3286076,58.337406,0,18.0,450.0,0.97249442,3.5318842,18.069031,416.95883,-10.775329
195.7889,0.70072621,9.3235788,58.337406,0,18.0,450.0,0.97263408,3.401814,18.065205,416.91556,-10.792764
195.7913,0.67747456,9.3204422,58.440678,0,18.0,450.0,0.97198051,3.2569413,18.068325,416.84827,-10.810549
195.7937,0.89104623,9.3245974,58.564606,0,18.0,450.0,0.97186369,4.280592,18.068306,416.77615,-10.829347
195.7961,0.61890024,9.3293352,58.688522,0,18.0,450.0,0.97152901,2.9904976,18.063343,416.70404,-10.84919
195.7985,0.69020045,9.3347483,58.81245,0,18.0,450.0,0.97282326,3.3594015,18.061911,416.63196,-10.866371
195.8009,0.6445114,9.3288279,58.85376,0,18.0,450.0,0.97302914,3.1714821,18.062733,416.56946,-10.88332
195.8033,0.62481135,9.3210964,58.85376,0,18.0,450.0,0.97236067,3.1364336,18.057667,416.51178,-10.902589
195.8057,0.68702984,9.311554,58.85376,0,18.0,450.0,0.97001863,3.3203585,18.062443,416.45413,-10.920428
195.8081,0.77304798,9.32372,58.85376,0,18.0,450.0,0.97114342,3.70719,18.062643,416.39645,-10.938447
195.8105,0.67694372,9.3256054,58.884079,0,18.0,450.0,0.97112876,3.3000195,18.06254,416.33157,-10.955645
195.8129,0.63074088,9.3238678,58.944725,0,18.0,450.0,0.97127312,3.1194756,18.061436,416.25946,-10.973767
195.8153,0.71231413,9.3117952,59.005371,0,18.0,450.0,0.97018671,3.4337831,18.062113,416.18738,-10.990635
195.8177,0.68514913,9.3251781,59.066013,0,18.0,450.0,0.97314161,3.2701719,18.062487,416.11526,-11.008735
195.8201,0.6914869,9.3238869,59.106441,0,18.0,450.0,0.972067,3.3439131,18.062208,416.04797,-11.02571
195.8225,0.69247848,9.3279142,59.106441,0,18.0,450.0,0.97160923,3.3526111,18.058258,415.9903,-11.044422
195.8249,0.61489129,9.3160486,59.106441,0,18.0,450.0,0.96934533,2.9250963,18.060814,415.93259,-11.063433
195.8273,0.789159,9.3324976,59.106441,0,18.0,450.0,0.97284245,3.7623119,18.058895,415.87491,-11.081341
195.8297,0.72740042,9.3244715,59.126217,0,18.0,450.0,0.97276133,3.5294757,18.059599,415.81723,-11.098758
195.8321,0.70200741,9.3213091,59.244869,0,18.0,450.0,0.97252488,3.3876112,18.058413,415.75955,-11.117244
195.8345,0.81972748,9.3170223,59.363525,0,18.0,450.0,0.97059947,3.9887285,18.056999,415.70187,-11.135917
195.8369,0.62052274,9.3328867,59.482178,0,18.0,450.0,0.97264886,2.990294,18.053957,415.6442,-11.153919
195.8393,0.71680146,9.324254,59.600834,0,18.0,450.0,0.97122103,3.4206185,18.056948,415.58652,-11.17058
195.8417,0.71418035,9.3233633,59.600834,0,18.0,450.0,0.97165895,3.4649029,18.058516,415.52164,-11.187778
195.8441,0.57008314,9.3154087,59.600834,0,18.0,450.0,0.9713788,2.7525084,18.053593,415.45676,-11.206326
195.8465,0.75950181,9.3234968,59.600834,0,18.0,450.0,0.97245318,3.6136055,18.051872,415.39188,-11.224636
195.8489,0.76909328,9.3215494,59.600834,0,18.0,450.0,0.97110832,3.6896071,18.051525,415.32697,-11.241921
195.8513,0.73524684,9.3274813,59.64917,0,18.0,450.0,0.97130972,3.5329721,18.053486,415.29211,-11.261028
195.8537,0.92877889,9.3356791,59.70718,0,18.0,450.0,0.9730891,4.4468341,18.053598,415.26328,-11.280709
195.8561,0.61490548,9.3328705,59.765186,0,18.0,450.0,0.9737044,2.9246445,18.047176,415.23444,-11.29789
195.8585,0.72270006,9.3267117,59.823196,0,18.0,450.0,0.9734515,3.4836912,18.049221,415.2056,-11.315027
195.8609,0.7193929,9.3188496,59.842533,0,18.0,450.0,0.97147226,3.4705455,18.051207,415.16232,-11.33266
195.8633,0.64556086,9.3178892,59.842533,0,18.0,450.0,0.9701944,3.2640026,18.042744,415.11185,-11.351353
196.0652,0.69254464,9.3276176,0.12906466,0,18.0,0.85476655,0.97249573,3.3315253,18.027357,411.80951,-11.478136
197.2652,0.63260955,9.3379927,5.6152035e-18,0,18.0,3.6951402e-17,0.97439831,3.0399301,18.000635,366.13416,-11.479551
198.4652,0.5684613,9.3413868,2.4429000000000003e-34,0,18.0,1.5974028e-33,0.97476101,2.7326517,18.000143,335.71179,-11.47952
199.6652,0.51452017,9.3428249,7.9874012e-44,0,18.0,1.4012985e-45,0.9750675,2.4766455,17.99976,315.45035,-11.480187
200.8652,0.5265553,9.3487873,7.9874012e-44,0,18.0,1.4012985e-45,0.97623581,2.5275717,17.998978,300.05081,-11.479981
202.0652,0.53400725,9.3533001,7.9874012e-44,0,18.0,1.4012985e-45,0.97697198,2.5588307,17.999483,286.66293,-11.480263
203.2652,0.53875464,9.359108,7.9874012e-44,0,18.0,1.4012985e-45,0.97800672,2.5775969,18.000372,274.73444,-11.480403
204.4652,0.54525703,9.3634968,7.9874012e-44,0,18.0,1.4012985e-45,0.97871614,2.6092751,18.000584,264.03345,-11.480189
205.6652,0.54917407,9.3679008,7.9874012e-44,0,18.0,1.4012985e-45,0.97966784,2.6229517,18.001104,254.74333,-11.480137
206.8652,0.55218494,9.3720427,7.9874012e-44,0,18.0,1.4012985e-45,0.98041081,2.635535,17.999409,246.43094,-11.479668
208.0652,0.55966413,9.3766069,7.9874012e-44,0,18.0,1.4012985e-45,0.98101604,2.6714263,18.000219,238.42371,-11.480297
209.2652,0.56352222,9.3804588,7.9874012e-44,0,18.0,1.4012985e-45,0.98185056,2.6900499,18.000341,231.46315,-11.480863
210.4652,0.56776929,9.3843279,7.9874012e-44,0,18.0,1.4012985e-45,0.98263407,2.702848,18.000025,224.15916,-11.480512
211.6652,0.56965351,9.3883686,7.9874012e-44,0,18.0,1.4012985e-45,0.98308694,2.7159305,17.999784,217.41594,-11.48048
212.8652,0.57429248,9.391861,7.9874012e-44,0,18.0,1.4012985e-45,0.98377365,2.7333932,17.999733,210.80066,-11.480447
214.0652,0.58033723,9.3957405,7.9874012e-44,0,18.0,1.4012985e-45,0.98459697,2.7594135,17.999792,204.5896,-11.480387
215.2652,0.58132339,9.3992672,7.9874012e-44,0,18.0,1.4012985e-45,0.98511767,2.7698438,18.000414,198.71861,-11.480491
216.4652,0.58885241,9.4021683,7.9874012e-44,0,18.0,1.4012985e-45,0.98562062,2.7970138,18.000797,193.03981,-11.480319
217.6652,0.5919559,9.4057751,7.9874012e-44,0,18.0,1.4012985e-45,0.98629028,2.8084953,17.999929,187.4599,-11.480348
218.8652,0.59244007,9.408843,7.9874012e-44,0,18.0,1.4012985e-45,0.98692346,2.8074818,18.000088,182.11594,-11.480434
220.0652,0.59954917,9.4120922,7.9874012e-44,0,18.0,1.4012985e-45,0.987481,2.8414915,18.00071,176.952,-11.480845
221.2652,0.60434705,9.415473,7.9874012e-44,0,18.0,1.4012985e-45,0.98798376,2.8676558,17.999491,172.07997,-11.480556
222.4652,0.60592163,9.4182587,7.9874012e-44,0,18.0,1.4012985e-45,0.98862708,2.8749857,17.99881,167.65094,-11.480375
223.6652,0.60685122,9.421134,7.9874012e-44,0,18.0,1.4012985e-45,0.98917973,2.8749809,18.000238,163.11145,-11.480542
224.8652,0.6169641,9.424015,7.9874012e-44,0,18.0,1.4012985e-45,0.98946995,2.9245875,17.999786,158.77167,-11.480475
226.0652,0.61602288,9.426671,7.9874012e-44,0,18.0,1.4012985e-45,0.99010789,2.9186831,17.999699,154.60835,-11.48058
227.2652,0.63123965,9.4290524,7.9874012e-44,0,18.0,1.4012985e-45,0.99062955,2.9802146,18.000216,150.72307,-11.48079
228.4652,0.62439662,9.4319706,7.9874012e-44,0,18.0,1.4012985e-45,0.99087924,2.9537179,18.000881,146.81633,-11.480846
229.6652,0.62687248,9.434679,7.9874012e-44,0,18.0,1.4012985e-45,0.99146676,2.9623823,18.000048,143.10262,-11.480691
230.8652,0.63498533,9.4372911,7.9874012e-44,0,18.0,1.4012985e-45,0.99206543,3.0017047,17.999281,139.35037,-11.480765
232.0652,0.63804018,9.4402227,7.9874012e-44,0,18.0,1.4012985e-45,0.99240375,3.0119522,18.000528,135.86719,-11.480784
233.2652,0.63877732,9.4421043,7.9874012e-44,0,18.0,1.4012985e-45,0.99277163,3.0103662,17.999235,132.39206,-11.480672
234.4652,0.6421752,9.4439745,7.9874012e-44,0,18.0,1.4012985e-45,0.99322265,3.032572,18.001139,129.04903,-11.480919
235.6652,0.6485936,9.4467106,7.9874012e-44,0,18.0,1.4012985e-45,0.9936552,3.051003,17.999956,125.72455,-11.480726
236.8652,0.64153057,9.4486637,7.9874012e-44,0,18.0,1.4012985e-45,0.99396068,3.028964,18.000294,122.62482,-11.480278
238.0652,0.64682674,9.4504147,7.9874012e-44,0,18.0,1.4012985e-45,0.99430257,3.0521348,17.999451,119.5631,-11.480719
239.2652,0.65282363,9.4527063,7.9874012e-44,0,18.0,1.4012985e-45,0.99476177,3.0741222,17.999645,116.71796,-11.480746
240.4652,0.65173531,9.4544373,7.9874012e-44,0,18.0,1.4012985e-45,0.99505633,3.069088,18.000437,113.74212,-11.480824
241.6652,0.66056269,9.4566221,7.9874012e-44,0,18.0,1.4012985e-45,0.99538833,3.1098866,18.001005,111.06799,-11.481052
242.8652,0.6511367,9.4585028,7.9874012e-44,0,18.0,1.4012985e-45,0.99588668,3.0631268,18.000481,108.21703,-11.480649
244.0652,0.65311861,9.4603729,7.9874012e-44,0,18.0,1.4012985e-45,0.99619734,3.0686972,17.999279,105.64046,-11.481037
245.2652,0.65572405,9.4623308,7.9874012e-44,0,18.0,1.4012985e-45,0.99637973,3.0874627,17.999426,103.05029,-11.481009
246.4652,0.6543107,9.4641485,7.9874012e-44,0,18.0,1.4012985e-45,0.99686807,3.0712285,17.99964,100.51454,-11.480626
247.6652,0.66209257,9.4661207,7.9874012e-44,0,18.0,1.4012985e-45,0.99726802,3.1094306,18.00016,98.07122,-11.481359
248.8652,0.65693736,9.4678984,7.9874012e-44,0,18.0,1.4012985e-45,0.99735957,3.0854793,18.000401,95.724312,-11.480985
250.0652,0.65895236,9.4689407,7.9874012e-44,0,18.0,1.4012985e-45,0.997711,3.0927167,17.999849,93.439133,-11.481367
251.2652,0.65581042,9.4707632,7.9874012e-44,0,18.0,1.4012985e-45,0.99811244,3.0805385,18.000881,91.294441,-11.481256
252.4652,0.66344368,9.472599,7.9874012e-44,0,18.0,1.4012985e-45,0.99819636,3.1076906,17.999014,89.157394,-11.481404
253.6652,0.65973437,9.4737196,7.9874012e-44,0,18.0,1.4012985e-45,0.99856502,3.0994055,17.999968,87.020241,-11.481212
254.8652,0.66024077,9.4751434,7.9874012e-44,0,18.0,1.4012985e-45,0.99892455,3.0943353,18.000141,85.026375,-11.481306
255.8652,0.66594034,9.4768171,7.9874012e-44,0,18.0,1.4012985e-45,0.99923271,3.1257911,17.998682,83.372238,-11.481183