File: raw data/testID_0237.csv
Time(sec),Force(kN),Jaw(mm),PowAngle(deg),Power(W),Pram,PTemp,Strain,Stress(MPa),Stroke(mm),TC1(C),wedge(mm)
0.0,1.2019114,0.028325958,0.0,0,11.076097,0.0015617122,0.0019092042,15.273252,11.076106,21.922302,-9.1224566
1.3,1.1390909,0.006708174,0.0,0,11.076097,3.815917,0.00045552338,14.502327,11.0767,21.982363,-9.4893017
2.6,1.1069679,0.006524066,0.0,0,11.076097,7.7159147,0.00043386672,14.07995,11.076402,21.919186,-9.4863653
3.9,1.0875099,0.0065252814,0.0,0,11.076097,11.615913,0.00046149449,13.849826,11.075525,21.931704,-9.4844589
5.2,1.0622462,0.0063502095,0.0,0,11.076097,15.515913,0.00044309467,13.517267,11.076344,21.991596,-9.4821997
6.5,1.0433381,0.0069143805,0.0,0,11.076097,19.415916,0.00045652152,13.281446,11.07603,21.988047,-9.4797478
7.8,1.0403472,0.0070750462,5.3213053,0,11.076097,23.315912,0.00045587812,13.252533,11.076253,21.935429,-9.4778757
9.1,1.0214,0.0070658345,27.428528,0,11.076097,27.215912,0.00044399922,13.00194,11.076153,22.232128,-9.4751883
10.4,1.0149791,0.0062090242,37.703926,0,11.076097,31.11591,0.00041128232,12.92272,11.076345,23.88352,-9.472723
11.7,1.0264047,0.0048761903,43.391361,0,11.076097,35.015919,0.00033334125,13.060766,11.075782,27.328907,-9.4712315
13.0,1.031088,0.0021705581,46.107521,0,11.076097,38.915916,0.00014159972,13.132889,11.076868,32.22913,-9.4690933
14.3,1.0206352,0.00049394876,47.504845,0,11.076097,42.815918,5.4287215e-05,13.002201,11.076383,37.6744,-9.4668121
15.6,1.0090957,-0.0021388154,47.955318,0,11.076097,46.715904,-0.00011806634,12.84484,11.075697,43.219978,-9.4645329
16.9,1.0038275,-0.0032854604,47.955318,0,11.076097,50.615902,-0.0002242234,12.782248,11.075477,48.595493,-9.4622908
18.2,1.0094059,-0.004130492,47.507015,0,11.076097,54.5159,-0.0002948115,12.863577,11.076261,53.570282,-9.4603806
19.5,1.0035498,-0.0049409857,47.493877,0,11.076097,58.415905,-0.00034851616,12.772931,11.075678,58.057652,-9.458272
20.8,0.99852008,-0.00632485,47.116779,0,11.076097,62.315907,-0.00041704378,12.739557,11.075992,62.226753,-9.4564133
22.1,0.99361998,-0.0067414856,47.489147,0,11.076097,66.215904,-0.00043638688,12.655342,11.0759,66.027565,-9.4540758
23.4,0.98208213,-0.0078269802,47.504883,0,11.076097,70.115898,-0.00052293367,12.506315,11.077003,69.833672,-9.4519062
24.7,0.98226285,-0.0083658705,47.927616,0,11.076097,74.015892,-0.00053119852,12.505854,11.076814,73.652313,-9.448947
26.0,0.97668839,-0.0089974012,48.070164,0,11.076097,77.915901,-0.00057354773,12.443755,11.077106,77.401169,-9.4471331
27.3,0.97373867,-0.0095305126,48.383785,0,11.076097,81.81591,-0.00064069621,12.401319,11.075583,81.34343,-9.4447832
28.6,0.96692336,-0.010340576,48.383724,0,11.076097,85.715904,-0.00071056554,12.322851,11.076285,85.398277,-9.4424829
29.9,0.97074914,-0.01123024,48.383785,0,11.076097,89.615913,-0.00076501269,12.368053,11.076143,89.227036,-9.4399471
31.2,0.9609676,-0.011691175,48.812252,0,11.076097,93.515907,-0.00076639309,12.24018,11.075842,93.028214,-9.4378014
32.5,0.96465421,-0.012954199,49.228649,0,11.076097,97.415894,-0.00085371552,12.288031,11.076099,96.847008,-9.4356842
33.8,0.95546353,-0.013594847,49.444324,0,11.076097,101.31587,-0.00089922769,12.171937,11.075532,100.63846,-9.4336166
35.1,0.95389575,-0.015020107,49.636227,0,11.076097,105.21589,-0.00096986635,12.160308,11.076296,104.5864,-9.4314203
36.4,0.94614798,-0.015695026,49.905754,0,11.076097,109.11588,-0.0010277185,12.061228,11.076632,108.5292,-9.4287901
37.7,0.94551432,-0.016654257,50.042721,0,11.076097,113.0159,-0.0011108181,12.038836,11.076359,112.51979,-9.4271202
39.0,0.95101911,-0.017135264,50.072136,0,11.076097,116.9159,-0.0011676862,12.11998,11.076032,116.40295,-9.4246836
40.3,0.94242841,-0.018374978,50.438229,0,11.076097,120.8159,-0.0012455981,12.017345,11.076061,120.38696,-9.4222164
41.6,0.94266027,-0.019845575,50.459084,0,11.076097,124.71589,-0.001318707,12.029515,11.075841,124.2551,-9.4201574
42.9,0.93960631,-0.020618347,50.82275,0,11.076097,128.61603,-0.0013640188,11.97954,11.076276,128.10307,-9.4179411
44.2,0.93812448,-0.02238184,50.82275,0,11.076097,132.51588,-0.0014946195,11.961054,11.075774,132.16472,-9.4156618
45.5,0.93770188,-0.023432273,50.972652,0,11.076097,136.41588,-0.001535185,11.964631,11.075919,136.03586,-9.4133892
46.8,0.94250059,-0.024702718,51.196041,0,11.076097,140.31589,-0.0016326918,12.020148,11.075806,139.9955,-9.4111919
48.1,0.93380672,-0.025367033,50.452862,0,11.076097,144.21588,-0.001699907,11.918232,11.076009,144.59474,-9.4088488
49.4,0.93395579,-0.027043527,50.820404,0,11.076097,148.11588,-0.0018216971,11.914151,11.076882,148.00702,-9.4069252
50.7,0.92975593,-0.027932225,51.156994,0,11.076097,152.01588,-0.0018738407,11.857271,11.076128,151.69524,-9.4044752
52.0,0.93358862,-0.029009702,51.199684,0,11.076097,155.91589,-0.0019156752,11.927264,11.075779,155.44946,-9.4023981
53.3,0.93032181,-0.030816436,51.56982,0,11.076097,159.81587,-0.002046058,11.871406,11.077191,159.33093,-9.4002237
54.6,0.92992347,-0.032102786,51.56982,0,11.076097,163.71588,-0.002129982,11.876676,11.076862,163.2756,-9.3979731
55.9,0.92937279,-0.033941709,51.700001,0,11.076097,167.61588,-0.0022311183,11.865652,11.075533,167.22864,-9.3959093
57.2,0.9180494,-0.035429642,51.932369,0,11.076097,171.51587,-0.0023452311,11.72565,11.077249,171.13341,-9.3933029
58.5,0.93276674,-0.036449675,52.149635,0,11.076097,175.41589,-0.0024368477,11.90413,11.076476,174.9543,-9.3915663
59.8,0.91922152,-0.038151864,52.283936,0,11.076097,179.31589,-0.0025640316,11.730447,11.076008,178.85976,-9.3890352
61.1,0.91918802,-0.039974328,52.417896,0,11.076097,183.21588,-0.0026690564,11.738765,11.07648,182.70187,-9.3868351
62.4,0.93277401,-0.041261174,51.932621,0,11.076097,187.11588,-0.0027407648,11.915302,11.077233,187.43221,-9.3846817
63.7,0.92110515,-0.0441048,51.26474,0,11.076097,191.01587,-0.0029390485,11.755549,11.077024,191.87915,-9.3823814
65.0,0.91084248,-0.045781665,50.82539,0,11.076097,194.91586,-0.0030341726,11.631157,11.075929,195.86292,-9.3800259
66.3,0.91771686,-0.047713324,50.822758,0,11.076097,198.81586,-0.0031497239,11.713657,11.076256,199.51443,-9.3778667
67.6,0.91385144,-0.048923146,50.822758,0,11.076097,202.71588,-0.0032523833,11.683668,11.07632,203.0416,-9.3759441
68.9,0.92245573,-0.050790261,51.193012,0,11.076097,206.61588,-0.0033978594,11.780134,11.076847,206.62555,-9.3735218
70.2,0.91618258,-0.052451838,51.196285,0,11.076097,210.51587,-0.0035099697,11.698383,11.076195,210.36122,-9.3712492
71.5,0.91292143,-0.054674536,50.504879,0,11.076097,214.41586,-0.0036418468,11.677098,11.075311,215.08714,-9.3688164
72.8,0.9132216,-0.056356832,51.181435,0,11.076097,218.31587,-0.003736825,11.671741,11.075865,218.32156,-9.3669882
74.1,0.91158229,-0.058198549,51.418278,0,11.076097,222.21587,-0.00387106,11.642501,11.075143,221.88078,-9.3646793
75.4,0.91680694,-0.060569666,51.56982,0,11.076097,226.11588,-0.0040211412,11.718468,11.0766,225.62558,-9.3622074
76.7,0.90971094,-0.062706739,51.921356,0,11.076097,230.01587,-0.0041451817,11.62718,11.077175,229.48511,-9.3603048
78.0,0.91445279,-0.064798541,51.932369,0,11.076097,233.91586,-0.0043006572,11.698585,11.076919,233.50179,-9.3581972
79.3,0.91310328,-0.067135215,51.971416,0,11.076097,237.81586,-0.0044761831,11.67766,11.076468,237.42999,-9.3557158
80.6,0.92353809,-0.069190018,52.275723,0,11.076097,241.71587,-0.0046305917,11.820069,11.076953,241.35591,-9.3537827
81.9,0.91725874,-0.071558297,52.07597,0,11.076097,245.61588,-0.0047715395,11.739361,11.075489,245.47107,-9.3515377
83.2,0.92332762,-0.07429152,52.221001,0,11.076097,249.51587,-0.0049299388,11.81205,11.076664,249.37305,-9.3489285
84.5,0.93711275,-0.075961709,51.933529,0,11.076097,253.41588,-0.0050467737,11.9981,11.07675,253.4153,-9.3473558
85.8,0.94047034,-0.078611977,51.932602,0,11.076097,257.3161,-0.0052184979,12.043216,11.076084,257.37308,-9.3449745
87.1,0.93731773,-0.080755502,51.932758,0,11.076097,261.21609,-0.0053452356,12.000796,11.076474,261.24521,-9.3426676
88.4,0.94240952,-0.083340004,52.117962,0,11.076097,265.11584,-0.0055218055,12.063493,11.076581,265.04547,-9.3406267
89.7,0.94268692,-0.085000299,52.192375,0,11.076097,269.01584,-0.0056616399,12.063363,11.076717,268.93207,-9.3383284
91.0,0.94410187,-0.08728268,52.210281,0,11.076097,272.91586,-0.0058224727,12.096044,11.07651,272.84973,-9.3361969
92.3,0.95579308,-0.089786835,52.282207,0,11.076097,276.81589,-0.0059878454,12.230116,11.07638,276.76935,-9.3340187
93.6,0.94343555,-0.092536025,52.275093,0,11.076097,280.71588,-0.0061506042,12.100433,11.076304,280.64728,-9.3314686
94.9,0.95661455,-0.095293164,52.283936,0,11.076097,284.61588,-0.0063288859,12.253172,11.075505,284.50256,-9.329298
96.2,0.95399851,-0.097175866,52.284019,0,11.076097,288.51584,-0.0064611761,12.219787,11.074976,288.28476,-9.327198
97.5,0.95794177,-0.10036892,52.634949,0,11.076097,292.41583,-0.0066485642,12.289697,11.074924,292.09659,-9.3251123
98.8,0.95423383,-0.10225159,52.473915,0,11.076097,296.31583,-0.0067739054,12.242383,11.075729,296.16147,-9.3228054
100.1,0.96120423,-0.10495991,52.44973,0,11.076097,300.21585,-0.0069762077,12.320473,11.076702,300.18378,-9.3209372
101.4,0.96728545,-0.10691418,52.51532,0,11.076097,304.11584,-0.0071111638,12.387768,11.076903,304.01978,-9.3186054
102.7,0.96109086,-0.10938406,52.635494,0,11.076097,308.01587,-0.0072913934,12.324461,11.076221,307.95099,-9.3160791
104.0,0.97396678,-0.11198887,52.52235,0,11.076097,311.91586,-0.0074443268,12.493315,11.077053,311.90359,-9.3143034
105.3,0.96997833,-0.11485977,52.34042,0,11.076097,315.81583,-0.0076207565,12.447636,11.076874,315.90012,-9.3120384
106.6,0.97558248,-0.11740731,52.283939,0,11.076097,319.71582,-0.0078002219,12.514963,11.076355,319.76126,-9.3095207
107.9,0.97671741,-0.11984964,52.283939,0,11.076097,323.61581,-0.0079331631,12.545458,11.075938,323.65012,-9.3077621
109.2,0.97405058,-0.12346307,52.296486,0,11.076097,327.51584,-0.0081670051,12.504929,11.076865,327.51923,-9.3051805
110.5,0.98392648,-0.12482502,52.52692,0,11.076097,331.41583,-0.0082841096,12.639023,11.077049,331.39145,-9.3032904
111.8,0.98002458,-0.12803324,52.383202,0,11.076097,335.31583,-0.008510055,12.579568,11.075458,335.35428,-9.3008223
113.1,0.98627251,-0.12997176,52.416573,0,11.076097,339.21585,-0.008644307,12.668434,11.076468,339.21658,-9.2988501
114.4,0.97946131,-0.13243085,52.491299,0,11.076097,343.11588,-0.0087962896,12.577883,11.076148,343.10098,-9.29632
115.7,0.99147922,-0.13523763,52.605186,0,11.076097,347.01584,-0.0089629693,12.739911,11.076319,346.97928,-9.2941828
117.0,0.9823218,-0.13767087,52.635197,0,11.076097,350.91586,-0.0091384882,12.630526,11.076342,350.84668,-9.2919302
118.3,0.99009627,-0.14070292,52.635494,0,11.076097,354.81583,-0.0093240142,12.715225,11.075911,354.69595,-9.2900105
119.6,0.98409569,-0.14276917,52.827435,0,11.076097,358.71579,-0.009445658,12.648953,11.077099,358.43036,-9.2873964
120.9,0.99379748,-0.14538412,52.97607,0,11.076097,362.61581,-0.0096402429,12.785103,11.075618,362.30444,-9.2854462
122.2,0.99558204,-0.14734882,52.872799,0,11.076097,366.51584,-0.0097849406,12.799942,11.076347,366.37744,-9.2831421
123.5,1.0037533,-0.14998347,52.976051,0,11.076097,370.41586,-0.0099775577,12.891009,11.076834,370.29593,-9.2812366
124.8,0.99663693,-0.15216236,52.761074,0,11.076097,374.31586,-0.010096989,12.829266,11.075852,374.39169,-9.2788486
126.1,0.99067128,-0.15512076,52.638927,0,11.076097,378.21585,-0.010280563,12.748793,11.076151,378.27017,-9.2766724
127.4,0.99658167,-0.15715942,52.924614,0,11.076097,382.11584,-0.010415096,12.81105,11.076163,382.07556,-9.2743273
128.7,1.0027881,-0.15963054,52.819878,0,11.076097,386.01578,-0.010578136,12.911162,11.076319,385.99286,-9.2724943
130.0,1.0021232,-0.16206877,52.829472,0,11.076097,389.9158,-0.010717325,12.900226,11.076454,389.90973,-9.2699232
131.3,0.98905379,-0.16454694,52.635502,0,11.076097,393.8158,-0.010896227,12.755795,11.076203,393.88992,-9.2677937
132.6,1.0082768,-0.16717963,52.635502,0,11.076097,397.71585,-0.01109687,12.984066,11.075293,397.79883,-9.2657051
133.9,0.99442542,-0.16931188,52.288063,0,11.076097,401.61584,-0.011250079,12.811153,11.076208,401.9863,-9.2633867
135.2,1.00051,-0.17165101,52.455818,0,11.076097,405.51584,-0.01138936,12.887231,11.077145,405.70496,-9.2613478
136.5,0.9907915,-0.17317425,52.597435,0,11.076097,409.41583,-0.011477972,12.755975,11.075637,409.45114,-9.2590036
137.8,0.98108828,-0.17579219,52.635494,0,11.076097,413.31583,-0.011654028,12.640305,11.076416,413.23035,-9.2567406
139.1,0.98241311,-0.17827746,52.835068,0,11.076097,417.21582,-0.011813999,12.659047,11.076079,416.91647,-9.2547722
140.4,0.97468704,-0.18050005,52.879074,0,11.076097,421.11578,-0.011939428,12.564844,11.075906,420.92383,-9.2526531
141.7,0.97328669,-0.18330963,52.976028,0,11.076097,425.01581,-0.012141193,12.537119,11.076585,424.82352,-9.2504349
143.0,0.95288306,-0.18472537,52.97607,0,11.076097,428.9158,-0.012250763,12.278715,11.075582,428.76569,-9.2480125
144.3,0.95624137,-0.18679456,52.97607,0,11.076097,432.81583,-0.012396004,12.327065,11.075637,432.59082,-9.2462215
145.6,0.94907868,-0.1884401,52.739483,0,11.076097,436.71585,-0.012512459,12.23974,11.075882,436.86475,-9.2436743
146.9,0.94570708,-0.1913877,52.635593,0,11.076097,440.61581,-0.012664848,12.198395,11.076733,440.77322,-9.2414932
148.2,0.94533044,-0.19183357,52.635502,0,11.076097,444.51578,-0.012700664,12.192944,11.076481,444.72073,-9.2394705
149.5,0.9317925,-0.19349894,52.632317,0,11.076097,448.4158,-0.012814802,12.010164,11.076758,448.62634,-9.2375612
150.8,0.92768174,-0.19477807,52.436886,0,11.076097,452.3158,-0.01287561,11.96144,11.076544,452.5766,-9.234951
152.1,0.9140017,-0.19576256,52.29192,0,11.076097,456.21579,-0.012951517,11.786168,11.076241,456.35007,-9.2331133
153.4,0.90614337,-0.19756626,52.504948,0,11.076097,460.11581,-0.013098707,11.692468,11.076103,460.14548,-9.2309713
154.7,0.89102691,-0.19765839,52.521271,0,11.076097,464.01581,-0.013121425,11.500721,11.075707,464.00699,-9.2284422
156.0,0.89204323,-0.19939876,52.595951,0,11.076097,467.91583,-0.01321857,11.508771,11.075711,467.94781,-9.2260609
157.3,0.8704378,-0.19932061,52.506248,0,11.076097,471.81586,-0.013196937,11.238943,11.076145,471.81204,-9.2239122
158.6,0.86393863,-0.20074515,52.572994,0,11.076097,475.71579,-0.013290059,11.13644,11.076132,475.75998,-9.2217684
159.9,0.85865432,-0.20016062,52.284492,0,11.076097,479.61581,-0.013251597,11.085172,11.076294,479.76105,-9.2197485
161.2,0.85467535,-0.20025757,52.389629,0,11.076097,483.51578,-0.013228229,11.04394,11.076439,483.50897,-9.2173119
162.5,0.84381586,-0.19888981,52.406387,0,11.076097,487.4158,-0.013154272,10.88743,11.076307,487.44788,-9.2150059
163.8,0.84909666,-0.19766495,52.283939,0,11.076097,491.3158,-0.01310071,10.945398,11.076262,491.48822,-9.2131958
165.1,0.8434689,-0.19390371,52.013893,0,11.076097,495.21582,-0.012858299,10.87751,11.075829,495.59756,-9.2113771
166.4,0.84308535,-0.19030677,51.932377,0,11.076097,499.11578,-0.012632281,10.882861,11.077042,499.44012,-9.2088737
167.7,0.5230242,-0.19952385,50.443771,0,11.076097,499.99884,-0.01321098,6.7399559,11.07584,501.78903,-9.2082977
169.0,0.35817304,-0.20372629,49.311443,0,11.076097,499.99884,-0.013483291,4.6299276,11.076669,502.08554,-9.2082672
170.3,0.34178528,-0.2037103,48.81226,0,11.076097,499.99884,-0.013487472,4.4130278,11.075938,501.7088,-9.2082777
171.6,0.34068885,-0.20396377,48.383793,0,11.076097,499.99884,-0.013486097,4.3988247,11.077438,501.43588,-9.2083921
172.9,0.33583054,-0.20424083,47.955326,0,11.076097,499.99884,-0.013502786,4.3256135,11.074951,501.24249,-9.2080431
174.2,0.34296498,-0.20401154,47.533363,0,11.076097,499.99884,-0.013507848,4.4314637,11.076373,501.10529,-9.2082739
175.5,0.34557226,-0.2044313,47.118755,0,11.076097,499.99884,-0.013550945,4.4603333,11.076632,501.0209,-9.2082291
176.8,0.34208333,-0.2041207,47.048523,0,11.076097,499.99884,-0.01354585,4.4043384,11.07555,500.82437,-9.2084818
178.1,0.34648624,-0.20444228,46.582035,0,11.076097,499.99884,-0.013554511,4.4600544,11.076055,500.66855,-9.2080812
179.4,0.34141549,-0.20443943,46.582035,0,11.076097,499.99884,-0.013526726,4.4122677,11.076073,500.51361,-9.2079887
180.7,0.35054499,-0.20449886,46.248928,0,11.076097,499.99884,-0.013534462,4.5226035,11.075836,500.55664,-9.2081232
182.0,0.3494193,-0.2053467,46.12006,0,11.076097,499.99884,-0.013589797,4.501142,11.074976,500.34558,-9.2080803
183.3,0.354922,-0.20491163,46.109623,0,11.076097,499.99884,-0.013535636,4.5762906,11.076426,500.24792,-9.2080126
184.6,0.35995391,-0.20552215,46.109623,0,11.076097,499.99884,-0.013596794,4.6519971,11.075562,500.28857,-9.2081404
185.9,0.35523775,-0.20552059,45.809158,0,11.076097,499.99884,-0.013614653,4.5825353,11.076248,500.33209,-9.2078209
187.2,0.35940889,-0.2065503,45.615238,0,11.076097,499.99884,-0.013691707,4.6534767,11.076427,500.28906,-9.2077456
188.5,0.35968804,-0.20604876,45.615238,0,11.076097,499.99884,-0.013653332,4.6481104,11.07662,500.19254,-9.2076826
189.8,0.35846356,-0.20690335,45.61755,0,11.076097,499.99884,-0.013686984,4.6371727,11.076573,500.17081,-9.2077303
191.1,0.35609913,-0.20679601,45.276142,0,11.076097,499.99884,-0.013691057,4.5990009,11.077151,500.37839,-9.2076025
192.4,0.36074194,-0.207728,45.187138,0,11.076097,499.99884,-0.013750437,4.6599541,11.077466,500.26575,-9.207551
193.7,0.36076996,-0.20721629,45.137711,0,11.076097,499.99884,-0.013691027,4.6646399,11.076685,500.21176,-9.2076406
195.0,0.36012149,-0.20832752,45.120853,0,11.076097,499.99884,-0.013775359,4.635457,11.077246,500.13187,-9.2074327
196.3,0.36536869,-0.20757772,45.120853,0,11.076097,499.99884,-0.013754372,4.712204,11.076493,500.09714,-9.2075405
197.6,0.36305711,-0.20859879,45.120857,0,11.076097,499.99884,-0.013834788,4.700614,11.075412,500.06909,-9.2073193
198.9,0.36032626,-0.20816709,45.120853,0,11.076097,499.99884,-0.013802488,4.6491904,11.077179,500.20703,-9.2071829
200.2,0.36761233,-0.20891646,44.652157,0,11.076097,499.99884,-0.0138195,4.7302556,11.07547,500.26358,-9.2073307
201.5,0.36746189,-0.20880885,44.7369,0,11.076097,499.99884,-0.013818985,4.7505941,11.076009,500.21875,-9.2071257
202.8,0.36486331,-0.20941913,44.607227,0,11.076097,499.99884,-0.0138589,4.736433,11.076889,500.09589,-9.2071114
204.1,0.36238047,-0.20986398,44.604614,0,11.076097,499.99884,-0.013874554,4.6777916,11.076578,500.1178,-9.2070522
205.4,0.36941266,-0.20982684,44.604496,0,11.076097,499.99884,-0.013869522,4.7753758,11.076103,500.18594,-9.2070274
206.7,0.36561629,-0.21040429,44.286186,0,11.076097,499.99884,-0.013937678,4.7297812,11.07582,500.28256,-9.206852
208.0,0.36394116,-0.21028945,44.120903,0,11.076097,499.99884,-0.013935325,4.6932826,11.076,500.17517,-9.2069483
209.3,0.37351611,-0.21121565,44.419979,0,11.076097,499.99884,-0.014009859,4.8098278,11.075717,500.0567,-9.2071018
210.6,0.36973235,-0.21079403,44.264698,0,11.076097,499.99884,-0.013957733,4.7880669,11.075567,500.09872,-9.2067251
211.8967,0.38520536,0.011679665,44.077915,0,11.076097,499.99884,0.00078738324,4.8992834,11.075789,500.07016,-9.2070599
211.9582,0.42004731,0.013982898,10.532493,0,11.076099,8.2256142e-14,0.00099198357,5.4520564,11.077038,499.97348,-9.206358
211.9608,0.40212521,0.018291419,0.0,0,11.076099,1.5391066e-31,0.0010504767,5.1074133,11.070925,499.96173,-9.2066622
211.9634,0.42031318,0.014292737,0.0,0,11.076099,0.0,0.00084331445,5.3584251,11.075119,499.9072,-9.208807
211.966,0.41073585,0.015853588,0.0,0,11.076099,0.0,0.00091905438,5.1763644,11.072966,499.85266,-9.2062635
211.9686,0.4118984,0.012121813,0.0,0,11.076099,0.0,0.00083819154,5.16923,11.076687,499.7981,-9.2068548
211.9712,0.3913281,0.012592003,0.0,0,11.076099,0.0,0.0010074046,5.0359197,11.077569,499.7673,-9.2070732
211.9738,0.42233825,0.013930742,0.0,0,11.076099,0.0,0.0011467054,5.3149996,11.077538,499.80627,-9.2062569
211.9764,0.40716538,0.014821945,0.0,0,11.076099,0.0,0.0010209247,5.2094312,11.076519,499.84521,-9.2066879
211.979,0.40903312,0.019761877,0.0,0,11.076099,0.0,0.0012167357,5.155302,11.072611,499.88419,-9.2076874
211.9816,0.43218029,0.01457826,0.0,0,11.076099,0.0,0.00085723132,5.4271541,11.078581,499.91324,-9.2074366
211.9842,0.4150233,0.018043624,0.0,0,11.076099,0.0,0.00098752766,5.3320422,11.079261,499.92883,-9.2074728
211.9868,0.4109132,0.013535579,0.0,0,11.076099,0.0,0.00087643712,5.2932115,11.077114,499.9444,-9.2074747
211.9894,0.43697512,0.015056854,0.0,0,11.076099,0.0,0.0010691204,5.5208945,11.078614,499.95999,-9.2061205
211.992,0.42118919,0.015464112,0.0,0,11.076099,0.0,0.0012306684,5.3611555,11.077378,499.97095,-9.2070084
211.9946,0.4138087,0.014640554,0.0,0,11.076099,0.0,0.0011364572,5.2847586,11.076775,499.97876,-9.2077007
211.9972,0.43844742,0.018788513,0.0,0,11.076099,0.0,0.0012663322,5.604651,11.081732,499.98654,-9.2091312
211.9998,0.4303771,0.015759686,0.0,0,11.076099,0.0,0.00095380767,5.4778452,11.075692,499.99432,-9.2074203
212.0024,0.42081165,0.019465445,0.0,0,11.076099,0.0,0.0010393723,5.3619843,11.076765,499.98431,-9.2067995
212.005,0.4251121,0.014748119,0.0,0,11.076099,0.0,0.00085342512,5.4353266,11.075407,499.96875,-9.2067919
212.0076,0.4301829,0.014887342,0.0,0,10.826063,0.0,0.0010273987,5.4731393,11.076956,499.95316,-9.2065105
212.0102,0.41369897,0.012965169,0.0,0,10.435008,0.0,0.0010907805,5.2563524,11.073448,499.93756,-9.2067947
212.0128,0.43341139,0.014927027,0.0,0,10.043953,0.0,0.0012060174,5.5948696,11.004425,499.92923,-9.2069521
212.0154,0.47362337,0.017826848,0.0,0,9.6528988,0.0,0.0013214691,6.0271287,10.758098,499.92145,-9.2072878
212.018,0.43387797,0.01762674,0.0,0,9.2678185,0.0,0.0011600701,5.4165988,10.36152,499.91367,-9.2069235
212.0206,0.97757661,0.038574122,0.0,0,8.8873863,0.0,0.0020685457,11.044126,9.8348932,499.93549,-9.2060843
212.0232,4.5368528,0.61674702,0.0,0,8.518857,0.0,0.041617192,54.723934,9.2689743,500.22372,-9.2029457
212.0258,4.2539072,1.0211692,0.0,0,8.1570415,0.0,0.069809556,50.515949,8.8110313,500.51199,-9.2041969
212.0284,4.6679049,1.414867,0.0,0,7.8078156,0.0,0.098738037,53.951809,8.4152451,500.80026,-9.2037144
212.031,4.8309193,1.728098,0.0,0,7.4635754,0.0,0.12219938,54.372917,8.060812,501.05917,-9.2035408
212.0336,4.8355598,2.0618289,0.0,0,7.1326995,0.0,0.14781603,53.118076,7.7294106,501.23834,-9.2027674
212.0362,5.2321563,2.3632915,0.0,0,6.8053074,0.0,0.17103361,56.128941,7.4247131,501.41754,-9.203022
212.0388,5.444438,2.6690571,0.0,0,6.4917622,0.0,0.1953225,57.008587,7.1244955,501.59671,-9.2034655
212.0414,5.9058499,2.9683464,0.0,0,6.1802821,0.0,0.21978553,60.310543,6.8138909,500.67914,-9.2023354
212.044,6.2265954,3.2768772,0.0,0,5.8832321,0.0,0.24585401,61.838142,6.5017424,498.35693,-9.2035284
212.0466,6.9186535,3.5852151,0.0,0,5.5874419,0.0,0.2726506,66.933708,6.1870623,496.03473,-9.2021942
212.0492,7.347683,3.8993709,0.0,0,5.3054934,0.0,0.30083913,69.229446,5.8723006,493.71249,-9.2018251
212.0518,7.6643782,4.2076693,0.0,0,5.0250487,0.0,0.32915375,70.119591,5.5632367,491.02539,-9.2028265
212.0544,7.9663167,4.50495,0.0,0,4.7569842,0.0,0.35683331,70.903282,5.2649889,488.10269,-9.2014017
212.057,8.2280064,4.8039432,0.0,0,4.4912457,0.0,0.38547927,71.174194,4.9731169,485.17999,-9.201623
212.0596,8.4389238,5.0842805,0.0,0,4.2362375,0.0,0.41320699,71.016083,4.6843896,482.25732,-9.201787
212.0622,8.910449,5.3575573,0.0,0,3.9844093,0.0,0.44096488,72.977631,4.4096885,481.52051,-9.20294
212.0648,9.1542063,5.6155167,0.0,0,3.7418811,0.0,0.46850672,72.950096,4.1499772,481.41135,-9.2025604
212.0674,9.3968191,5.8691196,0.0,0,3.5032687,0.0,0.49617818,72.822266,3.8953824,481.30219,-9.2026968
212.07,9.6512041,6.1182733,0.0,0,3.2725446,0.0,0.52417415,72.692894,3.6480279,481.19302,-9.2016563
212.0726,9.8778057,6.3594522,0.0,0,3.0464106,0.0,0.55157971,72.451584,3.4053073,480.39017,-9.2025595
212.0752,10.143162,6.6042619,0.0,0,2.8269184,0.0,0.58000368,72.282707,3.1712325,479.54785,-9.2013216
212.0778,10.420312,6.8357282,0.0,0,2.6126273,0.0,0.60756505,72.230667,2.9400575,478.70554,-9.2009506
212.0804,10.641381,7.0640292,0.0,0,2.4038472,0.0,0.63542926,71.731659,2.7185762,477.58228,-9.2013483
212.083,10.841026,7.2761803,0.0,0,2.2008004,0.0,0.66284227,71.12236,2.5040789,474.30511,-9.2023296
212.0856,11.103034,7.4844956,0.0,0,2.0022123,0.0,0.69064867,70.854774,2.2947485,471.02795,-9.2007713
212.0882,11.373313,7.6900268,0.0,0,1.8098084,0.0,0.71899539,70.541496,2.0881677,467.75079,-9.2011757
212.0908,11.609974,7.8918576,0.0,0,1.6208923,0.0,0.74714661,70.037132,1.8936939,464.66403,-9.1999149
212.0934,11.928031,8.0933218,0.0,0,1.4385693,0.0,0.77570474,69.900444,1.6955713,462.05582,-9.1999035
212.096,12.243448,8.2857666,0.0,0,1.2588574,0.0,0.80331284,69.817001,1.5052744,459.44757,-9.2004719
212.0986,12.545844,8.4786968,0.0,0,1.0861164,0.0,0.83165669,69.474121,1.3183991,456.83932,-9.1998796
212.1012,12.943255,8.6571846,0.0,0,0.91519243,0.0,0.85954159,69.725784,1.1332449,453.08813,-9.1998091
212.1038,13.351896,8.8325777,0.0,0,0.75155336,0.0,0.88779813,69.949913,0.94996411,447.96152,-9.1991625
212.1064,13.73336,9.0042562,0.0,0,0.58900136,0.0,0.91682649,69.872574,0.78274864,442.8349,-9.200388
212.109,14.207239,9.17173,0.0,0,0.4338859,0.0,0.94582415,70.209023,0.61189872,437.70828,-9.200532
212.1116,12.675639,9.2627621,0.0,0,0.27942541,0.0,0.96175629,61.62331,0.47542554,432.42349,-9.1999826
212.1142,11.795491,9.2847996,0.0,0,0.13226014,0.0,0.96533751,57.30817,0.41811383,427.04303,-9.200573
212.1168,11.24275,9.2851467,0.0,0,-0.014479235,0.0,0.96430475,54.604401,0.38605359,421.6626,-9.2029352
212.1194,10.853103,9.289463,0.0,0,-0.15794842,0.0,0.96492624,52.658249,0.35242864,416.28214,-9.2030458
212.122,10.903954,9.2941513,0.0,0,-0.30141643,0.0,0.96580464,52.839741,0.31380635,414.46869,-9.2035208
212.1246,11.186485,9.2934275,0.0,0,-0.44488442,0.0,0.96637702,54.142143,0.24693714,413.5903,-9.2034359
212.1272,11.33689,9.3018532,0.0,0,-0.58835238,0.0,0.96842349,54.820301,0.1692515,412.71191,-9.20226
212.1298,11.346913,9.3075981,0.0,0,-0.7318204,0.0,0.97000813,54.782993,0.10520195,411.83353,-9.202177
212.1324,11.23687,9.3134956,18.790285,0,-0.87528837,0.0,0.97061372,54.179611,0.04810347,412.24496,-9.2027817
212.135,11.027945,9.322731,38.332272,0,-1.0187564,0.0,0.97142327,53.178284,0.0057069147,412.70798,-9.2023296
212.1376,10.724839,9.3251257,57.874256,0,-0.9197427,499.99997,0.97130024,51.744411,-0.019526785,413.17102,-9.2028999
212.1402,10.309362,9.3274803,74.86084,0,-0.42304948,500.0,0.97142321,49.71064,-0.019081326,413.58478,-9.2043056
212.1428,10.089285,9.3203115,74.86084,0,0.073644094,500.0,0.97070795,48.589897,-0.0092104319,413.67111,-9.204566
212.1454,9.5945168,9.2928324,74.86084,0,0.57033795,500.0,0.96664798,46.462227,-0.0060136686,413.75742,-9.2038469
212.148,9.5384188,9.3235016,74.86084,0,1.0670311,500.0,0.97291231,45.969204,-0.0025156098,413.84375,-9.2044992
212.1506,9.0348349,9.3098345,74.834167,0,1.563725,500.0,0.97028852,43.655762,0.010251721,414.00064,-9.2045946
212.1532,7.7842789,9.3169985,74.74527,0,2.0604188,500.0,0.9708035,37.480373,0.096523911,414.32217,-9.2061396
212.1558,5.4310474,9.2879934,74.656357,0,2.557112,500.0,0.96506149,26.542765,0.25189039,414.64371,-9.2069349
212.1584,1.6444124,9.2777767,74.567459,0,3.0538058,500.0,0.96278602,8.5803461,0.50629848,414.96524,-9.2094288
212.161,-0.33853129,9.1338739,74.520271,0,3.5504992,500.0,0.93850285,-1.8101462,1.0951617,417.46198,-9.2134247
212.1636,-0.24011397,9.1379023,74.520271,0,4.0471931,500.0,0.93882036,-0.98313004,1.9853053,422.41925,-9.2116375
212.1662,0.30605832,9.2218285,74.520271,0,4.5438867,500.0,0.95429051,1.2946349,2.810708,427.37656,-9.2118797
212.1688,1.0569111,9.2802076,74.520271,0,5.0405803,500.0,0.96517134,5.2510581,3.4486783,432.33383,-9.2090874
212.1714,0.17920868,9.2451639,73.645035,0,5.5372739,500.0,0.95882708,0.84995073,3.9230216,434.29132,-9.2099266
212.174,0.32692787,9.2511473,72.27417,0,6.0339675,500.0,0.95923597,1.5663319,4.3833165,434.55014,-9.2098064
212.1766,0.46712869,9.2662926,70.903297,0,6.5306611,500.0,0.96077967,2.376672,4.8309178,434.80893,-9.2094183
212.1792,0.34346968,9.2478285,69.53244,0,7.0273547,500.0,0.95758861,1.7098886,5.2966628,435.06772,-9.2097435
212.1818,0.24349967,9.2404795,69.268799,0,7.5240483,500.0,0.95648062,1.1932491,5.7842627,435.10486,-9.2082272
212.1844,0.41404459,9.2314968,69.268799,0,8.0207424,500.0,0.95571804,1.9882119,6.3101687,435.08923,-9.2078037
212.187,0.22498916,9.2388382,69.268799,0,8.5174351,500.0,0.95781451,1.1392775,6.8365293,435.07361,-9.2088947
212.1896,0.4234589,9.2406063,69.268799,0,9.0141287,500.0,0.9583081,1.9803809,7.3617015,435.05798,-9.2076607
212.1922,0.38369972,9.2462387,69.153931,0,9.5108232,500.0,0.95873004,1.9140402,7.8790097,435.44067,-9.2061548
212.1948,0.48763743,9.2470999,69.036346,0,10.007517,500.0,0.95778072,2.4024673,8.3915501,435.83279,-9.207078
212.1974,0.26839679,9.2533798,68.918762,0,10.50421,500.0,0.95860213,1.3295273,8.8988914,436.22488,-9.2072191
212.2,0.33112273,9.2464838,68.818359,0,11.000903,500.0,0.95730901,1.5903873,9.4077797,436.61453,-9.2081585
212.2026,0.3760657,9.2399406,68.818359,0,11.497598,500.0,0.95683897,1.9361602,9.9186392,436.98972,-9.2069025
212.2052,0.17929426,9.2271528,68.818359,0,11.99429,500.0,0.95538694,0.85478503,10.422682,437.36487,-9.2061081
212.2078,0.42317545,9.2382183,68.818359,0,12.490984,500.0,0.95802128,2.0863967,10.939342,437.74005,-9.2063866
212.2104,0.35899258,9.240509,68.754143,0,12.987678,500.0,0.95798051,1.7698771,11.45422,438.11069,-9.2060614
212.213,0.13890181,9.2457523,68.550522,0,13.484371,500.0,0.95815986,0.66370469,11.955127,438.47144,-9.2061892
212.2156,0.44179225,9.2390099,68.346893,0,13.981066,500.0,0.95633638,2.1644421,12.455053,438.83218,-9.204546
212.2182,0.32116553,9.2541161,68.143272,0,14.477758,500.0,0.95834506,1.5044136,12.951362,439.19293,-9.2053308
212.2208,0.36515445,9.2433882,68.03833,0,14.974452,500.0,0.95705116,1.7961314,13.463703,439.47733,-9.2060118
212.2234,0.24588253,9.2489939,68.03833,0,15.471146,500.0,0.95876747,1.2677405,13.977845,439.68054,-9.2049646
212.226,0.33636221,9.2370195,68.03833,0,15.967839,500.0,0.95751137,1.728029,14.48822,439.88379,-9.2035894
212.2286,0.38782632,9.2441359,68.03833,0,16.464533,500.0,0.95894778,1.791098,15.001139,440.08701,-9.2054119
212.2312,0.41067171,9.2480183,67.927696,0,16.961227,500.0,0.95910561,1.9716295,15.499161,440.39322,-9.2054968
212.2338,0.46865642,9.2617874,67.758492,0,17.45792,500.0,0.96052206,2.3251667,15.991802,440.75397,-9.2060518
212.2364,0.40111959,9.2584562,67.589287,0,17.954613,500.0,0.95918059,1.9806002,16.477262,441.11472,-9.2043772
212.239,0.3007558,9.2549181,67.420074,0,18.0,500.0,0.958758,1.4477683,16.966215,441.47546,-9.2045755
212.2416,0.3963713,9.2493849,67.390137,0,18.0,500.0,0.95836031,1.987182,17.44034,441.69366,-9.2059994
212.2442,0.22997093,9.2451954,67.390137,0,18.0,500.0,0.95872939,1.1366318,17.86165,441.88126,-9.2070732
212.2468,0.39648178,9.2526932,67.390137,0,18.0,500.0,0.96019757,1.9318186,18.210192,442.06885,-9.2082005
212.2494,0.48057455,9.2538986,67.390137,0,18.0,500.0,0.96051276,2.3675911,18.442627,442.25644,-9.2113314
212.252,0.41774434,9.257781,67.171013,0,18.0,500.0,0.96042341,2.004092,18.539156,442.92599,-9.2182341
212.2546,0.60047257,9.26161,66.95018,0,18.0,500.0,0.96015871,2.9184184,18.4856,443.59927,-9.226449
212.2572,0.51182979,9.2650318,66.729347,0,18.0,500.0,0.96071255,2.5869937,18.335413,444.27255,-9.2386789
212.2598,0.47611544,9.2608461,66.544189,0,18.0,500.0,0.9598729,2.2848518,18.185081,444.74115,-9.2551203
212.2624,0.50249046,9.2561703,66.544189,0,18.0,500.0,0.95984906,2.4742603,18.081406,444.14709,-9.2748537
212.265,0.50557983,9.2364168,66.544189,0,18.0,500.0,0.95737761,2.4408364,18.03591,443.55307,-9.2968988
212.2676,0.45874855,9.2555962,66.544189,0,18.0,500.0,0.96093106,2.2812548,18.036543,442.95901,-9.3211155
212.2702,0.47832248,9.2567797,66.483475,0,18.0,500.0,0.96051699,2.3320007,18.054691,442.93692,-9.3443546
212.2728,0.38552493,9.2593203,66.299934,0,18.0,500.0,0.96010011,2.0262816,18.087046,444.07205,-9.3660593
212.2754,0.51788831,9.2468491,66.116386,0,18.0,500.0,0.95743459,2.6129909,18.109623,445.20718,-9.386076
212.278,0.39907092,9.2660351,65.932838,0,18.0,500.0,0.96071905,1.9132236,18.134979,446.34232,-9.4064913
212.2806,0.61252463,9.2524567,65.841064,0,18.0,500.0,0.95902735,2.9688897,18.143204,446.8161,-9.4239931
212.2832,0.42776141,9.2557249,65.841064,0,18.0,500.0,0.96004146,2.2926371,18.142294,446.62848,-9.4432907
212.2858,0.47940755,9.2443228,65.841064,0,18.0,500.0,0.95884037,2.3041482,18.148174,446.44089,-9.4643135
212.2884,0.61285263,9.2532301,65.841064,0,18.0,500.0,0.96035284,3.0039918,18.146528,446.2533,-9.4839821
212.291,0.57957822,9.2582388,65.841064,0,18.0,500.0,0.96053004,2.8604088,18.140974,446.44257,-9.5030413
212.2936,0.68816024,9.2692022,65.841064,0,18.0,500.0,0.96165335,3.356214,18.137447,446.81808,-9.52384
212.2962,0.54866499,9.2643118,65.841064,0,18.0,500.0,0.96004152,2.6453245,18.138138,447.1936,-9.5429249
212.2988,0.55987591,9.2585077,65.841064,0,18.0,500.0,0.95939726,2.7696042,18.126034,447.56912,-9.5610991
212.3014,0.49891728,9.2568607,65.841064,0,18.0,500.0,0.9600125,2.4127047,18.124647,447.76086,-9.582098
212.304,0.47103447,9.2487326,65.841064,0,18.0,500.0,0.95964813,2.2813358,18.124844,447.91718,-9.601428
212.3066,0.60212016,9.2567806,65.841064,0,18.0,500.0,0.96097362,2.9449322,18.119513,448.07352,-9.6196241
212.3092,0.54164946,9.2600031,65.839989,0,18.0,500.0,0.96124196,2.6320291,18.113335,448.23068,-9.6407566
212.3118,0.59824085,9.2588234,65.699455,0,18.0,500.0,0.96043414,2.8835182,18.117159,448.49643,-9.6615524
212.3144,0.7737177,9.2557478,65.558929,0,18.0,500.0,0.95904994,3.8091786,18.115286,448.76221,-9.6805305
212.317,0.38117057,9.2702456,65.418404,0,18.0,500.0,0.96158689,1.876321,18.111809,449.02795,-9.70016
212.3196,0.63933116,9.2581539,65.302734,0,18.0,500.0,0.95975375,3.0436258,18.10475,449.28403,-9.7193575
212.3222,0.61876434,9.2501087,65.302734,0,18.0,500.0,0.95922023,3.0183854,18.108118,449.49509,-9.737999
212.3248,0.43852186,9.236722,65.302734,0,18.0,500.0,0.95755005,2.1469395,18.105658,449.70612,-9.7594776
212.3274,0.62532234,9.2593822,65.302734,0,18.0,500.0,0.96141165,3.0412071,18.107767,449.91714,-9.7799206
212.33,0.66782278,9.2545004,65.252113,0,18.0,500.0,0.96001583,3.2657862,18.108015,450.14172,-9.7977419
212.3326,0.41281265,9.2580547,65.105843,0,18.0,500.0,0.95951188,2.1909544,18.10804,450.39185,-9.8188286
212.3352,0.62027127,9.2476044,64.959579,0,18.0,500.0,0.95760554,3.0185661,18.107138,450.64197,-9.8400965
212.3378,0.58531642,9.2632837,64.813316,0,18.0,500.0,0.96019685,2.8474293,18.104973,450.89209,-9.8583879
212.3404,0.56885582,9.2532234,64.742432,0,18.0,500.0,0.95926332,2.8087587,18.104271,451.10596,-9.8789835
212.343,0.53454715,9.2535162,64.742432,0,18.0,500.0,0.96011096,2.7790582,18.098558,451.28574,-9.8989134
212.3456,0.6368283,9.2417603,64.742432,0,18.0,500.0,0.95837522,3.1328044,18.105154,451.46548,-9.9173069
212.3482,0.59876919,9.2566338,64.742432,0,18.0,500.0,0.96055251,2.9420564,18.104685,451.64526,-9.9367552
212.3508,0.58886254,9.2634125,64.673714,0,18.0,500.0,0.96102768,2.8497071,18.101652,451.82504,-9.9556818
212.3534,0.8816576,9.2695189,64.573341,0,18.0,500.0,0.96146607,4.2704072,18.096758,452.00482,-9.9757204
212.356,0.51874626,9.2679996,64.472954,0,18.0,500.0,0.96059245,2.5851052,18.096619,452.1846,-9.9950008
212.3586,0.56403196,9.2607403,64.372581,0,18.0,500.0,0.96019834,2.689121,18.094566,452.36438,-10.014203
212.3612,0.67764932,9.2527428,64.35791,0,18.0,500.0,0.95948303,3.3010819,18.0928,452.52414,-10.03451
212.3638,0.45524079,9.2531815,64.35791,0,18.0,500.0,0.96052039,2.2183323,18.09436,452.68045,-10.053284
212.3664,0.59111041,9.260972,64.35791,0,18.0,500.0,0.96165258,2.8435357,18.095251,452.83679,-10.075429
212.369,0.71611863,9.260622,64.355591,0,18.0,500.0,0.96113253,3.452528,18.090363,452.99438,-10.094712
212.3716,0.63166213,9.2599716,64.255219,0,18.0,500.0,0.96024197,3.1173985,18.093971,453.20541,-10.113217
212.3742,0.74546641,9.2623901,64.154839,0,18.0,500.0,0.95998824,3.6154723,18.090307,453.41644,-10.134735
212.3768,0.56846976,9.2688913,64.054466,0,18.0,500.0,0.96137577,2.7578063,18.087269,453.62747,-10.152727
212.3794,0.6778428,9.2589293,63.973389,0,18.0,500.0,0.96012366,3.3029947,18.089851,453.82199,-10.171818
212.382,0.56200451,9.2535429,63.973389,0,18.0,500.0,0.96009153,2.7324407,18.086885,453.94705,-10.192713
212.3846,0.59501964,9.2367001,63.973389,0,18.0,500.0,0.95765704,2.8543739,18.084076,454.07211,-10.212802
212.3872,0.70619565,9.2616568,63.973389,0,18.0,500.0,0.961806,3.4779816,18.088636,454.19717,-10.231657
212.3898,0.60434103,9.2590084,63.954731,0,18.0,500.0,0.96053946,2.9552822,18.087498,454.31943,-10.252876
212.3924,0.61301243,9.2668247,63.903107,0,18.0,500.0,0.96088153,3.0526445,18.08498,454.43668,-10.272246
212.395,0.73162413,9.2469406,63.851486,0,18.0,500.0,0.95743448,3.6468925,18.083216,454.55389,-10.291021
212.3976,0.51591742,9.2677717,63.799862,0,18.0,500.0,0.96124536,2.4993212,18.08341,454.67114,-10.310817
212.4002,0.6925016,9.2555218,63.775635,0,18.0,500.0,0.9599278,3.3405578,18.082762,454.78009,-10.33186
212.4028,0.69493121,9.2518978,63.775635,0,18.0,500.0,0.9596203,3.6105433,18.07497,454.88171,-10.349671
212.4054,0.58310986,9.2485247,63.775635,0,18.0,500.0,0.95957798,2.8632662,18.081852,454.98331,-10.370235
212.408,0.70165884,9.2588234,63.775635,0,18.0,500.0,0.96086454,3.3295667,18.081955,455.08493,-10.390079
212.4106,0.72961944,9.2606106,63.739498,0,18.0,500.0,0.96026272,3.5753818,18.080221,455.2522,-10.409829
212.4132,0.81284171,9.269392,63.687874,0,18.0,500.0,0.96135169,3.916764,18.081692,455.4476,-10.430107
212.4158,0.61143994,9.264143,63.636253,0,18.0,500.0,0.96029598,2.9315495,18.075357,455.64301,-10.451056
212.4184,0.72161263,9.2539396,63.584629,0,18.0,500.0,0.95942152,3.5052278,18.073862,455.83841,-10.469486
212.421,0.62179601,9.2538958,63.577881,0,18.0,500.0,0.96001941,3.0795736,18.074659,455.96585,-10.488667
212.4236,0.51968777,9.2541466,63.577881,0,18.0,500.0,0.96093148,2.472569,18.076813,456.08307,-10.509864
212.4262,0.74653262,9.2571497,63.577881,0,18.0,500.0,0.96074951,3.6394687,18.073027,456.20029,-10.527942
212.4288,0.69815761,9.2611752,63.573803,0,18.0,500.0,0.96088856,3.4286015,18.072756,456.31873,-10.547928
212.4314,0.66127878,9.2605066,63.46769,0,18.0,500.0,0.96004456,3.1934938,18.074369,456.46722,-10.567904
212.434,0.93090695,9.2579813,63.361576,0,18.0,500.0,0.95904988,4.5516348,18.072231,456.61575,-10.586628
212.4366,0.55631709,9.2674294,63.255463,0,18.0,500.0,0.96110648,2.7520688,18.071924,456.76425,-10.606474
212.4392,0.68211538,9.2569437,63.171391,0,18.0,500.0,0.96008676,3.2996936,18.070332,456.90302,-10.62836
212.4418,0.75886136,9.2491245,63.171391,0,18.0,500.0,0.95966262,3.6880443,18.071634,457.00449,-10.647027
212.4444,0.59945983,9.2375202,63.171391,0,18.0,500.0,0.95765781,2.9545715,18.071991,457.10596,-10.665652
212.447,0.70507503,9.2643518,63.171391,0,18.0,500.0,0.9620254,3.4214642,18.072111,457.20743,-10.686745
212.4496,0.80352056,9.2589321,63.150852,0,18.0,500.0,0.96026939,3.890584,18.071512,457.32074,-10.704915
212.4522,0.6955561,9.2591066,63.096359,0,18.0,500.0,0.95945132,3.5328181,18.069094,457.45361,-10.72522
212.4548,0.73402733,9.2476625,63.041866,0,18.0,500.0,0.95759535,3.5973625,18.064013,457.58649,-10.744712
212.4574,0.72757339,9.2589216,62.987377,0,18.0,500.0,0.96010667,3.5163529,18.065931,457.71936,-10.763292
212.46,0.75195414,9.2496138,62.962646,0,18.0,500.0,0.95922893,3.6893094,18.066925,457.80524,-10.783653
212.4626,0.76542395,9.2519236,62.962646,0,18.0,500.0,0.96009135,3.8788767,18.062656,457.85208,-10.805427
212.4652,0.76044208,9.2442789,62.962646,0,18.0,500.0,0.95880967,3.6755974,18.064672,457.89893,-10.82504
212.4678,0.79080927,9.2553701,62.962646,0,18.0,500.0,0.96003938,3.9258301,18.06369,457.94577,-10.843434
212.4704,0.69552922,9.2605371,62.923664,0,18.0,500.0,0.95982635,3.393965,18.063068,458.04858,-10.864684
212.473,0.96257281,9.2654314,62.869175,0,18.0,500.0,0.96056646,4.6644936,18.064379,458.17361,-10.88431
212.4756,0.74791384,9.2601833,62.814682,0,18.0,500.0,0.95974141,3.6561582,18.056101,458.29868,-10.902351
212.4782,0.67547536,9.2560863,62.760197,0,18.0,500.0,0.9600181,3.2803683,18.057749,458.42374,-10.922576
212.4808,0.7828055,9.2505827,62.753906,0,18.0,500.0,0.95960081,3.798409,18.059406,458.54175,-10.942924
212.4834,0.63016158,9.2519894,62.753906,0,18.0,500.0,0.96021348,3.0817122,18.058704,458.65884,-10.961863
212.486,0.70868576,9.2582788,62.753906,0,18.0,500.0,0.9607529,3.4548945,18.057684,458.77594,-10.981993
212.4886,0.801238,9.2585516,62.753906,0,18.0,500.0,0.96011639,3.8854117,18.054199,458.88968,-11.00178
212.4912,0.81700534,9.2541857,62.753906,0,18.0,500.0,0.9588328,3.9902952,18.057533,458.94437,-11.020478
212.4938,0.88676864,9.2575541,62.753906,0,18.0,500.0,0.95915717,4.3803263,18.059771,458.99908,-11.040877
212.4964,0.66720241,9.2608995,62.753906,0,18.0,500.0,0.96055114,3.2200484,18.056419,459.0538,-11.061402
212.499,0.85550231,9.2482758,62.753906,0,18.0,500.0,0.95894063,4.206625,18.054649,459.11896,-11.080176
212.5016,0.73012358,9.2469225,62.753906,0,18.0,500.0,0.95932013,3.5770972,18.054716,459.22043,-11.09941
212.5042,0.67157972,9.2352533,62.753906,0,18.0,500.0,0.95726603,3.1966348,18.057074,459.3219,-11.12047
212.5068,0.88574535,9.2583504,62.753906,0,18.0,500.0,0.96067345,4.3267417,18.054276,459.42337,-11.138613
212.5094,0.7973485,9.2556238,62.711159,0,18.0,500.0,0.95931524,3.9127715,18.053322,459.56476,-11.159172
212.512,0.74831975,9.253499,62.602173,0,18.0,500.0,0.9583292,3.6691279,18.05225,459.76791,-11.178082
212.5146,0.93874997,9.2410755,62.493191,0,18.0,500.0,0.9565773,4.6441398,18.05418,459.97107,-11.19721
212.5172,0.72468966,9.2565575,62.384209,0,18.0,500.0,0.95999372,3.5885642,18.056152,460.17426,-11.21831
212.5198,0.78823352,9.2487335,62.336426,0,18.0,500.0,0.95956045,3.8405893,18.053339,460.21072,-11.238563
212.5224,1.0025988,9.2480469,62.336426,0,18.0,500.0,0.95958406,4.9756699,18.05575,460.11707,-11.25825
212.525,0.77116632,9.2435675,62.336426,0,18.0,500.0,0.95840132,3.7590065,18.054234,460.02341,-11.279051
212.5276,0.78958052,9.2550917,62.336426,0,18.0,500.0,0.95966327,3.8286808,18.055071,459.92972,-11.299121
212.5302,0.88851112,9.2544823,50.445175,0,18.0,500.0,0.95866901,4.2963676,18.047424,459.98438,-11.317431
212.5328,1.0226226,9.2610512,34.172615,0,18.0,500.0,0.9596588,4.964313,18.052979,460.09366,-11.336957
212.5354,0.7376684,9.2554502,17.900055,0,18.0,500.0,0.95906794,3.573674,18.046446,460.20294,-11.356136
213.2365,0.79041231,9.2519789,0.0,0,18.0,1.4427177e-07,0.95913166,3.8596976,18.004078,424.23492,-11.481141
214.5365,0.72353441,9.2456865,0.0,0,18.0,2.6994808e-25,0.95814645,3.5344286,18.00038,346.07141,-11.480923
215.8365,0.6577878,9.2379608,0.0,0,18.0,5.0446745e-43,0.95680857,3.2193198,18.000044,286.30276,-11.481317
217.1365,0.64451557,9.240593,0.0,0,18.0,1.4012985e-45,0.95717615,3.1457326,18.001041,241.57301,-11.481631
218.4365,0.64800525,9.2473965,0.0,0,18.0,1.4012985e-45,0.95843422,3.1614177,18.000046,211.53502,-11.481956
219.7365,0.64780223,9.2528849,0.0,0,18.0,1.4012985e-45,0.95944977,3.1640229,18.000004,191.24657,-11.48146
221.0365,0.6546849,9.2589369,0.0,0,18.0,1.4012985e-45,0.96042961,3.1932931,17.99966,177.12389,-11.481557
222.3365,0.66175717,9.2641087,0.0,0,18.0,1.4012985e-45,0.96125543,3.2209868,17.999666,166.02803,-11.481191
223.6365,0.65606391,9.2687998,0.0,0,18.0,1.4012985e-45,0.96204883,3.1951416,18.000015,156.38707,-11.48098
224.9365,0.6643942,9.273119,0.0,0,18.0,1.4012985e-45,0.96288979,3.2301106,17.999638,148.12097,-11.481165
226.2365,0.66920269,9.2772036,0.0,0,18.0,1.4012985e-45,0.96364748,3.2498219,17.999996,142.0143,-11.481225
227.5365,0.68232441,9.281641,0.0,0,18.0,1.4012985e-45,0.9643572,3.3103156,18.000162,136.21461,-11.481525
228.8365,0.68215674,9.2854261,0.0,0,18.0,1.4012985e-45,0.96504313,3.3123634,17.999748,130.90718,-11.481242
230.1365,0.69183487,9.2895346,0.0,0,18.0,1.4012985e-45,0.96582669,3.3549013,17.999619,126.34693,-11.481476
231.4365,0.69074488,9.2927113,0.0,0,18.0,1.4012985e-45,0.96636128,3.3450167,18.000185,122.18018,-11.481228
232.7365,0.692137,9.2963533,0.0,0,18.0,1.4012985e-45,0.96690589,3.3565147,17.999704,118.50691,-11.481236
234.0365,0.69814306,9.299901,0.0,0,18.0,1.4012985e-45,0.9674753,3.3755403,18.000389,115.04652,-11.481658
235.3365,0.70222622,9.3030243,0.0,0,18.0,1.4012985e-45,0.96807402,3.3938766,18.000172,112.30669,-11.48117
236.6365,0.71826869,9.3064041,0.0,0,18.0,1.4012985e-45,0.96873593,3.4719291,18.000134,108.74213,-11.481496
237.9365,0.70842904,9.3092756,0.0,0,18.0,1.4012985e-45,0.96924204,3.4209383,18.00066,106.20294,-11.481471
239.2365,0.71411407,9.3121023,0.0,0,18.0,1.4012985e-45,0.96967942,3.4514194,17.999336,103.27969,-11.481225
240.5365,0.7187202,9.314621,0.0,0,18.0,1.4012985e-45,0.97016782,3.4666255,18.00069,100.61847,-11.481515
241.8365,0.72138143,9.3170767,0.0,0,18.0,1.4012985e-45,0.97066295,3.4775622,18.000149,98.137367,-11.481154
243.1365,0.72347486,9.3200073,0.0,0,18.0,1.4012985e-45,0.97115356,3.4893355,18.000313,96.123955,-11.481211
244.4365,0.74317712,9.3228741,0.0,0,18.0,1.4012985e-45,0.97158515,3.58248,18.000732,93.927666,-11.481342
245.7365,0.73307687,9.3256044,0.0,0,18.0,1.4012985e-45,0.97201556,3.5311201,17.999912,91.670265,-11.481158
247.0365,0.72858649,9.3276939,0.0,0,18.0,1.4012985e-45,0.972408,3.5091031,17.999859,89.606895,-11.481089
248.3365,0.75063747,9.3297253,0.0,0,18.0,1.4012985e-45,0.97283888,3.60921,18.000059,87.575432,-11.481465
249.6365,0.74669081,9.332099,0.0,0,18.0,1.4012985e-45,0.97324318,3.5931635,18.000166,85.630455,-11.481226
250.9365,0.74648923,9.3343716,0.0,0,18.0,1.4012985e-45,0.97360456,3.58864,18.000694,83.983681,-11.481182
252.2365,0.74788779,9.3361635,0.0,0,18.0,1.4012985e-45,0.97398198,3.596004,17.999571,82.126549,-11.481095
253.5365,0.73619866,9.3381386,0.0,0,18.0,1.4012985e-45,0.97439998,3.5367069,17.999998,80.404701,-11.481208
254.8365,0.75798857,9.3406496,0.0,0,18.0,1.4012985e-45,0.97477627,3.6386185,18.001144,78.859001,-11.481066
256.1365,0.75368035,9.3427525,0.0,0,18.0,1.4012985e-45,0.9750697,3.6190124,18.000069,77.172813,-11.481277
257.4365,0.73660505,9.344656,0.0,0,18.0,1.4012985e-45,0.97540694,3.5341456,17.999832,75.453621,-11.480931
258.7365,0.76375288,9.3463869,0.0,0,18.0,1.4012985e-45,0.97570586,3.6667256,18.000164,73.882141,-11.481247
260.0365,0.7480309,9.3475389,0.0,0,18.0,1.4012985e-45,0.97601354,3.5917089,18.000124,72.596725,-11.481161
261.3365,0.74298531,9.3493786,0.0,0,18.0,1.4012985e-45,0.97630179,3.5604725,17.999786,71.265495,-11.480906
262.6365,0.75980049,9.3513403,0.0,0,18.0,1.4012985e-45,0.97660452,3.6460218,18.000481,68.953354,-11.481166
263.9365,0.7503922,9.3529148,0.0,0,18.0,1.4012985e-45,0.97696716,3.6003039,17.999678,67.61132,-11.480888
265.2365,0.74655646,9.3545218,0.0,0,18.0,1.4012985e-45,0.97727764,3.5795557,18.000555,66.423332,-11.480877
266.5365,0.74993777,9.3560247,0.0,0,18.0,1.4012985e-45,0.97746587,3.5958259,17.999451,65.269524,-11.480922
267.8365,0.76801735,9.3578348,0.0,0,18.0,1.4012985e-45,0.97773838,3.6756589,18.000565,64.203148,-11.481236
269.1365,0.77039868,9.3594913,0.0,0,18.0,1.4012985e-45,0.97798842,3.6919322,18.000372,62.87846,-11.481193
270.4365,0.75841224,9.360816,0.0,0,18.0,1.4012985e-45,0.97829151,3.6354983,18.000687,61.866096,-11.480923
271.7365,0.75189984,9.3617182,0.0,0,18.0,1.4012985e-45,0.97852075,3.5973117,17.999767,60.6875,-11.480994
272.5365,0.76645207,9.3630676,0.0,0,18.0,1.4012985e-45,0.978625,3.6706982,18.000057,60.171032,-11.638687