File: raw data/testID_0239.csv
Time(sec),Force(kN),Jaw(mm),PowAngle(deg),Power(W),Pram,PTemp,Strain,Stress(MPa),Stroke(mm),TC1(C),wedge(mm)
0.0,1.6322851,-0.042755306,0.0,0,10.594783,0.0013620744,-0.0028427802,20.847967,10.596064,13.224101,-9.120635
2.1,1.5221552,0.0050985529,0.0,0,10.594783,6.2159147,0.00034807119,19.360708,10.594452,13.293053,-9.4871759
4.2,1.4779282,0.0054938714,0.0,0,10.594783,12.515912,0.00037104019,18.817156,10.59516,13.240106,-9.4842482
6.3,1.4471768,0.0053117145,29.468721,0,10.594783,18.815912,0.00035925428,18.425415,10.594405,13.308414,-9.4806051
8.4,1.4616935,0.002676368,44.527176,0,10.594783,25.115913,0.00018377531,18.608574,10.594308,15.987804,-9.476346
10.5,1.4770921,-0.0023173806,49.526077,0,10.594783,31.415913,-0.00013974865,18.815306,10.595659,23.955175,-9.4733114
12.6,1.4659512,-0.0065914332,48.385246,0,10.594783,37.715927,-0.00041326019,18.675646,10.594766,35.600391,-9.4698086
14.7,1.4345435,-0.0079086628,43.022842,0,10.594783,44.015919,-0.00050904369,18.258841,10.594475,46.700691,-9.466198
16.8,1.4048264,-0.0063735866,38.551361,0,10.594783,50.31591,-0.00039554355,17.880833,10.59497,53.714264,-9.4626627
18.9,1.38861,-0.0048396732,39.920738,0,10.594783,56.61591,-0.00030195562,17.689674,10.595697,57.274483,-9.4594345
21.0,1.3889228,-0.0059785116,44.515202,0,10.594783,62.915913,-0.00039287351,17.695297,10.594214,60.589638,-9.4558258
23.1,1.3985487,-0.0086082909,47.05444,0,10.594783,69.215904,-0.0005592021,17.813173,10.595025,66.315353,-9.4523964
25.2,1.376773,-0.011220798,47.408264,0,10.594783,75.515915,-0.00075458013,17.545294,10.594487,74.296349,-9.4484873
27.3,1.3786087,-0.012803324,46.057407,0,10.594783,81.815926,-0.00085907022,17.581493,10.59508,82.33329,-9.4447746
29.4,1.3759604,-0.012630564,45.12085,0,10.594783,88.115921,-0.00085884763,17.534958,10.596081,88.905327,-9.4416885
31.5,1.3722166,-0.013771795,45.611599,0,10.594783,94.415924,-0.00093914615,17.489553,10.59432,94.416092,-9.4377708
33.6,1.3647933,-0.014649355,46.582027,0,10.594783,100.71591,-0.00099401886,17.385214,10.595636,99.918098,-9.4344072
35.7,1.3542717,-0.016812092,47.054604,0,10.594783,107.01591,-0.0011434167,17.263582,10.595511,106.20422,-9.4303608
37.8,1.3541007,-0.018664375,47.054447,0,10.594783,113.31593,-0.0012627144,17.27158,10.594337,113.10949,-9.4265757
39.9,1.3446057,-0.02040684,46.582035,0,10.594783,119.61593,-0.0013827201,17.147678,10.59499,119.95074,-9.4227829
42.0,1.3535697,-0.021601262,46.109623,0,10.594783,125.91592,-0.0014563751,17.248774,10.595463,126.18036,-9.4201937
44.1,1.3465958,-0.023610873,46.581997,0,10.594783,132.21591,-0.001581729,17.183552,10.594886,132.06198,-9.4164219
46.2,1.3455287,-0.025544338,47.05444,0,10.594783,138.5159,-0.0017008316,17.172138,10.594546,138.16869,-9.4131737
48.3,1.348539,-0.027896259,47.05444,0,10.594783,144.81592,-0.0018458044,17.194931,10.594137,144.6501,-9.4097023
50.4,1.3533387,-0.030484702,47.058353,0,10.594783,151.11592,-0.0020249903,17.258287,10.595318,150.9024,-9.4055443
52.5,1.347705,-0.03218846,47.055161,0,10.594783,157.41592,-0.0021325985,17.202686,10.594908,157.41302,-9.4019699
54.6,1.3396543,-0.034384843,46.66935,0,10.594783,163.71591,-0.0022783037,17.094681,10.594462,164.01039,-9.3987217
56.7,1.3302641,-0.036673564,46.677322,0,10.594783,170.0159,-0.0024301668,16.980312,10.594981,170.15897,-9.3955936
58.8,1.3504972,-0.03953078,47.002872,0,10.594783,176.3159,-0.0026334238,17.235107,10.594611,176.31476,-9.3920116
60.9,1.3386294,-0.041792836,46.66238,0,10.594783,182.61592,-0.0027795832,17.093811,10.594822,182.698,-9.3881388
63.0,1.3341219,-0.044638082,46.750591,0,10.594783,188.91591,-0.00296997,17.023848,10.594295,188.97221,-9.3845797
65.1,1.341023,-0.047333173,46.627716,0,10.594783,195.21591,-0.003137344,17.12372,10.593925,195.23819,-9.3812065
67.2,1.3520801,-0.050796736,46.582035,0,10.594783,201.5159,-0.0033617734,17.281082,10.594125,201.60483,-9.3778
69.3,1.3407342,-0.053742934,46.616985,0,10.594783,207.81592,-0.0035585132,17.123732,10.595605,207.84554,-9.374218
71.4,1.3362138,-0.057071205,46.582035,0,10.594783,214.11592,-0.0037726383,17.067394,10.595874,214.14442,-9.371089
73.5,1.3358282,-0.060765535,46.582035,0,10.594783,220.41591,-0.004017734,17.060665,10.594532,220.44031,-9.3672733
75.6,1.3511044,-0.064397745,46.582016,0,10.594783,226.71591,-0.0042740642,17.306606,10.593694,226.86816,-9.3633709
77.7,1.3419789,-0.067600332,46.109623,0,10.594783,233.0159,-0.0044947048,17.174894,10.594786,233.2233,-9.3598852
79.8,1.3492798,-0.07126268,46.568134,0,10.594783,239.3159,-0.0047532814,17.279114,10.594552,239.1537,-9.3565731
81.9,1.3546679,-0.075312436,46.071472,0,10.594783,245.61592,-0.005017898,17.338718,10.595098,246.03662,-9.3533773
84.0,1.3657665,-0.079289876,46.109619,0,10.594783,251.91591,-0.0052895183,17.465992,10.594913,251.99057,-9.3497772
86.1,1.3775015,-0.082571648,46.582027,0,10.594783,258.21619,-0.0055051707,17.635069,10.595782,257.93051,-9.3463812
88.2,1.3704107,-0.086812392,46.109623,0,10.594783,264.5159,-0.0057920446,17.545755,10.595057,264.67599,-9.3428631
90.3,1.3649225,-0.091008686,45.797852,0,10.594783,270.81592,-0.0060557653,17.480333,10.595849,271.07169,-9.3389654
92.4,1.39012,-0.095602661,46.10952,0,10.594783,277.11594,-0.0063562943,17.827326,10.594477,277.07336,-9.3357458
94.5,1.3951676,-0.09872821,46.285759,0,10.594783,283.41592,-0.006558605,17.878523,10.594819,283.18591,-9.3322687
96.6,1.3864071,-0.10383866,46.109623,0,10.594783,289.71588,-0.0068857656,17.766542,10.594292,289.74304,-9.3285208
98.7,1.3969011,-0.10787452,45.615238,0,10.594783,296.0159,-0.0071591218,17.919981,10.595499,296.31696,-9.3256559
100.8,1.4150512,-0.11210261,45.643578,0,10.594783,302.31592,-0.0074384776,18.148149,10.595006,302.37219,-9.3222218
102.9,1.4158801,-0.11646368,46.002861,0,10.594783,308.61591,-0.0077335606,18.156097,10.594638,308.63055,-9.3186951
105.0,1.4054357,-0.12077671,45.615238,0,10.594783,314.91592,-0.0080198925,18.037014,10.594018,315.15881,-9.315402
107.1,1.4295245,-0.12539268,45.615231,0,10.594783,321.21591,-0.0083155762,18.354326,10.596122,321.34235,-9.311904
109.2,1.4137526,-0.12794995,45.615231,0,10.594783,327.5159,-0.0084824795,18.16284,10.595314,327.49887,-9.3084097
111.3,1.4203122,-0.13199976,46.109474,0,10.594783,333.81592,-0.008739314,18.253929,10.594362,333.57172,-9.3045511
113.4,1.3867235,-0.13548419,45.604431,0,10.594783,340.11594,-0.0089674778,17.806416,10.593985,340.42697,-9.3005848
115.5,1.3866043,-0.13892388,45.304935,0,10.594783,346.41592,-0.0092016049,17.816418,10.594995,346.59668,-9.2974949
117.6,1.3677591,-0.14056666,45.61483,0,10.594783,352.71591,-0.0093136141,17.588385,10.594559,352.74927,-9.2937651
119.7,1.3487144,-0.14204976,45.543106,0,10.594783,359.0159,-0.0094203791,17.338863,10.595801,359.01935,-9.2906981
121.8,0.32408273,-0.161667,41.2145,0,10.594783,359.99924,-0.010725167,4.1782002,10.59502,362.48434,-9.2901564
123.9,0.33775651,-0.16003984,43.527237,0,10.594783,359.99924,-0.010628185,4.3557343,10.595108,359.63397,-9.2901411
126.0,0.37153703,-0.16346824,44.624348,0,10.594783,359.99924,-0.010859605,4.7819009,10.594986,359.24686,-9.2900925
128.1,0.36156616,-0.16512944,42.400963,0,10.594783,359.99924,-0.01097101,4.6546698,10.594555,361.1163,-9.2895861
130.2,0.3296614,-0.16508384,41.802982,0,10.594783,359.99924,-0.010963293,4.2412162,10.595226,360.75156,-9.2894058
132.3,0.35692531,-0.16544504,42.978512,0,10.594783,359.99924,-0.01098421,4.5903044,10.595417,359.69739,-9.2891798
134.4,0.3625989,-0.16788507,42.396286,0,10.594783,359.99924,-0.011131694,4.6599102,10.594815,360.23694,-9.2887516
136.5,0.36798871,-0.16868518,41.212032,0,10.594783,359.99924,-0.011183314,4.7493834,10.596085,360.65143,-9.2889023
138.6,0.3676002,-0.16841553,41.799381,0,10.594783,359.99924,-0.011151727,4.7300634,10.59403,360.11279,-9.2888308
140.7,0.36504161,-0.16987024,41.371288,0,10.594783,359.99924,-0.011246797,4.6998029,10.594395,360.18884,-9.2888947
142.8,0.37082219,-0.17062211,41.198734,0,10.594783,359.99924,-0.011305622,4.7695603,10.594979,360.20984,-9.2892256
144.9,0.36914507,-0.17131948,41.198727,0,10.594783,359.99924,-0.011358066,4.755734,10.594326,360.20007,-9.2891798
147.0,0.37033814,-0.1724306,40.572514,0,10.594783,359.99924,-0.011427855,4.78619,10.594032,360.2706,-9.2889786
149.1,0.37659046,-0.17266411,40.573917,0,10.594783,359.99924,-0.011447056,4.8505473,10.594681,360.06781,-9.28862
151.2,0.37710357,-0.17276095,40.781235,0,10.594783,359.99924,-0.011449566,4.8691697,10.594933,359.96307,-9.2885427
153.3,0.37583068,-0.1735106,40.572514,0,10.594783,359.99924,-0.011480869,4.8444214,10.594931,360.06769,-9.2884007
155.4,0.3712616,-0.17421776,40.037029,0,10.594783,359.99924,-0.011524301,4.7828875,10.594759,360.2496,-9.2885313
157.5,0.37870741,-0.17438358,40.143105,0,10.594783,359.99924,-0.011534135,4.8720465,10.594207,360.06213,-9.2884998
159.6,0.38361174,-0.17537345,40.044941,0,10.594783,359.99924,-0.011603479,4.9323301,10.594525,360.09158,-9.2890062
161.7,0.37043199,-0.17564596,39.925743,0,10.594783,359.99924,-0.011629292,4.7805223,10.594059,360.11584,-9.2887135
163.8,0.3710447,-0.17647554,39.924412,0,10.594783,359.99924,-0.011687561,4.7825809,10.594707,360.06555,-9.2886686
165.2825,0.51497495,0.015740175,39.125805,0,10.5948,0.00020810658,0.00096890592,6.5695128,10.596344,360.18509,-9.2885952
165.2867,0.51020676,0.017156873,22.357595,0,10.5948,4.7963358e-33,0.0010624117,6.4853597,10.596463,360.13416,-9.2888451
165.2909,0.5083195,0.014525498,5.5893822,0,10.5948,0.0,0.0012132132,6.5131712,10.596728,360.08325,-9.2890034
165.2951,0.53742683,0.017856801,0.0,0,10.5948,0.0,0.0010989478,6.7242718,10.592596,360.10022,-9.288434
165.2993,0.54622304,0.020507673,0.0,0,10.5948,0.0,0.0011780872,6.8904262,10.593938,360.15112,-9.2888145
165.3035,0.53782666,0.016204998,0.0,0,10.5948,0.0,0.0013183043,6.9221668,10.593191,360.19476,-9.2893744
165.3077,0.54615945,0.015539682,0.0,0,10.5948,0.0,0.00097079069,6.8876371,10.593333,360.22021,-9.2882614
165.3119,0.5380128,0.01863247,0.0,0,10.5948,0.0,0.0011640582,6.8314705,10.596199,360.2457,-9.2881393
165.3161,0.54099613,0.016621564,0.0,0,10.5948,0.0,0.0013196217,6.9521194,10.595084,360.16748,-9.2878265
165.3203,0.54873627,0.018614875,0.0,0,10.5948,0.0,0.0011428541,6.8782711,10.594698,360.07837,-9.288806
165.3245,0.54569501,0.021745287,0.0,0,10.5948,0.0,0.0012762183,6.947269,10.595204,360.03595,-9.2887859
165.3287,0.5713529,0.018158419,0.0,0,10.5948,0.0,0.0014371941,7.2374468,10.596522,360.03595,-9.2895365
165.3329,0.56663269,0.015743066,0.0,0,10.575864,0.0,0.0010214103,7.3323903,10.599212,360.04141,-9.2883854
165.3371,0.56798083,0.019643711,0.0,0,10.512864,0.0,0.001193154,7.2638345,10.593398,360.07959,-9.287632
165.3413,0.56606269,0.01700913,0.0,0,10.449863,0.0,0.0013456809,7.2147288,10.585698,360.1178,-9.2889719
165.3455,0.55944067,0.019916665,0.0,0,10.386864,0.0,0.001259831,7.2181349,10.539865,360.15598,-9.2882719
165.3497,0.56969017,0.022034282,0.0,0,10.323863,0.0,0.00129043,7.2719097,10.444773,360.19415,-9.2886734
165.3539,0.56896824,0.019018244,0.0,0,10.260864,0.0,0.0014769908,7.3412013,10.352722,360.2178,-9.2892561
165.3581,0.58631438,0.016776256,0.0,0,10.197864,0.0,0.0011468783,7.4041839,10.27576,360.2178,-9.2882481
165.3623,0.59735322,0.020458996,0.0,0,10.134863,0.0,0.0012543106,7.5980768,10.219691,360.2178,-9.2881126
165.3665,0.59903544,0.018087005,0.0,0,10.071864,0.0,0.0014089639,7.5904436,10.167351,360.17963,-9.2884722
165.3707,0.60214549,0.021069556,0.0,0,10.008863,0.0,0.0013255456,7.7152791,10.109729,360.14145,-9.2872086
165.3749,0.60527819,0.025232278,0.0,0,9.9458637,0.0,0.0014495924,7.6216674,10.04288,360.15054,-9.2884846
165.3791,0.59146339,0.018190453,0.0,0,9.882863,0.0,0.0014556263,7.5383964,9.9794426,360.18872,-9.2888241
165.3833,0.63997656,0.01977798,0.0,0,9.8198633,0.0,0.0013057133,8.0385046,9.9060297,360.21478,-9.2873526
165.3875,1.8854923,0.041162558,0.0,0,9.7568636,0.0,0.0026803431,23.803268,9.849185,360.20206,-9.2884083
165.3917,2.8359523,0.04983725,0.0,0,9.6938639,0.0,0.0034994369,35.746937,9.7954092,360.18933,-9.2874832
165.3959,3.9881997,0.10566543,0.0,0,9.6308632,0.0,0.0069844378,50.36623,9.7272558,360.49298,-9.2864132
165.4001,4.3535552,0.17856652,0.0,0,9.5678635,0.0,0.011662495,54.854275,9.6588516,360.8494,-9.2854872
165.4043,3.3849125,0.25438309,0.0,0,9.5048637,0.0,0.017301036,42.720478,9.5774221,361.327,-9.2860737
165.4085,3.4767997,0.3177568,0.0,0,9.4428434,0.0,0.021350296,43.343494,9.5145283,361.93796,-9.2852869
165.4127,4.3171988,0.36330345,0.0,0,9.3813896,0.0,0.024426067,53.514492,9.4625168,362.53436,-9.2856636
165.4169,4.1433697,0.42382994,0.0,0,9.3199348,0.0,0.028792793,51.327248,9.4059229,362.99258,-9.2871857
165.4211,3.3543298,0.49845266,0.0,0,9.258481,0.0,0.033737548,41.165398,9.331624,363.45081,-9.286582
165.4253,4.362165,0.55241317,0.0,0,9.1970263,0.0,0.037272621,53.379753,9.2772188,364.29034,-9.2869406
165.4295,4.8805161,0.60556114,0.0,0,9.1355715,0.0,0.041364167,59.668278,9.2113876,365.28241,-9.2845688
165.4337,5.1327744,0.66709423,0.0,0,9.0741167,0.0,0.045471605,62.449718,9.1483326,366.40125,-9.2865067
165.4379,5.3325415,0.73165762,0.0,0,9.0126629,0.0,0.049819805,64.557465,9.0825615,367.77359,-9.2854185
165.4421,5.5013666,0.7928071,0.0,0,8.9512091,0.0,0.054435171,66.332726,9.0206089,369.14597,-9.2854662
165.4463,5.6263151,0.85532457,0.0,0,8.8897533,0.0,0.058630381,67.438499,8.955822,370.66241,-9.2858887
165.4505,5.7567034,0.91838717,0.0,0,8.8282995,0.0,0.062849931,68.762001,8.8966455,372.1861,-9.287241
165.4547,5.862999,0.97336018,0.0,0,8.7668447,0.0,0.067333721,69.728111,8.8328934,373.57919,-9.2852097
165.4589,5.9137826,1.0343974,0.0,0,8.7075834,0.0,0.071391635,70.208542,8.7723608,374.87433,-9.2853022
165.4631,5.9891934,1.0976857,0.0,0,8.6491356,0.0,0.075834647,70.774109,8.7081213,376.05823,-9.28512
165.4673,6.0408459,1.1533341,0.0,0,8.5906887,0.0,0.080158494,71.003906,8.6491032,376.76929,-9.2866812
165.4715,6.0522947,1.2119224,0.0,0,8.5322428,0.0,0.084182732,70.870544,8.5919628,377.48035,-9.2846937
165.4757,6.145813,1.2734411,0.0,0,8.4737949,0.0,0.088371165,71.592796,8.5357428,377.92413,-9.2855291
165.4799,6.2321324,1.3270279,0.0,0,8.4153471,0.0,0.092849925,72.282677,8.4789391,378.30505,-9.2862558
165.4841,6.3034267,1.3889378,0.0,0,8.3568993,0.0,0.097090058,72.829979,8.4105883,378.60977,-9.2856951
165.4883,6.3457355,1.4510844,0.0,0,8.2984524,0.0,0.1015093,73.02549,8.3508711,378.81293,-9.2850313
165.4925,6.3734632,1.5078729,0.0,0,8.2400064,0.0,0.10606703,73.014191,8.2925425,379.0173,-9.2864952
165.4967,6.410058,1.5649322,0.0,0,8.1815586,0.0,0.11018398,73.073723,8.2316265,379.24585,-9.2872009
165.5009,6.4411335,1.6294173,0.0,0,8.1231117,0.0,0.11467928,73.078987,8.1718721,379.47443,-9.2861223
165.5051,6.4908371,1.6799581,0.0,0,8.0646648,0.0,0.11900193,73.389938,8.1197948,379.66064,-9.2866058
165.5093,6.5529151,1.7347193,0.0,0,8.0085573,0.0,0.12288056,73.773712,8.0561991,379.82571,-9.2850094
165.5135,6.6065578,1.7919722,0.0,0,7.95295,0.0,0.12700616,74.02774,8.0063696,379.96173,-9.2864704
165.5177,6.6765375,1.8462096,0.0,0,7.8973413,0.0,0.13152225,74.474159,7.9426222,380.02524,-9.2856932
165.5219,6.7140841,1.9056755,0.0,0,7.8417335,0.0,0.13588913,74.641701,7.8858066,380.08875,-9.2854481
165.5261,6.7363548,1.9670002,0.0,0,7.7861252,0.0,0.14016418,74.620117,7.830215,380.19818,-9.2859373
165.5303,6.7728658,2.018187,0.0,0,7.7305174,0.0,0.1447286,74.620605,7.7736845,380.31247,-9.2849998
165.5345,6.8038373,2.0687377,0.0,0,7.6749096,0.0,0.14844008,74.67292,7.7193813,380.42673,-9.2865114
165.5387,6.8532729,2.1256175,0.0,0,7.6193013,0.0,0.15256509,74.841408,7.664331,380.54102,-9.2866831
165.5429,6.9140711,2.1754527,0.0,0,7.5636935,0.0,0.156854,75.240005,7.6093979,380.62082,-9.2847319
165.5471,6.9870152,2.2324421,0.0,0,7.5080853,0.0,0.16111384,75.71212,7.55688,380.49384,-9.2854233
165.5513,7.0613909,2.294152,0.0,0,7.452477,0.0,0.16559438,76.236,7.4992452,380.36685,-9.2867794
165.5555,7.0954003,2.3476925,0.0,0,7.3968692,0.0,0.17037788,76.084351,7.4358354,380.1528,-9.2856836
165.5597,7.1047091,2.400553,0.0,0,7.3437643,0.0,0.17445871,75.961166,7.3869867,379.91156,-9.2837458
165.5639,7.1505156,2.4581518,0.0,0,7.2908783,0.0,0.17873998,76.045845,7.3287034,379.38492,-9.2853107
165.5681,7.1679277,2.5113907,0.0,0,7.2379913,0.0,0.18338639,75.96431,7.2750559,378.39453,-9.2863016
165.5723,7.2280941,2.558867,0.0,0,7.1851048,0.0,0.18707357,76.276321,7.2213182,377.40414,-9.2871103
165.5765,7.2893777,2.6186459,0.0,0,7.1322188,0.0,0.19145043,76.615738,7.1697145,375.67731,-9.2841558
165.5807,7.3254762,2.6661103,0.0,0,7.0793324,0.0,0.19595222,76.706451,7.1140804,373.95044,-9.2857361
165.5849,7.3660531,2.7163167,0.0,0,7.0264459,0.0,0.19977124,76.813522,7.0636215,372.85242,-9.2864418
165.5891,7.4211636,2.7710452,0.0,0,6.9735599,0.0,0.20404054,77.05928,7.0112863,372.14139,-9.2864199
165.5933,7.4445181,2.8238974,0.0,0,6.9206729,0.0,0.20868513,76.984001,6.9593744,371.65707,-9.2850428
165.5975,7.4995236,2.8759375,0.0,0,6.8677864,0.0,0.21294293,77.233551,6.9010634,371.89832,-9.2857628
165.6017,7.5760341,2.9367557,0.0,0,6.8148999,0.0,0.21748249,77.528687,6.8437443,372.13959,-9.2853794
165.6059,7.6217575,2.9838316,0.0,0,6.762064,0.0,0.22204868,77.714012,6.7955923,372.34818,-9.2858486
165.6101,7.6730781,3.0349433,0.0,0,6.7117357,0.0,0.22611506,77.948067,6.7394481,372.55133,-9.2849941
165.6143,7.7099004,3.0869765,0.0,0,6.6614199,0.0,0.23017018,78.001442,6.6904473,372.64566,-9.2861233
165.6185,7.7276587,3.1357472,0.0,0,6.611104,0.0,0.23471755,77.782028,6.6389403,372.62027,-9.2863045
165.6227,7.7757492,3.1847453,0.0,0,6.5607882,0.0,0.23866194,77.983894,6.5888681,372.58035,-9.28543
165.6269,7.8037672,3.2414646,0.0,0,6.5104718,0.0,0.24302389,77.92141,6.5364032,372.40259,-9.2867908
165.6311,7.8653402,3.2877243,0.0,0,6.460156,0.0,0.24760307,78.160965,6.4880977,372.22479,-9.2863283
165.6353,7.937633,3.3326252,0.0,0,6.4098401,0.0,0.25127915,78.568779,6.4406137,372.12866,-9.285181
165.6395,7.9989042,3.387183,0.0,0,6.3595238,0.0,0.25558531,78.829079,6.3891187,372.06522,-9.2860394
165.6437,8.0695953,3.4374712,0.0,0,6.3092084,0.0,0.26043361,79.174751,6.3336205,372.03983,-9.285243
165.6479,8.0995588,3.4860454,0.0,0,6.2588925,0.0,0.26462176,79.176743,6.2828479,372.09061,-9.2863989
165.6521,8.1181641,3.5443406,0.0,0,6.2085767,0.0,0.26908559,78.943886,6.2357931,372.14139,-9.2858171
165.6563,8.1610107,3.589046,0.0,0,6.1585317,0.0,0.27367836,79.08197,6.1847501,371.9866,-9.2850609
165.6605,8.225172,3.6366315,0.0,0,6.1106763,0.0,0.27771887,79.28318,6.1335874,371.82153,-9.2866001
165.6647,8.2774181,3.6880021,0.0,0,6.0628219,0.0,0.28179541,79.489616,6.0826874,371.59116,-9.2857084
165.6689,8.3414583,3.7349067,0.0,0,6.014967,0.0,0.28646737,79.692871,6.0354414,371.31183,-9.2845802
165.6731,8.3791428,3.7809381,0.0,0,5.9671125,0.0,0.29052621,79.850861,5.98563,371.07602,-9.2860279
165.6773,8.4359722,3.8346076,0.0,0,5.9192576,0.0,0.29471976,80.009224,5.9405956,371.02521,-9.2841806
165.6815,8.4797602,3.8816772,0.0,0,5.8714027,0.0,0.29965383,80.01432,5.8866367,370.97443,-9.2862854
165.6857,8.4929142,3.9241884,0.0,0,5.8235478,0.0,0.30342978,79.884293,5.843574,370.75919,-9.2851496
165.6899,8.5096769,3.9718003,0.0,0,5.7756925,0.0,0.30730546,79.64695,5.7930832,370.50522,-9.2855396
165.6941,8.5997505,4.0128384,0.0,0,5.7278385,0.0,0.31147915,80.135078,5.7510948,370.24039,-9.2864447
165.6983,8.7200813,4.0633864,0.0,0,5.6799831,0.0,0.3160769,80.92807,5.7020802,369.96106,-9.2870951
165.7025,8.792429,4.1213484,0.0,0,5.6321287,0.0,0.32072911,81.227455,5.6511989,369.69077,-9.2848606
165.7067,8.8294697,4.1685395,0.0,0,5.5847516,0.0,0.32581127,81.191917,5.603385,369.6019,-9.2858267
165.7109,8.8434715,4.2125983,0.0,0,5.5392232,0.0,0.3297835,80.998482,5.5548162,369.51303,-9.2849131
165.7151,8.8543959,4.2591438,0.0,0,5.4936957,0.0,0.33367038,80.720375,5.5086579,368.33051,-9.2859879
165.7193,8.8942289,4.3015718,0.0,0,5.4481678,0.0,0.33807257,80.765137,5.4647026,366.6012,-9.2863989
165.7235,8.9521532,4.3436837,0.0,0,5.4026399,0.0,0.34210134,80.945778,5.4185171,364.82092,-9.2846909
165.7277,9.008029,4.3958135,0.0,0,5.3571115,0.0,0.34621164,81.142883,5.3770318,362.91327,-9.2862015
165.7319,9.1222429,4.4384489,0.0,0,5.311584,0.0,0.35101482,81.729027,5.3334899,361.00558,-9.2834778
165.7361,9.1999264,4.4828563,0.0,0,5.2660561,0.0,0.35514113,82.142311,5.280457,360.75482,-9.2844563
165.7403,9.2348328,4.5360222,0.0,0,5.2205281,0.0,0.35974714,82.036133,5.2336378,360.67847,-9.2856941
165.7445,9.2556372,4.5789909,0.0,0,5.1749997,0.0,0.36434072,81.861145,5.1852832,360.65543,-9.2856083
165.7487,9.2899485,4.6210742,0.0,0,5.1294718,0.0,0.36849171,81.809685,5.1402154,360.68088,-9.2848101
165.7529,9.3471098,4.6721778,0.0,0,5.0839438,0.0,0.37260649,81.939041,5.0969443,360.67361,-9.2863207
165.7571,9.4395847,4.7167177,0.0,0,5.0390849,0.0,0.37774247,82.39418,5.0514936,360.46994,-9.2848282
165.7613,9.5081949,4.7571554,0.0,0,4.9957829,0.0,0.38167167,82.617439,5.005074,360.2663,-9.2848959
165.7655,9.5751715,4.8087125,0.0,0,4.9524813,0.0,0.38608727,82.869987,4.9609203,359.97537,-9.2846222
165.7697,9.6043844,4.8506269,0.0,0,4.9091787,0.0,0.39078736,82.761978,4.9137211,359.65717,-9.2841482
165.7739,9.5941458,4.8900599,0.0,0,4.8658767,0.0,0.39470884,82.302864,4.8745623,359.43594,-9.2848825
165.7781,9.645915,4.9376216,0.0,0,4.8225751,0.0,0.39860052,82.432037,4.8319073,359.37228,-9.2850904
165.7823,9.7245512,4.9789877,0.0,0,4.7792726,0.0,0.40356681,82.768555,4.7923307,359.30865,-9.2846222
165.7865,9.8186255,5.0184956,0.0,0,4.735971,0.0,0.40755516,83.092613,4.7446766,357.41162,-9.2854185
165.7907,9.894536,5.0667605,0.0,0,4.6926689,0.0,0.41178793,83.425171,4.6987562,355.51459,-9.2835875
165.7949,9.9630556,5.1100483,0.0,0,4.6493669,0.0,0.41664723,83.633453,4.6573896,353.68878,-9.2854176
165.7991,9.9778557,5.1493635,0.0,0,4.6060648,0.0,0.42077756,83.407349,4.6111679,351.90683,-9.2861919
165.8033,10.015299,5.2003746,0.0,0,4.5627627,0.0,0.42512158,83.358398,4.5720687,350.79169,-9.2836704
165.8075,10.091476,5.2381821,0.0,0,4.5202951,0.0,0.42978105,83.584312,4.5298734,351.81049,-9.2848358
165.8117,10.152899,5.2763567,0.0,0,4.4791017,0.0,0.43387735,83.811234,4.4882746,352.82925,-9.2858343
165.8159,10.193687,5.3210263,0.0,0,4.4379077,0.0,0.43770057,83.812401,4.442637,353.17117,-9.2841244
165.8201,10.256759,5.36098,0.0,0,4.3967142,0.0,0.44240993,83.911758,4.4052501,353.4003,-9.285058
165.8243,10.337512,5.4031768,0.0,0,4.3555207,0.0,0.44688728,84.222588,4.3600039,353.24149,-9.2841606
165.8285,10.41081,5.4509692,0.0,0,4.3143268,0.0,0.45099765,84.421265,4.3206348,352.65598,-9.2844057
165.8327,10.463714,5.4922819,0.0,0,4.2731338,0.0,0.45612463,84.48101,4.2762542,352.12015,-9.2842226
165.8369,10.488981,5.528121,0.0,0,4.2319398,0.0,0.46001807,84.375435,4.2362838,352.05652,-9.2846222
165.8411,10.55378,5.5724487,0.0,0,4.1907463,0.0,0.463945,84.489624,4.1982679,351.99289,-9.2843609
165.8453,10.61798,5.6152782,0.0,0,4.1495528,0.0,0.46907955,84.583954,4.1534724,352.4111,-9.2849722
165.8495,10.676516,5.6520476,0.0,0,4.1083593,0.0,0.47321874,84.706306,4.1111102,353.02206,-9.2846851
165.8537,10.772354,5.6989212,0.0,0,4.0671659,0.0,0.47731629,85.025223,4.0729656,353.67123,-9.2843227
165.8579,10.844989,5.7413502,0.0,0,4.0269618,0.0,0.48257226,85.298172,4.0303125,354.39673,-9.2841225
165.8621,10.91322,5.7744794,0.0,0,3.9877841,0.0,0.48644295,85.396439,3.9879243,355.12225,-9.2851343
165.8663,10.970883,5.8224492,0.0,0,3.9486067,0.0,0.49078339,85.530731,3.9498813,355.69019,-9.2864246
165.8705,11.000152,5.8631525,0.0,0,3.9094288,0.0,0.49583569,85.338379,3.905642,356.25021,-9.285738
165.8747,11.023512,5.8977346,0.0,0,3.8702514,0.0,0.49977136,85.096306,3.870146,356.90482,-9.2851677
165.8789,11.075779,5.9417753,0.0,0,3.831074,0.0,0.50370097,85.17791,3.8312366,357.63034,-9.2842522
165.8831,11.152196,5.9777398,0.0,0,3.7918961,0.0,0.50855666,85.417877,3.7937984,358.29037,-9.2848797
165.8873,11.239463,6.0094929,0.0,0,3.7527184,0.0,0.51233774,85.705681,3.7550914,358.67224,-9.2850037
165.8915,11.325655,6.0515852,0.0,0,3.713541,0.0,0.51605505,86.024689,3.7209036,359.05408,-9.2839336
165.8957,11.408327,6.0927553,0.0,0,3.6743636,0.0,0.52122313,86.228065,3.6771045,359.1474,-9.283989
165.8999,11.444686,6.1317034,0.0,0,3.635186,0.0,0.52587092,86.15564,3.6401293,359.17285,-9.2849321
165.9041,11.499174,6.1764612,0.0,0,3.5960083,0.0,0.5300265,86.191605,3.5967875,358.78375,-9.2839413
165.9083,11.574924,6.2177048,0.0,0,3.5579486,0.0,0.53523064,86.290314,3.5604508,357.84186,-9.2846909
165.9125,11.641294,6.248251,0.0,0,3.5206778,0.0,0.53932786,86.309601,3.5182936,356.88422,-9.2836485
165.9167,11.732814,6.2908082,0.0,0,3.483407,0.0,0.5430541,86.811783,3.4798045,355.61136,-9.2846727
165.9209,11.745233,6.3283315,0.0,0,3.4461365,0.0,0.54799694,86.458885,3.4431672,354.33853,-9.2838125
165.9251,11.781646,6.3602991,0.0,0,3.4088655,0.0,0.55218303,86.34848,3.4091985,353.57483,-9.2831459
165.9293,11.82783,6.3993917,0.0,0,3.3715944,0.0,0.55570519,86.427887,3.3709717,353.0657,-9.2837677
165.9335,11.892137,6.4395814,0.0,0,3.3343236,0.0,0.5609172,86.361267,3.3372753,352.51642,-9.284915
165.9377,11.996969,6.4668202,0.0,0,3.2970531,0.0,0.56457663,86.817314,3.2997639,351.86685,-9.2854671
165.9419,12.130627,6.5106897,0.0,0,3.2597823,0.0,0.56866872,87.40274,3.2571106,351.21725,-9.2844906
165.9461,12.238965,6.5507536,0.0,0,3.2225113,0.0,0.57400572,87.791603,3.220897,349.8399,-9.2833729
165.9503,12.307609,6.5888653,0.0,0,3.1852405,0.0,0.57892072,87.810661,3.1797731,348.38593,-9.2840338
165.9545,12.334009,6.6327353,0.0,0,3.1479697,0.0,0.58316123,87.687111,3.146548,347.2323,-9.2843857
165.9587,12.358311,6.6686716,0.0,0,3.1119354,0.0,0.58791453,87.443855,3.1088834,346.35172,-9.2853937
165.9629,12.404607,6.6975112,0.0,0,3.0764792,0.0,0.59206712,87.356911,3.0746126,345.59329,-9.2848883
165.9671,12.484447,6.7349844,0.0,0,3.0410228,0.0,0.59545952,87.629005,3.0381432,345.56778,-9.2849436
165.9713,12.597953,6.7763696,0.0,0,3.0055661,0.0,0.60100496,87.914139,3.0010455,345.54227,-9.2842169
165.9755,12.653005,6.807744,0.0,0,2.9701097,0.0,0.6052978,87.926201,2.9647679,344.90417,-9.28514
165.9797,12.685616,6.8468156,0.0,0,2.9346535,0.0,0.60899961,87.845047,2.9339263,344.07462,-9.2838736
165.9839,12.76902,6.885746,0.0,0,2.8991969,0.0,0.61432427,87.948265,2.901087,342.90961,-9.2833242
165.9881,12.872752,6.9099016,0.0,0,2.8637407,0.0,0.61794323,88.406807,2.8657019,341.19949,-9.2851372
165.9923,12.929353,6.9514427,0.0,0,2.8282843,0.0,0.62199903,88.368958,2.8265307,339.48938,-9.2849102
165.9965,12.97207,6.9887285,0.0,0,2.7928278,0.0,0.62716556,88.261169,2.7899356,338.18765,-9.2838049
166.0007,13.064069,7.018188,0.0,0,2.7573714,0.0,0.6314618,88.442734,2.7571423,336.88593,-9.2855988
166.0049,13.181238,7.0599589,0.0,0,2.721915,0.0,0.63550478,88.856201,2.7195663,335.83612,-9.2848959
166.0091,13.32069,7.1011047,0.0,0,2.6878028,0.0,0.64108604,89.309135,2.6849756,334.94138,-9.2850256
166.0133,13.38404,7.1299038,0.0,0,2.6540768,0.0,0.64560294,89.348213,2.6461391,334.19266,-9.2834072
166.0175,13.397103,7.170619,0.0,0,2.6203508,0.0,0.64957321,89.105797,2.6107111,333.91135,-9.2833929
166.0217,13.421556,7.2040739,0.0,0,2.5866249,0.0,0.65436929,88.805298,2.5754533,333.63,-9.2841721
166.0259,13.454184,7.230577,0.0,0,2.5528989,0.0,0.65851665,88.683182,2.5477684,332.78891,-9.2849226
166.0301,13.533842,7.2695785,0.0,0,2.5191729,0.0,0.66240501,88.789124,2.5134428,331.85449,-9.283967
166.0343,13.633087,7.3032641,0.0,0,2.4854469,0.0,0.66703445,89.092949,2.4840574,330.79819,-9.2863503
166.0385,13.744277,7.326663,0.0,0,2.451721,0.0,0.67103821,89.45752,2.4479198,329.60779,-9.2851419
166.0427,13.852801,7.3646512,0.0,0,2.4179947,0.0,0.67478245,89.82093,2.4173675,328.49905,-9.2844219
166.0469,13.967891,7.4021606,0.0,0,2.3842688,0.0,0.680076,90.051147,2.3824189,328.16629,-9.2857313
166.0511,14.021248,7.4345384,0.0,0,2.3505428,0.0,0.68509448,90.013641,2.3463416,327.8335,-9.2842455
166.0553,14.051242,7.4717441,0.0,0,2.3168168,0.0,0.68883532,89.839745,2.3133593,327.16241,-9.2856503
166.0595,14.107355,7.5076513,0.0,0,2.2845263,0.0,0.69387156,89.762756,2.2803662,326.35602,-9.2842216
166.0637,14.207652,7.5319366,0.0,0,2.2524469,0.0,0.69819427,89.986076,2.2448232,325.716,-9.2845802
166.0679,14.319311,7.5665374,0.0,0,2.2203674,0.0,0.70157611,90.355225,2.216445,325.40881,-9.2848225
166.0721,14.411657,7.6026831,0.0,0,2.1882877,0.0,0.70675159,90.503593,2.18381,325.10159,-9.2835274
166.0763,14.49699,7.631465,0.0,0,2.156208,0.0,0.71152318,90.559753,2.1468911,325.03821,-9.2834425
166.0805,14.560745,7.6689372,0.0,0,2.1241283,0.0,0.71538085,90.643051,2.1186407,324.98703,-9.2846022
166.0847,14.59578,7.7036376,0.0,0,2.0920489,0.0,0.72023237,90.489594,2.0869932,325.14063,-9.2848253
166.0889,14.633677,7.7241702,0.0,0,2.0599694,0.0,0.72438836,90.325928,2.0535474,325.44781,-9.283555
166.0931,14.73483,7.7591286,0.0,0,2.0278897,0.0,0.72798777,90.579231,2.0287457,325.68918,-9.2850246
166.0973,14.937573,7.7936182,0.0,0,1.9958102,0.0,0.73294538,91.35527,1.9943212,325.65079,-9.2837143
166.1015,15.063734,7.827301,0.0,0,1.9637306,0.0,0.73842394,91.625107,1.9594681,325.6124,-9.2858095
166.1057,15.157614,7.863862,0.0,0,1.9316509,0.0,0.74232787,91.844772,1.9259045,324.92117,-9.2849245
166.1099,15.209799,7.9033642,0.0,0,1.9010825,0.0,0.74803954,91.641594,1.8896891,324.07639,-9.2835007
166.1141,15.219486,7.92521,0.0,0,1.8705654,0.0,0.75236803,91.340424,1.8636378,323.21512,-9.2846212
166.1183,15.235091,7.9560394,0.0,0,1.8400483,0.0,0.75530034,91.151001,1.8327899,322.33191,-9.2845078
166.1225,15.343342,7.9876475,0.0,0,1.8095311,0.0,0.76008767,91.362709,1.798506,321.46762,-9.2856979
166.1267,15.445403,8.0143442,0.0,0,1.7790139,0.0,0.76503772,91.439743,1.7722774,320.98123,-9.2856321
166.1309,15.597083,8.0513287,0.0,0,1.7484967,0.0,0.768902,92.015923,1.7410901,320.49484,-9.2839842
166.1351,15.725595,8.0874004,0.0,0,1.7179794,0.0,0.7743091,92.301414,1.7065259,320.42657,-9.2842331
166.1393,15.79248,8.1080341,0.0,0,1.6874622,0.0,0.77857512,92.289955,1.6795787,320.56738,-9.2833405
166.1435,15.86425,8.141428,0.0,0,1.656945,0.0,0.78197217,92.396744,1.646778,320.66428,-9.2843027
166.1477,15.900536,8.1758528,0.0,0,1.6264278,0.0,0.78729397,92.16526,1.6194117,320.65149,-9.2841616
166.1519,15.956009,8.1966734,0.0,0,1.5959105,0.0,0.79134446,92.065857,1.5906537,320.63867,-9.284626
166.1561,16.044537,8.2314148,0.0,0,1.5654866,0.0,0.7952199,92.22052,1.559909,320.61429,-9.2844248
166.1603,16.156267,8.2622929,0.0,0,1.5364559,0.0,0.7998572,92.408226,1.533177,320.58868,-9.2849169
166.1645,16.331785,8.2865334,0.0,0,1.5074254,0.0,0.80477011,92.987503,1.5021868,320.52957,-9.2841864
166.1687,16.443258,8.3186016,0.0,0,1.478395,0.0,0.8082276,93.297859,1.4724615,320.43997,-9.2836437
166.1729,16.535448,8.3524246,0.0,0,1.4493648,0.0,0.81336612,93.35907,1.4426271,320.3284,-9.2846537
166.1771,16.575562,8.3765106,0.0,0,1.4203343,0.0,0.81836879,93.145172,1.4131666,320.08517,-9.2834082
166.1813,16.652748,8.4142179,0.0,0,1.3913039,0.0,0.82257968,93.162437,1.3849285,319.84195,-9.2836571
166.1855,16.764385,8.4447737,0.0,0,1.3622735,0.0,0.82712215,93.321266,1.3513514,319.86203,-9.283433
166.1897,16.89028,8.4682159,0.0,0,1.333243,0.0,0.8322404,93.533875,1.3233608,319.96445,-9.2846241
166.1939,16.994307,8.4949903,0.0,0,1.3042127,0.0,0.83507258,93.84256,1.2941936,320.02783,-9.2827578
166.1981,17.080534,8.5309153,0.0,0,1.2751824,0.0,0.84062332,93.801682,1.2645366,320.02783,-9.2828588
166.2023,17.155476,8.5528116,0.0,0,1.2461519,0.0,0.84525895,93.803139,1.2361209,320.02783,-9.2843618
166.2065,17.246897,8.5847778,0.0,0,1.2173454,0.0,0.84882408,93.975929,1.2082192,319.74597,-9.2852554
166.2107,17.295374,8.61903,0.0,0,1.1897346,0.0,0.85399103,93.763504,1.17974,319.46411,-9.2830324
166.2149,17.338591,8.6376877,0.0,0,1.1621238,0.0,0.85855079,93.534439,1.1538686,319.30109,-9.2842693
166.2191,17.472717,8.663908,0.0,0,1.134513,0.0,0.86139363,93.978065,1.1243027,319.21118,-9.2841969
166.2233,17.598553,8.6962061,0.0,0,1.1069021,0.0,0.86641103,94.194115,1.0983609,319.05484,-9.2834015
166.2275,17.715036,8.7170467,0.0,0,1.0792915,0.0,0.87113941,94.359207,1.0733129,318.68591,-9.2840099
166.2317,17.784767,8.7464876,0.0,0,1.0516806,0.0,0.87447613,94.441795,1.0431813,318.31702,-9.2840843
166.2359,17.845036,8.7829266,0.0,0,1.0240698,0.0,0.87999374,94.25605,1.0169643,318.1629,-9.2833595
166.2401,17.924026,8.7986679,0.0,0,0.99645901,0.0,0.88422161,94.264336,0.99044925,318.00876,-9.2835951
166.2443,18.033409,8.8293676,0.0,0,0.96884811,0.0,0.88777238,94.500656,0.96556795,317.97391,-9.2822313
166.2485,18.162268,8.856041,0.0,0,0.94123733,0.0,0.89209098,94.751617,0.93359023,318.01242,-9.282939
166.2527,18.305731,8.8806429,0.0,0,0.91362649,0.0,0.89751732,94.964333,0.90857124,317.98062,-9.2836456
166.2569,18.412962,8.9117613,0.0,0,0.88635784,0.0,0.90129662,95.191551,0.88081348,317.72375,-9.2835569
166.2611,18.555702,8.9455891,0.0,0,0.86009943,0.0,0.90652621,95.430824,0.85486817,317.46686,-9.2846355
166.2653,18.63175,8.9675694,0.0,0,0.83384103,0.0,0.91192806,95.298988,0.8242169,317.18796,-9.2820463
166.2695,18.668238,8.9934835,0.0,0,0.80758262,0.0,0.91489738,95.226593,0.79789627,316.9054,-9.2843027
166.2737,18.730814,9.0240097,0.0,0,0.78132421,0.0,0.91974759,95.052109,0.77103055,316.51276,-9.284194
166.2779,18.828249,9.0468359,0.0,0,0.7550658,0.0,0.92507029,95.069328,0.74566334,315.99899,-9.2833509
166.2821,18.94795,9.0714188,0.0,0,0.72880745,0.0,0.92773092,95.400482,0.7211675,315.49994,-9.2820864
166.2863,19.058708,9.1076288,0.0,0,0.70254904,0.0,0.93349832,95.402557,0.69430929,315.14029,-9.2844229
166.2905,19.184444,9.1239958,0.0,0,0.67629069,0.0,0.9381513,95.552879,0.66721654,314.78067,-9.2833481
166.2947,19.31986,9.1483049,0.0,0,0.65003228,0.0,0.94103503,95.958397,0.64313328,314.64124,-9.2844191
166.2989,19.39782,9.1808748,0.0,0,0.62377387,0.0,0.94629943,95.883438,0.61761332,314.58984,-9.2828655
166.3031,19.527748,9.2007713,0.0,0,0.59751546,0.0,0.95130372,96.024582,0.58696252,314.56845,-9.2828236
166.3073,19.581758,9.231822,0.0,0,0.57169873,0.0,0.9552964,95.93457,0.56255054,314.60696,-9.2845268
166.3115,19.656143,9.2608461,0.0,0,0.5467087,0.0,0.95983297,95.833191,0.53733891,314.64551,-9.2825422
166.3157,19.618814,9.2760448,0.0,0,0.52171868,0.0,0.96441472,95.28685,0.51434743,314.98984,-9.2825766
166.3199,18.999199,9.2791653,0.0,0,0.49672872,0.0,0.96379763,92.307327,0.49898085,315.34949,-9.2840023
166.3241,18.525732,9.2860556,0.0,0,0.4717387,0.0,0.96449959,89.920662,0.48236233,315.81186,-9.2834053
166.3283,18.23489,9.2879648,0.0,0,0.44674867,0.0,0.96641582,88.313843,0.46978167,316.35129,-9.2858057
166.3325,17.988768,9.293128,0.0,0,0.42175868,0.0,0.96624589,87.198357,0.45436627,316.82468,-9.2847281
166.3367,17.620275,9.3035164,0.0,0,0.39676869,0.0,0.96723288,85.31237,0.44175622,317.01733,-9.2856407
166.3409,17.175402,9.2966099,0.0,0,0.3717787,0.0,0.96811503,83.077255,0.43716189,317.20999,-9.2857513
166.3451,16.860678,9.2968922,0.0,0,0.3467887,0.0,0.96678823,81.657555,0.43030813,317.18433,-9.2867546
166.3493,16.69306,9.3018284,0.0,0,0.32179868,0.0,0.96735108,80.78331,0.42168343,317.10724,-9.2859173
166.3535,16.665174,9.2991018,0.0,0,0.29680869,0.0,0.96844125,80.547585,0.40500379,317.09073,-9.2866545
166.3577,16.789919,9.3036394,0.0,0,0.27236253,0.0,0.96807986,81.182365,0.37857577,317.15497,-9.285758
166.3619,17.025595,9.3150501,0.0,0,0.24859893,0.0,0.96917671,82.222824,0.34769154,317.21918,-9.2854595
166.3661,17.163126,9.3084135,0.0,0,0.22483534,0.0,0.97002798,82.841789,0.31401822,317.28339,-9.2848806
166.3703,17.228479,9.3142433,0.0,0,0.20107177,0.0,0.96991479,83.157249,0.28043827,317.34763,-9.2849874
166.3745,17.221411,9.3165464,0.0,0,0.17730817,0.0,0.96978354,83.142738,0.25182194,317.36902,-9.2858629
166.3787,17.194326,9.3159952,0.0,0,0.15354457,0.0,0.97153908,82.861794,0.22428541,317.36902,-9.284029
166.3829,17.162844,9.32197,0.0,0,0.12978098,0.0,0.97116327,82.731079,0.20153609,317.33231,-9.2858028
166.3871,17.134075,9.3302317,0.0,0,0.10601737,0.0,0.9718008,82.487366,0.17746928,317.20389,-9.2841864
166.3913,17.06377,9.3266087,0.0,0,0.082253762,0.0,0.97325093,82.113876,0.15551893,317.07544,-9.2843466
166.3955,17.003647,9.3258162,0.0,0,0.058490161,0.0,0.97186756,81.915421,0.13461839,316.97025,-9.2857199
166.3997,16.929502,9.334054,0.0,0,0.03472656,0.0,0.97277975,81.516472,0.11710309,316.86746,-9.2835407
166.4039,16.848717,9.3320589,0.0,0,0.01096296,0.0,0.97418326,80.967026,0.093243808,316.80508,-9.2850523
166.4081,16.775503,9.3316326,0.0,0,-0.012488429,0.0,0.9732182,80.722969,0.077164695,316.77939,-9.284215
166.4123,16.708117,9.3430338,0.0,0,-0.03567243,0.0,0.9740929,80.272575,0.065622307,316.75006,-9.2844143
166.4165,16.621998,9.3365726,0.0,0,-0.058856431,0.0,0.97510654,79.797394,0.048887372,316.69867,-9.2843342
166.4207,16.53277,9.3341742,0.0,0,-0.082040429,0.0,0.97349495,79.586586,0.03473356,316.64731,-9.2857189
166.4249,16.433681,9.3420525,19.740112,0,-0.10522442,0.0,0.97425216,78.982292,0.026892953,316.59592,-9.285058
166.4291,16.311863,9.3370981,45.64917,0,0.46232122,359.99997,0.97509485,78.331154,0.01810321,316.54456,-9.285656
166.4333,15.61897,9.337409,61.688232,0,1.2229583,359.99997,0.97436696,75.145844,0.03359868,316.60571,-9.2845173
166.4375,12.193658,9.3075733,61.688232,0,1.9835956,359.99997,0.9678604,59.151615,0.20965585,316.84976,-9.287446
166.4417,3.8353226,9.2877846,61.688232,0,2.7442317,359.99997,0.96656293,19.886002,0.51793128,317.09378,-9.2927246
166.4459,2.9851041,9.2891827,61.780518,0,3.504869,359.99997,0.96562868,14.263714,1.5600584,316.75986,-9.295929
166.4501,0.86939186,9.2846327,61.872807,0,4.2655053,359.99997,0.96408659,4.3176341,2.7881079,316.42593,-9.2953548
166.4543,0.95047474,9.2909555,61.907963,0,5.0261421,359.99997,0.96684557,4.5510192,3.6208482,317.13147,-9.2946043
166.4585,1.1391155,9.2998695,61.907963,0,5.7867794,359.99997,0.96755844,5.5461717,4.3384204,318.47675,-9.2929506
166.4627,1.0218366,9.2988768,61.907963,0,6.5474162,359.99997,0.96629167,4.9202518,5.0553565,319.2265,-9.2918625
166.4669,1.0962025,9.2797623,61.907963,0,7.308053,359.99997,0.96490097,5.2976503,5.7928753,318.07053,-9.2927523
166.4711,1.0169644,9.2828856,61.907963,0,8.0686913,359.99997,0.96471471,4.8847995,6.5703707,316.91458,-9.2909336
166.4753,0.9398706,9.2905483,61.907963,0,8.8293266,359.99997,0.96526682,4.6897297,7.3576298,317.93436,-9.2896852
166.4795,1.0608634,9.289979,61.907963,0,9.5899639,359.99997,0.96663958,5.1620731,8.1533966,319.31677,-9.2903891
166.4837,1.042101,9.2862978,61.637699,0,10.350601,359.99997,0.96531153,5.025456,8.938118,320.00421,-9.2893505
166.4879,0.9402228,9.2918587,61.070145,0,11.111238,359.99997,0.96487314,4.6462927,9.7157536,319.92715,-9.2894745
166.4921,1.0203264,9.2881889,60.556641,0,11.871875,359.99997,0.96625948,4.933969,10.481913,319.84525,-9.288413
166.4963,0.88842899,9.2751846,60.556641,0,12.632511,359.99997,0.96343553,4.2997675,11.254842,319.71722,-9.2893467
166.5005,1.0178164,9.2908278,60.556641,0,13.393147,359.99997,0.96537632,4.9332876,11.997295,319.5892,-9.2892122
166.5047,0.98793077,9.2844114,60.695068,0,14.153786,359.99997,0.96564746,4.769834,12.735922,319.48843,-9.2887278
166.5089,0.98053074,9.293047,60.88887,0,14.914423,359.99997,0.96662265,4.7438478,13.486078,319.3985,-9.2882404
166.5131,1.0086572,9.2926559,61.01807,0,15.67506,359.99997,0.96514511,4.8787909,14.252848,319.39404,-9.2887554
166.5173,0.97063094,9.2729292,61.01807,0,16.435696,359.99997,0.96370602,4.7299285,15.029636,319.56042,-9.2890768
166.5215,1.0757362,9.2845564,61.01807,0,17.196333,359.99997,0.96501517,5.2068758,15.798965,319.72684,-9.2871132
166.5257,1.205678,9.2918978,61.01807,0,17.95697,359.99997,0.96554041,5.8149724,16.55998,319.64914,-9.2869139
166.5299,0.99879307,9.2897005,61.01807,0,18.0,359.99997,0.96657062,4.7907076,17.318239,319.55923,-9.2877522
166.5341,1.0718697,9.28304,61.01807,0,18.0,359.99997,0.96487242,5.1860237,17.987085,319.52069,-9.2884464
166.5383,1.1868979,9.2922039,61.01807,0,18.0,359.99997,0.96495372,5.7514939,18.41765,319.52069,-9.2912197
166.5425,1.2172065,9.2869282,61.01807,0,18.0,359.99997,0.96605611,5.882185,18.47875,319.57452,-9.3021059
166.5467,1.3562093,9.2764616,61.01807,0,18.0,359.99997,0.96375293,6.6005502,18.267557,319.85709,-9.318491
166.5509,1.1863612,9.28969,61.01807,0,18.0,359.99997,0.96494168,5.7833419,18.088701,320.13965,-9.3446817
166.5551,1.1878238,9.2817831,61.01807,0,18.0,359.99997,0.96511132,5.8060145,18.043745,319.38525,-9.3782215
166.5593,1.2036433,9.283947,61.01807,0,18.0,359.99997,0.96505362,5.8638687,18.068022,318.38687,-9.4143181
166.5635,1.123399,9.2842779,61.215816,0,18.0,359.99997,0.96374768,5.4669838,18.100628,317.81635,-9.4478168
166.5677,1.0915567,9.2740278,61.677242,0,18.0,359.99997,0.96364605,5.2656207,18.133595,317.81635,-9.47997
166.5719,1.190991,9.2776976,62.116699,0,18.0,359.99997,0.9640162,5.7845688,18.139252,317.83646,-9.5097675
166.5761,1.0991892,9.2716761,62.116699,0,18.0,359.99997,0.96193165,5.3705554,18.142717,318.25885,-9.539155
166.5803,1.2129235,9.2801352,62.116699,0,18.0,359.99997,0.96477157,5.937809,18.132494,318.68124,-9.570385
166.5845,1.1571981,9.2767782,62.116699,0,18.0,359.99997,0.96384734,5.669939,18.128345,318.68506,-9.6020975
166.5887,1.0743754,9.2916632,62.116699,0,18.0,359.99997,0.96493411,5.2336125,18.122536,318.47955,-9.6324549
166.5929,1.1398946,9.279233,62.116699,0,18.0,359.99997,0.9645946,5.5549164,18.121506,318.34375,-9.6632452
166.5971,1.1069355,9.2567291,62.116699,0,18.0,359.99997,0.96028805,5.3428373,18.116276,318.38214,-9.6929598
166.6013,1.2088948,9.2802935,62.116699,0,18.0,359.99997,0.96330982,5.8916812,18.116528,318.42053,-9.725152
166.6055,1.4425555,9.2825289,62.116699,0,18.0,359.99997,0.9649229,6.9755039,18.111244,318.44745,-9.7523413
166.6097,1.1602944,9.2831736,62.116699,0,18.0,359.99997,0.96513987,5.6262927,18.108263,318.47311,-9.7858334
166.6139,1.167363,9.2834396,62.116699,0,18.0,359.99997,0.96342844,5.6758685,18.105715,318.34454,-9.815773
166.6181,1.176268,9.2776937,62.116699,0,18.0,359.99997,0.96434391,5.6890054,18.106768,318.07574,-9.845602
166.6223,1.1535715,9.2718897,62.142406,0,18.0,359.99997,0.96299011,5.6148686,18.104275,317.83801,-9.8781652
166.6265,1.2862673,9.2698298,62.322361,0,18.0,359.99997,0.96149492,6.2752662,18.101612,317.78662,-9.9079847
166.6307,1.1943337,9.2771416,62.502323,0,18.0,359.99997,0.96425122,5.7717495,18.099777,317.73526,-9.9393806
166.6349,1.2870204,9.2698631,62.54517,0,18.0,359.99997,0.96260387,6.2030907,18.102642,318.00583,-9.9703646
166.6391,1.3073866,9.2894497,62.54517,0,18.0,359.99997,0.96455115,6.378427,18.098446,318.37704,-9.9996872
166.6433,1.1800214,9.2779989,62.54517,0,18.0,359.99997,0.9642843,5.7498784,18.093227,318.53345,-10.030781
166.6475,1.1065216,9.2673588,62.54517,0,18.0,359.99997,0.9622032,5.3999858,18.091396,318.34079,-10.064034
166.6517,1.1557831,9.2792025,62.54517,0,18.0,359.99997,0.9629488,5.6318974,18.090565,318.14813,-10.092824
166.6559,1.0477363,9.2661772,62.54517,0,18.0,359.99997,0.96234721,5.0429363,18.091158,318.40414,-10.123191
166.6601,1.2553283,9.2739248,62.54517,0,18.0,359.99997,0.96344709,6.0918179,18.091351,318.66013,-10.153072
166.6643,1.2385941,9.2813148,62.490898,0,18.0,359.99997,0.96300119,6.0091987,18.087873,318.81332,-10.184954
166.6685,1.1347187,9.2865047,62.403225,0,18.0,359.99997,0.96566069,5.5287089,18.086246,318.90323,-10.216459
166.6727,1.1959045,9.2751179,62.336426,0,18.0,359.99997,0.96382779,5.8204041,18.084593,318.92297,-10.24702
166.6769,1.0989242,9.2615719,62.336426,0,18.0,359.99997,0.95992106,5.3333836,18.088133,318.71817,-10.276398
166.6811,1.1791103,9.2757349,62.336426,0,18.0,359.99997,0.96378732,5.7940454,18.080938,318.51337,-10.308417
166.6853,1.3751658,9.2761478,62.486717,0,18.0,359.99997,0.96378201,6.5129256,18.089775,318.40704,-10.336822
166.6895,1.1734083,9.2866964,62.662064,0,18.0,359.99997,0.96410102,5.6474228,18.081381,318.31711,-10.366838
166.6937,1.2313523,9.2764864,62.753906,0,18.0,359.99997,0.96403509,5.9558516,18.083483,318.28223,-10.398276
166.6979,1.24672,9.2668762,62.753906,0,18.0,359.99997,0.96223086,6.0617604,18.078043,318.30783,-10.430662
166.7021,1.2175504,9.2787199,62.753906,0,18.0,359.99997,0.96287078,5.9371877,18.07485,318.3371,-10.461165
166.7063,1.3218071,9.2705851,62.753906,0,18.0,359.99997,0.96284205,6.4378009,18.079556,318.40134,-10.491759
166.7105,1.1632315,9.2751446,62.753906,0,18.0,359.99997,0.96371067,5.6503072,18.07568,318.46555,-10.52189
166.7147,1.2214384,9.2738638,62.753906,0,18.0,359.99997,0.96194059,5.8838849,18.076086,318.44733,-10.553392
166.7189,1.2997983,9.2819366,62.753906,0,18.0,359.99997,0.96480656,6.2860861,18.073095,318.39612,-10.584101
166.7231,1.2316054,9.2691002,62.812355,0,18.0,359.99997,0.96281075,5.9680371,18.072502,318.31918,-10.616526
166.7273,1.1971632,9.2679214,62.987698,0,18.0,359.99997,0.96105325,5.8530879,18.072472,318.19073,-10.646256
166.7315,1.2203872,9.2772274,63.163036,0,18.0,359.99997,0.96402013,5.9353704,18.069363,318.06229,-10.676048
166.7357,1.0791086,9.268568,63.171391,0,18.0,359.99997,0.96283919,5.2677708,18.071196,318.20245,-10.706282
166.7399,1.243392,9.2833395,63.171391,0,18.0,359.99997,0.9635663,6.0707083,18.069241,318.35605,-10.736625
166.7441,1.1946183,9.2776575,63.171391,0,18.0,359.99997,0.96413821,5.7958584,18.068892,318.43655,-10.768909
166.7483,1.1062313,9.2735214,63.171391,0,18.0,359.99997,0.96339929,5.3887658,18.066113,318.46225,-10.799238
166.7525,1.2328197,9.2756777,63.171391,0,18.0,359.99997,0.96250892,5.9497733,18.064795,318.47818,-10.828635
166.7567,1.160437,9.2576857,63.171391,0,18.0,359.99997,0.96056354,5.6267691,18.066339,318.45261,-10.859981
166.7609,1.2614754,9.272296,63.171391,0,18.0,359.99997,0.96329755,6.1418257,18.067621,318.427,-10.890725
166.7651,1.3489717,9.2817545,63.238625,0,18.0,359.99997,0.96334457,6.4057031,18.05603,318.39093,-10.922229
166.7693,1.1575536,9.2870121,63.321682,0,18.0,359.99997,0.9657678,5.5851436,18.064461,318.35239,-10.952925
166.7735,1.1909159,9.2710896,63.369144,0,18.0,359.99997,0.96332335,5.7762079,18.055742,318.36328,-10.982327
166.7777,1.2022004,9.2690611,63.369144,0,18.0,359.99997,0.96112245,5.8196778,18.055529,318.44006,-11.01333
166.7819,1.2196016,9.2732182,63.369144,0,18.0,359.99997,0.96326113,5.8829784,18.057997,318.51199,-11.046681
166.7861,1.4140009,9.2661018,63.369144,0,18.0,359.99997,0.96242458,6.8797426,18.060408,318.4863,-11.075354
166.7903,1.239609,9.2831812,63.369144,0,18.0,359.99997,0.96366894,6.0208039,18.056225,318.46063,-11.107088
166.7945,1.2354007,9.2745304,63.369144,0,18.0,359.99997,0.96351421,6.0252862,18.057102,318.48621,-11.13832
166.7987,1.3112214,9.2749472,63.369144,0,18.0,359.99997,0.96405286,6.347177,18.056255,318.53738,-11.167456
166.8029,1.2016428,9.2754602,63.369144,0,18.0,359.99997,0.96242458,5.822834,18.057184,318.57397,-11.197528
166.8071,1.2049024,9.2607708,63.369144,0,18.0,359.99997,0.96102101,5.8664184,18.053514,318.57397,-11.228814
166.8113,1.2069601,9.2694063,63.369144,0,18.0,359.99997,0.96291572,5.8555012,18.05423,318.57397,-11.259633
166.8155,1.101747,9.274663,63.369144,0,18.0,359.99997,0.96201539,5.3396168,18.051916,318.52765,-11.289383
166.8197,1.3412176,9.2809582,63.369144,0,18.0,359.99997,0.96442306,6.523015,18.049948,318.47644,-11.320008
166.8239,1.2602063,9.2697086,49.428066,0,18.0,359.99997,0.96317482,6.157722,18.048286,318.47897,-11.353048
167.9258,1.0243531,9.2832079,0.0,0,18.0,3.6327796e-13,0.9646126,4.9707794,18.000671,283.41531,-11.481607
170.0258,0.90611243,9.2876244,0.0,0,18.0,8.372758300000001e-42,0.96541882,4.3902855,17.999277,240.1436,-11.481776
172.1258,0.90373576,9.2951298,0.0,0,18.0,1.4012985e-45,0.96678615,4.3762212,18.000353,218.25725,-11.481342
174.2258,0.91856211,9.3025904,0.0,0,18.0,1.4012985e-45,0.96808791,4.4443941,18.000601,204.2207,-11.481422
176.3258,0.92543411,9.3096285,0.0,0,18.0,1.4012985e-45,0.96930683,4.4703779,18.000017,192.13341,-11.48156
178.4258,0.92694515,9.3153725,0.0,0,18.0,1.4012985e-45,0.97030699,4.4697905,18.000137,181.58818,-11.481917
180.5258,0.94053066,9.3215227,0.0,0,18.0,1.4012985e-45,0.97132599,4.5306501,17.999678,172.362,-11.481956
182.6258,0.9553892,9.3266993,0.0,0,18.0,1.4012985e-45,0.97224641,4.6024828,17.999992,163.77296,-11.481833
184.7258,0.95496953,9.3321648,0.0,0,18.0,1.4012985e-45,0.97326267,4.598784,17.999512,155.79858,-11.482081
186.8258,0.96777171,9.3368902,0.0,0,18.0,1.4012985e-45,0.97411937,4.6485538,18.000069,148.66725,-11.482278
188.9258,0.97928393,9.3415489,0.0,0,18.0,1.4012985e-45,0.97495341,4.6988921,17.99959,142.09117,-11.482518
191.0258,0.9876408,9.3463049,0.0,0,18.0,1.4012985e-45,0.97580647,4.7433653,17.999701,135.75047,-11.482224
193.1258,0.98668462,9.350441,0.0,0,18.0,1.4012985e-45,0.97652894,4.7313957,17.999063,129.82661,-11.48199
195.2258,0.99512434,9.3545389,0.0,0,18.0,1.4012985e-45,0.9772566,4.7652884,18.000017,124.25874,-11.481809
197.3258,1.0104848,9.3584566,0.0,0,18.0,1.4012985e-45,0.97789574,4.8363152,18.000425,118.84921,-11.482032
199.4258,1.016342,9.3625355,0.0,0,18.0,1.4012985e-45,0.97859555,4.8616643,18.000154,113.83922,-11.482288
201.5258,1.0186468,9.366025,0.0,0,18.0,1.4012985e-45,0.97914582,4.8714261,17.999889,109.08009,-11.482347
203.6258,1.02539,9.3696575,0.0,0,18.0,1.4012985e-45,0.97978723,4.8977699,17.999758,104.40723,-11.4825
205.7258,1.0395672,9.3738136,0.0,0,18.0,1.4012985e-45,0.98052883,4.9577308,18.000248,100.10852,-11.481551
207.8258,1.0421042,9.3767023,0.0,0,18.0,1.4012985e-45,0.9810459,4.9793835,18.000118,95.874809,-11.48135
209.9258,1.0449661,9.3803911,0.0,0,18.0,1.4012985e-45,0.98173344,4.9868774,18.000172,91.949081,-11.481488
212.0258,1.0514545,9.3821878,0.0,0,18.0,1.4012985e-45,0.98211873,5.0086303,17.999449,88.198341,-11.481332
214.1258,1.0657755,9.3850117,0.0,0,18.0,1.4012985e-45,0.98265076,5.0864654,17.999487,84.697868,-11.481699
216.2258,1.0637029,9.3879128,0.0,0,18.0,1.4012985e-45,0.98317784,5.0692596,17.999487,81.235535,-11.481866
218.3258,1.0693713,9.3900576,0.0,0,18.0,1.4012985e-45,0.98354161,5.0927768,18.000261,77.927345,-11.482388
220.4258,1.0731078,9.3925123,0.0,0,18.0,1.4012985e-45,0.98396373,5.1034503,17.99999,74.870567,-11.482215
222.5258,1.0876551,9.3953762,0.0,0,18.0,1.4012985e-45,0.98445439,5.1755338,18.00012,71.981644,-11.482089
224.6258,1.0776349,9.3975773,0.0,0,18.0,1.4012985e-45,0.98483121,5.129539,17.999334,69.114388,-11.482026
226.7258,1.0866549,9.3990021,0.0,0,18.0,1.4012985e-45,0.98506778,5.1702189,18.000277,66.430862,-11.482581
226.8258,1.0893859,9.3994484,0.0,0,18.0,1.4012985e-45,0.98516893,5.1804662,18.000492,66.352432,-11.482537