File: raw data/testID_0220.csv
Time(sec),Force(kN),Jaw(mm),PowAngle(deg),Power(W),Pram,PTemp,Strain,Stress(MPa),Stroke(mm),TC1(C),wedge(mm)
0.0,1.0552019,0.33737478,0.0,0,11.076097,3.4595352e-05,0.02273833,13.129127,11.07618,12.125127,-9.1326036
1.2,1.0103741,-0.00045532346,0.0,0,11.076097,3.5156004,-3.5408935e-05,12.866568,11.076767,12.149549,-9.4979954
2.4,0.96376175,-0.00050958915,0.0,0,11.076097,7.1156011,-4.7173995e-05,12.280935,11.076154,12.17511,-9.4939756
3.6,0.94993538,-0.00052698661,0.0,0,11.076097,10.715604,-3.186291e-05,12.098887,11.075632,12.041191,-9.4922228
4.8,0.92874449,-0.00041054038,12.343194,0,11.076097,14.315604,-4.870761e-05,11.828917,11.076094,12.127904,-9.4899683
6.0,0.91917408,-0.0005465491,29.163576,0,11.076097,17.915607,-4.4428009e-05,11.705026,11.076313,12.570671,-9.4881659
7.2,0.92347103,-0.0023614077,36.055885,0,11.076097,21.515604,-0.00017666425,11.77679,11.076578,15.484928,-9.4853134
8.4,0.92079103,-0.004703939,37.08984,0,11.076097,25.115606,-0.00032193022,11.733507,11.07669,20.853655,-9.4828482
9.6,0.91389382,-0.0062072249,36.309818,0,11.076097,28.715607,-0.00044086904,11.63423,11.076315,26.457684,-9.4807711
10.8,0.90038943,-0.0077705993,35.498585,0,11.076097,32.315617,-0.00052149151,11.480088,11.076811,31.005415,-9.4793224
12.0,0.89952534,-0.0087528611,37.058601,0,11.076097,35.915623,-0.00060937158,11.444235,11.076514,34.618233,-9.4774485
13.2,0.89124686,-0.010273242,37.836834,0,11.076097,39.515621,-0.00069647451,11.358707,11.076479,38.25095,-9.4745827
14.4,0.89255553,-0.012113702,38.527107,0,11.076097,43.11562,-0.00082535733,11.390066,11.076974,41.947308,-9.4724255
15.6,0.87725312,-0.013520369,38.551022,0,11.076097,46.715618,-0.00090532511,11.182863,11.077179,45.795151,-9.469943
16.8,0.87915331,-0.014580614,38.726276,0,11.076097,50.31562,-0.00099852181,11.206495,11.076175,49.617382,-9.468173
18.0,0.87147677,-0.01616657,39.24316,0,11.076097,53.915619,-0.0010824124,11.097617,11.076214,53.243401,-9.4660749
19.2,0.8728196,-0.017591618,39.860226,0,11.076097,57.515621,-0.0012060475,11.141696,11.075619,56.872524,-9.4634495
20.4,0.86215502,-0.018763673,39.924313,0,11.076097,61.115616,-0.0012383841,10.98651,11.076621,60.557606,-9.4609728
21.6,0.86438549,-0.019990439,39.924313,0,11.076097,64.715614,-0.0013564155,11.027151,11.076021,64.402092,-9.4590168
22.8,0.86203945,-0.02133685,40.058781,0,11.076097,68.31562,-0.0014064314,10.997977,11.076283,67.906166,-9.4577312
24.0,0.86041111,-0.022872174,40.572506,0,11.076097,71.915619,-0.0015571286,10.969397,11.076041,71.55024,-9.4550533
25.2,0.85148317,-0.024652263,40.572506,0,11.076097,75.515625,-0.0016228734,10.855368,11.076681,75.191849,-9.4525375
26.4,0.8457039,-0.025778838,40.572746,0,11.076097,79.115631,-0.0017472393,10.780092,11.076752,78.777229,-9.4501247
27.6,0.8631205,-0.027623253,41.197624,0,11.076097,82.71563,-0.0018070448,11.002805,11.076451,82.313454,-9.4482746
28.8,0.86209601,-0.029160904,41.198727,0,11.076097,86.315628,-0.0019720767,11.003212,11.075986,85.99765,-9.4465303
30.0,0.84379679,-0.031057594,41.198727,0,11.076097,89.915634,-0.0020349498,10.765615,11.077043,89.756386,-9.4442234
31.2,0.84687036,-0.03241089,41.198727,0,11.076097,93.515633,-0.0021752582,10.80825,11.076719,93.249084,-9.4419937
32.4,0.85916001,-0.034313817,41.802975,0,11.076097,97.115646,-0.0022515121,10.98904,11.075569,96.775345,-9.4392776
33.6,0.85672915,-0.036225688,41.800007,0,11.076097,100.71564,-0.0024282727,10.935676,11.076925,100.5726,-9.4376564
34.8,0.84747469,-0.038121287,41.514496,0,11.076097,104.31564,-0.0025033099,10.802081,11.075881,104.2488,-9.4358959
36.0,0.83154851,-0.039585453,41.802975,0,11.076097,107.91563,-0.002640839,10.615253,11.077078,107.7138,-9.4335938
37.2,0.83947694,-0.041827895,42.006462,0,11.076097,111.51565,-0.0027473331,10.72136,11.075644,111.15643,-9.4313231
38.4,0.85069871,-0.043661747,42.396236,0,11.076097,115.11564,-0.0029100629,10.859142,11.076819,114.69901,-9.4288435
39.6,0.85634774,-0.04650357,42.396236,0,11.076097,118.71565,-0.003065241,10.940681,11.076964,118.55692,-9.4272919
40.8,0.85101658,-0.047759619,42.346355,0,11.076097,122.31564,-0.0031718581,10.877549,11.076022,122.26034,-9.4253397
42.0,0.83668029,-0.049843606,42.364441,0,11.076097,125.91565,-0.0032922744,10.694091,11.07719,125.83472,-9.4229431
43.2,0.83861488,-0.051523767,42.396236,0,11.076097,129.51576,-0.0034223516,10.71456,11.075649,129.25235,-9.4206085
44.4,0.85414225,-0.054330036,42.966354,0,11.076097,133.11563,-0.0035954018,10.911606,11.076101,132.75317,-9.4186106
45.6,0.85361654,-0.055799805,42.978512,0,11.076097,136.71564,-0.0037025458,10.917518,11.076754,136.43442,-9.4169664
46.8,0.84931415,-0.058127962,42.571472,0,11.076097,140.31563,-0.0038489609,10.835112,11.076142,140.3219,-9.4147873
48.0,0.84767216,-0.060021631,42.95533,0,11.076097,143.91563,-0.0039725043,10.838815,11.076536,143.83081,-9.4124498
49.2,0.84764761,-0.062755123,42.978512,0,11.076097,147.51564,-0.0041696667,10.842217,11.076077,147.2662,-9.4099512
50.4,0.85595864,-0.064620629,43.338631,0,11.076097,151.11562,-0.0042946148,10.948363,11.07736,150.77432,-9.4076834
51.6,0.8600269,-0.066912107,43.293522,0,11.076097,154.71564,-0.0044478639,11.001157,11.076526,154.56779,-9.406311
52.8,0.85484332,-0.069041029,42.978519,0,11.076097,158.31564,-0.0045892252,10.934886,11.076283,158.29076,-9.4043264
54.0,0.85438293,-0.071267091,43.47456,0,11.076097,161.91563,-0.0047418624,10.938055,11.07528,161.742,-9.4019318
55.2,0.87567914,-0.07410612,43.517807,0,11.076097,165.51564,-0.004914958,11.197584,11.075554,165.41913,-9.3998775
56.4,0.86086345,-0.075777791,43.236191,0,11.076097,169.11565,-0.005040288,11.038536,11.075191,169.15036,-9.3976927
57.6,0.86094046,-0.078302756,43.203144,0,11.076097,172.71564,-0.0051992573,11.030847,11.077518,172.69745,-9.3955975
58.8,0.86458278,-0.080664515,43.39502,0,11.076097,176.31564,-0.0053699105,11.065693,11.075931,176.29703,-9.3935299
60.0,0.878865,-0.083814219,43.527828,0,11.076097,179.91565,-0.0055736792,11.249032,11.075511,179.70644,-9.3916121
61.2,0.86600941,-0.085220955,43.717567,0,11.076097,183.51564,-0.0056782756,11.096637,11.076522,183.22983,-9.3897934
62.4,0.86805886,-0.087980077,43.929844,0,11.076097,187.11565,-0.0058420766,11.131538,11.076423,186.94867,-9.3877411
63.6,0.86950105,-0.089878529,43.527836,0,11.076097,190.71565,-0.0059880842,11.135611,11.076254,190.64989,-9.3855925
64.8,0.88280112,-0.092465743,44.07616,0,11.076097,194.31566,-0.0061522163,11.315176,11.076163,194.17189,-9.3833942
66.0,0.87411523,-0.095549077,44.077145,0,11.076097,197.91565,-0.0063601788,11.206286,11.076495,197.57907,-9.3811827
67.2,0.86741304,-0.098008774,44.077278,0,11.076097,201.51566,-0.0065267906,11.113456,11.075561,201.37515,-9.3789129
68.4,0.88069826,-0.099986799,43.910385,0,11.076097,205.11566,-0.0066542705,11.289406,11.076214,205.25716,-9.377347
69.6,0.88566864,-0.10230881,43.63715,0,11.076097,208.71567,-0.006802523,11.359189,11.075964,208.85402,-9.3757849
70.8,0.89034581,-0.10474199,44.438858,0,11.076097,212.31566,-0.0069816727,11.435293,11.076071,211.96483,-9.3733883
72.0,0.89459598,-0.10810787,44.604488,0,11.076097,215.91565,-0.0071742805,11.487371,11.076147,215.49458,-9.3712254
73.2,0.8815378,-0.10956559,44.604488,0,11.076097,219.51566,-0.0073112282,11.287843,11.075663,219.29901,-9.3683033
74.4,0.88483644,-0.1123655,44.585987,0,11.076097,223.11566,-0.0074483203,11.350768,11.077247,223.08234,-9.3664722
75.6,0.89374089,-0.1144508,44.466427,0,11.076097,226.71567,-0.0076277549,11.464813,11.076033,226.72519,-9.3648958
76.8,0.89207804,-0.11719316,44.604488,0,11.076097,230.31567,-0.0077726371,11.45784,11.075994,230.1019,-9.362998
78.0,0.90044707,-0.11930684,44.950325,0,11.076097,233.91566,-0.0079495832,11.55535,11.076504,233.60651,-9.3608637
79.2,0.90645009,-0.12188226,45.12085,0,11.076097,237.51567,-0.0080711227,11.645473,11.076754,237.27908,-9.3584604
80.4,0.90014464,-0.12461903,45.12085,0,11.076097,241.11566,-0.0083104605,11.556075,11.076978,240.92786,-9.356369
81.6,0.90382826,-0.12741576,44.621742,0,11.076097,244.71567,-0.0084320698,11.62064,11.076922,244.86165,-9.3542938
82.8,0.89952481,-0.12894934,44.604496,0,11.076097,248.31567,-0.0085839042,11.561376,11.076805,248.47601,-9.3522558
84.0,0.9144848,-0.13184699,45.123951,0,11.076097,251.91566,-0.008725781,11.747013,11.076174,251.52129,-9.3503017
85.2,0.91185236,-0.13486141,45.121037,0,11.076097,255.51569,-0.0089715067,11.727759,11.076387,255.43489,-9.3481922
86.4,0.90986961,-0.13764516,44.632763,0,11.076097,259.11594,-0.0090980856,11.684581,11.077009,259.31509,-9.3460569
87.6,0.91012353,-0.13972674,45.116409,0,11.076097,262.7157,-0.0092780888,11.705974,11.07588,262.69125,-9.3438272
88.8,0.92012709,-0.1428954,44.604546,0,11.076097,266.31564,-0.0094473781,11.836957,11.075722,266.50299,-9.341857
90.0,0.91234958,-0.14531553,44.630074,0,11.076097,269.91568,-0.0096319811,11.717637,11.076715,270.00281,-9.3396282
91.2,0.91749424,-0.14844315,45.12085,0,11.076097,273.51569,-0.0098177604,11.788129,11.075846,273.37024,-9.3376513
92.4,0.92939901,-0.15187007,44.604496,0,11.076097,277.11566,-0.010064267,11.961747,11.075971,277.3645,-9.3356934
93.6,0.94099265,-0.15359627,44.351692,0,11.076097,280.71564,-0.010171563,12.092791,11.076243,281.0954,-9.3341236
94.8,0.93380451,-0.15576899,44.604488,0,11.076097,284.31567,-0.01031907,12.013386,11.076117,284.37817,-9.331625
96.0,0.93894488,-0.15850486,44.604488,0,11.076097,287.91565,-0.010512979,12.086094,11.076784,287.89526,-9.3298063
97.2,0.93292058,-0.1613608,44.604488,0,11.076097,291.51566,-0.010690386,12.00397,11.075775,291.61783,-9.3275604
98.4,0.93040967,-0.16385151,44.077206,0,11.076097,295.11566,-0.010865422,11.985972,11.075171,295.45895,-9.325635
99.6,0.93986052,-0.16608481,44.60347,0,11.076097,298.71567,-0.010998742,12.097862,11.076098,298.71347,-9.3235531
100.8,0.93729359,-0.16948566,44.209816,0,11.076097,302.31567,-0.011247581,12.066836,11.075851,302.46231,-9.3215981
102.0,0.93955636,-0.17145124,44.306572,0,11.076097,305.91565,-0.011364129,12.101777,11.075459,305.91885,-9.3197412
103.2,0.94009775,-0.17444137,44.333282,0,11.076097,309.51566,-0.011569956,12.106343,11.076023,309.57718,-9.3176317
104.4,0.94476962,-0.17703113,44.077152,0,11.076097,313.11566,-0.011739458,12.169755,11.076311,313.21344,-9.3154583
105.6,0.94106263,-0.17978695,44.604469,0,11.076097,316.71567,-0.011935055,12.135389,11.076675,316.58344,-9.3136263
106.8,0.94371575,-0.18259487,44.112717,0,11.076097,320.31567,-0.012097783,12.160232,11.076572,320.36874,-9.3112602
108.0,0.94801998,-0.18491586,44.604488,0,11.076097,323.91565,-0.012279043,12.224812,11.076157,323.83582,-9.3093863
109.2,0.9593823,-0.18742476,44.397705,0,11.076097,327.51566,-0.012417687,12.338389,11.075572,327.52386,-9.3074093
110.4,0.9700613,-0.18947107,44.569206,0,11.076097,331.11566,-0.01258122,12.502368,11.075225,331.03445,-9.3055458
111.6,0.97058558,-0.19276965,44.167778,0,11.076097,334.7157,-0.012759306,12.507767,11.075054,334.7373,-9.3032093
112.8,0.97826648,-0.19520706,44.540123,0,11.076097,338.31567,-0.0129477,12.611199,11.076081,338.24445,-9.3015299
114.0,0.97475958,-0.19839075,44.077152,0,11.076097,341.91568,-0.01310727,12.566824,11.076016,342.06061,-9.2993803
115.2,0.98078138,-0.2011355,44.603905,0,11.076097,345.51566,-0.013336699,12.658403,11.076497,345.47516,-9.297451
116.4,0.97697932,-0.2038257,44.127754,0,11.076097,349.11569,-0.013455502,12.59987,11.075788,349.2001,-9.2954092
117.6,0.97828013,-0.20605822,44.379723,0,11.076097,352.71567,-0.013649718,12.627692,11.076436,352.66135,-9.2933111
118.8,0.98273945,-0.20859212,44.077213,0,11.076097,356.3157,-0.013767493,12.683868,11.077376,356.4906,-9.2912683
120.0,0.97696078,-0.21050109,44.311577,0,11.076097,359.91568,-0.013942432,12.603156,11.076417,359.8606,-9.2892666
121.2,0.98250395,-0.21266447,44.077194,0,11.076097,363.51572,-0.014042378,12.675447,11.076938,363.59131,-9.2874651
122.4,0.95322859,-0.21478765,44.077152,0,11.076097,367.11569,-0.01422327,12.301592,11.076181,367.22427,-9.2851868
123.6,0.95589149,-0.21763554,44.087162,0,11.076097,370.71573,-0.014385212,12.356437,11.076788,370.71631,-9.2828169
124.8,0.95784813,-0.21943353,44.077152,0,11.076097,374.3157,-0.014510266,12.370638,11.075834,374.41391,-9.2810488
126.0,0.96658587,-0.22197638,44.074162,0,11.076097,377.91571,-0.014663793,12.506175,11.075925,378.06116,-9.2792397
127.2,0.96355355,-0.22365636,43.692638,0,11.076097,381.51572,-0.014785457,12.442762,11.076426,381.74246,-9.2773972
128.4,0.97035795,-0.22569965,44.077145,0,11.076097,385.11572,-0.014916691,12.54149,11.076606,384.97186,-9.2754135
129.6,0.97185063,-0.22783703,44.077145,0,11.076097,388.71573,-0.015065915,12.573126,11.075899,388.75162,-9.2730074
130.8,0.96686232,-0.23067926,43.910187,0,11.076097,392.31573,-0.015261183,12.498897,11.075815,392.46979,-9.2711248
132.0,0.95434093,-0.2331152,44.077145,0,11.076097,395.91571,-0.015403181,12.342289,11.075797,395.80817,-9.2694397
133.2,0.93970215,-0.23413742,44.084526,0,11.076097,399.51572,-0.015489564,12.153105,11.077006,399.35141,-9.2671986
134.4,0.31482431,-0.24359082,42.396244,0,11.076097,399.99893,-0.016097166,4.0804601,11.076028,401.09201,-9.2670078
135.6,0.33442959,-0.24371713,43.527729,0,11.076097,399.99893,-0.016133212,4.3246894,11.076475,400.02792,-9.2668018
136.8,0.33517644,-0.24457778,42.978519,0,11.076097,399.99893,-0.016170314,4.3476911,11.075923,400.50281,-9.2668915
138.0,0.33419558,-0.24546963,42.396244,0,11.076097,399.99893,-0.016253926,4.3300629,11.075404,400.5361,-9.2668552
139.2,0.34533164,-0.24682114,42.301086,0,11.076097,399.99893,-0.01632298,4.4822836,11.0762,400.43417,-9.266839
140.4,0.32676411,-0.24708961,41.805958,0,11.076097,399.99893,-0.016361341,4.2359433,11.075303,400.41528,-9.266675
141.6,0.33228597,-0.24772123,41.952854,0,11.076097,399.99893,-0.016384179,4.3023539,11.075377,400.2803,-9.2668495
142.8,0.33599383,-0.24860281,41.545719,0,11.076097,399.99893,-0.016461056,4.3506303,11.076118,400.48431,-9.2668695
144.0,0.34748563,-0.24887775,41.789753,0,11.076097,399.99893,-0.016438449,4.497407,11.075646,400.28775,-9.2669106
145.2,0.34210905,-0.24992488,41.199921,0,11.076097,399.99893,-0.016567189,4.4286647,11.075018,400.34644,-9.2666636
146.4,0.34308332,-0.25160739,41.198734,0,11.076097,399.99893,-0.016602911,4.4518833,11.076413,400.36017,-9.266902
147.6,0.33318472,-0.25123149,40.573269,0,11.076097,399.99893,-0.016629007,4.303617,11.07628,400.49277,-9.266716
148.8,0.34142399,-0.25165185,41.101398,0,11.076097,399.99893,-0.016604094,4.4168,11.076016,400.20541,-9.2668514
150.0,0.34219897,-0.25236726,40.572514,0,11.076097,399.99893,-0.01669433,4.4308023,11.076413,400.28732,-9.2666187
151.2,0.34835204,-0.25269258,40.572514,0,11.076097,399.99893,-0.016673565,4.5163875,11.076043,400.2915,-9.2662125
152.4,0.35059473,-0.25316411,40.267208,0,11.076097,399.99893,-0.016733211,4.5388522,11.076439,400.34534,-9.2664614
153.6,0.34902409,-0.25514024,40.350708,0,11.076097,399.99893,-0.016846443,4.5344319,11.075948,400.14252,-9.2662067
154.8,0.34158742,-0.25439706,39.92432,0,11.076097,399.99893,-0.016811553,4.4111314,11.075789,400.23306,-9.2663383
156.0,0.33573776,-0.25552234,40.081188,0,11.076097,399.99893,-0.016878255,4.3629503,11.074958,400.08228,-9.266428
157.2,0.33847001,-0.25576165,39.92432,0,11.076097,399.99893,-0.01689917,4.3873334,11.076621,400.26425,-9.2663536
158.4,0.33913296,-0.25628406,39.665619,0,11.076097,399.99893,-0.016939793,4.4037156,11.076768,400.31711,-9.2661905
159.6,0.34658954,-0.25679928,39.892193,0,11.076097,399.99893,-0.016975384,4.4892397,11.077079,400.13345,-9.2666416
160.8,0.3440854,-0.25830927,39.357151,0,11.076097,399.99893,-0.017083978,4.4502568,11.075346,400.12506,-9.266326
162.0,0.34094992,-0.25754538,39.551285,0,11.076097,399.99893,-0.017028077,4.4139729,11.077132,400.11859,-9.2665129
163.2,0.34118,-0.25785342,39.31031,0,11.076097,399.99893,-0.017060477,4.431735,11.075868,400.00723,-9.2662792
164.4,0.35030782,-0.25849855,39.35358,0,11.076097,399.99893,-0.017096028,4.546,11.075408,400.06689,-9.2662544
165.6,0.33721337,-0.25849763,39.362122,0,11.076097,399.99893,-0.01711932,4.3610191,11.077119,400.01971,-9.2660885
166.8,0.35541993,-0.25991344,39.349258,0,11.076097,399.99893,-0.01718148,4.6026597,11.075583,400.06131,-9.2659864
168.0,0.35383156,-0.25960246,39.243168,0,11.076097,399.99893,-0.01718819,4.5861115,11.075983,400.26297,-9.2660265
169.2,0.34515604,-0.26037514,39.24316,0,11.076097,399.99893,-0.01719721,4.4674492,11.076263,400.15775,-9.2658987
170.4,0.34537616,-0.26050228,39.243149,0,11.076097,399.99893,-0.01725016,4.4850917,11.076664,400.0943,-9.2657814
171.6,0.35018086,-0.26070935,39.195724,0,11.076097,399.99893,-0.017206119,4.5284672,11.075704,400.0687,-9.2659893
172.8,0.34722263,-0.26118973,38.731903,0,11.076097,399.99893,-0.017283542,4.4964929,11.075547,400.10208,-9.2659922
174.0,0.35766506,-0.26236346,39.005421,0,11.076097,399.99893,-0.01731002,4.6339808,11.075661,400.04263,-9.2659464
175.2,0.35232997,-0.26252356,39.236813,0,11.076097,399.99893,-0.017347036,4.5655646,11.075984,399.99841,-9.2663069
176.4,0.33628961,-0.26280692,38.897701,0,11.076097,399.99893,-0.017336126,4.3588829,11.07585,400.06445,-9.2661009
177.6,0.350795,-0.26305306,38.572693,0,11.076097,399.99893,-0.017382303,4.5420184,11.07688,400.06256,-9.2661676
178.6137,0.44363958,0.022717288,28.624676,0,11.076099,65.879799,0.001483475,5.6770635,11.077036,400.13544,-9.2657995
178.6161,0.52347696,0.02525403,19.390898,0,11.076099,2.8481728e-15,0.0016159753,6.6155453,11.074395,400.12103,-9.2650337
178.6185,0.45685145,0.023699928,10.157119,0,11.076099,1.2312645000000001e-31,0.0016556008,5.7502589,11.074738,400.10663,-9.2648821
178.6209,0.46532726,0.022150693,0.92333841,0,11.076099,0.0,0.0016900325,5.9000607,11.074424,400.09219,-9.2652092
178.6233,0.45903563,0.021867957,0.0,0,11.076099,0.0,0.0015210265,5.8693089,11.075039,400.03885,-9.26542
178.6257,0.45009032,0.025897551,0.0,0,11.076099,0.0,0.0015554217,5.6655817,11.077183,399.98117,-9.2671146
178.6281,0.46042639,0.027524181,0.0,0,11.076099,0.0,0.0015015727,5.7826767,11.078398,399.92349,-9.2665319
178.6305,0.46044329,0.026372125,0.0,0,11.076099,0.0,0.0016849472,5.8207626,11.077212,399.86581,-9.2644253
178.6329,0.46922067,0.023886109,0.0,0,11.076099,0.0,0.0017892161,6.0026436,11.073864,399.87085,-9.2656975
178.6353,0.46935517,0.021275731,0.0,0,11.076099,0.0,0.0016294806,5.9596434,11.078082,399.89969,-9.2649813
178.6377,0.47286162,0.020848969,0.0,0,11.076099,0.0,0.0014155493,5.9174619,11.07744,399.92853,-9.2656813
178.6401,0.4657923,0.023148516,0.0,0,11.076099,0.0,0.0013767199,5.9203649,11.076962,399.95737,-9.265975
178.6425,0.47441971,0.023577403,0.0,0,11.076099,0.0,0.0014182552,6.1334062,11.077417,399.97034,-9.2651052
178.6449,0.48204815,0.022962922,0.0,0,11.076099,0.0,0.0015620146,6.1114631,11.075049,399.97034,-9.2649193
178.6473,0.46779308,0.02196952,0.0,0,11.076099,0.0,0.0016846289,5.9220262,11.076248,399.97034,-9.2652321
178.6497,0.46922642,0.022268694,0.0,0,11.076099,0.0,0.0016395086,6.0053358,11.077833,399.97034,-9.2659349
178.6521,0.47287244,0.024379747,0.0,0,11.076099,0.0,0.0015011488,5.9965706,11.077266,399.97305,-9.2662964
178.6545,0.46958649,0.027942667,0.0,0,11.076099,0.0,0.0015392515,5.9601626,11.076496,399.98026,-9.2649508
178.6569,0.47615692,0.027247844,0.0,0,11.076099,0.0,0.0016977589,6.0482268,11.078177,399.98746,-9.2646236
178.6593,0.4732891,0.025551181,0.0,0,11.076099,0.0,0.0018616448,6.1293139,11.07474,399.99466,-9.2659864
178.6617,0.47622049,0.022878759,0.0,0,11.076099,0.0,0.0017622346,6.0401802,11.077761,400.00333,-9.2671824
178.6641,0.4924992,0.022844322,0.0,0,11.006544,0.0,0.0015986359,6.2011957,11.077446,400.01773,-9.2677431
178.6665,0.48247573,0.024504492,0.0,0,10.645576,0.0,0.0014521856,6.0911546,11.077256,400.03217,-9.2657766
178.6689,0.48163614,0.025024546,0.0,0,10.284602,0.0,0.001546831,6.1597309,11.058197,400.04657,-9.267025
178.6713,0.50123852,0.02441583,0.0,0,9.9236288,0.0,0.0016284973,6.3073125,10.944024,400.06659,-9.2666969
178.6737,0.47080463,0.02383657,0.0,0,9.5626545,0.0,0.0017616218,6.0438714,10.673285,400.3045,-9.2664518
178.6761,0.53940421,0.022973858,0.0,0,9.2092896,0.0,0.0016440179,6.7898078,10.291263,400.54242,-9.2669525
178.6785,4.6086078,0.13309821,0.0,0,8.8581219,0.0,0.0086023416,57.182804,9.8339891,400.78033,-9.2643385
178.6809,5.9214993,0.63619286,0.0,0,8.518857,0.0,0.042662974,73.046227,9.2696533,401.01828,-9.2600479
178.6833,6.5375762,1.1017489,0.0,0,8.1848736,0.0,0.075487845,77.04232,8.8342867,400.66769,-9.2602701
178.6857,6.8464208,1.4542269,0.0,0,7.860775,0.0,0.10165475,78.888573,8.4698467,400.21326,-9.2590008
178.6881,7.0901198,1.7357723,0.0,0,7.543015,0.0,0.12297734,79.590836,8.1386003,399.75882,-9.2588224
178.6905,7.1746225,2.0412064,0.0,0,7.2334356,0.0,0.1460342,79.095428,7.8276587,399.30438,-9.2590475
178.6929,7.3778257,2.3245032,0.0,0,6.9312272,0.0,0.16795941,79.269135,7.5504384,398.42111,-9.2596664
178.6953,7.658103,2.5901432,0.0,0,6.6355214,0.0,0.18897013,80.606819,7.2771673,397.33139,-9.2604351
178.6977,7.9077396,2.8696628,0.0,0,6.3480015,0.0,0.21182297,81.381973,6.9954042,396.2417,-9.2604523
178.7001,8.1386166,3.1574638,0.0,0,6.0655355,0.0,0.23621316,81.786201,6.6995368,395.15198,-9.260273
178.7025,8.3765306,3.4486365,0.0,0,5.792079,0.0,0.26111758,82.167137,6.4055748,394.44095,-9.2610483
178.7049,8.687748,3.7380056,0.0,0,5.5222936,0.0,0.28618181,82.987877,6.1149774,394.10861,-9.2604399
178.7073,8.9564381,4.0303168,0.0,0,5.2621331,0.0,0.3121109,83.399803,5.8204083,393.77628,-9.2604017
178.7097,9.2331324,4.315731,0.0,0,5.0044241,0.0,0.33843759,83.697906,5.5355043,393.44394,-9.2605066
178.7121,9.4716177,4.5863867,0.0,0,4.7569838,0.0,0.3646152,83.72699,5.2596946,392.93079,-9.2612953
178.7145,9.7573481,4.8528867,0.0,0,4.5108657,0.0,0.39099237,83.995422,4.9901314,392.04214,-9.2606153
178.7169,10.045717,5.1112409,0.0,0,4.2754693,0.0,0.41661099,84.298225,4.7312603,391.15347,-9.2600603
178.7193,10.345317,5.3636184,0.0,0,4.0404716,0.0,0.44188204,84.662506,4.473474,390.2648,-9.2596312
178.7217,10.607782,5.6070948,0.0,0,3.8165052,0.0,0.46722335,84.62207,4.2359986,389.40759,-9.260067
178.7241,10.874044,5.840518,0.0,0,3.5926332,0.0,0.49269268,84.532837,3.9984879,388.72845,-9.2588291
178.7265,11.174193,6.0657153,0.0,0,3.3790326,0.0,0.51793915,84.743225,3.7717991,388.04935,-9.2600098
178.7289,11.495349,6.2862463,0.0,0,3.1660566,0.0,0.54333329,85.008232,3.5494399,387.37021,-9.2609386
178.7313,11.812108,6.5092654,0.0,0,2.9619904,0.0,0.5688054,85.100037,3.3301084,386.69107,-9.2595835
178.7337,12.113444,6.7303805,0.0,0,2.7593822,0.0,0.59452063,85.059341,3.1114094,385.74316,-9.2588949
178.7361,12.436247,6.9433942,0.0,0,2.5644472,0.0,0.62031209,85.114006,2.9047391,384.78836,-9.2600231
178.7385,12.785227,7.1469932,0.0,0,2.3717272,0.0,0.64657456,85.234482,2.7006383,383.83356,-9.2596464
178.7409,13.161927,7.3459764,0.0,0,2.185524,0.0,0.67293978,85.498848,2.5006688,382.87875,-9.2595167
178.7433,13.524891,7.5388103,0.0,0,2.002212,0.0,0.69862807,85.536438,2.2971871,379.37833,-9.2591076
178.7457,13.868567,7.731771,0.0,0,1.8243402,0.0,0.72413641,85.548531,2.1073856,375.24152,-9.2593565
178.7481,14.261052,7.9240561,0.0,0,1.6499562,0.0,0.750314,85.720436,1.9220686,371.10468,-9.2585564
178.7505,14.672329,8.1036844,0.0,0,1.4800411,0.0,0.77621245,85.916679,1.7376858,366.96786,-9.2590637
178.7529,15.08971,8.2821035,0.0,0,1.3141533,0.0,0.80314988,85.998421,1.5613168,365.99979,-9.2571917
178.7553,15.51405,8.4541616,0.0,0,1.1518563,0.0,0.8296994,86.119446,1.3867943,366.93289,-9.2578163
178.7577,15.941311,8.6237898,0.0,0,0.99408025,0.0,0.85543877,86.262245,1.2142457,367.86603,-9.2572708
178.7601,16.417509,8.7921982,0.0,0,0.83908123,0.0,0.88140732,86.513878,1.0443169,368.79916,-9.2576761
178.7625,16.911201,8.9581928,0.0,0,0.68903327,0.0,0.90778685,86.811333,0.88226891,371.25848,-9.257021
178.7649,17.34799,9.1108704,0.0,0,0.54098582,0.0,0.93385977,86.772438,0.72770083,375.58316,-9.2563591
178.7673,17.836515,9.2589464,0.0,0,0.39818579,0.0,0.96069235,86.852982,0.57555151,379.90784,-9.2562218
178.7697,16.368622,9.3336954,0.0,0,0.25673616,0.0,0.97481763,78.599518,0.4623639,384.23248,-9.2566576
178.7721,14.846873,9.3489504,0.0,0,0.12094405,0.0,0.97644645,71.350212,0.41090232,387.66589,-9.2592249
178.7745,14.086901,9.3573446,0.0,0,-0.014479335,0.0,0.97677559,67.552422,0.38170904,388.7496,-9.2611151
178.7769,13.669106,9.3631182,0.0,0,-0.14691253,0.0,0.97804922,65.478218,0.35481244,389.83331,-9.2611198
178.7793,13.614647,9.3625937,0.0,0,-0.27934453,0.0,0.97891051,65.114006,0.31600985,390.91705,-9.2599812
178.7817,13.916418,9.3719873,0.0,0,-0.41177651,0.0,0.98126853,66.387871,0.25491473,391.98126,-9.2611141
178.7841,14.102469,9.3765192,0.0,0,-0.54420853,0.0,0.98185992,67.256775,0.1896714,392.8699,-9.2596664
178.7865,14.118919,9.3849325,0.0,0,-0.67664051,0.0,0.98239309,67.286018,0.12408369,393.75858,-9.2616043
178.7889,14.005502,9.4004765,0.0,0,-0.80907249,0.0,0.98407495,66.685432,0.066739589,394.64722,-9.260026
178.7913,13.811077,9.4053001,0.0,0,-0.94150448,0.0,0.98537809,65.693909,0.022671238,395.53586,-9.2609854
178.7937,13.488412,9.4039984,3.04263,0,-1.0739366,0.0,0.98647362,64.069717,-0.0079199877,396.0033,-9.2605953
178.7961,13.065245,9.4015102,6.3319502,0,-0.76691389,400.0,0.98675203,62.06469,-0.018758299,396.43655,-9.2614794
178.7985,12.568543,9.4003668,9.6212692,0,-0.30842754,400.0,0.98577189,59.76516,-0.018766711,396.86984,-9.2623062
178.8009,12.157881,9.4024057,12.910589,0,0.15005879,400.0,0.98499316,57.828266,-0.013067505,397.30313,-9.2627449
178.8033,11.80713,9.4043684,13.73291,0,0.60854518,400.0,0.98504704,56.157143,-0.01111061,397.38977,-9.2632608
178.8057,11.562589,9.403306,13.73291,0,1.0670315,400.0,0.98564363,54.955349,-0.0083289975,397.36087,-9.2642412
178.8081,11.139824,9.3987741,13.73291,0,1.5255178,400.0,0.98577076,52.956623,0.0023729715,397.33197,-9.2645969
178.8105,9.7133198,9.3950205,13.73291,0,1.9840043,400.0,0.98550916,46.320995,0.070771389,397.30307,-9.2647829
178.8129,7.0890379,9.386467,14.053685,0,2.4424911,400.0,0.98295474,34.02504,0.20249172,397.22028,-9.2655506
178.8153,3.4995546,9.3707256,14.611554,0,2.9009774,400.0,0.97920042,17.078712,0.42094049,397.09766,-9.268856
178.8177,-0.31646624,9.3069525,15.169423,0,3.3594637,400.0,0.9678027,-1.3751069,0.82900894,396.97507,-9.2722673
178.8201,0.78383428,9.3717813,15.727291,0,3.81795,400.0,0.98010921,3.3657465,1.537712,396.85245,-9.2726316
178.8225,0.25621471,9.3405638,16.062012,0,4.2764363,400.0,0.97576863,1.10619,2.3558083,396.75577,-9.2718782
178.8249,0.30826521,9.351388,16.062012,0,4.7349229,400.0,0.97737545,1.5474958,3.0613091,396.698,-9.2710915
178.8273,0.28334337,9.3532906,16.062012,0,5.1934094,400.0,0.9768852,1.3786649,3.5873315,396.6402,-9.2697468
178.8297,0.27229011,9.3658905,16.062012,0,5.6518955,400.0,0.97813863,1.3482909,4.0238042,396.5824,-9.2695065
178.8321,0.34035495,9.3619194,16.174507,0,6.1103821,400.0,0.97806019,1.6283221,4.4435301,396.52133,-9.2693644
178.8345,0.17416222,9.3609467,16.674484,0,6.5688682,400.0,0.97890747,0.88285065,4.8567586,396.4491,-9.2687626
178.8369,0.30908456,9.3513527,17.174461,0,7.0273547,400.0,0.9778319,1.4336261,5.2933707,396.37683,-9.2667141
178.8393,0.24559635,9.3549309,17.674438,0,7.4858418,400.0,0.97757101,1.1653918,5.7423658,396.3046,-9.2666368
178.8417,0.26262701,9.3590746,18.149414,0,7.9443283,400.0,0.97721386,1.2419088,6.2200623,396.23669,-9.2662687
178.8441,0.23003884,9.3621206,18.149414,0,8.4028139,400.0,0.97725469,1.1129968,6.712429,396.25113,-9.2667351
178.8465,0.15370908,9.3608418,18.149414,0,8.8612995,400.0,0.97823656,0.74746162,7.198113,396.26556,-9.2658806
178.8489,0.13189721,9.3572617,18.149414,0,9.3197861,400.0,0.97871673,0.60011554,7.6673222,396.28003,-9.2659321
178.8513,0.17066449,9.351613,18.149414,0,9.7782726,400.0,0.97769511,0.82070225,8.1392632,396.29446,-9.2665606
178.8537,0.13838539,9.3518467,18.54545,0,10.236759,400.0,0.97636056,0.69099069,8.6092558,396.2204,-9.2668581
178.8561,0.1440548,9.3544979,18.99806,0,10.695246,400.0,0.97630024,0.66971225,9.0800514,396.13373,-9.2672329
178.8585,0.23425582,9.3545351,19.450672,0,11.153732,400.0,0.97660369,1.1066377,9.5551615,396.04703,-9.2652884
178.8609,0.075516805,9.3575602,19.90328,0,11.612218,400.0,0.97820884,0.37431037,10.023964,395.96033,-9.2656145
178.8633,0.20143235,9.3495388,20.039063,0,12.070705,400.0,0.97755378,0.95321751,10.505017,395.88376,-9.2657776
178.8657,0.09562403,9.3523436,20.039063,0,12.529191,400.0,0.97736299,0.48257819,10.985533,395.81149,-9.2657528
178.8681,0.095698424,9.3490877,20.039063,0,12.987678,400.0,0.97565544,0.41787091,11.454847,395.73926,-9.2642908
178.8705,0.11636444,9.35818,20.039063,0,13.446164,400.0,0.97660726,0.57739496,11.912041,395.66702,-9.2643251
178.8729,0.13433436,9.358182,20.25596,0,13.904651,400.0,0.97732651,0.62958258,12.357237,395.59854,-9.2641993
178.8753,0.1042993,9.3530817,20.6691,0,14.363137,400.0,0.97761863,0.49874982,12.811528,395.53354,-9.2643051
178.8777,0.087261796,9.3502722,21.082239,0,14.821624,400.0,0.97752428,0.38512674,13.284801,395.46851,-9.2643785
178.8801,0.13246593,9.3492317,21.495377,0,15.28011,400.0,0.97643459,0.68645054,13.766763,395.40347,-9.263545
178.8825,0.033976164,9.3513641,21.763916,0,15.738596,400.0,0.97583365,0.14831501,14.241888,395.3511,-9.2643328
178.8849,0.14793698,9.351428,21.763916,0,16.197083,400.0,0.97585887,0.68441176,14.721987,395.32217,-9.2648516
178.8873,0.0067152553,9.3466043,21.763916,0,16.655569,400.0,0.97591645,0.070173718,15.185065,395.29327,-9.2642508
178.8897,0.063271798,9.3475294,21.763916,0,17.114056,400.0,0.97701681,0.30897155,15.637276,395.26437,-9.2646074
178.8921,0.058891013,9.3497601,21.763916,0,17.572542,400.0,0.97715467,0.28200483,16.09239,395.24329,-9.2637253
178.8945,0.095630117,9.351449,21.763916,0,17.999401,400.0,0.97631943,0.48056984,16.553391,395.259,-9.2639008
178.8969,0.059739247,9.3565302,21.763916,0,18.0,400.0,0.97623986,0.25575531,17.005262,395.27469,-9.2650232
178.8993,0.10275489,9.3572617,21.763916,0,18.0,400.0,0.97696537,0.47626501,17.445662,395.29041,-9.2644377
178.9017,0.12076668,9.3537407,21.763916,0,18.0,400.0,0.9777202,0.56249332,17.834578,395.27679,-9.2654896
178.9041,0.28356436,9.3512564,21.763916,0,18.0,400.0,0.977759,1.3466785,18.166983,395.20453,-9.2664604
178.9065,0.40618333,9.3532133,21.763916,0,18.0,400.0,0.97722113,1.9679462,18.411995,395.13229,-9.2699251
178.9089,0.59481174,9.3586264,21.763916,0,18.0,400.0,0.97739774,2.801012,18.534159,395.06006,-9.2736683
178.9113,0.58929902,9.3637562,21.879744,0,18.0,400.0,0.97794074,2.8460999,18.529533,394.98209,-9.2818489
178.9137,0.56349516,9.3638039,22.611288,0,18.0,400.0,0.97861946,2.7005734,18.413385,394.87372,-9.2896395
178.9161,0.60628909,9.3585253,23.342833,0,18.0,400.0,0.97880924,2.9276338,18.263914,394.76535,-9.3026323
178.9185,0.54872555,9.3599892,24.074379,0,18.0,400.0,0.97910964,2.6323237,18.135521,394.65698,-9.3193655
178.9209,0.60231161,9.359396,24.805922,0,18.0,400.0,0.97800493,2.8680272,18.059235,394.54861,-9.3386583
178.9233,0.52049261,9.361208,24.818115,0,18.0,400.0,0.97731805,2.4931974,18.041016,394.47577,-9.3582516
178.9257,0.53061271,9.3613672,24.818115,0,18.0,400.0,0.97748554,2.5706277,18.045038,394.40353,-9.3802996
178.9281,0.54651296,9.3534479,24.818115,0,18.0,400.0,0.97728729,2.5840693,18.061064,394.33127,-9.4002151
178.9305,0.59257025,9.3543949,24.818115,0,18.0,400.0,0.97829294,2.8525057,18.091444,394.25903,-9.4212637
178.9329,0.53167993,9.3527117,25.084002,0,18.0,400.0,0.97743386,2.5551662,18.117855,394.17508,-9.4405403
178.9353,0.55460757,9.3524055,25.412935,0,18.0,400.0,0.97651857,2.6422131,18.132673,394.08838,-9.4573412
178.9377,0.57635486,9.3581572,25.741867,0,18.0,400.0,0.97705317,2.7637882,18.141087,394.00168,-9.4727392
178.9401,0.59664863,9.3604078,26.070799,0,18.0,400.0,0.9778744,2.8448806,18.148705,393.91498,-9.4909992
178.9425,0.58053184,9.3560171,26.191408,0,18.0,400.0,0.9780131,2.7839375,18.149281,393.8237,-9.5100384
178.9449,0.55221015,9.351119,26.191408,0,18.0,400.0,0.97769862,2.6601048,18.14485,393.7298,-9.5268431
178.9473,0.51069444,9.349124,26.191408,0,18.0,400.0,0.97653079,2.4116933,18.141363,393.63586,-9.5435019
178.9497,0.60757595,9.3577652,26.191408,0,18.0,400.0,0.97689641,2.8669767,18.136038,393.54196,-9.5608492
178.9521,0.6045121,9.3602648,26.462776,0,18.0,400.0,0.976987,2.8941157,18.135614,393.45798,-9.5792942
178.9545,0.59227669,9.3604364,27.054853,0,18.0,400.0,0.9781453,2.8504281,18.132565,393.38574,-9.5969324
178.9569,0.65493006,9.3560734,27.646929,0,18.0,400.0,0.97844398,3.1074967,18.127275,393.31348,-9.6146717
178.9593,0.56202579,9.3529873,28.239008,0,18.0,400.0,0.97796911,2.6727626,18.129333,393.24124,-9.6311607
178.9617,0.61661774,9.3538513,28.66333,0,18.0,400.0,0.97705317,2.9487236,18.123678,393.16489,-9.6490078
178.9641,0.60770142,9.3584175,28.66333,0,18.0,400.0,0.97699654,2.9113159,18.120949,393.07819,-9.6674604
178.9665,0.55950451,9.3574219,28.66333,0,18.0,400.0,0.97716385,2.7639754,18.122068,392.99149,-9.685462
178.9689,0.59442943,9.355792,28.66333,0,18.0,400.0,0.97781461,2.8519588,18.122208,392.90475,-9.7030039
178.9713,0.60997337,9.3541765,28.720629,0,18.0,400.0,0.97822982,2.9034243,18.11619,392.81494,-9.7210293
178.9737,0.62309176,9.3541365,29.249552,0,18.0,400.0,0.97759706,2.9582307,18.115168,392.69934,-9.7387781
178.9761,0.59082651,9.3566303,29.778475,0,18.0,400.0,0.97707003,2.8895836,18.112665,392.58374,-9.7585897
178.9785,0.52592689,9.3677635,30.307398,0,18.0,400.0,0.97806561,2.4965096,18.112947,392.46814,-9.7756119
178.9809,0.58356225,9.3604355,30.836321,0,18.0,400.0,0.97778708,2.7603264,18.1075,392.35257,-9.7935658
178.9833,0.61251694,9.3544626,30.871582,0,18.0,400.0,0.97811413,2.9422612,18.112337,392.2774,-9.8101234
178.9857,0.61850357,9.3524218,30.871582,0,18.0,400.0,0.97784895,2.980629,18.110285,392.20517,-9.8269224
178.9881,0.5844233,9.3499603,30.871582,0,18.0,400.0,0.97642154,2.8158715,18.110929,392.13293,-9.8448057
178.9905,0.60098928,9.3555145,30.871582,0,18.0,400.0,0.97651011,2.8871644,18.106192,392.06067,-9.8620596
178.9929,0.60389048,9.3571148,31.05517,0,18.0,400.0,0.97692877,2.8956053,18.107485,391.97748,-9.8798847
178.9953,0.63390321,9.357688,31.297262,0,18.0,400.0,0.97799528,3.0491197,18.107302,391.89078,-9.8977842
178.9977,0.62523824,9.3555822,31.539358,0,18.0,400.0,0.97835654,2.9932702,18.10059,391.80408,-9.9158525
179.0001,0.57589376,9.35495,31.781454,0,18.0,400.0,0.97811651,2.758534,18.101791,391.71741,-9.9339466
179.0025,0.59114194,9.3547611,31.882326,0,18.0,400.0,0.97680682,2.843457,18.101324,391.6012,-9.9503403
179.0049,0.63201666,9.3600035,31.882326,0,18.0,400.0,0.97686917,2.9881041,18.099407,391.46393,-9.9688606
179.0073,0.59880137,9.3557196,31.882326,0,18.0,400.0,0.97668433,2.8543155,18.099611,391.32666,-9.9881229
179.0097,0.60847694,9.3585968,31.882326,0,18.0,400.0,0.97849631,2.9315073,18.103416,391.18936,-10.006409
179.0121,0.58391434,9.3540936,32.067142,0,18.0,400.0,0.97836757,2.8334007,18.102955,391.06094,-10.024064
179.0145,0.61416924,9.3556595,32.519749,0,18.0,400.0,0.97775286,2.9111876,18.099907,390.94537,-10.039215
179.0169,0.76432669,9.3599386,32.972363,0,18.0,400.0,0.97737944,3.6697981,18.095884,390.82977,-10.055975
179.0193,0.62153441,9.36411,33.424973,0,18.0,400.0,0.97807789,2.9671409,18.094736,390.71417,-10.075072
179.0217,0.60501415,9.3596754,33.771973,0,18.0,400.0,0.97813451,2.9032762,18.09654,390.60699,-10.093577
179.0241,0.60994035,9.3546324,33.771973,0,18.0,400.0,0.97796208,2.9045265,18.096092,390.52753,-10.11215
179.0265,0.56297392,9.348567,33.771973,0,18.0,400.0,0.97695518,2.732269,18.096928,390.44806,-10.128162
179.0289,0.69238579,9.3553295,33.771973,0,18.0,400.0,0.97739089,3.3391249,18.095354,390.36856,-10.145883
179.0313,0.63463807,9.3628111,33.796074,0,18.0,400.0,0.97760403,3.0750461,18.093851,390.28741,-10.163973
179.0337,0.62163067,9.3644791,34.209209,0,18.0,400.0,0.97816056,2.9494231,18.095039,390.17905,-10.18191
179.0361,0.59994799,9.3584728,34.622349,0,18.0,400.0,0.97816581,2.8634276,18.088327,390.07068,-10.198018
179.0385,0.62267649,9.3603039,35.035488,0,18.0,400.0,0.97929829,3.014801,18.089415,389.96228,-10.217673
179.0409,0.64701039,9.3537416,35.448627,0,18.0,400.0,0.97773755,3.1112986,18.089096,389.85391,-10.234815
179.0433,0.62595052,9.3556938,35.49683,0,18.0,400.0,0.97702885,2.999198,18.087076,389.75192,-10.253034
179.0457,0.60635138,9.3579264,35.49683,0,18.0,400.0,0.97693199,2.9007685,18.089392,389.65079,-10.270208
179.0481,0.6753006,9.3563213,35.49683,0,18.0,400.0,0.9769119,3.2061238,18.087902,389.54965,-10.28686
179.0505,0.67583895,9.3581896,35.49683,0,18.0,400.0,0.9783569,3.258199,18.085295,389.44852,-10.305357
179.0529,0.64551634,9.3569136,35.767097,0,18.0,400.0,0.97871858,3.1196649,18.082499,389.35757,-10.323953
179.0553,0.61600906,9.3567305,36.148659,0,18.0,400.0,0.97777271,2.962831,18.079922,389.27087,-10.342399
179.0577,0.64134336,9.3607979,36.53022,0,18.0,400.0,0.97727996,3.0570488,18.082287,389.18417,-10.360922
179.0601,0.67057091,9.3658152,36.911781,0,18.0,400.0,0.97808218,3.1835036,18.080879,389.09747,-10.378061
179.0625,0.66940504,9.3625383,37.089844,0,18.0,400.0,0.97842777,3.2035747,18.079504,388.99921,-10.394407
179.0649,0.62438172,9.356348,37.089844,0,18.0,400.0,0.97849935,3.0197086,18.078375,388.89084,-10.413492
179.0673,0.58344543,9.3442421,37.089844,0,18.0,400.0,0.97645265,2.7626758,18.080524,388.78247,-10.429914
179.0697,0.69327325,9.3559046,37.089844,0,18.0,400.0,0.97732234,3.2626321,18.078789,388.6741,-10.447714
179.0721,0.68319422,9.3592443,37.215252,0,18.0,400.0,0.97712785,3.3112416,18.078901,388.56573,-10.46547
179.0745,0.65513504,9.3607664,37.565239,0,18.0,400.0,0.97785884,3.1596839,18.078604,388.45734,-10.483249
179.0769,0.73511875,9.3595524,37.915222,0,18.0,400.0,0.97856814,3.5517371,18.078539,388.34897,-10.502151
179.0793,0.61962849,9.3576241,38.265205,0,18.0,400.0,0.97880119,2.9356029,18.078941,388.2406,-10.51894
179.0817,0.68237412,9.3548851,38.551025,0,18.0,400.0,0.9778769,3.2500834,18.076706,388.13354,-10.535955
179.0841,0.68434221,9.3618126,38.551025,0,18.0,400.0,0.97779822,3.2683728,18.076433,388.03241,-10.554965
179.0865,0.53128201,9.3635607,38.551025,0,18.0,400.0,0.97745502,2.5444152,18.078726,387.93127,-10.572535
179.0889,0.6874525,9.3627644,38.551025,0,18.0,400.0,0.97823107,3.2963567,18.076721,387.83014,-10.590465
179.0913,0.67845553,9.3590012,38.553764,0,18.0,400.0,0.97880381,3.2644522,18.076862,387.72891,-10.608594
179.0937,0.69758326,9.3548594,38.882698,0,18.0,400.0,0.9783088,3.4230921,18.076778,387.62057,-10.625024
179.0961,0.68982977,9.3564453,39.211632,0,18.0,400.0,0.97765583,3.2465951,18.070627,387.51221,-10.64251
179.0985,0.57946146,9.3635893,39.540562,0,18.0,400.0,0.97783911,2.8054898,18.069914,387.40384,-10.660707
179.1009,0.66777992,9.3631668,39.869495,0,18.0,400.0,0.97815061,3.1580966,18.075125,387.29547,-10.678822
179.1033,0.71004331,9.3614216,39.924316,0,18.0,400.0,0.97855049,3.3655188,18.070698,387.19913,-10.69728
179.1057,0.716856,9.356616,39.924316,0,18.0,400.0,0.97858965,3.4321272,18.067013,387.10519,-10.713761
179.1081,0.6657455,9.3489695,39.924316,0,18.0,400.0,0.97689933,3.179889,18.065388,387.01126,-10.731839
179.1105,0.66974664,9.3571968,39.924316,0,18.0,400.0,0.97723281,3.2106826,18.068733,386.91736,-10.749689
179.1129,0.6934858,9.3636875,40.125271,0,18.0,400.0,0.97754461,3.3082688,18.063007,386.79965,-10.766911
179.1153,0.72013581,9.3654242,40.430519,0,18.0,400.0,0.97851264,3.4666462,18.065372,386.66959,-10.786046
179.1177,0.66760045,9.3616238,40.735771,0,18.0,400.0,0.97896433,3.2396207,18.065228,386.53955,-10.804184
179.1201,0.66011095,9.3594961,41.041019,0,18.0,400.0,0.97935683,3.1465559,18.067406,386.40952,-10.820309
179.1225,0.66500074,9.3555717,41.19873,0,18.0,400.0,0.97766519,3.1651549,18.065252,386.28995,-10.837262
179.1249,0.71999931,9.35888,41.19873,0,18.0,400.0,0.97732139,3.4236321,18.068426,386.18155,-10.855146
179.1273,0.65274209,9.352046,41.19873,0,18.0,400.0,0.97586817,3.1414154,18.068689,386.07318,-10.873048
179.1297,0.70683712,9.3616142,41.19873,0,18.0,400.0,0.97832763,3.4094026,18.062094,385.96481,-10.889793
179.1321,0.65991199,9.3568993,41.243359,0,18.0,400.0,0.97866982,3.1485407,18.063276,385.87204,-10.908284
179.1345,0.70357138,9.3562155,41.388084,0,18.0,400.0,0.97838265,3.3401084,18.064909,385.81424,-10.927579
179.1369,0.82383651,9.3597822,41.532818,0,18.0,400.0,0.97787422,3.9627044,18.067799,385.75644,-10.945662
179.1393,0.65932077,9.3686953,41.677544,0,18.0,400.0,0.97868001,3.1612916,18.061171,385.69864,-10.964373
179.1417,0.65890241,9.3661509,41.802979,0,18.0,400.0,0.97836465,3.1868443,18.062397,385.63699,-10.981475
179.1441,0.67731816,9.35993,41.802979,0,18.0,400.0,0.9784925,3.2502148,18.062286,385.55029,-10.998021
179.1465,0.61031401,9.3527193,41.802979,0,18.0,400.0,0.97794169,2.9366765,18.061132,385.46359,-11.014863
179.1489,0.77066517,9.3559437,41.802979,0,18.0,400.0,0.9779911,3.7185597,18.061871,385.37689,-11.033088
179.1513,0.69011974,9.3566198,41.802979,0,18.0,400.0,0.97709012,3.3340273,18.060863,385.29019,-11.051094
179.1537,0.66682953,9.3580666,42.072811,0,18.0,400.0,0.97698641,3.2354832,18.057884,385.20349,-11.068244
179.1561,0.79873413,9.3601971,42.354374,0,18.0,400.0,0.97774255,3.7020597,18.055567,385.11679,-11.086651
179.1585,0.66910934,9.3639355,42.635944,0,18.0,400.0,0.97952551,3.2223098,18.056572,385.03012,-11.103731
179.1609,0.70569545,9.3588457,42.917507,0,18.0,400.0,0.97903919,3.4200225,18.059677,384.94342,-11.121442
179.1633,0.670874,9.3563585,42.978516,0,18.0,400.0,0.977732,3.2671645,18.05687,384.85672,-11.139245
179.1657,0.74185306,9.3600264,42.978516,0,18.0,400.0,0.97733951,3.49596,18.054855,384.77002,-11.157712
179.1681,0.73928231,9.3589792,42.978516,0,18.0,400.0,0.97669327,3.492846,18.056253,384.68332,-11.175312
179.1705,0.75180501,9.3614378,42.978516,0,18.0,400.0,0.97848439,3.6475792,18.057379,384.59665,-11.195512
179.1729,0.69598514,9.3592577,43.138596,0,18.0,400.0,0.97887874,3.3452411,18.05345,384.49237,-11.211905
179.1753,0.6930517,9.3564043,43.401741,0,18.0,400.0,0.97855562,3.3046963,18.054029,384.37677,-11.228638
179.1777,0.7006619,9.3556547,43.664883,0,18.0,400.0,0.97723687,3.3795207,18.051022,384.26117,-11.247391
179.1801,0.7449286,9.3648796,43.928032,0,18.0,400.0,0.97800875,3.5839972,18.055874,384.14557,-11.265463
179.1825,0.72105002,9.362546,44.077148,0,18.0,400.0,0.97809637,3.4834244,18.052095,384.04877,-11.281423
179.1849,0.69380409,9.3596373,44.077148,0,18.0,400.0,0.97846431,3.3092887,18.050959,383.97653,-11.297748
179.1873,0.65488875,9.3442183,44.077148,0,18.0,400.0,0.97651732,3.1042864,18.054958,383.90427,-11.315117
179.1897,0.78853732,9.3567028,44.077148,0,18.0,400.0,0.97793466,3.806108,18.053093,383.83203,-11.333082
179.1921,0.75453776,9.3622742,41.349854,0,18.0,400.0,0.97777593,3.6207945,18.050222,383.75232,-11.352453
179.2942,0.72514516,9.3586473,0.0,0,18.0,17.344154,0.97802395,3.473814,18.038799,380.98242,-11.469779
180.4942,0.65613836,9.3662195,0.0,0,18.0,7.588628e-16,0.97934121,3.1376128,18.000406,339.33179,-11.481985
181.6942,0.59209567,9.3687649,0.0,0,18.0,3.2805517000000004e-32,0.97982293,2.831516,17.999092,312.47357,-11.481607
182.8942,0.5362668,9.3708534,0.0,0,18.0,1.4012985e-45,0.98015457,2.5644369,17.99995,294.3313,-11.482384
184.0942,0.54886079,9.3757524,0.0,0,18.0,1.4012985e-45,0.9809978,2.6179731,17.999758,279.83228,-11.482213
185.2942,0.5586924,9.3804665,0.0,0,18.0,1.4012985e-45,0.98185563,2.6631444,17.999866,267.99457,-11.482611
186.4942,0.56047744,9.3852415,0.0,0,18.0,1.4012985e-45,0.98262453,2.6715009,18.00033,257.7533,-11.482199
187.6942,0.56534201,9.3887062,0.0,0,18.0,1.4012985e-45,0.98325634,2.6920314,18.00012,248.56412,-11.482246
188.8942,0.57354522,9.3932962,0.0,0,18.0,1.4012985e-45,0.984047,2.7306781,17.998983,240.07912,-11.481895
190.0942,0.57451111,9.3975706,0.0,0,18.0,1.4012985e-45,0.98478895,2.7315724,18.00074,232.04703,-11.482238
191.2942,0.58229387,9.4013548,0.0,0,18.0,1.4012985e-45,0.98544168,2.7667484,18.00103,224.68062,-11.482133
192.4942,0.58342212,9.4046764,0.0,0,18.0,1.4012985e-45,0.98606271,2.7700026,18.00057,217.54999,-11.482618
193.6942,0.58915883,9.4091234,0.0,0,18.0,1.4012985e-45,0.98675662,2.7955403,18.001167,210.90779,-11.482389
194.8942,0.59049636,9.4121675,0.0,0,18.0,1.4012985e-45,0.98745573,2.8030109,18.000504,204.634,-11.482123
196.0942,0.59289026,9.4158468,0.0,0,18.0,1.4012985e-45,0.98798043,2.8063428,18.000902,198.74275,-11.482235
197.2942,0.6005289,9.4186049,0.0,0,18.0,1.4012985e-45,0.98861885,2.8437912,18.000647,193.00786,-11.482229
198.4942,0.60120559,9.4218168,0.0,0,18.0,1.4012985e-45,0.98908311,2.8481023,18.000641,187.57666,-11.482391
199.6942,0.6049909,9.4248772,0.0,0,18.0,1.4012985e-45,0.98977757,2.8621917,18.000669,182.24069,-11.482065
200.8942,0.60748005,9.4278784,0.0,0,18.0,1.4012985e-45,0.99020255,2.8765464,17.999819,177.24344,-11.482391
202.0942,0.61370683,9.4302874,0.0,0,18.0,1.4012985e-45,0.99079174,2.8983958,18.000294,172.36719,-11.482088
203.2942,0.62182045,9.4334974,0.0,0,18.0,1.4012985e-45,0.99123657,2.9429195,18.000216,167.81982,-11.4825
204.4942,0.61628687,9.4363489,0.0,0,18.0,1.4012985e-45,0.99190789,2.9102778,17.999912,163.35158,-11.482182
205.6942,0.6241163,9.4386406,0.0,0,18.0,1.4012985e-45,0.99218512,2.9476883,17.999722,158.89621,-11.482133
206.8942,0.62314594,9.4414024,0.0,0,18.0,1.4012985e-45,0.99285245,2.9394622,17.999815,154.79401,-11.48229
208.0942,0.62680942,9.4434776,0.0,0,18.0,1.4012985e-45,0.99310756,2.9529958,18.000078,150.82225,-11.482056
209.2942,0.63221753,9.4464817,0.0,0,18.0,1.4012985e-45,0.9937284,2.9810722,18.000219,146.9662,-11.48203
210.4942,0.63057321,9.4487619,0.0,0,18.0,1.4012985e-45,0.99409312,2.9648232,17.9991,143.1515,-11.481913
211.6942,0.63258237,9.4514093,0.0,0,18.0,1.4012985e-45,0.99459273,2.9829314,17.999266,139.41029,-11.48193
212.8942,0.62961936,9.4539919,0.0,0,18.0,1.4012985e-45,0.99504918,2.9625287,17.999634,135.75145,-11.481992
214.0942,0.63921869,9.4559174,0.0,0,18.0,1.4012985e-45,0.99533671,3.0043139,17.999245,132.31815,-11.482286
215.2942,0.63162869,9.4581366,0.0,0,18.0,1.4012985e-45,0.99577647,2.9692833,17.999256,128.97272,-11.482074
216.4942,0.63538998,9.4604759,0.0,0,18.0,1.4012985e-45,0.99613011,2.9861796,17.999872,125.61533,-11.482138
217.6942,0.63989496,9.462389,0.0,0,18.0,1.4012985e-45,0.99648029,3.0081251,18.000156,122.55474,-11.482379
218.8942,0.63344854,9.4644585,0.0,0,18.0,1.4012985e-45,0.99681407,2.9798086,18.000214,119.43131,-11.482257
220.0942,0.64281368,9.4666395,0.0,0,18.0,1.4012985e-45,0.99723852,3.0218027,18.000278,116.50885,-11.482443
221.2942,0.64827329,9.4684668,0.0,0,18.0,1.4012985e-45,0.99752963,3.0480466,18.000389,113.60855,-11.482662
222.4942,0.64102668,9.4705572,0.0,0,18.0,1.4012985e-45,0.99790567,3.0071526,18.000832,110.82588,-11.482512
223.6942,0.6434496,9.4726934,0.0,0,18.0,1.4012985e-45,0.99823427,3.0198011,18.000774,108.05705,-11.482714
224.8942,0.63887542,9.4736881,0.0,0,18.0,1.4012985e-45,0.99850994,2.9988379,18.00004,105.40878,-11.482344
226.0942,0.64999509,9.4760666,0.0,0,18.0,1.4012985e-45,0.99883914,3.0506372,17.999725,102.79158,-11.482433
227.2942,0.64348018,9.4771214,0.0,0,18.0,1.4012985e-45,0.99917525,3.019779,18.000546,100.35503,-11.482346
228.4942,0.64645052,9.4791851,0.0,0,18.0,1.4012985e-45,0.99941897,3.0290973,18.000046,97.926826,-11.482512
229.6942,0.65220153,9.4807215,0.0,0,18.0,1.4012985e-45,0.99989969,3.0559323,18.00119,95.558434,-11.48246
230.8942,0.64744288,9.4822206,0.0,0,18.0,1.4012985e-45,1.0000148,3.0269427,18.001339,93.363235,-11.482417
232.0942,0.65119272,9.48353,0.0,0,18.0,1.4012985e-45,1.0004383,3.0481186,17.999405,91.072449,-11.482258
233.2942,0.64769119,9.4855766,0.0,0,18.0,1.4012985e-45,1.0007019,3.03758,17.99996,88.956978,-11.482197
234.4942,0.65686488,9.4867249,0.0,0,18.0,1.4012985e-45,1.0010014,3.0702467,18.000446,86.854515,-11.482548
235.6942,0.65166408,9.4885006,0.0,0,18.0,1.4012985e-45,1.001289,3.0529828,18.000648,84.851349,-11.482084
236.8942,0.65536827,9.4901276,0.0,0,18.0,1.4012985e-45,1.001598,3.0629151,18.000029,82.868202,-11.48199
238.0942,0.6535694,9.491127,0.0,0,18.0,1.4012985e-45,1.0017664,3.0566931,17.999893,80.88372,-11.48226
239.1942,0.65774941,9.4926386,0.0,0,18.0,1.4012985e-45,1.0019653,3.0719204,17.999861,79.240776,-11.482273