File: raw data/testID_0223.csv
Time(sec),Force(kN),Jaw(mm),PowAngle(deg),Power(W),Pram,PTemp,Strain,Stress(MPa),Stroke(mm),TC1(C),wedge(mm)
0.0,0.28512785,-9.9439964,0.0,0,11.076097,0.00034632496,-0.50856972,6.0115266,11.076118,23.121416,-9.1205454
1.2,0.25584486,-0.0015951651,0.0,0,11.076097,3.5158744,-6.8257592e-05,3.270205,11.075914,23.121164,-9.4872675
2.4,0.2266117,-0.0015306583,0.0,0,11.076097,7.1158748,-0.00011173046,2.8879611,11.075839,23.171171,-9.4833727
3.6,0.21836603,-0.0016012507,0.0,0,11.076097,10.715878,-7.992077e-05,2.7773707,11.076385,23.122301,-9.4832506
4.8,0.20383094,-0.0018145844,0.0,0,11.076097,14.315877,-0.00015039169,2.6021926,11.076359,23.109869,-9.4810152
6.0,0.18493883,-0.0017774813,0.0,0,11.076097,17.915873,-0.00014096101,2.3488388,11.076045,23.142815,-9.478632
7.2,0.17394315,-0.0023100171,0.0,0,11.076097,21.515875,-0.00016432795,2.2192929,11.076241,23.153715,-9.4764643
8.4,0.15969069,-0.0020218669,10.883815,0,11.076097,25.115877,-0.00011653473,2.0326262,11.075717,23.090109,-9.4740639
9.6,0.16098508,-0.0022391491,29.328154,0,11.076097,28.715879,-0.00011194347,2.0557706,11.076068,23.196367,-9.4717894
10.8,0.16679417,-0.0031530599,40.071178,0,11.076097,32.315876,-0.00022465741,2.1255176,11.076592,23.84071,-9.4701262
12.0,0.18350834,-0.0060778214,47.158134,0,11.076097,35.915878,-0.00038342096,2.3442268,11.076172,25.429396,-9.4685411
13.2,0.19668493,-0.010261473,52.025276,0,11.076097,39.515881,-0.0007145225,2.5086846,11.076152,28.20241,-9.4667006
14.4,0.21501231,-0.015654132,55.035721,0,11.076097,43.115883,-0.0010528215,2.7297604,11.076434,32.430622,-9.4645433
15.6,0.22956212,-0.020877717,56.984943,0,11.076097,46.715885,-0.0013825169,2.9214125,11.076398,37.363567,-9.4623003
16.8,0.25834492,-0.027674614,58.067272,0,11.076097,50.315887,-0.0018252501,3.302341,11.076201,43.022827,-9.4601631
18.0,0.27514279,-0.033006813,58.215347,0,11.076097,53.915886,-0.0021751695,3.5101104,11.075906,49.132351,-9.4582062
19.2,0.28742787,-0.03710077,57.810066,0,11.076097,57.515888,-0.0025116429,3.6805685,11.076046,55.218506,-9.4557867
20.4,0.34328911,-0.041257627,56.712151,0,11.076097,61.115891,-0.0027651722,4.3794737,11.07634,61.284824,-9.4540329
21.6,0.45364791,-0.044257805,54.994473,0,11.076097,64.715874,-0.0029605043,5.7998276,11.076169,67.067551,-9.4522095
22.8,0.51592565,-0.047696263,52.978157,0,11.076097,68.315865,-0.0031626269,6.5892682,11.076144,72.392799,-9.4506159
24.0,0.58182883,-0.049997043,50.524055,0,11.076097,71.915871,-0.0032840373,7.4272871,11.075011,77.101601,-9.4481697
25.2,0.61875904,-0.051817894,48.126579,0,11.076097,75.515877,-0.0034817476,7.9026308,11.076171,81.099716,-9.446454
26.4,0.64223832,-0.053240303,46.110474,0,11.076097,79.115883,-0.0035479632,8.2019424,11.075771,84.277565,-9.4441919
27.6,0.62607491,-0.055270225,44.823883,0,11.076097,82.715874,-0.0036939399,8.0046911,11.075598,86.885559,-9.4422379
28.8,0.62659317,-0.055735562,44.932205,0,11.076097,86.315895,-0.0036866276,8.0127983,11.076342,88.880943,-9.4400377
30.0,0.61962634,-0.058514252,46.108341,0,11.076097,89.915871,-0.0038487359,7.9219308,11.075697,90.509125,-9.4379616
31.2,0.63456792,-0.059953358,47.954033,0,11.076097,93.515892,-0.0040249731,8.1091232,11.076147,92.257385,-9.436265
32.4,0.63221556,-0.063362874,50.040184,0,11.076097,97.115868,-0.0042200363,8.0851326,11.075329,94.303024,-9.4338531
33.6,0.64189833,-0.066638552,52.278671,0,11.076097,100.7159,-0.0044425284,8.2121754,11.075463,96.593193,-9.4313974
34.8,0.64686424,-0.071834408,54.247791,0,11.076097,104.31588,-0.0047520073,8.2726889,11.076668,99.57415,-9.4295588
36.0,0.65870452,-0.078410871,55.535,0,11.076097,107.9159,-0.005157602,8.4242182,11.07583,103.15591,-9.4274778
37.2,0.68085462,-0.081813805,56.698067,0,11.076097,111.51588,-0.0054778871,8.7246885,11.076431,107.10793,-9.4252167
38.4,0.67874229,-0.085952386,57.260738,0,11.076097,115.1159,-0.0057172105,8.6931858,11.075192,111.37951,-9.423049
39.6,0.68259478,-0.091466755,57.624287,0,11.076097,118.71588,-0.0060786596,8.7525101,11.076741,115.91481,-9.4209528
40.8,0.69348115,-0.096219026,57.810051,0,11.076097,122.3159,-0.0063802563,8.871666,11.076009,120.28102,-9.4188976
42.0,0.69335514,-0.1013104,57.810066,0,11.076097,125.91589,-0.0066967211,8.8908911,11.076998,124.60146,-9.4168253
43.2,0.70182639,-0.10554177,57.972763,0,11.076097,129.51599,-0.0070433035,9.0000362,11.076599,128.5945,-9.4152565
44.4,0.72302336,-0.11013107,57.968826,0,11.076097,133.11589,-0.0073263645,9.2784367,11.075518,132.55011,-9.4135981
45.6,0.72605783,-0.11594287,57.812389,0,11.076097,136.71587,-0.0076860003,9.3318186,11.076163,136.46634,-9.4115601
46.8,0.72962338,-0.11849776,57.810066,0,11.076097,140.3159,-0.0078804521,9.3843699,11.075544,140.22868,-9.4096279
48.0,0.72731823,-0.12239627,57.810661,0,11.076097,143.91588,-0.0081167752,9.3250742,11.075223,143.79916,-9.4077606
49.2,0.73275548,-0.12639444,57.899406,0,11.076097,147.51588,-0.0084073935,9.4166536,11.075763,147.34357,-9.405695
50.4,0.73227024,-0.13102923,58.073719,0,11.076097,151.11588,-0.008678712,9.4080343,11.075672,150.82172,-9.4035273
51.6,0.73165828,-0.13533726,58.246098,0,11.076097,154.71587,-0.0089348378,9.3980455,11.07649,154.20905,-9.4013529
52.8,0.74096018,-0.13866115,58.472656,0,11.076097,158.31587,-0.0092389816,9.5324678,11.075045,157.59674,-9.3995676
54.0,0.73689848,-0.14304075,58.853752,0,11.076097,161.91589,-0.0095001776,9.4747944,11.076407,160.94508,-9.3970966
55.2,0.74414909,-0.14820457,59.224987,0,11.076097,165.51588,-0.0098142903,9.5714283,11.076441,164.2722,-9.3946171
56.4,0.75924689,-0.15294692,59.600826,0,11.076097,169.11588,-0.010161506,9.7477093,11.075912,167.69548,-9.3927507
57.6,0.7580198,-0.15569675,60.084122,0,11.076097,172.71588,-0.010328777,9.7593889,11.07615,171.16513,-9.3905096
58.8,0.75901866,-0.15961497,60.384548,0,11.076097,176.31587,-0.010596068,9.7603703,11.075359,174.75604,-9.3885937
60.0,0.75658965,-0.16477151,60.755749,0,11.076097,179.91588,-0.010903968,9.734477,11.076643,178.45686,-9.3865528
61.2,0.75607651,-0.16986451,60.89378,0,11.076097,183.51588,-0.011228435,9.734993,11.076358,182.26759,-9.3843193
62.4,0.76003236,-0.1745249,61.018063,0,11.076097,187.11588,-0.011596234,9.7769213,11.076095,186.11041,-9.3824959
63.6,0.75286716,-0.17935279,61.021225,0,11.076097,190.71587,-0.011876004,9.7086287,11.075856,189.91685,-9.3809309
64.8,0.75446087,-0.18406476,61.191658,0,11.076097,194.31587,-0.012152668,9.728487,11.0768,193.75439,-9.3793974
66.0,0.75549513,-0.1884833,61.018669,0,11.076097,197.91588,-0.012525858,9.7258148,11.075321,197.76758,-9.3772812
67.2,0.763843,-0.19230291,60.856632,0,11.076097,201.51588,-0.012748349,9.8412981,11.07492,201.6682,-9.3752108
68.4,0.76650608,-0.19743831,60.787361,0,11.076097,205.11589,-0.013046117,9.8950233,11.07668,205.36986,-9.373085
69.6,0.76803488,-0.20242448,60.787361,0,11.076097,208.71588,-0.013424428,9.9191771,11.075622,208.92946,-9.3709621
70.8,0.76503199,-0.20629285,60.787361,0,11.076097,212.31589,-0.01368212,9.8721666,11.076538,212.46524,-9.3687429
72.0,0.77006638,-0.21044528,60.787361,0,11.076097,215.91589,-0.013928421,9.957386,11.075129,215.91502,-9.3667068
73.2,0.76100355,-0.21327759,60.915615,0,11.076097,219.5159,-0.014135444,9.8279581,11.0769,219.33722,-9.3650532
74.4,0.76339281,-0.21625678,61.064953,0,11.076097,223.11589,-0.014331221,9.8647537,11.075925,222.65935,-9.3631477
75.6,0.76225716,-0.21985891,61.467518,0,11.076097,226.7159,-0.014553626,9.8443708,11.07644,225.90421,-9.3613558
76.8,0.76550382,-0.22391313,61.741524,0,11.076097,230.3159,-0.014820176,9.8866739,11.07554,229.11563,-9.3593559
78.0,0.76618522,-0.22846583,62.204842,0,11.076097,233.91589,-0.015106324,9.9038763,11.076594,232.3862,-9.3568535
79.2,0.75746232,-0.23328246,62.698616,0,11.076097,237.5159,-0.015435847,9.8037195,11.075151,235.66216,-9.3549709
80.4,0.76507074,-0.23780034,63.169544,0,11.076097,241.11589,-0.015719598,9.8787031,11.075872,239.13135,-9.3529711
81.6,0.76156008,-0.24251005,63.571331,0,11.076097,244.7159,-0.016021267,9.852087,11.075696,242.70775,-9.3506813
82.8,0.76515412,-0.24722286,63.870358,0,11.076097,248.3159,-0.016352976,9.8843946,11.075227,246.31555,-9.3485155
84.0,0.76460201,-0.25196359,64.170357,0,11.076097,251.91589,-0.016645655,9.9166784,11.076387,250.11537,-9.3468857
85.2,0.76363301,-0.2568289,64.311722,0,11.076097,255.5159,-0.016954042,9.9004545,11.076302,254.15039,-9.3453035
86.4,0.75880998,-0.26212731,64.357903,0,11.076097,259.11612,-0.017333016,9.8368635,11.075882,258.11749,-9.3432188
87.6,0.75559986,-0.26696852,64.357903,0,11.076097,262.71588,-0.017625323,9.7832298,11.076745,261.91632,-9.3411064
88.8,0.75939029,-0.27231863,64.357903,0,11.076097,266.31589,-0.017977804,9.8485794,11.074917,265.89386,-9.3390627
90.0,0.76279706,-0.27647826,64.357903,0,11.076097,269.91586,-0.018277656,9.8765745,11.076771,269.69653,-9.3373775
91.2,0.76428872,-0.28130186,64.430275,0,11.076097,273.51587,-0.01857459,9.898385,11.076357,273.22168,-9.3352556
92.4,0.76398313,-0.28623998,64.555283,0,11.076097,277.11588,-0.018887822,9.9067173,11.077911,276.71942,-9.3331337
93.6,0.77028537,-0.29204157,64.555656,0,11.076097,280.71588,-0.019282527,10.00132,11.075693,280.27234,-9.3308744
94.8,0.77194279,-0.29701278,64.742432,0,11.076097,284.31589,-0.019607352,10.020838,11.076388,283.6572,-9.3288269
96.0,0.7808665,-0.30115291,64.929192,0,11.076097,287.91589,-0.019888697,10.131954,11.075653,287.19287,-9.3269987
97.2,0.78121763,-0.30427486,65.11573,0,11.076097,291.51587,-0.020095725,10.145508,11.075933,290.72855,-9.3247089
98.4,0.77428305,-0.30733064,65.302643,0,11.076097,295.11588,-0.020301135,10.073355,11.076556,294.1947,-9.3226652
99.6,0.77749974,-0.31180725,65.526711,0,11.076097,298.71588,-0.020583384,10.115588,11.076384,297.59442,-9.3209343
100.8,0.77477396,-0.31681725,65.734138,0,11.076097,302.31586,-0.020889116,10.08641,11.076783,301.1496,-9.3190374
102.0,0.76040512,-0.32132873,65.985039,0,11.076097,305.91586,-0.02122293,9.8923645,11.075185,304.72974,-9.3168087
103.2,0.76667774,-0.32659018,66.190147,0,11.076097,309.51587,-0.021553013,9.9922819,11.076748,308.26215,-9.3150187
104.4,0.76761752,-0.33147112,66.368401,0,11.076097,313.11588,-0.021831751,9.9795885,11.075905,311.89905,-9.3128872
105.6,0.76108032,-0.33637279,66.368401,0,11.076097,316.71588,-0.022217218,9.8913336,11.075654,315.91681,-9.3112764
106.8,0.78122908,-0.34026885,66.544182,0,11.076097,320.31589,-0.022417838,10.177833,11.075646,319.40491,-9.3093596
108.0,0.78429776,-0.34763604,66.708977,0,11.076097,323.91586,-0.022870747,10.213798,11.075499,322.96887,-9.3071966
109.2,0.78169382,-0.34979865,66.884758,0,11.076097,327.51587,-0.023087412,10.179566,11.075844,326.52869,-9.3049803
110.4,0.77716357,-0.35316005,66.884758,0,11.076097,331.11588,-0.02325359,10.140546,11.07655,330.43237,-9.3032417
111.6,0.77789968,-0.35840094,66.884773,0,11.076097,334.71588,-0.023587238,10.145346,11.076539,334.25858,-9.3013115
112.8,0.77383697,-0.36320212,66.884773,0,11.076097,338.31592,-0.023935817,10.075023,11.075687,338.17764,-9.2989368
114.0,0.76839238,-0.36820999,67.019859,0,11.076097,341.91589,-0.024247365,10.03722,11.075501,341.59814,-9.2970924
115.2,0.76687449,-0.37252873,67.049561,0,11.076097,345.51593,-0.02453606,9.9938869,11.076546,345.13037,-9.2945118
116.4,0.7779851,-0.38023674,67.217781,0,11.076097,349.11591,-0.025019044,10.155871,11.075773,348.58499,-9.2927732
117.6,0.79207265,-0.38310003,67.225342,0,11.076097,352.71588,-0.025251124,10.339293,11.075836,352.29227,-9.2905254
118.8,0.78332585,-0.38645658,67.390129,0,11.076097,356.31592,-0.025456002,10.236407,11.076387,355.65604,-9.2885551
120.0,0.77619934,-0.39149737,67.554642,0,11.076097,359.91589,-0.025730068,10.133015,11.0769,359.13864,-9.2863407
121.2,0.773799,-0.39627969,67.708733,0,11.076097,363.51593,-0.026113808,10.114543,11.076167,362.44662,-9.2847395
122.4,0.77393544,-0.40154412,68.035332,0,11.076097,367.11591,-0.02640624,10.113054,11.075707,365.7684,-9.2830572
123.6,0.78039128,-0.4065873,68.356934,0,11.076097,370.71594,-0.026715655,10.186983,11.076188,368.98804,-9.281064
124.8,0.79123414,-0.41453072,68.664474,0,11.076097,374.31589,-0.027275566,10.353937,11.075751,372.41269,-9.279521
126.0,0.78683496,-0.41721058,68.97216,0,11.076097,377.91592,-0.027440125,10.309026,11.07563,375.92026,-9.2775173
127.2,0.78436834,-0.42210296,69.268333,0,11.076097,381.5159,-0.027756011,10.267683,11.07548,379.56635,-9.2756796
128.4,0.7784847,-0.42952606,69.422607,0,11.076097,385.11594,-0.028212948,10.205721,11.075494,383.37421,-9.2735367
129.6,0.77346402,-0.43515697,69.576416,0,11.076097,388.71591,-0.028633015,10.139435,11.075048,387.35764,-9.2714434
130.8,0.77389514,-0.44095588,69.558044,0,11.076097,392.31589,-0.028959641,10.131346,11.075891,391.64664,-9.2695913
132.0,0.79538137,-0.44981572,69.422615,0,11.076097,395.91586,-0.02952298,10.433405,11.077247,395.75873,-9.2672319
133.2,0.79265946,-0.4508805,69.268806,0,11.076097,399.5159,-0.029635843,10.402807,11.075995,399.81512,-9.2648754
134.4,0.78534406,-0.45730457,68.973045,0,11.076097,403.11588,-0.030027248,10.302296,11.075912,404.01865,-9.2634087
135.6,0.77217424,-0.46315655,68.664566,0,11.076097,406.71591,-0.030411085,10.137869,11.075418,408.12878,-9.260952
136.8,0.79116917,-0.46703431,68.19265,0,11.076097,410.31586,-0.030641899,10.369054,11.076863,412.50516,-9.2590685
138.0,0.79429483,-0.4740904,67.708755,0,11.076097,413.91589,-0.031157466,10.432613,11.076206,416.49316,-9.2568159
139.2,0.78815258,-0.47459802,67.390144,0,11.076097,417.5159,-0.031123593,10.348238,11.075784,419.9639,-9.254591
140.4,0.77650374,-0.48059303,67.054482,0,11.076097,421.11588,-0.031505894,10.210995,11.074951,423.28403,-9.2524366
141.6,0.76822644,-0.48519146,66.884773,0,11.076097,424.71588,-0.031843666,10.090404,11.076131,426.47394,-9.2507954
142.8,0.79521769,-0.4913483,66.884773,0,11.076097,428.31589,-0.032238878,10.457905,11.076244,429.54315,-9.2485666
144.0,0.79955745,-0.49124056,66.907906,0,11.076097,431.91589,-0.032248646,10.515144,11.07605,432.37317,-9.2467222
145.2,0.78528893,-0.49676889,67.278915,0,11.076097,435.51587,-0.032540854,10.337089,11.075917,435.01102,-9.244401
146.4,0.77427596,-0.50157291,67.554924,0,11.076097,439.11588,-0.032924201,10.21102,11.075614,438.2821,-9.2426481
147.6,0.80334538,-0.50773567,67.743423,0,11.076097,442.71588,-0.033256155,10.580765,11.07632,441.62509,-9.2405787
148.8,0.79906428,-0.50977641,67.888557,0,11.076097,446.31589,-0.033434775,10.53828,11.076331,445.25418,-9.2386751
150.0,0.78660172,-0.51514065,68.191597,0,11.076097,449.91553,-0.033750124,10.371888,11.076234,448.68411,-9.2367287
151.2,0.78105503,-0.51908046,67.04969,0,11.076097,449.9989,-0.034050342,10.30226,11.076694,451.97586,-9.2364416
152.4,0.7650494,-0.51974517,64.211365,0,11.076097,449.9989,-0.034061011,10.072637,11.075346,457.7193,-9.2366724
153.6,0.76549238,-0.52198404,60.717117,0,11.076097,449.9989,-0.034190122,10.08699,11.075795,461.28671,-9.2363873
154.8,0.74264663,-0.5145734,57.343079,0,11.076097,449.9989,-0.033720095,9.7724609,11.076303,462.39697,-9.2365704
156.0,0.70458347,-0.51095825,54.150127,0,11.076097,449.9989,-0.033523317,9.2942991,11.076333,462.00629,-9.2369108
157.2,0.67488366,-0.50669962,51.939976,0,11.076097,449.9989,-0.033213142,8.8959112,11.075514,459.90604,-9.2369547
158.4,0.64747143,-0.50276351,50.891106,0,11.076097,449.9989,-0.032933794,8.5296812,11.076535,457.36737,-9.2369976
159.6,0.65406954,-0.49875209,50.438236,0,11.076097,449.9989,-0.032700576,8.6073742,11.07547,455.02942,-9.2368431
160.8,0.64362866,-0.4943926,51.280827,0,11.076097,449.9989,-0.032463852,8.4714022,11.076468,452.26688,-9.2368269
162.0,0.64249104,-0.49197847,52.72834,0,11.076097,449.9989,-0.032260571,8.4433966,11.076389,449.73434,-9.2366495
163.2,0.63708162,-0.49217653,54.614159,0,11.076097,449.9989,-0.032252472,8.3806868,11.07611,447.61853,-9.2366199
164.4,0.64661747,-0.49268666,56.421158,0,11.076097,449.9989,-0.032328345,8.5064478,11.075366,446.00143,-9.2363358
165.6,0.64897799,-0.4935993,58.49551,0,11.076097,449.9989,-0.032399364,8.5466938,11.076643,444.3941,-9.2365961
166.8,0.69238573,-0.49943021,61.672974,0,11.076097,449.9989,-0.032741271,9.1065426,11.075516,441.31744,-9.2363214
168.0,0.73607403,-0.50392789,63.16748,0,11.076097,449.9989,-0.033021115,9.6746635,11.076591,441.82614,-9.2365913
169.2,0.75544262,-0.50562799,64.170685,0,11.076097,449.9989,-0.033162516,9.9392586,11.076137,442.94281,-9.23666
170.4,0.76993859,-0.51098508,64.555634,0,11.076097,449.9989,-0.033522446,10.145416,11.07638,444.94092,-9.23703
171.6,0.77033681,-0.51613891,64.357918,0,11.076097,449.9989,-0.033827867,10.156964,11.076289,447.13306,-9.2364626
172.8,0.77093148,-0.51923597,63.637878,0,11.076097,449.9989,-0.033998799,10.15011,11.075725,449.76642,-9.2363472
174.0,0.7687245,-0.52113879,62.553196,0,11.076097,449.9989,-0.034156591,10.14725,11.075568,451.88727,-9.2364035
175.2,0.77836549,-0.52090049,61.265102,0,11.076097,449.9989,-0.034169093,10.219671,11.074656,453.54245,-9.2360563
176.4,0.77855718,-0.52150983,59.410175,0,11.076097,449.9989,-0.034154065,10.256288,11.074794,455.41934,-9.236167
177.6,0.76491994,-0.52312642,57.538231,0,11.076097,449.9989,-0.034247555,10.07684,11.075425,456.41336,-9.2362032
178.8,0.74231803,-0.51958847,55.540245,0,11.076097,449.9989,-0.034065347,9.7733574,11.0759,456.77176,-9.2366037
180.0,0.72475678,-0.51498425,53.975906,0,11.076097,449.9989,-0.03379602,9.5443106,11.075897,456.1662,-9.2366333
181.2,0.69855118,-0.51107925,52.976555,0,11.076097,449.9989,-0.033495788,9.1986609,11.07611,455.06866,-9.236414
182.4,0.68256629,-0.50866902,52.283947,0,11.076097,449.9989,-0.033336747,8.9986,11.075756,453.92645,-9.2368193
183.6,0.67109358,-0.50584912,51.932377,0,11.076097,449.9989,-0.033151332,8.840704,11.07633,452.94861,-9.2365227
184.8,0.6512841,-0.50335044,51.569828,0,11.076097,449.9989,-0.033023659,8.5892906,11.076537,452.09509,-9.2367868
186.0,0.58335453,-0.5017916,51.19632,0,11.076097,449.9989,-0.032889124,7.6850238,11.075438,451.70871,-9.236165
187.2,0.47810662,-0.50139803,51.569721,0,11.076097,449.9989,-0.032888383,6.2841902,11.076227,450.83731,-9.2361021
188.4,0.37877861,-0.50076032,52.619678,0,11.076097,449.9989,-0.032801382,4.9848943,11.075868,449.2301,-9.2360897
189.6,0.30813268,-0.50041902,54.496895,0,11.076097,449.9989,-0.032835767,4.0501723,11.077161,447.24323,-9.236248
190.8,0.25817245,-0.50044322,56.873951,0,11.076097,449.9989,-0.032819901,3.3880351,11.075555,445.0141,-9.2362242
192.0,0.23276225,-0.50163436,59.571068,0,11.076097,449.9989,-0.032897323,3.0725141,11.076072,442.73871,-9.2366629
193.2,0.21535692,-0.50460976,62.029976,0,11.076097,449.9989,-0.033067744,2.8386633,11.075891,441.24026,-9.2360277
194.4,0.20756595,-0.50937653,63.960342,0,11.076097,449.9989,-0.033404965,2.7224793,11.075681,440.82248,-9.2359343
195.2803,0.16207044,0.015826249,13.634965,0,11.076099,74.114784,0.0012637301,2.0818782,11.07344,441.31512,-9.2355375
195.2827,0.17930439,0.010409219,0.0,0,11.076099,3.2041952e-15,0.00096596056,2.2601943,11.074451,441.30704,-9.2359943
195.2851,0.18751486,0.0097484766,0.0,0,11.076099,1.3851730000000002e-31,0.0006725844,2.337172,11.074101,441.29263,-9.2357168
195.2875,0.17022362,0.012514029,0.0,0,11.076099,0.0,0.00061190664,2.1506329,11.077546,441.27823,-9.2344713
195.2899,0.16174194,0.014452497,0.0,0,11.076099,0.0,0.00079129537,2.00457,11.074179,441.26382,-9.234992
195.2923,0.15417467,0.013333467,0.0,0,11.076099,0.0,0.00090594339,1.9949452,11.073362,441.24945,-9.2357225
195.2947,0.15124358,0.0098241791,0.0,0,11.076099,0.0,0.00081045134,1.8716196,11.073582,441.23505,-9.235219
195.2971,0.15245037,0.0091399709,0.0,0,11.076099,0.0,0.00076493068,1.9385581,11.077537,441.22064,-9.2352314
195.2995,0.16331561,0.012569731,0.0,0,11.076099,0.0,0.00077244808,2.0999794,11.073329,441.20624,-9.2357006
195.3019,0.14798309,0.015269482,0.0,0,11.076099,0.0,0.00073867908,1.9200515,11.073874,441.19183,-9.2343626
195.3043,0.14217187,0.016401861,0.0,0,11.076099,0.0,0.00088941329,1.906128,11.077169,441.21164,-9.2356901
195.3067,0.14448823,0.015551305,0.0,0,11.076099,0.0,0.0010902252,1.8985476,11.080591,441.24045,-9.2368402
195.3091,0.14884701,0.0115555,0.0,0,11.076099,0.0,0.0010679963,1.8414873,11.075424,441.26923,-9.2368526
195.3115,0.14445275,0.011227211,0.0,0,11.076099,0.0,0.00089119788,1.8181069,11.07934,441.29803,-9.2355471
195.3139,0.14565912,0.012704612,0.0,0,11.076099,0.0,0.00076666294,1.833129,11.076465,441.31784,-9.2351704
195.3163,0.14064436,0.014321395,0.0,0,11.076099,0.0,0.00074998068,1.7128848,11.077466,441.33221,-9.2364016
195.3187,0.14747608,0.013874996,0.0,0,11.076099,0.0,0.00082057476,1.9547727,11.075541,441.34662,-9.2370243
195.3211,0.15989451,0.011875135,0.0,0,11.076099,0.0,0.00096696324,1.9302708,11.077964,441.36102,-9.2368088
195.3235,0.14136848,0.012751545,0.0,0,11.076099,0.0,0.0011016345,1.8502358,11.073581,441.3688,-9.2369032
195.3259,0.14128876,0.012638731,0.0,0,11.076099,0.0,0.00091485085,1.7916324,11.07515,441.3688,-9.2365379
195.3283,0.1414672,0.015726358,0.0,0,11.076099,0.0,0.00078627293,1.7667723,11.075727,441.3688,-9.2364368
195.3307,0.15181126,0.018240785,0.0,0,11.006544,0.0,0.00094446761,1.9010785,11.075665,441.3688,-9.2365208
195.3331,0.14049324,0.018655891,0.0,0,10.645576,0.0,0.0011825955,1.8254095,11.072516,441.3685,-9.2351398
195.3355,0.13029036,0.015131453,0.0,0,10.284602,0.0,0.0012107401,1.670964,11.060525,441.3613,-9.2354755
195.3379,0.15716521,0.012051558,0.0,0,9.9236288,0.0,0.0010773859,2.0270257,10.948259,441.3541,-9.2357292
195.3403,0.12610647,0.012947965,0.0,0,9.5626545,0.0,0.00091194344,1.7535621,10.676567,441.34689,-9.2357225
195.3427,0.19143496,0.014417984,0.0,0,9.2092896,0.0,0.00075758947,2.3444076,10.29943,441.33969,-9.2360039
195.3451,3.6651831,0.4075847,0.0,0,8.8581219,0.0,0.026638845,45.536224,9.8431435,450.3291,-9.2326984
195.3475,4.4051857,0.86340916,0.0,0,8.518857,0.0,0.05867485,52.547596,9.3076105,460.60373,-9.2314644
195.3499,4.0400147,1.3298379,0.0,0,8.1848736,0.0,0.092733383,46.976715,8.8250866,470.87836,-9.2325563
195.3523,4.3799782,1.7238551,0.0,0,7.860775,0.0,0.12196571,49.211613,8.4341297,481.15295,-9.231946
195.3547,4.5088906,2.032006,0.0,0,7.543015,0.0,0.14490207,49.79063,8.1129522,491.95984,-9.2315197
195.3571,4.5746298,2.3158188,0.0,0,7.2334356,0.0,0.16685976,49.124737,7.8122582,502.9859,-9.2320518
195.3595,4.5418601,2.593776,0.0,0,6.9312272,0.0,0.18927872,47.846935,7.5334544,514.0119,-9.232028
195.3619,4.7726178,2.8627439,0.0,0,6.6355214,0.0,0.21157156,49.058678,7.2610726,525.03796,-9.2326984
195.3643,4.8666601,3.1383581,0.0,0,6.3480015,0.0,0.23472348,49.128204,6.9839468,530.3241,-9.2334986
195.3667,5.0284047,3.4166327,0.0,0,6.0655355,0.0,0.25819126,49.422596,6.6957397,530.75348,-9.23351
195.3691,5.1321588,3.7157149,0.0,0,5.792079,0.0,0.28398433,49.173901,6.4002395,531.1828,-9.2327795
195.3715,5.2888913,4.0102754,0.0,0,5.5222936,0.0,0.31031382,49.277393,6.1068745,531.61218,-9.2329493
195.3739,5.4564118,4.3026829,0.0,0,5.2621331,0.0,0.33754963,49.526413,5.81497,531.65509,-9.2323122
195.3763,5.5561242,4.5875144,0.0,0,5.0044241,0.0,0.3649604,49.084808,5.518959,531.05402,-9.2311726
195.3787,5.6635637,4.8675017,0.0,0,4.7569838,0.0,0.39223599,48.705162,5.2432275,530.45294,-9.2316132
195.3811,5.7948241,5.1374106,0.0,0,4.5108657,0.0,0.41889656,48.497913,4.9715652,529.85181,-9.2315636
195.3835,5.9353571,5.4006653,0.0,0,4.2754693,0.0,0.44547352,48.327106,4.7112422,528.75568,-9.2318115
195.3859,6.0677342,5.6508384,0.0,0,4.0404716,0.0,0.47167799,48.248062,4.4639955,525.77808,-9.2319069
195.3883,6.176054,5.8857884,0.0,0,3.8165052,0.0,0.49778596,47.812817,4.2238455,522.80054,-9.2332764
195.3907,6.3345175,6.1115189,0.0,0,3.5926332,0.0,0.52341402,47.723839,3.9921069,519.823,-9.2317657
195.3931,6.4995999,6.33394,0.0,0,3.3790326,0.0,0.54868478,47.711487,3.7700274,516.78424,-9.2320137
195.3955,6.6913152,6.558012,0.0,0,3.1660566,0.0,0.57432222,47.974632,3.5500665,512.33807,-9.2317848
195.3979,6.8852892,6.781023,0.0,0,2.9619904,0.0,0.6005829,48.061344,3.3353722,507.89194,-9.2325239
195.4003,7.0556426,6.9977279,0.0,0,2.7593822,0.0,0.62750375,48.003582,3.1179099,503.4458,-9.2319307
195.4027,7.2811952,7.2071853,0.0,0,2.5644472,0.0,0.65464586,48.13979,2.9036248,498.99966,-9.2311888
195.4051,7.546742,7.4130797,0.0,0,2.3717272,0.0,0.68185669,48.537235,2.6987975,497.42865,-9.2306519
195.4075,7.7854567,7.6165028,0.0,0,2.185524,0.0,0.70872056,48.792473,2.4930902,496.26837,-9.2309504
195.4099,8.0313568,7.8165078,0.0,0,2.002212,0.0,0.73539174,48.999577,2.2975831,495.10809,-9.2304716
195.4123,8.2893391,8.0130005,0.0,0,1.8243402,0.0,0.76259369,49.26931,2.1039875,493.94778,-9.2299061
195.4147,8.6016483,8.2023954,0.0,0,1.6499562,0.0,0.79046535,49.576653,1.9167728,490.72354,-9.2306957
195.4171,8.9459972,8.3824005,0.0,0,1.4800411,0.0,0.81849641,50.198509,1.7333782,486.64941,-9.2300978
195.4195,9.266223,8.5587673,0.0,0,1.3141533,0.0,0.84594733,50.593254,1.5596197,482.57532,-9.2302065
195.4219,9.6123571,8.7353802,0.0,0,1.1518563,0.0,0.8728646,51.085537,1.3797724,478.50122,-9.2302752
195.4243,9.9890003,8.9072628,0.0,0,0.99408025,0.0,0.89971972,51.681156,1.2122651,473.60294,-9.2290401
195.4267,10.418383,9.0746469,0.0,0,0.83908123,0.0,0.92743689,52.424465,1.0448543,468.00732,-9.2289343
195.4291,10.840262,9.2305355,0.0,0,0.68903327,0.0,0.95488477,53.096302,0.88636357,462.41171,-9.2286091
195.4315,11.294568,9.3804522,0.0,0,0.54098582,0.0,0.9823792,53.810135,0.73016846,456.8161,-9.2293091
195.4339,11.770233,9.533103,0.0,0,0.39818579,0.0,1.010038,54.537823,0.57528168,453.68765,-9.2291079
195.4363,9.4934359,9.5757837,0.0,0,0.25673616,0.0,1.0167464,43.798065,0.49218562,454.67108,-9.2305365
195.4387,8.2318106,9.5876303,0.0,0,0.12094405,0.0,1.0182744,37.952057,0.4450762,455.65451,-9.2303658
195.4411,7.740479,9.5924091,0.0,0,-0.014479336,0.0,1.019101,35.59042,0.41633177,456.63794,-9.2319679
195.4435,7.4990654,9.5935545,0.0,0,-0.14691253,0.0,1.0206898,34.420448,0.38717705,458.10449,-9.2324162
195.4459,7.5422211,9.5926657,0.0,0,-0.27934453,0.0,1.0214987,34.567299,0.34932697,461.4068,-9.2324524
195.4483,7.8270202,9.5959473,0.0,0,-0.41177651,0.0,1.0216463,35.86364,0.2869387,464.70908,-9.2317657
195.4507,7.9623609,9.6057606,0.0,0,-0.54420853,0.0,1.0223283,36.430931,0.21492083,468.01138,-9.232008
195.4531,7.9628215,9.6157761,0.0,0,-0.67664051,0.0,1.0234786,36.417759,0.15256865,471.27679,-9.2326117
195.4555,7.8315039,9.6222591,0.0,0,-0.80907249,0.0,1.0252131,35.808899,0.097570993,473.69379,-9.2322474
195.4579,7.6281676,9.6238365,0.0,0,-0.94150448,0.0,1.0265702,34.812088,0.05634699,476.11078,-9.2322636
195.4603,7.3347802,9.6235142,0.0,0,-1.0739366,0.0,1.0270357,33.473549,0.026209457,478.52777,-9.2325468
195.4627,6.9555283,9.6272221,0.0,0,-0.76691389,450.0,1.0270647,31.732649,0.018867353,480.94476,-9.2328377
195.4651,6.5679173,9.6314631,0.0,0,-0.30842754,450.0,1.0267613,29.992165,0.023499725,483.02164,-9.2340908
195.4675,6.2434154,9.6349831,0.0,0,0.15005881,450.0,1.0268731,28.50466,0.029559322,485.04996,-9.2327137
195.4699,6.0131111,9.6346598,0.0,0,0.60854518,450.0,1.02749,27.408703,0.032068275,487.07825,-9.2333841
195.4723,5.855011,9.6297226,0.0,0,1.0670315,450.0,1.0280724,26.686001,0.030258516,489.10654,-9.2340107
195.4747,5.5651922,9.6241646,0.0,0,1.5255178,450.0,1.0272788,25.416494,0.035216846,491.14944,-9.234067
195.4771,4.739059,9.6225729,0.0,0,1.9840043,450.0,1.025861,21.734575,0.08088994,493.19839,-9.2361765
195.4795,3.0714769,9.616046,0.0,0,2.4424911,450.0,1.0236557,14.225076,0.19291553,495.24731,-9.2359152
195.4819,0.48640084,9.5924931,0.0,0,2.9009774,450.0,1.019508,2.4012768,0.41761464,497.29626,-9.2366867
195.4843,0.34697369,9.5045176,0.0,0,3.3594637,450.0,1.0043958,1.6870539,0.85731077,499.18192,-9.2381706
195.4867,-0.16357586,9.4445992,0.0,0,3.81795,450.0,0.99455988,-0.49597168,1.5440938,500.92938,-9.2371225
195.4891,-0.079903387,9.3752718,0.0,0,4.2764363,450.0,0.98203522,-0.47037527,2.3494978,502.67685,-9.237546
195.4915,0.096085697,9.3101931,0.0,0,4.7349229,450.0,0.96927327,0.44735065,3.0835352,504.42432,-9.2359142
195.4939,-0.029313672,9.2662888,0.0,0,5.1934094,450.0,0.96058577,-0.12297565,3.6231861,506.00513,-9.2358885
195.4963,0.02531107,9.2195892,0.0,0,5.6518955,450.0,0.95282459,0.12539084,4.0494795,507.3082,-9.2379932
195.4987,0.080505706,9.1694946,0.0,0,6.1103821,450.0,0.94550186,0.41053471,4.4634004,508.61127,-9.2375669
195.5011,-0.073338605,9.1151361,0.0,0,6.5688682,450.0,0.93699032,-0.32219341,4.8740172,509.91434,-9.2372065
195.5035,0.0080892025,9.0672035,0.0,0,7.0273547,450.0,0.92840952,-0.036243487,5.296464,511.16815,-9.2358322
195.5059,0.11030652,9.0237961,0.0,0,7.4858418,450.0,0.91978258,0.51339519,5.7563958,512.23486,-9.236269
195.5083,-0.041901216,8.990303,0.0,0,7.9443283,450.0,0.91386014,-0.12584293,6.2310166,513.30157,-9.2357807
195.5107,-0.043831669,8.9577198,0.0,0,8.4028139,450.0,0.90912628,-0.32458863,6.7242236,514.36823,-9.2372675
195.5131,0.1110442,8.9241104,0.0,0,8.8612995,450.0,0.90445089,0.53289467,7.2229991,515.42719,-9.2368698
195.5155,-0.031281747,8.9023428,0.0,0,9.3197861,450.0,0.90122008,-0.13247944,7.7039304,516.30768,-9.2354927
195.5179,0.023293652,8.8819962,0.0,0,9.7782726,450.0,0.8971256,0.073136687,8.1730089,517.18817,-9.2345829
195.5203,0.060396381,8.8669014,0.0,0,10.236759,450.0,0.89358175,0.32098672,8.6425619,518.06866,-9.2356768
195.5227,-0.065949164,8.8551235,0.0,0,10.695246,450.0,0.89114237,-0.36042646,9.104023,518.94916,-9.2356768
195.5251,0.017515441,8.8387156,0.0,0,11.153732,450.0,0.8896355,0.020996934,9.5689077,519.72302,-9.2351789
195.5275,0.064611807,8.8217278,0.0,0,11.612218,450.0,0.88789827,0.39707553,10.046461,520.48169,-9.2343626
195.5299,-0.084592961,8.8158178,0.0,0,12.070705,450.0,0.88705635,-0.41964337,10.518691,521.2403,-9.2341738
195.5323,0.029859565,8.8115721,0.0,0,12.529191,450.0,0.88526911,0.099706873,11.00024,521.99896,-9.2331915
195.5347,0.088667408,8.8128061,0.0,0,12.987678,450.0,0.88453889,0.5247007,11.467206,522.66626,-9.2341709
195.5371,-0.096336119,8.8146667,0.0,0,13.446164,450.0,0.88513678,-0.47595334,11.908522,523.29596,-9.2331152
195.5395,0.066041134,8.8097324,0.0,0,13.904651,450.0,0.88540316,0.30415052,12.365133,523.92566,-9.2342873
195.5419,0.064771973,8.8072119,0.0,0,14.363137,450.0,0.88574672,0.38064811,12.844114,524.55536,-9.2349596
195.5443,-0.13547622,8.807518,0.0,0,14.821624,450.0,0.88536566,-0.69923395,13.317108,525.13855,-9.2349463
195.5467,0.11878581,8.8093615,0.0,0,15.28011,450.0,0.8845669,0.55349886,13.796015,525.68243,-9.2341032
195.5491,0.069481328,8.8140259,0.0,0,15.738596,450.0,0.8844142,0.41671431,14.275714,526.22626,-9.2335396
195.5515,-0.14994003,8.818594,0.0,0,16.197083,450.0,0.88577706,-0.84566116,14.735085,526.77008,-9.2340393
195.5539,0.11562917,8.8115911,0.0,0,16.655569,450.0,0.88611221,0.54478079,15.201758,527.30316,-9.2341957
195.5563,0.015174461,8.8075819,0.0,0,17.114056,450.0,0.8858282,0.19282465,15.658938,527.81842,-9.2337246
195.5587,-0.018919908,8.8067541,0.0,0,17.572542,450.0,0.8850041,-0.15805376,16.105627,528.33362,-9.2341232
195.5611,0.071178064,8.810792,0.0,0,17.999401,450.0,0.88460493,0.31165725,16.559368,528.84882,-9.2334194
195.5635,-0.011078275,8.8102131,0.0,0,18.0,450.0,0.88428372,-0.069593817,17.022348,529.35065,-9.2331676
195.5659,-0.036066733,8.8120003,0.0,0,18.0,450.0,0.88523895,-0.24848329,17.451115,529.80145,-9.2342691
195.5683,0.093125015,8.8073473,0.0,0,18.0,450.0,0.88544899,0.52460527,17.838081,530.25226,-9.2347279
195.5707,0.037234113,8.8051558,0.0,0,18.0,450.0,0.8852067,0.18291268,18.159105,530.70306,-9.235611
195.5731,0.037842907,8.8107147,0.0,0,18.0,450.0,0.88541144,0.18774563,18.391766,531.15149,-9.2370157
195.5755,-0.0053118709,8.822999,0.0,0,18.0,450.0,0.88619834,-0.038296532,18.515673,531.54504,-9.2426777
195.5779,0.051685836,8.8314323,0.0,0,18.0,450.0,0.88755822,0.3128832,18.509773,531.9386,-9.2505903
195.5803,0.033660993,8.8383656,0.0,0,18.0,450.0,0.8897469,0.16620211,18.391041,532.33215,-9.2613115
195.5827,0.035689324,8.8453207,0.0,0,18.0,450.0,0.89190096,0.25195804,18.261034,532.72571,-9.2746897
195.5851,-0.041435629,8.8599405,0.0,0,18.0,450.0,0.89412624,-0.18530428,18.145933,533.08173,-9.2915382
195.5875,-0.056581426,8.8795719,0.0,0,18.0,450.0,0.89617854,-0.35644993,18.080774,533.43237,-9.3096437
195.5899,0.052039348,8.9034672,0.0,0,18.0,450.0,0.89943153,0.18530925,18.061134,533.78302,-9.3315229
195.5923,0.11501849,8.92274,0.0,0,18.0,450.0,0.90282148,0.53458202,18.061367,534.13361,-9.3525324
195.5947,0.028903481,8.9419584,0.0,0,18.0,450.0,0.9070124,0.23998085,18.071806,534.45892,-9.3725777
195.5971,-0.10261827,8.9589539,0.0,0,18.0,450.0,0.91052586,-0.46697921,18.091347,534.77386,-9.3930035
195.5995,-0.020217113,8.9754696,0.0,0,18.0,450.0,0.91268063,-0.18803951,18.115379,535.08875,-9.4115896
195.6019,0.10476141,8.9948263,0.0,0,18.0,450.0,0.91479814,0.49518687,18.126801,535.40363,-9.4297705
195.6043,0.078225508,9.0176544,0.0,0,18.0,450.0,0.91775739,0.41323403,18.138601,535.70306,-9.4462042
195.6067,-0.053440906,9.0388002,0.0,0,18.0,450.0,0.92215329,-0.15667117,18.142454,535.98938,-9.4636154
195.6091,-0.072159342,9.0527182,0.0,0,18.0,450.0,0.9258523,-0.41156903,18.140589,536.2757,-9.4815636
195.6115,0.050592422,9.0652781,0.0,0,18.0,450.0,0.92854106,0.1858649,18.138113,536.56201,-9.4997368
195.6139,0.12087143,9.0823307,0.0,0,18.0,450.0,0.93017095,0.56961465,18.136517,536.82953,-9.5165501
195.6163,0.026735775,9.1031427,0.0,0,18.0,450.0,0.93266147,0.1811114,18.136002,537.06573,-9.5326509
195.6187,-0.084967226,9.1223249,0.0,0,18.0,450.0,0.93605191,-0.35521713,18.133968,537.30194,-9.5514183
195.6211,-0.031568248,9.1402378,0.0,0,18.0,450.0,0.9397679,-0.23794433,18.130392,537.53809,-9.5702362
195.6235,0.11729304,9.1516514,0.0,0,18.0,450.0,0.9428463,0.53093362,18.128628,537.76984,-9.5874023
195.6259,0.086479776,9.1679792,0.0,0,18.0,450.0,0.94552499,0.48033935,18.128605,537.98456,-9.6050549
195.6283,-0.043507058,9.1934643,0.0,0,18.0,450.0,0.94889259,-0.14393136,18.126171,538.19934,-9.6230822
195.6307,-0.072792187,9.2153673,0.0,0,18.0,450.0,0.95175022,-0.40608227,18.120312,538.41406,-9.6417217
195.6331,0.048906032,9.2342348,0.0,0,18.0,450.0,0.95509356,0.20326653,18.119585,538.62823,-9.6607399
195.6355,0.11502048,9.2492743,0.0,0,18.0,450.0,0.95914602,0.60819936,18.116308,538.82867,-9.6789427
195.6379,0.035483133,9.2641201,0.0,0,18.0,450.0,0.96241146,0.21498688,18.117002,539.02905,-9.6950006
195.6403,-0.0872797,9.2806673,0.0,0,18.0,450.0,0.96500534,-0.34568408,18.113674,539.22949,-9.713377
195.6427,-0.025820116,9.2983055,0.0,0,18.0,450.0,0.96670526,-0.16671215,18.11272,539.42993,-9.7323484
195.6451,0.12865755,9.3186255,0.0,0,18.0,450.0,0.96985149,0.54065466,18.107933,539.6178,-9.7506857
195.6475,0.082870454,9.3377705,0.0,0,18.0,450.0,0.97356862,0.48556274,18.106068,539.80396,-9.7684803
195.6499,-0.042032175,9.3532267,0.0,0,18.0,450.0,0.97731704,-0.12595694,18.108643,539.99005,-9.7871065
195.6523,-0.076726273,9.3678408,0.0,0,18.0,450.0,0.98070174,-0.37762937,18.103518,540.17621,-9.8053474
195.6547,0.044173781,9.384799,0.0,0,18.0,450.0,0.98294687,0.17179738,18.107168,540.33185,-9.8236322
195.6571,0.11909046,9.4062796,0.0,0,18.0,450.0,0.98550999,0.57259071,18.105888,540.47504,-9.8398008
195.6595,0.051715706,9.4317265,0.0,0,18.0,450.0,0.98948318,0.27274093,18.105232,540.61816,-9.856576
195.6619,-0.09463419,9.4489946,0.0,0,18.0,450.0,0.99345326,-0.42311293,18.103275,540.76129,-9.8745432
195.6643,-0.021999167,9.459959,0.0,0,18.0,450.0,0.99707395,-0.15953153,18.102018,540.88892,-9.8945818
195.6667,0.12136977,9.4731207,0.0,0,18.0,450.0,0.99951065,0.52567714,18.103914,541.00348,-9.912715
195.6691,0.085629441,9.4910727,0.0,0,18.0,450.0,1.0016556,0.4640469,18.101065,541.11798,-9.9308786
195.6715,-0.046354204,9.5155058,0.0,0,18.0,450.0,1.0049367,-0.14702813,18.099253,541.23248,-9.9484892
195.6739,-0.093844935,9.5340748,0.0,0,18.0,450.0,1.0086713,-0.43286505,18.103468,541.35779,-9.9677315
195.6763,0.037473388,9.551506,0.0,0,18.0,450.0,1.0129179,0.11786287,18.103399,541.50092,-9.9849377
195.6787,0.1403598,9.5642519,0.0,0,18.0,450.0,1.0161958,0.62277752,18.103363,541.6441,-10.002501
195.6811,0.10609023,9.5826187,0.0,0,18.0,450.0,1.019125,0.50527996,18.098234,541.78729,-10.019054
195.6835,0.11096505,9.5936794,0.0,0,18.0,450.0,1.0199209,0.53433263,18.098627,541.9245,-10.03722
195.6859,0.0018736024,9.5915546,0.0,0,18.0,450.0,1.0189481,-0.054207806,18.100435,542.039,-10.055376
195.6883,0.11560479,9.5927162,0.0,0,18.0,450.0,1.0194539,0.51165068,18.097267,542.15356,-10.071534
195.6907,0.16637364,9.5902433,0.0,0,18.0,450.0,1.0203038,0.76409656,18.097631,542.26807,-10.091626
195.6931,0.03265518,9.5830059,0.0,0,18.0,450.0,1.0199472,0.19303925,18.097195,542.38049,-10.110302
195.6955,-0.031377688,9.5847464,0.0,0,18.0,450.0,1.0195067,-0.16820842,18.097679,542.44495,-10.126572
195.6979,0.10828204,9.5895119,0.0,0,18.0,450.0,1.019117,0.43010885,18.096048,542.50934,-10.144519
195.7003,0.16745877,9.5916786,0.0,0,18.0,450.0,1.0191162,0.7603215,18.097853,542.57379,-10.163268
195.7027,0.076855615,9.5907888,0.0,0,18.0,450.0,1.0193964,0.40044492,18.096903,542.63818,-10.179959
195.7051,0.0043972977,9.588336,0.0,0,18.0,450.0,1.0201709,0.012727701,18.088829,542.72766,-10.199465
195.7075,0.025846213,9.583766,0.0,0,18.0,450.0,1.0197711,0.09977971,18.090672,542.82068,-10.217371
195.7099,0.12346791,9.5841503,0.0,0,18.0,450.0,1.0190481,0.5492084,18.083864,542.91376,-10.235229
195.7123,0.12435805,9.5898457,0.0,0,18.0,450.0,1.0187289,0.56792569,18.090378,543.00677,-10.25421
195.7147,0.026404107,9.5938587,0.0,0,18.0,450.0,1.0191587,0.18627834,18.088652,543.10492,-10.27192
195.7171,-0.019682653,9.5938683,0.0,0,18.0,450.0,1.0203868,-0.06786526,18.086658,543.20514,-10.290383
195.7195,0.076699622,9.5883341,0.0,0,18.0,450.0,1.0206933,0.29105583,18.085817,543.30536,-10.308153
195.7219,0.14000109,9.5822744,0.0,0,18.0,450.0,1.0195678,0.65434039,18.084208,543.40552,-10.325475
195.7243,0.073008902,9.5859184,0.0,0,18.0,450.0,1.0188947,0.37927818,18.081053,543.48639,-10.342775
195.7267,-0.026693376,9.5909166,0.0,0,18.0,450.0,1.0189201,-0.069477864,18.083485,543.55078,-10.361854
195.7291,0.018024255,9.5905199,0.0,0,18.0,450.0,1.0192306,0.046572715,18.080135,543.61523,-10.379011
195.7315,0.1241878,9.5885954,0.0,0,18.0,450.0,1.0197927,0.53389311,18.081223,543.67963,-10.397467
195.7339,0.12754442,9.5847931,0.0,0,18.0,450.0,1.019846,0.57242274,18.082422,543.74408,-10.414778
195.7363,0.019477699,9.5850277,0.0,0,18.0,450.0,1.0194585,0.11939696,18.083937,543.80847,-10.431196
195.7387,-0.0094860103,9.5913448,0.0,0,18.0,450.0,1.019345,-0.061322127,18.080528,543.87292,-10.450545
195.7411,0.073648334,9.5941315,0.0,0,18.0,450.0,1.0191616,0.28030151,18.079266,543.93732,-10.468514
195.7435,0.13906318,9.5938282,0.0,0,18.0,450.0,1.0197092,0.63475537,18.078505,543.99731,-10.48698
195.7459,0.076269999,9.5914392,0.0,0,18.0,450.0,1.0208042,0.42454001,18.081417,544.04022,-10.504668
195.7483,-0.0010849498,9.5860863,0.0,0,18.0,450.0,1.0203887,-0.011966662,18.072941,544.08313,-10.523748
195.7507,0.015667452,9.5849552,0.0,0,18.0,450.0,1.01929,0.0472004,18.076712,544.1261,-10.542121
195.7531,0.1114157,9.5883512,0.0,0,18.0,450.0,1.0187777,0.51723307,18.076857,544.1687,-10.558645
195.7555,0.13778113,9.5910215,0.0,0,18.0,450.0,1.019078,0.66306245,18.074368,544.20453,-10.576083
195.7579,0.039592694,9.5918064,0.0,0,18.0,450.0,1.0199995,0.23736574,18.074032,544.24036,-10.596019
195.7603,-0.019968364,9.5893478,0.0,0,18.0,450.0,1.0206044,-0.091334634,18.070133,544.27612,-10.614849
195.7627,0.078794822,9.586051,0.0,0,18.0,450.0,1.0203921,0.3087247,18.072639,544.31195,-10.633579
195.7651,0.14404981,9.5869446,0.0,0,18.0,450.0,1.0194205,0.69120872,18.068121,544.354,-10.650303
195.7675,0.085297398,9.5922041,0.0,0,18.0,450.0,1.0190467,0.41646245,18.067945,544.39691,-10.668249
195.7699,0.0046936604,9.5973911,0.0,0,18.0,450.0,1.0199782,0.027182309,18.074148,544.43988,-10.686508
195.7723,0.018742014,9.5959263,0.0,0,18.0,450.0,1.021173,0.053219825,18.069874,544.48285,-10.704854
195.7747,0.1221934,9.5887289,0.0,0,18.0,450.0,1.0208099,0.531012,18.069916,544.51563,-10.720714
195.7771,0.13442913,9.5849018,0.0,0,18.0,450.0,1.0198261,0.64351475,18.072468,544.54425,-10.737626
195.7795,0.052705761,9.5886688,0.0,0,18.0,450.0,1.0190666,0.28724954,18.071787,544.57288,-10.755804
195.7819,-0.018469468,9.592906,0.0,0,18.0,450.0,1.0193242,-0.097983681,18.067696,544.6015,-10.776057
195.7843,0.077028714,9.5935621,0.0,0,18.0,450.0,1.0199662,0.31066346,18.066303,544.63788,-10.79283
195.7867,0.14512877,9.5924091,0.0,0,18.0,450.0,1.0207914,0.6917842,18.067215,544.68085,-10.811252
195.7891,0.085578896,9.5886965,0.0,0,18.0,450.0,1.0207703,0.44479164,18.063229,544.72382,-10.828209
195.7915,0.01883872,9.5888996,0.0,0,18.0,450.0,1.0202868,0.094142117,18.065779,544.76672,-10.846927
195.7939,0.0091433395,9.5946255,0.0,0,18.0,450.0,1.0198631,0.019419527,18.065012,544.80432,-10.866547
195.7963,0.11186736,9.5990295,0.0,0,18.0,450.0,1.0197922,0.48190919,18.064442,544.83295,-10.882875
195.7987,0.14680056,9.597188,0.0,0,18.0,450.0,1.020615,0.72199214,18.062233,544.86157,-10.900301
195.8011,0.054889899,9.5937386,0.0,0,18.0,450.0,1.0212733,0.27075309,18.064249,544.89026,-10.918752
195.8035,-0.022598466,9.5864687,0.0,0,18.0,450.0,1.0204908,-0.077511229,18.060663,544.91589,-10.937037
195.8059,0.090868376,9.5864687,0.0,0,18.0,450.0,1.0193659,0.35230321,18.061781,544.93018,-10.955454
195.8083,0.13956876,9.5884991,0.0,0,18.0,450.0,1.0185235,0.65694523,18.060385,544.94452,-10.972771
195.8107,0.11007897,9.591136,0.0,0,18.0,450.0,1.0190225,0.52949142,18.061504,544.9588,-10.990332
195.8131,0.017707832,9.5924196,0.0,0,18.0,450.0,1.020295,0.12681839,18.061983,544.97253,-11.007976
195.8155,0.013114626,9.5896606,0.0,0,18.0,450.0,1.0208365,0.01861483,18.061781,544.97253,-11.026396
195.8179,0.12481423,9.5862827,0.0,0,18.0,450.0,1.0201943,0.53599024,18.060167,544.97253,-11.04318
195.8203,0.1501227,9.5884409,0.0,0,18.0,450.0,1.0192786,0.70061088,18.056683,544.97253,-11.061299
195.8227,0.060722943,9.596262,0.0,0,18.0,450.0,1.0197189,0.3056339,18.05851,544.97253,-11.078535
195.8251,-0.0021119933,9.5988579,0.0,0,18.0,450.0,1.020478,-0.02011569,18.053667,544.97253,-11.099027
195.8275,0.077320777,9.595458,0.0,0,18.0,450.0,1.0212407,0.30145663,18.058266,544.97253,-11.117216
195.8299,0.1461595,9.5864935,0.0,0,18.0,450.0,1.0204015,0.67500043,18.054802,544.97253,-11.134125
195.8323,0.10751235,9.5859747,0.0,0,18.0,450.0,1.0197504,0.5270794,18.053799,544.97253,-11.152143
195.8347,0.025120443,9.5895128,0.0,0,18.0,450.0,1.0191451,0.12668398,18.053408,544.9776,-11.171574
195.8371,0.012420907,9.5937605,0.0,0,18.0,450.0,1.0193479,0.039131764,18.053707,544.98474,-11.190347
195.8395,0.11969054,9.5946693,0.0,0,18.0,450.0,1.0202386,0.53010696,18.051085,544.99194,-11.207495
195.8419,0.15034063,9.5915747,0.0,0,18.0,450.0,1.0208217,0.70542926,18.050779,544.99908,-11.223301
195.8443,0.070702761,9.5906878,0.0,0,18.0,450.0,1.0211822,0.37104452,18.052092,544.99847,-11.242479
195.8467,0.01446566,9.591032,0.0,0,18.0,450.0,1.0203835,0.062863126,18.056227,544.99133,-11.260456
195.8491,0.076787934,9.5946007,0.0,0,18.0,450.0,1.0196674,0.28320342,18.052723,544.98419,-11.278692
195.8515,0.14373158,9.5969324,0.0,0,18.0,450.0,1.0196335,0.63447601,18.052004,544.97699,-11.295436
195.8539,0.12349086,9.5951481,0.0,0,18.0,450.0,1.0203335,0.59989721,18.052004,544.96985,-11.311609
195.8563,0.026494533,9.5927572,0.0,0,18.0,450.0,1.0212711,0.18118882,18.050411,544.96271,-11.330197
195.8587,0.019276349,9.5868225,0.0,0,18.0,450.0,1.020419,0.013267388,18.049503,544.95557,-11.351118
195.9608,0.065700315,9.5926151,0.0,0,18.0,19.512171,1.0202421,0.30001765,18.037909,542.8916,-11.468808
197.1608,0.036498409,9.5982285,0.0,0,18.0,8.5372038e-16,1.0214353,0.16991001,18.00029,520.55273,-11.481309
198.3608,0.023100894,9.6019506,0.0,0,18.0,3.6906185000000005e-32,1.0219885,0.1044274,18.000015,508.02234,-11.481345
199.5608,0.018274361,9.6061068,0.0,0,18.0,1.4012985e-45,1.0226599,0.088810459,17.999899,496.73083,-11.482111
200.7608,0.022155443,9.6063108,0.0,0,18.0,1.4012985e-45,1.0229015,0.10074845,17.999966,485.95566,-11.482275
201.9608,0.015315557,9.607131,0.0,0,18.0,1.4012985e-45,1.0229175,0.07119672,18.000206,475.64478,-11.482092
203.1608,0.014725467,9.6078348,0.0,0,18.0,1.4012985e-45,1.0232415,0.067306891,18.000431,465.22714,-11.481512
204.3608,0.018977601,9.6088133,0.0,0,18.0,1.4012985e-45,1.0231678,0.08163128,17.999666,455.15527,-11.481445
205.5608,0.012167084,9.609478,0.0,0,18.0,1.4012985e-45,1.0234246,0.049728923,17.99983,445.38229,-11.481372
206.7608,0.01295478,9.6098928,0.0,0,18.0,1.4012985e-45,1.0234891,0.062824667,17.999998,435.7619,-11.481493
207.9608,0.018208524,9.6110945,0.0,0,18.0,1.4012985e-45,1.0237685,0.079941407,18.000013,426.47018,-11.482089
209.1608,0.011315457,9.6122828,0.0,0,18.0,1.4012985e-45,1.0239912,0.048527483,17.999573,417.49652,-11.482049
210.3608,0.011397332,9.6122513,0.0,0,18.0,1.4012985e-45,1.0238018,0.054563928,17.999798,408.89807,-11.481405
211.5608,0.015164207,9.6127129,0.0,0,18.0,1.4012985e-45,1.0240961,0.070657231,17.999521,400.31033,-11.481565
212.7608,0.007548172,9.6134262,0.0,0,18.0,1.4012985e-45,1.0240575,0.032728087,18.00034,392.13141,-11.481653
213.9608,0.010508785,9.614543,0.0,0,18.0,1.4012985e-45,1.0244832,0.053558622,17.999622,384.36832,-11.481404
215.1608,0.013502811,9.6151857,0.0,0,18.0,1.4012985e-45,1.024471,0.065862879,17.999157,376.58823,-11.481536
216.3608,0.0068859793,9.6159992,0.0,0,18.0,1.4012985e-45,1.0244958,0.032810587,17.999889,369.26279,-11.481575
217.5608,0.0095633576,9.6164474,0.0,0,18.0,1.4012985e-45,1.0248066,0.048805341,18.000008,361.96951,-11.481845
218.7608,0.012861223,9.6173859,0.0,0,18.0,1.4012985e-45,1.0248036,0.053917039,18.000694,354.95496,-11.48204
219.9608,0.0051086443,9.6178169,0.0,0,18.0,1.4012985e-45,1.0251172,0.02447203,17.999382,348.14975,-11.481941
221.1608,0.0076459209,9.6184311,0.0,0,18.0,1.4012985e-45,1.025027,0.038743794,17.999851,341.60507,-11.482304
222.3608,0.010333058,9.6199408,0.0,0,18.0,1.4012985e-45,1.0252525,0.04709832,18.00062,335.15054,-11.48187
223.5608,0.0031051859,9.6196432,0.0,0,18.0,1.4012985e-45,1.0253643,0.012777598,17.9998,328.95627,-11.48209
224.7608,0.0078515839,9.6205702,0.0,0,18.0,1.4012985e-45,1.0253913,0.039488062,18.000988,322.80542,-11.481878
225.9608,0.006589205,9.621006,0.0,0,18.0,1.4012985e-45,1.025668,0.027760005,17.998833,316.87054,-11.481809
227.1608,0.00085860415,9.6219969,0.0,0,18.0,1.4012985e-45,1.0257038,0.0043370435,18.000261,311.13934,-11.481996
228.3608,0.006706703,9.6222248,0.0,0,18.0,1.4012985e-45,1.0256429,0.032564905,17.999514,305.34625,-11.481679
229.5608,0.0049348189,9.6230984,0.0,0,18.0,1.4012985e-45,1.026032,0.017772779,18.00038,299.87659,-11.481506
230.7608,-0.0001999938,9.6235895,0.0,0,18.0,1.4012985e-45,1.0259732,0.001952939,17.999092,294.34549,-11.481577
231.9608,0.0032471584,9.623847,0.0,0,18.0,1.4012985e-45,1.0261441,0.016997363,17.999847,289.08072,-11.481412
233.1608,0.0051228809,9.6242018,0.0,0,18.0,1.4012985e-45,1.0262166,0.02204706,18.000284,283.91293,-11.481556
234.3608,-0.0011639681,9.6252918,0.0,0,18.0,1.4012985e-45,1.0262225,-0.0025768722,17.999531,278.65308,-11.481503
235.5608,0.0031700328,9.6258097,0.0,0,18.0,1.4012985e-45,1.0264099,0.018763058,17.999546,273.71808,-11.481117
236.7608,0.002341236,9.6260881,0.0,0,18.0,1.4012985e-45,1.0265186,0.0034342643,18.000246,268.92349,-11.481419
237.9608,-0.0031238885,9.6267214,0.0,0,18.0,1.4012985e-45,1.0265536,-0.0077795107,18.000925,263.98917,-11.481768
239.1608,0.0035335927,9.6271324,0.0,0,18.0,1.4012985e-45,1.0268146,0.017858239,18.000772,259.37335,-11.481613
240.3608,-0.00042884581,9.6272764,0.0,0,18.0,1.4012985e-45,1.0267373,-0.0047339671,18.000153,254.85666,-11.481311
241.5608,-0.0043934388,9.6282816,0.0,0,18.0,1.4012985e-45,1.0267636,-0.020734195,17.999716,250.4852,-11.48113
242.7608,0.0018593746,9.6288891,0.0,0,18.0,1.4012985e-45,1.0270433,0.010932705,17.999903,246.04402,-11.481296
243.9608,-0.0019922594,9.6293144,0.0,0,18.0,1.4012985e-45,1.0271029,-0.0093337102,17.999573,241.69571,-11.481245
245.1608,-0.0045029647,9.6297808,0.0,0,18.0,1.4012985e-45,1.0271442,-0.020401616,17.999802,237.56631,-11.481437
246.3608,0.00073864113,9.6304016,0.0,0,18.0,1.4012985e-45,1.0274372,0.0046080449,18.001177,233.51311,-11.481367
247.5608,-0.0020959254,9.6307907,0.0,0,18.0,1.4012985e-45,1.0273472,-0.0084260814,17.999037,229.36592,-11.481815
248.7608,-0.0062873862,9.631917,0.0,0,18.0,1.4012985e-45,1.0274297,-0.022959948,18.000721,225.51648,-11.481924
249.9608,0.00083854294,9.6320353,0.0,0,18.0,1.4012985e-45,1.0276831,0.0082047526,18.000164,221.42595,-11.481881
251.1608,-0.0042082747,9.6329193,0.0,0,18.0,1.4012985e-45,1.0277537,-0.025813442,18.000765,217.58955,-11.482242
252.3608,-0.0061630658,9.6334562,0.0,0,18.0,1.4012985e-45,1.027861,-0.025910562,17.999891,213.94662,-11.481894
253.5608,-0.0016556294,9.6329126,0.0,0,18.0,1.4012985e-45,1.0278888,-0.0038265125,18.000103,210.33116,-11.481712
254.7608,-0.0051287864,9.6343708,0.0,0,18.0,1.4012985e-45,1.028002,-0.028712897,17.99918,206.82475,-11.481233
255.8608,-0.0094761532,9.6346483,0.0,0,18.0,1.4012985e-45,1.0281087,-0.04022485,18.000338,203.41101,-11.585542