File: clean data/testID_0234.csv
level_0,index,Time(sec),Force(kN),Jaw(mm),PowAngle(deg),Power(W),Pram,PTemp,Strain,Stress(MPa),Stroke(mm),TC1(C),wedge(mm)
2439,2439,212.0106,1.1072519,0.015490071,0.0,0,9.0336905,0.0,0.0010952033,12.756617,10.075922,499.8161,-9.2077007
2440,2440,212.0108,2.2260218,0.034851853,0.0,0,9.004427,0.0,0.0018252498,25.135958,10.039535,499.80832,-9.2069855
2441,2441,212.011,3.3706527,0.054542176,0.0,0,8.9751625,0.0,0.0032628067,40.138325,10.008131,499.80057,-9.2063465
2442,2442,212.0112,3.928565,0.084031664,0.0,0,8.945899,0.0,0.0054754075,48.829079,9.9819117,499.79279,-9.2065907
2443,2443,212.0114,4.1517868,0.11353426,0.0,0,8.9166346,0.0,0.0070932764,52.053391,9.9519863,499.785,-9.2064018
2444,2444,212.0116,4.3324561,0.13391678,0.0,0,8.8873701,0.0,0.0085078431,54.118687,9.9172029,499.77722,-9.2059546
2445,2445,212.0118,4.5769601,0.18219484,0.0,0,8.8581066,0.0,0.011713388,57.046165,9.8776693,499.76944,-9.2052517
2446,2446,212.012,4.4890075,0.26095197,0.0,0,8.8288422,0.0,0.016301811,56.778828,9.8345327,499.76169,-9.2048197
2447,2447,212.0122,4.237072,0.33168578,0.0,0,8.7995787,0.0,0.021209296,53.467949,9.7843142,499.75391,-9.2047901
2448,2448,212.0124,4.2130651,0.39029947,0.0,0,8.7703142,0.0,0.025872752,52.03656,9.7302647,499.74612,-9.205143
2449,2449,212.0126,4.4292355,0.44320008,0.0,0,8.7416391,0.0,0.029221939,54.293407,9.6755486,499.73834,-9.2056293
2450,2450,212.0128,4.4742398,0.48785025,0.0,0,8.7136726,0.0,0.032118227,55.230721,9.6227016,499.73059,-9.2057362
2451,2451,212.013,4.3662715,0.54058665,0.0,0,8.6858349,0.0,0.036189154,53.842335,9.5723028,499.72281,-9.2060242
2452,2452,212.0132,4.4854431,0.59185898,0.0,0,8.6580029,0.0,0.039737828,54.361759,9.5231571,499.71503,-9.2054663
2453,2453,212.0134,4.7205811,0.61552358,0.0,0,8.6301708,0.0,0.041371524,57.180157,9.4788618,499.70724,-9.2047729
2454,2454,212.0136,4.7141099,0.62845397,0.0,0,8.6023388,0.0,0.042780638,57.802853,9.4393311,499.69949,-9.2046919
2455,2455,212.0138,4.4414582,0.651784,0.0,0,8.5745068,0.0,0.044288617,54.826157,9.3989182,499.69171,-9.2052984
2456,2456,212.014,4.3118367,0.6821788,0.0,0,8.5466747,0.0,0.045854587,52.562267,9.3644943,499.68393,-9.2063379
2457,2457,212.0142,4.4710164,0.71474665,0.0,0,8.5188427,0.0,0.048444312,53.643917,9.3337936,499.67615,-9.2058964
2458,2458,212.0144,4.7084045,0.74259889,0.0,0,8.4910107,0.0,0.050688524,56.368748,9.3018799,499.66837,-9.2047482
2459,2459,212.0146,4.8777618,0.76242691,0.0,0,8.4631786,0.0,0.051725037,58.539482,9.2687473,499.66061,-9.2044983
2460,2460,212.0148,4.9927115,0.79063737,0.0,0,8.4353466,0.0,0.053706497,59.996864,9.2325497,499.65283,-9.2042112
2461,2461,212.015,5.0352302,0.84119123,0.0,0,8.4075146,0.0,0.057225447,60.527874,9.1953716,499.64505,-9.2041607
2462,2462,212.0152,4.9249215,0.90214163,0.0,0,8.3796825,0.0,0.061029665,59.44368,9.1574755,499.63446,-9.204916
2463,2463,212.0154,4.7531161,0.95352823,0.0,0,8.3518505,0.0,0.064935438,57.199322,9.1189556,499.59857,-9.2056417
2464,2464,212.0156,4.6995797,0.99334496,0.0,0,8.3240185,0.0,0.068277128,55.915874,9.0755215,499.56268,-9.2060261
2465,2465,212.0158,4.7502999,1.0358884,0.0,0,8.2961864,0.0,0.070832357,56.249176,9.0289583,499.52679,-9.2064028
2466,2466,212.016,4.7739425,1.0837437,0.0,0,8.2683544,0.0,0.074089825,56.418114,8.9863157,499.49091,-9.2064438
2467,2467,212.0162,4.7380896,1.1257193,0.0,0,8.2405224,0.0,0.077696517,55.810997,8.9448357,499.45502,-9.2054472
2468,2468,212.0164,4.7410579,1.1598676,0.0,0,8.2126913,0.0,0.080011986,55.580875,8.906085,499.41913,-9.2047033
2469,2469,212.0166,4.8322625,1.1777953,0.0,0,8.1848593,0.0,0.081261136,56.415676,8.8709335,499.38324,-9.2046623
2470,2470,212.0168,4.8640313,1.1873351,0.0,0,8.1570263,0.0,0.082522228,57.089424,8.8364992,499.34735,-9.2046051
2471,2471,212.017,4.7569771,1.2167927,0.0,0,8.1291952,0.0,0.084203236,56.092224,8.8081808,499.31149,-9.2044363
2472,2472,212.0172,4.6577296,1.2534407,0.0,0,8.1013632,0.0,0.086416081,54.572235,8.7807465,499.2756,-9.204154
2473,2473,212.0174,4.7204175,1.2744405,0.0,0,8.0735302,0.0,0.088647746,54.760941,8.7535734,499.23972,-9.2048645
2474,2474,212.0176,4.9153285,1.2935952,0.0,0,8.0462542,0.0,0.090069003,56.729401,8.7259712,499.20383,-9.2059937
2475,2475,212.0178,5.0915899,1.3163892,0.0,0,8.0196476,0.0,0.091112107,58.815926,8.6990757,499.16794,-9.2060862
2476,2476,212.018,5.1624451,1.3405001,0.0,0,7.9931622,0.0,0.093164146,59.756405,8.6711588,499.13205,-9.2059536
2477,2477,212.0182,5.148437,1.385654,0.0,0,7.9666815,0.0,0.096439958,59.590683,8.6390734,499.09616,-9.2060862
2478,2478,212.0184,5.0905094,1.4375418,0.0,0,7.9402018,0.0,0.099717453,58.855602,8.6072559,499.06027,-9.2054176
2479,2479,212.0186,5.0087142,1.4690324,0.0,0,7.9137216,0.0,0.10257579,57.791634,8.576683,499.02438,-9.2046452
2480,2480,212.0188,4.9428463,1.5040351,0.0,0,7.8872414,0.0,0.1054096,56.757328,8.5425224,498.98849,-9.2044582
2481,2481,212.019,4.915524,1.5481129,0.0,0,7.8607612,0.0,0.10802615,56.191612,8.5051374,498.95261,-9.2042685
2482,2482,212.0192,4.9186263,1.5801231,0.0,0,7.8342814,0.0,0.11069091,56.072723,8.469635,498.91672,-9.2042503
2483,2483,212.0194,4.9388614,1.6124625,0.0,0,7.8078017,0.0,0.11357757,56.106674,8.4330292,498.88086,-9.2038937
2484,2484,212.0196,4.9715629,1.6401196,0.0,0,7.781321,0.0,0.1152776,56.34296,8.39995,498.84497,-9.2038765
2485,2485,212.0198,5.0248094,1.6487117,0.0,0,7.7548413,0.0,0.11606281,56.878017,8.3698997,498.80908,-9.2037926
2486,2486,212.02,5.0517902,1.6685562,0.0,0,7.7283611,0.0,0.1178597,57.165924,8.3398418,498.77319,-9.2039986
2487,2487,212.0202,5.0037479,1.7054912,0.0,0,7.7018814,0.0,0.12006669,56.702953,8.3133554,498.7373,-9.205368
2488,2488,212.0204,4.9334645,1.7304088,0.0,0,7.6754012,0.0,0.12191322,55.770741,8.2879553,498.70142,-9.2055931
2489,2489,212.0206,4.9382477,1.7488014,0.0,0,7.648921,0.0,0.12391822,55.436623,8.2619457,498.66553,-9.2053976
2490,2490,212.0208,5.03128,1.7700711,0.0,0,7.6224413,0.0,0.12529309,56.28442,8.2389355,498.62964,-9.205554
2491,2491,212.021,5.1414008,1.7885848,0.0,0,7.5959616,0.0,0.12632027,57.555073,8.216012,498.59375,-9.205101
2492,2492,212.0212,5.197679,1.8188868,0.0,0,7.5694814,0.0,0.12891255,58.153793,8.1899576,498.55786,-9.2047443
2493,2493,212.0214,5.2037888,1.8593926,0.0,0,7.5430012,0.0,0.13192949,58.132664,8.1637859,498.52197,-9.2048054
2494,2494,212.0216,5.2013378,1.8882253,0.0,0,7.5165215,0.0,0.13385649,58.037926,8.1354265,498.48611,-9.2048693
2495,2495,212.0218,5.1995702,1.9126426,0.0,0,7.4900417,0.0,0.13615604,57.821125,8.1047354,498.45023,-9.2046671
2496,2496,212.022,5.1761956,1.9448742,0.0,0,7.4635615,0.0,0.13858499,57.424652,8.0748959,498.41434,-9.204237
2497,2497,212.0222,5.1147203,1.9774238,0.0,0,7.4370813,0.0,0.14050387,56.757328,8.044857,498.37845,-9.2040043
2498,2498,212.0224,5.0623426,2.0067279,0.0,0,7.4106011,0.0,0.14321867,55.925152,8.0151644,498.34256,-9.2043152
2499,2499,212.0226,5.0671821,2.0324354,0.0,0,7.3846531,0.0,0.14563917,55.6926,7.9864287,498.30667,-9.2046394
2500,2500,212.0228,5.1238356,2.0510287,0.0,0,7.3593478,0.0,0.14657331,56.205441,7.9595394,498.27078,-9.2045126
2501,2501,212.023,5.1769342,2.068095,0.0,0,7.3341589,0.0,0.14799717,56.748798,7.9342895,498.23489,-9.2048302
2502,2502,212.0232,5.1800594,2.0917933,0.0,0,7.3089747,0.0,0.15017015,56.829456,7.9085879,498.19901,-9.2050591
2503,2503,212.0234,5.1486077,2.1221335,0.0,0,7.2837906,0.0,0.15192796,56.374939,7.8829923,498.16312,-9.2049809
2504,2504,212.0236,5.1311817,2.1468267,0.0,0,7.2586064,0.0,0.15388314,55.897182,7.8585486,498.12723,-9.2051353
2505,2505,212.0238,5.1484952,2.1619704,0.0,0,7.2334223,0.0,0.15576364,55.972923,7.8365965,498.09137,-9.2054892
2506,2506,212.024,5.194119,2.1834741,0.0,0,7.2082381,0.0,0.15690596,56.397453,7.8136635,498.05548,-9.2053471
2507,2507,212.0242,5.2480459,2.2095237,0.0,0,7.183054,0.0,0.15863529,56.826332,7.789381,498.01959,-9.2047195
2508,2508,212.0244,5.2846861,2.2350466,0.0,0,7.1578698,0.0,0.1612267,57.139061,7.7649069,497.9837,-9.2046156
2509,2509,212.0246,5.3003731,2.2673151,0.0,0,7.1326861,0.0,0.16340521,57.224575,7.7414312,497.94781,-9.204298
2510,2510,212.0248,5.302846,2.2941473,0.0,0,7.107502,0.0,0.16528645,57.218281,7.7173452,497.91193,-9.2035742
2511,2511,212.025,5.2968807,2.3122783,0.0,0,7.0823178,0.0,0.16733687,57.064507,7.6901712,497.87604,-9.2038002
2512,2512,212.0252,5.2857246,2.3434541,0.0,0,7.0571342,0.0,0.16945484,56.809589,7.6653705,497.832,-9.2045193
2513,2513,212.0254,5.2652369,2.3773587,0.0,0,7.03195,0.0,0.17163409,56.476509,7.642025,497.75543,-9.2053556
2514,2514,212.0256,5.2594099,2.3953044,0.0,0,7.0067658,0.0,0.17378597,56.208977,7.6159782,497.67889,-9.2060995
2515,2515,212.0258,5.2858877,2.4159796,0.0,0,6.9815817,0.0,0.1755272,56.363548,7.5898619,497.60233,-9.2054186
2516,2516,212.026,5.3240952,2.4412088,0.0,0,6.956398,0.0,0.17688151,56.703285,7.56253,497.52576,-9.2054281
2517,2517,212.0262,5.3412356,2.4573092,0.0,0,6.9312143,0.0,0.17860201,56.856289,7.5375514,497.44922,-9.2059584
2518,2518,212.0264,5.321033,2.4845905,0.0,0,6.9060297,0.0,0.18091772,56.609596,7.5155373,497.37265,-9.2059803
2519,2519,212.0266,5.2862267,2.5166607,0.0,0,6.880846,0.0,0.18284529,56.138077,7.4909515,497.29608,-9.2055321
2520,2520,212.0268,5.2737737,2.5297048,0.0,0,6.8556623,0.0,0.18433213,55.873348,7.4658694,497.21954,-9.2047844
2521,2521,212.027,5.3006191,2.5491457,0.0,0,6.8304787,0.0,0.18626173,55.943443,7.4416418,497.14297,-9.204072
2522,2522,212.0272,5.3475909,2.5795245,0.0,0,6.805294,0.0,0.18800159,56.309513,7.4199944,497.06644,-9.2040195
2523,2523,212.0274,5.3906884,2.6000321,0.0,0,6.7801099,0.0,0.18975255,56.70575,7.3969989,496.98987,-9.2043085
2524,2524,212.0276,5.4179583,2.6258991,0.0,0,6.7554288,0.0,0.19232886,56.905308,7.3728499,496.9133,-9.2043152
2525,2525,212.0278,5.4327888,2.6557915,0.0,0,6.7313542,0.0,0.19429345,56.977715,7.3499618,496.83676,-9.2045832
2526,2526,212.028,5.4382195,2.6717391,0.0,0,6.7073894,0.0,0.19560644,56.950573,7.3258715,496.76019,-9.2053165
2527,2527,212.0282,5.4259086,2.6948941,0.0,0,6.6834288,0.0,0.1979651,56.734276,7.3016119,496.68365,-9.2059031
2528,2528,212.0284,5.3971987,2.7289369,0.0,0,6.6594691,0.0,0.20027292,56.347672,7.2786474,496.60709,-9.2059717
2529,2529,212.0286,5.3783998,2.750246,0.0,0,6.635509,0.0,0.20181383,56.042385,7.2565002,496.53052,-9.2061653
2530,2530,212.0288,5.3886447,2.7689581,0.0,0,6.6115489,0.0,0.20396657,55.94202,7.2317967,496.45398,-9.2061262
2531,2531,212.029,5.4302258,2.794167,0.0,0,6.5875888,0.0,0.20583408,56.158455,7.2053308,496.37741,-9.2060804
2532,2532,212.0292,5.4852571,2.8129473,0.0,0,6.5636292,0.0,0.20698121,56.648422,7.1820421,496.30084,-9.2055683
2533,2533,212.0294,5.5193372,2.8346646,0.0,0,6.539669,0.0,0.20926988,56.949593,7.1580348,496.2243,-9.2048445
2534,2534,212.0296,5.5247941,2.8640797,0.0,0,6.5157094,0.0,0.2116794,56.914223,7.1328449,496.14774,-9.204565
2535,2535,212.0298,5.5053959,2.886158,0.0,0,6.4917493,0.0,0.2130423,56.674919,7.1097293,496.0712,-9.2044764
2536,2536,212.03,5.4865675,2.9048254,0.0,0,6.4677896,0.0,0.21498391,56.338711,7.0877914,495.99463,-9.2050619
2537,2537,212.0302,5.4930406,2.9299667,0.0,0,6.4438295,0.0,0.21719655,56.18494,7.0643725,495.91806,-9.2059088
2538,2538,212.0304,5.5064335,2.9554377,0.0,0,6.4198689,0.0,0.21873206,56.286987,7.0405493,495.84152,-9.2059011
2539,2539,212.0306,5.5336232,2.9793863,0.0,0,6.3959088,0.0,0.22096057,56.412102,7.0174904,495.76495,-9.2058277
2540,2540,212.0308,5.5671353,3.0035467,0.0,0,6.3719487,0.0,0.2234351,56.578331,6.9931297,495.68842,-9.2060089
2541,2541,212.031,5.5938277,3.0280306,0.0,0,6.3479891,0.0,0.2249148,56.831181,6.9687386,495.61185,-9.2059116
2542,2542,212.0312,5.6156015,3.0513809,0.0,0,6.324029,0.0,0.22684348,56.895012,6.9436989,495.53528,-9.2052107
2543,2543,212.0314,5.6176834,3.0753129,0.0,0,6.3000693,0.0,0.22938745,56.810783,6.9185929,495.45874,-9.2040262
2544,2544,212.0316,5.6041307,3.1051083,0.0,0,6.2761092,0.0,0.23137546,56.647907,6.8942904,495.38217,-9.2033024
2545,2545,212.0318,5.5963602,3.1295471,0.0,0,6.2521496,0.0,0.2333468,56.438633,6.8701859,495.3056,-9.2038355
2546,2546,212.032,5.608036,3.1465714,0.0,0,6.2281895,0.0,0.23550865,56.41272,6.8452015,495.22906,-9.2038517
2547,2547,212.0322,5.6222882,3.1717012,0.0,0,6.2042294,0.0,0.23714662,56.476982,6.8213377,495.1525,-9.2038755
2548,2548,212.0324,5.6397715,3.1973875,0.0,0,6.1802692,0.0,0.23891862,56.574112,6.7971678,495.07596,-9.2045765
2549,2549,212.0326,5.6605535,3.2153239,0.0,0,6.1567903,0.0,0.24121998,56.647396,6.7717466,494.99939,-9.2050867
2550,2550,212.0328,5.6742787,3.2424326,0.0,0,6.133893,0.0,0.2432341,56.636948,6.7460613,494.92282,-9.206007
2551,2551,212.033,5.6877513,3.268193,0.0,0,6.1111002,0.0,0.24495462,56.652817,6.7216358,494.84628,-9.205821
2552,2552,212.0332,5.7044053,3.2831495,0.0,0,6.0883117,0.0,0.24695048,56.681736,6.6973963,494.76971,-9.2051153
2553,2553,212.0334,5.7257028,3.3104944,0.0,0,6.0655241,0.0,0.24910089,56.707401,6.6742992,494.69315,-9.2055559
2554,2554,212.0336,5.7429295,3.3426673,0.0,0,6.0427361,0.0,0.25114605,56.771797,6.6508026,494.61661,-9.2055264
2555,2555,212.0338,5.7535691,3.3604431,0.0,0,6.019948,0.0,0.25332889,56.843445,6.6274834,494.54004,-9.2050591
2556,2556,212.034,5.7652583,3.3844247,0.0,0,5.99716,0.0,0.25558829,56.845371,6.603559,494.4635,-9.2048731
2557,2557,212.0342,5.7733312,3.4149408,0.0,0,5.9743714,0.0,0.25747028,56.85154,6.5775623,494.38693,-9.2043352
2558,2558,212.0344,5.7843437,3.4332759,0.0,0,5.9515834,0.0,0.25953883,56.850903,6.5535507,494.31036,-9.2038708
2559,2559,212.0346,5.7938333,3.4608078,0.0,0,5.9287958,0.0,0.26224041,56.776985,6.5308704,494.23383,-9.2039175
2560,2560,212.0348,5.7918777,3.4933953,0.0,0,5.9060082,0.0,0.26431638,56.690376,6.5063634,494.15726,-9.2043381
2561,2561,212.035,5.8008103,3.50844,0.0,0,5.8832202,0.0,0.26594299,56.645977,6.479845,494.08072,-9.2045603
2562,2562,212.0352,5.8269968,3.5300324,0.0,0,5.8604317,0.0,0.26831424,56.712563,6.4550476,493.98688,-9.2048655
2563,2563,212.0354,5.851934,3.561389,0.0,0,5.8376436,0.0,0.27029932,56.867054,6.430438,493.85284,-9.2050495
2564,2564,212.0356,5.8652897,3.5802994,0.0,0,5.8148556,0.0,0.27200204,56.896965,6.4066749,493.71884,-9.2049665
2565,2565,212.0358,5.8722372,3.6036444,0.0,0,5.7920671,0.0,0.27469209,56.800079,6.3824816,493.58481,-9.2050056
2566,2566,212.036,5.8912778,3.6347611,0.0,0,5.7692795,0.0,0.27693018,56.826664,6.3576398,493.45078,-9.2055483
2567,2567,212.0362,5.9079895,3.6538799,0.0,0,5.7464919,0.0,0.27850297,56.890244,6.3339314,493.31674,-9.2058382
2568,2568,212.0364,5.9036937,3.6767125,0.0,0,5.7237034,0.0,0.28113341,56.742912,6.3106208,493.18274,-9.2051935
2569,2569,212.0366,5.9017344,3.7089055,0.0,0,5.7009158,0.0,0.28359208,56.612877,6.2858796,493.04871,-9.2049761
2570,2570,212.0368,5.915998,3.7303724,0.0,0,5.6781278,0.0,0.2851412,56.593899,6.2617936,492.91467,-9.2049255
2571,2571,212.037,5.9423113,3.7506175,0.0,0,5.6553397,0.0,0.2875717,56.658794,6.2383766,492.78067,-9.2046471
2572,2572,212.0372,5.9706316,3.7785921,0.0,0,5.6325517,0.0,0.2899127,56.828979,6.2160015,492.64664,-9.2046804
2573,2573,212.0374,5.9973507,3.8007195,0.0,0,5.6097636,0.0,0.29139447,56.988247,6.1913223,492.5126,-9.2049952
2574,2574,212.0376,6.0190048,3.8224885,0.0,0,5.5874305,0.0,0.29395252,57.0513,6.1652408,492.37857,-9.2052345
2575,2575,212.0378,6.022018,3.8515205,0.0,0,5.5656466,0.0,0.29668957,56.98521,6.1417336,492.24457,-9.2056675
2576,2576,212.038,6.0112519,3.8761237,0.0,0,5.5439625,0.0,0.29822651,56.870213,6.1167378,492.11053,-9.2061691
2577,2577,212.0382,6.0147057,3.8978324,0.0,0,5.5222821,0.0,0.30049375,56.700077,6.0912485,491.9765,-9.2062054
2578,2578,212.0384,6.0242872,3.9239249,0.0,0,5.5006022,0.0,0.3031821,56.599556,6.0665188,491.8425,-9.2056503
2579,2579,212.0386,6.0318589,3.9509459,0.0,0,5.4789219,0.0,0.30492139,56.583515,6.0404944,491.70847,-9.2050333
2580,2580,212.0388,6.0505028,3.9743564,0.0,0,5.457242,0.0,0.30727515,56.618355,6.0156622,491.57443,-9.2047606
2581,2581,212.039,6.0807381,3.9959068,0.0,0,5.4355621,0.0,0.30983263,56.724941,5.9914141,491.44043,-9.2045822
2582,2582,212.0392,6.115448,4.0216923,0.0,0,5.4138823,0.0,0.31142077,56.929234,5.968112,491.3064,-9.2047815
2583,2583,212.0394,6.1404581,4.0458479,0.0,0,5.3922019,0.0,0.31360647,57.060444,5.9463367,491.17236,-9.2047892
2584,2584,212.0396,6.1510944,4.068119,0.0,0,5.370522,0.0,0.31638438,57.010033,5.9210296,491.03833,-9.2049398
2585,2585,212.0398,6.145772,4.0973172,0.0,0,5.3488421,0.0,0.31846002,56.900749,5.8958206,490.90433,-9.2051144
2586,2586,212.04,6.1360106,4.1223345,0.0,0,5.3271623,0.0,0.3205429,56.712635,5.8705692,490.77029,-9.205245
2587,2587,212.0402,6.1361194,4.139441,0.0,0,5.3054819,0.0,0.32291847,56.562065,5.8453817,490.63626,-9.2059803
2588,2588,212.0404,6.1554027,4.1661682,0.0,0,5.283802,0.0,0.32496044,56.563969,5.8221726,490.50226,-9.2062836
2589,2589,212.0406,6.1813169,4.1929293,0.0,0,5.2621217,0.0,0.32696053,56.656364,5.7973137,490.36823,-9.2058783
2590,2590,212.0408,6.2029777,4.20995,0.0,0,5.2404418,0.0,0.3293322,56.761349,5.7719946,490.23419,-9.2058144
2591,2591,212.041,6.2255878,4.2365808,0.0,0,5.2187619,0.0,0.33155081,56.880192,5.7514958,490.10019,-9.2054863
2592,2592,212.0412,6.2500796,4.2653346,0.0,0,5.197082,0.0,0.33349168,56.992638,5.7264566,489.96616,-9.2048035
2593,2593,212.0414,6.2704306,4.2820268,0.0,0,5.1754022,0.0,0.33580014,57.030655,5.696259,489.83212,-9.2045803
2594,2594,212.0416,6.2721224,4.3093276,0.0,0,5.1537223,0.0,0.33840796,56.945442,5.6738648,489.69809,-9.2039814
2595,2595,212.0418,6.2674403,4.3414273,0.0,0,5.1320419,0.0,0.34068576,56.840126,5.6537099,489.56409,-9.2037849
2596,2596,212.042,6.2636938,4.3572292,0.0,0,5.1103621,0.0,0.34285238,56.696701,5.6304202,489.43005,-9.2041597
2597,2597,212.0422,6.2625546,4.3813386,0.0,0,5.0886817,0.0,0.34539536,56.500488,5.6055684,489.29602,-9.2039499
2598,2598,212.0424,6.277267,4.4126558,0.0,0,5.0670018,0.0,0.34742647,56.443283,5.5791998,489.16202,-9.2041435
2599,2599,212.0426,6.299057,4.4280272,0.0,0,5.0457573,0.0,0.349363,56.532661,5.5527477,489.02798,-9.2046747
2600,2600,212.0428,6.317276,4.4502349,0.0,0,5.0250378,0.0,0.35209057,56.53196,5.5294781,488.89395,-9.2057943
2601,2601,212.043,6.3306179,4.4802341,0.0,0,5.0044136,0.0,0.35404563,56.54261,5.5086117,488.75992,-9.2059517
2602,2602,212.0432,6.3492708,4.4945884,0.0,0,4.9837933,0.0,0.35554558,56.662121,5.4860373,488.62592,-9.2049265
2603,2603,212.0434,6.3756847,4.5150595,0.0,0,4.9631734,0.0,0.35814786,56.722233,5.4630413,488.49188,-9.204895
2604,2604,212.0436,6.3848519,4.5456529,0.0,0,4.942553,0.0,0.36034593,56.661381,5.4412322,488.35785,-9.2053108
2605,2605,212.0438,6.3809552,4.5628281,0.0,0,4.9219332,0.0,0.36194223,56.531696,5.4167643,488.22385,-9.205142
2606,2606,212.044,6.3777614,4.5826302,0.0,0,4.9013133,0.0,0.36461094,56.341663,5.3930798,488.08981,-9.204463
2607,2607,212.0442,6.3793645,4.6123195,0.0,0,4.8806934,0.0,0.36695999,56.241245,5.3705826,487.95578,-9.2043943
2608,2608,212.0444,6.3961749,4.6322589,0.0,0,4.8600731,0.0,0.36840698,56.307583,5.3479862,487.82178,-9.2040339
2609,2609,212.0446,6.4102612,4.6537642,0.0,0,4.8394532,0.0,0.37118515,56.299431,5.3263998,487.68774,-9.2036963
2610,2610,212.0448,6.422852,4.6834526,0.0,0,4.8188334,0.0,0.37395993,56.307831,5.3045564,487.55371,-9.2042313
2611,2611,212.045,6.4513502,4.7035961,0.0,0,4.7982135,0.0,0.37544551,56.410007,5.2817464,487.41968,-9.2048807
2612,2612,212.0452,6.4839964,4.7220755,0.0,0,4.7775931,0.0,0.37788746,56.512299,5.2580914,487.19803,-9.2055025
2613,2613,212.0454,6.5002103,4.7488394,0.0,0,4.7569733,0.0,0.38049844,56.536385,5.2355061,486.84528,-9.205409
2614,2614,212.0456,6.5022111,4.7709889,0.0,0,4.7363534,0.0,0.38195989,56.477745,5.2151613,486.49249,-9.2053757
2615,2615,212.0458,6.504365,4.7896633,0.0,0,4.7157331,0.0,0.38433206,56.361404,5.1933513,486.13971,-9.2057381
2616,2616,212.046,6.5022984,4.812963,0.0,0,4.6951132,0.0,0.3869822,56.188244,5.1692705,485.78693,-9.2052784
2617,2617,212.0462,6.4991145,4.835186,0.0,0,4.6744933,0.0,0.3883698,56.080585,5.1472139,485.43417,-9.205184
2618,2618,212.0464,6.5043507,4.8549733,0.0,0,4.6538734,0.0,0.39056265,56.030125,5.1255488,485.08139,-9.2050133
2619,2619,212.0466,6.5257039,4.8772082,0.0,0,4.6332536,0.0,0.39334327,56.065338,5.1044292,484.72861,-9.2038441
2620,2620,212.0468,6.560523,4.9024992,0.0,0,4.6126332,0.0,0.39509073,56.25676,5.083602,484.37582,-9.2037477
2621,2621,212.047,6.5951533,4.9239297,0.0,0,4.5920129,0.0,0.39724922,56.387466,5.0600948,484.02304,-9.2038965
2622,2622,212.0472,6.6125588,4.9433775,0.0,0,4.571393,0.0,0.39997706,56.378281,5.0366549,483.67029,-9.204031
2623,2623,212.0474,6.6154022,4.9692664,0.0,0,4.5507731,0.0,0.40177602,56.355911,5.0171943,483.3175,-9.2046633
2624,2624,212.0476,6.6102757,4.9915648,0.0,0,4.5305653,0.0,0.40373069,56.233269,4.9939651,482.96472,-9.2053528
2625,2625,212.0478,6.5955458,5.0091171,0.0,0,4.5108557,0.0,0.40647212,55.994358,4.971664,482.61194,-9.2062187
2626,2626,212.048,6.5961547,5.036118,0.0,0,4.4912357,0.0,0.40862823,55.849892,4.9537535,482.25919,-9.2063599
2627,2627,212.0482,6.6133246,5.0596085,0.0,0,4.4716196,0.0,0.41055146,55.809658,4.9312506,481.9064,-9.2060127
2628,2628,212.0484,6.635644,5.0733685,0.0,0,4.4520035,0.0,0.4129568,55.818386,4.9074941,481.55362,-9.2053432
2629,2629,212.0486,6.6590538,5.0978708,0.0,0,4.4323874,0.0,0.41500339,55.878059,4.8862567,481.20084,-9.2049065
2630,2630,212.0488,6.6776848,5.1224422,0.0,0,4.4127712,0.0,0.41671646,55.957253,4.8645363,480.84808,-9.2047157
2631,2631,212.049,6.691226,5.13519,0.0,0,4.3931551,0.0,0.41891947,56.000683,4.8433681,480.4953,-9.2039948
2632,2632,212.0492,6.7048712,5.1583562,0.0,0,4.3735394,0.0,0.42124778,55.996624,4.821167,480.14252,-9.2039747
2633,2633,212.0494,6.7094646,5.1856828,0.0,0,4.3539238,0.0,0.42313656,55.951843,4.7985964,479.78973,-9.2045326
2634,2634,212.0496,6.7065516,5.1993132,0.0,0,4.3343077,0.0,0.42525104,55.816574,4.778091,479.43698,-9.2045918
2635,2635,212.0498,6.7143288,5.2232471,0.0,0,4.3146915,0.0,0.4279424,55.693367,4.7594461,479.0842,-9.2052412
2636,2636,212.05,6.7269483,5.2537713,0.0,0,4.2950759,0.0,0.43007931,55.709354,4.7395792,478.73141,-9.2059689
2637,2637,212.0502,6.7394228,5.2671218,0.0,0,4.2754593,0.0,0.43206903,55.73394,4.717669,478.37863,-9.2061005
2638,2638,212.0504,6.755672,5.2883606,0.0,0,4.2558432,0.0,0.43481126,55.712299,4.6966572,478.02588,-9.2060089
2639,2639,212.0506,6.7776942,5.3165588,0.0,0,4.236227,0.0,0.4367592,55.730637,4.6752973,477.6731,-9.2058744
2640,2640,212.0508,6.794733,5.3277388,0.0,0,4.2166114,0.0,0.43831426,55.766453,4.6533008,477.32031,-9.2058115
2641,2641,212.051,6.8075247,5.3458114,0.0,0,4.1969953,0.0,0.44089264,55.779716,4.6322408,476.96753,-9.2049408
2642,2642,212.0512,6.8212585,5.3739634,0.0,0,4.1773791,0.0,0.44281739,55.787937,4.6127725,476.61478,-9.2045965
2643,2643,212.0514,6.8370819,5.3874722,0.0,0,4.1577635,0.0,0.44423464,55.814754,4.592834,476.26199,-9.2048302
2644,2644,212.0516,6.8446903,5.4048805,0.0,0,4.1381474,0.0,0.44688898,55.740967,4.5727592,475.90921,-9.2046146
2645,2645,212.0518,6.8429017,5.433526,0.0,0,4.1185312,0.0,0.44917092,55.632431,4.5518961,475.55643,-9.2051821
2646,2646,212.052,6.8469892,5.4502091,0.0,0,4.0989156,0.0,0.45065171,55.581795,4.5329075,475.20367,-9.2057467
2647,2647,212.0522,6.8676157,5.4681945,0.0,0,4.0792994,0.0,0.4534103,55.537537,4.5115619,474.85089,-9.2057343
2648,2648,212.0524,6.8943915,5.4963317,0.0,0,4.0596833,0.0,0.45598808,55.606083,4.4915233,474.49811,-9.2052708
2649,2649,212.0526,6.9107084,5.5147519,0.0,0,4.0404615,0.0,0.45733806,55.693256,4.4734378,474.14532,-9.2047129
2650,2650,212.0528,6.9277482,5.5319533,0.0,0,4.0217156,0.0,0.45992109,55.671051,4.4514256,473.79254,-9.2046347
2651,2651,212.053,6.9547539,5.5580688,0.0,0,4.003056,0.0,0.46267256,55.736362,4.4291806,473.43979,-9.2047491
2652,2652,212.0532,6.985518,5.5766726,0.0,0,3.9843993,0.0,0.46395871,55.906029,4.4082975,473.08701,-9.2048521
2653,2653,212.0534,7.0121369,5.592361,0.0,0,3.9657435,0.0,0.46626952,55.946651,4.3864822,472.73422,-9.2046127
2654,2654,212.0536,7.0216212,5.6156855,0.0,0,3.9470873,0.0,0.46896321,55.924423,4.3655224,472.38144,-9.204217
2655,2655,212.0538,7.0152898,5.6368866,0.0,0,3.9284315,0.0,0.47037548,55.884998,4.346559,472.02869,-9.2045918
2656,2656,212.054,7.016006,5.6550288,0.0,0,3.9097755,0.0,0.47277477,55.707676,4.3270354,471.6759,-9.204915
2657,2657,212.0542,7.0274558,5.676259,0.0,0,3.8911195,0.0,0.47560439,55.600868,4.3064299,471.32312,-9.2046633
2658,2658,212.0544,7.0387206,5.6987953,0.0,0,3.8724637,0.0,0.47707742,55.63364,4.2844858,470.97034,-9.2046099
2659,2659,212.0546,7.052124,5.7175336,0.0,0,3.8538074,0.0,0.47927508,55.58762,4.2611079,470.61758,-9.2050877
2660,2660,212.0548,7.0734873,5.7361073,0.0,0,3.8351514,0.0,0.4821485,55.591896,4.240654,470.2648,-9.2049541
2661,2661,212.055,7.1000261,5.7600808,0.0,0,3.8164957,0.0,0.48381859,55.696167,4.2227612,469.91202,-9.2044716
2662,2662,212.0552,7.1220798,5.7791572,0.0,0,3.7978394,0.0,0.48571226,55.703457,4.2045107,469.63391,-9.2051382
2663,2663,212.0554,7.1336322,5.7931376,0.0,0,3.7791834,0.0,0.48827499,55.676991,4.1847434,469.43027,-9.2054119
2664,2664,212.0556,7.1390696,5.8167429,0.0,0,3.7605274,0.0,0.49006462,55.660198,4.1644959,469.22662,-9.2050085
2665,2665,212.0558,7.1441894,5.8377056,0.0,0,3.7418714,0.0,0.49196357,55.613716,4.1467657,469.02298,-9.2047024
2666,2666,212.056,7.1541128,5.8511152,0.0,0,3.7232156,0.0,0.49457684,55.548519,4.1257734,468.81934,-9.2039232
2667,2667,212.0562,7.1651564,5.8757181,0.0,0,3.7045596,0.0,0.49662682,55.548496,4.1039786,468.61569,-9.2031898
2668,2668,212.0564,7.1749306,5.8986554,0.0,0,3.6859035,0.0,0.49844286,55.511349,4.0828466,468.41205,-9.2026167
2669,2669,212.0566,7.1928105,5.9103603,0.0,0,3.6672475,0.0,0.50093293,55.452923,4.0638423,468.2084,-9.2026052
2670,2670,212.0568,7.228848,5.9342713,0.0,0,3.6485915,0.0,0.50332808,55.542953,4.0461321,468.00476,-9.2032404
2671,2671,212.057,7.2590547,5.9609532,0.0,0,3.6299353,0.0,0.50524807,55.701275,4.0278711,467.80112,-9.2034159
2672,2672,212.0572,7.2721086,5.9729838,0.0,0,3.6112795,0.0,0.50755012,55.748272,4.0077901,467.59747,-9.2039623
2673,2673,212.0574,7.2775455,5.9952025,0.0,0,3.5926235,0.0,0.5101499,55.607494,3.987637,467.39383,-9.2045336
2674,2674,212.0576,7.2852435,6.0218692,0.0,0,3.5743403,0.0,0.51207316,55.562405,3.9673245,467.19019,-9.2045679
2675,2675,212.0578,7.2941556,6.0325198,0.0,0,3.5565073,0.0,0.5141204,55.563473,3.945281,466.98654,-9.2046051
2676,2676,212.058,7.3025804,6.0518799,0.0,0,3.5387557,0.0,0.51680344,55.45919,3.9273469,466.7829,-9.2044544
2677,2677,212.0582,7.3127432,6.0778642,0.0,0,3.5210075,0.0,0.5185501,55.378635,3.9098418,466.57925,-9.2050781
2678,2678,212.0584,7.32265,6.0873876,0.0,0,3.5032594,0.0,0.52014357,55.34145,3.8914988,466.37561,-9.2055416
2679,2679,212.0586,7.3454986,6.1046271,0.0,0,3.4855113,0.0,0.52285945,55.383446,3.872211,466.17197,-9.2049274
2680,2680,212.0588,7.3755417,6.1330266,0.0,0,3.4677634,0.0,0.52485418,55.535378,3.8518853,465.96832,-9.2042389
2681,2681,212.059,7.4005404,6.1459079,0.0,0,3.4500155,0.0,0.52638274,55.654758,3.8340771,465.76468,-9.204216
2682,2682,212.0592,7.4204736,6.1627626,0.0,0,3.4322677,0.0,0.52924627,55.632561,3.8155298,465.56104,-9.2044401
2683,2683,212.0594,7.4351411,6.1904154,0.0,0,3.4145195,0.0,0.53147876,55.627956,3.7959847,465.35739,-9.2037935
2684,2684,212.0596,7.4367528,6.2046313,0.0,0,3.3967714,0.0,0.53286844,55.573643,3.7768939,465.15375,-9.2039413
2685,2685,212.0598,7.434113,6.2223377,0.0,0,3.3790233,0.0,0.53588557,55.354282,3.7577407,464.9501,-9.2045927
2686,2686,212.06,7.4398408,6.2506838,0.0,0,3.3612754,0.0,0.53856903,55.252918,3.738837,464.74646,-9.2044439
2687,2687,212.0602,7.458128,6.267035,0.0,0,3.3435276,0.0,0.54000586,55.320084,3.7187216,464.54282,-9.2037582
2688,2688,212.0604,7.4840002,6.2818117,0.0,0,3.3257794,0.0,0.54276085,55.314716,3.7018375,464.33917,-9.2035427
2689,2689,212.0606,7.5108862,6.3059545,0.0,0,3.3080316,0.0,0.54527175,55.374928,3.6832526,464.13553,-9.2035179
2690,2690,212.0608,7.5372448,6.3221035,0.0,0,3.2902834,0.0,0.54630762,55.532745,3.6627102,463.93188,-9.2032909
2691,2691,212.061,7.5624433,6.3352695,0.0,0,3.2725353,0.0,0.54872078,55.589722,3.6457076,463.72824,-9.2037687
2692,2692,212.0612,7.5843625,6.3575687,0.0,0,3.2547872,0.0,0.55141163,55.619167,3.6269691,463.5246,-9.2041311
2693,2693,212.0614,7.5954633,6.3758812,0.0,0,3.2370393,0.0,0.55254233,55.717098,3.6075513,463.32095,-9.2046185
2694,2694,212.0616,7.5951872,6.3898435,0.0,0,3.2192914,0.0,0.55481142,55.601315,3.5893254,463.11731,-9.2049246
2695,2695,212.0618,7.5957923,6.409698,0.0,0,3.2015433,0.0,0.5576185,55.390453,3.5715826,462.91367,-9.2053928
2696,2696,212.062,7.6052904,6.4306369,0.0,0,3.1837955,0.0,0.55898035,55.378304,3.5529213,462.71002,-9.2056208
2697,2697,212.0622,7.6316857,6.4477053,0.0,0,3.1660473,0.0,0.56134319,55.377815,3.5333178,462.50638,-9.2054482
2698,2698,212.0624,7.6632051,6.4668441,0.0,0,3.1482995,0.0,0.56437349,55.415291,3.5134435,462.30273,-9.2051811
2699,2699,212.0626,7.681273,6.488843,0.0,0,3.1309061,0.0,0.56589252,55.508259,3.495543,462.09909,-9.2041073
2700,2700,212.0628,7.7062569,6.5059586,0.0,0,3.1139412,0.0,0.56793588,55.539474,3.47754,461.89545,-9.2040367
2701,2701,212.063,7.7411385,6.5217366,0.0,0,3.0970535,0.0,0.57082611,55.590221,3.4583061,461.6918,-9.2040062
2702,2702,212.0632,7.7638121,6.5458388,0.0,0,3.0801694,0.0,0.57271701,55.664856,3.4418135,461.48816,-9.2039757
2703,2703,212.0634,7.761692,6.5656805,0.0,0,3.0632856,0.0,0.57477695,55.605751,3.4243882,461.28452,-9.2044859
2704,2704,212.0636,7.7542143,6.577879,0.0,0,3.0464017,0.0,0.57755888,55.460442,3.4053931,461.08087,-9.2038965
2705,2705,212.0638,7.7590141,6.5992808,0.0,0,3.0295177,0.0,0.57948297,55.34745,3.3873434,460.87723,-9.2038765
2706,2706,212.064,7.771769,6.6191759,0.0,0,3.0126336,0.0,0.58109623,55.271442,3.3693135,460.67358,-9.2047052
2707,2707,212.0642,7.7920613,6.6295238,0.0,0,2.9957495,0.0,0.58356106,55.277458,3.3508668,460.46994,-9.2047844
2708,2708,212.0644,7.8234515,6.6515784,0.0,0,2.9788656,0.0,0.58582366,55.387432,3.3313391,460.2663,-9.2046099
2709,2709,212.0646,7.8563757,6.6747789,0.0,0,2.9619818,0.0,0.58755827,55.540096,3.3124912,460.06265,-9.2048693
2710,2710,212.0648,7.8870444,6.6840644,0.0,0,2.9450977,0.0,0.58986843,55.623661,3.2949004,459.85901,-9.2048283
2711,2711,212.065,7.9109492,6.7041354,0.0,0,2.9282134,0.0,0.59222883,55.662056,3.2780445,459.65536,-9.2041273
2712,2712,212.0652,7.9200854,6.7287712,0.0,0,2.9113293,0.0,0.59390748,55.662827,3.25896,459.23334,-9.2034874
2713,2713,212.0654,7.9204979,6.7377176,0.0,0,2.8944454,0.0,0.59601414,55.556458,3.2408214,458.66608,-9.2034721
2714,2714,212.0656,7.929337,6.7563453,0.0,0,2.8775616,0.0,0.59875238,55.444855,3.2238247,458.09879,-9.203927
2715,2715,212.0658,7.9435973,6.7820621,0.0,0,2.8606775,0.0,0.60054255,55.427021,3.2058616,457.53152,-9.2042303
2716,2716,212.066,7.9650836,6.7913804,0.0,0,2.8437934,0.0,0.60237932,55.484299,3.1876955,456.96426,-9.2037077
2717,2717,212.0662,8.0006247,6.8092246,0.0,0,2.8269095,0.0,0.60535932,55.537224,3.16945,456.39697,-9.2033997
2718,2718,212.0664,8.0331554,6.8362298,0.0,0,2.8100252,0.0,0.60733575,55.598377,3.1516621,455.82971,-9.2040958
2719,2719,212.0666,8.0524731,6.8469076,0.0,0,2.7931414,0.0,0.60898769,55.671696,3.1353471,455.26245,-9.2038574
2720,2720,212.0668,8.0731421,6.8639398,0.0,0,2.7762575,0.0,0.61207175,55.720306,3.1193981,454.69516,-9.2031469
2721,2721,212.067,8.0941601,6.8918357,0.0,0,2.7593734,0.0,0.6142444,55.752792,3.0993621,454.1279,-9.2031164
2722,2722,212.0672,8.0987501,6.9032712,0.0,0,2.7424896,0.0,0.6155901,55.713879,3.0807943,453.56064,-9.2033901
2723,2723,212.0674,8.1029472,6.917706,0.0,0,2.7256055,0.0,0.61854696,55.596546,3.062938,452.99335,-9.2035904
2724,2724,212.0676,8.1129103,6.9434538,0.0,0,2.7090597,0.0,0.62097442,55.544899,3.0436883,452.42609,-9.2037392
2725,2725,212.0678,8.1297951,6.9560184,0.0,0,2.6929226,0.0,0.6221863,55.568954,3.0274935,451.85883,-9.2032318
2726,2726,212.068,8.156785,6.9688244,0.0,0,2.6768591,0.0,0.62494206,55.57526,3.0115025,451.29153,-9.2033367
2727,2727,212.0682,8.1813478,6.9926634,0.0,0,2.660799,0.0,0.6274699,55.612785,2.9910059,450.72427,-9.2037582
2728,2728,212.0684,8.1992483,7.0068154,0.0,0,2.6447389,0.0,0.62842458,55.686707,2.9739661,450.15701,-9.2032576
2729,2729,212.0686,8.2261353,7.0182829,0.0,0,2.6286788,0.0,0.63093638,55.726063,2.9589162,449.58972,-9.2032394
2730,2730,212.0688,8.256567,7.0404372,0.0,0,2.6126189,0.0,0.63369793,55.759735,2.9411571,449.02246,-9.2037535
2731,2731,212.069,8.2764978,7.0573969,0.0,0,2.5965588,0.0,0.63478333,55.816242,2.9244707,448.4552,-9.203186
2732,2732,212.0692,8.297905,7.0706272,0.0,0,2.5804987,0.0,0.63728237,55.825748,2.907258,447.88791,-9.2020845
2733,2733,212.0694,8.3187695,7.091846,0.0,0,2.5644388,0.0,0.64031863,55.784061,2.8908005,447.32065,-9.2024727
2734,2734,212.0696,8.330308,7.111299,0.0,0,2.5483787,0.0,0.64163351,55.81176,2.8739207,446.75339,-9.2030725
2735,2735,212.0698,8.3443089,7.1264858,0.0,0,2.5323186,0.0,0.64400887,55.80109,2.8548217,446.1861,-9.2033682
2736,2736,212.07,8.3624315,7.144114,0.0,0,2.5162587,0.0,0.64698434,55.697483,2.8389041,445.61884,-9.2036867
2737,2737,212.0702,8.3790455,7.1640267,0.0,0,2.5001988,0.0,0.64842182,55.692822,2.8245981,445.05157,-9.2046776
2738,2738,212.0704,8.4006748,7.1796851,0.0,0,2.4841387,0.0,0.6506319,55.736996,2.8094206,444.48428,-9.2045622
2739,2739,212.0706,8.4295521,7.1944208,0.0,0,2.4680789,0.0,0.65358502,55.774841,2.7940466,443.91702,-9.2035961
2740,2740,212.0708,8.454381,7.2156963,0.0,0,2.4520187,0.0,0.6551199,55.864399,2.7743301,443.34976,-9.2040739
2741,2741,212.071,8.4772425,7.2312884,0.0,0,2.4359589,0.0,0.65694702,55.904621,2.7555337,442.78247,-9.2043676
2742,2742,212.0712,8.4936543,7.2425909,0.0,0,2.419899,0.0,0.65985304,55.885971,2.7399986,442.21521,-9.204421
2743,2743,212.0714,8.5022678,7.2646151,0.0,0,2.4038389,0.0,0.66172874,55.868561,2.72247,441.64795,-9.2046118
2744,2744,212.0716,8.5169573,7.282824,0.0,0,2.3877788,0.0,0.66344357,55.817223,2.7053084,441.08066,-9.2041445
2745,2745,212.0718,8.5368919,7.2927008,0.0,0,2.3717189,0.0,0.66620916,55.773598,2.6892679,440.5134,-9.203476
2746,2746,212.072,8.5648537,7.314806,0.0,0,2.3556588,0.0,0.66846079,55.854168,2.6714568,439.94614,-9.203907
2747,2747,212.0722,8.5905027,7.3358259,0.0,0,2.3395987,0.0,0.67019594,55.945518,2.6548154,439.37885,-9.2039185
2748,2748,212.0724,8.6156807,7.3443594,0.0,0,2.3235388,0.0,0.67269927,55.986454,2.6384664,438.81158,-9.2037687
2749,2749,212.0726,8.648387,7.3644342,0.0,0,2.3078008,0.0,0.67517221,56.037563,2.6205456,438.24432,-9.2036762
2750,2750,212.0728,8.6749725,7.3869767,0.0,0,2.2924514,0.0,0.6768294,56.075897,2.6045139,437.67703,-9.2036171
2751,2751,212.073,8.6971626,7.394258,0.0,0,2.2771723,0.0,0.67894167,56.131683,2.5885844,437.10977,-9.203927
2752,2752,212.0732,8.7180223,7.4124789,0.0,0,2.2618961,0.0,0.6816256,56.135433,2.5719411,436.54251,-9.2041826
2753,2753,212.0734,8.7307167,7.4371405,0.0,0,2.2466199,0.0,0.68335909,56.145622,2.5558622,435.97522,-9.2041817
2754,2754,212.0736,8.746892,7.4443007,0.0,0,2.2313442,0.0,0.68522453,56.124844,2.5384586,435.40796,-9.2039576
2755,2755,212.0738,8.7738791,7.4596534,0.0,0,2.2160683,0.0,0.68809265,56.074013,2.5221813,434.8407,-9.2042799
2756,2756,212.074,8.7978516,7.4839153,0.0,0,2.2007923,0.0,0.68986648,56.124832,2.5067096,434.27341,-9.2044325
2757,2757,212.0742,8.8177528,7.4919415,0.0,0,2.1855161,0.0,0.69145131,56.184689,2.490037,433.70615,-9.2044449
2758,2758,212.0744,8.8439541,7.5081992,0.0,0,2.1702402,0.0,0.69461244,56.194889,2.4741395,433.13889,-9.2040348
2759,2759,212.0746,8.8771658,7.5351915,0.0,0,2.1549642,0.0,0.69683427,56.249985,2.4577801,432.57159,-9.2035561
2760,2760,212.0748,8.910759,7.5459156,0.0,0,2.1396883,0.0,0.69834048,56.380405,2.4401011,432.00433,-9.2033062
2761,2761,212.075,8.9427185,7.5602474,0.0,0,2.1244121,0.0,0.70149016,56.422138,2.4228187,431.43707,-9.2031355
2762,2762,212.0752,8.9590282,7.585289,0.0,0,2.1091361,0.0,0.70384216,56.403748,2.4070404,431.0123,-9.2036667
2763,2763,212.0754,8.9703054,7.5962234,0.0,0,2.0938601,0.0,0.70504451,56.430561,2.3910506,430.64844,-9.2038698
2764,2764,212.0756,8.9862461,7.6084914,0.0,0,2.0785842,0.0,0.7080344,56.337753,2.3748167,430.28458,-9.2035027
2765,2765,212.0758,9.0058136,7.6324582,0.0,0,2.0633082,0.0,0.71058422,56.289497,2.3550966,429.92072,-9.2033997
2766,2766,212.076,9.0293646,7.6452932,0.0,0,2.0480323,0.0,0.71153277,56.385605,2.3385382,429.55685,-9.2037172
2767,2767,212.0762,9.0547428,7.6568561,0.0,0,2.0327563,0.0,0.71434665,56.399261,2.3252096,429.19299,-9.2037554
2768,2768,212.0764,9.0925179,7.6791,0.0,0,2.0174804,0.0,0.71722001,56.466099,2.3101642,428.82913,-9.2029133
2769,2769,212.0766,9.1346254,7.6944346,0.0,0,2.0022042,0.0,0.71826214,56.626347,2.2940965,428.46527,-9.2021427
2770,2770,212.0768,9.1697721,7.7062731,0.0,0,1.986928,0.0,0.72089183,56.692738,2.279016,428.10141,-9.2018299
2771,2771,212.077,9.1968832,7.7260771,0.0,0,1.971652,0.0,0.72384983,56.733902,2.2633619,427.73755,-9.2016573
2772,2772,212.0772,9.2152452,7.7432203,0.0,0,1.956376,0.0,0.72490931,56.79702,2.246103,427.37369,-9.2020788
2773,2773,212.0774,9.2313309,7.7551908,0.0,0,1.9411,0.0,0.7273854,56.749481,2.2320786,427.00983,-9.2028379
2774,2774,212.0776,9.2401848,7.7724805,0.0,0,1.9261296,0.0,0.73051149,56.663662,2.2156024,426.64597,-9.2033434
2775,2775,212.0778,9.255249,7.7913194,0.0,0,1.9115278,0.0,0.73178649,56.685619,2.1983259,426.2821,-9.2038326
2776,2776,212.078,9.2913866,7.8052049,0.0,0,1.8969928,0.0,0.73407143,56.740089,2.1833451,425.91824,-9.2036686
2777,2777,212.0782,9.328186,7.8204818,0.0,0,1.8824607,0.0,0.73729962,56.75885,2.1662059,425.55438,-9.2032032
2778,2778,212.0784,9.3637667,7.8404083,0.0,0,1.8679286,0.0,0.73878914,56.899708,2.1490855,425.19052,-9.202508
2779,2779,212.0786,9.403573,7.8557158,0.0,0,1.8533967,0.0,0.74078345,57.017792,2.1330214,424.82666,-9.2018881
2780,2780,212.0788,9.4345293,7.8685179,0.0,0,1.8388647,0.0,0.74395204,57.025414,2.1164992,424.4628,-9.2021351
2781,2781,212.079,9.4554796,7.8892245,0.0,0,1.8243327,0.0,0.7457431,57.080639,2.1008921,424.09894,-9.2020569
2782,2782,212.0792,9.4763994,7.9046102,0.0,0,1.8098006,0.0,0.74754393,57.061974,2.0846796,423.73508,-9.2023335
2783,2783,212.0794,9.4867735,7.9136496,0.0,0,1.7952687,0.0,0.75041318,56.964817,2.0677192,423.37122,-9.2030115
2784,2784,212.0796,9.5029144,7.934,0.0,0,1.7807367,0.0,0.7523849,56.989315,2.0524993,423.00735,-9.2032413
2785,2785,212.0798,9.5302467,7.9518023,0.0,0,1.7662047,0.0,0.75393105,57.080574,2.037483,422.64349,-9.2032623
2786,2786,212.08,9.5586786,7.9589081,0.0,0,1.7516727,0.0,0.75649339,57.10397,2.020309,422.27963,-9.2036467
2787,2787,212.0802,9.5972891,7.9787312,0.0,0,1.7371407,0.0,0.75893086,57.187363,2.0048022,421.91577,-9.2036047
2788,2788,212.0804,9.6436367,8.0002966,0.0,0,1.7226087,0.0,0.76070678,57.33276,1.9901638,421.55191,-9.2024145
2789,2789,212.0806,9.6871367,8.0072985,0.0,0,1.7080767,0.0,0.76311094,57.419807,1.974624,421.18805,-9.2014017
2790,2790,212.0808,9.7211533,8.026268,0.0,0,1.6935447,0.0,0.76594329,57.489021,1.9569426,420.82419,-9.2012672
2791,2791,212.081,9.7407999,8.0506506,0.0,0,1.6790128,0.0,0.76787162,57.536896,1.9424891,420.46033,-9.2021151
2792,2792,212.0812,9.7479267,8.0582552,0.0,0,1.6644807,0.0,0.77008939,57.458256,1.9290609,420.09647,-9.2028141
2793,2793,212.0814,9.7638216,8.0749693,0.0,0,1.6499487,0.0,0.77319688,57.349049,1.9127579,419.7326,-9.2031584
2794,2794,212.0816,9.7864275,8.0990629,0.0,0,1.6354166,0.0,0.77508849,57.343925,1.898144,419.36874,-9.203371
2795,2795,212.0818,9.8111429,8.1054592,0.0,0,1.6208847,0.0,0.7766484,57.403568,1.8821419,419.00488,-9.2039709
2796,2796,212.082,9.8427715,8.1187706,0.0,0,1.6063527,0.0,0.77957547,57.436218,1.8644236,418.64102,-9.2043705
2797,2797,212.0822,9.8777742,8.1417465,0.0,0,1.5918207,0.0,0.78143924,57.53714,1.8487251,418.27716,-9.2038336
2798,2798,212.0824,9.9184361,8.1486435,0.0,0,1.5772886,0.0,0.78267831,57.6959,1.8342319,417.9133,-9.2032766
2799,2799,212.0826,9.9517136,8.1616259,0.0,0,1.5630474,0.0,0.78583741,57.730431,1.8182395,417.54944,-9.2027903
2800,2800,212.0828,9.9809923,8.1863413,0.0,0,1.549157,0.0,0.78823519,57.780109,1.8040493,417.18558,-9.2022066
2801,2801,212.083,10.006221,8.1956701,0.0,0,1.5353301,0.0,0.78951252,57.821487,1.7897437,416.82172,-9.2022266
2802,2802,212.0832,10.011799,8.2073259,0.0,0,1.521506,0.0,0.79260635,57.697166,1.774074,416.45786,-9.202713
2803,2803,212.0834,10.023223,8.2318878,0.0,0,1.507682,0.0,0.79523164,57.627289,1.7604684,416.09399,-9.2029533
2804,2804,212.0836,10.054047,8.2438583,0.0,0,1.493858,0.0,0.79634488,57.689396,1.7456864,415.73013,-9.2031155
2805,2805,212.0838,10.085578,8.2548456,0.0,0,1.480034,0.0,0.79949248,57.690071,1.7307755,415.3663,-9.2036629
2806,2806,212.084,10.121164,8.2774572,0.0,0,1.46621,0.0,0.80245674,57.741169,1.7190061,415.00244,-9.2038956
2807,2807,212.0842,10.163198,8.2906294,0.0,0,1.452386,0.0,0.80328804,57.943787,1.7047267,414.63858,-9.2040586
2808,2808,212.0844,10.206356,8.2999678,0.0,0,1.438562,0.0,0.80604208,58.043472,1.6887413,414.27472,-9.2037659
2809,2809,212.0846,10.250323,8.3186893,0.0,0,1.424738,0.0,0.80896777,58.111149,1.6749594,413.91086,-9.2030668
2810,2810,212.0848,10.285339,8.3332939,0.0,0,1.4109141,0.0,0.80977064,58.249611,1.6612277,413.547,-9.2023592
2811,2811,212.085,10.300649,8.3434534,0.0,0,1.3970901,0.0,0.81233859,58.199451,1.6460674,413.18314,-9.2021942
2812,2812,212.0852,10.313445,8.3608398,0.0,0,1.3832661,0.0,0.81553423,58.079437,1.6300781,412.79895,-9.2021275
2813,2813,212.0854,10.333831,8.3784952,0.0,0,1.3694421,0.0,0.81657207,58.11829,1.616384,412.40973,-9.2022381
2814,2814,212.0856,10.358936,8.3901644,0.0,0,1.355618,0.0,0.81887394,58.138081,1.6029102,412.02048,-9.2029867
2815,2815,212.0858,10.397262,8.4052048,0.0,0,1.341794,0.0,0.82225007,58.131912,1.5883827,411.63126,-9.2030449
2816,2816,212.086,10.434447,8.4241819,0.0,0,1.3279701,0.0,0.82364511,58.244762,1.5720906,411.24203,-9.2031307
2817,2817,212.0862,10.470942,8.4373302,0.0,0,1.3141462,0.0,0.8257404,58.337582,1.5552129,410.85281,-9.2031336
2818,2818,212.0864,10.510639,8.4488688,0.0,0,1.3003221,0.0,0.82901484,58.385662,1.5415529,410.46356,-9.2029276
2819,2819,212.0866,10.546365,8.4678545,0.0,0,1.2864981,0.0,0.83064479,58.503746,1.5288171,410.07434,-9.2022581
2820,2820,212.0868,10.573251,8.481781,0.0,0,1.2726741,0.0,0.83242631,58.540199,1.5128138,409.68512,-9.2018108
2821,2821,212.087,10.590275,8.4895515,0.0,0,1.2588501,0.0,0.8353191,58.471466,1.4975119,409.29587,-9.2018604
2822,2822,212.0872,10.617578,8.5090218,0.0,0,1.2450261,0.0,0.83710802,58.507381,1.4826185,408.90665,-9.2018576
2823,2823,212.0874,10.651755,8.5251694,0.0,0,1.2312021,0.0,0.83863449,58.588734,1.4675632,408.51743,-9.2024384
2824,2824,212.0876,10.680382,8.5302458,0.0,0,1.2176557,0.0,0.84125066,58.61237,1.4546736,408.12817,-9.2028427
2825,2825,212.0878,10.716597,8.5480309,0.0,0,1.2044444,0.0,0.84343755,58.66362,1.4408864,407.73895,-9.2028236
2826,2826,212.088,10.760124,8.5672741,0.0,0,1.1912937,0.0,0.84502429,58.775745,1.4253206,407.34973,-9.2028074
2827,2827,212.0882,10.799621,8.5734653,0.0,0,1.1781455,0.0,0.84762603,58.849335,1.4095126,406.96048,-9.2021503
2828,2828,212.0884,10.838483,8.5911674,0.0,0,1.1649976,0.0,0.85032922,58.924801,1.3946395,406.57126,-9.2018385
2829,2829,212.0886,10.876666,8.6131105,0.0,0,1.1518495,0.0,0.85204148,59.032619,1.3810838,406.18204,-9.202137
2830,2830,212.0888,10.911464,8.6185713,0.0,0,1.1387014,0.0,0.85433638,59.076077,1.3669608,405.79282,-9.2025299
2831,2831,212.089,10.938641,8.6348057,0.0,0,1.1255535,0.0,0.85748464,59.028904,1.3535721,405.40356,-9.2023449
2832,2832,212.0892,10.956549,8.6583138,0.0,0,1.1124055,0.0,0.85943919,59.024483,1.3387128,405.01434,-9.2023659
2833,2833,212.0894,10.980965,8.6628551,0.0,0,1.0992575,0.0,0.86117452,59.05204,1.3237951,404.62512,-9.2022018
2834,2834,212.0896,11.01196,8.6760254,0.0,0,1.0861095,0.0,0.86428583,59.014332,1.309882,404.23587,-9.2014952
2835,2835,212.0898,11.044549,8.6989517,0.0,0,1.0729614,0.0,0.86608988,59.10498,1.2963721,403.84665,-9.2012777
2836,2836,212.09,11.07993,8.703824,0.0,0,1.0598134,0.0,0.86732596,59.240952,1.283651,403.45743,-9.2012253
2837,2837,212.0902,11.119619,8.7155914,0.0,0,1.0466654,0.0,0.87062258,59.275105,1.268751,403.06818,-9.2012157
2838,2838,212.0904,11.169694,8.7390013,0.0,0,1.0335175,0.0,0.87271935,59.403355,1.2550513,402.67896,-9.2012501
2839,2839,212.0906,11.212642,8.745862,0.0,0,1.0203694,0.0,0.87376982,59.533512,1.2411441,402.28973,-9.2014732
2840,2840,212.0908,11.236539,8.7556591,0.0,0,1.0072215,0.0,0.87700981,59.495094,1.2271762,401.90048,-9.2015057
2841,2841,212.091,11.264383,8.7779036,0.0,0,0.99407339,0.0,0.87937665,59.501507,1.2140435,401.51126,-9.2015448
2842,2842,212.0912,11.302933,8.7875957,0.0,0,0.98092538,0.0,0.8803069,59.615425,1.2001437,401.12204,-9.2020111
2843,2843,212.0914,11.338654,8.7973986,0.0,0,0.96777743,0.0,0.88353634,59.617836,1.1858578,400.73279,-9.2021914
2844,2844,212.0916,11.37148,8.8194513,0.0,0,0.95462942,0.0,0.88640463,59.647297,1.1714045,400.34357,-9.2024517
2845,2845,212.0918,11.407954,8.8317728,0.0,0,0.94148141,0.0,0.88726723,59.771267,1.1569047,399.95435,-9.2024565
2846,2846,212.092,11.451197,8.8412657,0.0,0,0.92833346,0.0,0.89036685,59.80714,1.1446844,399.56512,-9.2016668
2847,2847,212.0922,11.497795,8.8616514,0.0,0,0.91518545,0.0,0.89356369,59.880581,1.1333997,399.17587,-9.2007046
2848,2848,212.0924,11.545008,8.874896,0.0,0,0.90203744,0.0,0.89441109,60.063759,1.120036,398.78665,-9.2001505
2849,2849,212.0926,11.591538,8.8829727,0.0,0,0.8891539,0.0,0.89699334,60.125881,1.1058291,398.39743,-9.2004652
2850,2850,212.0928,11.625734,8.8997278,0.0,0,0.87658954,0.0,0.90014535,60.110577,1.0938346,398.00818,-9.2005291
2851,2851,212.093,11.652849,8.9142828,0.0,0,0.86408287,0.0,0.90093398,60.237789,1.0805742,397.61896,-9.2008858
2852,2852,212.0932,11.677621,8.9228592,0.0,0,0.85157877,0.0,0.90313184,60.233097,1.0663884,397.22974,-9.2014723
2853,2853,212.0934,11.703015,8.9366331,0.0,0,0.83907479,0.0,0.90643674,60.134956,1.0534091,396.84048,-9.2022152
2854,2854,212.0936,11.740688,8.9539986,0.0,0,0.82657075,0.0,0.90752977,60.259098,1.0389361,396.45126,-9.2024107
2855,2855,212.0938,11.780795,8.9646215,0.0,0,0.81406677,0.0,0.90960318,60.363781,1.0232916,396.06204,-9.2026854
2856,2856,212.094,11.822364,8.9756804,0.0,0,0.80156279,0.0,0.91292357,60.396637,1.0101279,395.67279,-9.2031441
2857,2857,212.0942,11.872046,8.9941406,0.0,0,0.7890588,0.0,0.91438174,60.543987,0.99706656,395.28357,-9.2029276
2858,2858,212.0944,11.92203,9.0069561,0.0,0,0.77655482,0.0,0.91624272,60.680859,0.9838683,394.89435,-9.2023506
2859,2859,212.0946,11.964152,9.0156307,0.0,0,0.76405078,0.0,0.91958451,60.691669,0.97060078,394.50513,-9.2009087
2860,2860,212.0948,11.995572,9.034997,0.0,0,0.75154674,0.0,0.92161995,60.731304,0.95573205,394.11588,-9.2000475
2861,2861,212.095,12.024287,9.0508318,0.0,0,0.73904276,0.0,0.92347431,60.776966,0.94193488,393.72665,-9.1998072
2862,2862,212.0952,12.062533,9.0576963,0.0,0,0.72653878,0.0,0.92658448,60.776913,0.92675054,393.55783,-9.2001314
2863,2863,212.0954,12.104865,9.0763588,0.0,0,0.7140348,0.0,0.92880499,60.858017,0.91202867,393.41333,-9.2008314
2864,2864,212.0956,12.150983,9.0927162,0.0,0,0.70153075,0.0,0.93028933,60.986839,0.89884418,393.26883,-9.2012844
2865,2865,212.0958,12.196486,9.0964231,0.0,0,0.68902677,0.0,0.93284816,61.01638,0.88678014,393.12433,-9.201684
2866,2866,212.096,12.23416,9.1128187,0.0,0,0.67652279,0.0,0.93528652,61.074997,0.87485361,392.97983,-9.2023964
2867,2867,212.0962,12.284976,9.131856,0.0,0,0.66401881,0.0,0.93670779,61.281464,0.86156493,392.83533,-9.2030087
2868,2868,212.0964,12.342073,9.1351719,0.0,0,0.65151483,0.0,0.93899471,61.397541,0.84969956,392.69083,-9.2036057
2869,2869,212.0966,12.385785,9.1503277,0.0,0,0.63901079,0.0,0.94197923,61.449413,0.83489215,392.54633,-9.2035542
2870,2870,212.0968,12.429485,9.1720457,0.0,0,0.62650675,0.0,0.94370013,61.560886,0.81991971,392.40182,-9.2029762
2871,2871,212.097,12.461679,9.1758204,0.0,0,0.61400276,0.0,0.9457472,61.596928,0.80819446,392.25732,-9.2020216
2872,2872,212.0972,12.478927,9.1899281,0.0,0,0.60149878,0.0,0.94913954,61.509995,0.79276186,392.11282,-9.2007084
2873,2873,212.0974,12.513,9.2133179,0.0,0,0.5889948,0.0,0.95097369,61.528648,0.77954233,391.96835,-9.2003117
2874,2874,212.0976,12.559238,9.2172146,0.0,0,0.57673877,0.0,0.95246291,61.633884,0.76811486,391.82385,-9.2004938
2875,2875,212.0978,12.604151,9.2286501,0.0,0,0.5647822,0.0,0.95585382,61.640564,0.75373751,391.67935,-9.2010183
2876,2876,212.098,12.649031,9.2510576,0.0,0,0.55287975,0.0,0.9576993,61.747353,0.73925763,391.53485,-9.2017269
2877,2877,212.0982,12.70045,9.2550755,0.0,0,0.54097968,0.0,0.95871174,61.916786,0.72650325,391.39035,-9.2016993
2878,2878,212.0984,12.758081,9.2649403,0.0,0,0.52907968,0.0,0.96214014,61.978016,0.71253705,391.24585,-9.201148
2879,2879,212.0986,12.808158,9.2875195,0.0,0,0.51717961,0.0,0.96458179,62.096695,0.69797158,391.10135,-9.2012358
2880,2880,212.0988,12.84992,9.2953176,0.0,0,0.5052796,0.0,0.96556026,62.224865,0.68675643,390.95685,-9.2014408
2881,2881,212.099,12.877306,9.3045502,0.0,0,0.49337962,0.0,0.96891588,62.178249,0.67433637,390.81235,-9.201498
2882,2882,212.0992,12.906328,9.326292,0.0,0,0.48147961,0.0,0.97177708,62.167622,0.66136587,390.66785,-9.2015114
2883,2883,212.0994,12.952066,9.3367386,0.0,0,0.46957964,0.0,0.97263819,62.299702,0.64923656,390.52335,-9.2011442
2884,2884,212.0996,12.996895,9.3445454,0.0,0,0.45767963,0.0,0.97586834,62.293541,0.63694483,390.37885,-9.200738
2885,2885,212.0998,13.049274,9.3637638,0.0,0,0.44577962,0.0,0.97882926,62.362946,0.6240412,390.23434,-9.2007904
2886,2886,212.1,13.106143,9.3746738,0.0,0,0.43387961,0.0,0.97929031,62.62672,0.6113286,390.08984,-9.2008095
2887,2887,212.1002,13.162392,9.3812962,0.0,0,0.42197964,0.0,0.9820537,62.724445,0.59873509,389.94537,-9.2003565
2888,2888,212.1004,13.219014,9.3979492,0.0,0,0.41007963,0.0,0.98526186,62.799187,0.58615822,389.80087,-9.1999741
2889,2889,212.1006,13.264444,9.4120655,0.0,0,0.39817962,0.0,0.98596716,62.981113,0.57349503,389.65637,-9.1999378
2890,2890,212.1008,13.295479,9.420577,0.0,0,0.38627961,0.0,0.98869199,62.949989,0.56203586,389.51187,-9.1999502