File: clean data/testID_0229.csv
level_0,index,Time(sec),Force(kN),Jaw(mm),PowAngle(deg),Power(W),Pram,PTemp,Strain,Stress(MPa),Stroke(mm),TC1(C),wedge(mm)
2276,2276,195.3445,0.56536788,0.036531895,0.0,0,8.9459143,0.0,0.0020382057,6.4978433,9.9292612,450.15005,-9.231267
2277,2277,195.3447,1.1703339,0.048047945,0.0,0,8.9166498,0.0,0.0029698741,12.895681,9.887435,450.14587,-9.2320147
2278,2278,195.3449,2.1181757,0.08499977,0.0,0,8.8873854,0.0,0.0053120614,24.232325,9.8519325,450.14166,-9.2320499
2279,2279,195.3451,3.0680997,0.13025901,0.0,0,8.8581219,0.0,0.0079616681,36.375793,9.8199463,450.13748,-9.2307873
2280,2280,195.3453,3.794302,0.15447818,0.0,0,8.8288574,0.0,0.009985528,46.149448,9.7844667,450.1333,-9.2301216
2281,2281,195.3455,4.1566648,0.18731013,0.0,0,8.7995939,0.0,0.012264035,51.592854,9.7424917,450.12909,-9.229908
2282,2282,195.3457,4.2391472,0.25133216,0.0,0,8.7703295,0.0,0.015762094,53.182518,9.6960087,450.12491,-9.228961
2283,2283,195.3459,4.1586289,0.32991779,0.0,0,8.7416534,0.0,0.020988988,52.162979,9.6451054,450.12073,-9.2279463
2284,2284,195.3461,4.0463657,0.4124518,0.0,0,8.7136869,0.0,0.02705076,50.3503,9.5891085,450.11652,-9.2269983
2285,2285,195.3463,4.0423999,0.47742116,0.0,0,8.6858492,0.0,0.031438846,49.740871,9.529582,450.11234,-9.2265625
2286,2286,195.3465,4.0868306,0.51471215,0.0,0,8.6580172,0.0,0.034232516,50.250431,9.4667339,450.10812,-9.2274389
2287,2287,195.3467,4.0568142,0.56357777,0.0,0,8.6301851,0.0,0.037760254,49.958099,9.4065542,450.10394,-9.2286949
2288,2288,195.3469,4.032773,0.63032973,0.0,0,8.6023531,0.0,0.041959405,49.117043,9.3537016,450.09976,-9.229104
2289,2289,195.3471,4.274529,0.67636985,0.0,0,8.5745211,0.0,0.045397479,51.101242,9.3066607,450.09555,-9.2290955
2290,2290,195.3473,4.571496,0.69731212,0.0,0,8.546689,0.0,0.047621511,54.810093,9.2636824,450.09137,-9.2288189
2291,2291,195.3475,4.5212331,0.7078678,0.0,0,8.518857,0.0,0.048305936,55.174133,9.2226791,450.08719,-9.2285385
2292,2292,195.3477,4.2184448,0.72184873,0.0,0,8.491025,0.0,0.048858788,51.928303,9.1814671,450.05273,-9.2278709
2293,2293,195.3479,3.9767518,0.75953698,0.0,0,8.4631929,0.0,0.051561024,48.56929,9.1418848,449.98807,-9.2273512
2294,2294,195.3481,3.9822016,0.80803698,0.0,0,8.4353609,0.0,0.054900281,47.796474,9.1028805,449.9234,-9.2278309
2295,2295,195.3483,4.1750803,0.83446515,0.0,0,8.4075289,0.0,0.056699961,49.614197,9.0679731,449.8587,-9.227993
2296,2296,195.3485,4.3742356,0.84710956,0.0,0,8.3796968,0.0,0.057984177,51.919296,9.0360727,449.79404,-9.2273331
2297,2297,195.3487,4.5760784,0.87140745,0.0,0,8.3518648,0.0,0.05953617,54.360363,8.9994907,449.72937,-9.2270679
2298,2298,195.3489,4.7308097,0.9135499,0.0,0,8.3240328,0.0,0.061947677,56.3377,8.9624567,449.66467,-9.226882
2299,2299,195.3491,4.6698289,0.9701668,0.0,0,8.2962008,0.0,0.066093475,55.950043,8.9269638,449.60001,-9.2269678
2300,2300,195.3493,4.4555836,1.0232357,0.0,0,8.2683687,0.0,0.070133977,53.414116,8.8899107,449.53534,-9.2278414
2301,2301,195.3495,4.3387632,1.0574299,0.0,0,8.2405367,0.0,0.072483189,51.52879,8.8510952,449.47067,-9.2279673
2302,2302,195.3497,4.358151,1.0840487,0.0,0,8.2127056,0.0,0.07458321,51.377541,8.8125868,449.40598,-9.2279778
2303,2303,195.3499,4.3958254,1.119661,0.0,0,8.1848736,0.0,0.077232949,51.670364,8.7743225,449.34131,-9.2279024
2304,2304,195.3501,4.4054246,1.1643093,0.0,0,8.1570406,0.0,0.080039851,51.728317,8.7361317,449.27664,-9.2274065
2305,2305,195.3503,4.4294987,1.2036368,0.0,0,8.1292095,0.0,0.0830779,51.830296,8.7033072,449.21194,-9.2274914
2306,2306,195.3505,4.58181,1.2277641,0.0,0,8.1013775,0.0,0.085358575,53.199162,8.6707659,449.14728,-9.228014
2307,2307,195.3507,4.7419405,1.2464846,0.0,0,8.0735445,0.0,0.086394951,55.137577,8.6367512,449.08261,-9.2266083
2308,2308,195.3509,4.7049079,1.2712616,0.0,0,8.0462675,0.0,0.088059515,55.160522,8.6048269,449.01791,-9.2245369
2309,2309,195.3511,4.5199494,1.3044665,0.0,0,8.0196619,0.0,0.090728372,53.088047,8.5742607,448.95325,-9.2244282
2310,2310,195.3513,4.3945637,1.3434045,0.0,0,7.993176,0.0,0.093206383,51.237705,8.5463524,448.88858,-9.2251139
2311,2311,195.3515,4.4410706,1.3707846,0.0,0,7.9666953,0.0,0.095309898,51.263405,8.5186691,448.82391,-9.2264194
2312,2312,195.3517,4.5770035,1.3836852,0.0,0,7.9402156,0.0,0.096877441,52.636803,8.4937239,448.75922,-9.2278109
2313,2313,195.3519,4.7132268,1.4075583,0.0,0,7.9137354,0.0,0.098207034,54.157879,8.4684238,448.69455,-9.2280664
2314,2314,195.3521,4.8264875,1.4427358,0.0,0,7.8872552,0.0,0.10035962,55.377964,8.442112,448.62988,-9.2279158
2315,2315,195.3523,4.8632922,1.4750985,0.0,0,7.860775,0.0,0.10320385,55.894997,8.4150829,448.56519,-9.2273483
2316,2316,195.3525,4.7777348,1.5090504,0.0,0,7.8342953,0.0,0.10563518,55.093025,8.3864288,448.50052,-9.2274294
2317,2317,195.3527,4.6648178,1.5382268,0.0,0,7.8078156,0.0,0.10752703,53.662888,8.3562164,448.43585,-9.2276583
2318,2318,195.3529,4.6286392,1.5603406,0.0,0,7.7813349,0.0,0.10956362,52.927387,8.3265591,448.37115,-9.2275629
2319,2319,195.3531,4.6369438,1.5935876,0.0,0,7.7548552,0.0,0.1118954,52.809353,8.29778,448.30649,-9.227438
2320,2320,195.3533,4.6287837,1.6268197,0.0,0,7.728375,0.0,0.11405537,52.571648,8.2675552,448.24182,-9.2266569
2321,2321,195.3535,4.6371565,1.6400992,0.0,0,7.7018952,0.0,0.11563598,52.510166,8.239418,448.17712,-9.2265015
2322,2322,195.3537,4.7034197,1.6548058,0.0,0,7.675415,0.0,0.11680812,53.084106,8.2140827,448.11246,-9.226675
2323,2323,195.3539,4.7790709,1.6776165,0.0,0,7.6489348,0.0,0.11793195,53.873558,8.1891031,448.04779,-9.2263813
2324,2324,195.3541,4.7926269,1.6969264,0.0,0,7.6224551,0.0,0.11964822,54.134243,8.1615295,447.98312,-9.2258492
2325,2325,195.3543,4.7235031,1.7266386,0.0,0,7.5959754,0.0,0.12204118,53.42704,8.139576,447.91843,-9.2261305
2326,2326,195.3545,4.6591911,1.7553806,0.0,0,7.5694952,0.0,0.12382326,52.56432,8.1202049,447.85376,-9.2272367
2327,2327,195.3547,4.6950521,1.7624757,0.0,0,7.543015,0.0,0.1248047,52.682194,8.0972147,447.78909,-9.2273293
2328,2328,195.3549,4.7857833,1.7753844,0.0,0,7.5165353,0.0,0.12601814,53.53651,8.0751553,447.7244,-9.2276726
2329,2329,195.3551,4.8510356,1.8029097,0.0,0,7.4900556,0.0,0.12745169,54.302673,8.0521688,447.65973,-9.2287855
2330,2330,195.3553,4.8771591,1.8241421,0.0,0,7.4635754,0.0,0.12913552,54.593014,8.0300961,447.59506,-9.2286816
2331,2331,195.3555,4.8937697,1.8504769,0.0,0,7.4370952,0.0,0.13152866,54.579811,8.0066414,447.5304,-9.2279015
2332,2332,195.3557,4.9179173,1.8784106,0.0,0,7.410615,0.0,0.13331498,54.704403,7.9814758,447.4657,-9.2270975
2333,2333,195.3559,4.9101615,1.8931246,0.0,0,7.384666,0.0,0.13452695,54.647732,7.9579377,447.40103,-9.2260065
2334,2334,195.3561,4.8508463,1.9186082,0.0,0,7.3593607,0.0,0.13674416,53.947857,7.9355831,447.33636,-9.22577
2335,2335,195.3563,4.8054309,1.9551913,0.0,0,7.3341718,0.0,0.13908859,53.28093,7.9105444,447.27167,-9.226264
2336,2336,195.3565,4.8246703,1.9774776,0.0,0,7.3089876,0.0,0.14080122,53.276295,7.8854108,447.207,-9.2264137
2337,2337,195.3567,4.8777103,1.9949976,0.0,0,7.2838035,0.0,0.14265925,53.720493,7.8638701,447.14233,-9.2263393
2338,2338,195.3569,4.9138432,2.0151067,0.0,0,7.2586198,0.0,0.14403203,54.094391,7.8423262,447.07764,-9.2270832
2339,2339,195.3571,4.9157567,2.0306942,0.0,0,7.2334356,0.0,0.14492792,54.107216,7.8203087,447.01297,-9.2279634
2340,2340,195.3573,4.8970804,2.0532045,0.0,0,7.2082515,0.0,0.14697056,53.817173,7.7982836,446.9483,-9.227931
2341,2341,195.3575,4.872829,2.0823631,0.0,0,7.1830673,0.0,0.14917225,53.456657,7.7758474,446.88364,-9.2277899
2342,2342,195.3577,4.8568854,2.1004815,0.0,0,7.1578832,0.0,0.15034546,53.175381,7.7544065,446.84259,-9.2273893
2343,2343,195.3579,4.8738332,2.113869,0.0,0,7.132699,0.0,0.15182984,53.237499,7.7339764,446.82523,-9.22752
2344,2344,195.3581,4.9370618,2.1339734,0.0,0,7.1075149,0.0,0.15341587,53.765873,7.7119637,446.80786,-9.2273149
2345,2345,195.3583,5.0120311,2.1562355,0.0,0,7.0823312,0.0,0.15463038,54.498409,7.689714,446.7905,-9.227294
2346,2346,195.3585,5.0604062,2.1808372,0.0,0,7.0571475,0.0,0.15677716,54.989578,7.6704416,446.77313,-9.2273045
2347,2347,195.3587,5.0667496,2.2058635,0.0,0,7.0319633,0.0,0.15897451,55.013844,7.6487522,446.75577,-9.2264099
2348,2348,195.3589,5.056735,2.2266634,0.0,0,7.0067787,0.0,0.16020492,54.864952,7.6247926,446.7384,-9.2263269
2349,2349,195.3591,5.0387955,2.2477193,0.0,0,6.981595,0.0,0.16195929,54.559875,7.603642,446.72104,-9.2264881
2350,2350,195.3593,5.0055542,2.2730682,0.0,0,6.9564114,0.0,0.16418475,54.121685,7.583859,446.70367,-9.2265596
2351,2351,195.3595,4.9892068,2.299659,0.0,0,6.9312272,0.0,0.16585815,53.771698,7.5626698,446.68631,-9.2272539
2352,2352,195.3597,5.0205145,2.3210163,0.0,0,6.9060431,0.0,0.16769603,53.927105,7.5392933,446.66895,-9.2280531
2353,2353,195.3599,5.0874534,2.3369083,0.0,0,6.8808589,0.0,0.16943143,54.594669,7.5163603,446.65158,-9.2282333
2354,2354,195.3601,5.1473293,2.3579974,0.0,0,6.8556757,0.0,0.17060332,55.210781,7.493186,446.63422,-9.2280455
2355,2355,195.3603,5.1594825,2.3829031,0.0,0,6.8304915,0.0,0.17237295,55.346256,7.4722176,446.61685,-9.2273579
2356,2356,195.3605,5.1326365,2.4058321,0.0,0,6.8053074,0.0,0.17468952,55.045734,7.4503975,446.59949,-9.2274323
2357,2357,195.3607,5.1048727,2.4316981,0.0,0,6.7801232,0.0,0.1764223,54.608562,7.4282517,446.58212,-9.2272787
2358,2358,195.3609,5.0874662,2.4533966,0.0,0,6.7554412,0.0,0.17796904,54.226044,7.4052987,446.56473,-9.2265606
2359,2359,195.3611,5.0926762,2.4678104,0.0,0,6.7313666,0.0,0.17971706,54.113266,7.3825045,446.54736,-9.2263346
2360,2360,195.3613,5.1255608,2.4911451,0.0,0,6.7074018,0.0,0.18126628,54.341175,7.3615279,446.53,-9.2262583
2361,2361,195.3615,5.1712132,2.5169258,0.0,0,6.6834412,0.0,0.18301928,54.732491,7.3415456,446.51263,-9.2257967
2362,2362,195.3617,5.2173657,2.5341573,0.0,0,6.6594815,0.0,0.18500005,55.127419,7.3181543,446.49527,-9.225853
2363,2363,195.3619,5.2564702,2.5567591,0.0,0,6.6355214,0.0,0.18663196,55.500584,7.2925611,446.47791,-9.2265081
2364,2364,195.3621,5.2798047,2.580786,0.0,0,6.6115613,0.0,0.18810809,55.739208,7.2711315,446.46054,-9.22789
2365,2365,195.3623,5.2802148,2.5977361,0.0,0,6.5876012,0.0,0.18995234,55.645615,7.2495522,446.44318,-9.2284307
2366,2366,195.3625,5.266706,2.625211,0.0,0,6.5636415,0.0,0.19206379,55.398899,7.2245464,446.42581,-9.228384
2367,2367,195.3627,5.2541218,2.6556282,0.0,0,6.5396814,0.0,0.1940164,55.175922,7.1996818,446.40845,-9.2286482
2368,2368,195.3629,5.2590156,2.6699531,0.0,0,6.5157218,0.0,0.19577338,55.06403,7.1795855,446.39108,-9.2281017
2369,2369,195.3631,5.2913976,2.6898661,0.0,0,6.4917617,0.0,0.19750407,55.255531,7.1574397,446.37372,-9.2280712
2370,2370,195.3633,5.3393888,2.7173698,0.0,0,6.467802,0.0,0.19909662,55.665169,7.1332588,446.35635,-9.2273808
2371,2371,195.3635,5.3745856,2.7353711,0.0,0,6.4438419,0.0,0.20090355,55.952091,7.1098976,446.33899,-9.2266541
2372,2372,195.3637,5.381875,2.7614067,0.0,0,6.4198813,0.0,0.20324232,55.922066,7.0867515,446.32162,-9.2263947
2373,2373,195.3639,5.3788705,2.7902231,0.0,0,6.3959212,0.0,0.20510733,55.797585,7.0632544,446.30426,-9.226368
2374,2374,195.3641,5.3889046,2.8039,0.0,0,6.3719611,0.0,0.20660543,55.767315,7.0384717,446.2869,-9.2258158
2375,2375,195.3643,5.4166102,2.8273516,0.0,0,6.3480015,0.0,0.2087716,55.845047,7.012321,446.2695,-9.2256117
2376,2376,195.3645,5.4431515,2.8601429,0.0,0,6.3240414,0.0,0.21078135,56.000828,6.9868107,446.25214,-9.2265015
2377,2377,195.3647,5.4593358,2.8798885,0.0,0,6.3000817,0.0,0.21262196,56.12439,6.9648848,446.23477,-9.2272758
2378,2378,195.3649,5.476943,2.9027348,0.0,0,6.2761216,0.0,0.21503729,56.203415,6.9428511,446.21741,-9.2277851
2379,2379,195.3651,5.4977942,2.9316709,0.0,0,6.252162,0.0,0.21692282,56.325882,6.9190545,446.20004,-9.2279911
2380,2380,195.3653,5.510118,2.9504809,0.0,0,6.2282019,0.0,0.21845202,56.385769,6.8951573,446.18268,-9.2281637
2381,2381,195.3655,5.5177708,2.9751289,0.0,0,6.2042418,0.0,0.22097524,56.327538,6.8702168,446.16531,-9.2282686
2382,2382,195.3657,5.5195723,3.0070398,0.0,0,6.1802816,0.0,0.22321674,56.180939,6.8459992,446.14795,-9.2280779
2383,2383,195.3659,5.5203128,3.0271652,0.0,0,6.1568022,0.0,0.22474815,56.098949,6.8219895,446.13058,-9.2272043
2384,2384,195.3661,5.5423293,3.048857,0.0,0,6.1339045,0.0,0.22708374,56.189671,6.7977309,446.11322,-9.226572
2385,2385,195.3663,5.587965,3.0778351,0.0,0,6.1111116,0.0,0.22927639,56.470127,6.7733192,446.09586,-9.2265854
2386,2386,195.3665,5.6193209,3.0992997,0.0,0,6.0883236,0.0,0.23075609,56.720703,6.7500958,446.07849,-9.225852
2387,2387,195.3667,5.6293316,3.1216292,0.0,0,6.0655355,0.0,0.23311666,56.764103,6.7236304,446.06113,-9.2252407
2388,2388,195.3669,5.6361351,3.1495025,0.0,0,6.042748,0.0,0.2354546,56.706219,6.6968637,446.04376,-9.2257957
2389,2389,195.3671,5.639853,3.1707113,0.0,0,6.0199599,0.0,0.23683102,56.674301,6.6739292,446.0264,-9.2263613
2390,2390,195.3673,5.6537662,3.1918895,0.0,0,5.9971714,0.0,0.23900953,56.700405,6.6481895,446.00903,-9.2272711
2391,2391,195.3675,5.6669846,3.2195282,0.0,0,5.9743834,0.0,0.24143051,56.650673,6.6222,445.99164,-9.2280531
2392,2392,195.3677,5.6834478,3.24597,0.0,0,5.9515953,0.0,0.24309732,56.692669,6.5980649,445.98267,-9.2279053
2393,2393,195.3679,5.7197175,3.2715676,0.0,0,5.9288073,0.0,0.24556293,56.913223,6.5723228,445.98209,-9.2284298
2394,2394,195.3681,5.7577353,3.2983747,0.0,0,5.9060197,0.0,0.24814907,57.116844,6.5485158,445.98148,-9.2280722
2395,2395,195.3683,5.7873445,3.3232343,0.0,0,5.8832316,0.0,0.24980164,57.334305,6.5238748,445.98087,-9.2274675
2396,2396,195.3685,5.8032784,3.3478217,0.0,0,5.8604436,0.0,0.25205657,57.41132,6.4964213,445.98029,-9.2272568
2397,2397,195.3687,5.8080506,3.3747685,0.0,0,5.8376555,0.0,0.25471011,57.342964,6.4744849,445.97968,-9.2265615
2398,2398,195.3689,5.8056092,3.4026289,0.0,0,5.814867,0.0,0.2566168,57.23748,6.4485669,445.97906,-9.226615
2399,2399,195.3691,5.8015065,3.4266553,0.0,0,5.792079,0.0,0.25878137,57.076447,6.420743,445.97849,-9.2266293
2400,2400,195.3693,5.806951,3.4483643,0.0,0,5.7692914,0.0,0.26118246,56.961197,6.3956571,445.97787,-9.2267265
2401,2401,195.3695,5.8361063,3.4764841,0.0,0,5.7465034,0.0,0.26306239,57.068748,6.369256,445.97726,-9.2269306
2402,2402,195.3697,5.8817968,3.5034614,0.0,0,5.7237153,0.0,0.2652815,57.331532,6.3447723,445.97668,-9.2273617
2403,2403,195.3699,5.9138975,3.5242577,0.0,0,5.7009273,0.0,0.26774648,57.517014,6.3211322,445.97607,-9.2271681
2404,2404,195.3701,5.9308162,3.5504408,0.0,0,5.6781397,0.0,0.26958907,57.64679,6.2960563,445.97546,-9.2263031
2405,2405,195.3703,5.9418392,3.5750244,0.0,0,5.6553516,0.0,0.27148688,57.662861,6.2709465,445.97488,-9.2262754
2406,2406,195.3705,5.9532061,3.594291,0.0,0,5.6325636,0.0,0.27385351,57.573364,6.2463846,445.97427,-9.2262688
2407,2407,195.3707,5.9629698,3.6233981,0.0,0,5.6097751,0.0,0.27604285,57.554779,6.2199502,445.97369,-9.2264147
2408,2408,195.3709,5.9657059,3.6525347,0.0,0,5.5874414,0.0,0.27820909,57.521946,6.1936336,445.97308,-9.2273779
2409,2409,195.3711,5.9679894,3.6713583,0.0,0,5.5656581,0.0,0.28059775,57.425266,6.1680574,445.97247,-9.2272749
2410,2410,195.3713,5.9901733,3.6984193,0.0,0,5.5439734,0.0,0.28280208,57.473572,6.1434627,445.97189,-9.2269144
2411,2411,195.3715,6.0268912,3.7285476,0.0,0,5.5222936,0.0,0.28487378,57.584904,6.1198783,445.97128,-9.2270842
2412,2412,195.3717,6.056704,3.7479773,0.0,0,5.5006132,0.0,0.28720659,57.76886,6.0932636,445.97067,-9.2269535
2413,2413,195.3719,6.0813351,3.7749228,0.0,0,5.4789333,0.0,0.28961405,57.91526,6.0663419,445.97009,-9.2267494
2414,2414,195.3721,6.0983691,3.8050325,0.0,0,5.457253,0.0,0.29166961,57.944122,6.0427847,445.96948,-9.2264576
2415,2415,195.3723,6.1055393,3.8223753,0.0,0,5.4355731,0.0,0.29377133,57.955013,6.0183549,445.96887,-9.2257271
2416,2416,195.3725,6.1115437,3.847743,0.0,0,5.4138932,0.0,0.29623723,57.85854,5.9913969,445.96829,-9.2253199
2417,2417,195.3727,6.1242871,3.8794534,0.0,0,5.3922133,0.0,0.29834267,57.738827,5.963191,445.96768,-9.225482
2418,2418,195.3729,6.1434765,3.8979852,0.0,0,5.370533,0.0,0.30040637,57.753891,5.9382992,445.9671,-9.225975
2419,2419,195.3731,6.1600585,3.9232919,0.0,0,5.3488531,0.0,0.30305144,57.834686,5.9154992,445.96649,-9.2265472
2420,2420,195.3733,6.1785564,3.9544141,0.0,0,5.3271732,0.0,0.30524185,57.918755,5.8889332,445.96588,-9.2272415
2421,2421,195.3735,6.2043409,3.9713717,0.0,0,5.3054934,0.0,0.30709851,57.989445,5.8631191,445.9653,-9.2267675
2422,2422,195.3737,6.2227178,3.9962258,0.0,0,5.283813,0.0,0.30977148,58.023968,5.8365016,445.96469,-9.2260618
2423,2423,195.3739,6.2363248,4.0291314,0.0,0,5.2621331,0.0,0.31206051,58.094112,5.8096437,445.96408,-9.2258682
2424,2424,195.3741,6.2493877,4.0478559,0.0,0,5.2404532,0.0,0.31384012,58.207058,5.7876902,445.9635,-9.2259359
2425,2425,195.3743,6.2627463,4.0700517,0.0,0,5.2187734,0.0,0.31647751,58.243851,5.7651277,445.96289,-9.2266636
2426,2426,195.3745,6.2913551,4.0992851,0.0,0,5.1970935,0.0,0.3186371,58.201283,5.7394004,445.96228,-9.2267284
2427,2427,195.3747,6.30865,4.1178575,0.0,0,5.1754136,0.0,0.3202447,58.177071,5.7151384,445.9617,-9.226676
2428,2428,195.3749,6.3051476,4.141026,0.0,0,5.1537333,0.0,0.32293057,58.080891,5.6917133,445.96109,-9.2273684
2429,2429,195.3751,6.3139687,4.1712222,0.0,0,5.1320534,0.0,0.32532889,58.070835,5.6662431,445.96048,-9.2281265
2430,2430,195.3753,6.3364348,4.1899867,0.0,0,5.110373,0.0,0.32687223,58.152573,5.6421018,445.9599,-9.227417
2431,2431,195.3755,6.3580632,4.2112284,0.0,0,5.0886931,0.0,0.32937318,58.153748,5.6206226,445.95929,-9.2267971
2432,2432,195.3757,6.3824487,4.2413511,0.0,0,5.0670133,0.0,0.33191839,58.224667,5.5950994,445.95871,-9.227066
2433,2433,195.3759,6.4100986,4.2648115,0.0,0,5.0457678,0.0,0.3337082,58.372391,5.5698581,445.9581,-9.2267523
2434,2434,195.3761,6.4330869,4.2870626,0.0,0,5.0250483,0.0,0.33638147,58.451969,5.5490866,445.95749,-9.2263889
2435,2435,195.3763,6.4493756,4.3141942,0.0,0,5.0044241,0.0,0.33889598,58.496284,5.5244994,445.95691,-9.2265291
2436,2436,195.3765,6.4559536,4.336235,0.0,0,4.9838037,0.0,0.3404144,58.471741,5.4984126,445.9563,-9.2264862
2437,2437,195.3767,6.4605932,4.3574638,0.0,0,4.9631839,0.0,0.34291142,58.303146,5.4756951,445.95569,-9.2260675
2438,2438,195.3769,6.4605103,4.3837633,0.0,0,4.9425635,0.0,0.34555039,58.165493,5.4532824,445.95511,-9.2260828
2439,2439,195.3771,6.4639578,4.4060478,0.0,0,4.9219437,0.0,0.3470532,58.206841,5.4301643,445.9545,-9.22684
2440,2440,195.3773,6.4816408,4.4256577,0.0,0,4.9013238,0.0,0.34927055,58.236984,5.4055362,445.95389,-9.2278538
2441,2441,195.3775,6.508924,4.4490018,0.0,0,4.8807039,0.0,0.3518424,58.242954,5.3810487,445.95331,-9.2283039
2442,2442,195.3777,6.5450568,4.4726286,0.0,0,4.8600836,0.0,0.35346368,58.422611,5.3618789,445.86215,-9.2274895
2443,2443,195.3779,6.5790429,4.4950285,0.0,0,4.8394637,0.0,0.35570493,58.587265,5.3404164,445.68051,-9.227314
2444,2444,195.3781,6.5910158,4.5174365,0.0,0,4.8188438,0.0,0.35831398,58.624893,5.3143992,445.49884,-9.2279139
2445,2445,195.3783,6.5967054,4.5418334,0.0,0,4.798224,0.0,0.36003441,58.612576,5.2899981,445.31717,-9.2273417
2446,2446,195.3785,6.598979,4.5643768,0.0,0,4.7776036,0.0,0.36214998,58.492668,5.2665882,445.13553,-9.2265759
2447,2447,195.3787,6.5967097,4.5858622,0.0,0,4.7569838,0.0,0.36484224,58.335499,5.2444077,444.95386,-9.2265482
2448,2448,195.3789,6.6001139,4.6130447,0.0,0,4.7363639,0.0,0.36690801,58.2444,5.2219992,444.77222,-9.2265358
2449,2449,195.3791,6.6208677,4.6358752,0.0,0,4.7157435,0.0,0.36897513,58.279747,5.1996856,444.59055,-9.226265
2450,2450,195.3793,6.6543045,4.6534953,0.0,0,4.6951237,0.0,0.37147984,58.415768,5.1789098,444.40887,-9.2269621
2451,2451,195.3795,6.6839833,4.67942,0.0,0,4.6745038,0.0,0.37350354,58.563683,5.1560106,444.22723,-9.2279501
2452,2452,195.3797,6.7081199,4.7036271,0.0,0,4.6538839,0.0,0.3754831,58.658611,5.1304665,444.04556,-9.2274265
2453,2453,195.3799,6.7265072,4.7199039,0.0,0,4.6332641,0.0,0.37791553,58.690872,5.1070371,443.86389,-9.2274637
2454,2454,195.3801,6.7382393,4.7458334,0.0,0,4.6126437,0.0,0.38003257,58.665451,5.0872841,443.68225,-9.2279196
2455,2455,195.3803,6.7413058,4.7713895,0.0,0,4.5920234,0.0,0.38198167,58.57198,5.0673919,443.50058,-9.2270994
2456,2456,195.3805,6.7488914,4.785924,0.0,0,4.5714035,0.0,0.38422215,58.466396,5.0433345,443.31894,-9.2269344
2457,2457,195.3807,6.7612147,4.8108573,0.0,0,4.5507836,0.0,0.38640201,58.422112,5.0177941,443.13727,-9.2268686
2458,2458,195.3809,6.7833166,4.8371315,0.0,0,4.5305758,0.0,0.38831833,58.518745,4.9955087,442.9556,-9.2264166
2459,2459,195.3811,6.8110509,4.8511,0.0,0,4.5108657,0.0,0.3904599,58.635769,4.9742866,442.77396,-9.2265491
2460,2460,195.3813,6.824914,4.8751335,0.0,0,4.4912457,0.0,0.39285532,58.624321,4.9536719,442.59229,-9.2264395
2461,2461,195.3815,6.8412046,4.9026761,0.0,0,4.4716296,0.0,0.39486757,58.625957,4.9318218,442.41061,-9.2269688
2462,2462,195.3817,6.863256,4.9167137,0.0,0,4.4520135,0.0,0.39688775,58.646965,4.9102817,442.22897,-9.2265587
2463,2463,195.3819,6.8754139,4.9396291,0.0,0,4.4323974,0.0,0.39935723,58.646004,4.8886056,442.0473,-9.2259989
2464,2464,195.3821,6.8913016,4.9682875,0.0,0,4.4127812,0.0,0.40140694,58.694,4.8650608,441.86566,-9.2264242
2465,2465,195.3823,6.9061613,4.9824862,0.0,0,4.3931651,0.0,0.40336588,58.703587,4.8443794,441.68399,-9.2269564
2466,2466,195.3825,6.9138479,5.0043116,0.0,0,4.3735495,0.0,0.40596104,58.629356,4.8238511,441.50232,-9.2270689
2467,2467,195.3827,6.9221215,5.0324702,0.0,0,4.3539338,0.0,0.40790018,58.619465,4.8025422,441.32068,-9.2271633
2468,2468,195.3829,6.9393196,5.0467882,0.0,0,4.3343177,0.0,0.40955827,58.663368,4.7789674,441.13901,-9.2275429
2469,2469,195.3831,6.958055,5.0689912,0.0,0,4.3147016,0.0,0.41234589,58.602322,4.7594185,440.95737,-9.2275152
2470,2470,195.3833,6.9699478,5.0988326,0.0,0,4.2950859,0.0,0.41460359,58.562256,4.7398486,440.7757,-9.2278652
2471,2471,195.3835,6.9843154,5.1131248,0.0,0,4.2754693,0.0,0.41612285,58.608841,4.7166281,440.59402,-9.2274179
2472,2472,195.3837,7.0071316,5.1313915,0.0,0,4.2558532,0.0,0.41869819,58.670643,4.6958399,440.41238,-9.2263575
2473,2473,195.3839,7.0335584,5.1584196,0.0,0,4.236237,0.0,0.42084596,58.756336,4.6752858,440.23071,-9.225523
2474,2474,195.3841,7.0513272,5.1740623,0.0,0,4.2166214,0.0,0.42223275,58.822777,4.6542296,440.04904,-9.2252474
2475,2475,195.3843,7.0667682,5.1922054,0.0,0,4.1970053,0.0,0.42477909,58.825706,4.6340923,439.8674,-9.2252045
2476,2476,195.3845,7.0807486,5.2176433,0.0,0,4.1773891,0.0,0.42700425,58.827736,4.6135135,439.68573,-9.2250071
2477,2477,195.3847,7.0857697,5.233532,0.0,0,4.1577735,0.0,0.42833117,58.802818,4.5919547,439.50409,-9.2256031
2478,2478,195.3849,7.0957594,5.2517829,0.0,0,4.1381574,0.0,0.43095046,58.725887,4.5706272,439.32242,-9.2263708
2479,2479,195.3851,7.1053462,5.2787647,0.0,0,4.1185412,0.0,0.43350178,58.650074,4.5494947,439.14075,-9.2265091
2480,2480,195.3853,7.1238031,5.2985849,0.0,0,4.0989256,0.0,0.43496758,58.661251,4.5289702,438.95911,-9.2267981
2481,2481,195.3855,7.1500802,5.3166742,0.0,0,4.0793095,0.0,0.43740934,58.690186,4.5087967,438.77744,-9.2268209
2482,2482,195.3857,7.17133,5.3407874,0.0,0,4.0596933,0.0,0.43993005,58.713337,4.4902244,438.59576,-9.2266941
2483,2483,195.3859,7.1953244,5.3600221,0.0,0,4.0404716,0.0,0.44132537,58.837048,4.4698386,438.41412,-9.226038
2484,2484,195.3861,7.2120485,5.3770499,0.0,0,4.0217257,0.0,0.44363955,58.907665,4.4485784,438.23245,-9.2252674
2485,2485,195.3863,7.2173572,5.3998628,0.0,0,4.0030656,0.0,0.44623658,58.825836,4.4278965,438.05081,-9.2251644
2486,2486,195.3865,7.2217255,5.4197516,0.0,0,3.9844091,0.0,0.44766599,58.740898,4.4099092,437.86914,-9.2264681
2487,2487,195.3867,7.2257838,5.4373364,0.0,0,3.9657531,0.0,0.44988325,58.641689,4.3908291,437.68747,-9.2272692
2488,2488,195.3869,7.2384109,5.4586024,0.0,0,3.9470971,0.0,0.45248613,58.613575,4.369576,437.50583,-9.2265854
2489,2489,195.3871,7.2613292,5.479651,0.0,0,3.928441,0.0,0.45395833,58.716885,4.3480659,437.32416,-9.2265882
2490,2490,195.3873,7.2808709,5.4973087,0.0,0,3.9097853,0.0,0.45599309,58.728294,4.3269243,437.14252,-9.2267189
2491,2491,195.3875,7.3081412,5.5155492,0.0,0,3.8911293,0.0,0.4585126,58.769508,4.3081889,436.96085,-9.2268925
2492,2492,195.3877,7.3397474,5.5379519,0.0,0,3.8724732,0.0,0.46005195,58.946751,4.288312,436.85052,-9.2269001
2493,2493,195.3879,7.3640056,5.557662,0.0,0,3.8538172,0.0,0.46212438,59.01902,4.2686467,436.81155,-9.2271519
2494,2494,195.3881,7.3805838,5.5743575,0.0,0,3.8351612,0.0,0.46475139,58.994041,4.2495112,436.77258,-9.2269545
2495,2495,195.3883,7.3886509,5.5970669,0.0,0,3.8165052,0.0,0.46652791,58.982124,4.2320175,436.73361,-9.2264843
2496,2496,195.3885,7.3976026,5.6173401,0.0,0,3.7978492,0.0,0.46842298,58.901009,4.2129827,436.69461,-9.2265263
2497,2497,195.3887,7.4075561,5.6317086,0.0,0,3.7791932,0.0,0.47085109,58.823597,4.1922975,436.65564,-9.2264853
2498,2498,195.3889,7.4172339,5.6547918,0.0,0,3.7605371,0.0,0.47281903,58.842567,4.1739249,436.61667,-9.2262764
2499,2499,195.3891,7.4374886,5.6764317,0.0,0,3.7418811,0.0,0.47463667,58.884449,4.1539168,436.5777,-9.2263117
2500,2500,195.3893,7.4599819,5.6887636,0.0,0,3.7232251,0.0,0.47690821,58.88113,4.1334352,436.53873,-9.2262535
2501,2501,195.3895,7.4843407,5.7100997,0.0,0,3.7045693,0.0,0.47892112,58.951675,4.1153069,436.49973,-9.226099
2502,2502,195.3897,7.5103369,5.7322488,0.0,0,3.6859133,0.0,0.48064137,59.086514,4.097486,436.46075,-9.2263727
2503,2503,195.3899,7.5323806,5.7442007,0.0,0,3.6672573,0.0,0.48277053,59.161213,4.078217,436.42178,-9.2271137
2504,2504,195.3901,7.546638,5.7661228,0.0,0,3.6486013,0.0,0.48497516,59.166119,4.0584788,436.38281,-9.2273121
2505,2505,195.3903,7.5528016,5.7911816,0.0,0,3.629945,0.0,0.48685971,59.105003,4.0369158,436.34381,-9.2268991
2506,2506,195.3905,7.5627608,5.8031631,0.0,0,3.611289,0.0,0.48901418,59.042961,4.0180879,436.30484,-9.2261944
2507,2507,195.3907,7.5765448,5.8249698,0.0,0,3.5926332,0.0,0.49151474,58.998241,3.9992852,436.26587,-9.2264547
2508,2508,195.3909,7.5887051,5.8518229,0.0,0,3.5743496,0.0,0.49344784,59.010517,3.9782169,436.2269,-9.226717
2509,2509,195.3911,7.6114759,5.8641238,0.0,0,3.5565164,0.0,0.49545893,59.037384,3.9594018,436.18793,-9.2262239
2510,2510,195.3913,7.6380353,5.884665,0.0,0,3.5387647,0.0,0.49811614,59.066868,3.9408453,436.14893,-9.22647
2511,2511,195.3915,7.6520381,5.9100623,0.0,0,3.5210166,0.0,0.50002694,59.130772,3.9215026,436.10995,-9.2265396
2512,2512,195.3917,7.6725993,5.92065,0.0,0,3.5032687,0.0,0.50169373,59.120384,3.9020383,436.07098,-9.2265434
2513,2513,195.3919,7.7023396,5.9391618,0.0,0,3.4855206,0.0,0.5042097,59.165211,3.8842392,436.03201,-9.2271357
2514,2514,195.3921,7.7218409,5.9658422,0.0,0,3.4677725,0.0,0.50614387,59.285374,3.8660526,435.99301,-9.2265167
2515,2515,195.3923,7.7310896,5.978085,0.0,0,3.4500246,0.0,0.50772601,59.249184,3.845238,435.95404,-9.2258997
2516,2516,195.3925,7.7392292,5.9950461,0.0,0,3.4322767,0.0,0.51036018,59.121178,3.8268504,435.91507,-9.2262468
2517,2517,195.3927,7.7456264,6.0209541,0.0,0,3.4145288,0.0,0.51240087,59.034409,3.8115046,435.8761,-9.2261896
2518,2518,195.3929,7.7588892,6.03372,0.0,0,3.3967807,0.0,0.51386517,59.04343,3.7916536,435.83713,-9.2263775
2519,2519,195.3931,7.7750368,6.0511999,0.0,0,3.3790326,0.0,0.51663023,59.046795,3.770426,435.79813,-9.2264767
2520,2520,195.3933,7.8005323,6.0781708,0.0,0,3.3612847,0.0,0.51895988,59.074757,3.7524836,435.75916,-9.2260113
2521,2521,195.3935,7.8322349,6.0926671,0.0,0,3.3435366,0.0,0.5203855,59.173725,3.7349303,435.72018,-9.2258911
2522,2522,195.3937,7.8557849,6.1092901,0.0,0,3.3257885,0.0,0.52305692,59.217136,3.7163978,435.68121,-9.2257395
2523,2523,195.3939,7.8810673,6.1342654,0.0,0,3.3080406,0.0,0.52543956,59.285072,3.6978476,435.64221,-9.2251177
2524,2524,195.3941,7.9015894,6.14991,0.0,0,3.2902927,0.0,0.52677947,59.364697,3.6776977,435.60324,-9.2256575
2525,2525,195.3943,7.9027271,6.1657438,0.0,0,3.2725446,0.0,0.52934158,59.29454,3.6592493,435.56427,-9.2257948
2526,2526,195.3945,7.9010162,6.1891294,0.0,0,3.2547965,0.0,0.53184402,59.163979,3.6422839,435.5253,-9.2259254
2527,2527,195.3947,7.917028,6.2056632,0.0,0,3.2370486,0.0,0.53306276,59.142288,3.6226881,435.48633,-9.2264996
2528,2528,195.3949,7.9433022,6.2208133,0.0,0,3.2193005,0.0,0.53548813,59.167305,3.604151,435.44733,-9.2266045
2529,2529,195.3951,7.9686265,6.2423167,0.0,0,3.2015524,0.0,0.53815866,59.207371,3.5862689,435.40836,-9.2266397
2530,2530,195.3953,8.001502,6.260766,0.0,0,3.1838045,0.0,0.53943521,59.348377,3.5677981,435.36938,-9.2267151
2531,2531,195.3955,8.0354986,6.2770457,0.0,0,3.1660566,0.0,0.54178572,59.432865,3.5492446,435.33041,-9.2267065
2532,2532,195.3957,8.060276,6.2976799,0.0,0,3.1483085,0.0,0.54449403,59.467506,3.5297599,435.29141,-9.2265501
2533,2533,195.3959,8.0758486,6.3170619,0.0,0,3.1309149,0.0,0.54587287,59.537556,3.5103717,435.25244,-9.2257977
2534,2534,195.3961,8.078721,6.3327827,0.0,0,3.1139498,0.0,0.54811811,59.46656,3.4926229,435.21347,-9.2250223
2535,2535,195.3963,8.0815086,6.3513455,0.0,0,3.0970623,0.0,0.55079472,59.373032,3.4748898,435.1745,-9.2250299
2536,2536,195.3965,8.0913191,6.3720684,0.0,0,3.0801783,0.0,0.55223638,59.370327,3.4542747,435.13553,-9.2255898
2537,2537,195.3967,8.1030312,6.3898907,0.0,0,3.0632942,0.0,0.55442351,59.296272,3.4356341,435.09653,-9.2257261
2538,2538,195.3969,8.1233273,6.4069514,0.0,0,3.0464103,0.0,0.55725765,59.262249,3.4191713,435.05756,-9.2259102
2539,2539,195.3971,8.1520309,6.4284987,0.0,0,3.0295262,0.0,0.55894071,59.344624,3.400836,435.01859,-9.2265062
2540,2540,195.3973,8.1814575,6.447001,0.0,0,3.0126421,0.0,0.56097662,59.39032,3.3820777,434.97961,-9.2265425
2541,2541,195.3975,8.2130556,6.4621086,0.0,0,2.9957583,0.0,0.56370836,59.445263,3.3656485,434.94064,-9.2260799
2542,2542,195.3977,8.2340117,6.4842782,0.0,0,2.9788742,0.0,0.565593,59.487019,3.347681,434.8779,-9.2260027
2543,2543,195.3979,8.2459164,6.5034523,0.0,0,2.9619904,0.0,0.56755608,59.472919,3.3274195,434.79141,-9.2258844
2544,2544,195.3981,8.2482166,6.5160723,0.0,0,2.9451063,0.0,0.57005435,59.383736,3.3087187,434.70493,-9.2253199
2545,2545,195.3983,8.2528191,6.5370054,0.0,0,2.9282222,0.0,0.57190865,59.276264,3.2905517,434.61844,-9.2252789
2546,2546,195.3985,8.2690048,6.5562558,0.0,0,2.9113381,0.0,0.5736599,59.278114,3.2724955,434.53195,-9.2255354
2547,2547,195.3987,8.2929001,6.5672188,0.0,0,2.894454,0.0,0.57606786,59.299793,3.2540119,434.44547,-9.2254038
2548,2548,195.3989,8.3201771,6.5890641,0.0,0,2.8775702,0.0,0.57823557,59.344547,3.2357116,434.35898,-9.2255907
2549,2549,195.3991,8.3509951,6.6111469,0.0,0,2.8606861,0.0,0.57999212,59.461018,3.2171209,434.27249,-9.2257853
2550,2550,195.3993,8.3772507,6.6220169,0.0,0,2.8438022,0.0,0.58236355,59.542362,3.2022705,434.186,-9.2259159
2551,2551,195.3995,8.3987846,6.6436782,0.0,0,2.8269181,0.0,0.5848515,59.565647,3.1881638,434.09952,-9.2270079
2552,2552,195.3997,8.4180784,6.6678376,0.0,0,2.810034,0.0,0.58665287,59.560013,3.1706283,434.01303,-9.2274532
2553,2553,195.3999,8.4309387,6.6780481,0.0,0,2.7931502,0.0,0.58889228,59.548466,3.1513739,433.92654,-9.2276392
2554,2554,195.4001,8.4390707,6.6972337,0.0,0,2.7762663,0.0,0.59152615,59.467468,3.132818,433.84006,-9.2273092
2555,2555,195.4003,8.4484291,6.7216902,0.0,0,2.7593822,0.0,0.59337181,59.404541,3.1161594,433.75357,-9.2266569
2556,2556,195.4005,8.4603148,6.7319989,0.0,0,2.7424982,0.0,0.59534746,59.405895,3.100759,433.66708,-9.2266665
2557,2557,195.4007,8.4803629,6.7506075,0.0,0,2.7256143,0.0,0.59803241,59.381271,3.0837815,433.5806,-9.2264452
2558,2558,195.4009,8.5058746,6.7756395,0.0,0,2.7090681,0.0,0.59997684,59.417641,3.0657325,433.49411,-9.2257872
2559,2559,195.4011,8.5280657,6.7851682,0.0,0,2.6929309,0.0,0.60172653,59.4925,3.0456333,433.40765,-9.2253361
2560,2560,195.4013,8.549159,6.8029399,0.0,0,2.6768675,0.0,0.60452354,59.446556,3.0270071,433.32117,-9.2259111
2561,2561,195.4015,8.568902,6.8297672,0.0,0,2.6608074,0.0,0.60661024,59.433128,3.0111339,433.23468,-9.2265158
2562,2562,195.4017,8.5915089,6.8408399,0.0,0,2.6447473,0.0,0.60823864,59.476017,2.9928358,433.14819,-9.2265415
2563,2563,195.4019,8.6133223,6.8574061,0.0,0,2.6286871,0.0,0.61113328,59.474052,2.9755867,433.06171,-9.2264824
2564,2564,195.4021,8.629921,6.8824482,0.0,0,2.6126273,0.0,0.61327046,59.508385,2.9604573,432.97522,-9.2270269
2565,2565,195.4023,8.6381435,6.8932886,0.0,0,2.5965672,0.0,0.61461985,59.5005,2.9430246,432.88873,-9.226841
2566,2566,195.4025,8.6511211,6.9080262,0.0,0,2.580507,0.0,0.61734718,59.416515,2.9243507,432.80225,-9.2258711
2567,2567,195.4027,8.6798048,6.9319201,0.0,0,2.5644472,0.0,0.61954361,59.44231,2.9055746,432.71576,-9.2260876
2568,2568,195.4029,8.7091465,6.9443088,0.0,0,2.5483871,0.0,0.62078369,59.596275,2.8879411,432.62927,-9.2263479
2569,2569,195.4031,8.7358503,6.9587321,0.0,0,2.5323269,0.0,0.62354231,59.60078,2.8720188,432.54279,-9.2256222
2570,2570,195.4033,8.7560377,6.9817457,0.0,0,2.5162671,0.0,0.62605482,59.565109,2.8538549,432.4563,-9.2254715
2571,2571,195.4035,8.7718782,6.996047,0.0,0,2.5002072,0.0,0.6272158,59.649315,2.836519,432.36981,-9.2256165
2572,2572,195.4037,8.7953672,7.0111632,0.0,0,2.4841471,0.0,0.62991399,59.64967,2.8197083,432.28333,-9.2252054
2573,2573,195.4039,8.8167763,7.0338039,0.0,0,2.4680872,0.0,0.63268894,59.626163,2.8013756,432.19684,-9.2255859
2574,2574,195.4041,8.8295269,7.050549,0.0,0,2.4520271,0.0,0.6339972,59.60569,2.7850447,432.11035,-9.226306
2575,2575,195.4043,8.8421783,7.0660968,0.0,0,2.4359672,0.0,0.63673276,59.499653,2.7694345,432.02386,-9.2263803
2576,2576,195.4045,8.8578873,7.0875993,0.0,0,2.4199073,0.0,0.63964289,59.466316,2.7510126,431.93738,-9.2263803
2577,2577,195.4047,8.8698893,7.1057229,0.0,0,2.4038472,0.0,0.6409179,59.504787,2.7339013,431.85089,-9.22649
2578,2578,195.4049,8.8924532,7.1203051,0.0,0,2.3877871,0.0,0.64339781,59.476696,2.7164783,431.7644,-9.2262869
2579,2579,195.4051,8.9190245,7.1386704,0.0,0,2.3717272,0.0,0.64624721,59.4552,2.6980352,431.67792,-9.2256165
2580,2580,195.4053,8.9469175,7.157084,0.0,0,2.3556671,0.0,0.64750695,59.522675,2.6800292,431.59143,-9.2250519
2581,2581,195.4055,8.9734573,7.171813,0.0,0,2.339607,0.0,0.64970583,59.59042,2.6619751,431.50494,-9.2251043
2582,2582,195.4057,8.9984169,7.1880503,0.0,0,2.3235471,0.0,0.65247744,59.654411,2.6438117,431.41846,-9.2254124
2583,2583,195.4059,9.0188236,7.2065992,0.0,0,2.3078086,0.0,0.65382427,59.709888,2.6281435,431.33197,-9.2253103
2584,2584,195.4061,9.0290403,7.2210155,0.0,0,2.2924592,0.0,0.65587533,59.653091,2.6136808,431.24551,-9.2257032
2585,2585,195.4063,9.0438137,7.2350264,0.0,0,2.2771802,0.0,0.65878886,59.538605,2.5967801,431.15903,-9.2259121
2586,2586,195.4065,9.0648613,7.2556319,0.0,0,2.261904,0.0,0.66039252,59.570587,2.5794914,431.07254,-9.2252188
2587,2587,195.4067,9.0800095,7.2726588,0.0,0,2.2466278,0.0,0.66236329,59.580318,2.5621724,430.98605,-9.2257223
2588,2588,195.4069,9.0956564,7.2852449,0.0,0,2.2313521,0.0,0.66520709,59.506584,2.5441086,430.89957,-9.2259007
2589,2589,195.4071,9.1257076,7.3061152,0.0,0,2.2160761,0.0,0.66711098,59.574299,2.5270576,430.81308,-9.2252283
2590,2590,195.4073,9.1578569,7.3248072,0.0,0,2.2008002,0.0,0.66909415,59.668377,2.5111771,430.72659,-9.2252073
2591,2591,195.4075,9.1887617,7.3368192,0.0,0,2.185524,0.0,0.67192215,59.688057,2.4937017,430.64011,-9.2258425
2592,2592,195.4077,9.2132902,7.3593583,0.0,0,2.170248,0.0,0.67421055,59.716816,2.475688,430.53629,-9.225441
2593,2593,195.4079,9.2278347,7.3796821,0.0,0,2.1549721,0.0,0.67611837,59.696278,2.4594395,430.41513,-9.2248087
2594,2594,195.4081,9.2390594,7.3885169,0.0,0,2.1396961,0.0,0.67868572,59.633018,2.4418225,430.29395,-9.2252083
2595,2595,195.4083,9.2547321,7.4078965,0.0,0,2.1244199,0.0,0.68086398,59.592838,2.4268677,430.17279,-9.2251539
2596,2596,195.4085,9.2756529,7.4286466,0.0,0,2.109144,0.0,0.68247485,59.632084,2.4132683,430.05164,-9.2256804
2597,2597,195.4087,9.2903881,7.4367304,0.0,0,2.093868,0.0,0.68469626,59.642879,2.3950672,429.93048,-9.2263174
2598,2598,195.4089,9.3084135,7.4558005,0.0,0,2.0785921,0.0,0.68715751,59.578388,2.3781657,429.80933,-9.2258539
2599,2599,195.4091,9.3297796,7.4790773,0.0,0,2.0633161,0.0,0.68906176,59.617188,2.3624628,429.68817,-9.2261181
2600,2600,195.4093,9.3593702,7.4868512,0.0,0,2.0480402,0.0,0.69117337,59.697807,2.3451474,429.56702,-9.2266674
2601,2601,195.4095,9.3953171,7.5041018,0.0,0,2.0327642,0.0,0.69379598,59.740639,2.3272519,429.44586,-9.2256823
2602,2602,195.4097,9.4213495,7.5278883,0.0,0,2.0174882,0.0,0.69569826,59.81052,2.3089285,429.32468,-9.2248793
2603,2603,195.4099,9.4365358,7.5364919,0.0,0,2.002212,0.0,0.69752729,59.826523,2.2935164,429.20352,-9.224803
2604,2604,195.4101,9.4454918,7.553349,0.0,0,1.986936,0.0,0.70030576,59.704983,2.2800972,429.08237,-9.2249727
2605,2605,195.4103,9.458518,7.5773792,0.0,0,1.9716599,0.0,0.70235014,59.647743,2.2644732,428.96121,-9.2251358
2606,2606,195.4105,9.48207,7.5858326,0.0,0,1.9563839,0.0,0.70400846,59.674294,2.2480063,428.84006,-9.2249918
2607,2607,195.4107,9.5086651,7.6019998,0.0,0,1.941108,0.0,0.70705134,59.638504,2.2312133,428.7189,-9.2262478
2608,2608,195.4109,9.5320845,7.6265774,0.0,0,1.9261372,0.0,0.70921504,59.652607,2.2145414,428.59775,-9.2269983
2609,2609,195.4111,9.5606689,7.6352878,0.0,0,1.9115354,0.0,0.71056801,59.759232,2.1971159,428.47659,-9.2259569
2610,2610,195.4113,9.5911798,7.6501026,0.0,0,1.8970003,0.0,0.71360987,59.801941,2.1818173,428.35544,-9.2259169
2611,2611,195.4115,9.6170073,7.6748834,0.0,0,1.8824683,0.0,0.71598548,59.793869,2.1675422,428.23425,-9.2264233
2612,2612,195.4117,9.6323614,7.6851711,0.0,0,1.8679363,0.0,0.71724588,59.827591,2.1515779,428.1131,-9.22649
2613,2613,195.4119,9.6458998,7.6987047,0.0,0,1.8534042,0.0,0.72022188,59.783966,2.1348345,427.99194,-9.2259712
2614,2614,195.4121,9.6565695,7.722446,0.0,0,1.8388723,0.0,0.72272092,59.669811,2.1186385,427.87079,-9.2252092
2615,2615,195.4123,9.6631041,7.7340088,0.0,0,1.8243402,0.0,0.72384697,59.630508,2.1031051,427.74963,-9.2251215
2616,2616,195.4125,9.6791935,7.7457371,0.0,0,1.8098083,0.0,0.72664237,59.541256,2.0864866,427.62848,-9.2257967
2617,2617,195.4127,9.7052555,7.7683072,0.0,0,1.7952763,0.0,0.72924566,59.532459,2.0706747,427.50732,-9.2262497
2618,2618,195.4129,9.7318993,7.782166,0.0,0,1.7807442,0.0,0.73034626,59.653919,2.0585306,427.38617,-9.225585
2619,2619,195.4131,9.7677937,7.793541,0.0,0,1.7662122,0.0,0.73309827,59.675087,2.0442629,427.26498,-9.2251549
2620,2620,195.4133,9.8078384,7.8145418,0.0,0,1.7516803,0.0,0.73585057,59.727505,2.0258551,427.14383,-9.2251463
2621,2621,195.4135,9.8382082,7.8292327,0.0,0,1.7371483,0.0,0.73688257,59.886517,2.0107107,427.02267,-9.2256994
2622,2622,195.4137,9.8560066,7.8406243,0.0,0,1.7226163,0.0,0.73947608,59.853603,1.998163,426.90152,-9.2257271
2623,2623,195.4139,9.8607178,7.8599534,0.0,0,1.7080842,0.0,0.74241954,59.720165,1.9807209,426.78036,-9.2257595
2624,2624,195.4141,9.8700638,7.8761005,0.0,0,1.6935523,0.0,0.74357158,59.742329,1.9644619,426.65921,-9.2258291
2625,2625,195.4143,9.8830023,7.889421,0.0,0,1.6790203,0.0,0.74602818,59.665672,1.952608,426.53806,-9.2252283
2626,2626,195.4145,9.8992386,7.9075046,0.0,0,1.6644882,0.0,0.74916613,59.561596,1.9367952,426.4169,-9.2253246
2627,2627,195.4147,9.9271965,7.9249773,0.0,0,1.6499562,0.0,0.7505011,59.654087,1.9185399,426.29572,-9.2252073
2628,2628,195.4149,9.9613943,7.9377131,0.0,0,1.6354243,0.0,0.75266194,59.731945,1.9042624,426.17456,-9.224988
2629,2629,195.4151,9.9960194,7.9520016,0.0,0,1.6208922,0.0,0.75561589,59.75774,1.8919746,426.05341,-9.2249746
2630,2630,195.4153,10.033485,7.9700942,0.0,0,1.6063603,0.0,0.75704294,59.868446,1.8737906,425.93225,-9.2244463
2631,2631,195.4155,10.065157,7.9836926,0.0,0,1.5918282,0.0,0.75901508,59.948399,1.8555921,425.8111,-9.2244883
2632,2632,195.4157,10.079836,7.9966574,0.0,0,1.5772963,0.0,0.76200175,59.868568,1.8415209,425.68994,-9.2250242
2633,2633,195.4159,10.084127,8.01682,0.0,0,1.5630547,0.0,0.76382345,59.783554,1.8268154,425.56879,-9.2249842
2634,2634,195.4161,10.094858,8.0327663,0.0,0,1.5491643,0.0,0.76584184,59.737091,1.8104068,425.44763,-9.2251463
2635,2635,195.4163,10.117852,8.0435066,0.0,0,1.5353372,0.0,0.76880372,59.695236,1.7954279,425.32648,-9.225153
2636,2636,195.4165,10.139446,8.0628357,0.0,0,1.5215131,0.0,0.77068251,59.726055,1.7811463,425.20529,-9.2249899
2637,2637,195.4167,10.159947,8.0791969,0.0,0,1.5076891,0.0,0.77237505,59.734505,1.7661693,425.08414,-9.224906
2638,2638,195.4169,10.195799,8.0874519,0.0,0,1.4938651,0.0,0.77508366,59.747349,1.7505403,424.96298,-9.2250452
2639,2639,195.4171,10.236215,8.1072569,0.0,0,1.4800411,0.0,0.77729028,59.837116,1.7345425,424.84183,-9.2245989
2640,2640,195.4173,10.265937,8.1256599,0.0,0,1.4662172,0.0,0.77901626,59.923759,1.7173884,424.72067,-9.2245846
2641,2641,195.4175,10.287706,8.13239,0.0,0,1.4523932,0.0,0.78146154,59.912899,1.7031065,424.59952,-9.2250357
2642,2642,195.4177,10.301045,8.1505499,0.0,0,1.4385692,0.0,0.78382742,59.851635,1.6911408,424.51221,-9.2254581
2643,2643,195.4179,10.309103,8.1710138,0.0,0,1.4247452,0.0,0.78552455,59.80051,1.6734211,424.45874,-9.226099
2644,2644,195.4181,10.323442,8.1777754,0.0,0,1.4109212,0.0,0.78776246,59.759651,1.6570766,424.40524,-9.2259293
2645,2645,195.4183,10.347638,8.1948328,0.0,0,1.3970972,0.0,0.7903946,59.749161,1.6446748,424.35178,-9.2256451
2646,2646,195.4185,10.372425,8.217618,0.0,0,1.3832732,0.0,0.7922411,59.787628,1.6299411,424.29831,-9.2252588
2647,2647,195.4187,10.398143,8.2246246,0.0,0,1.3694493,0.0,0.79435652,59.818012,1.613842,424.24484,-9.2248735
2648,2648,195.4189,10.432422,8.2411251,0.0,0,1.3556252,0.0,0.79733461,59.837406,1.5977365,424.19135,-9.2242994
2649,2649,195.4191,10.467384,8.2642756,0.0,0,1.3418012,0.0,0.7991848,59.895649,1.5833451,424.13788,-9.2230921
2650,2650,195.4193,10.495676,8.2704306,0.0,0,1.3279773,0.0,0.80094671,59.954742,1.5688879,424.08441,-9.2231846
2651,2651,195.4195,10.518575,8.2848425,0.0,0,1.3141533,0.0,0.80400807,59.930164,1.5544951,424.03094,-9.2237778
2652,2652,195.4197,10.536143,8.3080072,0.0,0,1.3003292,0.0,0.80598658,59.861771,1.5402132,423.97745,-9.2242327
2653,2653,195.4199,10.548439,8.3156023,0.0,0,1.2865052,0.0,0.80758017,59.857513,1.5256009,423.92398,-9.2251062
2654,2654,195.4201,10.562027,8.3301601,0.0,0,1.2726812,0.0,0.81081605,59.783726,1.5128022,423.87051,-9.2251472
2655,2655,195.4203,10.581857,8.353241,0.0,0,1.2588573,0.0,0.81297642,59.753605,1.4990062,423.81705,-9.2255201
2656,2656,195.4205,10.610819,8.3605881,0.0,0,1.2450333,0.0,0.81419152,59.827137,1.483448,423.76355,-9.2261534
2657,2657,195.4207,10.644413,8.372633,0.0,0,1.2312093,0.0,0.81717092,59.818279,1.4681807,423.71008,-9.2256632
2658,2658,195.4209,10.67557,8.393549,0.0,0,1.2176626,0.0,0.81927657,59.854252,1.4540737,423.65662,-9.225028
2659,2659,195.4211,10.703659,8.4011812,0.0,0,1.2044512,0.0,0.82014674,59.963558,1.4404802,423.60315,-9.2244501
2660,2660,195.4213,10.73002,8.4120522,0.0,0,1.1913005,0.0,0.82305533,59.958248,1.4274684,423.54965,-9.2239618
2661,2661,195.4215,10.757647,8.4334545,0.0,0,1.1781523,0.0,0.8256284,59.954372,1.4130954,423.49619,-9.2245169
2662,2662,195.4217,10.776944,8.4438267,0.0,0,1.1650044,0.0,0.8265816,59.993641,1.3977381,423.44272,-9.2248402
2663,2663,195.4219,10.783384,8.4554796,0.0,0,1.1518563,0.0,0.82964295,59.888306,1.3813472,423.38925,-9.2247992
2664,2664,195.4221,10.798409,8.4776421,0.0,0,1.1387082,0.0,0.83271664,59.807709,1.3682795,423.33575,-9.2249365
2665,2665,195.4223,10.832685,8.4913282,0.0,0,1.1255603,0.0,0.8338384,59.879013,1.3570381,423.28229,-9.2245789
2666,2666,195.4225,10.866758,8.5026503,0.0,0,1.1124123,0.0,0.83668786,59.869049,1.3411583,423.22882,-9.2245884
2667,2667,195.4227,10.892097,8.5219202,0.0,0,1.0992643,0.0,0.83969069,59.847771,1.3231349,423.17535,-9.225132
2668,2668,195.4229,10.916211,8.5358963,0.0,0,1.0861163,0.0,0.84064245,59.935894,1.3096502,423.12189,-9.2252541
2669,2669,195.4231,10.948352,8.5462017,0.0,0,1.0729682,0.0,0.84326971,59.922623,1.2959092,423.06839,-9.2251053
2670,2670,195.4233,10.970311,8.5626879,0.0,0,1.0598202,0.0,0.84634894,59.863892,1.2808826,423.01492,-9.2251883
2671,2671,195.4235,10.993988,8.5765944,0.0,0,1.0466722,0.0,0.84717625,59.990833,1.268003,422.96146,-9.2252207
2672,2672,195.4237,11.021305,8.5864468,0.0,0,1.0335243,0.0,0.84920162,60.011581,1.2541064,422.90799,-9.2249928
2673,2673,195.4239,11.035387,8.6001663,0.0,0,1.0203762,0.0,0.85215479,59.910236,1.239215,422.85449,-9.225522
2674,2674,195.4241,11.057364,8.6152201,0.0,0,1.0072283,0.0,0.85327554,59.985435,1.2261792,422.80103,-9.2256565
2675,2675,195.4243,11.083107,8.6270046,0.0,0,0.99408025,0.0,0.85541099,60.010029,1.2125689,422.74756,-9.2253475
2676,2676,195.4245,11.112556,8.6404228,0.0,0,0.98093224,0.0,0.85861462,59.955296,1.1973748,422.69409,-9.2253733
2677,2677,195.4247,11.142661,8.6590099,0.0,0,0.96778423,0.0,0.86003256,59.975994,1.1835653,422.64059,-9.225111
2678,2678,195.4249,11.167559,8.6733332,0.0,0,0.95463622,0.0,0.86221194,59.987663,1.1703176,422.58713,-9.2244635
2679,2679,195.4251,11.198192,8.684185,0.0,0,0.94148827,0.0,0.86538684,59.999519,1.156319,422.53366,-9.224432
2680,2680,195.4253,11.230584,8.7018747,0.0,0,0.92834032,0.0,0.86697459,60.075737,1.1403332,422.48019,-9.2249537
2681,2681,195.4255,11.260318,8.7156162,0.0,0,0.91519231,0.0,0.86879981,60.102806,1.1270158,422.4267,-9.2249756
2682,2682,195.4257,11.279801,8.7236853,0.0,0,0.9020443,0.0,0.87179136,60.068104,1.1147367,422.37323,-9.2249813
2683,2683,195.4259,11.294369,8.7415485,0.0,0,0.88916039,0.0,0.87373286,60.041187,1.0999582,422.31976,-9.224947
2684,2684,195.4261,11.31749,8.7568827,0.0,0,0.87659597,0.0,0.87539655,59.998154,1.0860484,422.2663,-9.2244549
2685,2685,195.4263,11.345075,8.764226,0.0,0,0.86408937,0.0,0.87818313,59.974159,1.0721853,422.2128,-9.224472
2686,2686,195.4265,11.370238,8.7822628,0.0,0,0.85158527,0.0,0.88040417,59.987648,1.0582908,422.15933,-9.2250099
2687,2687,195.4267,11.392225,8.7989035,0.0,0,0.83908123,0.0,0.88192707,60.015308,1.0466245,422.10587,-9.2250328
2688,2688,195.4269,11.427858,8.8034353,0.0,0,0.82657719,0.0,0.88420361,60.036221,1.0321447,422.0524,-9.224987
2689,2689,195.4271,11.461793,8.8190365,0.0,0,0.8140732,0.0,0.88648504,60.06311,1.0178095,421.9989,-9.2248716
2690,2690,195.4273,11.485355,8.8379354,0.0,0,0.80156928,0.0,0.88808972,60.132931,1.0039247,421.94543,-9.2244482
2691,2691,195.4275,11.517584,8.8429928,0.0,0,0.78906524,0.0,0.89040917,60.15453,0.99023575,421.89197,-9.2245302
2692,2692,195.4277,11.539859,8.859621,0.0,0,0.77656126,0.0,0.89327604,60.105629,0.97819459,421.74677,-9.2244968
2693,2693,195.4279,11.555048,8.8817616,0.0,0,0.76405728,0.0,0.89511883,60.076908,0.96427184,421.50989,-9.2238922
2694,2694,195.4281,11.575933,8.8866758,0.0,0,0.75155324,0.0,0.89710242,60.067345,0.94916081,421.27298,-9.2243261
2695,2695,195.4283,11.595546,8.9003868,0.0,0,0.73904926,0.0,0.90007889,60.018906,0.93547839,421.0361,-9.2249594
2696,2696,195.4285,11.624294,8.9210176,0.0,0,0.72654527,0.0,0.90179759,60.034225,0.92273772,420.79919,-9.2250175
2697,2697,195.4287,11.663687,8.924799,0.0,0,0.71404123,0.0,0.9031688,60.126053,0.9103632,420.56232,-9.2249641
2698,2698,195.4289,11.703396,8.9367838,0.0,0,0.70153725,0.0,0.90625197,60.160915,0.89649385,420.32541,-9.224926
2699,2699,195.4291,11.736711,8.9578333,0.0,0,0.68903327,0.0,0.90819001,60.239166,0.88451898,420.08853,-9.2242928
2700,2700,195.4293,11.767424,8.9634924,0.0,0,0.67652929,0.0,0.90949893,60.309948,0.87098819,419.85162,-9.2244043
2701,2701,195.4295,11.791963,8.9757891,0.0,0,0.66402531,0.0,0.91275835,60.243919,0.85521168,419.61475,-9.2250385
2702,2702,195.4297,11.813524,8.9987593,0.0,0,0.65152127,0.0,0.91495812,60.240559,0.84318602,419.37784,-9.2243452
2703,2703,195.4299,11.834974,9.0068178,0.0,0,0.63901722,0.0,0.91632277,60.268028,0.83178806,419.14096,-9.2238054
2704,2704,195.4301,11.854061,9.0173264,0.0,0,0.62651324,0.0,0.91964203,60.181499,0.81847054,418.90405,-9.2242718
2705,2705,195.4303,11.874255,9.038126,0.0,0,0.61400926,0.0,0.92199427,60.143456,0.80611295,418.66718,-9.223979
2706,2706,195.4305,11.900295,9.0461769,0.0,0,0.60150528,0.0,0.92295039,60.186581,0.79642797,418.43027,-9.2240791
2707,2707,195.4307,11.935624,9.0559902,0.0,0,0.58900124,0.0,0.92605585,60.176624,0.78200448,418.19339,-9.2249594
2708,2708,195.4309,11.97598,9.0759115,0.0,0,0.57674497,0.0,0.92864031,60.217545,0.76789576,417.95648,-9.2249994
2709,2709,195.4311,12.018119,9.0847006,0.0,0,0.56478834,0.0,0.92922235,60.401031,0.7566731,417.7196,-9.2243147
2710,2710,195.4313,12.050156,9.0932865,0.0,0,0.55288589,0.0,0.93209302,60.396862,0.74248385,417.4827,-9.2237263
2711,2711,195.4315,12.069144,9.1122599,0.0,0,0.54098582,0.0,0.9351384,60.28912,0.72829497,417.24582,-9.2230358
2712,2712,195.4317,12.078568,9.1239691,0.0,0,0.52908581,0.0,0.93594545,60.314869,0.71669555,417.00891,-9.223485
2713,2713,195.4319,12.092559,9.1322126,0.0,0,0.51718581,0.0,0.93855965,60.229244,0.70431566,416.77203,-9.2241526
2714,2714,195.4321,12.113439,9.1490889,0.0,0,0.5052858,0.0,0.94165033,60.143063,0.68993729,416.53513,-9.2235518
2715,2715,195.4323,12.140467,9.1624632,0.0,0,0.49338579,0.0,0.94257462,60.211941,0.67579067,416.29825,-9.2235184
2716,2716,195.4325,12.17962,9.1717815,0.0,0,0.48148578,0.0,0.94514602,60.236282,0.66323286,416.06134,-9.2239943
2717,2717,195.4327,12.219055,9.1878633,0.0,0,0.46958581,0.0,0.94849527,60.246284,0.65032619,415.82446,-9.2241907
2718,2718,195.4329,12.259019,9.2030191,0.0,0,0.4576858,0.0,0.94951117,60.353416,0.63740861,415.58755,-9.2244043
2719,2719,195.4331,12.302782,9.2135983,0.0,0,0.44578579,0.0,0.95198315,60.407436,0.62653923,415.35068,-9.2247496
2720,2720,195.4333,12.330351,9.227541,0.0,0,0.43388578,0.0,0.95538658,60.371471,0.61365002,415.11377,-9.2247515
2721,2721,195.4335,12.34907,9.2428102,0.0,0,0.42198581,0.0,0.95656961,60.407207,0.59942478,414.87689,-9.2243671
2722,2722,195.4337,12.371248,9.2520084,0.0,0,0.4100858,0.0,0.95858806,60.371143,0.58786565,414.63998,-9.2243595
2723,2723,195.4339,12.393612,9.2616291,0.0,0,0.39818579,0.0,0.96159089,60.270042,0.57363588,414.40311,-9.2249403
2724,2724,195.4341,12.421644,9.2772713,0.0,0,0.38628578,0.0,0.96274489,60.347145,0.55904341,414.1662,-9.2242336