File: clean data/testID_0191.csv
level_0,index,Time(sec),Force(kN),Jaw(mm),PowAngle(deg),Power(W),Pram,PTemp,Strain,Stress(MPa),Stroke(mm),TC1(C),wedge(mm)
1773,1773,145.3471,0.69572574,0.020477535,0.0,0,9.0337067,0.0,0.0013225207,8.5658798,10.077297,310.9581,-9.3270798
1775,1775,145.3475,2.8199632,0.041072767,0.0,0,8.9751787,0.0,0.0026984648,30.957651,10.015149,311.45758,-9.3243484
1777,1777,145.3479,6.0190563,0.095308654,0.0,0,8.9166508,0.0,0.0058793314,73.829674,9.9563675,311.95703,-9.3240023
1779,1779,145.3483,6.6603799,0.14363445,0.0,0,8.8581219,0.0,0.0090617491,83.186165,9.8921156,312.45651,-9.320899
1781,1781,145.3487,7.5652351,0.26753917,0.0,0,8.7995939,0.0,0.017264314,93.88578,9.8096867,312.95596,-9.3206816
1783,1783,145.3491,7.723351,0.37455508,0.0,0,8.7416534,0.0,0.024432015,95.379669,9.7119284,313.45544,-9.3207092
1785,1785,145.3495,8.5883312,0.46284235,0.0,0,8.6858492,0.0,0.030663207,105.2542,9.6043386,313.9549,-9.3214111
1787,1787,145.3499,9.0825548,0.55076289,0.0,0,8.6301851,0.0,0.037009228,110.74689,9.5068512,314.45438,-9.3194857
1789,1789,145.3503,9.2780552,0.59750873,0.0,0,8.574522,0.0,0.039965738,113.90335,9.4209776,314.95383,-9.3182278
1791,1791,145.3507,9.036355,0.67294955,0.0,0,8.518857,0.0,0.045580618,109.80453,9.3477917,315.45331,-9.3195772
1793,1793,145.3511,9.5797796,0.73057204,0.0,0,8.4631929,0.0,0.049573753,115.53593,9.2790232,315.95276,-9.3202248
1795,1795,145.3515,9.9413309,0.79961258,0.0,0,8.4075298,0.0,0.053981666,119.53911,9.2114296,316.43512,-9.3186789
1797,1797,145.3519,9.9271784,0.89727813,0.0,0,8.3518648,0.0,0.061212953,119.26687,9.1280727,316.89182,-9.3171024
1799,1799,145.3523,9.7060118,0.99472499,0.0,0,8.2962017,0.0,0.067779213,115.30777,9.0413141,317.34851,-9.3173037
1801,1801,145.3527,10.027473,1.0859674,0.0,0,8.2405376,0.0,0.074441664,118.2988,8.9533291,317.80521,-9.3180056
1803,1803,145.3531,10.177933,1.1415604,0.0,0,8.1848736,0.0,0.079062425,119.38625,8.8713503,318.2619,-9.3173532
1805,1805,145.3535,10.43441,1.1829398,0.0,0,8.1292095,0.0,0.081555903,122.44386,8.8034315,318.7186,-9.317523
1807,1807,145.3539,10.121092,1.245375,0.0,0,8.0735455,0.0,0.086353444,118.49522,8.7449322,319.17529,-9.3181334
1809,1809,145.3543,10.453683,1.2884296,0.0,0,8.0196619,0.0,0.089641199,121.0162,8.6893587,319.63199,-9.3196363
1811,1811,145.3547,10.653554,1.3544078,0.0,0,7.9666953,0.0,0.093859345,123.50887,8.63029,320.08868,-9.3177376
1813,1813,145.3551,10.671007,1.4353951,0.0,0,7.9137359,0.0,0.10029634,122.86788,8.5638361,320.54538,-9.3165226
1815,1815,145.3555,10.52229,1.5067732,0.0,0,7.8607755,0.0,0.10527818,120.84965,8.4934368,321.00208,-9.3163404
1817,1817,145.3559,10.583076,1.5753362,0.0,0,7.8078156,0.0,0.11038012,120.39917,8.4267387,321.45877,-9.3171062
1819,1819,145.3563,10.792202,1.6172755,0.0,0,7.7548552,0.0,0.1141148,122.45734,8.3635712,321.91547,-9.3178606
1821,1821,145.3567,10.848343,1.6659518,0.0,0,7.7018952,0.0,0.11707549,122.82694,8.3067341,322.37216,-9.3184767
1823,1823,145.3571,10.822765,1.7220488,0.0,0,7.6489348,0.0,0.12158083,122.1489,8.2551775,322.82886,-9.3178082
1825,1825,145.3575,10.923691,1.7587292,0.0,0,7.5959754,0.0,0.12467291,122.40653,8.2059574,323.28555,-9.316308
1827,1827,145.3579,11.087131,1.8203105,0.0,0,7.543015,0.0,0.12855689,124.10079,8.1544037,323.74225,-9.317709
1829,1829,145.3583,11.078568,1.8806771,0.0,0,7.4900556,0.0,0.13362269,123.41948,8.0958519,324.19894,-9.3178997
1831,1831,145.3587,11.109891,1.9413227,0.0,0,7.4370952,0.0,0.13819835,123.30322,8.0356941,324.65564,-9.3177958
1833,1833,145.3591,11.097136,2.006022,0.0,0,7.3846664,0.0,0.14274926,122.33454,7.9779015,325.11234,-9.3189735
1835,1835,145.3595,11.265887,2.0395257,0.0,0,7.3341722,0.0,0.14612973,123.81704,7.9224524,325.56903,-9.3176527
1837,1837,145.3599,11.260649,2.0853398,0.0,0,7.2838039,0.0,0.14928989,123.42735,7.8720093,326.02573,-9.317565
1839,1839,145.3603,11.297887,2.1424172,0.0,0,7.2334356,0.0,0.15353347,123.29861,7.8273468,326.48242,-9.317028
1841,1841,145.3607,11.337216,2.174027,0.0,0,7.1830673,0.0,0.1566305,123.26598,7.7771072,326.93909,-9.3172388
1843,1843,145.3611,11.516528,2.2266593,0.0,0,7.1326995,0.0,0.16012307,124.78115,7.7331638,327.39578,-9.3180628
1845,1845,145.3615,11.51438,2.2855375,0.0,0,7.0823312,0.0,0.16471818,124.50552,7.6829777,327.64917,-9.3193493
1847,1847,145.3619,11.477081,2.3307235,0.0,0,7.0319633,0.0,0.1687485,123.41836,7.633368,327.65405,-9.3187599
1849,1849,145.3623,11.5201,2.3821335,0.0,0,6.981595,0.0,0.17235312,123.31297,7.5818734,327.65894,-9.3171101
1851,1851,145.3627,11.670848,2.4240818,0.0,0,6.9312277,0.0,0.17603667,124.38728,7.5307274,327.66382,-9.3166056
1853,1853,145.3631,11.71595,2.4658065,0.0,0,6.8808594,0.0,0.17932603,124.65114,7.4844389,327.6687,-9.3164091
1855,1855,145.3635,11.681201,2.5141423,0.0,0,6.830492,0.0,0.18283249,123.82136,7.4390998,327.67358,-9.3174534
1857,1857,145.3639,11.728601,2.5563848,0.0,0,6.7801232,0.0,0.18681405,123.8093,7.3949952,327.6785,-9.3193197
1859,1859,145.3643,11.853835,2.6039541,0.0,0,6.7313671,0.0,0.19025557,124.52134,7.3491654,327.68338,-9.3180981
1861,1861,145.3647,11.932549,2.6543674,0.0,0,6.6834416,0.0,0.19411777,125.02888,7.3000731,327.68826,-9.3166571
1863,1863,145.3651,11.918507,2.70274,0.0,0,6.6355219,0.0,0.19867298,124.39006,7.2538762,327.69315,-9.317275
1865,1865,145.3655,11.925841,2.7501884,0.0,0,6.5876017,0.0,0.20202245,124.04649,7.2048607,327.69803,-9.3179693
1867,1867,145.3659,12.036049,2.7930038,0.0,0,6.5396819,0.0,0.20550972,124.58125,7.1575427,327.70291,-9.3174524
1869,1869,145.3663,12.11566,2.8337877,0.0,0,6.4917622,0.0,0.20945905,125.0665,7.1088772,327.70779,-9.3185043
1871,1871,145.3667,12.151667,2.8841021,0.0,0,6.4438419,0.0,0.21280791,125.0681,7.0667939,327.71268,-9.3178167
1873,1873,145.3671,12.188302,2.9285791,0.0,0,6.3959212,0.0,0.21689317,124.91032,7.0204434,327.71756,-9.3179226
1875,1875,145.3675,12.266513,2.9766369,0.0,0,6.3480015,0.0,0.22099198,125.16132,6.9724717,327.72244,-9.3174582
1877,1877,145.3679,12.322466,3.0332079,0.0,0,6.3000817,0.0,0.22499605,125.3084,6.9240336,327.72733,-9.3178616
1879,1879,145.3683,12.349467,3.0758555,0.0,0,6.252162,0.0,0.2292864,125.00892,6.8759036,327.73221,-9.3184118
1881,1881,145.3687,12.422561,3.1206527,0.0,0,6.2042422,0.0,0.23289651,125.1539,6.8273292,327.73709,-9.3183708
1883,1883,145.3691,12.48947,3.1735551,0.0,0,6.1568027,0.0,0.23689809,125.40115,6.7752223,327.742,-9.3182631
1885,1885,145.3695,12.523205,3.212604,0.0,0,6.1111121,0.0,0.24101667,125.30715,6.7298393,327.74689,-9.3184652
1887,1887,145.3699,12.572266,3.2581699,0.0,0,6.065536,0.0,0.24436583,125.38274,6.6809716,327.75177,-9.3179092
1889,1889,145.3703,12.646954,3.3143077,0.0,0,6.0199599,0.0,0.24899806,125.43243,6.6328244,327.75665,-9.3188
1891,1891,145.3707,12.747568,3.3563623,0.0,0,5.9743834,0.0,0.25317022,125.8205,6.5871387,327.76154,-9.3183298
1893,1893,145.3711,12.786332,3.4083884,0.0,0,5.9288077,0.0,0.2570141,125.86143,6.5375233,327.76642,-9.3190603
1895,1895,145.3715,12.79344,3.461632,0.0,0,5.8832321,0.0,0.26195478,125.32066,6.4859281,327.80307,-9.3188133
1897,1897,145.3719,12.850358,3.5026314,0.0,0,5.8376555,0.0,0.26575232,125.38464,6.4410291,327.87146,-9.3178787
1899,1899,145.3723,12.941093,3.5543838,0.0,0,5.792079,0.0,0.26964155,125.8001,6.3899355,327.93988,-9.318985
1901,1901,145.3727,13.016288,3.5995295,0.0,0,5.7465038,0.0,0.27428943,125.90867,6.3423042,328.00827,-9.3179569
1903,1903,145.3731,13.038386,3.6415949,0.0,0,5.7009277,0.0,0.27779576,125.68201,6.2956066,328.07669,-9.3185616
1905,1905,145.3735,13.08097,3.6943758,0.0,0,5.6553516,0.0,0.28196606,125.51582,6.247674,328.14508,-9.3193817
1907,1907,145.3739,13.16671,3.740984,0.0,0,5.6097755,0.0,0.28686354,125.77171,6.2013192,328.21347,-9.3189983
1909,1909,145.3743,13.234636,3.78914,0.0,0,5.5656581,0.0,0.29064286,125.99924,6.1513419,328.28189,-9.3193121
1911,1911,145.3747,13.296304,3.839272,0.0,0,5.5222936,0.0,0.29499486,126.0115,6.1050663,328.35028,-9.3187113
1913,1913,145.3751,13.336661,3.8825686,0.0,0,5.4789333,0.0,0.29953715,125.79213,6.0579724,328.4187,-9.3185863
1915,1915,145.3755,13.389973,3.9355524,0.0,0,5.4355736,0.0,0.30349588,125.82187,6.0088577,328.48709,-9.3183508
1917,1917,145.3759,13.453744,3.981293,0.0,0,5.3922133,0.0,0.30804953,125.80037,5.9619832,328.55551,-9.3174839
1919,1919,145.3763,13.509275,4.0223079,0.0,0,5.3488536,0.0,0.3121607,125.89919,5.9138184,328.6239,-9.3183107
1921,1921,145.3767,13.569977,4.0783105,0.0,0,5.3054934,0.0,0.31628081,125.87241,5.8683619,328.69232,-9.3177319
1923,1923,145.3771,13.647014,4.120182,0.0,0,5.2621331,0.0,0.3208766,125.96071,5.8178625,328.76071,-9.3184757
1925,1925,145.3775,13.679426,4.1650753,0.0,0,5.2187734,0.0,0.32499766,125.81378,5.7709789,328.8291,-9.3181419
1927,1927,145.3779,13.736073,4.2205539,0.0,0,5.1754136,0.0,0.32941097,125.75266,5.7242727,328.89752,-9.3182783
1929,1929,145.3783,13.817451,4.2586198,0.0,0,5.1320534,0.0,0.3339631,125.9146,5.6762753,328.96591,-9.3173723
1931,1931,145.3787,13.890945,4.3069911,0.0,0,5.0886931,0.0,0.33792564,126.08089,5.6289377,329.03433,-9.3176479
1933,1933,145.3791,13.944092,4.3596067,0.0,0,5.0457683,0.0,0.34263122,125.97121,5.5826583,329.10272,-9.3185282
1935,1935,145.3795,13.9749,4.3994455,0.0,0,5.0044241,0.0,0.34715205,125.74163,5.533895,329.17114,-9.3184719
1937,1937,145.3799,14.030611,4.447331,0.0,0,4.9631839,0.0,0.35097334,125.69625,5.4846063,329.23953,-9.3179083
1939,1939,145.3803,14.132128,4.4976482,0.0,0,4.9219441,0.0,0.35592207,125.94528,5.4412208,329.30792,-9.3173046
1941,1941,145.3807,14.18746,4.5359058,0.0,0,4.8807039,0.0,0.36003685,125.96256,5.3971448,329.37634,-9.3177414
1943,1943,145.3811,14.235386,4.5850668,0.0,0,4.8394642,0.0,0.36396584,125.95377,5.3492041,329.44473,-9.31882
1945,1945,145.3815,14.267723,4.6316013,0.0,0,4.798224,0.0,0.36908761,125.55472,5.3044276,329.4809,-9.3188896
1947,1947,145.3819,14.34635,4.6723375,0.0,0,4.7569842,0.0,0.3729662,125.71113,5.2592497,329.49066,-9.3191023
1949,1949,145.3823,14.439538,4.7209396,0.0,0,4.715744,0.0,0.3771711,126.02654,5.2169142,329.50046,-9.318368
1951,1951,145.3827,14.502146,4.764328,0.0,0,4.6745043,0.0,0.38226163,125.8875,5.1674962,329.51022,-9.3178358
1953,1953,145.3831,14.527577,4.8092818,0.0,0,4.6332641,0.0,0.3860516,125.65146,5.1237106,329.51999,-9.3170967
1955,1955,145.3835,14.588978,4.8565416,0.0,0,4.5920238,0.0,0.39050326,125.63161,5.0804243,329.52975,-9.3185558
1957,1957,145.3839,14.662095,4.8967161,0.0,0,4.5507841,0.0,0.39530838,125.65982,5.0377226,329.53952,-9.3183336
1959,1959,145.3843,14.73536,4.9460592,0.0,0,4.5108657,0.0,0.3992213,125.75967,4.9944816,329.54932,-9.3181553
1961,1961,145.3847,14.794546,4.9888968,0.0,0,4.4716296,0.0,0.4038769,125.77483,4.9490418,329.55908,-9.3179359
1963,1963,145.3851,14.842648,5.0249438,0.0,0,4.4323978,0.0,0.4080855,125.58059,4.9078979,329.56885,-9.3172178
1965,1965,145.3855,14.901037,5.074976,0.0,0,4.3931656,0.0,0.41198692,125.57594,4.861783,329.57861,-9.3186979
1967,1967,145.3859,14.976071,5.1136084,0.0,0,4.3539338,0.0,0.41669461,125.58629,4.8190589,329.58838,-9.3179865
1969,1969,145.3863,15.078219,5.1565375,0.0,0,4.314702,0.0,0.4209902,125.95445,4.7770324,329.59818,-9.3179121
1971,1971,145.3867,15.135517,5.2093124,0.0,0,4.2754698,0.0,0.42538753,125.8821,4.7343574,329.60794,-9.318778
1973,1973,145.3871,15.168736,5.2449865,0.0,0,4.2362375,0.0,0.43025792,125.53337,4.6885748,329.61771,-9.3182678
1975,1975,145.3875,15.217905,5.2847548,0.0,0,4.1970053,0.0,0.43393579,125.49579,4.6497231,329.62747,-9.3180609
1977,1977,145.3879,15.301171,5.3322754,0.0,0,4.1577735,0.0,0.43839437,125.61774,4.6072178,329.63724,-9.3173475
1979,1979,145.3883,15.39635,5.3636532,0.0,0,4.1185417,0.0,0.44265196,125.83734,4.5647817,329.64703,-9.3165197
1981,1981,145.3887,15.457935,5.4074869,0.0,0,4.0793095,0.0,0.44629046,125.93925,4.5221138,329.6568,-9.3179121
1983,1983,145.3891,15.478304,5.4567766,0.0,0,4.0404716,0.0,0.45158362,125.42669,4.4820566,329.66656,-9.3186998
1985,1985,145.3895,15.562033,5.4899325,0.0,0,4.0030656,0.0,0.45580715,125.47437,4.4406328,329.67633,-9.3179703
1987,1987,145.3899,15.643756,5.5338092,0.0,0,3.9657533,0.0,0.45948866,125.71214,4.3996601,329.6861,-9.317687
1989,1989,145.3903,15.733191,5.5750203,0.0,0,3.9284413,0.0,0.46445215,125.86579,4.3567801,329.69589,-9.3165522
1991,1991,145.3907,15.797895,5.6082678,0.0,0,3.8911293,0.0,0.46808136,125.92172,4.317555,329.70566,-9.3170643
1993,1993,145.3911,15.838638,5.6527281,0.0,0,3.8538175,0.0,0.47207972,125.76568,4.277564,329.71542,-9.3183899
1995,1995,145.3915,15.922071,5.6927838,0.0,0,3.8165054,0.0,0.47733051,125.69975,4.237186,329.68121,-9.3171358
1997,1997,145.3919,16.002531,5.7313833,0.0,0,3.7791932,0.0,0.48107317,125.86888,4.198328,329.61771,-9.317893
1999,1999,145.3923,16.091034,5.7749186,0.0,0,3.7418811,0.0,0.4852289,126.01427,4.1582942,329.5542,-9.3180542
2001,2001,145.3927,16.155203,5.8097706,0.0,0,3.7045693,0.0,0.4900403,125.9319,4.1191945,329.49066,-9.3179951
2003,2003,145.3931,16.202398,5.8511415,0.0,0,3.6672573,0.0,0.49360442,125.8848,4.0810566,329.42715,-9.3174706
2005,2005,145.3935,16.299236,5.8919048,0.0,0,3.6299453,0.0,0.49823165,125.99662,4.0421824,329.36365,-9.3168888
2007,2007,145.3939,16.370644,5.9275637,0.0,0,3.5926332,0.0,0.50294262,126.04046,3.9990206,329.30011,-9.3168058
2009,2009,145.3943,16.462902,5.9725323,0.0,0,3.5565166,0.0,0.50664461,126.20199,3.9614367,329.2366,-9.3178234
2011,2011,145.3947,16.516945,6.005105,0.0,0,3.5210168,0.0,0.51115775,126.14571,3.9262891,329.1731,-9.3187714
2013,2013,145.3951,16.584173,6.0399637,0.0,0,3.4855206,0.0,0.51512659,126.11663,3.8875599,329.10956,-9.3180046
2015,2015,145.3955,16.668579,6.0873718,0.0,0,3.4500248,0.0,0.51927125,126.20672,3.8462079,329.04605,-9.317277
2017,2017,145.3959,16.733168,6.1193256,0.0,0,3.4145288,0.0,0.52414775,126.09052,3.8115747,328.98254,-9.3173189
2019,2019,145.3963,16.819847,6.1564536,0.0,0,3.3790326,0.0,0.52798045,126.25941,3.7727704,328.91901,-9.3176441
2021,2021,145.3967,16.906193,6.2030807,0.0,0,3.3435369,0.0,0.53255063,126.30419,3.734313,328.8555,-9.318428
2023,2023,145.3971,16.965878,6.2298479,0.0,0,3.3080409,0.0,0.53702033,126.20984,3.6997063,328.79199,-9.3178244
2025,2025,145.3975,17.042662,6.2678785,0.0,0,3.2725446,0.0,0.54032803,126.33257,3.6567824,328.72845,-9.3177404
2027,2027,145.3979,17.146223,6.3132181,0.0,0,3.2370486,0.0,0.54535908,126.44122,3.6212769,328.66495,-9.3169794
2029,2029,145.3983,17.240477,6.3421178,0.0,0,3.2015526,0.0,0.5497371,126.56854,3.5817499,328.60144,-9.3168507
2031,2031,145.3987,17.310587,6.3824682,0.0,0,3.1660566,0.0,0.55326831,126.71095,3.5477939,328.5379,-9.3163652
2033,2033,145.3991,17.370239,6.4230356,0.0,0,3.1309152,0.0,0.55861354,126.49874,3.5120599,328.4744,-9.3176785
2035,2035,145.3995,17.455923,6.4521103,0.0,0,3.0970623,0.0,0.56230819,126.62183,3.475616,328.41089,-9.3178387
2037,2037,145.3999,17.559921,6.4898562,0.0,0,3.0632944,0.0,0.56583703,126.86069,3.4406488,328.34735,-9.3171415
2039,2039,145.4003,17.656206,6.5261612,0.0,0,3.0295265,0.0,0.57116097,126.94855,3.4044631,328.28384,-9.3172321
2041,2041,145.4007,17.733749,6.5614853,0.0,0,2.9957583,0.0,0.57485235,127.05489,3.3672953,328.22034,-9.3168755
2043,2043,145.4011,17.797445,6.6022773,0.0,0,2.9619906,0.0,0.57914454,126.89565,3.3320324,328.1568,-9.3155556
2045,2045,145.4015,17.889017,6.6361904,0.0,0,2.9282222,0.0,0.58431357,126.9221,3.2940819,328.08456,-9.3162699
2047,2047,145.4019,17.992155,6.6734281,0.0,0,2.8944542,0.0,0.5878827,127.16526,3.2608876,328.0076,-9.3163185
2049,2049,145.4023,18.106848,6.7082491,0.0,0,2.8606863,0.0,0.59214026,127.50443,3.222816,327.93066,-9.3183765
2051,2051,145.4027,18.179676,6.7386303,0.0,0,2.8269184,0.0,0.5968402,127.36993,3.1874933,327.8537,-9.3172112
2053,2053,145.4031,18.245186,6.7804871,0.0,0,2.7931502,0.0,0.6004616,127.42417,3.1514478,327.77676,-9.3163443
2055,2055,145.4035,18.341091,6.8137965,0.0,0,2.7593822,0.0,0.60524285,127.39812,3.1172068,327.6998,-9.315012
2057,2057,145.4039,18.460846,6.8449588,0.0,0,2.7256143,0.0,0.60956687,127.70675,3.0800581,327.62283,-9.3148851
2059,2059,145.4043,18.564373,6.8905311,0.0,0,2.6929309,0.0,0.61367369,127.9509,3.0448463,327.5459,-9.3162575
2061,2061,145.4047,18.632164,6.9195147,0.0,0,2.6608074,0.0,0.61851948,127.76078,3.0100982,327.46893,-9.317481
2063,2063,145.4051,18.720232,6.9519591,0.0,0,2.6286874,0.0,0.62239087,127.81957,2.9745483,327.39197,-9.3178511
2065,2065,145.4055,18.818798,6.9958186,0.0,0,2.5965672,0.0,0.62686509,127.94701,2.9390149,327.31503,-9.3167467
2067,2067,145.4059,18.950634,7.0199823,0.0,0,2.5644474,0.0,0.63133049,128.28215,2.9045432,327.23807,-9.3163605
2069,2069,145.4063,19.060425,7.054884,0.0,0,2.5323272,0.0,0.63479334,128.60791,2.8702824,327.16113,-9.3162546
2071,2071,145.4067,19.127523,7.0976729,0.0,0,2.5002072,0.0,0.63990742,128.35207,2.8366446,327.08417,-9.3156872
2073,2073,145.4071,19.221762,7.1232433,0.0,0,2.4680872,0.0,0.64427596,128.40973,2.8080204,327.0072,-9.3162107
2075,2075,145.4075,19.33799,7.1607838,0.0,0,2.4359674,0.0,0.64791131,128.65973,2.7700322,326.93027,-9.3163567
2077,2077,145.4079,19.455944,7.2001696,0.0,0,2.4038472,0.0,0.65346044,128.83424,2.7335579,326.8533,-9.3167992
2079,2079,145.4083,19.569967,7.2260051,0.0,0,2.3717272,0.0,0.6573984,129.01721,2.7028532,326.77637,-9.3162956
2081,2081,145.4087,19.639305,7.2629905,0.0,0,2.3396072,0.0,0.66096467,129.07809,2.6678784,326.6994,-9.3157673
2083,2083,145.4091,19.74379,7.2971101,0.0,0,2.3078089,0.0,0.6664474,128.98907,2.6324933,326.62244,-9.3153133
2085,2085,145.4095,19.864922,7.3280182,0.0,0,2.2771804,0.0,0.67013794,129.32872,2.6002154,326.5455,-9.3158779
2087,2087,145.4099,20.000278,7.3659258,0.0,0,2.246628,0.0,0.67437965,129.62396,2.5676749,326.46854,-9.3154268
2089,2089,145.4103,20.108259,7.3969398,0.0,0,2.2160764,0.0,0.67976618,129.70084,2.538142,326.3916,-9.3148279
2091,2091,145.4107,20.195053,7.4295993,0.0,0,2.1855242,0.0,0.68323708,129.78784,2.5005462,326.31464,-9.3157005
2093,2093,145.4111,20.304539,7.4646797,0.0,0,2.1549723,0.0,0.68763804,129.90263,2.4660928,326.23767,-9.3155308
2095,2095,145.4115,20.43618,7.4922447,0.0,0,2.1244202,0.0,0.6926623,130.09187,2.4316692,326.18552,-9.3155937
2097,2097,145.4119,20.557989,7.5323081,0.0,0,2.0938683,0.0,0.69640172,130.39664,2.4001286,326.14398,-9.3157215
2099,2099,145.4123,20.674715,7.5641418,0.0,0,2.0633163,0.0,0.70118386,130.46951,2.3672516,326.10248,-9.3148584
2101,2101,145.4127,20.764072,7.5896616,0.0,0,2.0327644,0.0,0.705571,130.44713,2.3334944,326.06094,-9.3150902
2103,2103,145.4131,20.888954,7.6302791,0.0,0,2.0022123,0.0,0.70929044,130.73586,2.3020623,326.01941,-9.3151531
2105,2105,145.4135,21.007315,7.6566,0.0,0,1.9716601,0.0,0.71422845,130.88203,2.2706404,325.97787,-9.3162632
2107,2107,145.4139,21.151665,7.6854148,0.0,0,1.9411081,0.0,0.71803772,131.21516,2.2369106,325.93634,-9.315752
2109,2109,145.4143,21.26886,7.7281094,0.0,0,1.9115355,0.0,0.7225588,131.38927,2.2043121,325.89481,-9.3152523
2111,2111,145.4147,21.358318,7.7499461,0.0,0,1.8824685,0.0,0.72740936,131.34512,2.1740565,325.85327,-9.3147402
2113,2113,145.4151,21.482222,7.7815466,0.0,0,1.8534043,0.0,0.73085612,131.58101,2.1424706,325.81174,-9.3156061
2115,2115,145.4155,21.608027,7.8212771,0.0,0,1.8243403,0.0,0.73585165,131.74602,2.1091444,325.77023,-9.3162651
2117,2117,145.4159,21.754723,7.844358,0.0,0,1.7952764,0.0,0.74053031,131.9492,2.0799861,325.7287,-9.3149405
2119,2119,145.4163,21.864763,7.8774462,0.0,0,1.7662123,0.0,0.74392188,132.26826,2.0487359,325.68716,-9.3140335
2121,2121,145.4167,21.979509,7.9148564,0.0,0,1.7371484,0.0,0.74943984,132.16312,2.016696,325.64563,-9.3135509
2123,2123,145.4171,22.100973,7.9353838,0.0,0,1.7080843,0.0,0.7533232,132.42732,1.9860574,325.6041,-9.3148108
2125,2125,145.4175,22.246065,7.9705124,0.0,0,1.6790204,0.0,0.75682545,132.7769,1.9522274,325.56256,-9.3166418
2127,2127,145.4179,22.401821,8.002305,0.0,0,1.6499563,0.0,0.76223922,133.01633,1.9251422,325.52103,-9.316885
2129,2129,145.4183,22.51989,8.0288696,0.0,0,1.6208923,0.0,0.76617622,133.22191,1.8941187,325.47949,-9.3153667
2131,2131,145.4187,22.639786,8.0646563,0.0,0,1.5918283,0.0,0.77029341,133.38577,1.8655866,325.43796,-9.3131666
2133,2133,145.4191,22.774059,8.0916576,0.0,0,1.5630548,0.0,0.77573085,133.42908,1.8329508,325.39645,-9.3136129
2135,2135,145.4195,22.918713,8.12113,0.0,0,1.5353373,0.0,0.77901459,133.76619,1.8038888,325.35492,-9.3140516
2137,2137,145.4199,23.074465,8.1546965,0.0,0,1.5076892,0.0,0.78356045,134.1017,1.7737468,325.31339,-9.3152437
2139,2139,145.4203,23.218494,8.1800365,0.0,0,1.4800413,0.0,0.78874773,134.24101,1.7417462,325.27185,-9.314909
2141,2141,145.4207,23.332174,8.2122374,0.0,0,1.4523933,0.0,0.79200888,134.46298,1.715543,325.23032,-9.3138371
2143,2143,145.4211,23.462357,8.2411499,0.0,0,1.4247453,0.0,0.7966451,134.58342,1.6873883,325.18878,-9.3141375
2145,2145,145.4215,23.623415,8.2638292,0.0,0,1.3970973,0.0,0.80109209,134.9449,1.6589633,325.07761,-9.313982
2147,2147,145.4219,23.786633,8.300827,0.0,0,1.3694494,0.0,0.80465227,135.38339,1.6265868,324.94318,-9.3135309
2149,2149,145.4223,23.92524,8.3279829,0.0,0,1.3418013,0.0,0.80987507,135.45122,1.6003486,324.80878,-9.3131704
2151,2151,145.4227,24.051716,8.3538656,0.0,0,1.3141534,0.0,0.81399083,135.58144,1.5697994,324.67435,-9.3131666
2153,2153,145.4231,24.192886,8.3925819,0.0,0,1.2865053,0.0,0.81832612,135.81404,1.5377382,324.53995,-9.3143959
2155,2155,145.4235,24.354004,8.4121885,0.0,0,1.2588574,0.0,0.82296896,136.06503,1.5090996,324.40552,-9.3147173
2157,2157,145.4239,24.528097,8.4385891,0.0,0,1.2312094,0.0,0.82646686,136.56778,1.4830023,324.27112,-9.3138666
2159,2159,145.4243,24.663168,8.4761734,0.0,0,1.2044513,0.0,0.83125967,136.70114,1.452973,324.13669,-9.3131361
2161,2161,145.4247,24.783792,8.494875,0.0,0,1.1781524,0.0,0.83603305,136.68625,1.4231178,324.00229,-9.3120584
2163,2163,145.4251,24.936474,8.5250664,0.0,0,1.1518564,0.0,0.8393085,137.03792,1.39537,323.86786,-9.312314
2165,2165,145.4255,25.116245,8.5588064,0.0,0,1.1255604,0.0,0.84447521,137.32103,1.3664694,323.73346,-9.313262
2167,2167,145.4259,25.291714,8.5743093,0.0,0,1.0992644,0.0,0.84822565,137.82083,1.3423785,323.59903,-9.3146353
2169,2169,145.4263,25.430445,8.6060953,0.0,0,1.0729684,0.0,0.85153484,138.13403,1.3132073,323.46463,-9.312829
2171,2171,145.4267,25.566109,8.6389904,0.0,0,1.0466723,0.0,0.85755157,138.03235,1.2885771,323.3302,-9.3123579
2173,2173,145.4271,25.738068,8.6613741,0.0,0,1.0203763,0.0,0.86147761,138.38158,1.2592334,323.1958,-9.3115721
2175,2175,145.4275,25.932287,8.6944971,0.0,0,0.99408036,0.0,0.86528164,138.90292,1.2297781,323.06137,-9.3110971
2177,2177,145.4279,26.095509,8.7195024,0.0,0,0.96778435,0.0,0.87102085,138.96126,1.2043526,322.92697,-9.3134699
2179,2179,145.4283,26.230286,8.7410107,0.0,0,0.94148839,0.0,0.87384462,139.28491,1.1782914,322.79254,-9.3129511
2181,2181,145.4287,26.380215,8.7701702,0.0,0,0.91519243,0.0,0.87762988,139.56483,1.1498114,322.65814,-9.3131609
2183,2183,145.4291,26.546637,8.7921839,0.0,0,0.88916051,0.0,0.88282198,139.72308,1.1237894,322.52371,-9.312911
2185,2185,145.4295,26.744642,8.8218889,0.0,0,0.86408949,0.0,0.88604879,140.28847,1.0978494,322.38931,-9.3124342
2187,2187,145.4299,26.924238,8.8532696,0.0,0,0.83908135,0.0,0.89114708,140.52524,1.0674995,322.25488,-9.3111696
2189,2189,145.4303,27.070724,8.8728533,0.0,0,0.81407332,0.0,0.89610833,140.59784,1.042233,322.12048,-9.3108206
2191,2191,145.4307,27.229132,8.9032011,0.0,0,0.78906536,0.0,0.89893919,140.99931,1.0158246,321.98605,-9.3115664
2193,2193,145.4311,27.414667,8.9265528,0.0,0,0.7640574,0.0,0.90389627,141.29602,0.98956823,321.85165,-9.3125372
2195,2195,145.4315,27.610415,8.9466143,0.0,0,0.73904938,0.0,0.90778685,141.71407,0.96380848,321.7113,-9.3131437
2197,2197,145.4319,27.791601,8.9823713,0.0,0,0.71404135,0.0,0.91169137,142.13246,0.93930978,321.56949,-9.3124285
2199,2199,145.4323,27.957855,9.0015306,0.0,0,0.68903339,0.0,0.91678506,142.21277,0.91028923,321.42767,-9.3114529
2201,2201,145.4327,28.127979,9.0251017,0.0,0,0.66402543,0.0,0.92029542,142.61359,0.88761884,321.28586,-9.3113117
2203,2203,145.4331,28.313644,9.058485,0.0,0,0.63901734,0.0,0.92462134,142.93451,0.86286914,321.14404,-9.3112516
2205,2205,145.4335,28.512566,9.0721502,0.0,0,0.61400938,0.0,0.929066,143.29631,0.8340615,321.00223,-9.3114758
2207,2207,145.4339,28.699026,9.0969734,0.0,0,0.58900136,0.0,0.93194467,143.84065,0.80838531,320.86041,-9.3114452
2209,2209,145.4343,28.862417,9.1335373,0.0,0,0.56478846,0.0,0.93749636,143.83278,0.78229052,320.7186,-9.3111801
2211,2211,145.4347,29.047939,9.1481667,0.0,0,0.54098594,0.0,0.94186842,144.10091,0.75750828,320.57678,-9.3108902
2213,2213,145.4351,29.226959,9.1753941,0.0,0,0.51718587,0.0,0.94469303,144.58446,0.73388565,320.43497,-9.3115015
2215,2215,145.4355,29.427919,9.203619,0.0,0,0.49338591,0.0,0.95032686,144.7735,0.71047664,320.29315,-9.3110399
2217,2217,145.4359,29.610525,9.2180538,0.0,0,0.4695859,0.0,0.95373362,145.19136,0.68271983,320.15134,-9.3114901
2219,2219,145.4363,29.77873,9.2472458,0.0,0,0.44578591,0.0,0.95683926,145.55209,0.65992975,320.00952,-9.310813
2221,2221,145.4367,29.963781,9.2703476,0.0,0,0.42198589,0.0,0.96268791,145.61649,0.63543224,319.86771,-9.3098726
2223,2223,145.4371,30.165051,9.2887239,0.0,0,0.39818591,0.0,0.96560216,146.12953,0.60828382,319.72589,-9.3094006
2225,2225,145.4375,30.362341,9.3169127,0.0,0,0.37438589,0.0,0.96933138,146.57767,0.5867551,319.58405,-9.3098106
2227,2227,145.4379,30.549335,9.3376837,0.0,0,0.35058588,0.0,0.97488308,146.65981,0.5660454,319.44223,-9.310607
2229,2229,145.4383,30.719244,9.3612967,0.0,0,0.32678592,0.0,0.97769982,147.0676,0.54342449,319.30042,-9.3104992
2230,2230,145.4385,30.803173,9.3705101,0.0,0,0.31488591,0.0,0.98097247,146.95995,0.53071779,319.22952,-9.3100767