File: clean data/testID_0154.csv
level_0,index,Time(sec),Force(kN),Jaw(mm),PowAngle(deg),Power(W),Pram,PTemp,Strain,Stress(MPa),Stroke(mm),TC1(C),wedge(mm)
2410,2410,195.3751,0.73903388,0.016172437,0.0,0,9.9788637,0.0,0.0008395621,9.1718073,10.081722,450.28165,-9.2351551
2421,2421,195.3773,1.9424495,0.028834324,0.0,0,9.9458637,0.0,0.0021077124,24.40871,10.046235,450.46646,-9.2347374
2432,2432,195.3795,3.1024015,0.047665585,0.0,0,9.9128637,0.0,0.0028934684,39.197994,10.02171,450.65128,-9.2340622
2443,2443,195.3817,3.781575,0.067031145,0.0,0,9.8798637,0.0,0.0046373028,47.804832,9.9889154,450.83609,-9.233778
2454,2454,195.3839,4.1445074,0.10139532,0.0,0,9.8468628,0.0,0.0065646702,52.329823,9.9498539,451.17404,-9.2328424
2465,2465,195.3861,4.3493123,0.1361393,0.0,0,9.8138638,0.0,0.009363302,54.827545,9.9099684,451.64929,-9.2327423
2476,2476,195.3883,4.5005517,0.17894541,0.0,0,9.7808638,0.0,0.011595697,56.486141,9.8736439,452.12451,-9.2327929
2487,2487,195.3905,4.6139913,0.20835976,0.0,0,9.7478638,0.0,0.014161477,57.880684,9.8364277,452.59976,-9.2332954
2498,2498,195.3927,4.685895,0.24379762,0.0,0,9.7148628,0.0,0.016225232,58.627701,9.8018208,453.07501,-9.2319202
2509,2509,195.3949,4.7534556,0.27555832,0.0,0,9.6818638,0.0,0.018798431,59.283512,9.7659178,453.43253,-9.2324524
2520,2520,195.3971,4.7915688,0.31572729,0.0,0,9.6488638,0.0,0.020907167,59.65033,9.7311277,453.78894,-9.2330904
2531,2531,195.3993,4.8126755,0.34224468,0.0,0,9.6158638,0.0,0.023209702,59.846626,9.6976738,454.14539,-9.2330132
2542,2542,195.4015,4.8312244,0.3764196,0.0,0,9.5828629,0.0,0.02518888,59.992661,9.6653185,454.5018,-9.2344732
2553,2553,195.4037,4.8368487,0.40486133,0.0,0,9.5498638,0.0,0.027639715,59.904091,9.6329393,454.71423,-9.2338963
2564,2564,195.4059,4.8658066,0.44401303,0.0,0,9.5168638,0.0,0.029668212,60.228462,9.6005373,454.75381,-9.2328959
2575,2575,195.4081,4.8990369,0.47000781,0.0,0,9.4838638,0.0,0.032022666,60.358418,9.5669317,454.79343,-9.2329407
2586,2586,195.4103,4.9239764,0.50367159,0.0,0,9.451623,0.0,0.034012608,60.568645,9.5336542,454.83301,-9.2333336
2597,2597,195.4125,4.956346,0.53335929,0.0,0,9.4194326,0.0,0.036457665,60.774094,9.5005045,454.87262,-9.2332602
2608,2608,195.4147,4.9921594,0.57366979,0.0,0,9.3872423,0.0,0.038732614,61.145645,9.4679146,454.96677,-9.2346258
2619,2619,195.4169,5.0213227,0.5983606,0.0,0,9.355051,0.0,0.040855702,61.34547,9.4358072,455.06577,-9.2340279
2630,2630,195.4191,5.037334,0.63620347,0.0,0,9.3228617,0.0,0.043162085,61.468571,9.3961515,455.16479,-9.2335901
2641,2641,195.4213,5.0325575,0.66678816,0.0,0,9.2906713,0.0,0.045604561,61.129379,9.3608942,455.26379,-9.2332535
2652,2652,195.4235,5.0280848,0.70711672,0.0,0,9.258481,0.0,0.047998451,61.015244,9.3299637,455.38803,-9.2343082
2663,2663,195.4257,5.0386295,0.73214203,0.0,0,9.2262897,0.0,0.05013524,61.018547,9.299963,455.55304,-9.2344761
2674,2674,195.4279,5.050602,0.7649501,0.0,0,9.1940994,0.0,0.052184056,60.985218,9.266798,455.71805,-9.2340078
2685,2685,195.4301,5.0830531,0.7931841,0.0,0,9.1619081,0.0,0.054464202,61.332035,9.2330923,455.88306,-9.2342529
2696,2696,195.4323,5.0906935,0.83163142,0.0,0,9.1297188,0.0,0.056771722,61.338142,9.2022934,456.04807,-9.2334776
2707,2707,195.4345,5.1084743,0.8579855,0.0,0,9.0975285,0.0,0.05900931,61.303162,9.1702681,456.1796,-9.2333002
2718,2718,195.4367,5.1298323,0.8915354,0.0,0,9.0653381,0.0,0.061088692,61.453461,9.1385126,456.30499,-9.2337475
2729,2729,195.4389,5.149992,0.91944504,0.0,0,9.0331469,0.0,0.063373268,61.537376,9.1042614,456.43042,-9.2329416
2740,2740,195.4411,5.144557,0.95821774,0.0,0,9.0009575,0.0,0.065766111,61.377445,9.0719032,456.55582,-9.2343206
2751,2751,195.4433,5.1640177,0.98605329,0.0,0,8.9687662,0.0,0.068032928,61.439919,9.0417347,456.66898,-9.2347746
2762,2762,195.4455,5.1869626,1.0200187,0.0,0,8.9365768,0.0,0.070284575,61.533875,9.0057459,456.75479,-9.2340193
2773,2773,195.4477,5.2138815,1.0485655,0.0,0,8.9043856,0.0,0.072528832,61.606869,8.9723091,456.84061,-9.2337847
2784,2784,195.4499,5.2266693,1.0876658,0.0,0,8.8721952,0.0,0.07502231,61.721653,8.940979,456.92642,-9.2338648
2795,2795,195.4521,5.2513118,1.1136523,0.0,0,8.8400049,0.0,0.077209875,61.878761,8.9049864,457.01224,-9.2331944
2806,2806,195.4543,5.2612038,1.14833,0.0,0,8.8078146,0.0,0.079501875,61.842346,8.8749971,457.05212,-9.2348728
2817,2817,195.4565,5.26965,1.1771041,0.0,0,8.7756243,0.0,0.081773326,61.795918,8.8419962,457.07852,-9.2358294
2828,2828,195.4587,5.2780323,1.2159235,0.0,0,8.7437658,0.0,0.08432851,61.858662,8.8088522,457.10492,-9.2350826
2839,2839,195.4609,5.2790642,1.2422019,0.0,0,8.7131491,0.0,0.086474992,61.668938,8.7758112,457.13132,-9.2347946
2850,2850,195.4631,5.2946506,1.2771627,0.0,0,8.6825333,0.0,0.088906057,61.653091,8.7440023,457.14838,-9.23386
2861,2861,195.4653,5.3212142,1.3063915,0.0,0,8.6519194,0.0,0.091086835,61.885078,8.7097006,457.13516,-9.2336674
2872,2872,195.4675,5.3270826,1.3427176,0.0,0,8.6213045,0.0,0.093661986,61.722183,8.6785698,457.12198,-9.2339449
2883,2883,195.4697,5.3229933,1.3687342,0.0,0,8.5906887,0.0,0.095668025,61.619709,8.6506844,457.10876,-9.2352743
2894,2894,195.4719,5.3201547,1.399968,0.0,0,8.5600729,0.0,0.097884752,61.451042,8.6182384,457.09558,-9.2339983
2905,2905,195.4741,5.329567,1.4264425,0.0,0,8.529459,0.0,0.0998317,61.371918,8.5861912,456.57874,-9.233345
2916,2916,195.4763,5.3336129,1.460838,0.0,0,8.4988432,0.0,0.10242135,61.284317,8.5600424,455.8461,-9.2332411
2927,2927,195.4785,5.3345366,1.4866337,0.0,0,8.4682283,0.0,0.1042885,61.189735,8.530961,455.11343,-9.2340193
2938,2938,195.4807,5.351119,1.5149189,0.0,0,8.4376125,0.0,0.10651105,61.230301,8.5026007,454.38077,-9.2339964
2949,2949,195.4829,5.4010634,1.542762,0.0,0,8.4069986,0.0,0.10840424,61.614845,8.4714184,453.66431,-9.2345114
2960,2960,195.4851,5.4526291,1.5797139,0.0,0,8.3763819,0.0,0.11126063,62.070358,8.4374743,453.03067,-9.2347641
2971,2971,195.4873,5.4619827,1.6100357,0.0,0,8.345767,0.0,0.11339667,62.043484,8.4058647,452.397,-9.2341604
2982,2982,195.4895,5.4624863,1.6406901,0.0,0,8.3151522,0.0,0.11579774,61.944767,8.3740473,451.76334,-9.2333288
2993,2993,195.4917,5.470818,1.6699048,0.0,0,8.2845373,0.0,0.11792878,61.903564,8.3431683,451.1297,-9.2333794
3004,3004,195.4939,5.4713778,1.7056221,0.0,0,8.2539225,0.0,0.12074441,61.673496,8.3143387,450.95563,-9.233717
3015,3015,195.4961,5.4783974,1.7334238,0.0,0,8.2233057,0.0,0.12265266,61.748722,8.2817221,451.05463,-9.2343607
3026,3026,195.4983,5.4945526,1.763322,0.0,0,8.1926918,0.0,0.12514383,61.716244,8.24788,451.15366,-9.2331934
3037,3037,195.5005,5.4860287,1.7922986,0.0,0,8.162076,0.0,0.12708472,61.603985,8.2180882,451.25266,-9.2339926
3048,3048,195.5027,5.5078077,1.8278491,0.0,0,8.1314611,0.0,0.13009278,61.545502,8.1865664,451.35226,-9.2329178
3059,3059,195.5049,5.5449071,1.8558633,0.0,0,8.1008453,0.0,0.13185149,61.962891,8.1563635,451.45786,-9.2324286
3070,3070,195.5071,5.5589018,1.8842125,0.0,0,8.0702305,0.0,0.13433607,61.843628,8.1217709,451.56348,-9.2324982
3081,3081,195.5093,5.5689659,1.9142046,0.0,0,8.0403337,0.0,0.13631809,61.928566,8.0953856,451.6691,-9.2330103
3092,3092,195.5115,5.5688596,1.9470485,0.0,0,8.0112057,0.0,0.13924369,61.731873,8.0611172,451.77469,-9.2338381
3103,3103,195.5137,5.5886688,1.9771379,0.0,0,7.9820776,0.0,0.14113054,61.796143,8.0291519,451.93521,-9.2337742
3114,3114,195.5159,5.585381,2.0072312,0.0,0,7.95295,0.0,0.14373903,61.728462,7.9975581,452.13983,-9.2350254
3125,3125,195.5181,5.5826035,2.0367081,0.0,0,7.9238219,0.0,0.14570567,61.480885,7.9684772,452.34445,-9.234705
3136,3136,195.5203,5.6017365,2.066335,0.0,0,7.8946939,0.0,0.14839001,61.475262,7.9375138,452.54907,-9.2348204
3147,3147,195.5225,5.6111903,2.0942476,0.0,0,7.8655658,0.0,0.15005907,61.43708,7.9116678,452.75381,-9.235446
3158,3158,195.5247,5.6467767,2.1207039,0.0,0,7.8364377,0.0,0.15261929,61.615181,7.8786325,452.96503,-9.2345247
3169,3169,195.5269,5.648221,2.1505206,0.0,0,7.8073092,0.0,0.15447819,61.680042,7.8559809,453.17624,-9.2332239
3180,3180,195.5291,5.6553092,2.1810393,0.0,0,7.7781816,0.0,0.15735744,61.478107,7.8228855,453.38745,-9.2322798
3191,3191,195.5313,5.6582475,2.2121441,0.0,0,7.7490535,0.0,0.15918471,61.469654,7.7906027,453.59869,-9.2342777
3202,3202,195.5335,5.6731696,2.2370791,0.0,0,7.7199254,0.0,0.16167738,61.415989,7.7644768,453.79083,-9.2330847
3213,3213,195.5357,5.6870403,2.2672379,0.0,0,7.6907973,0.0,0.16358468,61.472885,7.7323632,453.96243,-9.2329092
3224,3224,195.5379,5.6839237,2.2953148,0.0,0,7.6616693,0.0,0.1663496,61.272957,7.7046428,454.13403,-9.2336855
3235,3235,195.5401,5.6968379,2.3256788,0.0,0,7.6325412,0.0,0.16814773,61.264259,7.6756968,454.30566,-9.2335024
3246,3246,195.5423,5.7098131,2.3482382,0.0,0,7.6034136,0.0,0.17054662,61.315292,7.6484766,454.47726,-9.2331982
3257,3257,195.5445,5.7229128,2.3769236,0.0,0,7.574285,0.0,0.17223561,61.313721,7.619554,454.66138,-9.233882
3268,3268,195.5467,5.7449369,2.4040349,0.0,0,7.5451574,0.0,0.17493621,61.338234,7.591433,454.84619,-9.2331924
3279,3279,195.5489,5.7589798,2.4377592,0.0,0,7.5160294,0.0,0.17693117,61.427479,7.5663571,455.03101,-9.2346945
3290,3290,195.5511,5.7957144,2.4627192,0.0,0,7.4869013,0.0,0.17963152,61.624119,7.5333791,455.21582,-9.2334738
3301,3301,195.5533,5.8068256,2.4935145,0.0,0,7.4577727,0.0,0.18148132,61.752758,7.507236,455.38983,-9.2337894
3312,3312,195.5555,5.8442721,2.5221484,0.0,0,7.4286451,0.0,0.18437791,61.820911,7.4729967,455.54825,-9.2337027
3323,3323,195.5577,5.8809013,2.5605297,0.0,0,7.3995175,0.0,0.18669391,62.148312,7.4387722,455.70667,-9.233674
3334,3334,195.5599,5.9001427,2.5857995,0.0,0,7.3714666,0.0,0.18949996,62.229931,7.4077516,455.86505,-9.2337885
3345,3345,195.5621,5.8963842,2.6200573,0.0,0,7.3437643,0.0,0.1916215,61.95068,7.3791676,456.02347,-9.2346992
3356,3356,195.5643,5.8814821,2.6459332,0.0,0,7.316062,0.0,0.194438,61.706139,7.3455172,456.11276,-9.2341061
3367,3367,195.5665,5.8440838,2.6797974,0.0,0,7.2883596,0.0,0.19637159,61.105919,7.3206162,456.19199,-9.2340031
3378,3378,195.5687,5.8509784,2.7000084,0.0,0,7.2606573,0.0,0.19868125,61.048817,7.2922812,456.27118,-9.2338171
3389,3389,195.5709,5.833077,2.7274699,0.0,0,7.232955,0.0,0.20042835,60.820518,7.2669072,456.3504,-9.2343693
3400,3400,195.5731,5.8522167,2.7508652,0.0,0,7.2052522,0.0,0.20295317,60.817253,7.2408061,456.43405,-9.2342987
3411,3411,195.5753,5.8775411,2.7845359,0.0,0,7.1775503,0.0,0.20483041,60.926666,7.2130189,456.52646,-9.2339087
3422,3422,195.5775,5.9080315,2.8050292,0.0,0,7.1498475,0.0,0.20727277,61.058105,7.1870556,456.61884,-9.2331839
3433,3433,195.5797,5.9334035,2.8354499,0.0,0,7.1221447,0.0,0.20921735,61.313663,7.1581516,456.71124,-9.2332306
3444,3444,195.5819,5.958056,2.858875,0.0,0,7.0944424,0.0,0.21182847,61.339539,7.1336937,456.80365,-9.2333317
3455,3455,195.5841,5.9591722,2.8942952,0.0,0,7.0667405,0.0,0.21391997,61.337681,7.1036363,456.9119,-9.2331696
3466,3466,195.5863,5.9621606,2.9142451,0.0,0,7.0390377,0.0,0.21626155,61.219254,7.0758934,457.02411,-9.2332983
3477,3477,195.5885,5.9876356,2.9432752,0.0,0,7.0113349,0.0,0.21822742,61.287273,7.0450873,457.13632,-9.2335854
3488,3488,195.5907,6.017869,2.9690256,0.0,0,6.983633,0.0,0.22103675,61.333443,7.0117631,457.24854,-9.2330227
3499,3499,195.5929,6.0189228,3.0091488,0.0,0,6.9559307,0.0,0.22337499,61.21875,6.9888253,457.35724,-9.2334919
3510,3510,195.5951,6.015933,3.0284986,0.0,0,6.9282284,0.0,0.22566554,61.075859,6.9590077,457.45627,-9.2342081
3521,3521,195.5973,6.055542,3.0572224,0.0,0,6.9005256,0.0,0.22766523,61.373768,6.9336562,457.55527,-9.2331629
3532,3532,195.5995,6.0663109,3.0804927,0.0,0,6.8728237,0.0,0.23018998,61.333641,6.9033942,457.65427,-9.2339115
3543,3543,195.6017,6.0610557,3.1169057,0.0,0,6.8451209,0.0,0.23254126,61.247517,6.8773804,457.75327,-9.2331619
3554,3554,195.6039,6.0700374,3.1364877,0.0,0,6.8174186,0.0,0.23476739,61.088593,6.8508596,457.55466,-9.2333059
3565,3565,195.6061,6.052031,3.1647837,0.0,0,6.7897158,0.0,0.2366741,60.804867,6.8239784,457.24442,-9.2340965
3576,3576,195.6083,6.0805469,3.1870811,0.0,0,6.762064,0.0,0.23901901,60.952084,6.7953353,456.9342,-9.2345552
3587,3587,195.6105,6.1073594,3.2230237,0.0,0,6.7356958,0.0,0.24155742,61.048664,6.7689695,456.62399,-9.2333746
3598,3598,195.6127,6.1218562,3.2441058,0.0,0,6.7093401,0.0,0.24382886,61.084583,6.7429266,456.21295,-9.2334929
3609,3609,195.6149,6.1402826,3.2739968,0.0,0,6.6829839,0.0,0.24601951,61.128006,6.712976,455.37466,-9.2345753
3620,3620,195.6171,6.1826434,3.2970231,0.0,0,6.6566281,0.0,0.2483827,61.445221,6.6843152,454.53641,-9.2337008
3631,3631,195.6193,6.1876674,3.3322735,0.0,0,6.6302719,0.0,0.25089785,61.356213,6.6580749,453.69815,-9.2328453
3642,3642,195.6215,6.1779938,3.3533995,0.0,0,6.6039157,0.0,0.25309131,61.072872,6.6288133,452.85989,-9.2330465
3653,3653,195.6237,6.1706848,3.3819609,0.0,0,6.5775599,0.0,0.25537264,60.832619,6.602088,452.30243,-9.2331524
3664,3664,195.6259,6.1549158,3.4034584,0.0,0,6.5512042,0.0,0.25745812,60.604553,6.5778561,451.89322,-9.2331867
3675,3675,195.6281,6.178483,3.4361413,0.0,0,6.524848,0.0,0.25990844,60.642628,6.5537224,451.48398,-9.2337646
3686,3686,195.6303,6.2058163,3.4563138,0.0,0,6.4984918,0.0,0.26202595,60.79187,6.5272002,451.07474,-9.2326231
3697,3697,195.6325,6.2428689,3.485482,0.0,0,6.472136,0.0,0.2643359,61.031147,6.4961619,450.71777,-9.2334232
3708,3708,195.6347,6.2570224,3.5095637,0.0,0,6.4457798,0.0,0.26653594,61.021828,6.4703155,450.75076,-9.2336702
3719,3719,195.6369,6.2667751,3.541187,0.0,0,6.4194241,0.0,0.26907712,61.016754,6.4476995,450.78378,-9.2333307
3730,3730,195.6391,6.2738404,3.5601113,0.0,0,6.3930678,0.0,0.27104774,60.953983,6.4192095,450.81677,-9.2331619
3741,3741,195.6413,6.2900567,3.5892627,0.0,0,6.3667121,0.0,0.27336338,60.949997,6.3948717,450.84979,-9.2341223
3752,3752,195.6435,6.2942266,3.6136715,0.0,0,6.3403563,0.0,0.27564994,60.878941,6.3655281,450.86743,-9.2344885
3763,3763,195.6457,6.3252888,3.647598,0.0,0,6.3140001,0.0,0.27852929,61.000153,6.340178,450.87402,-9.233304
3774,3774,195.6479,6.3501458,3.668659,0.0,0,6.2876444,0.0,0.28047922,61.010643,6.3099308,450.88062,-9.2331524
3785,3785,195.6501,6.3617797,3.6979637,0.0,0,6.2612886,0.0,0.28312197,61.072952,6.2842422,450.88724,-9.2342415
3796,3796,195.6523,6.3835821,3.7226772,0.0,0,6.2349324,0.0,0.28527203,61.135036,6.2551966,450.89832,-9.233902
3807,3807,195.6545,6.3837128,3.7553585,0.0,0,6.2085767,0.0,0.28815329,60.929867,6.2318468,451.00394,-9.2341499
3818,3818,195.6567,6.4313645,3.7776558,0.0,0,6.1822205,0.0,0.28996256,61.255486,6.2023201,451.10956,-9.2337675
3829,3829,195.6589,6.4226398,3.8026242,0.0,0,6.1562529,0.0,0.29241139,61.09174,6.1771426,451.21515,-9.2346134
3840,3840,195.6611,6.4025946,3.8298457,0.0,0,6.1311855,0.0,0.29470181,60.719105,6.1491342,451.32077,-9.2330246
3851,3851,195.6633,6.4106369,3.8625548,0.0,0,6.1061187,0.0,0.29775721,60.583229,6.124361,451.44318,-9.23454
3862,3862,195.6655,6.4180856,3.8843298,0.0,0,6.0810523,0.0,0.29952577,60.584507,6.0993176,451.58179,-9.2337828
3873,3873,195.6677,6.4520144,3.9085314,0.0,0,6.0559855,0.0,0.30195856,60.681446,6.0704341,451.7204,-9.2338009
3884,3884,195.6699,6.4768476,3.9332941,0.0,0,6.0309186,0.0,0.30389306,60.802338,6.0457845,451.85901,-9.2351751
3895,3895,195.6721,6.4760537,3.9628263,0.0,0,6.0058517,0.0,0.306945,60.637302,6.0233426,451.99762,-9.2346563
3906,3906,195.6743,6.4753966,3.985055,0.0,0,5.9807849,0.0,0.30852839,60.618649,5.9929771,452.19403,-9.2346687
3917,3917,195.6765,6.4943738,4.0093842,0.0,0,5.9557185,0.0,0.31103745,60.605087,5.971838,452.39203,-9.2337713
3928,3928,195.6787,6.4803157,4.0314746,0.0,0,5.9306512,0.0,0.31278488,60.320385,5.9463611,452.59003,-9.234045
3939,3939,195.6809,6.448535,4.0594625,0.0,0,5.9055848,0.0,0.31578004,59.887344,5.9215827,452.78806,-9.2340126
3950,3950,195.6831,6.4479113,4.0830193,0.0,0,5.880518,0.0,0.31736013,59.800518,5.897058,452.89389,-9.2347126
3961,3961,195.6853,6.4724154,4.1014066,0.0,0,5.8554511,0.0,0.3196269,59.84893,5.8756661,452.88071,-9.2331524
3972,3972,195.6875,6.5294218,4.1241989,0.0,0,5.8303843,0.0,0.3212803,60.29789,5.8508873,452.86749,-9.2336969
3983,3983,195.6897,6.5754948,4.1496539,0.0,0,5.8053174,0.0,0.32412776,60.571587,5.825563,452.85431,-9.2335062
3994,3994,195.6919,6.6022568,4.1752005,0.0,0,5.7802501,0.0,0.32586983,60.654118,5.8004084,452.84109,-9.2339134
4005,4005,195.6941,6.6164322,4.1994672,0.0,0,5.7551837,0.0,0.32864726,60.690136,5.7714877,451.87741,-9.2331266
4016,4016,195.6963,6.6177721,4.2272563,0.0,0,5.7301168,0.0,0.33070844,60.580193,5.7499471,450.80814,-9.2345104
4027,4027,195.6985,6.6209273,4.2524619,0.0,0,5.7050505,0.0,0.33367336,60.394695,5.7273579,449.73883,-9.2335482
4038,4038,195.7007,6.6204162,4.2793632,0.0,0,5.6799831,0.0,0.33542627,60.275055,5.698761,448.66956,-9.2327328
4049,4049,195.7029,6.6744428,4.2996821,0.0,0,5.6549168,0.0,0.33804595,60.610172,5.6744537,447.72507,-9.2323952
4060,4060,195.7051,6.7042403,4.3262229,0.0,0,5.6298494,0.0,0.33987886,60.795555,5.6492381,446.99902,-9.2336731
4071,4071,195.7073,6.7147436,4.3512526,0.0,0,5.6047826,0.0,0.34298429,60.684921,5.6218872,446.27295,-9.2340555
4082,4082,195.7095,6.716702,4.3817048,0.0,0,5.5804157,0.0,0.34503272,60.489109,5.5964751,445.54691,-9.2346764
4093,4093,195.7117,6.7441759,4.4031,0.0,0,5.5565677,0.0,0.34785584,60.615776,5.5704665,444.82083,-9.2336588
4104,4104,195.7139,6.7463031,4.4319024,0.0,0,5.5327196,0.0,0.34978595,60.504864,5.5465727,444.84833,-9.2337551
4115,4115,195.7161,6.7636695,4.4539814,0.0,0,5.5088716,0.0,0.35266796,60.575462,5.522687,445.03314,-9.2333708
4126,4126,195.7183,6.7457843,4.4814177,0.0,0,5.4850235,0.0,0.35439375,60.197651,5.4977093,445.21796,-9.2344894
4137,4137,195.7205,6.7276573,4.5017505,0.0,0,5.4611754,0.0,0.35719511,59.96891,5.4718614,445.40277,-9.2347631
4148,4148,195.7227,6.7222548,4.5270886,0.0,0,5.4373279,0.0,0.35885179,59.780651,5.450912,445.54916,-9.2331533
4159,4159,195.7249,6.760663,4.5480094,0.0,0,5.4134793,0.0,0.36162367,59.941635,5.4282579,445.60199,-9.2317839
4170,4170,195.7271,6.7840257,4.5776505,0.0,0,5.3896313,0.0,0.36352131,60.101334,5.4033842,445.65479,-9.2331905
4181,4181,195.7293,6.8080144,4.5944061,0.0,0,5.3657837,0.0,0.36618844,60.214069,5.3781672,445.70761,-9.2331877
4192,4192,195.7315,6.8044572,4.6212015,0.0,0,5.3419356,0.0,0.36790752,59.991085,5.3581119,445.76041,-9.2336912
4203,4203,195.7337,6.8137569,4.6422472,0.0,0,5.3180876,0.0,0.37074289,59.899376,5.3370948,445.94272,-9.2332802
4214,4214,195.7359,6.8160782,4.6708188,0.0,0,5.2942395,0.0,0.3723757,59.776348,5.3122272,446.16711,-9.2326021
4225,4225,195.7381,6.8495388,4.6864257,0.0,0,5.2703915,0.0,0.37508467,59.907639,5.286397,446.39154,-9.2336683
4236,4236,195.7403,6.8825812,4.7160897,0.0,0,5.2465439,0.0,0.3771213,60.084141,5.2647371,446.61597,-9.2339649
4247,4247,195.7425,6.9195409,4.7381911,0.0,0,5.2226958,0.0,0.38007459,60.179455,5.2377491,446.85333,-9.2334328
4258,4258,195.7447,6.9389625,4.769702,0.0,0,5.1988478,0.0,0.38201421,60.29393,5.2135463,447.13715,-9.2347088
4269,4269,195.7469,6.9582186,4.7840648,0.0,0,5.1749997,0.0,0.38458169,60.351448,5.1882005,447.42099,-9.2346888
4280,4280,195.7491,6.9645419,4.8150153,0.0,0,5.1511517,0.0,0.386664,60.27356,5.1614184,447.7048,-9.2332706
4291,4291,195.7513,6.9373856,4.8359065,0.0,0,5.1273036,0.0,0.38968736,59.875618,5.1398463,447.98862,-9.2329826
4302,4302,195.7535,6.9491997,4.8647914,0.0,0,5.1034555,0.0,0.39139038,59.831303,5.1162038,448.29141,-9.2338419
4313,4313,195.7557,6.9604769,4.8789158,0.0,0,5.079608,0.0,0.3938421,59.784599,5.0938892,448.60309,-9.2347403
4324,4324,195.7579,6.9689236,4.9073091,0.0,0,5.0557599,0.0,0.39589259,59.735657,5.0694747,448.91473,-9.2346601
4335,4335,195.7601,7.0079865,4.9270005,0.0,0,5.0328989,0.0,0.39865687,59.872864,5.0460944,449.22641,-9.2338715
4346,4346,195.7623,7.065506,4.9603815,0.0,0,5.0102167,0.0,0.40093124,60.280052,5.023643,449.32138,-9.2323151
4357,4357,195.7645,7.104723,4.9752393,0.0,0,4.987535,0.0,0.40338448,60.400051,4.9966702,449.15637,-9.2340937
4368,4368,195.7667,7.1070805,5.0044389,0.0,0,4.9648528,0.0,0.40557721,60.293304,4.9731007,448.99136,-9.2341166
4379,4379,195.7689,7.0922117,5.0260305,0.0,0,4.9421706,0.0,0.40857196,60.108814,4.9503884,448.82635,-9.2331476
4390,4390,195.7711,7.0745244,5.0585723,0.0,0,4.9194889,0.0,0.41083407,59.812969,4.9235458,448.66132,-9.2331791
4401,4401,195.7733,7.0661774,5.072051,0.0,0,4.8968072,0.0,0.4130435,59.514194,4.901463,448.36298,-9.2325983
4412,4412,195.7755,7.0622602,5.0966191,0.0,0,4.8741245,0.0,0.41487288,59.440536,4.8809862,448.05276,-9.2337484
4423,4423,195.7777,7.0679817,5.1127419,0.0,0,4.8514428,0.0,0.41716424,59.286324,4.8625369,447.74255,-9.2337685
4434,4434,195.7799,7.1027017,5.1449757,0.0,0,4.8287606,0.0,0.41959977,59.395992,4.836658,447.43231,-9.234046
4445,4445,195.7821,7.1372037,5.1589146,0.0,0,4.8060789,0.0,0.42180035,59.604584,4.816112,447.25568,-9.2329912
4456,4456,195.7843,7.1558337,5.1846213,0.0,0,4.7833967,0.0,0.42384878,59.6796,4.7891035,447.29529,-9.2327566
4467,4467,195.7865,7.1637487,5.2022004,0.0,0,4.7607145,0.0,0.42613292,59.549145,4.7700267,447.33487,-9.234149
4478,4478,195.7887,7.1837187,5.2325759,0.0,0,4.7380328,0.0,0.42854479,59.569054,4.7492781,447.37448,-9.2333345
4489,4489,195.7909,7.2079158,5.2492681,0.0,0,4.7153511,0.0,0.43089232,59.613625,4.7288833,447.41409,-9.2343874
4500,4500,195.7931,7.2193575,5.2758617,0.0,0,4.6926689,0.0,0.43309474,59.648052,4.7044191,447.40906,-9.2340622
4511,4511,195.7953,7.2270436,5.2927341,0.0,0,4.6699867,0.0,0.43545738,59.531544,4.6783977,447.39584,-9.2346735
4522,4522,195.7975,7.2642231,5.3247161,0.0,0,4.647305,0.0,0.43809763,59.648415,4.6573343,447.38266,-9.233922
4533,4533,195.7997,7.2787828,5.3407454,0.0,0,4.6246228,0.0,0.4402703,59.653049,4.635438,447.36945,-9.2344227
4544,4544,195.8019,7.3085303,5.3644176,0.0,0,4.6019411,0.0,0.44233796,59.764721,4.6104255,447.41132,-9.2335844
4555,4555,195.8041,7.3137302,5.3830304,0.0,0,4.5792584,0.0,0.44466141,59.766953,4.5881357,447.57632,-9.2344007
4566,4566,195.8063,7.3067474,5.4151878,0.0,0,4.5565767,0.0,0.44760555,59.444981,4.5653868,447.74136,-9.2340021
4577,4577,195.8085,7.3258567,5.4294362,0.0,0,4.5340271,0.0,0.4495233,59.466869,4.545907,447.90637,-9.2331343
4588,4588,195.8107,7.3299003,5.4559355,0.0,0,4.5124488,0.0,0.45196164,59.353439,4.5225968,448.07138,-9.2337961
4599,4599,195.8129,7.3527145,5.4748149,0.0,0,4.4908714,0.0,0.45418283,59.38438,4.4998364,448.28738,-9.2338953
4610,4610,195.8151,7.376574,5.5037384,0.0,0,4.4692936,0.0,0.45693821,59.425076,4.4761772,448.5184,-9.2334938
4621,4621,195.8173,7.4107409,5.5173717,0.0,0,4.4477158,0.0,0.45868886,59.642216,4.4543533,448.74942,-9.2335453
4632,4632,195.8195,7.429697,5.5443597,0.0,0,4.4261384,0.0,0.46136889,59.66198,4.4326825,448.98044,-9.2333241
4643,4643,195.8217,7.4490142,5.5634589,0.0,0,4.404561,0.0,0.46345589,59.715385,4.411561,449.21616,-9.2348576
4654,4654,195.8239,7.4539351,5.5915346,0.0,0,4.3829832,0.0,0.46626797,59.548225,4.3872323,449.46698,-9.2346449
4665,4665,195.8261,7.4228482,5.6070433,0.0,0,4.3614058,0.0,0.46798751,59.212238,4.3695202,449.71777,-9.2337551
4676,4676,195.8283,7.4396334,5.6315989,0.0,0,4.339828,0.0,0.47066283,59.195396,4.343266,449.9686,-9.2338066
4687,4687,195.8305,7.4806037,5.6503391,0.0,0,4.3182507,0.0,0.47263113,59.371464,4.3249116,450.21942,-9.2333632
4698,4698,195.8327,7.491919,5.6775613,0.0,0,4.2966728,0.0,0.47561345,59.247643,4.3034229,450.48874,-9.2345772
4709,4709,195.8349,7.5334644,5.6932135,0.0,0,4.275095,0.0,0.47721961,59.471752,4.2808514,450.76596,-9.2313175
4720,4720,195.8371,7.5688868,5.7178187,0.0,0,4.2535176,0.0,0.48005363,59.590805,4.261838,451.04318,-9.2331533
4731,4731,195.8393,7.5842381,5.7381926,0.0,0,4.2319398,0.0,0.48208317,59.627766,4.2374849,451.32037,-9.2331591
4742,4742,195.8415,7.5953794,5.7659812,0.0,0,4.2103624,0.0,0.48521149,59.545197,4.2152619,451.56198,-9.2330265
4753,4753,195.8437,7.603497,5.7826557,0.0,0,4.1887846,0.0,0.48670879,59.529156,4.1933985,451.62137,-9.2335081
4764,4764,195.8459,7.6177502,5.8047304,0.0,0,4.1672072,0.0,0.48944277,59.489044,4.176198,451.68079,-9.2326145
4775,4775,195.8481,7.6392674,5.8255692,0.0,0,4.1456294,0.0,0.49148619,59.525452,4.1530385,451.7402,-9.2325668
4786,4786,195.8503,7.6750998,5.8546519,0.0,0,4.124052,0.0,0.49500018,59.49482,4.1273766,451.79959,-9.2341118
4797,4797,195.8525,7.7013006,5.8730025,0.0,0,4.1024742,0.0,0.49648654,59.649036,4.10605,451.72238,-9.233798
4808,4808,195.8547,7.7188716,5.8931956,0.0,0,4.0808969,0.0,0.49918762,59.709133,4.0836248,451.56396,-9.2332325
4819,4819,195.8569,7.7683263,5.9150167,0.0,0,4.059319,0.0,0.5011102,59.932228,4.0619998,451.40555,-9.2330751
4830,4830,195.8591,7.7976928,5.9413962,0.0,0,4.0381556,0.0,0.50454348,59.907295,4.0410643,451.24713,-9.2327042
4841,4841,195.8613,7.7754545,5.9620543,0.0,0,4.0176339,0.0,0.50624669,59.737576,4.0124345,451.07611,-9.2328358
4852,4852,195.8635,7.7635336,5.9798489,0.0,0,3.9971123,0.0,0.50879693,59.462273,3.9931142,450.77908,-9.2331781
4863,4863,195.8657,7.7373204,6.0015049,0.0,0,3.9765906,0.0,0.51066411,59.111771,3.9734261,450.48206,-9.233614
4874,4874,195.8679,7.7485719,6.0250835,0.0,0,3.956069,0.0,0.51394725,58.957684,3.955065,450.18506,-9.2334366
4885,4885,195.8701,7.7580681,6.0456014,0.0,0,3.9355476,0.0,0.51543242,58.978622,3.9334402,449.88803,-9.2337713
4896,4896,195.8723,7.7876735,6.0616136,0.0,0,3.9150259,0.0,0.51809061,59.013927,3.9158089,449.53976,-9.2326708
4907,4907,195.8745,7.8057742,6.0834484,0.0,0,3.8945043,0.0,0.51964003,59.1441,3.8953402,449.15033,-9.2336903
4918,4918,195.8767,7.8488379,6.104867,0.0,0,3.8739827,0.0,0.52299565,59.240639,3.8740106,448.76089,-9.2340288
4929,4929,195.8789,7.8579173,6.1267862,0.0,0,3.853461,0.0,0.52439207,59.194847,3.8557205,448.37146,-9.2331324
4940,4940,195.8811,7.8530359,6.1402936,0.0,0,3.8329396,0.0,0.52695024,59.046612,3.8341243,447.98706,-9.2337809
4951,4951,195.8833,7.8611326,6.1611571,0.0,0,3.812418,0.0,0.52835917,58.963013,3.8148165,447.87485,-9.2337408
4962,4962,195.8855,7.8993397,6.1825852,0.0,0,3.7918961,0.0,0.53190225,59.069687,3.798569,447.76266,-9.2346783
4973,4973,195.8877,7.9364552,6.2073674,0.0,0,3.7713747,0.0,0.53340077,59.225277,3.7754107,447.65045,-9.2329445
4984,4984,195.8899,7.9856429,6.2220364,0.0,0,3.7508531,0.0,0.5363242,59.517952,3.7539413,447.53824,-9.2338552
4995,4995,195.8921,8.0426569,6.2480206,0.0,0,3.7303314,0.0,0.53824288,59.77449,3.7330515,447.68362,-9.2331486
5006,5006,195.8943,8.0577898,6.2665114,0.0,0,3.7098098,0.0,0.54150712,59.697239,3.7137218,448.10608,-9.2320309
5017,5017,195.8965,8.1053047,6.2930193,0.0,0,3.6892881,0.0,0.54331154,59.940567,3.6898675,448.5285,-9.2328835
5028,5028,195.8987,8.1076546,6.3100114,0.0,0,3.6687665,0.0,0.54643142,59.810219,3.6675501,448.95096,-9.2341585
5039,5039,195.9009,8.0952578,6.333199,0.0,0,3.6482451,0.0,0.54786754,59.608616,3.6460969,449.37338,-9.2343493
5050,5050,195.9031,8.0907145,6.3487768,0.0,0,3.6277235,0.0,0.55097038,59.388165,3.6255283,449.81451,-9.2336845
5061,5061,195.9053,8.0950499,6.3764777,0.0,0,3.6072018,0.0,0.55283374,59.275589,3.6099248,450.25674,-9.2332249
5072,5072,195.9075,8.1245003,6.3898792,0.0,0,3.5866802,0.0,0.55567926,59.317348,3.5848746,450.69897,-9.2331352
5083,5083,195.9097,8.1230841,6.414228,0.0,0,3.5668228,0.0,0.55737358,59.225052,3.5682049,451.1412,-9.2331219
5094,5094,195.9119,8.1516266,6.4299264,0.0,0,3.5472999,0.0,0.56038135,59.250668,3.546036,451.45383,-9.2329826
5105,5105,195.9141,8.2090397,6.4564481,0.0,0,3.527777,0.0,0.562051,59.559883,3.5269642,451.57925,-9.2317047
5116,5116,195.9163,8.2555943,6.4695039,0.0,0,3.5082545,0.0,0.56493288,59.758091,3.5087316,451.70465,-9.2333269
5127,5127,195.9185,8.2791758,6.4942756,0.0,0,3.4887314,0.0,0.56681103,59.785591,3.4850428,451.83008,-9.2338591
5138,5138,195.9207,8.2707949,6.5088949,0.0,0,3.4692085,0.0,0.56971014,59.549099,3.4655974,451.95547,-9.2339344
5149,5149,195.9229,8.2606564,6.5401053,0.0,0,3.4496861,0.0,0.57191712,59.356342,3.4483149,452.04056,-9.2337427
5160,5160,195.9251,8.2564983,6.5496645,0.0,0,3.4301629,0.0,0.57441491,59.181873,3.4291928,452.11978,-9.2333946
5171,5171,195.9273,8.2726269,6.5716434,0.0,0,3.4106405,0.0,0.57587618,59.229309,3.4097593,452.19897,-9.2331982
5182,5182,195.9295,8.3214731,6.584384,0.0,0,3.3911176,0.0,0.57863021,59.347507,3.3877604,452.2782,-9.2333403
5193,5193,195.9317,8.3554373,6.614223,0.0,0,3.3715944,0.0,0.58063769,59.512711,3.3684866,452.35074,-9.2344713
5204,5204,195.9339,8.3654547,6.6275563,0.0,0,3.352072,0.0,0.58359456,59.42252,3.3513925,452.41016,-9.2340469
5215,5215,195.9361,8.3970509,6.6498733,0.0,0,3.3325491,0.0,0.58529228,59.5247,3.3347185,452.46954,-9.2338247
5226,5226,195.9383,8.3839121,6.6615081,0.0,0,3.313026,0.0,0.58779621,59.300533,3.3118207,452.52896,-9.2333241
5237,5237,195.9405,8.4097462,6.6896858,0.0,0,3.2935035,0.0,0.58989447,59.398533,3.2913749,452.58838,-9.2334862
5248,5248,195.9427,8.4379053,6.7018466,0.0,0,3.2739804,0.0,0.5924722,59.374088,3.2720664,451.78708,-9.2333889
5259,5259,195.9449,8.4962931,6.7276483,0.0,0,3.254458,0.0,0.59461164,59.651772,3.253963,450.7706,-9.2330742
5270,5270,195.9471,8.5368605,6.7404642,0.0,0,3.234935,0.0,0.5973022,59.751183,3.2339702,449.75412,-9.2338009
5281,5281,195.9493,8.5648642,6.7713652,0.0,0,3.2154119,0.0,0.59970945,59.809635,3.2125719,448.73764,-9.2333851
5292,5292,195.9515,8.587081,6.7813392,0.0,0,3.1958895,0.0,0.60211152,59.983482,3.1971252,447.72638,-9.23454
5303,5303,195.9537,8.5952682,6.803514,0.0,0,3.1763666,0.0,0.60381967,59.774063,3.1754239,446.72968,-9.2345533
5314,5314,195.9559,8.6078405,6.8189464,0.0,0,3.1568439,0.0,0.60675532,59.778366,3.1558454,445.733,-9.234334
5325,5325,195.9581,8.6011171,6.8491802,0.0,0,3.137321,0.0,0.60934001,59.642952,3.1388669,444.73633,-9.2343178
5336,5336,195.9603,8.621273,6.8595676,0.0,0,3.1186893,0.0,0.61170948,59.573063,3.1201048,443.73962,-9.2336512
5347,5347,195.9625,8.6758099,6.88166,0.0,0,3.1001165,0.0,0.61347228,59.756474,3.1030345,441.95291,-9.2326555
5358,5358,195.9647,8.7296028,6.8953662,0.0,0,3.0815444,0.0,0.61606997,60.033222,3.0831182,439.86993,-9.232111
5369,5369,195.9669,8.7565041,6.9251323,0.0,0,3.0629718,0.0,0.61869657,60.006073,3.0624783,437.78696,-9.232686
5380,5380,195.9691,8.7915134,6.9375486,0.0,0,3.0443995,0.0,0.62109566,60.122101,3.0462513,435.70398,-9.2342005
5391,5391,195.9713,8.7890024,6.9611583,0.0,0,3.0258269,0.0,0.62344682,60.028305,3.0235527,433.78769,-9.2334194
5402,5402,195.9735,8.812809,6.9726882,0.0,0,3.0072546,0.0,0.62543511,60.024933,3.0059209,432.57791,-9.233469
5413,5413,195.9757,8.8450594,7.0021429,0.0,0,2.9886825,0.0,0.62849092,60.051285,2.9867144,431.36813,-9.2332315
5424,5424,195.9779,8.8371229,7.0143857,0.0,0,2.9701097,0.0,0.6306023,59.868362,2.9666154,430.15836,-9.2339821
5435,5435,195.9801,8.826375,7.0386968,0.0,0,2.9515376,0.0,0.63317871,59.689011,2.9500499,428.94858,-9.2352362
5446,5446,195.9823,8.8863306,7.0519443,0.0,0,2.932965,0.0,0.63525289,59.994179,2.9333107,429.03299,-9.233675
5457,5457,195.9845,8.9290829,7.0767455,0.0,0,2.9143927,0.0,0.63785231,60.085358,2.9114108,429.80048,-9.234519
5468,5468,195.9867,8.9488096,7.0868983,0.0,0,2.8958201,0.0,0.63976836,60.131725,2.8937323,430.56796,-9.2346621
5479,5479,195.9889,8.947196,7.111341,0.0,0,2.8772478,0.0,0.64245981,59.933792,2.8755565,431.33542,-9.2333069
5490,5490,195.9911,8.9440241,7.1272621,0.0,0,2.8586755,0.0,0.64467436,59.822598,2.8552263,432.0372,-9.2351818
5501,5501,195.9933,8.9513121,7.1502514,0.0,0,2.8401029,0.0,0.64727014,59.63945,2.8394299,432.24875,-9.2345524
5512,5512,195.9955,8.9963398,7.1610904,0.0,0,2.8215306,0.0,0.64898831,59.879444,2.8238461,432.4603,-9.2358809
5523,5523,195.9977,9.0189266,7.1810398,0.0,0,2.8029583,0.0,0.6514504,59.859531,2.8038945,432.67184,-9.2344131
5534,5534,195.9999,9.0890694,7.1941805,0.0,0,2.7843859,0.0,0.65317976,60.183296,2.7828279,432.88339,-9.2341194
5545,5545,196.0021,9.1468,7.2216864,0.0,0,2.7658136,0.0,0.65661341,60.343616,2.7680464,433.27573,-9.2343655
5556,5556,196.0043,9.1828156,7.2373967,0.0,0,2.747241,0.0,0.65878856,60.503468,2.7494049,433.79797,-9.2334967
5567,5567,196.0065,9.2193556,7.258368,0.0,0,2.7286685,0.0,0.66143626,60.566101,2.7290494,434.32022,-9.2339745
5578,5578,196.0087,9.221487,7.2731891,0.0,0,2.7102869,0.0,0.66327071,60.508018,2.7071738,434.8425,-9.2331505
5589,5589,196.0109,9.2447901,7.2981176,0.0,0,2.692621,0.0,0.66661108,60.443882,2.6886768,435.32358,-9.2345886
5600,5600,196.0131,9.2538462,7.3127694,0.0,0,2.6749551,0.0,0.6683526,60.412384,2.6721709,434.94016,-9.2339478
5611,5611,196.0153,9.2898569,7.3323789,0.0,0,2.657289,0.0,0.67123789,60.438015,2.6534467,434.55673,-9.2346144
5622,5622,196.0175,9.3199596,7.3502555,0.0,0,2.6396229,0.0,0.67331505,60.53101,2.6356797,434.17331,-9.2345276
5633,5633,196.0197,9.3459253,7.375061,0.0,0,2.6219571,0.0,0.67672235,60.480263,2.6152759,433.78989,-9.2332335
5644,5644,196.0219,9.3888884,7.3885393,0.0,0,2.604291,0.0,0.67808199,60.643852,2.5992639,433.52087,-9.2336988
5655,5655,196.0241,9.4053011,7.4036493,0.0,0,2.5866251,0.0,0.68053281,60.592426,2.578711,433.36221,-9.2331161
5666,5666,196.0263,9.3998489,7.4227052,0.0,0,2.568959,0.0,0.68255651,60.516037,2.5635295,433.20355,-9.2328749
5677,5677,196.0285,9.3975992,7.4460759,0.0,0,2.5512929,0.0,0.68625087,60.293446,2.543946,433.04489,-9.2338295
5688,5688,196.0307,9.4107227,7.4609027,0.0,0,2.533627,0.0,0.68747211,60.292427,2.5282104,432.88623,-9.2350655
5699,5699,196.0329,9.4149208,7.4749985,0.0,0,2.5159609,0.0,0.69001245,60.140446,2.5103562,433.76932,-9.2344389
5710,5710,196.0351,9.4505157,7.4904304,0.0,0,2.4982951,0.0,0.69136816,60.277096,2.4918387,434.68161,-9.2332411
5721,5721,196.0373,9.4923086,7.5097814,0.0,0,2.480629,0.0,0.69481766,60.317127,2.4768522,435.5939,-9.233222
5732,5732,196.0395,9.5452986,7.5268154,0.0,0,2.4629631,0.0,0.69620556,60.548763,2.4599898,436.5062,-9.2342882
5743,5743,196.0417,9.5900517,7.5422997,0.0,0,2.445297,0.0,0.69922298,60.662189,2.4405637,436.11649,-9.2340803
5754,5754,196.0439,9.6337481,7.5615349,0.0,0,2.4276309,0.0,0.70084411,60.858131,2.4230287,434.04501,-9.2333717
5765,5765,196.0461,9.6585941,7.5787272,0.0,0,2.409965,0.0,0.70422125,60.834312,2.4048464,431.97354,-9.2340412
5776,5776,196.0483,9.680769,7.5982976,0.0,0,2.3922989,0.0,0.70572007,60.879189,2.388485,429.9021,-9.2334967
5787,5787,196.0505,9.6951637,7.6132174,0.0,0,2.3746328,0.0,0.7088415,60.737373,2.3704233,427.83063,-9.2337561
5798,5798,196.0527,9.7138071,7.6331644,0.0,0,2.356967,0.0,0.71051455,60.780464,2.3561544,425.22943,-9.2339249
5809,5809,196.0549,9.7612181,7.6504769,0.0,0,2.3393009,0.0,0.71395719,60.847015,2.3359735,422.56937,-9.2339153
5820,5820,196.0571,9.7926779,7.671134,0.0,0,2.3216348,0.0,0.71554571,60.937534,2.3205585,419.9093,-9.2347803
5831,5831,196.0593,9.8341799,7.682436,0.0,0,2.3043852,0.0,0.71830279,61.034695,2.3040984,417.24924,-9.2334776
5842,5842,196.0615,9.8657446,7.7031717,0.0,0,2.2875817,0.0,0.7200405,61.178963,2.2819159,415.85025,-9.2329264
5853,5853,196.0637,9.8868675,7.7204208,0.0,0,2.2707779,0.0,0.72363549,61.053467,2.265002,416.6582,-9.2345142
5864,5864,196.0659,9.8994541,7.7385354,0.0,0,2.2539747,0.0,0.72472024,61.088295,2.2494657,417.46613,-9.2346897
5875,5875,196.0681,9.93857,7.7504539,0.0,0,2.2371707,0.0,0.72771859,61.130512,2.2309101,418.27408,-9.2344341
5886,5886,196.0703,9.9739799,7.7731113,0.0,0,2.2203674,0.0,0.72959268,61.224083,2.2137616,419.082,-9.2334633
5897,5897,196.0725,10.009436,7.7890015,0.0,0,2.2035637,0.0,0.73319221,61.229908,2.1951249,420.10361,-9.2337837
5908,5908,196.0747,10.061883,7.8136973,0.0,0,2.1867602,0.0,0.734914,61.380604,2.177103,421.16983,-9.2332516
5919,5919,196.0769,10.077845,7.8205667,0.0,0,2.1699564,0.0,0.73773056,61.289948,2.1616831,422.23602,-9.2343845
5930,5930,196.0791,10.089817,7.8419619,0.0,0,2.1531529,0.0,0.7391212,61.322075,2.1439066,423.30225,-9.2331591
5941,5941,196.0813,10.111603,7.8565559,0.0,0,2.1363492,0.0,0.74257195,61.253681,2.1288795,423.935,-9.2344637
5952,5952,196.0835,10.11059,7.8784242,0.0,0,2.1195457,0.0,0.74400246,61.189587,2.1126673,423.51117,-9.233283
5963,5963,196.0857,10.12019,7.8864427,0.0,0,2.102742,0.0,0.74675125,61.070934,2.095814,423.08731,-9.233304
5974,5974,196.0879,10.152122,7.9073873,0.0,0,2.0859385,0.0,0.74825972,61.173691,2.0806334,422.66348,-9.2334728
5985,5985,196.0901,10.220399,7.9196296,0.0,0,2.069135,0.0,0.7514562,61.38607,2.0631163,422.23965,-9.2338123
5996,5996,196.0923,10.275203,7.9423866,0.0,0,2.0523314,0.0,0.75297916,61.582668,2.0482175,422.06067,-9.2336245
6007,6007,196.0945,10.322702,7.9507432,0.0,0,2.0355277,0.0,0.75588828,61.687614,2.0281563,421.96133,-9.2330198
6018,6018,196.0967,10.381611,7.9730439,0.0,0,2.0187242,0.0,0.75760877,61.989521,2.0107932,421.862,-9.2331638
6029,6029,196.0989,10.430198,7.9866939,0.0,0,2.0019205,0.0,0.76098037,62.013134,1.9961072,421.76266,-9.2337828
6040,6040,196.1011,10.465282,8.0123405,0.0,0,1.985117,0.0,0.76270664,62.159748,1.9833691,421.86993,-9.2345247
6051,6051,196.1033,10.501901,8.0200567,0.0,0,1.9683133,0.0,0.76596016,62.205528,1.9650924,422.71762,-9.2341127
6062,6062,196.1055,10.516826,8.044838,0.0,0,1.9515098,0.0,0.767851,62.10564,1.9451498,423.56528,-9.2332726
6073,6073,196.1077,10.549425,8.0579824,0.0,0,1.9347062,0.0,0.77120489,62.089069,1.9295886,424.41296,-9.2327471
6084,6084,196.1099,10.58618,8.0819616,0.0,0,1.918521,0.0,0.77284443,62.244255,1.9142711,425.26062,-9.2325611
6095,6095,196.1121,10.633431,8.0889711,0.0,0,1.9025358,0.0,0.77577901,62.252644,1.892753,425.99966,-9.2325964
6106,6106,196.1143,10.678368,8.1143618,0.0,0,1.8865505,0.0,0.77803212,62.435749,1.8781286,426.68802,-9.2346811
6117,6117,196.1165,10.70714,8.1261568,0.0,0,1.8705654,0.0,0.78114504,62.423244,1.8596557,427.37637,-9.2339058
6128,6128,196.1187,10.697172,8.1500711,0.0,0,1.8545802,0.0,0.78293407,62.260784,1.8445983,428.06473,-9.234745
6139,6139,196.1209,10.681054,8.155364,0.0,0,1.838595,0.0,0.78530562,61.991982,1.8283757,428.66739,-9.234272
6150,6150,196.1231,10.693108,8.1789169,0.0,0,1.8226099,0.0,0.78747606,61.940086,1.814268,428.76666,-9.2336636
6161,6161,196.1253,10.713049,8.1878214,0.0,0,1.8066247,0.0,0.7901147,61.933319,1.7985741,428.86594,-9.2344561
6172,6172,196.1275,10.806782,8.2145395,0.0,0,1.7906394,0.0,0.79227984,62.288631,1.7849483,428.96521,-9.2332287
6183,6183,196.1297,10.883081,8.2210321,0.0,0,1.7746543,0.0,0.79484093,62.580055,1.7672321,429.06448,-9.2330208
6194,6194,196.1319,10.912036,8.2442331,0.0,0,1.758669,0.0,0.7971195,62.56358,1.7514756,429.04694,-9.2332792
6205,6205,196.1341,10.935711,8.2526445,0.0,0,1.7426839,0.0,0.79960001,62.582531,1.7328805,428.95438,-9.2329931
6216,6216,196.1363,10.968923,8.2792339,0.0,0,1.7266986,0.0,0.80202496,62.619675,1.7151864,428.86185,-9.2335014
6227,6227,196.1385,10.985511,8.2850285,0.0,0,1.7107134,0.0,0.80425173,62.573704,1.700896,428.76929,-9.2333603
6238,6238,196.1407,10.995725,8.3052521,0.0,0,1.6947283,0.0,0.8061676,62.579872,1.6839674,428.72339,-9.2347355
6249,6249,196.1429,11.020431,8.3150482,0.0,0,1.678743,0.0,0.80872864,62.510117,1.6695403,429.27206,-9.2344398
6260,6260,196.1451,11.036788,8.3398952,0.0,0,1.6627578,0.0,0.81122112,62.438591,1.6565373,429.82077,-9.2336941
6271,6271,196.1473,11.098536,8.3475771,0.0,0,1.6467726,0.0,0.81348825,62.649261,1.6402401,430.36945,-9.2325954
6282,6282,196.1495,11.144218,8.3671112,0.0,0,1.6307874,0.0,0.81550545,62.780495,1.6229119,430.91815,-9.2331085
6293,6293,196.1517,11.206336,8.3768492,0.0,0,1.6148022,0.0,0.81785202,62.907909,1.6063612,431.33566,-9.2330341
6304,6304,196.1539,11.245228,8.4000902,0.0,0,1.5988171,0.0,0.82029957,63.057049,1.5948367,431.63974,-9.2322321
6315,6315,196.1561,11.262556,8.4066563,0.0,0,1.5828317,0.0,0.82247108,63.053146,1.5775011,431.94385,-9.2333326
6326,6326,196.1583,11.297226,8.4282265,0.0,0,1.5668756,0.0,0.82499605,63.052696,1.5613035,432.24792,-9.2334976
6337,6337,196.1605,11.331079,8.439579,0.0,0,1.5516622,0.0,0.82716942,63.06543,1.5476135,432.55203,-9.2336283
6348,6348,196.1627,11.374994,8.4634056,0.0,0,1.5364559,0.0,0.83021569,63.125645,1.5296644,431.55969,-9.2334299
6359,6359,196.1649,11.422772,8.4713707,0.0,0,1.5212495,0.0,0.83218712,63.250725,1.5147547,430.56735,-9.2334538
6370,6370,196.1671,11.485597,8.4910202,0.0,0,1.506043,0.0,0.83463782,63.440708,1.4979563,429.57501,-9.2339592
6381,6381,196.1693,11.528036,8.50175,0.0,0,1.4908366,0.0,0.83664715,63.604561,1.4845005,428.58267,-9.2343321
6392,6392,196.1715,11.575762,8.5246792,0.0,0,1.4756303,0.0,0.83972144,63.659271,1.4698877,427.73145,-9.2331553
6403,6403,196.1737,11.623986,8.532999,0.0,0,1.4604239,0.0,0.84146357,63.815037,1.4529575,427.04346,-9.2330961
6414,6414,196.1759,11.668599,8.5524035,0.0,0,1.4452175,0.0,0.84428966,63.852909,1.4371349,426.3555,-9.2332764
6425,6425,196.1781,11.716863,8.5635595,0.0,0,1.430011,0.0,0.84610403,64.003952,1.4227558,425.66751,-9.2331657
6436,6436,196.1803,11.744207,8.5879784,0.0,0,1.4148048,0.0,0.84965718,63.926891,1.4066039,424.97955,-9.2332344
6447,6447,196.1825,11.776714,8.5982428,0.0,0,1.3995984,0.0,0.85157239,63.999645,1.3942026,425.34088,-9.232954
6458,6458,196.1847,11.833939,8.6175623,0.0,0,1.3843919,0.0,0.85448724,64.091927,1.37585,425.78452,-9.2332163
6469,6469,196.1869,11.873042,8.6276016,0.0,0,1.3691854,0.0,0.8559711,64.173218,1.3594363,426.22815,-9.2341099
6480,6480,196.1891,11.865649,8.6476898,0.0,0,1.3539791,0.0,0.85942769,63.940899,1.3472146,426.67181,-9.2349167
6491,6491,196.1913,11.88468,8.6587925,0.0,0,1.3387728,0.0,0.86089814,63.99062,1.3286752,427.17477,-9.2331467
6502,6502,196.1935,11.905832,8.6751194,0.0,0,1.3235664,0.0,0.86383981,63.915794,1.313818,427.7702,-9.2335815
6513,6513,196.1957,11.955682,8.6850424,0.0,0,1.30836,0.0,0.86490649,64.12207,1.3036455,428.36563,-9.2331676
6524,6524,196.1979,11.977941,8.7043581,0.0,0,1.2931535,0.0,0.86850166,63.997269,1.2856331,428.96106,-9.2333269
6535,6535,196.2001,12.031003,8.718626,0.0,0,1.2779471,0.0,0.87007284,64.147789,1.2720934,429.55649,-9.2329912
6546,6546,196.2023,12.114384,8.7331028,0.0,0,1.2627407,0.0,0.87303644,64.392281,1.2556044,430.32101,-9.2332554
6557,6557,196.2045,12.212203,8.745513,0.0,0,1.2475343,0.0,0.8742879,64.840607,1.2423759,431.11429,-9.2332878
6568,6568,196.2067,12.270242,8.7641153,0.0,0,1.2323278,0.0,0.87813914,64.906807,1.2267519,431.90759,-9.2332468
6579,6579,196.2089,12.324692,8.7786884,0.0,0,1.2173454,0.0,0.87935746,65.131622,1.2073054,432.70087,-9.2325487
6590,6590,196.2111,12.33911,8.7913666,0.0,0,1.2028826,0.0,0.88269377,65.000435,1.1974207,433.51099,-9.2335043
6601,6601,196.2133,12.324713,8.8063593,0.0,0,1.1884197,0.0,0.88405597,64.866699,1.1792817,434.35718,-9.2336626
6612,6612,196.2155,12.338817,8.8240204,0.0,0,1.173957,0.0,0.88794804,64.682404,1.1648259,435.20337,-9.2323399
6623,6623,196.2177,12.410774,8.838994,0.0,0,1.1594943,0.0,0.88911021,64.926651,1.1484797,436.04956,-9.2333479
6634,6634,196.2199,12.490517,8.8493271,0.0,0,1.1450313,0.0,0.89194894,65.163651,1.1351699,436.89575,-9.2331839
6645,6645,196.2221,12.559753,8.8654985,0.0,0,1.1305685,0.0,0.89357108,65.41394,1.1215863,437.27161,-9.2334538
6656,6656,196.2243,12.588328,8.8805456,0.0,0,1.1161058,0.0,0.89738673,65.325493,1.105391,437.5162,-9.2336588
6667,6667,196.2265,12.60638,8.8984251,0.0,0,1.101643,0.0,0.89867777,65.344742,1.0899061,437.7608,-9.2332754
6678,6678,196.2287,12.618503,8.9086952,0.0,0,1.0871801,0.0,0.90178066,65.177765,1.0745687,438.00537,-9.2338057
6689,6689,196.2309,12.597586,8.9241982,0.0,0,1.0727174,0.0,0.90291774,65.051041,1.0617722,437.99847,-9.2342987
6700,6700,196.2331,12.6198,8.937439,0.0,0,1.0582546,0.0,0.90684068,64.88398,1.0504621,437.21838,-9.2336998
6711,6711,196.2353,12.658584,8.9527607,0.0,0,1.0437918,0.0,0.90760136,65.00415,1.0368457,436.43832,-9.2330513
6722,6722,196.2375,12.693734,8.9601088,0.0,0,1.0293289,0.0,0.91039717,65.029167,1.0223719,435.65826,-9.2339897
6733,6733,196.2397,12.774091,8.9753838,0.0,0,1.0148661,0.0,0.91140223,65.314461,1.007646,434.87817,-9.2332268
6744,6744,196.2419,12.857624,8.9887972,0.0,0,1.0004034,0.0,0.91535348,65.525055,0.99621558,434.31375,-9.2331305
6755,6755,196.2441,12.931438,9.0073719,0.0,0,0.98594052,0.0,0.9165448,65.872543,0.98285478,433.83777,-9.2322159
6766,6766,196.2463,12.993017,9.015089,0.0,0,0.97147781,0.0,0.91972107,65.969582,0.96682948,433.36179,-9.2322578
6777,6777,196.2485,13.033418,9.0337162,0.0,0,0.95701498,0.0,0.92103672,66.069023,0.9515,432.88583,-9.2333965
6788,6788,196.2507,13.077733,9.0466166,0.0,0,0.94255221,0.0,0.92501104,66.055428,0.93626612,432.5697,-9.2338676
6799,6799,196.2529,13.134803,9.0629749,0.0,0,0.92808938,0.0,0.92586654,66.235886,0.92244726,433.01926,-9.2337093
6810,6810,196.2551,13.184675,9.0707035,0.0,0,0.91362655,0.0,0.92911577,66.301628,0.90651989,433.46878,-9.232996
6821,6821,196.2573,13.263969,9.0916433,0.0,0,0.89916378,0.0,0.93081748,66.558693,0.89172232,433.9183,-9.2324743
6832,6832,196.2595,13.358418,9.1028986,0.0,0,0.88510746,0.0,0.93469048,66.770485,0.88160896,434.36786,-9.2325859
6843,6843,196.2617,13.431741,9.1243429,0.0,0,0.87135309,0.0,0.9358691,67.072205,0.86668849,434.19476,-9.2331266
6854,6854,196.2639,13.471146,9.1287327,0.0,0,0.8575986,0.0,0.93902123,67.06543,0.84990299,433.66589,-9.2332678
6865,6865,196.2661,13.492704,9.1490421,0.0,0,0.84384423,0.0,0.94047379,67.089355,0.83752614,433.13705,-9.2339077
6876,6876,196.2683,13.545837,9.1587839,0.0,0,0.83008987,0.0,0.94433385,67.095627,0.82391191,432.60818,-9.2332344
6887,6887,196.2705,13.596449,9.1800995,0.0,0,0.81633544,0.0,0.94536048,67.252777,0.80606127,432.0694,-9.2340603
6898,6898,196.2727,13.624177,9.1844721,0.0,0,0.80258107,0.0,0.94849354,67.171608,0.79747218,431.44138,-9.2336073
6909,6909,196.2749,13.663386,9.2060289,0.0,0,0.7888267,0.0,0.95035779,67.225624,0.77840567,430.81335,-9.2329311
6920,6920,196.2771,13.706178,9.2148113,0.0,0,0.77507228,0.0,0.95385373,67.217331,0.76301962,430.1853,-9.2329493
6931,6931,196.2793,13.788165,9.2363005,0.0,0,0.76131791,0.0,0.95510715,67.519211,0.75375205,429.55728,-9.2334824
6942,6942,196.2815,13.851746,9.2426558,0.0,0,0.74756348,0.0,0.95851493,67.615761,0.73921156,429.55151,-9.2340469
6953,6953,196.2837,13.893915,9.2619753,0.0,0,0.73380905,0.0,0.95996368,67.774406,0.72389501,430.0275,-9.2329597
6964,6964,196.2859,13.906221,9.2699156,0.0,0,0.72005463,0.0,0.96341866,67.556808,0.70836341,430.50348,-9.2324629
6975,6975,196.2881,13.903275,9.2931147,0.0,0,0.70630032,0.0,0.96503764,67.456512,0.69794142,430.97943,-9.2329998
6986,6986,196.2903,13.902546,9.2947369,0.0,0,0.69254589,0.0,0.96757734,67.273811,0.68359721,431.4657,-9.2334347
6997,6997,196.2925,13.92596,9.3108501,0.0,0,0.67879146,0.0,0.96852958,67.266357,0.66887009,432.31848,-9.2335711
7008,7008,196.2947,13.98554,9.3192005,0.0,0,0.6650371,0.0,0.9721154,67.325218,0.65956622,433.1713,-9.2334709
7019,7019,196.2969,14.055002,9.3423777,0.0,0,0.65128267,0.0,0.97378582,67.583931,0.64760584,434.02408,-9.232522
7030,7030,196.2991,14.149608,9.345356,0.0,0,0.6375283,0.0,0.97644407,67.873741,0.631042,434.87689,-9.2339678
7041,7041,196.3013,14.257126,9.365715,0.0,0,0.62377387,0.0,0.97833234,68.26796,0.61819959,435.78162,-9.233326
7052,7052,196.3035,14.342782,9.3725128,0.0,0,0.61001945,0.0,0.98127192,68.443222,0.60829812,436.74017,-9.2326536
7063,7063,196.3057,14.398211,9.3934937,0.0,0,0.59626508,0.0,0.98298144,68.590843,0.59137267,437.69873,-9.2333126
7074,7074,196.3079,14.443652,9.3981781,0.0,0,0.58251071,0.0,0.98580754,68.626778,0.57785124,438.65729,-9.2333727
7085,7085,196.3101,14.517812,9.4204397,0.0,0,0.56931871,0.0,0.98815012,68.774841,0.56224984,439.61584,-9.2333794
7090,7090,196.3111,14.588929,9.4208612,0.0,0,0.56336868,0.0,0.9901247,69.042709,0.55451018,439.90823,-9.2324438