File: clean data/testID_0255.csv
level_0,index,Time(sec),Force(kN),Jaw(mm),PowAngle(deg),Power(W),Pram,PTemp,Strain,Stress(MPa),Stroke(mm),TC1(C),wedge(mm)
2597,2597,212.0467,1.5699339,0.036455579,0.0,0,9.915864,0.0,0.002283959,19.638739,10.013862,502.30588,-9.2065887
2608,2608,212.0489,2.5702682,0.044718757,0.0,0,9.882863,0.0,0.0031637133,32.395172,9.9864206,502.32648,-9.2050924
2619,2619,212.0511,3.0366886,0.073970564,0.0,0,9.849864,0.0,0.004652251,38.441212,9.9526262,502.40527,-9.2048922
2630,2630,212.0533,3.1608028,0.10731784,0.0,0,9.8168631,0.0,0.0073256213,39.971027,9.917551,502.48407,-9.2048979
2641,2641,212.0555,3.2254999,0.14651172,0.0,0,9.783864,0.0,0.0095691457,40.647141,9.8793974,502.56287,-9.2049828
2652,2652,212.0577,3.2664256,0.18281163,0.0,0,9.7508631,0.0,0.012432502,41.151421,9.8393917,502.64166,-9.2050238
2663,2663,212.0599,3.2726526,0.22391832,0.0,0,9.717864,0.0,0.014738441,40.957699,9.7953701,502.60703,-9.2056103
2674,2674,212.0621,3.2977195,0.25259799,0.0,0,9.6848631,0.0,0.017148497,41.256588,9.763504,502.5545,-9.2059393
2685,2685,212.0643,3.3084779,0.28706908,0.0,0,9.6518641,0.0,0.019182066,41.316032,9.7288065,502.50198,-9.2059336
2696,2696,212.0665,3.3131397,0.31818059,0.0,0,9.6188631,0.0,0.021634094,41.409317,9.6967697,502.44946,-9.205719
2707,2707,212.0687,3.2922988,0.35245997,0.0,0,9.5858631,0.0,0.023441313,40.954681,9.6680431,502.21307,-9.2055397
2718,2718,212.0709,3.3125257,0.37518999,0.0,0,9.5528631,0.0,0.025475549,41.142517,9.6374655,501.58276,-9.2042351
2729,2729,212.0731,3.3208091,0.40674397,0.0,0,9.5198641,0.0,0.027345266,41.163311,9.6046686,500.95242,-9.2052145
2740,2740,212.0753,3.3372416,0.43783718,0.0,0,9.4868631,0.0,0.029846301,41.219406,9.5711718,500.32211,-9.2056904
2751,2751,212.0775,3.3627181,0.47945932,0.0,0,9.4545488,0.0,0.032119542,41.478836,9.5377541,499.69177,-9.2058706
2762,2762,212.0797,3.3794725,0.50768363,0.0,0,9.4223585,0.0,0.034536477,41.569584,9.5001259,500.11154,-9.2059822
2773,2773,212.0819,3.3964279,0.54156226,0.0,0,9.3901691,0.0,0.036600914,41.656372,9.4698601,500.84012,-9.2064638
2784,2784,212.0841,3.4110322,0.57320315,0.0,0,9.3579779,0.0,0.039198935,41.763813,9.4342985,501.5687,-9.2050276
2795,2795,212.0863,3.4107125,0.61171901,0.0,0,9.3257875,0.0,0.041284844,41.66468,9.4034309,502.2973,-9.2057323
2806,2806,212.0885,3.4131062,0.63878298,0.0,0,9.2935972,0.0,0.043659285,41.567986,9.367836,503.13333,-9.2059097
2817,2817,212.0907,3.4138384,0.67256856,0.0,0,9.2614069,0.0,0.045708943,41.630692,9.3382092,504.33466,-9.2062674
2828,2828,212.0929,3.4164271,0.70222181,0.0,0,9.2292166,0.0,0.048178203,41.482861,9.3043489,505.53601,-9.2063122
2839,2839,212.0951,3.4224842,0.74248546,0.0,0,9.1970263,0.0,0.05041289,41.496536,9.2705154,506.73734,-9.2061434
2850,2850,212.0973,3.4279199,0.76989979,0.0,0,9.164835,0.0,0.052831907,41.400131,9.2364044,507.93869,-9.2066011
2861,2861,212.0995,3.4424002,0.80435848,0.0,0,9.1326456,0.0,0.054934137,41.438896,9.2025585,508.86679,-9.2057276
2872,2872,212.1017,3.4499462,0.83352339,0.0,0,9.1004553,0.0,0.057446782,41.396427,9.1716728,509.66742,-9.2055893
2883,2883,212.1039,3.4656022,0.87262869,0.0,0,9.068265,0.0,0.059578352,41.549129,9.1365967,510.46802,-9.2054272
2894,2894,212.1061,3.4689627,0.89658642,0.0,0,9.0360737,0.0,0.061724696,41.526691,9.1036873,511.26865,-9.2068272
2905,2905,212.1083,3.4495957,0.92756134,0.0,0,9.0038834,0.0,0.063657641,41.206684,9.0754442,512.13367,-9.2059727
2916,2916,212.1105,3.4524677,0.95584172,0.0,0,8.971693,0.0,0.066025764,41.171253,9.0482616,513.4068,-9.2072811
2927,2927,212.1127,3.4601018,0.99370503,0.0,0,8.9395027,0.0,0.068225481,41.101364,9.0121326,514.67993,-9.2074795
2938,2938,212.1149,3.4826555,1.0184233,0.0,0,8.9073124,0.0,0.070440635,41.290417,8.9792156,515.953,-9.2063942
2949,2949,212.1171,3.5022135,1.0551583,0.0,0,8.8751221,0.0,0.072806329,41.485611,8.9460278,517.22614,-9.2054977
2960,2960,212.1193,3.5095687,1.0849584,0.0,0,8.8429308,0.0,0.075302325,41.404991,8.9136295,518.18506,-9.2070656
2971,2971,212.1215,3.5279586,1.1232282,0.0,0,8.8107414,0.0,0.077525884,41.537609,8.8800344,518.92651,-9.2061472
2982,2982,212.1237,3.5559859,1.1483496,0.0,0,8.7785501,0.0,0.079770319,41.781044,8.8450212,519.66791,-9.207118
2993,2993,212.1259,3.5665472,1.1824237,0.0,0,8.7465487,0.0,0.081958406,41.850155,8.8142004,520.40936,-9.2059984
3004,3004,212.1281,3.5649905,1.2130301,0.0,0,8.7159328,0.0,0.084490262,41.735817,8.7788086,521.13196,-9.2059851
3015,3015,212.1303,3.5652416,1.2536246,0.0,0,8.685317,0.0,0.086985826,41.683372,8.7457781,521.45996,-9.206171
3026,3026,212.1325,3.555614,1.2807844,0.0,0,8.6547022,0.0,0.089343518,41.428741,8.7130127,521.7879,-9.2062769
3037,3037,212.1347,3.5492077,1.3123106,0.0,0,8.6240873,0.0,0.091470696,41.239716,8.6832733,522.11591,-9.2077303
3048,3048,212.1369,3.5338757,1.3394951,0.0,0,8.5934715,0.0,0.09373758,41.002689,8.6497278,522.44385,-9.2070999
3059,3059,212.1391,3.5664628,1.3766209,0.0,0,8.5628567,0.0,0.095999017,41.274559,8.6160154,522.77185,-9.2054625
3070,3070,212.1413,3.5700908,1.4003469,0.0,0,8.5322428,0.0,0.098119922,41.120617,8.5870476,523.09979,-9.205308
3081,3081,212.1435,3.5832853,1.4319971,0.0,0,8.501626,0.0,0.10019494,41.264717,8.5620642,523.4278,-9.2050982
3092,3092,212.1457,3.5804954,1.4573588,0.0,0,8.4710112,0.0,0.10235378,41.154282,8.5289841,523.75574,-9.2062044
3103,3103,212.1479,3.5890751,1.4947698,0.0,0,8.4403954,0.0,0.10471975,41.225529,8.4977217,524.08374,-9.2057409
3114,3114,212.1501,3.5911305,1.5190147,0.0,0,8.4097815,0.0,0.10688528,41.109447,8.4703579,524.33655,-9.2052126
3125,3125,212.1523,3.6033921,1.5525092,0.0,0,8.3791656,0.0,0.10913008,41.170162,8.4376984,524.58582,-9.2058659
3136,3136,212.1545,3.6054935,1.578831,0.0,0,8.3485498,0.0,0.11133781,41.113365,8.4059525,524.83508,-9.2044926
3147,3147,212.1567,3.6344445,1.6171649,0.0,0,8.317935,0.0,0.11382198,41.281948,8.377511,525.08435,-9.2058239
3158,3158,212.1589,3.6434319,1.6439785,0.0,0,8.2873201,0.0,0.11616207,41.29488,8.3463345,525.34436,-9.2063265
3169,3169,212.1611,3.6813109,1.6750396,0.0,0,8.2567053,0.0,0.1182759,41.629253,8.3106604,525.61981,-9.2053986
3180,3180,212.1633,3.7065012,1.704662,0.0,0,8.2260895,0.0,0.12067574,41.842155,8.2799549,525.89532,-9.2052679
3191,3191,212.1655,3.6811023,1.7423786,0.0,0,8.1954756,0.0,0.12329333,41.446178,8.2465334,526.17084,-9.2051611
3202,3202,212.1677,3.6626279,1.7685779,0.0,0,8.1648588,0.0,0.12548815,41.095661,8.217494,526.44635,-9.2049799
3213,3213,212.1699,3.680948,1.80098,0.0,0,8.134244,0.0,0.12775305,41.254871,8.1894245,526.84076,-9.2059374
3224,3224,212.1721,3.6883638,1.8291125,0.0,0,8.1036291,0.0,0.13012873,41.24276,8.1545897,527.25397,-9.2069092
3235,3235,212.1743,3.704531,1.8671684,0.0,0,8.0730143,0.0,0.13275708,41.27322,8.1234732,527.66724,-9.2058039
3246,3246,212.1765,3.6956375,1.8910968,0.0,0,8.0429821,0.0,0.13480553,41.111496,8.0906057,528.08044,-9.2060251
3257,3257,212.1787,3.7290912,1.9226801,0.0,0,8.013854,0.0,0.1369749,41.383766,8.0642862,528.41437,-9.2064838
3268,3268,212.1809,3.7292528,1.9517615,0.0,0,7.984726,0.0,0.13936435,41.285126,8.0343666,528.57837,-9.2054157
3279,3279,212.1831,3.7489569,1.988086,0.0,0,7.9555979,0.0,0.14194989,41.34045,7.996892,528.74237,-9.2061834
3290,3290,212.1853,3.7069411,2.0107999,0.0,0,7.9264693,0.0,0.1439178,40.907246,7.9710274,528.90637,-9.2056808
3301,3301,212.1875,3.6972833,2.0390761,0.0,0,7.8973413,0.0,0.1460768,40.757111,7.9437852,529.07031,-9.2054348
3312,3312,212.1897,3.7090809,2.0665121,0.0,0,7.8682137,0.0,0.14823247,40.720676,7.91257,529.13293,-9.2060785
3323,3323,212.1919,3.721061,2.1012516,0.0,0,7.8390856,0.0,0.15080316,40.680431,7.8813643,529.16577,-9.2065992
3334,3334,212.1941,3.7388003,2.1239359,0.0,0,7.8099575,0.0,0.15271753,40.914345,7.8557854,529.19855,-9.2063723
3345,3345,212.1963,3.7499893,2.1526988,0.0,0,7.7808294,0.0,0.15490392,40.966595,7.8258209,529.23138,-9.2065039
3356,3356,212.1985,3.7621839,2.1786366,0.0,0,7.7517014,0.0,0.15696806,40.978786,7.7978725,529.30145,-9.2060013
3367,3367,212.2007,3.7731147,2.211648,0.0,0,7.7225738,0.0,0.15937477,40.919796,7.7706356,529.49823,-9.2071753
3378,3378,212.2029,3.7914753,2.2365758,0.0,0,7.6934457,0.0,0.1614707,41.081932,7.7377081,529.69495,-9.2063227
3389,3389,212.2051,3.793401,2.2681105,0.0,0,7.6643171,0.0,0.1638919,41.027157,7.7129483,529.89172,-9.20508
3400,3400,212.2073,3.7923651,2.2956405,0.0,0,7.6351895,0.0,0.1660732,40.899456,7.6792579,530.0885,-9.2049589
3411,3411,212.2095,3.8220294,2.3296316,0.0,0,7.6060615,0.0,0.16874614,41.104477,7.6476383,530.36578,-9.2048292
3422,3422,212.2117,3.8173237,2.3545146,0.0,0,7.5769334,0.0,0.17071061,40.970337,7.6222706,530.68066,-9.2055178
3433,3433,212.2139,3.8203971,2.3841434,0.0,0,7.5478053,0.0,0.17311513,40.920879,7.5923929,530.99548,-9.2064962
3444,3444,212.2161,3.8289323,2.4118917,0.0,0,7.5186772,0.0,0.1752232,40.959969,7.5632591,531.31036,-9.2071466
3455,3455,212.2183,3.8364089,2.4453602,0.0,0,7.4895492,0.0,0.17793839,40.89724,7.5314012,531.60645,-9.205615
3466,3466,212.2205,3.8562324,2.4703755,0.0,0,7.4604211,0.0,0.17985953,41.040981,7.5045471,531.78357,-9.2045364
3477,3477,212.2227,3.8741903,2.4988849,0.0,0,7.431293,0.0,0.1822028,41.14407,7.4754729,531.96063,-9.2048492
3488,3488,212.2249,3.8592262,2.5264864,0.0,0,7.4021654,0.0,0.18434104,40.916889,7.4469743,532.13776,-9.2052975
3499,3499,212.2271,3.8775117,2.5598977,0.0,0,7.3739853,0.0,0.18719147,40.983234,7.4142051,532.31488,-9.2058249
3510,3510,212.2293,3.9032156,2.5871351,0.0,0,7.346283,0.0,0.18921274,41.132385,7.3830786,532.48035,-9.2050753
3521,3521,212.2315,3.9150896,2.6142633,0.0,0,7.3185806,0.0,0.1915143,41.101143,7.3561826,532.63776,-9.2045393
3532,3532,212.2337,3.9106503,2.6427488,0.0,0,7.2908783,0.0,0.19371876,41.021446,7.3258533,532.79523,-9.2054214
3543,3543,212.2359,3.9075933,2.674973,0.0,0,7.263176,0.0,0.19651553,40.826553,7.2965307,532.95264,-9.2048473
3554,3554,212.2381,3.9006581,2.7004206,0.0,0,7.2354732,0.0,0.19836351,40.745739,7.2697902,533.11243,-9.205122
3565,3565,212.2403,3.9059348,2.726367,0.0,0,7.2077708,0.0,0.20058841,40.775616,7.2435546,533.32233,-9.2056971
3576,3576,212.2425,3.9167337,2.7512984,0.0,0,7.1800685,0.0,0.20255816,40.705402,7.2164421,533.53223,-9.2047291
3587,3587,212.2447,3.9197643,2.7841413,0.0,0,7.1523662,0.0,0.20537339,40.615318,7.1864085,533.74213,-9.2054024
3598,3598,212.2469,3.9516063,2.8115251,0.0,0,7.1246629,0.0,0.20734955,40.86739,7.1592884,533.95203,-9.206995
3609,3609,212.2491,3.9820228,2.8391519,0.0,0,7.096961,0.0,0.20986171,41.069,7.130434,534.17181,-9.2051382
3620,3620,212.2513,3.9962869,2.866956,0.0,0,7.0692587,0.0,0.21198151,41.153828,7.0985746,534.40137,-9.2049589
3631,3631,212.2535,3.9629619,2.8985293,0.0,0,7.0415564,0.0,0.21487953,40.700897,7.0705495,534.63098,-9.2055922
3642,3642,212.2557,3.9660497,2.9250727,0.0,0,7.0138535,0.0,0.21672672,40.652523,7.0482898,534.86053,-9.2056618
3653,3653,212.2579,3.9793499,2.9486623,0.0,0,6.9861512,0.0,0.21893935,40.75864,7.0198293,535.09015,-9.2056255
3664,3664,212.2601,3.9986398,2.974674,0.0,0,6.9584489,0.0,0.22086334,40.8554,6.9903569,535.20081,-9.2064734
3675,3675,212.2623,3.9922969,3.0065358,0.0,0,6.930747,0.0,0.22381587,40.603226,6.9597831,535.30579,-9.2050028
3686,3686,212.2645,3.9807384,3.0327959,0.0,0,6.9030442,0.0,0.22564343,40.514668,6.9357128,535.41077,-9.2050772
3697,3697,212.2667,3.9936173,3.0582051,0.0,0,6.8753419,0.0,0.22808747,40.404293,6.9084778,535.51575,-9.2050591
3708,3708,212.2689,4.0363193,3.085247,0.0,0,6.8476396,0.0,0.2299986,40.766399,6.8803921,535.59119,-9.2047281
3719,3719,212.2711,4.0499268,3.1132283,0.0,0,6.8199368,0.0,0.232715,40.882427,6.85467,535.62402,-9.2050323
3730,3730,212.2733,4.0619369,3.1417735,0.0,0,6.7922344,0.0,0.23471615,40.872868,6.8258142,535.6568,-9.2045336
3741,3741,212.2755,4.0713377,3.1656129,0.0,0,6.7645321,0.0,0.23712309,40.906784,6.7941403,535.68964,-9.2044382
3752,3752,212.2777,4.0738664,3.1948888,0.0,0,6.7380919,0.0,0.23932725,40.837868,6.77174,535.72247,-9.205369
3763,3763,212.2799,4.0653162,3.2247958,0.0,0,6.7117357,0.0,0.24232136,40.68021,6.738008,535.77228,-9.2062883
3774,3774,212.2821,4.0723748,3.2548835,0.0,0,6.68538,0.0,0.24425364,40.563454,6.7111068,535.82471,-9.2050495
3785,3785,212.2843,4.0813904,3.2783813,0.0,0,6.6590238,0.0,0.24679373,40.517014,6.6806102,535.8772,-9.2049952
3796,3796,212.2865,4.0593638,3.303581,0.0,0,6.632668,0.0,0.24853246,40.23539,6.6567407,535.92969,-9.2057838
3807,3807,212.2887,4.0606251,3.3302495,0.0,0,6.6063118,0.0,0.25131381,40.14782,6.6312351,535.97797,-9.2052736
3818,3818,212.2909,4.0785851,3.3570926,0.0,0,6.5799561,0.0,0.25301963,40.354939,6.60607,536.01733,-9.2051191
3829,3829,212.2931,4.062664,3.3775156,0.0,0,6.5535998,0.0,0.25531617,40.124931,6.5819082,536.0567,-9.2055817
3840,3840,212.2953,4.10041,3.4042032,0.0,0,6.5272441,0.0,0.25715238,40.436562,6.5557828,536.09607,-9.2059603
3851,3851,212.2975,4.1086965,3.4317398,0.0,0,6.5008879,0.0,0.25999203,40.418423,6.5293269,536.13544,-9.2048531
3862,3862,212.2997,4.1046667,3.4586859,0.0,0,6.4745321,0.0,0.26173818,40.322224,6.5031295,536.15454,-9.2058039
3873,3873,212.3019,4.1085863,3.4794993,0.0,0,6.4481759,0.0,0.26420623,40.160408,6.4756999,536.16766,-9.2064648
3884,3884,212.3041,4.1383381,3.5086813,0.0,0,6.4218202,0.0,0.26614293,40.319332,6.4527884,536.18085,-9.2057934
3895,3895,212.3063,4.1622066,3.5359099,0.0,0,6.3954639,0.0,0.26915753,40.445923,6.4216275,536.19397,-9.2050962
3906,3906,212.3085,4.1868725,3.5654342,0.0,0,6.3691082,0.0,0.27104399,40.626408,6.3954663,536.20709,-9.2050114
3917,3917,212.3107,4.1888027,3.5870361,0.0,0,6.342752,0.0,0.27356857,40.595268,6.3711143,536.22021,-9.2058144
3928,3928,212.3129,4.1892104,3.6130085,0.0,0,6.3163962,0.0,0.27531636,40.537136,6.3463931,536.23334,-9.2056713
3939,3939,212.3151,4.1729884,3.6418023,0.0,0,6.2900405,0.0,0.27847737,40.331673,6.3163881,536.24646,-9.205513
3950,3950,212.3173,4.1979265,3.6729,0.0,0,6.2636843,0.0,0.28048435,40.340858,6.2904906,536.25958,-9.2052698
3961,3961,212.3195,4.1955671,3.6957514,0.0,0,6.2373285,0.0,0.28316259,40.258568,6.2585773,536.21899,-9.2057114
3972,3972,212.3217,4.1823297,3.7217042,0.0,0,6.2109723,0.0,0.28484192,40.058105,6.2346411,536.15338,-9.2040081
3983,3983,212.3239,4.2171874,3.7446978,0.0,0,6.1846166,0.0,0.28753281,40.221596,6.2093067,536.08777,-9.2051058
3994,3994,212.3261,4.243804,3.7757862,0.0,0,6.1585317,0.0,0.28956804,40.36832,6.1818008,536.02216,-9.2067823
4005,4005,212.3283,4.2658362,3.7992871,0.0,0,6.1334648,0.0,0.2923924,40.505615,6.1569166,535.96185,-9.2055693
4016,4016,212.3305,4.2742181,3.826611,0.0,0,6.1083975,0.0,0.29422447,40.594158,6.1290579,535.93561,-9.2051439
4027,4027,212.3327,4.2408156,3.8521757,0.0,0,6.0833311,0.0,0.29711148,40.054192,6.1056337,535.90942,-9.2056828
4038,4038,212.3349,4.2428679,3.8806901,0.0,0,6.0582643,0.0,0.29889512,40.025784,6.0791039,535.88318,-9.2037249
4049,4049,212.3371,4.2480421,3.9000828,0.0,0,6.0331974,0.0,0.30144086,40.087502,6.0535998,535.85693,-9.2030783
4060,4060,212.3393,4.2337518,3.9282904,0.0,0,6.0081306,0.0,0.30332553,39.798576,6.0275426,535.88885,-9.2037592
4071,4071,212.3415,4.2451739,3.9518728,0.0,0,5.9830642,0.0,0.30617136,39.728748,6.0008483,535.961,-9.206686
4082,4082,212.3437,4.2800446,3.9815476,0.0,0,5.9579968,0.0,0.3078472,39.929291,5.9781523,536.0332,-9.2060499
4093,4093,212.3459,4.3046002,3.997937,0.0,0,5.9329305,0.0,0.31028959,40.166088,5.9534163,536.10535,-9.2046919
4104,4104,212.3481,4.3273559,4.0274615,0.0,0,5.9078636,0.0,0.31225219,40.34626,5.9271445,536.17487,-9.20504
4115,4115,212.3503,4.3494902,4.0526218,0.0,0,5.8827968,0.0,0.31533277,40.430321,5.8990288,536.18799,-9.2047567
4126,4126,212.3525,4.3308711,4.0842443,0.0,0,5.8577299,0.0,0.31727341,40.150562,5.8732386,536.20111,-9.2039433
4137,4137,212.3547,4.3009887,4.1038709,0.0,0,5.8326631,0.0,0.31999266,39.718941,5.8471308,536.21423,-9.2049818
4148,4148,212.3569,4.3129053,4.1305981,0.0,0,5.8075962,0.0,0.32176638,39.791279,5.8257451,536.22736,-9.2049837
4159,4159,212.3591,4.3060803,4.1511502,0.0,0,5.7825289,0.0,0.32437548,39.594872,5.7968636,536.21094,-9.2052813
4170,4170,212.3613,4.3208804,4.1823473,0.0,0,5.7574625,0.0,0.3263365,39.732399,5.7769761,536.16498,-9.2050238
4181,4181,212.3635,4.3758917,4.2020497,0.0,0,5.7323956,0.0,0.32899481,40.099636,5.7512412,536.11908,-9.2049284
4192,4192,212.3657,4.3958321,4.2284746,0.0,0,5.7073288,0.0,0.33081308,40.253681,5.7240682,536.07318,-9.204258
4203,4203,212.3679,4.3904428,4.2507672,0.0,0,5.6822624,0.0,0.33363867,39.998959,5.6970611,536.02722,-9.2049799
4214,4214,212.3701,4.3770604,4.283637,0.0,0,5.6571956,0.0,0.33569822,39.857521,5.6754031,535.96252,-9.2054272
4225,4225,212.3723,4.3814969,4.3007121,0.0,0,5.6321287,0.0,0.33826247,39.774704,5.6506886,535.89691,-9.2048016
4236,4236,212.3745,4.3840766,4.3298311,0.0,0,5.6070614,0.0,0.34024027,39.743568,5.6240959,535.8313,-9.2034702
4247,4247,212.3767,4.384048,4.350894,0.0,0,5.5825839,0.0,0.34293526,39.650467,5.6000214,535.76569,-9.204936
4258,4258,212.3789,4.411088,4.3797488,0.0,0,5.5587354,0.0,0.34480834,39.799725,5.5758672,535.72693,-9.2040005
4269,4269,212.3811,4.4373465,4.400363,0.0,0,5.5348878,0.0,0.34754038,39.917671,5.5497274,535.72693,-9.2048578
4280,4280,212.3833,4.4474893,4.427309,0.0,0,5.5110397,0.0,0.34938508,39.9888,5.5239129,535.72693,-9.2038851
4291,4291,212.3855,4.46872,4.4490199,0.0,0,5.4871917,0.0,0.35222739,40.069489,5.4992371,535.72693,-9.2037878
4302,4302,212.3877,4.4345803,4.4790244,0.0,0,5.4633436,0.0,0.35414815,39.622635,5.4752283,535.72693,-9.2040234
4313,4313,212.3899,4.4536872,4.4963408,0.0,0,5.4394956,0.0,0.3566702,39.724548,5.4503298,535.77228,-9.2038565
4324,4324,212.3921,4.4134731,4.5240879,0.0,0,5.4156475,0.0,0.35867923,39.344692,5.4300942,535.82471,-9.2050161
4335,4335,212.3943,4.4221978,4.5416865,0.0,0,5.3917999,0.0,0.36107051,39.286476,5.4027214,535.8772,-9.2050171
4346,4346,212.3965,4.4476895,4.5717282,0.0,0,5.3679519,0.0,0.36303949,39.380829,5.3810472,535.92969,-9.2049942
4357,4357,212.3987,4.4686842,4.5881538,0.0,0,5.3441038,0.0,0.36547962,39.448933,5.3572307,535.9884,-9.2057238
4368,4368,212.4009,4.5083947,4.6140304,0.0,0,5.3202558,0.0,0.36734408,39.712795,5.3356981,536.06061,-9.2050323
4379,4379,212.4031,4.5179205,4.6350312,0.0,0,5.2964077,0.0,0.37003145,39.676582,5.3093233,536.13281,-9.206049
4390,4390,212.4053,4.5212498,4.66782,0.0,0,5.2725596,0.0,0.37231299,39.659538,5.2844205,536.20496,-9.2049904
4401,4401,212.4075,4.526433,4.6840582,0.0,0,5.2487121,0.0,0.374787,39.636784,5.26689,536.27716,-9.2056589
4412,4412,212.4097,4.5087013,4.7110562,0.0,0,5.224864,0.0,0.37669557,39.419399,5.2411013,536.3595,-9.2055531
4423,4423,212.4119,4.4945407,4.7309031,0.0,0,5.2010159,0.0,0.37930319,39.208744,5.2149315,536.44476,-9.2042627
4434,4434,212.4141,4.5160875,4.7617383,0.0,0,5.1771674,0.0,0.38140365,39.280289,5.1957707,536.53009,-9.2055435
4445,4445,212.4163,4.5509396,4.774147,0.0,0,5.1533198,0.0,0.38347992,39.460976,5.1726184,536.61536,-9.2052841
4456,4456,212.4185,4.5846057,4.8025088,0.0,0,5.1294718,0.0,0.38565105,39.698681,5.1425643,536.70215,-9.2044106
4467,4467,212.4207,4.6049414,4.8239408,0.0,0,5.1056237,0.0,0.38843605,39.746593,5.1174545,536.79401,-9.203702
4478,4478,212.4229,4.6587553,4.8590574,0.0,0,5.0817757,0.0,0.39096928,40.095459,5.0958767,536.88586,-9.2053146
4489,4489,212.4251,4.6477532,4.877038,0.0,0,5.0579276,0.0,0.39344954,40.028198,5.0672317,536.97772,-9.206439
4500,4500,212.4273,4.626687,4.9038544,0.0,0,5.0349607,0.0,0.39563754,39.717178,5.0461278,537.06958,-9.2065678
4511,4511,212.4295,4.5908256,4.9232311,0.0,0,5.012279,0.0,0.39821535,39.316982,5.024262,537.15698,-9.2064629
4522,4522,212.4317,4.6324358,4.9549088,0.0,0,4.9895968,0.0,0.40056589,39.486633,4.999599,537.24231,-9.2055378
4533,4533,212.4339,4.6235509,4.9713888,0.0,0,4.9669147,0.0,0.40290099,39.298634,4.976016,537.32758,-9.2058249
4544,4544,212.4361,4.6472936,4.9971442,0.0,0,4.9442329,0.0,0.40494815,39.397526,4.9533648,537.4129,-9.2057552
4555,4555,212.4383,4.6595564,5.0178661,0.0,0,4.9215508,0.0,0.40750483,39.426998,4.9300494,537.49463,-9.2055902
4566,4566,212.4405,4.6781874,5.0505466,0.0,0,4.898869,0.0,0.41006386,39.561153,4.9039888,537.55371,-9.2064638
4577,4577,212.4427,4.6979332,5.0631213,0.0,0,4.8761868,0.0,0.41199028,39.612514,4.8822455,537.61273,-9.2050905
4588,4588,212.4449,4.6785469,5.0884061,0.0,0,4.8535047,0.0,0.41407603,39.386478,4.8580327,537.67181,-9.2049761
4599,4599,212.4471,4.6621728,5.1078691,0.0,0,4.8308229,0.0,0.41655174,39.089119,4.8343554,537.73083,-9.2048168
4610,4610,212.4493,4.6477752,5.1383991,0.0,0,4.8081408,0.0,0.41905636,38.962868,4.8145823,537.78217,-9.2066021
4621,4621,212.4515,4.6396542,5.1528769,0.0,0,4.785459,0.0,0.42096841,38.785957,4.7941041,537.82806,-9.2055321
4632,4632,212.4537,4.6633749,5.1768227,0.0,0,4.7627769,0.0,0.42311889,38.881935,4.7717476,537.87396,-9.2037039
4643,4643,212.4559,4.7177587,5.196413,0.0,0,4.7400947,0.0,0.42553014,39.20517,4.7489333,537.91992,-9.20473
4654,4654,212.4581,4.7148471,5.2259436,0.0,0,4.7174129,0.0,0.4280251,39.105915,4.7263031,537.96552,-9.2050495
4665,4665,212.4603,4.7495031,5.2385693,0.0,0,4.6947308,0.0,0.42967671,39.323597,4.7074342,538.00488,-9.2042837
4676,4676,212.4625,4.7738576,5.2656474,0.0,0,4.6720486,0.0,0.43220535,39.414215,4.6832352,538.04425,-9.2054167
4687,4687,212.4647,4.773572,5.2858677,0.0,0,4.6493669,0.0,0.43464145,39.370544,4.6576171,538.08362,-9.2056465
4698,4698,212.4669,4.7957006,5.3179736,0.0,0,4.6266847,0.0,0.43739745,39.445404,4.6370435,538.12299,-9.2068815
4709,4709,212.4691,4.7837501,5.3324189,0.0,0,4.604003,0.0,0.43951544,39.283463,4.6140823,538.16565,-9.2063179
4720,4720,212.4713,4.8285604,5.3596983,0.0,0,4.5813208,0.0,0.44187221,39.473709,4.590611,538.21161,-9.205843
4731,4731,212.4735,4.8400311,5.3809686,0.0,0,4.5586386,0.0,0.44434422,39.504086,4.565805,538.25751,-9.2054911
4742,4742,212.4757,4.841888,5.411231,0.0,0,4.5359983,0.0,0.44718227,39.440369,4.5440121,538.30341,-9.2047386
4753,4753,212.4779,4.8367462,5.4262309,0.0,0,4.5144105,0.0,0.44906974,39.34901,4.521842,538.34937,-9.2049465
4764,4764,212.4801,4.8271985,5.4511619,0.0,0,4.4928331,0.0,0.45148367,39.116016,4.4984727,538.37653,-9.2048225
4775,4775,212.4823,4.8396587,5.470437,0.0,0,4.4712553,0.0,0.45363086,39.12746,4.4740663,538.40277,-9.2048597
4786,4786,212.4845,4.8387594,5.5002537,0.0,0,4.4496775,0.0,0.45653313,39.060345,4.452394,538.42902,-9.2056322
4797,4797,212.4867,4.8197432,5.5157909,0.0,0,4.4280996,0.0,0.45846376,38.854038,4.4323902,538.45526,-9.2058687
4808,4808,212.4889,4.8271556,5.5373769,0.0,0,4.4065223,0.0,0.46055481,38.77943,4.4139585,538.45465,-9.205615
4819,4819,212.4911,4.8281751,5.5531502,0.0,0,4.3849444,0.0,0.46246925,38.667019,4.3876681,538.41528,-9.2057333
4830,4830,212.4933,4.8455801,5.5808296,0.0,0,4.3633671,0.0,0.46511909,38.786053,4.3673553,538.37592,-9.2049541
4841,4841,212.4955,4.8863254,5.5965343,0.0,0,4.3417897,0.0,0.46691868,39.012901,4.3489189,538.33655,-9.2048206
4852,4852,212.4977,4.9293537,5.6214767,0.0,0,4.3202119,0.0,0.46967003,39.264526,4.3288412,538.29718,-9.2047796
4863,4863,212.4999,4.9307852,5.6401296,0.0,0,4.2986345,0.0,0.47159296,39.169571,4.3045125,538.23511,-9.2052479
4874,4874,212.5021,4.9516015,5.6704197,0.0,0,4.2770567,0.0,0.4747417,39.159126,4.2853131,538.16949,-9.2048292
4885,4885,212.5043,4.9489641,5.6849437,0.0,0,4.2554789,0.0,0.47632399,39.200508,4.2633309,538.10388,-9.2047949
4896,4896,212.5065,4.9459743,5.7091327,0.0,0,4.2339015,0.0,0.47902694,39.008183,4.2379794,538.03827,-9.2051821
4907,4907,212.5087,4.9573345,5.7283287,0.0,0,4.2123237,0.0,0.4811236,39.013889,4.215879,537.95593,-9.2057905
4918,4918,212.5109,4.9836311,5.7577915,0.0,0,4.1907463,0.0,0.484256,39.118362,4.1942749,537.83783,-9.2056923
4929,4929,212.5131,4.9995403,5.7733593,0.0,0,4.1691685,0.0,0.48583192,39.122932,4.1720028,537.71979,-9.2053356
4940,4940,212.5153,5.0359602,5.7957883,0.0,0,4.1475911,0.0,0.48840037,39.294628,4.1535549,537.60168,-9.2047558
4951,4951,212.5175,5.0109296,5.8133593,0.0,0,4.1260133,0.0,0.4901588,39.137928,4.1247778,537.48358,-9.2043781
4962,4962,212.5197,5.0187783,5.8421454,0.0,0,4.1044359,0.0,0.49350715,38.955437,4.1089549,537.27423,-9.2047329
4973,4973,212.5219,5.014071,5.8589277,0.0,0,4.0828586,0.0,0.4951691,38.896198,4.0863919,537.03796,-9.2048244
4984,4984,212.5241,5.0414901,5.8794303,0.0,0,4.0612807,0.0,0.4976069,39.026253,4.065845,536.80176,-9.2057371
4995,4995,212.5263,5.022728,5.8982625,0.0,0,4.0400209,0.0,0.4994128,38.816586,4.0444078,536.56555,-9.2057409
5006,5006,212.5285,5.0587687,5.9244251,0.0,0,4.0194993,0.0,0.50248605,38.937828,4.0244589,536.29803,-9.2055979
5017,5017,212.5307,5.069025,5.9438872,0.0,0,3.9989779,0.0,0.50440681,38.977863,4.0040936,535.92407,-9.204772
5028,5028,212.5329,5.0959496,5.9636154,0.0,0,3.9784563,0.0,0.50690335,39.126282,3.9827495,535.55011,-9.2042742
5039,5039,212.5351,5.0914526,5.9841256,0.0,0,3.9579346,0.0,0.50878495,39.003769,3.9621818,535.17615,-9.2042875
5050,5050,212.5373,5.1009417,6.0059824,0.0,0,3.9374132,0.0,0.51165479,38.930897,3.9394836,534.80219,-9.2050161
5061,5061,212.5395,5.1157637,6.0257244,0.0,0,3.9168916,0.0,0.5133937,38.99831,3.9195025,534.44171,-9.2056656
5072,5072,212.5417,5.1485777,6.0481935,0.0,0,3.8963699,0.0,0.51638216,39.13026,3.9012854,534.08746,-9.2047358
5083,5083,212.5439,5.1595998,6.0678258,0.0,0,3.8758483,0.0,0.51820296,39.130875,3.879214,533.73328,-9.2045012
5094,5094,212.5461,5.1955028,6.0923696,0.0,0,3.8553267,0.0,0.52137488,39.259785,3.8563514,533.37903,-9.2038727
5105,5105,212.5483,5.2163863,6.115499,0.0,0,3.834805,0.0,0.52333564,39.355984,3.8356838,532.96039,-9.2056656
5116,5116,212.5505,5.2228823,6.1348095,0.0,0,3.8142834,0.0,0.52613801,39.26881,3.815191,532.13391,-9.204215
5127,5127,212.5527,5.2011142,6.1553922,0.0,0,3.793762,0.0,0.52795625,39.104019,3.7915573,531.30743,-9.2048273
5138,5138,212.5549,5.2100911,6.179502,0.0,0,3.7732403,0.0,0.53124976,38.992748,3.7719884,530.48096,-9.2046919
5149,5149,212.5571,5.1875486,6.1984086,0.0,0,3.7527184,0.0,0.53271699,38.736832,3.7520921,529.65448,-9.2055073
5160,5160,212.5593,5.1662188,6.2146492,0.0,0,3.732197,0.0,0.53515363,38.58094,3.7326028,528.64966,-9.2052698
5171,5171,212.5615,5.1884289,6.2356939,0.0,0,3.7116754,0.0,0.53695738,38.636253,3.7148361,527.52148,-9.2056026
5182,5182,212.5637,5.2297077,6.2573466,0.0,0,3.6911538,0.0,0.54018557,38.830841,3.6946175,526.39325,-9.2050161
5193,5193,212.5659,5.2511492,6.27774,0.0,0,3.6706321,0.0,0.54174256,38.909954,3.6733582,525.26501,-9.2059851
5204,5204,212.5681,5.2712846,6.2956371,0.0,0,3.6501107,0.0,0.54448551,38.922913,3.6538625,524.17407,-9.2058077
5215,5215,212.5703,5.3290153,6.3157735,0.0,0,3.6295891,0.0,0.54620653,39.244839,3.6311386,523.86578,-9.2064161
5226,5226,212.5725,5.3357549,6.3378592,0.0,0,3.6090674,0.0,0.54947543,39.241383,3.6091495,523.5575,-9.205596
5237,5237,212.5747,5.3111033,6.3601713,0.0,0,3.5885458,0.0,0.55115706,38.978642,3.5915484,523.24921,-9.2058668
5248,5248,212.5769,5.3244467,6.3782611,0.0,0,3.5685976,0.0,0.55403829,38.921566,3.5696657,522.94092,-9.2049141
5259,5259,212.5791,5.3282967,6.3993468,0.0,0,3.5490746,0.0,0.55577219,38.866863,3.549613,522.91791,-9.2048693
5270,5270,212.5813,5.3326721,6.4179096,0.0,0,3.5295517,0.0,0.55881208,38.792316,3.5303802,523.1803,-9.2059326
5281,5281,212.5835,5.3317947,6.4377723,0.0,0,3.5100293,0.0,0.56029749,38.799843,3.5133443,523.44269,-9.2071524
5292,5292,212.5857,5.366869,6.4570441,0.0,0,3.4905062,0.0,0.56336302,38.936939,3.493093,523.70508,-9.2064619
5303,5303,212.5879,5.4111514,6.47855,0.0,0,3.4709835,0.0,0.5649839,39.10043,3.4724174,523.96747,-9.2060242
5314,5314,212.5901,5.4350681,6.4970498,0.0,0,3.4514608,0.0,0.56808853,39.211853,3.4519839,524.36517,-9.2047844
5325,5325,212.5923,5.447928,6.5205379,0.0,0,3.4319377,0.0,0.56989384,39.219936,3.433439,524.76935,-9.2034941
5336,5336,212.5945,5.4354749,6.5374932,0.0,0,3.412415,0.0,0.57279348,39.095383,3.4135399,525.17346,-9.2056923
5347,5347,212.5967,5.457334,6.559485,0.0,0,3.3928924,0.0,0.57461786,39.095455,3.392405,525.57764,-9.2066708
5358,5358,212.5989,5.4502277,6.5809712,0.0,0,3.3733692,0.0,0.57798558,38.946369,3.3711042,525.97699,-9.2057648
5369,5369,212.6011,5.4580126,6.6011162,0.0,0,3.3538468,0.0,0.57941866,38.967037,3.3514619,526.37054,-9.2063694
5380,5380,212.6033,5.4666924,6.6168008,0.0,0,3.3343236,0.0,0.58223528,38.883152,3.3312213,526.7641,-9.2055464
5391,5391,212.6055,5.4735432,6.6391592,0.0,0,3.314801,0.0,0.58395284,38.865097,3.3105991,527.15771,-9.2049732
5402,5402,212.6077,5.4929113,6.6572475,0.0,0,3.2952783,0.0,0.58720845,38.860931,3.2947304,527.55127,-9.2051477
5413,5413,212.6099,5.5166526,6.6788836,0.0,0,3.2757552,0.0,0.5885399,39.01899,3.2755208,527.82556,-9.2055273
5424,5424,212.6121,5.5276957,6.6921787,0.0,0,3.2562327,0.0,0.59124899,38.946003,3.2538273,528.08795,-9.2055454
5435,5435,212.6143,5.5404592,6.7157884,0.0,0,3.2367096,0.0,0.59319597,38.996208,3.2355893,528.35034,-9.2058105
5446,5446,212.6165,5.5384302,6.7319255,0.0,0,3.2171869,0.0,0.59627855,38.876598,3.218051,528.61267,-9.2057209
5457,5457,212.6187,5.5674329,6.7541661,0.0,0,3.1976643,0.0,0.59771228,39.0019,3.1973159,528.87744,-9.2060823
5468,5468,212.6209,5.620965,6.7677164,0.0,0,3.1781414,0.0,0.6005044,39.222145,3.1778231,529.14636,-9.2038784
5479,5479,212.6231,5.6633239,6.7928753,0.0,0,3.1586185,0.0,0.60247111,39.478561,3.1539736,529.41534,-9.2044659
5490,5490,212.6253,5.6852493,6.8114367,0.0,0,3.1390958,0.0,0.60592496,39.506237,3.1405544,529.68427,-9.2057152
5501,5501,212.6275,5.7001896,6.8363681,0.0,0,3.1203775,0.0,0.60766,39.556103,3.1180696,529.95319,-9.205514
5512,5512,212.6297,5.6842971,6.8493204,0.0,0,3.101805,0.0,0.61063373,39.267372,3.0976605,530.1792,-9.2057486
5523,5523,212.6319,5.6293945,6.8731036,0.0,0,3.0832329,0.0,0.6123147,38.849083,3.0791626,530.39563,-9.2051725
5534,5534,212.6341,5.6236134,6.8882198,0.0,0,3.0646603,0.0,0.6152544,38.676228,3.0605836,530.61206,-9.2057037
5545,5545,212.6363,5.6508675,6.9108005,0.0,0,3.0460877,0.0,0.61676049,38.794544,3.0437984,530.82855,-9.2050247
5556,5556,212.6385,5.694376,6.9222121,0.0,0,3.0275152,0.0,0.61954725,39.003109,3.0270891,531.02533,-9.2056265
5567,5567,212.6407,5.72826,6.9464312,0.0,0,3.0089428,0.0,0.62152892,39.138386,3.0063283,531.16962,-9.2048054
5578,5578,212.6429,5.7543125,6.961185,0.0,0,2.9903708,0.0,0.62433469,39.185806,2.988152,531.31396,-9.2062988
5589,5589,212.6451,5.7852798,6.9872675,0.0,0,2.9717982,0.0,0.62611216,39.385063,2.9697967,531.45831,-9.2055616
5600,5600,212.6473,5.7942734,6.998075,0.0,0,2.9532259,0.0,0.6289981,39.363651,2.9487758,531.6026,-9.2050219
5611,5611,212.6495,5.807816,7.0225091,0.0,0,2.9346535,0.0,0.63079441,39.358196,2.9301128,531.71832,-9.2050228
5622,5622,212.6517,5.8173718,7.0375953,0.0,0,2.916081,0.0,0.63401091,39.311054,2.9131031,531.82324,-9.2052784
5633,5633,212.6539,5.8152995,7.0634465,0.0,0,2.8975084,0.0,0.63575107,39.246067,2.8920395,531.92822,-9.2059593
5644,5644,212.6561,5.8204079,7.0742359,0.0,0,2.8789363,0.0,0.63854998,39.12944,2.8750541,532.03314,-9.2052946
5655,5655,212.6583,5.8311033,7.0976315,0.0,0,2.860364,0.0,0.64037663,39.154064,2.8562489,532.13092,-9.2047758
5666,5666,212.6605,5.8393807,7.1114783,0.0,0,2.8417914,0.0,0.64322591,39.106934,2.838161,532.19653,-9.2049189
5677,5677,212.6627,5.8681407,7.1366124,0.0,0,2.8232191,0.0,0.64498699,39.18438,2.822062,532.26208,-9.2050695
5688,5688,212.6649,5.9043474,7.1467075,0.0,0,2.8046467,0.0,0.64769512,39.336136,2.8035595,532.3277,-9.2052383
5699,5699,212.6671,5.9456902,7.1696587,0.0,0,2.7860744,0.0,0.64952892,39.502029,2.7861588,532.39325,-9.204917
5710,5710,212.6693,5.9697304,7.1837401,0.0,0,2.7675018,0.0,0.65249729,39.6315,2.7702074,532.46722,-9.2062263
5721,5721,212.6715,6.0012889,7.2127042,0.0,0,2.7489293,0.0,0.65464449,39.697952,2.7490225,532.5459,-9.2072411
5732,5732,212.6737,6.0005183,7.2238789,0.0,0,2.7303569,0.0,0.65756333,39.581272,2.7299914,532.62463,-9.2070112
5743,5743,212.6759,6.0426288,7.2499003,0.0,0,2.7118933,0.0,0.65971953,39.756424,2.7080221,532.70337,-9.2062178
5754,5754,212.6781,6.0531421,7.2651396,0.0,0,2.694227,0.0,0.66294682,39.766998,2.683181,532.78088,-9.2065392
5765,5765,212.6803,6.0604181,7.2930694,0.0,0,2.6765609,0.0,0.66504174,39.687141,2.6696773,532.8465,-9.2074804
5776,5776,212.6825,6.0788865,7.302412,0.0,0,2.658895,0.0,0.66766912,39.677227,2.6484778,532.91211,-9.2055054
5787,5787,212.6847,6.0519357,7.3244152,0.0,0,2.6412292,0.0,0.66955268,39.423618,2.6330388,532.97766,-9.2067986
5798,5798,212.6869,6.0411639,7.3361297,0.0,0,2.6235631,0.0,0.67216057,39.269295,2.6170874,533.04327,-9.2072792
5809,5809,212.6891,6.0056119,7.3627062,0.0,0,2.6058969,0.0,0.67420506,38.969055,2.6012659,533.0874,-9.2052164
5820,5820,212.6913,5.9880896,7.369966,0.0,0,2.5882311,0.0,0.67649508,38.772961,2.5849993,533.11365,-9.2056847
5831,5831,212.6935,5.9999585,7.3893414,0.0,0,2.570565,0.0,0.67808396,38.746769,2.5647802,533.13989,-9.2047834
5842,5842,212.6957,6.054183,7.4021525,0.0,0,2.5528989,0.0,0.68082702,38.976803,2.5485268,533.16614,-9.2054787
5853,5853,212.6979,6.1084614,7.4269805,0.0,0,2.535233,0.0,0.68253517,39.290306,2.5336747,533.19238,-9.2071648
5864,5864,212.7001,6.1402092,7.43606,0.0,0,2.5175669,0.0,0.68519741,39.399803,2.5160432,533.17926,-9.2064886
5875,5875,212.7023,6.1938996,7.4590254,0.0,0,2.4999011,0.0,0.68725008,39.629452,2.4961228,533.16614,-9.2064848
5886,5886,212.7045,6.2399421,7.4722776,0.0,0,2.482235,0.0,0.69013178,39.821411,2.4794915,533.15302,-9.2049646
5897,5897,212.7067,6.2597303,7.5014224,0.0,0,2.4645689,0.0,0.69255936,39.905655,2.4651139,533.13983,-9.2052145
5908,5908,212.7089,6.2720594,7.5097694,0.0,0,2.446903,0.0,0.69493032,39.865704,2.4444478,533.11481,-9.2070112
5919,5919,212.7111,6.2902665,7.5323119,0.0,0,2.4292369,0.0,0.69696534,39.911674,2.4217694,533.07544,-9.2060633
5930,5930,212.7133,6.3303843,7.5441761,0.0,0,2.411571,0.0,0.6997034,40.02182,2.4021652,533.03613,-9.2055368
5941,5941,212.7155,6.3359222,7.5743074,0.0,0,2.3939049,0.0,0.70238888,39.977566,2.3854179,532.99677,-9.2059698
5952,5952,212.7177,6.3650107,7.5833521,0.0,0,2.3762391,0.0,0.70483822,40.048862,2.37093,532.95746,-9.2068539
5963,5963,212.7199,6.3735995,7.6060662,0.0,0,2.358573,0.0,0.7069568,40.008438,2.3466439,532.84058,-9.2061272
5974,5974,212.7221,6.3577981,7.6188064,0.0,0,2.3409069,0.0,0.70957738,39.849419,2.3318751,532.71594,-9.2052536
5985,5985,212.7243,6.3825293,7.6464887,0.0,0,2.323241,0.0,0.71216136,39.849789,2.3121991,532.59131,-9.2034159
5996,5996,212.7265,6.3712659,7.6561332,0.0,0,2.3059127,0.0,0.7145437,39.73262,2.2997954,532.46661,-9.2055693
6007,6007,212.7287,6.3694205,7.6747537,0.0,0,2.2891092,0.0,0.71632147,39.627369,2.2815988,532.33484,-9.2069798
6018,6018,212.7309,6.3879247,7.6860929,0.0,0,2.2723055,0.0,0.71870947,39.616604,2.2671869,532.19055,-9.2060623
6029,6029,212.7331,6.4033141,7.7122335,0.0,0,2.255502,0.0,0.72131103,39.665356,2.2501638,532.04626,-9.2044182
6040,6040,212.7353,6.4545574,7.7240329,0.0,0,2.2386985,0.0,0.72379923,39.827103,2.2336104,531.90192,-9.2043343
6051,6051,212.7375,6.4669662,7.7431192,0.0,0,2.221895,0.0,0.72569007,39.80368,2.2146215,531.75763,-9.205102
6062,6062,212.7397,6.48351,7.7535233,0.0,0,2.2050912,0.0,0.72805393,39.909222,2.1979148,531.63477,-9.2056341
6073,6073,212.7419,6.5173683,7.7816539,0.0,0,2.1882877,0.0,0.73088896,39.939655,2.1804254,531.51672,-9.2047091
6084,6084,212.7441,6.5436621,7.7913208,0.0,0,2.171484,0.0,0.73304152,40.058651,2.1642792,531.39862,-9.2048378
6095,6095,212.7463,6.5520501,7.8104091,0.0,0,2.1546805,0.0,0.73499244,39.987282,2.1493704,531.28058,-9.2056007
6106,6106,212.7485,6.5791664,7.8220687,0.0,0,2.1378767,0.0,0.7372911,40.028111,2.1268516,531.15717,-9.2044487
6117,6117,212.7507,6.5925646,7.8507686,0.0,0,2.1210732,0.0,0.74042559,39.998009,2.1138258,531.01941,-9.204402
6128,6128,212.7529,6.5984454,7.8601375,0.0,0,2.1042697,0.0,0.74262899,39.985001,2.0979259,530.88165,-9.2050581
6139,6139,212.7551,6.6192775,7.8784204,0.0,0,2.087466,0.0,0.74461347,40.037033,2.084084,530.7439,-9.204833
6150,6150,212.7573,6.6423836,7.8896651,0.0,0,2.0706627,0.0,0.74674749,40.057388,2.0649483,530.60614,-9.2056007
6161,6161,212.7595,6.6483192,7.9132042,0.0,0,2.053859,0.0,0.74936277,40.025219,2.0480263,530.39209,-9.2053261
6172,6172,212.7617,6.6729407,7.9245858,0.0,0,2.0370555,0.0,0.75167167,40.09444,2.0308766,530.14941,-9.2047987
6183,6183,212.7639,6.6951022,7.9450846,0.0,0,2.0202518,0.0,0.75409007,40.09782,2.014215,529.90668,-9.2055454
6194,6194,212.7661,6.7360969,7.9575548,0.0,0,2.0034482,0.0,0.7561118,40.284172,1.9969817,529.664,-9.2058792
6205,6205,212.7683,6.7697177,7.98035,0.0,0,1.9866445,0.0,0.75900179,40.370289,1.9797293,529.41412,-9.204463
6216,6216,212.7705,6.806191,7.9906707,0.0,0,1.969841,0.0,0.76105869,40.470051,1.9640812,529.13208,-9.2051735
6227,6227,212.7727,6.7889786,8.0106087,0.0,0,1.9530374,0.0,0.76347303,40.2244,1.9482732,528.85004,-9.204463
6238,6238,212.7749,6.7809811,8.0231361,0.0,0,1.9362339,0.0,0.7656036,40.180439,1.9323249,528.56799,-9.2050104
6249,6249,212.7771,6.8145785,8.0472717,0.0,0,1.9199743,0.0,0.76860744,40.189358,1.9183975,528.28589,-9.2049541
6260,6260,212.7793,6.8119287,8.0565529,0.0,0,1.9039891,0.0,0.77029181,40.158028,1.9005275,528.07898,-9.2042751
6271,6271,212.7815,6.858613,8.073946,0.0,0,1.8880038,0.0,0.77276051,40.329403,1.8818146,527.91504,-9.2042484
6282,6282,212.7837,6.9272261,8.0884542,0.0,0,1.8720186,0.0,0.77487761,40.623962,1.8662947,527.75104,-9.2049694
6293,6293,212.7859,6.9665055,8.1136131,0.0,0,1.8560333,0.0,0.77823842,40.739227,1.8523018,527.58704,-9.2047939
6304,6304,212.7881,6.9703689,8.1242428,0.0,0,1.8400483,0.0,0.78009123,40.680363,1.8381972,527.44159,-9.2050276
6315,6315,212.7903,7.0005198,8.1412868,0.0,0,1.8240631,0.0,0.78257686,40.744701,1.8172288,527.4809,-9.2042198
6326,6326,212.7925,7.0361152,8.1562157,0.0,0,1.8080778,0.0,0.78460544,40.875854,1.8009537,527.52026,-9.2039785
6337,6337,212.7947,7.0664916,8.1788559,0.0,0,1.7920926,0.0,0.78802818,40.904964,1.7832741,527.55957,-9.2060747
6348,6348,212.7969,7.0807896,8.1902189,0.0,0,1.7761074,0.0,0.78971589,40.914909,1.7679677,527.59894,-9.2057562
6359,6359,212.7991,7.0616431,8.2084694,0.0,0,1.7601223,0.0,0.79242283,40.708038,1.7516446,527.66333,-9.2050295
6370,6370,212.8013,7.0800104,8.2205372,0.0,0,1.744137,0.0,0.79407269,40.773697,1.7322978,527.7486,-9.2055874
6381,6381,212.8035,7.1084862,8.2429714,0.0,0,1.7281518,0.0,0.79746258,40.741741,1.7202126,527.83386,-9.2049484
6392,6392,212.8057,7.1095781,8.2564135,0.0,0,1.7121667,0.0,0.79931033,40.719597,1.7044443,527.91913,-9.204833
6403,6403,212.8079,7.1202421,8.2709818,0.0,0,1.6961814,0.0,0.80175596,40.642826,1.6875271,528.00439,-9.2036314
6414,6414,212.8101,7.1659484,8.2845583,0.0,0,1.6801963,0.0,0.80360943,40.825886,1.6760792,527.87323,-9.2046003
6425,6425,212.8123,7.198946,8.3078613,0.0,0,1.6642109,0.0,0.80722618,40.829529,1.6609263,527.74207,-9.2046633
6436,6436,212.8145,7.2560205,8.3188562,0.0,0,1.6482258,0.0,0.80846488,41.180145,1.6431442,527.61084,-9.2033749
6447,6447,212.8167,7.3126402,8.3333988,0.0,0,1.6322405,0.0,0.81117505,41.359066,1.6256591,527.47968,-9.2048349
6458,6458,212.8189,7.3282104,8.3484421,0.0,0,1.6162554,0.0,0.81289703,41.392544,1.6098847,527.30377,-9.2055387
6469,6469,212.8211,7.3597355,8.3714705,0.0,0,1.6002703,0.0,0.81686682,41.405499,1.594712,527.07422,-9.2058077
6480,6480,212.8233,7.3788848,8.3858089,0.0,0,1.5842849,0.0,0.81858027,41.468155,1.5783027,526.84467,-9.2056513
6491,6491,212.8255,7.4156375,8.4027233,0.0,0,1.5682998,0.0,0.82154477,41.523014,1.5587761,526.61505,-9.2041492
6502,6502,212.8277,7.4457016,8.4183865,0.0,0,1.5530447,0.0,0.82351279,41.590214,1.540637,526.3855,-9.2048044
6513,6513,212.8299,7.4235458,8.4371185,0.0,0,1.5378383,0.0,0.82691276,41.333736,1.5244607,526.29309,-9.2054472
6524,6524,212.8321,7.4217658,8.4521828,0.0,0,1.5226319,0.0,0.82844883,41.231194,1.5115763,526.21436,-9.2057085
6535,6535,212.8343,7.4241939,8.4654245,0.0,0,1.5074254,0.0,0.83120245,41.156025,1.4948819,526.13562,-9.2051477
6546,6546,212.8365,7.4201274,8.4789,0.0,0,1.4922191,0.0,0.83269322,41.107391,1.4840623,526.05695,-9.2042332
6557,6557,212.8387,7.4324188,8.4969578,0.0,0,1.4770126,0.0,0.83620065,41.012894,1.4685103,526.0426,-9.2052393
6568,6568,212.8409,7.4410172,8.5102692,0.0,0,1.4618063,0.0,0.83741212,41.013077,1.4555838,526.14099,-9.2048798
6579,6579,212.8431,7.4996281,8.5225058,0.0,0,1.4465998,0.0,0.84001118,41.200298,1.4384112,526.23944,-9.2049685
6590,6590,212.8453,7.5438762,8.5379009,0.0,0,1.4313934,0.0,0.84157324,41.351093,1.4208565,526.33783,-9.2055292
6601,6601,212.8475,7.5976791,8.557229,0.0,0,1.4161872,0.0,0.84548849,41.508812,1.4092487,526.43622,-9.2052555
6612,6612,212.8497,7.6474051,8.5707035,0.0,0,1.4009807,0.0,0.84660774,41.749886,1.3888497,526.6795,-9.2040815
6623,6623,212.8519,7.6861033,8.5828657,0.0,0,1.3857744,0.0,0.84942132,41.821632,1.376865,526.95496,-9.2052212
6634,6634,212.8541,7.6710916,8.5980339,0.0,0,1.3705679,0.0,0.85097861,41.745831,1.3630388,527.23047,-9.2049637
6645,6645,212.8563,7.6913719,8.6154957,0.0,0,1.3553615,0.0,0.85458773,41.702877,1.3464128,527.50592,-9.20471
6656,6656,212.8585,7.7075853,8.6316557,0.0,0,1.3401551,0.0,0.85595739,41.677643,1.3323352,527.78503,-9.2048998
6667,6667,212.8607,7.7430201,8.6445084,0.0,0,1.3249488,0.0,0.85930318,41.769848,1.3156971,528.07361,-9.2049818
6678,6678,212.8629,7.7947102,8.6602325,0.0,0,1.3097425,0.0,0.86055982,41.948593,1.3021519,528.36224,-9.2061329
6689,6689,212.8651,7.8301344,8.6773052,0.0,0,1.2945359,0.0,0.86465853,42.016197,1.2891028,528.65088,-9.206049
6700,6700,212.8673,7.8862023,8.6943207,0.0,0,1.2793295,0.0,0.86587566,42.229481,1.2720274,528.93945,-9.2065411
6711,6711,212.8695,7.9342909,8.706831,0.0,0,1.2641231,0.0,0.86910367,42.346977,1.2542498,529.11359,-9.2059631
6722,6722,212.8717,7.9655809,8.722106,0.0,0,1.2489167,0.0,0.87030876,42.463097,1.2352971,529.24481,-9.20578
6733,6733,212.8739,7.9746876,8.7376261,0.0,0,1.2337103,0.0,0.8742559,42.371746,1.2236344,529.37598,-9.2046471
6744,6744,212.8761,7.9693875,8.755106,0.0,0,1.2186602,0.0,0.87551993,42.272202,1.210565,529.50714,-9.204423
6755,6755,212.8783,7.9758167,8.7666883,0.0,0,1.2041974,0.0,0.87867206,42.172012,1.1950059,529.6145,-9.2052584
6766,6766,212.8805,7.9951525,8.781209,0.0,0,1.1897346,0.0,0.87978333,42.23703,1.1789088,529.6145,-9.2049894
6777,6777,212.8827,8.0592718,8.7968636,0.0,0,1.1752717,0.0,0.88383275,42.372517,1.1646079,529.6145,-9.2061558
6788,6788,212.8849,8.0798607,8.8140697,0.0,0,1.160809,0.0,0.88503391,42.426449,1.1486174,529.6145,-9.2049999
6799,6799,212.8871,8.1286001,8.8236103,0.0,0,1.1463462,0.0,0.88795185,42.534607,1.1339686,529.6145,-9.2052765
6810,6810,212.8893,8.1659727,8.8410769,0.0,0,1.1318834,0.0,0.88946843,42.69582,1.1223649,529.68549,-9.2060251
6821,6821,212.8915,8.1955576,8.8595552,0.0,0,1.1174206,0.0,0.89392209,42.684586,1.1073425,529.79694,-9.2052498
6832,6832,212.8937,8.1800709,8.875185,0.0,0,1.1029578,0.0,0.8949905,42.56525,1.094148,529.90845,-9.2049465
6843,6843,212.8959,8.1711664,8.8844662,0.0,0,1.0884949,0.0,0.89780217,42.442863,1.0800977,530.01996,-9.2049217
6854,6854,212.8981,8.1746292,8.8992367,0.0,0,1.0740322,0.0,0.89880294,42.363277,1.0656036,530.12195,-9.2065401
6865,6865,212.9003,8.2025194,8.9105101,0.0,0,1.0595694,0.0,0.90228897,42.360008,1.0532349,530.12848,-9.2060175
6876,6876,212.9025,8.2399197,8.9290438,0.0,0,1.0451066,0.0,0.90368295,42.479351,1.0385826,530.13501,-9.2054834
6887,6887,212.9047,8.2856789,8.9385815,0.0,0,1.0306438,0.0,0.90698022,42.561756,1.0220201,530.1416,-9.2043037
6898,6898,212.9069,8.330081,8.9567242,0.0,0,1.016181,0.0,0.90818506,42.760826,1.0083095,530.14813,-9.2050905
6909,6909,212.9091,8.3820343,8.9664736,0.0,0,1.0017182,0.0,0.91167969,42.916466,0.99387258,529.99725,-9.2050991
6920,6920,212.9113,8.4223413,8.9836349,0.0,0,0.98725533,0.0,0.91265994,43.063805,0.9830128,529.71521,-9.2047167
6931,6931,212.9135,8.4641685,8.9930086,0.0,0,0.97279257,0.0,0.91606134,43.141727,0.96850371,529.43317,-9.2054472
6942,6942,212.9157,8.4952841,9.0123749,0.0,0,0.95832974,0.0,0.9174614,43.219707,0.95280135,529.15112,-9.2051716
6953,6953,212.9179,8.5441484,9.0254307,0.0,0,0.94386703,0.0,0.92153645,43.253647,0.93532199,528.86908,-9.2046967
6964,6964,212.9201,8.605051,9.0477657,0.0,0,0.9294042,0.0,0.92306197,43.511978,0.92323053,528.69855,-9.204423
6975,6975,212.9223,8.6739407,9.0534868,0.0,0,0.91494137,0.0,0.92614836,43.738201,0.90578693,528.52802,-9.2049313
6986,6986,212.9245,8.7253637,9.0702515,0.0,0,0.90047854,0.0,0.92722225,43.977131,0.89308381,528.35742,-9.2053432
6997,6997,212.9267,8.7469101,9.0847263,0.0,0,0.8863579,0.0,0.93136042,43.863522,0.87778121,528.18689,-9.2052851
7008,7008,212.9289,8.7430582,9.1054201,0.0,0,0.87260348,0.0,0.93278509,43.822857,0.85967737,528.00146,-9.2043848
7019,7019,212.9311,8.7282467,9.1114807,0.0,0,0.85884905,0.0,0.93597603,43.604095,0.84480089,527.7981,-9.2049389
7030,7030,212.9333,8.6765213,9.1276197,0.0,0,0.84509468,0.0,0.93692213,43.344116,0.83512437,527.59479,-9.2047014
7041,7041,212.9355,8.6630058,9.1405258,0.0,0,0.83134025,0.0,0.9409889,43.005604,0.82036358,527.39142,-9.2055769
7052,7052,212.9377,8.7078524,9.1589766,0.0,0,0.81758583,0.0,0.94196945,43.241604,0.80573219,527.18811,-9.2047272
7063,7063,212.9399,8.7617044,9.1622486,0.0,0,0.80383146,0.0,0.94460416,43.380856,0.79312497,527.09808,-9.2044554
7074,7074,212.9421,8.8201551,9.1803751,0.0,0,0.79007703,0.0,0.94596982,43.602638,0.78170538,527.01935,-9.20502
7085,7085,212.9443,8.8623953,9.1894045,0.0,0,0.77632266,0.0,0.94941604,43.674889,0.76650107,526.94067,-9.2043486
7096,7096,212.9465,8.9035368,9.2088366,0.0,0,0.76256824,0.0,0.95044404,43.820148,0.75487214,526.862,-9.2046547
7107,7107,212.9487,8.9489956,9.2130175,0.0,0,0.74881387,0.0,0.95353526,43.891636,0.7398988,526.72839,-9.2048302
7118,7118,212.9509,8.9673128,9.2325478,0.0,0,0.73505944,0.0,0.95502532,43.94865,0.7275846,526.49884,-9.2049818
7129,7129,212.9531,8.9892435,9.2416716,0.0,0,0.72130501,0.0,0.95859426,43.918034,0.71326482,526.26923,-9.2058382
7140,7140,212.9553,9.0491533,9.2630301,0.0,0,0.70755064,0.0,0.95986193,44.112949,0.70238239,526.03967,-9.2056875
7151,7151,212.9575,9.1189547,9.2685261,0.0,0,0.69379628,0.0,0.96302646,44.312527,0.68619597,525.81006,-9.2047977
7162,7162,212.9597,9.2252903,9.2895241,0.0,0,0.68004191,0.0,0.96497399,44.729103,0.67054677,525.45703,-9.2051115
7173,7173,212.9619,9.271369,9.299592,0.0,0,0.66628748,0.0,0.96839923,44.799541,0.65683377,525.0766,-9.2043905
7184,7184,212.9641,9.2757835,9.3190279,0.0,0,0.65253305,0.0,0.96965361,44.736015,0.64279044,524.69617,-9.2047672
7195,7195,212.9663,9.2483921,9.3243189,0.0,0,0.63877869,0.0,0.97284311,44.482285,0.63099825,524.31567,-9.2056665
7206,7206,212.9685,9.2530184,9.3423109,0.0,0,0.62502432,0.0,0.97423923,44.504009,0.61678195,524.0354,-9.2052069
7217,7217,212.9707,9.2514782,9.3521156,0.0,0,0.61126989,0.0,0.97769707,44.349358,0.6035791,524.02228,-9.2059908
7228,7228,212.9729,9.2571316,9.3728123,0.0,0,0.59751546,0.0,0.97927856,44.280235,0.59269303,524.00922,-9.2050009
7239,7239,212.9751,9.2733259,9.3739767,0.0,0,0.5837611,0.0,0.98165548,44.247417,0.57726353,523.99609,-9.2046614
7242,7242,212.9757,9.3396931,9.3791628,0.0,0,0.58003461,0.0,0.98222256,44.530762,0.57372236,523.99249,-9.203661