File: clean data/testID_0230.csv
level_0,index,Time(sec),Force(kN),Jaw(mm),PowAngle(deg),Power(W),Pram,PTemp,Strain,Stress(MPa),Stroke(mm),TC1(C),wedge(mm)
2276,2276,195.3489,0.54874051,0.0053866408,0.0,0,8.9459143,0.0,0.00023155288,6.5806022,9.9182167,450.00241,-9.2346544
2277,2277,195.3491,1.0212288,0.020731632,0.0,0,8.9166508,0.0,0.0012975411,11.471716,9.8735771,449.99884,-9.2349386
2278,2278,195.3493,1.8358886,0.057858407,0.0,0,8.8873863,0.0,0.0032567638,21.018831,9.8401127,449.99524,-9.2348022
2279,2279,195.3495,2.7806602,0.087662861,0.0,0,8.8581219,0.0,0.0053825402,32.759365,9.8119717,449.97308,-9.2341862
2280,2280,195.3497,3.6373641,0.1130466,0.0,0,8.8288584,0.0,0.0074659991,43.927387,9.7822952,449.95093,-9.2337713
2281,2281,195.3499,4.1533604,0.14234845,0.0,0,8.7995939,0.0,0.0090033496,51.307453,9.744669,449.92877,-9.2333498
2282,2282,195.3501,4.3197784,0.18479869,0.0,0,8.7703304,0.0,0.011513222,54.117611,9.7013426,449.90662,-9.2323132
2283,2283,195.3503,4.2392235,0.26261896,0.0,0,8.7416534,0.0,0.016728139,53.396709,9.6534472,449.88446,-9.2315044
2284,2284,195.3505,4.1421537,0.35002565,0.0,0,8.7136879,0.0,0.022497011,51.846153,9.6015778,449.8623,-9.2312737
2285,2285,195.3507,4.1842084,0.40115941,0.0,0,8.6858492,0.0,0.026354766,51.773403,9.5468283,449.84015,-9.2311268
2286,2286,195.3509,4.2721691,0.43427509,0.0,0,8.6580172,0.0,0.029086869,52.670231,9.4889488,449.81799,-9.231122
2287,2287,195.3511,4.2449284,0.48149738,0.0,0,8.6301851,0.0,0.031939518,52.502041,9.435813,449.79584,-9.2312641
2288,2288,195.3513,4.1882186,0.5406056,0.0,0,8.6023531,0.0,0.035602264,51.446758,9.3851223,449.77368,-9.2313604
2289,2289,195.3515,4.3924699,0.59605843,0.0,0,8.574522,0.0,0.039989531,52.950058,9.3389015,449.75153,-9.2315226
2290,2290,195.3517,4.7484641,0.62309515,0.0,0,8.546689,0.0,0.042341303,57.155869,9.2963161,449.72934,-9.2312899
2291,2291,195.3519,4.8138218,0.61973161,0.0,0,8.518857,0.0,0.042061202,58.911213,9.2533455,449.70718,-9.2309914
2292,2292,195.3521,4.525476,0.62668955,0.0,0,8.4910259,0.0,0.042550426,56.099079,9.2135849,449.68503,-9.2312813
2293,2293,195.3523,4.1979051,0.66727585,0.0,0,8.4631929,0.0,0.044972017,51.7897,9.176755,449.66287,-9.2321692
2294,2294,195.3525,4.1187768,0.71698821,0.0,0,8.4353609,0.0,0.048066415,49.943485,9.1443205,449.64072,-9.2328014
2295,2295,195.3527,4.3180842,0.74959624,0.0,0,8.4075298,0.0,0.050929256,51.684261,9.1133165,449.61856,-9.2328415
2296,2296,195.3529,4.5825372,0.76255089,0.0,0,8.3796968,0.0,0.052250639,54.865196,9.0819082,449.59641,-9.2333784
2297,2297,195.3531,4.804462,0.77745831,0.0,0,8.3518648,0.0,0.052795712,57.595207,9.0486259,449.57425,-9.2329798
2298,2298,195.3533,4.9390054,0.81924224,0.0,0,8.3240337,0.0,0.055436566,59.213917,9.012557,449.55209,-9.2317257
2299,2299,195.3535,4.9059305,0.88128811,0.0,0,8.2962017,0.0,0.059845123,59.02084,8.9745111,449.52994,-9.2313442
2300,2300,195.3537,4.7445564,0.93702358,0.0,0,8.2683697,0.0,0.063688211,57.080067,8.93503,449.50778,-9.2305508
2301,2301,195.3539,4.6274147,0.97183841,0.0,0,8.2405376,0.0,0.066546492,55.332031,8.8965645,449.48563,-9.2298136
2302,2302,195.3541,4.593082,0.99649358,0.0,0,8.2127056,0.0,0.0686123,54.663544,8.8595686,449.46347,-9.2309284
2303,2303,195.3543,4.5815272,1.0351982,0.0,0,8.1848736,0.0,0.07075581,54.381676,8.8197765,449.44131,-9.2316637
2304,2304,195.3545,4.5769348,1.0857284,0.0,0,8.1570415,0.0,0.074210756,54.086292,8.7789354,449.41916,-9.2315531
2305,2305,195.3547,4.5907216,1.1272036,0.0,0,8.1292095,0.0,0.077787489,53.932858,8.7412195,449.397,-9.2318363
2306,2306,195.3549,4.740242,1.1540695,0.0,0,8.1013775,0.0,0.079737581,55.302452,8.7074404,449.37485,-9.2316189
2307,2307,195.3551,4.9508581,1.1680295,0.0,0,8.0735455,0.0,0.080702908,57.715645,8.6752224,449.35269,-9.2309952
2308,2308,195.3553,4.9852157,1.1846313,0.0,0,8.0462685,0.0,0.082126625,58.542065,8.644165,449.33054,-9.2309036
2309,2309,195.3555,4.8359056,1.2231147,0.0,0,8.0196619,0.0,0.084496632,57.055943,8.614912,449.30838,-9.2306643
2310,2310,195.3557,4.6772165,1.2641605,0.0,0,7.993176,0.0,0.087282598,54.933659,8.5869503,449.28622,-9.2306004
2311,2311,195.3559,4.6605954,1.2848792,0.0,0,7.9666953,0.0,0.089466482,54.241436,8.5586538,449.26407,-9.2311783
2312,2312,195.3561,4.7847867,1.3030447,0.0,0,7.9402156,0.0,0.090742238,55.328453,8.5310545,449.24191,-9.2319469
2313,2313,195.3563,4.9522982,1.3294671,0.0,0,7.9137359,0.0,0.092094302,57.121925,8.5045252,449.21976,-9.2325211
2314,2314,195.3565,5.0794663,1.3590627,0.0,0,7.8872557,0.0,0.094487809,58.616249,8.4759722,449.1976,-9.2318783
2315,2315,195.3567,5.1061044,1.4010562,0.0,0,7.8607755,0.0,0.097492807,59.026985,8.4474335,449.17542,-9.2307291
2316,2316,195.3569,5.0314779,1.4410067,0.0,0,7.8342957,0.0,0.10015541,58.141483,8.4171362,449.15326,-9.2304802
2317,2317,195.3571,4.9418831,1.4627047,0.0,0,7.8078156,0.0,0.10230929,56.964626,8.3833799,449.1311,-9.2298794
2318,2318,195.3573,4.9159265,1.4918088,0.0,0,7.7813354,0.0,0.10449078,56.397503,8.3522606,449.10895,-9.2293196
2319,2319,195.3575,4.9337826,1.5315189,0.0,0,7.7548552,0.0,0.10685338,56.413193,8.3235607,449.08679,-9.2302608
2320,2320,195.3577,4.9088197,1.5576971,0.0,0,7.7283754,0.0,0.10922372,56.129642,8.290823,449.06464,-9.2303314
2321,2321,195.3579,4.8614578,1.5785599,0.0,0,7.7018952,0.0,0.11118327,55.412907,8.2625132,449.04248,-9.2305193
2322,2322,195.3581,4.9002347,1.5949579,0.0,0,7.675415,0.0,0.11200209,55.562622,8.2373257,449.02032,-9.230689
2323,2323,195.3583,5.006093,1.602357,0.0,0,7.6489348,0.0,0.1126548,56.663017,8.2099514,448.99817,-9.2307119
2324,2324,195.3585,5.0549979,1.6286252,0.0,0,7.6224551,0.0,0.11471702,57.338966,8.1853323,448.97601,-9.2312536
2325,2325,195.3587,4.9901524,1.6657857,0.0,0,7.5959754,0.0,0.11706553,56.728481,8.1610327,448.95386,-9.2305355
2326,2326,195.3589,4.9110427,1.6849581,0.0,0,7.5694952,0.0,0.11874322,55.65213,8.1359081,448.9317,-9.2292252
2327,2327,195.3591,4.9390454,1.6992809,0.0,0,7.543015,0.0,0.1202862,55.582413,8.1139488,448.90955,-9.2291155
2328,2328,195.3593,5.0556526,1.7173405,0.0,0,7.5165353,0.0,0.12125641,56.696259,8.0940075,448.88739,-9.2296419
2329,2329,195.3595,5.1518655,1.7348677,0.0,0,7.4900556,0.0,0.12240373,57.814865,8.0711718,448.86163,-9.2297153
2330,2330,195.3597,5.1693063,1.7653382,0.0,0,7.4635754,0.0,0.1249575,58.081524,8.0450354,448.83588,-9.229763
2331,2331,195.3599,5.15273,1.8006916,0.0,0,7.4370952,0.0,0.12739129,57.766891,8.0198727,448.81015,-9.230032
2332,2332,195.3601,5.1700721,1.8203179,0.0,0,7.410615,0.0,0.12882411,57.76693,7.9948497,448.78439,-9.2300005
2333,2333,195.3603,5.1810989,1.8399862,0.0,0,7.3846664,0.0,0.1307517,57.866215,7.9688787,448.75864,-9.2294645
2334,2334,195.3605,5.1246066,1.8719224,0.0,0,7.3593612,0.0,0.13294359,57.246208,7.9437218,448.73288,-9.2294416
2335,2335,195.3607,5.0516543,1.9015886,0.0,0,7.3341722,0.0,0.13485388,56.318356,7.9188685,448.70712,-9.2297297
2336,2336,195.3609,5.0483074,1.9290707,0.0,0,7.3089881,0.0,0.13739245,55.9659,7.8938375,448.6814,-9.2297544
2337,2337,195.3611,5.1238866,1.9529721,0.0,0,7.2838039,0.0,0.13933946,56.489311,7.8701224,448.65564,-9.2290831
2338,2338,195.3613,5.207479,1.9651753,0.0,0,7.2586198,0.0,0.14003775,57.417572,7.8467975,448.62988,-9.2290421
2339,2339,195.3615,5.2306452,1.9815675,0.0,0,7.2334356,0.0,0.14149141,57.82729,7.8244548,448.60413,-9.2297573
2340,2340,195.3617,5.1894011,2.0085442,0.0,0,7.2082515,0.0,0.1435363,57.421825,7.8011379,448.57837,-9.2304964
2341,2341,195.3619,5.135685,2.0335741,0.0,0,7.1830673,0.0,0.14511141,56.717896,7.7781377,448.55264,-9.2306128
2342,2342,195.3621,5.1170583,2.0539477,0.0,0,7.1578832,0.0,0.14697932,56.293201,7.7567835,448.52689,-9.2303886
2343,2343,195.3623,5.1568837,2.0715024,0.0,0,7.1326995,0.0,0.14862835,56.504257,7.7355833,448.50113,-9.2302876
2344,2344,195.3625,5.2232013,2.0902104,0.0,0,7.1075153,0.0,0.14963204,57.074791,7.7150631,448.47537,-9.2305441
2345,2345,195.3627,5.2625604,2.1138937,0.0,0,7.0823312,0.0,0.15142965,57.513477,7.6934628,448.44962,-9.2319288
2346,2346,195.3629,5.296452,2.1398938,0.0,0,7.0571475,0.0,0.15375157,57.755711,7.6702738,448.42389,-9.2314491
2347,2347,195.3631,5.342422,2.165149,0.0,0,7.0319633,0.0,0.1554127,58.167633,7.6470246,448.39813,-9.2300129
2348,2348,195.3633,5.37393,2.1877549,0.0,0,7.0067792,0.0,0.15714361,58.486866,7.6256261,448.37238,-9.2297955
2349,2349,195.3635,5.357307,2.2091346,0.0,0,6.981595,0.0,0.15920216,58.219963,7.5995002,448.34662,-9.2297688
2350,2350,195.3637,5.2945113,2.2378333,0.0,0,6.9564114,0.0,0.16099161,57.512817,7.5737376,448.32086,-9.2297211
2351,2351,195.3639,5.244256,2.2651923,0.0,0,6.9312277,0.0,0.16303274,56.804825,7.5537,448.29514,-9.2300243
2352,2352,195.3641,5.2492585,2.2826409,0.0,0,6.9060431,0.0,0.16512387,56.62439,7.5335355,448.26938,-9.2298822
2353,2353,195.3643,5.3014159,2.3033667,0.0,0,6.8808594,0.0,0.16645041,57.042847,7.5099277,448.24362,-9.2297754
2354,2354,195.3645,5.3658724,2.3242283,0.0,0,6.8556757,0.0,0.16775744,57.613052,7.4859114,448.21786,-9.2311525
2355,2355,195.3647,5.4095039,2.3421776,0.0,0,6.830492,0.0,0.16967781,58.014927,7.4622726,448.19211,-9.23174
2356,2356,195.3649,5.4177027,2.3705323,0.0,0,6.8053074,0.0,0.17166236,58.095371,7.4395614,448.16638,-9.2312899
2357,2357,195.3651,5.4050536,2.3964722,0.0,0,6.7801232,0.0,0.17343499,57.89933,7.4181886,448.14063,-9.2317486
2358,2358,195.3653,5.3856525,2.4086323,0.0,0,6.7554417,0.0,0.17498814,57.648094,7.3985996,448.11487,-9.2317667
2359,2359,195.3655,5.3869324,2.4293003,0.0,0,6.7313671,0.0,0.17642793,57.527733,7.3766499,448.08911,-9.2312288
2360,2360,195.3657,5.4182053,2.4555442,0.0,0,6.7074022,0.0,0.17797561,57.679844,7.3535485,448.06335,-9.231205
2361,2361,195.3659,5.4531288,2.4732394,0.0,0,6.6834416,0.0,0.17990789,57.912151,7.3322687,448.03763,-9.2305317
2362,2362,195.3661,5.4740448,2.4989183,0.0,0,6.6594815,0.0,0.18206295,58.114529,7.3100753,448.01187,-9.2297554
2363,2363,195.3663,5.496326,2.5263205,0.0,0,6.6355219,0.0,0.18369317,58.230255,7.2862158,447.98611,-9.2297201
2364,2364,195.3665,5.5257564,2.5398901,0.0,0,6.6115613,0.0,0.18519473,58.317642,7.2630324,447.96036,-9.2302437
2365,2365,195.3667,5.5416737,2.5639453,0.0,0,6.5876017,0.0,0.18727757,58.484394,7.2395892,447.9346,-9.2305479
2366,2366,195.3669,5.5384102,2.5967724,0.0,0,6.5636415,0.0,0.1893335,58.426907,7.2169733,447.90887,-9.2304583
2367,2367,195.3671,5.5268579,2.6156006,0.0,0,6.5396819,0.0,0.19119097,58.166454,7.1935749,447.88312,-9.2308826
2368,2368,195.3673,5.535634,2.6367936,0.0,0,6.5157218,0.0,0.19324428,58.075409,7.1689506,447.85736,-9.231144
2369,2369,195.3675,5.5676947,2.6604643,0.0,0,6.4917622,0.0,0.19477032,58.2617,7.1454778,447.8316,-9.2311907
2370,2370,195.3677,5.6089406,2.6739392,0.0,0,6.467802,0.0,0.19606489,58.605442,7.1221919,447.80585,-9.2318201
2371,2371,195.3679,5.6394653,2.6987987,0.0,0,6.4438419,0.0,0.19829205,58.85006,7.0994954,447.78012,-9.2318726
2372,2372,195.3681,5.6433568,2.730782,0.0,0,6.4198818,0.0,0.20036304,58.794113,7.076313,447.75436,-9.2311001
2373,2373,195.3683,5.6371155,2.7474382,0.0,0,6.3959212,0.0,0.20186318,58.585209,7.0547953,447.72861,-9.2304592
2374,2374,195.3685,5.6497111,2.7668784,0.0,0,6.3719616,0.0,0.20388697,58.559906,7.0285039,447.70285,-9.2299252
2375,2375,195.3687,5.6868916,2.7952862,0.0,0,6.3480015,0.0,0.20566557,58.804462,7.0026164,447.67709,-9.2303219
2376,2376,195.3689,5.7271314,2.8152919,0.0,0,6.3240418,0.0,0.2072227,59.165184,6.9816518,447.65137,-9.2300568
2377,2377,195.3691,5.7586946,2.8401208,0.0,0,6.3000817,0.0,0.20976356,59.382484,6.9600124,447.62561,-9.2294636
2378,2378,195.3693,5.7755604,2.8703105,0.0,0,6.2761221,0.0,0.21194223,59.415894,6.9368606,447.59985,-9.2294388
2379,2379,195.3695,5.7884741,2.8889799,0.0,0,6.252162,0.0,0.21331288,59.50766,6.9129486,447.60703,-9.2293501
2380,2380,195.3697,5.7993474,2.9110723,0.0,0,6.2282019,0.0,0.21559347,59.511189,6.8878994,447.61423,-9.2296143
2381,2381,195.3699,5.7925396,2.942179,0.0,0,6.2042422,0.0,0.21794273,59.280334,6.8636327,447.6214,-9.2297144
2382,2382,195.3701,5.7854896,2.9668856,0.0,0,6.1802821,0.0,0.21963242,59.098595,6.8385491,447.6286,-9.2304659
2383,2383,195.3703,5.7876544,2.9888515,0.0,0,6.1568027,0.0,0.22199859,58.974697,6.8121309,447.63577,-9.2314997
2384,2384,195.3705,5.8107514,3.0141046,0.0,0,6.1339049,0.0,0.22418195,59.05418,6.7858796,447.64297,-9.2315397
2385,2385,195.3707,5.8558726,3.0355184,0.0,0,6.1111121,0.0,0.22547905,59.454521,6.7621698,447.65015,-9.2311344
2386,2386,195.3709,5.9024453,3.0575752,0.0,0,6.0883236,0.0,0.22763021,59.842987,6.7400646,447.65735,-9.2311239
2387,2387,195.3711,5.9234123,3.0834789,0.0,0,6.065536,0.0,0.22999632,59.969154,6.718102,447.66452,-9.2305193
2388,2388,195.3713,5.9195495,3.1061163,0.0,0,6.042748,0.0,0.23144417,59.913216,6.6927047,447.67172,-9.2300129
2389,2389,195.3715,5.9222035,3.1278486,0.0,0,6.0199599,0.0,0.23347381,59.735802,6.6667447,447.67889,-9.2300043
2390,2390,195.3717,5.9324632,3.1520538,0.0,0,5.9971719,0.0,0.23574825,59.597397,6.64328,447.6861,-9.2295332
2391,2391,195.3719,5.9397764,3.1781092,0.0,0,5.9743834,0.0,0.23741846,59.655045,6.6210699,447.69327,-9.2288952
2392,2392,195.3721,5.9602976,3.2040484,0.0,0,5.9515953,0.0,0.23971102,59.734333,6.5977612,447.70047,-9.2290592
2393,2393,195.3723,5.9899225,3.2283847,0.0,0,5.9288077,0.0,0.24226616,59.847351,6.5712252,447.70764,-9.2301397
2394,2394,195.3725,6.0167246,3.2545333,0.0,0,5.9060202,0.0,0.24403654,60.003876,6.5438333,447.71484,-9.2308998
2395,2395,195.3727,6.0518246,3.2784305,0.0,0,5.8832321,0.0,0.24608187,60.166515,6.5187287,447.72202,-9.2312517
2396,2396,195.3729,6.0777812,3.300488,0.0,0,5.8604436,0.0,0.24854524,60.299625,6.4965887,447.72922,-9.2312698
2397,2397,195.3731,6.087678,3.3306069,0.0,0,5.8376555,0.0,0.25050685,60.316158,6.4719415,447.73639,-9.2312088
2398,2398,195.3733,6.0972924,3.358552,0.0,0,5.8148675,0.0,0.25270298,60.274059,6.4461498,447.74359,-9.2311954
2399,2399,195.3735,6.1032162,3.3782172,0.0,0,5.792079,0.0,0.25512767,60.174225,6.4219141,447.75076,-9.2304754
2400,2400,195.3737,6.1048937,3.4037271,0.0,0,5.7692914,0.0,0.256984,60.087936,6.3972988,447.75797,-9.2297516
2401,2401,195.3739,6.1169581,3.4292226,0.0,0,5.7465038,0.0,0.25889683,60.137333,6.372324,447.76514,-9.2286501
2402,2402,195.3741,6.1408005,3.4489551,0.0,0,5.7237153,0.0,0.26122603,60.241756,6.3473806,447.77234,-9.2290735
2403,2403,195.3743,6.1708541,3.477531,0.0,0,5.7009277,0.0,0.26338738,60.363834,6.3228245,447.77951,-9.2301626
2404,2404,195.3745,6.2026997,3.505059,0.0,0,5.6781397,0.0,0.26528791,60.487247,6.2993536,447.78668,-9.2303524
2405,2405,195.3747,6.2188683,3.521764,0.0,0,5.6553516,0.0,0.26743412,60.548241,6.2732263,447.79388,-9.2311831
2406,2406,195.3749,6.2335382,3.5483673,0.0,0,5.6325636,0.0,0.26961935,60.594997,6.2466455,447.80106,-9.2318897
2407,2407,195.3751,6.2599754,3.579109,0.0,0,5.6097755,0.0,0.27167851,60.639324,6.2222238,447.80826,-9.2325926
2408,2408,195.3753,6.2758431,3.5977116,0.0,0,5.5874419,0.0,0.27393374,60.661655,6.1953349,447.81543,-9.232832
2409,2409,195.3755,6.2802067,3.6236122,0.0,0,5.5656581,0.0,0.2762318,60.67598,6.1694751,447.82263,-9.2320938
2410,2410,195.3757,6.2884035,3.6534359,0.0,0,5.5439739,0.0,0.27816698,60.59745,6.1460042,447.8298,-9.2307386
2411,2411,195.3759,6.2985072,3.6705353,0.0,0,5.5222936,0.0,0.28017467,60.537006,6.1220026,447.83701,-9.2306786
2412,2412,195.3761,6.31247,3.6966529,0.0,0,5.5006137,0.0,0.2827282,60.521881,6.0982418,447.84418,-9.2303534
2413,2413,195.3763,6.3395643,3.7296045,0.0,0,5.4789333,0.0,0.28492036,60.590553,6.0720396,447.85138,-9.2295923
2414,2414,195.3765,6.3684793,3.7476037,0.0,0,5.4572535,0.0,0.28691369,60.777893,6.0474777,447.85855,-9.2291689
2415,2415,195.3767,6.3855395,3.7713468,0.0,0,5.4355736,0.0,0.28951189,60.83736,6.0219984,447.86575,-9.2291517
2416,2416,195.3769,6.4000125,3.8030324,0.0,0,5.4138937,0.0,0.29165816,60.851696,5.9960265,447.87292,-9.2303877
2417,2417,195.3771,6.4239278,3.822392,0.0,0,5.3922133,0.0,0.29352751,60.964996,5.9700022,447.88013,-9.2317209
2418,2418,195.3773,6.4475327,3.8469992,0.0,0,5.3705335,0.0,0.29622835,60.945362,5.9451704,447.8873,-9.232295
2419,2419,195.3775,6.4619408,3.8774745,0.0,0,5.3488536,0.0,0.29840252,60.944695,5.9218888,447.8945,-9.2325354
2420,2420,195.3777,6.4663248,3.8949933,0.0,0,5.3271737,0.0,0.29999453,60.978859,5.8975801,447.90167,-9.2328281
2421,2421,195.3779,6.4673896,3.9169679,0.0,0,5.3054934,0.0,0.30259365,60.857582,5.8726292,447.90887,-9.2323036
2422,2422,195.3781,6.4857249,3.9473593,0.0,0,5.2838135,0.0,0.3048985,60.843681,5.8485546,447.91605,-9.2313871
2423,2423,195.3783,6.5120392,3.9679029,0.0,0,5.2621331,0.0,0.30654013,60.958355,5.8254251,447.92325,-9.2316484
2424,2424,195.3785,6.5354266,3.9900777,0.0,0,5.2404532,0.0,0.30913782,61.053482,5.800467,447.93042,-9.2312469
2425,2425,195.3787,6.569212,4.019527,0.0,0,5.2187734,0.0,0.31151113,61.211861,5.7750874,447.93762,-9.2306585
2426,2426,195.3789,6.5967093,4.0407963,0.0,0,5.1970935,0.0,0.31305826,61.364605,5.7516551,447.94479,-9.2304993
2427,2427,195.3791,6.616261,4.0631661,0.0,0,5.1754136,0.0,0.31568801,61.35519,5.7277551,447.952,-9.2299614
2428,2428,195.3793,6.6270766,4.0934916,0.0,0,5.1537337,0.0,0.31839791,61.288002,5.7017231,447.95917,-9.2299433
2429,2429,195.3795,6.6319432,4.1170263,0.0,0,5.1320534,0.0,0.32010826,61.332314,5.6780071,447.87885,-9.2299786
2430,2430,195.3797,6.6424041,4.1402569,0.0,0,5.1103735,0.0,0.32270336,61.302505,5.6520681,447.79855,-9.2301359
2431,2431,195.3799,6.6554227,4.1679945,0.0,0,5.0886931,0.0,0.32528082,61.185036,5.6252365,447.71823,-9.2308521
2432,2432,195.3801,6.6701751,4.1911793,0.0,0,5.0670133,0.0,0.32689232,61.240646,5.6025887,447.63794,-9.2314129
2433,2433,195.3803,6.695127,4.2129626,0.0,0,5.0457683,0.0,0.32934558,61.336388,5.5788674,447.55762,-9.2308674
2434,2434,195.3805,6.7311578,4.2378263,0.0,0,5.0250487,0.0,0.33190861,61.445877,5.5541372,447.47733,-9.230752
2435,2435,195.3807,6.757998,4.2611213,0.0,0,5.0044241,0.0,0.33346957,61.56078,5.5316534,447.397,-9.2305059
2436,2436,195.3809,6.7735877,4.2815742,0.0,0,4.9838042,0.0,0.33566028,61.603542,5.5093246,447.31668,-9.2296896
2437,2437,195.3811,6.7919207,4.3047891,0.0,0,4.9631839,0.0,0.33823767,61.633667,5.4845386,447.23639,-9.2297182
2438,2438,195.3813,6.8018575,4.3309598,0.0,0,4.942564,0.0,0.33996484,61.604385,5.4585209,447.15607,-9.2300272
2439,2439,195.3815,6.8011007,4.3541646,0.0,0,4.9219441,0.0,0.34230295,61.52388,5.4322486,447.07578,-9.2293539
2440,2440,195.3817,6.8086905,4.3762875,0.0,0,4.9013243,0.0,0.3450087,61.377563,5.4067607,446.99545,-9.2298679
2441,2441,195.3819,6.8250546,4.4027262,0.0,0,4.8807039,0.0,0.3467882,61.380192,5.3833151,446.91516,-9.2306137
2442,2442,195.3821,6.8439059,4.4267173,0.0,0,4.8600841,0.0,0.34891546,61.446533,5.3606987,446.83484,-9.2307978
2443,2443,195.3823,6.8694067,4.4472604,0.0,0,4.8394642,0.0,0.35162964,61.458454,5.3370848,446.75455,-9.231349
2444,2444,195.3825,6.9096069,4.4746795,0.0,0,4.8188443,0.0,0.35378322,61.65641,5.3130155,446.67422,-9.2309589
2445,2445,195.3827,6.9482059,4.4994602,0.0,0,4.798224,0.0,0.35583359,61.887283,5.2902937,446.5939,-9.2296858
2446,2446,195.3829,6.97054,4.516479,0.0,0,4.7776041,0.0,0.35825431,61.947495,5.2664728,446.51361,-9.2291965
2447,2447,195.3831,6.9726868,4.5430393,0.0,0,4.7569842,0.0,0.36041927,61.860615,5.2427649,446.43329,-9.2296963
2448,2448,195.3833,6.9640727,4.5704813,0.0,0,4.7363639,0.0,0.36255565,61.705353,5.2197738,446.353,-9.2294512
2449,2449,195.3835,6.9668303,4.5875945,0.0,0,4.715744,0.0,0.36495903,61.585457,5.1980062,446.27267,-9.2294626
2450,2450,195.3837,6.9761271,4.6127381,0.0,0,4.6951241,0.0,0.36722523,61.505909,5.1752367,446.19238,-9.2297869
2451,2451,195.3839,6.9863362,4.6402178,0.0,0,4.6745043,0.0,0.36925051,61.45507,5.1498432,446.11206,-9.2298698
2452,2452,195.3841,7.0069299,4.6565304,0.0,0,4.6538844,0.0,0.3715294,61.49754,5.1260161,446.03174,-9.2298422
2453,2453,195.3843,7.034513,4.6812954,0.0,0,4.6332641,0.0,0.3738929,61.609627,5.103837,445.95145,-9.2299623
2454,2454,195.3845,7.067205,4.7098422,0.0,0,4.6126437,0.0,0.37592003,61.744907,5.083138,445.87112,-9.2306643
2455,2455,195.3847,7.0976253,4.7254124,0.0,0,4.5920238,0.0,0.3781296,61.851711,5.0590663,445.79083,-9.23106
2456,2456,195.3849,7.1154823,4.7493067,0.0,0,4.571404,0.0,0.38063678,61.843849,5.0352039,445.71051,-9.2304153
2457,2457,195.3851,7.1246519,4.7787442,0.0,0,4.5507841,0.0,0.38266769,61.823681,5.0148978,445.63022,-9.2298679
2458,2458,195.3853,7.1327014,4.7943497,0.0,0,4.5305758,0.0,0.38469106,61.806084,4.9923477,445.5499,-9.2303944
2459,2459,195.3855,7.1381531,4.8172116,0.0,0,4.5108657,0.0,0.38727939,61.6674,4.9711156,445.4696,-9.2305689
2460,2460,195.3857,7.1398091,4.845809,0.0,0,4.4912457,0.0,0.38927427,61.58633,4.9485006,445.38928,-9.2306566
2461,2461,195.3859,7.1472578,4.8593192,0.0,0,4.4716296,0.0,0.39099577,61.559906,4.9243937,445.30896,-9.231184
2462,2462,195.3861,7.1698689,4.8800678,0.0,0,4.4520135,0.0,0.39353389,61.562111,4.9044251,445.22867,-9.2312593
2463,2463,195.3863,7.2007546,4.9088135,0.0,0,4.4323978,0.0,0.39557049,61.708149,4.8850665,445.14835,-9.2313356
2464,2464,195.3865,7.2283649,4.9235916,0.0,0,4.4127817,0.0,0.39720809,61.826134,4.8629551,445.06805,-9.2313061
2465,2465,195.3867,7.2487035,4.9442644,0.0,0,4.3931656,0.0,0.39990216,61.871792,4.8398795,444.98773,-9.2312336
2466,2466,195.3869,7.266046,4.9732766,0.0,0,4.3735499,0.0,0.40212429,61.893311,4.8167858,444.90744,-9.231411
2467,2467,195.3871,7.2757554,4.9902124,0.0,0,4.3539338,0.0,0.40371573,61.874382,4.7936978,444.82712,-9.2308817
2468,2468,195.3873,7.2807689,5.010704,0.0,0,4.3343177,0.0,0.40644622,61.757568,4.7722754,444.74683,-9.2304726
2469,2469,195.3875,7.2866058,5.0395756,0.0,0,4.314702,0.0,0.40887833,61.617718,4.7517018,444.6665,-9.230979
2470,2470,195.3877,7.2934685,5.0572743,0.0,0,4.2950859,0.0,0.41040269,61.600475,4.7290964,444.58618,-9.2310572
2471,2471,195.3879,7.3131709,5.0759282,0.0,0,4.2754698,0.0,0.41301203,61.587208,4.7055259,444.50589,-9.2313528
2472,2472,195.3881,7.34236,5.1025195,0.0,0,4.2558532,0.0,0.41549248,61.644302,4.6852002,444.42557,-9.2313976
2473,2473,195.3883,7.374146,5.1212988,0.0,0,4.2362375,0.0,0.41694176,61.850777,4.6657834,444.34528,-9.2311306
2474,2474,195.3885,7.4093738,5.140439,0.0,0,4.2166214,0.0,0.41944405,61.987072,4.6449089,444.26495,-9.2311077
2475,2475,195.3887,7.4311838,5.1654277,0.0,0,4.1970053,0.0,0.42195684,62.018536,4.623982,444.18466,-9.2310658
2476,2476,195.3889,7.432137,5.1842508,0.0,0,4.1773896,0.0,0.42328507,61.96809,4.6042824,444.10434,-9.2304964
2477,2477,195.3891,7.4373717,5.2021465,0.0,0,4.1577735,0.0,0.42558339,61.839077,4.5845203,444.02402,-9.2302065
2478,2478,195.3893,7.4408751,5.2256346,0.0,0,4.1381574,0.0,0.4281297,61.710037,4.5631266,443.94373,-9.2299061
2479,2479,195.3895,7.4402289,5.2457108,0.0,0,4.1185417,0.0,0.4295719,61.606411,4.5404959,443.81485,-9.2294579
2480,2480,195.3897,7.4518013,5.2631888,0.0,0,4.0989256,0.0,0.43180624,61.597534,4.5185585,443.68597,-9.229701
2481,2481,195.3899,7.4768357,5.284101,0.0,0,4.0793095,0.0,0.43434292,61.662468,4.4961414,443.5571,-9.2299099
2482,2482,195.3901,7.5049272,5.3059468,0.0,0,4.0596938,0.0,0.43580425,61.738449,4.4776258,443.42825,-9.2305698
2483,2483,195.3903,7.5322356,5.3255939,0.0,0,4.0404716,0.0,0.43804753,61.809971,4.4595981,443.29938,-9.231144
2484,2484,195.3905,7.5536098,5.3453231,0.0,0,4.0217257,0.0,0.44074431,61.874416,4.4395275,443.1705,-9.2318115
2485,2485,195.3907,7.5676188,5.3678823,0.0,0,4.0030656,0.0,0.44228858,61.909248,4.4197173,443.04163,-9.231843
2486,2486,195.3909,7.5768275,5.3868814,0.0,0,3.9844093,0.0,0.44426969,61.858147,4.3981113,442.91275,-9.2313032
2487,2487,195.3911,7.5817127,5.4040194,0.0,0,3.9657533,0.0,0.44682556,61.761379,4.375248,442.78391,-9.2314329
2488,2488,195.3913,7.5972681,5.4277339,0.0,0,3.9470973,0.0,0.44856361,61.741745,4.3533578,442.65503,-9.230855
2489,2489,195.3915,7.6136336,5.4483409,0.0,0,3.9284413,0.0,0.45053163,61.747288,4.3346329,442.52615,-9.2299347
2490,2490,195.3917,7.630949,5.4634957,0.0,0,3.9097853,0.0,0.45303985,61.72488,4.3158207,442.39728,-9.2300005
2491,2491,195.3919,7.6545677,5.4870601,0.0,0,3.8911293,0.0,0.45495567,61.773453,4.2976103,442.2684,-9.2299509
2492,2492,195.3921,7.6739812,5.5085335,0.0,0,3.8724735,0.0,0.45682502,61.837616,4.2783003,442.13956,-9.229414
2493,2493,195.3923,7.6939874,5.5215812,0.0,0,3.8538175,0.0,0.45916831,61.834316,4.2564373,442.01068,-9.2298136
2494,2494,195.3925,7.7159119,5.5448332,0.0,0,3.8351612,0.0,0.46121898,61.942165,4.2348747,441.88181,-9.2303705
2495,2495,195.3927,7.7349229,5.5674162,0.0,0,3.8165054,0.0,0.46298021,62.037361,4.2172089,441.75293,-9.2300234
2496,2496,195.3929,7.7480893,5.5786295,0.0,0,3.7978494,0.0,0.46509233,61.99118,4.2008142,441.62405,-9.2297468
2497,2497,195.3931,7.7642736,5.5998716,0.0,0,3.7791932,0.0,0.46712756,61.967297,4.1828146,441.49521,-9.2294655
2498,2498,195.3933,7.7799325,5.6233873,0.0,0,3.7605371,0.0,0.46880132,61.917439,4.1622729,441.36633,-9.229764
2499,2499,195.3935,7.7905364,5.6348395,0.0,0,3.7418811,0.0,0.47086933,61.863503,4.1420689,441.23746,-9.230195
2500,2500,195.3937,7.8038311,5.656652,0.0,0,3.7232254,0.0,0.47323614,61.855862,4.1224213,441.10858,-9.2298946
2501,2501,195.3939,7.8215384,5.6828551,0.0,0,3.7045693,0.0,0.47509563,61.885918,4.1022625,440.97971,-9.229743
2502,2502,195.3941,7.8459449,5.6943932,0.0,0,3.6859133,0.0,0.47709724,61.937206,4.0840511,440.85086,-9.2303991
2503,2503,195.3943,7.8733506,5.7154527,0.0,0,3.6672573,0.0,0.47957402,62.008465,4.0664883,440.72198,-9.2303734
2504,2504,195.3945,7.8984785,5.7427578,0.0,0,3.6486013,0.0,0.48149079,62.108589,4.0441189,440.59311,-9.2296953
2505,2505,195.3947,7.9237633,5.75453,0.0,0,3.6299453,0.0,0.48343119,62.191437,4.0233865,440.46423,-9.2298565
2506,2506,195.3949,7.9430118,5.7733698,0.0,0,3.6112893,0.0,0.48609498,62.146458,4.0052428,440.33536,-9.2298431
2507,2507,195.3951,7.9489155,5.7998643,0.0,0,3.5926332,0.0,0.48803216,62.087055,3.9848835,440.20651,-9.2296953
2508,2508,195.3953,7.9570379,5.8118095,0.0,0,3.5743496,0.0,0.48956424,62.098339,3.9657381,440.07764,-9.2299871
2509,2509,195.3955,7.9681759,5.8295531,0.0,0,3.5565166,0.0,0.49217948,61.996181,3.9480927,439.94876,-9.2304621
2510,2510,195.3957,7.9789667,5.8558369,0.0,0,3.538765,0.0,0.4942373,61.941273,3.9294112,439.81989,-9.2304249
2511,2511,195.3959,7.9932575,5.8675327,0.0,0,3.5210168,0.0,0.49563622,61.979298,3.9108016,439.69101,-9.2300177
2512,2512,195.3961,8.0233088,5.883585,0.0,0,3.5032687,0.0,0.4981133,62.04055,3.891679,439.56216,-9.2303743
2513,2513,195.3963,8.0546474,5.9084277,0.0,0,3.4855206,0.0,0.5001241,62.148911,3.8720589,439.43329,-9.231638
2514,2514,195.3965,8.0733404,5.9222217,0.0,0,3.4677727,0.0,0.50144595,62.234226,3.8563173,439.30441,-9.2313938
2515,2515,195.3967,8.0923214,5.9402947,0.0,0,3.4500248,0.0,0.50418305,62.162724,3.8395669,439.17554,-9.2306643
2516,2516,195.3969,8.1021299,5.9677434,0.0,0,3.432277,0.0,0.50674045,62.113678,3.8186486,439.04666,-9.2301846
2517,2517,195.3971,8.1086903,5.983892,0.0,0,3.4145288,0.0,0.50814229,62.151474,3.7978289,438.91782,-9.2289114
2518,2518,195.3973,8.1225748,5.998704,0.0,0,3.3967807,0.0,0.51057696,62.071033,3.7792521,438.78894,-9.2288122
2519,2519,195.3975,8.1352549,6.0228176,0.0,0,3.3790326,0.0,0.51300567,61.992252,3.7613263,438.66006,-9.2287588
2520,2520,195.3977,8.1403856,6.0403891,0.0,0,3.3612847,0.0,0.51427829,61.95623,3.7425702,438.53119,-9.2291174
2521,2521,195.3979,8.1559935,6.0558476,0.0,0,3.3435369,0.0,0.51676416,61.897915,3.7241158,438.40231,-9.2304373
2522,2522,195.3981,8.1911802,6.078373,0.0,0,3.3257887,0.0,0.51946187,61.958122,3.708205,438.27347,-9.230937
2523,2523,195.3983,8.2236023,6.0962887,0.0,0,3.3080409,0.0,0.52072394,62.141197,3.6912911,438.14459,-9.2311134
2524,2524,195.3985,8.2425671,6.1114264,0.0,0,3.2902927,0.0,0.52301902,62.171192,3.6728377,438.01572,-9.231286
2525,2525,195.3987,8.2634935,6.1323428,0.0,0,3.2725446,0.0,0.52568293,62.177414,3.6539776,437.88684,-9.2312908
2526,2526,195.3989,8.2778616,6.1514025,0.0,0,3.2547965,0.0,0.52703005,62.211891,3.6354222,437.75797,-9.230999
2527,2527,195.3991,8.280818,6.1665549,0.0,0,3.2370486,0.0,0.52915353,62.145603,3.6150146,437.62912,-9.2302427
2528,2528,195.3993,8.2921104,6.1848044,0.0,0,3.2193007,0.0,0.53176433,62.018452,3.5962415,437.50024,-9.2301159
2529,2529,195.3995,8.3005476,6.2045078,0.0,0,3.2015526,0.0,0.53319651,61.95232,3.5819507,437.32739,-9.2301102
2530,2530,195.3997,8.307785,6.2205234,0.0,0,3.1838048,0.0,0.53520799,61.885399,3.5643964,437.15454,-9.2295809
2531,2531,195.3999,8.3369732,6.2361674,0.0,0,3.1660566,0.0,0.53775537,61.853825,3.5431411,436.98172,-9.230092
2532,2532,195.4001,8.3695335,6.2568979,0.0,0,3.1483088,0.0,0.53919929,62.020321,3.5242336,436.80887,-9.2302685
2533,2533,195.4003,8.3983631,6.2751288,0.0,0,3.1309152,0.0,0.54108149,62.203083,3.5078306,436.63602,-9.2298946
2534,2534,195.4005,8.4303274,6.2899442,0.0,0,3.11395,0.0,0.54372978,62.311192,3.4903202,436.46317,-9.2300301
2535,2535,195.4007,8.4496107,6.3122768,0.0,0,3.0970623,0.0,0.54553258,62.364941,3.4720902,436.29034,-9.2306242
2536,2536,195.4009,8.4581051,6.3320775,0.0,0,3.0801783,0.0,0.54747945,62.310383,3.4550593,436.11749,-9.2311878
2537,2537,195.4011,8.4632015,6.345561,0.0,0,3.0632944,0.0,0.55015296,62.153931,3.4370337,435.94464,-9.2312145
2538,2538,195.4013,8.4662209,6.3681955,0.0,0,3.0464106,0.0,0.5522294,62.032299,3.4174609,435.77182,-9.2305422
2539,2539,195.4015,8.4803152,6.3892398,0.0,0,3.0295265,0.0,0.5541262,62.015701,3.400969,435.59897,-9.23032
2540,2540,195.4017,8.4985781,6.400691,0.0,0,3.0126424,0.0,0.55653894,62.016125,3.3842225,435.42612,-9.2302923
2541,2541,195.4019,8.5182896,6.4215465,0.0,0,2.9957583,0.0,0.55859166,62.082031,3.3664494,435.25327,-9.2297411
2542,2542,195.4021,8.5514708,6.4419808,0.0,0,2.9788744,0.0,0.56023544,62.209393,3.3479972,435.08044,-9.2295656
2543,2543,195.4023,8.5872297,6.4512105,0.0,0,2.9619906,0.0,0.5623616,62.293724,3.3263738,434.90759,-9.2297373
2544,2544,195.4025,8.6192007,6.4715071,0.0,0,2.9451065,0.0,0.56455851,62.338161,3.3089738,434.73474,-9.2294302
2545,2545,195.4027,8.6418133,6.4958663,0.0,0,2.9282222,0.0,0.5663324,62.362396,3.2931039,434.56192,-9.2290659
2546,2546,195.4029,8.647294,6.5058885,0.0,0,2.9113381,0.0,0.5684256,62.354336,3.2742774,434.38907,-9.2293854
2547,2547,195.4031,8.6431866,6.5244656,0.0,0,2.8944542,0.0,0.57082438,62.21722,3.2557712,434.21622,-9.2295685
2548,2548,195.4033,8.6515217,6.5495667,0.0,0,2.8775704,0.0,0.57271308,62.130859,3.2372272,434.04337,-9.2297297
2549,2549,195.4035,8.6727676,6.5591855,0.0,0,2.8606863,0.0,0.57460058,62.120525,3.2196686,433.87054,-9.2302761
2550,2550,195.4037,8.6986303,6.5778117,0.0,0,2.8438022,0.0,0.57725388,62.119873,3.2027571,433.69769,-9.2302771
2551,2551,195.4039,8.7207136,6.60429,0.0,0,2.8269184,0.0,0.57928729,62.173519,3.1857641,433.52484,-9.2292185
2552,2552,195.4041,8.7452192,6.6148963,0.0,0,2.810034,0.0,0.58107114,62.236076,3.1675076,433.35202,-9.2285585
2553,2553,195.4043,8.7818699,6.6320939,0.0,0,2.7931502,0.0,0.58381975,62.281803,3.1490657,433.17917,-9.2283201
2554,2554,195.4045,8.8062878,6.6568966,0.0,0,2.7762663,0.0,0.58570945,62.335052,3.13293,433.00632,-9.2283764
2555,2555,195.4047,8.8209505,6.6669803,0.0,0,2.7593822,0.0,0.58712357,62.388565,3.1186714,432.83347,-9.2283659
2556,2556,195.4049,8.8271418,6.6831508,0.0,0,2.7424984,0.0,0.58992434,62.310692,3.1014271,432.66064,-9.2282257
2557,2557,195.4051,8.8309021,6.7085514,0.0,0,2.7256143,0.0,0.5920347,62.200268,3.0814967,432.48779,-9.228735
2558,2558,195.4053,8.8482876,6.7203088,0.0,0,2.7090683,0.0,0.59338242,62.19083,3.0651546,432.31494,-9.2294455
2559,2559,195.4055,8.8606539,6.7355728,0.0,0,2.6929309,0.0,0.59628135,62.117363,3.0486112,432.14209,-9.2297115
2560,2560,195.4057,8.879178,6.7607822,0.0,0,2.6768677,0.0,0.59867668,62.106087,3.032743,431.96927,-9.2298756
2561,2561,195.4059,8.9136448,6.7746701,0.0,0,2.6608074,0.0,0.59992772,62.220112,3.0172665,431.79642,-9.2298775
2562,2562,195.4061,8.9469252,6.7893639,0.0,0,2.6447473,0.0,0.60267693,62.24931,2.9990907,431.62357,-9.2291536
2563,2563,195.4063,8.9777803,6.8137808,0.0,0,2.6286874,0.0,0.6052773,62.33717,2.9799371,431.45074,-9.2283821
2564,2564,195.4065,8.9982948,6.8293633,0.0,0,2.6126273,0.0,0.60657829,62.4646,2.9624119,431.27789,-9.2284832
2565,2565,195.4067,9.0124559,6.84303,0.0,0,2.5965672,0.0,0.60918188,62.422962,2.9447634,431.10504,-9.2291718
2566,2566,195.4069,9.0219688,6.8643785,0.0,0,2.5805073,0.0,0.61166674,62.306145,2.9265251,430.93219,-9.2293119
2567,2567,195.4071,9.0263786,6.8795967,0.0,0,2.5644474,0.0,0.61275232,62.2631,2.9090145,430.75937,-9.2293758
2568,2568,195.4073,9.0406685,6.8932242,0.0,0,2.5483873,0.0,0.61518949,62.220325,2.8908522,430.58652,-9.2296762
2569,2569,195.4075,9.0638762,6.9135671,0.0,0,2.5323272,0.0,0.6179077,62.19627,2.8742068,430.41367,-9.2302256
2570,2570,195.4077,9.0905943,6.9308143,0.0,0,2.5162673,0.0,0.61913651,62.285606,2.8584239,430.24084,-9.2302761
2571,2571,195.4079,9.1159019,6.9455347,0.0,0,2.5002072,0.0,0.6215418,62.324879,2.8430166,430.06799,-9.2295876
2572,2572,195.4081,9.1485949,6.9645758,0.0,0,2.4841473,0.0,0.62442225,62.341438,2.8258641,429.89514,-9.2295589
2573,2573,195.4083,9.1851416,6.9841866,0.0,0,2.4680872,0.0,0.62577963,62.485195,2.8085375,429.72229,-9.2297649
2574,2574,195.4085,9.2035151,7.0001836,0.0,0,2.4520273,0.0,0.62807149,62.532623,2.7923379,429.54947,-9.2292385
2575,2575,195.4087,9.2158203,7.0181184,0.0,0,2.4359674,0.0,0.631073,62.408131,2.7731767,429.37662,-9.2291212
2576,2576,195.4089,9.2216215,7.0387282,0.0,0,2.4199073,0.0,0.63268709,62.322941,2.7538431,429.20377,-9.2292185
2577,2577,195.4091,9.227684,7.0543966,0.0,0,2.4038472,0.0,0.63482958,62.267052,2.7377019,429.03094,-9.2285795
2578,2578,195.4093,9.2471123,7.068799,0.0,0,2.3877873,0.0,0.63759971,62.219559,2.7208495,428.85809,-9.228982
2579,2579,195.4095,9.2764282,7.0887642,0.0,0,2.3717272,0.0,0.6391322,62.295555,2.6997924,428.66055,-9.2303848
2580,2580,195.4097,9.3059788,7.1050839,0.0,0,2.3556671,0.0,0.64097142,62.344482,2.6821361,428.46301,-9.2309589
2581,2581,195.4099,9.3363132,7.1174903,0.0,0,2.3396072,0.0,0.6436764,62.373455,2.6672451,428.26547,-9.2309723
2582,2582,195.4101,9.3653345,7.1381402,0.0,0,2.3235474,0.0,0.64554316,62.471691,2.649575,428.06793,-9.2304611
2583,2583,195.4103,9.389452,7.1563406,0.0,0,2.3078089,0.0,0.64735389,62.507118,2.6320598,427.87039,-9.2299261
2584,2584,195.4105,9.4137878,7.1678562,0.0,0,2.2924595,0.0,0.64997047,62.504749,2.6170917,427.67285,-9.2298269
2585,2585,195.4107,9.4305353,7.1896315,0.0,0,2.2771804,0.0,0.65214735,62.530079,2.6017334,427.47531,-9.2291269
2586,2586,195.4109,9.4466934,7.2102356,0.0,0,2.2619042,0.0,0.65410799,62.496376,2.5835819,427.2778,-9.2290192
2587,2587,195.4111,9.4543304,7.220942,0.0,0,2.246628,0.0,0.65670651,62.388157,2.56633,427.08026,-9.229537
2588,2588,195.4113,9.4715042,7.2422323,0.0,0,2.2313523,0.0,0.65909052,62.357479,2.5520849,426.88272,-9.2298584
2589,2589,195.4115,9.4951439,7.26437,0.0,0,2.2160764,0.0,0.66092038,62.373432,2.5354068,426.68518,-9.2294149
2590,2590,195.4117,9.5098438,7.2732787,0.0,0,2.2008004,0.0,0.66323066,62.334702,2.5170851,426.48764,-9.2292356
2591,2591,195.4119,9.5347776,7.2920952,0.0,0,2.1855242,0.0,0.66572905,62.373032,2.4996383,426.2901,-9.2296848
2592,2592,195.4121,9.5698633,7.3145676,0.0,0,2.1702483,0.0,0.66743618,62.489101,2.4819458,426.09256,-9.2299662
2593,2593,195.4123,9.6036348,7.3219342,0.0,0,2.1549723,0.0,0.66937673,62.566322,2.4641695,425.89502,-9.2297125
2594,2594,195.4125,9.6257668,7.3393602,0.0,0,2.1396964,0.0,0.67208469,62.563156,2.4479935,425.69748,-9.2294531
2595,2595,195.4127,9.6322584,7.3630733,0.0,0,2.1244202,0.0,0.6739946,62.543362,2.4332008,425.49994,-9.2297087
2596,2596,195.4129,9.6379099,7.3713846,0.0,0,2.1091442,0.0,0.67573738,62.460411,2.4128122,425.30243,-9.2291851
2597,2597,195.4131,9.6550379,7.3885808,0.0,0,2.0938683,0.0,0.67853129,62.330105,2.3961675,425.10489,-9.2291622
2598,2598,195.4133,9.6761265,7.4131622,0.0,0,2.0785923,0.0,0.68052077,62.33049,2.3826993,424.90735,-9.2291889
2599,2599,195.4135,9.7014551,7.422163,0.0,0,2.0633163,0.0,0.68218505,62.366566,2.3649452,424.70981,-9.2290688
2600,2600,195.4137,9.7283278,7.4387417,0.0,0,2.0480404,0.0,0.68521351,62.354519,2.3489125,424.51227,-9.2294054
2601,2601,195.4139,9.7557278,7.4639735,0.0,0,2.0327644,0.0,0.68735451,62.429447,2.3330631,424.31473,-9.2293444
2602,2602,195.4141,9.7852154,7.4733162,0.0,0,2.0174885,0.0,0.6887219,62.556423,2.3149827,424.11719,-9.2290859
2603,2603,195.4143,9.8161936,7.4878831,0.0,0,2.0022123,0.0,0.69170654,62.557755,2.2967956,423.91965,-9.229537
2604,2604,195.4145,9.8424177,7.5116673,0.0,0,1.9869361,0.0,0.6939522,62.54641,2.2823861,423.72211,-9.229394
2605,2605,195.4147,9.8570957,7.5212493,0.0,0,1.9716601,0.0,0.69513154,62.586742,2.2683687,423.52457,-9.2290611
2606,2606,195.4149,9.8752575,7.534483,0.0,0,1.9563841,0.0,0.69803238,62.557678,2.2514405,423.32706,-9.2288847
2607,2607,195.4151,9.8888063,7.5584559,0.0,0,1.9411081,0.0,0.70044732,62.482441,2.2362821,423.12952,-9.2280416
2608,2608,195.4153,9.9023285,7.5705113,0.0,0,1.9261373,0.0,0.70148981,62.489468,2.2197731,422.93198,-9.2285376
2609,2609,195.4155,9.9301138,7.5829916,0.0,0,1.9115355,0.0,0.70432264,62.495056,2.2016258,422.73444,-9.2293949
2610,2610,195.4157,9.9610586,7.6060953,0.0,0,1.8970004,0.0,0.70714879,62.508408,2.1844597,422.5369,-9.2290945
2611,2611,195.4159,9.9917974,7.6206121,0.0,0,1.8824685,0.0,0.70825952,62.625813,2.168438,422.33936,-9.2286062
2612,2612,195.4161,10.020403,7.633327,0.0,0,1.8679364,0.0,0.71101868,62.633446,2.1529918,422.14182,-9.2290916
2613,2613,195.4163,10.050872,7.6549335,0.0,0,1.8534043,0.0,0.71398419,62.621426,2.137306,421.94427,-9.2289171
2614,2614,195.4165,10.072514,7.67138,0.0,0,1.8388724,0.0,0.71516711,62.699772,2.1199162,421.74673,-9.2287769
2615,2615,195.4167,10.082159,7.6844406,0.0,0,1.8243403,0.0,0.7178154,62.634903,2.1053274,421.54919,-9.2288036
2616,2616,195.4169,10.093596,7.7035508,0.0,0,1.8098084,0.0,0.72078836,62.535603,2.0898466,421.35168,-9.2282581
2617,2617,195.4171,10.103155,7.7197084,0.0,0,1.7952764,0.0,0.7219274,62.503471,2.0717471,421.15414,-9.2281723
2618,2618,195.4173,10.121301,7.7315187,0.0,0,1.7807443,0.0,0.7242282,62.443401,2.0557935,420.9566,-9.2281418
2619,2619,195.4175,10.141083,7.7477436,0.0,0,1.7662123,0.0,0.72710806,62.419327,2.0408735,420.75906,-9.228076
2620,2620,195.4177,10.161831,7.7655349,0.0,0,1.7516804,0.0,0.72830933,62.467892,2.0251467,420.56152,-9.2280464
2621,2621,195.4179,10.197894,7.7788868,0.0,0,1.7371484,0.0,0.73042583,62.480743,2.0101197,420.36398,-9.2280254
2622,2622,195.4181,10.236689,7.7932239,0.0,0,1.7226164,0.0,0.73331499,62.538879,1.9936751,420.16644,-9.2279062
2623,2623,195.4183,10.270785,7.8120785,0.0,0,1.7080843,0.0,0.73467326,62.702133,1.9782592,419.9689,-9.2279949
2624,2624,195.4185,10.295074,7.8260221,0.0,0,1.6935524,0.0,0.73668236,62.731625,1.9665648,419.77136,-9.2281466
2625,2625,195.4187,10.309559,7.8379087,0.0,0,1.6790204,0.0,0.73960614,62.641747,1.9515291,419.57382,-9.2281618
2626,2626,195.4189,10.323483,7.8582096,0.0,0,1.6644883,0.0,0.74132025,62.607655,1.9362276,419.37631,-9.2287102
2627,2627,195.4191,10.339715,7.8754106,0.0,0,1.6499563,0.0,0.74339634,62.555702,1.9204987,419.17877,-9.2287292
2628,2628,195.4193,10.354984,7.8867426,0.0,0,1.6354244,0.0,0.74641752,62.4706,1.9046453,418.98123,-9.2286406
2629,2629,195.4195,10.375747,7.907486,0.0,0,1.6208923,0.0,0.74854821,62.470772,1.8885864,418.93256,-9.2291117
2630,2630,195.4197,10.41268,7.9254746,0.0,0,1.6063604,0.0,0.75045192,62.560246,1.8721292,418.88388,-9.228878
2631,2631,195.4199,10.454245,7.9349852,0.0,0,1.5918283,0.0,0.75312775,62.635456,1.8586584,418.83524,-9.2291794
2632,2632,195.4201,10.485844,7.9543304,0.0,0,1.5772964,0.0,0.75528759,62.701035,1.8451055,418.78656,-9.2296076
2633,2633,195.4203,10.514039,7.9724264,0.0,0,1.5630548,0.0,0.75697613,62.779633,1.8291101,418.73788,-9.2294226
2634,2634,195.4205,10.535646,7.9789438,0.0,0,1.5491644,0.0,0.75930637,62.780113,1.8122518,418.68924,-9.2293339
2635,2635,195.4207,10.545691,7.9964824,0.0,0,1.5353373,0.0,0.76160246,62.676456,1.7958907,418.64056,-9.2292767
2636,2636,195.4209,10.546519,8.0172033,0.0,0,1.5215132,0.0,0.76324606,62.586456,1.7816051,418.59189,-9.2291594
2637,2637,195.4211,10.549145,8.0232954,0.0,0,1.5076892,0.0,0.7653107,62.516964,1.7668153,418.54321,-9.229167
2638,2638,195.4213,10.570281,8.0391617,0.0,0,1.4938653,0.0,0.76782483,62.441044,1.7530527,418.49457,-9.2293329
2639,2639,195.4215,10.609039,8.0609426,0.0,0,1.4800413,0.0,0.76955789,62.521118,1.7396954,418.44589,-9.2288799
2640,2640,195.4217,10.647913,8.0676146,0.0,0,1.4662173,0.0,0.77149874,62.642654,1.7255508,418.39722,-9.2289801
2641,2641,195.4219,10.683625,8.0835314,0.0,0,1.4523933,0.0,0.77436501,62.693882,1.7102816,418.34854,-9.2295685
2642,2642,195.4221,10.721045,8.1072016,0.0,0,1.4385693,0.0,0.77631932,62.770645,1.6939422,418.2999,-9.2291021
2643,2643,195.4223,10.750136,8.1147404,0.0,0,1.4247453,0.0,0.77809417,62.837276,1.6772325,418.25122,-9.2291365
2644,2644,195.4225,10.768716,8.1306496,0.0,0,1.4109213,0.0,0.78122228,62.770626,1.6611159,418.20255,-9.2295198
2645,2645,195.4227,10.778056,8.1550665,0.0,0,1.3970973,0.0,0.78336579,62.672104,1.6470393,418.15387,-9.2294989
2646,2646,195.4229,10.779457,8.1626282,0.0,0,1.3832734,0.0,0.78494042,62.594353,1.6344914,418.10522,-9.2286701
2647,2647,195.4231,10.795146,8.1760864,0.0,0,1.3694494,0.0,0.78808045,62.481358,1.6194699,418.05655,-9.2281008
2648,2648,195.4233,10.830831,8.1991119,0.0,0,1.3556253,0.0,0.79015994,62.53067,1.6024702,418.00787,-9.2288465
2649,2649,195.4235,10.864979,8.2068758,0.0,0,1.3418013,0.0,0.79133046,62.678944,1.5881331,417.9592,-9.2287321
2650,2650,195.4237,10.904803,8.2184792,0.0,0,1.3279774,0.0,0.79426581,62.70689,1.5733199,417.91055,-9.2276545
2651,2651,195.4239,10.943424,8.240778,0.0,0,1.3141534,0.0,0.79654795,62.755604,1.5566673,417.86188,-9.2276011
2652,2652,195.4241,10.966763,8.2507687,0.0,0,1.3003293,0.0,0.79766273,62.879059,1.542892,417.8132,-9.2281885
2653,2653,195.4243,10.988897,8.2629023,0.0,0,1.2865053,0.0,0.80062926,62.828876,1.5305693,417.76453,-9.2282152
2654,2654,195.4245,11.001942,8.2848635,0.0,0,1.2726814,0.0,0.80324674,62.732697,1.5153723,417.71588,-9.2287874
2655,2655,195.4247,11.013124,8.2960529,0.0,0,1.2588574,0.0,0.80425555,62.758865,1.4996418,417.66721,-9.2295599
2656,2656,195.4249,11.032269,8.3068743,0.0,0,1.2450334,0.0,0.80710697,62.667736,1.4855593,417.61853,-9.2291555
2657,2657,195.4251,11.057812,8.3278723,0.0,0,1.2312094,0.0,0.80996937,62.599812,1.4714088,417.56985,-9.2287607
2658,2658,195.4253,11.087418,8.3411808,0.0,0,1.2176627,0.0,0.8108905,62.684013,1.4548987,417.52121,-9.228651
2659,2659,195.4255,11.121132,8.3518562,0.0,0,1.2044513,0.0,0.81350559,62.700386,1.439108,417.47253,-9.2284431
2660,2660,195.4257,11.157663,8.3697624,0.0,0,1.1913006,0.0,0.81642395,62.733841,1.425131,417.42386,-9.2284126
2661,2661,195.4259,11.191424,8.3827047,0.0,0,1.1781524,0.0,0.81736141,62.884651,1.4123698,417.37521,-9.2279539
2662,2662,195.4261,11.225147,8.3934612,0.0,0,1.1650045,0.0,0.81984675,62.910686,1.397278,417.32654,-9.2278147
2663,2663,195.4263,11.252092,8.4108286,0.0,0,1.1518564,0.0,0.82290012,62.862068,1.3822706,417.27786,-9.2285767
2664,2664,195.4265,11.266918,8.4272165,0.0,0,1.1387084,0.0,0.82409406,62.893921,1.3685133,417.22919,-9.2288485
2665,2665,195.4267,11.280873,8.4388161,0.0,0,1.1255604,0.0,0.82641792,62.826591,1.3564197,417.18054,-9.228652
2666,2666,195.4269,11.3036,8.4536619,0.0,0,1.1124125,0.0,0.82954967,62.733746,1.3427104,417.13187,-9.2284498
2667,2667,195.4271,11.333356,8.4706326,0.0,0,1.0992644,0.0,0.83091104,62.795067,1.3277888,417.08319,-9.2282925
2668,2668,195.4273,11.363986,8.4829702,0.0,0,1.0861164,0.0,0.83300203,62.817326,1.3135748,417.03452,-9.2282829
2669,2669,195.4275,11.393521,8.4959478,0.0,0,1.0729684,0.0,0.83605224,62.810658,1.298893,416.98587,-9.2281761
2670,2670,195.4277,11.431364,8.5141659,0.0,0,1.0598203,0.0,0.83754277,62.968502,1.2861481,416.93719,-9.2281713
2671,2671,195.4279,11.470546,8.5272818,0.0,0,1.0466723,0.0,0.83946991,63.033058,1.2718291,416.88852,-9.2276239
2672,2672,195.4281,11.503361,8.5377245,0.0,0,1.0335244,0.0,0.84249818,63.009018,1.2542849,416.83984,-9.2278652
2673,2673,195.4283,11.526641,8.5569992,0.0,0,1.0203763,0.0,0.84430563,63.053146,1.2408727,416.7912,-9.2283373
2674,2674,195.4285,11.541485,8.5717382,0.0,0,1.0072284,0.0,0.84618503,63.032352,1.2284391,416.74252,-9.2280903
2675,2675,195.4287,11.552937,8.5789509,0.0,0,0.99408036,0.0,0.8489868,62.932663,1.2120495,416.69385,-9.2281036
2676,2676,195.4289,11.570518,8.5967636,0.0,0,0.98093235,0.0,0.85084581,62.899078,1.196968,416.64517,-9.2280264
2677,2677,195.4291,11.592061,8.6126633,0.0,0,0.96778435,0.0,0.85241169,62.930473,1.1842012,416.59653,-9.2279186
2678,2678,195.4293,11.628987,8.6189013,0.0,0,0.95463634,0.0,0.85498029,62.962185,1.171159,416.54785,-9.2279825
2679,2679,195.4295,11.672915,8.6367111,0.0,0,0.94148839,0.0,0.85731304,63.023952,1.1574641,416.27744,-9.2274532
2680,2680,195.4297,11.707521,8.6551094,0.0,0,0.92834044,0.0,0.85902011,63.107143,1.1438985,416.00702,-9.2272844
2681,2681,195.4299,11.740978,8.6613026,0.0,0,0.91519243,0.0,0.86144108,63.167057,1.1295673,415.73663,-9.2279625
2682,2682,195.4301,11.773973,8.6783619,0.0,0,0.90204442,0.0,0.86397737,63.158997,1.1147661,415.46622,-9.228569
2683,2683,195.4303,11.79759,8.6987505,0.0,0,0.88916051,0.0,0.86573017,63.159161,1.1000348,415.19583,-9.2284355
2684,2684,195.4305,11.817117,8.7044592,0.0,0,0.87659609,0.0,0.8679117,63.150616,1.0853494,414.92542,-9.2284689
2685,2685,195.4307,11.83659,8.7205572,0.0,0,0.86408949,0.0,0.87088245,63.049885,1.0724005,414.655,-9.2286863
2686,2686,195.4309,11.858409,8.7428923,0.0,0,0.85158539,0.0,0.8727861,63.059921,1.0592295,414.38461,-9.2282362
2687,2687,195.4311,11.886082,8.7477417,0.0,0,0.83908135,0.0,0.87454104,63.103706,1.0434515,414.1142,-9.228138
2688,2688,195.4313,11.914982,8.7604971,0.0,0,0.82657731,0.0,0.87750334,63.044285,1.0295079,413.84378,-9.2280903
2689,2689,195.4315,11.955193,8.7818604,0.0,0,0.81407332,0.0,0.87929863,63.124821,1.0181623,413.57339,-9.2286425
2690,2690,195.4317,11.990242,8.786849,0.0,0,0.8015694,0.0,0.8807739,63.262981,1.0039929,413.30298,-9.2287655
2691,2691,195.4319,12.0192,8.7995291,0.0,0,0.78906536,0.0,0.8838287,63.229973,0.98813713,413.03256,-9.228447
2692,2692,195.4321,12.048389,8.8212996,0.0,0,0.77656138,0.0,0.88579541,63.229752,0.97452772,412.76218,-9.2284489
2693,2693,195.4323,12.081016,8.8267164,0.0,0,0.7640574,0.0,0.88711292,63.293785,0.96114218,412.49176,-9.228508
2694,2694,195.4325,12.10148,8.8387423,0.0,0,0.75155336,0.0,0.89028466,63.194092,0.94795603,412.22134,-9.2284527
2695,2695,195.4327,12.116662,8.8615437,0.0,0,0.73904938,0.0,0.8925398,63.162312,0.93449754,411.95096,-9.2274809
2696,2696,195.4329,12.145354,8.8690224,0.0,0,0.72654539,0.0,0.89366788,63.244278,0.9218961,411.68054,-9.2268457
2697,2697,195.4331,12.174114,8.8798342,0.0,0,0.71404135,0.0,0.8968693,63.189339,0.90862572,411.41016,-9.2271004
2698,2698,195.4333,12.202887,8.9009428,0.0,0,0.70153737,0.0,0.89934289,63.19931,0.89418411,411.13974,-9.2277126
2699,2699,195.4335,12.24227,8.9091558,0.0,0,0.68903339,0.0,0.90020573,63.328842,0.87919259,410.86932,-9.2282677
2700,2700,195.4337,12.276456,8.9190149,0.0,0,0.67652941,0.0,0.90328187,63.301479,0.86757803,410.59894,-9.2282696
2701,2701,195.4339,12.309848,8.9403753,0.0,0,0.66402543,0.0,0.90616488,63.282677,0.85645902,410.32852,-9.2287445
2702,2702,195.4341,12.346786,8.9519901,0.0,0,0.65152138,0.0,0.90711379,63.40052,0.84295774,410.05811,-9.2292986
2703,2703,195.4343,12.372244,8.9613457,0.0,0,0.63901734,0.0,0.91007131,63.393635,0.83132178,409.78772,-9.2290144
2704,2704,195.4345,12.393422,8.980442,0.0,0,0.62651336,0.0,0.91308409,63.327187,0.81802857,409.5173,-9.2290916
2705,2705,195.4347,12.419115,8.9932947,0.0,0,0.61400938,0.0,0.91385716,63.385426,0.80266333,409.24689,-9.2291794
2706,2706,195.4349,12.438566,9.0021696,0.0,0,0.6015054,0.0,0.91645759,63.329414,0.78878212,408.9765,-9.2287493
2707,2707,195.4351,12.45367,9.0179405,0.0,0,0.58900136,0.0,0.91946435,63.228252,0.77632034,408.70609,-9.2290583
2708,2708,195.4353,12.479856,9.0303669,0.0,0,0.57674509,0.0,0.92014307,63.307232,0.76507843,408.4357,-9.2294464
2709,2709,195.4355,12.519011,9.0390339,0.0,0,0.56478846,0.0,0.92246675,63.32402,0.75131559,408.16528,-9.2284975
2710,2710,195.4357,12.558442,9.052536,0.0,0,0.55288601,0.0,0.925515,63.289307,0.73829567,407.89487,-9.2271709
2711,2711,195.4359,12.595952,9.0660563,0.0,0,0.54098594,0.0,0.9262538,63.431263,0.7282263,407.62448,-9.2266493
2712,2712,195.4361,12.628984,9.075161,0.0,0,0.52908593,0.0,0.9283486,63.490513,0.71325016,407.35406,-9.2266026
2713,2713,195.4363,12.649704,9.0869207,0.0,0,0.51718587,0.0,0.93155003,63.42448,0.69923335,407.08365,-9.2270613
2714,2714,195.4365,12.67436,9.1040688,0.0,0,0.50528592,0.0,0.93285525,63.471386,0.68716049,406.81326,-9.227499
2715,2715,195.4367,12.692438,9.1167574,0.0,0,0.49338591,0.0,0.93497026,63.442539,0.67361802,406.54285,-9.2278013
2716,2716,195.4369,12.708655,9.1274796,0.0,0,0.4814859,0.0,0.93830281,63.295158,0.66175473,406.27243,-9.2281475
2717,2717,195.4371,12.742652,9.1458025,0.0,0,0.4695859,0.0,0.93996114,63.308613,0.64902502,406.00204,-9.2281742
2718,2718,195.4373,12.780805,9.1588831,0.0,0,0.45768592,0.0,0.94191307,63.378677,0.63498759,405.73163,-9.2279129
2719,2719,195.4375,12.819182,9.1658726,0.0,0,0.44578591,0.0,0.94501984,63.375999,0.62309867,405.46121,-9.2277126
2720,2720,195.4377,12.867281,9.182909,0.0,0,0.4338859,0.0,0.94675297,63.499748,0.61242086,405.19083,-9.2278843
2721,2721,195.4379,12.911481,9.1956339,0.0,0,0.42198589,0.0,0.94823122,63.652485,0.59926736,404.92041,-9.227458
2722,2722,195.4381,12.946052,9.1994495,0.0,0,0.41008592,0.0,0.95076108,63.693874,0.58753848,404.65002,-9.2267694
2723,2723,195.4383,12.97578,9.2154245,0.0,0,0.39818591,0.0,0.95262742,63.691139,0.57509369,404.37961,-9.2267561
2724,2724,195.4385,12.996169,9.230238,0.0,0,0.3862859,0.0,0.95405519,63.689007,0.56076396,404.10919,-9.2267551
2725,2725,195.4387,13.005724,9.2339287,0.0,0,0.37438589,0.0,0.95649368,63.646881,0.55030721,403.83881,-9.226613
2726,2726,195.4389,13.031864,9.2502403,0.0,0,0.36248589,0.0,0.9587028,63.63179,0.53752953,403.56839,-9.2271528
2727,2727,195.4391,13.064479,9.2676363,0.0,0,0.35058588,0.0,0.96017301,63.680271,0.52327156,403.29797,-9.2271738