File: clean data/testID_0222.csv
index,Time(sec),Force(kN),Jaw(mm),PowAngle(deg),Power(W),Pram,PTemp,Strain,Stress(MPa),Stroke(mm),TC1(C),wedge(mm)
2274,195.348,0.80729324,0.015193864,0.0,0,9.0337067,0.0,0.00076625735,9.2505198,10.059192,451.25934,-9.2357998
2275,195.3482,1.866696,0.022676812,0.0,0,9.0044422,0.0,0.0015806081,20.477882,10.020847,451.28384,-9.2357082
2276,195.3484,3.257725,0.052747034,0.0,0,8.9751787,0.0,0.003140599,37.897724,9.9903049,451.30835,-9.2356949
2277,195.3486,4.1758256,0.088705845,0.0,0,8.9459143,0.0,0.0051990179,50.941238,9.9625015,451.33286,-9.2349491
2278,195.3488,4.573236,0.10967573,0.0,0,8.9166508,0.0,0.0072070267,56.864952,9.932457,451.32471,-9.2335892
2279,195.349,4.8060646,0.13947499,0.0,0,8.8873863,0.0,0.0090043368,60.035095,9.8980427,451.29483,-9.2327738
2280,195.3492,5.1334548,0.19070092,0.0,0,8.8581219,0.0,0.011699676,63.746681,9.8614082,451.26495,-9.2325106
2281,195.3494,5.2121921,0.25432271,0.0,0,8.8288584,0.0,0.016170977,65.332573,9.8177605,451.23508,-9.2324781
2282,195.3496,5.0300031,0.3314746,0.0,0,8.7995939,0.0,0.021469373,63.192848,9.7655916,451.2052,-9.2335129
2283,195.3498,4.9832268,0.39554706,0.0,0,8.7703304,0.0,0.025635818,61.698845,9.7102814,451.17529,-9.2339115
2284,195.35,5.2678447,0.42990285,0.0,0,8.7416534,0.0,0.028552318,64.423378,9.6549797,451.14542,-9.2336683
2285,195.3502,5.4444027,0.47465551,0.0,0,8.7136879,0.0,0.031728577,66.852112,9.6015892,451.11554,-9.2333775
2286,195.3504,5.4001036,0.53420836,0.0,0,8.6858492,0.0,0.035248507,66.487236,9.55198,451.08566,-9.2324295
2287,195.3506,5.5103555,0.57275397,0.0,0,8.6580172,0.0,0.038356628,67.029831,9.5055838,451.05579,-9.2320728
2288,195.3508,5.7615733,0.59632367,0.0,0,8.6301851,0.0,0.04056007,69.926109,9.4608154,451.02588,-9.2321138
2289,195.351,5.757555,0.61493671,0.0,0,8.6023531,0.0,0.041418433,70.647621,9.4205914,450.996,-9.2315931
2290,195.3512,5.435926,0.62955415,0.0,0,8.574522,0.0,0.04239003,67.197289,9.3858261,450.96613,-9.2313137
2291,195.3514,5.2740927,0.66568625,0.0,0,8.546689,0.0,0.045059107,64.295273,9.3553305,450.93625,-9.2318897
2292,195.3516,5.5096312,0.70991552,0.0,0,8.518857,0.0,0.047774035,66.045929,9.3247814,450.90637,-9.2323818
2293,195.3518,5.8442764,0.73079574,0.0,0,8.4910259,0.0,0.049452078,70.03923,9.2927923,450.87646,-9.2326603
2294,195.352,5.9831018,0.75174695,0.0,0,8.4631929,0.0,0.051361207,72.110077,9.2619896,450.84659,-9.2332001
2295,195.3522,6.0266991,0.79070324,0.0,0,8.4353609,0.0,0.053596068,72.594559,9.2275743,450.81671,-9.2331657
2296,195.3524,6.100935,0.83542287,0.0,0,8.4075298,0.0,0.056356203,73.210052,9.190877,450.78683,-9.2320595
2297,195.3526,6.0860505,0.888524,0.0,0,8.3796968,0.0,0.060452443,73.135483,9.1503229,450.75696,-9.2318497
2298,195.3528,5.8850355,0.94277161,0.0,0,8.3518648,0.0,0.064282537,70.849922,9.106287,450.72705,-9.232151
2299,195.353,5.6881695,0.98175097,0.0,0,8.3240337,0.0,0.066855319,68.081894,9.0629845,450.69717,-9.232172
2300,195.3532,5.7110486,1.0193387,0.0,0,8.2962017,0.0,0.069938287,67.493553,9.0210466,450.6673,-9.2318926
2301,195.3534,5.8852034,1.0661756,0.0,0,8.2683697,0.0,0.073293291,69.086395,8.9797182,450.63742,-9.2317629
2302,195.3536,5.9786673,1.1051729,0.0,0,8.2405376,0.0,0.075774848,70.345001,8.9363222,450.60754,-9.2315941
2303,195.3538,5.9441466,1.1312921,0.0,0,8.2127056,0.0,0.078204229,70.052589,8.8968611,450.57764,-9.2318544
2304,195.354,5.968699,1.1517605,0.0,0,8.1848736,0.0,0.079924569,70.004799,8.8617926,450.54776,-9.2322865
2305,195.3542,6.0603771,1.1718934,0.0,0,8.1570415,0.0,0.080830634,71.003059,8.8296061,450.51788,-9.2323103
2306,195.3544,6.0445385,1.1997217,0.0,0,8.1292095,0.0,0.082838535,71.035309,8.8013325,450.48801,-9.2321796
2307,195.3546,5.9001021,1.2336811,0.0,0,8.1013775,0.0,0.085571259,69.257805,8.7722025,450.45813,-9.2321625
2308,195.3548,5.8235908,1.2640321,0.0,0,8.0735455,0.0,0.087479576,67.893852,8.7443352,450.42822,-9.2324257
2309,195.355,5.9872246,1.2845331,0.0,0,8.0462685,0.0,0.089115657,69.121239,8.7175388,450.39835,-9.231741
2310,195.3552,6.2237558,1.3032047,0.0,0,8.0196619,0.0,0.090874545,71.78904,8.68818,450.36847,-9.2307606
2311,195.3554,6.3091455,1.3375696,0.0,0,7.993176,0.0,0.092755929,73.113411,8.6571007,450.33859,-9.2306805
2312,195.3556,6.2575216,1.380491,0.0,0,7.9666953,0.0,0.095678009,72.497841,8.6251745,450.30872,-9.2304869
2313,195.3558,6.2085433,1.4190187,0.0,0,7.9402156,0.0,0.099081159,71.647789,8.5946999,450.27881,-9.2297087
2314,195.356,6.2182956,1.4586936,0.0,0,7.9137359,0.0,0.10174959,71.561531,8.5631552,450.24893,-9.2300653
2315,195.3562,6.1848807,1.4931597,0.0,0,7.8872557,0.0,0.10409403,71.164772,8.527997,450.21906,-9.2308216
2316,195.3564,6.0848498,1.5226593,0.0,0,7.8607755,0.0,0.10681789,69.924751,8.4940853,450.18918,-9.2310534
2317,195.3566,6.0351872,1.5614353,0.0,0,7.8342957,0.0,0.10942893,68.932823,8.4605055,450.1593,-9.2317619
2318,195.3568,6.0984826,1.5925223,0.0,0,7.8078156,0.0,0.11150306,69.246147,8.4267817,450.12939,-9.2325001
2319,195.357,6.1862197,1.6039742,0.0,0,7.7813354,0.0,0.11308851,70.176247,8.3968306,450.09952,-9.2326088
2320,195.3572,6.215271,1.6230034,0.0,0,7.7548552,0.0,0.11435103,70.580193,8.3671198,450.06964,-9.2325096
2321,195.3574,6.2054763,1.6523572,0.0,0,7.7283754,0.0,0.1158625,70.452003,8.3388071,450.03976,-9.2320251
2322,195.3576,6.2117238,1.6756055,0.0,0,7.7018952,0.0,0.11805173,70.35054,8.3127985,450.00989,-9.2315578
2323,195.3578,6.2261953,1.7068079,0.0,0,7.675415,0.0,0.12055065,70.375366,8.2853298,449.97998,-9.2311716
2324,195.358,6.2141967,1.7368205,0.0,0,7.6489348,0.0,0.12233883,70.146339,8.2605591,449.9501,-9.2305393
2325,195.3582,6.2285676,1.748214,0.0,0,7.6224551,0.0,0.12366017,70.02256,8.2369957,449.92023,-9.230607
2326,195.3584,6.3269877,1.7707272,0.0,0,7.5959754,0.0,0.1255458,70.725403,8.2107754,449.89035,-9.2310791
2327,195.3586,6.4151502,1.807767,0.0,0,7.5694952,0.0,0.1276305,71.699303,8.1852198,449.86047,-9.2316418
2328,195.3588,6.4046297,1.8338636,0.0,0,7.543015,0.0,0.12987317,71.72049,8.1577625,449.77435,-9.2323694
2329,195.359,6.3498588,1.8632704,0.0,0,7.5165353,0.0,0.13254605,70.944267,8.1268702,449.63205,-9.232523
2330,195.3592,6.3500218,1.8967439,0.0,0,7.4900556,0.0,0.13452709,70.725296,8.0975323,449.48972,-9.2325296
2331,195.3594,6.3877659,1.9188175,0.0,0,7.4635754,0.0,0.13623779,71.007118,8.0685205,449.34741,-9.2325392
2332,195.3596,6.3707981,1.9506335,0.0,0,7.4370952,0.0,0.13913953,70.714287,8.0398893,449.20508,-9.2318468
2333,195.3598,6.3188548,1.9889666,0.0,0,7.410615,0.0,0.14168356,69.985077,8.0119095,449.06277,-9.231142
2334,195.36,6.3240156,2.0081406,0.0,0,7.3846664,0.0,0.14311936,69.782166,7.9826698,448.92044,-9.2310629
2335,195.3602,6.3997378,2.0244966,0.0,0,7.3593612,0.0,0.14494511,70.371353,7.9556952,448.77814,-9.2310648
2336,195.3604,6.4399643,2.0516436,0.0,0,7.3341722,0.0,0.14671032,70.784706,7.9270391,448.6358,-9.2311068
2337,195.3606,6.4011488,2.0758183,0.0,0,7.3089881,0.0,0.1482072,70.415642,7.9001465,448.4935,-9.2311239
2338,195.3608,6.3518109,2.1012855,0.0,0,7.2838039,0.0,0.15069462,69.741119,7.878428,448.35117,-9.2313528
2339,195.361,6.3590832,2.1292634,0.0,0,7.2586198,0.0,0.15290244,69.518669,7.8555059,448.20886,-9.2320013
2340,195.3612,6.403451,2.1461225,0.0,0,7.2334356,0.0,0.15382069,69.830086,7.8319864,448.06653,-9.2319584
2341,195.3614,6.4429431,2.162482,0.0,0,7.2082515,0.0,0.15547939,70.108215,7.8084483,447.92422,-9.2320442
2342,195.3616,6.4924073,2.1903162,0.0,0,7.1830673,0.0,0.15768749,70.507233,7.7830911,447.78189,-9.2325706
2343,195.3618,6.5512805,2.2180564,0.0,0,7.1578832,0.0,0.15932477,71.049698,7.7599583,447.63959,-9.2319365
2344,195.362,6.59306,2.2421665,0.0,0,7.1326995,0.0,0.16158333,71.385513,7.7366891,447.49725,-9.2313509
2345,195.3622,6.584599,2.2680378,0.0,0,7.1075153,0.0,0.16394389,71.21344,7.7095881,447.35495,-9.2312078
2346,195.3624,6.5440192,2.2956097,0.0,0,7.0823312,0.0,0.16547492,70.668968,7.6827149,447.21262,-9.23176
2347,195.3626,6.5154076,2.3226063,0.0,0,7.0571475,0.0,0.16764101,70.170303,7.6586666,447.07031,-9.2324314
2348,195.3628,6.5067329,2.3498142,0.0,0,7.0319633,0.0,0.1702535,69.834526,7.6345525,446.92798,-9.2330208
2349,195.363,6.510437,2.3760023,0.0,0,7.0067792,0.0,0.17192784,69.761887,7.6096549,446.78568,-9.2332878
2350,195.3632,6.5363235,2.3948917,0.0,0,6.981595,0.0,0.17351602,69.896889,7.5842433,446.64334,-9.2324457
2351,195.3634,6.5950513,2.4109192,0.0,0,6.9564114,0.0,0.17531012,70.299461,7.5592499,446.50104,-9.2318373
2352,195.3636,6.6424637,2.4367359,0.0,0,6.9312277,0.0,0.17679948,70.764458,7.536694,446.3587,-9.2313738
2353,195.3638,6.6359167,2.4642923,0.0,0,6.9060431,0.0,0.17874777,70.762627,7.5136452,446.2164,-9.2310648
2354,195.364,6.5965877,2.4838061,0.0,0,6.8808594,0.0,0.18102561,70.219635,7.4880548,446.07407,-9.2317381
2355,195.3642,6.5686312,2.5072434,0.0,0,6.8556757,0.0,0.18263417,69.687454,7.465169,445.93176,-9.2324581
2356,195.3644,6.5810499,2.5294127,0.0,0,6.830492,0.0,0.1839996,69.614166,7.4448843,445.78943,-9.2326441
2357,195.3646,6.6211772,2.5461285,0.0,0,6.8053074,0.0,0.18590963,69.883461,7.4208469,445.64713,-9.2327099
2358,195.3648,6.6578054,2.5758636,0.0,0,6.7801232,0.0,0.18800735,70.165138,7.3960748,445.50479,-9.2329292
2359,195.365,6.6849704,2.6061563,0.0,0,6.7554417,0.0,0.1899472,70.36261,7.3725882,445.36249,-9.2329369
2360,195.3652,6.7147942,2.6219468,0.0,0,6.7313671,0.0,0.19194898,70.590485,7.3491926,445.22015,-9.2326393
2361,195.3654,6.7302275,2.6461809,0.0,0,6.7074022,0.0,0.19394106,70.660309,7.3255458,445.07785,-9.232583
2362,195.3656,6.7198119,2.6770809,0.0,0,6.6834416,0.0,0.19571796,70.414711,7.3010473,444.93552,-9.2323446
2363,195.3658,6.7070627,2.6955903,0.0,0,6.6594815,0.0,0.19769725,70.106537,7.2787967,444.79321,-9.2316322
2364,195.366,6.7114911,2.7209332,0.0,0,6.6355219,0.0,0.20001876,69.941536,7.254992,444.65088,-9.2312412
2365,195.3662,6.7259984,2.7494409,0.0,0,6.6115613,0.0,0.2017327,69.96492,7.2293682,444.50858,-9.2312164
2366,195.3664,6.7477341,2.7618766,0.0,0,6.5876017,0.0,0.20314045,70.104462,7.2077298,444.36624,-9.2312517
2367,195.3666,6.7843466,2.7838151,0.0,0,6.5636415,0.0,0.20527369,70.2901,7.187088,444.22394,-9.2314386
2368,195.3668,6.8090358,2.8158507,0.0,0,6.5396819,0.0,0.20720446,70.43924,7.1615224,444.0816,-9.2315645
2369,195.367,6.8078585,2.8341191,0.0,0,6.5157218,0.0,0.20891131,70.370766,7.1359582,443.9393,-9.2321386
2370,195.3672,6.8114791,2.8556018,0.0,0,6.4917622,0.0,0.2112149,70.176826,7.1126823,443.79697,-9.2325916
2371,195.3674,6.828639,2.8835809,0.0,0,6.467802,0.0,0.21291585,70.148872,7.0886045,443.65466,-9.2326107
2372,195.3676,6.857451,2.9004109,0.0,0,6.4438419,0.0,0.21424471,70.352318,7.0647602,443.51233,-9.2321939
2373,195.3678,6.8900762,2.9232342,0.0,0,6.4198818,0.0,0.21670887,70.547241,7.0414166,443.37003,-9.2314816
2374,195.368,6.9143353,2.9553943,0.0,0,6.3959212,0.0,0.2189568,70.63781,7.0185952,443.22769,-9.2315493
2375,195.3682,6.9311657,2.9748135,0.0,0,6.3719616,0.0,0.22035258,70.797226,6.9957123,443.08539,-9.2318258
2376,195.3684,6.9387789,2.9948804,0.0,0,6.3480015,0.0,0.22258726,70.819832,6.972436,442.94305,-9.2314148
2377,195.3686,6.9340024,3.0251927,0.0,0,6.3240418,0.0,0.22486067,70.642731,6.9495711,442.80075,-9.230814
2378,195.3688,6.9267526,3.0482602,0.0,0,6.3000817,0.0,0.22641405,70.392609,6.9256635,442.63828,-9.2307072
2379,195.369,6.9254856,3.0703256,0.0,0,6.2761221,0.0,0.22883955,70.081429,6.9004679,442.44559,-9.2308607
2380,195.3692,6.9464498,3.0970507,0.0,0,6.252162,0.0,0.23109838,70.113594,6.8774672,442.2529,-9.2306862
2381,195.3694,6.9897871,3.1161687,0.0,0,6.2282019,0.0,0.23218101,70.44838,6.85287,442.06021,-9.2312288
2382,195.3696,7.0220757,3.1352632,0.0,0,6.2042422,0.0,0.23421445,70.657646,6.8258696,441.86752,-9.2317972
2383,195.3698,7.0408039,3.1627417,0.0,0,6.1802821,0.0,0.23667705,70.690132,6.800159,441.67484,-9.23211
2384,195.37,7.0510821,3.1882434,0.0,0,6.1568027,0.0,0.23819746,70.686821,6.7760715,441.48215,-9.2323904
2385,195.3702,7.0523977,3.2101989,0.0,0,6.1339049,0.0,0.24038014,70.598984,6.7513361,441.28946,-9.2324085
2386,195.3704,7.0520153,3.2330196,0.0,0,6.1111121,0.0,0.2427721,70.409485,6.7278433,441.09677,-9.232605
2387,195.3706,7.0575519,3.2577877,0.0,0,6.0883236,0.0,0.24427101,70.326736,6.7057767,440.90408,-9.2326021
2388,195.3708,7.0706654,3.2813323,0.0,0,6.065536,0.0,0.24636935,70.303032,6.6834822,440.7114,-9.23277
2389,195.371,7.0930362,3.3046157,0.0,0,6.042748,0.0,0.2488772,70.287796,6.659328,440.51871,-9.2322512
2390,195.3712,7.1248803,3.3322215,0.0,0,6.0199599,0.0,0.25058314,70.475952,6.6357517,440.32602,-9.2313251
2391,195.3714,7.1611347,3.3556063,0.0,0,5.9971719,0.0,0.25252783,70.746582,6.6135945,440.13333,-9.2311106
2392,195.3716,7.1892009,3.3751793,0.0,0,5.9743834,0.0,0.25490946,70.876999,6.5890779,439.94064,-9.230937
2393,195.3718,7.2027302,3.4036191,0.0,0,5.9515953,0.0,0.25682402,70.880608,6.5616937,439.74796,-9.2309675
2394,195.372,7.1983829,3.4307196,0.0,0,5.9288077,0.0,0.25888735,70.726593,6.5371757,439.55527,-9.2313156
2395,195.3722,7.1961503,3.449554,0.0,0,5.9060202,0.0,0.26131624,70.536072,6.511374,439.36258,-9.2319908
2396,195.3724,7.206881,3.4763534,0.0,0,5.8832321,0.0,0.2633611,70.428383,6.4845996,439.16989,-9.2328386
2397,195.3726,7.2229452,3.5033815,0.0,0,5.8604436,0.0,0.26515812,70.414757,6.463654,438.9772,-9.2328644
2398,195.3728,7.2376733,3.5215213,0.0,0,5.8376555,0.0,0.26738372,70.415756,6.4407248,438.78452,-9.2331343
2399,195.373,7.253056,3.5509465,0.0,0,5.8148675,0.0,0.26979333,70.437607,6.4141788,438.59183,-9.2329016
2400,195.3732,7.2843351,3.5823491,0.0,0,5.792079,0.0,0.27189997,70.610664,6.3899832,438.39914,-9.2322006
2401,195.3734,7.3207126,3.5979753,0.0,0,5.7692914,0.0,0.27400669,70.87101,6.365231,438.20645,-9.2322292
2402,195.3736,7.3469172,3.6211421,0.0,0,5.7465038,0.0,0.27617577,71.033264,6.3405943,438.01376,-9.2322216
2403,195.3738,7.3546782,3.6513124,0.0,0,5.7237153,0.0,0.27804881,70.909645,6.3176293,437.82108,-9.2317286
2404,195.374,7.3575435,3.6689165,0.0,0,5.7009277,0.0,0.28009135,70.76519,6.295042,437.62839,-9.2318754
2405,195.3742,7.365653,3.694046,0.0,0,5.6781397,0.0,0.28263175,70.68605,6.2709384,437.4357,-9.232584
2406,195.3744,7.3685465,3.7239974,0.0,0,5.6553516,0.0,0.28454188,70.559914,6.2452078,437.24301,-9.2324371
2407,195.3746,7.3791976,3.7389526,0.0,0,5.6325636,0.0,0.28627855,70.555763,6.2206879,437.05032,-9.2324314
2408,195.3748,7.4057326,3.7632098,0.0,0,5.6097755,0.0,0.28894085,70.572624,6.1956177,436.85764,-9.232439
2409,195.375,7.4362335,3.7972023,0.0,0,5.5874419,0.0,0.29109359,70.673584,6.1713605,436.66495,-9.2320747
2410,195.3752,7.4584365,3.8160353,0.0,0,5.5656581,0.0,0.29287061,70.806984,6.1479845,436.47226,-9.2316818
2411,195.3754,7.4823589,3.8383019,0.0,0,5.5439739,0.0,0.29553202,70.868141,6.1228023,436.2796,-9.2320194
2412,195.3756,7.5095921,3.8695443,0.0,0,5.5222936,0.0,0.29770339,70.958694,6.0978246,436.08691,-9.2325764
2413,195.3758,7.5195341,3.8892264,0.0,0,5.5006137,0.0,0.29938126,70.984756,6.0763078,435.89423,-9.2319174
2414,195.376,7.5226955,3.9132361,0.0,0,5.4789333,0.0,0.30217627,70.802063,6.0519466,435.70154,-9.2318439
2415,195.3762,7.5228024,3.9454257,0.0,0,5.4572535,0.0,0.30470276,70.623886,6.0243726,435.50885,-9.2325354
2416,195.3764,7.5265536,3.9656296,0.0,0,5.4355736,0.0,0.30621734,70.570473,5.9994917,435.31616,-9.2313328
2417,195.3766,7.5392919,3.9854286,0.0,0,5.4138937,0.0,0.30866688,70.493263,5.9759378,435.12347,-9.2313423
2418,195.3768,7.5540562,4.0135784,0.0,0,5.3922133,0.0,0.31112579,70.457008,5.9518886,434.93079,-9.2319221
2419,195.377,7.5802402,4.0353537,0.0,0,5.3705335,0.0,0.31260285,70.566658,5.9279408,434.7381,-9.2317848
2420,195.3772,7.6172299,4.0561404,0.0,0,5.3488536,0.0,0.31510019,70.721687,5.9018321,434.54541,-9.2314854
2421,195.3774,7.6401143,4.0829134,0.0,0,5.3271737,0.0,0.31762558,70.808434,5.8770146,434.35272,-9.2308111
2422,195.3776,7.6548076,4.1056442,0.0,0,5.3054934,0.0,0.31902102,70.879211,5.8551431,434.16003,-9.231122
2423,195.3778,7.6674919,4.127336,0.0,0,5.2838135,0.0,0.32149091,70.786369,5.8326907,433.96735,-9.2317333
2424,195.378,7.6633134,4.1540484,0.0,0,5.2621331,0.0,0.32425866,70.594261,5.8083472,433.77466,-9.2321243
2425,195.3782,7.6648855,4.1799316,0.0,0,5.2404532,0.0,0.32586697,70.459114,5.7839251,433.58197,-9.2317276
2426,195.3784,7.6785336,4.2017827,0.0,0,5.2187734,0.0,0.32812285,70.334236,5.7613854,433.38928,-9.2317228
2427,195.3786,7.6954837,4.2246017,0.0,0,5.1970935,0.0,0.3307943,70.291298,5.7372079,433.19659,-9.2315598
2428,195.3788,7.7228193,4.2504425,0.0,0,5.1754136,0.0,0.33249873,70.411842,5.7122483,432.95792,-9.2311783
2429,195.379,7.7523966,4.2733822,0.0,0,5.1537337,0.0,0.33466837,70.554985,5.6884055,432.61194,-9.2310858
2430,195.3792,7.782268,4.2946625,0.0,0,5.1320534,0.0,0.33740756,70.685165,5.6620164,432.26593,-9.2315378
2431,195.3794,7.809031,4.3219938,0.0,0,5.1103735,0.0,0.33930179,70.772079,5.6354518,431.91995,-9.2317266
2432,195.3796,7.8164973,4.3461905,0.0,0,5.0886931,0.0,0.34135783,70.7136,5.6127963,431.57397,-9.2315435
2433,195.3798,7.8143902,4.3638887,0.0,0,5.0670133,0.0,0.34391221,70.554169,5.5911908,431.228,-9.231328
2434,195.38,7.8224163,4.3913159,0.0,0,5.0457683,0.0,0.34594232,70.458817,5.5680447,430.88202,-9.2308874
2435,195.3802,7.8316088,4.417738,0.0,0,5.0250487,0.0,0.34794661,70.36261,5.5436792,430.53604,-9.2308998
2436,195.3804,7.8433466,4.4343419,0.0,0,5.0044241,0.0,0.35041279,70.276306,5.5204248,430.19006,-9.2309694
2437,195.3806,7.8646431,4.4609895,0.0,0,4.9838042,0.0,0.3526096,70.325523,5.4983997,429.84409,-9.231061
2438,195.3808,7.8887868,4.4878807,0.0,0,4.9631839,0.0,0.35450655,70.425598,5.4743147,429.49811,-9.231286
2439,195.381,7.916357,4.50316,0.0,0,4.942564,0.0,0.35682467,70.509491,5.4508352,429.15213,-9.2315998
2440,195.3812,7.9430919,4.5305839,0.0,0,4.9219441,0.0,0.35929072,70.536446,5.4275055,428.80615,-9.2315865
2441,195.3814,7.9589472,4.5611296,0.0,0,4.9013243,0.0,0.36135608,70.568085,5.4030004,428.46014,-9.2310047
2442,195.3816,7.9695044,4.5755296,0.0,0,4.8807039,0.0,0.36352071,70.54493,5.377708,428.11417,-9.2307558
2443,195.3818,7.9784536,4.6001229,0.0,0,4.8600841,0.0,0.36613578,70.404099,5.3532996,427.76819,-9.2308788
2444,195.382,7.9829359,4.6311593,0.0,0,4.8394642,0.0,0.36821607,70.309769,5.3309827,427.42221,-9.231451
2445,195.3822,7.993546,4.6460328,0.0,0,4.8188443,0.0,0.3702032,70.280945,5.3083911,427.07623,-9.2316418
2446,195.3824,8.0116682,4.6689801,0.0,0,4.798224,0.0,0.37288433,70.185013,5.2853889,426.73026,-9.2311258
2447,195.3826,8.0257177,4.6985884,0.0,0,4.7776041,0.0,0.37483546,70.176712,5.2627473,426.38428,-9.2318354
2448,195.3828,8.0421991,4.7124906,0.0,0,4.7569842,0.0,0.37656298,70.268486,5.2395277,426.0383,-9.2323313
2449,195.383,8.0670881,4.7347088,0.0,0,4.7363639,0.0,0.37934935,70.297302,5.2175908,425.69232,-9.2319145
2450,195.3832,8.0953865,4.7657218,0.0,0,4.715744,0.0,0.38155368,70.379234,5.1954885,425.34634,-9.2314453
2451,195.3834,8.1148224,4.7816286,0.0,0,4.6951241,0.0,0.38322392,70.403946,5.1728482,425.00037,-9.2309504
2452,195.3836,8.1224995,4.8025174,0.0,0,4.6745043,0.0,0.38597232,70.270187,5.1507883,424.65439,-9.2309275
2453,195.3838,8.1315451,4.8333941,0.0,0,4.6538844,0.0,0.38827392,70.217735,5.1251655,424.30838,-9.2311296
2454,195.384,8.141305,4.85144,0.0,0,4.6332641,0.0,0.38982171,70.224281,5.1030612,423.9624,-9.2310791
2455,195.3842,8.1465578,4.8716373,0.0,0,4.6126437,0.0,0.39261934,70.110741,5.083899,423.61642,-9.230938
2456,195.3844,8.1538305,4.900651,0.0,0,4.5920238,0.0,0.39523569,69.979919,5.0603333,423.27045,-9.2309217
2457,195.3846,8.1660099,4.9191275,0.0,0,4.571404,0.0,0.39662626,69.958015,5.0389338,422.92447,-9.2310476
2458,195.3848,8.1816254,4.9388738,0.0,0,4.5507841,0.0,0.39924815,69.87133,5.0183172,422.57849,-9.2311563
2459,195.385,8.2085772,4.9671655,0.0,0,4.5305758,0.0,0.40198612,69.894539,4.994854,422.23251,-9.2318621
2460,195.3852,8.2337227,4.9878716,0.0,0,4.5108657,0.0,0.40340739,70.030701,4.9741373,421.88654,-9.2324133
2461,195.3854,8.2505674,5.005456,0.0,0,4.4912457,0.0,0.40576735,69.98867,4.9534016,421.54056,-9.2324324
2462,195.3856,8.2669401,5.0293784,0.0,0,4.4716296,0.0,0.40830645,69.928963,4.9307356,421.19458,-9.2320499
2463,195.3858,8.2752943,5.0508738,0.0,0,4.4520135,0.0,0.40972224,69.919426,4.9094005,420.8486,-9.2314882
2464,195.386,8.2801905,5.0689626,0.0,0,4.4323978,0.0,0.41205323,69.816566,4.8882155,420.50262,-9.2312651
2465,195.3862,8.2960501,5.0921044,0.0,0,4.4127817,0.0,0.41482329,69.745605,4.8643289,420.15662,-9.230792
2466,195.3864,8.3088675,5.116281,0.0,0,4.3931656,0.0,0.41637751,69.734253,4.8419967,419.81064,-9.2307711
2467,195.3866,8.3192234,5.1351113,0.0,0,4.3735499,0.0,0.41854429,69.663055,4.8222938,419.46466,-9.2311153
2468,195.3868,8.342947,5.1549196,0.0,0,4.3539338,0.0,0.42129147,69.66169,4.8015308,419.11868,-9.2311287
2469,195.387,8.3721352,5.1807261,0.0,0,4.3343177,0.0,0.42299128,69.745621,4.7779527,418.77271,-9.2318602
2470,195.3872,8.3940363,5.2024894,0.0,0,4.314702,0.0,0.42506838,69.810989,4.7561212,418.42673,-9.2320776
2471,195.3874,8.4134598,5.2202315,0.0,0,4.2950859,0.0,0.42776242,69.833221,4.7344136,418.08075,-9.2319832
2472,195.3876,8.4311771,5.2455449,0.0,0,4.2754698,0.0,0.42969105,69.845436,4.7117257,417.73477,-9.2319593
2473,195.3878,8.4418726,5.2667007,0.0,0,4.2558532,0.0,0.43161532,69.78038,4.6929188,417.38879,-9.2315235
2474,195.388,8.4485989,5.2813888,0.0,0,4.2362375,0.0,0.43411493,69.644371,4.6737127,417.04282,-9.2311487
2475,195.3882,8.4507227,5.3069882,0.0,0,4.2166214,0.0,0.43621311,69.574257,4.6519804,416.69684,-9.2312098
2476,195.3884,8.4568844,5.3304758,0.0,0,4.1970053,0.0,0.43807933,69.502434,4.6310506,416.35086,-9.2314034
2477,195.3886,8.4748564,5.3440261,0.0,0,4.1773896,0.0,0.44049668,69.438194,4.6109858,416.00485,-9.2310677
2478,195.3888,8.5008278,5.3683381,0.0,0,4.1577735,0.0,0.44276598,69.459953,4.5873756,415.68356,-9.2310486
2479,195.389,8.5284319,5.3945007,0.0,0,4.1381574,0.0,0.44459599,69.538239,4.5645003,415.46097,-9.2304001
2480,195.3892,8.5518103,5.4070201,0.0,0,4.1185417,0.0,0.44685259,69.606796,4.5443339,415.23834,-9.2303371
2481,195.3894,8.5764322,5.4298892,0.0,0,4.0989256,0.0,0.44932544,69.660568,4.5244899,415.01575,-9.2309723
2482,195.3896,8.5946455,5.458147,0.0,0,4.0793095,0.0,0.45119315,69.694412,4.5054679,414.79315,-9.2310247
2483,195.3898,8.6022739,5.4702301,0.0,0,4.0596938,0.0,0.45323423,69.620911,4.4840589,414.57056,-9.2310152
2484,195.39,8.6043272,5.4915805,0.0,0,4.0404716,0.0,0.45587137,69.516998,4.4626427,414.34793,-9.2311831
2485,195.3902,8.6107893,5.5202079,0.0,0,4.0217257,0.0,0.45786023,69.435883,4.4438219,414.12534,-9.2312107
2486,195.3904,8.6212263,5.532692,0.0,0,4.0030656,0.0,0.45970893,69.310104,4.4229279,413.90274,-9.2313251
2487,195.3906,8.6464005,5.552289,0.0,0,3.9844093,0.0,0.46242833,69.258842,4.4006748,413.68015,-9.2314825
2488,195.3908,8.6783295,5.5800667,0.0,0,3.9657533,0.0,0.46437091,69.366005,4.3803658,413.45752,-9.231144
2489,195.391,8.7053471,5.5925164,0.0,0,3.9470973,0.0,0.46586326,69.511955,4.3593335,413.23492,-9.2309227
2490,195.3912,8.7337818,5.6113195,0.0,0,3.9284413,0.0,0.46870366,69.571358,4.3381176,413.01233,-9.2308578
2491,195.3914,8.7567883,5.6398287,0.0,0,3.9097853,0.0,0.47090435,69.588089,4.3190236,412.78973,-9.2301769
2492,195.3916,8.7644091,5.6533494,0.0,0,3.8911293,0.0,0.47221583,69.553215,4.3004198,412.56711,-9.2295542
2493,195.3918,8.7659922,5.671154,0.0,0,3.8724735,0.0,0.47497931,69.405029,4.2796555,412.34451,-9.2302599
2494,195.392,8.7730198,5.6999111,0.0,0,3.8538175,0.0,0.47747904,69.297386,4.2579689,412.12192,-9.2312832
2495,195.3922,8.7850008,5.7165394,0.0,0,3.8351612,0.0,0.47891012,69.287163,4.2388835,411.89932,-9.2313299
2496,195.3924,8.7998104,5.732779,0.0,0,3.8165054,0.0,0.48162037,69.1894,4.2211947,411.6767,-9.2316055
2497,195.3926,8.8166637,5.7582455,0.0,0,3.7978494,0.0,0.48408735,69.126984,4.1996827,411.4541,-9.2316608
2498,195.3928,8.8466797,5.7752895,0.0,0,3.7791932,0.0,0.48521179,69.254814,4.1785026,411.23151,-9.2311172
2499,195.393,8.878664,5.7906699,0.0,0,3.7605371,0.0,0.4877032,69.35096,4.1600385,411.00891,-9.2305002
2500,195.3932,8.900219,5.8145938,0.0,0,3.7418811,0.0,0.4904094,69.393639,4.1408176,410.78629,-9.2304802
2501,195.3934,8.9183788,5.8335037,0.0,0,3.7232254,0.0,0.49158037,69.455673,4.1222486,410.56369,-9.230978
2502,195.3936,8.9284239,5.8495655,0.0,0,3.7045693,0.0,0.49391234,69.381218,4.1046534,410.34109,-9.2309389
2503,195.3938,8.924407,5.8710918,0.0,0,3.6859133,0.0,0.49663335,69.225739,4.0850635,410.1185,-9.2309113
2504,195.394,8.9282408,5.8910208,0.0,0,3.6672573,0.0,0.49792439,69.167297,4.0631542,409.89587,-9.2316942
2505,195.3942,8.9451094,5.9071455,0.0,0,3.6486013,0.0,0.50013405,69.052727,4.0427961,409.67328,-9.2324514
2506,195.3944,8.9619226,5.926836,0.0,0,3.6299453,0.0,0.50285459,68.914146,4.0232244,409.45068,-9.2324619
2507,195.3946,8.9859028,5.9492097,0.0,0,3.6112893,0.0,0.50431341,68.994507,4.004909,409.22809,-9.2323685
2508,195.3948,9.0202856,5.9666495,0.0,0,3.5926332,0.0,0.5063951,69.110123,3.9882159,409.00546,-9.2316742
2509,195.395,9.0529013,5.982553,0.0,0,3.5743496,0.0,0.50915587,69.19593,3.9687736,408.78287,-9.2310534
2510,195.3952,9.0740213,6.005127,0.0,0,3.5565166,0.0,0.51073897,69.316078,3.9470155,408.56027,-9.2310152
2511,195.3954,9.091094,6.024641,0.0,0,3.538765,0.0,0.51265395,69.309235,3.927701,408.33768,-9.230566
2512,195.3956,9.1017199,6.0385003,0.0,0,3.5210168,0.0,0.51537549,69.194962,3.9112678,408.11505,-9.2298059
2513,195.3958,9.0992317,6.0618663,0.0,0,3.5032687,0.0,0.51733303,69.052032,3.8941302,407.89246,-9.2300425
2514,195.396,9.098279,6.0828524,0.0,0,3.4855206,0.0,0.5191741,68.90667,3.8741486,407.66986,-9.2303305
2515,195.3962,9.1060753,6.0949516,0.0,0,3.4677727,0.0,0.52163732,68.815224,3.8562133,407.44727,-9.2305479
2516,195.3964,9.1328182,6.117734,0.0,0,3.4500248,0.0,0.52373445,68.853394,3.8405194,407.22464,-9.2317371
2517,195.3966,9.162303,6.1401,0.0,0,3.432277,0.0,0.5254057,68.928558,3.821677,407.00204,-9.2324667
2518,195.3968,9.1940393,6.1505022,0.0,0,3.4145288,0.0,0.52766323,69.030746,3.8001201,406.77945,-9.2321081
2519,195.397,9.2295675,6.1710625,0.0,0,3.3967807,0.0,0.52989751,69.161842,3.7799573,406.55685,-9.232317
2520,195.3972,9.2497358,6.1944866,0.0,0,3.3790326,0.0,0.53156692,69.193748,3.762321,406.33423,-9.2319994
2521,195.3974,9.2627268,6.2039967,0.0,0,3.3612847,0.0,0.53362304,69.132454,3.7450223,406.11163,-9.2307806
2522,195.3976,9.2710886,6.2249827,0.0,0,3.3435369,0.0,0.53613752,69.036598,3.7278366,405.88904,-9.2294426
2523,195.3978,9.2792349,6.2521877,0.0,0,3.3257887,0.0,0.53798258,68.993813,3.7109554,405.66644,-9.2283707
2524,195.398,9.2965012,6.2623944,0.0,0,3.3080409,0.0,0.53989875,68.992172,3.6925554,405.44382,-9.2288857
2525,195.3982,9.3145313,6.2810359,0.0,0,3.2902927,0.0,0.54260099,68.945221,3.6720626,405.22122,-9.2300797
2526,195.3984,9.3354464,6.3077941,0.0,0,3.2725446,0.0,0.54449707,68.960854,3.6528411,404.99863,-9.2307043
2527,195.3986,9.367568,6.3178458,0.0,0,3.2547965,0.0,0.54619187,69.028854,3.63381,404.77603,-9.230999
2528,195.3988,9.4024382,6.335041,0.0,0,3.2370486,0.0,0.54903191,69.078255,3.6148269,404.54562,-9.2313585
2529,195.399,9.4398117,6.3626337,0.0,0,3.2193007,0.0,0.55110162,69.207359,3.5985539,404.24515,-9.2311058
2530,195.3992,9.4647675,6.3742332,0.0,0,3.2015526,0.0,0.55254626,69.310486,3.5808346,403.94467,-9.2308998
2531,195.3994,9.4747553,6.3901591,0.0,0,3.1838048,0.0,0.55533606,69.230339,3.562114,403.6442,-9.2308884
2532,195.3996,9.4810371,6.4164691,0.0,0,3.1660566,0.0,0.55752909,69.114647,3.5436127,403.34372,-9.2300873
2533,195.3998,9.4814138,6.4286051,0.0,0,3.1483088,0.0,0.55869311,69.049568,3.5253189,403.04324,-9.2297792
2534,195.4,9.4927521,6.4428511,0.0,0,3.1309152,0.0,0.56138659,68.912773,3.5084481,402.74277,-9.2301655
2535,195.4002,9.5161839,6.4685316,0.0,0,3.11395,0.0,0.56386554,68.898926,3.4927025,402.44229,-9.2297096
2536,195.4004,9.5482788,6.4836559,0.0,0,3.0970623,0.0,0.56504947,69.061264,3.4749198,402.14178,-9.2287836
2537,195.4006,9.5835752,6.4975386,0.0,0,3.0801783,0.0,0.56772137,69.130745,3.4548531,401.84131,-9.2289038
2538,195.4008,9.61868,6.5209208,0.0,0,3.0632944,0.0,0.57037926,69.204147,3.4372387,401.54083,-9.2301702
2539,195.401,9.6534271,6.5382342,0.0,0,3.0464106,0.0,0.57150882,69.331619,3.4224262,401.24036,-9.2309628
2540,195.4012,9.6714916,6.5536995,0.0,0,3.0295265,0.0,0.57410622,69.306923,3.4044187,400.93988,-9.2310877
2541,195.4014,9.6838398,6.5762448,0.0,0,3.0126424,0.0,0.57703876,69.222717,3.3840058,400.6394,-9.231225
2542,195.4016,9.6945648,6.5943518,0.0,0,2.9957583,0.0,0.57823873,69.209312,3.3655782,400.33893,-9.2306395
2543,195.4018,9.7093611,6.6078668,0.0,0,2.9788744,0.0,0.58051562,69.17318,3.3484709,400.03845,-9.2300167
2544,195.402,9.7322769,6.6268191,0.0,0,2.9619906,0.0,0.58330494,69.127434,3.3316264,399.73798,-9.2302551
2545,195.4022,9.7507401,6.6466951,0.0,0,2.9451065,0.0,0.58458978,69.173096,3.3139405,399.4375,-9.2297115
2546,195.4024,9.7824774,6.6618943,0.0,0,2.9282222,0.0,0.58674252,69.194725,3.2943559,399.13702,-9.2289619
2547,195.4026,9.8188772,6.6793423,0.0,0,2.9113381,0.0,0.5895946,69.222755,3.275053,398.83652,-9.2286587
2548,195.4028,9.8476057,6.701025,0.0,0,2.8944542,0.0,0.59115523,69.385643,3.2588871,398.53604,-9.2289152
2549,195.403,9.8775444,6.7176061,0.0,0,2.8775704,0.0,0.5932104,69.455238,3.2413232,398.23557,-9.2295065
2550,195.4032,9.8988705,6.731914,0.0,0,2.8606863,0.0,0.59601724,69.422852,3.2225513,397.93509,-9.2302122
2551,195.4034,9.9117908,6.7543302,0.0,0,2.8438022,0.0,0.59780711,69.415497,3.2042124,397.63461,-9.2316065
2552,195.4036,9.9322786,6.7730799,0.0,0,2.8269184,0.0,0.59967667,69.380341,3.1861901,397.33414,-9.2310228
2553,195.4038,9.9561996,6.7849903,0.0,0,2.810034,0.0,0.60238111,69.352501,3.1679282,397.03366,-9.2299271
2554,195.404,9.9783955,6.8074474,0.0,0,2.7931502,0.0,0.60439372,69.385185,3.1500261,396.73318,-9.2305756
2555,195.4042,9.9984903,6.8278751,0.0,0,2.7762663,0.0,0.60616714,69.39167,3.1325092,396.43271,-9.2309637
2556,195.4044,10.017279,6.8377166,0.0,0,2.7593822,0.0,0.6086992,69.35981,3.1141043,396.13223,-9.2303801
2557,195.4046,10.047338,6.859005,0.0,0,2.7424984,0.0,0.61087549,69.38588,3.0990093,395.83176,-9.2298241
2558,195.4048,10.081606,6.8818464,0.0,0,2.7256143,0.0,0.61258835,69.503944,3.0825865,395.53128,-9.2296553
2559,195.405,10.115335,6.8913326,0.0,0,2.7090683,0.0,0.61492044,69.620224,3.0634274,395.23077,-9.2294693
2560,195.4052,10.146979,6.9120445,0.0,0,2.6929309,0.0,0.61750644,69.651352,3.0447462,394.9303,-9.2296562
2561,195.4054,10.166081,6.9372554,0.0,0,2.6768677,0.0,0.61942172,69.628014,3.0266669,394.62982,-9.2297335
2562,195.4056,10.182142,6.9448667,0.0,0,2.6608074,0.0,0.62145674,69.578728,3.0114446,394.32935,-9.2301388
2563,195.4058,10.201536,6.9629478,0.0,0,2.6447473,0.0,0.62414652,69.551239,2.9960454,394.02887,-9.2306471
2564,195.406,10.217093,6.9892387,0.0,0,2.6286874,0.0,0.62602538,69.563362,2.9768584,393.72839,-9.2307434
2565,195.4062,10.239722,6.9977698,0.0,0,2.6126273,0.0,0.62778258,69.573143,2.9567995,393.42792,-9.2304106
2566,195.4064,10.27552,7.0150113,0.0,0,2.5965672,0.0,0.63070583,69.568748,2.9396446,393.12744,-9.2308884
2567,195.4066,10.322404,7.0407667,0.0,0,2.5805073,0.0,0.63265425,69.737328,2.9209785,392.82697,-9.2312794
2568,195.4068,10.358036,7.0497847,0.0,0,2.5644474,0.0,0.63412112,69.917572,2.9035144,392.52649,-9.2306213
2569,195.407,10.38706,7.0655727,0.0,0,2.5483873,0.0,0.63711751,69.90596,2.8897734,392.22601,-9.2300234
2570,195.4072,10.415547,7.0925307,0.0,0,2.5323272,0.0,0.63931912,69.974312,2.8733306,391.92551,-9.2302485
2571,195.4074,10.434487,7.104733,0.0,0,2.5162673,0.0,0.64081293,70.019653,2.8551276,391.62503,-9.2314482
2572,195.4076,10.449436,7.120213,0.0,0,2.5002072,0.0,0.64401418,69.853241,2.8379865,391.32455,-9.2308226
2573,195.4078,10.466427,7.1468511,0.0,0,2.4841473,0.0,0.64654058,69.790077,2.8206561,391.02408,-9.2301817
2574,195.408,10.495759,7.1599212,0.0,0,2.4680872,0.0,0.64775723,69.887123,2.8039558,390.7236,-9.2306786
2575,195.4082,10.520288,7.1724834,0.0,0,2.4520273,0.0,0.65058196,69.858681,2.7868383,390.42313,-9.2301655
2576,195.4084,10.542256,7.1966543,0.0,0,2.4359674,0.0,0.65318429,69.832199,2.7690887,390.12265,-9.2296162
2577,195.4086,10.578853,7.2115602,0.0,0,2.4199073,0.0,0.65426081,69.977394,2.7528858,389.82217,-9.2301397
2578,195.4088,10.624364,7.2238364,0.0,0,2.4038472,0.0,0.65696526,70.098465,2.7367811,389.5217,-9.230691
2579,195.409,10.660372,7.2460618,0.0,0,2.3877873,0.0,0.6598205,70.152733,2.7195032,389.09933,-9.2305908
2580,195.4092,10.68996,7.2614717,0.0,0,2.3717272,0.0,0.66086626,70.249649,2.7010906,388.67694,-9.2303171
2581,195.4094,10.714562,7.2732873,0.0,0,2.3556671,0.0,0.66330129,70.232521,2.6817269,388.25458,-9.2298832
2582,195.4096,10.71842,7.2939267,0.0,0,2.3396072,0.0,0.66624641,70.094719,2.6663311,387.83221,-9.2295513
2583,195.4098,10.731569,7.3126531,0.0,0,2.3235474,0.0,0.66750509,70.108604,2.6503789,387.40985,-9.2295141
2584,195.41,10.764451,7.3264289,0.0,0,2.3078089,0.0,0.66983819,70.141319,2.6333923,386.98749,-9.2295122
2585,195.4102,10.792628,7.3452601,0.0,0,2.2924595,0.0,0.67298043,70.090179,2.6165173,386.56512,-9.229497
2586,195.4104,10.831127,7.3657532,0.0,0,2.2771804,0.0,0.674474,70.18071,2.5980959,386.14276,-9.229495
2587,195.4106,10.873533,7.3798766,0.0,0,2.2619042,0.0,0.67654377,70.323395,2.5812013,385.72037,-9.2295332
2588,195.4108,10.914667,7.3942037,0.0,0,2.246628,0.0,0.67951018,70.4216,2.5638907,385.298,-9.2292986
2589,195.411,10.960412,7.4155817,0.0,0,2.2313523,0.0,0.68113321,70.56842,2.5468352,384.87564,-9.2292519
2590,195.4112,10.991529,7.4320669,0.0,0,2.2160764,0.0,0.68315148,70.626617,2.5311294,384.45328,-9.2294893
2591,195.4114,11.008105,7.4440432,0.0,0,2.2008004,0.0,0.68612003,70.55381,2.5149601,384.03091,-9.2301044
2592,195.4116,11.020458,7.4659305,0.0,0,2.1855242,0.0,0.6881389,70.523689,2.4966543,383.60855,-9.2305908
2593,195.4118,11.034185,7.4842868,0.0,0,2.1702483,0.0,0.69003099,70.486153,2.4774702,383.18619,-9.2307482
2594,195.412,11.058881,7.4949074,0.0,0,2.1549723,0.0,0.69279814,70.407272,2.459758,382.76379,-9.2304058
2595,195.4122,11.088056,7.5170383,0.0,0,2.1396964,0.0,0.6950866,70.45034,2.443938,382.34143,-9.2295818
2596,195.4124,11.129439,7.5374079,0.0,0,2.1244202,0.0,0.69680935,70.593834,2.426816,381.91907,-9.229701
2597,195.4126,11.176691,7.5455418,0.0,0,2.1091442,0.0,0.69934851,70.693497,2.4105213,381.4967,-9.2297611
2598,195.4128,11.216068,7.5660491,0.0,0,2.0938683,0.0,0.70190167,70.755966,2.3937798,381.07434,-9.2290211
2599,195.413,11.253236,7.5890064,0.0,0,2.0785923,0.0,0.70369875,70.845665,2.3760345,380.65198,-9.2287893
2600,195.4132,11.279093,7.5963063,0.0,0,2.0633163,0.0,0.70595223,70.880478,2.3588247,380.22961,-9.2286253
2601,195.4134,11.307074,7.6148233,0.0,0,2.0480404,0.0,0.70857501,70.878784,2.3417776,379.80725,-9.2284298
2602,195.4136,11.327814,7.6397629,0.0,0,2.0327644,0.0,0.71049666,70.869568,2.3277521,379.38486,-9.2284594
2603,195.4138,11.344763,7.647059,0.0,0,2.0174885,0.0,0.71257943,70.822357,2.3119884,378.96249,-9.2288437
2604,195.414,11.37105,7.663506,0.0,0,2.0022123,0.0,0.71546108,70.76767,2.2946577,378.54013,-9.2298851
2605,195.4142,11.399725,7.6876926,0.0,0,1.9869361,0.0,0.71725267,70.827385,2.2777805,378.11777,-9.2306366
2606,195.4144,11.446071,7.6945748,0.0,0,1.9716601,0.0,0.71879834,70.982208,2.2611947,377.6954,-9.2309723
2607,195.4146,11.501787,7.7095914,0.0,0,1.9563841,0.0,0.72183686,71.06601,2.2436268,377.27304,-9.2303724
2608,195.4148,11.547953,7.7348399,0.0,0,1.9411081,0.0,0.72386116,71.207794,2.2266009,376.85068,-9.2297602
2609,195.415,11.575118,7.7434907,0.0,0,1.9261373,0.0,0.72521847,71.319572,2.2116287,376.42828,-9.2296295
2610,195.4152,11.590631,7.7573953,0.0,0,1.9115355,0.0,0.72838604,71.21109,2.1942248,376.00592,-9.2293034
2611,195.4154,11.612369,7.7835274,0.0,0,1.8970004,0.0,0.73081571,71.127739,2.1804852,375.58356,-9.2293882
2612,195.4156,11.634621,7.794744,0.0,0,1.8824685,0.0,0.73212564,71.201149,2.1657002,375.16119,-9.2292862
2613,195.4158,11.651999,7.8081803,0.0,0,1.8679364,0.0,0.73531979,71.140739,2.1486318,374.73883,-9.229888
2614,195.416,11.677063,7.8334422,0.0,0,1.8534043,0.0,0.73805988,71.048523,2.1337104,374.31647,-9.2301655
2615,195.4162,11.712579,7.8457255,0.0,0,1.8388724,0.0,0.73916692,71.124382,2.1165483,373.8941,-9.229497
2616,195.4164,11.764567,7.8568101,0.0,0,1.8243403,0.0,0.7420941,71.239273,2.1013246,373.47171,-9.2294874
2617,195.4166,11.817236,7.8788991,0.0,0,1.8098084,0.0,0.74487036,71.371658,2.0880466,373.04935,-9.2290668
2618,195.4168,11.855333,7.8927469,0.0,0,1.7952764,0.0,0.74574482,71.530083,2.0741272,372.62698,-9.2290459
2619,195.417,11.877546,7.9026337,0.0,0,1.7807443,0.0,0.74831605,71.513237,2.0567148,372.20462,-9.2294655
2620,195.4172,11.889163,7.9211664,0.0,0,1.7662123,0.0,0.75120801,71.410751,2.0380309,371.78226,-9.2300205
2621,195.4174,11.904246,7.9370842,0.0,0,1.7516804,0.0,0.75209308,71.446121,2.0227234,371.35989,-9.2301836
2622,195.4176,11.929,7.9488807,0.0,0,1.7371484,0.0,0.75451279,71.425354,2.0068641,370.93753,-9.2297363
2623,195.4178,11.962191,7.9669027,0.0,0,1.7226164,0.0,0.75770539,71.38279,1.9915797,370.51514,-9.2294931
2624,195.418,11.996372,7.9845891,0.0,0,1.7080843,0.0,0.75885415,71.487144,1.976482,370.09277,-9.2295609
2625,195.4182,12.0411,7.9969478,0.0,0,1.6935524,0.0,0.76109362,71.594795,1.9617258,369.67041,-9.2296591
2626,195.4184,12.092661,8.0123453,0.0,0,1.6790204,0.0,0.76432973,71.648102,1.9470054,369.24805,-9.2291946
2627,195.4186,12.132433,8.0317106,0.0,0,1.6644883,0.0,0.76573402,71.787567,1.9299065,368.82568,-9.2286291
2628,195.4188,12.170657,8.0453901,0.0,0,1.6499563,0.0,0.7678144,71.886917,1.9133435,368.40332,-9.2294283
2629,195.419,12.20484,8.0573864,0.0,0,1.6354244,0.0,0.77095532,71.854065,1.8994633,368.51459,-9.2297506
2630,195.4192,12.229379,8.0782614,0.0,0,1.6208923,0.0,0.77262074,71.874016,1.8848085,368.68518,-9.2292452
2631,195.4194,12.251572,8.0937967,0.0,0,1.6063604,0.0,0.7745164,71.89431,1.8685256,368.85574,-9.2294664
2632,195.4196,12.279709,8.1025248,0.0,0,1.5918283,0.0,0.77741969,71.83709,1.8520535,369.02631,-9.2294912
2633,195.4198,12.313707,8.1226549,0.0,0,1.5772964,0.0,0.77931958,71.901291,1.8390718,369.19687,-9.2296438
2634,195.42,12.350228,8.139122,0.0,0,1.5630548,0.0,0.78090197,72.00106,1.8238715,369.36743,-9.2295351
2635,195.4202,12.386234,8.1457872,0.0,0,1.5491644,0.0,0.78363627,72.015167,1.8071822,369.53799,-9.2293568
2636,195.4204,12.430019,8.1656799,0.0,0,1.5353373,0.0,0.78593302,72.090393,1.7919657,369.70859,-9.229475
2637,195.4206,12.477239,8.1857777,0.0,0,1.5215132,0.0,0.78758264,72.226654,1.7761307,369.87915,-9.228755
2638,195.4208,12.518663,8.1927271,0.0,0,1.5076892,0.0,0.79017085,72.273102,1.7632109,370.04971,-9.2280855
2639,195.421,12.554075,8.2118292,0.0,0,1.4938653,0.0,0.79286438,72.291077,1.7500688,370.22028,-9.228179
2640,195.4212,12.579419,8.2337303,0.0,0,1.4800413,0.0,0.79459822,72.322571,1.7366358,370.39084,-9.2294636
2641,195.4214,12.614951,8.2385015,0.0,0,1.4662173,0.0,0.79657799,72.341599,1.7183254,370.56143,-9.2298899
2642,195.4216,12.648431,8.2541866,0.0,0,1.4523933,0.0,0.79926986,72.368797,1.702323,370.73199,-9.2299976
2643,195.4218,12.679873,8.2766552,0.0,0,1.4385693,0.0,0.800951,72.438583,1.6908282,370.90256,-9.2302523
2644,195.422,12.72107,8.2811098,0.0,0,1.4247453,0.0,0.8026281,72.536682,1.6746016,371.07312,-9.2295246
2645,195.4222,12.768445,8.296133,0.0,0,1.4109213,0.0,0.80570769,72.574188,1.6597501,371.24368,-9.2288694
2646,195.4224,12.8122,8.3205128,0.0,0,1.3970973,0.0,0.80766571,72.707603,1.6482148,371.41425,-9.2281475
2647,195.4226,12.852945,8.3265486,0.0,0,1.3832734,0.0,0.80914772,72.851334,1.6319928,371.58484,-9.227973
2648,195.4228,12.899143,8.3403816,0.0,0,1.3694494,0.0,0.81243259,72.848518,1.6157466,371.7554,-9.2277842
2649,195.423,12.937136,8.3658495,0.0,0,1.3556253,0.0,0.81474429,72.891266,1.6022896,371.92596,-9.2277985
2650,195.4232,12.962575,8.3742361,0.0,0,1.3418013,0.0,0.81612182,72.941704,1.5886581,372.09653,-9.2284689
2651,195.4234,12.990583,8.3863602,0.0,0,1.3279774,0.0,0.81933421,72.863426,1.5745369,372.26709,-9.2288561
2652,195.4236,13.023809,8.4112835,0.0,0,1.3141534,0.0,0.82187086,72.858154,1.5592933,372.43768,-9.229229
2653,195.4238,13.060037,8.4212294,0.0,0,1.3003293,0.0,0.82298988,72.956963,1.5431837,372.60825,-9.229063
2654,195.424,13.095668,8.4306097,0.0,0,1.2865053,0.0,0.82586718,72.94825,1.5271444,372.77881,-9.2287312
2655,195.4242,13.140107,8.4517088,0.0,0,1.2726814,0.0,0.82842153,73.000435,1.5141526,372.94937,-9.2288132
2656,195.4244,13.192085,8.4616003,0.0,0,1.2588574,0.0,0.82908094,73.194763,1.5017689,373.11993,-9.2279835
2657,195.4246,13.239099,8.4701052,0.0,0,1.2450334,0.0,0.83180678,73.281967,1.4866199,373.2905,-9.2278376
2658,195.4248,13.286489,8.4906988,0.0,0,1.2312094,0.0,0.8348316,73.356392,1.4710915,373.46109,-9.2282658
2659,195.425,13.32876,8.5048037,0.0,0,1.2176627,0.0,0.83563125,73.541267,1.4560225,373.63165,-9.2278996
2660,195.4252,13.362812,8.5142183,0.0,0,1.2044513,0.0,0.83829713,73.570236,1.4411384,373.80222,-9.2278099
2661,195.4254,13.400219,8.532773,0.0,0,1.1913006,0.0,0.84149653,73.532494,1.4276564,373.97278,-9.2274923
2662,195.4256,13.437653,8.5484886,0.0,0,1.1781524,0.0,0.84244192,73.653839,1.4130646,374.14334,-9.2272282
2663,195.4258,13.467337,8.558691,0.0,0,1.1650045,0.0,0.84493864,73.660088,1.398356,374.31393,-9.2278376
2664,195.426,13.509356,8.5753469,0.0,0,1.1518564,0.0,0.84823507,73.612053,1.3863194,374.4845,-9.2279835
2665,195.4262,13.561711,8.5927134,0.0,0,1.1387084,0.0,0.84935856,73.762794,1.3739369,374.65506,-9.2284422
2666,195.4264,13.612386,8.6039982,0.0,0,1.1255604,0.0,0.85153532,73.895958,1.3589894,374.82562,-9.2285051
2667,195.4266,13.666462,8.6168613,0.0,0,1.1124125,0.0,0.8549062,73.978668,1.3441417,374.99619,-9.2279654
2668,195.4268,13.718791,8.6354723,0.0,0,1.0992644,0.0,0.85631031,74.15377,1.3296474,375.16675,-9.2277536
2669,195.427,13.761465,8.6477699,0.0,0,1.0861164,0.0,0.85811657,74.213875,1.3144069,375.33734,-9.2284565
2670,195.4272,13.798362,8.6563292,0.0,0,1.0729684,0.0,0.86109293,74.18293,1.2995458,375.5079,-9.2285204
2671,195.4274,13.833207,8.6744232,0.0,0,1.0598203,0.0,0.86272627,74.291977,1.286783,375.67847,-9.2280111
2672,195.4276,13.868078,8.6890392,0.0,0,1.0466723,0.0,0.8644439,74.34761,1.2743305,375.84903,-9.2287073
2673,195.4278,13.904931,8.6968794,0.0,0,1.0335244,0.0,0.86746866,74.308571,1.258852,376.01959,-9.2292891
2674,195.428,13.948631,8.7168655,0.0,0,1.0203763,0.0,0.8697722,74.363388,1.2456023,376.19019,-9.2294092
2675,195.4282,13.997931,8.7345943,0.0,0,1.0072284,0.0,0.87149704,74.505302,1.2318453,376.36075,-9.229125
2676,195.4284,14.048684,8.7410231,0.0,0,0.99408036,0.0,0.87436986,74.57811,1.214528,376.53131,-9.2287884
2677,195.4286,14.10381,8.7596483,0.0,0,0.98093235,0.0,0.87693173,74.630974,1.2001742,376.70187,-9.2277565
2678,195.4288,14.152593,8.7780905,0.0,0,0.96778435,0.0,0.8783958,74.788376,1.18782,376.87244,-9.2266655
2679,195.429,14.196479,8.7820148,0.0,0,0.95463634,0.0,0.88064384,74.875,1.174479,376.90366,-9.2269897
2680,195.4292,14.233192,8.7976294,0.0,0,0.94148839,0.0,0.88323754,74.852005,1.1615313,376.90002,-9.2276211
2681,195.4294,14.265334,8.8174934,0.0,0,0.92834044,0.0,0.88458198,74.938431,1.147289,376.89639,-9.227767
2682,195.4296,14.300334,8.8207216,0.0,0,0.91519243,0.0,0.8865068,74.989197,1.1331207,376.89276,-9.2284222
2683,195.4298,14.338512,8.8357401,0.0,0,0.90204442,0.0,0.88972127,74.943047,1.120164,376.88913,-9.2287931
2684,195.43,14.384762,8.859457,0.0,0,0.88916051,0.0,0.89164406,75.043007,1.1069825,376.8855,-9.2287207
2685,195.4302,14.436479,8.8642998,0.0,0,0.87659609,0.0,0.8933171,75.187759,1.0935065,376.88187,-9.2287235
2686,195.4304,14.501136,8.8774519,0.0,0,0.86408949,0.0,0.89667386,75.25798,1.0789127,376.87823,-9.2288265
2687,195.4306,14.567176,8.9012766,0.0,0,0.85158539,0.0,0.89872134,75.440399,1.0658749,376.8746,-9.2285862
2688,195.4308,14.620369,8.9069052,0.0,0,0.83908135,0.0,0.89997864,75.637726,1.0531914,376.871,-9.2280149
2689,195.431,14.659452,8.9180079,0.0,0,0.82657731,0.0,0.90327662,75.609512,1.040692,376.86737,-9.2278004
2690,195.4312,14.692296,8.9411373,0.0,0,0.81407332,0.0,0.90544134,75.643715,1.0272375,376.86374,-9.2270336
2691,195.4314,14.722663,8.9470348,0.0,0,0.8015694,0.0,0.90633011,75.721832,1.0132378,376.86011,-9.2266321
2692,195.4316,14.756413,8.955636,0.0,0,0.78906536,0.0,0.90949833,75.632164,0.99889845,376.85648,-9.226903
2693,195.4318,14.801137,8.977581,0.0,0,0.77656138,0.0,0.91202754,75.663643,0.98596019,376.85284,-9.2274084
2694,195.432,14.85354,8.9863882,0.0,0,0.7640574,0.0,0.91273296,75.877197,0.97128326,376.84921,-9.2281466
2695,195.4322,14.915926,8.9951382,0.0,0,0.75155336,0.0,0.91588533,75.95208,0.95676214,376.84558,-9.2282648
2696,195.4324,14.983536,9.0151081,0.0,0,0.73904938,0.0,0.91882443,76.051331,0.94477552,376.84195,-9.2284193
2697,195.4326,15.048996,9.0265675,0.0,0,0.72654539,0.0,0.91938186,76.331497,0.93218249,376.83832,-9.2287149
2698,195.4328,15.105977,9.0350151,0.0,0,0.71404135,0.0,0.92229474,76.41404,0.91739601,376.83469,-9.2281084
2699,195.433,15.143716,9.0540504,0.0,0,0.70153737,0.0,0.92559439,76.386223,0.90303302,376.83105,-9.2277546
2700,195.4332,15.172812,9.0688229,0.0,0,0.68903339,0.0,0.92644286,76.47728,0.89007568,376.82742,-9.2273922
2701,195.4334,15.212996,9.0778446,0.0,0,0.67652941,0.0,0.92912412,76.422379,0.87730128,376.82382,-9.226615
2702,195.4336,15.258016,9.0936947,0.0,0,0.66402543,0.0,0.93243569,76.397095,0.86621392,376.82019,-9.2264013
2703,195.4338,15.314579,9.1086178,0.0,0,0.65152138,0.0,0.9333266,76.624252,0.85208398,376.81656,-9.227088
2704,195.434,15.379038,9.1178246,0.0,0,0.63901734,0.0,0.93562526,76.759621,0.83837312,376.81293,-9.2278299
2705,195.4342,15.445056,9.1311493,0.0,0,0.62651336,0.0,0.9390974,76.825996,0.82590818,376.8093,-9.2273512
2706,195.4344,15.517877,9.1481686,0.0,0,0.61400938,0.0,0.94021177,77.101936,0.81160265,376.80566,-9.2280769
2707,195.4346,15.581903,9.1584969,0.0,0,0.6015054,0.0,0.94221312,77.271843,0.79873413,376.80203,-9.2285662
2708,195.4348,15.630108,9.1687479,0.0,0,0.58900136,0.0,0.94564706,77.239288,0.78559166,376.7984,-9.227663
2709,195.435,15.669515,9.1868992,0.0,0,0.57674509,0.0,0.947146,77.335236,0.77291512,376.79477,-9.2270708
2710,195.4352,15.713067,9.1992903,0.0,0,0.56478846,0.0,0.94885409,77.401848,0.76000601,376.79114,-9.2264957
2711,195.4354,15.757386,9.2063026,0.0,0,0.55288601,0.0,0.95195335,77.376114,0.74740028,376.78751,-9.2262993
2712,195.4356,15.800683,9.2237778,0.0,0,0.54098594,0.0,0.95376277,77.464417,0.73383814,376.78387,-9.2264633
2713,195.4358,15.857285,9.2377281,0.0,0,0.52908593,0.0,0.95527244,77.631691,0.71790779,376.78027,-9.2265368
2714,195.436,15.924194,9.2431517,0.0,0,0.51718587,0.0,0.95830685,77.744797,0.70424592,376.77664,-9.2263718
2715,195.4362,15.997871,9.2612696,0.0,0,0.50528592,0.0,0.96050858,77.901146,0.69129264,376.77301,-9.2261276
2716,195.4364,16.069239,9.2786169,0.0,0,0.49338591,0.0,0.96196193,78.113869,0.67758143,376.76938,-9.2261124
2717,195.4366,16.126459,9.2829018,0.0,0,0.4814859,0.0,0.96478665,78.197784,0.66517568,376.76575,-9.2258396
2718,195.4368,16.174948,9.2994919,0.0,0,0.4695859,0.0,0.96755856,78.212685,0.65316153,376.76212,-9.2265568
2719,195.437,16.222639,9.3197613,0.0,0,0.45768592,0.0,0.96915096,78.300003,0.63834107,376.75848,-9.2271614
2720,195.4372,16.271708,9.3235121,0.0,0,0.44578591,0.0,0.97146046,78.364075,0.62281972,376.75485,-9.2264719
2721,195.4374,16.31776,9.3382406,0.0,0,0.4338859,0.0,0.97457057,78.345757,0.61074322,376.75122,-9.2258501
2722,195.4376,16.37167,9.3600216,0.0,0,0.42198589,0.0,0.97637963,78.448364,0.59898674,376.74759,-9.2256794
2723,195.4378,16.433598,9.3623743,0.0,0,0.41008592,0.0,0.97832227,78.592842,0.58557612,376.74396,-9.2261839
2724,195.438,16.49581,9.3752804,0.0,0,0.39818591,0.0,0.9816187,78.616501,0.5739972,376.74033,-9.2255154
2725,195.4382,16.567881,9.39816,0.0,0,0.3862859,0.0,0.98335278,78.811333,0.5612694,376.73669,-9.2248859
2726,195.4384,16.630096,9.4016809,0.0,0,0.37438589,0.0,0.98483485,78.986534,0.549142,376.73309,-9.2263823