File: clean data/testID_0098.csv
level_0,index,Time(sec),Force(kN),Jaw(mm),PowAngle(deg),Power(W),Pram,PTemp,Strain,Stress(MPa),Stroke(mm),TC1(C),wedge(mm)
2105,2105,178.677,0.81891006,0.017636571,0.0,0,9.0629702,0.0,0.0010582268,10.150216,10.100879,404.95715,-9.2662706
2106,2106,178.6772,1.4236101,0.023499385,0.0,0,9.0337057,0.0,0.0012903885,15.746483,10.06666,405.13882,-9.2661123
2107,2107,178.6774,3.0199969,0.036370277,0.0,0,9.0044422,0.0,0.0024545335,33.741337,10.038028,405.3205,-9.2657757
2108,2108,178.6776,4.6687961,0.065871887,0.0,0,8.9751778,0.0,0.0040054088,55.394241,10.015702,405.50217,-9.2656126
2109,2109,178.6778,5.5451922,0.092684902,0.0,0,8.9459143,0.0,0.0056712711,68.610764,9.993041,405.68381,-9.2652216
2110,2110,178.678,5.8313594,0.10455924,0.0,0,8.9166498,0.0,0.0070495373,73.271873,9.9658022,405.86548,-9.2639065
2111,2111,178.6782,6.0070162,0.13290071,0.0,0,8.8873854,0.0,0.0085376827,75.405014,9.9331284,406.04715,-9.2625237
2112,2112,178.6784,6.2513413,0.18686315,0.0,0,8.8581219,0.0,0.011476192,78.170723,9.8953428,406.22882,-9.2618837
2113,2113,178.6786,6.2662163,0.24797876,0.0,0,8.8288574,0.0,0.015952457,78.614517,9.8579845,406.41049,-9.2617865
2114,2114,178.6788,6.1137977,0.30746874,0.0,0,8.7995939,0.0,0.020145966,76.549927,9.8175268,406.59216,-9.2618837
2115,2115,178.679,6.26123,0.34598222,0.0,0,8.7703295,0.0,0.022640968,77.215057,9.772068,406.77383,-9.2625389
2116,2116,178.6792,6.6945086,0.36437088,0.0,0,8.7416534,0.0,0.024334673,82.085648,9.7278299,406.95551,-9.262991
2117,2117,178.6794,6.8722763,0.40565988,0.0,0,8.7136869,0.0,0.026926218,84.885223,9.6841831,407.13718,-9.2622681
2118,2118,178.6796,6.8538823,0.46601534,0.0,0,8.6858492,0.0,0.030445045,84.600296,9.6408138,407.31885,-9.2615023
2119,2119,178.6798,7.029717,0.50140768,0.0,0,8.6580172,0.0,0.033527203,85.911118,9.6012697,407.50052,-9.2613258
2120,2120,178.68,7.2456665,0.51605195,0.0,0,8.6301851,0.0,0.03512175,88.597061,9.5645437,407.68219,-9.2610683
2121,2121,178.6802,7.1559186,0.52542728,0.0,0,8.6023531,0.0,0.035303213,88.462997,9.5295219,407.86383,-9.2609816
2122,2122,178.6804,6.801661,0.54113728,0.0,0,8.5745211,0.0,0.036221776,84.393738,9.4989119,408.0455,-9.2607889
2123,2123,178.6806,6.6725063,0.58921748,0.0,0,8.546689,0.0,0.039552238,81.621216,9.4693575,408.22717,-9.2611895
2124,2124,178.6808,6.9817767,0.64427185,0.0,0,8.518857,0.0,0.043077581,84.123169,9.4400768,408.40884,-9.2621098
2125,2125,178.681,7.402637,0.66403544,0.0,0,8.491025,0.0,0.044899002,89.16568,9.4095373,408.59052,-9.2619534
2126,2126,178.6812,7.5966778,0.67448407,0.0,0,8.4631929,0.0,0.04606954,92.039787,9.3761148,408.77219,-9.2614975
2127,2127,178.6814,7.5786371,0.70600873,0.0,0,8.4353609,0.0,0.047588021,92.057961,9.3424702,408.95386,-9.2607355
2128,2128,178.6816,7.5462122,0.7530331,0.0,0,8.4075289,0.0,0.050513182,91.434357,9.3056612,409.13553,-9.2594376
2129,2129,178.6818,7.5187745,0.81367141,0.0,0,8.3796968,0.0,0.055172913,90.697182,9.2662563,409.3172,-9.2588501
2130,2130,178.682,7.4160981,0.86771923,0.0,0,8.3518648,0.0,0.059006672,89.185989,9.2288513,409.49887,-9.2591028
2131,2131,178.6822,7.2937064,0.89646703,0.0,0,8.3240328,0.0,0.060994972,87.502235,9.1896086,409.68054,-9.2597313
2132,2132,178.6824,7.3112473,0.92586309,0.0,0,8.2962008,0.0,0.063401178,87.157898,9.1471996,409.86221,-9.2607508
2133,2133,178.6826,7.4667544,0.96996516,0.0,0,8.2683687,0.0,0.066353604,88.551071,9.1058464,410.04388,-9.2611904
2134,2134,178.6828,7.6266298,1.0077195,0.0,0,8.2405367,0.0,0.068828426,90.350418,9.0659485,410.22552,-9.2612286
2135,2135,178.683,7.7057152,1.0328923,0.0,0,8.2127056,0.0,0.071160324,91.252174,9.0288181,410.4072,-9.261447
2136,2136,178.6832,7.7307997,1.0533289,0.0,0,8.1848736,0.0,0.072734334,91.522095,8.9958525,410.58887,-9.2608814
2137,2137,178.6834,7.7284741,1.0748758,0.0,0,8.1570406,0.0,0.073821142,91.446228,8.9647274,410.87985,-9.2599888
2138,2138,178.6836,7.6829767,1.1077551,0.0,0,8.1292095,0.0,0.076264694,90.771286,8.9325075,411.17084,-9.2596636
2139,2139,178.6838,7.6134624,1.1463174,0.0,0,8.1013775,0.0,0.079223625,89.685265,8.9020834,411.46179,-9.2598915
2140,2140,178.684,7.6017966,1.1762693,0.0,0,8.0735445,0.0,0.081067897,89.160881,8.8724709,411.75278,-9.259737
2141,2141,178.6842,7.7218952,1.1982018,0.0,0,8.0462675,0.0,0.082862906,90.152557,8.8426409,412.04373,-9.259655
2142,2142,178.6844,7.9164362,1.2245338,0.0,0,8.0196619,0.0,0.085012645,92.134514,8.8132486,412.33472,-9.2596712
2143,2143,178.6846,8.060771,1.2634993,0.0,0,7.993176,0.0,0.087248072,93.772842,8.7814989,412.62567,-9.2593813
2144,2144,178.6848,8.0846233,1.3066397,0.0,0,7.9666953,0.0,0.090369716,94.08036,8.7445946,412.91666,-9.2595501
2145,2145,178.685,8.0130072,1.3438339,0.0,0,7.9402156,0.0,0.093646072,93.138763,8.7093229,413.20761,-9.2595673
2146,2146,178.6852,7.942627,1.3808553,0.0,0,7.9137354,0.0,0.096007362,92.062393,8.674736,413.4986,-9.2599058
2147,2147,178.6854,7.9137182,1.4163294,0.0,0,7.8872552,0.0,0.098456502,91.389267,8.6403074,413.78955,-9.2602062
2148,2148,178.6856,7.9089665,1.4477158,0.0,0,7.860775,0.0,0.10130888,91.02758,8.6066608,414.08054,-9.2599621
2149,2149,178.6858,7.9284077,1.4864606,0.0,0,7.8342953,0.0,0.10382032,90.96904,8.5674896,414.37149,-9.2602282
2150,2150,178.686,7.9790964,1.5186675,0.0,0,7.8078156,0.0,0.10602658,91.237762,8.5303574,414.66248,-9.2602167
2151,2151,178.6862,8.0470562,1.5359185,0.0,0,7.7813349,0.0,0.10798558,91.800743,8.4997015,414.95346,-9.2593699
2152,2152,178.6864,8.106144,1.5618789,0.0,0,7.7548552,0.0,0.10966615,92.399063,8.4674387,415.24442,-9.2594156
2153,2153,178.6866,8.1320648,1.5946065,0.0,0,7.728375,0.0,0.11155728,92.597656,8.4352064,415.5354,-9.2599821
2154,2154,178.6868,8.1128283,1.6222862,0.0,0,7.7018952,0.0,0.11412016,92.177811,8.4058676,415.82635,-9.2599878
2155,2155,178.687,8.0868168,1.6587226,0.0,0,7.675415,0.0,0.11680689,91.653534,8.3789454,416.11734,-9.2594643
2156,2156,178.6872,8.1125774,1.693567,0.0,0,7.6489348,0.0,0.11892758,91.613647,8.3517895,416.40829,-9.2599354
2157,2157,178.6874,8.1990557,1.7098066,0.0,0,7.6224551,0.0,0.12074073,92.225174,8.3207235,416.69928,-9.2602825
2158,2158,178.6876,8.2927361,1.7346293,0.0,0,7.5959754,0.0,0.12274367,93.169762,8.2917175,416.99023,-9.2597122
2159,2159,178.6878,8.3342438,1.7716695,0.0,0,7.5694952,0.0,0.12483975,93.642509,8.2619619,417.28122,-9.2591896
2160,2160,178.688,8.3176584,1.8002415,0.0,0,7.543015,0.0,0.12729318,93.378494,8.2288389,417.57217,-9.2589569
2161,2161,178.6882,8.3101301,1.8362329,0.0,0,7.5165353,0.0,0.13032828,92.865997,8.1980705,417.86316,-9.2589273
2162,2162,178.6884,8.3408127,1.8750066,0.0,0,7.4900556,0.0,0.13277869,92.8507,8.1666031,418.15414,-9.258441
2163,2163,178.6886,8.3585253,1.8963901,0.0,0,7.4635754,0.0,0.13469949,93.009178,8.1341143,418.4451,-9.2588053
2164,2164,178.6888,8.3419924,1.924812,0.0,0,7.4370952,0.0,0.13723145,92.604622,8.1016026,418.73608,-9.2589006
2165,2165,178.689,8.3294516,1.9630781,0.0,0,7.410615,0.0,0.13954483,92.177971,8.0719318,419.02704,-9.2598419
2166,2166,178.6892,8.3686666,1.9870825,0.0,0,7.384666,0.0,0.14149255,92.392937,8.0433054,419.31802,-9.2611399
2167,2167,178.6894,8.434948,2.0114257,0.0,0,7.3593607,0.0,0.14388004,92.917038,8.0119925,419.60898,-9.2606802
2168,2168,178.6896,8.4717073,2.0409846,0.0,0,7.3341718,0.0,0.14570852,93.197731,7.9838133,419.89996,-9.2601261
2169,2169,178.6898,8.4575605,2.060905,0.0,0,7.3089876,0.0,0.14715257,92.999466,7.9537539,420.19092,-9.2600155
2170,2170,178.69,8.422019,2.0877063,0.0,0,7.2838035,0.0,0.14969012,92.433609,7.9257083,420.4819,-9.2598028
2171,2171,178.6902,8.4218845,2.1240852,0.0,0,7.2586198,0.0,0.15223219,92.080421,7.9015989,420.77286,-9.2597284
2172,2172,178.6904,8.4634438,2.1468737,0.0,0,7.2334356,0.0,0.15382022,92.28653,7.8738589,421.06384,-9.2591295
2173,2173,178.6906,8.509985,2.1654451,0.0,0,7.2082515,0.0,0.15580946,92.661133,7.8460736,421.3548,-9.2585678
2174,2174,178.6908,8.5583296,2.1923716,0.0,0,7.1830673,0.0,0.1577806,92.988129,7.8183174,421.64578,-9.2589846
2175,2175,178.691,8.6144371,2.2185802,0.0,0,7.1578832,0.0,0.15933634,93.396309,7.7887836,421.93677,-9.2597256
2176,2176,178.6912,8.6639099,2.2486365,0.0,0,7.132699,0.0,0.16204326,93.737946,7.759099,422.22772,-9.2599745
2177,2177,178.6914,8.6857805,2.2828698,0.0,0,7.1075149,0.0,0.16486782,93.730225,7.7325721,422.51871,-9.2595406
2178,2178,178.6916,8.6607828,2.3110468,0.0,0,7.0823312,0.0,0.16664006,93.340149,7.7070179,422.80966,-9.2592869
2179,2179,178.6918,8.6163044,2.3365848,0.0,0,7.0571475,0.0,0.16892099,92.73027,7.6782618,423.10065,-9.259593
2180,2180,178.692,8.6020012,2.3653533,0.0,0,7.0319633,0.0,0.17146106,92.233337,7.6496363,423.3916,-9.2599316
2181,2181,178.6922,8.6284685,2.3948517,0.0,0,7.0067787,0.0,0.17327915,92.237061,7.6224804,423.68259,-9.2603083
2182,2182,178.6924,8.6700106,2.4193163,0.0,0,6.981595,0.0,0.17538832,92.481125,7.5949993,423.97354,-9.2604628
2183,2183,178.6926,8.7175684,2.4401803,0.0,0,6.9564114,0.0,0.17753807,92.847855,7.5685062,424.26453,-9.2601805
2184,2184,178.6928,8.7572365,2.4646568,0.0,0,6.9312272,0.0,0.17894693,93.186455,7.5452199,424.55548,-9.2594824
2185,2185,178.693,8.7734375,2.4896207,0.0,0,6.9060431,0.0,0.18087441,93.16848,7.5203371,424.84647,-9.2584705
2186,2186,178.6932,8.7672758,2.5137713,0.0,0,6.8808589,0.0,0.18340214,92.975578,7.4934664,425.13742,-9.2582264
2187,2187,178.6934,8.7550678,2.5423405,0.0,0,6.8556757,0.0,0.18521881,92.738358,7.4659886,425.28333,-9.2586432
2188,2188,178.6936,8.7595854,2.5658422,0.0,0,6.8304915,0.0,0.18690297,92.549355,7.4385209,425.4292,-9.2586203
2189,2189,178.6938,8.7839756,2.5825479,0.0,0,6.8053074,0.0,0.18896244,92.512489,7.4147,425.5751,-9.2585058
2190,2190,178.694,8.8256044,2.6103423,0.0,0,6.7801232,0.0,0.19083415,92.705414,7.3900151,425.72101,-9.2587738
2191,2191,178.6942,8.8653383,2.6401203,0.0,0,6.7554412,0.0,0.1928215,92.970734,7.3639536,425.86688,-9.2593441
2192,2192,178.6944,8.8947344,2.6598597,0.0,0,6.7313666,0.0,0.19508846,93.127823,7.3395476,426.01279,-9.2592621
2193,2193,178.6946,8.9097748,2.6884038,0.0,0,6.7074018,0.0,0.19718085,93.117851,7.3137503,426.15869,-9.2592173
2194,2194,178.6948,8.9203386,2.7187593,0.0,0,6.6834412,0.0,0.19908497,93.008224,7.287046,426.30457,-9.2596693
2195,2195,178.695,8.9306622,2.7374926,0.0,0,6.6594815,0.0,0.20119072,92.929039,7.2615824,426.45047,-9.2593641
2196,2196,178.6952,8.9327593,2.7653906,0.0,0,6.6355214,0.0,0.20349517,92.82856,7.2373114,426.59634,-9.2594414
2197,2197,178.6954,8.9365215,2.7971704,0.0,0,6.6115613,0.0,0.20546004,92.675911,7.2126346,426.74225,-9.2598009
2198,2198,178.6956,8.9399662,2.813206,0.0,0,6.5876012,0.0,0.20732932,92.528694,7.1864018,426.88815,-9.2597399
2199,2199,178.6958,8.9562874,2.8360918,0.0,0,6.5636415,0.0,0.20941588,92.479042,7.1624875,427.03403,-9.2596064
2200,2200,178.696,8.9889593,2.8654852,0.0,0,6.5396814,0.0,0.21116601,92.62191,7.1388521,427.17993,-9.2599039
2201,2201,178.6962,9.0097198,2.8823247,0.0,0,6.5157218,0.0,0.21299614,92.666046,7.1132026,427.32584,-9.2598181
2202,2202,178.6964,9.0171413,2.9080675,0.0,0,6.4917617,0.0,0.21545258,92.516174,7.0870271,427.47171,-9.2601767
2203,2203,178.6966,9.0264759,2.9395347,0.0,0,6.467802,0.0,0.21738932,92.398903,7.0624719,427.61761,-9.2604103
2204,2204,178.6968,9.0561705,2.9544268,0.0,0,6.4438419,0.0,0.21886308,92.517807,7.0389428,427.76349,-9.2594175
2205,2205,178.697,9.103323,2.9754474,0.0,0,6.4198813,0.0,0.22105846,92.766701,7.0151377,427.90939,-9.2586937
2206,2206,178.6972,9.1395416,3.0064995,0.0,0,6.3959212,0.0,0.22300816,92.924644,6.991467,428.0553,-9.2588739
2207,2207,178.6974,9.1477337,3.0258379,0.0,0,6.3719611,0.0,0.22459826,92.888275,6.9661283,428.20117,-9.258872
2208,2208,178.6976,9.1381826,3.0503244,0.0,0,6.3480015,0.0,0.22717516,92.663673,6.9425435,428.34708,-9.258419
2209,2209,178.6978,9.1367311,3.0822456,0.0,0,6.3240414,0.0,0.22946376,92.572594,6.9204135,428.49295,-9.2584105
2210,2210,178.698,9.1530218,3.1022699,0.0,0,6.3000817,0.0,0.2309926,92.566109,6.893857,428.63885,-9.2588387
2211,2211,178.6982,9.1663713,3.1236181,0.0,0,6.2761216,0.0,0.23336969,92.390518,6.8661571,428.78476,-9.2595539
2212,2212,178.6984,9.1762409,3.1537125,0.0,0,6.252162,0.0,0.2356592,92.257294,6.8430657,428.93063,-9.2605991
2213,2213,178.6986,9.205389,3.1751873,0.0,0,6.2282019,0.0,0.23709704,92.428566,6.8189707,429.07654,-9.2613354
2214,2214,178.6988,9.2467766,3.194536,0.0,0,6.2042418,0.0,0.23932444,92.630936,6.7941141,429.22244,-9.2615271
2215,2215,178.699,9.2762394,3.2209446,0.0,0,6.1802816,0.0,0.24159309,92.766098,6.7730112,429.36832,-9.2608128
2216,2216,178.6992,9.2922039,3.2422006,0.0,0,6.1568022,0.0,0.242906,92.863121,6.7509837,429.51422,-9.2599173
2217,2217,178.6994,9.293437,3.2628641,0.0,0,6.1339045,0.0,0.24510825,92.616516,6.7247839,429.6601,-9.2596502
2218,2218,178.6996,9.2787819,3.2894328,0.0,0,6.1111116,0.0,0.24748918,92.22435,6.6993303,429.806,-9.2596283
2219,2219,178.6998,9.2759123,3.3131564,0.0,0,6.0883236,0.0,0.24885106,92.096016,6.6757164,429.9519,-9.2591887
2220,2220,178.7,9.3052053,3.3334877,0.0,0,6.0655355,0.0,0.2509113,92.155434,6.6533017,430.09778,-9.2590981
2221,2221,178.7002,9.3493366,3.3564723,0.0,0,6.042748,0.0,0.25326726,92.296623,6.6287861,430.24368,-9.2598448
2222,2222,178.7004,9.38764,3.3818681,0.0,0,6.0199599,0.0,0.25477454,92.519691,6.6063199,430.38959,-9.260004
2223,2223,178.7006,9.4194241,3.4062576,0.0,0,5.9971714,0.0,0.25697371,92.687134,6.5838733,430.53546,-9.2599955
2224,2224,178.7008,9.4357214,3.4294674,0.0,0,5.9743834,0.0,0.25958136,92.676399,6.55725,430.68137,-9.2599297
2225,2225,178.701,9.4514112,3.4554629,0.0,0,5.9515953,0.0,0.26123893,92.649162,6.5340481,430.82724,-9.2606173
2226,2226,178.7012,9.4590855,3.4787786,0.0,0,5.9288073,0.0,0.26320648,92.467987,6.5108671,430.97314,-9.260726
2227,2227,178.7014,9.4512243,3.4985321,0.0,0,5.9060197,0.0,0.26561373,92.213089,6.4851232,431.11905,-9.2599983
2228,2228,178.7016,9.4565353,3.5254247,0.0,0,5.8832316,0.0,0.2674081,92.162079,6.4615269,431.26492,-9.2599192
2229,2229,178.7018,9.478488,3.549144,0.0,0,5.8604436,0.0,0.26929945,92.16832,6.4405446,431.41083,-9.2599545
2230,2230,178.702,9.5034494,3.5655644,0.0,0,5.8376555,0.0,0.27155256,92.139153,6.417367,431.55673,-9.2602129
2231,2231,178.7022,9.5230799,3.5916581,0.0,0,5.814867,0.0,0.27343068,92.189964,6.3911009,431.70261,-9.2598801
2232,2232,178.7024,9.5605488,3.6180813,0.0,0,5.792079,0.0,0.27520958,92.375465,6.3665619,431.84851,-9.258934
2233,2233,178.7026,9.5977602,3.6358047,0.0,0,5.7692914,0.0,0.27740404,92.485786,6.3432336,431.99438,-9.2592001
2234,2234,178.7028,9.6059418,3.6632853,0.0,0,5.7465034,0.0,0.27962187,92.43605,6.3216906,432.14029,-9.2598562
2235,2235,178.703,9.6111317,3.6920385,0.0,0,5.7237153,0.0,0.28158799,92.297577,6.2986269,432.28619,-9.259922
2236,2236,178.7032,9.6125469,3.7069974,0.0,0,5.7009273,0.0,0.2836324,92.151825,6.2737832,432.43207,-9.2605591
2237,2237,178.7034,9.6211348,3.7312908,0.0,0,5.6781397,0.0,0.28584301,92.059151,6.2524934,432.50406,-9.2606316
2238,2238,178.7036,9.6465654,3.761735,0.0,0,5.6553516,0.0,0.28775865,92.09169,6.2284451,432.57602,-9.2601128
2239,2239,178.7038,9.6712761,3.778404,0.0,0,5.6325636,0.0,0.28976953,92.15097,6.2031817,432.64798,-9.2600498
2240,2240,178.704,9.6886997,3.8034613,0.0,0,5.6097751,0.0,0.29229423,92.087219,6.179956,432.71997,-9.2599564
2241,2241,178.7042,9.7095604,3.8327479,0.0,0,5.5874414,0.0,0.2942017,92.049431,6.1559353,432.79193,-9.2593746
2242,2242,178.7044,9.7396545,3.8462911,0.0,0,5.5656581,0.0,0.29585302,92.137192,6.1344471,432.86392,-9.2586908
2243,2243,178.7046,9.7589054,3.8689311,0.0,0,5.5439734,0.0,0.29833823,92.192459,6.1127477,432.93588,-9.2592716
2244,2244,178.7048,9.7678976,3.8999462,0.0,0,5.5222936,0.0,0.3003574,92.162048,6.0884538,433.00787,-9.2604589
2245,2245,178.705,9.7828817,3.9168653,0.0,0,5.5006132,0.0,0.30205244,92.106491,6.0633516,433.07983,-9.2605152
2246,2246,178.7052,9.799901,3.939028,0.0,0,5.4789333,0.0,0.30465129,91.996582,6.0393262,433.15182,-9.2605734
2247,2247,178.7054,9.8180714,3.9698138,0.0,0,5.457253,0.0,0.30678034,91.975456,6.0167756,433.22379,-9.26122
2248,2248,178.7056,9.8282232,3.9888647,0.0,0,5.4355731,0.0,0.30843666,91.999634,5.9923129,433.29575,-9.2606878
2249,2249,178.7058,9.8344469,4.0117044,0.0,0,5.4138932,0.0,0.31114298,91.781059,5.9711757,433.36774,-9.2599344
2250,2250,178.706,9.8563423,4.0418024,0.0,0,5.3922133,0.0,0.31346649,91.71476,5.947875,433.4397,-9.2592354
2251,2251,178.7062,9.8889008,4.0599494,0.0,0,5.370533,0.0,0.31490108,91.845428,5.9231687,433.51169,-9.2590532
2252,2252,178.7064,9.9224272,4.0795369,0.0,0,5.3488531,0.0,0.31733844,91.914459,5.8993464,433.58365,-9.2596807
2253,2253,178.7066,9.949131,4.1078053,0.0,0,5.3271732,0.0,0.31971377,92.025154,5.8736777,433.65564,-9.2591591
2254,2254,178.7068,9.9718704,4.127892,0.0,0,5.3054934,0.0,0.3210606,92.069077,5.8501034,433.7276,-9.2587843
2255,2255,178.707,9.9937983,4.1475806,0.0,0,5.283813,0.0,0.32346898,91.968605,5.8282146,433.79956,-9.2593031
2256,2256,178.7072,10.011025,4.1751027,0.0,0,5.2621331,0.0,0.3260954,91.885231,5.8061614,433.87155,-9.259284
2257,2257,178.7074,10.014862,4.1975942,0.0,0,5.2404532,0.0,0.3275758,91.882309,5.7816801,433.94351,-9.25947
2258,2258,178.7076,10.019864,4.2181311,0.0,0,5.2187734,0.0,0.32992989,91.754654,5.75774,434.0155,-9.2601662
2259,2259,178.7078,10.037078,4.2434382,0.0,0,5.1970935,0.0,0.33246508,91.599884,5.7344985,434.08746,-9.2605114
2260,2260,178.708,10.059991,4.266469,0.0,0,5.1754136,0.0,0.33392063,91.643059,5.7116041,434.15945,-9.2610846
2261,2261,178.7082,10.089554,4.2874813,0.0,0,5.1537333,0.0,0.33619803,91.727089,5.6882043,434.23141,-9.2615404
2262,2262,178.7084,10.122221,4.3117156,0.0,0,5.1320534,0.0,0.33893642,91.790306,5.6651411,434.30341,-9.261076
2263,2263,178.7086,10.149765,4.3374834,0.0,0,5.110373,0.0,0.34064642,91.879341,5.6429629,434.37537,-9.2608757
2264,2264,178.7088,10.166446,4.3592668,0.0,0,5.0886931,0.0,0.34278315,91.822624,5.6186318,434.44733,-9.2604084
2265,2265,178.709,10.172318,4.3795452,0.0,0,5.0670133,0.0,0.34546188,91.595856,5.59689,434.51932,-9.2591572
2266,2266,178.7092,10.18565,4.4062986,0.0,0,5.0457678,0.0,0.34727636,91.541443,5.574141,434.59128,-9.2592163
2267,2267,178.7094,10.204223,4.4300156,0.0,0,5.0250483,0.0,0.34926829,91.560287,5.5484395,434.66327,-9.2592735
2268,2268,178.7096,10.214218,4.4473057,0.0,0,5.0044241,0.0,0.35178882,91.487236,5.5258937,434.73523,-9.2593288
2269,2269,178.7098,10.224892,4.4717731,0.0,0,4.9838037,0.0,0.35362807,91.423592,5.5029473,434.80722,-9.2593241
2270,2270,178.71,10.247801,4.4949574,0.0,0,4.9631839,0.0,0.35545453,91.430534,5.4789672,434.87918,-9.2591906
2271,2271,178.7102,10.272274,4.5116358,0.0,0,4.9425635,0.0,0.35786465,91.44194,5.4571476,434.95117,-9.2591209
2272,2272,178.7104,10.299467,4.5387182,0.0,0,4.9219437,0.0,0.3600131,91.478958,5.4347887,435.02313,-9.2591515
2273,2273,178.7106,10.327648,4.5655351,0.0,0,4.9013238,0.0,0.36198819,91.556915,5.4101028,435.09509,-9.2598419
2274,2274,178.7108,10.340461,4.5810413,0.0,0,4.8807039,0.0,0.36428526,91.496689,5.3871036,435.16708,-9.2602129
2275,2275,178.711,10.35408,4.6068578,0.0,0,4.8600836,0.0,0.36662835,91.406303,5.365706,435.23904,-9.2607985
2276,2276,178.7112,10.368226,4.6358819,0.0,0,4.8394637,0.0,0.36865044,91.281311,5.3432531,435.31104,-9.2605963
2277,2277,178.7114,10.382436,4.6511688,0.0,0,4.8188438,0.0,0.3708967,91.203995,5.3224125,435.383,-9.2603397
2278,2278,178.7116,10.400525,4.6748524,0.0,0,4.798224,0.0,0.37334093,91.161667,5.2994337,435.45499,-9.260273
2279,2279,178.7118,10.416945,4.7033405,0.0,0,4.7776036,0.0,0.37515655,91.112114,5.2756796,435.52695,-9.2595367
2280,2280,178.712,10.432175,4.7175236,0.0,0,4.7569838,0.0,0.37713531,91.086266,5.2550497,435.59891,-9.2594213
2281,2281,178.7122,10.459281,4.7406425,0.0,0,4.7363639,0.0,0.37980294,91.081642,5.2328992,435.6709,-9.2596655
2282,2282,178.7124,10.493876,4.7706041,0.0,0,4.7157435,0.0,0.38188702,91.219887,5.2080035,435.74286,-9.260293
2283,2283,178.7126,10.52162,4.7849569,0.0,0,4.6951237,0.0,0.38369498,91.287598,5.1845093,435.81485,-9.260417
2284,2284,178.7128,10.541768,4.8061261,0.0,0,4.6745038,0.0,0.38635609,91.186424,5.1662869,435.88681,-9.2601118
2285,2285,178.713,10.553555,4.8361416,0.0,0,4.6538839,0.0,0.38843718,91.117737,5.1460805,435.9588,-9.2601776
2286,2286,178.7132,10.566928,4.8514581,0.0,0,4.6332641,0.0,0.39004976,91.062057,5.1233096,436.03076,-9.2599745
2287,2287,178.7134,10.585259,4.8724461,0.0,0,4.6126437,0.0,0.39281461,90.981865,5.1001949,435.85361,-9.2602615
2288,2288,178.7136,10.600171,4.9025898,0.0,0,4.5920234,0.0,0.39509422,90.924675,5.0743499,435.67648,-9.2599735
2289,2289,178.7138,10.608814,4.9191885,0.0,0,4.5714035,0.0,0.39666674,90.820801,5.0516858,435.49933,-9.2601967
2290,2290,178.714,10.62254,4.939085,0.0,0,4.5507836,0.0,0.3994095,90.707298,5.0328393,435.3222,-9.2602024
2291,2291,178.7142,10.644658,4.9681325,0.0,0,4.5305758,0.0,0.40178326,90.716507,5.0117583,435.14508,-9.2599297
2292,2292,178.7144,10.674158,4.986546,0.0,0,4.5108657,0.0,0.40323073,90.77681,4.9925613,434.96793,-9.2602072
2293,2293,178.7146,10.706694,5.0048723,0.0,0,4.4912457,0.0,0.40588829,90.777603,4.9721527,434.7908,-9.2599583
2294,2294,178.7148,10.731102,5.0319476,0.0,0,4.4716296,0.0,0.40844044,90.761543,4.9489708,434.61365,-9.2599821
2295,2295,178.715,10.748649,5.0516996,0.0,0,4.4520135,0.0,0.40975371,90.792183,4.9258509,434.43652,-9.2606745
2296,2296,178.7152,10.760159,5.0693455,0.0,0,4.4323974,0.0,0.41217804,90.678925,4.9041762,434.2594,-9.2604485
2297,2297,178.7154,10.770758,5.0937309,0.0,0,4.4127812,0.0,0.41483292,90.526848,4.8825374,434.08224,-9.2600136
2298,2298,178.7156,10.775153,5.113924,0.0,0,4.3931651,0.0,0.41614261,90.460114,4.8611779,433.90512,-9.2596655
2299,2299,178.7158,10.784892,5.1315951,0.0,0,4.3735495,0.0,0.41835845,90.337646,4.840764,433.72797,-9.2591743
2300,2300,178.716,10.814044,5.1546955,0.0,0,4.3539338,0.0,0.42104217,90.297157,4.8165054,433.55084,-9.2590961
2301,2301,178.7162,10.856441,5.1778946,0.0,0,4.3343177,0.0,0.42254132,90.515167,4.7937446,433.37369,-9.2586079
2302,2302,178.7164,10.898626,5.198009,0.0,0,4.3147016,0.0,0.42489451,90.673225,4.7720346,433.19656,-9.258913
2303,2303,178.7166,10.929565,5.2194705,0.0,0,4.2950859,0.0,0.42777646,90.672562,4.7506051,433.01944,-9.2596121
2304,2304,178.7168,10.944691,5.2429223,0.0,0,4.2754693,0.0,0.42934319,90.679665,4.7302947,432.84229,-9.2599583
2305,2305,178.717,10.953628,5.262888,0.0,0,4.2558532,0.0,0.43142787,90.524872,4.7080884,432.66516,-9.2600203
2306,2306,178.7172,10.954017,5.2820292,0.0,0,4.236237,0.0,0.43423918,90.287827,4.6857071,432.48801,-9.2604589
2307,2307,178.7174,10.949114,5.3075461,0.0,0,4.2166214,0.0,0.43607324,90.107536,4.6673045,432.31088,-9.2604523
2308,2308,178.7176,10.959766,5.3285518,0.0,0,4.1970053,0.0,0.4380773,90.023926,4.6462908,432.13373,-9.2600527
2309,2309,178.7178,10.985194,5.3435979,0.0,0,4.1773891,0.0,0.44063503,89.98481,4.6246791,431.9566,-9.2600012
2310,2310,178.718,11.024036,5.3675556,0.0,0,4.1577735,0.0,0.44244722,90.082329,4.6046381,431.77948,-9.2599001
2311,2311,178.7182,11.059091,5.3896918,0.0,0,4.1381574,0.0,0.44426158,90.275131,4.5858173,431.60233,-9.2589102
2312,2312,178.7184,11.098895,5.4043498,0.0,0,4.1185412,0.0,0.44678679,90.399178,4.5652227,431.4252,-9.2581472
2313,2313,178.7186,11.128837,5.4300313,0.0,0,4.0989256,0.0,0.4490239,90.417,4.5423732,431.24805,-9.2581062
2314,2314,178.7188,11.136702,5.4543443,0.0,0,4.0793095,0.0,0.45086882,90.344482,4.5201526,431.07092,-9.2586746
2315,2315,178.719,11.138897,5.4662466,0.0,0,4.0596933,0.0,0.45312345,90.191307,4.4977889,430.8938,-9.2597055
2316,2316,178.7192,11.139978,5.4894695,0.0,0,4.0404716,0.0,0.45546412,90.001762,4.4778347,430.71664,-9.2599211
2317,2317,178.7194,11.162363,5.5166554,0.0,0,4.0217257,0.0,0.45737052,89.988037,4.4568772,430.53952,-9.2600918
2318,2318,178.7196,11.19842,5.5293818,0.0,0,4.0030656,0.0,0.45954487,90.024651,4.4370294,430.36237,-9.260849
2319,2319,178.7198,11.22635,5.5510888,0.0,0,3.9844091,0.0,0.46212423,89.996918,4.41961,430.18524,-9.2607307
2320,2320,178.72,11.255549,5.5797133,0.0,0,3.9657531,0.0,0.46404222,90.034599,4.3979416,430.00809,-9.2598991
2321,2321,178.7202,11.290398,5.5923295,0.0,0,3.9470971,0.0,0.46604195,90.133041,4.3759131,429.83096,-9.25986
2322,2322,178.7204,11.319988,5.6132765,0.0,0,3.928441,0.0,0.46888205,90.161751,4.3546519,429.65384,-9.2592564
2323,2323,178.7206,11.335153,5.6420727,0.0,0,3.9097853,0.0,0.47091043,90.149719,4.3335114,429.47668,-9.2585258
2324,2324,178.7208,11.346046,5.654439,0.0,0,3.8911293,0.0,0.47254226,90.096748,4.3137732,429.29956,-9.2583828
2325,2325,178.721,11.358642,5.6730442,0.0,0,3.8724732,0.0,0.47524568,89.914108,4.293292,429.12241,-9.2581816
2326,2326,178.7212,11.372496,5.700315,0.0,0,3.8538172,0.0,0.47733259,89.811745,4.2729769,428.94528,-9.258954
2327,2327,178.7214,11.395041,5.7137046,0.0,0,3.8351612,0.0,0.47880343,89.863197,4.2532263,428.76816,-9.2598038
2328,2328,178.7216,11.420573,5.7322927,0.0,0,3.8165052,0.0,0.48157448,89.794296,4.2340341,428.591,-9.2602758
2329,2329,178.7218,11.441346,5.76056,0.0,0,3.7978492,0.0,0.48388654,89.765823,4.2138968,428.41388,-9.261014
2330,2330,178.722,11.470467,5.7753367,0.0,0,3.7791932,0.0,0.48534125,89.881172,4.1932058,428.23672,-9.2608252
2331,2331,178.7222,11.509985,5.7930002,0.0,0,3.7605371,0.0,0.4881402,89.914925,4.1719031,428.0596,-9.2609291
2332,2332,178.7224,11.538462,5.8205571,0.0,0,3.7418811,0.0,0.49058539,89.937057,4.1531239,427.88245,-9.2607622
2333,2333,178.7226,11.559308,5.8371258,0.0,0,3.7232251,0.0,0.49190292,89.969658,4.1319509,427.70532,-9.2599745
2334,2334,178.7228,11.573189,5.8531332,0.0,0,3.7045693,0.0,0.49457192,89.821274,4.1110201,427.5282,-9.2593737
2335,2335,178.723,11.581639,5.8782763,0.0,0,3.6859133,0.0,0.49726826,89.667686,4.0914097,427.35104,-9.2587299
2336,2336,178.7232,11.598425,5.8965211,0.0,0,3.6672573,0.0,0.49855819,89.684364,4.0707378,427.17389,-9.2587013
2337,2337,178.7234,11.616521,5.9121795,0.0,0,3.6486013,0.0,0.50092965,89.631432,4.0520654,426.86575,-9.2586117
2338,2338,178.7236,11.630721,5.9351859,0.0,0,3.629945,0.0,0.50364137,89.49794,4.0333509,426.55759,-9.2584629
2339,2339,178.7238,11.657495,5.9547491,0.0,0,3.611289,0.0,0.50498134,89.49942,4.0144529,426.24942,-9.2591944
2340,2340,178.724,11.694566,5.9709778,0.0,0,3.5926332,0.0,0.50721449,89.545059,3.9949181,425.94125,-9.2599154
2341,2341,178.7242,11.729038,5.9920578,0.0,0,3.5743496,0.0,0.51000261,89.622063,3.9752715,425.63309,-9.2605667
2342,2342,178.7244,11.760868,6.0138507,0.0,0,3.5565164,0.0,0.51158738,89.762451,3.9548182,425.32492,-9.2609177
2343,2343,178.7246,11.787539,6.0321584,0.0,0,3.5387647,0.0,0.51391149,89.75061,3.9337323,425.01675,-9.260478
2344,2344,178.7248,11.801954,6.0519342,0.0,0,3.5210166,0.0,0.51679927,89.608566,3.9148362,424.70862,-9.2601337
2345,2345,178.725,11.816424,6.0752516,0.0,0,3.5032687,0.0,0.51844072,89.592499,3.8966277,424.40045,-9.2597675
2346,2346,178.7252,11.828482,6.0933647,0.0,0,3.4855206,0.0,0.52045059,89.529739,3.8781395,424.09229,-9.2591591
2347,2347,178.7254,11.839684,6.1088066,0.0,0,3.4677725,0.0,0.52320355,89.288742,3.8597076,423.78412,-9.2584209
2348,2348,178.7256,11.864742,6.132422,0.0,0,3.4500246,0.0,0.52502513,89.244263,3.8374658,423.47595,-9.2582331
2349,2349,178.7258,11.894938,6.1519966,0.0,0,3.4322767,0.0,0.52696496,89.329689,3.8155742,423.16779,-9.2587214
2350,2350,178.726,11.929597,6.1645827,0.0,0,3.4145288,0.0,0.52955461,89.390915,3.798425,422.85962,-9.2589092
2351,2351,178.7262,11.967957,6.1866322,0.0,0,3.3967807,0.0,0.53133768,89.489395,3.7831728,422.55148,-9.2592239
2352,2352,178.7264,11.994385,6.2062764,0.0,0,3.3790326,0.0,0.53296423,89.553696,3.7629156,422.24332,-9.2596626
2353,2353,178.7266,12.015632,6.2164726,0.0,0,3.3612847,0.0,0.53529787,89.50975,3.7406247,421.93515,-9.2597046
2354,2354,178.7268,12.042632,6.2384048,0.0,0,3.3435366,0.0,0.53739882,89.512581,3.7212138,421.62698,-9.2599049
2355,2355,178.727,12.062709,6.2616377,0.0,0,3.3257885,0.0,0.53911686,89.532951,3.7023244,421.31882,-9.2599354
2356,2356,178.7272,12.073963,6.2723236,0.0,0,3.3080406,0.0,0.54143709,89.406921,3.6869853,421.01065,-9.2586145
2357,2357,178.7274,12.091449,6.2941051,0.0,0,3.2902927,0.0,0.54395092,89.340134,3.66903,420.70248,-9.2577057
2358,2358,178.7276,12.11898,6.3210979,0.0,0,3.2725446,0.0,0.54595816,89.377792,3.6472435,420.39435,-9.2584629
2359,2359,178.7278,12.150197,6.3330255,0.0,0,3.2547965,0.0,0.54823756,89.375862,3.6286671,420.08618,-9.2586594
2360,2360,178.728,12.189463,6.3542943,0.0,0,3.2370486,0.0,0.55099654,89.37516,3.6091707,419.77802,-9.2590113
2361,2361,178.7282,12.226878,6.3818908,0.0,0,3.2193005,0.0,0.55302191,89.455223,3.5888815,419.46985,-9.2597675
2362,2362,178.7284,12.254575,6.3921828,0.0,0,3.2015524,0.0,0.55494839,89.537155,3.5716665,419.16168,-9.2596684
2363,2363,178.7286,12.273267,6.4106255,0.0,0,3.1838045,0.0,0.55768448,89.469681,3.5544727,418.85352,-9.2594662
2364,2364,178.7288,12.285814,6.4368768,0.0,0,3.1660566,0.0,0.55956548,89.388596,3.5353439,418.54535,-9.2589912
2365,2365,178.729,12.30436,6.4461803,0.0,0,3.1483085,0.0,0.56105781,89.335037,3.5170197,418.23721,-9.2586498
2366,2366,178.7292,12.325344,6.461545,0.0,0,3.1309149,0.0,0.56367779,89.249092,3.5002246,417.92905,-9.2584248
2367,2367,178.7294,12.347397,6.4866185,0.0,0,3.1139498,0.0,0.56552064,89.279877,3.481693,417.62088,-9.25807
2368,2368,178.7296,12.371804,6.4968548,0.0,0,3.0970623,0.0,0.56678563,89.336617,3.4613419,417.31271,-9.2576714
2369,2369,178.7298,12.402554,6.511476,0.0,0,3.0801783,0.0,0.56952411,89.308167,3.4461174,417.00455,-9.25772
2370,2370,178.73,12.443055,6.5382924,0.0,0,3.0632942,0.0,0.57181472,89.392883,3.4286067,416.69638,-9.2583122
2371,2371,178.7302,12.478554,6.5529332,0.0,0,3.0464103,0.0,0.57324696,89.539772,3.4101639,416.38821,-9.2586727
2372,2372,178.7304,12.502407,6.5689015,0.0,0,3.0295262,0.0,0.57626498,89.485626,3.3941226,416.08008,-9.259696
2373,2373,178.7306,12.525084,6.5961428,0.0,0,3.0126421,0.0,0.57901108,89.425682,3.3754678,415.77191,-9.2609491
2374,2374,178.7308,12.550619,6.6129713,0.0,0,2.9957583,0.0,0.5803321,89.444328,3.3585386,415.46375,-9.2603483
2375,2375,178.731,12.569077,6.6274705,0.0,0,2.9788742,0.0,0.5831272,89.325394,3.340163,415.15558,-9.2595749
2376,2376,178.7312,12.59005,6.650569,0.0,0,2.9619904,0.0,0.58578467,89.255287,3.3210745,414.84741,-9.259654
2377,2377,178.7314,12.605893,6.6670718,0.0,0,2.9451063,0.0,0.58680123,89.319695,3.3028812,414.53925,-9.2595272
2378,2378,178.7316,12.623055,6.6805792,0.0,0,2.9282222,0.0,0.58921272,89.215324,3.2837856,414.23108,-9.2595797
2379,2379,178.7318,12.659955,6.7002106,0.0,0,2.9113381,0.0,0.59191453,89.169815,3.2643476,413.92294,-9.2584352
2380,2380,178.732,12.705409,6.7170773,0.0,0,2.894454,0.0,0.59299082,89.403015,3.2474413,413.61478,-9.2578516
2381,2381,178.7322,12.749883,6.7313094,0.0,0,2.8775702,0.0,0.59523094,89.480476,3.2318342,413.30661,-9.258317
2382,2382,178.7324,12.786754,6.7498865,0.0,0,2.8606861,0.0,0.59802574,89.465294,3.2152879,412.99844,-9.2588692
2383,2383,178.7326,12.815391,6.7699509,0.0,0,2.8438022,0.0,0.59930837,89.57653,3.1968403,412.69028,-9.2594833
2384,2384,178.7328,12.831121,6.7858462,0.0,0,2.8269181,0.0,0.60151201,89.518288,3.1787601,412.38211,-9.2602158
2385,2385,178.733,12.847624,6.8023186,0.0,0,2.810034,0.0,0.60446644,89.372368,3.1615055,412.07394,-9.2609825
2386,2386,178.7332,12.872149,6.8236117,0.0,0,2.7931502,0.0,0.60604632,89.394707,3.1429701,411.76581,-9.260581
2387,2387,178.7334,12.894133,6.8397174,0.0,0,2.7762663,0.0,0.60802692,89.366447,3.1236036,411.71652,-9.2600355
2388,2388,178.7336,12.918908,6.8530622,0.0,0,2.7593822,0.0,0.61080486,89.246315,3.1060321,411.66724,-9.2600002
2389,2389,178.7338,12.956436,6.8762264,0.0,0,2.7424982,0.0,0.61260509,89.323784,3.0891132,411.61795,-9.2593002
2390,2390,178.734,12.999983,6.8944325,0.0,0,2.7256143,0.0,0.61446917,89.474991,3.0712256,411.56866,-9.258461
2391,2391,178.7342,13.038374,6.904727,0.0,0,2.7090681,0.0,0.6171391,89.527199,3.0534189,411.51938,-9.2579689
2392,2392,178.7344,13.075319,6.9264956,0.0,0,2.6929309,0.0,0.61913186,89.586029,3.0356598,411.47006,-9.2578773
2393,2393,178.7346,13.105944,6.945817,0.0,0,2.6768675,0.0,0.62076962,89.621788,3.0176659,411.42078,-9.2580814
2394,2394,178.7348,13.127655,6.9546576,0.0,0,2.6608074,0.0,0.62321138,89.563454,3.0015166,411.37149,-9.2582016
2395,2395,178.735,13.148702,6.9761963,0.0,0,2.6447473,0.0,0.62537336,89.52253,2.9862936,411.3222,-9.2584953
2396,2396,178.7352,13.167138,6.9994183,0.0,0,2.6286871,0.0,0.62713665,89.526245,2.9703453,411.27292,-9.2590599
2397,2397,178.7354,13.197595,7.0082846,0.0,0,2.6126273,0.0,0.62958479,89.497864,2.9528661,411.22363,-9.2599993
2398,2398,178.7356,13.23464,7.0272241,0.0,0,2.5965672,0.0,0.63201672,89.49437,2.9343851,411.17435,-9.2605362
2399,2399,178.7358,13.280941,7.051559,0.0,0,2.580507,0.0,0.63376963,89.693077,2.9179597,411.12506,-9.2604542
2400,2400,178.736,13.33362,7.0601912,0.0,0,2.5644472,0.0,0.6358462,89.880829,2.9011827,411.07578,-9.2601318
2401,2401,178.7362,13.377667,7.0782104,0.0,0,2.5483871,0.0,0.63856858,89.901474,2.8824477,411.02649,-9.2596722
2402,2402,178.7364,13.4114,7.1036654,0.0,0,2.5323269,0.0,0.6404404,89.999695,2.861516,410.9772,-9.2591467
2403,2403,178.7366,13.436872,7.111383,0.0,0,2.5162671,0.0,0.64212626,90.044083,2.8445063,410.92792,-9.2585096
2404,2404,178.7368,13.454034,7.1279716,0.0,0,2.5002072,0.0,0.64505357,89.88459,2.8307297,410.8786,-9.2579136
2405,2405,178.737,13.464685,7.1540089,0.0,0,2.4841471,0.0,0.64713126,89.768883,2.8127177,410.82932,-9.2572794
2406,2406,178.7372,13.486142,7.1639152,0.0,0,2.4680872,0.0,0.64865828,89.729721,2.7962661,410.78003,-9.2567892
2407,2407,178.7374,13.517294,7.1811428,0.0,0,2.4520271,0.0,0.65172786,89.650948,2.7819698,410.73074,-9.2573395
2408,2408,178.7376,13.561723,7.2072186,0.0,0,2.4359672,0.0,0.65397012,89.725769,2.7657821,410.68146,-9.2584181
2409,2409,178.7378,13.609401,7.2172332,0.0,0,2.4199073,0.0,0.65527213,89.906479,2.7477174,410.63217,-9.2591791
2410,2410,178.738,13.649508,7.2306309,0.0,0,2.4038472,0.0,0.65818447,89.942627,2.730685,410.58289,-9.2592592
2411,2411,178.7382,13.692418,7.2554383,0.0,0,2.3877871,0.0,0.66052431,89.98571,2.7142231,410.5336,-9.259017
2412,2412,178.7384,13.732709,7.2680745,0.0,0,2.3717272,0.0,0.66166562,90.124779,2.6971362,410.48431,-9.2590942
2413,2413,178.7386,13.760333,7.2802582,0.0,0,2.3556671,0.0,0.66449827,90.097984,2.682353,410.43503,-9.2594557
2414,2414,178.7388,13.778424,7.303524,0.0,0,2.339607,0.0,0.66700953,90.002831,2.6652789,410.38574,-9.2591267
2415,2415,178.739,13.795897,7.3183889,0.0,0,2.3235471,0.0,0.66808164,90.026657,2.6463056,410.33646,-9.2584753
2416,2416,178.7392,13.821325,7.3311005,0.0,0,2.3078086,0.0,0.67086518,89.963882,2.630054,410.28717,-9.2583704
2417,2417,178.7394,13.858158,7.3532753,0.0,0,2.2924592,0.0,0.67372727,89.918198,2.6148748,410.23785,-9.257206
2418,2418,178.7396,13.908495,7.3708057,0.0,0,2.2771802,0.0,0.67500454,90.107964,2.5980654,410.18857,-9.2564058
2419,2419,178.7398,13.967228,7.3838553,0.0,0,2.261904,0.0,0.67768812,90.247749,2.5787044,410.13928,-9.2570639
2420,2420,178.74,14.018035,7.4035511,0.0,0,2.2466278,0.0,0.68062842,90.277855,2.5610604,410.09,-9.2578545
2421,2421,178.7402,14.05547,7.4214549,0.0,0,2.2313521,0.0,0.68176174,90.396118,2.5443492,410.04071,-9.2582502
2422,2422,178.7404,14.088862,7.4347715,0.0,0,2.2160761,0.0,0.68416524,90.423294,2.5264449,409.99142,-9.2582722
2423,2423,178.7406,14.111697,7.4521604,0.0,0,2.2008002,0.0,0.68719685,90.339638,2.5110428,409.94214,-9.2586393
2424,2424,178.7408,14.128619,7.4709749,0.0,0,2.185524,0.0,0.68841976,90.346687,2.4955301,409.89285,-9.2586908
2425,2425,178.741,14.150744,7.4852924,0.0,0,2.170248,0.0,0.69049913,90.318474,2.4783647,409.84357,-9.2589245
2426,2426,178.7412,14.187695,7.5005317,0.0,0,2.1549721,0.0,0.69357109,90.268814,2.4595983,409.79428,-9.2591677
2427,2427,178.7414,14.229072,7.5217967,0.0,0,2.1396961,0.0,0.69526994,90.372726,2.4410758,409.745,-9.2586441
2428,2428,178.7416,14.271446,7.5377817,0.0,0,2.1244199,0.0,0.69723266,90.462433,2.4256265,409.69571,-9.2588949
2429,2429,178.7418,14.313407,7.5490074,0.0,0,2.109144,0.0,0.70017493,90.454285,2.4097614,409.64639,-9.2591696
2430,2430,178.742,14.356112,7.5698252,0.0,0,2.093868,0.0,0.70200914,90.578156,2.3930783,409.59711,-9.2587166
2431,2431,178.7422,14.402289,7.5872431,0.0,0,2.0785921,0.0,0.70360672,90.754021,2.3769259,409.54782,-9.2583656
2432,2432,178.7424,14.436805,7.5960126,0.0,0,2.0633161,0.0,0.70631808,90.722099,2.3597116,409.49854,-9.2577372
2433,2433,178.7426,14.461931,7.6169076,0.0,0,2.0480402,0.0,0.70860457,90.619293,2.3444238,409.44925,-9.2576189
2434,2434,178.7428,14.491436,7.6369867,0.0,0,2.0327642,0.0,0.71035701,90.610588,2.3289843,409.39996,-9.2580318
2435,2435,178.743,14.527122,7.645721,0.0,0,2.0174882,0.0,0.71293104,90.61216,2.3113148,409.35068,-9.2575607
2436,2436,178.7432,14.561553,7.6670537,0.0,0,2.002212,0.0,0.71547496,90.587204,2.2943773,409.30139,-9.257885
2437,2437,178.7434,14.598272,7.6900625,0.0,0,1.986936,0.0,0.71729463,90.63781,2.2769594,409.04337,-9.2585974
2438,2438,178.7436,14.64419,7.6976647,0.0,0,1.9716599,0.0,0.71960115,90.720741,2.2620041,408.78537,-9.2584047
2439,2439,178.7438,14.696799,7.7155099,0.0,0,1.9563839,0.0,0.72230577,90.799423,2.2482572,408.52737,-9.2583561
2440,2440,178.744,14.749487,7.7388163,0.0,0,1.941108,0.0,0.72414488,90.986389,2.2304707,408.26938,-9.2581568
2441,2441,178.7442,14.794525,7.745564,0.0,0,1.9261372,0.0,0.72605109,91.097389,2.2138214,408.01135,-9.2581892
2442,2442,178.7444,14.828884,7.7620707,0.0,0,1.9115354,0.0,0.72894108,91.036308,2.1992216,407.75336,-9.2583866
2443,2443,178.7446,14.857045,7.7870965,0.0,0,1.8970003,0.0,0.73089707,91.030113,2.1821709,407.49536,-9.2582712
2444,2444,178.7448,14.87457,7.794405,0.0,0,1.8824683,0.0,0.73261905,91.017494,2.1646829,407.23737,-9.25842
2445,2445,178.745,14.901594,7.8090067,0.0,0,1.8679363,0.0,0.73569101,90.906723,2.1492391,406.97934,-9.2588043
2446,2446,178.7452,14.941844,7.8339272,0.0,0,1.8534042,0.0,0.73767579,90.901314,2.1342161,406.72134,-9.2585011
2447,2447,178.7454,14.986147,7.842627,0.0,0,1.8388723,0.0,0.73901206,91.02404,2.1185493,406.46335,-9.2581701
2448,2448,178.7456,15.038732,7.8562827,0.0,0,1.8243402,0.0,0.74211657,91.07753,2.1028101,406.20535,-9.2576208
2449,2449,178.7458,15.087319,7.8804431,0.0,0,1.8098083,0.0,0.74442416,91.169281,2.0873902,405.94733,-9.2569008
2450,2450,178.746,15.126716,7.8893213,0.0,0,1.7952763,0.0,0.74554861,91.323532,2.0729566,405.68933,-9.2568073
2451,2451,178.7462,15.164289,7.9009147,0.0,0,1.7807442,0.0,0.74847353,91.316643,2.0572462,405.43134,-9.2568607
2452,2452,178.7464,15.199186,7.9248486,0.0,0,1.7662122,0.0,0.75093973,91.29129,2.0416703,405.17334,-9.2576284
2453,2453,178.7466,15.234809,7.9376087,0.0,0,1.7516803,0.0,0.75200242,91.379517,2.0251083,404.91534,-9.258297
2454,2454,178.7468,15.266949,7.9492698,0.0,0,1.7371483,0.0,0.75504941,91.319687,2.0089493,404.65732,-9.2585506
2455,2455,178.747,15.30439,7.9718909,0.0,0,1.7226163,0.0,0.75799572,91.315269,1.9930102,404.39932,-9.2583361
2456,2456,178.7472,15.355264,7.9872127,0.0,0,1.7080842,0.0,0.75908673,91.496117,1.9759188,404.14133,-9.2580795
2457,2457,178.7474,15.40858,7.9990425,0.0,0,1.6935523,0.0,0.76200116,91.518234,1.9590812,403.88333,-9.2573576
2458,2458,178.7476,15.455238,8.0190992,0.0,0,1.6790203,0.0,0.76499176,91.532982,1.9426785,403.62531,-9.2565947
2459,2459,178.7478,15.510301,8.0339823,0.0,0,1.6644882,0.0,0.76590723,91.759682,1.9286643,403.36731,-9.2575026
2460,2460,178.748,15.560726,8.0443773,0.0,0,1.6499562,0.0,0.76835364,91.86834,1.9156319,403.10931,-9.2575617
2461,2461,178.7482,15.600871,8.061245,0.0,0,1.6354243,0.0,0.77129602,91.869759,1.9006456,402.85132,-9.2570419
2462,2462,178.7484,15.644819,8.077692,0.0,0,1.6208922,0.0,0.77227676,92.028732,1.8836926,402.59329,-9.2570467
2463,2463,178.7486,15.678761,8.0899763,0.0,0,1.6063603,0.0,0.77450776,91.996025,1.8666983,402.3353,-9.2575617
2464,2464,178.7488,15.711814,8.1056166,0.0,0,1.5918282,0.0,0.77772367,91.871834,1.8486392,402.0773,-9.2577543
2465,2465,178.749,15.7492,8.124424,0.0,0,1.5772963,0.0,0.77912873,91.95826,1.8347796,401.81931,-9.2575397
2466,2466,178.7492,15.785184,8.137887,0.0,0,1.5630547,0.0,0.78114194,91.990112,1.8201178,401.56128,-9.2580662
2467,2467,178.7494,15.825968,8.1500683,0.0,0,1.5491643,0.0,0.78429037,91.922714,1.8058966,401.30328,-9.258462
2468,2468,178.7496,15.871092,8.1704636,0.0,0,1.5353372,0.0,0.78600776,92.030617,1.7920508,401.04529,-9.2590046
2469,2469,178.7498,15.92518,8.1864042,0.0,0,1.5215131,0.0,0.7880013,92.188477,1.7770987,400.78729,-9.2586679
2470,2470,178.75,15.982738,8.1965475,0.0,0,1.5076891,0.0,0.79110533,92.229897,1.7621298,400.52927,-9.2574596
2471,2471,178.7502,16.031162,8.2166853,0.0,0,1.4938651,0.0,0.79304618,92.324974,1.7458031,400.27127,-9.2568073
2472,2472,178.7504,16.067877,8.2325926,0.0,0,1.4800411,0.0,0.79473001,92.391701,1.7321368,400.01328,-9.2562237
2473,2473,178.7506,16.100914,8.2392282,0.0,0,1.4662172,0.0,0.79733086,92.346359,1.7170428,399.75528,-9.2557831
2474,2474,178.7508,16.141146,8.2582121,0.0,0,1.4523932,0.0,0.79941297,92.36644,1.6997989,399.49725,-9.2561665
2475,2475,178.751,16.180037,8.2765436,0.0,0,1.4385692,0.0,0.80097818,92.429199,1.6842777,399.23926,-9.2565575
2476,2476,178.7512,16.224697,8.282362,0.0,0,1.4247452,0.0,0.80345273,92.423431,1.6706806,398.98126,-9.2568026
2477,2477,178.7514,16.264496,8.3002806,0.0,0,1.4109212,0.0,0.80588663,92.432541,1.657413,398.72327,-9.2577085
2478,2478,178.7516,16.313749,8.3213625,0.0,0,1.3970972,0.0,0.80747777,92.549065,1.6424766,398.46524,-9.2583418
2479,2479,178.7518,16.37888,8.3262548,0.0,0,1.3832732,0.0,0.8096779,92.714546,1.6273315,398.20724,-9.2583656
2480,2480,178.752,16.438713,8.3415737,0.0,0,1.3694493,0.0,0.81238902,92.863029,1.6148418,397.94925,-9.2579422
2481,2481,178.7522,16.486073,8.3638706,0.0,0,1.3556252,0.0,0.81402695,92.999001,1.6017635,397.69125,-9.2571964
2482,2482,178.7524,16.520889,8.3689032,0.0,0,1.3418012,0.0,0.81589413,93.027695,1.5869343,397.43326,-9.2562523
2483,2483,178.7526,16.555689,8.3846321,0.0,0,1.3279773,0.0,0.81908756,92.878426,1.5700017,397.17523,-9.2547436
2484,2484,178.7528,16.597643,8.4098225,0.0,0,1.3141533,0.0,0.82114846,92.874229,1.5527121,396.91724,-9.2545214
2485,2485,178.753,16.640409,8.4161081,0.0,0,1.3003292,0.0,0.82275182,93.001541,1.5400149,396.65924,-9.2554445
2486,2486,178.7532,16.688272,8.4293318,0.0,0,1.2865052,0.0,0.82597917,92.967865,1.5271692,396.40125,-9.2559118
2487,2487,178.7534,16.738676,8.452878,0.0,0,1.2726812,0.0,0.82803899,93.062729,1.5127088,396.31937,-9.2559261
2488,2488,178.7536,16.791176,8.4589825,0.0,0,1.2588573,0.0,0.82920069,93.243965,1.4968174,396.23749,-9.256259
2489,2489,178.7538,16.853083,8.4701529,0.0,0,1.2450333,0.0,0.83231348,93.240013,1.4818331,396.15561,-9.2568426
2490,2490,178.754,16.910536,8.4933815,0.0,0,1.2312093,0.0,0.834472,93.376633,1.470324,396.07376,-9.2574043
2491,2491,178.7542,16.956989,8.5019274,0.0,0,1.2176626,0.0,0.83541369,93.565506,1.456468,395.99188,-9.2579775
2492,2492,178.7544,17.000463,8.5122957,0.0,0,1.2044512,0.0,0.83854371,93.501854,1.4408139,395.91,-9.257906
2493,2493,178.7546,17.040649,8.5341043,0.0,0,1.1913005,0.0,0.84106553,93.508194,1.4237657,395.82813,-9.2573318
2494,2494,178.7548,17.076313,8.544692,0.0,0,1.1781523,0.0,0.84182972,93.647789,1.4106088,395.74625,-9.2561178
2495,2495,178.755,17.120039,8.554513,0.0,0,1.1650044,0.0,0.8448202,93.590195,1.3973553,395.6644,-9.2554092
2496,2496,178.7552,17.173071,8.5748425,0.0,0,1.1518563,0.0,0.84771025,93.604042,1.3825243,395.58252,-9.2551041
2497,2497,178.7554,17.230822,8.5876884,0.0,0,1.1387082,0.0,0.84847879,93.839424,1.3694806,395.50064,-9.2547235
2498,2498,178.7556,17.293987,8.5978889,0.0,0,1.1255603,0.0,0.85137928,93.887688,1.3559721,395.41876,-9.2551289
2499,2499,178.7558,17.35742,8.6161041,0.0,0,1.1124123,0.0,0.85454482,93.931358,1.3426335,395.33688,-9.256073
2500,2500,178.756,17.416824,8.6304607,0.0,0,1.0992643,0.0,0.85528016,94.226715,1.3282984,395.25504,-9.2561588
2501,2501,178.7562,17.473297,8.6405458,0.0,0,1.0861163,0.0,0.85775799,94.339745,1.3129029,395.17316,-9.2562742
2502,2502,178.7564,17.524168,8.6560411,0.0,0,1.0729682,0.0,0.86094999,94.30175,1.2990876,395.09128,-9.2567902
2503,2503,178.7566,17.561966,8.6717587,0.0,0,1.0598202,0.0,0.86192018,94.405525,1.2881192,395.0094,-9.2567902
2504,2504,178.7568,17.598047,8.6826344,0.0,0,1.0466722,0.0,0.86409211,94.3619,1.2740234,394.92752,-9.2568188
2505,2505,178.757,17.646198,8.6963882,0.0,0,1.0335243,0.0,0.86740208,94.290497,1.2564833,394.84567,-9.2563591
2506,2506,178.7572,17.702101,8.7150126,0.0,0,1.0203762,0.0,0.86883593,94.45742,1.2448975,394.76379,-9.2563181
2507,2507,178.7574,17.763565,8.727375,0.0,0,1.0072283,0.0,0.87087101,94.58934,1.2325637,394.68192,-9.2563734
2508,2508,178.7576,17.827417,8.7375374,0.0,0,0.99408025,0.0,0.8741616,94.640495,1.2153509,394.60004,-9.2558651
2509,2509,178.7578,17.896378,8.7560482,0.0,0,0.98093224,0.0,0.87581909,94.836914,1.201822,394.51816,-9.2559748
2510,2510,178.758,17.960176,8.7688751,0.0,0,0.96778423,0.0,0.87745583,94.983536,1.1893905,394.43631,-9.2557707
2511,2511,178.7582,18.017845,8.7758999,0.0,0,0.95463622,0.0,0.88035166,95.037514,1.1749032,394.35443,-9.256011
2512,2512,178.7584,18.065672,8.7947645,0.0,0,0.94148827,0.0,0.88221842,95.14222,1.1613086,394.27255,-9.2566442
2513,2513,178.7586,18.107407,8.8109093,0.0,0,0.92834032,0.0,0.88384068,95.219856,1.1456474,394.19067,-9.2559042
2514,2514,178.7588,18.155146,8.8166819,0.0,0,0.91519231,0.0,0.8866567,95.191299,1.1311355,394.1088,-9.2552519
2515,2515,178.759,18.20841,8.8355684,0.0,0,0.9020443,0.0,0.88909811,95.200439,1.1181759,394.02695,-9.2553148
2516,2516,178.7592,18.268124,8.8550739,0.0,0,0.88916039,0.0,0.89091396,95.360367,1.1039703,393.94507,-9.2559261
2517,2517,178.7594,18.336952,8.8597507,0.0,0,0.87659597,0.0,0.89338923,95.46553,1.0921024,393.86319,-9.2560701
2518,2518,178.7596,18.408436,8.8761845,0.0,0,0.86408937,0.0,0.8959986,95.566933,1.0792248,393.78131,-9.2554646
2519,2519,178.7598,18.476875,8.8967228,0.0,0,0.85158527,0.0,0.89761424,95.807159,1.0646363,393.69943,-9.2558069
2520,2520,178.76,18.545271,8.9010677,0.0,0,0.83908123,0.0,0.89971679,95.942497,1.0501939,393.61758,-9.2558308
2521,2521,178.7602,18.603199,8.9163246,0.0,0,0.82657719,0.0,0.9028126,95.937263,1.0342185,393.53571,-9.2553043
2522,2522,178.7604,18.650608,8.9384222,0.0,0,0.8140732,0.0,0.90460241,96.035194,1.0198665,393.45383,-9.2556124
2523,2523,178.7606,18.693106,8.9425449,0.0,0,0.80156928,0.0,0.90632647,96.086494,1.0083126,393.37195,-9.2553587
2524,2524,178.7608,18.741535,8.955122,0.0,0,0.78906524,0.0,0.90947008,96.027863,0.99391693,393.29007,-9.2549343
2525,2525,178.761,18.798002,8.9768066,0.0,0,0.77656126,0.0,0.91117585,96.176048,0.97769201,393.20822,-9.2557096
2526,2526,178.7612,18.866205,8.9808683,0.0,0,0.76405728,0.0,0.91235256,96.406487,0.96385461,393.12634,-9.2559319
2527,2527,178.7614,18.939589,8.9927063,0.0,0,0.75155324,0.0,0.91562587,96.423233,0.95201385,393.04446,-9.2554054
2528,2528,178.7616,19.010355,9.0165901,0.0,0,0.73904926,0.0,0.91785043,96.541824,0.93737483,392.96259,-9.2553368
2529,2529,178.7618,19.082191,9.023612,0.0,0,0.72654527,0.0,0.91908407,96.815575,0.9224264,392.88071,-9.2548046
2530,2530,178.762,19.144278,9.0340471,0.0,0,0.71404123,0.0,0.92257833,96.836067,0.90931809,392.79886,-9.2544441
2531,2531,178.7622,19.19302,9.0567636,0.0,0,0.70153725,0.0,0.9250893,96.850616,0.89603955,392.71698,-9.2544994
2532,2532,178.7624,19.237362,9.0656872,0.0,0,0.68903327,0.0,0.92601854,97.013664,0.88171595,392.6351,-9.254302
2533,2533,178.7626,19.283754,9.0756636,0.0,0,0.67652929,0.0,0.92937756,96.914207,0.86763871,392.55322,-9.2547436
2534,2534,178.7628,19.337057,9.0968466,0.0,0,0.66402531,0.0,0.93225449,96.873703,0.85622686,392.47134,-9.2551775
2535,2535,178.763,19.404139,9.1058989,0.0,0,0.65152127,0.0,0.93285102,97.13781,0.84350604,392.3895,-9.255209
2536,2536,178.7632,19.47542,9.113203,0.0,0,0.63901722,0.0,0.93566781,97.198441,0.82897711,392.30765,-9.2548685
2537,2537,178.7634,19.545237,9.1318693,0.0,0,0.62651324,0.0,0.9386763,97.256439,0.81587493,392.64566,-9.2547007
2538,2538,178.7636,19.619328,9.1440935,0.0,0,0.61400926,0.0,0.93931013,97.585777,0.80320251,392.98367,-9.2550697
2539,2539,178.7638,19.689915,9.1522655,0.0,0,0.60150528,0.0,0.94194323,97.687584,0.79106045,393.32169,-9.2551165
2540,2540,178.764,19.752226,9.1683588,0.0,0,0.58900124,0.0,0.94513732,97.680344,0.77833724,393.65973,-9.2544308
2541,2541,178.7642,19.803007,9.1819744,0.0,0,0.57674497,0.0,0.94583845,97.892761,0.76443452,393.99774,-9.2551479
2542,2542,178.7644,19.854963,9.191967,0.0,0,0.56478834,0.0,0.94839859,97.90033,0.74911952,394.33575,-9.2563257
2543,2543,178.7646,19.91432,9.2075186,0.0,0,0.55288589,0.0,0.95195234,97.799644,0.7355454,394.6738,-9.2558088
2544,2544,178.7648,19.972588,9.2236395,0.0,0,0.54098582,0.0,0.95307362,97.961761,0.72378623,395.01181,-9.25525
2545,2545,178.765,20.037455,9.2338715,0.0,0,0.52908581,0.0,0.9553808,98.049767,0.7104246,395.34982,-9.2550201
2546,2546,178.7652,20.109671,9.2449999,0.0,0,0.51718581,0.0,0.9587326,98.071136,0.69741637,395.68787,-9.2556448
2547,2547,178.7654,20.180616,9.2612629,0.0,0,0.5052858,0.0,0.95992684,98.31192,0.68381351,396.02588,-9.2562962
2548,2548,178.7656,20.245026,9.2720804,0.0,0,0.49338579,0.0,0.96172714,98.466827,0.67081225,396.36389,-9.2558022
2549,2549,178.7658,20.306726,9.2797842,0.0,0,0.48148578,0.0,0.96493644,98.48101,0.65796292,396.7019,-9.2546949
2550,2550,178.766,20.371305,9.2966576,0.0,0,0.46958581,0.0,0.9663766,98.634216,0.64387983,397.03995,-9.2544289
2551,2551,178.7662,20.432037,9.3091803,0.0,0,0.4576858,0.0,0.96784079,98.768837,0.63238251,397.37796,-9.2546005
2552,2552,178.7664,20.487289,9.3143873,0.0,0,0.44578579,0.0,0.9707405,98.744469,0.61949259,397.71597,-9.2540808
2553,2553,178.7666,20.542767,9.3327274,0.0,0,0.43388578,0.0,0.97284859,98.799072,0.60548085,398.05402,-9.2543182
2554,2554,178.7668,20.605242,9.3495235,0.0,0,0.42198581,0.0,0.97472268,98.919563,0.59459907,398.39203,-9.2543049
2555,2555,178.767,20.674673,9.3541803,0.0,0,0.4100858,0.0,0.97762066,98.937485,0.5825572,398.73004,-9.2541723
2556,2556,178.7672,20.733381,9.3707228,0.0,0,0.39818579,0.0,0.98001915,99.003929,0.56956112,399.06808,-9.2547665
2557,2557,178.7674,20.797678,9.3885031,0.0,0,0.38628578,0.0,0.98147929,99.185135,0.5587002,399.4061,-9.2555075