File: clean data/testID_0104.csv
level_0,index,Time(sec),Force(kN),Jaw(mm),PowAngle(deg),Power(W),Pram,PTemp,Strain,Stress(MPa),Stroke(mm),TC1(C),wedge(mm)
2256,2256,178.7072,0.74967277,0.0084306262,0.0,0,9.9398632,0.0,0.00079467281,9.4034157,10.041514,399.17841,-9.263751
2267,2267,178.7094,1.9238176,0.019112952,0.0,0,9.9068632,0.0,0.0011225978,24.019053,10.010245,399.33069,-9.2645445
2278,2278,178.7116,3.3759077,0.027646951,0.0,0,9.8738632,0.0,0.0020675273,42.578304,9.981843,399.483,-9.2622833
2289,2289,178.7138,4.5044703,0.053875502,0.0,0,9.8408632,0.0,0.0032878828,57.043739,9.9542665,399.63531,-9.2621269
2300,2300,178.716,5.1001067,0.080535144,0.0,0,9.8078632,0.0,0.0054665124,64.447212,9.9154816,399.7876,-9.2623634
2311,2311,178.7182,5.5220513,0.11730962,0.0,0,9.7748632,0.0,0.0077363146,69.663895,9.8709278,399.99863,-9.2623968
2322,2322,178.7204,5.840529,0.15313029,0.0,0,9.7418633,0.0,0.010336295,73.453484,9.829072,400.25027,-9.2615528
2333,2333,178.7226,6.0438561,0.19384617,0.0,0,9.7088633,0.0,0.012844981,75.894302,9.791646,400.50189,-9.2608156
2344,2344,178.7248,6.1899796,0.22276482,0.0,0,9.6758623,0.0,0.015009676,77.587257,9.7565022,400.75354,-9.2604694
2355,2355,178.727,6.2770205,0.2553682,0.0,0,9.6428633,0.0,0.017145883,78.498207,9.7188292,400.99796,-9.2612753
2366,2366,178.7292,6.3571467,0.28245994,0.0,0,9.6098623,0.0,0.018981751,79.484543,9.6875238,401.09067,-9.2600946
2377,2377,178.7314,6.4379487,0.31652576,0.0,0,9.5768633,0.0,0.021275187,80.223297,9.6593523,401.18338,-9.2604389
2388,2388,178.7336,6.4971972,0.34612951,0.0,0,9.5438633,0.0,0.023284195,80.909279,9.6292009,401.27609,-9.2602844
2399,2399,178.7358,6.5824914,0.37517089,0.0,0,9.5108633,0.0,0.025341673,81.672615,9.5907545,401.3688,-9.2613668
2410,2410,178.738,6.6824903,0.40513727,0.0,0,9.4779606,0.0,0.027259272,82.732552,9.5637217,401.44827,-9.2613039
2421,2421,178.7402,6.7619348,0.44084987,0.0,0,9.4457693,0.0,0.02995972,83.551842,9.5302267,401.5145,-9.2633524
2432,2432,178.7424,6.8113961,0.47478595,0.0,0,9.413579,0.0,0.031971388,84.079285,9.4927626,401.58072,-9.2619476
2443,2443,178.7446,6.8545308,0.50356537,0.0,0,9.3813887,0.0,0.034247018,84.322762,9.4628448,401.64694,-9.2623444
2454,2454,178.7468,6.8890119,0.53848207,0.0,0,9.3491983,0.0,0.036368147,84.5783,9.4297562,401.71313,-9.2625189
2465,2465,178.749,6.9315577,0.57224804,0.0,0,9.317008,0.0,0.039048389,84.886589,9.3979387,401.79202,-9.2622452
2476,2476,178.7512,6.9688859,0.60543841,0.0,0,9.2848177,0.0,0.040917557,85.157822,9.3637352,401.87149,-9.2625723
2487,2487,178.7534,7.0047994,0.63311958,0.0,0,9.2526264,0.0,0.043257691,85.326263,9.329154,401.95093,-9.2609167
2498,2498,178.7556,7.0528417,0.6687451,0.0,0,9.2204361,0.0,0.045417927,85.763786,9.2931051,402.0304,-9.2625837
2509,2509,178.7578,7.120718,0.70109814,0.0,0,9.1882467,0.0,0.048102822,86.370201,9.2586107,402.11258,-9.2632437
2520,2520,178.76,7.1519184,0.73931468,0.0,0,9.1560564,0.0,0.050183099,86.548454,9.2285299,402.19867,-9.2626495
2531,2531,178.7622,7.1667743,0.76455957,0.0,0,9.1238651,0.0,0.052471712,86.556168,9.1911612,402.28476,-9.26157
2542,2542,178.7644,7.1860151,0.79784298,0.0,0,9.0916748,0.0,0.054486025,86.659973,9.1583147,402.37085,-9.2623816
2553,2553,178.7666,7.2013369,0.82538748,0.0,0,9.0594845,0.0,0.05686646,86.658722,9.1262627,402.45691,-9.2626362
2564,2564,178.7688,7.2181983,0.86497194,0.0,0,9.0272942,0.0,0.059081763,86.666016,9.0985966,402.54874,-9.2627602
2575,2575,178.771,7.2424016,0.89026618,0.0,0,8.9951038,0.0,0.061333373,86.75705,9.0606174,402.64145,-9.2625437
2586,2586,178.7732,7.2836409,0.92232752,0.0,0,8.9629135,0.0,0.063335709,86.964294,9.0335379,402.73416,-9.2617416
2597,2597,178.7754,7.3295479,0.95362747,0.0,0,8.9307232,0.0,0.065775104,87.40123,8.9957323,402.82687,-9.2618828
2608,2608,178.7776,7.3806958,0.99264449,0.0,0,8.8985329,0.0,0.06833782,87.721649,8.9618711,402.92169,-9.2628851
2619,2619,178.7798,7.3918014,1.0173167,0.0,0,8.8663416,0.0,0.070275299,87.681686,8.9336643,403.021,-9.2634058
2630,2630,178.782,7.3983502,1.0481474,0.0,0,8.8341522,0.0,0.072398074,87.662766,8.9006462,403.12033,-9.2628307
2641,2641,178.7842,7.4339614,1.0779786,0.0,0,8.8019609,0.0,0.074562252,87.774048,8.8663826,403.21967,-9.2613258
2652,2652,178.7864,7.46453,1.1183242,0.0,0,8.7697706,0.0,0.077329487,88.034721,8.8363953,403.31897,-9.2624683
2663,2663,178.7886,7.4840961,1.1472713,0.0,0,8.7381973,0.0,0.079502352,88.024887,8.7970743,402.86053,-9.2631683
2674,2674,178.7908,7.4947119,1.1783575,0.0,0,8.7075825,0.0,0.081827819,87.924263,8.7713518,402.23807,-9.2638054
2685,2685,178.793,7.529613,1.2076583,0.0,0,8.6769676,0.0,0.083846174,88.198006,8.7353802,401.6156,-9.264782
2696,2696,178.7952,7.5856667,1.2427088,0.0,0,8.6463518,0.0,0.086587958,88.535507,8.7047119,400.99313,-9.2633591
2707,2707,178.7974,7.6090918,1.2748346,0.0,0,8.615736,0.0,0.088533469,88.693672,8.6718884,400.34656,-9.2627811
2718,2718,178.7996,7.582901,1.3002213,0.0,0,8.5851212,0.0,0.090815626,88.189743,8.6406183,399.61807,-9.2619562
2729,2729,178.8018,7.5791249,1.3314052,0.0,0,8.5545063,0.0,0.092711702,87.960121,8.6111526,398.88962,-9.2625675
2740,2740,178.804,7.6060209,1.3604896,0.0,0,8.5238914,0.0,0.095261954,88.078171,8.5825624,398.16113,-9.2627764
2751,2751,178.8062,7.6240091,1.3920344,0.0,0,8.4932756,0.0,0.097027749,88.039322,8.551424,397.43265,-9.2628193
2762,2762,178.8084,7.6404724,1.4154955,0.0,0,8.4626608,0.0,0.099288262,88.083542,8.5236835,397.34085,-9.2615633
2773,2773,178.8106,7.6798396,1.4492707,0.0,0,8.4320459,0.0,0.1013518,88.406136,8.4909954,397.54611,-9.2622471
2784,2784,178.8128,7.7333775,1.4769713,0.0,0,8.4014311,0.0,0.10386,88.653419,8.4617853,397.7514,-9.2619114
2795,2795,178.815,7.7778854,1.512557,0.0,0,8.3708153,0.0,0.10591172,89.023186,8.4273481,397.9567,-9.2620974
2806,2806,178.8172,7.8066254,1.5396979,0.0,0,8.3402004,0.0,0.10842873,89.174683,8.3991547,398.18997,-9.2633276
2817,2817,178.8194,7.8064208,1.5706075,0.0,0,8.3095846,0.0,0.11048813,89.084686,8.3645144,398.60059,-9.2617998
2828,2828,178.8216,7.8109002,1.5989354,0.0,0,8.2789698,0.0,0.11302055,88.812271,8.3341885,399.0112,-9.2625713
2839,2839,178.8238,7.8277392,1.6362455,0.0,0,8.2483549,0.0,0.11519074,88.833015,8.3079777,399.42184,-9.263526
2850,2850,178.826,7.8557162,1.660863,0.0,0,8.2177391,0.0,0.11751539,88.823906,8.2738562,399.83246,-9.264123
2861,2861,178.8282,7.8790407,1.6919142,0.0,0,8.1871243,0.0,0.11952925,88.997955,8.2427778,400.1413,-9.262702
2872,2872,178.8304,7.9136391,1.7210913,0.0,0,8.1565094,0.0,0.12193465,89.131821,8.2103462,400.3797,-9.2610712
2883,2883,178.8326,7.9635963,1.7594894,0.0,0,8.1258945,0.0,0.1245737,89.347771,8.180892,400.6181,-9.2618151
2894,2894,178.8348,8.0082722,1.7861323,0.0,0,8.0952787,0.0,0.12680665,89.801384,8.1448374,400.85648,-9.2622356
2905,2905,178.837,8.0262136,1.8193405,0.0,0,8.0646639,0.0,0.12925832,89.798302,8.1125031,401.09457,-9.2615252
2916,2916,178.8392,8.0301819,1.8475299,0.0,0,8.035037,0.0,0.13141869,89.738312,8.0850601,401.32635,-9.2617235
2927,2927,178.8414,8.0273409,1.8854798,0.0,0,8.005909,0.0,0.13429764,89.295403,8.0501881,401.55814,-9.261178
2938,2938,178.8436,8.0243416,1.9100927,0.0,0,7.9767809,0.0,0.13610344,89.132614,8.0203276,401.78992,-9.2617035
2949,2949,178.8458,8.0248299,1.9402156,0.0,0,7.9476528,0.0,0.13853936,89.035461,7.9922719,402.0217,-9.2619076
2960,2960,178.848,8.0391111,1.9644227,0.0,0,7.9185252,0.0,0.1402237,88.958817,7.9633598,402.26669,-9.264308
2971,2971,178.8502,8.0585546,1.994471,0.0,0,7.8893971,0.0,0.1428972,88.855232,7.9365878,402.52496,-9.2626495
2982,2982,178.8524,8.1157293,2.0236101,0.0,0,7.8602691,0.0,0.14470479,89.401062,7.9062743,402.7832,-9.2615643
2993,2993,178.8546,8.1509438,2.0514421,0.0,0,7.8311405,0.0,0.14722511,89.557503,7.8760109,403.04147,-9.2618694
3004,3004,178.8568,8.1613579,2.0801189,0.0,0,7.8020129,0.0,0.14902496,89.526024,7.8460784,403.29974,-9.2624722
3015,3015,178.859,8.1591759,2.1066487,0.0,0,7.7728853,0.0,0.1515236,89.327011,7.8210659,403.4379,-9.2627678
3026,3026,178.8612,8.1617765,2.1387055,0.0,0,7.7437572,0.0,0.15343864,89.147461,7.7895522,403.57031,-9.2633038
3037,3037,178.8634,8.1848125,2.1633403,0.0,0,7.7146287,0.0,0.15596767,89.234154,7.7635484,403.70276,-9.2625637
3048,3048,178.8656,8.2160873,2.1942949,0.0,0,7.6855006,0.0,0.15787236,89.316933,7.7336755,403.83521,-9.2629757
3059,3059,178.8678,8.2536507,2.2204218,0.0,0,7.656373,0.0,0.16045648,89.383102,7.7025723,403.92429,-9.2629824
3070,3070,178.87,8.2829876,2.2537999,0.0,0,7.6272449,0.0,0.16240731,89.670776,7.6768889,403.95078,-9.2627792
3081,3081,178.8722,8.3383541,2.2766776,0.0,0,7.5981174,0.0,0.16486396,90.070335,7.6430759,403.97726,-9.2619162
3092,3092,178.8744,8.356144,2.3096504,0.0,0,7.5689888,0.0,0.16700239,90.041039,7.6147346,404.00378,-9.2611437
3103,3103,178.8766,8.3721085,2.3369911,0.0,0,7.5398607,0.0,0.16955622,90.063377,7.5802317,404.03027,-9.2618542
3114,3114,178.8788,8.3740616,2.3740461,0.0,0,7.5107331,0.0,0.17196587,89.871483,7.5540614,403.70218,-9.2627096
3125,3125,178.881,8.369936,2.397507,0.0,0,7.4816046,0.0,0.17426442,89.559822,7.5234103,403.31808,-9.2628345
3136,3136,178.8832,8.3826199,2.4262633,0.0,0,7.4524765,0.0,0.1763241,89.467346,7.4947796,402.93402,-9.2646723
3147,3147,178.8854,8.4263306,2.4513226,0.0,0,7.4233489,0.0,0.17854369,89.702354,7.4675112,402.54996,-9.261982
3158,3158,178.8876,8.4522915,2.4873619,0.0,0,7.3942208,0.0,0.18107627,89.743073,7.4349494,402.07947,-9.2623596
3169,3169,178.8898,8.4997492,2.5114422,0.0,0,7.3664298,0.0,0.18329665,90.087242,7.4030886,401.42389,-9.2619839
3180,3180,178.892,8.5228071,2.5416794,0.0,0,7.338727,0.0,0.18559073,90.152184,7.3785343,400.76831,-9.2618494
3191,3191,178.8942,8.5245018,2.5692163,0.0,0,7.3110251,0.0,0.18785587,90.009583,7.3452258,400.1127,-9.262001
3202,3202,178.8964,8.5074577,2.6026471,0.0,0,7.2833219,0.0,0.19058557,89.597473,7.3163638,399.45712,-9.2624083
3213,3213,178.8986,8.4968176,2.6256442,0.0,0,7.25562,0.0,0.19227421,89.210869,7.2908769,399.25186,-9.2628508
3224,3224,178.9008,8.5128269,2.6506696,0.0,0,7.2279172,0.0,0.19452924,89.276382,7.2638135,399.17902,-9.2626352
3235,3235,178.903,8.5463762,2.6767216,0.0,0,7.2002153,0.0,0.1963224,89.387062,7.237874,399.10617,-9.2633333
3246,3246,178.9052,8.5760002,2.7044249,0.0,0,7.1725125,0.0,0.1989723,89.416313,7.2143741,399.03333,-9.262248
3257,3257,178.9074,8.6106672,2.7344131,0.0,0,7.1448097,0.0,0.20098901,89.625824,7.1822119,399.06586,-9.2618628
3268,3268,178.9096,8.6568298,2.7589333,0.0,0,7.1171079,0.0,0.20343117,89.89399,7.155941,399.45654,-9.2609882
3279,3279,178.9118,8.6846714,2.7871006,0.0,0,7.0894055,0.0,0.20526583,90.017281,7.1252465,399.84726,-9.2622786
3290,3290,178.914,8.690773,2.8141818,0.0,0,7.0617032,0.0,0.20807576,89.954773,7.0987949,400.23795,-9.2626734
3301,3301,178.9162,8.711791,2.8460259,0.0,0,7.0340004,0.0,0.20998177,89.939651,7.0740733,400.62866,-9.2632732
3312,3312,178.9184,8.7240162,2.8692856,0.0,0,7.0062981,0.0,0.21253066,89.814507,7.0431318,400.91098,-9.2634621
3323,3323,178.9206,8.7295408,2.8994758,0.0,0,6.9785957,0.0,0.21450271,89.750023,7.0137129,401.14276,-9.2622471
3334,3334,178.9228,8.7406836,2.924453,0.0,0,6.9508939,0.0,0.21720645,89.562943,6.9883904,401.37454,-9.2604189
3345,3345,178.925,8.7971067,2.9595053,0.0,0,6.9231906,0.0,0.21920869,89.912949,6.9588485,401.60629,-9.2612343
3356,3356,178.9272,8.8318434,2.9771073,0.0,0,6.8954887,0.0,0.22149087,90.136795,6.9306808,401.84079,-9.2609482
3367,3367,178.9294,8.8807106,3.0087824,0.0,0,6.8677859,0.0,0.22356944,90.367188,6.9009938,402.09241,-9.2624426
3378,3378,178.9316,8.8944635,3.034946,0.0,0,6.8400836,0.0,0.22636396,90.239098,6.8715544,402.34406,-9.2618542
3389,3389,178.9338,8.8922024,3.0724835,0.0,0,6.8123813,0.0,0.22887979,90.091072,6.8447037,402.59567,-9.2611094
3400,3400,178.936,8.8717299,3.0921612,0.0,0,6.7846789,0.0,0.23108487,89.724358,6.8113647,402.84732,-9.2611437
3411,3411,178.9382,8.8876419,3.1226628,0.0,0,6.7572594,0.0,0.23319538,89.600723,6.7899623,403.142,-9.2613258
3422,3422,178.9404,8.8869047,3.1457148,0.0,0,6.7309036,0.0,0.23547083,89.408546,6.7599635,403.46649,-9.2614813
3433,3433,178.9426,8.9426098,3.1775892,0.0,0,6.7045474,0.0,0.23784405,89.776955,6.7355185,403.79095,-9.261466
3444,3444,178.9448,8.9722824,3.1996162,0.0,0,6.6781917,0.0,0.23997419,89.842865,6.7017703,404.11545,-9.2618828
3455,3455,178.947,8.9806089,3.2277062,0.0,0,6.6518354,0.0,0.24224667,89.750313,6.6793647,404.4324,-9.2615919
3466,3466,178.9492,8.992487,3.2514484,0.0,0,6.6254797,0.0,0.24426571,89.644974,6.6522942,404.59134,-9.2629061
3477,3477,178.9514,9.0050516,3.2811186,0.0,0,6.5991235,0.0,0.24690442,89.520103,6.6276426,404.75027,-9.263834
3488,3488,178.9536,9.0164604,3.3028095,0.0,0,6.5727673,0.0,0.24855497,89.561905,6.6013594,404.90918,-9.2612019
3499,3499,178.9558,9.0235291,3.3280444,0.0,0,6.546411,0.0,0.25097659,89.42807,6.5746584,405.06812,-9.2610788
3510,3510,178.958,9.0504751,3.3555827,0.0,0,6.5200553,0.0,0.25301325,89.495583,6.5483203,404.96545,-9.2609129
3521,3521,178.9602,9.0894938,3.3847218,0.0,0,6.4936996,0.0,0.25592172,89.559052,6.5238051,404.60126,-9.2606087
3532,3532,178.9624,9.1115656,3.4099658,0.0,0,6.4673433,0.0,0.25757435,89.639938,6.4940691,404.23703,-9.2613287
3543,3543,178.9646,9.152669,3.4323642,0.0,0,6.4409876,0.0,0.26003516,89.876015,6.4687219,403.87283,-9.2611837
3554,3554,178.9668,9.1694851,3.4613068,0.0,0,6.4146314,0.0,0.26206413,89.878326,6.4419661,403.50861,-9.2613316
3565,3565,178.969,9.1956539,3.4876554,0.0,0,6.3882756,0.0,0.26494265,89.906937,6.4163566,402.5564,-9.2617531
3576,3576,178.9712,9.2207804,3.5183856,0.0,0,6.3619199,0.0,0.26693833,89.915504,6.3847728,401.57617,-9.2610779
3587,3587,178.9734,9.2214727,3.5431178,0.0,0,6.3355637,0.0,0.26973712,89.648674,6.3595018,400.59595,-9.2631197
3598,3598,178.9756,9.2357254,3.5718372,0.0,0,6.3092079,0.0,0.2716178,89.616997,6.3327227,399.61572,-9.2618885
3609,3609,178.9778,9.2593555,3.5957205,0.0,0,6.2828522,0.0,0.27442753,89.613731,6.3013783,398.92276,-9.2622347
3620,3620,178.98,9.3051157,3.6283872,0.0,0,6.256496,0.0,0.2764073,89.74601,6.2727723,398.64462,-9.2616978
3631,3631,178.9822,9.318264,3.6478302,0.0,0,6.2301397,0.0,0.27891541,89.711319,6.2499485,398.36652,-9.2620268
3642,3642,178.9844,9.3320684,3.6766138,0.0,0,6.203784,0.0,0.28097016,89.62915,6.2239385,398.08838,-9.2622976
3653,3653,178.9866,9.3232841,3.6975305,0.0,0,6.1774278,0.0,0.28334808,89.463531,6.197526,397.81027,-9.2613192
3664,3664,178.9888,9.3391685,3.7314017,0.0,0,6.1516943,0.0,0.28564382,89.378456,6.1705203,398.19568,-9.2614098
3675,3675,178.991,9.3413181,3.7514455,0.0,0,6.1266274,0.0,0.28798193,89.190338,6.1427541,398.68585,-9.2617083
3686,3686,178.9932,9.3330946,3.7773228,0.0,0,6.1015611,0.0,0.28987306,88.891785,6.1249466,399.17606,-9.2626925
3697,3697,178.9954,9.3331299,3.7953546,0.0,0,6.0764942,0.0,0.29183105,88.798126,6.1022272,399.66623,-9.2625675
3708,3708,178.9976,9.4018822,3.8267791,0.0,0,6.0514274,0.0,0.29427919,89.125763,6.0753455,400.07208,-9.2626562
3719,3719,178.9998,9.4815149,3.8487122,0.0,0,6.0263605,0.0,0.29653504,89.743446,6.043519,400.29724,-9.2617884
3730,3730,179.002,9.5052872,3.877903,0.0,0,6.0012937,0.0,0.2990011,89.765419,6.0183129,400.5224,-9.2611494
3741,3741,179.0042,9.4998026,3.8994744,0.0,0,5.9762273,0.0,0.30094892,89.570297,5.9955273,400.74753,-9.2611485
3752,3752,179.0064,9.5041723,3.9310033,0.0,0,5.95116,0.0,0.30392212,89.297966,5.9692993,400.97269,-9.2615376
3763,3763,179.0086,9.4808073,3.9525933,0.0,0,5.9260931,0.0,0.30577603,88.902649,5.9419813,401.12622,-9.2616434
3774,3774,179.0108,9.506422,3.9769647,0.0,0,5.9010267,0.0,0.30809566,88.988335,5.9207821,401.25864,-9.2612638
3785,3785,179.013,9.5065317,3.999536,0.0,0,5.8759599,0.0,0.30985677,88.827179,5.8961887,401.39108,-9.2613659
3796,3796,179.0152,9.5182142,4.0252061,0.0,0,5.850893,0.0,0.31270364,88.640556,5.8685164,401.52353,-9.2618761
3807,3807,179.0174,9.5662842,4.0492773,0.0,0,5.8258262,0.0,0.3142927,88.912994,5.8471055,401.67401,-9.2625179
3818,3818,179.0196,9.6031151,4.0692344,0.0,0,5.8007593,0.0,0.31667447,89.057594,5.8255701,401.88593,-9.2616978
3829,3829,179.0218,9.6622496,4.0959482,0.0,0,5.775692,0.0,0.3185778,89.471123,5.7973795,402.09784,-9.2617283
3840,3840,179.024,9.7114019,4.1233664,0.0,0,5.7506256,0.0,0.32173607,89.605835,5.7689147,402.30972,-9.262022
3851,3851,179.0262,9.6952715,4.155026,0.0,0,5.7255588,0.0,0.32394668,89.345528,5.7444997,402.52164,-9.2615147
3862,3862,179.0284,9.7073488,4.1754551,0.0,0,5.7004919,0.0,0.32650104,89.176704,5.7176132,402.71097,-9.2617264
3873,3873,179.0306,9.7036409,4.2003512,0.0,0,5.6754255,0.0,0.32811448,89.009232,5.6932745,402.88977,-9.2624607
3884,3884,179.0328,9.7339745,4.2219162,0.0,0,5.6503587,0.0,0.33096313,88.998451,5.6664095,403.06854,-9.2626219
3895,3895,179.035,9.7335863,4.2560773,0.0,0,5.6252918,0.0,0.3331798,88.790634,5.6407852,403.24734,-9.2619915
3906,3906,179.0372,9.7747908,4.2751536,0.0,0,5.6002245,0.0,0.33574012,88.834282,5.6185646,403.41983,-9.2625351
3917,3917,179.0394,9.8191757,4.2998252,0.0,0,5.5760789,0.0,0.33748284,89.164986,5.5944676,403.55228,-9.2616472
3928,3928,179.0416,9.8175182,4.3192124,0.0,0,5.5522313,0.0,0.33990613,89.070854,5.5696177,403.68472,-9.261857
3939,3939,179.0438,9.8294373,4.3530841,0.0,0,5.5283833,0.0,0.3423644,88.862671,5.5459991,403.81717,-9.2620602
3950,3950,179.046,9.8551264,4.3712454,0.0,0,5.5045352,0.0,0.34461194,88.934471,5.5150943,403.94962,-9.2610569
3961,3961,179.0482,9.8729029,4.3992705,0.0,0,5.4806871,0.0,0.34687307,88.820122,5.4933257,404.039,-9.2605829
3972,3972,179.0504,9.8747711,4.4183855,0.0,0,5.4568391,0.0,0.3490082,88.645309,5.467803,404.0986,-9.2618341
3983,3983,179.0526,9.8857155,4.4485116,0.0,0,5.432991,0.0,0.35152128,88.536888,5.4495726,404.15817,-9.2605276
3994,3994,179.0548,9.9135551,4.466979,0.0,0,5.4091434,0.0,0.35356516,88.675125,5.4215045,404.21777,-9.2610254
4005,4005,179.057,9.9619761,4.4911227,0.0,0,5.3852954,0.0,0.35584596,88.810928,5.3968492,404.28009,-9.2618504
4016,4016,179.0592,9.9800787,4.5134935,0.0,0,5.3614473,0.0,0.35790226,88.740356,5.3688865,404.39929,-9.2613659
4027,4027,179.0614,9.9639797,4.544765,0.0,0,5.3375993,0.0,0.36101145,88.43856,5.3473783,404.51846,-9.2618227
4038,4038,179.0636,9.9670658,4.5640039,0.0,0,5.3137512,0.0,0.36264503,88.315453,5.3299041,404.63766,-9.2621603
4049,4049,179.0658,9.9924307,4.5838046,0.0,0,5.2899032,0.0,0.36483097,88.427094,5.306684,404.75687,-9.2620411
4060,4060,179.068,10.026918,4.6071925,0.0,0,5.2660556,0.0,0.36669517,88.481956,5.2793493,404.87277,-9.2621651
4071,4071,179.0702,10.050446,4.6328869,0.0,0,5.2422071,0.0,0.36970738,88.416473,5.2549777,404.98535,-9.2615328
4082,4082,179.0724,10.047808,4.6578312,0.0,0,5.2183595,0.0,0.37141436,88.277573,5.235363,405.0979,-9.2625771
4093,4093,179.0746,10.081764,4.6764441,0.0,0,5.1945114,0.0,0.37392578,88.250465,5.2106714,405.21048,-9.2624531
4104,4104,179.0768,10.140701,4.7005329,0.0,0,5.1706634,0.0,0.37557662,88.718132,5.1888475,405.32306,-9.2624836
4115,4115,179.079,10.204568,4.7250252,0.0,0,5.1468153,0.0,0.3787975,88.985367,5.1614771,405.35345,-9.2624111
4126,4126,179.0812,10.207181,4.7539039,0.0,0,5.1229672,0.0,0.3806484,88.889313,5.1389923,405.37994,-9.261035
4137,4137,179.0834,10.196268,4.7731228,0.0,0,5.0991192,0.0,0.3834126,88.48056,5.1096439,405.40643,-9.2616339
4148,4148,179.0856,10.20447,4.8003964,0.0,0,5.0752711,0.0,0.38533127,88.351929,5.0894265,405.43292,-9.2617836
4159,4159,179.0878,10.209644,4.8194594,0.0,0,5.0514665,0.0,0.38794753,88.163406,5.0664353,405.46753,-9.2618837
4170,4170,179.09,10.244941,4.8485317,0.0,0,5.0287743,0.0,0.38983479,88.320869,5.0424943,405.51392,-9.2618017
4181,4181,179.0922,10.287816,4.865458,0.0,0,5.0060925,0.0,0.39237487,88.4235,5.0164027,405.56027,-9.2620859
4192,4192,179.0944,10.323973,4.8928232,0.0,0,4.9834104,0.0,0.39443812,88.578163,4.9943528,405.60663,-9.2624216
4203,4203,179.0966,10.374679,4.9122515,0.0,0,4.9607282,0.0,0.39709479,88.84861,4.9754047,405.65298,-9.262352
4214,4214,179.0988,10.3912,4.946631,0.0,0,4.9380465,0.0,0.39967608,88.739502,4.9502249,405.60211,-9.2623053
4225,4225,179.101,10.400249,4.9631405,0.0,0,4.9153647,0.0,0.40203965,88.562576,4.9225101,405.53589,-9.2602825
4236,4236,179.1032,10.410017,4.9897623,0.0,0,4.8926821,0.0,0.40417108,88.484589,4.8987136,405.46967,-9.2602901
4247,4247,179.1054,10.433941,5.0101233,0.0,0,4.8700004,0.0,0.40661627,88.441711,4.8722839,405.40344,-9.2604637
4258,4258,179.1076,10.421926,5.0406141,0.0,0,4.8473182,0.0,0.40933689,88.114487,4.8531046,405.35828,-9.2627296
4269,4269,179.1098,10.426374,5.0555897,0.0,0,4.8246365,0.0,0.41106281,87.970078,4.8288975,405.35828,-9.2619286
4280,4280,179.112,10.406106,5.0774069,0.0,0,4.8019543,0.0,0.41324472,87.670494,4.8077641,405.35828,-9.2616663
4291,4291,179.1142,10.458698,5.0986295,0.0,0,4.7792721,0.0,0.41527796,87.886269,4.7894301,405.35828,-9.2621918
4302,4302,179.1164,10.481296,5.1225929,0.0,0,4.7565904,0.0,0.41778821,87.873329,4.7655206,405.35828,-9.2610359
4313,4313,179.1186,10.513162,5.1413603,0.0,0,4.7339087,0.0,0.41948685,88.006851,4.7445626,405.50668,-9.2631531
4324,4324,179.1208,10.527203,5.1625366,0.0,0,4.7112265,0.0,0.4219844,87.914856,4.7217898,405.69873,-9.2633848
4335,4335,179.123,10.558308,5.1853313,0.0,0,4.6885443,0.0,0.42390069,88.072693,4.6997323,405.89078,-9.2615528
4346,4346,179.1252,10.600303,5.2111492,0.0,0,4.6658621,0.0,0.42696413,88.067657,4.6761975,406.08279,-9.2619772
4357,4357,179.1274,10.617851,5.2341299,0.0,0,4.6431804,0.0,0.42875016,87.992828,4.6534476,406.26431,-9.262825
4368,4368,179.1296,10.659295,5.253901,0.0,0,4.6204987,0.0,0.4314394,88.092468,4.6310778,406.41,-9.2632828
4379,4379,179.1318,10.706532,5.2785554,0.0,0,4.597816,0.0,0.43330395,88.390633,4.606863,406.55566,-9.2615681
4390,4390,179.134,10.740978,5.3009686,0.0,0,4.5751343,0.0,0.43644163,88.385849,4.5845809,406.70135,-9.2620544
4401,4401,179.1362,10.771325,5.329721,0.0,0,4.5524526,0.0,0.43848807,88.43045,4.5623775,406.84702,-9.2615938
4412,4412,179.1384,10.782094,5.347599,0.0,0,4.5301027,0.0,0.44125587,88.369316,4.5321584,406.93402,-9.260787
4423,4423,179.1406,10.77238,5.3741708,0.0,0,4.5085254,0.0,0.44313425,88.051979,4.5148106,406.99362,-9.2619553
4434,4434,179.1428,10.774449,5.3915925,0.0,0,4.4869475,0.0,0.44592926,87.805367,4.4946737,407.05322,-9.2610464
4445,4445,179.145,10.793168,5.4203258,0.0,0,4.4653697,0.0,0.44778317,87.793098,4.4726076,407.11282,-9.2612267
4456,4456,179.1472,10.860742,5.4360728,0.0,0,4.4437923,0.0,0.45044792,88.096733,4.4455156,407.16611,-9.2609291
4467,4467,179.1494,10.874946,5.4628778,0.0,0,4.4222145,0.0,0.45247874,88.038536,4.4223223,407.17935,-9.2613792
4478,4478,179.1516,10.833444,5.4778109,0.0,0,4.4006371,0.0,0.45483124,87.552818,4.4024978,407.1926,-9.2622643
4489,4489,179.1538,10.869724,5.5074897,0.0,0,4.3790593,0.0,0.45704317,87.615387,4.3826237,407.20584,-9.2620134
4500,4500,179.156,10.896209,5.5196924,0.0,0,4.357482,0.0,0.4590171,87.632813,4.362834,407.21909,-9.2623301
4511,4511,179.1582,10.916376,5.5455327,0.0,0,4.3359041,0.0,0.46131754,87.579323,4.3404398,406.92709,-9.2620525
4522,4522,179.1604,10.915981,5.5618329,0.0,0,4.3143263,0.0,0.46343011,87.461884,4.3208947,406.42383,-9.2604504
4533,4533,179.1626,10.95498,5.5901918,0.0,0,4.2927489,0.0,0.46597043,87.594376,4.2993112,405.92053,-9.2606192
4544,4544,179.1648,11.032132,5.6057134,0.0,0,4.2711716,0.0,0.4680005,87.945969,4.2766275,405.41727,-9.2606239
4555,4555,179.167,11.068186,5.6306663,0.0,0,4.2495937,0.0,0.47061461,88.003494,4.2537284,404.89502,-9.2614975
4566,4566,179.1692,11.084621,5.6498775,0.0,0,4.2280164,0.0,0.47260723,87.975525,4.2327633,403.97455,-9.2616472
4577,4577,179.1714,11.112088,5.6771564,0.0,0,4.2064385,0.0,0.47566506,87.914787,4.2084665,403.05408,-9.2603292
4588,4588,179.1736,11.114593,5.6942296,0.0,0,4.1848607,0.0,0.47719339,87.838181,4.1884995,402.13361,-9.2617197
4599,4599,179.1758,11.110009,5.7137814,0.0,0,4.1632833,0.0,0.47967592,87.587997,4.1714797,401.21313,-9.2613516
4610,4610,179.178,11.134861,5.7339163,0.0,0,4.1417055,0.0,0.48132724,87.635338,4.150619,400.59732,-9.2617712
4621,4621,179.1802,11.156129,5.7580218,0.0,0,4.1201286,0.0,0.48457119,87.425278,4.1255417,400.28607,-9.2626648
4632,4632,179.1824,11.205183,5.7808833,0.0,0,4.0985508,0.0,0.48635361,87.681595,4.1050563,399.97485,-9.2602549
4643,4643,179.1846,11.267706,5.7970977,0.0,0,4.0769734,0.0,0.48889777,88.001907,4.0846429,399.66364,-9.2617626
4654,4654,179.1868,11.321592,5.8215284,0.0,0,4.0553956,0.0,0.49074635,88.262161,4.064775,399.35239,-9.2616243
4665,4665,179.189,11.355655,5.8444619,0.0,0,4.0344238,0.0,0.49415627,88.17395,4.0408096,399.66064,-9.261178
4676,4676,179.1912,11.394809,5.8719511,0.0,0,4.0139022,0.0,0.49607655,88.371353,4.0135946,399.99835,-9.2608519
4687,4687,179.1934,11.429718,5.8863964,0.0,0,3.9933805,0.0,0.49875867,88.362701,3.9943514,400.33609,-9.2612133
4698,4698,179.1956,11.431762,5.9108281,0.0,0,3.9728591,0.0,0.50058198,88.212852,3.9712412,400.6738,-9.2620773
4709,4709,179.1978,11.41021,5.9303942,0.0,0,3.9523377,0.0,0.50370651,87.813881,3.9496698,401.01151,-9.2631283
4720,4720,179.2,11.39158,5.9608016,0.0,0,3.9318161,0.0,0.50577581,87.453323,3.9296362,401.34924,-9.2624416
4731,4731,179.2022,11.408865,5.9715891,0.0,0,3.9112942,0.0,0.5080151,87.40583,3.9101264,401.68695,-9.262043
4742,4742,179.2044,11.459609,5.9954638,0.0,0,3.8907726,0.0,0.50989598,87.637672,3.888695,402.02469,-9.2616863
4753,4753,179.2066,11.492125,6.010603,0.0,0,3.8702509,0.0,0.51240849,87.674248,3.867861,402.3624,-9.2611065
4764,4764,179.2088,11.505433,6.0370417,0.0,0,3.8497295,0.0,0.51447803,87.581619,3.8491421,402.65436,-9.2611437
4775,4775,179.211,11.546026,6.0499234,0.0,0,3.8292079,0.0,0.51661962,87.753479,3.8320007,402.93912,-9.2622442
4786,4786,179.2132,11.584672,6.0740252,0.0,0,3.808686,0.0,0.51884013,87.850029,3.8135598,403.22388,-9.2621069
4797,4797,179.2154,11.601028,6.0895743,0.0,0,3.7881649,0.0,0.52089876,87.783005,3.7916114,403.50861,-9.2608824
4808,4808,179.2176,11.617959,6.1183681,0.0,0,3.767643,0.0,0.52383178,87.626434,3.7667675,403.79968,-9.261343
4819,4819,179.2198,11.638801,6.1349306,0.0,0,3.7471216,0.0,0.5259642,87.541618,3.7531931,404.10431,-9.2627344
4830,4830,179.222,11.681915,6.1558084,0.0,0,3.7265999,0.0,0.52825719,87.663109,3.7316048,404.40891,-9.2625561
4841,4841,179.2242,11.731716,6.1737132,0.0,0,3.7060783,0.0,0.5301975,87.929977,3.7099981,404.71353,-9.2618589
4852,4852,179.2264,11.782324,6.1996813,0.0,0,3.6855567,0.0,0.53331196,87.980904,3.686677,405.01816,-9.2613583
4863,4863,179.2286,11.826752,6.2172675,0.0,0,3.6650352,0.0,0.53502238,88.211815,3.6634593,405.13342,-9.2618055
4874,4874,179.2308,11.846775,6.237566,0.0,0,3.6445136,0.0,0.5377171,88.11882,3.6472237,405.19302,-9.2622995
4885,4885,179.233,11.849035,6.258647,0.0,0,3.623992,0.0,0.53955054,88.011909,3.6256378,405.25262,-9.2614937
4896,4896,179.2352,11.881717,6.2816124,0.0,0,3.6034701,0.0,0.54295731,87.909729,3.6046717,405.31223,-9.2614756
4907,4907,179.2374,11.907256,6.3026853,0.0,0,3.5829487,0.0,0.54454213,87.933655,3.5842791,405.31763,-9.2609453
4918,4918,179.2396,11.961721,6.3187933,0.0,0,3.5632727,0.0,0.54724771,88.086464,3.5666711,405.13885,-9.261548
4929,4929,179.2418,11.975724,6.3435941,0.0,0,3.5437498,0.0,0.54923362,88.060059,3.5407102,404.96005,-9.2623367
4940,4940,179.244,12.022852,6.3600607,0.0,0,3.5242271,0.0,0.55217087,88.059738,3.5245361,404.78128,-9.2615309
4951,4951,179.2462,12.017395,6.3872418,0.0,0,3.5047045,0.0,0.55406493,87.973785,3.503412,404.60248,-9.2621088
4962,4962,179.2484,12.029531,6.4008217,0.0,0,3.4851816,0.0,0.55690449,87.768456,3.4839487,404.60428,-9.26231
4973,4973,179.2506,12.055062,6.4222083,0.0,0,3.4656587,0.0,0.55841666,87.863647,3.4614565,404.69037,-9.261446
4984,4984,179.2528,12.068175,6.4361024,0.0,0,3.446136,0.0,0.56112117,87.621689,3.4474511,404.77646,-9.2626219
4995,4995,179.255,12.054907,6.462925,0.0,0,3.4266131,0.0,0.56289548,87.470345,3.4285386,404.86255,-9.2613001
5006,5006,179.2572,12.098823,6.4728041,0.0,0,3.4070902,0.0,0.56521904,87.51329,3.408849,404.90347,-9.2614498
5017,5017,179.2594,12.16295,6.495924,0.0,0,3.3875678,0.0,0.56713897,87.801537,3.3895149,404.65845,-9.2612343
5028,5028,179.2616,12.263238,6.5133514,0.0,0,3.3680446,0.0,0.57001776,88.272049,3.3671429,404.41345,-9.2613916
5039,5039,179.2638,12.3096,6.5432425,0.0,0,3.3485219,0.0,0.57257944,88.45076,3.3458314,404.16843,-9.262188
5050,5050,179.266,12.317955,6.5559859,0.0,0,3.3289993,0.0,0.57489836,88.252983,3.3295922,403.9234,-9.2632704
5061,5061,179.2682,12.310699,6.5773735,0.0,0,3.3094761,0.0,0.57679403,88.037071,3.3092165,403.6236,-9.2627811
5072,5072,179.2704,12.361891,6.5914955,0.0,0,3.2899537,0.0,0.57891166,88.257042,3.289731,403.28589,-9.2616568
5083,5083,179.2726,12.390359,6.6193662,0.0,0,3.2704306,0.0,0.58193219,88.212547,3.2715914,402.94815,-9.2620707
5094,5094,179.2748,12.418688,6.6330171,0.0,0,3.2509077,0.0,0.58388579,88.20237,3.2523923,402.61041,-9.2624245
5105,5105,179.277,12.427866,6.6549993,0.0,0,3.2313852,0.0,0.58642513,88.003922,3.2319696,402.31274,-9.2630968
5116,5116,179.2792,12.475149,6.6707678,0.0,0,3.2118621,0.0,0.58816677,88.160263,3.2117255,402.85577,-9.2627268
5127,5127,179.2814,12.531173,6.6965275,0.0,0,3.1923394,0.0,0.59148008,88.279167,3.1925781,403.39877,-9.2625933
5138,5138,179.2836,12.62484,6.7135582,0.0,0,3.1728165,0.0,0.59306818,88.788445,3.1720679,403.94177,-9.2607861
5149,5149,179.2858,12.628377,6.7328215,0.0,0,3.1532936,0.0,0.59599918,88.620422,3.1510336,404.4848,-9.2615309
5160,5160,179.288,12.653374,6.7534823,0.0,0,3.1338847,0.0,0.59784526,88.629547,3.1274271,404.9689,-9.2618237
5171,5171,179.2902,12.659936,6.7773285,0.0,0,3.1153119,0.0,0.60161853,88.343651,3.1091168,405.3941,-9.2627439
5182,5182,179.2924,12.709154,6.7981105,0.0,0,3.0967393,0.0,0.60308665,88.57505,3.0886374,405.81931,-9.2629509
5193,5193,179.2946,12.741863,6.8114438,0.0,0,3.0781672,0.0,0.60579073,88.529915,3.0682774,406.24451,-9.2618294
5204,5204,179.2968,12.758993,6.8336582,0.0,0,3.0595946,0.0,0.60743189,88.489922,3.049814,406.56833,-9.2624788
5215,5215,179.299,12.76107,6.8490672,0.0,0,3.0410223,0.0,0.61057377,88.20784,3.0338395,406.43588,-9.2621117
5226,5226,179.3012,12.772728,6.8716044,0.0,0,3.02245,0.0,0.61203498,88.120056,3.0136282,406.30344,-9.2625608
5237,5237,179.3034,12.78128,6.8844905,0.0,0,3.0038774,0.0,0.61486429,87.95089,2.9975212,406.17099,-9.2622194
5248,5248,179.3056,12.796233,6.9056454,0.0,0,2.9853051,0.0,0.61630893,87.953217,2.9823823,406.03854,-9.2615223
5259,5259,179.3078,12.817051,6.9175763,0.0,0,2.9667327,0.0,0.61895436,87.865257,2.9627435,405.9946,-9.2602911
5270,5270,179.31,12.847724,6.9434748,0.0,0,2.9481604,0.0,0.62070268,87.925499,2.9496264,406.00122,-9.2613373
5281,5281,179.3122,12.893946,6.9514894,0.0,0,2.9295878,0.0,0.6230709,88.101097,2.9284952,406.00784,-9.2619247
5292,5292,179.3144,12.95908,6.974411,0.0,0,2.9110155,0.0,0.62502003,88.286499,2.909518,406.01447,-9.2610989
5303,5303,179.3166,13.035343,6.9885855,0.0,0,2.8924432,0.0,0.62772143,88.561729,2.8935826,406.03253,-9.2607927
5314,5314,179.3188,13.13199,7.0174499,0.0,0,2.8738706,0.0,0.63024974,88.991745,2.8762915,406.16498,-9.2621794
5325,5325,179.321,13.203662,7.0286307,0.0,0,2.855298,0.0,0.63241076,89.262985,2.8547659,406.29739,-9.2634144
5336,5336,179.3232,13.22937,7.0514641,0.0,0,2.836726,0.0,0.63480055,89.309105,2.8340089,406.42984,-9.2629299
5347,5347,179.3254,13.256541,7.0689449,0.0,0,2.8181536,0.0,0.63734686,89.233665,2.8132658,406.56229,-9.2625504
5358,5358,179.3276,13.276141,7.0960121,0.0,0,2.7995811,0.0,0.64040643,89.09803,2.7941003,406.66583,-9.2618637
5369,5369,179.3298,13.297605,7.1082854,0.0,0,2.7810087,0.0,0.64222729,89.085945,2.7748098,406.7453,-9.2607031
5380,5380,179.332,13.295594,7.1302867,0.0,0,2.7624362,0.0,0.6450724,88.841171,2.7566042,406.82477,-9.2616835
5391,5391,179.3342,13.333342,7.1459656,0.0,0,2.7438641,0.0,0.64685208,88.867592,2.74085,406.90424,-9.2627802
5402,5402,179.3364,13.383013,7.1686716,0.0,0,2.7252913,0.0,0.65003312,88.878258,2.7213893,406.9837,-9.2618341
5413,5413,179.3386,13.449819,7.1845512,0.0,0,2.7070746,0.0,0.65158248,89.257858,2.7013421,407.08966,-9.2602386
5424,5424,179.3408,13.490292,7.2033272,0.0,0,2.6894085,0.0,0.65456128,89.222404,2.6837087,407.19559,-9.2609053
5435,5435,179.343,13.509632,7.2219882,0.0,0,2.6717424,0.0,0.65627134,89.240135,2.6667852,407.30154,-9.2610474
5446,5446,179.3452,13.507427,7.2389979,0.0,0,2.6540766,0.0,0.65941566,88.963913,2.6490271,407.40747,-9.2612486
5457,5457,179.3474,13.530584,7.2589002,0.0,0,2.6364107,0.0,0.66089118,88.968323,2.6275244,406.88113,-9.2624321
5468,5468,179.3496,13.574851,7.2722206,0.0,0,2.6187446,0.0,0.66376352,89.006721,2.6114054,405.5961,-9.2628031
5479,5479,179.3518,13.626328,7.2944851,0.0,0,2.6010787,0.0,0.66546345,89.154991,2.5925293,404.31104,-9.2619152
5490,5490,179.354,13.630432,7.3080926,0.0,0,2.5834126,0.0,0.66854662,88.935127,2.5800686,403.026,-9.2619972
5501,5501,179.3562,13.664694,7.331183,0.0,0,2.5657465,0.0,0.67001516,89.003296,2.5615408,401.74097,-9.2617044
5512,5512,179.3584,13.677974,7.34024,0.0,0,2.5480807,0.0,0.67268652,88.855141,2.5458522,400.7753,-9.2615242
5523,5523,179.3606,13.747204,7.3628507,0.0,0,2.5304146,0.0,0.67440301,89.16748,2.5279014,399.84158,-9.2605686
5534,5534,179.3628,13.781888,7.3743162,0.0,0,2.5127485,0.0,0.67718184,89.130112,2.5117202,398.9079,-9.2610054
5545,5545,179.365,13.829675,7.4004388,0.0,0,2.4950826,0.0,0.67909062,89.299759,2.492986,397.97418,-9.2609196
5556,5556,179.3672,13.869596,7.4092073,0.0,0,2.4774165,0.0,0.68168473,89.304642,2.4759495,397.58484,-9.2619619
5567,5567,179.3694,13.929384,7.4314704,0.0,0,2.4597507,0.0,0.68361467,89.523178,2.4572513,398.14807,-9.2618771
5578,5578,179.3716,13.997295,7.4447899,0.0,0,2.4420846,0.0,0.68631101,89.686874,2.4395597,398.71133,-9.2611694
5589,5589,179.3738,14.055798,7.4727011,0.0,0,2.4244187,0.0,0.68876195,89.843559,2.4217701,399.2746,-9.261425
5600,5600,179.376,14.12537,7.4812407,0.0,0,2.4067526,0.0,0.69099665,90.114685,2.4015303,399.83783,-9.2604361
5611,5611,179.3782,14.199913,7.5053077,0.0,0,2.3890867,0.0,0.69358522,90.348457,2.3843913,400.59583,-9.261426
5622,5622,179.3804,14.239547,7.5189028,0.0,0,2.3714206,0.0,0.69578356,90.415833,2.365047,401.39709,-9.261776
5633,5633,179.3826,14.25825,7.5463409,0.0,0,2.3537545,0.0,0.69908869,90.225342,2.3435133,402.19836,-9.2610559
5644,5644,179.3848,14.249211,7.5591941,0.0,0,2.3360887,0.0,0.70107955,89.990257,2.3272953,402.99963,-9.26019
5655,5655,179.387,14.248556,7.5809174,0.0,0,2.3184226,0.0,0.7040295,89.716499,2.3099911,403.71783,-9.2610664
5666,5666,179.3892,14.239427,7.5929594,0.0,0,2.3013299,0.0,0.7054441,89.500183,2.2936339,404.21448,-9.2620134
5677,5677,179.3914,14.253624,7.610908,0.0,0,2.2845261,0.0,0.70817095,89.408989,2.27917,404.71112,-9.2620344
5688,5688,179.3936,14.332134,7.6250749,0.0,0,2.2677226,0.0,0.70946151,89.751312,2.2639172,405.20776,-9.2621756
5699,5699,179.3958,14.420481,7.642139,0.0,0,2.2509189,0.0,0.71250886,90.054451,2.2455578,405.70444,-9.2608271
5710,5710,179.398,14.471006,7.6599236,0.0,0,2.2341156,0.0,0.71425253,90.201935,2.2295623,405.67612,-9.2611475
5721,5721,179.4002,14.5068,7.6753159,0.0,0,2.2173119,0.0,0.71734214,90.167946,2.2128005,405.45099,-9.2622147
5732,5732,179.4024,14.539853,7.6956844,0.0,0,2.2005084,0.0,0.7189132,90.18528,2.1954427,405.22583,-9.2630806
5743,5743,179.4046,14.598598,7.7069111,0.0,0,2.1837046,0.0,0.72169608,90.309532,2.1800423,405.00067,-9.261651
5754,5754,179.4068,14.651445,7.7296052,0.0,0,2.1669011,0.0,0.72362715,90.458725,2.1614919,404.76108,-9.2614727
5765,5765,179.409,14.725165,7.7447305,0.0,0,2.1500976,0.0,0.72711205,90.622566,2.1416159,404.45645,-9.2602501
5776,5776,179.4112,14.785477,7.7687407,0.0,0,2.1332939,0.0,0.72863096,90.867805,2.1256955,404.15186,-9.2608776
5787,5787,179.4134,14.820553,7.7760806,0.0,0,2.1164901,0.0,0.73141217,90.843559,2.1100726,403.84723,-9.260272
5798,5798,179.4156,14.880045,7.79878,0.0,0,2.0996866,0.0,0.73319781,90.985481,2.0931835,403.54263,-9.2602987
5809,5809,179.4178,14.919132,7.8101544,0.0,0,2.0828831,0.0,0.73611885,90.979065,2.0704083,402.94724,-9.2602043
5820,5820,179.42,14.901573,7.8363881,0.0,0,2.0660796,0.0,0.73809534,90.735481,2.0552602,402.1857,-9.261941
5831,5831,179.4222,14.859866,7.844377,0.0,0,2.0492759,0.0,0.74073833,90.251106,2.0424507,401.42416,-9.2627831
5842,5842,179.4244,14.883669,7.8640213,0.0,0,2.0324724,0.0,0.74245369,90.173752,2.0269995,400.66263,-9.2618484
5853,5853,179.4266,14.939591,7.8749232,0.0,0,2.0156686,0.0,0.74495047,90.296974,2.0119021,399.72238,-9.2610388
5864,5864,179.4288,15.027712,7.8995595,0.0,0,1.9988651,0.0,0.74724686,90.595825,1.9949341,396.99518,-9.2616091
5875,5875,179.431,15.138369,7.9063368,0.0,0,1.9820615,0.0,0.74915791,91.116646,1.9764916,394.26797,-9.2606897
5886,5886,179.4332,15.197282,7.9283447,0.0,0,1.9652579,0.0,0.75157213,91.1707,1.9597009,391.54077,-9.2612886
5897,5897,179.4354,15.255898,7.9398513,0.0,0,1.9484544,0.0,0.75381571,91.437447,1.9440343,388.81357,-9.2619171
5908,5908,179.4376,15.293961,7.9660292,0.0,0,1.9316506,0.0,0.75707424,91.312309,1.9298762,386.94418,-9.2620144
5919,5919,179.4398,15.316319,7.9748588,0.0,0,1.9156144,0.0,0.75858885,91.344727,1.9106534,385.78961,-9.2608118
5930,5930,179.442,15.352415,7.9946346,0.0,0,1.8996292,0.0,0.76153499,91.263939,1.8927144,384.63507,-9.2592669
5941,5941,179.4442,15.423491,8.0072117,0.0,0,1.883644,0.0,0.76310021,91.509377,1.87691,383.4805,-9.2604351
5952,5952,179.4464,15.47628,8.0293808,0.0,0,1.8676589,0.0,0.76654011,91.551231,1.8626645,382.32596,-9.2613506
5963,5963,179.4486,15.527112,8.0423956,0.0,0,1.8516736,0.0,0.76775336,91.770088,1.8460977,383.90631,-9.2623301
5974,5974,179.4508,15.599256,8.0573559,0.0,0,1.8356884,0.0,0.77066803,91.895798,1.8275771,385.48669,-9.2605019
5985,5985,179.453,15.643549,8.0741024,0.0,0,1.8197031,0.0,0.77221388,91.998352,1.8091526,387.06708,-9.260684
5996,5996,179.4552,15.671396,8.0919371,0.0,0,1.8037181,0.0,0.77590299,91.867188,1.7957318,388.64746,-9.2617121
6007,6007,179.4574,15.692345,8.1077242,0.0,0,1.7877327,0.0,0.77708817,91.882866,1.7832128,389.86539,-9.2610283
6018,6018,179.4596,15.722131,8.1217079,0.0,0,1.7717476,0.0,0.78028119,91.757126,1.7637695,390.64847,-9.2611198
6029,6029,179.4618,15.744442,8.1392908,0.0,0,1.7557623,0.0,0.78155017,91.732506,1.7497988,391.43152,-9.2609758
6040,6040,179.464,15.796631,8.1514053,0.0,0,1.7397772,0.0,0.78488702,91.73774,1.7322284,392.21457,-9.2607222
6051,6051,179.4662,15.867789,8.1761484,0.0,0,1.723792,0.0,0.78659481,91.958603,1.7182051,392.99762,-9.2603188
6062,6062,179.4684,15.973162,8.1840916,0.0,0,1.7078067,0.0,0.78957051,92.350372,1.6994925,393.40662,-9.260251
6073,6073,179.4706,16.049444,8.2045679,0.0,0,1.6918216,0.0,0.79101443,92.666603,1.6823733,393.77823,-9.2600126
6084,6084,179.4728,16.127142,8.2174587,0.0,0,1.6758363,0.0,0.7944755,92.77327,1.6671585,394.14984,-9.2604837
6095,6095,179.475,16.17724,8.2394915,0.0,0,1.6598512,0.0,0.79605472,92.91983,1.6571767,394.52145,-9.2609081
6106,6106,179.4772,16.22226,8.2480764,0.0,0,1.6438659,0.0,0.79896438,92.86116,1.6357682,394.91711,-9.2612429
6117,6117,179.4794,16.258791,8.2692909,0.0,0,1.6278808,0.0,0.80089563,92.930252,1.6233459,395.35486,-9.2618036
6128,6128,179.4816,16.316244,8.2815342,0.0,0,1.6118956,0.0,0.80378765,92.965378,1.6067841,395.79263,-9.261795
6139,6139,179.4838,16.410812,8.3061666,0.0,0,1.5959103,0.0,0.80622262,93.273033,1.5889629,396.23038,-9.2621374
6150,6150,179.486,16.499828,8.3146906,0.0,0,1.5799252,0.0,0.80840552,93.556206,1.5710912,396.66812,-9.2608595
6161,6161,179.4882,16.541983,8.3374224,0.0,0,1.5641037,0.0,0.81122607,93.559822,1.5519465,397.00272,-9.2612114
6172,6172,179.4904,16.566015,8.3502884,0.0,0,1.5488971,0.0,0.81359977,93.494873,1.5370692,397.31436,-9.2611046
6183,6183,179.4926,16.580877,8.3742476,0.0,0,1.5336909,0.0,0.81664318,93.306297,1.5248207,397.62601,-9.2617321
6194,6194,179.4948,16.580343,8.382863,0.0,0,1.5184844,0.0,0.81839818,93.143517,1.5068177,397.93765,-9.2606888
6205,6205,179.497,16.566807,8.3996801,0.0,0,1.503278,0.0,0.82097161,92.833405,1.4937853,398.26004,-9.2607813
6216,6216,179.4992,16.576971,8.4079218,0.0,0,1.4880716,0.0,0.82202363,92.786987,1.4792916,398.61099,-9.2609797
6227,6227,179.5014,16.632441,8.4285784,0.0,0,1.4728652,0.0,0.82560652,92.717758,1.4662725,398.96198,-9.2604408
6238,6238,179.5036,16.71587,8.4397755,0.0,0,1.4576588,0.0,0.82654083,93.097107,1.449849,399.31296,-9.261796
6249,6249,179.5058,16.815277,8.4547291,0.0,0,1.4424524,0.0,0.8296234,93.356361,1.4385939,399.66394,-9.2611847
6260,6260,179.508,16.914053,8.4696751,0.0,0,1.4272461,0.0,0.83103865,93.818825,1.4197506,400.11603,-9.2610712
6271,6271,179.5102,16.99629,8.4834948,0.0,0,1.4120396,0.0,0.83441466,93.955971,1.4035075,400.60608,-9.2600307
6282,6282,179.5124,17.044329,8.5010548,0.0,0,1.3968332,0.0,0.83578432,94.123909,1.3865144,401.0961,-9.2602425
6293,6293,179.5146,17.105019,8.5142574,0.0,0,1.3816268,0.0,0.83910829,94.117943,1.3732108,401.58612,-9.2605762
6304,6304,179.5168,17.107687,8.533,0.0,0,1.3664205,0.0,0.84057128,94.024025,1.3566996,402.03162,-9.2606859
6315,6315,179.519,17.170591,8.5457535,0.0,0,1.3512141,0.0,0.84420967,93.993271,1.3439018,402.27664,-9.2593832
6326,6326,179.5212,17.258463,8.5654621,0.0,0,1.3360077,0.0,0.84532338,94.286362,1.3270648,402.52164,-9.2602406
6337,6337,179.5234,17.321846,8.5727835,0.0,0,1.3208011,0.0,0.84826422,94.42498,1.3107603,402.76666,-9.2610054
6348,6348,179.5256,17.358662,8.5926752,0.0,0,1.3055948,0.0,0.84988433,94.451759,1.3004316,403.01169,-9.2623882
6359,6359,179.5278,17.394119,8.6036682,0.0,0,1.2903885,0.0,0.85324234,94.385155,1.2864617,403.19769,-9.2613792
6370,6370,179.53,17.439972,8.6256227,0.0,0,1.2751821,0.0,0.85469407,94.498245,1.2674372,403.35001,-9.2600689
6381,6381,179.5322,17.493618,8.62992,0.0,0,1.2599757,0.0,0.85720712,94.520729,1.2546843,403.50232,-9.2604284
6392,6392,179.5344,17.562479,8.6516294,0.0,0,1.2447693,0.0,0.859254,94.701393,1.2368228,403.65463,-9.2617893
6403,6403,179.5366,17.615583,8.6610413,0.0,0,1.229563,0.0,0.86206836,94.706291,1.2280337,403.8009,-9.2612505
6414,6414,179.5388,17.710421,8.6843748,0.0,0,1.2147156,0.0,0.86431694,95.000778,1.2096597,403.88699,-9.2606087
6425,6425,179.541,17.814192,8.689867,0.0,0,1.2002528,0.0,0.86644959,95.333321,1.1958561,403.97308,-9.2605629
6436,6436,179.5432,17.921082,8.709693,0.0,0,1.1857899,0.0,0.86873358,95.681595,1.1798201,404.05917,-9.2598715
6447,6447,179.5454,17.960865,8.7197323,0.0,0,1.1713271,0.0,0.87076759,95.716698,1.1616048,404.14526,-9.2603178
6458,6458,179.5476,17.984867,8.7439251,0.0,0,1.1568644,0.0,0.87427342,95.546684,1.1476164,404.19522,-9.2611465
6469,6469,179.5498,18.010883,8.7524376,0.0,0,1.1424015,0.0,0.87577444,95.551956,1.1346456,404.21509,-9.2606449
6480,6480,179.552,18.079504,8.7688341,0.0,0,1.1279387,0.0,0.87855792,95.620331,1.1216435,404.23492,-9.260293
6491,6491,179.5542,18.131758,8.7826023,0.0,0,1.1134759,0.0,0.88045526,95.753883,1.106904,404.25479,-9.2612476
6502,6502,179.5564,18.174797,8.7960863,0.0,0,1.0990132,0.0,0.88315177,95.695915,1.0877354,404.27466,-9.261694
6513,6513,179.5586,18.271955,8.8078756,0.0,0,1.0845503,0.0,0.88430983,96.022751,1.0797846,404.35413,-9.26054
6524,6524,179.5608,18.351248,8.8245316,0.0,0,1.0700876,0.0,0.88790989,96.114708,1.0646888,404.43359,-9.2601089
6535,6535,179.563,18.454416,8.8393545,0.0,0,1.0556247,0.0,0.88925254,96.569283,1.0489136,404.51306,-9.2612095
6546,6546,179.5652,18.518442,8.8536739,0.0,0,1.0411619,0.0,0.89289618,96.530876,1.0349851,404.59253,-9.2612991
6557,6557,179.5674,18.56299,8.8726854,0.0,0,1.0266991,0.0,0.8945148,96.645912,1.0174801,404.63889,-9.2623491
6568,6568,179.5696,18.591888,8.8802853,0.0,0,1.0122362,0.0,0.89722931,96.58477,1.0054339,404.64551,-9.2616844
6579,6579,179.5718,18.648088,8.8965178,0.0,0,0.99777353,0.0,0.89851576,96.659302,0.99123836,404.65213,-9.2603035
6590,6590,179.574,18.717674,8.9099569,0.0,0,0.98331064,0.0,0.90245152,96.634079,0.97448426,404.65875,-9.2611017
6601,6601,179.5762,18.788443,8.9324789,0.0,0,0.96884787,0.0,0.90389383,96.89048,0.95657814,404.66537,-9.2609272
6612,6612,179.5784,18.870195,8.9374886,0.0,0,0.9543851,0.0,0.90691346,96.989944,0.94429427,402.93021,-9.2604046
6623,6623,179.5806,18.941019,8.9565935,0.0,0,0.93992227,0.0,0.90825599,97.204231,0.9321602,401.02087,-9.2611399
6634,6634,179.5828,19.02223,8.9671564,0.0,0,0.92545944,0.0,0.91176331,97.331726,0.91822809,399.11154,-9.2607737
6645,6645,179.585,19.112923,8.9890184,0.0,0,0.91099668,0.0,0.91338938,97.597221,0.9032712,397.20221,-9.2615366
6656,6656,179.5872,19.155823,8.9921074,0.0,0,0.89653391,0.0,0.91571158,97.640839,0.8894577,395.35071,-9.260272
6667,6667,179.5894,19.220259,9.0150175,0.0,0,0.88260645,0.0,0.91807109,97.730545,0.87468588,393.60046,-9.2601709
6678,6678,179.5916,19.280632,9.0229206,0.0,0,0.86885202,0.0,0.92079657,97.745354,0.86101544,391.85022,-9.2602482
6689,6689,179.5938,19.344961,9.0467224,0.0,0,0.85509765,0.0,0.92321604,97.797508,0.8429423,390.09995,-9.261302
6700,6700,179.596,19.440683,9.0499001,0.0,0,0.84134322,0.0,0.92498702,98.163483,0.82894897,388.3497,-9.2606182
6711,6711,179.5982,19.541019,9.0706263,0.0,0,0.82758886,0.0,0.92782247,98.320007,0.81720358,387.59714,-9.2595177
6722,6722,179.6004,19.629622,9.079196,0.0,0,0.81383443,0.0,0.92976004,98.610382,0.80323052,387.06625,-9.2596302
6733,6733,179.6026,19.685503,9.1008472,0.0,0,0.80008006,0.0,0.93296236,98.615211,0.78559542,386.53537,-9.2602758
6744,6744,179.6048,19.709354,9.1079292,0.0,0,0.78632563,0.0,0.93441355,98.589767,0.76983589,386.00449,-9.2618723
6755,6755,179.607,19.669218,9.1231747,0.0,0,0.77257121,0.0,0.93704206,98.146103,0.76146859,385.22705,-9.2623968
6766,6766,179.6092,19.624861,9.1327896,0.0,0,0.75881684,0.0,0.93834442,97.755478,0.74819744,383.79208,-9.2602739
6777,6777,179.6114,19.655083,9.1478329,0.0,0,0.74506241,0.0,0.94149965,97.609009,0.73543811,382.35712,-9.2601519
6788,6788,179.6136,19.717363,9.1571083,0.0,0,0.73130804,0.0,0.94216102,97.838982,0.72321719,380.92212,-9.259922
6799,6799,179.6158,19.807232,9.1689491,0.0,0,0.71755362,0.0,0.94542921,97.957306,0.7137689,379.48715,-9.2616911
6810,6810,179.618,19.937447,9.1793947,0.0,0,0.70379925,0.0,0.94600821,98.534454,0.70104349,378.77194,-9.2606726
6821,6821,179.6202,20.083597,9.1959801,0.0,0,0.69004482,0.0,0.95024335,98.866776,0.68595445,378.3266,-9.2601843
6832,6832,179.6224,20.202671,9.2135859,0.0,0,0.67629045,0.0,0.95174789,99.327469,0.67238587,377.88129,-9.2600393
6843,6843,179.6246,20.301065,9.2194099,0.0,0,0.66253603,0.0,0.95433843,99.56266,0.65532488,377.43594,-9.26017
6854,6854,179.6268,20.384155,9.2351789,0.0,0,0.64878166,0.0,0.95531636,99.837646,0.64310336,377.21185,-9.2598753
6865,6865,179.629,20.462116,9.2460976,0.0,0,0.63502723,0.0,0.95917809,99.842537,0.62721354,377.98322,-9.2602615
6876,6876,179.6312,20.572449,9.2686663,0.0,0,0.62127286,0.0,0.96084118,100.20387,0.61349255,378.75458,-9.2597704
6887,6887,179.6334,20.654783,9.2750759,0.0,0,0.60751843,0.0,0.96424007,100.25063,0.59842992,379.52597,-9.259594
6898,6898,179.6356,20.713408,9.2930365,0.0,0,0.59376407,0.0,0.96549565,100.36239,0.58605272,380.29733,-9.2601509
6909,6909,179.6378,20.754465,9.3019609,0.0,0,0.58003438,0.0,0.96888703,100.29924,0.57524508,381.08502,-9.261673
6920,6920,179.64,20.825083,9.3228445,0.0,0,0.56693846,0.0,0.97050846,100.45717,0.56030756,381.88205,-9.260973
6931,6931,179.6422,20.880812,9.3261137,0.0,0,0.55384851,0.0,0.97318578,100.49473,0.54700881,382.67908,-9.2611189
6942,6942,179.6444,20.932646,9.3459158,0.0,0,0.54075849,0.0,0.97497708,100.54533,0.53433734,383.4761,-9.2608585
6948,6948,179.6456,21.029837,9.3519278,0.0,0,0.53361851,0.0,0.97642243,100.87893,0.52599841,383.91086,-9.2587166