File: clean data/testID_0244.csv
level_0,index,Time(sec),Force(kN),Jaw(mm),PowAngle(deg),Power(W),Pram,PTemp,Strain,Stress(MPa),Stroke(mm),TC1(C),wedge(mm)
2255,2255,178.7074,1.6278949,0.0094426312,0.0,0,9.9428635,0.0,0.00078699709,20.359724,10.044989,400.05508,-9.2639074
2266,2266,178.7096,2.8343475,0.015912589,0.0,0,9.9098635,0.0,0.00086683786,35.730412,10.010724,400.07501,-9.2635393
2277,2277,178.7118,3.8181665,0.034657024,0.0,0,9.8768635,0.0,0.002459557,48.434673,9.9847355,400.18649,-9.2628698
2288,2288,178.714,4.1544123,0.071949005,0.0,0,9.8438625,0.0,0.0045165,52.603703,9.9465113,400.64432,-9.2618532
2299,2299,178.7162,4.3653345,0.10393637,0.0,0,9.8108635,0.0,0.0071274419,55.176903,9.9042845,401.10217,-9.2618694
2310,2310,178.7184,4.5188832,0.1411415,0.0,0,9.7778635,0.0,0.0092572151,57.05368,9.8667068,401.56,-9.2615814
2321,2321,178.7206,4.6147232,0.17618008,0.0,0,9.7448635,0.0,0.011991019,58.02486,9.8265162,402.01782,-9.2632742
2332,2332,178.7228,4.6988373,0.21754366,0.0,0,9.7118626,0.0,0.014223755,58.969769,9.7912216,404.27219,-9.2622976
2343,2343,178.725,4.7401047,0.24377884,0.0,0,9.6788635,0.0,0.016453894,59.222569,9.7617588,407.40048,-9.2623615
2354,2354,178.7272,4.7636981,0.27530491,0.0,0,9.6458635,0.0,0.018400263,59.617863,9.7281246,410.52878,-9.2620773
2365,2365,178.7294,4.7812467,0.3042033,0.0,0,9.6128635,0.0,0.020695219,59.569935,9.6969471,413.65707,-9.2635002
2376,2376,178.7316,4.8102765,0.33903828,0.0,0,9.5798635,0.0,0.022522509,59.898727,9.6673508,416.96274,-9.2629747
2387,2387,178.7338,4.8318872,0.36374694,0.0,0,9.5468636,0.0,0.024649756,59.968128,9.6359463,421.39163,-9.2635021
2398,2398,178.736,4.8692927,0.39864525,0.0,0,9.5138636,0.0,0.02672077,60.255028,9.5987024,425.82053,-9.2625284
2409,2409,178.7382,4.8922777,0.42760745,0.0,0,9.4808941,0.0,0.029017353,60.465992,9.5675812,430.24942,-9.2639437
2420,2420,178.7404,4.9436316,0.46711987,0.0,0,9.4486961,0.0,0.031369273,60.938484,9.5360241,434.67831,-9.2638597
2431,2431,178.7426,4.9911227,0.49719015,0.0,0,9.4165058,0.0,0.033778742,61.443634,9.4976759,437.67908,-9.2638264
2442,2442,178.7448,5.0263324,0.53368074,0.0,0,9.3843155,0.0,0.036041066,61.756046,9.466958,439.72775,-9.2626724
2453,2453,178.747,5.0224652,0.56344211,0.0,0,9.3521252,0.0,0.038338069,61.565151,9.4315977,441.77643,-9.2624264
2464,2464,178.7492,5.0381665,0.60538775,0.0,0,9.3199348,0.0,0.040996186,61.547478,9.397686,443.8251,-9.2629614
2475,2475,178.7514,5.0315046,0.63388205,0.0,0,9.2877445,0.0,0.043117262,61.353905,9.3617144,445.76526,-9.2616425
2486,2486,178.7536,5.0440612,0.66867757,0.0,0,9.2555542,0.0,0.045525339,61.279942,9.3264189,446.10849,-9.2632875
2497,2497,178.7558,5.0368237,0.69793928,0.0,0,9.2233629,0.0,0.047639992,61.065582,9.296813,446.45172,-9.2638884
2508,2508,178.758,5.028285,0.73487693,0.0,0,9.1911736,0.0,0.050191164,60.955452,9.2673302,446.79492,-9.2635059
2519,2519,178.7602,5.0621386,0.76012152,0.0,0,9.1589823,0.0,0.052035447,61.159393,9.2306023,447.13815,-9.2630453
2530,2530,178.7624,5.0862589,0.79163247,0.0,0,9.126792,0.0,0.05418954,61.387604,9.1985159,447.33871,-9.2637501
2541,2541,178.7646,5.1157975,0.81960952,0.0,0,9.0946016,0.0,0.056119144,61.594162,9.172473,447.41132,-9.2623348
2552,2552,178.7668,5.1303048,0.85706574,0.0,0,9.0624113,0.0,0.058843296,61.581573,9.1376982,447.48392,-9.2629938
2563,2563,178.769,5.1318021,0.88688731,0.0,0,9.030221,0.0,0.060790814,61.44408,9.1037607,447.55652,-9.2630405
2574,2574,178.7712,5.1510744,0.91764295,0.0,0,8.9980307,0.0,0.063164152,61.506374,9.0686722,447.62912,-9.2631969
2585,2585,178.7734,5.151897,0.94887406,0.0,0,8.9658403,0.0,0.065188266,61.503902,9.0394249,447.73444,-9.2644768
2596,2596,178.7756,5.1705484,0.98366612,0.0,0,8.93365,0.0,0.067964114,61.588078,9.0057764,447.84006,-9.2635956
2607,2607,178.7778,5.1833129,1.0173635,0.0,0,8.9014597,0.0,0.070066519,61.577766,8.9728317,447.94568,-9.2642899
2618,2618,178.78,5.2213035,1.044637,0.0,0,8.8692694,0.0,0.072277837,61.781742,8.9360151,448.05127,-9.2632179
2629,2629,178.7822,5.245533,1.0768102,0.0,0,8.837079,0.0,0.074309237,61.962799,8.906353,448.1629,-9.2633724
2640,2640,178.7844,5.2671924,1.1092011,0.0,0,8.8048878,0.0,0.077004582,62.038891,8.8718405,448.28171,-9.2620487
2651,2651,178.7866,5.2507153,1.1445316,0.0,0,8.7726974,0.0,0.079104975,61.873745,8.8391714,448.40051,-9.2622862
2662,2662,178.7888,5.244503,1.171698,0.0,0,8.7409821,0.0,0.081469648,61.563061,8.8063002,448.51932,-9.2624388
2673,2673,178.791,5.2521863,1.2053376,0.0,0,8.7103662,0.0,0.083561905,61.518658,8.776967,448.63812,-9.2635088
2684,2684,178.7932,5.2937546,1.2361481,0.0,0,8.6797504,0.0,0.08620777,61.892193,8.7416182,448.83569,-9.2636042
2695,2695,178.7954,5.3020048,1.2731899,0.0,0,8.6491356,0.0,0.088372178,61.756264,8.7113132,449.04031,-9.2622356
2706,2706,178.7976,5.3115878,1.2987884,0.0,0,8.6185207,0.0,0.090786271,61.697453,8.676137,449.24493,-9.2625523
2717,2717,178.7998,5.3387852,1.3310697,0.0,0,8.5879049,0.0,0.092742182,61.885681,8.6420174,449.44955,-9.2617912
2728,2728,178.802,5.3314776,1.3589929,0.0,0,8.5572901,0.0,0.095173061,61.737759,8.6179266,449.65671,-9.2632895
2739,2739,178.8042,5.3494859,1.3947409,0.0,0,8.5266752,0.0,0.097162902,61.8494,8.5848846,449.86792,-9.2625799
2750,2750,178.8064,5.327899,1.4173095,0.0,0,8.4960604,0.0,0.099441819,61.423904,8.5549078,450.07913,-9.2630072
2761,2761,178.8086,5.3384786,1.4514205,0.0,0,8.4654446,0.0,0.10157539,61.43,8.5271559,450.29034,-9.262619
2772,2772,178.8108,5.3563395,1.4785776,0.0,0,8.4348297,0.0,0.10401162,61.488392,8.4944229,450.50156,-9.2626371
2783,2783,178.813,5.3820319,1.5154251,0.0,0,8.4042158,0.0,0.10618901,61.591454,8.4628048,450.63467,-9.26299
2794,2794,178.8152,5.4027023,1.5395514,0.0,0,8.3735991,0.0,0.10844259,61.643356,8.4338179,450.75348,-9.2631845
2805,2805,178.8174,5.4401331,1.5726696,0.0,0,8.3429842,0.0,0.11059437,61.958767,8.3983345,450.87228,-9.263339
2816,2816,178.8196,5.465755,1.6018249,0.0,0,8.3123684,0.0,0.11304992,62.128918,8.3672419,450.99109,-9.263855
2827,2827,178.8218,5.485383,1.6410583,0.0,0,8.2817535,0.0,0.11562302,62.277294,8.3357897,451.11194,-9.2626867
2838,2838,178.824,5.488102,1.6671338,0.0,0,8.2511396,0.0,0.11792277,62.15089,8.3042784,451.23737,-9.2633247
2849,2849,178.8262,5.4511046,1.6989678,0.0,0,8.2205229,0.0,0.12005684,61.601631,8.2753668,451.36276,-9.2629919
2860,2860,178.8284,5.4609213,1.7242802,0.0,0,8.189908,0.0,0.12210733,61.600513,8.2454271,451.48819,-9.263341
2871,2871,178.8306,5.4861355,1.7615972,0.0,0,8.1592932,0.0,0.12481348,61.536835,8.2148132,451.61359,-9.2631435
2882,2882,178.8328,5.5095911,1.7864885,0.0,0,8.1286783,0.0,0.12682924,61.725426,8.182086,451.7186,-9.26404
2893,2893,178.835,5.5362048,1.8198649,0.0,0,8.0980625,0.0,0.12927975,61.911758,8.1526985,451.81763,-9.2638273
2904,2904,178.8372,5.5737743,1.8473053,0.0,0,8.0674477,0.0,0.13135384,62.21883,8.1202345,451.91663,-9.263567
2915,2915,178.8394,5.5900893,1.88396,0.0,0,8.0376854,0.0,0.13417487,62.242729,8.087039,452.01563,-9.2631407
2926,2926,178.8416,5.5751648,1.9121736,0.0,0,8.0085573,0.0,0.13626075,61.977127,8.0556297,452.0928,-9.2625799
2937,2937,178.8438,5.5713305,1.9410746,0.0,0,7.9794292,0.0,0.13861011,61.84832,8.0274448,452.0994,-9.2628012
2948,2948,178.846,5.5480595,1.9682842,0.0,0,7.9503016,0.0,0.14053747,61.340115,7.9965324,452.10599,-9.262496
2959,2959,178.8482,5.5667963,2.0007732,0.0,0,7.921174,0.0,0.14323251,61.408463,7.9692645,452.11258,-9.2634869
2970,2970,178.8504,5.5828843,2.0288622,0.0,0,7.892046,0.0,0.1451252,61.444977,7.9388771,452.11917,-9.2630224
2981,2981,178.8526,5.6039333,2.0569384,0.0,0,7.8629174,0.0,0.14747311,61.429302,7.9112792,452.13965,-9.2637405
2992,2992,178.8548,5.6234097,2.083699,0.0,0,7.8337893,0.0,0.14934175,61.613216,7.8804822,452.16605,-9.263628
3003,3003,178.857,5.6601915,2.1148157,0.0,0,7.8046613,0.0,0.15214871,61.864334,7.8480844,452.19244,-9.2633429
3014,3014,178.8592,5.6752834,2.1442053,0.0,0,7.7755337,0.0,0.15402776,61.96175,7.8223295,452.21884,-9.2624826
3025,3025,178.8614,5.6798983,2.1698954,0.0,0,7.7464056,0.0,0.15642805,61.889271,7.7881742,452.24741,-9.2623129
3036,3036,178.8636,5.6774397,2.2011738,0.0,0,7.7172771,0.0,0.1583876,61.739685,7.7628455,452.28702,-9.2634344
3047,3047,178.8658,5.6632657,2.2303174,0.0,0,7.6881495,0.0,0.16124934,61.372814,7.730216,452.32663,-9.2624331
3058,3058,178.868,5.6617222,2.2610075,0.0,0,7.6590214,0.0,0.16306712,61.289978,7.7018495,452.36624,-9.2624636
3069,3069,178.8702,5.7043443,2.2831843,0.0,0,7.6298933,0.0,0.16536446,61.542912,7.6737452,452.40582,-9.2620935
3080,3080,178.8724,5.7236991,2.3127592,0.0,0,7.6007657,0.0,0.16720243,61.570583,7.6454787,452.3999,-9.2628317
3091,3091,178.8746,5.7459974,2.341259,0.0,0,7.5716372,0.0,0.17003427,61.768917,7.6163783,452.36688,-9.2622204
3102,3102,178.8768,5.7718792,2.3753645,0.0,0,7.5425091,0.0,0.1719624,61.865993,7.5856266,452.33389,-9.2628393
3113,3113,178.879,5.7977419,2.3986297,0.0,0,7.5133815,0.0,0.17450759,62.064667,7.5597005,452.30087,-9.2630644
3124,3124,178.8812,5.7914004,2.4311628,0.0,0,7.4842534,0.0,0.17660001,61.840736,7.5278349,452.27448,-9.2635565
3135,3135,178.8834,5.7873073,2.4573557,0.0,0,7.4551249,0.0,0.17922153,61.641529,7.5000114,452.31409,-9.2633553
3146,3146,178.8856,5.8028193,2.4916782,0.0,0,7.4259973,0.0,0.18124536,61.635647,7.469285,452.35367,-9.2622147
3157,3157,178.8878,5.8238964,2.5155962,0.0,0,7.3968692,0.0,0.18380521,61.699226,7.4417205,452.39328,-9.2617064
3168,3168,178.89,5.8636765,2.5482161,0.0,0,7.3689485,0.0,0.18599984,61.935055,7.4133334,452.43289,-9.2626076
3179,3179,178.8922,5.8962302,2.5753417,0.0,0,7.3412457,0.0,0.18860045,62.037338,7.3812923,452.47617,-9.262393
3190,3190,178.8944,5.8816381,2.6093922,0.0,0,7.3135438,0.0,0.19079143,61.845417,7.3459148,452.52237,-9.2622433
3201,3201,178.8966,5.8844376,2.6319177,0.0,0,7.285841,0.0,0.19306183,61.813938,7.3176336,452.56857,-9.2635746
3212,3212,178.8988,5.8877864,2.6624954,0.0,0,7.2581387,0.0,0.19528973,61.692963,7.2926755,452.61478,-9.262454
3223,3223,178.901,5.8767352,2.6864376,0.0,0,7.2304363,0.0,0.19757025,61.505962,7.263484,452.66064,-9.2624273
3234,3234,178.9032,5.8371525,2.7172587,0.0,0,7.202734,0.0,0.19956961,60.97604,7.2386632,452.68704,-9.262496
3245,3245,178.9054,5.8537784,2.7382398,0.0,0,7.1750317,0.0,0.20156881,60.888023,7.2145853,452.71344,-9.2645988
3256,3256,178.9076,5.9059138,2.7678254,0.0,0,7.1473289,0.0,0.20384035,61.297787,7.1892881,452.73984,-9.2642479
3267,3267,178.9098,5.9713955,2.7936773,0.0,0,7.1196265,0.0,0.2061376,61.814148,7.1569691,452.76624,-9.2635565
3278,3278,178.912,5.985693,2.8261256,0.0,0,7.0919242,0.0,0.2086664,61.887653,7.1285496,452.81171,-9.2632551
3289,3289,178.9142,5.9958768,2.8511455,0.0,0,7.0642223,0.0,0.21080786,61.911373,7.1025605,452.87772,-9.263114
3300,3300,178.9164,6.0087318,2.8797829,0.0,0,7.0365191,0.0,0.21310021,61.839241,7.0713434,452.94373,-9.2628174
3311,3311,178.9186,6.0224662,2.9062555,0.0,0,7.0088167,0.0,0.21533941,61.845928,7.0435815,453.00974,-9.2634602
3322,3322,178.9208,6.0182137,2.9371934,0.0,0,6.9811144,0.0,0.21791494,61.624149,7.015676,453.07574,-9.2626648
3333,3333,178.923,6.0223894,2.9621542,0.0,0,6.9534125,0.0,0.21991138,61.550652,6.9905615,453.16046,-9.2622967
3344,3344,178.9252,6.0211277,2.9905212,0.0,0,6.9257097,0.0,0.22235939,61.35236,6.9616604,453.24628,-9.263793
3355,3355,178.9274,6.0579948,3.0174303,0.0,0,6.8980074,0.0,0.22449684,61.58289,6.929915,453.33206,-9.263051
3366,3366,178.9296,6.08003,3.0477386,0.0,0,6.8703055,0.0,0.22724184,61.657825,6.9010816,453.41788,-9.2624464
3377,3377,178.9318,6.095026,3.0758679,0.0,0,6.8426027,0.0,0.22914332,61.710182,6.8763027,453.52527,-9.2619629
3388,3388,178.934,6.1118989,3.09935,0.0,0,6.8148999,0.0,0.2315228,61.756176,6.8503213,453.66388,-9.2629395
3399,3399,178.9362,6.1359549,3.1268876,0.0,0,6.7871976,0.0,0.23354043,61.846424,6.819612,453.80249,-9.262043
3410,3410,178.9384,6.1344643,3.1566477,0.0,0,6.759656,0.0,0.23646343,61.680847,6.7906599,453.9411,-9.2630587
3421,3421,178.9406,6.140574,3.1864059,0.0,0,6.7332997,0.0,0.23846893,61.674881,6.7673874,454.07971,-9.262639
3432,3432,178.9428,6.1551547,3.2103171,0.0,0,6.706944,0.0,0.24107769,61.511368,6.7324677,454.17224,-9.2622833
3443,3443,178.945,6.170259,3.2395394,0.0,0,6.6805878,0.0,0.24306478,61.564426,6.7049866,454.25806,-9.2627516
3454,3454,178.9472,6.1705766,3.265348,0.0,0,6.654232,0.0,0.2457954,61.425915,6.6778207,454.34387,-9.2636395
3465,3465,178.9494,6.1800833,3.2956038,0.0,0,6.6278758,0.0,0.24768715,61.475033,6.6543651,454.42969,-9.2629747
3476,3476,178.9516,6.1926146,3.3171878,0.0,0,6.6015201,0.0,0.2501848,61.390228,6.6256328,454.51105,-9.2640667
3487,3487,178.9538,6.193996,3.3451805,0.0,0,6.5751638,0.0,0.25203848,61.292141,6.6010742,454.58365,-9.2638721
3498,3498,178.956,6.1930971,3.3690765,0.0,0,6.5488081,0.0,0.25465229,61.173889,6.5731845,454.65625,-9.2622042
3509,3509,178.9582,6.1665039,3.3991864,0.0,0,6.5224519,0.0,0.25640392,60.899292,6.5484834,454.72885,-9.2605648
3520,3520,178.9604,6.1755748,3.4177682,0.0,0,6.4960961,0.0,0.25884977,60.716274,6.5240626,454.80145,-9.262187
3531,3531,178.9626,6.1918883,3.4437535,0.0,0,6.4697399,0.0,0.26050955,60.691437,6.4958043,453.15158,-9.2622871
3542,3542,178.9648,6.2328315,3.4649606,0.0,0,6.4433842,0.0,0.26294622,60.974285,6.4717488,451.07111,-9.2627306
3553,3553,178.967,6.2935424,3.4982836,0.0,0,6.417028,0.0,0.26506519,61.517143,6.4494958,448.99063,-9.2635565
3564,3564,178.9692,6.3398676,3.5194094,0.0,0,6.3906722,0.0,0.26766494,61.653973,6.4203305,446.91019,-9.2620983
3575,3575,178.9714,6.3380957,3.5496445,0.0,0,6.3643165,0.0,0.2698454,61.70047,6.3935437,444.7966,-9.2634039
3586,3586,178.9736,6.362617,3.5737281,0.0,0,6.3379602,0.0,0.27237305,61.721935,6.3650513,442.59061,-9.2625618
3597,3597,178.9758,6.3624797,3.6096137,0.0,0,6.311604,0.0,0.27491537,61.552528,6.332509,440.38461,-9.2623644
3608,3608,178.978,6.3579993,3.6321352,0.0,0,6.2852483,0.0,0.27732742,61.478947,6.3104815,438.17859,-9.2624168
3619,3619,178.9802,6.3484597,3.6596138,0.0,0,6.2588925,0.0,0.27940434,61.156284,6.2792196,435.9726,-9.2629423
3630,3630,178.9824,6.3615804,3.6819198,0.0,0,6.2325363,0.0,0.28178751,61.088081,6.2545934,435.36618,-9.2630444
3641,3641,178.9846,6.3864717,3.7148049,0.0,0,6.2061806,0.0,0.28424698,61.177265,6.2307062,435.35956,-9.2622576
3652,3652,178.9868,6.4152417,3.7344573,0.0,0,6.1798244,0.0,0.28637117,61.295673,6.2029047,435.35297,-9.2621555
3663,3663,178.989,6.4397659,3.7628763,0.0,0,6.1539736,0.0,0.28872824,61.373657,6.174952,435.34634,-9.262311
3674,3674,178.9912,6.425487,3.786098,0.0,0,6.1289067,0.0,0.29086608,61.147831,6.1507406,435.32837,-9.2627096
3685,3685,178.9934,6.4197845,3.8171744,0.0,0,6.1038404,0.0,0.29353562,60.98875,6.1228471,435.26227,-9.2620201
3696,3696,178.9956,6.421545,3.837786,0.0,0,6.0787735,0.0,0.29545453,60.964951,6.1011429,435.19617,-9.26332
3707,3707,178.9978,6.430233,3.8640552,0.0,0,6.0537066,0.0,0.29789007,60.807724,6.0748744,435.13007,-9.2622585
3718,3718,179.0,6.468585,3.8884807,0.0,0,6.0286398,0.0,0.29999104,61.003265,6.0470605,435.06396,-9.2616234
3729,3729,179.0022,6.4831834,3.9181976,0.0,0,6.0035729,0.0,0.30285132,61.001148,6.0241933,434.98923,-9.2623606
3740,3740,179.0044,6.5069466,3.942096,0.0,0,5.9785061,0.0,0.30464458,61.138542,5.9991951,434.90988,-9.2620182
3751,3751,179.0066,6.5072751,3.9660645,0.0,0,5.9534397,0.0,0.30713919,60.923458,5.9699078,434.83057,-9.2620153
3762,3762,179.0088,6.5226188,3.9884031,0.0,0,5.9283724,0.0,0.30897802,60.99971,5.945262,434.75122,-9.2612963
3773,3773,179.011,6.5173364,4.0166969,0.0,0,5.903306,0.0,0.31185678,60.803059,5.9216909,434.67267,-9.2610979
3784,3784,179.0132,6.5274682,4.0439715,0.0,0,5.8782392,0.0,0.31381491,60.741032,5.8971286,434.59995,-9.2621479
3795,3795,179.0154,6.53652,4.0642576,0.0,0,5.8531723,0.0,0.31619966,60.584476,5.8704338,434.52722,-9.2617645
3806,3806,179.0176,6.5368595,4.088181,0.0,0,5.8281054,0.0,0.31793055,60.580299,5.8491611,434.4545,-9.2621803
3817,3817,179.0198,6.5526981,4.1128283,0.0,0,5.8030386,0.0,0.32080996,60.530777,5.8229561,434.38177,-9.2621241
3828,3828,179.022,6.5930762,4.1409903,0.0,0,5.7779713,0.0,0.32268548,60.735512,5.7997837,434.38599,-9.2627392
3839,3839,179.0242,6.6110616,4.1619802,0.0,0,5.7529049,0.0,0.3253074,60.764889,5.7700987,434.4455,-9.2637033
3850,3850,179.0264,6.6182933,4.1882148,0.0,0,5.7278385,0.0,0.32705906,60.744019,5.7505374,434.50497,-9.2639608
3861,3861,179.0286,6.6451836,4.2094998,0.0,0,5.7027712,0.0,0.32974899,60.810226,5.7238898,434.56448,-9.2636738
3872,3872,179.0308,6.6544423,4.2403626,0.0,0,5.6777043,0.0,0.33184078,60.825073,5.6989169,434.63541,-9.2624369
3883,3883,179.033,6.6644092,4.259985,0.0,0,5.652638,0.0,0.33448794,60.731548,5.6717153,434.94611,-9.2636728
3894,3894,179.0352,6.6989903,4.2902684,0.0,0,5.6275706,0.0,0.33649266,60.905331,5.6459589,435.25681,-9.2631111
3905,3905,179.0374,6.7036295,4.3106933,0.0,0,5.6025043,0.0,0.33918494,60.816303,5.6235418,435.56754,-9.263196
3916,3916,179.0396,6.7157822,4.3434057,0.0,0,5.5782475,0.0,0.34132084,60.757835,5.5961776,435.87823,-9.2623758
3927,3927,179.0418,6.7348547,4.3624654,0.0,0,5.5544,0.0,0.34394789,60.768223,5.5683861,436.2226,-9.2621899
3938,3938,179.044,6.7562394,4.3908648,0.0,0,5.5305514,0.0,0.34605616,60.893631,5.5446768,436.5994,-9.2626486
3949,3949,179.0462,6.7638173,4.4113164,0.0,0,5.5067039,0.0,0.3485949,60.797985,5.5225487,436.97623,-9.2621384
3960,3960,179.0484,6.7651229,4.4431276,0.0,0,5.4828553,0.0,0.35071391,60.67255,5.4946065,437.35303,-9.2614594
3971,3971,179.0506,6.7421885,4.4599166,0.0,0,5.4590077,0.0,0.35316628,60.252529,5.4697661,437.72983,-9.2614851
3982,3982,179.0528,6.7248449,4.4860711,0.0,0,5.4351597,0.0,0.35503942,60.121899,5.4457579,438.19025,-9.2611923
3993,3993,179.055,6.7476602,4.5047956,0.0,0,5.4113116,0.0,0.35751423,60.099335,5.4268117,438.65302,-9.2627401
4004,4004,179.0572,6.7729974,4.5365276,0.0,0,5.3874636,0.0,0.35969624,60.224693,5.4005361,439.11578,-9.2623606
4015,4015,179.0594,6.800674,4.5544138,0.0,0,5.3636155,0.0,0.361983,60.284325,5.3757572,439.57852,-9.2628212
4026,4026,179.0616,6.847908,4.5816889,0.0,0,5.3397679,0.0,0.36427614,60.562469,5.3539143,440.04129,-9.2622776
4037,4037,179.0638,6.8583336,4.6011872,0.0,0,5.3159194,0.0,0.36646977,60.602947,5.3277988,440.50406,-9.2625227
4048,4048,179.066,6.8718052,4.6315417,0.0,0,5.2920718,0.0,0.36891112,60.578022,5.3032246,440.9668,-9.2622156
4059,4059,179.0682,6.8293562,4.6481175,0.0,0,5.2682238,0.0,0.37093621,60.05336,5.2809658,441.42957,-9.2634583
4070,4070,179.0704,6.8194814,4.672328,0.0,0,5.2443757,0.0,0.37316751,59.830624,5.2609773,441.89233,-9.2625399
4081,4081,179.0726,6.8512678,4.6933336,0.0,0,5.2205281,0.0,0.3752813,59.819016,5.2362671,442.35483,-9.2620573
4092,4092,179.0748,6.8846784,4.7222891,0.0,0,5.1966796,0.0,0.37804773,59.999752,5.2125101,442.81729,-9.2617006
4103,4103,179.077,6.9638972,4.7411075,0.0,0,5.172832,0.0,0.37988269,60.61343,5.1889348,443.27975,-9.2615566
4114,4114,179.0792,7.010716,4.767796,0.0,0,5.148984,0.0,0.38252589,60.86668,5.1632547,443.74225,-9.2628975
4125,4125,179.0814,7.0409341,4.791275,0.0,0,5.1251359,0.0,0.3847349,61.068718,5.1365843,444.16135,-9.262886
4136,4136,179.0836,7.0564733,4.8239298,0.0,0,5.1012874,0.0,0.38816181,60.961216,5.1068091,444.50464,-9.2631702
4147,4147,179.0858,7.0095162,4.8467212,0.0,0,5.0774398,0.0,0.38999006,60.428337,5.0855813,444.8479,-9.2616024
4158,4158,179.088,6.9925008,4.8681459,0.0,0,5.0535922,0.0,0.39247471,60.143356,5.0625849,445.19116,-9.2636061
4169,4169,179.0902,6.9979005,4.8907032,0.0,0,5.0308371,0.0,0.39424923,60.069012,5.0392561,445.53442,-9.2635927
4180,4180,179.0924,7.0117669,4.9154878,0.0,0,5.0081549,0.0,0.39733663,59.985287,5.0172114,445.77939,-9.2619009
4191,4191,179.0946,7.0407114,4.9395971,0.0,0,4.9854732,0.0,0.39901814,60.18903,4.9926696,446.00378,-9.2621841
4202,4202,179.0968,7.0631747,4.9580889,0.0,0,4.962791,0.0,0.40150985,60.167576,4.971344,446.22821,-9.2617989
4213,4213,179.099,7.0763121,4.983562,0.0,0,4.9401088,0.0,0.40341875,60.154823,4.9502177,446.45264,-9.2621536
4224,4224,179.1012,7.0878477,5.0089293,0.0,0,4.9174271,0.0,0.40677094,60.068207,4.9212275,446.6713,-9.2625971
4235,4235,179.1034,7.1206484,5.0337067,0.0,0,4.8947449,0.0,0.40830749,60.225742,4.8995948,446.87592,-9.2615128
4246,4246,179.1056,7.1029081,5.0484462,0.0,0,4.8720627,0.0,0.41062543,59.997257,4.8793015,447.08051,-9.2631903
4257,4257,179.1078,7.1008635,5.0757418,0.0,0,4.849381,0.0,0.41272515,59.870075,4.8577528,447.28513,-9.2626028
4268,4268,179.11,7.1052189,5.0968657,0.0,0,4.8266988,0.0,0.41562393,59.712315,4.8319693,447.48975,-9.2629852
4279,4279,179.1122,7.1229401,5.1245494,0.0,0,4.8040171,0.0,0.41744077,59.672829,4.8083749,447.66946,-9.2624311
4290,4290,179.1144,7.1409163,5.1393747,0.0,0,4.7813349,0.0,0.41981664,59.710651,4.7881961,447.84109,-9.2623339
4301,4301,179.1166,7.1521239,5.1628895,0.0,0,4.7586527,0.0,0.42147747,59.78355,4.7681761,448.0127,-9.2631903
4312,4312,179.1188,7.1760545,5.1814914,0.0,0,4.735971,0.0,0.42427143,59.782345,4.7468348,448.18433,-9.2631645
4323,4323,179.121,7.2144623,5.2126422,0.0,0,4.7132888,0.0,0.42634058,59.921841,4.7233448,448.35449,-9.2631378
4334,4334,179.1232,7.2313285,5.2269607,0.0,0,4.6906066,0.0,0.4288646,59.950199,4.7008309,448.5195,-9.2629013
4345,4345,179.1254,7.2355328,5.2548065,0.0,0,4.6679249,0.0,0.43088931,59.968418,4.6768579,448.68451,-9.2621059
4356,4356,179.1276,7.2492523,5.2705898,0.0,0,4.6452427,0.0,0.4334338,59.882427,4.6561923,448.84952,-9.2632866
4367,4367,179.1298,7.2742229,5.3023138,0.0,0,4.622561,0.0,0.43561363,59.902149,4.6334977,449.01453,-9.2642651
4378,4378,179.132,7.3112273,5.319315,0.0,0,4.5998788,0.0,0.43825606,60.071022,4.6115632,449.26053,-9.2630129
4389,4389,179.1342,7.3410006,5.3482904,0.0,0,4.5771966,0.0,0.4405182,60.15868,4.5868549,449.54437,-9.2641821
4400,4400,179.1364,7.3765564,5.3641281,0.0,0,4.5545149,0.0,0.44284686,60.318935,4.5632434,449.82819,-9.2622643
4411,4411,179.1386,7.3900261,5.3983049,0.0,0,4.5320649,0.0,0.44562674,60.271534,4.5354991,450.112,-9.2634792
4422,4422,179.1408,7.3817592,5.4141994,0.0,0,4.5104871,0.0,0.44800371,60.081417,4.5132794,450.38528,-9.263916
4433,4433,179.143,7.3793235,5.4398227,0.0,0,4.4889092,0.0,0.45019856,59.891579,4.4928417,450.5965,-9.2633734
4444,4444,179.1452,7.3405929,5.4548726,0.0,0,4.4673314,0.0,0.45217094,59.473076,4.4705081,450.80771,-9.2622347
4455,4455,179.1474,7.3864131,5.4858246,0.0,0,4.4457541,0.0,0.45496958,59.647305,4.4487057,451.01892,-9.2625036
4466,4466,179.1496,7.3904481,5.5016189,0.0,0,4.4241767,0.0,0.4570094,59.600391,4.4293785,451.23013,-9.2623711
4477,4477,179.1518,7.4105272,5.5255156,0.0,0,4.4025993,0.0,0.45943213,59.590267,4.4063153,451.3891,-9.2630577
4488,4488,179.154,7.4263492,5.5455894,0.0,0,4.3810215,0.0,0.46144497,59.55426,4.3846259,451.51453,-9.2625942
4499,4499,179.1562,7.4356279,5.5700684,0.0,0,4.3594441,0.0,0.46417472,59.53054,4.3595881,451.63992,-9.2631092
4510,4510,179.1584,7.4621973,5.5869913,0.0,0,4.3378663,0.0,0.46583647,59.684151,4.3409977,451.76532,-9.2625732
4521,4521,179.1606,7.4671388,5.6082435,0.0,0,4.3162889,0.0,0.4682011,59.540543,4.3203425,451.89505,-9.262599
4532,4532,179.1628,7.4570756,5.626893,0.0,0,4.2947111,0.0,0.47011408,59.338261,4.3002567,452.0799,-9.2622652
4543,4543,179.165,7.4626951,5.6530652,0.0,0,4.2731338,0.0,0.47318164,59.178532,4.2803164,452.26471,-9.2616711
4554,4554,179.1672,7.4865847,5.6729269,0.0,0,4.2515559,0.0,0.47480211,59.260052,4.2584271,452.44952,-9.2620869
4565,4565,179.1694,7.542583,5.6908484,0.0,0,4.2299786,0.0,0.47725525,59.524837,4.2378249,452.63434,-9.2632456
4576,4576,179.1716,7.6090398,5.712039,0.0,0,4.2084007,0.0,0.47904205,60.003616,4.2146668,452.79791,-9.2620163
4587,4587,179.1738,7.6604233,5.7374139,0.0,0,4.1868229,0.0,0.48245454,60.252556,4.1919389,452.94312,-9.2626419
4598,4598,179.176,7.6666188,5.761785,0.0,0,4.1652455,0.0,0.48425168,60.12672,4.1685314,453.08835,-9.2626266
4609,4609,179.1782,7.670969,5.7805047,0.0,0,4.1436677,0.0,0.48701218,60.018848,4.1434431,453.23355,-9.262125
4620,4620,179.1804,7.6486955,5.8045669,0.0,0,4.1220903,0.0,0.48888898,59.744717,4.1250606,453.37875,-9.2621479
4631,4631,179.1826,7.6505499,5.8245068,0.0,0,4.100513,0.0,0.49200532,59.54417,4.1023264,453.47775,-9.2624331
4642,4642,179.1848,7.6185517,5.8481798,0.0,0,4.0789351,0.0,0.49349329,59.185791,4.0856719,453.57675,-9.26297
4653,4653,179.187,7.6180463,5.8623662,0.0,0,4.0573578,0.0,0.49602103,59.042233,4.0641103,453.67578,-9.262989
4664,4664,179.1892,7.6541243,5.8838172,0.0,0,4.0362897,0.0,0.49760231,59.246071,4.0458083,453.77478,-9.2626858
4675,4675,179.1914,7.7561631,5.9041281,0.0,0,4.0157685,0.0,0.50076514,59.802628,4.0209341,453.86459,-9.262393
4686,4686,179.1936,7.7853446,5.9332199,0.0,0,3.9952466,0.0,0.50270611,59.995075,4.0026426,453.94382,-9.2618742
4697,4697,179.1958,7.812912,5.9471693,0.0,0,3.9747252,0.0,0.50541848,60.048122,3.9799783,454.02301,-9.2630157
4708,4708,179.198,7.8417835,5.9714713,0.0,0,3.9542036,0.0,0.50722855,60.115074,3.9533598,454.10223,-9.2632351
4719,4719,179.2002,7.8293476,5.9916348,0.0,0,3.933682,0.0,0.51053733,59.853329,3.933619,454.18143,-9.262228
4730,4730,179.2024,7.799911,6.0232649,0.0,0,3.9131603,0.0,0.512784,59.486301,3.9140911,454.23004,-9.26402
4741,4741,179.2046,7.779429,6.0335927,0.0,0,3.8926387,0.0,0.51505744,59.228027,3.8937743,454.27625,-9.2633562
4752,4752,179.2068,7.802959,6.0568671,0.0,0,3.872117,0.0,0.5167743,59.266663,3.877862,454.32245,-9.2631245
4763,4763,179.209,7.8372326,6.0707178,0.0,0,3.8515954,0.0,0.51918179,59.361271,3.8562365,454.36865,-9.2633638
4774,4774,179.2112,7.8800688,6.1018806,0.0,0,3.831074,0.0,0.52157873,59.552673,3.8374691,454.34518,-9.2631817
4785,4785,179.2134,7.9145951,6.1139255,0.0,0,3.8105524,0.0,0.52382624,59.761253,3.8167593,454.21317,-9.2620945
4796,4796,179.2156,7.9355922,6.1379933,0.0,0,3.7900305,0.0,0.52592683,59.736839,3.7935576,454.08118,-9.2624941
4807,4807,179.2178,7.9531336,6.1545258,0.0,0,3.7695091,0.0,0.52849019,59.656395,3.7732434,453.94916,-9.2623692
4818,4818,179.22,7.97998,6.1842265,0.0,0,3.7489874,0.0,0.53112131,59.728962,3.7526972,453.81714,-9.2637615
4829,4829,179.2222,7.9988508,6.196898,0.0,0,3.728466,0.0,0.53312922,59.781372,3.7306435,453.4595,-9.2631426
4840,4840,179.2244,8.0004463,6.2226143,0.0,0,3.7079442,0.0,0.53562355,59.619202,3.7074649,453.06348,-9.2626219
4851,4851,179.2266,8.0176363,6.2381153,0.0,0,3.6874225,0.0,0.53785104,59.594875,3.6897023,452.66745,-9.2623653
4862,4862,179.2288,8.0638666,6.2667789,0.0,0,3.6669011,0.0,0.54054874,59.745167,3.6684616,452.27142,-9.2623787
4873,4873,179.231,8.0894442,6.2800603,0.0,0,3.6463795,0.0,0.54251534,59.902836,3.6505039,451.82709,-9.2626963
4884,4884,179.2332,8.076004,6.3014865,0.0,0,3.6258578,0.0,0.54484177,59.664104,3.6289964,451.27924,-9.2618113
4895,4895,179.2354,8.0940237,6.3196268,0.0,0,3.6053362,0.0,0.54692817,59.677254,3.6089699,450.73138,-9.2626104
4906,4906,179.2376,8.1282587,6.3464098,0.0,0,3.5848145,0.0,0.55009973,59.712856,3.5889082,450.18353,-9.2623491
4917,4917,179.2398,8.1606159,6.362206,0.0,0,3.565048,0.0,0.55172998,59.809246,3.5668018,449.63571,-9.2619972
4928,4928,179.242,8.2074299,6.3840332,0.0,0,3.5455253,0.0,0.55458421,60.025021,3.5465574,447.9873,-9.2620249
4939,4939,179.2442,8.2191648,6.4052358,0.0,0,3.5260022,0.0,0.55669236,59.957596,3.5264375,446.0318,-9.262764
4950,4950,179.2464,8.2239494,6.4292936,0.0,0,3.5064795,0.0,0.55988693,59.817726,3.5043054,444.07629,-9.263052
4961,4961,179.2486,8.2418737,6.4479561,0.0,0,3.4869566,0.0,0.56150591,59.817848,3.4823463,442.12079,-9.2623987
4972,4972,179.2508,8.2446594,6.4655409,0.0,0,3.4674337,0.0,0.5640924,59.729725,3.4668281,440.31772,-9.2629566
4983,4983,179.253,8.2201881,6.4844117,0.0,0,3.4479113,0.0,0.56578714,59.422882,3.4493291,438.98315,-9.2624445
4994,4994,179.2552,8.2418814,6.5018482,0.0,0,3.4283881,0.0,0.56871235,59.440105,3.4283133,437.64862,-9.2615547
5005,5005,179.2574,8.2960987,6.5245476,0.0,0,3.4088655,0.0,0.57030731,59.745441,3.4096229,436.31406,-9.2628431
5016,5016,179.2596,8.3041887,6.5421066,0.0,0,3.3893428,0.0,0.57334977,59.594315,3.3889275,434.97949,-9.2637396
5027,5027,179.2618,8.3210697,6.5637879,0.0,0,3.3698196,0.0,0.57503164,59.623154,3.3665223,435.10693,-9.2634716
5038,5038,179.264,8.3705149,6.5830827,0.0,0,3.3502972,0.0,0.57828557,59.73978,3.3488641,435.83411,-9.2629967
5049,5049,179.2662,8.3985357,6.6073022,0.0,0,3.3307743,0.0,0.58004594,59.876404,3.3314235,436.56131,-9.2622089
5060,5060,179.2684,8.4543867,6.6220121,0.0,0,3.3112512,0.0,0.58295184,60.143185,3.3061213,437.28848,-9.2628679
5071,5071,179.2706,8.4728184,6.6429052,0.0,0,3.2917287,0.0,0.58438426,60.132164,3.2873971,438.00085,-9.2623606
5082,5082,179.2728,8.4860401,6.662528,0.0,0,3.2722056,0.0,0.58787608,60.054409,3.2679203,438.64209,-9.2639103
5093,5093,179.275,8.4786253,6.6886401,0.0,0,3.2526829,0.0,0.58960503,59.817345,3.2495775,439.28333,-9.2646036
5104,5104,179.2772,8.4845581,6.6981711,0.0,0,3.2331603,0.0,0.59214234,59.720062,3.2306957,439.92459,-9.2632589
5115,5115,179.2794,8.4746237,6.7211671,0.0,0,3.2136371,0.0,0.59382057,59.595432,3.2129109,440.56583,-9.2630281
5126,5126,179.2816,8.5015125,6.7355957,0.0,0,3.1941147,0.0,0.59675181,59.601555,3.1937485,441.00937,-9.2634878
5137,5137,179.2838,8.5440426,6.7638159,0.0,0,3.1745918,0.0,0.5986585,59.741135,3.1753216,441.3399,-9.2635212
5148,5148,179.286,8.584219,6.7750335,0.0,0,3.1550689,0.0,0.60141623,59.892506,3.1554611,441.67044,-9.2632971
5159,5159,179.2882,8.6048832,6.7991891,0.0,0,3.1355815,0.0,0.60326242,59.995907,3.1368015,442.00098,-9.2624388
5170,5170,179.2904,8.6457272,6.8131194,0.0,0,3.1170006,0.0,0.60589409,60.095947,3.119288,442.32755,-9.2623062
5181,5181,179.2926,8.6469774,6.8405299,0.0,0,3.098428,0.0,0.6082117,59.904789,3.0988002,442.61819,-9.2625561
5192,5192,179.2948,8.6680079,6.8526988,0.0,0,3.0798559,0.0,0.61064512,59.922642,3.0764108,442.90887,-9.2636251
5203,5203,179.297,8.6817122,6.8758354,0.0,0,3.0612833,0.0,0.6128571,59.885635,3.060986,443.19952,-9.262845
5214,5214,179.2992,8.7056541,6.8888764,0.0,0,3.042711,0.0,0.61514276,59.908905,3.0380633,443.4902,-9.2627716
5225,5225,179.3014,8.727107,6.9169393,0.0,0,3.0241387,0.0,0.61781085,59.851311,3.0218732,443.82544,-9.2628059
5236,5236,179.3036,8.7518234,6.9284935,0.0,0,3.0055661,0.0,0.61993611,59.873535,3.0007939,444.19516,-9.2631903
5247,5247,179.3058,8.7756367,6.9491439,0.0,0,2.986994,0.0,0.62210792,59.965256,2.9820325,444.56491,-9.2628031
5258,5258,179.308,8.8047867,6.9657021,0.0,0,2.9684215,0.0,0.62442863,59.998325,2.9647875,444.93463,-9.2640381
5269,5269,179.3102,8.8138647,6.989995,0.0,0,2.9498491,0.0,0.62711936,59.981674,2.9498608,445.2995,-9.2634096
5280,5280,179.3124,8.8276834,7.0026493,0.0,0,2.9312766,0.0,0.62897205,59.926022,2.928093,445.49091,-9.2635603
5291,5291,179.3146,8.8383942,7.0232544,0.0,0,2.9127042,0.0,0.63150924,59.86935,2.9100044,445.68234,-9.2633743
5302,5302,179.3168,8.8860722,7.0393076,0.0,0,2.8941319,0.0,0.63349289,60.018665,2.8901539,445.87375,-9.2617903
5313,5313,179.319,8.8858604,7.0628037,0.0,0,2.8755593,0.0,0.63661683,59.836132,2.8758812,446.06516,-9.2618742
5324,5324,179.3212,8.9367638,7.0762019,0.0,0,2.8569868,0.0,0.63794088,60.08234,2.8573422,446.14639,-9.2619581
5335,5335,179.3234,8.9826488,7.0961423,0.0,0,2.8384147,0.0,0.64086968,60.230465,2.8413706,446.1134,-9.2624178
5346,5346,179.3256,9.0463352,7.1121783,0.0,0,2.8198423,0.0,0.64247531,60.512711,2.8186605,446.08041,-9.2630062
5357,5357,179.3278,9.0760698,7.1352415,0.0,0,2.8012698,0.0,0.64594465,60.584621,2.801739,446.04739,-9.2626753
5368,5368,179.33,9.1074858,7.1554456,0.0,0,2.7826974,0.0,0.64782697,60.634823,2.7786593,446.0144,-9.2620411
5379,5379,179.3322,9.1062832,7.1712561,0.0,0,2.7641251,0.0,0.65060687,60.512581,2.7639487,446.12003,-9.2629328
5390,5390,179.3344,9.1406088,7.1915674,0.0,0,2.7455528,0.0,0.65229744,60.629555,2.7456141,446.23221,-9.2622004
5401,5401,179.3366,9.1779976,7.2109013,0.0,0,2.72698,0.0,0.65581042,60.627472,2.7263548,446.34442,-9.2636061
5412,5412,179.3388,9.2046175,7.2335453,0.0,0,2.7086811,0.0,0.65766007,60.707184,2.7021041,446.45663,-9.2622614
5423,5423,179.341,9.2089119,7.2477174,0.0,0,2.691015,0.0,0.66058302,60.543461,2.6870365,446.64612,-9.2633371
5434,5434,179.3432,9.2096558,7.2697363,0.0,0,2.6733489,0.0,0.66230744,60.470272,2.6675341,446.94315,-9.2625532
5445,5445,179.3454,9.2453299,7.2842317,0.0,0,2.655683,0.0,0.66541773,60.535229,2.6525369,447.24017,-9.2635746
5456,5456,179.3476,9.2759771,7.3076982,0.0,0,2.6380169,0.0,0.66702926,60.552448,2.6353977,447.5372,-9.2624903
5467,5467,179.3498,9.2962332,7.3191838,0.0,0,2.6203508,0.0,0.66995865,60.546036,2.6129043,447.83423,-9.2620564
5478,5478,179.352,9.3036728,7.3410673,0.0,0,2.602685,0.0,0.67149836,60.518486,2.5954564,448.18362,-9.2633743
5489,5489,179.3542,9.2964163,7.3549104,0.0,0,2.5850191,0.0,0.67468929,60.265419,2.5814989,448.54007,-9.2626095
5500,5500,179.3564,9.324873,7.3809786,0.0,0,2.567353,0.0,0.67648447,60.312862,2.5577936,448.89651,-9.2626362
5511,5511,179.3586,9.3551521,7.3898544,0.0,0,2.5496869,0.0,0.67907602,60.394611,2.5425048,449.25293,-9.2624626
5522,5522,179.3608,9.3914595,7.4120102,0.0,0,2.532021,0.0,0.6808461,60.532948,2.5243716,449.59113,-9.2633724
5533,5533,179.363,9.4397621,7.4242148,0.0,0,2.5143549,0.0,0.68380624,60.674839,2.5099041,449.89474,-9.2626467
5544,5544,179.3652,9.4639807,7.4505763,0.0,0,2.4966891,0.0,0.68568748,60.762226,2.4914031,450.19836,-9.2625475
5555,5555,179.3674,9.499238,7.4598227,0.0,0,2.479023,0.0,0.68814147,60.789024,2.4738779,450.50201,-9.2619305
5566,5566,179.3696,9.5163584,7.4803905,0.0,0,2.4613569,0.0,0.69005108,60.82877,2.4551163,450.80563,-9.2631369
5577,5577,179.3718,9.5433645,7.4925385,0.0,0,2.443691,0.0,0.69278002,60.686245,2.4363923,450.90097,-9.2629194
5588,5588,179.374,9.5917253,7.5198736,0.0,0,2.4260249,0.0,0.69514471,60.880951,2.4180446,450.94717,-9.2623386
5599,5599,179.3762,9.653389,7.5327787,0.0,0,2.4083591,0.0,0.69782192,61.092873,2.3999898,450.99338,-9.2618027
5610,5610,179.3784,9.6809044,7.5535498,0.0,0,2.3906929,0.0,0.69996607,61.198135,2.382139,451.03958,-9.2627974
5621,5621,179.3806,9.7390213,7.5665288,0.0,0,2.3730268,0.0,0.70228034,61.404808,2.3654966,451.07318,-9.2624798
5632,5632,179.3828,9.7493153,7.5921607,0.0,0,2.355361,0.0,0.70502168,61.30954,2.3449044,451.07318,-9.2622213
5643,5643,179.385,9.7215319,7.6035523,0.0,0,2.3376951,0.0,0.7072283,60.991615,2.3319395,451.07318,-9.262392
5654,5654,179.3872,9.7063522,7.6246285,0.0,0,2.3200288,0.0,0.70981467,60.811913,2.3119693,451.07318,-9.2638788
5665,5665,179.3894,9.7311563,7.6369638,0.0,0,2.3028576,0.0,0.71168375,60.878761,2.2976487,451.07318,-9.262496
5676,5676,179.3916,9.7565908,7.6605802,0.0,0,2.2860541,0.0,0.71454477,60.770767,2.2821798,451.15582,-9.2625818
5687,5687,179.3938,9.8403282,7.6725512,0.0,0,2.2692504,0.0,0.71633339,61.142467,2.2622776,451.26804,-9.2624998
5698,5698,179.396,9.8857212,7.6914105,0.0,0,2.2524469,0.0,0.7191177,61.350399,2.2484493,451.38025,-9.2623558
5709,5709,179.3982,9.9095793,7.7081485,0.0,0,2.2356431,0.0,0.72118229,61.308525,2.2301426,451.49243,-9.2626305
5720,5720,179.4004,9.9000854,7.7291074,0.0,0,2.2188396,0.0,0.72433007,61.06144,2.210721,451.59674,-9.263526
5731,5731,179.4026,9.9235172,7.741375,0.0,0,2.2020361,0.0,0.72554898,61.198227,2.1971495,451.66934,-9.2625818
5742,5742,179.4048,9.9085035,7.7571807,0.0,0,2.1852326,0.0,0.728306,60.904774,2.1824179,451.74194,-9.2624559
5753,5753,179.407,9.9158468,7.7720571,0.0,0,2.1684289,0.0,0.72978848,60.883862,2.1650295,451.81454,-9.2623224
5764,5764,179.4092,9.9348097,7.7913537,0.0,0,2.1516254,0.0,0.73329175,60.76313,2.1489224,451.88715,-9.2632847
5775,5775,179.4114,9.9892864,7.8090115,0.0,0,2.1348217,0.0,0.73466557,61.027775,2.1319911,451.98166,-9.2633553
5786,5786,179.4136,10.093235,7.8214889,0.0,0,2.1180182,0.0,0.7372883,61.44503,2.1132653,452.08725,-9.2627268
5797,5797,179.4158,10.162313,7.8410764,0.0,0,2.1012144,0.0,0.73909491,61.805191,2.0995903,452.19284,-9.262536
5808,5808,179.418,10.211718,7.8570557,0.0,0,2.0844109,0.0,0.74245173,61.868118,2.0790677,452.29846,-9.2626276
5819,5819,179.4202,10.254423,7.8798041,0.0,0,2.0676074,0.0,0.74438572,62.010277,2.0630386,452.40994,-9.2625618
5830,5830,179.4224,10.301102,7.8931503,0.0,0,2.0508039,0.0,0.74767655,62.101891,2.0438838,452.56177,-9.2616329
5841,5841,179.4246,10.327351,7.9109311,0.0,0,2.0340002,0.0,0.7488969,62.208702,2.0264926,452.71359,-9.2619658
5852,5852,179.4268,10.339028,7.9255519,0.0,0,2.0171967,0.0,0.75237238,62.040474,2.0075984,452.86539,-9.2625265
5863,5863,179.429,10.361711,7.9498863,0.0,0,2.0003929,0.0,0.75410724,62.0872,1.9897075,453.01721,-9.2615833
5874,5874,179.4312,10.382912,7.9624581,0.0,0,1.9835894,0.0,0.75746828,61.960144,1.9720824,453.10364,-9.2618074
5885,5885,179.4334,10.449469,7.9838872,0.0,0,1.9667857,0.0,0.75917524,62.252712,1.9544036,453.14481,-9.2618189
5896,5896,179.4356,10.473099,7.995347,0.0,0,1.9499823,0.0,0.76232541,62.20274,1.9351244,453.18597,-9.2629461
5907,5907,179.4378,10.495509,8.0196047,0.0,0,1.9331787,0.0,0.76406556,62.270412,1.9217947,453.22717,-9.2629385
5918,5918,179.44,10.515634,8.0293989,0.0,0,1.9170679,0.0,0.76706278,62.21048,1.9074138,453.29648,-9.2625332
5929,5929,179.4422,10.538002,8.0502119,0.0,0,1.9010825,0.0,0.76879919,62.231091,1.89061,453.46149,-9.2623329
5940,5940,179.4444,10.527407,8.0618229,0.0,0,1.8850974,0.0,0.77172899,61.969109,1.8721844,453.6265,-9.26299
5951,5951,179.4466,10.527172,8.0872469,0.0,0,1.8691123,0.0,0.77371097,61.829659,1.8575194,453.7915,-9.2626963
5962,5962,179.4488,10.529173,8.0932169,0.0,0,1.853127,0.0,0.7760911,61.733677,1.8407233,453.95654,-9.2633705
5973,5973,179.451,10.570079,8.1137924,0.0,0,1.8371419,0.0,0.77795362,61.798164,1.8270881,454.03491,-9.2616377
5984,5984,179.4532,10.608715,8.1245794,0.0,0,1.8211566,0.0,0.7806477,61.868542,1.8103145,454.07449,-9.2624826
5995,5995,179.4554,10.641788,8.1465502,0.0,0,1.8051715,0.0,0.78252149,61.935825,1.7946323,454.11411,-9.2628212
6006,6006,179.4576,10.664756,8.1528225,0.0,0,1.7891862,0.0,0.78454167,61.963005,1.7847421,454.15372,-9.2610416
6017,6017,179.4598,10.742507,8.1728897,0.0,0,1.773201,0.0,0.7867108,62.272198,1.7708718,454.16577,-9.2614956
6028,6028,179.462,10.806174,8.1844263,0.0,0,1.7572159,0.0,0.78893232,62.490242,1.748401,454.02716,-9.2617464
6039,6039,179.4642,10.841132,8.2110739,0.0,0,1.7412306,0.0,0.79236007,62.478264,1.7324154,453.88855,-9.2629547
6050,6050,179.4664,10.889306,8.2196503,0.0,0,1.7252455,0.0,0.79415184,62.677631,1.7189076,453.74994,-9.2625141
6061,6061,179.4686,10.952982,8.2389269,0.0,0,1.7092602,0.0,0.79678351,62.860176,1.6987126,453.61133,-9.2630787
6072,6072,179.4708,10.991644,8.2509737,0.0,0,1.693275,0.0,0.79883587,62.901375,1.6828158,453.61145,-9.262434
6083,6083,179.473,11.040364,8.2753382,0.0,0,1.6772897,0.0,0.80213302,62.987465,1.666787,453.69727,-9.2622147
6094,6094,179.4752,11.083785,8.285347,0.0,0,1.6613046,0.0,0.80372006,63.210094,1.6543409,453.78305,-9.2618752
6105,6105,179.4774,11.106702,8.3050041,0.0,0,1.6453193,0.0,0.80672741,63.126862,1.6387938,453.86887,-9.2627249
6116,6116,179.4796,11.121723,8.3166265,0.0,0,1.6293342,0.0,0.80821574,63.133835,1.6209117,453.9433,-9.2624779
6127,6127,179.4818,11.15584,8.3356438,0.0,0,1.613349,0.0,0.81146312,63.102348,1.6041847,453.8905,-9.2626982
6138,6138,179.484,11.167398,8.351943,0.0,0,1.5973638,0.0,0.81337035,63.067276,1.5888506,453.83771,-9.2633905
6149,6149,179.4862,11.210938,8.367939,0.0,0,1.5813786,0.0,0.81645685,63.042301,1.5729873,453.78491,-9.2625036
6160,6160,179.4884,11.290592,8.3835936,0.0,0,1.5654866,0.0,0.81791449,63.410488,1.5575249,453.73212,-9.2625151
6171,6171,179.4906,11.346721,8.401227,0.0,0,1.5502799,0.0,0.82167643,63.478371,1.5438713,453.44531,-9.2628927
6182,6182,179.4928,11.353413,8.4198742,0.0,0,1.5350735,0.0,0.8232711,63.472908,1.5257655,452.96347,-9.2627001
6193,6193,179.495,11.346966,8.4293289,0.0,0,1.5198671,0.0,0.82593906,63.215069,1.5094776,452.48163,-9.2627125
6204,6204,179.4972,11.320986,8.4438429,0.0,0,1.5046606,0.0,0.82694775,63.039368,1.4959296,451.99979,-9.2624121
6215,6215,179.4994,11.294405,8.4577246,0.0,0,1.4894543,0.0,0.83044213,62.687153,1.4827963,451.52042,-9.2624941
6226,6226,179.5016,11.324627,8.477334,0.0,0,1.4742478,0.0,0.83197939,62.784496,1.4709263,451.3092,-9.2620277
6237,6237,179.5038,11.38194,8.4852219,0.0,0,1.4590415,0.0,0.83477175,62.854103,1.4544863,451.09796,-9.2624254
6248,6248,179.506,11.470032,8.502142,0.0,0,1.4438351,0.0,0.83569384,63.259853,1.4377201,450.88675,-9.2633085
6259,6259,179.5082,11.56431,8.5136356,0.0,0,1.4286287,0.0,0.83924598,63.578007,1.4275955,450.67554,-9.2633533
6270,6270,179.5104,11.663774,8.5358992,0.0,0,1.4134222,0.0,0.84087455,64.032455,1.4076051,449.54593,-9.2635832
6281,6281,179.5126,11.728357,8.5437899,0.0,0,1.3982159,0.0,0.84376484,64.23452,1.3941183,447.39197,-9.2617397
6292,6292,179.5148,11.785536,8.566184,0.0,0,1.3830094,0.0,0.8457703,64.385208,1.3756129,445.23798,-9.2616549
6303,6303,179.517,11.784936,8.5763845,0.0,0,1.3678031,0.0,0.84908295,64.199951,1.3598739,443.08401,-9.262496
6314,6314,179.5192,11.807978,8.6030216,0.0,0,1.3525968,0.0,0.85120249,64.199432,1.3436685,440.93005,-9.2622929
6325,6325,179.5214,11.813744,8.6059618,0.0,0,1.3373904,0.0,0.85337567,64.057114,1.3276387,436.3887,-9.261838
6336,6336,179.5236,11.85201,8.6267004,0.0,0,1.322184,0.0,0.85524887,64.164124,1.3132988,431.68509,-9.2617769
6347,6347,179.5258,11.904933,8.6371937,0.0,0,1.3069774,0.0,0.85845345,64.233673,1.300131,426.98145,-9.2631073
6358,6358,179.528,11.980881,8.6637859,0.0,0,1.2917712,0.0,0.86075914,64.456375,1.2859485,422.27783,-9.2643509
6369,6369,179.5302,12.054622,8.668704,0.0,0,1.2765647,0.0,0.86306608,64.745735,1.2689184,418.65317,-9.2623529
6380,6380,179.5324,12.123289,8.6875582,0.0,0,1.2613584,0.0,0.86497176,65.038193,1.2517631,416.647,-9.2611399
6391,6391,179.5346,12.17965,8.6995506,0.0,0,1.2461519,0.0,0.86804849,65.135567,1.2339098,414.64084,-9.2608185
6402,6402,179.5368,12.220603,8.7267036,0.0,0,1.2309455,0.0,0.87104136,65.155891,1.2212625,412.63467,-9.2613811
6413,6413,179.539,12.221161,8.731266,0.0,0,1.2160306,0.0,0.87298608,64.997482,1.2041093,410.62851,-9.2613831
6424,6424,179.5412,12.225318,8.7511816,0.0,0,1.2015678,0.0,0.87539756,64.876869,1.1881311,411.80267,-9.2624006
6435,6435,179.5434,12.201499,8.76085,0.0,0,1.1871049,0.0,0.87732852,64.618187,1.1744827,413.47903,-9.262538
6446,6446,179.5456,12.219324,8.7829266,0.0,0,1.1726422,0.0,0.88035017,64.488823,1.1604452,415.15543,-9.2623148
6457,6457,179.5478,12.242066,8.7874756,0.0,0,1.1581794,0.0,0.88179535,64.498718,1.1506586,416.83179,-9.2623091
6468,6468,179.55,12.302796,8.806572,0.0,0,1.1437165,0.0,0.88461053,64.657883,1.1359388,418.44937,-9.2615776
6479,6479,179.5522,12.31786,8.8178711,0.0,0,1.1292537,0.0,0.8864373,64.638786,1.1196893,419.94608,-9.2621031
6490,6490,179.5544,12.351479,8.8370142,0.0,0,1.114791,0.0,0.88949895,64.612831,1.1072658,421.44281,-9.2626591
6501,6501,179.5566,12.392076,8.8466654,0.0,0,1.1003282,0.0,0.89081228,64.750572,1.0987521,422.93954,-9.2626171
6512,6512,179.5588,12.428643,8.8605089,0.0,0,1.0858653,0.0,0.89350903,64.7556,1.0816137,424.43628,-9.2620811
6523,6523,179.561,12.510363,8.8714638,0.0,0,1.0714027,0.0,0.89469796,65.081406,1.0672182,424.51355,-9.2611198
6534,6534,179.5632,12.628292,8.8894281,0.0,0,1.0569397,0.0,0.89842463,65.444855,1.0550107,424.21552,-9.261879
6545,6545,179.5654,12.749218,8.9028816,0.0,0,1.042477,0.0,0.8997336,65.977554,1.0362097,423.91751,-9.2620134
6556,6556,179.5676,12.843841,8.9177532,0.0,0,1.0280141,0.0,0.90308332,66.261597,1.0206194,423.61951,-9.2618484
6567,6567,179.5698,12.910522,8.9352655,0.0,0,1.0135514,0.0,0.90493226,66.5252,1.0062582,423.42935,-9.2610044
6578,6578,179.572,12.959558,8.9512892,0.0,0,0.99908859,0.0,0.90876412,66.490921,0.98898488,423.55521,-9.2607899
6589,6589,179.5742,12.981505,8.9663172,0.0,0,0.98462576,0.0,0.90987664,66.59436,0.9736253,423.68103,-9.2622156
6600,6600,179.5764,13.017116,8.9770489,0.0,0,0.97016299,0.0,0.91313124,66.525871,0.95628941,423.80685,-9.2616634
6611,6611,179.5786,13.006368,8.9960747,0.0,0,0.95570022,0.0,0.91485131,66.336472,0.94465375,423.93268,-9.2624598
6622,6622,179.5808,13.012921,9.0106716,0.0,0,0.94123739,0.0,0.91899019,66.062439,0.9304865,424.42947,-9.262454
6633,6633,179.583,13.020727,9.0288162,0.0,0,0.92677456,0.0,0.92004931,66.030861,0.91381371,425.07187,-9.2628202
6644,6644,179.5852,13.033145,9.0358019,0.0,0,0.91231167,0.0,0.9231528,65.8965,0.90225393,425.71423,-9.2627563
6655,6655,179.5874,13.061639,9.0525932,0.0,0,0.89784902,0.0,0.92430234,66.003944,0.88925081,426.35663,-9.2621803
6666,6666,179.5896,13.082377,9.0607214,0.0,0,0.88385707,0.0,0.92738754,65.893394,0.87588739,427.02045,-9.2626152
6677,6677,179.5918,13.110067,9.0783825,0.0,0,0.8701027,0.0,0.9281882,65.985146,0.8620249,427.78088,-9.2620058
6688,6688,179.594,13.141847,9.0820274,0.0,0,0.85634828,0.0,0.93105906,65.945114,0.85225809,428.54132,-9.2616386
6699,6699,179.5962,13.206351,9.1018677,0.0,0,0.84259385,0.0,0.93253684,66.156235,0.83601278,429.30176,-9.2623396
6710,6710,179.5984,13.311799,9.1117067,0.0,0,0.82883948,0.0,0.93606615,66.455391,0.82652819,430.06216,-9.2602682
6721,6721,179.6006,13.437984,9.1365719,0.0,0,0.81508505,0.0,0.9379701,66.906883,0.80546904,430.84396,-9.2620144
6732,6732,179.6028,13.507402,9.1404562,0.0,0,0.80133069,0.0,0.94078958,67.144714,0.78997576,431.63748,-9.2623396
6743,6743,179.605,13.592649,9.1592016,0.0,0,0.78757626,0.0,0.94229138,67.458069,0.77796108,432.43103,-9.2616463
6754,6754,179.6072,13.649879,9.1677532,0.0,0,0.77382189,0.0,0.94553399,67.497742,0.76379013,433.22455,-9.262269
6765,6765,179.6094,13.684027,9.1929855,0.0,0,0.76006752,0.0,0.94803077,67.524307,0.74755102,433.9993,-9.2614851
6776,6776,179.6116,13.652852,9.1982317,0.0,0,0.74631304,0.0,0.95040572,67.226234,0.73443699,434.62073,-9.2618675
6787,6787,179.6138,13.674134,9.2157431,0.0,0,0.73255867,0.0,0.95236909,67.202271,0.72417641,435.24213,-9.2608118
6798,6798,179.616,13.704315,9.223444,0.0,0,0.7188043,0.0,0.95483822,67.157455,0.70674664,435.86356,-9.2611837
6809,6809,179.6182,13.763371,9.2453365,0.0,0,0.70504987,0.0,0.95735949,67.243813,0.6931687,436.48495,-9.2623949
6820,6820,179.6204,13.795948,9.2497368,0.0,0,0.69129544,0.0,0.95906991,67.301842,0.68042171,437.19727,-9.2626133
6831,6831,179.6226,13.837117,9.2660294,0.0,0,0.67754108,0.0,0.96140951,67.342606,0.66815323,437.97733,-9.2625227
6842,6842,179.6248,13.8855,9.2753572,0.0,0,0.66378671,0.0,0.96334082,67.477989,0.65473473,438.75739,-9.2621517
6853,6853,179.627,13.937014,9.2963572,0.0,0,0.65003228,0.0,0.96642643,67.564995,0.64447296,439.53748,-9.2619724
6864,6864,179.6292,13.954365,9.2990808,0.0,0,0.63627785,0.0,0.967619,67.561806,0.6284638,440.29807,-9.2618475
6875,6875,179.6314,14.003703,9.3164825,0.0,0,0.62252349,0.0,0.97048575,67.574448,0.62091774,440.54269,-9.2628002
6886,6886,179.6336,14.061113,9.326231,0.0,0,0.60876906,0.0,0.97208369,67.724586,0.60442138,440.78729,-9.2623672
6897,6897,179.6358,14.181135,9.3469486,0.0,0,0.59501469,0.0,0.97595042,68.022858,0.59128201,441.03189,-9.2613249
6908,6908,179.638,14.290896,9.3539772,0.0,0,0.58126026,0.0,0.97671729,68.478493,0.57605416,441.27649,-9.2609701
6919,6919,179.6402,14.390542,9.3672934,0.0,0,0.56812865,0.0,0.97978574,68.762085,0.56091416,441.59702,-9.261343
6930,6930,179.6424,14.486824,9.3789854,0.0,0,0.55503875,0.0,0.98112231,69.210495,0.54709852,441.99344,-9.2610493
6940,6940,179.6444,14.545001,9.3932371,0.0,0,0.54313874,0.0,0.98459852,69.198227,0.53646785,442.35382,-9.2610397