File: clean data/testID_0199.csv
level_0,index,Time(sec),Force(kN),Jaw(mm),PowAngle(deg),Power(W),Pram,PTemp,Strain,Stress(MPa),Stroke(mm),TC1(C),wedge(mm)
1875,1875,155.3453,0.56108326,0.0095155397,0.0,0,8.9751787,0.0,0.00059953623,5.6774955,9.9867649,335.5,-9.3016939
1877,1877,155.3457,3.8013105,0.057135206,0.0,0,8.9166508,0.0,0.0035391934,43.405819,9.9224167,335.54388,-9.3004522
1879,1879,155.3461,5.8241692,0.11445784,0.0,0,8.8581219,0.0,0.0070724138,72.250977,9.8563137,335.58777,-9.2985287
1881,1881,155.3465,6.6558609,0.20105116,0.0,0,8.7995939,0.0,0.01274104,82.328598,9.7713413,335.638,-9.2978354
1883,1883,155.3469,7.1556597,0.33871835,0.0,0,8.7416534,0.0,0.022063781,89.029396,9.6756926,335.80853,-9.2988882
1885,1885,155.3473,7.6209345,0.42549217,0.0,0,8.6858492,0.0,0.027908133,93.460594,9.5664396,335.97906,-9.2986441
1887,1887,155.3477,8.1225605,0.52481931,0.0,0,8.6301851,0.0,0.035135839,99.246758,9.4658375,336.1496,-9.2968817
1889,1889,155.3481,8.7659359,0.56353509,0.0,0,8.574522,0.0,0.038065247,106.99241,9.3800058,336.32016,-9.295166
1891,1891,155.3485,8.3726835,0.61296082,0.0,0,8.518857,0.0,0.041065581,102.93645,9.315094,336.49069,-9.2932863
1893,1893,155.3489,8.66325,0.6824789,0.0,0,8.4631929,0.0,0.046411339,104.49924,9.2458887,336.66122,-9.2960997
1895,1895,155.3493,8.9921751,0.73275775,0.0,0,8.4075298,0.0,0.049472153,108.70825,9.1854391,336.83176,-9.2964373
1897,1897,155.3497,9.3692198,0.82089329,0.0,0,8.3518648,0.0,0.055640321,112.54918,9.1109076,337.00232,-9.2959547
1899,1899,155.3501,8.9639397,0.9201234,0.0,0,8.2962017,0.0,0.062760182,108.01537,9.0305681,337.17285,-9.2947664
1901,1901,155.3505,9.1256409,1.0022792,0.0,0,8.2405376,0.0,0.068441331,107.84556,8.9435673,337.34338,-9.2948599
1903,1903,155.3509,9.2473898,1.0733283,0.0,0,8.1848736,0.0,0.074093379,109.55055,8.8681049,337.51392,-9.2946224
1905,1905,155.3513,9.553299,1.1059911,0.0,0,8.1292095,0.0,0.07636825,112.06118,8.7987242,337.68445,-9.2954063
1907,1907,155.3517,9.5518665,1.1598566,0.0,0,8.0735455,0.0,0.079759814,112.84219,8.7414246,337.85501,-9.2958612
1909,1909,155.3521,9.383112,1.2175329,0.0,0,8.0196619,0.0,0.084603988,109.42284,8.6892366,338.02554,-9.296442
1911,1911,155.3525,9.7848434,1.2762035,0.0,0,7.9666953,0.0,0.088151865,113.87079,8.6323051,338.19608,-9.2947083
1913,1913,155.3529,9.8078156,1.3604553,0.0,0,7.9137359,0.0,0.094357342,113.54774,8.5659418,338.36661,-9.2938032
1915,1915,155.3533,9.8262796,1.4322131,0.0,0,7.8607755,0.0,0.10021479,113.32641,8.4921169,338.53714,-9.2942514
1917,1917,155.3537,9.6373692,1.5073434,0.0,0,7.8078156,0.0,0.10504584,110.48275,8.4232225,338.7077,-9.2949629
1919,1919,155.3541,9.8503599,1.5501765,0.0,0,7.7548552,0.0,0.10895178,112.24015,8.3606167,338.87823,-9.2939939
1921,1921,155.3545,9.9575682,1.5797867,0.0,0,7.7018952,0.0,0.11115302,113.2804,8.3063622,339.04877,-9.2943516
1923,1923,155.3549,10.051047,1.6422105,0.0,0,7.6489348,0.0,0.11507449,114.09901,8.2572975,339.2193,-9.2948885
1925,1925,155.3553,9.9695282,1.6866124,0.0,0,7.5959754,0.0,0.11919681,112.63946,8.2082033,339.38986,-9.2941532
1927,1927,155.3557,10.200024,1.7353425,0.0,0,7.543015,0.0,0.12251654,114.72317,8.156991,339.56039,-9.2944975
1929,1929,155.3561,10.163625,1.8037057,0.0,0,7.4900556,0.0,0.12741825,113.98842,8.1019983,339.73093,-9.2936316
1931,1931,155.3565,10.253131,1.8519092,0.0,0,7.4370952,0.0,0.13169298,114.28032,8.0437393,339.89401,-9.2928448
1933,1933,155.3569,10.148298,1.9106748,0.0,0,7.3846664,0.0,0.13561803,113.03722,7.9855494,339.99023,-9.2933693
1935,1935,155.3573,10.285755,1.9586107,0.0,0,7.3341722,0.0,0.13957743,113.5899,7.931138,340.08646,-9.2957497
1937,1937,155.3577,10.364043,1.9925226,0.0,0,7.2838039,0.0,0.14244868,114.45647,7.881804,340.18265,-9.2956982
1939,1939,155.3581,10.359341,2.0457842,0.0,0,7.2334356,0.0,0.14596152,113.89806,7.8404541,340.27887,-9.2945585
1941,1941,155.3585,10.393757,2.0901818,0.0,0,7.1830673,0.0,0.1499604,113.93185,7.7925568,340.37509,-9.2929335
1943,1943,155.3589,10.494921,2.1325905,0.0,0,7.1326995,0.0,0.15311238,114.37681,7.7465291,340.47128,-9.2931824
1945,1945,155.3593,10.625943,2.1905019,0.0,0,7.0823312,0.0,0.15715492,115.6076,7.6947203,340.5675,-9.2933998
1947,1947,155.3597,10.546608,2.242852,0.0,0,7.0319633,0.0,0.16185254,114.38383,7.641192,340.66373,-9.2957945
1949,1949,155.3601,10.528149,2.2949421,0.0,0,6.981595,0.0,0.16565256,113.55539,7.5929093,340.75992,-9.2955914
1951,1951,155.3605,10.618999,2.3351402,0.0,0,6.9312277,0.0,0.16874881,114.09,7.5474768,340.85614,-9.294219
1953,1953,155.3609,10.76263,2.3726912,0.0,0,6.8808594,0.0,0.17226341,115.27684,7.5023241,340.95236,-9.2937517
1955,1955,155.3613,10.754708,2.4224637,0.0,0,6.830492,0.0,0.17555559,114.89606,7.4569998,341.04855,-9.2941513
1957,1957,155.3617,10.738023,2.4650548,0.0,0,6.7801232,0.0,0.17913783,114.38614,7.4123936,341.14478,-9.2944498
1959,1959,155.3621,10.821535,2.5102656,0.0,0,6.7313671,0.0,0.18309207,114.63875,7.3661919,341.241,-9.2953005
1961,1961,155.3625,10.928051,2.5667298,0.0,0,6.6834416,0.0,0.18680434,115.24142,7.315136,341.33719,-9.2955332
1963,1963,155.3629,10.939013,2.6113992,0.0,0,6.6355219,0.0,0.19094807,115.08001,7.2679529,341.43341,-9.2945786
1965,1965,155.3633,10.924544,2.6550198,0.0,0,6.5876017,0.0,0.19462676,114.50224,7.220716,341.52963,-9.2950621
1967,1967,155.3637,10.989351,2.7037866,0.0,0,6.5396819,0.0,0.19794628,114.74891,7.1697106,341.62582,-9.2941093
1969,1969,155.3641,11.077514,2.7397802,0.0,0,6.4917622,0.0,0.20163304,115.25251,7.1255145,341.72205,-9.2955847
1971,1971,155.3645,11.130149,2.7833893,0.0,0,6.4438419,0.0,0.20485438,115.49019,7.0854006,341.81827,-9.2955742
1973,1973,155.3649,11.170442,2.8367581,0.0,0,6.3959212,0.0,0.2089477,115.28197,7.0340724,341.91446,-9.2950573
1975,1975,155.3653,11.228719,2.8805311,0.0,0,6.3480015,0.0,0.213166,115.37706,6.9858489,342.01068,-9.2958746
1977,1977,155.3657,11.282153,2.9335694,0.0,0,6.3000817,0.0,0.21688434,115.63145,6.9407954,342.1069,-9.2958021
1979,1979,155.3661,11.317139,2.9877546,0.0,0,6.252162,0.0,0.2216123,115.34599,6.8958459,342.20309,-9.2943029
1981,1981,155.3665,11.348039,3.0262949,0.0,0,6.2042422,0.0,0.22527064,115.23502,6.8448529,342.28012,-9.2949429
1983,1983,155.3669,11.431176,3.0741086,0.0,0,6.1568027,0.0,0.22858354,115.6491,6.7929344,342.24847,-9.2948093
1985,1985,155.3673,11.493686,3.1235917,0.0,0,6.1111121,0.0,0.23329151,115.76954,6.7462606,342.2168,-9.2949944
1987,1987,155.3677,11.516281,3.1661496,0.0,0,6.065536,0.0,0.23680045,115.73721,6.7012467,342.18515,-9.2947044
1989,1989,155.3681,11.559285,3.2184377,0.0,0,6.0199599,0.0,0.24078304,115.63803,6.651752,342.15347,-9.294919
1991,1991,155.3685,11.640679,3.2666845,0.0,0,5.9743834,0.0,0.24556124,115.80489,6.6009469,342.1218,-9.2945585
1993,1993,155.3689,11.721605,3.3167558,0.0,0,5.9288077,0.0,0.24931946,116.26576,6.5524111,342.09015,-9.2938976
1995,1995,155.3693,11.747021,3.3699346,0.0,0,5.8832321,0.0,0.25383466,116.0738,6.5017481,342.05847,-9.2950859
1997,1997,155.3697,11.769656,3.4144616,0.0,0,5.8376555,0.0,0.25830421,115.74823,6.4562688,342.02682,-9.2944899
1999,1999,155.3701,11.835224,3.4686165,0.0,0,5.792079,0.0,0.2622506,115.83994,6.4049606,341.99515,-9.2949629
2001,2001,155.3705,11.921482,3.5155408,0.0,0,5.7465038,0.0,0.26668105,116.17148,6.3568335,341.96347,-9.2948751
2003,2003,155.3709,11.983412,3.5589046,0.0,0,5.7009277,0.0,0.27085364,116.34901,6.3076491,341.93182,-9.2951107
2005,2005,155.3713,11.995444,3.6158502,0.0,0,5.6553516,0.0,0.27490634,116.02974,6.2570038,341.90015,-9.2949743
2007,2007,155.3717,12.049472,3.6593542,0.0,0,5.6097755,0.0,0.27945158,115.8829,6.2078791,341.8685,-9.2944164
2009,2009,155.3721,12.104904,3.7067177,0.0,0,5.5656581,0.0,0.28348112,116.04366,6.1574359,341.83682,-9.2951984
2011,2011,155.3725,12.174397,3.7646513,0.0,0,5.5222936,0.0,0.28804255,116.18616,6.1072483,341.80515,-9.296298
2013,2013,155.3729,12.222523,3.804543,0.0,0,5.4789333,0.0,0.2925595,116.09602,6.0623598,341.7735,-9.2953758
2015,2015,155.3733,12.262172,3.8529475,0.0,0,5.4355736,0.0,0.29635403,116.10098,6.0106077,341.74182,-9.2952576
2017,2017,155.3737,12.321725,3.9094083,0.0,0,5.3922133,0.0,0.30119401,116.08993,5.9633665,341.71017,-9.2963486
2019,2019,155.3741,12.375783,3.947484,0.0,0,5.3488536,0.0,0.30544901,116.07302,5.9133286,341.6785,-9.2960558
2021,2021,155.3745,12.432962,3.9999537,0.0,0,5.3054934,0.0,0.30936077,116.1244,5.8669519,341.64682,-9.2944717
2023,2023,155.3749,12.503372,4.0528808,0.0,0,5.2621331,0.0,0.31450474,116.17683,5.8201742,341.61517,-9.2942924
2025,2025,155.3753,12.544336,4.093091,0.0,0,5.2187734,0.0,0.3185696,116.1773,5.7694111,341.5835,-9.2946663
2027,2027,155.3757,12.581839,4.1445746,0.0,0,5.1754136,0.0,0.32252985,115.95588,5.7223806,341.55185,-9.2959843
2029,2029,155.3761,12.635093,4.1926126,0.0,0,5.1320534,0.0,0.32762951,115.87402,5.6724882,341.52017,-9.2959261
2031,2031,155.3765,12.714813,4.2372732,0.0,0,5.0886931,0.0,0.33165538,116.11588,5.6245465,341.48193,-9.2958765
2033,2033,155.3769,12.772681,4.2876153,0.0,0,5.0457683,0.0,0.33588144,116.20036,5.5776424,341.41739,-9.2951241
2035,2035,155.3773,12.816054,4.3340831,0.0,0,5.0044241,0.0,0.34100354,116.05573,5.528399,341.35284,-9.2952194
2037,2037,155.3777,12.828126,4.3823433,0.0,0,4.9631839,0.0,0.34491125,115.67094,5.4828682,341.2883,-9.2959414
2039,2039,155.3781,12.902835,4.4294996,0.0,0,4.9219441,0.0,0.34936142,115.8127,5.4345574,341.22375,-9.2959242
2041,2041,155.3785,12.984284,4.4689097,0.0,0,4.8807039,0.0,0.35380834,116.0003,5.3904667,341.15918,-9.2944326
2043,2043,155.3789,13.03256,4.5211792,0.0,0,4.8394642,0.0,0.35775167,115.99392,5.3425574,341.09464,-9.2940302
2045,2045,155.3793,13.059974,4.5646253,0.0,0,4.798224,0.0,0.36247724,115.69026,5.2977667,341.03009,-9.2943172
2047,2047,155.3797,13.097588,4.6069016,0.0,0,4.7569842,0.0,0.36685315,115.46894,5.2517705,340.96555,-9.2953196
2049,2049,155.3801,13.185173,4.6614928,0.0,0,4.715744,0.0,0.37108359,115.79689,5.2058907,340.901,-9.2960062
2051,2051,155.3805,13.271259,4.6993809,0.0,0,4.6745043,0.0,0.37570781,115.94062,5.1608276,340.83646,-9.2965012
2053,2053,155.3809,13.309802,4.743784,0.0,0,4.6332641,0.0,0.37973347,115.89668,5.1140871,340.77191,-9.294611
2055,2055,155.3813,13.342714,4.7972703,0.0,0,4.5920238,0.0,0.38434932,115.628,5.069097,340.70737,-9.294631
2057,2057,155.3817,13.397561,4.8332415,0.0,0,4.5507841,0.0,0.38899514,115.60651,5.0239778,340.64282,-9.2937851
2059,2059,155.3821,13.472372,4.8778982,0.0,0,4.5108657,0.0,0.39263886,115.78004,4.9815612,340.57828,-9.2953253
2061,2061,155.3825,13.54816,4.9285879,0.0,0,4.4716296,0.0,0.3976081,115.79117,4.9374824,340.51373,-9.2952862
2063,2063,155.3829,13.57502,4.9628711,0.0,0,4.4323978,0.0,0.40176454,115.65676,4.8939257,340.44919,-9.2958517
2065,2065,155.3833,13.615975,5.00804,0.0,0,4.3931656,0.0,0.40540904,115.48783,4.8491063,340.38464,-9.2956553
2067,2067,155.3837,13.675043,5.0548348,0.0,0,4.3539338,0.0,0.41056684,115.3975,4.8051825,340.3201,-9.2951632
2069,2069,155.3841,13.738784,5.0918312,0.0,0,4.314702,0.0,0.41455775,115.49325,4.7649798,340.25555,-9.2958641
2071,2071,155.3845,13.818697,5.1396203,0.0,0,4.2754698,0.0,0.41858199,115.71967,4.7210102,340.19098,-9.2944603
2073,2073,155.3849,13.863609,5.1816874,0.0,0,4.2362375,0.0,0.42376605,115.48952,4.6766801,340.12643,-9.2956858
2075,2075,155.3853,13.896289,5.2224059,0.0,0,4.1970053,0.0,0.42758256,115.32066,4.6359,340.06189,-9.294548
2077,2077,155.3857,13.934167,5.2667637,0.0,0,4.1577735,0.0,0.43167073,115.159,4.5941248,339.99734,-9.2955074
2079,2079,155.3861,14.019098,5.3042264,0.0,0,4.1185417,0.0,0.43647912,115.26662,4.5549278,339.9328,-9.295536
2081,2081,155.3865,14.079457,5.3459854,0.0,0,4.0793095,0.0,0.43996578,115.47025,4.5114942,339.871,-9.2956047
2083,2083,155.3869,14.129885,5.3873873,0.0,0,4.0404716,0.0,0.44432133,115.34339,4.4714193,339.81741,-9.2947559
2085,2085,155.3873,14.16797,5.4229627,0.0,0,4.0030656,0.0,0.44887331,115.14006,4.4333634,339.76382,-9.2950077
2087,2087,155.3877,14.227279,5.4704356,0.0,0,3.9657533,0.0,0.45269528,115.08598,4.3924794,339.71024,-9.2942314
2089,2089,155.3881,14.299106,5.5096517,0.0,0,3.9284413,0.0,0.4575012,115.18089,4.3529897,339.65665,-9.295619
2091,2091,155.3885,14.389128,5.5457349,0.0,0,3.8911293,0.0,0.46149963,115.43262,4.3084364,339.60306,-9.2965479
2093,2093,155.3889,14.433311,5.5939169,0.0,0,3.8538175,0.0,0.46557766,115.36374,4.269311,339.54947,-9.2953968
2095,2095,155.3893,14.470707,5.6251497,0.0,0,3.8165054,0.0,0.47001302,115.15446,4.2315254,339.49588,-9.2947273
2097,2097,155.3897,14.538959,5.6626301,0.0,0,3.7791932,0.0,0.4736639,115.22945,4.1897087,339.44229,-9.2941647
2099,2099,155.3901,14.615865,5.7132044,0.0,0,3.7418811,0.0,0.47840828,115.25011,4.1510177,339.3887,-9.2946129
2101,2101,155.3905,14.679243,5.7438755,0.0,0,3.7045693,0.0,0.48296747,115.30486,4.108707,339.33511,-9.2943764
2103,2103,155.3909,14.733829,5.7832642,0.0,0,3.6672573,0.0,0.48627308,115.33775,4.0730472,339.28152,-9.2943954
2105,2105,155.3913,14.765831,5.826694,0.0,0,3.6299453,0.0,0.49108678,115.04377,4.0297065,339.22794,-9.2951822
2107,2107,155.3917,14.837799,5.8553452,0.0,0,3.5926332,0.0,0.49501273,115.12405,3.9912469,339.17438,-9.2963409
2109,2109,155.3921,14.923964,5.8989267,0.0,0,3.5565166,0.0,0.49863252,115.37001,3.9538906,339.12079,-9.2945938
2111,2111,155.3925,14.987353,5.9423447,0.0,0,3.5210168,0.0,0.50412852,115.22695,3.9164076,339.0672,-9.2943401
2113,2113,155.3929,15.040858,5.9753294,0.0,0,3.4855206,0.0,0.50804293,115.16608,3.8797314,339.01361,-9.2935715
2115,2115,155.3933,15.086461,6.0168824,0.0,0,3.4500248,0.0,0.5117752,115.11152,3.8411906,338.96002,-9.2937565
2117,2117,155.3937,15.143244,6.0504675,0.0,0,3.4145288,0.0,0.51658392,115.00227,3.801944,338.90643,-9.2948494
2119,2119,155.3941,15.233773,6.0831623,0.0,0,3.3790326,0.0,0.51982421,115.25996,3.7679167,338.85284,-9.2953892
2121,2121,155.3945,15.307946,6.1244187,0.0,0,3.3435369,0.0,0.52392089,115.41234,3.7304618,338.79926,-9.2942362
2123,2123,155.3949,15.361819,6.1578121,0.0,0,3.3080409,0.0,0.52878463,115.24363,3.6940804,338.74567,-9.2937031
2125,2125,155.3953,15.415913,6.1987548,0.0,0,3.2725446,0.0,0.53217697,115.2069,3.6578879,338.69208,-9.2950573
2127,2127,155.3957,15.464998,6.2367954,0.0,0,3.2370486,0.0,0.53700542,115.04866,3.6207695,338.63849,-9.2944078
2129,2129,155.3961,15.564055,6.2675424,0.0,0,3.2015526,0.0,0.54132211,115.2438,3.5840192,338.5849,-9.2943068
2131,2131,155.3965,15.668033,6.3107262,0.0,0,3.1660566,0.0,0.54483169,115.61046,3.5466428,338.4921,-9.2945747
2133,2133,155.3969,15.701618,6.3417816,0.0,0,3.1309152,0.0,0.54933125,115.44399,3.5116825,338.30783,-9.2949228
2135,2135,155.3973,15.751512,6.3756623,0.0,0,3.0970623,0.0,0.55330455,115.32511,3.4751279,338.1236,-9.2958498
2137,2137,155.3977,15.828273,6.4230256,0.0,0,3.0632944,0.0,0.55761367,115.3325,3.4396379,337.93933,-9.2951546
2139,2139,155.3981,15.91992,6.4510932,0.0,0,3.0295265,0.0,0.56235492,115.46544,3.4036787,337.75507,-9.293889
2141,2141,155.3985,16.018251,6.4850168,0.0,0,2.9957583,0.0,0.56574082,115.79111,3.3691134,337.5708,-9.2944756
2143,2143,155.3989,16.048428,6.5287929,0.0,0,2.9619906,0.0,0.57029641,115.52573,3.3343015,337.38654,-9.2936554
2145,2145,155.3993,16.116905,6.5550122,0.0,0,2.9282222,0.0,0.57471395,115.43291,3.2994766,337.20227,-9.2950506
2147,2147,155.3997,16.207611,6.596055,0.0,0,2.8944542,0.0,0.57837272,115.6687,3.2626188,337.01804,-9.2954273
2149,2149,155.4001,16.3134,6.6383839,0.0,0,2.8606863,0.0,0.58374274,115.75302,3.2260945,336.83377,-9.29529
2151,2151,155.4005,16.398426,6.6658177,0.0,0,2.8269184,0.0,0.58782583,115.91354,3.189863,336.64951,-9.2943592
2153,2153,155.4009,16.450741,6.705049,0.0,0,2.7931502,0.0,0.59134871,115.93592,3.1524291,336.46524,-9.2927151
2155,2155,155.4013,16.529741,6.7401118,0.0,0,2.7593822,0.0,0.59658682,115.8353,3.1162877,336.28098,-9.2929077
2157,2157,155.4017,16.619305,6.7697001,0.0,0,2.7256143,0.0,0.60012692,116.03047,3.0823219,336.09671,-9.294486
2159,2159,155.4021,16.723356,6.8094997,0.0,0,2.6929309,0.0,0.60409808,116.29562,3.0465539,335.91248,-9.2943354
2161,2161,155.4025,16.798853,6.8431458,0.0,0,2.6608074,0.0,0.60947549,116.23315,3.0113807,335.72821,-9.2934322
2163,2163,155.4029,16.864622,6.8808742,0.0,0,2.6286874,0.0,0.61333913,116.24271,2.9770138,335.54395,-9.2935123
2165,2165,155.4033,16.936758,6.9211221,0.0,0,2.5965672,0.0,0.61798745,116.25794,2.9402003,335.35968,-9.2943048
2167,2167,155.4037,17.033867,6.9509425,0.0,0,2.5644474,0.0,0.62287486,116.28735,2.90521,335.17542,-9.2937031
2169,2169,155.4041,17.154415,6.9870152,0.0,0,2.5323272,0.0,0.62613761,116.69425,2.8710997,334.99115,-9.2941008
2171,2171,155.4045,17.231333,7.0197358,0.0,0,2.5002072,0.0,0.63058966,116.70853,2.8381,334.80692,-9.2928982
2173,2173,155.4049,17.285078,7.0469632,0.0,0,2.4680872,0.0,0.63480175,116.65993,2.7984862,334.62265,-9.2925777
2175,2175,155.4053,17.373194,7.0924239,0.0,0,2.4359674,0.0,0.63897181,116.66924,2.7645168,334.43839,-9.2927704
2177,2177,155.4057,17.477276,7.1243987,0.0,0,2.4038472,0.0,0.64426392,116.76736,2.7338963,334.25412,-9.2928972
2179,2179,155.4061,17.593822,7.1557698,0.0,0,2.3717272,0.0,0.64815837,117.10278,2.6962399,334.06985,-9.2935696
2181,2181,155.4065,17.665789,7.1995034,0.0,0,2.3396072,0.0,0.65245438,117.07723,2.6679907,333.90527,-9.293088
2183,2183,155.4069,17.735025,7.2227421,0.0,0,2.3078089,0.0,0.6570822,116.98872,2.6296239,333.77725,-9.2927876
2185,2185,155.4073,17.824678,7.2539811,0.0,0,2.2771804,0.0,0.66037035,117.19015,2.5985494,333.6492,-9.2927723
2187,2187,155.4077,17.930275,7.2965908,0.0,0,2.246628,0.0,0.66529071,117.32569,2.5651374,333.52115,-9.2928629
2189,2189,155.4081,18.036314,7.3233371,0.0,0,2.2160764,0.0,0.67018819,117.41096,2.5299935,333.39313,-9.2942829
2191,2191,155.4085,18.119167,7.3602772,0.0,0,2.1855242,0.0,0.6737954,117.5955,2.4993386,333.26508,-9.294343
2193,2193,155.4089,18.189373,7.3984256,0.0,0,2.1549723,0.0,0.67915159,117.41819,2.4654465,333.13705,-9.2928953
2195,2195,155.4093,18.300304,7.4215426,0.0,0,2.1244202,0.0,0.68294722,117.63389,2.4312103,333.009,-9.2917442
2197,2197,155.4097,18.397898,7.4569106,0.0,0,2.0938683,0.0,0.6863479,117.84335,2.3989451,332.88098,-9.2926445
2199,2199,155.4101,18.507475,7.4883752,0.0,0,2.0633163,0.0,0.69161624,117.91407,2.3683298,332.75293,-9.2940636
2201,2201,155.4105,18.594004,7.5166693,0.0,0,2.0327644,0.0,0.69521058,118.0758,2.3390348,332.62488,-9.2943439
2203,2203,155.4109,18.677359,7.5557446,0.0,0,2.0022123,0.0,0.69953537,118.1132,2.3010502,332.49686,-9.2936649
2205,2205,155.4113,18.77656,7.5859489,0.0,0,1.9716601,0.0,0.70499158,118.061,2.2716017,332.3688,-9.2936058
2207,2207,155.4117,18.884336,7.6167455,0.0,0,1.9411081,0.0,0.70828921,118.33151,2.237252,332.24078,-9.2914104
2209,2209,155.4121,19.00157,7.6516042,0.0,0,1.9115355,0.0,0.71274215,118.53124,2.2075219,332.11273,-9.2907505
2211,2211,155.4125,19.098417,7.6772623,0.0,0,1.8824685,0.0,0.71757805,118.61827,2.1745617,331.98468,-9.2924767
2213,2213,155.4129,19.197243,7.7139211,0.0,0,1.8534043,0.0,0.72090906,118.82288,2.1408396,331.85666,-9.2937269
2215,2215,155.4133,19.288464,7.7442007,0.0,0,1.8243403,0.0,0.72586751,118.77877,2.1127546,331.72861,-9.2935572
2217,2217,155.4137,19.404459,7.7685843,0.0,0,1.7952764,0.0,0.73006916,118.97272,2.0812495,331.60059,-9.2935247
2219,2219,155.4141,19.541105,7.8093691,0.0,0,1.7662123,0.0,0.73373979,119.33362,2.0476096,331.47253,-9.2920179
2221,2221,155.4145,19.630804,7.8345346,0.0,0,1.7371484,0.0,0.73883259,119.38467,2.0178287,331.34448,-9.2911682
2223,2223,155.4149,19.715139,7.8632398,0.0,0,1.7080843,0.0,0.7426579,119.3821,1.985926,331.21646,-9.2922096
2225,2225,155.4153,19.822706,7.9029493,0.0,0,1.6790204,0.0,0.74699539,119.51949,1.9571929,331.08841,-9.2927885
2227,2227,155.4157,19.96265,7.9240522,0.0,0,1.6499563,0.0,0.75179595,119.76335,1.9276356,330.96039,-9.2927818
2229,2229,155.4161,20.092476,7.9552088,0.0,0,1.6208923,0.0,0.75509828,120.19479,1.8947704,330.83234,-9.2925091
2231,2231,155.4165,20.196695,7.9947257,0.0,0,1.5918283,0.0,0.76036137,120.14174,1.8658539,330.68124,-9.291853
2233,2233,155.4169,20.288038,8.0148525,0.0,0,1.5630548,0.0,0.76467443,120.12788,1.8367364,330.49557,-9.2912169
2235,2235,155.4173,20.398575,8.0480452,0.0,0,1.5353373,0.0,0.76803946,120.45341,1.8040593,330.30991,-9.2914572
2237,2237,155.4177,20.533363,8.0829268,0.0,0,1.5076892,0.0,0.77357769,120.48471,1.7749057,330.12424,-9.2923031
2239,2239,155.4181,20.666874,8.1042509,0.0,0,1.4800413,0.0,0.77741212,120.88029,1.7461236,329.93857,-9.2914572
2241,2241,155.4185,20.76412,8.1407604,0.0,0,1.4523933,0.0,0.78118491,120.95329,1.7122431,329.75293,-9.2925682
2243,2243,155.4189,20.86207,8.1716633,0.0,0,1.4247453,0.0,0.78697777,120.87515,1.6839842,329.56726,-9.2921829
2245,2245,155.4193,20.995096,8.1964865,0.0,0,1.3970973,0.0,0.79036051,121.20983,1.6536219,329.38159,-9.2912407
2247,2247,155.4197,21.125704,8.2282524,0.0,0,1.3694494,0.0,0.79426688,121.46474,1.6276568,329.19592,-9.2912321
2249,2249,155.4201,21.275478,8.2530651,0.0,0,1.3418013,0.0,0.79946387,121.70152,1.5983485,329.01025,-9.2923498
2251,2251,155.4205,21.369387,8.2835007,0.0,0,1.3141534,0.0,0.8026861,121.88266,1.5672884,328.82458,-9.2921858
2253,2253,155.4209,21.463285,8.3160849,0.0,0,1.2865053,0.0,0.80756074,121.84129,1.5397294,328.63892,-9.2921896
2255,2255,155.4213,21.605625,8.3406563,0.0,0,1.2588574,0.0,0.81251091,122.00083,1.5098612,328.45325,-9.2913074
2257,2257,155.4217,21.766977,8.3761358,0.0,0,1.2312094,0.0,0.81619942,122.37893,1.4806414,328.26758,-9.2906513
2259,2259,155.4221,21.899979,8.4038973,0.0,0,1.2044513,0.0,0.82127494,122.62494,1.4549692,328.08194,-9.2907057
2261,2261,155.4225,22.002151,8.42523,0.0,0,1.1781524,0.0,0.82501161,122.71826,1.4262673,327.89627,-9.2914267
2263,2263,155.4229,22.120823,8.4600277,0.0,0,1.1518564,0.0,0.82847625,122.93605,1.3970497,327.7106,-9.2922611
2265,2265,155.4233,22.262531,8.4805584,0.0,0,1.1255604,0.0,0.83333671,123.11134,1.3691106,327.52493,-9.2910719
2267,2267,155.4237,22.421103,8.508359,0.0,0,1.0992644,0.0,0.83708644,123.55425,1.3375525,327.33926,-9.2896852
2269,2269,155.4241,22.552732,8.5468493,0.0,0,1.0729684,0.0,0.84210432,123.67757,1.3099303,327.15359,-9.2905254
2271,2271,155.4245,22.667944,8.5664854,0.0,0,1.0466723,0.0,0.84710336,123.6918,1.2840831,326.96793,-9.2908068
2273,2273,155.4249,22.797316,8.5948343,0.0,0,1.0203763,0.0,0.85019231,123.9827,1.2564361,326.78226,-9.2907591
2275,2275,155.4253,22.94943,8.6293468,0.0,0,0.99408036,0.0,0.85536689,124.13692,1.2251679,326.59659,-9.2904301
2277,2277,155.4257,23.112064,8.6436863,0.0,0,0.96778435,0.0,0.85921097,124.59222,1.198509,326.41095,-9.289937
2279,2279,155.4261,23.243759,8.6758146,0.0,0,0.94148839,0.0,0.86233491,124.86178,1.1737034,326.22528,-9.2911768
2281,2281,155.4265,23.372625,8.7089138,0.0,0,0.91519243,0.0,0.8686232,124.77349,1.1430329,325.89133,-9.2898397
2283,2283,155.4269,23.51186,8.7313766,0.0,0,0.88916051,0.0,0.87259102,125.01662,1.1156554,325.37619,-9.2895765
2285,2285,155.4273,23.674574,8.7632866,0.0,0,0.86408949,0.0,0.87636173,125.40699,1.0871273,324.86108,-9.2902908
2287,2287,155.4277,23.840508,8.7860909,0.0,0,0.83908135,0.0,0.88167089,125.63074,1.0608159,324.34595,-9.2903242
2289,2289,155.4281,23.984594,8.8057537,0.0,0,0.81407332,0.0,0.88422072,126.0163,1.0358468,323.83084,-9.2897005
2291,2291,155.4285,24.111187,8.835968,0.0,0,0.78906536,0.0,0.88823527,126.20104,1.0084654,323.3157,-9.2897453
2293,2293,155.4289,24.256376,8.859889,0.0,0,0.7640574,0.0,0.89379281,126.27443,0.98261988,322.80057,-9.2896214
2295,2295,155.4293,24.418446,8.89256,0.0,0,0.73904938,0.0,0.89753717,126.64816,0.95450985,322.28546,-9.2892675
2297,2297,155.4297,24.602423,8.923315,0.0,0,0.71404135,0.0,0.90285552,126.87232,0.92752039,321.77032,-9.2896748
2299,2299,155.4301,24.763914,8.9417181,0.0,0,0.68903339,0.0,0.90743786,127.14654,0.89933366,321.25522,-9.2908421
2301,2301,155.4305,24.894466,8.9715462,0.0,0,0.66402543,0.0,0.91031212,127.47533,0.87322813,320.74008,-9.2902985
2303,2303,155.4309,25.03698,8.9918871,0.0,0,0.63901734,0.0,0.91475159,127.63387,0.84803712,320.22495,-9.2909708
2305,2305,155.4313,25.200895,9.013278,0.0,0,0.61400938,0.0,0.91868019,127.9351,0.819956,319.70984,-9.2901506
2307,2307,155.4317,25.375639,9.0507202,0.0,0,0.58900136,0.0,0.92298508,128.29001,0.79827261,319.1947,-9.2889738
2309,2309,155.4321,25.531553,9.0701618,0.0,0,0.56478846,0.0,0.9282912,128.38271,0.76804227,318.6796,-9.2893724
2311,2311,155.4325,25.665194,9.0950966,0.0,0,0.54098594,0.0,0.93167263,128.63635,0.74515438,318.16446,-9.2893028
2313,2313,155.4329,25.811003,9.127861,0.0,0,0.51718587,0.0,0.9363541,128.76788,0.72030193,317.64932,-9.2894287
2315,2315,155.4333,25.977552,9.1393385,0.0,0,0.49338591,0.0,0.94055325,129.05627,0.69307774,317.13422,-9.2891436
2317,2317,155.4337,26.165575,9.1648636,0.0,0,0.4695859,0.0,0.94339752,129.61342,0.6677177,316.61908,-9.2883635
2319,2319,155.4341,26.324984,9.1970482,0.0,0,0.44578591,0.0,0.94868159,129.73558,0.64769924,316.10397,-9.2887268
2321,2321,155.4345,26.468147,9.2129002,0.0,0,0.42198589,0.0,0.95291495,129.90468,0.61980277,315.58884,-9.289463
2323,2323,155.4349,26.630859,9.2425709,0.0,0,0.39818591,0.0,0.95615369,130.22044,0.59409386,315.0737,-9.2888641
2325,2325,155.4353,26.796436,9.2683935,0.0,0,0.37438589,0.0,0.96211135,130.29903,0.57270187,314.55859,-9.2883062
2327,2327,155.4357,26.982975,9.283699,0.0,0,0.35058588,0.0,0.96506494,130.8163,0.55054027,314.04346,-9.2881517
2329,2329,155.4361,27.144184,9.3135462,0.0,0,0.32678592,0.0,0.96840721,131.15215,0.52306777,313.52835,-9.2877932
2331,2331,155.4365,27.288923,9.3348141,0.0,0,0.30298588,0.0,0.97419864,131.10823,0.50002128,313.28851,-9.2876987
2333,2333,155.4369,27.448759,9.355526,0.0,0,0.27942541,0.0,0.97696316,131.49475,0.47706717,313.32394,-9.2881241
2335,2335,155.4373,27.611542,9.3811827,0.0,0,0.25673628,0.0,0.98070264,131.76546,0.45482475,313.35938,-9.287467