File: clean data/testID_0220.csv
level_0,index,Time(sec),Force(kN),Jaw(mm),PowAngle(deg),Power(W),Pram,PTemp,Strain,Stress(MPa),Stroke(mm),TC1(C),wedge(mm)
2108,2108,178.6777,0.78901529,0.028257174,0.0,0,8.9751778,0.0,0.00168054,8.7295151,9.9677448,400.70105,-9.2654572
2109,2109,178.6779,1.8470844,0.045215469,0.0,0,8.9459143,0.0,0.0027145613,20.120766,9.9265976,400.72086,-9.26507
2110,2110,178.6781,3.1978962,0.079614438,0.0,0,8.9166498,0.0,0.0050464398,37.086624,9.8929739,400.74069,-9.265254
2111,2111,178.6783,4.1218314,0.11256985,0.0,0,8.8873854,0.0,0.0070152674,50.06221,9.8658895,400.76053,-9.2652187
2112,2112,178.6785,4.6086078,0.13309821,0.0,0,8.8581219,0.0,0.0086023416,57.182804,9.8339891,400.78033,-9.2643385
2113,2113,178.6787,4.9145837,0.1551189,0.0,0,8.8288574,0.0,0.010258079,61.257599,9.793644,400.80017,-9.2633839
2114,2114,178.6789,5.2037792,0.20788796,0.0,0,8.7995939,0.0,0.013012995,64.714844,9.7509747,400.82001,-9.2625542
2115,2115,178.6791,5.2867937,0.28706345,0.0,0,8.7703295,0.0,0.018032938,66.07019,9.704072,400.83981,-9.2617712
2116,2116,178.6793,5.2077818,0.35741961,0.0,0,8.7416534,0.0,0.023436068,64.967567,9.6546946,400.85965,-9.2611876
2117,2117,178.6795,5.344605,0.40439445,0.0,0,8.7136869,0.0,0.026734196,65.589905,9.6036072,400.87949,-9.2619257
2118,2118,178.6797,5.6873217,0.43783292,0.0,0,8.6858492,0.0,0.028985504,69.462463,9.5487566,400.89932,-9.2626925
2119,2119,178.6799,5.8135123,0.48357478,0.0,0,8.6580172,0.0,0.032272633,71.622681,9.4931555,400.91913,-9.2625904
2120,2120,178.6801,5.7590261,0.55330896,0.0,0,8.6301851,0.0,0.036669653,70.742912,9.4408855,400.93896,-9.2623186
2121,2121,178.6803,5.9631577,0.60631579,0.0,0,8.6023531,0.0,0.040505558,72.150154,9.3950834,400.9588,-9.2618361
2122,2122,178.6805,6.2808223,0.61487734,0.0,0,8.5745211,0.0,0.042018808,76.027397,9.3493805,400.97861,-9.2608013
2123,2123,178.6807,6.2530704,0.61473483,0.0,0,8.546689,0.0,0.041875318,76.667175,9.3064938,400.99844,-9.2601366
2124,2124,178.6809,5.9214993,0.63619286,0.0,0,8.518857,0.0,0.042662974,73.046227,9.2696533,401.01828,-9.2600479
2125,2125,178.6811,5.7468033,0.67617637,0.0,0,8.491025,0.0,0.045554247,70.106316,9.2372456,401.03809,-9.2598877
2126,2126,178.6813,5.9694371,0.724199,0.0,0,8.4631929,0.0,0.049001757,71.596344,9.2051544,401.04639,-9.259963
2127,2127,178.6815,6.3304443,0.75336313,0.0,0,8.4353609,0.0,0.050940022,75.669456,9.1729717,401.00851,-9.2605953
2128,2128,178.6817,6.4932585,0.76003247,0.0,0,8.4075289,0.0,0.051857937,78.180847,9.1418791,400.97064,-9.2616739
2129,2129,178.6819,6.516077,0.79028809,0.0,0,8.3796968,0.0,0.05372148,78.525375,9.1097078,400.93277,-9.2610369
2130,2130,178.6821,6.5757332,0.84808373,0.0,0,8.3518648,0.0,0.057025436,78.81736,9.0731792,400.8949,-9.2599554
2131,2131,178.6823,6.5907316,0.8982662,0.0,0,8.3240328,0.0,0.060963623,78.936165,9.0319653,400.85703,-9.2603912
2132,2132,178.6825,6.4635673,0.94162637,0.0,0,8.2962008,0.0,0.064446665,77.469009,8.9914999,400.81915,-9.2603846
2133,2133,178.6827,6.3416476,0.9792636,0.0,0,8.2683687,0.0,0.066791415,75.7258,8.9508133,400.78128,-9.260375
2134,2134,178.6829,6.3553967,1.009465,0.0,0,8.2405367,0.0,0.069072671,75.372269,8.9107466,400.74341,-9.2609034
2135,2135,178.6831,6.4556875,1.0536536,0.0,0,8.2127056,0.0,0.072413057,76.219315,8.872983,400.70554,-9.2609577
2136,2136,178.6833,6.5375762,1.1017489,0.0,0,8.1848736,0.0,0.075487845,77.04232,8.8342867,400.66769,-9.2602701
2137,2137,178.6835,6.5743051,1.1263515,0.0,0,8.1570406,0.0,0.077531449,77.356216,8.7966032,400.62982,-9.2602854
2138,2138,178.6837,6.6485486,1.1451004,0.0,0,8.1292095,0.0,0.079368711,78.021423,8.7627459,400.59195,-9.2604523
2139,2139,178.6839,6.7526188,1.171281,0.0,0,8.1013775,0.0,0.08079356,79.154877,8.7299156,400.55408,-9.2605782
2140,2140,178.6841,6.7411323,1.1964122,0.0,0,8.0735445,0.0,0.082450107,79.189346,8.698638,400.5162,-9.2611055
2141,2141,178.6843,6.5899658,1.2309985,0.0,0,8.0462675,0.0,0.085321873,77.411781,8.66959,400.47833,-9.2611465
2142,2142,178.6845,6.4980278,1.2663404,0.0,0,8.0196619,0.0,0.087725706,75.950821,8.645339,400.44046,-9.2610083
2143,2143,178.6847,6.6131921,1.2833902,0.0,0,7.993176,0.0,0.088980041,76.756523,8.6192446,400.40259,-9.2613821
2144,2144,178.6849,6.8072,1.3033096,0.0,0,7.9666953,0.0,0.090752527,78.805344,8.5881624,400.36472,-9.2615633
2145,2145,178.6851,6.9187393,1.3395865,0.0,0,7.9402156,0.0,0.093083635,80.197807,8.5595417,400.32684,-9.2604418
2146,2146,178.6853,6.9345012,1.3783759,0.0,0,7.9137354,0.0,0.095544375,80.311203,8.5314522,400.28897,-9.2594852
2147,2147,178.6855,6.8916597,1.4182906,0.0,0,7.8872552,0.0,0.098855473,79.61071,8.501524,400.2511,-9.2593927
2148,2148,178.6857,6.8464208,1.4542269,0.0,0,7.860775,0.0,0.10165475,78.888573,8.4698467,400.21326,-9.2590008
2149,2149,178.6859,6.8196387,1.4793148,0.0,0,7.8342953,0.0,0.10320543,78.395889,8.4360695,400.17538,-9.2589817
2150,2150,178.6861,6.8021851,1.5076323,0.0,0,7.8078156,0.0,0.1055412,77.985016,8.4038267,400.13751,-9.2593622
2151,2151,178.6863,6.7977524,1.542492,0.0,0,7.7813349,0.0,0.1082289,77.711304,8.3748388,400.09964,-9.2594004
2152,2152,178.6865,6.8000164,1.5689917,0.0,0,7.7548552,0.0,0.10995578,77.574371,8.3462591,400.06177,-9.2595348
2153,2153,178.6867,6.83005,1.5846239,0.0,0,7.728375,0.0,0.11151096,77.756256,8.3159752,400.0239,-9.2600994
2154,2154,178.6869,6.90839,1.5989214,0.0,0,7.7018952,0.0,0.11277098,78.492157,8.2872362,399.98602,-9.2608976
2155,2155,178.6871,6.9807649,1.6206208,0.0,0,7.675415,0.0,0.11381783,79.222687,8.2611685,399.94815,-9.2611694
2156,2156,178.6873,6.9745259,1.6515634,0.0,0,7.6489348,0.0,0.11613159,79.102188,8.2354383,399.91028,-9.2612352
2157,2157,178.6875,6.9053659,1.682076,0.0,0,7.6224551,0.0,0.11880479,78.201485,8.2087307,399.87241,-9.2612123
2158,2158,178.6877,6.892396,1.7044498,0.0,0,7.5959754,0.0,0.12022921,77.743935,8.1843519,399.83453,-9.2604618
2159,2159,178.6879,6.9819808,1.7193198,0.0,0,7.5694952,0.0,0.1213903,78.45192,8.163415,399.79666,-9.2591333
2160,2160,178.6881,7.0901198,1.7357723,0.0,0,7.543015,0.0,0.12297734,79.590836,8.1386003,399.75882,-9.2588224
2161,2161,178.6883,7.1263666,1.7668259,0.0,0,7.5165353,0.0,0.12481215,79.995827,8.1095133,399.72095,-9.2586107
2162,2162,178.6885,7.1038232,1.8017619,0.0,0,7.4900556,0.0,0.12728669,79.689102,8.0803022,399.68307,-9.258131
2163,2163,178.6887,7.1027231,1.8264939,0.0,0,7.4635754,0.0,0.12971371,79.454071,8.0551348,399.6452,-9.2586451
2164,2164,178.6889,7.137238,1.8523396,0.0,0,7.4370952,0.0,0.13138779,79.61068,8.031395,399.60733,-9.2593355
2165,2165,178.6891,7.141768,1.8784237,0.0,0,7.410615,0.0,0.13312151,79.649437,8.0049973,399.56946,-9.2602844
2166,2166,178.6893,7.0938573,1.9019152,0.0,0,7.384666,0.0,0.13539927,79.032951,7.9779882,399.53159,-9.2610731
2167,2167,178.6895,7.068747,1.9344468,0.0,0,7.3593607,0.0,0.1376352,78.442429,7.9506574,399.49371,-9.2610693
2168,2168,178.6897,7.111619,1.9613098,0.0,0,7.3341718,0.0,0.13944851,78.628975,7.9248447,399.45584,-9.2610826
2169,2169,178.6899,7.1838555,1.9725355,0.0,0,7.3089876,0.0,0.1409498,79.302017,7.9019346,399.41797,-9.2609587
2170,2170,178.6901,7.2258286,1.9923431,0.0,0,7.2838035,0.0,0.14230847,79.778923,7.8761525,399.3801,-9.2607317
2171,2171,178.6903,7.2111478,2.0206268,0.0,0,7.2586198,0.0,0.14396887,79.64592,7.8495641,399.34222,-9.2596445
2172,2172,178.6905,7.1746225,2.0412064,0.0,0,7.2334356,0.0,0.1460342,79.095428,7.8276587,399.30438,-9.2590475
2173,2173,178.6907,7.1602359,2.066438,0.0,0,7.2082515,0.0,0.14805499,78.679153,7.8068171,399.26651,-9.259532
2174,2174,178.6909,7.1865525,2.0910292,0.0,0,7.1830673,0.0,0.14947791,78.753616,7.7847667,399.22864,-9.2589397
2175,2175,178.6911,7.2402124,2.1024315,0.0,0,7.1578832,0.0,0.1507349,79.172173,7.7610211,399.19077,-9.2589369
2176,2176,178.6913,7.3010936,2.1261287,0.0,0,7.132699,0.0,0.15263873,79.640457,7.7370658,399.14758,-9.2595539
2177,2177,178.6915,7.3514743,2.1606262,0.0,0,7.1075149,0.0,0.15467846,80.079559,7.7148938,399.05679,-9.2596226
2178,2178,178.6917,7.3871388,2.1813431,0.0,0,7.0823312,0.0,0.15670152,80.326195,7.6904497,398.96597,-9.2599468
2179,2179,178.6919,7.4085598,2.2048156,0.0,0,7.0571475,0.0,0.15893033,80.41243,7.6656055,398.87515,-9.260397
2180,2180,178.6921,7.398592,2.2336106,0.0,0,7.0319633,0.0,0.16063446,80.246002,7.6432676,398.78436,-9.2611599
2181,2181,178.6923,7.3663216,2.2528074,0.0,0,7.0067787,0.0,0.16222861,79.726563,7.620122,398.69354,-9.2617273
2182,2182,178.6925,7.3374782,2.27985,0.0,0,6.981595,0.0,0.16464555,79.194168,7.5956154,398.60272,-9.261097
2183,2183,178.6927,7.3395233,2.3106337,0.0,0,6.9564114,0.0,0.16670585,79.016335,7.5729098,398.51193,-9.2601051
2184,2184,178.6929,7.3778257,2.3245032,0.0,0,6.9312272,0.0,0.16795941,79.269135,7.5504384,398.42111,-9.2596664
2185,2185,178.6931,7.4336853,2.341069,0.0,0,6.9060431,0.0,0.16966926,79.755508,7.524322,398.33029,-9.2594557
2186,2186,178.6933,7.48206,2.3684628,0.0,0,6.8808589,0.0,0.17133497,80.230255,7.5004787,398.2395,-9.2595072
2187,2187,178.6935,7.5084033,2.3895843,0.0,0,6.8556757,0.0,0.17282867,80.472313,7.4796481,398.14868,-9.2596569
2188,2188,178.6937,7.5066237,2.4134488,0.0,0,6.8304915,0.0,0.17525284,80.298485,7.4594588,398.05789,-9.2603416
2189,2189,178.6939,7.4858623,2.4403532,0.0,0,6.8053074,0.0,0.17727035,79.879463,7.4362187,397.96707,-9.2613688
2190,2190,178.6941,7.474061,2.4551859,0.0,0,6.7801232,0.0,0.17823051,79.59964,7.4134536,397.87625,-9.2614594
2191,2191,178.6943,7.4965005,2.4732151,0.0,0,6.7554412,0.0,0.18003038,79.664383,7.3923416,397.78546,-9.2617435
2192,2192,178.6945,7.5387936,2.5018899,0.0,0,6.7313666,0.0,0.18217257,79.976334,7.3692341,397.69464,-9.261713
2193,2193,178.6947,7.574645,2.5255413,0.0,0,6.7074018,0.0,0.1836939,80.277824,7.3479724,397.60382,-9.2611771
2194,2194,178.6949,7.6041818,2.5463638,0.0,0,6.6834412,0.0,0.18579896,80.393333,7.3247766,397.51303,-9.2604599
2195,2195,178.6951,7.6333394,2.5695469,0.0,0,6.6594815,0.0,0.18779746,80.465744,7.299541,397.42221,-9.2603722
2196,2196,178.6953,7.658103,2.5901432,0.0,0,6.6355214,0.0,0.18897013,80.606819,7.2771673,397.33139,-9.2604351
2197,2197,178.6955,7.670681,2.6132538,0.0,0,6.6115613,0.0,0.19109298,80.605827,7.2553163,397.2406,-9.260335
2198,2198,178.6957,7.6681905,2.6404221,0.0,0,6.5876012,0.0,0.19353253,80.4217,7.2290282,397.14978,-9.2609529
2199,2199,178.6959,7.6646895,2.6630743,0.0,0,6.5636415,0.0,0.19494398,80.293701,7.204977,397.05896,-9.2610922
2200,2200,178.6961,7.677752,2.6821687,0.0,0,6.5396814,0.0,0.19670908,80.270584,7.1832819,396.96817,-9.2605772
2201,2201,178.6963,7.7129164,2.703407,0.0,0,6.5157218,0.0,0.19869623,80.418396,7.1588364,396.87735,-9.2606001
2202,2202,178.6965,7.7559142,2.7285168,0.0,0,6.4917617,0.0,0.20021376,80.774734,7.1361165,396.78653,-9.2609692
2203,2203,178.6967,7.7805767,2.7531884,0.0,0,6.467802,0.0,0.20229556,80.958244,7.112721,396.69574,-9.2605572
2204,2204,178.6969,7.7960515,2.7741864,0.0,0,6.4438419,0.0,0.20452654,80.901398,7.0878706,396.60492,-9.2599888
2205,2205,178.6971,7.8138146,2.7974195,0.0,0,6.4198813,0.0,0.20593075,80.876869,7.0649171,396.5141,-9.2598267
2206,2206,178.6973,7.8382282,2.8202295,0.0,0,6.3959212,0.0,0.20763525,80.998161,7.0407472,396.42331,-9.2597761
2207,2207,178.6975,7.8714399,2.8410292,0.0,0,6.3719611,0.0,0.20988338,81.204651,7.0179491,396.33249,-9.2597551
2208,2208,178.6977,7.9077396,2.8696628,0.0,0,6.3480015,0.0,0.21182297,81.381973,6.9954042,396.2417,-9.2604523
2209,2209,178.6979,7.9290175,2.8956778,0.0,0,6.3240414,0.0,0.21379575,81.450806,6.971149,396.15088,-9.2610683
2210,2210,178.6981,7.9389472,2.913662,0.0,0,6.3000817,0.0,0.21600179,81.461357,6.9457178,396.06006,-9.2611513
2211,2211,178.6983,7.951786,2.9401846,0.0,0,6.2761216,0.0,0.2178794,81.418938,6.9210262,395.96927,-9.2611103
2212,2212,178.6985,7.9738412,2.9678912,0.0,0,6.252162,0.0,0.21975449,81.421494,6.8967981,395.87845,-9.2606211
2213,2213,178.6987,7.9898353,2.9883168,0.0,0,6.2282019,0.0,0.22208512,81.441986,6.8708653,395.78763,-9.2600241
2214,2214,178.6989,7.9925437,3.0169322,0.0,0,6.2042418,0.0,0.22424796,81.362045,6.8460484,395.69684,-9.2600431
2215,2215,178.6991,8.0071392,3.0447521,0.0,0,6.1802816,0.0,0.2260748,81.29969,6.8214316,395.60602,-9.2601175
2216,2216,178.6993,8.0476656,3.0606737,0.0,0,6.1568022,0.0,0.22801192,81.444214,6.7962861,395.5152,-9.2599611
2217,2217,178.6995,8.0966415,3.0864251,0.0,0,6.1339045,0.0,0.2301162,81.75647,6.7739654,395.42441,-9.2603779
2218,2218,178.6997,8.1255178,3.116833,0.0,0,6.1111116,0.0,0.23207313,81.99128,6.7510815,395.33359,-9.2607813
2219,2219,178.6999,8.1366997,3.133975,0.0,0,6.0883236,0.0,0.23405394,81.980263,6.7240496,395.24277,-9.2602215
2220,2220,178.7001,8.1386166,3.1574638,0.0,0,6.0655355,0.0,0.23621316,81.786201,6.6995368,395.15198,-9.260273
2221,2221,178.7003,8.1477146,3.1859694,0.0,0,6.042748,0.0,0.23792937,81.76889,6.6750393,395.06116,-9.260952
2222,2222,178.7005,8.1674156,3.2027545,0.0,0,6.0199599,0.0,0.23968752,81.79705,6.6496892,394.97034,-9.2609138
2223,2223,178.7007,8.1863976,3.2278574,0.0,0,5.9971714,0.0,0.24215503,81.735626,6.6263475,394.87955,-9.2609367
2224,2224,178.7009,8.2126942,3.259902,0.0,0,5.9743834,0.0,0.24424239,81.864746,6.6032734,394.78873,-9.2609348
2225,2225,178.7011,8.2529058,3.2774704,0.0,0,5.9515953,0.0,0.24604058,82.103828,6.5783391,394.69794,-9.2603426
2226,2226,178.7013,8.2913141,3.2996082,0.0,0,5.9288073,0.0,0.24839611,82.299675,6.5533891,394.60712,-9.2598171
2227,2227,178.7015,8.3274584,3.3305616,0.0,0,5.9060197,0.0,0.25041327,82.527115,6.5298901,394.57941,-9.2602243
2228,2228,178.7017,8.3516273,3.3507676,0.0,0,5.8832316,0.0,0.25221431,82.630463,6.5041633,394.55173,-9.2602425
2229,2229,178.7019,8.3602018,3.3757079,0.0,0,5.8604436,0.0,0.2548801,82.538429,6.4799852,394.52402,-9.2595844
2230,2230,178.7021,8.3615093,3.4066873,0.0,0,5.8376555,0.0,0.25709933,82.375198,6.4584455,394.49634,-9.2597237
2231,2231,178.7023,8.3638058,3.4256032,0.0,0,5.814867,0.0,0.25864667,82.257942,6.4327865,394.46863,-9.2604933
2232,2232,178.7025,8.3765306,3.4486365,0.0,0,5.792079,0.0,0.26111758,82.167137,6.4055748,394.44095,-9.2610483
2233,2233,178.7027,8.3942451,3.4800131,0.0,0,5.7692914,0.0,0.26346767,82.132271,6.3827777,394.41324,-9.2611313
2234,2234,178.7029,8.4339151,3.5010915,0.0,0,5.7465034,0.0,0.26511875,82.351166,6.3601489,394.38556,-9.2611485
2235,2235,178.7031,8.4883738,3.5224526,0.0,0,5.7237153,0.0,0.26753905,82.657501,6.3340058,394.35785,-9.2611456
2236,2236,178.7033,8.5232897,3.5499055,0.0,0,5.7009273,0.0,0.26977506,82.882561,6.3104148,394.33017,-9.2610674
2237,2237,178.7035,8.5318041,3.5698309,0.0,0,5.6781397,0.0,0.27111161,82.86805,6.2860179,394.30246,-9.2610559
2238,2238,178.7037,8.5398951,3.5913134,0.0,0,5.6553516,0.0,0.27346629,82.695595,6.2592187,394.27478,-9.2605944
2239,2239,178.7039,8.5500126,3.6196837,0.0,0,5.6325636,0.0,0.27597636,82.608467,6.2349138,394.24707,-9.2598982
2240,2240,178.7041,8.5647335,3.6418617,0.0,0,5.6097751,0.0,0.27746046,82.573524,6.2133842,394.21939,-9.2598715
2241,2241,178.7043,8.5877466,3.6622176,0.0,0,5.5874414,0.0,0.27968407,82.576492,6.1899214,394.19168,-9.2598133
2242,2242,178.7045,8.6136713,3.6886604,0.0,0,5.5656581,0.0,0.28213233,82.633438,6.1657815,394.164,-9.2602806
2243,2243,178.7047,8.6483431,3.7139914,0.0,0,5.5439734,0.0,0.28378442,82.835709,6.1428514,394.13629,-9.2603703
2244,2244,178.7049,8.687748,3.7380056,0.0,0,5.5222936,0.0,0.28618181,82.987877,6.1149774,394.10861,-9.2604399
2245,2245,178.7051,8.7154884,3.7643867,0.0,0,5.5006132,0.0,0.2888346,83.014114,6.0900116,394.0809,-9.26085
2246,2246,178.7053,8.7275486,3.7910984,0.0,0,5.4789333,0.0,0.29062602,83.088638,6.0674963,394.05322,-9.260869
2247,2247,178.7055,8.7445564,3.815625,0.0,0,5.457253,0.0,0.29295868,83.062561,6.0415387,394.02551,-9.2610874
2248,2248,178.7057,8.7637577,3.8394399,0.0,0,5.4355731,0.0,0.29560664,82.984962,6.0169311,393.99783,-9.2610931
2249,2249,178.7059,8.7758646,3.8657691,0.0,0,5.4138932,0.0,0.29743356,82.987785,5.9937539,393.97012,-9.260396
2250,2250,178.7061,8.7916613,3.8892045,0.0,0,5.3922133,0.0,0.29948786,82.949608,5.9674721,393.94244,-9.2596264
2251,2251,178.7063,8.8176823,3.9083736,0.0,0,5.370533,0.0,0.30186379,82.950569,5.942553,393.91473,-9.259594
2252,2252,178.7065,8.8464966,3.9336023,0.0,0,5.3488531,0.0,0.30361724,83.094818,5.9208188,393.88705,-9.259799
2253,2253,178.7067,8.8715353,3.9574995,0.0,0,5.3271732,0.0,0.30555436,83.182472,5.8951974,393.85934,-9.2605543
2254,2254,178.7069,8.8983231,3.9761996,0.0,0,5.3054934,0.0,0.30802172,83.19696,5.8692937,393.83167,-9.2611246
2255,2255,178.7071,8.9283161,4.00424,0.0,0,5.283813,0.0,0.31012657,83.279663,5.845943,393.80396,-9.2611256
2256,2256,178.7073,8.9564381,4.0303168,0.0,0,5.2621331,0.0,0.3121109,83.399803,5.8204083,393.77628,-9.2604017
2257,2257,178.7075,8.9813738,4.0474029,0.0,0,5.2404532,0.0,0.31438923,83.438667,5.7971077,393.74857,-9.2597075
2258,2258,178.7077,8.9920588,4.0744557,0.0,0,5.2187734,0.0,0.31656283,83.447823,5.7735782,393.72089,-9.25912
2259,2259,178.7079,9.0029125,4.1028509,0.0,0,5.1970935,0.0,0.31869599,83.41011,5.7464623,393.69318,-9.2591867
2260,2260,178.7081,9.0208664,4.1205511,0.0,0,5.1754136,0.0,0.32102454,83.301231,5.7221408,393.6655,-9.260272
2261,2261,178.7083,9.0426407,4.1461201,0.0,0,5.1537333,0.0,0.32324877,83.325287,5.6994572,393.63779,-9.2609005
2262,2262,178.7085,9.0744324,4.174562,0.0,0,5.1320534,0.0,0.32519951,83.394623,5.6777334,393.61011,-9.2606134
2263,2263,178.7087,9.0991421,4.1917639,0.0,0,5.110373,0.0,0.32739535,83.443741,5.6560121,393.5824,-9.2599277
2264,2264,178.7089,9.1287813,4.2176619,0.0,0,5.0886931,0.0,0.32993668,83.546066,5.6316614,393.55472,-9.2598772
2265,2265,178.7091,9.1687202,4.248178,0.0,0,5.0670133,0.0,0.33204371,83.691757,5.6066456,393.52701,-9.2605448
2266,2266,178.7093,9.1937761,4.2640457,0.0,0,5.0457678,0.0,0.33402005,83.7612,5.5829773,393.49933,-9.2609539
2267,2267,178.7095,9.2134447,4.2865906,0.0,0,5.0250483,0.0,0.33644289,83.723938,5.5586681,393.47162,-9.2609377
2268,2268,178.7097,9.2331324,4.315731,0.0,0,5.0044241,0.0,0.33843759,83.697906,5.5355043,393.44394,-9.2605066
2269,2269,178.7099,9.24471,4.3311853,0.0,0,4.9838037,0.0,0.34027955,83.670341,5.5143185,393.41623,-9.2604942
2270,2270,178.7101,9.2545242,4.3539176,0.0,0,4.9631839,0.0,0.34287766,83.544533,5.4918776,393.38855,-9.2603865
2271,2271,178.7103,9.2762327,4.3851061,0.0,0,4.9425635,0.0,0.3449634,83.515511,5.4664559,393.36084,-9.2598457
2272,2272,178.7105,9.3040228,4.4015765,0.0,0,4.9219437,0.0,0.34670931,83.692268,5.4415817,393.33316,-9.2598095
2273,2273,178.7107,9.3271961,4.423512,0.0,0,4.9013238,0.0,0.34940088,83.728584,5.4187279,393.30545,-9.2597942
2274,2274,178.7109,9.3526869,4.4539061,0.0,0,4.8807039,0.0,0.35157034,83.724144,5.397048,393.27777,-9.259902
2275,2275,178.7111,9.3871927,4.4702725,0.0,0,4.8600836,0.0,0.3531673,83.89109,5.3737335,393.25006,-9.2604418
2276,2276,178.7113,9.4203501,4.4901299,0.0,0,4.8394637,0.0,0.35576117,83.940918,5.3500547,393.22238,-9.2608471
2277,2277,178.7115,9.4386415,4.5187531,0.0,0,4.8188438,0.0,0.35800618,83.945709,5.3288498,393.15295,-9.2609119
2278,2278,178.7117,9.4476118,4.5371637,0.0,0,4.798224,0.0,0.35948291,84.003319,5.3060813,393.07889,-9.2606277
2279,2279,178.7119,9.4527731,4.5576305,0.0,0,4.7776036,0.0,0.36208755,83.860138,5.2823849,393.00485,-9.2606287
2280,2280,178.7121,9.4716177,4.5863867,0.0,0,4.7569838,0.0,0.3646152,83.72699,5.2596946,392.93079,-9.2612953
2281,2281,178.7123,9.4968586,4.6066871,0.0,0,4.7363639,0.0,0.36613941,83.745438,5.2381411,392.85672,-9.2613115
2282,2282,178.7125,9.5194893,4.6264777,0.0,0,4.7157435,0.0,0.36864311,83.747055,5.2145319,392.78268,-9.260397
2283,2283,178.7127,9.5544748,4.6542931,0.0,0,4.6951237,0.0,0.37121356,83.862053,5.1931219,392.70862,-9.2596302
2284,2284,178.7129,9.5966692,4.6770024,0.0,0,4.6745038,0.0,0.37282747,84.09507,5.1709394,392.63458,-9.2590942
2285,2285,178.7131,9.627099,4.6977339,0.0,0,4.6538839,0.0,0.37541929,84.183952,5.146872,392.56052,-9.2587376
2286,2286,178.7133,9.6472406,4.7235465,0.0,0,4.6332641,0.0,0.37807277,84.168663,5.1261282,392.48645,-9.2592201
2287,2287,178.7135,9.6608906,4.7451344,0.0,0,4.6126437,0.0,0.37955928,84.155983,5.1046286,392.41241,-9.2601471
2288,2288,178.7137,9.6754284,4.7648206,0.0,0,4.5920234,0.0,0.38191023,84.074677,5.0790238,392.33835,-9.2607851
2289,2289,178.7139,9.6968632,4.7894974,0.0,0,4.5714035,0.0,0.38455951,83.988853,5.0552053,392.26428,-9.2603903
2290,2290,178.7141,9.7149429,4.8127074,0.0,0,4.5507836,0.0,0.38618162,84.026871,5.0340128,392.19025,-9.261055
2291,2291,178.7143,9.7342243,4.8324003,0.0,0,4.5305758,0.0,0.38843164,84.038116,5.0121651,392.11618,-9.2611523
2292,2292,178.7145,9.7573481,4.8528867,0.0,0,4.5108657,0.0,0.39099237,83.995422,4.9901314,392.04214,-9.2606153
2293,2293,178.7147,9.7778959,4.8756804,0.0,0,4.4912457,0.0,0.39250392,84.031189,4.9665842,391.96808,-9.2609549
2294,2294,178.7149,9.8066359,4.8964052,0.0,0,4.4716296,0.0,0.39451298,84.130119,4.9444647,391.89401,-9.260828
2295,2295,178.7151,9.846549,4.915832,0.0,0,4.4520135,0.0,0.39717394,84.222885,4.9231973,391.81998,-9.2608452
2296,2296,178.7153,9.8813868,4.9410429,0.0,0,4.4323974,0.0,0.39900339,84.366486,4.9024253,391.74591,-9.2603617
2297,2297,178.7155,9.9037724,4.9634395,0.0,0,4.4127812,0.0,0.40099627,84.433975,4.8826175,391.67184,-9.260313
2298,2298,178.7157,9.9169464,4.9807329,0.0,0,4.3931651,0.0,0.40356562,84.308243,4.8607874,391.59781,-9.2607431
2299,2299,178.7159,9.9282436,5.0067387,0.0,0,4.3735495,0.0,0.40564954,84.241318,4.8385549,391.52374,-9.2603321
2300,2300,178.7161,9.944212,5.0311251,0.0,0,4.3539338,0.0,0.40776351,84.188713,4.8172851,391.44971,-9.26052
2301,2301,178.7163,9.974885,5.0474381,0.0,0,4.3343177,0.0,0.41028956,84.157951,4.7943945,391.37564,-9.2611341
2302,2302,178.7165,9.9998722,5.0736718,0.0,0,4.3147016,0.0,0.4124718,84.178467,4.7736135,391.30157,-9.2611589
2303,2303,178.7167,10.016736,5.0984168,0.0,0,4.2950859,0.0,0.41440338,84.212471,4.7526298,391.22754,-9.2608204
2304,2304,178.7169,10.045717,5.1112409,0.0,0,4.2754693,0.0,0.41661099,84.298225,4.7312603,391.15347,-9.2600603
2305,2305,178.7171,10.085953,5.1340547,0.0,0,4.2558532,0.0,0.41873261,84.421562,4.7079477,391.07941,-9.2598181
2306,2306,178.7173,10.118416,5.1594086,0.0,0,4.236237,0.0,0.42052054,84.577446,4.6847992,391.00537,-9.2603998
2307,2307,178.7175,10.142154,5.1720219,0.0,0,4.2166214,0.0,0.4226473,84.585388,4.6658697,390.9313,-9.2614965
2308,2308,178.7177,10.158754,5.1952534,0.0,0,4.1970053,0.0,0.42507431,84.483368,4.6445584,390.85727,-9.261694
2309,2309,178.7179,10.170027,5.223999,0.0,0,4.1773891,0.0,0.42707357,84.437309,4.6222677,390.7832,-9.261013
2310,2310,178.7181,10.177985,5.2377148,0.0,0,4.1577735,0.0,0.42917812,84.347809,4.6042051,390.70914,-9.2609482
2311,2311,178.7183,10.193005,5.2601805,0.0,0,4.1381574,0.0,0.4317407,84.284744,4.5847163,390.6351,-9.2605324
2312,2312,178.7185,10.214982,5.2884426,0.0,0,4.1185412,0.0,0.43373138,84.260925,4.5605173,390.56104,-9.2603483
2313,2313,178.7187,10.244938,5.3015471,0.0,0,4.0989256,0.0,0.43557152,84.30764,4.5379381,390.48697,-9.2601242
2314,2314,178.7189,10.287618,5.3222847,0.0,0,4.0793095,0.0,0.43823296,84.450935,4.516438,390.41293,-9.2595758
2315,2315,178.7191,10.323083,5.349884,0.0,0,4.0596933,0.0,0.44027373,84.598137,4.4956303,390.33887,-9.2595758
2316,2316,178.7193,10.345317,5.3636184,0.0,0,4.0404716,0.0,0.44188204,84.662506,4.473474,390.2648,-9.2596312
2317,2317,178.7195,10.360674,5.3843355,0.0,0,4.0217257,0.0,0.44462821,84.574593,4.4522791,390.19077,-9.2603922
2318,2318,178.7197,10.376816,5.4127865,0.0,0,4.0030656,0.0,0.44684246,84.51741,4.4343629,390.1167,-9.2615023
2319,2319,178.7199,10.386538,5.426734,0.0,0,3.9844091,0.0,0.44838944,84.45417,4.4158683,390.04266,-9.2614985
2320,2320,178.7201,10.399964,5.4449592,0.0,0,3.9657531,0.0,0.45107082,84.315659,4.3952079,389.9686,-9.2611103
2321,2321,178.7203,10.419065,5.472146,0.0,0,3.9470971,0.0,0.45322829,84.252907,4.3757782,389.89453,-9.2604151
2322,2322,178.7205,10.447291,5.4865093,0.0,0,3.928441,0.0,0.45455664,84.372482,4.3567224,389.8205,-9.2596436
2323,2323,178.7207,10.487086,5.5033851,0.0,0,3.9097853,0.0,0.45715383,84.523148,4.3346829,389.74643,-9.2598591
2324,2324,178.7209,10.527324,5.5301714,0.0,0,3.8911293,0.0,0.45947927,84.625313,4.3131251,389.67236,-9.259861
2325,2325,178.7211,10.554064,5.5464859,0.0,0,3.8724732,0.0,0.46077159,84.761536,4.292068,389.59833,-9.2590179
2326,2326,178.7213,10.582238,5.5628829,0.0,0,3.8538172,0.0,0.46327996,84.799377,4.2723279,389.52426,-9.2588186
2327,2327,178.7215,10.604193,5.588201,0.0,0,3.8351612,0.0,0.46584404,84.710625,4.2553163,389.46417,-9.2593422
2328,2328,178.7217,10.607782,5.6070948,0.0,0,3.8165052,0.0,0.46722335,84.62207,4.2359986,389.40759,-9.260067
2329,2329,178.7219,10.614125,5.6240759,0.0,0,3.7978492,0.0,0.46963608,84.449699,4.2168322,389.35098,-9.2601461
2330,2330,178.7221,10.63568,5.6467471,0.0,0,3.7791932,0.0,0.47222313,84.40609,4.1982164,389.2944,-9.2596674
2331,2331,178.7223,10.668913,5.6653647,0.0,0,3.7605371,0.0,0.47354868,84.524033,4.1778092,389.23779,-9.2597952
2332,2332,178.7225,10.69513,5.6820006,0.0,0,3.7418811,0.0,0.47584099,84.509293,4.1569839,389.18121,-9.2602854
2333,2333,178.7227,10.728245,5.7038789,0.0,0,3.7232251,0.0,0.47843233,84.582832,4.138504,389.12463,-9.2600546
2334,2334,178.7229,10.766029,5.7241015,0.0,0,3.7045693,0.0,0.47980654,84.745094,4.1204114,389.06802,-9.2595129
2335,2335,178.7231,10.797989,5.7415032,0.0,0,3.6859133,0.0,0.48206833,84.759628,4.0971646,389.01144,-9.259758
2336,2336,178.7233,10.815037,5.7612925,0.0,0,3.6672573,0.0,0.4847143,84.749176,4.0743346,388.95483,-9.2604418
2337,2337,178.7235,10.824811,5.7821136,0.0,0,3.6486013,0.0,0.48615736,84.758965,4.054873,388.89825,-9.2603045
2338,2338,178.7237,10.843668,5.8002906,0.0,0,3.629945,0.0,0.48826101,84.690369,4.0357623,388.84164,-9.2595263
2339,2339,178.7239,10.858679,5.8179765,0.0,0,3.611289,0.0,0.49095702,84.589134,4.0165458,388.78506,-9.2589521
2340,2340,178.7241,10.874044,5.840518,0.0,0,3.5926332,0.0,0.49269268,84.532837,3.9984879,388.72845,-9.2588291
2341,2341,178.7243,10.898543,5.8598595,0.0,0,3.5743496,0.0,0.49471053,84.524551,3.9794238,388.67188,-9.2593632
2342,2342,178.7245,10.927084,5.8749871,0.0,0,3.5565164,0.0,0.49725407,84.519112,3.9599833,388.61526,-9.2596722
2343,2343,178.7247,10.969292,5.8978491,0.0,0,3.5387647,0.0,0.49906433,84.687111,3.9401741,388.55869,-9.2597389
2344,2344,178.7249,11.010858,5.9175797,0.0,0,3.5210166,0.0,0.50091469,84.873985,3.9222574,388.50208,-9.25982
2345,2345,178.7251,11.031995,5.9308772,0.0,0,3.5032687,0.0,0.50338888,84.890968,3.9043846,388.4455,-9.2599201
2346,2346,178.7253,11.04747,5.9541211,0.0,0,3.4855206,0.0,0.50535512,84.839981,3.88396,388.38889,-9.2590313
2347,2347,178.7255,11.064672,5.975975,0.0,0,3.4677725,0.0,0.5071525,84.750832,3.8653929,388.33231,-9.2588234
2348,2348,178.7257,11.078662,5.987699,0.0,0,3.4500246,0.0,0.50947756,84.687302,3.8461709,388.2757,-9.2594795
2349,2349,178.7259,11.086852,6.0094671,0.0,0,3.4322767,0.0,0.51156861,84.65387,3.8256993,388.21912,-9.2595139
2350,2350,178.7261,11.10256,6.0330067,0.0,0,3.4145288,0.0,0.51335835,84.595634,3.8089011,388.16254,-9.2595749
2351,2351,178.7263,11.136249,6.0441446,0.0,0,3.3967807,0.0,0.5155586,84.604729,3.7930262,388.10593,-9.2597866
2352,2352,178.7265,11.174193,6.0657153,0.0,0,3.3790326,0.0,0.51793915,84.743225,3.7717991,388.04935,-9.2600098
2353,2353,178.7267,11.214203,6.0918355,0.0,0,3.3612847,0.0,0.5199278,84.844872,3.753082,387.99274,-9.2604265
2354,2354,178.7269,11.246948,6.1034303,0.0,0,3.3435366,0.0,0.52212012,84.846512,3.7372251,387.93616,-9.2609062
2355,2355,178.7271,11.266932,6.1238894,0.0,0,3.3257885,0.0,0.52467304,84.824059,3.7170317,387.87955,-9.2607393
2356,2356,178.7273,11.28454,6.1499834,0.0,0,3.3080406,0.0,0.52657914,84.817223,3.6983232,387.82297,-9.2600584
2357,2357,178.7275,11.298111,6.1602659,0.0,0,3.2902927,0.0,0.52842861,84.766922,3.6791525,387.76636,-9.2595081
2358,2358,178.7277,11.31572,6.1791573,0.0,0,3.2725446,0.0,0.53107989,84.682129,3.6580529,387.70978,-9.2587376
2359,2359,178.7279,11.340515,6.2053509,0.0,0,3.2547965,0.0,0.532978,84.704971,3.6393578,387.65317,-9.2586679
2360,2360,178.7281,11.373869,6.2159657,0.0,0,3.2370486,0.0,0.53459936,84.80574,3.6213453,387.59659,-9.258666
2361,2361,178.7283,11.400413,6.2336287,0.0,0,3.2193005,0.0,0.53734207,84.753334,3.6042411,387.53998,-9.2581816
2362,2362,178.7285,11.422975,6.2592869,0.0,0,3.2015524,0.0,0.53927398,84.770119,3.5858097,387.4834,-9.2589645
2363,2363,178.7287,11.4592,6.2701759,0.0,0,3.1838045,0.0,0.54062319,84.938087,3.5667343,387.42679,-9.2602005
2364,2364,178.7289,11.495349,6.2862463,0.0,0,3.1660566,0.0,0.54333329,85.008232,3.5494399,387.37021,-9.2609386
2365,2365,178.7291,11.522278,6.311904,0.0,0,3.1483085,0.0,0.54545432,85.019844,3.5322959,387.3136,-9.261138
2366,2366,178.7293,11.535192,6.3246427,0.0,0,3.1309149,0.0,0.54672658,84.989998,3.514544,387.25702,-9.2606125
2367,2367,178.7295,11.549947,6.3407469,0.0,0,3.1139498,0.0,0.54948646,84.853424,3.4962351,387.20044,-9.2599039
2368,2368,178.7297,11.579267,6.368031,0.0,0,3.0970623,0.0,0.55201477,84.824242,3.4770033,387.14383,-9.2599306
2369,2369,178.7299,11.603696,6.3841853,0.0,0,3.0801783,0.0,0.55344403,84.888397,3.4584415,387.08725,-9.2586012
2370,2370,178.7301,11.622622,6.400095,0.0,0,3.0632942,0.0,0.55624068,84.818657,3.44136,387.03064,-9.2581072
2371,2371,178.7303,11.64919,6.4250174,0.0,0,3.0464103,0.0,0.55893725,84.794273,3.4226122,386.97406,-9.2592993
2372,2372,178.7305,11.687442,6.4410701,0.0,0,3.0295262,0.0,0.56017607,84.96051,3.4022281,386.91745,-9.2587729
2373,2373,178.7307,11.719811,6.4558229,0.0,0,3.0126421,0.0,0.56271827,84.990723,3.3844075,386.86087,-9.2582455
2374,2374,178.7309,11.752944,6.4782391,0.0,0,2.9957583,0.0,0.56535125,84.976852,3.3673763,386.80426,-9.258956
2375,2375,178.7311,11.79006,6.4952426,0.0,0,2.9788742,0.0,0.56647491,85.116951,3.3491216,386.74768,-9.2596235
2376,2376,178.7313,11.812108,6.5092654,0.0,0,2.9619904,0.0,0.5688054,85.100037,3.3301084,386.69107,-9.2595835
2377,2377,178.7315,11.823771,6.5295029,0.0,0,2.9451063,0.0,0.57148272,84.996277,3.3107655,386.61841,-9.2600527
2378,2378,178.7317,11.841755,6.5479903,0.0,0,2.9282222,0.0,0.57277352,85.038582,3.2931709,386.53885,-9.2602463
2379,2379,178.7319,11.868738,6.5633569,0.0,0,2.9113381,0.0,0.57504284,85.005516,3.2752056,386.45926,-9.2598543
2380,2380,178.7321,11.897763,6.5825081,0.0,0,2.894454,0.0,0.57788742,84.926811,3.2559371,386.3797,-9.2595921
2381,2381,178.7323,11.928451,6.6029568,0.0,0,2.8775702,0.0,0.57935339,85.022736,3.2357593,386.30014,-9.2594309
2382,2382,178.7325,11.957782,6.6199598,0.0,0,2.8606861,0.0,0.58156759,85.060417,3.2168925,386.22058,-9.2590179
2383,2383,178.7327,11.986614,6.6362147,0.0,0,2.8438022,0.0,0.58436894,85.051186,3.2027745,386.14099,-9.2583075
2384,2384,178.7329,12.019266,6.6569357,0.0,0,2.8269181,0.0,0.58585536,85.187057,3.1852219,386.06143,-9.2576704
2385,2385,178.7331,12.056725,6.6745062,0.0,0,2.810034,0.0,0.58791703,85.268028,3.1641273,385.98187,-9.2581301
2386,2386,178.7333,12.077683,6.6890812,0.0,0,2.7931502,0.0,0.59070295,85.185875,3.1461685,385.90231,-9.2585735
2387,2387,178.7335,12.091899,6.7116108,0.0,0,2.7762663,0.0,0.59253472,85.136871,3.1286621,385.82272,-9.2586842
2388,2388,178.7337,12.113444,6.7303805,0.0,0,2.7593822,0.0,0.59452063,85.059341,3.1114094,385.74316,-9.2588949
2389,2389,178.7339,12.13297,6.7423205,0.0,0,2.7424982,0.0,0.59715128,84.946159,3.0958438,385.6636,-9.2591925
2390,2390,178.7341,12.159868,6.7641368,0.0,0,2.7256143,0.0,0.59909195,84.972054,3.0785,385.58405,-9.2604475
2391,2391,178.7343,12.194554,6.7839146,0.0,0,2.7090681,0.0,0.60086668,85.064896,3.0601568,385.50446,-9.2610674
2392,2392,178.7345,12.229346,6.7946181,0.0,0,2.6929309,0.0,0.60345161,85.080643,3.0445304,385.4249,-9.2609777
2393,2393,178.7347,12.266134,6.8166718,0.0,0,2.6768675,0.0,0.60569084,85.108261,3.0268352,385.34534,-9.2605209
2394,2394,178.7349,12.303458,6.8383698,0.0,0,2.6608074,0.0,0.60745102,85.254349,3.0068424,385.26578,-9.2599087
2395,2395,178.7351,12.332099,6.8477712,0.0,0,2.6447473,0.0,0.60972762,85.349243,2.990092,385.18619,-9.2588558
2396,2396,178.7353,12.354575,6.8673005,0.0,0,2.6286871,0.0,0.61193395,85.298195,2.9738092,385.10663,-9.2573767
2397,2397,178.7355,12.376855,6.8901067,0.0,0,2.6126273,0.0,0.61373657,85.248566,2.9558578,385.02707,-9.2573118
2398,2398,178.7357,12.394414,6.8996954,0.0,0,2.5965672,0.0,0.61588246,85.178093,2.9379692,384.94751,-9.2579565
2399,2399,178.7359,12.411753,6.9192395,0.0,0,2.580507,0.0,0.61843616,85.086105,2.9213798,384.86792,-9.2586002
2400,2400,178.7361,12.436247,6.9433942,0.0,0,2.5644472,0.0,0.62031209,85.114006,2.9047391,384.78836,-9.2600231
2401,2401,178.7363,12.467092,6.950841,0.0,0,2.5483871,0.0,0.62209338,85.162071,2.887181,384.7088,-9.2602644
2402,2402,178.7365,12.505816,6.9679389,0.0,0,2.5323269,0.0,0.62473345,85.192047,2.8695936,384.62924,-9.2597132
2403,2403,178.7367,12.544754,6.9933944,0.0,0,2.5162671,0.0,0.62665844,85.310539,2.8532083,384.54965,-9.2594872
2404,2404,178.7369,12.575357,7.0031977,0.0,0,2.5002072,0.0,0.62843227,85.419777,2.8374767,384.47009,-9.259428
2405,2405,178.7371,12.601105,7.0206122,0.0,0,2.4841471,0.0,0.63142514,85.362312,2.820158,384.39053,-9.2594233
2406,2406,178.7373,12.623014,7.0468397,0.0,0,2.4680872,0.0,0.63356048,85.28495,2.8024414,384.31097,-9.2593765
2407,2407,178.7375,12.63413,7.057591,0.0,0,2.4520271,0.0,0.63510442,85.23156,2.7862227,384.23138,-9.2587872
2408,2408,178.7377,12.653485,7.0735741,0.0,0,2.4359672,0.0,0.63805926,85.095184,2.7682126,384.15182,-9.2580633
2409,2409,178.7379,12.683097,7.0990634,0.0,0,2.4199073,0.0,0.64028138,85.089592,2.750535,384.07227,-9.2580719
2410,2410,178.7381,12.711847,7.1100621,0.0,0,2.4038472,0.0,0.64162791,85.167542,2.7343657,383.99271,-9.258707
2411,2411,178.7383,12.749827,7.1235962,0.0,0,2.3877871,0.0,0.64440775,85.170937,2.7171106,383.91312,-9.2592468
2412,2412,178.7385,12.785227,7.1469932,0.0,0,2.3717272,0.0,0.64657456,85.234482,2.7006383,383.83356,-9.2596464
2413,2413,178.7387,12.826722,7.1583805,0.0,0,2.3556671,0.0,0.64764583,85.346939,2.6831779,383.754,-9.2599106
2414,2414,178.7389,12.868387,7.1711917,0.0,0,2.339607,0.0,0.65036118,85.389046,2.6645982,383.67444,-9.2603474
2415,2415,178.7391,12.896509,7.195323,0.0,0,2.3235471,0.0,0.65296477,85.427376,2.646348,383.59485,-9.2603865
2416,2416,178.7393,12.914707,7.2105608,0.0,0,2.3078086,0.0,0.65418589,85.463242,2.6308584,383.51529,-9.2591801
2417,2417,178.7395,12.929943,7.2243676,0.0,0,2.2924592,0.0,0.65695906,85.354759,2.616497,383.43573,-9.2589226
2418,2418,178.7397,12.956149,7.2468758,0.0,0,2.2771802,0.0,0.6598103,85.264107,2.6013353,383.35617,-9.259223
2419,2419,178.7399,12.985316,7.2634401,0.0,0,2.261904,0.0,0.66111261,85.300217,2.5859568,383.27661,-9.258647
2420,2420,178.7401,13.01604,7.2769408,0.0,0,2.2466278,0.0,0.66370547,85.281616,2.5676835,383.19702,-9.2580872
2421,2421,178.7403,13.053995,7.2970228,0.0,0,2.2313521,0.0,0.66654664,85.287277,2.5488107,383.11746,-9.2585697
2422,2422,178.7405,13.091096,7.3144131,0.0,0,2.2160761,0.0,0.66780108,85.439125,2.5326955,383.0379,-9.2586813
2423,2423,178.7407,13.122622,7.3279161,0.0,0,2.2008002,0.0,0.67012137,85.51194,2.5162055,382.95834,-9.2589016
2424,2424,178.7409,13.161927,7.3459764,0.0,0,2.185524,0.0,0.67293978,85.498848,2.5006688,382.87875,-9.2595167
2425,2425,178.7411,13.191732,7.3638229,0.0,0,2.170248,0.0,0.674236,85.561142,2.4824545,382.79919,-9.2597065
2426,2426,178.7413,13.209734,7.3771982,0.0,0,2.1549721,0.0,0.67636794,85.506279,2.465028,382.71964,-9.2595005
2427,2427,178.7415,13.228024,7.3929138,0.0,0,2.1396961,0.0,0.67926627,85.340912,2.4470289,382.48096,-9.2594805
2428,2428,178.7417,13.25006,7.4124765,0.0,0,2.1244199,0.0,0.68075091,85.324875,2.4296308,382.13623,-9.2590494
2429,2429,178.7419,13.282453,7.4280338,0.0,0,2.109144,0.0,0.68280542,85.352936,2.4180715,381.79147,-9.2581511
2430,2430,178.7421,13.315417,7.4423709,0.0,0,2.093868,0.0,0.6857962,85.341255,2.4018569,381.44675,-9.2582054
2431,2431,178.7423,13.357739,7.4630957,0.0,0,2.0785921,0.0,0.68752933,85.440918,2.3834682,381.10202,-9.2587385
2432,2432,178.7425,13.406892,7.4793973,0.0,0,2.0633161,0.0,0.6894865,85.539185,2.3654375,380.75726,-9.259264
2433,2433,178.7427,13.446799,7.4904981,0.0,0,2.0480402,0.0,0.69223362,85.579124,2.3466613,380.41254,-9.2594833
2434,2434,178.7429,13.469689,7.5111127,0.0,0,2.0327642,0.0,0.69416815,85.631004,2.330358,380.06781,-9.2593164
2435,2435,178.7431,13.496295,7.5289731,0.0,0,2.0174882,0.0,0.69606811,85.622437,2.3134899,379.72305,-9.2593098
2436,2436,178.7433,13.524891,7.5388103,0.0,0,2.002212,0.0,0.69862807,85.536438,2.2971871,379.37833,-9.2591076
2437,2437,178.7435,13.540865,7.5586233,0.0,0,1.986936,0.0,0.70060951,85.498802,2.2822304,379.0336,-9.2583523
2438,2438,178.7437,13.562976,7.5768542,0.0,0,1.9716599,0.0,0.70224154,85.532715,2.2668431,378.68887,-9.2580414
2439,2439,178.7439,13.593872,7.584444,0.0,0,1.9563839,0.0,0.70460129,85.508949,2.251853,378.34412,-9.2578764
2440,2440,178.7441,13.631296,7.6040487,0.0,0,1.941108,0.0,0.70696336,85.53833,2.2338488,377.99939,-9.2578716
2441,2441,178.7443,13.673954,7.6258407,0.0,0,1.9261372,0.0,0.70868051,85.687202,2.2166829,377.65466,-9.2580252
2442,2442,178.7445,13.713409,7.6336193,0.0,0,1.9115354,0.0,0.71094906,85.766968,2.2008352,377.30991,-9.2586393
2443,2443,178.7447,13.745708,7.6526976,0.0,0,1.8970003,0.0,0.71372426,85.689209,2.1839826,376.96518,-9.2591009
2444,2444,178.7449,13.77213,7.6770101,0.0,0,1.8824683,0.0,0.71566135,85.654297,2.1667314,376.62045,-9.258708
2445,2445,178.7451,13.795439,7.6854978,0.0,0,1.8679363,0.0,0.71779954,85.656815,2.1518002,376.27573,-9.2588472
2446,2446,178.7453,13.822024,7.7024193,0.0,0,1.8534042,0.0,0.72058004,85.565262,2.1388905,375.93097,-9.2593937
2447,2447,178.7455,13.845618,7.724864,0.0,0,1.8388723,0.0,0.72237563,85.535484,2.1236343,375.58624,-9.2595139
2448,2448,178.7457,13.868567,7.731771,0.0,0,1.8243402,0.0,0.72413641,85.548531,2.1073856,375.24152,-9.2593565
2449,2449,178.7459,13.895989,7.7467499,0.0,0,1.8098083,0.0,0.72694731,85.490746,2.0909271,374.89676,-9.2585659
2450,2450,178.7461,13.930366,7.7691531,0.0,0,1.7952763,0.0,0.72865158,85.551338,2.0757599,374.55203,-9.2579546
2451,2451,178.7463,13.976009,7.7763529,0.0,0,1.7807442,0.0,0.73003167,85.69857,2.0605206,374.20731,-9.2578554
2452,2452,178.7465,14.027573,7.7919445,0.0,0,1.7662122,0.0,0.73313367,85.749352,2.0445967,373.86258,-9.257163
2453,2453,178.7467,14.072386,7.8167715,0.0,0,1.7516803,0.0,0.73530185,85.832298,2.0298748,373.51782,-9.2573013
2454,2454,178.7469,14.101292,7.8256416,0.0,0,1.7371483,0.0,0.73667306,85.86219,2.0145288,373.1731,-9.2579947
2455,2455,178.7471,14.122102,7.8396921,0.0,0,1.7226163,0.0,0.73988426,85.714432,1.9983054,372.82837,-9.2580261
2456,2456,178.7473,14.14513,7.8641844,0.0,0,1.7080842,0.0,0.74228972,85.672264,1.9836231,372.48361,-9.2585659
2457,2457,178.7475,14.171327,7.8747072,0.0,0,1.6935523,0.0,0.74342406,85.728798,1.970227,372.13889,-9.2595978
2458,2458,178.7477,14.201814,7.887351,0.0,0,1.6790203,0.0,0.74647176,85.634964,1.9543258,371.79416,-9.2591467
2459,2459,178.7479,14.232944,7.9111137,0.0,0,1.6644882,0.0,0.7491886,85.635437,1.9367628,371.44943,-9.2581186
2460,2460,178.7481,14.261052,7.9240561,0.0,0,1.6499562,0.0,0.750314,85.720436,1.9220686,371.10468,-9.2585564
2461,2461,178.7483,14.305866,7.935895,0.0,0,1.6354243,0.0,0.75308406,85.747017,1.9074105,370.75995,-9.258749
2462,2462,178.7485,14.352918,7.9570937,0.0,0,1.6208922,0.0,0.75590599,85.80368,1.8926519,370.41522,-9.2575464
2463,2463,178.7487,14.389831,7.970623,0.0,0,1.6063603,0.0,0.75689006,85.922241,1.8785133,370.07047,-9.2573175
2464,2464,178.7489,14.415149,7.9813261,0.0,0,1.5918282,0.0,0.75944924,85.858635,1.8627722,369.72574,-9.2574568
2465,2465,178.7491,14.43142,8.0010672,0.0,0,1.5772963,0.0,0.76247126,85.687889,1.8480322,369.38101,-9.2574635
2466,2466,178.7493,14.454155,8.0164289,0.0,0,1.5630547,0.0,0.76349342,85.733665,1.8337688,369.03629,-9.2579718
2467,2467,178.7495,14.483476,8.0271187,0.0,0,1.5491643,0.0,0.76576871,85.71875,1.8155378,368.69153,-9.2585745
2468,2468,178.7497,14.514737,8.0437765,0.0,0,1.5353372,0.0,0.76861107,85.65416,1.799467,368.3468,-9.2586651
2469,2469,178.7499,14.551115,8.059763,0.0,0,1.5215131,0.0,0.76975548,85.751411,1.7858204,368.00208,-9.2587938
2470,2470,178.7501,14.60069,8.0715342,0.0,0,1.5076891,0.0,0.77201945,85.814323,1.7706261,367.65732,-9.2595272
2471,2471,178.7503,14.641169,8.0861874,0.0,0,1.4938651,0.0,0.77494079,85.81189,1.7559338,367.31259,-9.2595596
2472,2472,178.7505,14.672329,8.1036844,0.0,0,1.4800411,0.0,0.77621245,85.916679,1.7376858,366.96786,-9.2590637
2473,2473,178.7507,14.712337,8.1171436,0.0,0,1.4662172,0.0,0.77835524,85.96666,1.7221639,366.62314,-9.2583427
2474,2474,178.7509,14.745582,8.1310787,0.0,0,1.4523932,0.0,0.78144568,85.88855,1.7092834,366.27838,-9.2580557
2475,2475,178.7511,14.767929,8.1508398,0.0,0,1.4385692,0.0,0.78303838,85.900787,1.6937959,365.93365,-9.2577734
2476,2476,178.7513,14.794677,8.1659145,0.0,0,1.4247452,0.0,0.78512317,85.86338,1.6789969,365.58893,-9.2577553
2477,2477,178.7515,14.825078,8.1767273,0.0,0,1.4109212,0.0,0.78819096,85.765755,1.6648073,365.45544,-9.2580452
2478,2478,178.7517,14.862885,8.1961269,0.0,0,1.3970972,0.0,0.79001415,85.82238,1.6489356,365.5332,-9.2581005
2479,2479,178.7519,14.904029,8.212142,0.0,0,1.3832732,0.0,0.79187804,85.890739,1.6333208,365.61096,-9.2586145
2480,2480,178.7521,14.933605,8.2201157,0.0,0,1.3694493,0.0,0.79463822,85.841393,1.6216201,365.68872,-9.2593346
2481,2481,178.7523,14.971541,8.2389498,0.0,0,1.3556252,0.0,0.79665011,85.892075,1.6084461,365.76648,-9.2589951
2482,2482,178.7525,15.022908,8.2558212,0.0,0,1.3418012,0.0,0.79831982,86.05217,1.5910491,365.84424,-9.2587118
2483,2483,178.7527,15.06202,8.2627878,0.0,0,1.3279773,0.0,0.80083293,86.052933,1.5760714,365.92203,-9.2579002
2484,2484,178.7529,15.08971,8.2821035,0.0,0,1.3141533,0.0,0.80314988,85.998421,1.5613168,365.99979,-9.2571917
2485,2485,178.7531,15.119476,8.3020382,0.0,0,1.3003292,0.0,0.80484343,86.005089,1.5444101,366.07755,-9.2569609
2486,2486,178.7533,15.15111,8.3085279,0.0,0,1.2865052,0.0,0.80722827,85.984718,1.5303,366.1553,-9.257143
2487,2487,178.7535,15.174721,8.3255939,0.0,0,1.2726812,0.0,0.80980355,85.916824,1.5168059,366.23306,-9.2579842
2488,2488,178.7537,15.202849,8.3458691,0.0,0,1.2588573,0.0,0.8113988,85.944885,1.5003076,366.31082,-9.2584572
2489,2489,178.7539,15.243717,8.3509455,0.0,0,1.2450333,0.0,0.81337339,86.010239,1.485665,366.38858,-9.2585354
2490,2490,178.7541,15.281901,8.3662395,0.0,0,1.2312093,0.0,0.81605226,86.001411,1.4739908,366.46634,-9.2588549
2491,2491,178.7543,15.325865,8.3885317,0.0,0,1.2176626,0.0,0.81769449,86.109879,1.4594439,366.5441,-9.258831
2492,2492,178.7545,15.378478,8.3944788,0.0,0,1.2044512,0.0,0.819511,86.206711,1.4428298,366.62186,-9.2580833
2493,2493,178.7547,15.419202,8.4094687,0.0,0,1.1913005,0.0,0.82276219,86.160759,1.4310297,366.69962,-9.2573395
2494,2494,178.7549,15.451986,8.433279,0.0,0,1.1781523,0.0,0.82485723,86.197121,1.4185811,366.77737,-9.2567158
2495,2495,178.7551,15.485229,8.4403238,0.0,0,1.1650044,0.0,0.82647622,86.233688,1.4024397,366.85513,-9.257906
2496,2496,178.7553,15.51405,8.4541616,0.0,0,1.1518563,0.0,0.8296994,86.119446,1.3867943,366.93289,-9.2578163
2497,2497,178.7555,15.538566,8.477911,0.0,0,1.1387082,0.0,0.83184034,86.078941,1.3720196,367.01065,-9.2572823
2498,2498,178.7557,15.577583,8.4857187,0.0,0,1.1255603,0.0,0.83317506,86.154114,1.3586029,367.08841,-9.2578402
2499,2499,178.7559,15.619296,8.4974985,0.0,0,1.1124123,0.0,0.83632404,86.114098,1.3430201,367.1662,-9.2578678
2500,2500,178.7561,15.657722,8.5194235,0.0,0,1.0992643,0.0,0.83852518,86.125534,1.327462,367.24396,-9.2578678
2501,2501,178.7563,15.7046,8.5271549,0.0,0,1.0861163,0.0,0.83946413,86.335243,1.3151597,367.32172,-9.2578678
2502,2502,178.7565,15.752314,8.537221,0.0,0,1.0729682,0.0,0.8424648,86.385872,1.3037343,367.39948,-9.2580194
2503,2503,178.7567,15.798421,8.5591917,0.0,0,1.0598202,0.0,0.8449899,86.386429,1.2884263,367.47723,-9.2580204
2504,2504,178.7569,15.825481,8.5697403,0.0,0,1.0466722,0.0,0.84588212,86.482315,1.2736202,367.55499,-9.2572908
2505,2505,178.7571,15.84682,8.5794897,0.0,0,1.0335243,0.0,0.848849,86.347496,1.2585305,367.63275,-9.2572603
2506,2506,178.7573,15.876655,8.6001844,0.0,0,1.0203762,0.0,0.85166526,86.254143,1.2426363,367.71051,-9.2572861
2507,2507,178.7575,15.906001,8.6132641,0.0,0,1.0072283,0.0,0.8526684,86.34935,1.2288401,367.78827,-9.257288
2508,2508,178.7577,15.941311,8.6237898,0.0,0,0.99408025,0.0,0.85543877,86.262245,1.2142457,367.86603,-9.2572708
2509,2509,178.7579,15.988424,8.6422405,0.0,0,0.98093224,0.0,0.85832417,86.19429,1.1981291,367.94379,-9.2567177
2510,2510,178.7581,16.029253,8.6556358,0.0,0,0.96778423,0.0,0.85928607,86.357239,1.1835614,368.02155,-9.2574387
2511,2511,178.7583,16.073244,8.6649427,0.0,0,0.95463622,0.0,0.86183482,86.415901,1.1724534,368.0993,-9.2580261
2512,2512,178.7585,16.129383,8.6816788,0.0,0,0.94148827,0.0,0.86498332,86.418465,1.1589472,368.17706,-9.2580395
2513,2513,178.7587,16.170794,8.6974716,0.0,0,0.92834032,0.0,0.86600554,86.540344,1.1447909,368.25482,-9.257658
2514,2514,178.7589,16.200998,8.7085114,0.0,0,0.91519231,0.0,0.86838561,86.511078,1.1318223,368.33258,-9.2571011
2515,2515,178.7591,16.227198,8.7238817,0.0,0,0.9020443,0.0,0.87167519,86.3964,1.1179618,368.41037,-9.2567348
2516,2516,178.7593,16.250063,8.7408867,0.0,0,0.88916039,0.0,0.87298465,86.437111,1.1027504,368.48813,-9.256361
2517,2517,178.7595,16.283127,8.7519207,0.0,0,0.87659597,0.0,0.87522101,86.401703,1.0862803,368.56589,-9.2557878
2518,2518,178.7597,16.322412,8.7641792,0.0,0,0.86408937,0.0,0.87833625,86.31295,1.0720948,368.64365,-9.2564917
2519,2519,178.7599,16.367168,8.7809687,0.0,0,0.85158527,0.0,0.87953401,86.435654,1.0588782,368.72141,-9.2577896
2520,2520,178.7601,16.417509,8.7921982,0.0,0,0.83908123,0.0,0.88140732,86.513878,1.0443169,368.79916,-9.2576761
2521,2521,178.7603,16.466419,8.802002,0.0,0,0.82657719,0.0,0.88455099,86.502167,1.0291457,368.87692,-9.2575312
2522,2522,178.7605,16.517136,8.8204298,0.0,0,0.8140732,0.0,0.88615686,86.61882,1.01513,368.95468,-9.2572727
2523,2523,178.7607,16.553078,8.8344021,0.0,0,0.80156928,0.0,0.88783389,86.663757,1.004289,369.03244,-9.2574673
2524,2524,178.7609,16.574991,8.8419466,0.0,0,0.78906524,0.0,0.89077836,86.578362,0.99090588,369.1102,-9.2580643
2525,2525,178.7611,16.601248,8.8601465,0.0,0,0.77656126,0.0,0.89276147,86.535461,0.97544956,369.18796,-9.2580547
2526,2526,178.7613,16.631449,8.875248,0.0,0,0.76405728,0.0,0.89438754,86.538719,0.961914,369.26572,-9.2581968
2527,2527,178.7615,16.667566,8.8810501,0.0,0,0.75155324,0.0,0.89713669,86.499588,0.94792747,369.45654,-9.2581882
2528,2528,178.7617,16.712852,8.8991461,0.0,0,0.73904926,0.0,0.89946711,86.491219,0.93418288,369.81693,-9.257988
2529,2529,178.7619,16.762917,8.9172888,0.0,0,0.72654527,0.0,0.90111059,86.580811,0.92302513,370.17734,-9.2577839
2530,2530,178.7621,16.810236,8.9224377,0.0,0,0.71404123,0.0,0.90359449,86.633049,0.90894538,370.53772,-9.2570734
2531,2531,178.7623,16.860565,8.9387331,0.0,0,0.70153725,0.0,0.9061408,86.697754,0.89426398,370.8981,-9.2564983
2532,2532,178.7625,16.911201,8.9581928,0.0,0,0.68903327,0.0,0.90778685,86.811333,0.88226891,371.25848,-9.257021
2533,2533,178.7627,16.946154,8.9623165,0.0,0,0.67652929,0.0,0.90994728,86.810249,0.87086326,371.61887,-9.2572365
2534,2534,178.7629,16.964022,8.9772549,0.0,0,0.66402531,0.0,0.91274542,86.699516,0.85941368,371.97928,-9.2573624
2535,2535,178.7631,16.984661,8.9976254,0.0,0,0.65152127,0.0,0.91439551,86.661491,0.84504557,372.33966,-9.2582273
2536,2536,178.7633,17.014479,9.0012245,0.0,0,0.63901722,0.0,0.91613925,86.64077,0.8320365,372.70004,-9.2579689
2537,2537,178.7635,17.04587,9.0146208,0.0,0,0.62651324,0.0,0.91912502,86.535179,0.81957966,373.06042,-9.2581806
2538,2538,178.7637,17.090393,9.0355701,0.0,0,0.61400926,0.0,0.92086607,86.600571,0.80533344,373.42084,-9.2581472
2539,2539,178.7639,17.14229,9.0396414,0.0,0,0.60150528,0.0,0.92235333,86.73111,0.79070044,373.78122,-9.2570696
2540,2540,178.7641,17.193192,9.0523491,0.0,0,0.58900124,0.0,0.92558134,86.707062,0.77980745,374.1416,-9.2564621
2541,2541,178.7643,17.24375,9.0742006,0.0,0,0.57674497,0.0,0.92755204,86.810333,0.76750833,374.50198,-9.2562332
2542,2542,178.7645,17.286406,9.0786448,0.0,0,0.56478834,0.0,0.92868632,86.924377,0.75431848,374.86237,-9.2551908
2543,2543,178.7647,17.322216,9.089551,0.0,0,0.55288589,0.0,0.93179119,86.821167,0.74220848,375.22278,-9.2550983
2544,2544,178.7649,17.34799,9.1108704,0.0,0,0.54098582,0.0,0.93385977,86.772438,0.72770083,375.58316,-9.2563591
2545,2545,178.7651,17.367476,9.1172314,0.0,0,0.52908581,0.0,0.93493199,86.791931,0.7143594,375.94354,-9.2569952
2546,2546,178.7653,17.402678,9.1275063,0.0,0,0.51718581,0.0,0.93817168,86.674538,0.70275402,376.30392,-9.2577477
2547,2547,178.7655,17.446646,9.1482506,0.0,0,0.5052858,0.0,0.94064498,86.670227,0.69053167,376.66434,-9.2575321
2548,2548,178.7657,17.49091,9.1562433,0.0,0,0.49338579,0.0,0.94144773,86.852615,0.67762947,377.02472,-9.2575445
2549,2549,178.7659,17.545605,9.1648226,0.0,0,0.48148578,0.0,0.94440973,86.851074,0.66414499,377.3851,-9.257947
2550,2550,178.7661,17.606186,9.184761,0.0,0,0.46958581,0.0,0.94721836,86.880936,0.64998966,377.74548,-9.2579679
2551,2551,178.7663,17.660597,9.1952629,0.0,0,0.4576858,0.0,0.94804126,87.069565,0.63815767,378.10587,-9.2579775
2552,2552,178.7665,17.701416,9.2049809,0.0,0,0.44578579,0.0,0.95118058,87.020332,0.6244157,378.46628,-9.2569675
2553,2553,178.7667,17.732073,9.2242594,0.0,0,0.43388578,0.0,0.95445216,86.915596,0.6119858,378.82666,-9.2558422
2554,2554,178.7669,17.759962,9.235611,0.0,0,0.42198581,0.0,0.95504016,87.002655,0.59962565,379.18704,-9.2556334
2555,2555,178.7671,17.796083,9.2435265,0.0,0,0.4100858,0.0,0.95764846,86.928139,0.58701581,379.54742,-9.2557964
2556,2556,178.7673,17.836515,9.2589464,0.0,0,0.39818579,0.0,0.96069235,86.852982,0.57555151,379.90784,-9.2562218
2557,2557,178.7675,17.875221,9.2707548,0.0,0,0.38628578,0.0,0.96117067,87.011497,0.56353056,380.26822,-9.2564507
2558,2558,178.7677,17.919401,9.2781858,0.0,0,0.37438577,0.0,0.96354437,87.007431,0.55098474,380.6286,-9.2567549
2559,2559,178.7679,17.971085,9.2906981,0.0,0,0.36248577,0.0,0.9664734,86.989281,0.53703624,380.98898,-9.2573566