File: clean data/testID_0224.csv
level_0,index,Time(sec),Force(kN),Jaw(mm),PowAngle(deg),Power(W),Pram,PTemp,Strain,Stress(MPa),Stroke(mm),TC1(C),wedge(mm)
2273,2273,195.3454,0.49889529,0.020593584,0.0,0,9.0337057,0.0,0.001328892,4.9819784,10.062638,461.61307,-9.2356272
2274,2274,195.3456,1.7281759,0.043709196,0.0,0,9.0044422,0.0,0.0023076062,18.312094,10.027101,462.12552,-9.2350912
2275,2275,195.3458,3.232928,0.063529037,0.0,0,8.9751778,0.0,0.0040151807,37.451622,9.9951239,462.63794,-9.2344713
2276,2276,195.346,4.1154552,0.088911347,0.0,0,8.9459143,0.0,0.0058547156,50.441513,9.9653835,463.15039,-9.2337561
2277,2277,195.3462,4.3622217,0.11865321,0.0,0,8.9166498,0.0,0.0072990041,54.896122,9.9359379,463.66284,-9.2329798
2278,2278,195.3464,4.3703923,0.15033211,0.0,0,8.8873854,0.0,0.0094810929,55.212372,9.9008074,464.17529,-9.2321644
2279,2279,195.3466,4.4898405,0.21201336,0.0,0,8.8581219,0.0,0.01353219,56.043282,9.8625517,464.68774,-9.2319107
2280,2280,195.3468,4.5438614,0.29010549,0.0,0,8.8288574,0.0,0.018283878,56.833447,9.8177128,465.2002,-9.2311811
2281,2281,195.347,4.4014659,0.34711364,0.0,0,8.7995939,0.0,0.022560962,55.280563,9.7665968,465.71265,-9.2304249
2282,2282,195.3472,4.2779059,0.39966902,0.0,0,8.7703295,0.0,0.026593834,53.240555,9.7147617,466.2251,-9.2310495
2283,2283,195.3474,4.3639197,0.45805848,0.0,0,8.7416534,0.0,0.030111315,53.641205,9.6612196,466.73752,-9.2317533
2284,2284,195.3476,4.4726486,0.50630963,0.0,0,8.7136869,0.0,0.033487223,54.906185,9.608139,467.24997,-9.2324915
2285,2285,195.3478,4.5418615,0.55246115,0.0,0,8.6858492,0.0,0.037176568,55.558437,9.5592623,467.76242,-9.2327814
2286,2286,195.348,4.7018132,0.58883947,0.0,0,8.6580172,0.0,0.039519414,57.115566,9.5138302,468.27487,-9.232192
2287,2287,195.3482,4.7827234,0.60134274,0.0,0,8.6301851,0.0,0.040496729,58.444153,9.4693632,468.78732,-9.2319632
2288,2288,195.3484,4.6312833,0.62077528,0.0,0,8.6023531,0.0,0.042164773,56.948509,9.430233,469.29977,-9.2318983
2289,2289,195.3486,4.4422965,0.65681779,0.0,0,8.5745211,0.0,0.044211455,54.394951,9.3961105,469.84625,-9.2313585
2290,2290,195.3488,4.4855833,0.68561131,0.0,0,8.546689,0.0,0.046054646,54.240414,9.364542,470.39273,-9.2313194
2291,2291,195.349,4.6974068,0.70955133,0.0,0,8.518857,0.0,0.048279647,56.442554,9.3355055,470.93921,-9.2312984
2292,2292,195.3492,4.8413,0.73425931,0.0,0,8.491025,0.0,0.049951378,58.375381,9.3063059,471.48569,-9.2307882
2293,2293,195.3494,4.9526768,0.75763482,0.0,0,8.4631929,0.0,0.05119665,59.665096,9.2760201,472.03217,-9.2311516
2294,2294,195.3496,5.1200061,0.79553455,0.0,0,8.4353609,0.0,0.054021735,61.409187,9.2418222,472.57864,-9.2312498
2295,2295,195.3498,5.1872578,0.84895688,0.0,0,8.4075289,0.0,0.057705872,62.340034,9.2062578,473.12512,-9.2307234
2296,2296,195.35,4.998385,0.89860463,0.0,0,8.3796968,0.0,0.06086269,60.444427,9.1678333,473.6716,-9.2304678
2297,2297,195.3502,4.7307768,0.94187284,0.0,0,8.3518648,0.0,0.064315759,56.967628,9.1260166,474.21808,-9.2305374
2298,2298,195.3504,4.7052341,0.98634738,0.0,0,8.3240328,0.0,0.067645483,55.831703,9.0842638,474.76456,-9.2314768
2299,2299,195.3506,4.8680606,1.0313196,0.0,0,8.2962008,0.0,0.070394345,57.326176,9.0419769,475.31104,-9.2327881
2300,2300,195.3508,4.9202409,1.0736847,0.0,0,8.2683687,0.0,0.073711112,58.068001,8.9979115,475.85751,-9.2327394
2301,2301,195.351,4.8446426,1.1088612,0.0,0,8.2405367,0.0,0.076653443,57.188126,8.958806,476.40399,-9.232626
2302,2302,195.3512,4.8700705,1.1324704,0.0,0,8.2127056,0.0,0.078043133,57.128029,8.9214544,476.95047,-9.2327261
2303,2303,195.3514,4.9950099,1.1490549,0.0,0,8.1848736,0.0,0.079374604,58.458672,8.8845606,477.49695,-9.232851
2304,2304,195.3516,4.9982581,1.170821,0.0,0,8.1570406,0.0,0.081248336,58.839516,8.851943,478.04343,-9.2332201
2305,2305,195.3518,4.841476,1.2042172,0.0,0,8.1292095,0.0,0.083097108,57.162418,8.8226347,478.5899,-9.2325563
2306,2306,195.352,4.7467389,1.2346201,0.0,0,8.1013775,0.0,0.085250914,55.639446,8.7955456,479.13638,-9.2317295
2307,2307,195.3522,4.8773699,1.2539625,0.0,0,8.0735445,0.0,0.087283053,56.511841,8.7671709,479.68286,-9.2316942
2308,2308,195.3524,5.0957994,1.2780756,0.0,0,8.0462675,0.0,0.088647857,58.910603,8.740777,480.22934,-9.2317791
2309,2309,195.3526,5.2026887,1.308203,0.0,0,8.0196619,0.0,0.090518609,60.453243,8.7138653,480.77582,-9.2317333
2310,2310,195.3528,5.2097011,1.3422385,0.0,0,7.993176,0.0,0.093470454,60.545227,8.6831923,481.3223,-9.231657
2311,2311,195.353,5.2170982,1.3877597,0.0,0,7.9666953,0.0,0.096472718,60.325989,8.6515818,481.86877,-9.2309589
2312,2312,195.3532,5.2058101,1.4297142,0.0,0,7.9402156,0.0,0.099283054,60.073036,8.6194181,482.41525,-9.230792
2313,2313,195.3534,5.1254368,1.4616297,0.0,0,7.9137354,0.0,0.10221251,59.18507,8.5848789,482.96173,-9.2308302
2314,2314,195.3536,5.020761,1.5037369,0.0,0,7.8872552,0.0,0.1050883,57.744053,8.5490208,483.50821,-9.2311029
2315,2315,195.3538,4.9688892,1.548195,0.0,0,7.860775,0.0,0.10795692,56.785393,8.5123787,484.05469,-9.2317009
2316,2316,195.354,4.988421,1.5774201,0.0,0,7.8342953,0.0,0.1107885,56.790115,8.4750013,484.60117,-9.2317476
2317,2317,195.3542,5.0347147,1.6038432,0.0,0,7.8078156,0.0,0.11296407,57.229893,8.4402552,485.14767,-9.2318125
2318,2318,195.3544,5.0571456,1.6270766,0.0,0,7.7813349,0.0,0.11420693,57.4529,8.4101048,485.69415,-9.2319508
2319,2319,195.3546,5.069942,1.6405553,0.0,0,7.7548552,0.0,0.1155958,57.498951,8.3825521,486.24063,-9.2323284
2320,2320,195.3548,5.0856099,1.6684628,0.0,0,7.728375,0.0,0.11773996,57.536877,8.3570642,486.78711,-9.2321873
2321,2321,195.355,5.069572,1.7032443,0.0,0,7.7018952,0.0,0.11974264,57.353642,8.3285933,487.33359,-9.2320757
2322,2322,195.3552,5.0361185,1.7184588,0.0,0,7.675415,0.0,0.12140159,56.907898,8.3009977,487.88007,-9.231576
2323,2323,195.3554,5.0703468,1.7372783,0.0,0,7.6489348,0.0,0.12313504,56.90078,8.2758484,488.42654,-9.2310791
2324,2324,195.3556,5.1839447,1.764496,0.0,0,7.6224551,0.0,0.12444458,57.902664,8.2497625,488.97302,-9.2316799
2325,2325,195.3558,5.2743564,1.7839881,0.0,0,7.5959754,0.0,0.12603267,59.050213,8.2268057,489.5195,-9.2319326
2326,2326,195.356,5.277874,1.8147908,0.0,0,7.5694952,0.0,0.12877794,59.208401,8.2018547,490.06598,-9.2315264
2327,2327,195.3562,5.2484303,1.8530751,0.0,0,7.543015,0.0,0.13115959,58.657516,8.1740875,490.61246,-9.2308588
2328,2328,195.3564,5.2710466,1.875797,0.0,0,7.5165353,0.0,0.13298413,58.61726,8.1457443,491.15894,-9.2303391
2329,2329,195.3566,5.3190446,1.9047468,0.0,0,7.4900556,0.0,0.13561858,59.109379,8.1162663,491.70541,-9.2305965
2330,2330,195.3568,5.2916408,1.9449149,0.0,0,7.4635754,0.0,0.13817614,58.776581,8.0851698,492.25189,-9.2306881
2331,2331,195.357,5.2021651,1.972414,0.0,0,7.4370952,0.0,0.1402639,57.622238,8.053875,492.79837,-9.2304029
2332,2332,195.3572,5.1751027,1.9982573,0.0,0,7.410615,0.0,0.14283638,57.014965,8.0266304,493.34485,-9.2304955
2333,2333,195.3574,5.2313304,2.0252302,0.0,0,7.384666,0.0,0.14470415,57.390491,7.9984455,493.89133,-9.2306442
2334,2334,195.3576,5.2740383,2.0415514,0.0,0,7.3593607,0.0,0.14573351,57.932045,7.9688473,494.43781,-9.2312412
2335,2335,195.3578,5.2499003,2.0641863,0.0,0,7.3341718,0.0,0.14785007,57.737106,7.9413099,494.98428,-9.2317781
2336,2336,195.358,5.2098284,2.096137,0.0,0,7.3089876,0.0,0.15020718,57.166393,7.9165878,495.53076,-9.2317848
2337,2337,195.3582,5.2227592,2.1180947,0.0,0,7.2838035,0.0,0.15162188,57.040623,7.8929367,496.07724,-9.2321053
2338,2338,195.3584,5.2531457,2.1352243,0.0,0,7.2586198,0.0,0.15342347,57.174229,7.869041,496.62369,-9.2321625
2339,2339,195.3586,5.2640939,2.1581426,0.0,0,7.2334356,0.0,0.15524341,57.261623,7.8441429,496.68817,-9.2318792
2340,2340,195.3588,5.2949119,2.1815221,0.0,0,7.2082515,0.0,0.15654562,57.495228,7.8196373,496.75262,-9.2312536
2341,2341,195.359,5.363472,2.206809,0.0,0,7.1830673,0.0,0.15881369,58.037525,7.7956181,496.81708,-9.230547
2342,2342,195.3592,5.4255123,2.2349648,0.0,0,7.1578832,0.0,0.16115983,58.645763,7.773427,496.88156,-9.230093
2343,2343,195.3594,5.4298587,2.259897,0.0,0,7.132699,0.0,0.16261432,58.808613,7.7519855,496.94601,-9.2300606
2344,2344,195.3596,5.389904,2.2838445,0.0,0,7.1075149,0.0,0.16472887,58.346989,7.72609,497.0105,-9.2303467
2345,2345,195.3598,5.3602853,2.312829,0.0,0,7.0823312,0.0,0.16732378,57.818138,7.6982017,497.07495,-9.2304811
2346,2346,195.36,5.3611159,2.344856,0.0,0,7.0571475,0.0,0.16931976,57.615116,7.6707025,497.1394,-9.2305069
2347,2347,195.3602,5.3568897,2.3711247,0.0,0,7.0319633,0.0,0.17152214,57.403309,7.6439805,497.20389,-9.2306414
2348,2348,195.3604,5.3497691,2.3908775,0.0,0,7.0067787,0.0,0.17374027,57.201172,7.6188912,497.26834,-9.2313175
2349,2349,195.3606,5.3794618,2.4138041,0.0,0,6.981595,0.0,0.17503192,57.408176,7.5960546,497.33282,-9.2318087
2350,2350,195.3608,5.4283476,2.4366286,0.0,0,6.9564114,0.0,0.17666447,57.838036,7.570848,497.39728,-9.2312756
2351,2351,195.361,5.4444318,2.4580493,0.0,0,6.9312272,0.0,0.17895459,57.915527,7.5444055,497.46173,-9.230937
2352,2352,195.3612,5.4118161,2.4867461,0.0,0,6.9060431,0.0,0.18081383,57.595089,7.5212431,497.52621,-9.2308407
2353,2353,195.3614,5.3821502,2.5100985,0.0,0,6.8808589,0.0,0.18250565,57.256886,7.4985409,497.59067,-9.2302599
2354,2354,195.3616,5.3791437,2.5248766,0.0,0,6.8556757,0.0,0.18434529,57.065887,7.4729018,497.65515,-9.2301674
2355,2355,195.3618,5.3927841,2.5498965,0.0,0,6.8304915,0.0,0.18597896,57.004063,7.4500093,497.7196,-9.2303305
2356,2356,195.362,5.4251289,2.57706,0.0,0,6.8053074,0.0,0.18772198,57.156429,7.4292288,497.78406,-9.230834
2357,2357,195.3622,5.4707298,2.5961089,0.0,0,6.7801232,0.0,0.18990213,57.517612,7.4054389,497.84854,-9.2317333
2358,2358,195.3624,5.5288639,2.6235054,0.0,0,6.7554412,0.0,0.19200209,58.011387,7.3790593,497.91299,-9.2323141
2359,2359,195.3626,5.5660901,2.6520276,0.0,0,6.7313666,0.0,0.19375797,58.369442,7.3540916,497.97748,-9.232954
2360,2360,195.3628,5.5655808,2.6698594,0.0,0,6.7074018,0.0,0.19574641,58.323246,7.3303213,498.04193,-9.2334042
2361,2361,195.363,5.5404367,2.6987662,0.0,0,6.6834412,0.0,0.19810806,57.990593,7.3051486,498.10638,-9.2328234
2362,2362,195.3632,5.5172205,2.7322972,0.0,0,6.6594815,0.0,0.20017478,57.550804,7.2821283,498.17087,-9.2318325
2363,2363,195.3634,5.5150218,2.7493372,0.0,0,6.6355214,0.0,0.20214866,57.359016,7.2581778,498.23532,-9.2313719
2364,2364,195.3636,5.5262985,2.7722249,0.0,0,6.6115613,0.0,0.20425557,57.397476,7.2312512,498.2998,-9.230896
2365,2365,195.3638,5.5431223,2.8007994,0.0,0,6.5876012,0.0,0.20583929,57.451263,7.2075167,498.36426,-9.2305698
2366,2366,195.364,5.5634151,2.8165255,0.0,0,6.5636415,0.0,0.20755155,57.545845,7.183033,498.42871,-9.2311964
2367,2367,195.3642,5.5749307,2.8414066,0.0,0,6.5396814,0.0,0.21000318,57.57003,7.1573195,498.49319,-9.2311611
2368,2368,195.3644,5.5838418,2.8724606,0.0,0,6.5157218,0.0,0.21188997,57.522427,7.1347561,498.55765,-9.2310276
2369,2369,195.3646,5.6019354,2.8874731,0.0,0,6.4917617,0.0,0.21334085,57.558788,7.1119294,498.62213,-9.2315826
2370,2370,195.3648,5.614038,2.9089658,0.0,0,6.467802,0.0,0.21561696,57.569599,7.0865607,498.68658,-9.2313871
2371,2371,195.365,5.625493,2.9403033,0.0,0,6.4438419,0.0,0.21758659,57.598469,7.0623541,498.75104,-9.2314577
2372,2372,195.3652,5.649529,2.958708,0.0,0,6.4198813,0.0,0.21909353,57.687775,7.0398068,498.81552,-9.2324696
2373,2373,195.3654,5.6700592,2.9812684,0.0,0,6.3959212,0.0,0.22150508,57.72583,7.0155172,498.87997,-9.2329845
2374,2374,195.3656,5.6846166,3.0113466,0.0,0,6.3719611,0.0,0.22350968,57.845093,6.992981,498.94446,-9.2328806
2375,2375,195.3658,5.7048345,3.0304558,0.0,0,6.3480015,0.0,0.22499098,57.981926,6.9687476,499.00891,-9.2328033
2376,2376,195.366,5.7148304,3.0545692,0.0,0,6.3240414,0.0,0.2276046,57.927002,6.9414606,499.07336,-9.2323551
2377,2377,195.3662,5.7046123,3.0872288,0.0,0,6.3000817,0.0,0.23005863,57.693123,6.9167523,499.13785,-9.2313175
2378,2378,195.3664,5.697248,3.1086771,0.0,0,6.2761216,0.0,0.23152317,57.53746,6.8911295,499.2023,-9.230731
2379,2379,195.3666,5.71065,3.1281044,0.0,0,6.252162,0.0,0.23374429,57.516731,6.8660192,499.26678,-9.2307673
2380,2380,195.3668,5.7459469,3.1559203,0.0,0,6.2282019,0.0,0.23603241,57.661961,6.8426661,499.33124,-9.2311258
2381,2381,195.367,5.7755013,3.1795866,0.0,0,6.2042418,0.0,0.23748015,57.900307,6.8192668,499.39569,-9.2316742
2382,2382,195.3672,5.7802744,3.2018464,0.0,0,6.1802816,0.0,0.23987275,57.92812,6.7969933,499.46017,-9.2318678
2383,2383,195.3674,5.7736969,3.2291603,0.0,0,6.1568022,0.0,0.24229568,57.738277,6.7716355,499.52463,-9.231885
2384,2384,195.3676,5.7667909,3.2514427,0.0,0,6.1339045,0.0,0.24359798,57.585186,6.7456532,499.58911,-9.2311411
2385,2385,195.3678,5.7692361,3.2709415,0.0,0,6.1111116,0.0,0.24567725,57.452827,6.7205009,499.65356,-9.2310286
2386,2386,195.368,5.7749863,3.2957952,0.0,0,6.0883236,0.0,0.24805436,57.358154,6.695704,499.71802,-9.2316341
2387,2387,195.3682,5.7914529,3.3210127,0.0,0,6.0655355,0.0,0.24956441,57.428749,6.671936,499.7825,-9.231946
2388,2388,195.3684,5.8208079,3.3428791,0.0,0,6.042748,0.0,0.25165084,57.53661,6.6470976,499.84695,-9.2326784
2389,2389,195.3686,5.8560357,3.3664284,0.0,0,6.0199599,0.0,0.25413895,57.764137,6.6235814,499.56918,-9.2332392
2390,2390,195.3688,5.8867035,3.39326,0.0,0,5.9971714,0.0,0.25577813,58.03672,6.5999484,499.29144,-9.2332716
2391,2391,195.369,5.9017286,3.4171207,0.0,0,5.9743834,0.0,0.25786901,58.090191,6.5744381,499.01367,-9.2320013
2392,2392,195.3692,5.9034653,3.4406331,0.0,0,5.9515953,0.0,0.26055807,58.002274,6.5517874,498.73593,-9.23067
2393,2393,195.3694,5.8919277,3.4699121,0.0,0,5.9288073,0.0,0.26248631,57.749504,6.5270019,498.45816,-9.2309399
2394,2394,195.3696,5.8786983,3.494556,0.0,0,5.9060197,0.0,0.26450509,57.422867,6.5022187,498.18042,-9.2306271
2395,2395,195.3698,5.8763232,3.5142739,0.0,0,5.8832316,0.0,0.26695991,57.259075,6.4794483,497.90268,-9.2297935
2396,2396,195.37,5.8922453,3.5423257,0.0,0,5.8604436,0.0,0.26886666,57.28294,6.4561424,497.62491,-9.2302914
2397,2397,195.3702,5.9247556,3.5686684,0.0,0,5.8376555,0.0,0.27079856,57.45002,6.4304509,497.34717,-9.230731
2398,2398,195.3704,5.9594398,3.5869472,0.0,0,5.814867,0.0,0.27326852,57.669601,6.4045129,497.0694,-9.2307549
2399,2399,195.3706,5.9846258,3.6137137,0.0,0,5.792079,0.0,0.27531958,57.828617,6.3809252,496.79166,-9.2319698
2400,2400,195.3708,5.997016,3.6398025,0.0,0,5.7692914,0.0,0.27707627,57.927071,6.3577428,496.51392,-9.2323484
2401,2401,195.371,5.9983907,3.655798,0.0,0,5.7465034,0.0,0.27928326,57.876667,6.3355045,496.23615,-9.2317591
2402,2402,195.3712,5.9971743,3.682976,0.0,0,5.7237153,0.0,0.28150576,57.651165,6.3123093,495.9584,-9.2319574
2403,2403,195.3714,5.9995942,3.7128458,0.0,0,5.7009273,0.0,0.2834326,57.499569,6.2864833,495.68063,-9.2317972
2404,2404,195.3716,6.00107,3.7283428,0.0,0,5.6781397,0.0,0.28558373,57.4151,6.2632365,495.40289,-9.2310171
2405,2405,195.3718,6.0098176,3.7530808,0.0,0,5.6553516,0.0,0.28781727,57.329411,6.2411189,495.12512,-9.2304993
2406,2406,195.372,6.0321655,3.7841825,0.0,0,5.6325636,0.0,0.28962755,57.399361,6.2150531,494.84738,-9.2305822
2407,2407,195.3722,6.0665493,3.8009956,0.0,0,5.6097751,0.0,0.29179612,57.59396,6.189805,494.56964,-9.231041
2408,2408,195.3724,6.1011367,3.8269339,0.0,0,5.5874414,0.0,0.29447669,57.768726,6.1648908,494.29187,-9.2316637
2409,2409,195.3726,6.123713,3.8590014,0.0,0,5.5656581,0.0,0.29653502,57.893372,6.1419463,494.01413,-9.2324581
2410,2410,195.3728,6.1226139,3.8752403,0.0,0,5.5439734,0.0,0.29839939,57.840931,6.1188955,493.73636,-9.2322302
2411,2411,195.373,6.1095099,3.8994892,0.0,0,5.5222936,0.0,0.30101645,57.593803,6.0922737,493.45862,-9.2317991
2412,2412,195.3732,6.1083574,3.9315803,0.0,0,5.5006132,0.0,0.30315298,57.43988,6.0679722,493.18085,-9.2323313
2413,2413,195.3734,6.1157117,3.9485164,0.0,0,5.4789333,0.0,0.30487198,57.415649,6.0457492,492.90311,-9.2322073
2414,2414,195.3736,6.1251593,3.9712808,0.0,0,5.457253,0.0,0.30754787,57.314373,6.0219412,492.62537,-9.2312365
2415,2415,195.3738,6.1326489,4.001915,0.0,0,5.4355731,0.0,0.30964664,57.289417,5.9959793,492.3476,-9.2304983
2416,2416,195.374,6.1425686,4.0182328,0.0,0,5.4138932,0.0,0.31114927,57.349342,5.9720082,492.06985,-9.2309589
2417,2417,195.3742,6.1680508,4.039288,0.0,0,5.3922133,0.0,0.31372866,57.384472,5.9496384,491.79208,-9.2309294
2418,2418,195.3744,6.1990194,4.0694528,0.0,0,5.370533,0.0,0.31592467,57.544033,5.9243469,491.51434,-9.2308912
2419,2419,195.3746,6.2156949,4.0877032,0.0,0,5.3488531,0.0,0.31737658,57.609287,5.9010229,491.2366,-9.2316332
2420,2420,195.3748,6.2299829,4.1078796,0.0,0,5.3271732,0.0,0.31995928,57.524033,5.8776426,490.95883,-9.2320728
2421,2421,195.375,6.2420135,4.1374826,0.0,0,5.3054934,0.0,0.3224161,57.503948,5.8541298,490.68109,-9.2325277
2422,2422,195.3752,6.244195,4.1587181,0.0,0,5.283813,0.0,0.32389846,57.485264,5.8314557,490.40332,-9.2328243
2423,2423,195.3754,6.2442255,4.1800928,0.0,0,5.2621331,0.0,0.32651341,57.346848,5.8082461,490.12558,-9.2328815
2424,2424,195.3756,6.2524972,4.2099333,0.0,0,5.2404532,0.0,0.32919133,57.215645,5.7852101,489.84781,-9.2326145
2425,2425,195.3758,6.2680712,4.2324848,0.0,0,5.2187734,0.0,0.33066797,57.249184,5.7612672,489.57007,-9.2321234
2426,2426,195.376,6.2863832,4.2527986,0.0,0,5.1970935,0.0,0.33312944,57.316971,5.7368298,489.29233,-9.2318802
2427,2427,195.3762,6.3091726,4.2804933,0.0,0,5.1754136,0.0,0.33584771,57.399521,5.7124305,489.01456,-9.2317915
2428,2428,195.3764,6.332551,4.3047857,0.0,0,5.1537333,0.0,0.33740088,57.493412,5.6897492,488.73682,-9.2313738
2429,2429,195.3766,6.3522196,4.3255968,0.0,0,5.1320534,0.0,0.33980614,57.500816,5.6656609,488.45905,-9.2307053
2430,2430,195.3768,6.3593612,4.3506398,0.0,0,5.110373,0.0,0.3425546,57.486492,5.6400838,488.1813,-9.2302895
2431,2431,195.377,6.3569827,4.3759627,0.0,0,5.0886931,0.0,0.34418979,57.407444,5.6166568,487.90356,-9.2304153
2432,2432,195.3772,6.3552661,4.3976102,0.0,0,5.0670133,0.0,0.34642655,57.228561,5.5948706,487.62579,-9.2314854
2433,2433,195.3774,6.3559728,4.4201884,0.0,0,5.0457678,0.0,0.34908846,57.086987,5.5717254,487.34805,-9.2320995
2434,2434,195.3776,6.3618536,4.4458098,0.0,0,5.0250483,0.0,0.35077611,57.029415,5.5462384,487.07028,-9.2315903
2435,2435,195.3778,6.3722072,4.4667997,0.0,0,5.0044241,0.0,0.35285616,57.001713,5.5226016,486.79254,-9.2315807
2436,2436,195.378,6.3964348,4.485858,0.0,0,4.9838037,0.0,0.35543045,57.079231,5.502049,486.51477,-9.2323503
2437,2437,195.3782,6.4299445,4.5116491,0.0,0,4.9631839,0.0,0.35721165,57.253761,5.4808483,486.23703,-9.2320614
2438,2438,195.3784,6.4488831,4.5343976,0.0,0,4.9425635,0.0,0.35917509,57.339066,5.4560323,485.95929,-9.2315283
2439,2439,195.3786,6.4595509,4.5525322,0.0,0,4.9219437,0.0,0.36174423,57.305744,5.4317594,485.78433,-9.2315588
2440,2440,195.3788,6.4667912,4.5800982,0.0,0,4.9013238,0.0,0.36387148,57.239342,5.4107304,485.60941,-9.2311993
2441,2441,195.379,6.4738779,4.6056504,0.0,0,4.8807039,0.0,0.36591473,57.166893,5.3875561,485.43448,-9.2309761
2442,2442,195.3792,6.4765768,4.6225162,0.0,0,4.8600836,0.0,0.3684414,57.024651,5.362895,485.25955,-9.2316456
2443,2443,195.3794,6.4780827,4.6488886,0.0,0,4.8394637,0.0,0.37065825,56.885826,5.3400326,485.08459,-9.23242
2444,2444,195.3796,6.4912033,4.6751323,0.0,0,4.8188438,0.0,0.37254724,56.886055,5.3182001,484.90967,-9.2323055
2445,2445,195.3798,6.5103192,4.6906676,0.0,0,4.798224,0.0,0.374843,56.963734,5.2937026,484.73474,-9.2321815
2446,2446,195.38,6.5296464,4.7159286,0.0,0,4.7776036,0.0,0.37718892,56.934715,5.2692919,484.55978,-9.232048
2447,2447,195.3802,6.549798,4.7438002,0.0,0,4.7569838,0.0,0.37910077,56.975082,5.249671,484.38486,-9.2318726
2448,2448,195.3804,6.5733848,4.7582383,0.0,0,4.7363639,0.0,0.38129643,57.120754,5.2301126,484.20993,-9.2311354
2449,2449,195.3806,6.5900116,4.7834086,0.0,0,4.7157435,0.0,0.38390547,57.099129,5.2083263,484.035,-9.2303848
2450,2450,195.3808,6.5914187,4.8129392,0.0,0,4.6951237,0.0,0.38592041,57.04298,5.1850128,483.86005,-9.2303429
2451,2451,195.381,6.5922298,4.8266497,0.0,0,4.6745038,0.0,0.38792291,56.968327,5.1596785,483.68512,-9.2303476
2452,2452,195.3812,6.5951743,4.8505116,0.0,0,4.6538839,0.0,0.39058256,56.826855,5.134563,483.51019,-9.2303524
2453,2453,195.3814,6.6081276,4.8811693,0.0,0,4.6332641,0.0,0.39265549,56.807491,5.1128154,483.33527,-9.2310019
2454,2454,195.3816,6.6231322,4.8949776,0.0,0,4.6126437,0.0,0.39456165,56.850273,5.0929537,483.16031,-9.2317476
2455,2455,195.3818,6.6367288,4.9156327,0.0,0,4.5920234,0.0,0.39725,56.813854,5.0717626,482.98538,-9.2317142
2456,2456,195.382,6.6559067,4.9450383,0.0,0,4.5714035,0.0,0.39922574,56.775494,5.0499816,482.81046,-9.2314606
2457,2457,195.3822,6.6714845,4.9594517,0.0,0,4.5507836,0.0,0.40084475,56.824429,5.0274453,482.6355,-9.2315865
2458,2458,195.3824,6.6868653,4.9805298,0.0,0,4.5305758,0.0,0.40362281,56.810341,5.0053258,482.46057,-9.2312202
2459,2459,195.3826,6.7046118,5.0112247,0.0,0,4.5108657,0.0,0.40584037,56.843685,4.9837761,482.28564,-9.2307405
2460,2460,195.3828,6.7235446,5.0269289,0.0,0,4.4912457,0.0,0.40735629,56.953541,4.960072,482.11072,-9.2306156
2461,2461,195.383,6.727603,5.0465245,0.0,0,4.4716296,0.0,0.41008246,56.855171,4.9377332,481.93576,-9.2309589
2462,2462,195.3832,6.7333813,5.0763798,0.0,0,4.4520135,0.0,0.41249052,56.756653,4.9153724,481.76083,-9.2315311
2463,2463,195.3834,6.7480226,5.0947375,0.0,0,4.4323974,0.0,0.41405135,56.721859,4.8932662,481.58591,-9.2316751
2464,2464,195.3836,6.7524304,5.1142344,0.0,0,4.4127812,0.0,0.41685134,56.609371,4.8734951,481.41095,-9.2318077
2465,2465,195.3838,6.7567015,5.1423855,0.0,0,4.3931651,0.0,0.41941443,56.545769,4.852798,481.23602,-9.2313557
2466,2466,195.384,6.7732825,5.1618638,0.0,0,4.3735495,0.0,0.42081228,56.593292,4.8293061,481.0611,-9.2306242
2467,2467,195.3842,6.7976971,5.1807213,0.0,0,4.3539338,0.0,0.42352459,56.631355,4.8073506,480.88617,-9.2305155
2468,2468,195.3844,6.8236423,5.2074342,0.0,0,4.3343177,0.0,0.42627609,56.657646,4.7853918,480.71121,-9.2312298
2469,2469,195.3846,6.8405428,5.227428,0.0,0,4.3147016,0.0,0.42759255,56.709209,4.7627416,480.53629,-9.2320738
2470,2470,195.3848,6.8506074,5.2445283,0.0,0,4.2950859,0.0,0.42993832,56.719284,4.7430744,480.36136,-9.2322006
2471,2471,195.385,6.8587956,5.2689562,0.0,0,4.2754693,0.0,0.43266341,56.645832,4.7228041,480.1864,-9.2313881
2472,2472,195.3852,6.8655877,5.2903056,0.0,0,4.2558532,0.0,0.43406394,56.609264,4.6990709,480.01147,-9.2312975
2473,2473,195.3854,6.8642135,5.3077011,0.0,0,4.236237,0.0,0.43626723,56.525764,4.6772246,479.83655,-9.2318172
2474,2474,195.3856,6.8692002,5.3301897,0.0,0,4.2166214,0.0,0.43906417,56.377304,4.6561174,479.66162,-9.2315559
2475,2475,195.3858,6.8898411,5.3534112,0.0,0,4.1970053,0.0,0.44062686,56.379036,4.6344385,479.48666,-9.231739
2476,2476,195.386,6.9080615,5.3731775,0.0,0,4.1773891,0.0,0.44281769,56.422421,4.6150012,479.31174,-9.2321205
2477,2477,195.3862,6.9262938,5.394042,0.0,0,4.1577735,0.0,0.44573751,56.427711,4.5956635,479.13681,-9.2319632
2478,2478,195.3864,6.9493561,5.4189496,0.0,0,4.1381574,0.0,0.44754541,56.48,4.5761409,478.96188,-9.231348
2479,2479,195.3866,6.9669104,5.4396477,0.0,0,4.1185412,0.0,0.44963235,56.51152,4.5548906,478.78693,-9.2305288
2480,2480,195.3868,6.9699039,5.4573956,0.0,0,4.0989256,0.0,0.45240355,56.446095,4.5321598,478.612,-9.2304354
2481,2481,195.387,6.9665856,5.4823022,0.0,0,4.0793095,0.0,0.4542504,56.319088,4.5101471,478.43707,-9.2305374
2482,2482,195.3872,6.968843,5.5024071,0.0,0,4.0596933,0.0,0.45615456,56.203262,4.4885111,478.26212,-9.2308521
2483,2483,195.3874,6.9787574,5.5166121,0.0,0,4.0404716,0.0,0.45876458,56.10989,4.4692988,478.08719,-9.2314491
2484,2484,195.3876,6.9944348,5.5411921,0.0,0,4.0217257,0.0,0.46074098,56.172802,4.4504147,477.91226,-9.2317562
2485,2485,195.3878,7.0144291,5.5638151,0.0,0,4.0030656,0.0,0.46255463,56.230915,4.42871,477.73734,-9.2318478
2486,2486,195.388,7.0364623,5.577683,0.0,0,3.9844091,0.0,0.46505067,56.211353,4.408937,477.56238,-9.2312737
2487,2487,195.3882,7.0637498,5.6024098,0.0,0,3.9657531,0.0,0.46732575,56.372776,4.3894024,477.38745,-9.2312403
2488,2488,195.3884,7.0896297,5.6275177,0.0,0,3.9470971,0.0,0.46920472,56.517704,4.3677421,477.21252,-9.2312613
2489,2489,195.3886,7.1029391,5.6407108,0.0,0,3.928441,0.0,0.47154689,56.464355,4.3455353,477.34579,-9.2310753
2490,2490,195.3888,7.1047907,5.6644335,0.0,0,3.9097853,0.0,0.4739908,56.299805,4.3254051,477.47903,-9.2314463
2491,2491,195.389,7.1058555,5.6908431,0.0,0,3.8911293,0.0,0.47595286,56.206989,4.3056564,477.6123,-9.2317095
2492,2492,195.3892,7.1166205,5.7023854,0.0,0,3.8724732,0.0,0.47813991,56.167416,4.2832561,477.74557,-9.2318974
2493,2493,195.3894,7.1292119,5.72437,0.0,0,3.8538172,0.0,0.48068538,56.091846,4.2636423,477.87881,-9.2320309
2494,2494,195.3896,7.1413426,5.7525201,0.0,0,3.8351612,0.0,0.48256597,56.056412,4.2431312,478.01208,-9.2320347
2495,2495,195.3898,7.1600852,5.7634354,0.0,0,3.8165052,0.0,0.48443684,56.073685,4.2197003,478.14532,-9.2313128
2496,2496,195.39,7.1822481,5.7833018,0.0,0,3.7978492,0.0,0.48710683,56.115051,4.1987824,478.27859,-9.2310495
2497,2497,195.3902,7.2073464,5.8117619,0.0,0,3.7791932,0.0,0.4891043,56.218903,4.1799254,478.41187,-9.2308683
2498,2498,195.3904,7.2319231,5.823225,0.0,0,3.7605371,0.0,0.49083948,56.319405,4.1594529,478.5451,-9.2303619
2499,2499,195.3906,7.2587066,5.842422,0.0,0,3.7418811,0.0,0.49369046,56.355721,4.13837,478.67838,-9.2310791
2500,2500,195.3908,7.2721586,5.8720374,0.0,0,3.7232251,0.0,0.49578494,56.338383,4.1184421,478.81161,-9.2318411
2501,2501,195.391,7.2654004,5.8856072,0.0,0,3.7045693,0.0,0.49732882,56.255882,4.099133,478.94489,-9.2316179
2502,2502,195.3912,7.2647905,5.9027901,0.0,0,3.6859133,0.0,0.50024247,56.107063,4.0815263,479.07816,-9.2316046
2503,2503,195.3914,7.2760935,5.9307141,0.0,0,3.6672573,0.0,0.50248945,56.018295,4.061533,479.2114,-9.231842
2504,2504,195.3916,7.2933326,5.9454961,0.0,0,3.6486013,0.0,0.50393707,56.044727,4.0409651,479.34467,-9.2311106
2505,2505,195.3918,7.316505,5.9635825,0.0,0,3.629945,0.0,0.50692439,56.049568,4.0195136,479.47791,-9.2301722
2506,2506,195.392,7.3440309,5.9920082,0.0,0,3.611289,0.0,0.50944555,56.111938,3.9998579,479.61118,-9.2294207
2507,2507,195.3922,7.3627944,6.0074558,0.0,0,3.5926332,0.0,0.51076543,56.206284,3.9811523,479.74445,-9.2294035
2508,2508,195.3924,7.3787374,6.0223823,0.0,0,3.5743496,0.0,0.51341259,56.209579,3.9605262,479.87769,-9.2301121
2509,2509,195.3926,7.3935533,6.0476389,0.0,0,3.5565164,0.0,0.51592886,56.194092,3.9403901,480.01096,-9.2310476
2510,2510,195.3928,7.3944745,6.0654135,0.0,0,3.5387647,0.0,0.51713663,56.135284,3.9212482,480.1442,-9.2318354
2511,2511,195.393,7.3928523,6.0806842,0.0,0,3.5210166,0.0,0.51974148,55.946644,3.9025476,480.27747,-9.2318277
2512,2512,195.3932,7.3888178,6.1040545,0.0,0,3.5032687,0.0,0.52243418,55.769154,3.8839233,480.41074,-9.2324219
2513,2513,195.3934,7.3962564,6.1229143,0.0,0,3.4855206,0.0,0.52359068,55.757244,3.8656168,480.54398,-9.2325487
2514,2514,195.3936,7.4244232,6.1385145,0.0,0,3.4677725,0.0,0.52601457,55.778008,3.8449879,480.67725,-9.2314863
2515,2515,195.3938,7.4619074,6.1605988,0.0,0,3.4500246,0.0,0.52886176,55.886032,3.8235633,480.81049,-9.2308044
2516,2516,195.394,7.5001893,6.1812544,0.0,0,3.4322767,0.0,0.53027558,56.085464,3.8046823,480.94376,-9.2304058
2517,2517,195.3942,7.5272179,6.1978049,0.0,0,3.4145288,0.0,0.53260446,56.162113,3.7873495,481.07703,-9.2302332
2518,2518,195.3944,7.5394616,6.2172561,0.0,0,3.3967807,0.0,0.53544736,56.124866,3.7689245,481.21027,-9.2299576
2519,2519,195.3946,7.5385661,6.2389483,0.0,0,3.3790326,0.0,0.53690678,56.069443,3.74968,481.34354,-9.230485
2520,2520,195.3948,7.5354104,6.2565718,0.0,0,3.3612847,0.0,0.5391171,55.943237,3.7311635,481.47678,-9.230875
2521,2521,195.395,7.5340457,6.2744083,0.0,0,3.3435366,0.0,0.54208356,55.805557,3.7123082,481.61005,-9.230876
2522,2522,195.3952,7.5415626,6.2979984,0.0,0,3.3257885,0.0,0.54381067,55.787701,3.6934981,481.74332,-9.230917
2523,2523,195.3954,7.5655713,6.3165164,0.0,0,3.3080406,0.0,0.54583097,55.794022,3.6742816,481.87656,-9.2304192
2524,2524,195.3956,7.5972548,6.3308125,0.0,0,3.2902927,0.0,0.54857844,55.876381,3.6537552,482.00983,-9.2309399
2525,2525,195.3958,7.6253157,6.3542557,0.0,0,3.2725446,0.0,0.55038774,55.994762,3.634835,482.14307,-9.2316828
2526,2526,195.396,7.6524982,6.374434,0.0,0,3.2547965,0.0,0.55230004,56.060757,3.6153703,482.27634,-9.2319183
2527,2527,195.3962,7.6771126,6.3864594,0.0,0,3.2370486,0.0,0.55495912,56.089443,3.5975308,482.40961,-9.2319345
2528,2528,195.3964,7.6885991,6.4098678,0.0,0,3.2193005,0.0,0.55703241,56.074379,3.5808334,482.54285,-9.2315264
2529,2529,195.3966,7.6899738,6.4307547,0.0,0,3.2015524,0.0,0.5587557,56.013336,3.5619302,482.67612,-9.2314653
2530,2530,195.3968,7.6990504,6.4402657,0.0,0,3.1838045,0.0,0.56108356,55.932835,3.5424347,482.80936,-9.2318277
2531,2531,195.397,7.7163072,6.4615564,0.0,0,3.1660566,0.0,0.56321722,55.932831,3.5238662,482.94263,-9.2313299
2532,2532,195.3972,7.7321076,6.4840264,0.0,0,3.1483085,0.0,0.5649035,55.939972,3.5067885,483.0759,-9.2312918
2533,2533,195.3974,7.7483559,6.4935765,0.0,0,3.1309149,0.0,0.56712306,55.905968,3.4895103,483.20914,-9.230752
2534,2534,195.3976,7.7674851,6.51477,0.0,0,3.1139498,0.0,0.56955642,55.927765,3.4709539,483.34241,-9.2294197
2535,2535,195.3978,7.7924623,6.5402894,0.0,0,3.0970623,0.0,0.57146955,56.01881,3.4518116,483.47565,-9.2289696
2536,2536,195.398,7.813107,6.5505099,0.0,0,3.0801783,0.0,0.57368076,56.036461,3.4322848,483.60892,-9.2291813
2537,2537,195.3982,7.8265462,6.5718722,0.0,0,3.0632942,0.0,0.57645446,55.965485,3.4144106,483.74219,-9.2303371
2538,2538,195.3984,7.8407269,6.5996952,0.0,0,3.0464103,0.0,0.57849765,55.973415,3.3977408,483.87543,-9.2312784
2539,2539,195.3986,7.8550649,6.6102138,0.0,0,3.0295262,0.0,0.58054942,55.975647,3.3788679,483.9447,-9.2320795
2540,2540,195.3988,7.8619342,6.6288929,0.0,0,3.0126421,0.0,0.58347595,55.847569,3.360383,484.01401,-9.2327948
2541,2541,195.399,7.8716936,6.6550808,0.0,0,2.9957583,0.0,0.58541745,55.787804,3.3427072,484.08328,-9.2326164
2542,2542,195.3992,7.8913512,6.6636763,0.0,0,2.9788742,0.0,0.58686513,55.82671,3.3238268,484.15256,-9.2328243
2543,2543,195.3994,7.9059825,6.6783991,0.0,0,2.9619904,0.0,0.58949864,55.802418,3.3067744,484.22186,-9.2326241
2544,2544,195.3996,7.9208417,6.7033162,0.0,0,2.9451063,0.0,0.59136778,55.82058,3.2906852,484.29114,-9.2312002
2545,2545,195.3998,7.9437356,6.7129455,0.0,0,2.9282222,0.0,0.59263247,55.878902,3.2729213,484.36041,-9.2296658
2546,2546,195.4,7.9732275,6.7271771,0.0,0,2.9113381,0.0,0.5954026,55.909672,3.2554808,484.42972,-9.2288303
2547,2547,195.4002,7.9974899,6.7530146,0.0,0,2.894454,0.0,0.59759492,56.014824,3.2396224,484.49899,-9.2287254
2548,2548,195.4004,8.0161018,6.765552,0.0,0,2.8775702,0.0,0.59885526,56.100235,3.2214141,484.56827,-9.2287216
2549,2549,195.4006,8.0346813,6.7811227,0.0,0,2.8606861,0.0,0.60175282,56.030865,3.1997635,484.63754,-9.229435
2550,2550,195.4008,8.0480309,6.8083186,0.0,0,2.8438022,0.0,0.6043641,55.951481,3.180445,484.70685,-9.2306376
2551,2551,195.401,8.064805,6.823421,0.0,0,2.8269181,0.0,0.6056903,55.979134,3.1651843,484.77612,-9.230978
2552,2552,195.4012,8.0795021,6.8374915,0.0,0,2.810034,0.0,0.60855037,55.932224,3.1493864,484.8454,-9.2313166
2553,2553,195.4014,8.0874138,6.8616152,0.0,0,2.7931502,0.0,0.61127603,55.853687,3.1301033,484.9147,-9.2321682
2554,2554,195.4016,8.1050072,6.8772073,0.0,0,2.7762663,0.0,0.61227882,55.909039,3.1121671,484.98398,-9.2317467
2555,2555,195.4018,8.1380968,6.8897619,0.0,0,2.7593822,0.0,0.61469817,55.977982,3.0947723,485.05325,-9.2304554
2556,2556,195.402,8.1722193,6.910615,0.0,0,2.7424982,0.0,0.61753404,56.062881,3.0779719,485.12256,-9.230113
2557,2557,195.4022,8.1968765,6.9277167,0.0,0,2.7256143,0.0,0.6187073,56.235626,3.0619078,485.19183,-9.2297411
2558,2558,195.4024,8.2160826,6.9408717,0.0,0,2.7090681,0.0,0.62103534,56.219238,3.044579,485.26111,-9.2288771
2559,2559,195.4026,8.2323704,6.9604349,0.0,0,2.6929309,0.0,0.62387156,56.077793,3.0278993,485.33038,-9.2286539
2560,2560,195.4028,8.2448053,6.979938,0.0,0,2.6768675,0.0,0.62510574,56.122494,3.0108833,485.39969,-9.2288961
2561,2561,195.403,8.2573137,6.9947252,0.0,0,2.6608074,0.0,0.62739009,56.122074,2.9923363,485.46896,-9.2296124
2562,2562,195.4032,8.2678909,7.0123043,0.0,0,2.6447473,0.0,0.63039643,56.013874,2.9731154,485.53824,-9.230237
2563,2563,195.4034,8.2850456,7.0324192,0.0,0,2.6286871,0.0,0.63178736,56.051037,2.9561028,485.60754,-9.2304449
2564,2564,195.4036,8.31464,7.0469937,0.0,0,2.6126273,0.0,0.63375539,56.125256,2.9404778,485.67682,-9.2307339
2565,2565,195.4038,8.345767,7.0611215,0.0,0,2.5965672,0.0,0.6366508,56.185081,2.9248588,485.74609,-9.2307987
2566,2566,195.404,8.3778486,7.082036,0.0,0,2.580507,0.0,0.63822824,56.329639,2.9080396,485.8154,-9.2305317
2567,2567,195.4042,8.4061985,7.0982876,0.0,0,2.5644472,0.0,0.64005399,56.409065,2.8896384,485.88467,-9.2303457
2568,2568,195.4044,8.4283924,7.1106467,0.0,0,2.5483871,0.0,0.64296103,56.354916,2.8724651,485.95395,-9.2301254
2569,2569,195.4046,8.4415989,7.1324725,0.0,0,2.5323269,0.0,0.64486277,56.338097,2.8557117,486.02322,-9.2301931
2570,2570,195.4048,8.4447975,7.1503711,0.0,0,2.5162671,0.0,0.64655691,56.306835,2.8389356,486.09253,-9.2301178
2571,2571,195.405,8.4554625,7.1614347,0.0,0,2.5002072,0.0,0.64929706,56.224995,2.8221228,486.1618,-9.2300148
2572,2572,195.4052,8.4717865,7.1842332,0.0,0,2.4841471,0.0,0.6515674,56.195091,2.8058574,486.23108,-9.229557
2573,2573,195.4054,8.496398,7.20433,0.0,0,2.4680872,0.0,0.65335131,56.209167,2.791245,486.30038,-9.2290821
2574,2574,195.4056,8.5215511,7.212811,0.0,0,2.4520271,0.0,0.65580887,56.245461,2.7742856,486.36966,-9.2292213
2575,2575,195.4058,8.5459118,7.2336578,0.0,0,2.4359672,0.0,0.65809542,56.331081,2.7577825,486.43893,-9.2291737
2576,2576,195.406,8.5800877,7.25598,0.0,0,2.4199073,0.0,0.65975285,56.453331,2.7420821,486.50824,-9.2291641
2577,2577,195.4062,8.6075649,7.2630806,0.0,0,2.4038472,0.0,0.66198993,56.507908,2.7245693,486.57751,-9.2292728
2578,2578,195.4064,8.6195192,7.2816887,0.0,0,2.3877871,0.0,0.66453147,56.47802,2.707248,486.64679,-9.2297001
2579,2579,195.4066,8.631567,7.3057323,0.0,0,2.3717272,0.0,0.66622472,56.48362,2.6884515,486.71606,-9.2297621
2580,2580,195.4068,8.6482344,7.312676,0.0,0,2.3556671,0.0,0.66818297,56.464279,2.6698489,486.78537,-9.2300472
2581,2581,195.407,8.6684914,7.3299432,0.0,0,2.339607,0.0,0.67098731,56.371822,2.652262,486.85464,-9.2307215
2582,2582,195.4072,8.6886044,7.355402,0.0,0,2.3235471,0.0,0.67280829,56.377003,2.6395104,486.92392,-9.231369
2583,2583,195.4074,8.7087765,7.3627219,0.0,0,2.3078086,0.0,0.67451632,56.414684,2.6263053,486.99323,-9.231142
2584,2584,195.4076,8.7404852,7.3789954,0.0,0,2.2924592,0.0,0.67752439,56.45956,2.6079204,487.0625,-9.2305956
2585,2585,195.4078,8.7789497,7.4048104,0.0,0,2.2771802,0.0,0.67948616,56.575867,2.5909638,487.13177,-9.2304945
2586,2586,195.408,8.8116913,7.4130616,0.0,0,2.261904,0.0,0.68093473,56.690201,2.5757518,487.20108,-9.2302485
2587,2587,195.4082,8.8328629,7.4275417,0.0,0,2.2466278,0.0,0.68383646,56.732628,2.5616536,487.27036,-9.2301903
2588,2588,195.4084,8.8513803,7.4529653,0.0,0,2.2313521,0.0,0.68593401,56.744576,2.5455978,487.33963,-9.2299604
2589,2589,195.4086,8.8672266,7.4624267,0.0,0,2.2160761,0.0,0.68726873,56.74448,2.5273638,487.43219,-9.2300491
2590,2590,195.4088,8.8825064,7.4756603,0.0,0,2.2008002,0.0,0.69027638,56.686428,2.5093606,487.52478,-9.229929
2591,2591,195.409,8.8953085,7.5013294,0.0,0,2.185524,0.0,0.69274271,56.672581,2.4953797,487.61734,-9.2298803
2592,2592,195.4092,8.9080009,7.5132413,0.0,0,2.170248,0.0,0.69394469,56.670338,2.4786193,487.7099,-9.2303391
2593,2593,195.4094,8.9293375,7.5262008,0.0,0,2.1549721,0.0,0.69682842,56.600216,2.4587855,487.80246,-9.23032
2594,2594,195.4096,8.9636803,7.5506039,0.0,0,2.1396961,0.0,0.69947088,56.674,2.443891,487.89502,-9.2302408
2595,2595,195.4098,9.0078592,7.5640569,0.0,0,2.1244199,0.0,0.70056564,56.873615,2.4287357,487.98758,-9.2302437
2596,2596,195.41,9.0468845,7.5760913,0.0,0,2.109144,0.0,0.70341218,56.941559,2.4103146,488.08017,-9.2300768
2597,2597,195.4102,9.0711603,7.5985422,0.0,0,2.093868,0.0,0.70625114,56.983971,2.3939252,488.17273,-9.22995
2598,2598,195.4104,9.0855894,7.6137137,0.0,0,2.0785921,0.0,0.70719451,57.040417,2.3773873,488.26529,-9.2294722
2599,2599,195.4106,9.0939398,7.6249433,0.0,0,2.0633161,0.0,0.70977515,56.95467,2.3616459,488.35785,-9.2294455
2600,2600,195.4108,9.112155,7.644464,0.0,0,2.0480402,0.0,0.71267128,56.875515,2.3470087,488.45041,-9.2293987
2601,2601,195.411,9.1343708,7.6614251,0.0,0,2.0327642,0.0,0.71375477,56.927105,2.331744,488.54297,-9.229598
2602,2602,195.4112,9.1533413,7.6736317,0.0,0,2.0174882,0.0,0.71631396,56.92522,2.3168845,488.63556,-9.2302971
2603,2603,195.4114,9.1811991,7.6920152,0.0,0,2.002212,0.0,0.719441,56.921471,2.3010154,488.72812,-9.2305841
2604,2604,195.4116,9.2247219,7.7109241,0.0,0,1.986936,0.0,0.72064447,57.095806,2.2846231,488.82068,-9.2305927
2605,2605,195.4118,9.2702961,7.7233706,0.0,0,1.9716599,0.0,0.72280407,57.261566,2.2672153,488.91324,-9.230073
2606,2606,195.412,9.3006115,7.7388477,0.0,0,1.9563839,0.0,0.72586685,57.315411,2.2505655,489.0058,-9.230051
2607,2607,195.4122,9.3197823,7.7591023,0.0,0,1.941108,0.0,0.72721589,57.34156,2.235415,489.09839,-9.230155
2608,2608,195.4124,9.3326912,7.7735724,0.0,0,1.9261371,0.0,0.72926956,57.295399,2.2199109,489.19095,-9.2294016
2609,2609,195.4126,9.350029,7.786428,0.0,0,1.9115354,0.0,0.73249573,57.192478,2.2034688,489.28351,-9.2287855
2610,2610,195.4128,9.3649349,7.8065319,0.0,0,1.8970003,0.0,0.7341218,57.178505,2.1866033,489.37607,-9.2287655
2611,2611,195.413,9.3732014,7.8215055,0.0,0,1.8824683,0.0,0.73592436,57.162807,2.169548,489.46863,-9.2285376
2612,2612,195.4132,9.3962584,7.832509,0.0,0,1.8679363,0.0,0.73891944,57.12542,2.1531339,489.56119,-9.2290077
2613,2613,195.4134,9.4309092,7.8536754,0.0,0,1.8534042,0.0,0.74081612,57.216099,2.1366575,489.65378,-9.2292986
2614,2614,195.4136,9.4686613,7.8708849,0.0,0,1.8388723,0.0,0.74261284,57.340435,2.121078,489.74634,-9.2293024
2615,2615,195.4138,9.5110645,7.8801274,0.0,0,1.8243402,0.0,0.74558878,57.434963,2.1060243,489.8389,-9.2300758
2616,2616,195.414,9.5522337,7.9010406,0.0,0,1.8098083,0.0,0.74782962,57.55257,2.0900428,489.93146,-9.2303972
2617,2617,195.4142,9.585022,7.9206681,0.0,0,1.7952763,0.0,0.74952507,57.64278,2.073832,490.02402,-9.2299423
2618,2618,195.4144,9.6014032,7.9283981,0.0,0,1.7807442,0.0,0.7521432,57.571533,2.0588751,490.11661,-9.2291832
2619,2619,195.4146,9.6100836,7.9469395,0.0,0,1.7662122,0.0,0.75448924,57.499615,2.0429578,490.20917,-9.2288036
2620,2620,195.4148,9.626173,7.9682484,0.0,0,1.7516803,0.0,0.75613165,57.53566,2.0263822,490.30173,-9.2287388
2621,2621,195.415,9.6566944,7.97505,0.0,0,1.7371483,0.0,0.75844193,57.533051,2.0107086,490.39429,-9.2287283
2622,2622,195.4152,9.6904325,7.9926376,0.0,0,1.7226163,0.0,0.76111192,57.563026,1.9965889,490.48685,-9.2286263
2623,2623,195.4154,9.7243748,8.0157595,0.0,0,1.7080842,0.0,0.76283306,57.697495,1.98173,490.57941,-9.2282238
2624,2624,195.4156,9.7656507,8.0208197,0.0,0,1.6935523,0.0,0.76475245,57.807915,1.9641224,490.672,-9.2278605
2625,2625,195.4158,9.807313,8.0369396,0.0,0,1.6790203,0.0,0.76768434,57.883728,1.9485968,490.76456,-9.2284498
2626,2626,195.416,9.8427286,8.0621901,0.0,0,1.6644882,0.0,0.76973009,58.002785,1.9334235,490.85712,-9.2289505
2627,2627,195.4162,9.8648653,8.0707846,0.0,0,1.6499562,0.0,0.7717151,58.046085,1.9167874,490.94968,-9.2287827
2628,2628,195.4164,9.8760376,8.087738,0.0,0,1.6354243,0.0,0.77505898,57.912262,1.900999,491.04224,-9.228857
2629,2629,195.4166,9.891037,8.1129627,0.0,0,1.6208922,0.0,0.77716035,57.837601,1.8866111,491.13483,-9.2298546
2630,2630,195.4168,9.9087343,8.1202545,0.0,0,1.6063603,0.0,0.77870798,57.872128,1.8716568,491.22739,-9.2305679
2631,2631,195.417,9.9304962,8.1334429,0.0,0,1.5918282,0.0,0.78201598,57.824669,1.8544908,491.31995,-9.2303333
2632,2632,195.4172,9.9702911,8.1573305,0.0,0,1.5772963,0.0,0.78412259,57.910591,1.8387448,491.41251,-9.2298489
2633,2633,195.4174,10.015392,8.1657772,0.0,0,1.5630547,0.0,0.78523248,58.111542,1.8238306,491.50507,-9.2294083
2634,2634,195.4176,10.050227,8.17803,0.0,0,1.5491643,0.0,0.7883209,58.174557,1.8083168,491.59763,-9.2291164
2635,2635,195.4178,10.087173,8.2018862,0.0,0,1.5353372,0.0,0.79078692,58.219944,1.7940418,491.69022,-9.228735
2636,2636,195.418,10.12031,8.2121162,0.0,0,1.5215131,0.0,0.79172981,58.326637,1.7803875,491.78278,-9.2281275
2637,2637,195.4182,10.145452,8.2226763,0.0,0,1.5076891,0.0,0.79467946,58.309288,1.7628343,491.87534,-9.2276106
2638,2638,195.4184,10.165078,8.245348,0.0,0,1.4938651,0.0,0.79754406,58.241642,1.7469826,491.9679,-9.2281656
2639,2639,195.4186,10.182439,8.2583637,0.0,0,1.4800411,0.0,0.7985664,58.292408,1.7331073,491.90338,-9.2287159
2640,2640,195.4188,10.2079,8.269393,0.0,0,1.4662172,0.0,0.80145025,58.248615,1.7191319,491.83887,-9.228756
2641,2641,195.419,10.238809,8.2908325,0.0,0,1.4523932,0.0,0.80448323,58.23698,1.7061568,491.77438,-9.2294683
2642,2642,195.4192,10.274764,8.3055534,0.0,0,1.4385692,0.0,0.80544746,58.404118,1.6897373,491.70987,-9.2305298
2643,2643,195.4194,10.313824,8.3166742,0.0,0,1.4247452,0.0,0.80821139,58.467926,1.6738963,491.64536,-9.2305927
2644,2644,195.4196,10.354593,8.3362112,0.0,0,1.4109212,0.0,0.81150907,58.475868,1.6610514,491.58087,-9.23032
2645,2645,195.4198,10.390436,8.3522596,0.0,0,1.3970972,0.0,0.8125239,58.637123,1.64662,491.51636,-9.2297287
2646,2646,195.42,10.421583,8.3628635,0.0,0,1.3832732,0.0,0.81504875,58.723419,1.6311448,491.45184,-9.2292128
2647,2647,195.4202,10.43983,8.3795862,0.0,0,1.3694493,0.0,0.81835771,58.63829,1.6169204,491.38733,-9.2290401
2648,2648,195.4204,10.453298,8.3970213,0.0,0,1.3556252,0.0,0.81943661,58.651611,1.602326,491.32285,-9.2285748
2649,2649,195.4206,10.481483,8.4084444,0.0,0,1.3418012,0.0,0.82163048,58.651237,1.5859433,491.25833,-9.2284803
2650,2650,195.4208,10.509506,8.4224882,0.0,0,1.3279773,0.0,0.82497895,58.59314,1.5698392,491.19382,-9.2291994
2651,2651,195.421,10.53861,8.4421358,0.0,0,1.3141533,0.0,0.8264755,58.678104,1.5549413,491.12933,-9.2293177
2652,2652,195.4212,10.57541,8.4565315,0.0,0,1.3003292,0.0,0.82858771,58.751675,1.5400195,491.06482,-9.2287893
2653,2653,195.4214,10.615936,8.4684896,0.0,0,1.2865052,0.0,0.83188921,58.763783,1.5250236,491.00031,-9.2293234
2654,2654,195.4216,10.65444,8.4883032,0.0,0,1.2726812,0.0,0.83368242,58.874828,1.5109267,490.93579,-9.229969
2655,2655,195.4218,10.693472,8.5016518,0.0,0,1.2588573,0.0,0.83540052,59.00322,1.4987416,490.87131,-9.2298717
2656,2656,195.422,10.728654,8.5088043,0.0,0,1.2450333,0.0,0.83826661,59.040359,1.4845085,490.80679,-9.2293653
2657,2657,195.4222,10.755021,8.5276375,0.0,0,1.2312093,0.0,0.84007663,59.112061,1.4683596,490.74228,-9.2294617
2658,2658,195.4224,10.77845,8.5430918,0.0,0,1.2176626,0.0,0.84159058,59.176254,1.4521091,490.67776,-9.2293463
2659,2659,195.4226,10.805331,8.5501375,0.0,0,1.2044512,0.0,0.84439695,59.14949,1.4381912,490.61328,-9.2289171
2660,2660,195.4228,10.841004,8.5701952,0.0,0,1.1913005,0.0,0.84683418,59.190189,1.4244107,490.54877,-9.2286739
2661,2661,195.423,10.87258,8.5889387,0.0,0,1.1781523,0.0,0.8486039,59.251369,1.4098731,490.48425,-9.2280502
2662,2662,195.4232,10.904591,8.5952101,0.0,0,1.1650044,0.0,0.85119629,59.270206,1.3958257,490.41977,-9.2282228
2663,2663,195.4234,10.947443,8.6139793,0.0,0,1.1518563,0.0,0.8538757,59.322304,1.3807669,490.35526,-9.2287178
2664,2664,195.4236,10.995521,8.6352825,0.0,0,1.1387082,0.0,0.85562634,59.420338,1.3660182,490.29074,-9.2287779
2665,2665,195.4238,11.038467,8.6405306,0.0,0,1.1255603,0.0,0.8579219,59.52079,1.3516077,490.22623,-9.2287855
2666,2666,195.424,11.070591,8.6571779,0.0,0,1.1124123,0.0,0.86087739,59.570053,1.3381706,490.16174,-9.2286444
2667,2667,195.4242,11.101896,8.6796837,0.0,0,1.0992643,0.0,0.86258394,59.638977,1.3225873,490.09723,-9.2284651
2668,2668,195.4244,11.128949,8.6840191,0.0,0,1.0861163,0.0,0.86449218,59.667564,1.3071626,490.03271,-9.2278414
2669,2669,195.4246,11.146778,8.6984882,0.0,0,1.0729682,0.0,0.86764574,59.589897,1.2947177,489.96823,-9.2272158
2670,2670,195.4248,11.171671,8.7215691,0.0,0,1.0598202,0.0,0.86943299,59.619968,1.2810389,489.90372,-9.2272873
2671,2671,195.425,11.207478,8.7267485,0.0,0,1.0466722,0.0,0.87107414,59.672302,1.2660244,489.8392,-9.2275105
2672,2672,195.4252,11.243709,8.7394314,0.0,0,1.0335243,0.0,0.87427044,59.652138,1.2517182,489.77469,-9.2279558
2673,2673,195.4254,11.290656,8.762043,0.0,0,1.0203762,0.0,0.87612265,59.815895,1.2358036,489.71021,-9.2282467
2674,2674,195.4256,11.340415,8.7671442,0.0,0,1.0072283,0.0,0.8773886,59.978214,1.2209786,489.64569,-9.2281961
2675,2675,195.4258,11.377933,8.7781687,0.0,0,0.99408025,0.0,0.88060534,59.973618,1.2094412,489.58118,-9.228508
2676,2676,195.426,11.41827,8.8010836,0.0,0,0.98093224,0.0,0.88273019,60.084522,1.1958083,489.51669,-9.2284813
2677,2677,195.4262,11.456562,8.8079453,0.0,0,0.96778423,0.0,0.88378215,60.223972,1.1816118,489.45218,-9.2280197
2678,2678,195.4264,11.481885,8.818531,0.0,0,0.95463622,0.0,0.88708758,60.170929,1.1677839,489.38766,-9.2283268
2679,2679,195.4266,11.505164,8.8430519,0.0,0,0.94148827,0.0,0.88977873,60.171795,1.1526769,489.32315,-9.2281752
2680,2680,195.4268,11.538947,8.8541698,0.0,0,0.92834032,0.0,0.89081866,60.28001,1.1390558,489.25867,-9.2281046
2681,2681,195.427,11.576324,8.8642693,0.0,0,0.91519231,0.0,0.89412838,60.256237,1.1248453,489.19415,-9.2279396
2682,2682,195.4272,11.615434,8.886939,0.0,0,0.9020443,0.0,0.89722514,60.27951,1.110297,489.12964,-9.2272377
2683,2683,195.4274,11.668245,8.8993626,0.0,0,0.88916039,0.0,0.89814967,60.469284,1.0970947,489.06512,-9.2272205
2684,2684,195.4276,11.717257,8.9077196,0.0,0,0.87659597,0.0,0.90114117,60.534821,1.0849923,489.00064,-9.2271891
2685,2685,195.4278,11.760045,8.926198,0.0,0,0.86408937,0.0,0.90424484,60.585335,1.0722568,488.93613,-9.2273703
2686,2686,195.428,11.798487,8.9384604,0.0,0,0.85158527,0.0,0.90485716,60.756699,1.0581131,488.87161,-9.2274818
2687,2687,195.4282,11.829764,8.9460497,0.0,0,0.83908123,0.0,0.90732098,60.764965,1.0434426,488.80713,-9.2274876
2688,2688,195.4284,11.854427,8.9621372,0.0,0,0.82657719,0.0,0.91042084,60.707737,1.0309782,488.74261,-9.227972
2689,2689,195.4286,11.875961,8.9769268,0.0,0,0.8140732,0.0,0.91120583,60.787205,1.0177246,488.81366,-9.2285423
2690,2690,195.4288,11.906319,8.9867382,0.0,0,0.80156928,0.0,0.91371852,60.787888,1.0016057,488.88467,-9.2283192
2691,2691,195.429,11.947401,9.0011034,0.0,0,0.78906524,0.0,0.91706294,60.77029,0.98571944,488.95572,-9.2281542
2692,2692,195.4292,12.003087,9.0168858,0.0,0,0.77656126,0.0,0.91798925,60.949024,0.97183967,489.02673,-9.2286024
2693,2693,195.4294,12.056026,9.0273361,0.0,0,0.76405728,0.0,0.9201743,61.095634,0.95927823,489.09778,-9.2286797
2694,2694,195.4296,12.10696,9.0397768,0.0,0,0.75155324,0.0,0.92367971,61.172283,0.94639301,489.16879,-9.2279263
2695,2695,195.4298,12.155212,9.0584164,0.0,0,0.73904926,0.0,0.92507946,61.334248,0.93466783,489.23984,-9.227438
2696,2696,195.43,12.191037,9.0713558,0.0,0,0.72654527,0.0,0.92720962,61.393734,0.92145205,489.31088,-9.2274179
2697,2697,195.4302,12.21972,9.0822163,0.0,0,0.71404123,0.0,0.93086332,61.320969,0.90665925,489.3819,-9.2272005
2698,2698,195.4304,12.24136,9.1026745,0.0,0,0.70153725,0.0,0.93276173,61.320557,0.89412439,489.45294,-9.2271833
2699,2699,195.4306,12.269657,9.1166534,0.0,0,0.68903327,0.0,0.93458205,61.323135,0.88139302,489.52396,-9.2272139
2700,2700,195.4308,12.302234,9.1228561,0.0,0,0.67652929,0.0,0.93766087,61.309834,0.86867285,489.595,-9.2272682
2701,2701,195.431,12.338965,9.1405144,0.0,0,0.66402531,0.0,0.93958348,61.383957,0.85546941,489.66602,-9.2285433
2702,2702,195.4312,12.388541,9.154479,0.0,0,0.65152127,0.0,0.94101411,61.512035,0.84204733,489.73706,-9.229332
2703,2703,195.4314,12.443554,9.1581583,0.0,0,0.63901722,0.0,0.94359678,61.621399,0.82910693,489.80811,-9.2288208
2704,2704,195.4316,12.499149,9.1752863,0.0,0,0.62651324,0.0,0.94576752,61.757568,0.8172062,489.87912,-9.2287121
2705,2705,195.4318,12.548179,9.1925488,0.0,0,0.61400926,0.0,0.94716269,61.917561,0.80428982,489.95016,-9.2286997
2706,2706,195.432,12.583592,9.1956844,0.0,0,0.60150528,0.0,0.94955444,61.953342,0.78786272,490.02118,-9.2287416
2707,2707,195.4322,12.612766,9.2119741,0.0,0,0.58900124,0.0,0.95224893,61.918129,0.77355576,490.09222,-9.2286139
2708,2708,195.4324,12.636759,9.232523,0.0,0,0.57674497,0.0,0.95398349,61.923573,0.76437992,490.16324,-9.2282553
2709,2709,195.4326,12.659242,9.2363253,0.0,0,0.56478834,0.0,0.95636785,61.899361,0.75266236,490.23428,-9.2283487
2710,2710,195.4328,12.695916,9.2516155,0.0,0,0.55288589,0.0,0.95945472,61.871307,0.73706722,490.3053,-9.2279577
2711,2711,195.433,12.743726,9.2733946,0.0,0,0.54098582,0.0,0.96116281,61.994648,0.72378826,490.37634,-9.2275038
2712,2712,195.4332,12.796047,9.2765026,0.0,0,0.52908581,0.0,0.96302599,62.142845,0.71001405,490.44739,-9.2277946
2713,2713,195.4334,12.855302,9.2892284,0.0,0,0.51718581,0.0,0.96625149,62.2346,0.69720894,490.5184,-9.2271595
2714,2714,195.4336,12.913166,9.3116379,0.0,0,0.5052858,0.0,0.96802443,62.38274,0.68408096,490.58945,-9.2267962
2715,2715,195.4338,12.961661,9.3149328,0.0,0,0.49338579,0.0,0.96941036,62.520622,0.67031634,490.66046,-9.2272367
2716,2716,195.434,13.001029,9.3255777,0.0,0,0.48148578,0.0,0.9726826,62.52721,0.65745276,490.73151,-9.2273893
2717,2717,195.4342,13.029435,9.3472738,0.0,0,0.46958581,0.0,0.97470576,62.546745,0.64557248,490.80252,-9.2273903
2718,2718,195.4344,13.058247,9.3523169,0.0,0,0.4576858,0.0,0.97594005,62.614792,0.6328941,490.87357,-9.2274027
2719,2719,195.4346,13.089859,9.3630781,0.0,0,0.44578579,0.0,0.97944611,62.540443,0.6190933,490.94458,-9.2273378
2720,2720,195.4348,13.132123,9.3857708,0.0,0,0.43388578,0.0,0.98177075,62.605213,0.60615426,491.01563,-9.2272224
2721,2721,195.435,13.186704,9.3926029,0.0,0,0.42198581,0.0,0.98261464,62.810326,0.59517902,491.08667,-9.2272673
2722,2722,195.4352,13.245691,9.4005365,0.0,0,0.4100858,0.0,0.98601955,62.83337,0.58317286,491.15768,-9.2276945
2723,2723,195.4354,13.304279,9.4214945,0.0,0,0.39818579,0.0,0.98870051,62.942924,0.57049584,491.22873,-9.2281904
2724,2724,195.4356,13.356611,9.4298334,0.0,0,0.38628578,0.0,0.98918039,63.17424,0.55750817,491.29974,-9.2281027