File: clean data/testID_0130.csv
level_0,index,Time(sec),Force(kN),Jaw(mm),PowAngle(deg),Power(W),Pram,PTemp,Strain,Stress(MPa),Stroke(mm),TC1(C),wedge(mm)
1775,1775,145.3443,2.9365764,0.038526177,0.0,0,8.975173,0.0,0.0021801852,37.248634,10.018098,318.27197,-9.3255653
1777,1777,145.3447,5.0856004,0.050045338,0.0,0,8.9166451,0.0,0.0033481831,59.873966,9.9416466,318.56363,-9.3258915
1779,1779,145.3451,7.5787082,0.10589911,0.0,0,8.8581161,0.0,0.0066797454,94.233932,9.8859587,318.85529,-9.3250465
1781,1781,145.3455,8.2715197,0.15938286,0.0,0,8.7995882,0.0,0.010010355,103.14786,9.8239794,319.14694,-9.32302
1783,1783,145.3459,8.8714743,0.28088275,0.0,0,8.7416477,0.0,0.01805019,110.9613,9.7375755,319.4386,-9.3212385
1785,1785,145.3463,8.9913321,0.40289667,0.0,0,8.6858435,0.0,0.026477946,110.38654,9.6345167,319.73026,-9.3210335
1787,1787,145.3467,9.8813496,0.49615678,0.0,0,8.6301794,0.0,0.032775111,121.35365,9.5254498,320.02191,-9.3211174
1789,1789,145.3471,10.068624,0.60594964,0.0,0,8.5745163,0.0,0.040834337,122.1846,9.4254131,320.31357,-9.3222342
1791,1791,145.3475,10.489769,0.64791709,0.0,0,8.5188513,0.0,0.043649144,128.22766,9.3335266,320.60522,-9.3208551
1793,1793,145.3479,9.9100246,0.72972637,0.0,0,8.4631872,0.0,0.049350038,120.1144,9.2506275,320.89688,-9.3208475
1795,1795,145.3483,10.679996,0.78538138,0.0,0,8.4075241,0.0,0.053721145,127.89037,9.1788187,321.18854,-9.3207226
1797,1797,145.3487,10.786304,0.82186377,0.0,0,8.3518591,0.0,0.055714086,130.00055,9.1115112,321.48019,-9.3192387
1799,1799,145.3491,10.877665,0.91598707,0.0,0,8.296196,0.0,0.062621474,130.00175,9.0422363,321.77185,-9.3207006
1801,1801,145.3495,10.632555,0.99484199,0.0,0,8.2405319,0.0,0.068078041,126.70113,8.9682846,322.06351,-9.3207674
1803,1803,145.3499,10.995929,1.0806748,0.0,0,8.1848679,0.0,0.073964752,129.35312,8.8926716,322.35516,-9.3204956
1805,1805,145.3503,11.163202,1.1516597,0.0,0,8.1292038,0.0,0.079727776,131.40581,8.8142681,322.64682,-9.31989
1807,1807,145.3507,11.172338,1.222701,0.0,0,8.0735397,0.0,0.084201239,130.50876,8.7359953,322.93848,-9.3189297
1809,1809,145.3511,11.115726,1.3020777,0.0,0,8.0196571,0.0,0.090258032,129.61249,8.6593704,323.23013,-9.3189411
1811,1811,145.3515,11.169986,1.3532619,0.0,0,7.9666901,0.0,0.094534867,128.88109,8.5938253,323.52176,-9.3204031
1813,1813,145.3519,11.600803,1.405676,0.0,0,7.9137306,0.0,0.097614683,133.81245,8.5288916,323.81342,-9.3206367
1815,1815,145.3523,11.396439,1.4670904,0.0,0,7.8607702,0.0,0.10259213,131.10779,8.4699059,324.10507,-9.3190393
1817,1817,145.3527,11.495864,1.5184113,0.0,0,7.8078103,0.0,0.10645183,131.54904,8.4156094,324.39673,-9.3193235
1819,1819,145.3531,11.460481,1.5844129,0.0,0,7.7548499,0.0,0.11075725,130.62114,8.3576059,324.68839,-9.3184004
1821,1821,145.3535,11.742359,1.6319503,0.0,0,7.70189,0.0,0.11509512,132.89999,8.3000603,324.98004,-9.3188133
1823,1823,145.3539,11.721502,1.6898466,0.0,0,7.6489296,0.0,0.11889778,132.718,8.2397337,325.2717,-9.3201084
1825,1825,145.3543,11.669325,1.768905,0.0,0,7.5959702,0.0,0.1246791,131.05098,8.1763783,325.56335,-9.3210516
1827,1827,145.3547,11.768257,1.8095371,0.0,0,7.5430098,0.0,0.12854333,131.62569,8.115921,325.85498,-9.3203669
1829,1829,145.3551,11.879541,1.8622262,0.0,0,7.4900503,0.0,0.13188437,132.46182,8.0632296,326.14664,-9.3196936
1831,1831,145.3555,11.924261,1.9217284,0.0,0,7.4370899,0.0,0.13668658,132.50072,8.007309,326.43829,-9.3182764
1833,1833,145.3559,11.929733,1.9582777,0.0,0,7.3846612,0.0,0.13978449,131.9964,7.9573722,326.72995,-9.3179998
1835,1835,145.3563,12.001417,2.0080431,0.0,0,7.3341675,0.0,0.14297813,132.41188,7.9038081,327.02161,-9.3186321
1837,1837,145.3567,12.092985,2.050993,0.0,0,7.2837992,0.0,0.14688598,132.77065,7.8593059,327.31326,-9.320508
1839,1839,145.3571,12.157652,2.1012108,0.0,0,7.2334309,0.0,0.15051876,133.32915,7.8109112,327.60492,-9.320591
1841,1841,145.3575,12.089854,2.1609912,0.0,0,7.1830626,0.0,0.15491618,131.88182,7.7596779,327.89658,-9.3206367
1843,1843,145.3579,12.206404,2.2019191,0.0,0,7.1326947,0.0,0.15882431,132.47839,7.7118988,328.18823,-9.3180685
1845,1845,145.3583,12.29052,2.2505884,0.0,0,7.0823264,0.0,0.16204807,133.06625,7.6595922,328.47986,-9.3173714
1847,1847,145.3587,12.345106,2.3027761,0.0,0,7.0319586,0.0,0.16607435,133.05235,7.6116447,328.77151,-9.3196201
1849,1849,145.3591,12.306357,2.3402262,0.0,0,6.9815903,0.0,0.16962193,132.29147,7.5640779,329.06317,-9.3211803
1851,1851,145.3595,12.373286,2.3901439,0.0,0,6.9312229,0.0,0.17285593,132.41327,7.5226908,329.35483,-9.3211765
1853,1853,145.3599,12.525208,2.4289103,0.0,0,6.8808546,0.0,0.17633761,133.66365,7.4758658,329.64648,-9.3208599
1855,1855,145.3603,12.532434,2.4712317,0.0,0,6.8304873,0.0,0.18000229,133.36354,7.4314127,329.68369,-9.3192587
1857,1857,145.3607,12.525458,2.5279591,0.0,0,6.7801185,0.0,0.18370195,132.69324,7.3857427,329.63614,-9.3177528
1859,1859,145.3611,12.56953,2.5632,0.0,0,6.7313623,0.0,0.18725538,132.63315,7.3372107,329.58862,-9.3181229
1861,1861,145.3615,12.701716,2.6082163,0.0,0,6.6834369,0.0,0.190669,133.49463,7.2907834,329.54108,-9.3195667
1863,1863,145.3619,12.715573,2.6626058,0.0,0,6.6355171,0.0,0.19463171,133.20995,7.2474351,329.49353,-9.3201971
1865,1865,145.3623,12.737119,2.7000918,0.0,0,6.5875969,0.0,0.198478,132.94083,7.2018981,329.44598,-9.3210945
1867,1867,145.3627,12.771029,2.7462747,0.0,0,6.5396771,0.0,0.20176448,132.85292,7.1541061,329.39844,-9.3203592
1869,1869,145.3631,12.886406,2.7933488,0.0,0,6.4917574,0.0,0.2054635,133.48933,7.1058965,329.35089,-9.3184013
1871,1871,145.3635,12.94571,2.8311465,0.0,0,6.4438376,0.0,0.20917955,133.69283,7.0625639,329.30334,-9.3179884
1873,1873,145.3639,12.978728,2.8792658,0.0,0,6.3959169,0.0,0.21245991,133.43526,7.0190587,329.2558,-9.3187265
1875,1875,145.3643,13.057829,2.9293945,0.0,0,6.3479972,0.0,0.21685466,133.78397,6.9714799,329.20825,-9.3196611
1877,1877,145.3647,13.118194,2.971266,0.0,0,6.3000774,0.0,0.22057743,133.92188,6.9248276,329.16071,-9.320837
1879,1879,145.3651,13.173013,3.0183325,0.0,0,6.2521577,0.0,0.22401112,133.99225,6.8803644,329.11316,-9.3192692
1881,1881,145.3655,13.204391,3.0656762,0.0,0,6.2042375,0.0,0.22854581,133.7162,6.8312025,329.06561,-9.3195362
1883,1883,145.3659,13.282349,3.1088753,0.0,0,6.1567979,0.0,0.23198183,133.98738,6.7847905,329.01807,-9.3194704
1885,1885,145.3663,13.343066,3.1569164,0.0,0,6.1111078,0.0,0.23558325,134.14879,6.7369065,328.97055,-9.3194656
1887,1887,145.3667,13.389016,3.202234,0.0,0,6.0655317,0.0,0.24014395,134.03873,6.6907959,328.923,-9.3196583
1889,1889,145.3671,13.422834,3.2494063,0.0,0,6.0199556,0.0,0.24353102,133.95062,6.6424775,328.87546,-9.320013
1891,1891,145.3675,13.513758,3.2978354,0.0,0,5.9743791,0.0,0.24770075,134.20753,6.5970612,328.82791,-9.3198471
1893,1893,145.3679,13.609798,3.3412583,0.0,0,5.9288034,0.0,0.25209495,134.59721,6.5513825,328.78036,-9.3200912
1895,1895,145.3683,13.668984,3.3917823,0.0,0,5.8832278,0.0,0.25555652,134.6805,6.5020928,328.73282,-9.3195744
1897,1897,145.3687,13.69125,3.4367802,0.0,0,5.8376513,0.0,0.25991809,134.43488,6.4551153,328.68527,-9.3186398
1899,1899,145.3691,13.766305,3.4815643,0.0,0,5.7920747,0.0,0.26403987,134.50107,6.4046965,328.63773,-9.3185987
1901,1901,145.3695,13.855827,3.5406196,0.0,0,5.7464995,0.0,0.26819983,134.79202,6.35849,328.59018,-9.3194818
1903,1903,145.3699,13.924342,3.5857217,0.0,0,5.7009234,0.0,0.27299371,134.90097,6.3071489,328.54263,-9.3196964
1905,1905,145.3703,13.973886,3.6332347,0.0,0,5.6553473,0.0,0.27699006,134.84782,6.2565455,328.27435,-9.319396
1907,1907,145.3707,14.012798,3.691453,0.0,0,5.6097713,0.0,0.28152949,134.56447,6.2121096,327.93256,-9.3195505
1909,1909,145.3711,14.097188,3.7289989,0.0,0,5.5656543,0.0,0.28587288,134.81956,6.1610279,327.59076,-9.3191986
1911,1911,145.3715,14.184023,3.7742476,0.0,0,5.5222898,0.0,0.28931051,135.19791,6.1162987,327.24896,-9.3194084
1913,1913,145.3719,14.255639,3.8300393,0.0,0,5.4789295,0.0,0.29405248,135.21727,6.0663776,326.90717,-9.3208132
1915,1915,145.3723,14.296963,3.8688626,0.0,0,5.4355693,0.0,0.29832852,135.00302,6.0153565,326.56534,-9.3209238
1917,1917,145.3727,14.358271,3.9230163,0.0,0,5.3922095,0.0,0.30232263,135.00662,5.9686532,326.22354,-9.3203287
1919,1919,145.3731,14.412633,3.9745502,0.0,0,5.3488493,0.0,0.30742481,134.87364,5.9192204,325.88174,-9.3187551
1921,1921,145.3735,14.511249,4.0144091,0.0,0,5.3054895,0.0,0.31134486,135.20888,5.872787,325.53995,-9.3174696
1923,1923,145.3739,14.573806,4.0660038,0.0,0,5.2621293,0.0,0.31530929,135.37202,5.8257236,325.19812,-9.3183289
1925,1925,145.3743,14.630717,4.1108756,0.0,0,5.2187696,0.0,0.32020491,135.15413,5.7775507,324.85632,-9.3202295
1927,1927,145.3747,14.680517,4.1558914,0.0,0,5.1754098,0.0,0.32401964,135.11476,5.7305365,324.51453,-9.3211069
1929,1929,145.3751,14.758554,4.2080598,0.0,0,5.1320496,0.0,0.32842651,135.2294,5.6813407,324.17273,-9.3202295
1931,1931,145.3755,14.856169,4.2514462,0.0,0,5.0886893,0.0,0.33339572,135.44635,5.636601,323.8309,-9.3180408
1933,1933,145.3759,14.937092,4.300436,0.0,0,5.045764,0.0,0.33721888,135.67644,5.5838537,323.48911,-9.3179731
1935,1935,145.3763,14.979838,4.3481007,0.0,0,5.0044203,0.0,0.34167698,135.48621,5.5397024,323.14731,-9.318737
1937,1937,145.3767,15.038935,4.3895373,0.0,0,4.9631801,0.0,0.3462944,135.38011,5.491797,322.80551,-9.3202486
1939,1939,145.3771,15.110101,4.4413075,0.0,0,4.9219403,0.0,0.35024795,135.50801,5.4439397,322.46368,-9.3199806
1941,1941,145.3775,15.207,4.4836416,0.0,0,4.8807001,0.0,0.35470209,135.70676,5.3995786,322.12189,-9.3184719
1943,1943,145.3779,15.271152,4.5241475,0.0,0,4.8394604,0.0,0.35894892,135.7319,5.3530617,321.78009,-9.3190565
1945,1945,145.3783,15.318655,4.5796266,0.0,0,4.7982202,0.0,0.36319053,135.58255,5.3066807,321.43829,-9.3180218
1947,1947,145.3787,15.395814,4.6185904,0.0,0,4.7569804,0.0,0.36788997,135.62126,5.2616005,321.09647,-9.3187304
1949,1949,145.3791,15.481507,4.6626763,0.0,0,4.7157402,0.0,0.37190261,135.81854,5.21561,320.75467,-9.3189898
1951,1951,145.3795,15.590233,4.716598,0.0,0,4.6745005,0.0,0.3765246,136.08101,5.168735,320.41287,-9.3189249
1953,1953,145.3799,15.656739,4.7529383,0.0,0,4.6332603,0.0,0.38105524,136.15408,5.1215577,320.07108,-9.3181849
1955,1955,145.3803,15.708663,4.7987413,0.0,0,4.59202,0.0,0.38490841,136.07179,5.0748868,319.875,-9.3181057
1957,1957,145.3807,15.791756,4.8504114,0.0,0,4.5507803,0.0,0.38990018,136.0296,5.0318971,319.72751,-9.3187017
1959,1959,145.3811,15.884315,4.887217,0.0,0,4.5108619,0.0,0.39427048,136.26624,4.9875627,319.58002,-9.3192616
1961,1961,145.3815,15.949751,4.9345765,0.0,0,4.4716258,0.0,0.39816037,136.34496,4.9460993,319.4325,-9.3202896
1963,1963,145.3819,16.023293,4.9819398,0.0,0,4.432394,0.0,0.4032959,136.22403,4.9017625,319.285,-9.3201227
1965,1965,145.3823,16.074306,5.0189948,0.0,0,4.3931618,0.0,0.40724438,136.08531,4.8581653,319.13748,-9.3186016
1967,1967,145.3827,16.146248,5.0641232,0.0,0,4.35393,0.0,0.411037,136.2252,4.8165236,318.98999,-9.3171959
1969,1969,145.3831,16.230902,5.1060333,0.0,0,4.3146982,0.0,0.41613129,136.30235,4.7711573,318.8425,-9.3183765
1971,1971,145.3835,16.327061,5.1456113,0.0,0,4.275466,0.0,0.41977492,136.54654,4.729991,318.69498,-9.3183403
1973,1973,145.3839,16.421932,5.1899219,0.0,0,4.2362337,0.0,0.42383209,136.75549,4.6887608,318.54749,-9.3187046
1975,1975,145.3843,16.489908,5.2295513,0.0,0,4.1970015,0.0,0.42880356,136.68405,4.6460838,318.39996,-9.3185987
1977,1977,145.3847,16.56772,5.2726169,0.0,0,4.1577697,0.0,0.43242481,136.79187,4.6042929,318.25247,-9.3180103
1979,1979,145.3851,16.648575,5.3179445,0.0,0,4.1185379,0.0,0.43715239,136.89433,4.5638924,318.10498,-9.3180285
1981,1981,145.3855,16.74917,5.3546653,0.0,0,4.0793056,0.0,0.44177303,136.96352,4.5188289,317.95746,-9.3183002
1983,1983,145.3859,16.832958,5.4004736,0.0,0,4.0404677,0.0,0.44535896,137.21306,4.4792171,317.80997,-9.3183651
1985,1985,145.3863,16.887287,5.4378042,0.0,0,4.0030622,0.0,0.44988668,137.03511,4.4391599,317.66245,-9.317625
1987,1987,145.3867,16.952427,5.4720736,0.0,0,3.9657497,0.0,0.45386368,137.05914,4.3991385,317.51495,-9.3174076
1989,1989,145.3871,17.06176,5.5217109,0.0,0,3.9284377,0.0,0.45782635,137.28058,4.3575044,317.36746,-9.3181467
1991,1991,145.3875,17.173218,5.5541797,0.0,0,3.8911257,0.0,0.46249992,137.55717,4.3161082,317.21994,-9.3194399
1993,1993,145.3879,17.260605,5.5915627,0.0,0,3.8538139,0.0,0.46610793,137.81979,4.2755537,317.07245,-9.3185892
1995,1995,145.3883,17.332268,5.6409602,0.0,0,3.8165019,0.0,0.4706918,137.74197,4.236692,316.92493,-9.3182316
1997,1997,145.3887,17.417973,5.6714697,0.0,0,3.7791896,0.0,0.4751468,137.78439,4.1941323,316.77744,-9.3167267
1999,1999,145.3891,17.514107,5.7128592,0.0,0,3.7418776,0.0,0.47873184,138.11023,4.1552911,316.62994,-9.3170805
2001,2001,145.3895,17.62475,5.7594099,0.0,0,3.7045658,0.0,0.4836511,138.30444,4.1151376,316.48242,-9.3176241
2003,2003,145.3899,17.703121,5.7886739,0.0,0,3.6672537,0.0,0.48774502,138.2944,4.0764637,316.33493,-9.3166771
2005,2005,145.3903,17.773241,5.8319354,0.0,0,3.6299417,0.0,0.49134678,138.35765,4.038588,316.43008,-9.3182096
2007,2007,145.3907,17.861717,5.8728857,0.0,0,3.5926297,0.0,0.49654269,138.3192,3.998256,316.60611,-9.3185463
2009,2009,145.3911,17.958263,5.9027543,0.0,0,3.5565133,0.0,0.50005162,138.63739,3.9580803,316.78214,-9.3179827
2011,2011,145.3915,18.084707,5.9421644,0.0,0,3.5210135,0.0,0.50345212,139.0856,3.9235082,316.95813,-9.3174591
2013,2013,145.3919,18.176605,5.9786077,0.0,0,3.4855173,0.0,0.50858545,139.10388,3.8860271,317.13416,-9.3174572
2015,2015,145.3923,18.228104,6.0151753,0.0,0,3.4500215,0.0,0.51211631,139.04237,3.8478177,317.31018,-9.3166037
2017,2017,145.3927,18.32593,6.0598254,0.0,0,3.4145255,0.0,0.5165953,139.11292,3.8098278,317.48618,-9.3173437
2019,2019,145.3931,18.441845,6.0945368,0.0,0,3.3790293,0.0,0.52165657,139.25262,3.7743969,317.6622,-9.3180056
2021,2021,145.3935,18.548573,6.1337237,0.0,0,3.3435335,0.0,0.52500361,139.59312,3.7365685,317.83823,-9.3179693
2023,2023,145.3939,18.619188,6.1684155,0.0,0,3.3080375,0.0,0.52919424,139.61565,3.7021546,318.01422,-9.3174086
2025,2025,145.3943,18.698027,6.1967139,0.0,0,3.2725413,0.0,0.53334504,139.67326,3.6635406,318.19025,-9.3170424
2027,2027,145.3947,18.808002,6.2402616,0.0,0,3.2370453,0.0,0.53675121,139.92072,3.6250792,318.36624,-9.3170462
2029,2029,145.3951,18.930187,6.273581,0.0,0,3.2015493,0.0,0.54138559,140.2108,3.5902259,318.54227,-9.3177652
2031,2031,145.3955,19.0469,6.3082714,0.0,0,3.1660533,0.0,0.54550672,140.50046,3.5547323,318.71829,-9.3167372
2033,2033,145.3959,19.130209,6.3551459,0.0,0,3.1309118,0.0,0.54976511,140.55022,3.5174711,318.89429,-9.3166504
2035,2035,145.3963,19.226097,6.3811569,0.0,0,3.0970592,0.0,0.55431032,140.58142,3.4821253,319.07031,-9.3165751
2037,2037,145.3967,19.332699,6.4147229,0.0,0,3.0632911,0.0,0.55761766,140.87532,3.4482892,319.24634,-9.316432
2039,2039,145.3971,19.476866,6.4612641,0.0,0,3.0295231,0.0,0.56227362,141.1684,3.4098787,319.42233,-9.3171768
2041,2041,145.3975,19.584211,6.4898558,0.0,0,2.9957552,0.0,0.56704319,141.38615,3.3714049,319.59836,-9.3164663
2043,2043,145.3979,19.66609,6.5288053,0.0,0,2.9619873,0.0,0.5706169,141.44766,3.336663,319.77438,-9.3155975
2045,2045,145.3983,19.770645,6.5687776,0.0,0,2.9282191,0.0,0.57543802,141.53159,3.3034775,319.95038,-9.3162012
2047,2047,145.3987,19.895267,6.5926666,0.0,0,2.8944509,0.0,0.57911187,141.89417,3.2657304,320.1264,-9.316267
2049,2049,145.3991,20.031321,6.6314559,0.0,0,2.860683,0.0,0.5825994,142.32631,3.2307551,320.30243,-9.3158388
2051,2051,145.3995,20.157413,6.6692457,0.0,0,2.826915,0.0,0.58791411,142.52515,3.1937141,320.47842,-9.3164425
2053,2053,145.3999,20.253796,6.701797,0.0,0,2.7931471,0.0,0.59184164,142.60857,3.1582773,320.65445,-9.3169546
2055,2055,145.4003,20.366182,6.7456889,0.0,0,2.7593791,0.0,0.59622639,142.75963,3.1232431,320.68283,-9.3161545
2057,2057,145.4007,20.49337,6.7781978,0.0,0,2.7256112,0.0,0.60141832,142.94415,3.0881705,320.66208,-9.3156567
2059,2059,145.4011,20.63772,6.8112774,0.0,0,2.6929281,0.0,0.60483301,143.43547,3.0506155,320.6413,-9.3150301
2061,2061,145.4015,20.768793,6.8480916,0.0,0,2.6608045,0.0,0.60899001,143.73178,3.0139117,320.62054,-9.3151121
2063,2063,145.4019,20.857807,6.877316,0.0,0,2.6286843,0.0,0.61369896,143.73344,2.9800663,320.59976,-9.3167858
2065,2065,145.4023,20.981833,6.9153333,0.0,0,2.5965643,0.0,0.61715353,144.0528,2.9481692,320.57901,-9.3170795
2067,2067,145.4027,21.12446,6.9499173,0.0,0,2.5644443,0.0,0.62180746,144.29131,2.9155324,320.55823,-9.3158855
2069,2069,145.4031,21.260719,6.9803257,0.0,0,2.5323241,0.0,0.62652564,144.59418,2.8779545,320.53748,-9.3157034
2071,2071,145.4035,21.4027,7.0244513,0.0,0,2.5002043,0.0,0.63039714,145.00893,2.8412821,320.51669,-9.3159122
2073,2073,145.4039,21.51034,7.054388,0.0,0,2.4680843,0.0,0.63529825,145.00713,2.8120754,320.49591,-9.3157825
2075,2075,145.4043,21.640383,7.0831323,0.0,0,2.4359643,0.0,0.63904554,145.34402,2.7738609,320.47516,-9.3155537
2077,2077,145.4047,21.785601,7.1267381,0.0,0,2.4038444,0.0,0.64315945,145.69315,2.7407413,320.45438,-9.3159714
2079,2079,145.4051,21.94631,7.1517577,0.0,0,2.3717244,0.0,0.6480152,146.02554,2.7077017,320.43362,-9.3149796
2081,2081,145.4055,22.069506,7.1856017,0.0,0,2.3396041,0.0,0.65158129,146.38214,2.6718812,320.41284,-9.3149481
2083,2083,145.4059,22.193684,7.2280231,0.0,0,2.307806,0.0,0.65642881,146.45671,2.6368465,320.39209,-9.3150425
2085,2085,145.4063,22.326544,7.2512946,0.0,0,2.2771773,0.0,0.66094404,146.65717,2.6042659,320.37131,-9.3154259
2087,2087,145.4067,22.48542,7.2866144,0.0,0,2.2466252,0.0,0.66408396,147.18777,2.5723052,320.35056,-9.3159857
2089,2089,145.4071,22.648842,7.3257747,0.0,0,2.2160735,0.0,0.66940665,147.53683,2.5367129,320.32977,-9.3147926
2091,2091,145.4075,22.787416,7.3505316,0.0,0,2.1855214,0.0,0.67361999,147.84756,2.5036011,320.30899,-9.3151579
2093,2093,145.4079,22.927174,7.3883305,0.0,0,2.1549692,0.0,0.67722964,148.18964,2.4719121,320.28824,-9.3147411
2095,2095,145.4083,23.07185,7.4221401,0.0,0,2.1244173,0.0,0.68264979,148.32849,2.4373267,320.26746,-9.3147249
2097,2097,145.4087,23.224895,7.4490366,0.0,0,2.0938654,0.0,0.6862753,148.78792,2.4052088,320.2467,-9.3150082
2099,2099,145.4091,23.388767,7.4868932,0.0,0,2.0633135,0.0,0.69026858,149.21124,2.3700123,320.22592,-9.3143988
2101,2101,145.4095,23.538065,7.5143042,0.0,0,2.0327616,0.0,0.69543755,149.38232,2.3410528,320.20517,-9.3141422
2103,2103,145.4099,23.660284,7.5448871,0.0,0,2.0022092,0.0,0.69866073,149.73988,2.3087399,320.18439,-9.3146553
2105,2105,145.4103,23.805126,7.5801783,0.0,0,1.9716572,0.0,0.70293123,149.99347,2.2759099,320.04257,-9.314723
2107,2107,145.4107,23.964439,7.6055527,0.0,0,1.9411051,0.0,0.70786202,150.26057,2.2472112,319.86044,-9.3147936
2109,2109,145.4111,24.158083,7.6405668,0.0,0,1.9115326,0.0,0.71101326,150.93781,2.2133539,319.67831,-9.3139172
2111,2111,145.4115,24.308178,7.6729798,0.0,0,1.8824656,0.0,0.71592361,151.19299,2.180341,319.49619,-9.3137379
2113,2113,145.4119,24.438589,7.7006378,0.0,0,1.8534015,0.0,0.72068828,151.30415,2.1522207,319.31406,-9.3134346
2115,2115,145.4123,24.607737,7.740797,0.0,0,1.8243376,0.0,0.72443557,151.71846,2.1208222,319.13193,-9.3131571
2117,2117,145.4127,24.782814,7.7645106,0.0,0,1.7952735,0.0,0.72916019,152.10365,2.0874875,318.9498,-9.3136806
2119,2119,145.4131,24.975935,7.7892036,0.0,0,1.7662096,0.0,0.73246688,152.76146,2.0553241,318.76767,-9.3133698
2121,2121,145.4135,25.120066,7.8295064,0.0,0,1.7371455,0.0,0.73661005,153.02589,2.0258069,318.58554,-9.3131104
2123,2123,145.4139,25.260908,7.8530407,0.0,0,1.7080816,0.0,0.74170148,153.09694,1.9933426,318.40341,-9.313117
2125,2125,145.4143,25.420387,7.8848596,0.0,0,1.6790177,0.0,0.7452718,153.50734,1.9641764,318.22125,-9.312994
2127,2127,145.4147,25.607372,7.9246616,0.0,0,1.6499536,0.0,0.75030023,153.8054,1.9343445,318.03912,-9.3137598
2129,2129,145.4151,25.793438,7.9436989,0.0,0,1.6208895,0.0,0.75464994,154.33063,1.9036211,317.85699,-9.3137617
2131,2131,145.4155,25.952667,7.9752846,0.0,0,1.5918256,0.0,0.75770098,154.80193,1.8719603,317.67487,-9.3120632
2133,2133,145.4159,26.107731,8.009779,0.0,0,1.5630522,0.0,0.76291937,154.87935,1.84253,317.49274,-9.3119183
2135,2135,145.4163,26.28973,8.0286102,0.0,0,1.5353347,0.0,0.76654398,155.38362,1.8143791,317.31061,-9.3129768
2137,2137,145.4167,26.488359,8.0623751,0.0,0,1.5076866,0.0,0.76987725,156.08762,1.7835613,317.12848,-9.3129463
2139,2139,145.4171,26.695238,8.0931644,0.0,0,1.4800386,0.0,0.775576,156.35545,1.754887,316.94635,-9.3130865
2141,2141,145.4175,26.857634,8.1209965,0.0,0,1.4523906,0.0,0.77946246,156.77887,1.7241091,316.76422,-9.3120623
2143,2143,145.4179,27.012663,8.1564474,0.0,0,1.4247426,0.0,0.78357804,157.03526,1.6981667,316.58209,-9.3124933
2145,2145,145.4183,27.212408,8.1804562,0.0,0,1.3970947,0.0,0.78879756,157.3351,1.6726625,316.39996,-9.3119516
2147,2147,145.4187,27.421637,8.2063847,0.0,0,1.3694466,0.0,0.79135472,158.14178,1.641131,316.21783,-9.3123798
2149,2149,145.4191,27.621494,8.2351236,0.0,0,1.3417987,0.0,0.79533148,158.6951,1.6121771,316.03568,-9.3115911
2151,2151,145.4195,27.799551,8.2580376,0.0,0,1.3141507,0.0,0.80028683,158.89014,1.5831584,315.85355,-9.3119297
2153,2153,145.4199,27.981121,8.2952003,0.0,0,1.2865027,0.0,0.80393004,159.36003,1.5529813,315.67142,-9.3120518
2155,2155,145.4203,28.194059,8.3254137,0.0,0,1.2588546,0.0,0.80931318,159.69189,1.527364,315.31543,-9.3117113
2157,2157,145.4207,28.399477,8.3473892,0.0,0,1.2312068,0.0,0.81357974,160.16832,1.4983314,314.90152,-9.3109522
2159,2159,145.4211,28.608166,8.3822546,0.0,0,1.2044488,0.0,0.81686234,160.82855,1.4668367,314.48761,-9.3111753
2161,2161,145.4215,28.791925,8.4022617,0.0,0,1.1781499,0.0,0.82135129,161.11496,1.4381642,314.0737,-9.310833
2163,2163,145.4219,28.97884,8.4250135,0.0,0,1.1518539,0.0,0.82463443,161.62927,1.4105554,313.65979,-9.3119783
2165,2165,145.4223,29.183359,8.4611273,0.0,0,1.1255579,0.0,0.82869732,162.1244,1.3822823,313.24588,-9.3116064
2167,2167,145.4227,29.401623,8.4816084,0.0,0,1.0992619,0.0,0.83383405,162.47903,1.3544908,312.83197,-9.3101749
2169,2169,145.4231,29.625732,8.5111885,0.0,0,1.0729659,0.0,0.8374728,163.11679,1.3278166,312.41806,-9.310544
2171,2171,145.4235,29.82089,8.5482616,0.0,0,1.0466698,0.0,0.84255701,163.39943,1.3023716,312.00415,-9.3106861
2173,2173,145.4239,30.03303,8.5626688,0.0,0,1.0203738,0.0,0.84666294,163.85077,1.273039,311.59024,-9.312273
2175,2175,145.4243,30.241772,8.589859,0.0,0,0.9940778,0.0,0.84913361,164.60039,1.2462029,311.17633,-9.3120232
2177,2177,145.4247,30.467466,8.6183882,0.0,0,0.96778184,0.0,0.85410434,165.01247,1.2190552,310.76242,-9.3105259
2179,2179,145.4251,30.689634,8.6356668,0.0,0,0.94148582,0.0,0.8577866,165.61688,1.1938128,310.34851,-9.3089657
2181,2181,145.4255,30.873943,8.6686087,0.0,0,0.91518986,0.0,0.8610056,166.06422,1.171888,309.9346,-9.3092937
2183,2183,145.4259,31.080956,8.6955261,0.0,0,0.88915813,0.0,0.86696684,166.18164,1.1445656,309.52069,-9.3107491
2185,2185,145.4263,31.309645,8.715353,0.0,0,0.86408705,0.0,0.8699944,166.88081,1.1191835,309.10675,-9.3111725
2187,2187,145.4267,31.542418,8.7456169,0.0,0,0.83907896,0.0,0.87357306,167.54027,1.0926337,308.69284,-9.311347
2189,2189,145.4271,31.766581,8.7678318,0.0,0,0.81407094,0.0,0.87901777,167.83899,1.0696633,308.27893,-9.3095312
2191,2191,145.4275,31.989655,8.7920942,0.0,0,0.78906298,0.0,0.88148969,168.55644,1.0408012,307.86502,-9.3086472
2193,2193,145.4279,32.187645,8.8173237,0.0,0,0.76405495,0.0,0.88550514,168.96413,1.014886,307.45111,-9.3089724
2195,2195,145.4283,32.40815,8.8346748,0.0,0,0.73904693,0.0,0.89000201,169.33806,0.99116594,307.0372,-9.3099785
2197,2197,145.4287,32.656879,8.8654776,0.0,0,0.71403897,0.0,0.89289486,170.16054,0.96653748,306.62329,-9.308733
2199,2199,145.4291,32.890202,8.8904133,0.0,0,0.68903095,0.0,0.89786315,170.50325,0.94008023,306.20938,-9.3101616
2201,2201,145.4295,33.094311,8.9098463,0.0,0,0.66402298,0.0,0.90178144,170.92276,0.91967905,305.79547,-9.3086863
2203,2203,145.4299,33.319061,8.9414396,0.0,0,0.63901496,0.0,0.90494955,171.51436,0.89084846,305.38156,-9.3080206
2205,2205,145.4303,33.558151,8.9586563,0.0,0,0.61400694,0.0,0.90958786,171.94672,0.86610955,305.36072,-9.308589
2207,2207,145.4307,33.824665,8.9788656,0.0,0,0.58899897,0.0,0.91273546,172.71184,0.84145403,305.47079,-9.3096485
2209,2209,145.4311,34.078239,9.0129013,0.0,0,0.5647862,0.0,0.91678107,173.34558,0.819538,305.5809,-9.3091488
2211,2211,145.4315,34.291737,9.0271587,0.0,0,0.54098368,0.0,0.92131883,173.67897,0.79320413,305.69098,-9.3087311
2213,2213,145.4319,34.514603,9.0496531,0.0,0,0.5171836,0.0,0.92412299,174.26009,0.76788485,305.80109,-9.3072834
2215,2215,145.4323,34.766483,9.0817471,0.0,0,0.49338362,0.0,0.92871594,174.72597,0.74440521,305.91116,-9.3074017
2217,2217,145.4327,35.041363,9.0922499,0.0,0,0.46958363,0.0,0.93259239,175.43481,0.7187345,306.02124,-9.3072224
2219,2219,145.4331,35.290798,9.1192722,0.0,0,0.44578362,0.0,0.93511224,176.27666,0.69736916,306.13135,-9.3069239
2221,2221,145.4335,35.51413,9.1468754,0.0,0,0.42198363,0.0,0.94073123,176.38748,0.6708231,306.24142,-9.3077621
2223,2223,145.4339,35.755135,9.1630468,0.0,0,0.39818361,0.0,0.94436646,176.90472,0.65035975,306.35153,-9.3072166
2225,2225,145.4343,36.021065,9.1916571,0.0,0,0.3743836,0.0,0.94735676,177.70988,0.62635857,306.46161,-9.3078203
2227,2227,145.4347,36.306431,9.2119112,0.0,0,0.35058361,0.0,0.95268911,178.16685,0.60167652,306.57169,-9.3079548
2229,2229,145.4351,36.55854,9.2273636,0.0,0,0.32678363,0.0,0.95483887,179.06711,0.58132488,306.68179,-9.3069019
2231,2231,145.4355,36.800747,9.2526398,0.0,0,0.30298361,0.0,0.95824069,179.59843,0.56012541,306.79187,-9.3062944
2233,2233,145.4359,37.052219,9.2734671,0.0,0,0.27942321,0.0,0.96372706,179.89949,0.53943729,306.90198,-9.3056946
2235,2235,145.4363,37.341587,9.2982578,0.0,0,0.2567341,0.0,0.96627492,180.74072,0.51563448,307.01205,-9.3070278