File: clean data/testID_0095.csv
level_0,index,Time(sec),Force(kN),Jaw(mm),PowAngle(deg),Power(W),Pram,PTemp,Strain,Stress(MPa),Stroke(mm),TC1(C),wedge(mm)
1972,1972,165.348,0.9739269,0.054304663,0.0,0,9.0629702,0.0,0.0035553174,11.259854,10.110188,361.5661,-9.2876406
1974,1974,165.3484,4.022541,0.084401734,0.0,0,9.0044422,0.0,0.0054679979,46.097275,10.045779,361.57092,-9.2874918
1976,1976,165.3488,6.0664115,0.13570511,0.0,0,8.9459143,0.0,0.0086616939,75.501625,10.003862,361.57574,-9.2867489
1978,1978,165.3492,6.5447378,0.18874045,0.0,0,8.8873863,0.0,0.012245959,81.515137,9.9375925,361.58057,-9.2831268
1980,1980,165.3496,6.7229505,0.30918843,0.0,0,8.8288584,0.0,0.020063849,84.151077,9.8635693,361.47626,-9.2814722
1982,1982,165.35,7.0941076,0.37902325,0.0,0,8.7703304,0.0,0.025130004,86.867882,9.7751741,361.34467,-9.2808113
1984,1984,165.3504,7.5947895,0.45742649,0.0,0,8.7136879,0.0,0.030449603,93.655678,9.685914,361.21304,-9.2809973
1986,1986,165.3508,8.0188017,0.54128879,0.0,0,8.6580172,0.0,0.036361154,97.610291,9.6084013,361.08145,-9.2814713
1988,1988,165.3512,7.8947949,0.55521804,0.0,0,8.6023531,0.0,0.037380476,97.638062,9.5396729,360.94983,-9.2808771
1990,1990,165.3516,7.6617451,0.64286822,0.0,0,8.546689,0.0,0.04339074,92.872826,9.4809179,360.81824,-9.2814713
1992,1992,165.352,8.386982,0.69896841,0.0,0,8.4910259,0.0,0.047362763,101.19714,9.4189634,360.68665,-9.2820787
1994,1994,165.3524,8.4670181,0.74976397,0.0,0,8.4353609,0.0,0.050679486,102.46078,9.3499603,360.55502,-9.279624
1996,1996,165.3528,8.4763002,0.8659808,0.0,0,8.3796968,0.0,0.058913648,102.04698,9.274312,360.42343,-9.2799759
1998,1998,165.3532,8.2925186,0.94026715,0.0,0,8.3240337,0.0,0.06395141,99.213135,9.1964598,360.29181,-9.282424
2000,2000,165.3536,8.5768986,1.0142374,0.0,0,8.2683697,0.0,0.069515653,101.5704,9.1144094,360.16022,-9.2815151
2002,2002,165.354,8.7175579,1.0711465,0.0,0,8.2127056,0.0,0.073844858,103.0242,9.042613,360.02859,-9.2814217
2004,2004,165.3544,8.7589378,1.1223897,0.0,0,8.1570415,0.0,0.077043749,103.26768,8.9791365,359.897,-9.2806654
2006,2006,165.3548,8.6971073,1.1851954,0.0,0,8.1013775,0.0,0.082148232,102.13998,8.9167023,359.76538,-9.2809868
2008,2008,165.3552,8.92239,1.2341086,0.0,0,8.0462685,0.0,0.085357927,103.91389,8.8551455,359.63379,-9.2811613
2010,2010,165.3556,9.1725969,1.3113418,0.0,0,7.993176,0.0,0.090647556,106.71503,8.7945166,359.5022,-9.2818356
2012,2012,165.356,9.0055103,1.3866801,0.0,0,7.9402156,0.0,0.096670009,104.30915,8.7218161,359.37057,-9.2812147
2014,2014,165.3564,9.025713,1.4560018,0.0,0,7.8872557,0.0,0.10135015,103.71571,8.6500578,359.23898,-9.2816486
2016,2016,165.3568,9.1388035,1.525121,0.0,0,7.8342957,0.0,0.10681283,104.44456,8.5787067,359.10736,-9.281435
2018,2018,165.3572,9.2856188,1.5698678,0.0,0,7.7813354,0.0,0.11039095,105.70539,8.5143366,358.97577,-9.2809572
2020,2020,165.3576,9.2742033,1.6246681,0.0,0,7.7283754,0.0,0.1139441,105.49422,8.4505844,358.84415,-9.2808323
2022,2022,165.358,9.2110806,1.6918861,0.0,0,7.675415,0.0,0.11942958,104.00752,8.3922405,358.71255,-9.2816324
2024,2024,165.3584,9.4570799,1.739946,0.0,0,7.6224551,0.0,0.1229188,106.14192,8.3388567,358.58096,-9.2815723
2026,2026,165.3588,9.5559149,1.8003633,0.0,0,7.5694952,0.0,0.12716129,107.22073,8.2749958,358.44934,-9.2821741
2028,2028,165.3592,9.5476151,1.8708706,0.0,0,7.5165353,0.0,0.13306005,106.37283,8.2170954,358.31775,-9.2815485
2030,2030,165.3596,9.5491133,1.9333073,0.0,0,7.4635754,0.0,0.13728695,106.08363,8.1535521,358.08377,-9.281436
2032,2032,165.36,9.5456734,1.9936297,0.0,0,7.410615,0.0,0.14207008,105.36813,8.0893221,357.80591,-9.2807341
2034,2034,165.3604,9.7316742,2.0400751,0.0,0,7.3593612,0.0,0.14617321,106.89179,8.0284252,357.52805,-9.280798
2036,2036,165.3608,9.7270203,2.0955794,0.0,0,7.3089881,0.0,0.14965108,106.68592,7.9743829,357.25018,-9.2813625
2038,2038,165.3612,9.7566395,2.1507056,0.0,0,7.2586198,0.0,0.15448904,106.27542,7.9186349,356.97232,-9.2812777
2040,2040,165.3616,9.8046627,2.1942153,0.0,0,7.2082515,0.0,0.15795602,106.54026,7.8628645,356.69449,-9.2806711
2042,2042,165.362,9.91362,2.2589376,0.0,0,7.1578832,0.0,0.16226868,107.1268,7.809783,356.41663,-9.280962
2044,2044,165.3624,9.972352,2.3130257,0.0,0,7.1075153,0.0,0.1673155,107.50262,7.7558417,356.13876,-9.2811451
2046,2046,165.3628,9.9707088,2.3691297,0.0,0,7.0571475,0.0,0.17135951,106.97233,7.6958375,355.8609,-9.2811689
2048,2048,165.3632,10.014953,2.4298396,0.0,0,7.0067792,0.0,0.17605381,106.81125,7.6402545,355.58304,-9.279911
2050,2050,165.3636,10.095902,2.4678466,0.0,0,6.9564114,0.0,0.17971504,107.33202,7.5864429,355.30521,-9.2812014
2052,2052,165.364,10.106862,2.5225329,0.0,0,6.9060431,0.0,0.18338875,107.16031,7.5320182,355.02734,-9.2808075
2054,2054,165.3644,10.128691,2.5783012,0.0,0,6.8556757,0.0,0.18831731,106.79156,7.4806366,354.74948,-9.2812319
2056,2056,165.3648,10.238776,2.6193295,0.0,0,6.8053074,0.0,0.191734,107.57261,7.4311671,354.47162,-9.2800417
2058,2058,165.3652,10.303665,2.6760137,0.0,0,6.7554417,0.0,0.19574422,107.88391,7.3791904,354.19376,-9.2807369
2060,2060,165.3656,10.303377,2.7286446,0.0,0,6.7074022,0.0,0.20064531,107.32131,7.3241711,353.91589,-9.2809381
2062,2062,165.366,10.331574,2.7808251,0.0,0,6.6594815,0.0,0.20458105,107.11166,7.2697763,353.63806,-9.2811155
2064,2064,165.3664,10.407001,2.8324649,0.0,0,6.6115613,0.0,0.20866148,107.44173,7.2204781,353.3602,-9.2813616
2066,2066,165.3668,10.485476,2.8764832,0.0,0,6.5636415,0.0,0.21286897,107.8514,7.168735,353.08234,-9.2814198
2068,2068,165.3672,10.494671,2.9301989,0.0,0,6.5157218,0.0,0.21669008,107.69325,7.1167259,352.80447,-9.2806911
2070,2070,165.3676,10.492223,2.9821272,0.0,0,6.467802,0.0,0.22119214,106.94614,7.0683422,352.52661,-9.2797489
2072,2072,165.368,10.596953,3.023802,0.0,0,6.4198818,0.0,0.22519688,107.64481,7.0172191,352.24875,-9.280117
2074,2074,165.3684,10.661551,3.0828249,0.0,0,6.3719616,0.0,0.22923601,107.88094,6.9659843,351.97092,-9.2803841
2076,2076,165.3688,10.695794,3.1291282,0.0,0,6.3240418,0.0,0.23370646,107.79133,6.9153824,351.69305,-9.2814102
2078,2078,165.3692,10.675317,3.1764603,0.0,0,6.2761221,0.0,0.23771822,107.25015,6.8640757,351.41519,-9.2814293
2080,2080,165.3696,10.723433,3.2317643,0.0,0,6.2282019,0.0,0.2417869,107.17137,6.8132439,351.64182,-9.281146
2082,2082,165.37,10.80553,3.2709072,0.0,0,6.1802821,0.0,0.24589369,107.47229,6.763669,352.2048,-9.2813644
2084,2084,165.3704,10.845334,3.3225052,0.0,0,6.1339049,0.0,0.24986309,107.63406,6.7153888,352.76776,-9.2809343
2086,2086,165.3708,10.871008,3.3794682,0.0,0,6.0883236,0.0,0.25450283,107.24873,6.6647363,353.33072,-9.2819481
2088,2088,165.3712,10.91638,3.4173954,0.0,0,6.042748,0.0,0.25858974,107.33887,6.616704,353.89371,-9.2810841
2090,2090,165.3716,10.959048,3.4664671,0.0,0,5.9971719,0.0,0.26212224,107.31822,6.5688958,354.45667,-9.2805443
2092,2092,165.372,11.007149,3.5183153,0.0,0,5.9515953,0.0,0.2667191,107.30376,6.52035,355.01962,-9.2800913
2094,2094,165.3724,11.044344,3.5604167,0.0,0,5.9060202,0.0,0.27085799,107.27884,6.470787,355.58261,-9.2812004
2096,2096,165.3728,11.083197,3.6097651,0.0,0,5.8604436,0.0,0.27455613,107.25445,6.4205313,356.14557,-9.2807608
2098,2098,165.3732,11.12503,3.6582401,0.0,0,5.8148675,0.0,0.27927318,107.11107,6.3742976,356.70856,-9.2799807
2100,2100,165.3736,11.161618,3.7032864,0.0,0,5.7692914,0.0,0.28322431,107.01672,6.3260736,357.27151,-9.2809229
2102,2102,165.374,11.196053,3.7524471,0.0,0,5.7237153,0.0,0.28719762,106.92284,6.2816186,357.83447,-9.2803936
2104,2104,165.3744,11.278707,3.7966287,0.0,0,5.6781397,0.0,0.29184583,107.17714,6.2315688,358.39746,-9.2807627
2106,2106,165.3748,11.321858,3.8448071,0.0,0,5.6325636,0.0,0.29567617,107.27226,6.1849246,358.96042,-9.2800961
2108,2108,165.3752,11.334515,3.8902807,0.0,0,5.5874419,0.0,0.29960692,106.93606,6.1397643,359.52338,-9.2805309
2110,2110,165.3756,11.365024,3.9328148,0.0,0,5.5439739,0.0,0.30405343,106.73943,6.0932813,360.08636,-9.280982
2112,2112,165.376,11.407182,3.981745,0.0,0,5.5006137,0.0,0.30769822,106.75767,6.0444727,360.64932,-9.280694
2114,2114,165.3764,11.486444,4.023531,0.0,0,5.4572535,0.0,0.31191927,107.02412,5.998528,361.21228,-9.2809954
2116,2116,165.3768,11.496036,4.0674777,0.0,0,5.4138937,0.0,0.31616524,106.71184,5.953299,361.77527,-9.2801657
2118,2118,165.3772,11.537832,4.1222606,0.0,0,5.3705335,0.0,0.32026836,106.61488,5.9083052,362.33823,-9.2805996
2120,2120,165.3776,11.564958,4.1630273,0.0,0,5.3271737,0.0,0.3249065,106.39759,5.8637147,362.90121,-9.2806425
2122,2122,165.378,11.628538,4.2054558,0.0,0,5.2838135,0.0,0.32868344,106.47569,5.8206673,363.46417,-9.2809229
2124,2124,165.3784,11.694283,4.2565913,0.0,0,5.2404532,0.0,0.33290398,106.65578,5.7717237,364.02713,-9.2814112
2126,2126,165.3788,11.72588,4.2931352,0.0,0,5.1970935,0.0,0.33724812,106.44657,5.726264,364.59012,-9.2806911
2128,2128,165.3792,11.764227,4.3390613,0.0,0,5.1537337,0.0,0.34080157,106.46481,5.6821222,365.15308,-9.2819262
2130,2130,165.3796,11.792699,4.3914757,0.0,0,5.1103735,0.0,0.34576413,106.19578,5.6345315,365.89911,-9.2818213
2132,2132,165.38,11.845678,4.4290986,0.0,0,5.0670133,0.0,0.35003439,106.19239,5.5912118,366.82825,-9.2820721
2134,2134,165.3804,11.925417,4.4790034,0.0,0,5.0250487,0.0,0.35381114,106.50497,5.5440207,367.75735,-9.2811661
2136,2136,165.3808,11.964532,4.5254593,0.0,0,4.9838042,0.0,0.35887,106.41537,5.5000639,368.68646,-9.2801714
2138,2138,165.3812,11.977324,4.5638628,0.0,0,4.942564,0.0,0.36258024,106.12413,5.4551001,369.61557,-9.2802544
2140,2140,165.3816,12.014802,4.6120572,0.0,0,4.9013243,0.0,0.36659604,106.01226,5.407156,370.54471,-9.2794943
2142,2142,165.382,12.067764,4.6555758,0.0,0,4.8600841,0.0,0.37147611,105.94526,5.3623972,371.47382,-9.2816191
2144,2144,165.3824,12.151257,4.6978755,0.0,0,4.8188443,0.0,0.37522033,106.23555,5.3204474,372.40292,-9.2819843
2146,2146,165.3828,12.185473,4.7460074,0.0,0,4.7776041,0.0,0.3796438,106.13078,5.2767987,373.33203,-9.2814016
2148,2148,165.3832,12.192741,4.7856255,0.0,0,4.7363639,0.0,0.38435158,105.68793,5.2303252,374.26117,-9.2810555
2150,2150,165.3836,12.24392,4.8314724,0.0,0,4.6951241,0.0,0.38797337,105.67185,5.1878395,375.19028,-9.2809505
2152,2152,165.384,12.316669,4.874279,0.0,0,4.6538844,0.0,0.39252645,105.83706,5.1440935,376.11938,-9.279767
2154,2154,165.3844,12.382597,4.9131598,0.0,0,4.6126437,0.0,0.39691901,106.00346,5.0979538,377.04849,-9.2799215
2156,2156,165.3848,12.404994,4.9663982,0.0,0,4.571404,0.0,0.4010585,105.83041,5.0549254,377.97763,-9.2806225
2158,2158,165.3852,12.425249,5.0056319,0.0,0,4.5305758,0.0,0.40579331,105.43653,5.0104342,378.90674,-9.2817383
2160,2160,165.3856,12.481579,5.0450845,0.0,0,4.4912457,0.0,0.40967751,105.3674,4.9701395,379.83585,-9.2812052
2162,2162,165.386,12.562052,5.095211,0.0,0,4.4520135,0.0,0.4140214,105.65542,4.9271216,380.76495,-9.2811165
2164,2164,165.3864,12.607407,5.1284537,0.0,0,4.4127817,0.0,0.4184452,105.59991,4.8860946,381.69409,-9.280695
2166,2166,165.3868,12.639682,5.1705737,0.0,0,4.3735499,0.0,0.4221262,105.48814,4.8410468,382.6232,-9.2804289
2168,2168,165.3872,12.679819,5.2234497,0.0,0,4.3343177,0.0,0.42725509,105.32956,4.7988057,383.55231,-9.2800493
2170,2170,165.3876,12.734485,5.2561812,0.0,0,4.2950859,0.0,0.43159369,105.23129,4.7560058,384.48141,-9.2801714
2172,2172,165.388,12.804008,5.3003225,0.0,0,4.2558532,0.0,0.43515661,105.47575,4.7148728,385.41055,-9.2801247
2174,2174,165.3884,12.866479,5.3456059,0.0,0,4.2166214,0.0,0.44029486,105.46,4.6733103,386.33966,-9.2815113
2176,2176,165.3888,12.896479,5.3787475,0.0,0,4.1773896,0.0,0.44399709,105.29552,4.6333423,387.26877,-9.2814512
2178,2178,165.3892,12.937859,5.4245796,0.0,0,4.1381574,0.0,0.44794917,105.29037,4.5923424,388.19788,-9.2813702
2180,2180,165.3896,12.998055,5.464891,0.0,0,4.0989256,0.0,0.45311737,105.12453,4.5530353,388.86832,-9.2813711
2182,2182,165.39,13.071404,5.5025277,0.0,0,4.0596938,0.0,0.45673335,105.32262,4.5074291,389.15073,-9.2806482
2184,2184,165.3904,13.131282,5.5477295,0.0,0,4.0217257,0.0,0.46091986,105.46592,4.4692316,389.43314,-9.2809458
2186,2186,165.3908,13.164587,5.5844483,0.0,0,3.9844093,0.0,0.46584651,105.18354,4.4275703,389.71555,-9.2801371
2188,2188,165.3912,13.205831,5.6278877,0.0,0,3.9470973,0.0,0.46954006,105.12071,4.3864021,389.99796,-9.2816143
2190,2190,165.3916,13.262986,5.6691251,0.0,0,3.9097853,0.0,0.47416914,105.02751,4.3462429,390.28033,-9.2819891
2192,2192,165.392,13.330465,5.7034883,0.0,0,3.8724735,0.0,0.47856942,105.15085,4.3082023,390.56274,-9.281455
2194,2194,165.3924,13.403502,5.7502933,0.0,0,3.8351612,0.0,0.48237973,105.3206,4.2658443,390.84515,-9.280364
2196,2196,165.3928,13.43557,5.7862911,0.0,0,3.7978494,0.0,0.4870837,105.10002,4.2258701,391.12756,-9.2800303
2198,2198,165.3932,13.483116,5.822021,0.0,0,3.7605371,0.0,0.49117413,105.01764,4.1835256,391.40994,-9.2804031
2200,2200,165.3936,13.546302,5.8719997,0.0,0,3.7232254,0.0,0.49549791,105.05376,4.1435966,391.69235,-9.2815838
2202,2202,165.394,13.631409,5.903018,0.0,0,3.6859133,0.0,0.50008404,105.23824,4.1028996,391.97476,-9.2814922
2204,2204,165.3944,13.696995,5.9426789,0.0,0,3.6486013,0.0,0.50398624,105.35234,4.0634298,392.25717,-9.2803764
2206,2206,165.3948,13.733574,5.9915762,0.0,0,3.6112893,0.0,0.50891697,105.10799,4.0238819,392.53958,-9.278697
2208,2208,165.3952,13.793605,6.0221696,0.0,0,3.5743496,0.0,0.51352495,105.02151,3.9840589,392.82196,-9.2798624
2210,2210,165.3956,13.852162,6.0639405,0.0,0,3.538765,0.0,0.517147,105.092,3.9448726,393.10437,-9.2813892
2212,2212,165.396,13.925409,6.1080394,0.0,0,3.5032687,0.0,0.52232391,105.09392,3.9072654,393.38678,-9.2805433
2214,2214,165.3964,13.987652,6.1399097,0.0,0,3.4677727,0.0,0.52644122,105.1329,3.8694766,393.66919,-9.278513
2216,2216,165.3968,14.036656,6.1823745,0.0,0,3.432277,0.0,0.53039646,105.07552,3.8328862,393.9516,-9.2784338
2218,2218,165.3972,14.087003,6.2209902,0.0,0,3.3967807,0.0,0.53558111,104.95191,3.7916484,394.23398,-9.2797117
2220,2220,165.3976,14.147762,6.254775,0.0,0,3.3612847,0.0,0.53928512,104.96556,3.749404,394.51639,-9.2810545
2222,2222,165.398,14.240476,6.2962618,0.0,0,3.3257887,0.0,0.54339463,105.22243,3.7131095,394.7988,-9.2804327
2224,2224,165.3984,14.3014,6.3339453,0.0,0,3.2902927,0.0,0.54866135,105.21053,3.6747408,395.08121,-9.2798548
2226,2226,165.3988,14.354365,6.372005,0.0,0,3.2547965,0.0,0.55241573,105.15879,3.6357856,395.36359,-9.2792749
2228,2228,165.3992,14.390214,6.4117842,0.0,0,3.2193007,0.0,0.55694509,105.00541,3.6001027,395.646,-9.2798367
2230,2230,165.3996,14.470221,6.4442892,0.0,0,3.1838048,0.0,0.56168866,105.01054,3.5618761,395.71161,-9.2802906
2232,2232,165.4,14.55231,6.486578,0.0,0,3.1483088,0.0,0.56547189,105.21246,3.5240905,395.27136,-9.2807522
2234,2234,165.4004,14.631837,6.5209618,0.0,0,3.11395,0.0,0.57005227,105.3189,3.4881132,394.83109,-9.2804708
2236,2236,165.4008,14.663337,6.5546017,0.0,0,3.0801783,0.0,0.57439017,105.12307,3.4518132,394.39084,-9.2799501
2238,2238,165.4012,14.719898,6.6005402,0.0,0,3.0464106,0.0,0.57865155,105.07558,3.4134264,393.95059,-9.2795572
2240,2240,165.4016,14.803258,6.633256,0.0,0,3.0126424,0.0,0.58372253,105.11243,3.3772249,393.51031,-9.2800179
2242,2242,165.402,14.892573,6.6676064,0.0,0,2.9788744,0.0,0.58758253,105.32578,3.3385432,393.07007,-9.2807798
2244,2244,165.4024,14.961361,6.7110629,0.0,0,2.9451065,0.0,0.59203053,105.31051,3.3030248,392.62979,-9.280653
2246,2246,165.4028,14.997746,6.737165,0.0,0,2.9113381,0.0,0.59654725,105.14189,3.2688715,392.18954,-9.2801609
2248,2248,165.4032,15.067498,6.7735648,0.0,0,2.8775704,0.0,0.60001081,105.22939,3.2299192,391.7493,-9.2798977
2250,2250,165.4036,15.147717,6.8172774,0.0,0,2.8438022,0.0,0.60521591,105.238,3.1957984,391.30902,-9.2796421
2252,2252,165.404,15.234961,6.8462214,0.0,0,2.810034,0.0,0.60978061,105.37514,3.1554246,390.86877,-9.2792349
2254,2254,165.4044,15.286417,6.8855624,0.0,0,2.7762663,0.0,0.61339605,105.39153,3.1213312,390.4285,-9.2800865
2256,2256,165.4048,15.345066,6.9239511,0.0,0,2.7424984,0.0,0.61890948,105.19801,3.0889821,389.98825,-9.2791605
2258,2258,165.4052,15.39897,6.951942,0.0,0,2.7090683,0.0,0.62257642,105.14147,3.0523081,389.54797,-9.2799196
2260,2260,165.4056,15.489738,6.9889255,0.0,0,2.6768677,0.0,0.62623411,105.34133,3.0179651,389.10773,-9.2791595
2262,2262,165.406,15.603494,7.0226178,0.0,0,2.6447473,0.0,0.6315667,105.53705,2.9814916,388.66748,-9.278985
2264,2264,165.4064,15.665016,7.0565572,0.0,0,2.6126273,0.0,0.63522321,105.5947,2.9473462,388.2272,-9.2786741
2266,2266,165.4068,15.715557,7.0957041,0.0,0,2.5805073,0.0,0.63976443,105.4987,2.9115999,387.78696,-9.2789421
2268,2268,165.4072,15.780375,7.1263013,0.0,0,2.5483873,0.0,0.64483225,105.37609,2.8777678,387.34668,-9.2795448
2270,2270,165.4076,15.877777,7.1642728,0.0,0,2.5162673,0.0,0.64839548,105.59303,2.8427985,386.90643,-9.2786751
2272,2272,165.408,15.984118,7.1968393,0.0,0,2.4841473,0.0,0.65305883,105.91149,2.8068252,386.46619,-9.2795382
2274,2274,165.4084,16.032806,7.225863,0.0,0,2.4520273,0.0,0.65753269,105.74637,2.7787385,386.02591,-9.2785454
2276,2276,165.4088,16.088263,7.2676229,0.0,0,2.4199073,0.0,0.66135615,105.63544,2.7457302,385.58566,-9.2784424
2278,2278,165.4092,16.161453,7.2959142,0.0,0,2.3877873,0.0,0.66618299,105.68655,2.7100701,385.14539,-9.2784748
2280,2280,165.4096,16.270931,7.3255172,0.0,0,2.3556671,0.0,0.66993904,105.96704,2.6737642,384.67264,-9.2796106
2282,2282,165.41,16.365665,7.368721,0.0,0,2.3235474,0.0,0.67441374,106.12059,2.6386354,384.06992,-9.2794161
2284,2284,165.4104,16.425547,7.3939567,0.0,0,2.2924595,0.0,0.67938131,106.025,2.6084111,383.46719,-9.2784719
2286,2286,165.4108,16.486853,7.4277596,0.0,0,2.2619042,0.0,0.68299997,106.00169,2.5739191,382.86447,-9.2788668
2288,2288,165.4112,16.576323,7.4672565,0.0,0,2.2313523,0.0,0.68792689,106.02945,2.5429518,382.26175,-9.2782946
2290,2290,165.4116,16.684797,7.4894643,0.0,0,2.2008004,0.0,0.69213426,106.25327,2.5082593,381.65903,-9.2782946
2292,2292,165.412,16.76399,7.5256443,0.0,0,2.1702483,0.0,0.69551247,106.42287,2.4744031,381.0563,-9.2793531
2294,2294,165.4124,16.847551,7.5633769,0.0,0,2.1396964,0.0,0.70109415,106.38653,2.4459383,380.45358,-9.2798977
2296,2296,165.4128,16.911995,7.5881686,0.0,0,2.1091442,0.0,0.70516098,106.32735,2.4097192,379.85086,-9.2795486
2298,2298,165.4132,17.01886,7.6261568,0.0,0,2.0785923,0.0,0.70908147,106.56277,2.3771648,379.24814,-9.2787476
2300,2300,165.4136,17.110622,7.6574626,0.0,0,2.0480404,0.0,0.71442527,106.56638,2.3465288,378.64539,-9.2782354
2302,2302,165.414,17.215071,7.6859102,0.0,0,2.0174885,0.0,0.71792543,106.88713,2.3150764,378.04266,-9.2777967
2304,2304,165.4144,17.28952,7.7203984,0.0,0,1.9869361,0.0,0.72192597,106.91754,2.2846117,377.43994,-9.2794886
2306,2306,165.4148,17.379364,7.7488875,0.0,0,1.9563841,0.0,0.72732633,106.85294,2.2494433,376.83722,-9.2792397
2308,2308,165.4152,17.472254,7.7836485,0.0,0,1.9261373,0.0,0.73075455,107.08302,2.2213347,376.2345,-9.2788496
2310,2310,165.4156,17.573252,7.8159781,0.0,0,1.8970004,0.0,0.73558503,107.19202,2.1895125,375.63177,-9.2783022
2312,2312,165.416,17.683781,7.8420477,0.0,0,1.8679364,0.0,0.74026716,107.31081,2.1543803,375.02905,-9.2775784
2314,2314,165.4164,17.761698,7.8796415,0.0,0,1.8388724,0.0,0.7438525,107.46171,2.1236534,374.42633,-9.2782297
2316,2316,165.4168,17.850159,7.9066954,0.0,0,1.8098084,0.0,0.74862355,107.44888,2.0980532,373.82361,-9.2788467
2318,2318,165.4172,17.936756,7.9347739,0.0,0,1.7807443,0.0,0.75278527,107.48755,2.0634177,373.22089,-9.2789154
2320,2320,165.4176,18.063145,7.9743018,0.0,0,1.7516804,0.0,0.75698256,107.79893,2.0304136,372.61816,-9.2781734
2322,2322,165.418,18.1782,7.9976521,0.0,0,1.7226164,0.0,0.76198345,107.94376,2.0037165,372.01544,-9.2763071
2324,2324,165.4184,18.271458,8.0278492,0.0,0,1.6935524,0.0,0.76565927,108.10212,1.9697788,371.41272,-9.2763615
2326,2326,165.4188,18.353962,8.0681543,0.0,0,1.6644883,0.0,0.7707299,108.06299,1.9395199,370.80997,-9.2774019
2328,2328,165.4192,18.459988,8.0869513,0.0,0,1.6354244,0.0,0.77509481,108.20545,1.9075637,370.20724,-9.2780247
2330,2330,165.4196,18.582571,8.1196346,0.0,0,1.6063604,0.0,0.77832383,108.53502,1.8755841,369.65045,-9.2782316
2332,2332,165.42,18.699745,8.1570692,0.0,0,1.5772964,0.0,0.78409332,108.64105,1.8471617,369.50708,-9.2780151
2334,2334,165.4204,18.792028,8.1786413,0.0,0,1.5491644,0.0,0.78823173,108.7373,1.8160928,369.36368,-9.2775164
2336,2336,165.4208,18.883175,8.2130623,0.0,0,1.5215132,0.0,0.79186261,108.88828,1.7820029,369.22031,-9.2781248
2338,2338,165.4212,18.985151,8.2442865,0.0,0,1.4938653,0.0,0.79764599,108.81602,1.7526554,369.0769,-9.2776718
2340,2340,165.4216,19.119108,8.2691288,0.0,0,1.4662173,0.0,0.80121005,109.17962,1.7240353,368.93353,-9.277524
2342,2342,165.422,19.24217,8.3020201,0.0,0,1.4385693,0.0,0.80511391,109.47297,1.6947984,368.79013,-9.2764797
2344,2344,165.4224,19.332743,8.3288736,0.0,0,1.4109213,0.0,0.81073242,109.36823,1.6671637,368.64676,-9.2769079
2346,2346,165.4228,19.43536,8.3607759,0.0,0,1.3832734,0.0,0.81428677,109.57359,1.637369,368.50336,-9.2773952
2348,2348,165.4232,19.55475,8.3925362,0.0,0,1.3556253,0.0,0.81892568,109.74045,1.6118854,368.35999,-9.2781401
2350,2350,165.4236,19.69882,8.4158812,0.0,0,1.3279774,0.0,0.82392019,109.89797,1.5806868,368.21658,-9.2783079
2352,2352,165.424,19.82266,8.4508476,0.0,0,1.3003293,0.0,0.82753062,110.28143,1.5531269,368.07321,-9.2787113
2354,2354,165.4244,19.902328,8.47787,0.0,0,1.2726814,0.0,0.83248615,110.15958,1.5218433,367.92981,-9.2774773
2356,2356,165.4248,20.008923,8.5000858,0.0,0,1.2450334,0.0,0.83664155,110.26843,1.4905983,367.78644,-9.2766123
2358,2358,165.4252,20.139427,8.5386343,0.0,0,1.2176627,0.0,0.84054172,110.55856,1.4612421,367.64304,-9.2767687
2360,2360,165.4256,20.282698,8.5599842,0.0,0,1.1913006,0.0,0.84570855,110.78562,1.4317222,367.49966,-9.2782192
2362,2362,165.426,20.412268,8.5885391,0.0,0,1.1650045,0.0,0.84953862,111.08335,1.4074478,367.35626,-9.2783966
2364,2364,165.4264,20.497919,8.6275215,0.0,0,1.1387084,0.0,0.85477787,110.98021,1.3754886,367.21289,-9.2778234
2366,2366,165.4268,20.618229,8.6459427,0.0,0,1.1124125,0.0,0.85952324,111.04163,1.3460519,367.06949,-9.276001
2368,2368,165.4272,20.753448,8.6748791,0.0,0,1.0861164,0.0,0.86267179,111.45435,1.3194368,366.92612,-9.2754459
2370,2370,165.4276,20.916058,8.7073784,0.0,0,1.0598203,0.0,0.8678484,111.71948,1.2914182,366.78271,-9.2764587
2372,2372,165.428,21.036831,8.7246571,0.0,0,1.0335244,0.0,0.87192065,111.93501,1.2605988,366.63934,-9.27672
2374,2374,165.4284,21.136703,8.7564383,0.0,0,1.0072284,0.0,0.8752439,112.11692,1.2325363,366.49597,-9.2774324
2376,2376,165.4288,21.264097,8.7885933,0.0,0,0.98093235,0.0,0.88142198,112.04766,1.2043881,366.35257,-9.2759075
2378,2378,165.4292,21.398849,8.8108482,0.0,0,0.95463634,0.0,0.88538176,112.30116,1.1760792,366.2092,-9.2754412
2380,2380,165.4296,21.554117,8.8428183,0.0,0,0.92834044,0.0,0.8892439,112.6875,1.1498021,366.0658,-9.275939
2382,2382,165.43,21.674713,8.8668423,0.0,0,0.90204442,0.0,0.89474422,112.71423,1.1249932,366.27417,-9.2754736
2384,2384,165.4304,21.782356,8.8928022,0.0,0,0.87659609,0.0,0.89808708,112.93955,1.0982716,366.48254,-9.2763138
2386,2386,165.4308,21.919315,8.9224586,0.0,0,0.85158539,0.0,0.90232921,113.11251,1.0696994,366.69092,-9.2759094
2388,2388,165.4312,22.080095,8.9438391,0.0,0,0.82657731,0.0,0.9077031,113.33057,1.0415989,366.89926,-9.2751522
2390,2390,165.4316,22.237728,8.9741087,0.0,0,0.8015694,0.0,0.91083932,113.79989,1.0147339,367.10764,-9.2740812
2392,2392,165.432,22.361118,9.0004072,0.0,0,0.77656138,0.0,0.91579878,113.88356,0.98657221,367.31601,-9.274971
2394,2394,165.4324,22.485634,9.0211277,0.0,0,0.75155336,0.0,0.92039537,113.96043,0.96146852,367.52438,-9.2760324
2396,2396,165.4328,22.623333,9.0553904,0.0,0,0.72654539,0.0,0.9239195,114.26305,0.93465638,367.73276,-9.2752991
2398,2398,165.4332,22.780813,9.0766048,0.0,0,0.70153737,0.0,0.92918718,114.44485,0.90841824,367.94113,-9.2757845
2400,2400,165.4336,22.941269,9.1012068,0.0,0,0.67652941,0.0,0.93311834,114.78607,0.88273311,368.14951,-9.2755919
2402,2402,165.434,23.084394,9.136939,0.0,0,0.65152138,0.0,0.93750674,115.027,0.85389286,368.35788,-9.2746496
2404,2404,165.4344,23.212446,9.1520233,0.0,0,0.62651336,0.0,0.9424504,115.09681,0.82970893,368.56625,-9.2744312
2406,2406,165.4348,23.355263,9.1758928,0.0,0,0.6015054,0.0,0.94539624,115.44547,0.80198473,368.7746,-9.2756948
2408,2408,165.4352,23.513275,9.2089863,0.0,0,0.57674509,0.0,0.95066053,115.64231,0.77512896,368.98297,-9.2752695
2410,2410,165.4356,23.683439,9.2252808,0.0,0,0.55288601,0.0,0.95520049,115.92899,0.7506088,369.19135,-9.2764673
2412,2412,165.436,23.813248,9.2549467,0.0,0,0.52908593,0.0,0.958534,116.17542,0.72672755,369.39972,-9.2759762
2414,2414,165.4364,23.947464,9.2848186,0.0,0,0.50528592,0.0,0.96456432,116.16949,0.69594103,369.60809,-9.2749615
2416,2416,165.4368,24.093124,9.2996302,0.0,0,0.4814859,0.0,0.96797776,116.42731,0.67272156,369.81647,-9.2746
2418,2418,165.4372,24.253586,9.3283882,0.0,0,0.45768592,0.0,0.97129577,116.82294,0.6472348,370.02484,-9.2745523
2420,2420,165.4376,24.430748,9.3528748,0.0,0,0.4338859,0.0,0.97725534,117.01044,0.62197232,370.23322,-9.2752876
2422,2422,165.438,24.573606,9.3736458,0.0,0,0.41008592,0.0,0.98032701,117.34975,0.59779572,370.44159,-9.2741957
2424,2424,165.4384,24.702623,9.4033117,0.0,0,0.3862859,0.0,0.98449129,117.44234,0.57293499,370.64993,-9.2744627
2425,2425,165.4386,24.777712,9.4116564,0.0,0,0.37438589,0.0,0.98674136,117.51676,0.56027138,370.75412,-9.2743568