File: clean data/testID_0237.csv
level_0,index,Time(sec),Force(kN),Jaw(mm),PowAngle(deg),Power(W),Pram,PTemp,Strain,Stress(MPa),Stroke(mm),TC1(C),wedge(mm)
2443,2443,212.0204,0.53720087,0.017363243,0.0,0,8.9166508,0.0,0.0012515431,6.4716725,9.8761902,499.9133,-9.2061138
2444,2444,212.0206,0.97757661,0.038574122,0.0,0,8.8873863,0.0,0.0020685457,11.044126,9.8348932,499.93549,-9.2060843
2445,2445,212.0208,1.7445222,0.0642884,0.0,0,8.8581219,0.0,0.0038519255,20.013121,9.8033381,499.95764,-9.2061644
2446,2446,212.021,2.6939454,0.098415963,0.0,0,8.8288584,0.0,0.006303872,31.514341,9.7766123,499.97983,-9.2062292
2447,2447,212.0212,3.5569715,0.12677528,0.0,0,8.7995939,0.0,0.0079952087,42.846512,9.7450895,500.00198,-9.2061405
2448,2448,212.0214,4.0263638,0.14266421,0.0,0,8.7703304,0.0,0.0092000896,49.940384,9.7072506,500.02417,-9.2053509
2449,2449,212.0216,4.12047,0.18929823,0.0,0,8.7416534,0.0,0.012209226,51.825871,9.6657076,500.04636,-9.2045736
2450,2450,212.0218,4.0156198,0.27171612,0.0,0,8.7136879,0.0,0.017076047,50.607384,9.6201792,500.06851,-9.2043839
2451,2451,212.022,3.952754,0.345166,0.0,0,8.6858492,0.0,0.022167074,49.313869,9.5694008,500.0907,-9.203742
2452,2452,212.0222,4.0129514,0.39992407,0.0,0,8.6580172,0.0,0.026536947,49.581951,9.5162621,500.11285,-9.2030716
2453,2453,212.0224,4.0573711,0.44403988,0.0,0,8.6301851,0.0,0.029396303,50.124893,9.4609528,500.13504,-9.2031832
2454,2454,212.0226,4.0053477,0.48520154,0.0,0,8.6023531,0.0,0.032046065,49.548889,9.4074669,500.15723,-9.203208
2455,2455,212.0228,3.9849813,0.54318231,0.0,0,8.574522,0.0,0.036239725,48.855541,9.3603086,500.17938,-9.2029533
2456,2456,212.023,4.216311,0.5987221,0.0,0,8.546689,0.0,0.04008574,50.844566,9.3134775,500.20157,-9.2029409
2457,2457,212.0232,4.5368528,0.61674702,0.0,0,8.518857,0.0,0.041617192,54.723934,9.2689743,500.22372,-9.2029457
2458,2458,212.0234,4.54006,0.61756432,0.0,0,8.4910259,0.0,0.042142395,55.677521,9.2304106,500.24591,-9.2029743
2459,2459,212.0236,4.2514458,0.63380092,0.0,0,8.4631929,0.0,0.042937994,52.723907,9.1950226,500.2681,-9.2032318
2460,2460,212.0238,3.9778488,0.6687538,0.0,0,8.4353609,0.0,0.044816457,49.051636,9.1603775,500.29025,-9.2039051
2461,2461,212.024,3.9327745,0.71168596,0.0,0,8.4075298,0.0,0.04812004,47.730843,9.1268101,500.31244,-9.2041521
2462,2462,212.0242,4.0959263,0.74191415,0.0,0,8.3796968,0.0,0.050560396,49.224644,9.0932531,500.33459,-9.204174
2463,2463,212.0244,4.3027387,0.75217789,0.0,0,8.3518648,0.0,0.051167209,51.659733,9.0618296,500.35678,-9.2042828
2464,2464,212.0246,4.5141253,0.77087957,0.0,0,8.3240337,0.0,0.052492596,54.02457,9.0324755,500.37897,-9.2036276
2465,2465,212.0248,4.6588387,0.81575382,0.0,0,8.2962017,0.0,0.055413857,55.784229,8.9984903,500.40112,-9.203125
2466,2466,212.025,4.6154251,0.87289274,0.0,0,8.2683697,0.0,0.058980517,55.658878,8.961524,500.42331,-9.2030497
2467,2467,212.0252,4.4344468,0.92194521,0.0,0,8.2405376,0.0,0.062753208,53.450706,8.9260702,500.4455,-9.2022448
2468,2468,212.0254,4.3179488,0.95368659,0.0,0,8.2127056,0.0,0.065512165,51.618839,8.8880129,500.46765,-9.2022171
2469,2469,212.0256,4.2790327,0.98189902,0.0,0,8.1848736,0.0,0.067171976,50.951611,8.8497972,500.48984,-9.2031708
2470,2470,212.0258,4.2539072,1.0211692,0.0,0,8.1570415,0.0,0.069809556,50.515949,8.8110313,500.51199,-9.2041969
2471,2471,212.026,4.2477965,1.0679088,0.0,0,8.1292095,0.0,0.073445514,50.291679,8.7729664,500.53418,-9.2046995
2472,2472,212.0262,4.2771058,1.1104605,0.0,0,8.1013775,0.0,0.076306894,50.409206,8.7375727,500.55637,-9.2043123
2473,2473,212.0264,4.4127755,1.1350896,0.0,0,8.0735455,0.0,0.078249641,51.613194,8.7039909,500.57852,-9.2043171
2474,2474,212.0266,4.5763144,1.146961,0.0,0,8.0462685,0.0,0.079595268,53.53096,8.6708794,500.60071,-9.2037563
2475,2475,212.0268,4.5999031,1.1732324,0.0,0,8.0196619,0.0,0.08099103,54.133255,8.6389408,500.62286,-9.2035208
2476,2476,212.027,4.4691782,1.2123563,0.0,0,7.993176,0.0,0.083500393,52.733311,8.6077671,500.64505,-9.2034969
2477,2477,212.0272,4.3354678,1.2455646,0.0,0,7.9666953,0.0,0.086458415,50.931938,8.5793495,500.66724,-9.2027702
2478,2478,212.0274,4.3304877,1.2737619,0.0,0,7.9402156,0.0,0.088436961,50.355412,8.5541553,500.68939,-9.2034302
2479,2479,212.0276,4.4486198,1.293865,0.0,0,7.9137359,0.0,0.089698143,51.392342,8.5282526,500.71158,-9.2043505
2480,2480,212.0278,4.6011801,1.311177,0.0,0,7.8872557,0.0,0.091315456,53.071812,8.5014038,500.73373,-9.2043285
2481,2481,212.028,4.7139845,1.3473195,0.0,0,7.8607755,0.0,0.093651824,54.372265,8.4727211,500.75592,-9.2043724
2482,2482,212.0282,4.7391973,1.3889856,0.0,0,7.8342957,0.0,0.096295811,54.751953,8.4450178,500.77811,-9.2042971
2483,2483,212.0284,4.6679049,1.414867,0.0,0,7.8078156,0.0,0.098738037,53.951809,8.4152451,500.80026,-9.2037144
2484,2484,212.0286,4.5936532,1.4450814,0.0,0,7.7813354,0.0,0.10100745,52.926418,8.3840685,500.82245,-9.2038841
2485,2485,212.0288,4.5833883,1.4816668,0.0,0,7.7548552,0.0,0.10315096,52.604824,8.3542337,500.8446,-9.2040462
2486,2486,212.029,4.5779886,1.5086598,0.0,0,7.7283754,0.0,0.10556001,52.485489,8.3233786,500.86679,-9.2035761
2487,2487,212.0292,4.5441999,1.5401274,0.0,0,7.7018952,0.0,0.10816593,52.007671,8.2924347,500.88898,-9.2032137
2488,2488,212.0294,4.5384769,1.565564,0.0,0,7.675415,0.0,0.10970192,51.766747,8.2640076,500.91113,-9.2029305
2489,2489,212.0296,4.607687,1.5716882,0.0,0,7.6489348,0.0,0.11045999,52.423946,8.2368555,500.93332,-9.2029381
2490,2490,212.0298,4.7020111,1.5894713,0.0,0,7.6224551,0.0,0.111928,53.452049,8.2081022,500.95547,-9.2035913
2491,2491,212.03,4.715559,1.6222078,0.0,0,7.5959754,0.0,0.11374676,53.694469,8.1811657,500.97766,-9.203784
2492,2492,212.0302,4.6397266,1.6467276,0.0,0,7.5694952,0.0,0.11570677,52.840103,8.1571703,500.99985,-9.2031374
2493,2493,212.0304,4.5873938,1.6706538,0.0,0,7.543015,0.0,0.11796311,52.011551,8.1327057,501.01782,-9.2029448
2494,2494,212.0306,4.6305647,1.6926112,0.0,0,7.5165353,0.0,0.11929695,52.16357,8.107893,501.03159,-9.2030916
2495,2495,212.0308,4.7471838,1.703786,0.0,0,7.4900556,0.0,0.12015015,53.31797,8.084734,501.04538,-9.2036314
2496,2496,212.031,4.8309193,1.728098,0.0,0,7.4635754,0.0,0.12219938,54.372917,8.060812,501.05917,-9.2035408
2497,2497,212.0312,4.8504667,1.7651947,0.0,0,7.4370952,0.0,0.12456489,54.604595,8.0335197,501.07294,-9.2032156
2498,2498,212.0314,4.8618579,1.7891517,0.0,0,7.410615,0.0,0.12637329,54.569504,8.0099354,501.08673,-9.2031784
2499,2499,212.0316,4.8777819,1.81076,0.0,0,7.3846664,0.0,0.12851606,54.577541,7.986249,501.10052,-9.2030067
2500,2500,212.0318,4.8700895,1.8403007,0.0,0,7.3593612,0.0,0.13050415,54.463951,7.9588985,501.11429,-9.2028341
2501,2501,212.032,4.814858,1.8686711,0.0,0,7.3341722,0.0,0.13230716,53.884087,7.9324679,501.12808,-9.2027283
2502,2502,212.0322,4.7543998,1.9005263,0.0,0,7.3089881,0.0,0.13511856,52.984005,7.9052415,501.14188,-9.2028685
2503,2503,212.0324,4.7560353,1.9318019,0.0,0,7.2838039,0.0,0.13761623,52.67149,7.8795538,501.15564,-9.2023964
2504,2504,212.0326,4.8370175,1.9495157,0.0,0,7.2586198,0.0,0.13875687,53.37677,7.8526068,501.16943,-9.2018442
2505,2505,212.0328,4.9267087,1.964514,0.0,0,7.2334356,0.0,0.14026894,54.316238,7.8250947,501.18323,-9.2021875
2506,2506,212.033,4.9600372,1.988358,0.0,0,7.2082515,0.0,0.14212827,54.721024,7.8012285,501.19699,-9.2020073
2507,2507,212.0332,4.9256339,2.0145984,0.0,0,7.1830673,0.0,0.14363968,54.435299,7.7753325,501.21078,-9.2021675
2508,2508,212.0334,4.8615808,2.0398116,0.0,0,7.1578832,0.0,0.14585893,53.653358,7.7510748,501.22458,-9.2028923
2509,2509,212.0336,4.8355598,2.0618289,0.0,0,7.1326995,0.0,0.14781603,53.118076,7.7294106,501.23834,-9.2027674
2510,2510,212.0338,4.8679123,2.0796192,0.0,0,7.1075153,0.0,0.14874075,53.284679,7.7056737,501.25214,-9.2029276
2511,2511,212.034,4.9236851,2.0998809,0.0,0,7.0823312,0.0,0.15044592,53.795704,7.6835294,501.2659,-9.2037106
2512,2512,212.0342,4.9802723,2.1254129,0.0,0,7.0571475,0.0,0.15271133,54.338028,7.6611643,501.27969,-9.2036142
2513,2513,212.0344,5.0406528,2.1527555,0.0,0,7.0319633,0.0,0.15440208,54.875694,7.6387587,501.29349,-9.2029886
2514,2514,212.0346,5.1019812,2.1765428,0.0,0,7.0067792,0.0,0.15627922,55.394382,7.6162257,501.30725,-9.2028837
2515,2515,212.0348,5.1485834,2.1963866,0.0,0,6.981595,0.0,0.15822442,55.82436,7.5938225,501.32104,-9.2025957
2516,2516,212.035,5.1449313,2.2228632,0.0,0,6.9564114,0.0,0.15983506,55.876335,7.5710154,501.33484,-9.2018919
2517,2517,212.0352,5.0905161,2.2521243,0.0,0,6.9312277,0.0,0.16200164,55.284115,7.54494,501.3486,-9.2020855
2518,2518,212.0354,5.0482693,2.2752202,0.0,0,6.9060431,0.0,0.1644299,54.586037,7.5207019,501.3624,-9.2026873
2519,2519,212.0356,5.0629773,2.2998698,0.0,0,6.8808594,0.0,0.16613813,54.49379,7.4972701,501.37619,-9.202775
2520,2520,212.0358,5.123251,2.3205667,0.0,0,6.8556757,0.0,0.16754591,54.989449,7.473218,501.38995,-9.2034597
2521,2521,212.036,5.1904254,2.3354762,0.0,0,6.830492,0.0,0.1691771,55.664413,7.4497943,501.40375,-9.2035255
2522,2522,212.0362,5.2321563,2.3632915,0.0,0,6.8053074,0.0,0.17103361,56.128941,7.4247131,501.41754,-9.203022
2523,2523,212.0364,5.2446961,2.3932664,0.0,0,6.7801232,0.0,0.17304698,56.208462,7.401485,501.4313,-9.2029629
2524,2524,212.0366,5.2468753,2.4106717,0.0,0,6.7554417,0.0,0.1750285,56.090263,7.3793511,501.4451,-9.2028828
2525,2525,212.0368,5.2410145,2.4329648,0.0,0,6.7313671,0.0,0.17675194,55.94788,7.3570719,501.45889,-9.2027264
2526,2526,212.037,5.2447391,2.458288,0.0,0,6.7074022,0.0,0.17827399,55.891186,7.333147,501.47266,-9.2020741
2527,2527,212.0372,5.2636843,2.475457,0.0,0,6.6834416,0.0,0.18008551,55.947731,7.308918,501.48645,-9.2017574
2528,2528,212.0374,5.2843213,2.5020533,0.0,0,6.6594815,0.0,0.18223581,56.045815,7.287241,501.50021,-9.2019005
2529,2529,212.0376,5.3165593,2.5312493,0.0,0,6.6355219,0.0,0.18406412,56.28981,7.2645307,501.51401,-9.2020254
2530,2530,212.0378,5.3611674,2.5445235,0.0,0,6.6115613,0.0,0.1856177,56.65414,7.2397957,501.5278,-9.2027273
2531,2531,212.038,5.4062567,2.5662305,0.0,0,6.5876017,0.0,0.18749173,56.958275,7.2169003,501.54156,-9.203084
2532,2532,212.0382,5.4317632,2.5971196,0.0,0,6.5636415,0.0,0.18935287,57.155056,7.1941934,501.55536,-9.2031002
2533,2533,212.0384,5.4262033,2.6160984,0.0,0,6.5396819,0.0,0.19121069,57.09222,7.1702218,501.56915,-9.2030973
2534,2534,212.0386,5.4209652,2.6411262,0.0,0,6.5157218,0.0,0.19358183,56.948776,7.1486773,501.58292,-9.2034931
2535,2535,212.0388,5.444438,2.6690571,0.0,0,6.4917622,0.0,0.1953225,57.008587,7.1244955,501.59671,-9.2034655
2536,2536,212.039,5.4825244,2.6819742,0.0,0,6.467802,0.0,0.19651347,57.230606,7.1012077,501.6105,-9.2029133
2537,2537,212.0392,5.5358844,2.7037432,0.0,0,6.4438419,0.0,0.19864072,57.596897,7.0782251,501.62427,-9.2029486
2538,2538,212.0394,5.5833931,2.7363949,0.0,0,6.4198818,0.0,0.20075229,57.976074,7.0522623,501.63806,-9.2026939
2539,2539,212.0396,5.5991817,2.7557771,0.0,0,6.3959212,0.0,0.20239958,58.183735,7.0280318,501.65186,-9.2026634
2540,2540,212.0398,5.6011438,2.7754204,0.0,0,6.3719616,0.0,0.20457569,58.105083,7.0047259,501.66562,-9.2027693
2541,2541,212.04,5.6162701,2.8033619,0.0,0,6.3480015,0.0,0.20647244,58.114861,6.9805121,501.67941,-9.2022438
2542,2542,212.0402,5.6606636,2.8232579,0.0,0,6.3240418,0.0,0.20785046,58.481743,6.9569745,501.69318,-9.2029095
2543,2543,212.0404,5.727704,2.8470302,0.0,0,6.3000817,0.0,0.21024777,58.958252,6.9341664,501.5723,-9.2041836
2544,2544,212.0406,5.7686329,2.8770123,0.0,0,6.2761221,0.0,0.21260299,59.305664,6.9106832,501.39365,-9.203661
2545,2545,212.0408,5.798378,2.896342,0.0,0,6.252162,0.0,0.21394221,59.574268,6.8875575,501.21503,-9.2031221
2546,2546,212.041,5.8494864,2.9156456,0.0,0,6.2282019,0.0,0.2159421,59.864674,6.865005,501.03641,-9.2031412
2547,2547,212.0412,5.8878431,2.9431555,0.0,0,6.2042422,0.0,0.21814629,60.134487,6.8384995,500.85776,-9.2024107
2548,2548,212.0414,5.9058499,2.9683464,0.0,0,6.1802821,0.0,0.21978553,60.310543,6.8138909,500.67914,-9.2023354
2549,2549,212.0416,5.916223,2.9925239,0.0,0,6.1568027,0.0,0.22222163,60.2533,6.7913671,500.50049,-9.2029982
2550,2550,212.0418,5.9318404,3.0175986,0.0,0,6.1339049,0.0,0.22450678,60.230419,6.7672591,500.32187,-9.202507
2551,2551,212.042,5.975986,3.0382814,0.0,0,6.1111121,0.0,0.22578193,60.602093,6.7438011,500.14325,-9.2016678
2552,2552,212.0422,6.0424066,3.0599174,0.0,0,6.0883236,0.0,0.22778399,61.17849,6.7213454,499.9646,-9.2015266
2553,2553,212.0424,6.1094027,3.0858164,0.0,0,6.065536,0.0,0.23019855,61.752399,6.6971226,499.78598,-9.2021971
2554,2554,212.0426,6.1613822,3.1104908,0.0,0,6.042748,0.0,0.23186134,62.160591,6.6710019,499.60733,-9.2028437
2555,2555,212.0428,6.1876984,3.1322169,0.0,0,6.0199599,0.0,0.23380569,62.325001,6.6450329,499.42871,-9.2028828
2556,2556,212.043,6.198503,3.1530671,0.0,0,5.9971719,0.0,0.23592237,62.353455,6.6210766,499.25009,-9.2028141
2557,2557,212.0432,6.1956778,3.1773779,0.0,0,5.9743834,0.0,0.23745888,62.23143,6.5994282,499.07144,-9.2033463
2558,2558,212.0434,6.1732435,3.2015281,0.0,0,5.9515953,0.0,0.23952717,61.887905,6.5735545,498.89282,-9.2036095
2559,2559,212.0436,6.1579089,3.2240803,0.0,0,5.9288077,0.0,0.24204002,61.552437,6.5474992,498.71417,-9.2036495
2560,2560,212.0438,6.1751447,3.2520404,0.0,0,5.9060202,0.0,0.24392287,61.523449,6.5256948,498.53555,-9.2035666
2561,2561,212.044,6.2265954,3.2768772,0.0,0,5.8832321,0.0,0.24585401,61.838142,6.5017424,498.35693,-9.2035284
2562,2562,212.0442,6.2919922,3.2968767,0.0,0,5.8604436,0.0,0.24813662,62.328949,6.4768524,498.17828,-9.2034569
2563,2563,212.0444,6.3502154,3.3257411,0.0,0,5.8376555,0.0,0.25018188,62.845409,6.4542561,497.99966,-9.2016888
2564,2564,212.0446,6.3940468,3.353857,0.0,0,5.8148675,0.0,0.2523396,63.184067,6.429534,497.82104,-9.2008991
2565,2565,212.0448,6.4220653,3.3735797,0.0,0,5.792079,0.0,0.25470629,63.303516,6.4043093,497.6424,-9.2006006
2566,2566,212.045,6.4451299,3.3998172,0.0,0,5.7692914,0.0,0.25673532,63.387753,6.3779392,497.46378,-9.2005758
2567,2567,212.0452,6.4782104,3.4265547,0.0,0,5.7465038,0.0,0.25856718,63.574711,6.3520169,497.28513,-9.2013874
2568,2568,212.0454,6.5296268,3.4444604,0.0,0,5.7237153,0.0,0.26073831,63.934082,6.3290715,497.10651,-9.2021055
2569,2569,212.0456,6.5892682,3.4709809,0.0,0,5.7009277,0.0,0.26297122,64.370567,6.3059311,496.92789,-9.2028265
2570,2570,212.0458,6.6623011,3.4991758,0.0,0,5.6781397,0.0,0.26483226,64.874214,6.2822437,496.74924,-9.2029762
2571,2571,212.046,6.7361817,3.5134737,0.0,0,5.6553516,0.0,0.26667094,65.415985,6.2572374,496.57062,-9.2029696
2572,2572,212.0462,6.7958865,3.536438,0.0,0,5.6325636,0.0,0.26875699,65.973198,6.2325878,496.39197,-9.2024136
2573,2573,212.0464,6.8546958,3.5666287,0.0,0,5.6097755,0.0,0.27063188,66.483757,6.210012,496.21335,-9.2022362
2574,2574,212.0466,6.9186535,3.5852151,0.0,0,5.5874419,0.0,0.2726506,66.933708,6.1870623,496.03473,-9.2021942
2575,2575,212.0468,6.9616094,3.6100767,0.0,0,5.5656581,0.0,0.27512431,67.206833,6.1634097,495.85608,-9.2016354
2576,2576,212.047,6.9904141,3.6407888,0.0,0,5.5439739,0.0,0.27714121,67.365181,6.1393709,495.67746,-9.2015648
2577,2577,212.0472,7.0375233,3.6579583,0.0,0,5.5222936,0.0,0.27896518,67.625221,6.1174841,495.49881,-9.201272
2578,2578,212.0474,7.06531,3.6818538,0.0,0,5.5006137,0.0,0.28149351,67.76757,6.0919838,495.32019,-9.2012615
2579,2579,212.0476,7.0818253,3.7133775,0.0,0,5.4789333,0.0,0.28363475,67.886574,6.06599,495.14157,-9.2015429
2580,2580,212.0478,7.1184697,3.7312436,0.0,0,5.4572535,0.0,0.28537515,68.093521,6.0425177,494.96292,-9.2021027
2581,2581,212.048,7.1619406,3.753377,0.0,0,5.4355736,0.0,0.28790078,68.316269,6.0177732,494.7843,-9.2025623
2582,2582,212.0482,7.2035217,3.782805,0.0,0,5.4138937,0.0,0.29000261,68.58786,5.9931092,494.60565,-9.2019272
2583,2583,212.0484,7.2312779,3.8018284,0.0,0,5.3922133,0.0,0.29163194,68.819183,5.9696498,494.42703,-9.2014961
2584,2584,212.0486,7.2583823,3.8250957,0.0,0,5.3705335,0.0,0.29424486,68.875214,5.9441409,494.24841,-9.2014294
2585,2585,212.0488,7.298327,3.8560781,0.0,0,5.3488536,0.0,0.29663342,68.963547,5.9168587,494.06976,-9.2010088
2586,2586,212.049,7.3347178,3.8775284,0.0,0,5.3271737,0.0,0.29830468,69.227013,5.8955355,493.89114,-9.2010355
2587,2587,212.0492,7.347683,3.8993709,0.0,0,5.3054934,0.0,0.30083913,69.229446,5.8723006,493.71249,-9.2018251
2588,2588,212.0494,7.3536973,3.9281414,0.0,0,5.2838135,0.0,0.30330759,69.168816,5.8463702,493.53387,-9.2024593
2589,2589,212.0496,7.3892622,3.9504619,0.0,0,5.2621331,0.0,0.30495912,69.353378,5.822289,493.35526,-9.2022581
2590,2590,212.0498,7.4287009,3.9723938,0.0,0,5.2404532,0.0,0.30740649,69.516617,5.7976575,493.17661,-9.2024298
2591,2591,212.05,7.4562373,3.9997537,0.0,0,5.2187734,0.0,0.30982795,69.646751,5.7732406,492.99799,-9.2030334
2592,2592,212.0502,7.4982233,4.0216861,0.0,0,5.1970935,0.0,0.31131157,69.879601,5.7498255,492.81937,-9.2024937
2593,2593,212.0504,7.5376711,4.0424976,0.0,0,5.1754136,0.0,0.31370297,70.023094,5.7266102,492.59915,-9.2026272
2594,2594,212.0506,7.5625973,4.0676265,0.0,0,5.1537337,0.0,0.31622019,70.049828,5.7048779,492.37433,-9.2025394
2595,2595,212.0508,7.581933,4.0904107,0.0,0,5.1320534,0.0,0.31775165,70.193092,5.6808705,492.14951,-9.2021723
2596,2596,212.051,7.5974641,4.1117153,0.0,0,5.1103735,0.0,0.32003123,70.250427,5.6557078,491.92468,-9.2020187
2597,2597,212.0512,7.6123075,4.1361375,0.0,0,5.0886931,0.0,0.32260853,70.219193,5.6317549,491.69986,-9.2020082
2598,2598,212.0514,7.6261783,4.1618037,0.0,0,5.0670133,0.0,0.32431063,70.228653,5.6062374,491.47504,-9.2027225
2599,2599,212.0516,7.6433673,4.1850023,0.0,0,5.0457683,0.0,0.32654276,70.142998,5.5835562,491.25021,-9.2028723
2600,2600,212.0518,7.6643782,4.2076693,0.0,0,5.0250487,0.0,0.32915375,70.119591,5.5632367,491.02539,-9.2028265
2601,2601,212.052,7.6946015,4.2338648,0.0,0,5.0044241,0.0,0.33098277,70.328239,5.5402584,490.80057,-9.2027206
2602,2602,212.0522,7.7307138,4.2574,0.0,0,4.9838042,0.0,0.3331548,70.471825,5.5139785,490.57574,-9.20257
2603,2603,212.0524,7.7639761,4.2767968,0.0,0,4.9631839,0.0,0.3356289,70.569511,5.4889407,490.35092,-9.2022371
2604,2604,212.0526,7.7863517,4.3031869,0.0,0,4.942564,0.0,0.33757406,70.664154,5.4654479,490.1261,-9.2017612
2605,2605,212.0528,7.7946863,4.3276858,0.0,0,4.9219441,0.0,0.3396695,70.633789,5.440475,489.90128,-9.2020111
2606,2606,212.053,7.8003597,4.3445683,0.0,0,4.9013243,0.0,0.34204954,70.561157,5.418117,489.67645,-9.2019987
2607,2607,212.0532,7.8140321,4.3695068,0.0,0,4.8807039,0.0,0.34404278,70.52758,5.3975391,489.45163,-9.2024746
2608,2608,212.0534,7.829124,4.3944545,0.0,0,4.8600841,0.0,0.34591067,70.481964,5.3746095,489.22681,-9.2031851
2609,2609,212.0536,7.8434052,4.4109907,0.0,0,4.8394642,0.0,0.3481783,70.445351,5.3499713,489.00198,-9.2035275
2610,2610,212.0538,7.873878,4.4371557,0.0,0,4.8188443,0.0,0.35041264,70.544571,5.3271613,488.77716,-9.2035408
2611,2611,212.054,7.9076719,4.4650083,0.0,0,4.798224,0.0,0.35243002,70.689568,5.3057575,488.55234,-9.2028112
2612,2612,212.0542,7.9417043,4.480587,0.0,0,4.7776041,0.0,0.35458481,70.833778,5.2862024,488.32751,-9.2020388
2613,2613,212.0544,7.9663167,4.50495,0.0,0,4.7569842,0.0,0.35683331,70.903282,5.2649889,488.10269,-9.2014017
2614,2614,212.0546,7.968976,4.5337548,0.0,0,4.7363639,0.0,0.35888964,70.830856,5.2394543,487.87787,-9.2013817
2615,2615,212.0548,7.9792027,4.5497799,0.0,0,4.715744,0.0,0.36109003,70.758255,5.2161083,487.65305,-9.2015419
2616,2616,212.055,7.9972329,4.5739017,0.0,0,4.6951241,0.0,0.36358672,70.766106,5.1959171,487.42822,-9.2017317
2617,2617,212.0552,8.0112991,4.6030312,0.0,0,4.6745043,0.0,0.36555877,70.768822,5.1742086,487.2034,-9.202158
2618,2618,212.0554,8.0331678,4.6175833,0.0,0,4.6538844,0.0,0.36743802,70.78019,5.1474776,486.97858,-9.2025604
2619,2619,212.0556,8.0571489,4.6412048,0.0,0,4.6332641,0.0,0.37013364,70.783745,5.1261816,486.75375,-9.2023363
2620,2620,212.0558,8.0912399,4.6719246,0.0,0,4.6126437,0.0,0.37236106,70.934326,5.105124,486.52893,-9.2024927
2621,2621,212.056,8.1315365,4.6871572,0.0,0,4.5920238,0.0,0.3741644,71.202301,5.0808735,486.30411,-9.2022095
2622,2622,212.0562,8.1627254,4.7086201,0.0,0,4.571404,0.0,0.37671676,71.340744,5.0578995,486.07928,-9.2007523
2623,2623,212.0564,8.186738,4.7374368,0.0,0,4.5507841,0.0,0.37873235,71.401329,5.03302,485.85446,-9.2001095
2624,2624,212.0566,8.205657,4.7539487,0.0,0,4.5305758,0.0,0.38048503,71.425491,5.0112023,485.62964,-9.2007799
2625,2625,212.0568,8.2188807,4.7752833,0.0,0,4.5108657,0.0,0.38327184,71.307426,4.9932766,485.40482,-9.2010956
2626,2626,212.057,8.2280064,4.8039432,0.0,0,4.4912457,0.0,0.38547927,71.174194,4.9731169,485.17999,-9.201623
2627,2627,212.0572,8.23102,4.8210173,0.0,0,4.4716296,0.0,0.38703489,71.179375,4.950191,484.95517,-9.2019129
2628,2628,212.0574,8.248847,4.8413901,0.0,0,4.4520135,0.0,0.38971424,71.169968,4.9275432,484.73035,-9.201684
2629,2629,212.0576,8.2703791,4.8702655,0.0,0,4.4323978,0.0,0.39215896,71.179665,4.9055457,484.50552,-9.2017069
2630,2630,212.0578,8.2900057,4.8894353,0.0,0,4.4127817,0.0,0.39365512,71.280991,4.882535,484.2807,-9.2015934
2631,2631,212.058,8.320653,4.9089561,0.0,0,4.3931656,0.0,0.39624742,71.29245,4.8597803,484.05588,-9.2015448
2632,2632,212.0582,8.3470135,4.9351897,0.0,0,4.3735499,0.0,0.39878362,71.306763,4.8385015,483.83105,-9.2014351
2633,2633,212.0584,8.3709793,4.9546804,0.0,0,4.3539338,0.0,0.40017048,71.414833,4.8160543,483.60623,-9.2015028
2634,2634,212.0586,8.3879328,4.9738059,0.0,0,4.3343177,0.0,0.4025971,71.380035,4.7928534,483.38141,-9.201458
2635,2635,212.0588,8.3904066,4.9990764,0.0,0,4.314702,0.0,0.40522254,71.295555,4.7703691,483.15659,-9.2015343
2636,2636,212.059,8.3919449,5.0197616,0.0,0,4.2950859,0.0,0.40670782,71.234581,4.7495627,482.93176,-9.2017269
2637,2637,212.0592,8.3975363,5.0389733,0.0,0,4.2754698,0.0,0.40906763,71.036583,4.7277131,482.70694,-9.2014933
2638,2638,212.0594,8.4117622,5.0620675,0.0,0,4.2558532,0.0,0.41171166,70.911499,4.7076774,482.48212,-9.2014999
2639,2639,212.0596,8.4389238,5.0842805,0.0,0,4.2362375,0.0,0.41320699,71.016083,4.6843896,482.25732,-9.201787
2640,2640,212.0598,8.4697275,5.105103,0.0,0,4.2166214,0.0,0.41549537,71.153923,4.66012,482.0325,-9.2023382
2641,2641,212.06,8.5065174,5.1261129,0.0,0,4.1970053,0.0,0.41810864,71.275589,4.6400933,481.80768,-9.2029171
2642,2642,212.0602,8.5481968,5.1476359,0.0,0,4.1773896,0.0,0.41964993,71.465096,4.6196256,481.60446,-9.2024765
2643,2643,212.0604,8.6038971,5.1668129,0.0,0,4.1577735,0.0,0.42165923,71.774353,4.5975671,481.59607,-9.2014408
2644,2644,212.0606,8.6580067,5.1851535,0.0,0,4.1381574,0.0,0.42417774,72.07621,4.5757623,481.58768,-9.2011099
2645,2645,212.0608,8.68715,5.2094383,0.0,0,4.1185417,0.0,0.42593786,72.195442,4.5565782,481.57928,-9.2013636
2646,2646,212.061,8.7033882,5.2307758,0.0,0,4.0989256,0.0,0.4279249,72.169098,4.5369158,481.57089,-9.2011127
2647,2647,212.0612,8.7307377,5.2474241,0.0,0,4.0793095,0.0,0.43053994,72.20166,4.5141778,481.5625,-9.2010736
2648,2648,212.0614,8.7737017,5.2716818,0.0,0,4.0596938,0.0,0.43255275,72.426834,4.491909,481.55411,-9.2012415
2649,2649,212.0616,8.8094482,5.294178,0.0,0,4.0404716,0.0,0.43455285,72.615128,4.4708014,481.54568,-9.2013206
2650,2650,212.0618,8.8351727,5.3098783,0.0,0,4.0217257,0.0,0.43704027,72.683304,4.4517279,481.53729,-9.2022152
2651,2651,212.062,8.8697977,5.3343534,0.0,0,4.0030656,0.0,0.43913245,72.814766,4.4309878,481.5289,-9.2029533
2652,2652,212.0622,8.910449,5.3575573,0.0,0,3.9844093,0.0,0.44096488,72.977631,4.4096885,481.52051,-9.20294
2653,2653,212.0624,8.9376917,5.3703375,0.0,0,3.9657533,0.0,0.44322011,73.023994,4.3907242,481.51212,-9.2029428
2654,2654,212.0626,8.9480209,5.3934822,0.0,0,3.9470973,0.0,0.44540954,72.958542,4.3726158,481.50372,-9.2024078
2655,2655,212.0628,8.9602308,5.419179,0.0,0,3.9284413,0.0,0.44728559,72.895302,4.350441,481.4953,-9.2022152
2656,2656,212.063,8.9734602,5.4313955,0.0,0,3.9097853,0.0,0.44942111,72.893394,4.3277216,481.48691,-9.2019949
2657,2657,212.0632,8.9901772,5.45262,0.0,0,3.8911293,0.0,0.45168626,72.90065,4.3078513,481.47852,-9.2011299
2658,2658,212.0634,9.0138788,5.4795794,0.0,0,3.8724735,0.0,0.45358866,72.880829,4.2868342,481.47012,-9.2005453
2659,2659,212.0636,9.0455875,5.4921374,0.0,0,3.8538175,0.0,0.4556191,72.967728,4.2672739,481.46173,-9.2011681
2660,2660,212.0638,9.0711279,5.5138221,0.0,0,3.8351612,0.0,0.45821068,73.07962,4.2484531,481.45334,-9.2010393
2661,2661,212.064,9.0986195,5.5424166,0.0,0,3.8165054,0.0,0.4602814,73.139946,4.2304974,481.44492,-9.2006559
2662,2662,212.0642,9.1303663,5.5554924,0.0,0,3.7978494,0.0,0.46214962,73.195236,4.2107949,481.43652,-9.2020283
2663,2663,212.0644,9.1446199,5.5750728,0.0,0,3.7791932,0.0,0.46476191,73.179611,4.1918321,481.42813,-9.2026634
2664,2664,212.0646,9.154397,5.6022482,0.0,0,3.7605371,0.0,0.46677843,73.085403,4.1719718,481.41974,-9.2025547
2665,2665,212.0648,9.1542063,5.6155167,0.0,0,3.7418811,0.0,0.46850672,72.950096,4.1499772,481.41135,-9.2025604
2666,2666,212.065,9.1549149,5.6344042,0.0,0,3.7232254,0.0,0.47116888,72.846237,4.1294856,481.40295,-9.2027636
2667,2667,212.0652,9.1742001,5.6606655,0.0,0,3.7045693,0.0,0.47315967,72.829544,4.1082506,481.39453,-9.2023993
2668,2668,212.0654,9.2041359,5.6735435,0.0,0,3.6859133,0.0,0.47447655,72.878365,4.0887942,481.38614,-9.2022314
2669,2669,212.0656,9.2340412,5.6904111,0.0,0,3.6672573,0.0,0.47699198,72.889061,4.0700674,481.37775,-9.2020597
2670,2670,212.0658,9.2696562,5.7168274,0.0,0,3.6486013,0.0,0.47924244,72.984215,4.0505528,481.36935,-9.201457
2671,2671,212.066,9.2936068,5.7321439,0.0,0,3.6299453,0.0,0.48067698,73.122429,4.0312319,481.36096,-9.2007704
2672,2672,212.0662,9.3106995,5.7494721,0.0,0,3.6112893,0.0,0.48339251,73.109825,4.0134802,481.35257,-9.200038
2673,2673,212.0664,9.3278074,5.7755413,0.0,0,3.5926332,0.0,0.48589268,73.058083,3.9946816,481.34418,-9.1999283
2674,2674,212.0666,9.3313847,5.7921243,0.0,0,3.5743496,0.0,0.48723045,73.029327,3.9732611,481.33575,-9.2004604
2675,2675,212.0668,9.3404074,5.8092294,0.0,0,3.5565166,0.0,0.48976576,72.89196,3.9543869,481.32736,-9.2012177
2676,2676,212.067,9.3515949,5.8347096,0.0,0,3.538765,0.0,0.49244979,72.753792,3.9348953,481.31897,-9.2020693
2677,2677,212.0672,9.3688936,5.8531098,0.0,0,3.5210168,0.0,0.49378619,72.788147,3.9162862,481.31058,-9.2028122
2678,2678,212.0674,9.3968191,5.8691196,0.0,0,3.5032687,0.0,0.49617818,72.822266,3.8953824,481.30219,-9.2026968
2679,2679,212.0676,9.4225674,5.8907661,0.0,0,3.4855206,0.0,0.49877176,72.793144,3.8744049,481.29379,-9.2021112
2680,2680,212.0678,9.4490452,5.9089627,0.0,0,3.4677727,0.0,0.50005931,72.900505,3.8566899,481.28537,-9.201601
2681,2681,212.068,9.4711542,5.9251175,0.0,0,3.4500248,0.0,0.5023151,72.942474,3.836587,481.27698,-9.2013206
2682,2682,212.0682,9.4875689,5.9456792,0.0,0,3.432277,0.0,0.50488275,72.84095,3.8176227,481.26859,-9.2005539
2683,2683,212.0684,9.5058193,5.9657993,0.0,0,3.4145288,0.0,0.506266,72.882393,3.7990785,481.26019,-9.1999216
2684,2684,212.0686,9.5190477,5.9828949,0.0,0,3.3967807,0.0,0.50845033,72.88221,3.7787085,481.2518,-9.2006006
2685,2685,212.0688,9.5285692,6.0009642,0.0,0,3.3790326,0.0,0.51113135,72.766411,3.7600133,481.24341,-9.2013292
2686,2686,212.069,9.5386486,6.0224776,0.0,0,3.3612847,0.0,0.51268953,72.746895,3.7419517,481.23499,-9.2007542
2687,2687,212.0692,9.5509071,6.0425682,0.0,0,3.3435369,0.0,0.51486504,72.704857,3.7234235,481.22659,-9.2005777
2688,2688,212.0694,9.5685749,6.0598841,0.0,0,3.3257887,0.0,0.51766425,72.625473,3.7039614,481.2182,-9.2014637
2689,2689,212.0696,9.5918322,6.0837836,0.0,0,3.3080409,0.0,0.51958072,72.635567,3.6853859,481.20981,-9.2023878
2690,2690,212.0698,9.625577,6.1045289,0.0,0,3.2902927,0.0,0.52161139,72.67749,3.667032,481.20142,-9.2022095
2691,2691,212.07,9.6512041,6.1182733,0.0,0,3.2725446,0.0,0.52417415,72.692894,3.6480279,481.19302,-9.2016563
2692,2692,212.0702,9.6658278,6.1409841,0.0,0,3.2547965,0.0,0.52615893,72.718231,3.6305583,481.16769,-9.2018604
2693,2693,212.0704,9.6859198,6.1614375,0.0,0,3.2370486,0.0,0.52799886,72.741615,3.6109715,481.10291,-9.2016563
2694,2694,212.0706,9.6978388,6.1732526,0.0,0,3.2193007,0.0,0.53036731,72.62973,3.5901415,481.03812,-9.2009478
2695,2695,212.0708,9.7003279,6.1949625,0.0,0,3.2015526,0.0,0.53249598,72.467163,3.5718138,480.97333,-9.2001991
2696,2696,212.071,9.7064037,6.2166271,0.0,0,3.1838048,0.0,0.53426218,72.356606,3.5550497,480.90851,-9.2004299
2697,2697,212.0712,9.7205973,6.2280583,0.0,0,3.1660566,0.0,0.53649449,72.312523,3.5373628,480.84372,-9.2009649
2698,2698,212.0714,9.7377081,6.2502718,0.0,0,3.1483088,0.0,0.53883868,72.331665,3.5169139,480.77893,-9.200532
2699,2699,212.0716,9.7680387,6.2749729,0.0,0,3.1309152,0.0,0.54072362,72.397255,3.4971771,480.71414,-9.2012568
2700,2700,212.0718,9.8058653,6.2851939,0.0,0,3.11395,0.0,0.54283249,72.450142,3.4798186,480.64935,-9.2019625
2701,2701,212.072,9.8358421,6.3043094,0.0,0,3.0970623,0.0,0.54529113,72.480614,3.4623981,480.58456,-9.2016563
2702,2702,212.0722,9.8568592,6.3288035,0.0,0,3.0801783,0.0,0.54708767,72.572884,3.4444141,480.51974,-9.2023344
2703,2703,212.0724,9.8680649,6.3395805,0.0,0,3.0632944,0.0,0.54891968,72.582481,3.4248636,480.45496,-9.2027092
2704,2704,212.0726,9.8778057,6.3594522,0.0,0,3.0464106,0.0,0.55157971,72.451584,3.4053073,480.39017,-9.2025595
2705,2705,212.0728,9.8889608,6.386723,0.0,0,3.0295265,0.0,0.55367708,72.406509,3.3869424,480.32538,-9.2021599
2706,2706,212.073,9.9005318,6.3985281,0.0,0,3.0126424,0.0,0.55553943,72.366676,3.3716977,480.26059,-9.2016392
2707,2707,212.0732,9.9236908,6.4169354,0.0,0,2.9957583,0.0,0.55834353,72.271744,3.3534007,480.1958,-9.201375
2708,2708,212.0734,9.9533367,6.4435663,0.0,0,2.9788744,0.0,0.5604735,72.308937,3.3333719,480.13098,-9.2005234
2709,2709,212.0736,9.9849854,6.4547276,0.0,0,2.9619906,0.0,0.5619964,72.430984,3.3155429,480.06619,-9.200366
2710,2710,212.0738,10.019513,6.4712305,0.0,0,2.9451065,0.0,0.56473374,72.490334,3.2987847,480.0014,-9.2004042
2711,2711,212.074,10.050223,6.4968915,0.0,0,2.9282222,0.0,0.56687433,72.538521,3.2819054,479.93661,-9.2006121
2712,2712,212.0742,10.075227,6.5089188,0.0,0,2.9113381,0.0,0.56822985,72.623627,3.2619796,479.87183,-9.2014008
2713,2713,212.0744,10.095243,6.5243917,0.0,0,2.8944542,0.0,0.5710268,72.561943,3.2417867,479.80704,-9.2027178
2714,2714,212.0746,10.105879,6.5496716,0.0,0,2.8775704,0.0,0.57337356,72.462654,3.2225637,479.74222,-9.2035046
2715,2715,212.0748,10.11018,6.5642953,0.0,0,2.8606863,0.0,0.57470232,72.457916,3.2060773,479.67743,-9.2028875
2716,2716,212.075,10.121264,6.580039,0.0,0,2.8438022,0.0,0.57746428,72.357094,3.1892495,479.61264,-9.2022467
2717,2717,212.0752,10.143162,6.6042619,0.0,0,2.8269184,0.0,0.58000368,72.282707,3.1712325,479.54785,-9.2013216
2718,2718,212.0754,10.176286,6.6198907,0.0,0,2.810034,0.0,0.58122087,72.398918,3.1533248,479.48306,-9.2012444
2719,2719,212.0756,10.204377,6.6352673,0.0,0,2.7931502,0.0,0.58386004,72.46965,3.1348004,479.41824,-9.2006521
2720,2720,212.0758,10.239324,6.6587663,0.0,0,2.7762663,0.0,0.58664811,72.537949,3.1188517,479.35345,-9.1997509
2721,2721,212.076,10.276114,6.6768255,0.0,0,2.7593822,0.0,0.58800048,72.636238,3.1022925,479.28867,-9.2000189
2722,2722,212.0762,10.297115,6.6924562,0.0,0,2.7424984,0.0,0.59061724,72.592087,3.0812168,479.22388,-9.2008162
2723,2723,212.0764,10.303452,6.7132602,0.0,0,2.7256143,0.0,0.59346759,72.461998,3.0633662,479.15909,-9.2015619
2724,2724,212.0766,10.292299,6.7312441,0.0,0,2.7090683,0.0,0.59477919,72.26358,3.0474451,479.0943,-9.2015839
2725,2725,212.0768,10.292557,6.7461901,0.0,0,2.6929309,0.0,0.59705299,72.117996,3.0296824,479.02948,-9.2021217
2726,2726,212.077,10.318809,6.7645054,0.0,0,2.6768677,0.0,0.59987384,72.091629,3.0110946,478.96469,-9.2021132
2727,2727,212.0772,10.345422,6.783865,0.0,0,2.6608074,0.0,0.60126406,72.141693,2.9923761,478.8999,-9.2010708
2728,2728,212.0774,10.365454,6.7997532,0.0,0,2.6447473,0.0,0.60337853,72.124687,2.9747539,478.83511,-9.2010698
2729,2729,212.0776,10.389413,6.8157473,0.0,0,2.6286874,0.0,0.60612363,72.077736,2.9582946,478.77032,-9.2010088
2730,2730,212.0778,10.420312,6.8357282,0.0,0,2.6126273,0.0,0.60756505,72.230667,2.9400575,478.70554,-9.2009506
2731,2731,212.078,10.44309,6.8525176,0.0,0,2.5965672,0.0,0.60958916,72.2798,2.9215839,478.64072,-9.2011814
2732,2732,212.0782,10.451098,6.8662596,0.0,0,2.5805073,0.0,0.61232662,72.162651,2.90557,478.57593,-9.201726
2733,2733,212.0784,10.455616,6.8876095,0.0,0,2.5644474,0.0,0.61404151,72.045692,2.8878634,478.51114,-9.2019253
2734,2734,212.0786,10.463197,6.90623,0.0,0,2.5483873,0.0,0.61599106,71.899109,2.8706543,478.44635,-9.2021112
2735,2735,212.0788,10.478705,6.9182272,0.0,0,2.5323272,0.0,0.61873519,71.822243,2.8538604,478.38156,-9.2018404
2736,2736,212.079,10.486421,6.9397097,0.0,0,2.5162673,0.0,0.62072045,71.785843,2.8356318,478.31677,-9.2011309
2737,2737,212.0792,10.496659,6.9592962,0.0,0,2.5002072,0.0,0.62247413,71.729446,2.8189087,478.25195,-9.201087
2738,2738,212.0794,10.527518,6.9686012,0.0,0,2.4841473,0.0,0.62485808,71.720047,2.8025014,478.18716,-9.2009192
2739,2739,212.0796,10.560854,6.9883127,0.0,0,2.4680872,0.0,0.62691343,71.770302,2.78526,478.12238,-9.2004604
2740,2740,212.0798,10.587419,7.0095234,0.0,0,2.4520273,0.0,0.62865412,71.873154,2.7683871,478.05759,-9.2002831
2741,2741,212.08,10.613505,7.0197144,0.0,0,2.4359674,0.0,0.63097733,71.925255,2.7499907,477.9928,-9.2004137
2742,2742,212.0802,10.635365,7.0404267,0.0,0,2.4199073,0.0,0.63349473,71.846916,2.7335966,477.83435,-9.2007446
2743,2743,212.0804,10.641381,7.0640292,0.0,0,2.4038472,0.0,0.63542926,71.731659,2.7185762,477.58228,-9.2013483
2744,2744,212.0806,10.644304,7.0737576,0.0,0,2.3877873,0.0,0.63757205,71.579155,2.7014925,477.33017,-9.2013588
2745,2745,212.0808,10.655665,7.0928655,0.0,0,2.3717272,0.0,0.64026123,71.479263,2.6838248,477.07809,-9.2018881
2746,2746,212.081,10.671261,7.1171713,0.0,0,2.3556671,0.0,0.64212728,71.470924,2.6681366,476.82599,-9.2019253
2747,2747,212.0812,10.694472,7.1259446,0.0,0,2.3396072,0.0,0.64402777,71.473846,2.651284,476.57391,-9.2011003
2748,2748,212.0814,10.718412,7.1428447,0.0,0,2.3235474,0.0,0.64684612,71.440147,2.6337085,476.32181,-9.2008705
2749,2749,212.0816,10.748049,7.1671901,0.0,0,2.3078089,0.0,0.64867556,71.493652,2.6176374,476.06973,-9.2004271
2750,2750,212.0818,10.774981,7.1761208,0.0,0,2.2924595,0.0,0.65024233,71.597862,2.6005726,475.81766,-9.2003946
2751,2751,212.082,10.788621,7.1911902,0.0,0,2.2771804,0.0,0.65300781,71.532272,2.5835314,475.56555,-9.2005758
2752,2752,212.0822,10.800027,7.2153068,0.0,0,2.2619042,0.0,0.65495634,71.439453,2.5678742,475.31348,-9.2003527
2753,2753,212.0824,10.803617,7.2249179,0.0,0,2.246628,0.0,0.6564132,71.353195,2.5521307,475.06137,-9.2008991
2754,2754,212.0826,10.802981,7.240231,0.0,0,2.2313523,0.0,0.65940547,71.178352,2.5366652,474.8093,-9.2015705
2755,2755,212.0828,10.815501,7.2654266,0.0,0,2.2160764,0.0,0.66169548,71.082565,2.5202944,474.55719,-9.2023363
2756,2756,212.083,10.841026,7.2761803,0.0,0,2.2008004,0.0,0.66284227,71.12236,2.5040789,474.30511,-9.2023296
2757,2757,212.0832,10.8701,7.2894568,0.0,0,2.1855242,0.0,0.6655463,71.081581,2.4874985,474.05301,-9.2017374
2758,2758,212.0834,10.900991,7.3134174,0.0,0,2.1702483,0.0,0.66802621,71.100967,2.4705465,473.80093,-9.2009907
2759,2759,212.0836,10.928033,7.3269358,0.0,0,2.1549723,0.0,0.66922361,71.247147,2.4550834,473.54886,-9.2000608
2760,2760,212.0838,10.944874,7.3402882,0.0,0,2.1396964,0.0,0.67207289,71.211906,2.4365141,473.29675,-9.2002039
2761,2761,212.084,10.959213,7.3625922,0.0,0,2.1244202,0.0,0.67476457,71.120018,2.4203269,473.04468,-9.2004766
2762,2762,212.0842,10.975522,7.3765111,0.0,0,2.1091442,0.0,0.67585921,71.123337,2.405992,472.79257,-9.2007589
2763,2763,212.0844,10.98584,7.3884463,0.0,0,2.0938683,0.0,0.67836076,70.940155,2.391475,472.5405,-9.2019157
2764,2764,212.0846,10.997373,7.4078393,0.0,0,2.0785923,0.0,0.68095493,70.786469,2.3748946,472.28839,-9.2020874
2765,2765,212.0848,11.009064,7.4230795,0.0,0,2.0633163,0.0,0.68204492,70.857399,2.3570783,472.03632,-9.2014303
2766,2766,212.085,11.028946,7.4356532,0.0,0,2.0480404,0.0,0.68451893,70.795471,2.3403978,471.78424,-9.2014236
2767,2767,212.0852,11.0539,7.4538856,0.0,0,2.0327644,0.0,0.68732667,70.708145,2.3231783,471.53214,-9.2011595
2768,2768,212.0854,11.073531,7.4710455,0.0,0,2.0174885,0.0,0.68839681,70.792122,2.3088689,471.28006,-9.2004986
2769,2769,212.0856,11.103034,7.4844956,0.0,0,2.0022123,0.0,0.69064867,70.854774,2.2947485,471.02795,-9.2007713
2770,2770,212.0858,11.131446,7.5011005,0.0,0,1.9869361,0.0,0.69361395,70.844971,2.2775302,470.77588,-9.2013664
2771,2771,212.086,11.15065,7.5196424,0.0,0,1.9716601,0.0,0.6949774,70.856544,2.2614939,470.52377,-9.2009726
2772,2772,212.0862,11.165168,7.5342751,0.0,0,1.9563841,0.0,0.69706929,70.81842,2.2466044,470.2717,-9.2009764
2773,2773,212.0864,11.184459,7.5487618,0.0,0,1.9411081,0.0,0.70007479,70.703804,2.2321339,470.01959,-9.2018938
2774,2774,212.0866,11.202038,7.5687251,0.0,0,1.9261373,0.0,0.70169425,70.647499,2.2149982,469.76752,-9.201539
2775,2775,212.0868,11.211582,7.5849113,0.0,0,1.9115355,0.0,0.70362246,70.59166,2.1980906,469.51544,-9.2005291
2776,2776,212.087,11.224535,7.5963802,0.0,0,1.8970004,0.0,0.70645016,70.509102,2.1807423,469.26334,-9.2006083
2777,2777,212.0872,11.242134,7.6157451,0.0,0,1.8824685,0.0,0.70824653,70.512619,2.1641541,469.01126,-9.2010393
2778,2778,212.0874,11.27109,7.6323891,0.0,0,1.8679364,0.0,0.70997649,70.53598,2.1508934,468.75916,-9.2012739
2779,2779,212.0876,11.302683,7.6420894,0.0,0,1.8534043,0.0,0.71264458,70.535049,2.1356459,468.50708,-9.2006121
2780,2780,212.0878,11.334591,7.662642,0.0,0,1.8388724,0.0,0.71481794,70.59108,2.1193917,468.25497,-9.199893
2781,2781,212.088,11.360975,7.6815953,0.0,0,1.8243403,0.0,0.71654648,70.60817,2.1045575,468.0029,-9.200511
2782,2782,212.0882,11.373313,7.6900268,0.0,0,1.8098084,0.0,0.71899539,70.541496,2.0881677,467.75079,-9.2011757
2783,2783,212.0884,11.384856,7.7085409,0.0,0,1.7952764,0.0,0.72121686,70.492401,2.0709808,467.49872,-9.2011871
2784,2784,212.0886,11.398323,7.7288084,0.0,0,1.7807443,0.0,0.7228328,70.409653,2.056704,467.24664,-9.2010288
2785,2785,212.0888,11.409142,7.736702,0.0,0,1.7662123,0.0,0.72509855,70.318855,2.0417554,466.99454,-9.2012596
2786,2786,212.089,11.425439,7.7547159,0.0,0,1.7516804,0.0,0.72763729,70.269104,2.0270009,466.74246,-9.201438
2787,2787,212.0892,11.454194,7.7773671,0.0,0,1.7371484,0.0,0.72944123,70.273384,2.0130143,466.49036,-9.2018585
2788,2788,212.0894,11.479555,7.7849884,0.0,0,1.7226164,0.0,0.73146796,70.28801,1.9984672,466.23828,-9.2020159
2789,2789,212.0896,11.507173,7.8014121,0.0,0,1.7080843,0.0,0.73419118,70.271797,1.9819674,465.98618,-9.2015982
2790,2790,212.0898,11.54268,7.8232312,0.0,0,1.6935524,0.0,0.73599941,70.337593,1.9672775,465.7341,-9.2009811
2791,2791,212.09,11.571225,7.8295727,0.0,0,1.6790204,0.0,0.73765624,70.423035,1.9515989,465.48199,-9.1995258
2792,2792,212.0902,11.578588,7.845243,0.0,0,1.6644883,0.0,0.74053061,70.31633,1.9347748,465.26593,-9.1995583
2793,2793,212.0904,11.579726,7.8690243,0.0,0,1.6499563,0.0,0.74253052,70.185623,1.9205413,465.06531,-9.2001009
2794,2794,212.0906,11.594645,7.8769808,0.0,0,1.6354244,0.0,0.74409223,70.134003,1.9081122,464.86469,-9.1993065
2795,2795,212.0908,11.609974,7.8918576,0.0,0,1.6208923,0.0,0.74714661,70.037132,1.8936939,464.66403,-9.1999149
2796,2796,212.091,11.627756,7.916163,0.0,0,1.6063604,0.0,0.74938691,69.996803,1.8768133,464.46341,-9.200511
2797,2797,212.0912,11.661649,7.9258752,0.0,0,1.5918283,0.0,0.75077176,70.033325,1.8608388,464.26276,-9.1999273
2798,2798,212.0914,11.698759,7.9400096,0.0,0,1.5772964,0.0,0.75383812,70.018013,1.8466668,464.06213,-9.2002506
2799,2799,212.0916,11.728606,7.9632072,0.0,0,1.5630548,0.0,0.75616968,70.06781,1.8329438,463.86151,-9.2004156
2800,2800,212.0918,11.750384,7.9725995,0.0,0,1.5491644,0.0,0.75723869,70.191978,1.8179088,463.66086,-9.2004242
2801,2801,212.092,11.769718,7.9836216,0.0,0,1.5353373,0.0,0.76009506,70.150192,1.80291,463.46024,-9.2007761
2802,2802,212.0922,11.796618,8.0049334,0.0,0,1.5215132,0.0,0.762555,70.077736,1.7870264,463.25961,-9.2006044
2803,2803,212.0924,11.818729,8.0162649,0.0,0,1.5076892,0.0,0.76349795,70.114571,1.7699583,463.05896,-9.2007589
2804,2804,212.0926,11.829462,8.027318,0.0,0,1.4938653,0.0,0.76617289,69.996483,1.7534993,462.85834,-9.2008801
2805,2805,212.0928,11.837271,8.0484886,0.0,0,1.4800413,0.0,0.76895666,69.838394,1.7395384,462.65771,-9.2009106
2806,2806,212.093,11.855296,8.0626535,0.0,0,1.4662173,0.0,0.77005881,69.863823,1.7248979,462.45706,-9.200676
2807,2807,212.0932,11.888941,8.0738897,0.0,0,1.4523933,0.0,0.77270257,69.87339,1.7101353,462.25644,-9.1999712
2808,2808,212.0934,11.928031,8.0933218,0.0,0,1.4385693,0.0,0.77570474,69.900444,1.6955713,462.05582,-9.1999035
2809,2809,212.0936,11.963008,8.1090765,0.0,0,1.4247453,0.0,0.77681607,70.027679,1.6785551,461.85516,-9.1998634
2810,2810,212.0938,11.991758,8.1212578,0.0,0,1.4109213,0.0,0.77933693,69.99884,1.663668,461.65454,-9.2005062
2811,2811,212.094,12.011472,8.1387434,0.0,0,1.3970973,0.0,0.78243929,69.876762,1.6496053,461.45389,-9.2006998
2812,2812,212.0942,12.023354,8.1553288,0.0,0,1.3832734,0.0,0.78359365,69.877533,1.6348124,461.25327,-9.2002115
2813,2813,212.0944,12.029572,8.1675158,0.0,0,1.3694494,0.0,0.78577852,69.800179,1.6198694,461.05264,-9.2007694
2814,2814,212.0946,12.037306,8.1807499,0.0,0,1.3556253,0.0,0.78874338,69.643517,1.6059471,460.85199,-9.2013569
2815,2815,212.0948,12.061446,8.1977596,0.0,0,1.3418013,0.0,0.79002464,69.636078,1.5933889,460.65137,-9.2012005
2816,2816,212.095,12.095876,8.2112827,0.0,0,1.3279774,0.0,0.7920388,69.693718,1.5770243,460.45074,-9.2010546
2817,2817,212.0952,12.132671,8.2234049,0.0,0,1.3141534,0.0,0.79510123,69.68293,1.5615541,460.25009,-9.2006922
2818,2818,212.0954,12.170362,8.2424173,0.0,0,1.3003293,0.0,0.7966969,69.787521,1.5482137,460.04947,-9.2002172
2819,2819,212.0956,12.202599,8.2569675,0.0,0,1.2865053,0.0,0.79849887,69.902336,1.5352261,459.84885,-9.2007217
2820,2820,212.0958,12.230186,8.2665272,0.0,0,1.2726814,0.0,0.8013947,69.867943,1.5209073,459.64819,-9.2010546
2821,2821,212.096,12.243448,8.2857666,0.0,0,1.2588574,0.0,0.80331284,69.817001,1.5052744,459.44757,-9.2004719
2822,2822,212.0962,12.244472,8.3022747,0.0,0,1.2450334,0.0,0.80514097,69.698502,1.4897851,459.24695,-9.1999922
2823,2823,212.0964,12.256459,8.3105974,0.0,0,1.2312094,0.0,0.8079356,69.520622,1.4753777,459.0463,-9.2001095
2824,2824,212.0966,12.276484,8.3300705,0.0,0,1.2176627,0.0,0.81012744,69.471191,1.4622979,458.84567,-9.200491
2825,2825,212.0968,12.301375,8.3487148,0.0,0,1.2044513,0.0,0.8119235,69.509293,1.4475764,458.64502,-9.2002764
2826,2826,212.097,12.332412,8.3558197,0.0,0,1.1913006,0.0,0.81440204,69.502205,1.4326729,458.4444,-9.2005291
2827,2827,212.0972,12.371265,8.3732185,0.0,0,1.1781524,0.0,0.81669104,69.558701,1.4187404,458.24377,-9.2010794
2828,2828,212.0974,12.406573,8.3928185,0.0,0,1.1650045,0.0,0.81840581,69.656754,1.4047214,458.04312,-9.2005091
2829,2829,212.0976,12.433127,8.3984795,0.0,0,1.1518564,0.0,0.82060266,69.686157,1.3920445,457.8425,-9.200326
2830,2830,212.0978,12.47614,8.4143467,0.0,0,1.1387084,0.0,0.82313013,69.719826,1.3770455,457.64188,-9.2009478
2831,2831,212.098,12.499488,8.4357243,0.0,0,1.1255604,0.0,0.82485807,69.722473,1.3605102,457.44122,-9.2005968
2832,2832,212.0982,12.507762,8.4410133,0.0,0,1.1124125,0.0,0.82691282,69.634979,1.3464946,457.2406,-9.2000494
2833,2833,212.0984,12.521515,8.4557371,0.0,0,1.0992644,0.0,0.82980251,69.510284,1.3324236,457.03998,-9.1999893
2834,2834,212.0986,12.545844,8.4786968,0.0,0,1.0861164,0.0,0.83165669,69.474121,1.3183991,456.83932,-9.1998796
2835,2835,212.0988,12.577387,8.484971,0.0,0,1.0729684,0.0,0.83339995,69.525146,1.302682,456.6387,-9.1998644
2836,2836,212.099,12.598868,8.4988089,0.0,0,1.0598203,0.0,0.83650172,69.492722,1.2873666,456.43808,-9.1992941
2837,2837,212.0992,12.633482,8.5217571,0.0,0,1.0466723,0.0,0.83858424,69.494476,1.2736014,456.23743,-9.1990519
2838,2838,212.0994,12.676998,8.5285997,0.0,0,1.0335244,0.0,0.83999127,69.616882,1.2593894,456.0368,-9.2002382
2839,2839,212.0996,12.720436,8.5412502,0.0,0,1.0203763,0.0,0.84298992,69.675514,1.2447146,455.83615,-9.201045
2840,2840,212.0998,12.745706,8.5638618,0.0,0,1.0072284,0.0,0.84510672,69.672249,1.2311839,455.63553,-9.2004652
2841,2841,212.1,12.759027,8.5716276,0.0,0,0.99408036,0.0,0.84639847,69.684479,1.2179999,455.43491,-9.2007685
2842,2842,212.1002,12.774008,8.5820837,0.0,0,0.98093235,0.0,0.84948522,69.564735,1.204797,455.05994,-9.2013035
2843,2843,212.1004,12.797645,8.6039953,0.0,0,0.96778435,0.0,0.8518042,69.490021,1.1890551,454.66556,-9.2011652
2844,2844,212.1006,12.828063,8.6137323,0.0,0,0.95463634,0.0,0.85282725,69.561768,1.1750617,454.27121,-9.2011404
2845,2845,212.1008,12.861798,8.6241388,0.0,0,0.94148839,0.0,0.85593009,69.514175,1.1618882,453.87686,-9.2004805
2846,2846,212.101,12.903007,8.6457224,0.0,0,0.92834044,0.0,0.85870373,69.546509,1.147984,453.48251,-9.1998863
2847,2847,212.1012,12.943255,8.6571846,0.0,0,0.91519243,0.0,0.85954159,69.725784,1.1332449,453.08813,-9.1998091
2848,2848,212.1014,12.98388,8.6666937,0.0,0,0.90204442,0.0,0.86243498,69.741158,1.1152583,452.69379,-9.1990652
2849,2849,212.1016,13.023701,8.6851387,0.0,0,0.88916051,0.0,0.86534417,69.731079,1.1024739,452.29944,-9.1988716
2850,2850,212.1018,13.04787,8.6980085,0.0,0,0.87659609,0.0,0.86610848,69.838638,1.0912907,451.90509,-9.1996088
2851,2851,212.102,13.069271,8.7080469,0.0,0,0.86408949,0.0,0.86864042,69.775558,1.0764099,451.51071,-9.1998091
2852,2852,212.1022,13.098001,8.7253113,0.0,0,0.85158539,0.0,0.87164629,69.679657,1.0624825,451.11636,-9.1998186
2853,2853,212.1024,13.119697,8.7400246,0.0,0,0.83908135,0.0,0.87264228,69.744003,1.0476116,450.72202,-9.2000961
2854,2854,212.1026,13.1475,8.7502871,0.0,0,0.82657731,0.0,0.87507975,69.730988,1.0344357,450.32767,-9.20012
2855,2855,212.1028,13.182718,8.7651548,0.0,0,0.81407332,0.0,0.87828958,69.702644,1.0222248,449.93329,-9.2003908
2856,2856,212.103,13.21886,8.7809973,0.0,0,0.8015694,0.0,0.87939596,69.829788,1.0072052,449.53894,-9.2007036
2857,2857,212.1032,13.257779,8.7918501,0.0,0,0.78906536,0.0,0.88152528,69.885284,0.99537855,449.14459,-9.200902
2858,2858,212.1034,13.299212,8.8036795,0.0,0,0.77656138,0.0,0.88461137,69.845909,0.98254979,448.75024,-9.2006702
2859,2859,212.1036,13.330994,8.8204269,0.0,0,0.7640574,0.0,0.88588375,69.936607,0.96519232,448.35587,-9.1998644
2860,2860,212.1038,13.351896,8.8325777,0.0,0,0.75155336,0.0,0.88779813,69.949913,0.94996411,447.96152,-9.1991625
2861,2861,212.104,13.375299,8.8424902,0.0,0,0.73904938,0.0,0.89095515,69.839935,0.93719709,447.56717,-9.1991825
2862,2862,212.1042,13.401858,8.8607655,0.0,0,0.72654539,0.0,0.89276379,69.834824,0.92469013,447.17282,-9.1997271
2863,2863,212.1044,13.426702,8.8752203,0.0,0,0.71404135,0.0,0.89458311,69.841568,0.9127239,446.77844,-9.1993761
2864,2864,212.1046,13.451976,8.8822775,0.0,0,0.70153737,0.0,0.897421,69.787369,0.90123779,446.38409,-9.1993437
2865,2865,212.1048,13.482502,8.8994713,0.0,0,0.68903339,0.0,0.89930618,69.80471,0.88845158,445.98975,-9.1996422
2866,2866,212.105,13.51122,8.9150572,0.0,0,0.67652941,0.0,0.90096468,69.845207,0.87248886,445.5954,-9.1997318
2867,2867,212.1052,13.544913,8.9216795,0.0,0,0.66402543,0.0,0.90371531,69.814331,0.85788476,445.20102,-9.1998234
2868,2868,212.1054,13.584904,8.9396191,0.0,0,0.65152138,0.0,0.90604281,69.851822,0.84518856,444.80667,-9.19981
2869,2869,212.1056,13.620852,8.9574461,0.0,0,0.63901734,0.0,0.90770495,69.937065,0.83324146,444.41232,-9.1998091
2870,2870,212.1058,13.651977,8.9638729,0.0,0,0.62651336,0.0,0.91027665,69.916878,0.82229328,444.01797,-9.1998138
2871,2871,212.106,13.677342,8.9812183,0.0,0,0.61400938,0.0,0.9129504,69.858421,0.80931258,443.6236,-9.2004328
2872,2872,212.1062,13.708117,9.0006933,0.0,0,0.6015054,0.0,0.91466653,69.872604,0.79521585,443.22925,-9.2006111
2873,2873,212.1064,13.73336,9.0042562,0.0,0,0.58900136,0.0,0.91682649,69.872574,0.78274864,442.8349,-9.200388
2874,2874,212.1066,13.752634,9.0183191,0.0,0,0.57674509,0.0,0.91960776,69.817482,0.76967114,442.44055,-9.200222
2875,2875,212.1068,13.783174,9.0388031,0.0,0,0.56478846,0.0,0.9211688,69.851768,0.7550844,442.04617,-9.199295
2876,2876,212.107,13.814188,9.0414619,0.0,0,0.55288601,0.0,0.92284745,69.884796,0.74231464,441.65182,-9.1999302
2877,2877,212.1072,13.85147,9.0536346,0.0,0,0.54098594,0.0,0.92584068,69.864281,0.73145264,441.25748,-9.2004499
2878,2878,212.1074,13.896035,9.0748034,0.0,0,0.52908593,0.0,0.92752022,69.963234,0.71802717,440.86313,-9.1991138
2879,2879,212.1076,13.936851,9.0791235,0.0,0,0.51718587,0.0,0.92895967,70.055702,0.70476419,440.46875,-9.1985617
2880,2880,212.1078,13.977591,9.0917511,0.0,0,0.50528592,0.0,0.9323163,70.007744,0.69232112,440.0744,-9.1992998
2881,2881,212.108,14.008569,9.1134014,0.0,0,0.49338591,0.0,0.93434119,70.011932,0.6788879,439.68005,-9.2005587
2882,2882,212.1082,14.033721,9.1193619,0.0,0,0.4814859,0.0,0.93553096,70.072472,0.66495472,439.28571,-9.201148
2883,2883,212.1084,14.066022,9.1318474,0.0,0,0.4695859,0.0,0.93891615,70.00975,0.65115196,438.89133,-9.2010736
2884,2884,212.1086,14.109374,9.154233,0.0,0,0.45768592,0.0,0.94127721,70.045448,0.63872021,438.49698,-9.2003975
2885,2885,212.1088,14.157543,9.1620073,0.0,0,0.44578591,0.0,0.94250762,70.198769,0.62605262,438.10263,-9.1999378
2886,2886,212.109,14.207239,9.17173,0.0,0,0.4338859,0.0,0.94582415,70.209023,0.61189872,437.70828,-9.200532
2887,2887,212.1092,14.266726,9.1917038,0.0,0,0.42198589,0.0,0.94827229,70.328804,0.59981656,437.3139,-9.2005663
2888,2888,212.1094,14.326867,9.1994257,0.0,0,0.41008592,0.0,0.94887596,70.603203,0.58796281,436.91956,-9.199439
2889,2889,212.1096,14.377243,9.2067976,0.0,0,0.39818591,0.0,0.95163673,70.650864,0.57217997,436.52521,-9.1986408
2890,2890,212.1098,14.418324,9.224576,0.0,0,0.3862859,0.0,0.9542045,70.659279,0.56061608,436.13086,-9.1984377
2891,2891,212.11,14.45465,9.2336836,0.0,0,0.37438589,0.0,0.95473355,70.811691,0.55083936,435.73453,-9.1986456
2892,2892,212.1102,14.496736,9.2415075,0.0,0,0.36248589,0.0,0.95751637,70.790131,0.53853983,435.32065,-9.198658