File: clean data/testID_0198.csv
level_0,index,Time(sec),Force(kN),Jaw(mm),PowAngle(deg),Power(W),Pram,PTemp,Strain,Stress(MPa),Stroke(mm),TC1(C),wedge(mm)
1872,1872,155.3437,0.61815524,0.057298113,0.0,0,9.0629702,0.0,0.0033447733,6.0777164,10.077232,343.5795,-9.3066301
1874,1874,155.3441,3.9884503,0.10576876,0.0,0,9.0044422,0.0,0.0067218179,45.726212,10.01852,344.26465,-9.3050251
1876,1876,155.3445,5.808507,0.15103552,0.0,0,8.9459143,0.0,0.0099512814,72.087601,9.9625969,344.94983,-9.3032055
1878,1878,155.3449,6.4062109,0.24288239,0.0,0,8.8873854,0.0,0.015154202,79.503586,9.8814144,345.63498,-9.3012238
1880,1880,155.3453,6.5974865,0.38678604,0.0,0,8.8288574,0.0,0.025509877,81.998573,9.7938948,346.32013,-9.3003302
1882,1882,155.3457,7.1810646,0.4434973,0.0,0,8.7703295,0.0,0.029525287,87.707649,9.6939106,347.00528,-9.3011341
1884,1884,155.3461,7.4567642,0.55740726,0.0,0,8.7136869,0.0,0.036853272,91.323082,9.5986099,347.69043,-9.3007841
1886,1886,155.3465,8.0590887,0.60501033,0.0,0,8.6580172,0.0,0.041374482,97.892754,9.5122042,348.43655,-9.3007059
1888,1888,155.3469,7.5340142,0.63196212,0.0,0,8.6023531,0.0,0.042372905,93.049477,9.4418526,349.24368,-9.2992611
1890,1890,155.3473,7.7646828,0.73761404,0.0,0,8.546689,0.0,0.04982432,92.941299,9.3748159,350.05081,-9.2995863
1892,1892,155.3477,8.2738743,0.76684481,0.0,0,8.491025,0.0,0.052434836,99.951485,9.3111124,350.85791,-9.29951
1894,1894,155.3481,8.3593235,0.84888899,0.0,0,8.4353609,0.0,0.057239469,100.33379,9.2417631,351.66504,-9.2984982
1896,1896,155.3485,8.1603203,0.95019746,0.0,0,8.3796968,0.0,0.065059803,97.893295,9.1583023,352.47214,-9.2997551
1898,1898,155.3489,8.1108789,1.0209734,0.0,0,8.3240328,0.0,0.069928974,95.801941,9.0827122,353.27927,-9.3013411
1900,1900,155.3493,8.477025,1.0977402,0.0,0,8.2683687,0.0,0.07538271,100.12997,9.0026302,354.08636,-9.2996483
1902,1902,155.3497,8.4606705,1.1388301,0.0,0,8.2127056,0.0,0.079018176,99.358223,8.932785,354.89349,-9.2995071
1904,1904,155.3501,8.6183348,1.1948195,0.0,0,8.1570406,0.0,0.08237198,101.24294,8.871274,355.70059,-9.2995005
1906,1906,155.3505,8.2844353,1.2602382,0.0,0,8.1013775,0.0,0.087305896,96.754906,8.8141212,356.50772,-9.2992907
1908,1908,155.3509,8.8355598,1.3072714,0.0,0,8.0462675,0.0,0.091108531,101.95802,8.7545013,357.31482,-9.2998075
1910,1910,155.3513,8.8340635,1.3896016,0.0,0,7.993176,0.0,0.096267447,102.53574,8.6924028,358.12195,-9.2990885
1912,1912,155.3517,8.7229366,1.4673471,0.0,0,7.9402156,0.0,0.10251956,100.16474,8.6242332,358.92905,-9.2991819
1914,1914,155.3521,8.6802349,1.525861,0.0,0,7.8872552,0.0,0.10691568,99.377579,8.5560417,359.73618,-9.2984018
1916,1916,155.3525,8.7525005,1.592123,0.0,0,7.8342953,0.0,0.11140995,99.437187,8.4934807,360.54327,-9.2991095
1918,1918,155.3529,8.9895201,1.6166868,0.0,0,7.7813349,0.0,0.11406539,102.10036,8.4331713,361.3504,-9.2992563
1920,1920,155.3533,8.8701706,1.6716131,0.0,0,7.728375,0.0,0.11767836,100.48277,8.3806715,362.1575,-9.2990999
1922,1922,155.3537,8.9172564,1.7365383,0.0,0,7.675415,0.0,0.12243253,100.33009,8.3296642,362.96463,-9.2979889
1924,1924,155.3541,9.0808039,1.7701479,0.0,0,7.6224551,0.0,0.12546027,101.68723,8.2741461,363.77176,-9.2982683
1926,1926,155.3545,9.1873684,1.8399571,0.0,0,7.5694952,0.0,0.13014497,102.64234,8.2161112,364.57886,-9.2987137
1928,1928,155.3549,9.1113586,1.9036038,0.0,0,7.5165353,0.0,0.13517234,101.38272,8.1579266,365.38599,-9.2994461
1930,1930,155.3553,9.1364536,1.9545083,0.0,0,7.4635754,0.0,0.13942826,101.16434,8.0992908,366.19308,-9.2986422
1932,1932,155.3557,9.1758261,2.0103698,0.0,0,7.410615,0.0,0.14327647,101.17201,8.0431356,367.00021,-9.2982721
1934,1934,155.3561,9.2994699,2.0528715,0.0,0,7.3593607,0.0,0.14696701,102.11135,7.988863,367.80731,-9.2982855
1936,1936,155.3565,9.2632046,2.1059692,0.0,0,7.3089876,0.0,0.1509611,101.53989,7.9378433,368.61444,-9.2982426
1938,1938,155.3569,9.2541647,2.1575058,0.0,0,7.2586198,0.0,0.15474527,100.81121,7.8871942,369.42154,-9.2987499
1940,1940,155.3573,9.4274111,2.2016358,0.0,0,7.2082515,0.0,0.15859963,102.27965,7.838098,369.38995,-9.2989244
1942,1942,155.3577,9.4898682,2.259069,0.0,0,7.1578832,0.0,0.16276428,102.6472,7.7873006,369.35837,-9.2980776
1944,1944,155.3581,9.4640055,2.3128383,0.0,0,7.1075149,0.0,0.16687517,102.08896,7.7330952,369.32681,-9.2971325
1946,1946,155.3585,9.4173746,2.3642633,0.0,0,7.0571475,0.0,0.17143813,100.99334,7.6777153,369.29523,-9.2976303
1948,1948,155.3589,9.5136452,2.4129901,0.0,0,7.0067787,0.0,0.17482081,101.67304,7.6259723,369.26364,-9.2983255
1950,1950,155.3593,9.6293049,2.4546876,0.0,0,6.9564114,0.0,0.17831151,102.5649,7.5781312,369.23206,-9.299408
1952,1952,155.3597,9.6194553,2.5065463,0.0,0,6.9060431,0.0,0.18280908,102.06194,7.5299134,369.20047,-9.2992411
1954,1954,155.3601,9.5813503,2.5579939,0.0,0,6.8556757,0.0,0.18632779,101.24982,7.4830899,369.16888,-9.2990589
1956,1956,155.3605,9.6982803,2.6004939,0.0,0,6.8053074,0.0,0.1901314,101.88033,7.4355512,369.13733,-9.2989025
1958,1958,155.3609,9.7909546,2.6475859,0.0,0,6.7554412,0.0,0.19400212,102.6915,7.3857236,369.10574,-9.2980528
1960,1960,155.3613,9.7749376,2.7019906,0.0,0,6.7074018,0.0,0.19781284,102.00195,7.3354802,369.07416,-9.2987671
1962,1962,155.3617,9.818471,2.746129,0.0,0,6.6594815,0.0,0.20204581,102.08833,7.286118,369.04257,-9.2986431
1964,1964,155.3621,9.8045368,2.7894435,0.0,0,6.6115613,0.0,0.20536773,101.67686,7.2351575,369.01099,-9.2992315
1966,1966,155.3625,9.9319906,2.8435726,0.0,0,6.5636415,0.0,0.2094795,102.46279,7.18889,368.9794,-9.3005161
1968,1968,155.3629,9.9289198,2.8867705,0.0,0,6.5157218,0.0,0.2137063,102.17995,7.1409063,368.94785,-9.2985525
1970,1970,155.3633,9.9904823,2.9308093,0.0,0,6.467802,0.0,0.21682978,102.30621,7.09201,368.91626,-9.2980309
1972,1972,155.3637,10.055792,2.9839013,0.0,0,6.4198813,0.0,0.22125375,102.68861,7.0463738,368.88467,-9.2986488
1974,1974,155.3641,10.092042,3.0286088,0.0,0,6.3719611,0.0,0.22538702,102.51389,6.9963422,368.85309,-9.2984943
1976,1976,155.3645,10.124272,3.0797112,0.0,0,6.3240414,0.0,0.22910009,102.52297,6.9468131,368.8215,-9.298521
1978,1978,155.3649,10.145841,3.1324387,0.0,0,6.2761216,0.0,0.23406878,102.19199,6.8993707,368.78992,-9.2976446
1980,1980,155.3653,10.230434,3.1747954,0.0,0,6.2282019,0.0,0.23756106,102.6172,6.8491974,368.75836,-9.2991495
1982,1982,155.3657,10.272043,3.2275841,0.0,0,6.1802816,0.0,0.24156287,102.61658,6.7989564,368.72678,-9.2997818
1984,1984,155.3661,10.284247,3.2734098,0.0,0,6.1339045,0.0,0.24610387,102.3981,6.7519345,368.69519,-9.2995329
1986,1986,155.3665,10.315332,3.3155668,0.0,0,6.0883236,0.0,0.2493178,102.29028,6.7025399,368.6636,-9.2997227
1988,1988,155.3669,10.416584,3.3668337,0.0,0,6.042748,0.0,0.25349414,102.7891,6.6543784,368.62524,-9.2984476
1990,1990,155.3673,10.466074,3.410748,0.0,0,5.9971714,0.0,0.25800943,102.87263,6.6066661,368.45798,-9.297574
1992,1992,155.3677,10.477246,3.4646885,0.0,0,5.9515953,0.0,0.26190361,102.69098,6.5539451,368.29074,-9.2980537
1994,1994,155.3681,10.481842,3.5121291,0.0,0,5.9060197,0.0,0.26636967,102.19418,6.5073032,368.12347,-9.2991238
1996,1996,155.3685,10.555841,3.5539651,0.0,0,5.8604436,0.0,0.27034369,102.44572,6.4601483,367.95621,-9.3004656
1998,1998,155.3689,10.646655,3.609601,0.0,0,5.814867,0.0,0.27431542,102.93636,6.4143429,367.78897,-9.3001528
2000,2000,155.3693,10.678126,3.6505718,0.0,0,5.7692914,0.0,0.27862999,102.87251,6.3655643,367.6217,-9.2994528
2002,2002,155.3697,10.676407,3.6953893,0.0,0,5.7237153,0.0,0.28252858,102.40636,6.3161197,367.45444,-9.2985134
2004,2004,155.3701,10.730612,3.7529659,0.0,0,5.6781397,0.0,0.28705478,102.46152,6.2724423,367.2872,-9.2979221
2006,2006,155.3705,10.80137,3.7929027,0.0,0,5.6325636,0.0,0.29145107,102.70488,6.2214694,367.11993,-9.299221
2008,2008,155.3709,10.857076,3.8410189,0.0,0,5.5874414,0.0,0.29527351,102.82648,6.1750183,366.9527,-9.299962
2010,2010,155.3713,10.871917,3.8968098,0.0,0,5.5439734,0.0,0.30010208,102.50906,6.1260443,366.78543,-9.3001766
2012,2012,155.3717,10.912388,3.9346662,0.0,0,5.5006132,0.0,0.30416325,102.42817,6.0774527,366.61816,-9.3007984
2014,2014,155.3721,10.962674,3.9853837,0.0,0,5.457253,0.0,0.30814233,102.55672,6.0309205,366.45093,-9.299983
2016,2016,155.3725,11.019063,4.0369024,0.0,0,5.4138932,0.0,0.31309465,102.49191,5.9841328,366.28366,-9.3002024
2018,2018,155.3729,11.077747,4.077632,0.0,0,5.370533,0.0,0.31709415,102.70655,5.9362516,366.11639,-9.2990932
2020,2020,155.3733,11.11699,4.1282697,0.0,0,5.3271732,0.0,0.32108682,102.61008,5.8870769,365.94916,-9.2992067
2022,2022,155.3737,11.159702,4.1756816,0.0,0,5.283813,0.0,0.32614526,102.5503,5.8385901,365.78189,-9.2986202
2024,2024,155.3741,11.199246,4.220623,0.0,0,5.2404532,0.0,0.33010253,102.41271,5.7890534,365.61462,-9.2994146
2026,2026,155.3745,11.245992,4.270155,0.0,0,5.1970935,0.0,0.33431473,102.47916,5.7446918,365.44739,-9.2996502
2028,2028,155.3749,11.320267,4.3146558,0.0,0,5.1537333,0.0,0.33919075,102.63895,5.6964822,365.28012,-9.3000364
2030,2030,155.3753,11.374771,4.3616443,0.0,0,5.110373,0.0,0.34301013,102.72744,5.6485238,365.11285,-9.2993078
2032,2032,155.3757,11.405249,4.4095068,0.0,0,5.0670133,0.0,0.34751803,102.59414,5.5997195,364.94562,-9.2991409
2034,2034,155.3761,11.44496,4.4524627,0.0,0,5.0250483,0.0,0.35219643,102.42298,5.5547862,364.77835,-9.2985954
2036,2036,155.3765,11.503933,4.5054145,0.0,0,4.9838037,0.0,0.35639089,102.53517,5.5075231,364.61111,-9.2991333
2038,2038,155.3769,11.569988,4.5506697,0.0,0,4.9425635,0.0,0.36111164,102.6321,5.4598002,364.46179,-9.2993002
2040,2040,155.3773,11.604502,4.5935292,0.0,0,4.9013238,0.0,0.3656033,102.57666,5.4142957,364.47394,-9.2994652
2042,2042,155.3777,11.641316,4.6469784,0.0,0,4.8600836,0.0,0.36982727,102.35233,5.3658686,364.48608,-9.2994804
2044,2044,155.3781,11.69319,4.6857548,0.0,0,4.8188438,0.0,0.37419608,102.33085,5.320106,364.49823,-9.2989168
2046,2046,155.3785,11.750899,4.730083,0.0,0,4.7776036,0.0,0.37851405,102.37386,5.2743654,364.51038,-9.2979174
2048,2048,155.3789,11.812557,4.7847013,0.0,0,4.7363639,0.0,0.38319251,102.49627,5.2323637,364.52252,-9.2984228
2050,2050,155.3793,11.854538,4.824759,0.0,0,4.6951237,0.0,0.38804013,102.30238,5.1830463,364.53467,-9.2997456
2052,2052,155.3797,11.886527,4.8695178,0.0,0,4.6538839,0.0,0.39192587,102.24839,5.139348,364.54681,-9.2998247
2054,2054,155.3801,11.908655,4.9181805,0.0,0,4.6126437,0.0,0.39656517,101.9808,5.091804,364.55896,-9.299962
2056,2056,155.3805,11.98041,4.9546499,0.0,0,4.5714035,0.0,0.40090996,102.1012,5.0489197,364.57111,-9.2994604
2058,2058,155.3809,12.043524,5.0021262,0.0,0,4.5305758,0.0,0.4047403,102.29252,5.0082631,364.58325,-9.2982521
2060,2060,155.3813,12.086058,5.048758,0.0,0,4.4912457,0.0,0.41002873,102.12289,4.959928,364.5954,-9.2977257
2062,2062,155.3817,12.12079,5.087306,0.0,0,4.4520135,0.0,0.41414312,102.03535,4.9206886,364.60754,-9.2989969
2064,2064,155.3821,12.152746,5.134007,0.0,0,4.4127812,0.0,0.41817656,101.87617,4.8769269,364.61969,-9.2997627
2066,2066,155.3825,12.218287,5.1769729,0.0,0,4.3735495,0.0,0.42332739,101.85242,4.8311915,364.63184,-9.2992573
2068,2068,155.3829,12.288145,5.2157097,0.0,0,4.3343177,0.0,0.42690915,102.04385,4.7919793,364.64398,-9.2986479
2070,2070,155.3833,12.331462,5.2595696,0.0,0,4.2950859,0.0,0.43103907,102.01533,4.747448,364.65613,-9.2985716
2072,2072,155.3837,12.363746,5.2985644,0.0,0,4.2558532,0.0,0.43591011,101.7466,4.7058325,364.66827,-9.2998037
2074,2074,155.3841,12.404884,5.3432541,0.0,0,4.2166214,0.0,0.43967274,101.69454,4.6639905,364.68042,-9.2999001
2076,2076,155.3845,12.47151,5.3857999,0.0,0,4.1773891,0.0,0.44420156,101.76437,4.6205711,364.69257,-9.3002253
2078,2078,155.3849,12.543755,5.423347,0.0,0,4.1381574,0.0,0.44884953,101.90576,4.5789824,364.70471,-9.299366
2080,2080,155.3853,12.574232,5.4701781,0.0,0,4.0989256,0.0,0.45270294,101.8036,4.5360045,364.71686,-9.2986774
2082,2082,155.3857,12.602004,5.5068078,0.0,0,4.0596933,0.0,0.45708808,101.58243,4.4953008,364.729,-9.2990141
2084,2084,155.3861,12.654832,5.5423303,0.0,0,4.0217257,0.0,0.46121088,101.51583,4.4555473,364.74115,-9.2999115
2086,2086,155.3865,12.740828,5.5909877,0.0,0,3.9844091,0.0,0.46525285,101.85684,4.4175467,364.7533,-9.3000584
2088,2088,155.3869,12.812257,5.6272125,0.0,0,3.9470971,0.0,0.4700771,101.9164,4.3775034,364.76669,-9.2989225
2090,2090,155.3873,12.837677,5.66818,0.0,0,3.9097853,0.0,0.47420326,101.75926,4.3338675,364.78735,-9.2977228
2092,2092,155.3877,12.873919,5.7173066,0.0,0,3.8724732,0.0,0.47890946,101.49819,4.293098,364.80798,-9.2984409
2094,2094,155.3881,12.956022,5.7473202,0.0,0,3.8351612,0.0,0.48331925,101.72857,4.2539029,364.82864,-9.2991791
2096,2096,155.3885,13.020089,5.786272,0.0,0,3.7978492,0.0,0.48676035,101.89653,4.2158885,364.84927,-9.299057
2098,2098,155.3889,13.073075,5.8332372,0.0,0,3.7605371,0.0,0.49179941,101.82145,4.1763401,364.8699,-9.2991304
2100,2100,155.3893,13.112178,5.8641367,0.0,0,3.7232251,0.0,0.49595398,101.65969,4.135303,364.89056,-9.2985687
2102,2102,155.3897,13.168112,5.9080787,0.0,0,3.6859133,0.0,0.49966347,101.62488,4.0927725,364.91119,-9.2985744
2104,2104,155.3901,13.241901,5.9507718,0.0,0,3.6486013,0.0,0.50508136,101.67893,4.053473,364.93182,-9.2990236
2106,2106,155.3905,13.305595,5.9839377,0.0,0,3.611289,0.0,0.50890261,101.77082,4.0161443,364.95248,-9.2984056
2108,2108,155.3909,13.37343,6.0273314,0.0,0,3.5743496,0.0,0.51293379,101.89286,3.9761939,364.97311,-9.2981262
2110,2110,155.3913,13.420063,6.063971,0.0,0,3.5387647,0.0,0.51795745,101.73567,3.9352577,364.99374,-9.2976542
2112,2112,155.3917,13.463599,6.1001115,0.0,0,3.5032687,0.0,0.52153462,101.69629,3.8989959,365.0144,-9.2985859
2114,2114,155.3921,13.527163,6.1425986,0.0,0,3.4677725,0.0,0.52589458,101.76299,3.8624971,365.03503,-9.2989864
2116,2116,155.3925,13.602637,6.1781931,0.0,0,3.4322767,0.0,0.53099149,101.77782,3.8217483,365.05566,-9.2992373
2118,2118,155.3929,13.67784,6.2219477,0.0,0,3.3967807,0.0,0.53490102,101.9172,3.7853935,365.07632,-9.2992525
2120,2120,155.3933,13.719013,6.2591949,0.0,0,3.3612847,0.0,0.53954971,101.79985,3.7450545,365.09695,-9.2992058
2122,2122,155.3937,13.770626,6.2903643,0.0,0,3.3257885,0.0,0.54384559,101.73768,3.7094893,365.11758,-9.2990704
2124,2124,155.3941,13.836937,6.333981,0.0,0,3.2902927,0.0,0.54757166,101.84993,3.671221,365.13824,-9.2992287
2126,2126,155.3945,13.926383,6.3664989,0.0,0,3.2547965,0.0,0.55219442,101.95411,3.6313126,365.15887,-9.2992201
2128,2128,155.3949,13.989848,6.4020734,0.0,0,3.2193005,0.0,0.5563795,102.08778,3.5952222,365.17953,-9.2992592
2130,2130,155.3953,14.035675,6.4491806,0.0,0,3.1838045,0.0,0.56076324,101.96971,3.559634,365.20016,-9.2993412
2132,2132,155.3957,14.092848,6.4786401,0.0,0,3.1483085,0.0,0.56550103,101.87883,3.5203106,365.22079,-9.2990227
2134,2134,155.3961,14.166538,6.514956,0.0,0,3.1139498,0.0,0.56931841,101.96262,3.4853261,365.24146,-9.2990236
2136,2136,155.3965,14.245392,6.560061,0.0,0,3.0801783,0.0,0.57407945,102.09904,3.4462264,365.26208,-9.2982197
2138,2138,155.3969,14.313517,6.5872016,0.0,0,3.0464103,0.0,0.57844079,102.15739,3.4114051,365.27325,-9.2984791
2140,2140,155.3973,14.363746,6.6240549,0.0,0,3.0126421,0.0,0.58195561,102.19521,3.3758068,365.24652,-9.2983561
2142,2142,155.3977,14.411104,6.6655006,0.0,0,2.9788742,0.0,0.58692956,102.0183,3.3388591,365.21982,-9.2988348
2144,2144,155.3981,14.493534,6.69238,0.0,0,2.9451063,0.0,0.59102792,102.17872,3.3069415,365.19308,-9.297801
2146,2146,155.3985,14.588252,6.7340384,0.0,0,2.9113381,0.0,0.59485835,102.43922,3.2677565,365.16635,-9.2979898
2148,2148,155.3989,14.66233,6.7709789,0.0,0,2.8775702,0.0,0.60027289,102.35993,3.2298844,365.13965,-9.2979622
2150,2150,155.3993,14.705266,6.8012929,0.0,0,2.8438022,0.0,0.60391766,102.31686,3.1966727,365.11292,-9.2986307
2152,2152,155.3997,14.768604,6.8411145,0.0,0,2.810034,0.0,0.60798246,102.3089,3.1625614,365.08618,-9.2974644
2154,2154,155.4001,14.844382,6.8761005,0.0,0,2.7762663,0.0,0.61331952,102.32805,3.127552,365.05948,-9.2973537
2156,2156,155.4005,14.957161,6.909368,0.0,0,2.7424982,0.0,0.61693716,102.71431,3.0924287,365.03275,-9.2970018
2158,2158,155.4009,15.025719,6.9455466,0.0,0,2.7090681,0.0,0.62103432,102.72573,3.0553949,365.00604,-9.2968779
2160,2160,155.4013,15.079016,6.9750018,0.0,0,2.6768675,0.0,0.62580067,102.64384,3.0186901,364.97931,-9.2983694
2162,2162,155.4017,15.155387,7.0145593,0.0,0,2.6447473,0.0,0.62941968,102.76334,2.9866672,364.95258,-9.2981529
2164,2164,155.4021,15.234928,7.0495071,0.0,0,2.6126273,0.0,0.63434672,102.79607,2.9532731,364.92587,-9.2986183
2166,2166,155.4025,15.344616,7.0800104,0.0,0,2.580507,0.0,0.6388579,102.99262,2.9188077,364.89914,-9.2977467
2168,2168,155.4029,15.403259,7.1230798,0.0,0,2.5483871,0.0,0.64298457,103.11297,2.8819823,364.87241,-9.2963352
2170,2170,155.4033,15.460172,7.1507778,0.0,0,2.5162671,0.0,0.64756924,102.95007,2.8469281,364.8457,-9.2961273
2172,2172,155.4037,15.545069,7.182384,0.0,0,2.4841471,0.0,0.65152287,103.14061,2.8158038,364.81897,-9.2965975
2174,2174,155.4041,15.641793,7.2258577,0.0,0,2.4520271,0.0,0.6559732,103.30508,2.7799909,364.79227,-9.2967796
2176,2176,155.4045,15.738703,7.2506056,0.0,0,2.4199073,0.0,0.66058224,103.47294,2.748735,364.76553,-9.297946
2178,2178,155.4049,15.808393,7.2844782,0.0,0,2.3877871,0.0,0.66428506,103.50146,2.7158384,364.7388,-9.2975178
2180,2180,155.4053,15.861535,7.3268104,0.0,0,2.3556671,0.0,0.66927224,103.37428,2.6782117,364.7121,-9.297802
2182,2182,155.4057,15.945321,7.351048,0.0,0,2.3235471,0.0,0.67378199,103.4163,2.6468422,364.68536,-9.2974854
2184,2184,155.4061,16.041296,7.385468,0.0,0,2.2924592,0.0,0.67708069,103.7278,2.6146739,364.65863,-9.2975702
2186,2186,155.4065,16.14246,7.4230862,0.0,0,2.261904,0.0,0.68231875,103.78348,2.586096,364.63193,-9.2971954
2188,2188,155.4069,16.211739,7.4467425,0.0,0,2.2313521,0.0,0.68619543,103.94127,2.550142,364.50156,-9.2969532
2190,2190,155.4073,16.273113,7.4838195,0.0,0,2.2008002,0.0,0.69003832,103.90272,2.5180421,364.06033,-9.2978001
2192,2192,155.4077,16.3771,7.5199499,0.0,0,2.170248,0.0,0.69579375,103.93051,2.4851561,363.61908,-9.2975368
2194,2194,155.4081,16.479803,7.5474472,0.0,0,2.1396961,0.0,0.69928855,104.18979,2.4543619,363.17783,-9.296484
2196,2196,155.4085,16.594616,7.5820355,0.0,0,2.109144,0.0,0.70321977,104.48281,2.4189985,362.73657,-9.2962408
2198,2198,155.4089,16.654112,7.6108665,0.0,0,2.0785921,0.0,0.70840353,104.42027,2.3850601,362.29535,-9.2966251
2200,2200,155.4093,16.733101,7.6425152,0.0,0,2.0480402,0.0,0.71174693,104.4712,2.3570993,361.8541,-9.2982016
2202,2202,155.4097,16.840813,7.6769214,0.0,0,2.0174882,0.0,0.71614236,104.66699,2.3221579,361.41284,-9.2981033
2204,2204,155.4101,16.943615,7.7065997,0.0,0,1.986936,0.0,0.72143185,104.80178,2.2893639,360.97162,-9.2967072
2206,2206,155.4105,17.047379,7.7447844,0.0,0,1.9563839,0.0,0.72524154,105.05154,2.2603829,360.53036,-9.2961283
2208,2208,155.4109,17.125019,7.7737164,0.0,0,1.9261372,0.0,0.72995079,105.0129,2.2265553,360.08911,-9.2962542
2210,2210,155.4113,17.19541,7.799448,0.0,0,1.8970003,0.0,0.73430836,105.03227,2.1937888,359.64789,-9.2965937
2212,2212,155.4117,17.301304,7.8380384,0.0,0,1.8679363,0.0,0.73794705,105.26565,2.1636951,359.20663,-9.2961693
2214,2214,155.4121,17.417307,7.8630342,0.0,0,1.8388723,0.0,0.74277824,105.4282,2.132184,358.76538,-9.2961435
2216,2216,155.4125,17.521622,7.8932981,0.0,0,1.8098083,0.0,0.74679112,105.69265,2.1011567,358.32416,-9.2962332
2218,2218,155.4129,17.603672,7.936614,0.0,0,1.7807442,0.0,0.75160891,105.68996,2.0703521,357.8829,-9.2955837
2220,2220,155.4133,17.69594,7.9605274,0.0,0,1.7516803,0.0,0.75665677,105.70695,2.0401683,357.44165,-9.2957544
2222,2222,155.4137,17.815338,7.9903178,0.0,0,1.7226163,0.0,0.76017421,106.01674,2.0140371,357.00043,-9.2958269
2224,2224,155.4141,17.937429,8.0278568,0.0,0,1.6935523,0.0,0.7652148,106.15114,1.9812112,356.55917,-9.2960825
2226,2226,155.4145,18.036745,8.04846,0.0,0,1.6644882,0.0,0.76944733,106.3705,1.9499098,356.11792,-9.2963562
2228,2228,155.4149,18.125851,8.0830698,0.0,0,1.6354243,0.0,0.77294409,106.51172,1.9170303,355.6767,-9.2975006
2230,2230,155.4153,18.227568,8.1180677,0.0,0,1.6063603,0.0,0.77872431,106.45641,1.890265,355.23544,-9.2968855
2232,2232,155.4157,18.333542,8.142086,0.0,0,1.5772963,0.0,0.78266901,106.67645,1.8612123,354.79419,-9.2961254
2234,2234,155.4161,18.46245,8.1763773,0.0,0,1.5491643,0.0,0.78649211,107.00995,1.8303794,354.35297,-9.2959881
2236,2236,155.4165,18.590876,8.2052984,0.0,0,1.5215131,0.0,0.79204518,107.10649,1.7973527,353.91171,-9.29601
2238,2238,155.4169,18.689955,8.2321997,0.0,0,1.4938651,0.0,0.79560763,107.34843,1.7669642,353.39795,-9.2948427
2240,2240,155.4173,18.792994,8.2688437,0.0,0,1.4662172,0.0,0.80006367,107.43822,1.7347155,352.71497,-9.2965727
2242,2242,155.4177,18.89987,8.2957582,0.0,0,1.4385692,0.0,0.80574429,107.42485,1.705768,352.03201,-9.2966194
2244,2244,155.4181,19.039656,8.3265409,0.0,0,1.4109212,0.0,0.809057,107.86868,1.6771916,351.34903,-9.2968731
2246,2246,155.4185,19.160349,8.3562698,0.0,0,1.3832732,0.0,0.8135916,108.09326,1.6456678,350.66608,-9.2953358
2248,2248,155.4189,19.269955,8.3799925,0.0,0,1.3556252,0.0,0.81850219,108.16981,1.617051,349.98309,-9.2954502
2250,2250,155.4193,19.367313,8.417326,0.0,0,1.3279773,0.0,0.82243371,108.28995,1.5843127,349.30014,-9.2953176
2252,2252,155.4197,19.496428,8.4440956,0.0,0,1.3003292,0.0,0.82741326,108.44948,1.556981,348.61716,-9.2960281
2254,2254,155.4201,19.65118,8.4688368,0.0,0,1.2726812,0.0,0.83161491,108.85902,1.5308561,347.93417,-9.2967606
2256,2256,155.4205,19.782993,8.5073452,0.0,0,1.2450333,0.0,0.83579898,109.12595,1.497046,347.25122,-9.2966089
2258,2258,155.4209,19.867268,8.5300798,0.0,0,1.2176626,0.0,0.8409757,109.09092,1.4705557,346.56824,-9.2954788
2260,2260,155.4213,19.99136,8.557662,0.0,0,1.1913005,0.0,0.84481227,109.29138,1.4408518,345.88528,-9.295311
2262,2262,155.4217,20.128857,8.5957842,0.0,0,1.1650044,0.0,0.84957874,109.51015,1.4119879,345.2023,-9.2955666
2264,2264,155.4221,20.277262,8.6124973,0.0,0,1.1387082,0.0,0.85424185,109.82062,1.3826536,344.51935,-9.2947292
2266,2266,155.4225,20.414082,8.6425505,0.0,0,1.1124123,0.0,0.85751671,110.23596,1.3560506,343.83636,-9.2943468
2268,2268,155.4229,20.521151,8.6801443,0.0,0,1.0861163,0.0,0.86321336,110.15821,1.3251446,343.15341,-9.2950773
2270,2270,155.4233,20.642267,8.6994963,0.0,0,1.0598202,0.0,0.86795235,110.2957,1.2933195,342.47043,-9.2957106
2272,2272,155.4237,20.789726,8.731575,0.0,0,1.0335243,0.0,0.87128788,110.68512,1.2679558,341.78745,-9.2947474
2274,2274,155.4241,20.959677,8.7602654,0.0,0,1.0072283,0.0,0.87676525,110.97414,1.2372081,341.10449,-9.295104
2276,2276,155.4245,21.097637,8.7797718,0.0,0,0.98093224,0.0,0.88037372,111.31394,1.2102134,340.42151,-9.2946444
2278,2278,155.4249,21.208239,8.814887,0.0,0,0.95463622,0.0,0.88462281,111.43744,1.1778913,339.73856,-9.2939882
2280,2280,155.4253,21.330759,8.8422556,0.0,0,0.92834032,0.0,0.89075673,111.35804,1.1512234,339.05557,-9.2944698
2282,2282,155.4257,21.481314,8.8678894,0.0,0,0.9020443,0.0,0.89422494,111.77715,1.1237322,338.37262,-9.2953377
2284,2284,155.4261,21.650946,8.8973389,0.0,0,0.87659597,0.0,0.89830452,112.13931,1.0945022,337.68964,-9.2946329
2286,2286,155.4265,21.772701,8.9193125,0.0,0,0.85158527,0.0,0.90351623,112.2903,1.0680583,337.00668,-9.2931156
2288,2288,155.4269,21.884306,8.9485121,0.0,0,0.82657719,0.0,0.90660107,112.48287,1.0396973,336.45905,-9.2936888
2290,2290,155.4273,22.024342,8.9751444,0.0,0,0.80156928,0.0,0.91146129,112.62264,1.012661,336.16278,-9.2945576
2292,2292,155.4277,22.186359,8.997818,0.0,0,0.77656126,0.0,0.91651881,112.86729,0.98592198,335.86652,-9.2949085
2294,2294,155.4281,22.347944,9.0332165,0.0,0,0.75155324,0.0,0.92038286,113.31831,0.95685029,335.57022,-9.2953033
2296,2296,155.4285,22.475296,9.0557909,0.0,0,0.72654527,0.0,0.92542738,113.37613,0.93180072,335.27396,-9.2944717
2298,2298,155.4289,22.607273,9.0752048,0.0,0,0.70153725,0.0,0.92922544,113.55793,0.90608168,334.97769,-9.2946901
2300,2300,155.4293,22.758236,9.1108074,0.0,0,0.67652929,0.0,0.93329632,113.88138,0.88229877,334.68143,-9.2931442
2302,2302,155.4297,22.907764,9.1269798,0.0,0,0.65152127,0.0,0.93791884,114.09593,0.8572666,334.38516,-9.2929535
2304,2304,155.4301,23.087849,9.1520329,0.0,0,0.62651324,0.0,0.94150722,114.53793,0.83183336,334.08887,-9.2937002
2306,2306,155.4305,23.207071,9.1877842,0.0,0,0.60150528,0.0,0.94666785,114.59042,0.80903292,333.7926,-9.2959833
2308,2308,155.4309,23.343439,9.2048664,0.0,0,0.57674497,0.0,0.95163029,114.66154,0.77837145,333.49634,-9.2960768
2310,2310,155.4313,23.482883,9.2321205,0.0,0,0.55288589,0.0,0.9548735,114.98716,0.75626981,333.20007,-9.2940321
2312,2312,155.4317,23.638435,9.2625856,0.0,0,0.52908581,0.0,0.96012735,115.18398,0.72792637,332.90378,-9.2929688
2314,2314,155.4321,23.796637,9.2762194,0.0,0,0.5052858,0.0,0.9639405,115.48318,0.7025677,332.60751,-9.2914705
2316,2316,155.4325,23.93854,9.305109,0.0,0,0.48148578,0.0,0.96711349,115.79089,0.67624694,332.31125,-9.292141
2318,2318,155.4329,24.074959,9.3317137,0.0,0,0.4576858,0.0,0.97304153,115.77866,0.64967388,332.01498,-9.2933168
2320,2320,155.4333,24.233589,9.348279,0.0,0,0.43388578,0.0,0.97618061,116.16467,0.62686247,331.71872,-9.293972
2322,2322,155.4337,24.413179,9.3778648,0.0,0,0.4100858,0.0,0.98003012,116.55918,0.6017952,331.42242,-9.292798
2324,2324,155.4341,24.56654,9.3999624,0.0,0,0.38628578,0.0,0.98573452,116.66687,0.57385033,331.12616,-9.2909803
2326,2326,155.4345,24.722115,9.4238453,0.0,0,0.36248577,0.0,0.98911816,116.97436,0.5503701,330.8299,-9.2906351