File: clean data/testID_0152.csv
index,Time(sec),Force(kN),Jaw(mm),PowAngle(deg),Power(W),Pram,PTemp,Strain,Stress(MPa),Stroke(mm),TC1(C),wedge(mm)
2415,195.3721,1.1450636,0.036266755,0.0,0,9.9668627,0.0,0.0021847603,14.28298,10.068676,449.39178,-9.2358074
2425,195.3741,2.1635962,0.042708013,0.0,0,9.936862,0.0,0.0028220012,27.137476,10.041588,449.48438,-9.2348366
2435,195.3761,3.2170477,0.054968305,0.0,0,9.9068623,0.0,0.0038433739,40.618252,10.015784,449.86688,-9.2335691
2445,195.3781,3.7734728,0.081827529,0.0,0,9.8768625,0.0,0.00557714,47.616722,9.9864712,450.24939,-9.2324886
2455,195.3801,4.0014734,0.11243403,0.0,0,9.8468618,0.0,0.0073994994,50.574604,9.9511681,450.6319,-9.2322788
2465,195.3821,4.1740646,0.15096821,0.0,0,9.8168621,0.0,0.0097532412,52.645176,9.9138441,451.01437,-9.2319965
2475,195.3841,4.29392,0.1801572,0.0,0,9.7868624,0.0,0.012037257,54.09938,9.8766651,451.42581,-9.2328501
2485,195.3861,4.3730326,0.21129288,0.0,0,9.7568626,0.0,0.01433723,54.953278,9.841855,451.93979,-9.2332792
2495,195.3881,4.4280648,0.24500738,0.0,0,9.726862,0.0,0.016638158,55.421642,9.8135347,452.45377,-9.232893
2505,195.3901,4.4567199,0.27737132,0.0,0,9.6968622,0.0,0.018554904,55.735001,9.7779722,452.96774,-9.232832
2515,195.3921,4.4871902,0.30777121,0.0,0,9.6668625,0.0,0.020346086,55.971691,9.7501678,453.48175,-9.2336931
2525,195.3941,4.5283961,0.33049276,0.0,0,9.6368618,0.0,0.022187296,56.395809,9.7209787,453.90909,-9.2337894
2535,195.3961,4.5602303,0.36130834,0.0,0,9.6068621,0.0,0.024488835,56.653915,9.692028,454.01071,-9.2332325
2545,195.3981,4.5882411,0.39299572,0.0,0,9.5768623,0.0,0.026706651,56.809883,9.6605167,454.1123,-9.2330589
2555,195.4001,4.6084437,0.42374948,0.0,0,9.5468626,0.0,0.02862959,56.978188,9.6295166,454.2139,-9.233305
2565,195.4021,4.6318445,0.4562149,0.0,0,9.5168629,0.0,0.030571099,57.198338,9.6011267,454.31552,-9.2338371
2575,195.4041,4.6364999,0.48096788,0.0,0,9.4868622,0.0,0.032382693,57.155441,9.5665054,454.38724,-9.2345572
2585,195.4061,4.6485972,0.51054841,0.0,0,9.4574738,0.0,0.034702353,57.247784,9.5385981,454.33942,-9.233737
2595,195.4081,4.6730571,0.54005748,0.0,0,9.4282103,0.0,0.036943018,57.417038,9.5101681,454.2916,-9.2346716
2605,195.4101,4.7080874,0.57193643,0.0,0,9.3989468,0.0,0.038889553,57.619492,9.4797754,454.2438,-9.2350531
2615,195.4121,4.7078223,0.60639787,0.0,0,9.3696823,0.0,0.041024219,57.47958,9.4468098,454.19598,-9.2338037
2625,195.4141,4.7186766,0.631154,0.0,0,9.3404188,0.0,0.042744443,57.548466,9.4162502,454.15613,-9.233614
2635,195.4161,4.7244945,0.65918839,0.0,0,9.3111544,0.0,0.044969629,57.555012,9.3846226,454.15015,-9.2336836
2645,195.4181,4.7243214,0.68737459,0.0,0,9.2818909,0.0,0.047207989,57.409599,9.3578415,454.14417,-9.2353096
2655,195.4201,4.7386189,0.71604121,0.0,0,9.2526264,0.0,0.048990257,57.512131,9.3299704,454.13818,-9.2343826
2665,195.4221,4.7491484,0.74947566,0.0,0,9.223362,0.0,0.050978869,57.498802,9.3011208,454.13223,-9.2337847
2675,195.4241,4.7543683,0.7741971,0.0,0,9.1940985,0.0,0.052800342,57.437321,9.2683353,454.13379,-9.2347288
2685,195.4261,4.7796235,0.8034851,0.0,0,9.164834,0.0,0.05492381,57.525295,9.240696,454.16962,-9.2339859
2695,195.4281,4.8090653,0.82773823,0.0,0,9.1355705,0.0,0.056949012,57.83062,9.2113361,454.20547,-9.2344379
2705,195.4301,4.8290958,0.85904318,0.0,0,9.1063061,0.0,0.059096929,57.91703,9.182333,454.24133,-9.2346802
2715,195.4321,4.8405428,0.89328039,0.0,0,9.0770416,0.0,0.061321151,57.935493,9.1534004,454.27719,-9.232954
2725,195.4341,4.8534107,0.91999537,0.0,0,9.0477781,0.0,0.063071713,58.077625,9.1206532,454.33237,-9.2338028
2735,195.4361,4.8808246,0.95104063,0.0,0,9.0185146,0.0,0.065244235,58.179123,9.0911655,454.48178,-9.2359838
2745,195.4381,4.8845363,0.97691715,0.0,0,8.9892502,0.0,0.067461804,58.048363,9.0595703,454.6312,-9.2341509
2755,195.4401,4.8905931,1.0069739,0.0,0,8.9599867,0.0,0.069690384,58.021317,9.0276613,454.78061,-9.2338123
2765,195.4421,4.9081569,1.0415189,0.0,0,8.9307222,0.0,0.071948603,58.08234,8.9982166,454.93002,-9.2338753
2775,195.4441,4.9217982,1.0662993,0.0,0,8.9014587,0.0,0.073528871,58.146046,8.968668,455.08997,-9.2353706
2785,195.4461,4.9369321,1.0994112,0.0,0,8.8721943,0.0,0.075849824,58.142529,8.9373951,455.30515,-9.2339153
2795,195.4481,4.9404292,1.1236926,0.0,0,8.8429298,0.0,0.077851482,58.149693,8.9097624,455.52029,-9.2333803
2805,195.4501,4.9337678,1.1499207,0.0,0,8.8136663,0.0,0.079987414,57.968349,8.878808,455.73544,-9.2344923
2815,195.4521,4.948596,1.180764,0.0,0,8.7844019,0.0,0.082129724,57.94347,8.8543673,455.95062,-9.2348509
2825,195.4541,4.9659925,1.2090536,0.0,0,8.7551384,0.0,0.08393161,58.160931,8.8224058,456.15143,-9.2332611
2835,195.4561,4.9944372,1.24086,0.0,0,8.7270641,0.0,0.08600878,58.358414,8.7955141,456.27094,-9.2333231
2845,195.4581,5.0126243,1.2643842,0.0,0,8.6992321,0.0,0.088019103,58.480495,8.7640486,456.39047,-9.2350273
2855,195.4601,5.0440645,1.2946651,0.0,0,8.671401,0.0,0.09042906,58.611111,8.7338181,456.50998,-9.2353144
2865,195.4621,5.0311327,1.3267908,0.0,0,8.643568,0.0,0.092812277,58.349888,8.7008753,456.62952,-9.2339964
2875,195.4641,5.0316739,1.3568062,0.0,0,8.615736,0.0,0.094708912,58.25658,8.673933,456.73648,-9.2339096
2885,195.4661,5.0086775,1.3871907,0.0,0,8.587904,0.0,0.096621946,57.810116,8.6469002,456.76636,-9.2341433
2895,195.4681,5.0195627,1.4057553,0.0,0,8.5600719,0.0,0.098281734,57.830723,8.6253061,456.79626,-9.2336702
2905,195.4701,5.028039,1.4333086,0.0,0,8.5322418,0.0,0.10057531,57.977821,8.5938358,456.82614,-9.2339306
2915,195.4721,5.0485916,1.4606497,0.0,0,8.5044079,0.0,0.10275706,57.96162,8.5661221,456.85602,-9.2345896
2925,195.4741,5.0682912,1.4887457,0.0,0,8.4765768,0.0,0.10452684,58.201488,8.540204,456.88669,-9.2344723
2935,195.4761,5.0931592,1.5226473,0.0,0,8.4487448,0.0,0.10668379,58.342148,8.5096064,456.92255,-9.2336969
2945,195.4781,5.1002541,1.5459558,0.0,0,8.4209118,0.0,0.10853731,58.225838,8.4835415,456.9584,-9.232605
2955,195.4801,5.1139188,1.5740825,0.0,0,8.3930807,0.0,0.11088099,58.240898,8.4508762,456.99426,-9.233675
2965,195.4821,5.127852,1.6033776,0.0,0,8.3652487,0.0,0.11326759,58.354866,8.4235649,457.03012,-9.2342825
2975,195.4841,5.13094,1.6319555,0.0,0,8.3374176,0.0,0.11525425,58.25444,8.3956442,457.06311,-9.2327518
2985,195.4861,5.1219497,1.6652094,0.0,0,8.3095846,0.0,0.11740162,57.992023,8.3640966,457.07507,-9.2337351
2995,195.4881,5.1389847,1.6885293,0.0,0,8.2817526,0.0,0.11925957,58.049458,8.336462,457.08704,-9.2338877
3005,195.4901,5.1398525,1.7157837,0.0,0,8.2539215,0.0,0.12143079,58.054134,8.3105087,457.09897,-9.2342253
3015,195.4921,5.1453815,1.7405397,0.0,0,8.2260885,0.0,0.12361188,57.841702,8.2803726,457.11093,-9.2327871
3025,195.4941,5.1549754,1.7696236,0.0,0,8.1982574,0.0,0.12566262,57.957619,8.2523155,457.12619,-9.2335176
3035,195.4961,5.1577897,1.8026273,0.0,0,8.1704254,0.0,0.12780918,57.90559,8.2251329,457.16803,-9.2334938
3045,195.4981,5.1590266,1.8256536,0.0,0,8.1425934,0.0,0.12952326,57.779308,8.1956348,457.20987,-9.2343655
3055,195.5001,5.1729498,1.8513918,0.0,0,8.1147614,0.0,0.13161722,57.730995,8.1714163,457.25168,-9.2348413
3065,195.5021,5.1816235,1.8757614,0.0,0,8.0869293,0.0,0.13379191,57.815151,8.1432562,457.29352,-9.2335434
3075,195.5041,5.2069473,1.9037133,0.0,0,8.0590973,0.0,0.13590874,57.864819,8.1144133,457.327,-9.2328701
3085,195.5061,5.2317886,1.9380513,0.0,0,8.0323896,0.0,0.13821647,58.039051,8.0842066,457.28516,-9.2338285
3095,195.5081,5.2513423,1.9635131,0.0,0,8.005909,0.0,0.1400483,58.156693,8.0574646,457.24332,-9.2333183
3105,195.5101,5.2523727,1.9942633,0.0,0,7.9794283,0.0,0.14238712,58.022663,8.0268459,457.20148,-9.2322912
3115,195.5121,5.2483015,2.0176322,0.0,0,7.9529486,0.0,0.1445595,57.826363,7.9960818,457.15964,-9.2329865
3125,195.5141,5.2461696,2.0442231,0.0,0,7.9264679,0.0,0.14677496,57.651718,7.9685102,457.10007,-9.233655
3135,195.5161,5.2482948,2.0759962,0.0,0,7.8999882,0.0,0.14899205,57.582119,7.9461222,456.86099,-9.2342949
3145,195.5181,5.2394662,2.1003056,0.0,0,7.873508,0.0,0.15059301,57.43969,7.9195457,456.62192,-9.2344303
3155,195.5201,5.2531185,2.1269517,0.0,0,7.8470287,0.0,0.1525833,57.51664,7.8928542,456.38284,-9.2336998
3165,195.5221,5.2677674,2.1501114,0.0,0,7.8205481,0.0,0.15471345,57.358955,7.8649192,456.1438,-9.2337551
3175,195.5241,5.274106,2.1754854,0.0,0,7.7940683,0.0,0.15693516,57.429707,7.8391876,455.91476,-9.2337284
3185,195.5261,5.2803073,2.2051542,0.0,0,7.7675881,0.0,0.15911856,57.320194,7.8115845,455.80121,-9.2330799
3195,195.5281,5.2981033,2.2297518,0.0,0,7.7411084,0.0,0.16078582,57.387249,7.7835612,455.68765,-9.2338018
3205,195.5301,5.3039441,2.2569954,0.0,0,7.7146277,0.0,0.16268046,57.317539,7.7606044,455.5741,-9.2330313
3215,195.5321,5.31037,2.2776337,0.0,0,7.688148,0.0,0.16465622,57.360821,7.7325444,455.46054,-9.2345858
3225,195.5341,5.3239112,2.3033106,0.0,0,7.6616683,0.0,0.16693351,57.362843,7.7089949,455.35663,-9.2340927
3235,195.5361,5.3453717,2.3310122,0.0,0,7.6351881,0.0,0.16913678,57.489742,7.6823592,455.38052,-9.23382
3245,195.5381,5.3532066,2.3576512,0.0,0,7.6087084,0.0,0.17084712,57.497322,7.6542835,455.40445,-9.2347183
3255,195.5401,5.3702502,2.3885508,0.0,0,7.5822282,0.0,0.17299891,57.561562,7.6264772,455.42834,-9.2337809
3265,195.5421,5.3875289,2.4101384,0.0,0,7.555748,0.0,0.17498112,57.510612,7.5999923,455.45227,-9.23316
3275,195.5441,5.4043012,2.4356351,0.0,0,7.5292683,0.0,0.17732359,57.636127,7.5740924,455.4751,-9.233552
3285,195.5461,5.4216433,2.4601898,0.0,0,7.5027881,0.0,0.17952156,57.605625,7.5467744,455.48108,-9.2346125
3295,195.5481,5.455039,2.489563,0.0,0,7.4763083,0.0,0.18152706,57.917095,7.5213408,455.48703,-9.2331791
3305,195.5501,5.4613667,2.5224688,0.0,0,7.4498281,0.0,0.18366437,57.899052,7.4927459,455.49301,-9.2336397
3315,195.5521,5.4875317,2.5431657,0.0,0,7.4233479,0.0,0.18554461,57.956005,7.4655128,455.49899,-9.2336502
3325,195.5541,5.4795094,2.5711038,0.0,0,7.3968682,0.0,0.18814217,57.705936,7.4355927,455.51215,-9.2344456
3335,195.5561,5.4836879,2.5967891,0.0,0,7.3714657,0.0,0.19044958,57.743305,7.4077501,455.66156,-9.2345753
3345,195.5581,5.4842992,2.6242156,0.0,0,7.346282,0.0,0.19237395,57.523712,7.381815,455.81097,-9.2330971
3355,195.5601,5.4906044,2.6535227,0.0,0,7.3210979,0.0,0.19437307,57.565868,7.359128,455.96039,-9.2324657
3365,195.5621,5.5129347,2.6752524,0.0,0,7.2959137,0.0,0.19614822,57.640686,7.3292122,456.1098,-9.2332325
3375,195.5641,5.5268521,2.7001595,0.0,0,7.27073,0.0,0.1984641,57.673138,7.3049245,456.26138,-9.2340956
3385,195.5661,5.5290956,2.7253246,0.0,0,7.2455459,0.0,0.2008523,57.59547,7.280129,456.46457,-9.23452
3395,195.5681,5.5151229,2.7506962,0.0,0,7.2203617,0.0,0.20272833,57.275089,7.2566175,456.66776,-9.2339602
3405,195.5701,5.517293,2.7786403,0.0,0,7.195178,0.0,0.20459588,57.246433,7.2309413,456.87094,-9.2343616
3415,195.5721,5.5384579,2.7992413,0.0,0,7.1699934,0.0,0.20618075,57.369984,7.2054381,457.07416,-9.2325811
3425,195.5741,5.5451331,2.8227084,0.0,0,7.1448092,0.0,0.20831008,57.39389,7.1804051,457.24808,-9.2330723
3435,195.5761,5.5755973,2.8446798,0.0,0,7.1196256,0.0,0.21062523,57.445755,7.1538315,456.47711,-9.233078
3445,195.5781,5.5903955,2.8719928,0.0,0,7.0944414,0.0,0.21271589,57.512798,7.1289234,455.70615,-9.2337971
3455,195.5801,5.6092587,2.901628,0.0,0,7.0692577,0.0,0.21481234,57.635498,7.1054339,454.93518,-9.2325382
3465,195.5821,5.6304579,2.925441,0.0,0,7.0440741,0.0,0.2166646,57.756252,7.0790329,454.16422,-9.2330332
3475,195.5841,5.6318107,2.9517195,0.0,0,7.0188899,0.0,0.21886747,57.682266,7.0528235,453.39108,-9.2334099
3485,195.5861,5.6326299,2.9725125,0.0,0,6.9937057,0.0,0.22105017,57.421078,7.0257492,452.51254,-9.2344332
3495,195.5881,5.6305852,2.9997017,0.0,0,6.9685211,0.0,0.22334361,57.436314,7.0026989,451.63397,-9.2337866
3505,195.5901,5.6535783,3.0269971,0.0,0,6.9433374,0.0,0.22542591,57.437099,6.9737206,450.75543,-9.2325974
3515,195.5921,5.6393666,3.0507648,0.0,0,6.9181538,0.0,0.22704847,57.283627,6.9516978,449.87686,-9.2323589
3525,195.5941,5.6621861,3.0772097,0.0,0,6.8929701,0.0,0.22922461,57.274761,6.9267979,449.00864,-9.2332792
3535,195.5961,5.6774397,3.0941231,0.0,0,6.8677855,0.0,0.23104133,57.343296,6.9010382,449.15805,-9.2335052
3545,195.5981,5.6782155,3.118629,0.0,0,6.8426018,0.0,0.23334363,57.241405,6.8766112,449.30743,-9.2338686
3555,195.6001,5.6918669,3.1481433,0.0,0,6.8174176,0.0,0.23571008,57.319115,6.8519025,449.45685,-9.2337542
3565,195.6021,5.7063332,3.1739862,0.0,0,6.7922335,0.0,0.23755951,57.297733,6.8270206,449.60626,-9.2333508
3575,195.6041,5.7288818,3.2000923,0.0,0,6.7670493,0.0,0.23952672,57.442787,6.8015265,449.79031,-9.2337141
3585,195.6061,5.7523007,3.221082,0.0,0,6.7428832,0.0,0.24158053,57.504616,6.7748446,450.11307,-9.2330112
3595,195.6081,5.7728429,3.2476013,0.0,0,6.7189231,0.0,0.24426706,57.585705,6.7483516,450.43579,-9.232851
3605,195.6101,5.7550583,3.276094,0.0,0,6.694963,0.0,0.24667059,57.276661,6.7224278,450.75851,-9.233592
3615,195.6121,5.7526226,3.302093,0.0,0,6.6710029,0.0,0.24840504,57.086098,6.6947803,451.08124,-9.2331438
3625,195.6141,5.758481,3.3268805,0.0,0,6.6470428,0.0,0.25024763,57.024635,6.6729178,451.38354,-9.2343559
3635,195.6161,5.7572751,3.3463202,0.0,0,6.6230831,0.0,0.25224215,57.019894,6.6504922,451.59869,-9.2336798
3645,195.6181,5.7596135,3.3693697,0.0,0,6.599123,0.0,0.25461444,56.890858,6.6238961,451.81384,-9.2325296
3655,195.6201,5.7705688,3.3940644,0.0,0,6.5751629,0.0,0.25686413,56.817528,6.5996799,452.02902,-9.2321482
3665,195.6221,5.7587605,3.4183896,0.0,0,6.5512033,0.0,0.25861782,56.607761,6.5755925,452.24417,-9.2337532
3675,195.6241,5.7720809,3.4464836,0.0,0,6.5272431,0.0,0.26059514,56.712502,6.5546541,452.44104,-9.2335196
3685,195.6261,5.792367,3.464467,0.0,0,6.503283,0.0,0.2623207,56.725555,6.5304408,452.5546,-9.2341995
3695,195.6281,5.811677,3.4875419,0.0,0,6.4793229,0.0,0.26473492,56.75642,6.504693,452.66815,-9.2340174
3705,195.6301,5.8203664,3.5108562,0.0,0,6.4553633,0.0,0.26705694,56.76049,6.4824214,452.78171,-9.2324572
3715,195.6321,5.8439651,3.534677,0.0,0,6.4314032,0.0,0.26881087,56.797447,6.4588785,452.89526,-9.232542
3725,195.6341,5.8580818,3.5661526,0.0,0,6.407443,0.0,0.27106556,56.862038,6.4374585,452.95901,-9.2323608
3735,195.6361,5.8787785,3.5866308,0.0,0,6.3834834,0.0,0.27292356,56.955936,6.4102502,452.77972,-9.2336159
3745,195.6381,5.8905358,3.6098373,0.0,0,6.3595228,0.0,0.27521715,56.895428,6.3859358,452.60043,-9.2341461
3755,195.6401,5.9019618,3.6318829,0.0,0,6.3355632,0.0,0.27768779,56.977592,6.3592696,452.42114,-9.2339754
3765,195.6421,5.9107013,3.6581235,0.0,0,6.3116031,0.0,0.27972174,56.867855,6.3348804,452.24185,-9.2330751
3775,195.6441,5.9152932,3.6890261,0.0,0,6.2876434,0.0,0.28203601,56.82246,6.3094592,452.04724,-9.2328825
3785,195.6461,5.9276552,3.7091844,0.0,0,6.2636833,0.0,0.2837002,56.814087,6.2846541,451.77231,-9.2323942
3795,195.6481,5.9471297,3.7296069,0.0,0,6.2397232,0.0,0.28573665,56.856907,6.2636027,451.49741,-9.2343102
3805,195.6501,5.9492698,3.7529516,0.0,0,6.2157631,0.0,0.28825459,56.797817,6.2397022,451.22247,-9.2343912
3815,195.6521,5.9522071,3.7783201,0.0,0,6.191803,0.0,0.29052314,56.598526,6.2116899,450.94754,-9.2344313
3825,195.6541,5.9484615,3.8066928,0.0,0,6.1678429,0.0,0.29258093,56.510082,6.1906672,450.72192,-9.2331715
3835,195.6561,5.9665399,3.8270898,0.0,0,6.1448579,0.0,0.29416689,56.587383,6.1705775,450.77573,-9.2329121
3845,195.6581,5.9794307,3.8492961,0.0,0,6.1220698,0.0,0.29625407,56.588352,6.145967,450.8295,-9.2325907
3855,195.6601,5.9957156,3.8684363,0.0,0,6.0992818,0.0,0.29852447,56.594284,6.1205158,450.8833,-9.2337599
3865,195.6621,6.0187802,3.8908832,0.0,0,6.0764937,0.0,0.30060521,56.751167,6.0977912,450.93707,-9.2345057
3875,195.6641,6.0326614,3.9215658,0.0,0,6.0537057,0.0,0.30314577,56.801083,6.075336,451.01346,-9.2344275
3885,195.6661,6.052525,3.9434216,0.0,0,6.0309176,0.0,0.30471417,56.801338,6.0500088,451.22864,-9.2336464
3895,195.6681,6.062757,3.9692168,0.0,0,6.0081296,0.0,0.30695823,56.752056,6.0279193,451.44379,-9.2337065
3905,195.6701,6.0645342,3.9868176,0.0,0,5.9853415,0.0,0.30903521,56.719604,6.0018358,451.65894,-9.2333908
3915,195.6721,6.0541835,4.0098386,0.0,0,5.9625535,0.0,0.31143385,56.471375,5.9814711,451.87411,-9.2332201
3925,195.6741,6.0613194,4.0350451,0.0,0,5.9397655,0.0,0.31351385,56.358952,5.9565544,452.09314,-9.2338228
3935,195.6761,6.0764351,4.0572228,0.0,0,5.9169779,0.0,0.3151308,56.426624,5.9360342,452.3382,-9.2332668
3945,195.6781,6.0849552,4.0819192,0.0,0,5.8941898,0.0,0.31713095,56.443764,5.9120784,452.58322,-9.2345343
3955,195.6801,6.0996313,4.0966239,0.0,0,5.8714018,0.0,0.31891504,56.397972,5.889905,452.82828,-9.2329941
3965,195.6821,6.1347265,4.1215053,0.0,0,5.8486137,0.0,0.32157063,56.667507,5.8639255,453.0733,-9.2322407
3975,195.6841,6.1461287,4.1458163,0.0,0,5.8258257,0.0,0.32386696,56.598213,5.8443704,453.32767,-9.2328663
3985,195.6861,6.1579962,4.1694417,0.0,0,5.8030376,0.0,0.32555866,56.55109,5.8182607,453.65042,-9.2326975
3995,195.6881,6.1728773,4.1969023,0.0,0,5.7802491,0.0,0.32765371,56.614307,5.79635,453.97314,-9.2324181
4005,195.6901,6.1785836,4.2142158,0.0,0,5.7574615,0.0,0.3295821,56.514278,5.776845,454.29587,-9.2339611
4015,195.6921,6.2016459,4.2345448,0.0,0,5.7346735,0.0,0.33192787,56.654034,5.7536907,454.61859,-9.2330494
4025,195.6941,6.2085233,4.259583,0.0,0,5.7118855,0.0,0.33439499,56.508102,5.7289953,454.9433,-9.2324667
4035,195.6961,6.2168131,4.2836938,0.0,0,5.6890974,0.0,0.33631471,56.561256,5.7030215,455.28397,-9.2331123
4045,195.6981,6.2432418,4.31109,0.0,0,5.6663094,0.0,0.33829463,56.640381,5.6807642,455.62463,-9.2321873
4055,195.7001,6.2486925,4.3264327,0.0,0,5.6435213,0.0,0.33998451,56.649586,5.6599607,455.9653,-9.2325392
4065,195.7021,6.2528906,4.3503551,0.0,0,5.6207333,0.0,0.34271491,56.569511,5.6364579,456.30597,-9.2321005
4075,195.7041,6.2684402,4.3734398,0.0,0,5.5979452,0.0,0.34513885,56.506359,5.6128917,456.63885,-9.2337236
4085,195.7061,6.2702904,4.3971386,0.0,0,5.5760784,0.0,0.34704667,56.451881,5.5922141,456.90182,-9.2333298
4095,195.7081,6.2908344,4.4261427,0.0,0,5.554399,0.0,0.34920758,56.530472,5.5681715,457.16479,-9.2337561
4105,195.7101,6.2955041,4.4437819,0.0,0,5.5327187,0.0,0.35089326,56.476284,5.5417638,457.42773,-9.2337093
4115,195.7121,6.2837262,4.4640198,0.0,0,5.5110388,0.0,0.35335448,56.156578,5.5226817,457.6907,-9.2337818
4125,195.7141,6.2654338,4.4821882,0.0,0,5.4893584,0.0,0.35542634,55.928349,5.5018787,457.94827,-9.2343702
4135,195.7161,6.2542577,4.5060258,0.0,0,5.4676785,0.0,0.3575452,55.759418,5.480217,458.15137,-9.2330475
4145,195.7181,6.2573943,4.5329242,0.0,0,5.4459987,0.0,0.35946816,55.686905,5.4624968,458.35446,-9.2320595
4155,195.7201,6.3076096,4.5482373,0.0,0,5.4243188,0.0,0.36092439,56.00053,5.4370422,458.55756,-9.2323093
4165,195.7221,6.3308764,4.5704823,0.0,0,5.4026389,0.0,0.36319038,56.118134,5.4172645,458.76068,-9.2340946
4175,195.7241,6.3495555,4.5900927,0.0,0,5.3809586,0.0,0.36563,56.11866,5.3956561,458.95993,-9.234478
4185,195.7261,6.3577199,4.6144729,0.0,0,5.3592787,0.0,0.36790735,55.992023,5.3744092,459.11514,-9.2321444
4195,195.7281,6.3528986,4.6397204,0.0,0,5.3375988,0.0,0.36993429,55.898113,5.3525133,459.27036,-9.2331104
4205,195.7301,6.3673158,4.6606436,0.0,0,5.3159184,0.0,0.37165329,55.933201,5.3314457,459.42557,-9.2338676
4215,195.7321,6.3875618,4.6837878,0.0,0,5.2942386,0.0,0.37391871,55.979435,5.3098855,459.58075,-9.2331533
4225,195.7341,6.4126534,4.6991844,0.0,0,5.2725587,0.0,0.37601072,56.090862,5.2869525,459.73471,-9.2337971
4235,195.7361,6.4176922,4.7205892,0.0,0,5.2508788,0.0,0.37831858,55.980698,5.2635813,459.87198,-9.2337141
4245,195.7381,6.420547,4.750299,0.0,0,5.2291985,0.0,0.38087225,55.940254,5.2415638,460.00925,-9.2332277
4255,195.7401,6.4193335,4.7710924,0.0,0,5.2075191,0.0,0.38248158,55.77821,5.2207909,460.14655,-9.2329063
4265,195.7421,6.4327269,4.7938161,0.0,0,5.1858387,0.0,0.38459253,55.784279,5.1973038,460.28381,-9.2333603
4275,195.7441,6.4469538,4.8087606,0.0,0,5.1641588,0.0,0.38649309,55.791405,5.1770496,460.42181,-9.2326212
4285,195.7461,6.4566731,4.830399,0.0,0,5.1424785,0.0,0.38910872,55.651207,5.1544819,460.57101,-9.2328348
4295,195.7481,6.4699836,4.8591213,0.0,0,5.1207986,0.0,0.39166808,55.672707,5.1348176,460.72021,-9.2322083
4305,195.7501,6.4751177,4.8758345,0.0,0,5.0991187,0.0,0.39288774,55.684109,5.1126966,460.86945,-9.2340231
4315,195.7521,6.4875813,4.9011641,0.0,0,5.0774388,0.0,0.39512566,55.638863,5.0902991,461.01865,-9.2340889
4325,195.7541,6.4978065,4.9154749,0.0,0,5.055759,0.0,0.3970077,55.615074,5.0674739,461.16397,-9.2335825
4335,195.7561,6.5231142,4.9364176,0.0,0,5.0349598,0.0,0.3994565,55.73745,5.0476403,461.2356,-9.2327881
4345,195.7581,6.5407867,4.9616914,0.0,0,5.0143399,0.0,0.40193924,55.673866,5.0270181,461.30722,-9.2322264
4355,195.7601,6.5551214,4.9850216,0.0,0,4.9937201,0.0,0.40379632,55.716549,5.0056462,461.37885,-9.2332535
4365,195.7621,6.5684948,5.0107765,0.0,0,4.9731002,0.0,0.40585089,55.682117,4.9822936,461.45047,-9.2343178
4375,195.7641,6.5876374,5.0238152,0.0,0,4.9524803,0.0,0.40763891,55.779625,4.9644976,461.52017,-9.2331743
4385,195.7661,6.5878816,5.0430231,0.0,0,4.93186,0.0,0.41000959,55.677395,4.9383759,461.54407,-9.2327709
4395,195.7681,6.5991783,5.0666847,0.0,0,4.9112396,0.0,0.41260409,55.560654,4.9183936,461.56793,-9.2339582
4405,195.7701,6.6069059,5.0893683,0.0,0,4.8906198,0.0,0.41448534,55.548397,4.8991985,461.59183,-9.2347116
4415,195.7721,6.6300721,5.1133604,0.0,0,4.8699999,0.0,0.41623756,55.669952,4.8802781,461.61569,-9.2341623
4425,195.7741,6.6634932,5.1287208,0.0,0,4.84938,0.0,0.41808704,55.856411,4.8580933,461.61624,-9.2330198
4435,195.7761,6.677897,5.1484199,0.0,0,4.8287597,0.0,0.4206723,55.809464,4.8348699,460.86359,-9.233942
4445,195.7781,6.6764121,5.1730242,0.0,0,4.8081398,0.0,0.42349818,55.709541,4.8115015,460.11093,-9.232934
4455,195.7801,6.6585751,5.1956363,0.0,0,4.7875199,0.0,0.42527476,55.351204,4.7916808,459.35831,-9.2315207
4465,195.7821,6.6625457,5.218626,0.0,0,4.7669001,0.0,0.42715168,55.361259,4.7718573,458.60565,-9.2332039
4475,195.7841,6.6776443,5.2334008,0.0,0,4.7462797,0.0,0.42857826,55.290657,4.7561717,457.84592,-9.2336092
4485,195.7861,6.6945996,5.2511129,0.0,0,4.7256598,0.0,0.43085963,55.317875,4.7326956,456.74066,-9.2338142
4495,195.7881,6.7154164,5.269742,0.0,0,4.70504,0.0,0.43324009,55.479912,4.7145844,455.63541,-9.2332821
4505,195.7901,6.7242575,5.2896314,0.0,0,4.6844196,0.0,0.43508199,55.42004,4.6940866,454.53015,-9.2337503
4515,195.7921,6.7380114,5.315341,0.0,0,4.6637998,0.0,0.43716735,55.420551,4.6739426,453.4249,-9.2313652
4525,195.7941,6.7890525,5.3333635,0.0,0,4.6431799,0.0,0.43893752,55.742039,4.6552,452.32086,-9.2330666
4535,195.7961,6.8126202,5.3533864,0.0,0,4.62256,0.0,0.44123337,55.770077,4.6319809,451.33472,-9.2318106
4545,195.7981,6.8231659,5.370461,0.0,0,4.6019402,0.0,0.44374204,55.732059,4.6129518,450.3486,-9.2349129
4555,195.8001,6.8306236,5.3953929,0.0,0,4.5813198,0.0,0.44613254,55.66267,4.5935416,449.36246,-9.2331104
4565,195.8021,6.8354497,5.4197826,0.0,0,4.5606995,0.0,0.4482044,55.621029,4.5688529,448.37634,-9.2327795
4575,195.8041,6.8594975,5.439374,0.0,0,4.5400796,0.0,0.45003238,55.694416,4.547502,447.39023,-9.2328186
4585,195.8061,6.8611579,5.4588594,0.0,0,4.5202942,0.0,0.45206863,55.581985,4.5299115,446.56531,-9.2329397
4595,195.8081,6.8775682,5.4735022,0.0,0,4.5006781,0.0,0.45427504,55.674141,4.5107784,445.74039,-9.2323608
4605,195.8101,6.9080338,5.4952617,0.0,0,4.4810619,0.0,0.45677471,55.6591,4.4899912,444.9155,-9.2326393
4615,195.8121,6.918963,5.5189099,0.0,0,4.4614463,0.0,0.4587808,55.619072,4.4693208,444.09058,-9.2328463
4625,195.8141,6.9250865,5.5396981,0.0,0,4.4418302,0.0,0.46069971,55.646431,4.4477186,443.26566,-9.2340145
4635,195.8161,6.9641461,5.5627365,0.0,0,4.422214,0.0,0.46288511,55.82618,4.4277625,443.21603,-9.2329369
4645,195.8181,6.9691262,5.5778713,0.0,0,4.4025984,0.0,0.46500117,55.765224,4.4046226,443.17419,-9.2322226
4655,195.8201,6.9707532,5.5976167,0.0,0,4.3829823,0.0,0.4675169,55.579266,4.3876371,443.13235,-9.2331295
4665,195.8221,6.9756703,5.6228867,0.0,0,4.3633661,0.0,0.47011214,55.471836,4.3666539,443.09052,-9.2334776
4675,195.8241,6.9592896,5.6411538,0.0,0,4.34375,0.0,0.4714382,55.28825,4.3485298,443.04868,-9.2325678
4685,195.8261,6.970778,5.6621013,0.0,0,4.3241343,0.0,0.47332945,55.305595,4.3276834,442.98331,-9.2311373
4695,195.8281,6.9818206,5.6766028,0.0,0,4.3045182,0.0,0.47547314,55.273281,4.3067617,442.91748,-9.2331839
4705,195.8301,6.9977951,5.695416,0.0,0,4.2849021,0.0,0.4779419,55.325222,4.2884741,442.85162,-9.2329426
4715,195.8321,7.0202904,5.7167001,0.0,0,4.2652864,0.0,0.4802731,55.263065,4.2696047,442.78577,-9.2322989
4725,195.8341,7.0650096,5.7375326,0.0,0,4.2456703,0.0,0.48195046,55.529102,4.2489557,442.71994,-9.2323666
4735,195.8361,7.0908117,5.7640424,0.0,0,4.2260537,0.0,0.48427486,55.622593,4.2290616,442.16061,-9.2342854
4745,195.8381,7.0847216,5.7794256,0.0,0,4.2064381,0.0,0.48634943,55.473969,4.2122521,441.58603,-9.2333374
4755,195.8401,7.0909252,5.7968307,0.0,0,4.1868219,0.0,0.48884112,55.421207,4.1921062,441.01144,-9.2323418
4765,195.8421,7.0796361,5.8167796,0.0,0,4.1672063,0.0,0.49121734,55.187637,4.1714706,440.43689,-9.2324533
4775,195.8441,7.0977702,5.8382268,0.0,0,4.1475902,0.0,0.4929755,55.187275,4.1492414,439.8623,-9.2336264
4785,195.8461,7.0896821,5.8645701,0.0,0,4.127974,0.0,0.495289,55.040932,4.1298051,439.09229,-9.2331934
4795,195.8481,7.1037226,5.8763766,0.0,0,4.1083584,0.0,0.49675283,55.078011,4.1152062,438.31415,-9.2325125
4805,195.8501,7.1494164,5.8927217,0.0,0,4.0887423,0.0,0.49916717,55.215389,4.093277,437.53598,-9.2335958
4815,195.8521,7.1592464,5.9121161,0.0,0,4.0691261,0.0,0.50164586,55.173702,4.0729823,436.75784,-9.2324829
4825,195.8541,7.1551223,5.9319391,0.0,0,4.0495105,0.0,0.50347948,55.081749,4.0587926,435.97968,-9.2330065
4835,195.8561,7.1742644,5.9589953,0.0,0,4.0306921,0.0,0.50567818,55.063557,4.0364575,435.77588,-9.2327719
4845,195.8581,7.1880751,5.9732509,0.0,0,4.0120363,0.0,0.50738633,55.105167,4.0172253,435.60229,-9.2330523
4855,195.8601,7.2135582,5.9896755,0.0,0,3.9933801,0.0,0.50965852,55.246029,3.9976363,435.42871,-9.2334194
4865,195.8621,7.2519579,6.0075402,0.0,0,3.9747245,0.0,0.51223409,55.3288,3.975286,435.2551,-9.233284
4875,195.8641,7.2779632,6.030261,0.0,0,3.9560683,0.0,0.51447719,55.37056,3.9567792,435.08151,-9.2335091
4885,195.8661,7.2957168,6.0581045,0.0,0,3.9374123,0.0,0.51685876,55.390911,3.9381485,435.68445,-9.2327499
4895,195.8681,7.3033891,6.0741138,0.0,0,3.9187562,0.0,0.51855981,55.309753,3.9145172,436.33688,-9.2326117
4905,195.8701,7.304081,6.0888114,0.0,0,3.9001,0.0,0.52054071,55.228409,3.8970742,436.98935,-9.2322092
4915,195.8721,7.2851968,6.1023579,0.0,0,3.8814442,0.0,0.52268481,55.058704,3.879967,437.64182,-9.2323198
4925,195.8741,7.2919068,6.1237769,0.0,0,3.862788,0.0,0.52513069,54.895145,3.8615692,438.29425,-9.2332745
4935,195.8761,7.2764125,6.1474109,0.0,0,3.8441322,0.0,0.52720934,54.694401,3.8451331,439.14133,-9.2338963
4945,195.8781,7.29914,6.1624904,0.0,0,3.8254764,0.0,0.52859324,54.767563,3.8270311,440.00305,-9.2335615
4955,195.8801,7.3302083,6.1803136,0.0,0,3.8068202,0.0,0.53062761,54.952904,3.8135939,440.86478,-9.232605
4965,195.8821,7.382957,6.1922483,0.0,0,3.7881644,0.0,0.53271294,55.119255,3.7931056,441.72647,-9.2330475
4975,195.8841,7.4059687,6.2116756,0.0,0,3.7695081,0.0,0.53515959,55.189159,3.7749913,442.5882,-9.2332726
4985,195.8861,7.4329233,6.2378144,0.0,0,3.7508521,0.0,0.53765196,55.232254,3.7582202,443.20187,-9.2324476
4995,195.8881,7.4614897,6.2525587,0.0,0,3.7321961,0.0,0.53886032,55.391045,3.7359974,443.79401,-9.2335215
5005,195.8901,7.5017195,6.2728305,0.0,0,3.7135401,0.0,0.54102153,55.546585,3.7175152,444.38614,-9.232398
5015,195.8921,7.5078135,6.2891922,0.0,0,3.6948841,0.0,0.54361159,55.503632,3.7014718,444.97827,-9.2337542
5025,195.8941,7.5548358,6.308229,0.0,0,3.6762283,0.0,0.54625815,55.659706,3.6798623,445.57037,-9.2334833
5035,195.8961,7.5792217,6.3300734,0.0,0,3.6575723,0.0,0.54844445,55.769672,3.6595132,445.93912,-9.2331066
5045,195.8981,7.5894637,6.3513808,0.0,0,3.6389163,0.0,0.55027699,55.697956,3.644521,446.28577,-9.2331324
5055,195.9001,7.6238594,6.3752584,0.0,0,3.6202602,0.0,0.55270916,55.818718,3.6200526,446.63239,-9.2334595
5065,195.9021,7.643846,6.3866091,0.0,0,3.6016042,0.0,0.55459768,55.825912,3.6002233,446.97903,-9.2323675
5075,195.9041,7.6527505,6.4063325,0.0,0,3.5829482,0.0,0.55744028,55.848911,3.5823102,447.32568,-9.23209
5085,195.9061,7.6506181,6.4270353,0.0,0,3.565047,0.0,0.55992675,55.630646,3.5643127,447.67767,-9.2317305
5095,195.9081,7.658618,6.4456301,0.0,0,3.5472991,0.0,0.5613718,55.640697,3.5443096,448.0303,-9.2326069
5105,195.9101,7.6673012,6.4682751,0.0,0,3.529551,0.0,0.56351364,55.547264,3.5252082,448.3829,-9.2330065
5115,195.9121,7.6827388,6.4809113,0.0,0,3.5118032,0.0,0.56547791,55.585365,3.5059309,448.73553,-9.2333584
5125,195.9141,7.6963377,6.4966254,0.0,0,3.494055,0.0,0.56798196,55.548573,3.489435,449.08813,-9.2331772
5135,195.9161,7.7185721,6.5178771,0.0,0,3.4763069,0.0,0.57064432,55.509449,3.4713864,449.30777,-9.2336292
5145,195.9181,7.7168837,6.5356827,0.0,0,3.458559,0.0,0.57216173,55.396183,3.4529128,449.51099,-9.2325439
5155,195.9201,7.7119503,6.5564971,0.0,0,3.4408112,0.0,0.57386589,55.286762,3.43732,449.71417,-9.2331619
5165,195.9221,7.7123775,6.5673385,0.0,0,3.423063,0.0,0.57560319,55.218861,3.4219179,449.91739,-9.2341433
5175,195.9241,7.7110419,6.5845385,0.0,0,3.4053149,0.0,0.57819659,55.088966,3.4016418,450.12057,-9.233717
5185,195.9261,7.7456188,6.6005373,0.0,0,3.3875673,0.0,0.58054549,55.198292,3.3872685,450.18176,-9.233387
5195,195.9281,7.7640715,6.6185198,0.0,0,3.3698189,0.0,0.58219171,55.195621,3.3698747,450.2236,-9.233264
5205,195.9301,7.8149915,6.6403451,0.0,0,3.3520713,0.0,0.58405924,55.525433,3.3549464,450.26544,-9.2330265
5215,195.9321,7.8345542,6.6556959,0.0,0,3.3343229,0.0,0.58586961,55.553764,3.3397937,450.30728,-9.2337589
5225,195.9341,7.8774037,6.6690149,0.0,0,3.3165751,0.0,0.58821577,55.70557,3.3182139,450.34912,-9.234189
5235,195.9361,7.9062133,6.6883483,0.0,0,3.2988269,0.0,0.59102827,55.784004,3.3005259,450.38055,-9.2327747
5245,195.9381,7.9295659,6.7078857,0.0,0,3.2810788,0.0,0.59307081,55.811977,3.2811604,450.41043,-9.2337923
5255,195.9401,7.9394865,6.7306476,0.0,0,3.2633312,0.0,0.59501708,55.764385,3.2638099,450.44031,-9.2341948
5265,195.9421,7.9551849,6.7476625,0.0,0,3.2455828,0.0,0.59697998,55.783863,3.2439795,450.47021,-9.2330837
5275,195.9441,7.9594302,6.7638378,0.0,0,3.2278352,0.0,0.59924072,55.713455,3.2269962,450.50009,-9.2330608
5285,195.9461,7.9607682,6.7773767,0.0,0,3.2100868,0.0,0.60179996,55.588875,3.2103975,450.43231,-9.2338743
5295,195.9481,7.9967866,6.7981644,0.0,0,3.1923389,0.0,0.60420519,55.629581,3.1926181,450.34863,-9.2342606
5305,195.9501,8.0248423,6.8231921,0.0,0,3.1745908,0.0,0.60650814,55.694794,3.1748567,450.26498,-9.2332458
5315,195.9521,8.0456705,6.8349166,0.0,0,3.1568429,0.0,0.60771823,55.785145,3.1558149,450.1813,-9.2328405
5325,195.9541,8.070097,6.8518147,0.0,0,3.1390951,0.0,0.6097846,55.873005,3.1380432,450.09763,-9.2328777
5335,195.9561,8.0959158,6.8672771,0.0,0,3.1220653,0.0,0.61251622,55.88945,3.1224325,449.8006,-9.2332764
5345,195.9581,8.0956573,6.8873672,0.0,0,3.1051812,0.0,0.61517107,55.709904,3.1049321,449.46591,-9.2338915
5355,195.9601,8.0987558,6.9094439,0.0,0,3.0882971,0.0,0.61741889,55.680489,3.0871024,449.13123,-9.23316
5365,195.9621,8.1196518,6.922946,0.0,0,3.071413,0.0,0.61852735,55.702923,3.0685558,448.79654,-9.2339621
5375,195.9641,8.1277237,6.9421062,0.0,0,3.054529,0.0,0.62084293,55.618908,3.0561807,448.46185,-9.2345409
5385,195.9661,8.1617918,6.9572549,0.0,0,3.0376453,0.0,0.62334561,55.722393,3.0350983,448.36816,-9.2331486
5395,195.9681,8.1887445,6.9711943,0.0,0,3.020761,0.0,0.62573737,55.768566,3.019743,448.32034,-9.2332249
5405,195.9701,8.2393532,6.9936013,0.0,0,3.0038772,0.0,0.6282438,55.963371,3.0004466,448.27252,-9.2335119
5415,195.9721,8.232708,7.0155392,0.0,0,2.9869933,0.0,0.63012218,55.787228,2.9827745,448.2247,-9.2334652
5425,195.9741,8.2221613,7.0306468,0.0,0,2.970109,0.0,0.63167322,55.699524,2.9659824,448.17688,-9.2317877
5435,195.9761,8.2511721,7.0404115,0.0,0,2.9532251,0.0,0.63359481,55.73772,2.9493458,448.16379,-9.233799
5445,195.9781,8.2576818,7.0588365,0.0,0,2.936341,0.0,0.63650382,55.609604,2.9304552,448.15781,-9.2329435
5455,195.9801,8.2811174,7.0785246,0.0,0,2.919457,0.0,0.63896435,55.633556,2.9142902,448.15182,-9.2325392
5465,195.9821,8.301631,7.0952291,0.0,0,2.9025733,0.0,0.64033324,55.681267,2.8982038,448.14584,-9.2331724
5475,195.9841,8.3190174,7.1144886,0.0,0,2.8856893,0.0,0.64212543,55.683628,2.8820901,448.13986,-9.2325048
5485,195.9861,8.3256378,7.1247573,0.0,0,2.8688052,0.0,0.64407289,55.695683,2.865885,448.05057,-9.2334776
5495,195.9881,8.3615093,7.1399059,0.0,0,2.8519211,0.0,0.64669007,55.742371,2.8493235,447.94299,-9.2331524
5505,195.9901,8.3922777,7.1579638,0.0,0,2.835037,0.0,0.64940214,55.84185,2.8353965,447.83545,-9.2324047
5515,195.9921,8.440937,7.1774607,0.0,0,2.8181531,0.0,0.65101242,56.032852,2.8174095,447.72787,-9.2334185
5525,195.9941,8.4920664,7.1992903,0.0,0,2.8012691,0.0,0.65292984,56.241219,2.7974284,447.6203,-9.2328558
5535,195.9961,8.5331907,7.2091928,0.0,0,2.7843852,0.0,0.65472478,56.409184,2.7851195,447.83224,-9.2328691
5545,195.9981,8.5597744,7.2267218,0.0,0,2.7675011,0.0,0.65757358,56.441628,2.7640281,448.11911,-9.2337389
5555,196.0001,8.5759487,7.2440906,0.0,0,2.750617,0.0,0.66035903,56.387226,2.7457273,448.40598,-9.2337418
5565,196.0021,8.5966282,7.2647638,0.0,0,2.7337332,0.0,0.66234994,56.44994,2.728991,448.69287,-9.2343969
5575,196.0041,8.5955343,7.2861743,0.0,0,2.7168491,0.0,0.66431785,56.305584,2.7121785,448.97974,-9.2333937
5585,196.0061,8.6105003,7.2992315,0.0,0,2.7006505,0.0,0.66611803,56.332539,2.6950362,449.39572,-9.2324266
5595,196.0081,8.6252766,7.3114319,0.0,0,2.6845903,0.0,0.66832477,56.268108,2.6809406,449.84396,-9.2325697
5605,196.0101,8.6398573,7.3251171,0.0,0,2.6685302,0.0,0.67081326,56.233646,2.663228,450.29218,-9.2333117
5615,196.0121,8.6560326,7.3462768,0.0,0,2.6524704,0.0,0.67325169,56.175846,2.6498845,450.74042,-9.2318697
5625,196.0141,8.667984,7.3691816,0.0,0,2.6364105,0.0,0.67529827,56.165867,2.6324189,451.18866,-9.2340193
5635,196.0161,8.6946564,7.3786764,0.0,0,2.6203501,0.0,0.6763804,56.257229,2.6186633,451.59442,-9.2331676
5645,196.0181,8.727149,7.3926172,0.0,0,2.6042902,0.0,0.67875332,56.287941,2.6024561,451.98886,-9.2331982
5655,196.0201,8.7697487,7.4043207,0.0,0,2.5882304,0.0,0.68107444,56.481167,2.5856876,452.3833,-9.2329597
5665,196.0221,8.7978601,7.4259734,0.0,0,2.5721703,0.0,0.68394178,56.541275,2.5691011,452.77777,-9.2322426
5675,196.0241,8.8319063,7.4468021,0.0,0,2.5561104,0.0,0.68579507,56.643566,2.5532854,453.17221,-9.232233
5685,196.0261,8.8735943,7.4602385,0.0,0,2.5400503,0.0,0.6872142,56.84341,2.5361552,453.49207,-9.2333708
5695,196.0281,8.9076853,7.4781113,0.0,0,2.5239902,0.0,0.68973219,56.90089,2.5195575,453.79089,-9.2337761
5705,196.0301,8.93085,7.4924688,0.0,0,2.5079303,0.0,0.69246477,56.917763,2.5018356,454.08972,-9.2322073
5715,196.0321,8.9348621,7.5056725,0.0,0,2.4918704,0.0,0.69456547,56.795399,2.486804,454.38855,-9.2321672
5725,196.0341,8.9346304,7.5291529,0.0,0,2.4758103,0.0,0.69705904,56.635887,2.4711471,454.68738,-9.232213
5735,196.0361,8.9496813,7.5419512,0.0,0,2.4597502,0.0,0.69820225,56.686356,2.4545598,454.9494,-9.2323456
5745,196.0381,8.9861326,7.560606,0.0,0,2.4436903,0.0,0.70055491,56.771091,2.4410105,455.20041,-9.2324839
5755,196.0401,8.995409,7.5724554,0.0,0,2.4276302,0.0,0.70300657,56.722427,2.4235864,455.45142,-9.2329092
5765,196.0421,9.0226002,7.5856209,0.0,0,2.4115703,0.0,0.70529872,56.759823,2.4044304,455.70242,-9.2341022
5775,196.0441,9.0398531,7.6053267,0.0,0,2.3955102,0.0,0.70769548,56.724796,2.3903453,455.95343,-9.2347469
5785,196.0461,9.0470171,7.6221461,0.0,0,2.3794503,0.0,0.70914584,56.68718,2.3760221,456.06818,-9.2333412
5795,196.0481,9.0810041,7.6412382,0.0,0,2.3633902,0.0,0.7112782,56.820381,2.3599067,456.13989,-9.2331457
5805,196.0501,9.1157312,7.6506896,0.0,0,2.3473303,0.0,0.71334076,56.863457,2.3445292,456.21161,-9.2320976
5815,196.0521,9.1488771,7.6666288,0.0,0,2.3312702,0.0,0.71625745,56.947906,2.3280392,456.28333,-9.232481
5825,196.0541,9.1876736,7.6845284,0.0,0,2.3152101,0.0,0.71860075,57.044586,2.3109,456.35507,-9.2335787
5835,196.0561,9.2204113,7.7011962,0.0,0,2.2998018,0.0,0.72009283,57.124481,2.293931,456.43127,-9.2336082
5845,196.0581,9.241106,7.7216096,0.0,0,2.2845259,0.0,0.7221362,57.203533,2.2819684,456.50897,-9.2330666
5855,196.0601,9.2577524,7.7318468,0.0,0,2.2692497,0.0,0.72425205,57.172768,2.2633471,456.58667,-9.2319927
5865,196.0621,9.2763405,7.7473769,0.0,0,2.253974,0.0,0.72709662,57.089695,2.2468812,456.66437,-9.232317
5875,196.0641,9.2938433,7.7654891,0.0,0,2.2386978,0.0,0.73006529,57.033646,2.2321632,456.74207,-9.2335329
5885,196.0661,9.2895222,7.7826176,0.0,0,2.2234218,0.0,0.7315526,56.888264,2.214808,456.70035,-9.2337103
5895,196.0681,9.3074112,7.8027987,0.0,0,2.2081459,0.0,0.73340702,56.922348,2.1993296,456.61667,-9.2328539
5905,196.0701,9.3405685,7.8127556,0.0,0,2.1928699,0.0,0.73515731,57.010361,2.1846406,456.53302,-9.232955
5915,196.0721,9.3478575,7.8237119,0.0,0,2.1775939,0.0,0.737652,56.95602,2.1690831,456.44934,-9.2327309
5925,196.0741,9.3608103,7.8403034,0.0,0,2.1623178,0.0,0.74040931,56.863861,2.1542513,456.36566,-9.2345705
5935,196.0761,9.3825665,7.8567095,0.0,0,2.1470418,0.0,0.7420181,56.869152,2.1403289,455.94168,-9.2338696
5945,196.0781,9.4188786,7.8775721,0.0,0,2.1317658,0.0,0.74404371,56.998379,2.1267679,455.39182,-9.2331009
5955,196.0801,9.4554424,7.8875494,0.0,0,2.1164899,0.0,0.74552089,57.097881,2.1114948,454.84198,-9.2335672
5965,196.0821,9.4970465,7.9011354,0.0,0,2.1012137,0.0,0.74818784,57.210171,2.0948498,454.29214,-9.2336044
5975,196.0841,9.5038166,7.9145575,0.0,0,2.085938,0.0,0.7508111,57.113518,2.079571,453.74228,-9.2329817
5985,196.0861,9.5308962,7.9285517,0.0,0,2.070662,0.0,0.75232071,57.160248,2.063446,452.67166,-9.2324152
5995,196.0881,9.5688591,7.952075,0.0,0,2.0553858,0.0,0.75483155,57.231838,2.0493314,451.39853,-9.2333107
6005,196.0901,9.5911484,7.9644456,0.0,0,2.0401099,0.0,0.75636262,57.355824,2.0347252,450.1254,-9.2337189
6015,196.0921,9.6210794,7.9766655,0.0,0,2.0248339,0.0,0.7584945,57.397274,2.0193729,448.85226,-9.2338133
6025,196.0941,9.6517019,7.9864669,0.0,0,2.009558,0.0,0.76091325,57.420609,2.0052958,447.57916,-9.2322454
6035,196.0961,9.6980181,8.0071487,0.0,0,1.9942819,0.0,0.76380038,57.500252,1.9924207,446.25464,-9.2316895
6045,196.0981,9.756299,8.0290451,0.0,0,1.9790059,0.0,0.76599878,57.730698,1.9754205,444.90918,-9.2336922
6055,196.1001,9.8079624,8.0406027,0.0,0,1.9637299,0.0,0.76726574,57.976719,1.9616907,443.56369,-9.2338409
6065,196.1021,9.8560152,8.0544367,0.0,0,1.948454,0.0,0.76935023,58.126415,1.9474638,442.2182,-9.233427
6075,196.1041,9.9312859,8.0680256,0.0,0,1.9331779,0.0,0.77237195,58.342865,1.9278607,440.87271,-9.2323008
6085,196.1061,9.9845219,8.0876408,0.0,0,1.9185205,0.0,0.775442,58.491642,1.91213,439.8364,-9.232954
6095,196.1081,9.9863186,8.1082554,0.0,0,1.9039885,0.0,0.7777437,58.446667,1.8962837,438.93253,-9.2334557
6105,196.1101,10.022454,8.1223469,0.0,0,1.8894564,0.0,0.77919233,58.479515,1.8819746,438.02866,-9.2329378
6115,196.1121,10.02938,8.1402054,0.0,0,1.8749244,0.0,0.78173047,58.447578,1.8631682,437.12482,-9.2325115
6125,196.1141,10.045403,8.1494942,0.0,0,1.8603925,0.0,0.78367025,58.402729,1.8455651,436.22095,-9.2317619
6135,196.1161,10.025869,8.1622639,0.0,0,1.8458605,0.0,0.78641647,58.188545,1.8319579,435.62274,-9.2331457
6145,196.1181,10.016598,8.1831074,0.0,0,1.8313285,0.0,0.78913897,57.939137,1.8209275,435.16183,-9.2322397
6155,196.1201,9.9799728,8.1980152,0.0,0,1.8167964,0.0,0.7902084,57.635986,1.8070818,434.70093,-9.2322445
6165,196.1221,9.9963026,8.2123289,0.0,0,1.8022645,0.0,0.79191184,57.617233,1.7924225,434.24002,-9.2329168
6175,196.1241,10.03071,8.2169304,0.0,0,1.7877324,0.0,0.7934916,57.754612,1.7818139,433.77911,-9.2327929
6185,196.1261,10.087246,8.2303143,0.0,0,1.7732004,0.0,0.79633582,57.903156,1.768595,433.81891,-9.2324381
6195,196.1281,10.130156,8.2489719,0.0,0,1.7586684,0.0,0.79898667,58.012142,1.7524246,434.09424,-9.2329636
6205,196.1301,10.185961,8.2654505,0.0,0,1.7441365,0.0,0.80051935,58.192585,1.736591,434.3696,-9.2326937
6215,196.1321,10.214348,8.2807131,0.0,0,1.7296044,0.0,0.8018527,58.333702,1.7256702,434.64493,-9.2322617
6225,196.1341,10.277114,8.2880192,0.0,0,1.7150724,0.0,0.80375004,58.547516,1.7115119,434.92029,-9.2332859
6235,196.1361,10.337388,8.3020592,0.0,0,1.7005404,0.0,0.8067711,58.726673,1.697786,435.12744,-9.2324438
6245,196.1381,10.40146,8.3196306,0.0,0,1.6860083,0.0,0.80969405,58.948944,1.6784824,435.30103,-9.2328348
6255,196.1401,10.441164,8.337142,0.0,0,1.6714765,0.0,0.81142825,59.030998,1.6630043,435.47461,-9.2322865
6265,196.1421,10.472662,8.3541059,0.0,0,1.6569444,0.0,0.81296301,59.165154,1.6502594,435.64819,-9.2328959
6275,196.1441,10.493943,8.3624163,0.0,0,1.6424124,0.0,0.81467068,59.158909,1.6365877,435.82178,-9.2333536
6285,196.1461,10.521713,8.3766193,0.0,0,1.6278805,0.0,0.81775141,59.119095,1.6193887,436.23242,-9.2328806
6295,196.1481,10.526677,8.3928165,0.0,0,1.6133484,0.0,0.82083118,59.00219,1.60382,436.76517,-9.2331676
6305,196.1501,10.536916,8.4069757,0.0,0,1.5988165,0.0,0.82230967,58.956779,1.5908648,437.29791,-9.233366
6315,196.1521,10.561328,8.4299707,0.0,0,1.5842843,0.0,0.82464707,58.943325,1.5790635,437.83066,-9.2323074
6325,196.1541,10.591751,8.4376373,0.0,0,1.5697525,0.0,0.82587498,59.090149,1.5633539,438.3634,-9.23277
6335,196.1561,10.622644,8.4467182,0.0,0,1.5558089,0.0,0.8282941,59.12355,1.5495652,439.14114,-9.2332726
6345,196.1581,10.667936,8.4622641,0.0,0,1.5419849,0.0,0.83131057,59.128792,1.5367639,440.05078,-9.2337799
6355,196.1601,10.698296,8.4785414,0.0,0,1.5281609,0.0,0.83335757,59.222195,1.5235575,440.96042,-9.2337646
6365,196.1621,10.733883,8.4959545,0.0,0,1.5143369,0.0,0.83511186,59.33984,1.5072107,441.87006,-9.2335186
6375,196.1641,10.769595,8.5086327,0.0,0,1.5005128,0.0,0.83669472,59.38105,1.4925456,442.77969,-9.2326555
6385,196.1661,10.801398,8.522747,0.0,0,1.4866889,0.0,0.83955884,59.408043,1.4812943,443.49365,-9.2328501
6395,196.1681,10.828506,8.5303774,0.0,0,1.4728649,0.0,0.84179193,59.41552,1.4645464,444.09756,-9.2336826
6405,196.1701,10.869949,8.5467567,0.0,0,1.4590409,0.0,0.84405875,59.509697,1.4498558,444.70148,-9.2337637
6415,196.1721,10.906424,8.5713081,0.0,0,1.4452169,0.0,0.84679228,59.532249,1.4352686,445.30536,-9.2325878
6425,196.1741,10.948785,8.5801716,0.0,0,1.4313928,0.0,0.84778291,59.708595,1.4242697,445.90927,-9.2336092
6435,196.1761,10.959083,8.591589,0.0,0,1.4175689,0.0,0.84996128,59.716301,1.4082195,445.90277,-9.2344332
6445,196.1781,10.993741,8.604104,0.0,0,1.4037448,0.0,0.85281622,59.646179,1.3954916,445.53784,-9.233077
6455,196.1801,10.993295,8.6161318,0.0,0,1.3899208,0.0,0.85519195,59.529503,1.3803136,445.17291,-9.2329912
6465,196.1821,11.044284,8.6367025,0.0,0,1.3760968,0.0,0.8576147,59.660824,1.3658847,444.80798,-9.2319479
6475,196.1841,11.105747,8.6493692,0.0,0,1.3622729,0.0,0.85877293,59.950523,1.3542953,444.44305,-9.2328568
6485,196.1861,11.170208,8.6645632,0.0,0,1.3484489,0.0,0.86113137,60.126522,1.3391151,444.1228,-9.2332058
6495,196.1881,11.186909,8.671936,0.0,0,1.3346249,0.0,0.86326647,60.07444,1.3237664,443.82996,-9.2318678
6505,196.1901,11.199887,8.68643,0.0,0,1.3208008,0.0,0.86606956,59.972893,1.3079209,443.53711,-9.2324114
6515,196.1921,11.209668,8.7044115,0.0,0,1.3069768,0.0,0.86858326,59.860439,1.2985051,443.24423,-9.233757
6525,196.1941,11.229752,8.7189159,0.0,0,1.2931529,0.0,0.86990511,59.881184,1.2836626,442.95139,-9.2328339
6535,196.1961,11.250537,8.7338476,0.0,0,1.2793289,0.0,0.87190622,59.921135,1.2724384,443.18011,-9.232233
6545,196.1981,11.281641,8.738718,0.0,0,1.2655048,0.0,0.87345159,60.000927,1.2566274,443.74228,-9.2342911
6555,196.2001,11.334594,8.7498999,0.0,0,1.2516809,0.0,0.87634724,60.074066,1.2442055,444.30444,-9.2333679
6565,196.2021,11.403551,8.7705336,0.0,0,1.2378569,0.0,0.87944579,60.241699,1.2303854,444.86661,-9.2336025
6575,196.2041,11.459884,8.7852764,0.0,0,1.2240329,0.0,0.88081348,60.467995,1.2166692,445.42874,-9.2325163
6585,196.2061,11.481747,8.8010397,0.0,0,1.2107708,0.0,0.88236254,60.495895,1.2039317,445.86877,-9.231905
6595,196.2081,11.519843,8.80618,0.0,0,1.1976228,0.0,0.88403952,60.600231,1.1893543,446.22736,-9.2330332
6605,196.2101,11.536347,8.8186169,0.0,0,1.1844749,0.0,0.88719261,60.489807,1.1768605,446.58594,-9.2331915
6615,196.2121,11.575489,8.8362122,0.0,0,1.1713269,0.0,0.89022857,60.463768,1.1640208,446.94452,-9.2318544
6625,196.2141,11.620274,8.8494444,0.0,0,1.1581788,0.0,0.89154422,60.627239,1.1490973,447.30313,-9.2317019
6635,196.2161,11.653006,8.8678312,0.0,0,1.1450309,0.0,0.89330685,60.694038,1.138522,447.59473,-9.2323256
6645,196.2181,11.70986,8.8729506,0.0,0,1.1318828,0.0,0.89470923,60.933407,1.121929,447.83975,-9.2326565
6655,196.2201,11.754787,8.8851175,0.0,0,1.1187348,0.0,0.89775389,60.972675,1.1101087,448.08481,-9.2335329
6665,196.2221,11.805378,8.8994637,0.0,0,1.1055869,0.0,0.90067708,61.059536,1.096994,448.32983,-9.2336082
6675,196.2241,11.853723,8.9136724,0.0,0,1.0924387,0.0,0.90225494,61.185665,1.0815569,448.57489,-9.2320557
6685,196.2261,11.885015,8.9333458,0.0,0,1.0792909,0.0,0.90435648,61.257359,1.07139,448.7402,-9.2315664
6695,196.2281,11.922873,8.9398146,0.0,0,1.0661428,0.0,0.90541255,61.369705,1.055953,448.84778,-9.2335958
6705,196.2301,11.953291,8.9514647,0.0,0,1.0529948,0.0,0.90828896,61.318619,1.0448098,448.95532,-9.2327528
6715,196.2321,12.001332,8.9641018,0.0,0,1.0398468,0.0,0.91124994,61.421627,1.0301952,449.0629,-9.2322693
6725,196.2341,12.031235,8.9783163,0.0,0,1.0266988,0.0,0.91308403,61.455513,1.0168209,449.17047,-9.232028
6735,196.2361,12.078952,8.9980164,0.0,0,1.0135508,0.0,0.9151805,61.555408,1.002334,449.34619,-9.2328405
6745,196.2381,12.102328,9.0047998,0.0,0,1.0004028,0.0,0.91611463,61.643009,0.99207139,449.5733,-9.2325144
6755,196.2401,12.136194,9.0150547,0.0,0,0.9872548,0.0,0.91854894,61.656647,0.97954011,449.80042,-9.2309265
6765,196.2421,12.180736,9.0241442,0.0,0,0.97410685,0.0,0.9213801,61.692944,0.96583247,450.02753,-9.2326641
6775,196.2441,12.218049,9.0396433,0.0,0,0.96095878,0.0,0.92364269,61.777832,0.95454144,450.25464,-9.2326622
6785,196.2461,12.248139,9.0572405,0.0,0,0.94781077,0.0,0.9255085,61.819454,0.94219643,450.36124,-9.2336321
6795,196.2481,12.274769,9.0680799,0.0,0,0.93466276,0.0,0.92690808,61.876816,0.93038172,450.3732,-9.232583
6805,196.2501,12.367511,9.0810518,0.0,0,0.92151481,0.0,0.92931449,62.192207,0.91438967,450.38516,-9.2325287
6815,196.2521,12.431031,9.0891037,0.0,0,0.9083668,0.0,0.93176937,62.359753,0.90384376,450.39709,-9.2320051
6825,196.2541,12.494801,9.1021147,0.0,0,0.89521879,0.0,0.93448609,62.481335,0.88975316,450.40906,-9.2324209
6835,196.2561,12.529433,9.1210165,0.0,0,0.88260609,0.0,0.93679744,62.506989,0.87720066,450.42429,-9.231946
6845,196.2581,12.583088,9.1324768,0.0,0,0.87010211,0.0,0.93794221,62.723782,0.86513931,450.44223,-9.2324562
6855,196.2601,12.632973,9.1473265,0.0,0,0.85759807,0.0,0.94015884,62.807388,0.8519488,450.46014,-9.2327709
6865,196.2621,12.698632,9.1534939,0.0,0,0.84509408,0.0,0.94234782,62.988617,0.83955896,450.47809,-9.2323294
6875,196.2641,12.738874,9.1661978,0.0,0,0.8325901,0.0,0.94541502,63.024258,0.82673728,450.49603,-9.2319899
6885,196.2661,12.77577,9.1878729,0.0,0,0.82008612,0.0,0.9486295,62.991863,0.81074703,450.12659,-9.2320862
6895,196.2681,12.831829,9.2023125,0.0,0,0.80758208,0.0,0.94987649,63.179447,0.7984817,449.42719,-9.2329578
6905,196.2701,12.868572,9.2160721,0.0,0,0.7950781,0.0,0.9518671,63.263435,0.78734237,448.72781,-9.2333879
6915,196.2721,12.921934,9.2211847,0.0,0,0.78257412,0.0,0.95362556,63.446541,0.77393454,448.02844,-9.2320833
6925,196.2741,12.962784,9.2309971,0.0,0,0.77007008,0.0,0.95644295,63.415524,0.75788206,447.32904,-9.232934
6935,196.2761,12.963497,9.2491837,0.0,0,0.75756609,0.0,0.95966196,63.219879,0.74429244,446.23007,-9.2322645
6945,196.2781,12.948618,9.264286,0.0,0,0.74506211,0.0,0.96107155,63.065224,0.7356168,444.77679,-9.2320852
6955,196.2801,12.922367,9.27917,0.0,0,0.73255813,0.0,0.96251321,62.871967,0.72265011,443.32352,-9.2322741
6965,196.2821,12.948177,9.2828455,0.0,0,0.72005409,0.0,0.9641552,62.859238,0.71062106,441.87024,-9.2331791
6975,196.2841,12.975591,9.2912846,0.0,0,0.70755011,0.0,0.96685582,62.804176,0.69888467,440.41693,-9.2336693
6985,196.2861,13.044019,9.3079967,0.0,0,0.69504607,0.0,0.96993327,62.973515,0.6865378,439.07196,-9.2336168
6995,196.2881,13.111464,9.3191986,0.0,0,0.68254209,0.0,0.97096211,63.229652,0.67890924,437.8269,-9.2337217
7005,196.2901,13.216526,9.3364697,0.0,0,0.6700381,0.0,0.97270477,63.613293,0.66209555,436.58185,-9.2333612
7015,196.2921,13.289895,9.3452778,0.0,0,0.65753412,0.0,0.97482073,63.840504,0.64955753,435.33679,-9.2329292
7025,196.2941,13.361447,9.3533783,0.0,0,0.64503014,0.0,0.9774527,64.019112,0.63676327,434.09174,-9.2322388
7035,196.2961,13.425519,9.3682318,0.0,0,0.6325261,0.0,0.98079735,64.109016,0.62432969,433.27408,-9.2322092
7045,196.2981,13.473844,9.3837852,0.0,0,0.62002212,0.0,0.98279691,64.200775,0.60940534,432.86707,-9.2323036
7055,196.3001,13.497331,9.4022732,0.0,0,0.60751808,0.0,0.98467666,64.223206,0.5957849,432.46002,-9.2325468
7065,196.3021,13.532156,9.4082699,0.0,0,0.5950141,0.0,0.98590767,64.294533,0.58646351,432.05298,-9.2322626
7075,196.3041,13.551789,9.4194679,0.0,0,0.58251011,0.0,0.98888135,64.195137,0.57339025,431.64594,-9.2322359
7085,196.3061,13.582104,9.4276848,0.0,0,0.57050818,0.0,0.99130869,64.173927,0.56182051,431.66992,-9.2328777
7095,196.3081,13.611079,9.4414501,0.0,0,0.55860817,0.0,0.99327242,64.147591,0.5465495,432.12485,-9.2317066
7098,196.3087,13.660286,9.4445667,0.0,0,0.55503821,0.0,0.99402934,64.337105,0.54161417,432.26132,-9.2322454