File: clean data/testID_0097.csv
level_0,index,Time(sec),Force(kN),Jaw(mm),PowAngle(deg),Power(W),Pram,PTemp,Strain,Stress(MPa),Stroke(mm),TC1(C),wedge(mm)
2105,2105,178.6824,0.60456663,0.008188406,0.0,0,9.0629702,0.0,0.00063148519,7.3995662,10.106804,400.4411,-9.2647533
2106,2106,178.6826,1.1757803,0.014949855,0.0,0,9.0337067,0.0,0.0011298653,12.708526,10.069744,400.40015,-9.2645588
2107,2107,178.6828,2.670136,0.032711711,0.0,0,9.0044422,0.0,0.0017440965,29.589428,10.037098,400.35922,-9.2645874
2108,2108,178.683,4.1989207,0.060568042,0.0,0,8.9751787,0.0,0.0036326204,49.746506,10.011881,400.31827,-9.2640371
2109,2109,178.6832,5.0286846,0.087119147,0.0,0,8.9459143,0.0,0.0057464945,62.135559,9.9916801,400.27734,-9.2637091
2110,2110,178.6834,5.3306613,0.10791653,0.0,0,8.9166508,0.0,0.0068336679,66.861458,9.9644375,400.23642,-9.2629452
2111,2111,178.6836,5.4876838,0.13403031,0.0,0,8.8873863,0.0,0.0084632849,68.774727,9.9322662,400.19547,-9.2615461
2112,2112,178.6838,5.6743593,0.18140849,0.0,0,8.8581219,0.0,0.01170974,70.973694,9.8953762,400.15454,-9.2607384
2113,2113,178.684,5.6331382,0.25246626,0.0,0,8.8288584,0.0,0.015930491,70.955551,9.8547153,400.11359,-9.2604027
2114,2114,178.6842,5.4516306,0.31449562,0.0,0,8.7995939,0.0,0.02022603,68.40921,9.8142805,400.07266,-9.2604094
2115,2115,178.6844,5.5627933,0.34530097,0.0,0,8.7703304,0.0,0.023187978,68.59021,9.7686453,400.03174,-9.2614079
2116,2116,178.6846,5.9509029,0.37105998,0.0,0,8.7416534,0.0,0.024715768,73.011604,9.7242022,399.99078,-9.2614861
2117,2117,178.6848,6.107172,0.41121227,0.0,0,8.7136879,0.0,0.026972268,75.449738,9.6812305,399.94986,-9.2609596
2118,2118,178.685,6.092361,0.46016818,0.0,0,8.6858492,0.0,0.030695342,75.129295,9.6369572,399.90891,-9.2608299
2119,2119,178.6852,6.2774034,0.5084371,0.0,0,8.6580172,0.0,0.034047719,76.603577,9.5968609,399.86798,-9.2601662
2120,2120,178.6854,6.5208445,0.52958125,0.0,0,8.6301851,0.0,0.035538729,79.656364,9.5596476,399.82706,-9.2594404
2121,2121,178.6856,6.4619055,0.52581066,0.0,0,8.6023531,0.0,0.035811223,79.794235,9.5250893,399.7861,-9.2592812
2122,2122,178.6858,6.1109943,0.5461728,0.0,0,8.574522,0.0,0.036794934,75.793579,9.4930305,399.74518,-9.2598915
2123,2123,178.686,5.941885,0.59621036,0.0,0,8.546689,0.0,0.03950996,72.763206,9.4622211,399.70422,-9.260663
2124,2124,178.6862,6.1970677,0.63821465,0.0,0,8.518857,0.0,0.042937048,74.622803,9.4339933,399.6633,-9.2615709
2125,2125,178.6864,6.5820413,0.66692632,0.0,0,8.4910259,0.0,0.045313783,79.078064,9.4043598,399.62238,-9.2618151
2126,2126,178.6866,6.7603955,0.68484271,0.0,0,8.4631929,0.0,0.046238825,81.843422,9.3716316,399.58142,-9.2605448
2127,2127,178.6868,6.7786503,0.70044422,0.0,0,8.4353609,0.0,0.047447804,82.299736,9.3376265,399.5405,-9.2595081
2128,2128,178.687,6.7988586,0.74952114,0.0,0,8.4075298,0.0,0.050708055,82.239502,9.3018627,399.49954,-9.2581816
2129,2129,178.6872,6.8053632,0.81861341,0.0,0,8.3796968,0.0,0.055004388,82.107742,9.2625332,399.45862,-9.2576895
2130,2130,178.6874,6.7237196,0.86370379,0.0,0,8.3518648,0.0,0.058630358,80.983498,9.2241259,399.80777,-9.2587118
2131,2131,178.6876,6.6137953,0.89891791,0.0,0,8.3240337,0.0,0.06158936,79.412514,9.1843252,400.15692,-9.2590694
2132,2132,178.6878,6.5997376,0.93771714,0.0,0,8.2962017,0.0,0.063848726,78.863289,9.1423826,400.50607,-9.2596598
2133,2133,178.688,6.694171,0.97173899,0.0,0,8.2683697,0.0,0.066253878,79.505447,9.101018,400.85522,-9.2605057
2134,2134,178.6882,6.8194809,1.0143255,0.0,0,8.2405376,0.0,0.069693312,80.637573,9.0605001,401.20441,-9.2611418
2135,2135,178.6884,6.8685656,1.05208,0.0,0,8.2127056,0.0,0.072189853,81.245872,9.0229864,401.55356,-9.2613039
2136,2136,178.6886,6.8726635,1.0655276,0.0,0,8.1848736,0.0,0.073233634,81.319931,8.9860649,401.90271,-9.260416
2137,2137,178.6888,6.8938026,1.0837263,0.0,0,8.1570415,0.0,0.074896909,81.365433,8.953392,402.25186,-9.259717
2138,2138,178.689,6.8830271,1.1197017,0.0,0,8.1292095,0.0,0.077071451,81.146324,8.9225264,402.60101,-9.2600164
2139,2139,178.6892,6.8347454,1.1513504,0.0,0,8.1013775,0.0,0.079091452,80.495216,8.8923817,402.95016,-9.2602062
2140,2140,178.6894,6.8381381,1.1769925,0.0,0,8.0735455,0.0,0.08151301,80.128746,8.8637028,403.29932,-9.2603855
2141,2141,178.6896,6.9654756,1.2019167,0.0,0,8.0462685,0.0,0.08334779,81.14727,8.8332634,403.64847,-9.2608929
2142,2142,178.6898,7.1467876,1.2241659,0.0,0,8.0196619,0.0,0.084491663,83.131592,8.8058434,403.99762,-9.2609072
2143,2143,178.69,7.2580547,1.2573767,0.0,0,7.993176,0.0,0.087057568,84.525734,8.7782812,404.34677,-9.2606764
2144,2144,178.6902,7.2666163,1.3034346,0.0,0,7.9666953,0.0,0.090414345,84.572723,8.7468357,404.69592,-9.2606649
2145,2145,178.6904,7.2097411,1.3439994,0.0,0,7.9402156,0.0,0.093062364,83.741203,8.7141562,405.04507,-9.2604074
2146,2146,178.6906,7.1492672,1.3779052,0.0,0,7.9137359,0.0,0.095883384,82.776352,8.6783829,405.39426,-9.2603903
2147,2147,178.6908,7.1317639,1.4135528,0.0,0,7.8872557,0.0,0.0986664,82.224182,8.6420851,405.74341,-9.2606544
2148,2148,178.691,7.1621351,1.4513452,0.0,0,7.8607755,0.0,0.10096997,82.364891,8.6058683,406.09256,-9.2606735
2149,2149,178.6912,7.2165389,1.4876266,0.0,0,7.8342957,0.0,0.10381752,82.733154,8.5677013,406.44171,-9.2609453
2150,2150,178.6914,7.2656364,1.5183996,0.0,0,7.8078156,0.0,0.10657427,83.05838,8.5305586,406.79086,-9.2608404
2151,2151,178.6916,7.2918558,1.5441411,0.0,0,7.7813354,0.0,0.10813443,83.310829,8.4977074,407.14001,-9.2598667
2152,2152,178.6918,7.2966938,1.5664052,0.0,0,7.7548552,0.0,0.10974845,83.258301,8.4674339,407.48917,-9.2595844
2153,2153,178.692,7.2892823,1.5905287,0.0,0,7.7283754,0.0,0.11200278,83.015091,8.435544,407.83832,-9.2601023
2154,2154,178.6922,7.273468,1.6264941,0.0,0,7.7018952,0.0,0.11423685,82.73027,8.4036732,408.18747,-9.2611685
2155,2155,178.6924,7.2413192,1.6617632,0.0,0,7.675415,0.0,0.11670701,82.188675,8.3744698,408.53662,-9.2614374
2156,2156,178.6926,7.2485595,1.6843112,0.0,0,7.6489348,0.0,0.11905687,81.894951,8.3470144,408.88577,-9.2615995
2157,2157,178.6928,7.3456287,1.7089498,0.0,0,7.6224551,0.0,0.12061398,82.636108,8.3216553,409.23492,-9.2617626
2158,2158,178.693,7.4804397,1.7340956,0.0,0,7.5959754,0.0,0.12216278,84.021408,8.2938719,409.58408,-9.2614937
2159,2159,178.6932,7.5488939,1.7566347,0.0,0,7.5694952,0.0,0.12435581,84.757164,8.2627716,409.93326,-9.2613258
2160,2160,178.6934,7.5348339,1.794184,0.0,0,7.543015,0.0,0.12691154,84.517159,8.2326212,410.28241,-9.2609138
2161,2161,178.6936,7.517817,1.8347341,0.0,0,7.5165353,0.0,0.12954064,84.134827,8.2027245,410.63156,-9.2602797
2162,2162,178.6938,7.5307317,1.8606557,0.0,0,7.4900556,0.0,0.13208544,83.966858,8.1703644,410.98071,-9.2592573
2163,2163,178.694,7.5374742,1.8912312,0.0,0,7.4635754,0.0,0.13442054,83.831108,8.1395226,411.32986,-9.258462
2164,2164,178.6942,7.5025034,1.9257753,0.0,0,7.4370952,0.0,0.13652545,83.362411,8.1111841,411.67902,-9.2591209
2165,2165,178.6944,7.4704199,1.9500223,0.0,0,7.410615,0.0,0.13889182,82.789795,8.0808058,412.02817,-9.2604694
2166,2166,178.6946,7.5046659,1.9825279,0.0,0,7.3846664,0.0,0.14150268,82.835251,8.0483923,412.37732,-9.260457
2167,2167,178.6948,7.5850921,2.0158505,0.0,0,7.3593612,0.0,0.14350116,83.513435,8.0172491,412.72647,-9.2604513
2168,2168,178.695,7.6326723,2.0312295,0.0,0,7.3341722,0.0,0.14515659,83.98156,7.988605,413.07562,-9.2608004
2169,2169,178.6952,7.631197,2.0551918,0.0,0,7.3089881,0.0,0.14727488,83.819908,7.9607062,413.42477,-9.2609243
2170,2170,178.6954,7.6143084,2.0892589,0.0,0,7.2838039,0.0,0.14926799,83.471542,7.9317245,413.77393,-9.2605047
2171,2171,178.6956,7.6027689,2.1117301,0.0,0,7.2586198,0.0,0.15119083,83.235786,7.9020529,414.12311,-9.2603779
2172,2172,178.6958,7.6060176,2.1364932,0.0,0,7.2334356,0.0,0.15358743,83.059219,7.8771873,414.47226,-9.2605019
2173,2173,178.696,7.6240935,2.1637866,0.0,0,7.2082515,0.0,0.15529035,83.063591,7.851357,414.82141,-9.2598352
2174,2174,178.6962,7.6607428,2.1792421,0.0,0,7.1830673,0.0,0.15648191,83.317253,7.8228364,415.17056,-9.2592249
2175,2175,178.6964,7.7201128,2.2050588,0.0,0,7.1578832,0.0,0.15885589,83.691376,7.7948422,415.51971,-9.2592945
2176,2176,178.6966,7.7830267,2.2430565,0.0,0,7.1326995,0.0,0.16134152,84.182121,7.7685814,415.86887,-9.2605515
2177,2177,178.6968,7.8247123,2.2705197,0.0,0,7.1075153,0.0,0.16334593,84.521286,7.742167,416.21802,-9.2612228
2178,2178,178.697,7.8373508,2.2980902,0.0,0,7.0823312,0.0,0.16605344,84.50412,7.7154512,416.56717,-9.2607441
2179,2179,178.6972,7.8255849,2.3308868,0.0,0,7.0571475,0.0,0.16840966,84.237877,7.6873965,416.91632,-9.2607613
2180,2180,178.6974,7.8074546,2.3551471,0.0,0,7.0319633,0.0,0.17003542,83.873871,7.6603823,417.35919,-9.2607546
2181,2181,178.6976,7.8011293,2.3801451,0.0,0,7.0067792,0.0,0.17252244,83.538734,7.6331625,417.80206,-9.2604113
2182,2182,178.6978,7.8244214,2.4113843,0.0,0,6.981595,0.0,0.17497334,83.541634,7.6052871,418.24493,-9.2602911
2183,2183,178.698,7.8594937,2.4336472,0.0,0,6.9564114,0.0,0.17638251,83.792809,7.5768857,418.68781,-9.260005
2184,2184,178.6982,7.8787694,2.4536369,0.0,0,6.9312277,0.0,0.17839503,83.893005,7.5491085,419.13065,-9.2594585
2185,2185,178.6984,7.8827343,2.4815254,0.0,0,6.9060431,0.0,0.18068494,83.838921,7.5254011,419.57352,-9.2595024
2186,2186,178.6986,7.886764,2.5085177,0.0,0,6.8808594,0.0,0.18233572,83.741882,7.4989953,420.01639,-9.2594004
2187,2187,178.6988,7.9035282,2.5334406,0.0,0,6.8556757,0.0,0.18463315,83.646919,7.4715157,420.45926,-9.2592983
2188,2188,178.699,7.9246449,2.5572295,0.0,0,6.830492,0.0,0.18692262,83.600159,7.4468336,420.90213,-9.2596941
2189,2189,178.6992,7.9492197,2.579088,0.0,0,6.8053074,0.0,0.18820672,83.764244,7.4225569,421.345,-9.2602654
2190,2190,178.6994,7.9790702,2.6023569,0.0,0,6.7801232,0.0,0.19013298,83.969543,7.3963218,421.78784,-9.26021
2191,2191,178.6996,8.0098982,2.6287942,0.0,0,6.7554417,0.0,0.19261439,84.131294,7.3711271,422.23071,-9.2601519
2192,2192,178.6998,8.0293617,2.6586804,0.0,0,6.7313671,0.0,0.19444931,84.241875,7.3461356,422.67358,-9.2598858
2193,2193,178.7,8.0250025,2.6841128,0.0,0,6.7074022,0.0,0.1965504,84.012215,7.3202386,423.11646,-9.2594166
2194,2194,178.7002,8.0219021,2.7052481,0.0,0,6.6834416,0.0,0.19893606,83.705551,7.2922373,423.55933,-9.2597933
2195,2195,178.7004,8.0388155,2.7341194,0.0,0,6.6594815,0.0,0.20071241,83.710541,7.2659287,424.0022,-9.2600851
2196,2196,178.7006,8.0633039,2.7615519,0.0,0,6.6355219,0.0,0.20268361,83.789352,7.2413626,424.44504,-9.2599897
2197,2197,178.7008,8.083499,2.7820222,0.0,0,6.6115613,0.0,0.20505103,83.803505,7.2175593,424.88791,-9.2602358
2198,2198,178.701,8.0987329,2.8100195,0.0,0,6.5876017,0.0,0.20700015,83.82148,7.1924486,425.33078,-9.260458
2199,2199,178.7012,8.122839,2.8355196,0.0,0,6.5636415,0.0,0.20878327,83.900642,7.1655865,425.77365,-9.2604275
2200,2200,178.7014,8.1633692,2.8521771,0.0,0,6.5396819,0.0,0.21087305,84.146255,7.1404514,426.21652,-9.2606077
2201,2201,178.7016,8.1824007,2.8803797,0.0,0,6.5157218,0.0,0.21293184,84.14312,7.1164179,426.65939,-9.2605438
2202,2202,178.7018,8.1549969,2.9115155,0.0,0,6.4917622,0.0,0.214908,83.779556,7.0910959,427.10223,-9.2599955
2203,2203,178.702,8.1348324,2.9301999,0.0,0,6.467802,0.0,0.21709798,83.398079,7.067555,427.5451,-9.2594042
2204,2204,178.7022,8.1590719,2.9549444,0.0,0,6.4438419,0.0,0.21920009,83.311165,7.0446024,427.98798,-9.2598066
2205,2205,178.7024,8.19841,2.9821944,0.0,0,6.4198818,0.0,0.22089057,83.58609,7.0193968,428.43085,-9.2605152
2206,2206,178.7026,8.2293072,2.9973433,0.0,0,6.3959212,0.0,0.22266844,83.818481,6.9957891,428.87372,-9.2613935
2207,2207,178.7028,8.2520943,3.0233748,0.0,0,6.3719616,0.0,0.22497538,83.912079,6.9714489,429.31659,-9.262145
2208,2208,178.703,8.2744427,3.056632,0.0,0,6.3480015,0.0,0.22700386,84.004982,6.9438825,429.75946,-9.2609167
2209,2209,178.7032,8.2998877,3.0739515,0.0,0,6.3240418,0.0,0.22881535,84.123924,6.9184089,430.2023,-9.2599659
2210,2210,178.7034,8.3216877,3.0973973,0.0,0,6.3000817,0.0,0.23119147,84.099152,6.8955202,430.64517,-9.2597904
2211,2211,178.7036,8.3134699,3.1283078,0.0,0,6.2761221,0.0,0.23315838,83.831322,6.8697996,431.08804,-9.2592287
2212,2212,178.7038,8.2969875,3.1457272,0.0,0,6.252162,0.0,0.23482805,83.538773,6.8449512,431.53091,-9.2596655
2213,2213,178.704,8.3103371,3.1695516,0.0,0,6.2282019,0.0,0.23732984,83.361519,6.8234572,431.97379,-9.2596769
2214,2214,178.7042,8.3401995,3.2007942,0.0,0,6.2042422,0.0,0.23936416,83.455025,6.7977452,432.41666,-9.2597218
2215,2215,178.7044,8.3726778,3.2180531,0.0,0,6.1802821,0.0,0.24087331,83.696754,6.7707229,432.8595,-9.2604599
2216,2216,178.7046,8.3998604,3.2401195,0.0,0,6.1568027,0.0,0.24333239,83.857513,6.7462845,433.30237,-9.2611713
2217,2217,178.7048,8.4171762,3.2717645,0.0,0,6.1339049,0.0,0.24554175,83.830444,6.7197542,433.74524,-9.2608089
2218,2218,178.705,8.4226236,3.2916954,0.0,0,6.1111121,0.0,0.24708554,83.703102,6.6964664,434.18811,-9.2605762
2219,2219,178.7052,8.4328022,3.3126352,0.0,0,6.0883236,0.0,0.24949607,83.6334,6.6731148,434.63098,-9.260438
2220,2220,178.7054,8.4536657,3.3413219,0.0,0,6.065536,0.0,0.25167945,83.569611,6.649507,435.07385,-9.2606659
2221,2221,178.7056,8.4790449,3.3607554,0.0,0,6.042748,0.0,0.2529082,83.716072,6.6256175,435.51669,-9.2608576
2222,2222,178.7058,8.4937973,3.3807414,0.0,0,6.0199599,0.0,0.2551567,83.787056,6.6017051,435.95956,-9.2597513
2223,2223,178.706,8.5007515,3.4086101,0.0,0,5.9971719,0.0,0.25755823,83.648643,6.5782619,436.40244,-9.2593985
2224,2224,178.7062,8.5142374,3.4309583,0.0,0,5.9743834,0.0,0.25898924,83.634361,6.5525427,436.84531,-9.2592669
2225,2225,178.7064,8.5404921,3.4524355,0.0,0,5.9515953,0.0,0.26130143,83.669121,6.5275917,437.28818,-9.2592716
2226,2226,178.7066,8.5709162,3.4789357,0.0,0,5.9288077,0.0,0.26376206,83.742592,6.5049572,437.73105,-9.2595043
2227,2227,178.7068,8.5966263,3.5032856,0.0,0,5.9060202,0.0,0.26525101,83.898911,6.4831119,438.17389,-9.2600546
2228,2228,178.707,8.6165371,3.5255842,0.0,0,5.8832321,0.0,0.26753742,83.881462,6.4587646,438.61676,-9.2598467
2229,2229,178.7072,8.6274786,3.5504456,0.0,0,5.8604436,0.0,0.27011007,83.770241,6.432795,439.05963,-9.2592545
2230,2230,178.7074,8.6462984,3.5758641,0.0,0,5.8376555,0.0,0.2716645,83.861031,6.4080505,439.1076,-9.2599087
2231,2231,178.7076,8.6709099,3.5981765,0.0,0,5.8148675,0.0,0.27375576,83.943619,6.3842206,439.15561,-9.2606955
2232,2232,178.7078,8.6721516,3.6202376,0.0,0,5.792079,0.0,0.27623597,83.756294,6.3621025,439.20358,-9.2604513
2233,2233,178.708,8.6618605,3.6464875,0.0,0,5.7692914,0.0,0.27793774,83.513939,6.3395796,439.25156,-9.2604427
2234,2234,178.7082,8.6706448,3.66924,0.0,0,5.7465038,0.0,0.27990085,83.423347,6.3121462,439.29956,-9.2599325
2235,2235,178.7084,8.6875582,3.6878645,0.0,0,5.7237153,0.0,0.28224736,83.390465,6.2873373,439.34753,-9.2592802
2236,2236,178.7086,8.7131166,3.7135422,0.0,0,5.7009277,0.0,0.28396276,83.522919,6.2672739,439.39551,-9.2599354
2237,2237,178.7088,8.7519426,3.7374671,0.0,0,5.6781397,0.0,0.28578094,83.787117,6.2436652,439.44348,-9.2605
2238,2238,178.709,8.7864656,3.755563,0.0,0,5.6553516,0.0,0.28812441,83.894592,6.2182121,439.49149,-9.2605553
2239,2239,178.7092,8.8126144,3.7836523,0.0,0,5.6325636,0.0,0.29018486,83.902336,6.1948342,439.53946,-9.2598448
2240,2240,178.7094,8.8263388,3.8103366,0.0,0,5.6097755,0.0,0.29217798,83.873856,6.1723232,439.58743,-9.2589321
2241,2241,178.7096,8.8254948,3.8262386,0.0,0,5.5874419,0.0,0.2944226,83.664848,6.1498723,439.63544,-9.2588959
2242,2242,178.7098,8.8243799,3.8517373,0.0,0,5.5656581,0.0,0.29647186,83.420738,6.1269398,439.68341,-9.2593899
2243,2243,178.71,8.8320446,3.8797035,0.0,0,5.5439739,0.0,0.2983273,83.352592,6.1055169,439.73138,-9.2600794
2244,2244,178.7102,8.8451338,3.8951912,0.0,0,5.5222936,0.0,0.30045313,83.313583,6.0844865,439.77939,-9.2599697
2245,2245,178.7104,8.8694534,3.9196458,0.0,0,5.5006137,0.0,0.30264488,83.351402,6.0615311,439.82736,-9.2598324
2246,2246,178.7106,8.9043865,3.9482467,0.0,0,5.4789333,0.0,0.30444953,83.611816,6.0356255,439.87534,-9.2602606
2247,2247,178.7108,8.9396114,3.96226,0.0,0,5.4572535,0.0,0.30638576,83.797119,6.0120554,439.92331,-9.2603998
2248,2248,178.711,8.9624796,3.9865093,0.0,0,5.4355736,0.0,0.30886534,83.755516,5.9922404,439.97131,-9.2598429
2249,2249,178.7112,8.9709921,4.0182352,0.0,0,5.4138937,0.0,0.31090409,83.711533,5.9694862,440.01929,-9.2589073
2250,2250,178.7114,8.969368,4.0348482,0.0,0,5.3922133,0.0,0.31282777,83.587227,5.9427762,440.06726,-9.259017
2251,2251,178.7116,8.9706907,4.0578222,0.0,0,5.3705335,0.0,0.31546423,83.421501,5.9191861,440.11526,-9.2596445
2252,2252,178.7118,8.988059,4.0885477,0.0,0,5.3488536,0.0,0.31747839,83.357185,5.8976035,440.16324,-9.2599878
2253,2253,178.712,9.0007191,4.1046472,0.0,0,5.3271737,0.0,0.31911701,83.273422,5.8742895,440.21121,-9.260047
2254,2254,178.7122,9.0183926,4.1260581,0.0,0,5.3054934,0.0,0.32168302,83.215477,5.8524356,440.25922,-9.2603025
2255,2255,178.7124,9.0515518,4.1552877,0.0,0,5.2838135,0.0,0.32371631,83.315613,5.8295684,440.30719,-9.2605782
2256,2256,178.7126,9.0913343,4.1704512,0.0,0,5.2621331,0.0,0.32513696,83.536369,5.8054433,440.35516,-9.2605991
2257,2257,178.7128,9.1248217,4.1895499,0.0,0,5.2404532,0.0,0.32758886,83.616486,5.7835088,440.40314,-9.2600365
2258,2258,178.713,9.1455717,4.2190762,0.0,0,5.2187734,0.0,0.32978857,83.697029,5.7608109,440.45114,-9.2592945
2259,2259,178.7132,9.1580114,4.2376661,0.0,0,5.1970935,0.0,0.33119482,83.734283,5.7372165,440.49911,-9.2590418
2260,2260,178.7134,9.1582737,4.2573233,0.0,0,5.1754136,0.0,0.33374542,83.536423,5.7150073,440.54709,-9.2590199
2261,2261,178.7136,9.1568632,4.2865968,0.0,0,5.1537337,0.0,0.33621812,83.378098,5.6908154,440.59509,-9.2593784
2262,2262,178.7138,9.1706514,4.3070946,0.0,0,5.1320534,0.0,0.33764511,83.356178,5.6667619,440.64307,-9.2602959
2263,2263,178.714,9.1933908,4.3270655,0.0,0,5.1103735,0.0,0.34019724,83.246895,5.6447444,440.69104,-9.2602043
2264,2264,178.7142,9.2149868,4.3550096,0.0,0,5.0886931,0.0,0.34283206,83.169327,5.6229038,440.73904,-9.2600279
2265,2265,178.7144,9.2382402,4.377418,0.0,0,5.0670133,0.0,0.34431058,83.296722,5.6012807,440.78702,-9.2611074
2266,2266,178.7146,9.2668734,4.3976612,0.0,0,5.0457683,0.0,0.34667295,83.371582,5.575973,440.83499,-9.2611618
2267,2267,178.7148,9.2998857,4.4225039,0.0,0,5.0250487,0.0,0.34928524,83.468384,5.5509534,440.88297,-9.2605944
2268,2268,178.715,9.324439,4.4453368,0.0,0,5.0044241,0.0,0.35080251,83.564125,5.5294485,440.93097,-9.2603703
2269,2269,178.7152,9.3328686,4.4650078,0.0,0,4.9838042,0.0,0.35298231,83.514824,5.5071435,440.97894,-9.2596302
2270,2270,178.7154,9.3372908,4.4862204,0.0,0,4.9631839,0.0,0.3554849,83.371239,5.4855151,441.02692,-9.2595177
2271,2271,178.7156,9.3469963,4.5103817,0.0,0,4.942564,0.0,0.35702711,83.232811,5.4610214,441.07492,-9.259573
2272,2272,178.7158,9.3637056,4.5325418,0.0,0,4.9219441,0.0,0.35917509,83.121208,5.4349222,441.12289,-9.2591457
2273,2273,178.716,9.3808165,4.5533371,0.0,0,4.9013243,0.0,0.36179388,83.053925,5.4140906,441.17087,-9.2592297
2274,2274,178.7162,9.3975763,4.5788836,0.0,0,4.8807039,0.0,0.36357719,83.118263,5.3947988,441.21887,-9.2599392
2275,2275,178.7164,9.42764,4.6019344,0.0,0,4.8600841,0.0,0.36568719,83.237419,5.3725562,441.26685,-9.2605581
2276,2276,178.7166,9.4667711,4.6206985,0.0,0,4.8394642,0.0,0.36829972,83.380142,5.3486109,441.31482,-9.2600756
2277,2277,178.7168,9.5014467,4.6469822,0.0,0,4.8188443,0.0,0.37026012,83.470314,5.326283,441.36279,-9.2596502
2278,2278,178.717,9.51126,4.6703916,0.0,0,4.798224,0.0,0.37225655,83.443802,5.3055115,441.4108,-9.2595377
2279,2279,178.7172,9.5149574,4.6864557,0.0,0,4.7776041,0.0,0.37473428,83.347176,5.2814112,441.45877,-9.2585869
2280,2280,178.7174,9.5263567,4.7127981,0.0,0,4.7569842,0.0,0.3767949,83.230186,5.2584677,441.44437,-9.2584267
2281,2281,178.7176,9.5391817,4.7388082,0.0,0,4.7363639,0.0,0.37870404,83.152382,5.2366824,441.42999,-9.259016
2282,2282,178.7178,9.5503683,4.7536821,0.0,0,4.715744,0.0,0.38103557,83.061432,5.2126489,441.41559,-9.2590227
2283,2283,178.718,9.5580788,4.77882,0.0,0,4.6951241,0.0,0.38337085,82.95858,5.1897149,441.40118,-9.2591352
2284,2284,178.7182,9.5812111,4.8064713,0.0,0,4.6745043,0.0,0.38529339,82.983917,5.1693063,441.38678,-9.2597351
2285,2285,178.7184,9.6229992,4.820611,0.0,0,4.6538844,0.0,0.38739163,83.10498,5.1475339,441.37241,-9.2601633
2286,2286,178.7186,9.6543493,4.8448133,0.0,0,4.6332641,0.0,0.3898952,83.159691,5.1233096,441.358,-9.2601442
2287,2287,178.7188,9.6735735,4.8741336,0.0,0,4.6126437,0.0,0.3919225,83.182312,5.1024084,441.3436,-9.260397
2288,2288,178.719,9.6910324,4.8881269,0.0,0,4.5920238,0.0,0.3939319,83.1744,5.0836763,441.32922,-9.2595901
2289,2289,178.7192,9.699379,4.910253,0.0,0,4.571404,0.0,0.39650053,83.077629,5.0612106,441.31482,-9.2588606
2290,2290,178.7194,9.7048912,4.9398465,0.0,0,4.5507841,0.0,0.39848521,82.986992,5.0382318,441.30042,-9.2590961
2291,2291,178.7196,9.7106752,4.9543591,0.0,0,4.5305758,0.0,0.40035003,82.84787,5.0159922,441.28604,-9.2589588
2292,2292,178.7198,9.7277164,4.9755459,0.0,0,4.5108657,0.0,0.4030945,82.694016,4.9939651,441.27164,-9.2589321
2293,2293,178.72,9.7549419,5.0052242,0.0,0,4.4912457,0.0,0.40521261,82.731697,4.973856,441.25723,-9.2587996
2294,2294,178.7202,9.7804203,5.0195956,0.0,0,4.4716296,0.0,0.40681478,82.845901,4.9531274,441.24283,-9.2588167
2295,2295,178.7204,9.8118153,5.0385084,0.0,0,4.4520135,0.0,0.40937588,82.849327,4.9302621,441.22845,-9.2585659
2296,2296,178.7206,9.8381271,5.0678039,0.0,0,4.4323978,0.0,0.41152063,82.925354,4.9056597,441.21405,-9.2583141
2297,2297,178.7208,9.8523865,5.0839305,0.0,0,4.4127817,0.0,0.41305223,82.985405,4.8851252,441.19965,-9.2588396
2298,2298,178.721,9.8715315,5.1023712,0.0,0,4.3931656,0.0,0.41577229,82.903519,4.8646646,441.18527,-9.2592535
2299,2299,178.7212,9.8832045,5.1304231,0.0,0,4.3735499,0.0,0.41815484,82.831825,4.8422623,441.17087,-9.2590008
2300,2300,178.7214,9.8862944,5.1480389,0.0,0,4.3539338,0.0,0.41957572,82.727646,4.820889,441.15646,-9.2588568
2301,2301,178.7216,9.8945293,5.1670156,0.0,0,4.3343177,0.0,0.42224768,82.51947,4.7965741,441.14209,-9.2592974
2302,2302,178.7218,9.9142103,5.1950827,0.0,0,4.314702,0.0,0.42487916,82.508369,4.7732658,441.12769,-9.2593451
2303,2303,178.722,9.9456072,5.2152486,0.0,0,4.2950859,0.0,0.42630929,82.66777,4.754499,441.11328,-9.2589731
2304,2304,178.7222,9.9754715,5.2330351,0.0,0,4.2754698,0.0,0.42882776,82.617523,4.735013,441.09888,-9.2589111
2305,2305,178.7224,9.9989653,5.2579622,0.0,0,4.2558532,0.0,0.4315187,82.6259,4.713975,441.0845,-9.2588377
2306,2306,178.7226,10.01632,5.2792578,0.0,0,4.2362375,0.0,0.43295512,82.717255,4.6915107,441.0701,-9.2590885
2307,2307,178.7228,10.033617,5.2970338,0.0,0,4.2166214,0.0,0.43534622,82.661674,4.6712852,441.05569,-9.259366
2308,2308,178.723,10.056789,5.3200998,0.0,0,4.1970053,0.0,0.43808198,82.621323,4.6488757,441.04132,-9.2591248
2309,2309,178.7232,10.073318,5.3430891,0.0,0,4.1773896,0.0,0.43960714,82.62027,4.6265225,441.02692,-9.259203
2310,2310,178.7234,10.091088,5.3613224,0.0,0,4.1577735,0.0,0.44182184,82.559517,4.6065993,441.01251,-9.2594767
2311,2311,178.7236,10.105028,5.3810196,0.0,0,4.1381574,0.0,0.44452778,82.458008,4.5859427,440.99814,-9.2596703
2312,2312,178.7238,10.115281,5.4048982,0.0,0,4.1185417,0.0,0.44606665,82.440788,4.5663781,440.98373,-9.2597284
2313,2313,178.724,10.130714,5.4242468,0.0,0,4.0989256,0.0,0.44809383,82.367393,4.5470157,440.96933,-9.2594395
2314,2314,178.7242,10.151472,5.4416833,0.0,0,4.0793095,0.0,0.45084137,82.306915,4.5256448,440.95493,-9.2591105
2315,2315,178.7244,10.178036,5.4659719,0.0,0,4.0596938,0.0,0.45257178,82.41787,4.5027804,440.94055,-9.2590971
2316,2316,178.7246,10.206124,5.4865837,0.0,0,4.0404716,0.0,0.45456386,82.479568,4.4799666,440.92615,-9.2590923
2317,2317,178.7248,10.233639,5.5032492,0.0,0,4.0217257,0.0,0.45732665,82.434029,4.4582577,440.91174,-9.2591343
2318,2318,178.725,10.255711,5.5294228,0.0,0,4.0030656,0.0,0.45937496,82.452614,4.4385004,440.89737,-9.2593994
2319,2319,178.7252,10.275216,5.5516987,0.0,0,3.9844093,0.0,0.4612577,82.469429,4.4207788,440.88297,-9.2597609
2320,2320,178.7254,10.288729,5.5650225,0.0,0,3.9657533,0.0,0.46372542,82.364891,4.4010081,440.86856,-9.2602673
2321,2321,178.7256,10.300941,5.5898099,0.0,0,3.9470973,0.0,0.465922,82.29847,4.378974,440.85419,-9.2605858
2322,2322,178.7258,10.311364,5.6143317,0.0,0,3.9284413,0.0,0.46778905,82.237015,4.3579698,440.83978,-9.2601442
2323,2323,178.726,10.329804,5.6268048,0.0,0,3.9097853,0.0,0.47006437,82.16729,4.33602,440.82538,-9.2597351
2324,2324,178.7262,10.359963,5.6496263,0.0,0,3.8911293,0.0,0.47240409,82.191216,4.3166652,440.81097,-9.2595711
2325,2325,178.7264,10.394419,5.6755013,0.0,0,3.8724735,0.0,0.47426656,82.310852,4.2949023,440.7966,-9.2589741
2326,2326,178.7266,10.426994,5.6872125,0.0,0,3.8538175,0.0,0.47638834,82.425797,4.2722969,440.7822,-9.2587891
2327,2327,178.7268,10.459211,5.7093196,0.0,0,3.8351612,0.0,0.47895575,82.470314,4.2553806,440.76779,-9.2585497
2328,2328,178.727,10.485929,5.7376823,0.0,0,3.8165054,0.0,0.48090947,82.510979,4.2358356,440.75342,-9.2585468
2329,2329,178.7272,10.494215,5.7502909,0.0,0,3.7978494,0.0,0.48303068,82.430725,4.2125487,440.73901,-9.2590895
2330,2330,178.7274,10.497332,5.7712779,0.0,0,3.7791932,0.0,0.48584157,82.203514,4.1914558,440.68085,-9.2591162
2331,2331,178.7276,10.503823,5.799952,0.0,0,3.7605371,0.0,0.48778448,82.095955,4.1720529,440.62265,-9.2591629
2332,2332,178.7278,10.515772,5.8126793,0.0,0,3.7418811,0.0,0.48959699,82.057014,4.1537585,440.56448,-9.2592735
2333,2333,178.728,10.541368,5.8316135,0.0,0,3.7232254,0.0,0.49247667,81.973511,4.1337509,440.50629,-9.2599211
2334,2334,178.7282,10.579748,5.8587799,0.0,0,3.7045693,0.0,0.49443501,82.059196,4.1124663,440.44812,-9.2599401
2335,2335,178.7284,10.624058,5.8709126,0.0,0,3.6859133,0.0,0.49586526,82.280014,4.0912042,440.38995,-9.2587175
2336,2336,178.7286,10.657422,5.8883405,0.0,0,3.6672573,0.0,0.49864566,82.33429,4.0718145,440.33176,-9.2582712
2337,2337,178.7288,10.676311,5.916501,0.0,0,3.6486013,0.0,0.5008601,82.325569,4.0510187,440.27359,-9.2581749
2338,2338,178.729,10.689383,5.931715,0.0,0,3.6299453,0.0,0.50228602,82.32177,4.0298505,440.21539,-9.2582664
2339,2339,178.7292,10.697125,5.9492707,0.0,0,3.6112893,0.0,0.50514853,82.149803,4.010776,440.15723,-9.2583084
2340,2340,178.7294,10.706233,5.9776115,0.0,0,3.5926332,0.0,0.50785106,81.956245,3.991292,440.09906,-9.2580328
2341,2341,178.7296,10.717706,5.9943771,0.0,0,3.5743496,0.0,0.50928444,81.934425,3.972749,440.04086,-9.2584352
2342,2342,178.7298,10.744188,6.0096769,0.0,0,3.5565166,0.0,0.51195061,81.901505,3.9531605,439.9827,-9.2589264
2343,2343,178.73,10.773821,6.0351691,0.0,0,3.538765,0.0,0.51460803,81.894394,3.9324689,439.9245,-9.2591019
2344,2344,178.7302,10.80061,6.0538764,0.0,0,3.5210168,0.0,0.5158568,82.035782,3.9128923,439.86633,-9.2587385
2345,2345,178.7304,10.835206,6.069427,0.0,0,3.5032687,0.0,0.51836312,82.085609,3.8904674,439.80817,-9.258461
2346,2346,178.7306,10.870676,6.0915351,0.0,0,3.4855206,0.0,0.52109629,82.141754,3.8701735,439.74997,-9.258441
2347,2347,178.7308,10.903747,6.1108718,0.0,0,3.4677727,0.0,0.52238625,82.338272,3.8530278,439.6918,-9.2580643
2348,2348,178.731,10.917257,6.1275177,0.0,0,3.4500248,0.0,0.5247587,82.295921,3.8347476,439.63361,-9.257679
2349,2349,178.7312,10.920274,6.1486931,0.0,0,3.432277,0.0,0.52761239,82.068001,3.8158116,439.57544,-9.2580919
2350,2350,178.7314,10.932528,6.1700487,0.0,0,3.4145288,0.0,0.52909827,81.99987,3.7936883,439.51727,-9.2587776
2351,2351,178.7316,10.952704,6.1871929,0.0,0,3.3967807,0.0,0.53135419,81.966461,3.7722199,439.45908,-9.2583942
2352,2352,178.7318,10.981902,6.2059097,0.0,0,3.3790326,0.0,0.53423333,81.928581,3.7532148,439.40091,-9.2579241
2353,2353,178.732,11.014703,6.2283692,0.0,0,3.3612847,0.0,0.53579074,81.986595,3.7351379,439.34271,-9.2587938
2354,2354,178.7322,11.044785,6.246779,0.0,0,3.3435369,0.0,0.53786176,82.08593,3.716099,439.28455,-9.2589846
2355,2355,178.7324,11.080753,6.263103,0.0,0,3.3257887,0.0,0.54071993,82.15892,3.6970186,439.22638,-9.2586794
2356,2356,178.7326,11.119761,6.2871866,0.0,0,3.3080409,0.0,0.5425514,82.229286,3.6769972,439.16818,-9.2590771
2357,2357,178.7328,11.140954,6.3070092,0.0,0,3.2902927,0.0,0.54457355,82.209473,3.6572638,439.11002,-9.259037
2358,2358,178.733,11.142928,6.3197165,0.0,0,3.2725446,0.0,0.54724902,82.055534,3.6384935,439.05182,-9.2581825
2359,2359,178.7332,11.148748,6.3430214,0.0,0,3.2547965,0.0,0.54922712,81.920593,3.620702,438.99365,-9.2576771
2360,2360,178.7334,11.162499,6.364634,0.0,0,3.2370486,0.0,0.55113262,81.842461,3.6030145,438.93549,-9.2580547
2361,2361,178.7336,11.181267,6.3761225,0.0,0,3.2193007,0.0,0.55368203,81.790192,3.5844939,438.87729,-9.2584429
2362,2362,178.7338,11.209096,6.3987889,0.0,0,3.2015526,0.0,0.55591053,81.84005,3.5650361,438.81912,-9.25842
2363,2363,178.734,11.235086,6.4223099,0.0,0,3.1838048,0.0,0.55776459,81.895821,3.5463881,438.76093,-9.2579269
2364,2364,178.7342,11.268736,6.4321661,0.0,0,3.1660566,0.0,0.55998862,81.933357,3.5281579,438.70276,-9.2582636
2365,2365,178.7344,11.311919,6.4517069,0.0,0,3.1483088,0.0,0.56222898,82.035057,3.509582,438.64459,-9.2589417
2366,2366,178.7346,11.344435,6.4767632,0.0,0,3.1309152,0.0,0.5640763,82.143517,3.4924052,438.5864,-9.2595682
2367,2367,178.7348,11.360329,6.4869561,0.0,0,3.11395,0.0,0.56624365,82.117668,3.473943,438.52823,-9.2596626
2368,2368,178.735,11.37359,6.5073099,0.0,0,3.0970623,0.0,0.56894493,81.974571,3.4543002,438.47003,-9.2591667
2369,2369,178.7352,11.386494,6.534493,0.0,0,3.0801783,0.0,0.57091987,81.894699,3.4359112,438.41187,-9.2584858
2370,2370,178.7354,11.399698,6.5441031,0.0,0,3.0632944,0.0,0.57272524,81.835648,3.4183462,438.3537,-9.2577429
2371,2371,178.7356,11.413853,6.5629797,0.0,0,3.0464106,0.0,0.575504,81.721146,3.399652,438.2955,-9.2577791
2372,2372,178.7358,11.438903,6.5897679,0.0,0,3.0295265,0.0,0.57755876,81.687149,3.3814008,438.23734,-9.258215
2373,2373,178.736,11.478765,6.5993276,0.0,0,3.0126424,0.0,0.57915437,81.789589,3.3627927,438.17914,-9.2587261
2374,2374,178.7362,11.515816,6.6161289,0.0,0,2.9957583,0.0,0.58197987,81.859253,3.3441792,438.12097,-9.2584743
2375,2375,178.7364,11.555914,6.6428585,0.0,0,2.9788744,0.0,0.5840885,81.949188,3.3262084,438.06281,-9.2585373
2376,2376,178.7366,11.585752,6.6541538,0.0,0,2.9619906,0.0,0.58546454,82.070007,3.308079,438.00461,-9.2589817
2377,2377,178.7368,11.601564,6.6697669,0.0,0,2.9451065,0.0,0.58833623,81.989151,3.2892368,437.94644,-9.2589598
2378,2378,178.737,11.617894,6.6967502,0.0,0,2.9282222,0.0,0.59074479,81.905525,3.2723632,437.88824,-9.2590303
2379,2379,178.7372,11.633623,6.7102757,0.0,0,2.9113381,0.0,0.59208429,81.921211,3.2542894,437.83008,-9.2583275
2380,2380,178.7374,11.653495,6.7245784,0.0,0,2.8944542,0.0,0.5949074,81.819023,3.2368157,437.87564,-9.257679
2381,2381,178.7376,11.681762,6.7492166,0.0,0,2.8775704,0.0,0.59747869,81.764069,3.2202666,437.9212,-9.2580013
2382,2382,178.7378,11.712668,6.7641015,0.0,0,2.8606863,0.0,0.59861887,81.860397,3.1991255,437.96677,-9.2582378
2383,2383,178.738,11.749046,6.778513,0.0,0,2.8438022,0.0,0.6012612,81.924049,3.1807027,438.01233,-9.2584324
2384,2384,178.7382,11.788057,6.8021226,0.0,0,2.8269184,0.0,0.6040442,81.992546,3.1627929,438.05786,-9.2588816
2385,2385,178.7384,11.826106,6.8184319,0.0,0,2.810034,0.0,0.60525352,82.1604,3.1426284,438.10342,-9.2592497
2386,2386,178.7386,11.855187,6.8316288,0.0,0,2.7931502,0.0,0.60771751,82.17379,3.1255553,438.14899,-9.2592697
2387,2387,178.7388,11.87668,6.8532414,0.0,0,2.7762663,0.0,0.61047029,82.114609,3.109292,438.19455,-9.2591066
2388,2388,178.739,11.892459,6.8719597,0.0,0,2.7593822,0.0,0.61169231,82.096977,3.0930264,438.24011,-9.2585154
2389,2389,178.7392,11.904126,6.8868337,0.0,0,2.7424984,0.0,0.6141125,81.993561,3.0732331,438.28568,-9.2577648
2390,2390,178.7394,11.924688,6.906199,0.0,0,2.7256143,0.0,0.61711264,81.898857,3.0544574,438.33124,-9.2576828
2391,2391,178.7396,11.957731,6.9264293,0.0,0,2.7090683,0.0,0.61853284,81.968315,3.0386789,438.3768,-9.2576704
2392,2392,178.7398,11.996044,6.9421706,0.0,0,2.6929309,0.0,0.62072426,82.053383,3.0213192,438.42233,-9.2572937
2393,2393,178.74,12.033595,6.9581418,0.0,0,2.6768677,0.0,0.62364,82.065536,3.0040019,438.4679,-9.2577353
2394,2394,178.7402,12.0661,6.9786172,0.0,0,2.6608074,0.0,0.62511891,82.181564,2.9871695,438.51346,-9.2587786
2395,2395,178.7404,12.095191,6.9953518,0.0,0,2.6447473,0.0,0.62712562,82.243248,2.9680574,438.55902,-9.2590666
2396,2396,178.7406,12.13103,7.0087609,0.0,0,2.6286874,0.0,0.63010502,82.252968,2.9505217,438.60458,-9.258913
2397,2397,178.7408,12.159857,7.0302529,0.0,0,2.6126273,0.0,0.63193989,82.290123,2.9336669,438.65015,-9.2588415
2398,2398,178.741,12.17777,7.0491958,0.0,0,2.5965672,0.0,0.63383353,82.206757,2.9152982,438.69571,-9.258234
2399,2399,178.7412,12.195535,7.0612788,0.0,0,2.5805073,0.0,0.63663656,82.072327,2.8985016,438.74127,-9.2575722
2400,2400,178.7414,12.221902,7.0832782,0.0,0,2.5644474,0.0,0.63874018,82.066597,2.8818104,438.7868,-9.2573977
2401,2401,178.7416,12.249293,7.1028261,0.0,0,2.5483873,0.0,0.64050889,82.16124,2.8635929,438.83237,-9.2574081
2402,2402,178.7418,12.275097,7.1121154,0.0,0,2.5323272,0.0,0.64293522,82.141151,2.8439133,438.87793,-9.2571039
2403,2403,178.742,12.306904,7.1330705,0.0,0,2.5162673,0.0,0.64511698,82.125122,2.825397,438.92349,-9.2571163
2404,2404,178.7422,12.343164,7.1548395,0.0,0,2.5002072,0.0,0.64687997,82.259575,2.8100975,438.96906,-9.257575
2405,2405,178.7424,12.382855,7.1630268,0.0,0,2.4841473,0.0,0.64921772,82.360565,2.7933979,439.01462,-9.2581139
2406,2406,178.7426,12.412829,7.1823339,0.0,0,2.4680872,0.0,0.65165657,82.393158,2.7774847,439.06018,-9.2586164
2407,2407,178.7428,12.431291,7.206532,0.0,0,2.4520273,0.0,0.65335959,82.385712,2.7651553,439.10574,-9.2588005
2408,2408,178.743,12.450452,7.215332,0.0,0,2.4359674,0.0,0.65551561,82.320625,2.7470036,439.15131,-9.2584076
2409,2409,178.7432,12.473049,7.2332187,0.0,0,2.4199073,0.0,0.65834916,82.202087,2.7288985,439.19684,-9.2578211
2410,2410,178.7434,12.495696,7.2584023,0.0,0,2.4038472,0.0,0.6602335,82.220818,2.7109938,439.2424,-9.2577381
2411,2411,178.7436,12.527651,7.2677426,0.0,0,2.3877873,0.0,0.6620841,82.250923,2.6931365,439.28796,-9.2575808
2412,2412,178.7438,12.561994,7.2844987,0.0,0,2.3717272,0.0,0.66506875,82.153511,2.6791599,439.33353,-9.2577524
2413,2413,178.744,12.592031,7.3092656,0.0,0,2.3556671,0.0,0.66697198,82.208435,2.6640773,439.37909,-9.2577
2414,2414,178.7442,12.631716,7.3171735,0.0,0,2.3396072,0.0,0.66835219,82.327148,2.6464703,439.42465,-9.2574854
2415,2415,178.7444,12.674083,7.331768,0.0,0,2.3235474,0.0,0.67135549,82.371178,2.6274061,439.47021,-9.257514
2416,2416,178.7446,12.705414,7.3568764,0.0,0,2.3078089,0.0,0.6734187,82.457558,2.6106157,439.51578,-9.2575274
2417,2417,178.7448,12.724002,7.3664818,0.0,0,2.2924595,0.0,0.67463136,82.488831,2.5949378,439.56131,-9.2580853
2418,2418,178.745,12.745094,7.3799372,0.0,0,2.2771804,0.0,0.67757493,82.402351,2.5780139,439.60687,-9.2584209
2419,2419,178.7452,12.766264,7.4043231,0.0,0,2.2619042,0.0,0.67991018,82.373039,2.5620568,439.65244,-9.2579775
2420,2420,178.7454,12.786589,7.4163694,0.0,0,2.246628,0.0,0.68106425,82.386093,2.5467434,439.698,-9.2579308
2421,2421,178.7456,12.811036,7.4295096,0.0,0,2.2313523,0.0,0.68400192,82.286354,2.5296955,439.74356,-9.2578516
2422,2422,178.7458,12.841891,7.4526873,0.0,0,2.2160764,0.0,0.6866501,82.266342,2.5125511,439.78912,-9.2575636
2423,2423,178.746,12.88539,7.4663057,0.0,0,2.2008004,0.0,0.68755448,82.45578,2.4969931,439.83469,-9.2575665
2424,2424,178.7462,12.929848,7.4783177,0.0,0,2.1855242,0.0,0.69019884,82.516022,2.480154,439.88025,-9.2579861
2425,2425,178.7464,12.974119,7.4994245,0.0,0,2.1702483,0.0,0.69300765,82.5504,2.4662702,439.92578,-9.2577229
2426,2426,178.7466,13.012485,7.5146523,0.0,0,2.1549723,0.0,0.69400382,82.71225,2.450125,439.97134,-9.2571411
2427,2427,178.7468,13.033004,7.5265799,0.0,0,2.1396964,0.0,0.69649559,82.685661,2.4312863,440.01691,-9.2573338
2428,2428,178.747,13.052836,7.5454478,0.0,0,2.1244202,0.0,0.6993801,82.560379,2.4159493,440.06247,-9.2573948
2429,2429,178.7472,13.075346,7.5623832,0.0,0,2.1091442,0.0,0.70045072,82.572861,2.3993754,440.10803,-9.2573948
2430,2430,178.7474,13.093796,7.5748181,0.0,0,2.0938683,0.0,0.70274377,82.513763,2.3819761,440.04446,-9.2577667
2431,2431,178.7476,13.120905,7.5913,0.0,0,2.0785923,0.0,0.70582587,82.426498,2.3667908,439.98087,-9.2581491
2432,2432,178.7478,13.155158,7.6103768,0.0,0,2.0633163,0.0,0.70713693,82.516541,2.3526142,439.9173,-9.2579098
2433,2433,178.748,13.202424,7.6237154,0.0,0,2.0480404,0.0,0.70915633,82.637924,2.337909,439.85373,-9.2576189
2434,2434,178.7482,13.251293,7.6371565,0.0,0,2.0327644,0.0,0.71203339,82.715454,2.3222706,439.79016,-9.2575245
2435,2435,178.7484,13.287651,7.6573591,0.0,0,2.0174885,0.0,0.7135554,82.831322,2.3041492,439.72656,-9.2575083
2436,2436,178.7486,13.327586,7.6724935,0.0,0,2.0022123,0.0,0.71556002,82.903336,2.2862391,439.66299,-9.2575703
2437,2437,178.7488,13.356536,7.6840081,0.0,0,1.9869361,0.0,0.71846855,82.870232,2.2703068,439.59943,-9.2575941
2438,2438,178.749,13.371783,7.7045231,0.0,0,1.9716601,0.0,0.72028148,82.81739,2.2581656,439.53583,-9.2575941
2439,2439,178.7492,13.387679,7.7208018,0.0,0,1.9563841,0.0,0.72198755,82.747894,2.2434208,439.47226,-9.2570019
2440,2440,178.7494,13.40742,7.7293177,0.0,0,1.9411081,0.0,0.72463411,82.678673,2.2272005,439.40869,-9.2565022
2441,2441,178.7496,13.442663,7.74927,0.0,0,1.9261373,0.0,0.72663909,82.747459,2.2114265,439.34512,-9.256876
2442,2442,178.7498,13.487058,7.7676439,0.0,0,1.9115355,0.0,0.72815657,82.845039,2.1948199,439.28152,-9.2569256
2443,2443,178.75,13.534193,7.7741504,0.0,0,1.8970004,0.0,0.73050463,82.904716,2.180656,439.21796,-9.257081
2444,2444,178.7502,13.58398,7.7938786,0.0,0,1.8824685,0.0,0.73283637,83.033501,2.1645124,439.15439,-9.2575302
2445,2445,178.7504,13.631142,7.8158665,0.0,0,1.8679364,0.0,0.73462451,83.148453,2.1465731,439.09079,-9.2576218
2446,2446,178.7506,13.661448,7.8219533,0.0,0,1.8534043,0.0,0.73693091,83.173576,2.1319468,439.02722,-9.2576675
2447,2447,178.7508,13.676405,7.839015,0.0,0,1.8388724,0.0,0.73944795,83.132507,2.1182396,438.96365,-9.2581348
2448,2448,178.751,13.695201,7.8616266,0.0,0,1.8243403,0.0,0.74112815,83.129875,2.1042402,438.90009,-9.258111
2449,2449,178.7512,13.724344,7.867723,0.0,0,1.8098084,0.0,0.74315715,83.111046,2.090513,438.83649,-9.2575874
2450,2450,178.7514,13.757849,7.8841748,0.0,0,1.7952764,0.0,0.74610078,83.053734,2.0749965,438.77292,-9.2575645
2451,2451,178.7516,13.798613,7.9091849,0.0,0,1.7807443,0.0,0.74793202,83.130119,2.057956,438.70935,-9.2569704
2452,2452,178.7518,13.846128,7.9158111,0.0,0,1.7662123,0.0,0.74954021,83.26622,2.0425041,438.64578,-9.2561436
2453,2453,178.752,13.89548,7.929738,0.0,0,1.7516804,0.0,0.75259006,83.328865,2.0288503,438.58218,-9.2559423
2454,2454,178.7522,13.95306,7.9537764,0.0,0,1.7371484,0.0,0.75450617,83.49575,2.0110762,438.51862,-9.2560482
2455,2455,178.7524,14.001384,7.9612169,0.0,0,1.7226164,0.0,0.75582236,83.658302,1.9953485,438.45505,-9.2560425
2456,2456,178.7526,14.026998,7.9741073,0.0,0,1.7080843,0.0,0.75889319,83.569328,1.9814378,438.39145,-9.2558336
2457,2457,178.7528,14.04248,7.9977322,0.0,0,1.6935524,0.0,0.76095265,83.503395,1.967556,438.32788,-9.2561789
2458,2458,178.753,14.063938,8.0056677,0.0,0,1.6790204,0.0,0.76201445,83.55191,1.9532087,438.26431,-9.2569313
2459,2459,178.7532,14.093127,8.0170183,0.0,0,1.6644883,0.0,0.76501495,83.459442,1.936329,438.20074,-9.2579002
2460,2460,178.7534,14.133161,8.0408096,0.0,0,1.6499563,0.0,0.76743066,83.480766,1.9190373,438.13715,-9.2580404
2461,2461,178.7536,14.174986,8.0513058,0.0,0,1.6354244,0.0,0.76832932,83.645348,1.9036071,438.07358,-9.2574902
2462,2462,178.7538,14.21928,8.062151,0.0,0,1.6208923,0.0,0.77124047,83.641617,1.8899373,438.01001,-9.2574787
2463,2463,178.754,14.270747,8.0848036,0.0,0,1.6063604,0.0,0.77416438,83.700264,1.8755778,437.94641,-9.2570009
2464,2464,178.7542,14.319514,8.0983486,0.0,0,1.5918283,0.0,0.77512211,83.906181,1.8603666,437.88284,-9.2561512
2465,2465,178.7544,14.362771,8.1092587,0.0,0,1.5772964,0.0,0.77789032,83.944672,1.8459446,437.81927,-9.2554111
2466,2466,178.7546,14.39633,8.1298618,0.0,0,1.5630548,0.0,0.78083462,83.922745,1.8319674,437.75571,-9.255455
2467,2467,178.7548,14.41802,8.1445684,0.0,0,1.5491644,0.0,0.78177613,83.980751,1.8167988,437.69211,-9.2556305
2468,2468,178.755,14.444876,8.1544418,0.0,0,1.5353373,0.0,0.7842778,83.917458,1.8018608,437.62854,-9.2556868
2469,2469,178.7552,14.481334,8.1718941,0.0,0,1.5215132,0.0,0.78729224,83.858185,1.7860575,437.56497,-9.2559633
2470,2470,178.7554,14.523017,8.1882915,0.0,0,1.5076892,0.0,0.7883845,84.014107,1.7725372,437.5014,-9.2572594
2471,2471,178.7556,14.573926,8.1992083,0.0,0,1.4938653,0.0,0.79056829,84.099129,1.7589999,437.43781,-9.2581453
2472,2472,178.7558,14.626499,8.2137098,0.0,0,1.4800413,0.0,0.7936185,84.160515,1.7431535,437.37424,-9.2577343
2473,2473,178.756,14.673323,8.2316418,0.0,0,1.4662173,0.0,0.79483825,84.339317,1.7286153,437.31067,-9.2576399
2474,2474,178.7562,14.720982,8.2442789,0.0,0,1.4523933,0.0,0.79688281,84.418724,1.7127944,437.24707,-9.2573977
2475,2475,178.7564,14.766043,8.2562056,0.0,0,1.4385693,0.0,0.80000907,84.429527,1.6956007,437.1835,-9.256031
2476,2476,178.7566,14.794055,8.275404,0.0,0,1.4247453,0.0,0.801503,84.459122,1.6809624,437.11993,-9.2548456
2477,2477,178.7568,14.815656,8.2901516,0.0,0,1.4109213,0.0,0.80342877,84.416962,1.6692017,437.05637,-9.2551374
2478,2478,178.757,14.852096,8.300602,0.0,0,1.3970973,0.0,0.80664146,84.334755,1.6552951,436.99277,-9.2557344
2479,2479,178.7572,14.895342,8.3212681,0.0,0,1.3832734,0.0,0.80860698,84.408821,1.6396078,436.9292,-9.2565813
2480,2480,178.7574,14.939189,8.3371067,0.0,0,1.3694494,0.0,0.81022018,84.549187,1.6265179,436.75888,-9.2571621
2481,2481,178.7576,14.993294,8.3435545,0.0,0,1.3556253,0.0,0.81293011,84.603111,1.6092557,436.58856,-9.2573671
2482,2482,178.7578,15.04786,8.3621721,0.0,0,1.3418013,0.0,0.81503946,84.723228,1.5916795,436.41824,-9.257534
2483,2483,178.758,15.102658,8.3801308,0.0,0,1.3279774,0.0,0.81659687,84.930099,1.5791007,436.24792,-9.2570066
2484,2484,178.7582,15.155424,8.3861351,0.0,0,1.3141534,0.0,0.81907654,84.979546,1.5650878,436.07764,-9.2569809
2485,2485,178.7584,15.192796,8.4040651,0.0,0,1.3003293,0.0,0.82154763,85.004189,1.5527959,435.90732,-9.2569704
2486,2486,178.7586,15.221422,8.4247427,0.0,0,1.2865053,0.0,0.82322097,85.074005,1.5419557,435.737,-9.2566462
2487,2487,178.7588,15.253221,8.4304953,0.0,0,1.2726814,0.0,0.82544214,85.034714,1.5262595,435.56668,-9.2563629
2488,2488,178.759,15.287526,8.4472532,0.0,0,1.2588574,0.0,0.82823688,84.988579,1.5087035,435.39636,-9.2558689
2489,2489,178.7592,15.328424,8.4694672,0.0,0,1.2450334,0.0,0.83002579,85.047859,1.4945937,435.22604,-9.2556543
2490,2490,178.7594,15.375663,8.47474,0.0,0,1.2312094,0.0,0.83191985,85.127365,1.4821433,435.05573,-9.2557077
2491,2491,178.7596,15.430314,8.4893932,0.0,0,1.2176627,0.0,0.83487552,85.16449,1.4661142,434.88541,-9.2565041
2492,2492,178.7598,15.48715,8.5121737,0.0,0,1.2044513,0.0,0.83668375,85.292839,1.451108,434.71509,-9.2570744
2493,2493,178.76,15.537236,8.5178938,0.0,0,1.1913006,0.0,0.83832484,85.444717,1.4377372,434.5448,-9.2567043
2494,2494,178.7602,15.585333,8.5314693,0.0,0,1.1781524,0.0,0.84166998,85.448151,1.4228029,434.37448,-9.2564659
2495,2495,178.7604,15.634812,8.555439,0.0,0,1.1650045,0.0,0.84368205,85.564499,1.4095641,434.20416,-9.2568731
2496,2496,178.7606,15.681799,8.562109,0.0,0,1.1518564,0.0,0.84484214,85.716568,1.3959302,434.03384,-9.2562351
2497,2497,178.7608,15.72016,8.573699,0.0,0,1.1387084,0.0,0.84810382,85.639793,1.3801606,433.86353,-9.2556391
2498,2498,178.761,15.754222,8.5974731,0.0,0,1.1255604,0.0,0.85046029,85.658669,1.3666437,433.69321,-9.255414
2499,2499,178.7612,15.797089,8.605896,0.0,0,1.1124125,0.0,0.85147464,85.785187,1.3542863,433.52289,-9.2554998
2500,2500,178.7614,15.845969,8.6160336,0.0,0,1.0992644,0.0,0.85467482,85.759392,1.3402729,433.35257,-9.2558842
2501,2501,178.7616,15.903721,8.6385679,0.0,0,1.0861164,0.0,0.85735625,85.83783,1.325529,433.18228,-9.2561388
2502,2502,178.7618,15.956879,8.6491146,0.0,0,1.0729684,0.0,0.85829031,86.083511,1.3107426,433.01196,-9.25634
2503,2503,178.762,16.008087,8.658658,0.0,0,1.0598203,0.0,0.86134607,86.118439,1.2928413,432.84164,-9.2560892
2504,2504,178.7622,16.064728,8.6792278,0.0,0,1.0466723,0.0,0.86420077,86.120132,1.2778567,432.67133,-9.2561426
2505,2505,178.7624,16.110817,8.6918545,0.0,0,1.0335244,0.0,0.86494452,86.308617,1.2654617,432.50101,-9.2562351
2506,2506,178.7626,16.149231,8.7007113,0.0,0,1.0203763,0.0,0.86761737,86.294777,1.249256,432.33069,-9.2561398
2507,2507,178.7628,16.184694,8.7194138,0.0,0,1.0072284,0.0,0.8707037,86.232849,1.2337837,432.16037,-9.2552834
2508,2508,178.763,16.226112,8.734539,0.0,0,0.99408036,0.0,0.87173659,86.370071,1.2202445,431.99005,-9.25455
2509,2509,178.7632,16.277071,8.7448711,0.0,0,0.98093235,0.0,0.87442255,86.395004,1.2061347,431.81976,-9.25455
2510,2510,178.7634,16.335075,8.7615213,0.0,0,0.96778435,0.0,0.8777191,86.41571,1.1903238,431.64944,-9.2551413
2511,2511,178.7636,16.389717,8.7773857,0.0,0,0.95463634,0.0,0.87875956,86.612701,1.1754628,431.47913,-9.2554245
2512,2512,178.7638,16.446871,8.7878428,0.0,0,0.94148839,0.0,0.8809706,86.721642,1.1623678,431.30881,-9.2555351
2513,2513,178.764,16.507412,8.8007574,0.0,0,0.92834044,0.0,0.88416338,86.772728,1.1509693,431.13849,-9.256196
2514,2514,178.7642,16.569386,8.8186283,0.0,0,0.91519243,0.0,0.88544011,86.957947,1.1369491,430.96817,-9.2562399
2515,2515,178.7644,16.62303,8.8312893,0.0,0,0.90204442,0.0,0.88752776,87.033073,1.1209551,430.79785,-9.2559376
2516,2516,178.7646,16.665375,8.8417645,0.0,0,0.88916051,0.0,0.89082235,87.003418,1.1074837,430.62753,-9.2559204
2517,2517,178.7648,16.711853,8.8608131,0.0,0,0.87659609,0.0,0.89247912,87.088379,1.0961026,430.45721,-9.2552452
2518,2518,178.765,16.758015,8.8748512,0.0,0,0.86408949,0.0,0.89437866,87.179939,1.0822786,430.28693,-9.2549992
2519,2519,178.7652,16.803593,8.8826408,0.0,0,0.85158539,0.0,0.89755434,87.170921,1.0660119,430.11661,-9.2549038
2520,2520,178.7654,16.857073,8.9013968,0.0,0,0.83908135,0.0,0.8995778,87.247154,1.0530576,429.94629,-9.2545099
2521,2521,178.7656,16.91193,8.9178009,0.0,0,0.82657731,0.0,0.90125972,87.373962,1.0416344,429.77597,-9.2545795
2522,2522,178.7658,16.967337,8.9240665,0.0,0,0.81407332,0.0,0.90408313,87.418297,1.025519,429.60565,-9.2544394
2523,2523,178.766,17.028502,8.9413748,0.0,0,0.8015694,0.0,0.90645903,87.513939,1.0111802,429.43533,-9.2545128
2524,2524,178.7662,17.087498,8.9590693,0.0,0,0.78906536,0.0,0.90807933,87.670532,0.9980073,429.26501,-9.2548265
2525,2525,178.7664,17.13978,8.9634409,0.0,0,0.77656138,0.0,0.91044515,87.741272,0.98468775,429.0947,-9.2549191
2526,2526,178.7666,17.180523,8.9798555,0.0,0,0.7640574,0.0,0.91291434,87.762474,0.97124016,428.92441,-9.2551785
2527,2527,178.7668,17.22035,9.0000286,0.0,0,0.75155336,0.0,0.91451406,87.848022,0.95781064,428.75409,-9.2557859
2528,2528,178.767,17.266188,9.0033827,0.0,0,0.73904938,0.0,0.91671312,87.841301,0.94473302,428.58377,-9.2558813
2529,2529,178.7672,17.310009,9.0179892,0.0,0,0.72654539,0.0,0.91960359,87.77169,0.93013382,428.41345,-9.2550564
2530,2530,178.7674,17.36331,9.0401087,0.0,0,0.71404135,0.0,0.92132264,87.91983,0.91538489,428.55319,-9.2544289
2531,2531,178.7676,17.429714,9.0440083,0.0,0,0.70153737,0.0,0.92321599,88.104912,0.90123242,428.69296,-9.2541294
2532,2532,178.7678,17.496441,9.0576372,0.0,0,0.68903339,0.0,0.92654622,88.123901,0.88713926,428.8327,-9.2540588
2533,2533,178.768,17.565647,9.0808849,0.0,0,0.67652941,0.0,0.92838687,88.300217,0.87308687,428.97244,-9.2539339
2534,2534,178.7682,17.632484,9.0862274,0.0,0,0.66402543,0.0,0.92992538,88.500946,0.86138445,429.11218,-9.2537851
2535,2535,178.7684,17.683615,9.0988674,0.0,0,0.65152138,0.0,0.93345296,88.484192,0.84926707,429.25195,-9.2542248
2536,2536,178.7686,17.724344,9.1214085,0.0,0,0.63901734,0.0,0.93550652,88.536018,0.83425069,429.39169,-9.2545977
2537,2537,178.7688,17.769739,9.1264849,0.0,0,0.62651336,0.0,0.93656999,88.636711,0.8182466,429.53143,-9.2548447
2538,2538,178.769,17.816372,9.1362362,0.0,0,0.61400938,0.0,0.9398337,88.55941,0.80264276,429.6712,-9.2552443
2539,2539,178.7692,17.86202,9.1578827,0.0,0,0.6015054,0.0,0.94210923,88.583969,0.7899316,429.81094,-9.2554684
2540,2540,178.7694,17.913977,9.1640844,0.0,0,0.58900136,0.0,0.94273829,88.785225,0.77939403,429.95068,-9.2549725
2541,2541,178.7696,17.966537,9.1718349,0.0,0,0.57674509,0.0,0.94586331,88.810188,0.76743668,430.09042,-9.255065
2542,2542,178.7698,18.035566,9.1941509,0.0,0,0.56478846,0.0,0.94871062,88.905426,0.75531298,430.23019,-9.2549677
2543,2543,178.77,18.113968,9.2045851,0.0,0,0.55288601,0.0,0.94943404,89.207184,0.74132675,430.36993,-9.2544241
2544,2544,178.7702,18.174654,9.2121496,0.0,0,0.54098594,0.0,0.95255476,89.236443,0.72563839,430.50967,-9.2543316
2545,2545,178.7704,18.222475,9.2318172,0.0,0,0.52908593,0.0,0.95578384,89.175583,0.71356457,430.64944,-9.2546377
2546,2546,178.7706,18.262281,9.2437077,0.0,0,0.51718587,0.0,0.95636111,89.329109,0.70310086,430.78918,-9.2547445
2547,2547,178.7708,18.303732,9.2517891,0.0,0,0.50528592,0.0,0.95910251,89.292534,0.68812817,430.92892,-9.2541771
2548,2548,178.771,18.357187,9.2692165,0.0,0,0.49338591,0.0,0.96253288,89.22879,0.67470694,431.06866,-9.2541533
2549,2549,178.7712,18.416447,9.2835913,0.0,0,0.4814859,0.0,0.96334833,89.434326,0.66113377,431.20844,-9.2545834
2550,2550,178.7714,18.481264,9.2925253,0.0,0,0.4695859,0.0,0.96592027,89.492546,0.64724129,431.34818,-9.2546062
2551,2551,178.7716,18.557636,9.3062716,0.0,0,0.45768592,0.0,0.96930867,89.53215,0.63635474,431.48792,-9.2544441
2552,2552,178.7718,18.637823,9.3207731,0.0,0,0.44578591,0.0,0.97018403,89.849037,0.62430942,431.62766,-9.2546301
2553,2553,178.772,18.71192,9.3298092,0.0,0,0.4338859,0.0,0.97228241,90.038673,0.61135811,431.76743,-9.2546291
2554,2554,178.7722,18.767139,9.3406439,0.0,0,0.42198589,0.0,0.97555757,90.045433,0.59639317,431.90717,-9.2542315
2555,2555,178.7724,18.819572,9.3569384,0.0,0,0.41008592,0.0,0.97663307,90.205269,0.58213705,432.04691,-9.2536831
2556,2556,178.7726,18.87042,9.3670902,0.0,0,0.39818591,0.0,0.9783619,90.283112,0.57103658,432.18668,-9.253293