File: clean data/testID_0201.csv
level_0,index,Time(sec),Force(kN),Jaw(mm),PowAngle(deg),Power(W),Pram,PTemp,Strain,Stress(MPa),Stroke(mm),TC1(C),wedge(mm)
1873,1873,155.3485,0.4504846,0.037800841,0.0,0,9.0337067,0.0,0.0022790064,4.6078897,10.072439,341.64557,-9.3062315
1875,1875,155.3489,3.5068355,0.084958225,0.0,0,8.9751787,0.0,0.0051705572,39.623093,10.00783,341.75253,-9.3067665
1877,1877,155.3493,5.491715,0.12311125,0.0,0,8.9166508,0.0,0.0082249744,68.236649,9.9494028,341.8595,-9.3054647
1879,1879,155.3497,6.2140441,0.20413327,0.0,0,8.8581219,0.0,0.012702462,76.757835,9.8715811,342.1571,-9.3036232
1881,1881,155.3501,6.8640771,0.33860567,0.0,0,8.7995939,0.0,0.022126049,85.258949,9.7818241,342.45471,-9.3022022
1883,1883,155.3505,7.3129191,0.43453133,0.0,0,8.7416534,0.0,0.028778918,89.340393,9.6763144,342.75232,-9.3008137
1885,1885,155.3509,7.8199048,0.54675311,0.0,0,8.6858492,0.0,0.036191836,95.610519,9.5675039,343.04993,-9.3013906
1887,1887,155.3513,8.2799597,0.6082409,0.0,0,8.6301851,0.0,0.041333325,100.77047,9.4730806,343.34753,-9.3000669
1889,1889,155.3517,8.0785103,0.65837699,0.0,0,8.574522,0.0,0.044429798,98.68985,9.3945303,343.64514,-9.2999163
1891,1891,155.3521,8.3505716,0.729936,0.0,0,8.518857,0.0,0.049209323,100.65448,9.3206921,343.94275,-9.3010454
1893,1893,155.3525,8.6425095,0.78236306,0.0,0,8.4631929,0.0,0.053447381,103.98528,9.2516031,344.24036,-9.2999992
1895,1895,155.3529,8.968276,0.87191099,0.0,0,8.4075298,0.0,0.058910627,107.50198,9.1748428,344.53796,-9.2989988
1897,1897,155.3533,8.6140823,0.97810566,0.0,0,8.3518648,0.0,0.066691674,103.149,9.0920458,344.83557,-9.2989407
1899,1899,155.3537,8.8133516,1.0604309,0.0,0,8.2962017,0.0,0.073026352,103.74637,9.0020914,345.13315,-9.3000555
1901,1901,155.3541,8.9000883,1.1449699,0.0,0,8.2405376,0.0,0.078551725,104.83933,8.9197397,345.43076,-9.3006353
1903,1903,155.3545,9.1600409,1.1873049,0.0,0,8.1848736,0.0,0.082298607,106.98129,8.8454494,345.72836,-9.2999058
1905,1905,155.3549,9.0755415,1.2379665,0.0,0,8.1292095,0.0,0.085838392,106.48215,8.7825251,346.02597,-9.2992592
1907,1907,155.3553,9.086298,1.3043749,0.0,0,8.0735455,0.0,0.090166993,105.36023,8.7251472,346.32358,-9.2996101
1909,1909,155.3557,9.3701019,1.3527589,0.0,0,8.0196619,0.0,0.094255678,108.51334,8.664669,346.62119,-9.2991152
1911,1911,155.3561,9.4407272,1.4295908,0.0,0,7.9666953,0.0,0.099528275,108.62749,8.5994129,346.91879,-9.2989683
1913,1913,155.3565,9.3954964,1.5177044,0.0,0,7.9137359,0.0,0.10583724,107.87376,8.5287886,347.2164,-9.2983894
1915,1915,155.3569,9.2767925,1.581854,0.0,0,7.8607755,0.0,0.11122178,105.67107,8.4593306,347.51401,-9.3002005
1917,1917,155.3573,9.4195442,1.6358616,0.0,0,7.8078156,0.0,0.11494995,106.73818,8.3944769,347.81161,-9.2998686
1919,1919,155.3577,9.5408087,1.6783789,0.0,0,7.7548552,0.0,0.11827559,107.76054,8.3379192,348.10922,-9.2990303
1921,1921,155.3581,9.5616522,1.719159,0.0,0,7.7018952,0.0,0.12163906,107.84518,8.2837448,348.40683,-9.2993307
1923,1923,155.3585,9.5460033,1.7679092,0.0,0,7.6489348,0.0,0.12481368,107.13313,8.237525,348.70444,-9.29914
1925,1925,155.3589,9.748745,1.818234,0.0,0,7.5959754,0.0,0.12900177,109.00294,8.1874552,349.00201,-9.2989979
1927,1927,155.3593,9.7365961,1.8744364,0.0,0,7.543015,0.0,0.13317767,108.56023,8.1353254,349.29962,-9.298914
1929,1929,155.3597,9.7731695,1.9376346,0.0,0,7.4900556,0.0,0.1376548,108.44965,8.0787382,349.51208,-9.2996197
1931,1931,155.3601,9.7413559,1.9946425,0.0,0,7.4370952,0.0,0.14258313,107.53329,8.0163565,349.72455,-9.2990303
1933,1933,155.3605,9.8301392,2.0388539,0.0,0,7.3846664,0.0,0.1457646,107.94764,7.9651031,349.93704,-9.2995539
1935,1935,155.3609,9.887763,2.0790489,0.0,0,7.3341722,0.0,0.14871459,108.5136,7.9165282,350.14951,-9.2998114
1937,1937,155.3613,9.8872013,2.1255205,0.0,0,7.2838039,0.0,0.15277821,108.05583,7.8685846,350.36197,-9.2986403
1939,1939,155.3617,9.9235859,2.1711931,0.0,0,7.2334356,0.0,0.15579934,108.11169,7.824748,350.57443,-9.298521
1941,1941,155.3621,10.024427,2.2157834,0.0,0,7.1830673,0.0,0.15942815,108.70743,7.7788329,350.7869,-9.2989159
1943,1943,155.3625,10.136528,2.2645168,0.0,0,7.1326995,0.0,0.16356429,109.56601,7.7307668,350.99936,-9.2987432
1945,1945,155.3629,10.06844,2.323652,0.0,0,7.0823312,0.0,0.16752677,108.51669,7.6818376,351.21182,-9.2996817
1947,1947,155.3633,10.056952,2.3697569,0.0,0,7.0319633,0.0,0.17170773,107.85206,7.6308141,351.42429,-9.2996712
1949,1949,155.3637,10.149575,2.4087355,0.0,0,6.981595,0.0,0.17490946,108.46214,7.5837102,351.63675,-9.3003855
1951,1951,155.3641,10.253498,2.4587204,0.0,0,6.9312277,0.0,0.17826122,109.20506,7.5355463,351.84921,-9.2992239
1953,1953,155.3645,10.235817,2.4984908,0.0,0,6.8808594,0.0,0.18203339,108.68347,7.4942179,352.06168,-9.2988167
1955,1955,155.3649,10.244934,2.5413849,0.0,0,6.830492,0.0,0.18521956,108.4013,7.4459081,352.27414,-9.2999897
1957,1957,155.3653,10.321644,2.5962527,0.0,0,6.7801232,0.0,0.18936767,108.71771,7.4010797,352.4866,-9.3001547
1959,1959,155.3657,10.395333,2.6347132,0.0,0,6.7313671,0.0,0.19317465,109.08979,7.3578458,352.6991,-9.2998266
1961,1961,155.3661,10.410932,2.6815841,0.0,0,6.6834416,0.0,0.19633149,109.02009,7.3092556,352.91156,-9.2991772
1963,1963,155.3665,10.423572,2.7295599,0.0,0,6.6355219,0.0,0.20048963,108.55676,7.263999,353.12402,-9.2991381
1965,1965,155.3669,10.485374,2.7637913,0.0,0,6.5876017,0.0,0.20362367,108.84372,7.2169943,353.33649,-9.2997618
1967,1967,155.3673,10.563121,2.8137274,0.0,0,6.5396819,0.0,0.20698428,109.23384,7.1688704,353.54895,-9.2992201
1969,1969,155.3677,10.607566,2.8616877,0.0,0,6.4917622,0.0,0.21149728,109.25821,7.1270924,353.76141,-9.2996168
1971,1971,155.3681,10.630486,2.9028859,0.0,0,6.4438419,0.0,0.21486686,109.15648,7.0830922,353.97388,-9.3003216
1973,1973,155.3685,10.709028,2.9526722,0.0,0,6.3959212,0.0,0.21853165,109.47858,7.0366516,354.18634,-9.2999296
1975,1975,155.3689,10.756438,2.9983699,0.0,0,6.3480015,0.0,0.22295842,109.51339,6.9888473,354.3988,-9.3004856
1977,1977,155.3693,10.76654,3.0461533,0.0,0,6.3000817,0.0,0.22652131,109.33511,6.9421763,354.61127,-9.3000402
1979,1979,155.3697,10.794821,3.0955915,0.0,0,6.252162,0.0,0.23057979,109.09702,6.8899875,354.67917,-9.2998123
1981,1981,155.3701,10.892676,3.1372869,0.0,0,6.2042422,0.0,0.234745,109.54707,6.8463707,354.74704,-9.2998972
1983,1983,155.3705,10.948796,3.1900253,0.0,0,6.1568027,0.0,0.23837961,109.82581,6.7992783,354.81491,-9.2997599
1985,1985,155.3709,10.974713,3.2345235,0.0,0,6.1111121,0.0,0.242503,109.57049,6.750701,354.88281,-9.2999802
1987,1987,155.3713,10.999533,3.2766914,0.0,0,6.065536,0.0,0.24644883,109.40827,6.7025661,354.95068,-9.299984
1989,1989,155.3717,11.081416,3.3323557,0.0,0,6.0199599,0.0,0.25031257,109.75233,6.6529818,355.01859,-9.2999201
1991,1991,155.3721,11.159906,3.3763716,0.0,0,5.9743834,0.0,0.25471121,110.0925,6.6052566,355.08646,-9.2997065
1993,1993,155.3725,11.194191,3.427314,0.0,0,5.9288077,0.0,0.25903958,109.94313,6.5555115,355.15436,-9.299159
1995,1995,155.3729,11.207433,3.4858727,0.0,0,5.8832321,0.0,0.26352835,109.64693,6.5075874,355.22223,-9.300271
1997,1997,155.3733,11.268035,3.5273221,0.0,0,5.8376555,0.0,0.26796436,109.7007,6.4586382,355.2901,-9.3001356
1999,1999,155.3737,11.35306,3.576474,0.0,0,5.792079,0.0,0.27179593,110.05939,6.4092722,355.358,-9.2997189
2001,2001,155.3741,11.418921,3.6305702,0.0,0,5.7465038,0.0,0.27637982,110.30438,6.3606529,355.42587,-9.2998466
2003,2003,155.3745,11.42968,3.6706266,0.0,0,5.7009277,0.0,0.2806327,109.90606,6.3109202,355.49377,-9.3001404
2005,2005,155.3749,11.474885,3.7217579,0.0,0,5.6553516,0.0,0.28438681,109.85798,6.2594042,355.56165,-9.2997484
2007,2007,155.3753,11.537348,3.7753534,0.0,0,5.6097755,0.0,0.28943765,109.88953,6.2102661,355.62955,-9.2999954
2009,2009,155.3757,11.597645,3.8192186,0.0,0,5.5656581,0.0,0.29377401,110.04939,6.1595364,355.69742,-9.2993803
2011,2011,155.3761,11.662643,3.8740215,0.0,0,5.5222936,0.0,0.29791909,110.10741,6.1121602,355.76532,-9.2997122
2013,2013,155.3765,11.709612,3.9238374,0.0,0,5.4789333,0.0,0.3030667,110.06367,6.0648623,355.83319,-9.2997227
2015,2015,155.3769,11.736906,3.9680324,0.0,0,5.4355736,0.0,0.30701223,109.89643,6.0137773,355.90106,-9.2999277
2017,2017,155.3773,11.785705,4.0185375,0.0,0,5.3922133,0.0,0.31107885,109.92362,5.9616356,355.96896,-9.299695
2019,2019,155.3777,11.864629,4.0667186,0.0,0,5.3488536,0.0,0.31618577,110.0612,5.9111524,356.03683,-9.299552
2021,2021,155.3781,11.928223,4.1171975,0.0,0,5.3054934,0.0,0.32029104,110.23776,5.8636308,356.10474,-9.2988358
2023,2023,155.3785,11.953613,4.1686606,0.0,0,5.2621331,0.0,0.32490766,109.98129,5.8140502,356.17261,-9.2992945
2025,2025,155.3789,11.98575,4.213305,0.0,0,5.2187734,0.0,0.32986477,109.66292,5.7650833,356.24051,-9.3003416
2027,2027,155.3793,12.053958,4.266891,0.0,0,5.1754136,0.0,0.33387423,109.82987,5.7178793,356.30838,-9.300066
2029,2029,155.3797,12.14467,4.3133397,0.0,0,5.1320534,0.0,0.33860478,110.14074,5.6668415,356.33505,-9.3010807
2031,2031,155.3801,12.193187,4.3558216,0.0,0,5.0886931,0.0,0.3430602,110.15175,5.622169,356.36172,-9.3002825
2033,2033,155.3805,12.215622,4.4143658,0.0,0,5.0457683,0.0,0.34750441,109.82096,5.5710816,356.3884,-9.2987537
2035,2035,155.3809,12.249725,4.4566426,0.0,0,5.0044241,0.0,0.35230467,109.60394,5.5265179,356.41507,-9.2998199
2037,2037,155.3813,12.323983,4.49898,0.0,0,4.9631839,0.0,0.35628924,109.84335,5.4785094,356.44171,-9.3004522
2039,2039,155.3817,12.392337,4.5529451,0.0,0,4.9219441,0.0,0.36074141,109.97243,5.4272571,356.46838,-9.2997942
2041,2041,155.3821,12.428548,4.5915513,0.0,0,4.8807039,0.0,0.36544004,109.77918,5.3816605,356.49506,-9.2997742
2043,2043,155.3825,12.465638,4.6383982,0.0,0,4.8394642,0.0,0.36937234,109.68007,5.3354468,356.52173,-9.2994461
2045,2045,155.3829,12.505958,4.6918602,0.0,0,4.798224,0.0,0.37430972,109.43607,5.2904968,356.5484,-9.3001633
2047,2047,155.3833,12.573995,4.7291341,0.0,0,4.7569842,0.0,0.37881309,109.58856,5.2429175,356.57507,-9.3003311
2049,2049,155.3837,12.6406,4.7805414,0.0,0,4.715744,0.0,0.38290182,109.65232,5.1967669,356.60175,-9.2992229
2051,2051,155.3841,12.678227,4.8295093,0.0,0,4.6745043,0.0,0.38808748,109.46875,5.1538138,356.62842,-9.298604
2053,2053,155.3845,12.717734,4.8661761,0.0,0,4.6332641,0.0,0.39214095,109.42055,5.1069632,356.65506,-9.3000078
2055,2055,155.3849,12.772758,4.9129047,0.0,0,4.5920238,0.0,0.39589852,109.38007,5.0622292,356.68173,-9.2996302
2057,2057,155.3853,12.825057,4.9564528,0.0,0,4.5507841,0.0,0.40093043,109.29443,5.0212569,356.7084,-9.2999544
2059,2059,155.3857,12.874577,4.9967537,0.0,0,4.5108657,0.0,0.40480348,109.35353,4.9782572,356.73508,-9.2991409
2061,2061,155.3861,12.928579,5.0437837,0.0,0,4.4716296,0.0,0.4090564,109.34097,4.9334226,356.76175,-9.3000231
2063,2063,155.3865,12.959077,5.0838056,0.0,0,4.4323978,0.0,0.41399914,109.01979,4.8888259,356.78842,-9.2989435
2065,2065,155.3869,13.009633,5.1268559,0.0,0,4.3931656,0.0,0.41765484,109.02751,4.8490481,356.81509,-9.2989864
2067,2067,155.3873,13.075767,5.1705933,0.0,0,4.3539338,0.0,0.42202172,109.04012,4.8069377,356.84177,-9.2990541
2069,2069,155.3877,13.132821,5.2080245,0.0,0,4.314702,0.0,0.42665213,109.12144,4.7636657,356.86844,-9.3004351
2071,2071,155.3881,13.191457,5.2538762,0.0,0,4.2754698,0.0,0.43028033,109.18922,4.723917,356.89508,-9.2999668
2073,2073,155.3885,13.211593,5.2931728,0.0,0,4.2362375,0.0,0.43484971,108.90816,4.6832709,356.92175,-9.2985859
2075,2075,155.3889,13.274102,5.3311181,0.0,0,4.1970053,0.0,0.43912405,108.90479,4.6405678,356.94843,-9.2990828
2077,2077,155.3893,13.331504,5.3808184,0.0,0,4.1577735,0.0,0.44312748,108.96046,4.6003256,356.9751,-9.2986155
2079,2079,155.3897,13.396709,5.4135208,0.0,0,4.1185417,0.0,0.44757557,108.94368,4.5613594,356.85388,-9.3002758
2081,2081,155.3901,13.447175,5.4505839,0.0,0,4.0793095,0.0,0.4513025,108.97655,4.5202951,356.73267,-9.3003588
2083,2083,155.3905,13.494182,5.500885,0.0,0,4.0404716,0.0,0.45575255,108.89405,4.4793,356.61142,-9.299799
2085,2085,155.3909,13.539182,5.5322704,0.0,0,4.0030656,0.0,0.46035352,108.77272,4.4397368,356.4902,-9.2985954
2087,2087,155.3913,13.604024,5.574254,0.0,0,3.9657533,0.0,0.46402636,108.88301,4.3986368,356.36899,-9.2983294
2089,2089,155.3917,13.675541,5.621706,0.0,0,3.9284413,0.0,0.46890455,108.93655,4.3573585,356.24777,-9.2990284
2091,2091,155.3921,13.731338,5.6519198,0.0,0,3.8911293,0.0,0.47308692,108.9391,4.3201399,356.12656,-9.2992907
2093,2093,155.3925,13.773692,5.6947179,0.0,0,3.8538175,0.0,0.47652921,108.88423,4.2776036,356.00534,-9.3003492
2095,2095,155.3929,13.818873,5.736392,0.0,0,3.8165054,0.0,0.4816024,108.7165,4.239819,355.88409,-9.2995625
2097,2097,155.3933,13.89243,5.7682424,0.0,0,3.7791932,0.0,0.48544484,108.72099,4.2019377,355.76288,-9.298543
2099,2099,155.3937,13.977305,5.8115602,0.0,0,3.7418811,0.0,0.48918894,109.02871,4.1596737,355.64166,-9.2988386
2101,2101,155.3941,14.039765,5.8503461,0.0,0,3.7045693,0.0,0.4943029,109.01049,4.1236992,355.52045,-9.2989244
2103,2103,155.3945,14.066163,5.8871326,0.0,0,3.6672573,0.0,0.49805728,108.7822,4.0830388,355.39923,-9.3004627
2105,2105,155.3949,14.128767,5.9305072,0.0,0,3.6299453,0.0,0.50230336,108.75469,4.0440197,355.27802,-9.300478
2107,2107,155.3953,14.20658,5.9653034,0.0,0,3.5926332,0.0,0.50722206,108.84059,4.0075765,355.15677,-9.2990389
2109,2109,155.3957,14.285165,6.0039673,0.0,0,3.5565166,0.0,0.51052469,109.15729,3.9658382,355.03555,-9.2989016
2111,2111,155.3961,14.330775,6.0430007,0.0,0,3.5210168,0.0,0.51491255,109.02402,3.9300716,354.91434,-9.3000097
2113,2113,155.3965,14.362547,6.075397,0.0,0,3.4855206,0.0,0.51950264,108.76932,3.8921018,354.79312,-9.2993488
2115,2115,155.3969,14.425851,6.1201138,0.0,0,3.4500248,0.0,0.52330494,108.78005,3.856966,354.67191,-9.2986097
2117,2117,155.3973,14.523076,6.155714,0.0,0,3.4145288,0.0,0.52788568,108.94955,3.8177826,354.55069,-9.2982235
2119,2119,155.3977,14.597174,6.1897564,0.0,0,3.3790326,0.0,0.53221953,109.10635,3.7800419,354.42944,-9.2992382
2121,2121,155.3981,14.639276,6.2381816,0.0,0,3.3435369,0.0,0.53637505,108.91437,3.7390428,354.30823,-9.2996635
2123,2123,155.3985,14.684403,6.2690349,0.0,0,3.3080409,0.0,0.54107499,108.80437,3.7040834,354.18701,-9.3002939
2125,2125,155.3989,14.761278,6.3028922,0.0,0,3.2725446,0.0,0.54474187,108.96338,3.6679478,354.0658,-9.2992754
2127,2127,155.3993,14.853767,6.3474879,0.0,0,3.2370486,0.0,0.54916632,109.16114,3.6288075,353.94458,-9.2987461
2129,2129,155.3997,14.934852,6.3776684,0.0,0,3.2015526,0.0,0.5537287,109.27766,3.5908313,353.65317,-9.2982607
2131,2131,155.4001,14.983415,6.4184771,0.0,0,3.1660566,0.0,0.55771858,109.18387,3.5544951,353.36176,-9.2981977
2133,2133,155.4005,15.045171,6.4629135,0.0,0,3.1309152,0.0,0.56287771,109.08035,3.5184312,353.07037,-9.2997875
2135,2135,155.4009,15.121747,6.489522,0.0,0,3.0970623,0.0,0.56695741,109.15916,3.4805791,352.77896,-9.300621
2137,2137,155.4013,15.20901,6.5272489,0.0,0,3.0632944,0.0,0.57025766,109.44111,3.4479246,352.48758,-9.2992296
2139,2139,155.4017,15.291047,6.5679731,0.0,0,3.0295265,0.0,0.57568604,109.43764,3.409162,352.19617,-9.2976255
2141,2141,155.4021,15.346668,6.6006336,0.0,0,2.9957583,0.0,0.57987177,109.37,3.3711584,351.90475,-9.2984171
2143,2143,155.4025,15.404459,6.6438541,0.0,0,2.9619906,0.0,0.58401477,109.30312,3.3336244,351.61337,-9.2990742
2145,2145,155.4029,15.495142,6.6812453,0.0,0,2.9282222,0.0,0.58957744,109.34875,3.2988105,351.32196,-9.3003864
2147,2147,155.4033,15.585534,6.7118831,0.0,0,2.8944542,0.0,0.59290308,109.62363,3.2624311,351.03058,-9.2994947
2149,2149,155.4037,15.662145,6.7512574,0.0,0,2.8606863,0.0,0.59706903,109.69576,3.2228105,350.73917,-9.2984495
2151,2151,155.4041,15.713755,6.7830315,0.0,0,2.8269184,0.0,0.60223001,109.51675,3.1883497,350.44775,-9.2972307
2153,2153,155.4045,15.773832,6.8210635,0.0,0,2.7931502,0.0,0.60563159,109.52805,3.1526344,350.15637,-9.2980947
2155,2155,155.4049,15.870157,6.8568234,0.0,0,2.7593822,0.0,0.61022991,109.70182,3.116993,349.86496,-9.2983732
2157,2157,155.4053,15.95772,6.8895965,0.0,0,2.7256143,0.0,0.61511004,109.78593,3.0858777,349.57358,-9.2988071
2159,2159,155.4057,16.034966,6.9333067,0.0,0,2.6929309,0.0,0.61911023,109.87681,3.0458372,349.28217,-9.2987871
2161,2161,155.4061,16.093197,6.9675398,0.0,0,2.6608074,0.0,0.62422371,109.75853,3.0130966,348.99075,-9.2974806
2163,2163,155.4065,16.179474,6.9969077,0.0,0,2.6286874,0.0,0.62832916,109.8428,2.9769156,348.69937,-9.2978201
2165,2165,155.4069,16.268976,7.0388002,0.0,0,2.5965672,0.0,0.63210732,110.01471,2.9390194,348.40796,-9.2987452
2167,2167,155.4073,16.349621,7.0657172,0.0,0,2.5644474,0.0,0.63692725,110.08558,2.9034274,348.11658,-9.2992458
2169,2169,155.4077,16.438587,7.1006603,0.0,0,2.5323272,0.0,0.6409384,110.25031,2.8704994,347.82516,-9.2987385
2171,2171,155.4081,16.512318,7.1460395,0.0,0,2.5002072,0.0,0.64575392,110.15783,2.835778,347.53375,-9.2980347
2173,2173,155.4085,16.5844,7.1734657,0.0,0,2.4680872,0.0,0.65072274,110.11846,2.804239,347.24237,-9.2975101
2175,2175,155.4089,16.673155,7.2099509,0.0,0,2.4359674,0.0,0.65437824,110.27444,2.7682545,346.95096,-9.2984285
2177,2177,155.4093,16.772102,7.2494202,0.0,0,2.4038472,0.0,0.6593098,110.37688,2.7338438,346.65958,-9.2981882
2179,2179,155.4097,16.859699,7.2726064,0.0,0,2.3717272,0.0,0.66345596,110.53768,2.6998484,346.47363,-9.2981215
2181,2181,155.4101,16.934608,7.3102026,0.0,0,2.3396072,0.0,0.66705668,110.6382,2.6647537,346.28772,-9.297883
2183,2183,155.4105,17.008644,7.3477554,0.0,0,2.3078089,0.0,0.67290235,110.43365,2.6288002,346.10178,-9.2972775
2185,2185,155.4109,17.091904,7.3755112,0.0,0,2.2771804,0.0,0.67665201,110.55051,2.5999084,345.91586,-9.2978306
2187,2187,155.4113,17.209841,7.4133406,0.0,0,2.246628,0.0,0.68056983,110.87197,2.5639896,345.72995,-9.2987261
2189,2189,155.4117,17.319105,7.4433842,0.0,0,2.2160764,0.0,0.68578798,110.95808,2.5299134,345.54401,-9.2981539
2191,2191,155.4121,17.37442,7.4744878,0.0,0,2.1855242,0.0,0.68938762,111.03625,2.4952352,345.35809,-9.2982283
2193,2193,155.4125,17.456156,7.5125003,0.0,0,2.1549723,0.0,0.69389403,111.0119,2.4606791,345.17215,-9.298192
2195,2195,155.4129,17.56786,7.5415096,0.0,0,2.1244202,0.0,0.69922084,111.10981,2.435231,344.98624,-9.2969484
2197,2197,155.4133,17.684778,7.5777016,0.0,0,2.0938683,0.0,0.70264161,111.47313,2.3975484,344.80029,-9.2961445
2199,2199,155.4137,17.767733,7.6102667,0.0,0,2.0633163,0.0,0.70727575,111.50768,2.3652885,344.61438,-9.2977705
2201,2201,155.4141,17.835236,7.6353402,0.0,0,2.0327644,0.0,0.7117219,111.37846,2.336416,344.42844,-9.2981005
2203,2203,155.4145,17.927227,7.6729808,0.0,0,2.0022123,0.0,0.71525878,111.52937,2.3021421,344.24252,-9.2973557
2205,2205,155.4149,18.027901,7.7017245,0.0,0,1.9716601,0.0,0.7201246,111.66832,2.2702558,344.05661,-9.2975435
2207,2207,155.4153,18.155691,7.7303295,0.0,0,1.9411081,0.0,0.72442228,111.91115,2.2381344,343.87067,-9.2980537
2209,2209,155.4157,18.252882,7.7762308,0.0,0,1.9115355,0.0,0.72904569,112.04441,2.205893,343.68475,-9.2976942
2211,2211,155.4161,18.327505,7.8009691,0.0,0,1.8824685,0.0,0.73429692,111.93886,2.17623,343.49881,-9.2976427
2213,2213,155.4165,18.425179,7.829392,0.0,0,1.8534043,0.0,0.737652,112.13065,2.1425703,343.3129,-9.2980099
2215,2215,155.4169,18.547583,7.8666539,0.0,0,1.8243403,0.0,0.74209189,112.33042,2.1129198,343.12695,-9.2974033
2217,2217,155.4173,18.68257,7.8866606,0.0,0,1.7952764,0.0,0.74660474,112.62424,2.0779765,342.94104,-9.2973166
2219,2219,155.4177,18.768351,7.9234405,0.0,0,1.7662123,0.0,0.75025564,112.81156,2.0462401,342.75513,-9.296483
2221,2221,155.4181,18.858501,7.9651742,0.0,0,1.7371484,0.0,0.75626051,112.66916,2.0167017,342.56918,-9.2965021
2223,2223,155.4185,18.970327,7.9883566,0.0,0,1.7080843,0.0,0.76085007,112.78962,1.9850608,342.38327,-9.2978554
2225,2225,155.4189,19.091827,8.0234928,0.0,0,1.6790204,0.0,0.76431262,113.12114,1.9561173,342.19733,-9.2982025
2227,2227,155.4193,19.229834,8.053051,0.0,0,1.6499563,0.0,0.76965302,113.32709,1.9238304,342.01141,-9.2981672
2229,2229,155.4197,19.315142,8.0754099,0.0,0,1.6208923,0.0,0.77303511,113.4669,1.888829,341.69119,-9.2957163
2231,2231,155.4201,19.399136,8.110981,0.0,0,1.5918283,0.0,0.77691424,113.51086,1.8594685,341.37097,-9.2957201
2233,2233,155.4205,19.518764,8.14293,0.0,0,1.5630548,0.0,0.78301448,113.50469,1.8296149,341.05078,-9.2962627
2235,2235,155.4209,19.650131,8.1736135,0.0,0,1.5353373,0.0,0.78682154,113.86978,1.7966841,340.73056,-9.2977791
2237,2237,155.4213,19.777983,8.2082777,0.0,0,1.5076892,0.0,0.7911827,114.0459,1.7680467,340.41037,-9.2967319
2239,2239,155.4217,19.876886,8.2311401,0.0,0,1.4800413,0.0,0.79634267,114.06172,1.7369696,340.09015,-9.2963533
2241,2241,155.4221,19.975939,8.2613077,0.0,0,1.4523933,0.0,0.7991792,114.2888,1.7110864,339.76993,-9.2963467
2243,2243,155.4225,20.094856,8.2904482,0.0,0,1.4247453,0.0,0.8039546,114.46328,1.6810461,339.44974,-9.2959137
2245,2245,155.4229,20.239155,8.3157129,0.0,0,1.3970973,0.0,0.80883282,114.71873,1.6485518,339.12952,-9.2964525
2247,2247,155.4233,20.373768,8.3560724,0.0,0,1.3694494,0.0,0.81284159,115.0074,1.6221426,338.80933,-9.297184
2249,2249,155.4237,20.473101,8.3816061,0.0,0,1.3418013,0.0,0.81812811,114.94011,1.5935543,338.48911,-9.2951908
2251,2251,155.4241,20.572071,8.4083662,0.0,0,1.3141534,0.0,0.82223392,115.09127,1.5619782,338.16888,-9.2954216
2253,2253,155.4245,20.712877,8.4478092,0.0,0,1.2865053,0.0,0.82658547,115.31286,1.5324388,337.84869,-9.2957897
2255,2255,155.4249,20.84384,8.4663639,0.0,0,1.2588574,0.0,0.83154374,115.50063,1.5050632,337.52847,-9.2954082
2257,2257,155.4253,20.985966,8.4929724,0.0,0,1.2312094,0.0,0.83475697,115.90981,1.4760092,337.20828,-9.2948503
2259,2259,155.4257,21.106054,8.5323391,0.0,0,1.2044513,0.0,0.83987796,115.94579,1.448493,336.88806,-9.2957153
2261,2261,155.4261,21.224335,8.551507,0.0,0,1.1781524,0.0,0.8447488,116.03701,1.4170673,336.56784,-9.2966509
2263,2263,155.4265,21.362696,8.5835648,0.0,0,1.1518564,0.0,0.84804249,116.4659,1.3873414,336.24765,-9.29634
2265,2265,155.4269,21.50326,8.6174431,0.0,0,1.1255604,0.0,0.8536765,116.5336,1.3602673,335.92743,-9.2951069
2267,2267,155.4273,21.643026,8.6353674,0.0,0,1.0992644,0.0,0.85773814,116.79336,1.3290226,335.60724,-9.2949896
2269,2269,155.4277,21.760883,8.6688576,0.0,0,1.0729684,0.0,0.86125207,116.99957,1.3026259,335.28702,-9.2943754
2271,2271,155.4281,21.873531,8.6988716,0.0,0,1.0466723,0.0,0.86720854,116.97565,1.276047,334.9668,-9.2950191
2273,2273,155.4285,22.013838,8.7206488,0.0,0,1.0203763,0.0,0.87079072,117.23585,1.2474402,334.64661,-9.29492
2275,2275,155.4289,22.163532,8.7528753,0.0,0,0.99408036,0.0,0.87454641,117.60683,1.2166969,334.32639,-9.2958469
2277,2277,155.4293,22.319357,8.7758512,0.0,0,0.96778435,0.0,0.88022494,117.75444,1.1887444,334.00616,-9.2944155
2279,2279,155.4297,22.449484,8.8006172,0.0,0,0.94148839,0.0,0.88305324,118.12138,1.1626614,333.35614,-9.2943411
2281,2281,155.4301,22.561993,8.8319902,0.0,0,0.91519243,0.0,0.8875823,118.18822,1.1384066,332.70612,-9.2942724
2283,2283,155.4305,22.705023,8.8540363,0.0,0,0.88916051,0.0,0.89290136,118.28724,1.1100638,332.05612,-9.2946329
2285,2285,155.4309,22.852028,8.886179,0.0,0,0.86408949,0.0,0.89626098,118.65276,1.0838214,331.4061,-9.2944946
2287,2287,155.4313,23.007212,8.9132748,0.0,0,0.83908135,0.0,0.90137553,118.88281,1.0550914,330.75607,-9.2943039
2289,2289,155.4317,23.136826,8.9327526,0.0,0,0.81407332,0.0,0.905788,119.00736,1.0274007,330.10605,-9.2943068
2291,2291,155.4321,23.254597,8.9676208,0.0,0,0.78906536,0.0,0.90942812,119.1707,1.0012435,329.45602,-9.2941036
2293,2293,155.4325,23.405901,8.9897585,0.0,0,0.7640574,0.0,0.91465479,119.3537,0.97654212,328.806,-9.2940493
2295,2295,155.4329,23.585396,9.0102997,0.0,0,0.73904938,0.0,0.91810864,119.79636,0.94796753,328.15598,-9.2947826
2297,2297,155.4333,23.740776,9.0448875,0.0,0,0.71404135,0.0,0.92218727,120.15435,0.92355269,327.50595,-9.2934752
2299,2299,155.4337,23.873549,9.0630016,0.0,0,0.68903339,0.0,0.9272508,120.19137,0.89684343,326.85596,-9.2940674
2301,2301,155.4341,24.00601,9.0884361,0.0,0,0.66402543,0.0,0.9306246,120.50074,0.87116045,326.20593,-9.2932396
2303,2303,155.4345,24.160967,9.1240549,0.0,0,0.63901734,0.0,0.9358055,120.59897,0.84459263,325.55591,-9.2938032
2305,2305,155.4349,24.34305,9.1385164,0.0,0,0.61400938,0.0,0.94037133,120.95862,0.81795025,324.90588,-9.2949076
2307,2307,155.4353,24.504074,9.1665659,0.0,0,0.58900136,0.0,0.94322348,121.4143,0.7909674,324.25586,-9.2946749
2309,2309,155.4357,24.625393,9.1988363,0.0,0,0.56478846,0.0,0.94922096,121.28971,0.76874703,323.60583,-9.2938185
2311,2311,155.4361,24.766546,9.2132349,0.0,0,0.54098594,0.0,0.95293927,121.53444,0.73995686,322.95581,-9.2931585
2313,2313,155.4365,24.938971,9.2433739,0.0,0,0.51718587,0.0,0.95634168,121.94638,0.71501452,322.30579,-9.2924652
2315,2315,155.4369,25.134825,9.2681246,0.0,0,0.49338591,0.0,0.96205872,122.1907,0.68932134,321.65579,-9.2932997
2317,2317,155.4373,25.296402,9.2860718,0.0,0,0.4695859,0.0,0.96527785,122.59879,0.6634239,321.00577,-9.294096
2319,2319,155.4377,25.439138,9.3182707,0.0,0,0.44578591,0.0,0.96937585,122.74643,0.64054829,320.35574,-9.2935295
2321,2321,155.4381,25.58127,9.3402605,0.0,0,0.42198589,0.0,0.97542262,122.76099,0.61693597,319.70572,-9.2934179
2323,2323,155.4385,25.756937,9.3615141,0.0,0,0.39818591,0.0,0.97786236,123.25806,0.59104604,319.05569,-9.292387
2325,2325,155.4389,25.939121,9.3886013,0.0,0,0.37438589,0.0,0.98199111,123.63405,0.56783599,318.40567,-9.292799
2327,2327,155.4393,26.107002,9.4068232,0.0,0,0.35058588,0.0,0.98736537,123.76165,0.54463923,317.75568,-9.2933331