File: clean data/testID_0246.csv
level_0,index,Time(sec),Force(kN),Jaw(mm),PowAngle(deg),Power(W),Pram,PTemp,Strain,Stress(MPa),Stroke(mm),TC1(C),wedge(mm)
2296,2296,178.7158,1.1280044,0.030802371,0.0,0,9.8198633,0.0,0.0022763968,14.120421,9.9080639,400.06631,-9.2646704
2307,2307,178.718,1.9041536,0.047937874,0.0,0,9.7868633,0.0,0.0028956705,24.103971,9.8766031,400.04544,-9.2638073
2318,2318,178.7202,2.0241051,0.036108416,0.0,0,9.7538633,0.0,0.0026334478,25.672691,9.8466473,400.01889,-9.2643681
2329,2329,178.7224,3.1379919,0.053989638,0.0,0,9.7208633,0.0,0.0034547288,39.441105,9.8169994,399.99237,-9.2636461
2340,2340,178.7246,3.7414362,0.07746201,0.0,0,9.6878624,0.0,0.0053697401,47.206905,9.7841434,399.96582,-9.2622147
2351,2351,178.7268,4.0412278,0.11839277,0.0,0,9.6548634,0.0,0.0075514112,50.909443,9.7564373,399.95667,-9.2617712
2362,2362,178.729,4.2568903,0.14565244,0.0,0,9.6218634,0.0,0.0099423025,53.521675,9.7209206,400.40787,-9.2624874
2373,2373,178.7312,4.4609823,0.18249418,0.0,0,9.5888634,0.0,0.012067747,55.955093,9.6820984,400.85907,-9.2628908
2384,2384,178.7334,4.5748453,0.21553297,0.0,0,9.5558634,0.0,0.014704679,57.342308,9.6429806,401.31027,-9.2630453
2395,2395,178.7356,4.6507325,0.26067865,0.0,0,9.5228634,0.0,0.017139429,58.217426,9.6056814,401.76147,-9.2624073
2406,2406,178.7378,4.716948,0.28905511,0.0,0,9.4898634,0.0,0.019614331,58.925037,9.5705986,402.32547,-9.2620201
2417,2417,178.74,4.7553658,0.32333383,0.0,0,9.4574747,0.0,0.021613901,59.142876,9.5356636,403.00226,-9.2621746
2428,2428,178.7422,4.7892094,0.35380474,0.0,0,9.4252853,0.0,0.024081821,59.524319,9.5018425,403.67908,-9.2621603
2439,2439,178.7444,4.8152409,0.39476705,0.0,0,9.393095,0.0,0.026322452,59.665169,9.4696054,404.35587,-9.2638817
2450,2450,178.7466,4.8581991,0.42242792,0.0,0,9.3609047,0.0,0.028739188,60.007595,9.4309092,405.03268,-9.2630119
2461,2461,178.7488,4.8846869,0.45750326,0.0,0,9.3287144,0.0,0.030798482,60.281483,9.3965092,404.95499,-9.2626114
2472,2472,178.751,4.9100275,0.48306692,0.0,0,9.2965231,0.0,0.032961871,60.464066,9.3682146,404.84882,-9.2622128
2483,2483,178.7532,4.9172063,0.52100772,0.0,0,9.2643328,0.0,0.035043068,60.496529,9.3385,404.74265,-9.2634211
2494,2494,178.7554,4.9358807,0.54574996,0.0,0,9.2321424,0.0,0.03718631,60.582985,9.3084879,404.63647,-9.2638512
2505,2505,178.7576,4.9555736,0.58014929,0.0,0,9.1999531,0.0,0.03926624,60.771469,9.2726851,404.41693,-9.2640505
2516,2516,178.7598,4.9841723,0.60913688,0.0,0,9.1677618,0.0,0.041634824,60.854263,9.2399921,404.04535,-9.2640543
2527,2527,178.762,4.9940095,0.64992619,0.0,0,9.1355715,0.0,0.04401182,60.836376,9.2060499,403.67377,-9.2629194
2538,2538,178.7642,5.0119896,0.67463779,0.0,0,9.1033812,0.0,0.046146058,60.931877,9.1797295,403.30219,-9.2634554
2549,2549,178.7664,5.0575385,0.70498645,0.0,0,9.0711908,0.0,0.047970995,61.268921,9.1437845,402.9306,-9.2629204
2560,2560,178.7686,5.1100793,0.73473048,0.0,0,9.0390005,0.0,0.050351031,61.701111,9.1104622,402.91373,-9.2628794
2571,2571,178.7708,5.1338468,0.77554387,0.0,0,9.0068102,0.0,0.052813023,62.044498,9.078927,402.94025,-9.262907
2582,2582,178.773,5.1454601,0.8015601,0.0,0,8.9746189,0.0,0.055008482,62.101894,9.0482807,402.9668,-9.2626772
2593,2593,178.7752,5.1513524,0.83717263,0.0,0,8.9424286,0.0,0.057282895,61.947472,9.0138311,402.99335,-9.2644787
2604,2604,178.7774,5.1646028,0.86661547,0.0,0,8.9102392,0.0,0.059588131,61.985542,8.9791698,403.0246,-9.2632332
2615,2615,178.7796,5.1953273,0.90395343,0.0,0,8.8780489,0.0,0.061952636,62.17519,8.9462996,403.06439,-9.2636986
2626,2626,178.7818,5.2147555,0.92974263,0.0,0,8.8458576,0.0,0.064141817,62.234344,8.9133234,403.10422,-9.2626209
2637,2637,178.784,5.2359667,0.96470237,0.0,0,8.8136673,0.0,0.066306852,62.355247,8.8814812,403.14401,-9.2623882
2648,2648,178.7862,5.2719221,0.99228364,0.0,0,8.781476,0.0,0.068464182,62.689377,8.8494883,403.18384,-9.2617426
2659,2659,178.7884,5.2950392,1.0288395,0.0,0,8.7493448,0.0,0.07085935,62.859436,8.8164063,403.31052,-9.2639446
2670,2670,178.7906,5.3258181,1.0570287,0.0,0,8.7187157,0.0,0.073097296,63.014854,8.7862434,403.45648,-9.2639446
2681,2681,178.7928,5.3291593,1.0901064,0.0,0,8.6880999,0.0,0.075349964,62.98085,8.7532091,403.60245,-9.2620506
2692,2692,178.795,5.3410883,1.1187254,0.0,0,8.657486,0.0,0.077517912,62.998535,8.7218952,403.74844,-9.2626419
2703,2703,178.7972,5.3535352,1.1552144,0.0,0,8.6268702,0.0,0.079947285,62.853638,8.6904793,403.91684,-9.2625923
2714,2714,178.7994,5.3808861,1.1814475,0.0,0,8.5962553,0.0,0.082073331,63.068241,8.6562662,404.14246,-9.2625551
2725,2725,178.8016,5.3858252,1.2148499,0.0,0,8.5656395,0.0,0.084371388,63.00811,8.6299047,404.36804,-9.2630787
2736,2736,178.8038,5.4246387,1.2439042,0.0,0,8.5350256,0.0,0.086573206,63.359215,8.593524,404.59366,-9.2632389
2747,2747,178.806,5.4630928,1.2811205,0.0,0,8.5044088,0.0,0.08918383,63.534328,8.5636339,404.81924,-9.2630386
2758,2758,178.8082,5.4794145,1.3091118,0.0,0,8.4737949,0.0,0.091335937,63.789921,8.5326147,404.89645,-9.2623768
2769,2769,178.8104,5.481555,1.341185,0.0,0,8.4431791,0.0,0.093601406,63.5886,8.5031252,404.923,-9.2620707
2780,2780,178.8126,5.4856195,1.3682448,0.0,0,8.4125643,0.0,0.095588669,63.524563,8.4697838,404.94955,-9.2622137
2791,2791,178.8148,5.4968886,1.4042414,0.0,0,8.3819485,0.0,0.098171756,63.414124,8.438776,404.97607,-9.2629271
2802,2802,178.817,5.5227051,1.4315516,0.0,0,8.3513327,0.0,0.10029886,63.640591,8.406558,405.03177,-9.2642155
2813,2813,178.8192,5.5513854,1.4635316,0.0,0,8.3207188,0.0,0.10265152,63.737885,8.3752451,405.19763,-9.2635546
2824,2824,178.8214,5.5582404,1.4907255,0.0,0,8.290103,0.0,0.10462044,63.772461,8.3447113,405.36353,-9.2635679
2835,2835,178.8236,5.596735,1.5272532,0.0,0,8.2594881,0.0,0.10737606,63.940731,8.3119917,405.52939,-9.2621002
2846,2846,178.8258,5.610527,1.5534147,0.0,0,8.2288723,0.0,0.10922523,64.124336,8.2848082,405.69528,-9.2617235
2857,2857,178.828,5.6355386,1.5826522,0.0,0,8.1982584,0.0,0.11155195,64.185951,8.2527037,405.91028,-9.2623367
2868,2868,178.8302,5.636622,1.6116474,0.0,0,8.1676426,0.0,0.11359048,64.035637,8.2227716,406.14914,-9.262311
2879,2879,178.8324,5.6528459,1.6456156,0.0,0,8.1370277,0.0,0.11626051,64.106644,8.1902771,406.38803,-9.2620306
2890,2890,178.8346,5.6726446,1.6732583,0.0,0,8.1064119,0.0,0.1180827,64.206367,8.1617012,406.62689,-9.2622538
2901,2901,178.8368,5.7117958,1.7022675,0.0,0,8.0757971,0.0,0.12054051,64.4282,8.1288986,406.854,-9.2633314
2912,2912,178.839,5.7227407,1.733304,0.0,0,8.0456295,0.0,0.12267355,64.437286,8.0949745,407.00662,-9.2637348
2923,2923,178.8412,5.7511711,1.7661006,0.0,0,8.0165014,0.0,0.12545198,64.615105,8.0696154,407.15924,-9.2631979
2934,2934,178.8434,5.7819271,1.7946023,0.0,0,7.9873738,0.0,0.12720697,64.904015,8.0389175,407.31186,-9.263154
2945,2945,178.8456,5.8070769,1.8230618,0.0,0,7.9582458,0.0,0.12965,64.931366,8.0033207,407.46448,-9.2618723
2956,2956,178.8478,5.8176112,1.854228,0.0,0,7.9291172,0.0,0.13178179,64.934616,7.9736404,407.65292,-9.2628145
2967,2967,178.85,5.8237586,1.8867698,0.0,0,7.8999891,0.0,0.13458626,64.908096,7.9427953,407.86523,-9.2635336
2978,2978,178.8522,5.8235912,1.9178237,0.0,0,7.8708615,0.0,0.13654798,64.780579,7.9107475,408.07758,-9.2625656
2989,2989,178.8544,5.8393817,1.9443208,0.0,0,7.8417335,0.0,0.13888359,64.642868,7.8856139,408.28989,-9.2630959
3000,3000,178.8566,5.854032,1.9702353,0.0,0,7.8126054,0.0,0.14060417,64.710373,7.8544173,408.50772,-9.2622957
3011,3011,178.8588,5.8621635,1.9998393,0.0,0,7.7834773,0.0,0.14324781,64.679558,7.8278804,408.8063,-9.2623549
3022,3022,178.861,5.8825035,2.0283003,0.0,0,7.7543492,0.0,0.14503682,64.753799,7.7991185,409.10489,-9.2641163
3033,3033,178.8632,5.9269266,2.0535331,0.0,0,7.7252216,0.0,0.1473853,65.072342,7.7742009,409.40347,-9.2629318
3044,3044,178.8654,5.979187,2.0829237,0.0,0,7.696094,0.0,0.14928153,65.543785,7.7455678,409.70206,-9.262291
3055,3055,178.8676,5.9854765,2.1151662,0.0,0,7.666965,0.0,0.1522086,65.494926,7.7122312,409.97617,-9.2629309
3066,3066,178.8698,5.9905062,2.1465805,0.0,0,7.6378374,0.0,0.15413821,65.474403,7.6831841,410.2283,-9.2630816
3077,3077,178.872,6.0049696,2.1717038,0.0,0,7.6087093,0.0,0.15660115,65.369499,7.6529021,410.48044,-9.2631474
3088,3088,178.8742,6.0177522,2.2006786,0.0,0,7.5795817,0.0,0.15838128,65.356232,7.6244545,410.7326,-9.2635803
3099,3099,178.8764,6.0346322,2.2294955,0.0,0,7.5504532,0.0,0.16125508,65.463074,7.5960417,410.98474,-9.2622747
3110,3110,178.8786,6.0732026,2.2609677,0.0,0,7.5213251,0.0,0.16304292,65.647789,7.5672784,411.03964,-9.2625771
3121,3121,178.8808,6.0966244,2.2848477,0.0,0,7.4921975,0.0,0.16550641,65.767525,7.5375342,411.09271,-9.2623339
3132,3132,178.883,6.126595,2.3147354,0.0,0,7.4630694,0.0,0.16732888,65.91626,7.5090642,411.14581,-9.2624264
3143,3143,178.8852,6.155704,2.3430908,0.0,0,7.4339414,0.0,0.1701505,66.147369,7.4822206,411.19888,-9.2632189
3154,3154,178.8874,6.169322,2.3769083,0.0,0,7.4048128,0.0,0.17218307,66.041107,7.4486752,411.23389,-9.262948
3165,3165,178.8896,6.1741552,2.4041045,0.0,0,7.3765039,0.0,0.17492324,66.044807,7.4191771,411.24713,-9.2622786
3176,3176,178.8918,6.1936054,2.435292,0.0,0,7.3488011,0.0,0.17687958,66.142578,7.3904471,411.26041,-9.262558
3187,3187,178.894,6.2064319,2.4617331,0.0,0,7.3210988,0.0,0.17959671,66.02964,7.3598456,411.27368,-9.261548
3198,3198,178.8962,6.2334547,2.4955318,0.0,0,7.2933965,0.0,0.18149546,66.269981,7.334856,411.28693,-9.2619371
3209,3209,178.8984,6.2577477,2.5155153,0.0,0,7.2656941,0.0,0.18381347,66.207962,7.3012972,411.36115,-9.262928
3220,3220,178.9006,6.2612162,2.5455658,0.0,0,7.2379913,0.0,0.18570083,66.179276,7.2761617,411.44077,-9.2625237
3231,3231,178.9028,6.2815623,2.5703204,0.0,0,7.210289,0.0,0.18828481,66.313362,7.2448792,411.52039,-9.2622013
3242,3242,178.905,6.298759,2.6030803,0.0,0,7.1825867,0.0,0.19014825,66.321861,7.2205234,411.60001,-9.2621813
3253,3253,178.9072,6.2997222,2.6232159,0.0,0,7.1548843,0.0,0.19255809,66.176643,7.1897655,411.67709,-9.2628374
3264,3264,178.9094,6.2984467,2.6547797,0.0,0,7.1271815,0.0,0.19450606,65.970901,7.1638823,411.75009,-9.2636003
3275,3275,178.9116,6.3410654,2.6796815,0.0,0,7.0994792,0.0,0.1971318,66.281769,7.1364579,411.82309,-9.2614412
3286,3286,178.9138,6.3993483,2.7126777,0.0,0,7.0717773,0.0,0.19899467,66.668892,7.1117711,411.89609,-9.2610664
3297,3297,178.916,6.4266891,2.7343144,0.0,0,7.044075,0.0,0.20142686,66.851028,7.0817189,411.96906,-9.2627087
3308,3308,178.9182,6.4635353,2.7652903,0.0,0,7.0163722,0.0,0.20355898,67.145142,7.0509739,411.99158,-9.2634974
3319,3319,178.9204,6.4685559,2.7916327,0.0,0,6.9886694,0.0,0.2063068,66.982124,7.0240064,412.00482,-9.2632313
3330,3330,178.9226,6.4883904,2.8265948,0.0,0,6.9609675,0.0,0.20833121,67.108856,6.9941492,412.0181,-9.2632456
3341,3341,178.9248,6.4921165,2.8477612,0.0,0,6.9332652,0.0,0.21077387,66.899864,6.9634938,412.03137,-9.2638054
3352,3352,178.927,6.5011768,2.8777633,0.0,0,6.9055629,0.0,0.21267116,66.884102,6.9405012,412.04462,-9.2623739
3363,3363,178.9292,6.52034,2.9037738,0.0,0,6.8778601,0.0,0.21540907,66.945862,6.9092102,412.05789,-9.2628269
3374,3374,178.9314,6.5570903,2.9375298,0.0,0,6.8501582,0.0,0.21755321,67.169907,6.8828483,412.07117,-9.2635975
3385,3385,178.9336,6.5941453,2.9583714,0.0,0,6.8224554,0.0,0.21986786,67.366928,6.8547635,412.08441,-9.262846
3396,3396,178.9358,6.6180568,2.9888473,0.0,0,6.7947526,0.0,0.22198762,67.463814,6.8263931,412.09769,-9.2614756
3407,3407,178.938,6.6392646,3.012361,0.0,0,6.7670503,0.0,0.22442178,67.512856,6.7987285,412.09558,-9.2628908
3418,3418,178.9402,6.6442118,3.048173,0.0,0,6.7404881,0.0,0.22679403,67.471382,6.7712913,412.08896,-9.2629976
3429,3429,178.9424,6.6607661,3.0686741,0.0,0,6.7141318,0.0,0.22911392,67.443619,6.7414904,412.08231,-9.2632713
3440,3440,178.9446,6.6695962,3.0978825,0.0,0,6.6877761,0.0,0.23113473,67.395241,6.7156963,412.07568,-9.2630138
3451,3451,178.9468,6.6912065,3.1229191,0.0,0,6.6614199,0.0,0.23368201,67.480675,6.6869731,412.04709,-9.2637758
3462,3462,178.949,6.7146416,3.156142,0.0,0,6.6350636,0.0,0.23595816,67.474373,6.6581378,411.94757,-9.2637491
3473,3473,178.9512,6.7456141,3.1764805,0.0,0,6.6087079,0.0,0.23812589,67.59227,6.6321378,411.84805,-9.2638216
3484,3484,178.9534,6.7452755,3.2054212,0.0,0,6.5823522,0.0,0.24016155,67.47197,6.6074362,411.74854,-9.2634201
3495,3495,178.9556,6.7553988,3.2257438,0.0,0,6.5559959,0.0,0.24240389,67.513237,6.5805521,411.64899,-9.2621145
3506,3506,178.9578,6.7576518,3.2586708,0.0,0,6.5296402,0.0,0.2445609,67.437286,6.5573416,411.56342,-9.2614784
3517,3517,178.96,6.7758384,3.2758341,0.0,0,6.503284,0.0,0.2464907,67.423294,6.5331397,411.48376,-9.2635689
3528,3528,178.9622,6.790966,3.3035672,0.0,0,6.4769282,0.0,0.24855036,67.448235,6.5029898,411.40414,-9.2636404
3539,3539,178.9644,6.7999663,3.3252919,0.0,0,6.450572,0.0,0.25083449,67.401749,6.4862976,411.32452,-9.2641325
3550,3550,178.9666,6.8274527,3.3577266,0.0,0,6.4242163,0.0,0.25308704,67.494583,6.4588637,411.2536,-9.2630863
3561,3561,178.9688,6.898273,3.3776572,0.0,0,6.3978601,0.0,0.25518218,67.989372,6.4293966,411.22705,-9.2635584
3572,3572,178.971,6.9703069,3.4071572,0.0,0,6.3715043,0.0,0.25749439,68.536491,6.4027052,411.2005,-9.2632637
3583,3583,178.9732,6.9960661,3.4345062,0.0,0,6.3451481,0.0,0.26009005,68.71524,6.3719978,411.17395,-9.2623682
3594,3594,178.9754,7.0140147,3.4710584,0.0,0,6.3187923,0.0,0.26288223,68.714951,6.3494964,411.1474,-9.2620087
3605,3605,178.9776,7.0332584,3.4912548,0.0,0,6.2924366,0.0,0.26498955,68.618858,6.3162446,410.96271,-9.26301
3616,3616,178.9798,7.0330629,3.5200891,0.0,0,6.2660804,0.0,0.26736829,68.546669,6.2898998,410.68402,-9.2613955
3627,3627,178.982,7.0254059,3.5438688,0.0,0,6.2397246,0.0,0.26958585,68.37606,6.2657852,410.40533,-9.261425
3638,3638,178.9842,7.0524797,3.5767555,0.0,0,6.2133684,0.0,0.27220631,68.38295,6.2377367,410.12665,-9.2618513
3649,3649,178.9864,7.050384,3.5963016,0.0,0,6.1870127,0.0,0.27423388,68.241943,6.2097425,409.83951,-9.2634125
3660,3660,178.9886,7.0988388,3.6258144,0.0,0,6.1608109,0.0,0.27652541,68.561905,6.1854386,409.46793,-9.2628689
3671,3671,178.9908,7.1604886,3.6499212,0.0,0,6.1357436,0.0,0.27879155,68.979141,6.1566348,409.09634,-9.261879
3682,3682,178.993,7.1760092,3.682519,0.0,0,6.1106763,0.0,0.28163171,68.966385,6.1332574,408.72479,-9.2611475
3693,3693,178.9952,7.1816969,3.7022684,0.0,0,6.0856099,0.0,0.28348923,68.85762,6.1058707,408.35321,-9.2616434
3704,3704,178.9974,7.1671829,3.7281055,0.0,0,6.0605431,0.0,0.2857177,68.637802,6.0794926,408.11411,-9.2622585
3715,3715,178.9996,7.1910748,3.7503164,0.0,0,6.0354762,0.0,0.28768256,68.656593,6.052525,407.98138,-9.2615795
3726,3726,179.0018,7.2028246,3.7803161,0.0,0,6.0104094,0.0,0.29026154,68.506821,6.0289011,407.84869,-9.2615223
3737,3737,179.004,7.2064481,3.8016384,0.0,0,5.9853425,0.0,0.29229283,68.533157,6.00247,407.71597,-9.2614241
3748,3748,179.0062,7.2220607,3.8254864,0.0,0,5.9602757,0.0,0.2944594,68.488365,5.9767108,407.58618,-9.261364
3759,3759,179.0084,7.2728314,3.847959,0.0,0,5.9352088,0.0,0.29633829,68.788155,5.9554377,407.61273,-9.2608204
3770,3770,179.0106,7.3077087,3.8777239,0.0,0,5.9101424,0.0,0.29913437,69.022461,5.9315524,407.63928,-9.2622671
3781,3781,179.0128,7.3358564,3.8985355,0.0,0,5.8850756,0.0,0.30082944,69.100845,5.9069295,407.6658,-9.2615643
3792,3792,179.015,7.3532386,3.9221056,0.0,0,5.8600087,0.0,0.30318227,69.159279,5.8812599,407.69235,-9.2621574
3803,3803,179.0172,7.3750987,3.9492834,0.0,0,5.8349419,0.0,0.30544415,69.218834,5.8549962,407.72528,-9.2622385
3814,3814,179.0194,7.3926172,3.9781311,0.0,0,5.809875,0.0,0.30819348,69.140808,5.8298683,407.76511,-9.2626286
3825,3825,179.0216,7.3917475,3.9992907,0.0,0,5.7848082,0.0,0.30988786,68.985252,5.8048749,407.8049,-9.262599
3836,3836,179.0238,7.4267497,4.0240426,0.0,0,5.7597413,0.0,0.31241241,69.158752,5.777873,407.84473,-9.2621384
3847,3847,179.026,7.4762902,4.0468817,0.0,0,5.7346745,0.0,0.31422222,69.508873,5.7555046,407.88452,-9.2623434
3858,3858,179.0282,7.5151429,4.0760078,0.0,0,5.7096076,0.0,0.31723994,69.586929,5.7259965,407.69849,-9.2624731
3869,3869,179.0304,7.5504174,4.1012392,0.0,0,5.6845412,0.0,0.31909075,69.886078,5.7020431,407.49942,-9.2621403
3880,3880,179.0326,7.5671706,4.1248498,0.0,0,5.6594744,0.0,0.32165116,69.858208,5.6782126,407.30038,-9.2612457
3891,3891,179.0348,7.5615134,4.1491046,0.0,0,5.634407,0.0,0.32359236,69.774986,5.6513128,407.10132,-9.2609959
3902,3902,179.037,7.5918088,4.1770787,0.0,0,5.6093407,0.0,0.32659867,69.652687,5.6280942,406.91312,-9.2624197
3913,3913,179.0392,7.6177907,4.2015371,0.0,0,5.5847516,0.0,0.3283436,69.824921,5.6008263,406.7406,-9.2627573
3924,3924,179.0414,7.62112,4.2247453,0.0,0,5.5609035,0.0,0.33097985,69.756279,5.5778389,406.56808,-9.26297
3935,3935,179.0436,7.6612682,4.2514334,0.0,0,5.5370555,0.0,0.33297533,69.935051,5.552588,406.39557,-9.2621574
3946,3946,179.0458,7.6845121,4.2771516,0.0,0,5.5132074,0.0,0.33601078,69.90583,5.5287447,406.22305,-9.2616282
3957,3957,179.048,7.6995091,4.3007398,0.0,0,5.4893594,0.0,0.337477,69.939583,5.5024338,406.259,-9.2609568
3968,3968,179.0502,7.7196088,4.3210273,0.0,0,5.4655118,0.0,0.34002259,69.952347,5.4781365,406.32535,-9.2619734
3979,3979,179.0524,7.7197566,4.3455811,0.0,0,5.4416633,0.0,0.34173724,69.766838,5.4572449,406.39169,-9.2613649
3990,3990,179.0546,7.7199221,4.3689408,0.0,0,5.4178157,0.0,0.34455061,69.616905,5.4335408,406.45804,-9.2621126
4001,4001,179.0568,7.7719145,4.3944292,0.0,0,5.3939681,0.0,0.34627181,69.992874,5.410213,406.51547,-9.2619705
4012,4012,179.059,7.8098416,4.4150157,0.0,0,5.3701196,0.0,0.34892583,70.199944,5.3864675,406.55527,-9.2622414
4023,4023,179.0612,7.8497567,4.4427366,0.0,0,5.346272,0.0,0.35084444,70.389191,5.3645153,406.59509,-9.2625103
4034,4034,179.0634,7.8631096,4.4654331,0.0,0,5.3224235,0.0,0.35372713,70.292809,5.3372025,406.63492,-9.2614679
4045,4045,179.0656,7.906065,4.4934144,0.0,0,5.2985759,0.0,0.35561821,70.507034,5.3139319,406.67471,-9.261405
4056,4056,179.0678,7.9453282,4.5133615,0.0,0,5.2747283,0.0,0.35827035,70.712502,5.2909284,406.62961,-9.2610645
4067,4067,179.07,7.9748669,4.5405221,0.0,0,5.2508798,0.0,0.36014858,70.854103,5.2637172,406.56323,-9.2609119
4078,4078,179.0722,7.9894404,4.5649033,0.0,0,5.2270317,0.0,0.36321771,70.682899,5.2385869,406.49689,-9.2622232
4089,4089,179.0744,7.9891386,4.5937448,0.0,0,5.2031837,0.0,0.36511552,70.624153,5.2124324,406.43054,-9.2622395
4100,4100,179.0766,7.9749823,4.6100054,0.0,0,5.1793361,0.0,0.36757979,70.337433,5.1892915,406.3642,-9.2628393
4111,4111,179.0788,8.0067701,4.6360531,0.0,0,5.155488,0.0,0.36927748,70.358971,5.1673388,406.29785,-9.2620363
4122,4122,179.081,8.0154419,4.6582952,0.0,0,5.13164,0.0,0.37230116,70.313416,5.1454368,406.23148,-9.2615242
4133,4133,179.0832,8.0568638,4.6867828,0.0,0,5.1077919,0.0,0.37404576,70.633476,5.1196451,406.16513,-9.2618265
4144,4144,179.0854,8.088624,4.7015367,0.0,0,5.0839438,0.0,0.37652478,70.670853,5.0964994,406.09879,-9.2618046
4155,4155,179.0876,8.1257734,4.7292919,0.0,0,5.0600958,0.0,0.37828419,70.903709,5.0762467,405.87317,-9.261714
4166,4166,179.0898,8.141058,4.74861,0.0,0,5.0370226,0.0,0.38111064,70.802826,5.056078,405.58786,-9.2614365
4177,4177,179.092,8.1843224,4.7803621,0.0,0,5.0143409,0.0,0.3830989,71.102592,5.0242238,405.30255,-9.2613831
4188,4188,179.0942,8.2220573,4.7989826,0.0,0,4.9916592,0.0,0.38600492,71.187469,5.0028658,405.01721,-9.2616396
4199,4199,179.0964,8.2443037,4.8251734,0.0,0,4.968977,0.0,0.38762558,71.232033,4.980731,404.70151,-9.2622414
4210,4210,179.0986,8.2629681,4.8477945,0.0,0,4.9462948,0.0,0.39085221,71.129723,4.9534831,404.25693,-9.2618036
4221,4221,179.1008,8.2520018,4.8780208,0.0,0,4.9236126,0.0,0.39270926,70.869171,4.9304342,403.81238,-9.2624273
4232,4232,179.103,8.2727299,4.8915563,0.0,0,4.9009309,0.0,0.39511901,70.973389,4.9083076,403.3678,-9.2612476
4243,4243,179.1052,8.3014488,4.9148011,0.0,0,4.8782492,0.0,0.39668155,71.122261,4.8891554,402.92322,-9.2622757
4254,4254,179.1074,8.3382015,4.9357204,0.0,0,4.8555665,0.0,0.39954105,71.125519,4.8669558,402.7132,-9.26227
4265,4265,179.1096,8.3443766,4.9656844,0.0,0,4.8328848,0.0,0.40136856,71.096375,4.8392596,402.62692,-9.2630005
4276,4276,179.1118,8.3466091,4.9787059,0.0,0,4.8102031,0.0,0.4037576,71.010483,4.8189144,402.54068,-9.2623425
4287,4287,179.114,8.3614168,5.0048351,0.0,0,4.7875209,0.0,0.40561238,70.996971,4.8020792,402.45441,-9.2623777
4298,4298,179.1162,8.4125738,5.0249763,0.0,0,4.7648387,0.0,0.40834183,71.157562,4.7764802,402.38855,-9.2610502
4309,4309,179.1184,8.4721766,5.0564957,0.0,0,4.7421565,0.0,0.41042715,71.513229,4.7529678,402.47482,-9.2620306
4320,4320,179.1206,8.4932756,5.0696993,0.0,0,4.7194748,0.0,0.41282853,71.571022,4.7313433,402.56107,-9.2615604
4331,4331,179.1228,8.5306511,5.0966563,0.0,0,4.6967926,0.0,0.41481,71.710335,4.7075453,402.64734,-9.2608929
4342,4342,179.125,8.5640192,5.1148596,0.0,0,4.6741109,0.0,0.41746891,71.848068,4.6850204,402.73358,-9.2618141
4353,4353,179.1272,8.5945368,5.1473374,0.0,0,4.6514287,0.0,0.41978824,71.890205,4.6596022,402.75421,-9.2612858
4364,4364,179.1294,8.6077919,5.1643758,0.0,0,4.628747,0.0,0.42239961,71.855476,4.6325226,402.72766,-9.2609491
4375,4375,179.1316,8.6123161,5.1927023,0.0,0,4.6060648,0.0,0.42466342,71.756645,4.6124563,402.70114,-9.2614031
4386,4386,179.1338,8.6089954,5.2084937,0.0,0,4.5833831,0.0,0.42695051,71.51223,4.5896831,402.67459,-9.2629566
4397,4397,179.136,8.6391697,5.2383547,0.0,0,4.5607004,0.0,0.42908549,71.598343,4.5674582,402.64532,-9.2622061
4408,4408,179.1382,8.676424,5.2536578,0.0,0,4.5380187,0.0,0.43148786,71.774414,4.5470061,402.55908,-9.2623281
4419,4419,179.1404,8.7098799,5.2800474,0.0,0,4.5163722,0.0,0.43354225,71.882355,4.5213547,402.47284,-9.2624493
4430,4430,179.1426,8.7441292,5.2960105,0.0,0,4.4947944,0.0,0.43588027,72.001839,4.5024123,402.38657,-9.2621994
4441,4441,179.1448,8.7662086,5.3284001,0.0,0,4.4732165,0.0,0.43842721,71.984505,4.4801645,402.30032,-9.2614632
4452,4452,179.147,8.780201,5.3419852,0.0,0,4.4516392,0.0,0.44055668,71.977234,4.460053,402.10257,-9.2613573
4463,4463,179.1492,8.8044643,5.3689861,0.0,0,4.4300613,0.0,0.44280136,71.932686,4.4357948,401.79736,-9.2613688
4474,4474,179.1514,8.8499355,5.387588,0.0,0,4.408484,0.0,0.44520077,72.148888,4.4099689,401.49213,-9.2618628
4485,4485,179.1536,8.8761539,5.4166722,0.0,0,4.3869061,0.0,0.44770247,72.234596,4.3899417,401.18689,-9.2627707
4496,4496,179.1558,8.8947506,5.4317169,0.0,0,4.3653288,0.0,0.44989035,72.178024,4.370327,400.88168,-9.2621155
4507,4507,179.158,8.9165916,5.4561019,0.0,0,4.343751,0.0,0.4518345,72.288406,4.3517437,400.39572,-9.2612562
4518,4518,179.1602,8.9386806,5.4747024,0.0,0,4.3221736,0.0,0.45415661,72.262306,4.3280525,399.90472,-9.2606716
4529,4529,179.1624,8.9648657,5.504756,0.0,0,4.3005962,0.0,0.45687327,72.242012,4.3024216,399.4137,-9.2615614
4540,4540,179.1646,8.9898281,5.5187898,0.0,0,4.2790184,0.0,0.45885685,72.311325,4.2829986,398.92267,-9.261322
4551,4551,179.1668,8.9998102,5.5434008,0.0,0,4.2574406,0.0,0.46112317,72.286888,4.2611141,398.41986,-9.2625465
4562,4562,179.169,9.011219,5.5617466,0.0,0,4.2358632,0.0,0.46329623,72.19397,4.2426653,397.90182,-9.2615709
4573,4573,179.1712,9.0665913,5.5880113,0.0,0,4.2142854,0.0,0.46573675,72.438713,4.2195644,397.38376,-9.2623482
4584,4584,179.1734,9.109333,5.6031942,0.0,0,4.192708,0.0,0.4678424,72.647842,4.1981754,396.86569,-9.2628765
4595,4595,179.1756,9.1594028,5.6285591,0.0,0,4.1711302,0.0,0.47021586,72.886757,4.177424,396.34763,-9.2621307
4606,4606,179.1778,9.2166357,5.6497507,0.0,0,4.1495528,0.0,0.47262713,73.141464,4.1539125,395.91891,-9.2625036
4617,4617,179.18,9.2337971,5.6803765,0.0,0,4.127975,0.0,0.47577348,73.12326,4.1309986,395.50009,-9.2620821
4628,4628,179.1822,9.2519989,5.6969824,0.0,0,4.1063976,0.0,0.47768274,73.068581,4.1120872,395.0813,-9.2614603
4639,4639,179.1844,9.2452402,5.7203135,0.0,0,4.0848203,0.0,0.48020911,72.847046,4.088665,394.66248,-9.2617302
4650,4650,179.1866,9.2362957,5.7373753,0.0,0,4.0632424,0.0,0.48192564,72.687416,4.0650544,394.22913,-9.2607861
4661,4661,179.1888,9.2461395,5.7622585,0.0,0,4.0418863,0.0,0.48470911,72.473969,4.0433097,393.77032,-9.260849
4672,4672,179.191,9.2803144,5.7789927,0.0,0,4.0213647,0.0,0.48650554,72.646103,4.0232654,393.31152,-9.261198
4683,4683,179.1932,9.3401804,5.8031545,0.0,0,4.0008435,0.0,0.48920715,72.886734,4.0055718,392.85272,-9.2615862
4694,4694,179.1954,9.3949223,5.822258,0.0,0,3.9803219,0.0,0.49108756,73.172653,3.9829664,392.39395,-9.260932
4705,4705,179.1976,9.442214,5.8483925,0.0,0,3.9598002,0.0,0.4940595,73.340767,3.9610715,391.97363,-9.2618198
4716,4716,179.1998,9.4648876,5.8666511,0.0,0,3.9392786,0.0,0.49582148,73.433517,3.9425919,391.5614,-9.2634792
4727,4727,179.202,9.4429474,5.8887358,0.0,0,3.918757,0.0,0.49864385,73.016121,3.9185903,391.14914,-9.2634096
4738,4738,179.2042,9.4213419,5.9058623,0.0,0,3.8982356,0.0,0.50031018,72.737633,3.8972485,390.73688,-9.2615404
4749,4749,179.2064,9.4246054,5.9304104,0.0,0,3.8777139,0.0,0.50320917,72.527695,3.8782718,390.44647,-9.2617903
4760,4760,179.2086,9.4593048,5.9460611,0.0,0,3.8571923,0.0,0.50453919,72.690613,3.8575425,390.45313,-9.2616949
4771,4771,179.2108,9.5199671,5.9642091,0.0,0,3.8366706,0.0,0.50694871,73.02771,3.8382366,390.45978,-9.2611513
4782,4782,179.213,9.5924616,5.9835286,0.0,0,3.816149,0.0,0.50872946,73.389221,3.8186002,390.46643,-9.2609463
4793,4793,179.2152,9.6210585,6.0094028,0.0,0,3.7956276,0.0,0.51213878,73.438576,3.799644,390.47308,-9.2595215
4804,4804,179.2174,9.6683083,6.0283389,0.0,0,3.775106,0.0,0.51357877,73.667648,3.7811942,390.64532,-9.2611208
4815,4815,179.2196,9.7017975,6.0478334,0.0,0,3.7545841,0.0,0.51640373,73.67572,3.7599938,390.8714,-9.2615585
4826,4826,179.2218,9.7198429,6.0684562,0.0,0,3.7340627,0.0,0.51820296,73.695801,3.7370193,391.09747,-9.2612009
4837,4837,179.224,9.752655,6.0940857,0.0,0,3.713541,0.0,0.52157938,73.737579,3.7166014,391.32352,-9.2616825
4848,4848,179.2262,9.7723818,6.1141138,0.0,0,3.6930194,0.0,0.52316499,73.756294,3.6980276,391.51477,-9.2615929
4859,4859,179.2284,9.8139744,6.1330528,0.0,0,3.672498,0.0,0.52600121,73.768661,3.6728981,391.58127,-9.2610598
4870,4870,179.2306,9.8561897,6.1541624,0.0,0,3.6519761,0.0,0.52770805,73.971703,3.6511328,391.64777,-9.2613478
4881,4881,179.2328,9.8752699,6.1765776,0.0,0,3.6314545,0.0,0.53104579,73.973343,3.6322491,391.71426,-9.2626886
4892,4892,179.235,9.8644142,6.1982384,0.0,0,3.6109331,0.0,0.53264701,73.708046,3.6139371,391.78076,-9.2623167
4903,4903,179.2372,9.8789949,6.214076,0.0,0,3.5904114,0.0,0.53517759,73.61483,3.5941367,391.49814,-9.2607603
4914,4914,179.2394,9.9022312,6.2338667,0.0,0,3.5703723,0.0,0.53661549,73.73027,3.5724494,391.05264,-9.2594881
4925,4925,179.2416,9.9552393,6.2556562,0.0,0,3.5508497,0.0,0.54012603,73.884285,3.5528135,390.60715,-9.2600412
4936,4936,179.2438,9.9997635,6.2761307,0.0,0,3.5313265,0.0,0.54152077,74.106842,3.5322344,390.16165,-9.2613878
4947,4947,179.246,10.04227,6.2937436,0.0,0,3.5118039,0.0,0.54446268,74.214386,3.5099518,389.73743,-9.262023
4958,4958,179.2482,10.085359,6.3186946,0.0,0,3.492281,0.0,0.54630309,74.309158,3.4921029,389.4382,-9.2617159
4969,4969,179.2504,10.112673,6.3371434,0.0,0,3.4727583,0.0,0.54948074,74.265961,3.4683406,389.13898,-9.2620115
4980,4980,179.2526,10.135621,6.3614788,0.0,0,3.4532356,0.0,0.55119264,74.33371,3.4488683,388.83975,-9.2620707
4991,4991,179.2548,10.123985,6.3767619,0.0,0,3.4337125,0.0,0.55400497,74.063881,3.4274907,388.54056,-9.2619505
5002,5002,179.257,10.134024,6.3954644,0.0,0,3.4141898,0.0,0.55521762,74.039528,3.4117153,388.5856,-9.2607946
5013,5013,179.2592,10.131488,6.412652,0.0,0,3.3946671,0.0,0.55833077,73.810661,3.3945315,388.85156,-9.2618408
5024,5024,179.2614,10.163537,6.4380589,0.0,0,3.375144,0.0,0.56009686,73.885513,3.376236,389.11752,-9.2622042
5035,5035,179.2636,10.190691,6.4499559,0.0,0,3.3556216,0.0,0.56270468,73.946945,3.3565168,389.38351,-9.2610931
5046,5046,179.2658,10.240527,6.4728279,0.0,0,3.3360984,0.0,0.564255,74.128235,3.3380158,389.6456,-9.2605324
5057,5057,179.268,10.276624,6.4890804,0.0,0,3.316576,0.0,0.5671913,74.185707,3.3170247,389.8584,-9.2605019
5068,5068,179.2702,10.33897,6.5140076,0.0,0,3.2970531,0.0,0.56886232,74.557358,3.3012638,390.07117,-9.2613115
5079,5079,179.2724,10.384605,6.5273466,0.0,0,3.27753,0.0,0.57175791,74.712021,3.2794414,390.28397,-9.2618742
5090,5090,179.2746,10.42921,6.5511594,0.0,0,3.2580075,0.0,0.57345271,74.83699,3.2601242,390.49673,-9.2610903
5101,5101,179.2768,10.456686,6.5678334,0.0,0,3.2384844,0.0,0.57653016,74.812218,3.2403779,390.64175,-9.2612648
5112,5112,179.279,10.492948,6.5945621,0.0,0,3.218962,0.0,0.57836062,74.950073,3.2226212,390.72818,-9.2620068
5123,5123,179.2812,10.526715,6.6067576,0.0,0,3.199439,0.0,0.5811516,74.897476,3.2007647,390.81464,-9.26157
5134,5134,179.2834,10.563854,6.6314478,0.0,0,3.1799161,0.0,0.58304226,75.055809,3.178899,390.90106,-9.2613354
5145,5145,179.2856,10.603341,6.6502566,0.0,0,3.1603935,0.0,0.58636796,75.106689,3.1608965,390.98749,-9.259367
5156,5156,179.2878,10.651736,6.6755605,0.0,0,3.1408706,0.0,0.58792096,75.353714,3.1376975,391.1026,-9.2605324
5167,5167,179.29,10.684852,6.6863871,0.0,0,3.122066,0.0,0.59063137,75.351845,3.1231854,391.21771,-9.260726
5178,5178,179.2922,10.688578,6.7110753,0.0,0,3.1034935,0.0,0.59267676,75.300323,3.1019585,391.33282,-9.2607737
5189,5189,179.2944,10.68568,6.7292914,0.0,0,3.0849211,0.0,0.59607834,74.955727,3.085711,391.44794,-9.2614365
5200,5200,179.2966,10.704041,6.7549577,0.0,0,3.0663486,0.0,0.59756607,74.992737,3.0643735,391.50027,-9.2610054
5211,5211,179.2988,10.728208,6.7635074,0.0,0,3.0477762,0.0,0.60007918,74.973755,3.0448387,391.50027,-9.260479
5222,5222,179.301,10.728942,6.7874565,0.0,0,3.0292039,0.0,0.60190606,74.827209,3.0275276,391.50027,-9.2595997
5233,5233,179.3032,10.783134,6.8027916,0.0,0,3.0106313,0.0,0.60491621,74.98703,3.0101719,391.50027,-9.2605381
5244,5244,179.3054,10.821033,6.8300347,0.0,0,2.9920592,0.0,0.60679847,75.093544,2.9914727,391.50052,-9.261281
5255,5255,179.3076,10.893061,6.83922,0.0,0,2.9734867,0.0,0.60918373,75.40744,2.9715791,391.5271,-9.2610159
5266,5266,179.3098,10.940275,6.8605409,0.0,0,2.9549143,0.0,0.61082458,75.591438,2.9487607,391.55371,-9.2616615
5277,5277,179.312,10.954097,6.8768249,0.0,0,2.9363418,0.0,0.61394984,75.488853,2.9335592,391.58029,-9.2622023
5288,5288,179.3142,10.966561,6.9060278,0.0,0,2.9177694,0.0,0.61621708,75.395638,2.9157991,391.6069,-9.2615671
5299,5299,179.3164,10.995484,6.9167948,0.0,0,2.8991969,0.0,0.61875224,75.425468,2.8957253,391.66492,-9.2601271
5310,5310,179.3186,11.032029,6.9410291,0.0,0,2.8806245,0.0,0.62085956,75.473816,2.8751836,391.758,-9.2607298
5321,5321,179.3208,11.068524,6.952703,0.0,0,2.8620524,0.0,0.62330091,75.515518,2.857111,391.8511,-9.2611723
5332,5332,179.323,11.111104,6.9803562,0.0,0,2.8434799,0.0,0.62546992,75.639442,2.8411715,391.94418,-9.2614241
5343,5343,179.3252,11.137429,6.9889832,0.0,0,2.8249075,0.0,0.62768179,75.690109,2.8177426,392.03729,-9.2607708
5354,5354,179.3274,11.179058,7.0126381,0.0,0,2.806335,0.0,0.62978852,75.757156,2.8010023,392.05566,-9.2607107
5365,5365,179.3296,11.186307,7.0254292,0.0,0,2.7877626,0.0,0.63232225,75.68531,2.7864377,392.06897,-9.2602863
5376,5376,179.3318,11.221112,7.0538721,0.0,0,2.7691901,0.0,0.63486332,75.761673,2.7679746,392.08228,-9.2607222
5387,5387,179.334,11.247321,7.0642819,0.0,0,2.7506177,0.0,0.63705498,75.761604,2.7467096,392.09558,-9.2613258
5398,5398,179.3362,11.296471,7.0875206,0.0,0,2.7320457,0.0,0.63925564,75.882416,2.7295659,392.09824,-9.2617178
5409,5409,179.3384,11.341915,7.1002831,0.0,0,2.7135069,0.0,0.64166671,76.006554,2.7118657,392.08493,-9.2614288
5420,5420,179.3406,11.385372,7.1280093,0.0,0,2.695833,0.0,0.64422041,76.151031,2.6900651,392.07162,-9.261117
5431,5431,179.3428,11.445408,7.1374707,0.0,0,2.6781669,0.0,0.64627713,76.335052,2.6710708,392.05832,-9.2605143
5442,5442,179.345,11.483512,7.1614537,0.0,0,2.660501,0.0,0.64864433,76.470245,2.6541319,392.04501,-9.2595377
5453,5453,179.3472,11.494266,7.1757307,0.0,0,2.6428349,0.0,0.65101922,76.312698,2.6377521,392.00876,-9.2605791
5464,5464,179.3494,11.492938,7.2022014,0.0,0,2.625169,0.0,0.6537692,76.177528,2.6226125,391.96887,-9.2604313
5475,5475,179.3516,11.496878,7.2115297,0.0,0,2.6075029,0.0,0.65567213,76.021851,2.603904,391.92899,-9.2608566
5486,5486,179.3538,11.515564,7.2350607,0.0,0,2.5898371,0.0,0.65820777,75.922569,2.5850947,391.88907,-9.2627506
5497,5497,179.356,11.552985,7.2452674,0.0,0,2.572171,0.0,0.6599257,76.005531,2.5703743,391.84482,-9.2619362
5508,5508,179.3582,11.603286,7.2691827,0.0,0,2.5545051,0.0,0.66255647,76.161491,2.5543141,391.79163,-9.2615643
5519,5519,179.3604,11.66788,7.2825685,0.0,0,2.536839,0.0,0.66465682,76.323914,2.5372536,391.73843,-9.26087
5530,5530,179.3626,11.729868,7.306138,0.0,0,2.5191729,0.0,0.66748244,76.525002,2.5159943,391.68524,-9.2601004
5541,5541,179.3648,11.755262,7.3204107,0.0,0,2.501507,0.0,0.66941255,76.618874,2.4955356,391.63205,-9.2600336
5552,5552,179.367,11.809466,7.3433366,0.0,0,2.4838409,0.0,0.67218304,76.747742,2.4815583,391.57886,-9.2599363
5563,5563,179.3692,11.83499,7.3562493,0.0,0,2.4661748,0.0,0.67415965,76.793694,2.4592464,391.52567,-9.2600584
5574,5574,179.3714,11.85827,7.3772774,0.0,0,2.448509,0.0,0.67692029,76.765244,2.4414175,391.47247,-9.2609529
5585,5585,179.3736,11.875555,7.3913293,0.0,0,2.4308429,0.0,0.6787371,76.693794,2.424185,391.41928,-9.2617674
5596,5596,179.3758,11.91822,7.4166818,0.0,0,2.413177,0.0,0.6819787,76.708054,2.4072642,391.34241,-9.2615767
5607,5607,179.378,11.961637,7.4272141,0.0,0,2.3955109,0.0,0.68334979,76.881485,2.3891916,391.19611,-9.2613745
5618,5618,179.3802,11.974846,7.4463277,0.0,0,2.377845,0.0,0.6862126,76.788055,2.3706534,391.04984,-9.2603989
5629,5629,179.3824,11.999195,7.4613476,0.0,0,2.3601789,0.0,0.68784297,76.803627,2.3545516,390.90353,-9.2614641
5640,5640,179.3846,12.031631,7.4839125,0.0,0,2.3425131,0.0,0.69117188,76.774673,2.3380201,390.75726,-9.2612314
5651,5651,179.3868,12.053988,7.4963517,0.0,0,2.324847,0.0,0.6924054,76.793922,2.3182342,390.52979,-9.2606707
5662,5662,179.389,12.066874,7.5149889,0.0,0,2.3074405,0.0,0.6952424,76.683647,2.3054073,390.27048,-9.260313
5673,5673,179.3912,12.113927,7.5288072,0.0,0,2.2906368,0.0,0.69677949,76.864922,2.290215,390.01117,-9.2608299
5684,5684,179.3934,12.176126,7.5514493,0.0,0,2.2738333,0.0,0.70019984,76.955605,2.2714252,389.75183,-9.2619581
5695,5695,179.3956,12.256348,7.5654745,0.0,0,2.2570295,0.0,0.70160246,77.312065,2.2524917,389.45142,-9.2611485
5706,5706,179.3978,12.314166,7.5819564,0.0,0,2.240226,0.0,0.70433939,77.507057,2.2377191,388.966,-9.2607813
5717,5717,179.4,12.355062,7.6010003,0.0,0,2.2234225,0.0,0.70643365,77.589737,2.2162342,388.48062,-9.2609596
5728,5728,179.4022,12.386592,7.6216826,0.0,0,2.206619,0.0,0.70984548,77.509438,2.1998224,387.99521,-9.2619543
5739,5739,179.4044,12.375894,7.6367698,0.0,0,2.1898153,0.0,0.71115577,77.38134,2.1826122,387.5098,-9.2617197
5750,5750,179.4066,12.351121,7.654665,0.0,0,2.1730118,0.0,0.71431005,77.010109,2.1653321,387.21326,-9.2620459
5761,5761,179.4088,12.354073,7.6683035,0.0,0,2.156208,0.0,0.71548957,76.91732,2.1502862,387.02042,-9.2613716
5772,5772,179.411,12.408247,7.6851282,0.0,0,2.1394045,0.0,0.71866888,77.017014,2.1334417,386.82758,-9.2595387
5783,5783,179.4132,12.461507,7.7041125,0.0,0,2.1226008,0.0,0.72008055,77.232239,2.1163106,386.63474,-9.2602558
5794,5794,179.4154,12.518703,7.7171588,0.0,0,2.1057973,0.0,0.72296244,77.290901,2.1014624,386.48471,-9.2612696
5805,5805,179.4176,12.57544,7.7347918,0.0,0,2.0889935,0.0,0.72434354,77.607803,2.0875702,386.6842,-9.2618818
5816,5816,179.4198,12.624148,7.7551699,0.0,0,2.0721903,0.0,0.7282654,77.605171,2.068135,386.88367,-9.2615633
5827,5827,179.422,12.661993,7.7712245,0.0,0,2.0553865,0.0,0.72942144,77.722481,2.0507486,387.08316,-9.2621422
5838,5838,179.4242,12.708731,7.7841268,0.0,0,2.038583,0.0,0.73208964,77.840744,2.0342493,387.28262,-9.2610531
5849,5849,179.4264,12.746131,7.8027029,0.0,0,2.0217793,0.0,0.73370814,77.941391,2.0212877,387.39832,-9.2612677
5860,5860,179.4286,12.772346,7.8212614,0.0,0,2.0049758,0.0,0.73753476,77.77179,2.0039418,387.45154,-9.260767
5871,5871,179.4308,12.841975,7.8419189,0.0,0,1.9881722,0.0,0.73899692,78.092117,1.9848096,387.50473,-9.2606707
5882,5882,179.433,12.927739,7.8556004,0.0,0,1.9713686,0.0,0.74230915,78.331245,1.9670866,387.55792,-9.2618923
5893,5893,179.4352,12.962794,7.8756571,0.0,0,1.954565,0.0,0.74394029,78.478004,1.9504691,387.60364,-9.2617025
5904,5904,179.4374,13.007406,7.8913517,0.0,0,1.9377614,0.0,0.74743724,78.408455,1.9328282,387.45068,-9.2609415
5915,5915,179.4396,13.021179,7.9122496,0.0,0,1.9214275,0.0,0.7489531,78.413742,1.9127945,387.29776,-9.2606831
5926,5926,179.4418,13.074403,7.9262176,0.0,0,1.9054422,0.0,0.75229138,78.464355,1.8946184,387.14481,-9.2600498
5937,5937,179.444,13.10481,7.9457474,0.0,0,1.889457,0.0,0.75359106,78.551704,1.8801038,386.99188,-9.2597132
5948,5948,179.4462,13.126801,7.9604578,0.0,0,1.8734717,0.0,0.75716597,78.385201,1.8654503,386.76581,-9.2599192
5959,5959,179.4484,13.134896,7.9825535,0.0,0,1.8574866,0.0,0.75871593,78.280029,1.8476593,386.46658,-9.2607613
5970,5970,179.4506,13.138647,7.9919777,0.0,0,1.8415015,0.0,0.76180065,78.046379,1.8292091,386.16736,-9.2615337
5981,5981,179.4528,13.130116,8.012228,0.0,0,1.8255162,0.0,0.76320946,77.922821,1.8182937,385.86813,-9.2616501
5992,5992,179.455,13.156707,8.0238171,0.0,0,1.8095311,0.0,0.76651943,77.849518,1.8024521,385.56894,-9.2614927
6003,6003,179.4572,13.181681,8.0454884,0.0,0,1.7935458,0.0,0.76764113,77.877136,1.7829905,385.47476,-9.2608156
6014,6014,179.4594,13.192253,8.0519571,0.0,0,1.7775607,0.0,0.7704457,77.710419,1.7669805,385.38834,-9.2615814
6025,6025,179.4616,13.234975,8.0716534,0.0,0,1.7615755,0.0,0.77162147,77.953491,1.7580506,385.30188,-9.2615662
6036,6036,179.4638,13.271768,8.082592,0.0,0,1.7455902,0.0,0.77479082,77.841835,1.7418357,385.21545,-9.2619476
6047,6047,179.466,13.316892,8.1039791,0.0,0,1.729605,0.0,0.7761091,78.014282,1.7257001,385.24835,-9.260767
6058,6058,179.4682,13.39383,8.1123409,0.0,0,1.7136198,0.0,0.77912688,78.231728,1.7073483,385.44116,-9.2607231
6069,6069,179.4704,13.475227,8.1334143,0.0,0,1.6976346,0.0,0.78057039,78.618713,1.6957216,385.634,-9.2615499
6080,6080,179.4726,13.560414,8.1460657,0.0,0,1.6816494,0.0,0.7840634,78.815254,1.6783617,385.82681,-9.2614517
6091,6091,179.4748,13.606792,8.1720142,0.0,0,1.6656642,0.0,0.78585184,78.963219,1.6602108,386.01965,-9.2615852
6102,6102,179.477,13.679992,8.1783791,0.0,0,1.6496789,0.0,0.78876299,79.162598,1.6432232,385.74448,-9.2610111
6113,6113,179.4792,13.718241,8.202116,0.0,0,1.6336937,0.0,0.79071307,79.262321,1.627143,385.41202,-9.2596092
6124,6124,179.4814,13.744684,8.2153921,0.0,0,1.6177086,0.0,0.79419398,79.096291,1.6084957,385.07956,-9.2604618
6135,6135,179.4836,13.755909,8.2396755,0.0,0,1.6017234,0.0,0.7958045,79.035423,1.5919681,384.7471,-9.2608843
6146,6146,179.4858,13.792381,8.2447844,0.0,0,1.5857382,0.0,0.79856116,78.995193,1.5753226,384.44998,-9.26266
6157,6157,179.488,13.824714,8.2700386,0.0,0,1.5697531,0.0,0.80089813,78.968559,1.5588373,384.21725,-9.2610579
6168,6168,179.4902,13.890683,8.2787657,0.0,0,1.5544271,0.0,0.80367279,79.127892,1.5442806,383.98453,-9.2607841
6179,6179,179.4924,13.902573,8.3059292,0.0,0,1.5392207,0.0,0.80568743,79.04509,1.5257577,383.75183,-9.2615576
6190,6190,179.4946,13.910456,8.3096752,0.0,0,1.5240144,0.0,0.80805522,78.926109,1.5138896,383.5191,-9.2621555
6201,6201,179.4968,13.903907,8.3302917,0.0,0,1.5088079,0.0,0.80976504,78.792191,1.5008307,383.84128,-9.2623596
6212,6212,179.499,13.917414,8.3373165,0.0,0,1.4936016,0.0,0.8123678,78.656525,1.4840248,384.28677,-9.2616339
6223,6223,179.5012,13.947402,8.3634396,0.0,0,1.478395,0.0,0.81446487,78.646469,1.4683648,384.73227,-9.2588062
6234,6234,179.5034,13.982836,8.370163,0.0,0,1.4631886,0.0,0.81712735,78.622414,1.456905,385.1778,-9.2601109
6245,6245,179.5056,14.03553,8.3894224,0.0,0,1.4479822,0.0,0.8186897,78.788651,1.4441148,385.54272,-9.2604084
6256,6256,179.5078,14.134771,8.3975096,0.0,0,1.4327759,0.0,0.82128346,79.12439,1.4277973,385.7023,-9.2608862
6267,6267,179.51,14.22722,8.4237213,0.0,0,1.4175695,0.0,0.82376957,79.465942,1.4097157,385.86188,-9.2596979
6278,6278,179.5122,14.296283,8.4303741,0.0,0,1.4023631,0.0,0.82625872,79.654396,1.3937985,386.02148,-9.2607784
6289,6289,179.5144,14.325814,8.4549646,0.0,0,1.3871567,0.0,0.82859606,79.653015,1.3796339,386.18106,-9.2605639
6300,6300,179.5166,14.343351,8.4628983,0.0,0,1.3719503,0.0,0.83125156,79.587837,1.3622403,385.94907,-9.26015
6311,6311,179.5188,14.37023,8.4871197,0.0,0,1.3567439,0.0,0.83359587,79.538918,1.3497777,385.58334,-9.2607965
6322,6322,179.521,14.385939,8.4938536,0.0,0,1.3415375,0.0,0.83588588,79.414192,1.3333017,385.21765,-9.2608538
6333,6333,179.5232,14.412592,8.5154104,0.0,0,1.3263311,0.0,0.83817387,79.377014,1.3143069,384.85193,-9.2609921
6344,6344,179.5254,14.452371,8.5244074,0.0,0,1.3111248,0.0,0.84058917,79.358688,1.3024896,384.44168,-9.2598438
6355,6355,179.5276,14.498337,8.5488977,0.0,0,1.2959183,0.0,0.84320962,79.426208,1.2875283,383.86295,-9.2593508
6366,6366,179.5298,14.528103,8.5515652,0.0,0,1.2807119,0.0,0.84455663,79.464798,1.2722108,383.28421,-9.2599525
6377,6377,179.532,14.545218,8.5719166,0.0,0,1.2655054,0.0,0.8469736,79.397774,1.260506,382.70547,-9.260726
6388,6388,179.5342,14.572602,8.5815125,0.0,0,1.2502991,0.0,0.84918761,79.384171,1.2455244,382.12674,-9.2607021
6399,6399,179.5364,14.64045,8.6054163,0.0,0,1.2350928,0.0,0.8520118,79.495491,1.2301301,381.81653,-9.2614689
6410,6410,179.5386,14.699396,8.6123781,0.0,0,1.2199754,0.0,0.85402012,79.69207,1.2166742,381.63696,-9.2612095
6421,6421,179.5408,14.780204,8.6332474,0.0,0,1.2055123,0.0,0.85661221,79.899017,1.1995537,381.45737,-9.2616348
6432,6432,179.543,14.866551,8.6435127,0.0,0,1.1910495,0.0,0.85882229,80.18589,1.185733,381.27777,-9.2607307
6443,6443,179.5452,14.928984,8.6692028,0.0,0,1.1765865,0.0,0.86221129,80.252632,1.1648409,381.01999,-9.2608852
6454,6454,179.5474,14.977839,8.6767864,0.0,0,1.1621238,0.0,0.86393523,80.332153,1.1480839,380.26694,-9.2607174
6465,6465,179.5496,15.022738,8.6948528,0.0,0,1.1476611,0.0,0.86655205,80.398659,1.1335874,379.51385,-9.2621088
6476,6476,179.5518,15.00923,8.7056541,0.0,0,1.1331981,0.0,0.86837327,80.185799,1.1187773,378.76077,-9.2609549
6487,6487,179.554,14.970384,8.7272949,0.0,0,1.1187353,0.0,0.87148947,79.756653,1.107527,378.00772,-9.2620487
6498,6498,179.5562,14.991499,8.7346277,0.0,0,1.1042726,0.0,0.8729471,79.670113,1.0919755,377.30261,-9.2612734
6509,6509,179.5584,15.013954,8.7482119,0.0,0,1.0898098,0.0,0.87530416,79.676872,1.0786852,376.62952,-9.2606525
6520,6520,179.5606,15.039352,8.7563248,0.0,0,1.0753471,0.0,0.87658399,79.719872,1.0652264,375.95642,-9.2622747
6531,6531,179.5628,15.05914,8.7783241,0.0,0,1.0608841,0.0,0.87994772,79.503769,1.0519962,375.28333,-9.2613068
6542,6542,179.565,15.109524,8.7860708,0.0,0,1.0464214,0.0,0.88118356,79.692665,1.0383028,374.67807,-9.2614498
6553,6553,179.5672,15.197545,8.7997637,0.0,0,1.0319586,0.0,0.88360375,79.958183,1.0274909,375.07126,-9.2613258
6564,6564,179.5694,15.276624,8.8118372,0.0,0,1.0174959,0.0,0.88520986,80.278419,1.0118953,375.46445,-9.2594719
6575,6575,179.5716,15.34984,8.8327904,0.0,0,1.0030329,0.0,0.88882887,80.348793,0.99751812,375.85764,-9.2599001
6586,6586,179.5738,15.372684,8.8436766,0.0,0,0.98857021,0.0,0.89024734,80.384102,0.98451161,376.25082,-9.2612419
6597,6597,179.576,15.3957,8.8565779,0.0,0,0.97410738,0.0,0.89283198,80.270378,0.96878934,376.59485,-9.2617645
6608,6608,179.5782,15.444119,8.8695135,0.0,0,0.95964456,0.0,0.89452249,80.344482,0.95598191,376.89474,-9.2600851
6619,6619,179.5804,15.505711,8.8881369,0.0,0,0.94518179,0.0,0.89822012,80.415367,0.93937886,377.19464,-9.259428
6630,6630,179.5826,15.600352,8.9013338,0.0,0,0.93071902,0.0,0.89961052,80.753143,0.9231993,377.49454,-9.2596817
6641,6641,179.5848,15.684937,8.9166517,0.0,0,0.91625619,0.0,0.90275431,80.940887,0.91116065,377.79446,-9.2603779
6652,6652,179.587,15.764761,8.9277716,0.0,0,0.90179336,0.0,0.90396267,81.268959,0.89885122,378.0217,-9.2613258
6663,6663,179.5892,15.853513,8.9480724,0.0,0,0.88760829,0.0,0.90808862,81.400658,0.88296098,378.24829,-9.2609234
6674,6674,179.5914,15.924964,8.9639139,0.0,0,0.87385386,0.0,0.90962261,81.631699,0.86474973,378.47485,-9.2611609
6685,6685,179.5936,15.971032,8.9765415,0.0,0,0.86009949,0.0,0.91286862,81.594879,0.84773397,378.70145,-9.2607298
6696,6696,179.5958,15.978773,8.9902086,0.0,0,0.84634507,0.0,0.91412729,81.57592,0.83410925,378.9129,-9.2606831
6707,6707,179.598,15.983719,9.0092354,0.0,0,0.83259064,0.0,0.91831952,81.212105,0.82297629,379.10617,-9.2595835
6718,6718,179.6002,15.984095,9.0224018,0.0,0,0.81883627,0.0,0.91940081,81.128082,0.80759293,379.29944,-9.2605314
6729,6729,179.6024,16.013834,9.0353336,0.0,0,0.8050819,0.0,0.9228785,80.998001,0.79056561,379.49271,-9.2607069
6740,6740,179.6046,16.027061,9.0489321,0.0,0,0.79132748,0.0,0.92364675,81.016258,0.77978188,379.68597,-9.2613134
6751,6751,179.6068,16.050671,9.0630894,0.0,0,0.77757305,0.0,0.92746568,80.827568,0.76618892,379.78134,-9.2605925
6762,6762,179.609,16.067291,9.077384,0.0,0,0.76381862,0.0,0.92842668,80.853226,0.75193673,379.86795,-9.2601271
6773,6773,179.6112,16.08493,9.0866861,0.0,0,0.75006431,0.0,0.93143332,80.683197,0.73679817,379.95459,-9.2612858
6784,6784,179.6134,16.101681,9.1029835,0.0,0,0.73630983,0.0,0.93273443,80.69091,0.72852457,380.04123,-9.2602901
6795,6795,179.6156,16.169086,9.1134186,0.0,0,0.72255546,0.0,0.9362067,80.678658,0.71470624,380.07443,-9.2602024
6806,6806,179.6178,16.274946,9.1281052,0.0,0,0.70880103,0.0,0.9368434,81.174728,0.70244116,380.02112,-9.2615414
6817,6817,179.62,16.359674,9.1358366,0.0,0,0.69504666,0.0,0.93996662,81.369713,0.68976718,379.96777,-9.2622519
6828,6828,179.6222,16.446003,9.1518574,0.0,0,0.6812923,0.0,0.94107074,81.689087,0.67300391,379.91446,-9.2616358
6839,6839,179.6244,16.510853,9.1666098,0.0,0,0.66753787,0.0,0.94531626,81.683311,0.6587615,379.86115,-9.2604818
6850,6850,179.6266,16.575686,9.1880026,0.0,0,0.6537835,0.0,0.94715506,81.854362,0.64111269,379.50922,-9.2598381
6861,6861,179.6288,16.609629,9.193758,0.0,0,0.64002907,0.0,0.94995213,81.788177,0.63209146,379.10269,-9.2605629
6872,6872,179.631,16.638803,9.209177,0.0,0,0.6262747,0.0,0.95086217,81.857178,0.6153577,378.69617,-9.2608833
6883,6883,179.6332,16.672489,9.2226963,0.0,0,0.61252028,0.0,0.95514756,81.63797,0.60257894,378.28967,-9.2613316
6894,6894,179.6354,16.709454,9.2430611,0.0,0,0.59876591,0.0,0.95646471,81.743126,0.5855338,377.93051,-9.2607603
6905,6905,179.6376,16.757483,9.2457581,0.0,0,0.58501148,0.0,0.9593218,81.755432,0.5751946,377.67728,-9.2615557
6916,6916,179.6398,16.76227,9.2658691,0.0,0,0.57169878,0.0,0.96058965,81.667801,0.56056505,377.42404,-9.2604198
6927,6927,179.642,16.81431,9.2739801,0.0,0,0.55860871,0.0,0.96412337,81.618851,0.54750907,377.17078,-9.2606125
6936,6936,179.6438,16.816582,9.2819719,0.0,0,0.54789877,0.0,0.96532285,81.570396,0.53966618,376.96359,-9.2614689