File: clean data/testID_0151.csv
level_0,index,Time(sec),Force(kN),Jaw(mm),PowAngle(deg),Power(W),Pram,PTemp,Strain,Stress(MPa),Stroke(mm),TC1(C),wedge(mm)
2250,2250,178.706,0.82937688,0.021168076,0.0,0,9.9578638,0.0,0.0013554476,10.304692,10.060843,399.84454,-9.2643452
2261,2261,178.7082,2.1044183,0.032285336,0.0,0,9.9248638,0.0,0.0022029567,26.503931,10.030263,400.27582,-9.2631397
2272,2272,178.7104,3.5319469,0.040583264,0.0,0,9.8918638,0.0,0.0026210432,44.565826,9.9996386,400.70712,-9.2616053
2283,2283,178.7126,4.5030875,0.06373325,0.0,0,9.8588629,0.0,0.0043501309,57.047306,9.9699345,401.1384,-9.2606096
2294,2294,178.7148,4.8959546,0.09837079,0.0,0,9.8258638,0.0,0.0064747417,61.912815,9.9300623,401.5697,-9.259469
2305,2305,178.717,5.1575227,0.13708229,0.0,0,9.7928638,0.0,0.0091630379,65.050171,9.887454,402.09122,-9.2615414
2316,2316,178.7192,5.3546391,0.17323548,0.0,0,9.7598639,0.0,0.011446872,67.411896,9.8477602,402.63531,-9.2594614
2327,2327,178.7214,5.4743619,0.21206486,0.0,0,9.7268629,0.0,0.014295228,68.727699,9.8105459,403.17941,-9.2595243
2338,2338,178.7236,5.5614271,0.24559137,0.0,0,9.6938639,0.0,0.016341291,69.585449,9.7764225,403.72351,-9.259347
2349,2349,178.7258,5.6446772,0.27657786,0.0,0,9.6608629,0.0,0.018687548,70.550064,9.7417183,404.11893,-9.2608566
2360,2360,178.728,5.703196,0.30857185,0.0,0,9.6278639,0.0,0.020595932,71.084892,9.7102985,404.09903,-9.2593222
2371,2371,178.7302,5.7472196,0.3404552,0.0,0,9.5948629,0.0,0.023049064,71.500603,9.6763849,404.0791,-9.2600546
2382,2382,178.7324,5.7693229,0.37205461,0.0,0,9.5618639,0.0,0.024888296,71.640594,9.6444349,404.0592,-9.2597017
2393,2393,178.7346,5.8059549,0.40205452,0.0,0,9.5288639,0.0,0.027284592,71.949181,9.6140385,404.03931,-9.259346
2404,2404,178.7368,5.840662,0.43283972,0.0,0,9.4958639,0.0,0.029072328,72.239517,9.5832767,403.93253,-9.259903
2415,2415,178.739,5.8869224,0.46552563,0.0,0,9.4633293,0.0,0.031706508,72.501343,9.5498505,403.79318,-9.2600555
2426,2426,178.7412,5.9387107,0.49965441,0.0,0,9.431138,0.0,0.033620041,73.026077,9.5109816,403.65384,-9.2603331
2437,2437,178.7434,5.99367,0.53066808,0.0,0,9.3989477,0.0,0.036170717,73.503387,9.4750481,403.5145,-9.2612419
2448,2448,178.7456,6.0254555,0.5645588,0.0,0,9.3667564,0.0,0.038146272,73.848343,9.4432449,403.53476,-9.261569
2459,2459,178.7478,6.0486693,0.59802234,0.0,0,9.3345671,0.0,0.040905386,73.891792,9.4101801,404.23148,-9.261384
2470,2470,178.75,6.0443854,0.63511169,0.0,0,9.3023767,0.0,0.042990781,73.769783,9.3759079,404.92819,-9.2601376
2481,2481,178.7522,6.0602841,0.66143394,0.0,0,9.2701855,0.0,0.045285825,73.768555,9.3432884,405.62491,-9.2596893
2492,2492,178.7544,6.0712175,0.6936422,0.0,0,9.2379951,0.0,0.047147453,73.71093,9.3111506,406.32159,-9.2602987
2503,2503,178.7566,6.0944796,0.72366178,0.0,0,9.2058048,0.0,0.0497168,73.833321,9.279952,407.14426,-9.2607279
2514,2514,178.7588,6.1053681,0.7613017,0.0,0,9.1736145,0.0,0.051739246,73.814888,9.243885,408.03339,-9.2607479
2525,2525,178.761,6.139647,0.78788054,0.0,0,9.1414251,0.0,0.054181572,73.898949,9.2143002,408.92252,-9.2621832
2536,2536,178.7632,6.1754389,0.82236183,0.0,0,9.1092339,0.0,0.056136556,74.356529,9.1814547,409.81165,-9.2615337
2547,2547,178.7654,6.2151046,0.85270387,0.0,0,9.0770426,0.0,0.058796443,74.59436,9.1493168,410.63492,-9.2612371
2558,2558,178.7676,6.2314973,0.88911408,0.0,0,9.0448523,0.0,0.060732834,74.594864,9.1174746,410.96664,-9.2617416
2569,2569,178.7698,6.2460327,0.91781533,0.0,0,9.0126629,0.0,0.063314311,74.708023,9.0811052,411.2984,-9.2608967
2580,2580,178.772,6.2482572,0.95136696,0.0,0,8.9804716,0.0,0.065288708,74.558365,9.0477085,411.63016,-9.2599182
2591,2591,178.7742,6.2729588,0.98156983,0.0,0,8.9482822,0.0,0.067917757,74.646347,9.0157442,411.96188,-9.2612753
2602,2602,178.7764,6.2839394,1.0198122,0.0,0,8.916091,0.0,0.070044369,74.564392,8.9844389,412.12378,-9.2620745
2613,2613,178.7786,6.2905836,1.0463791,0.0,0,8.8839006,0.0,0.072523236,74.478424,8.9500141,412.1636,-9.2622576
2624,2624,178.7808,6.3359547,1.0785751,0.0,0,8.8517103,0.0,0.074383624,74.795616,8.9172182,412.2034,-9.2610226
2635,2635,178.783,6.3711996,1.107883,0.0,0,8.819521,0.0,0.076952949,75.061241,8.8874264,412.24323,-9.2608089
2646,2646,178.7852,6.3890047,1.1463639,0.0,0,8.7873297,0.0,0.079085179,75.134567,8.8503771,412.26733,-9.2615976
2657,2657,178.7874,6.3821859,1.1713936,0.0,0,8.7551394,0.0,0.081514187,74.963966,8.8212233,411.96216,-9.2617664
2668,2668,178.7896,6.3920279,1.2056764,0.0,0,8.7242823,0.0,0.083587028,74.824257,8.7876606,411.65695,-9.2620258
2679,2679,178.7918,6.398253,1.234983,0.0,0,8.6936674,0.0,0.086121656,74.761368,8.7582283,411.35175,-9.2617617
2690,2690,178.794,6.4099035,1.2720566,0.0,0,8.6630526,0.0,0.088229202,74.676369,8.7240238,411.04654,-9.2617235
2701,2701,178.7962,6.4398727,1.2952379,0.0,0,8.6324368,0.0,0.090505168,74.844772,8.691761,410.70081,-9.2614899
2712,2712,178.7984,6.4593353,1.3290069,0.0,0,8.6018219,0.0,0.092588283,74.937576,8.6650982,410.31595,-9.262043
2723,2723,178.8006,6.4969554,1.357481,0.0,0,8.5712061,0.0,0.095147185,75.251602,8.63169,409.93109,-9.2616434
2734,2734,178.8028,6.5160389,1.3972164,0.0,0,8.5405912,0.0,0.097436197,75.17395,8.6002111,409.54626,-9.2616205
2745,2745,178.805,6.5177484,1.4209313,0.0,0,8.5099754,0.0,0.099696741,75.185684,8.5661888,409.16141,-9.2614365
2756,2756,178.8072,6.5296421,1.454093,0.0,0,8.4793606,0.0,0.10172175,75.131165,8.53613,409.06702,-9.2615423
2767,2767,178.8094,6.5326457,1.4839489,0.0,0,8.4487457,0.0,0.10439877,74.956558,8.5045595,408.98074,-9.2601738
2778,2778,178.8116,6.5413828,1.522061,0.0,0,8.4181299,0.0,0.10668553,74.895615,8.470047,408.8945,-9.2612801
2789,2789,178.8138,6.5456543,1.5452808,0.0,0,8.3875151,0.0,0.10882597,74.825943,8.4384012,408.80823,-9.2615719
2800,2800,178.816,6.552475,1.575372,0.0,0,8.3568993,0.0,0.11078164,74.651642,8.4125738,408.8291,-9.2629404
2811,2811,178.8182,6.5746045,1.6013864,0.0,0,8.3262854,0.0,0.11308701,74.66954,8.3836145,408.98834,-9.2624741
2822,2822,178.8204,6.6112566,1.6379142,0.0,0,8.2956686,0.0,0.1153971,74.972847,8.3497896,409.14758,-9.2625895
2833,2833,178.8226,6.6309881,1.6619328,0.0,0,8.2650547,0.0,0.11756835,75.089668,8.3229542,409.30682,-9.2615204
2844,2844,178.8248,6.6472368,1.6933492,0.0,0,8.2344389,0.0,0.11969429,75.183037,8.2954779,409.46606,-9.2614784
2855,2855,178.827,6.6605778,1.7205703,0.0,0,8.203825,0.0,0.12194996,75.129097,8.260951,409.60144,-9.2622213
2866,2866,178.8292,6.6813369,1.7578579,0.0,0,8.1732092,0.0,0.1243772,75.124504,8.2315464,409.73413,-9.2612028
2877,2877,178.8314,6.6921601,1.7823174,0.0,0,8.1425943,0.0,0.12662661,75.037781,8.196085,409.86685,-9.2603111
2888,2888,178.8336,6.7165341,1.8181508,0.0,0,8.1119785,0.0,0.12906468,75.162148,8.1633968,409.99957,-9.2606964
2899,2899,178.8358,6.7456841,1.8440558,0.0,0,8.0813627,0.0,0.13128626,75.278099,8.1358109,410.14194,-9.2624216
2910,2910,178.838,6.7597985,1.8810915,0.0,0,8.0509262,0.0,0.13379498,75.241928,8.1009226,410.30118,-9.2620401
2921,2921,178.8402,6.8006549,1.9051114,0.0,0,8.0217981,0.0,0.1358825,75.58963,8.0741482,410.46042,-9.261755
2932,2932,178.8424,6.8052726,1.9374714,0.0,0,7.9926691,0.0,0.1382523,75.502701,8.043129,410.61966,-9.2607298
2943,2943,178.8446,6.7973371,1.9648895,0.0,0,7.9635415,0.0,0.14042404,75.229042,8.0118036,410.77893,-9.2607918
2954,2954,178.8468,6.7876058,2.0020602,0.0,0,7.9344139,0.0,0.14308783,74.869141,7.9799924,410.96011,-9.2616243
2965,2965,178.849,6.7997885,2.0263135,0.0,0,7.9052858,0.0,0.14512198,74.868904,7.9515738,411.1459,-9.2617359
2976,2976,178.8512,6.8122091,2.0550768,0.0,0,7.8761578,0.0,0.14729191,74.821106,7.9204407,411.3317,-9.2616091
2987,2987,178.8534,6.8413153,2.0811989,0.0,0,7.8470297,0.0,0.14931744,75.022774,7.8938298,411.51749,-9.2618084
2998,2998,178.8556,6.8568654,2.1161513,0.0,0,7.8179016,0.0,0.15196066,75.041771,7.8648353,411.62222,-9.2623873
3009,3009,178.8578,6.8816514,2.1395805,0.0,0,7.7887735,0.0,0.15387128,75.073601,7.8377552,411.52933,-9.2615767
3020,3020,178.86,6.9117956,2.1687112,0.0,0,7.7596455,0.0,0.15614323,75.340233,7.8049588,411.43643,-9.2613478
3031,3031,178.8622,6.9267855,2.1949837,0.0,0,7.7305174,0.0,0.15817158,75.250336,7.7791047,411.34354,-9.260253
3042,3042,178.8644,6.9169054,2.2299283,0.0,0,7.7013893,0.0,0.1609288,75.045235,7.7459788,411.25064,-9.2600937
3053,3053,178.8666,6.9236269,2.2574992,0.0,0,7.6722617,0.0,0.16297056,74.931396,7.7160225,410.70215,-9.2619019
3064,3064,178.8688,6.9414058,2.2852356,0.0,0,7.6431332,0.0,0.16529299,74.886223,7.6900239,410.00543,-9.2615309
3075,3075,178.871,6.971139,2.3129468,0.0,0,7.6140056,0.0,0.16734536,75.118713,7.6567073,409.30872,-9.2611713
3086,3086,178.8732,6.9978938,2.3457389,0.0,0,7.5848775,0.0,0.170137,75.20295,7.6299014,408.61203,-9.2613659
3097,3097,178.8754,7.0222769,2.3707216,0.0,0,7.5557494,0.0,0.17186797,75.281403,7.5983925,408.02969,-9.2609015
3108,3108,178.8776,7.0515881,2.4006956,0.0,0,7.5266213,0.0,0.17445834,75.363586,7.5716252,407.85715,-9.2604847
3119,3119,178.8798,7.0567603,2.4304671,0.0,0,7.4974933,0.0,0.17670295,75.293381,7.5392017,407.68463,-9.2608557
3130,3130,178.882,7.074832,2.4630964,0.0,0,7.4683657,0.0,0.17944223,75.27742,7.5106239,407.51212,-9.261632
3141,3141,178.8842,7.0784545,2.4905868,0.0,0,7.4392376,0.0,0.18140322,75.261505,7.4820642,407.3396,-9.2616005
3152,3152,178.8864,7.0874243,2.5188842,0.0,0,7.410109,0.0,0.18393581,75.077538,7.4484239,407.53806,-9.2615013
3163,3163,178.8886,7.112184,2.5492971,0.0,0,7.3815403,0.0,0.18606506,75.083061,7.4183798,407.90964,-9.2612095
3174,3174,178.8908,7.1261716,2.5783968,0.0,0,7.353838,0.0,0.18877193,75.018379,7.3910861,408.28119,-9.2611275
3185,3185,178.893,7.1246624,2.6055927,0.0,0,7.3261356,0.0,0.19051716,74.903008,7.3658867,408.65277,-9.261014
3196,3196,178.8952,7.149487,2.6302824,0.0,0,7.2984333,0.0,0.19295333,75.037613,7.3359284,408.94522,-9.2600546
3207,3207,178.8974,7.1681652,2.6583316,0.0,0,7.270731,0.0,0.19479088,75.236221,7.3116727,408.77267,-9.2610712
3218,3218,178.8996,7.1877136,2.6894734,0.0,0,7.2430286,0.0,0.1977464,75.166679,7.2801785,408.60016,-9.2603302
3229,3229,178.9018,7.1965799,2.7171485,0.0,0,7.2153258,0.0,0.19957988,75.084831,7.2498307,408.42764,-9.2612152
3240,3240,178.904,7.179915,2.7430646,0.0,0,7.1876235,0.0,0.20217817,74.726837,7.2207289,408.25513,-9.2619534
3251,3251,178.9062,7.2051258,2.7712944,0.0,0,7.1599212,0.0,0.20399015,74.869461,7.1936827,408.09473,-9.2628174
3262,3262,178.9084,7.2260475,2.7995322,0.0,0,7.1322188,0.0,0.20685029,74.797035,7.1676989,407.94211,-9.2619753
3273,3273,178.9106,7.2323446,2.828963,0.0,0,7.104516,0.0,0.2086574,74.794365,7.1386571,407.78952,-9.2615318
3284,3284,178.9128,7.246345,2.8505375,0.0,0,7.0768137,0.0,0.21099119,74.684906,7.111836,407.6369,-9.2620211
3295,3295,178.915,7.2585053,2.8784752,0.0,0,7.0491114,0.0,0.21275148,74.719826,7.0850859,407.50455,-9.2613745
3306,3306,178.9172,7.2701545,2.9036615,0.0,0,7.021409,0.0,0.21538949,74.672455,7.0592566,407.63065,-9.2628164
3317,3317,178.9194,7.3022852,2.9333837,0.0,0,6.9937067,0.0,0.21727164,74.870041,7.0297847,407.75671,-9.2625523
3328,3328,178.9216,7.3339934,2.9579401,0.0,0,6.9660039,0.0,0.21994589,74.936836,7.0030313,407.88278,-9.2624159
3339,3339,178.9238,7.3335533,2.9905841,0.0,0,6.938302,0.0,0.22204985,74.80304,6.9724259,408.00885,-9.2608318
3350,3350,178.926,7.3635249,3.0158696,0.0,0,6.9105997,0.0,0.22480054,74.913483,6.9457965,408.18475,-9.2602139
3361,3361,178.9282,7.3910375,3.0495896,0.0,0,6.8828974,0.0,0.22679529,74.954063,6.9132648,408.40372,-9.2602959
3372,3372,178.9304,7.4056821,3.069478,0.0,0,6.8551946,0.0,0.22922032,75.00029,6.8894625,408.62268,-9.261302
3383,3383,178.9326,7.439239,3.0990617,0.0,0,6.8274922,0.0,0.23104122,75.101357,6.8564305,408.84164,-9.2616053
3394,3394,178.9348,7.4338002,3.1240089,0.0,0,6.7997894,0.0,0.23383933,74.941559,6.8343234,409.06061,-9.2623158
3405,3405,178.937,7.4441414,3.1579423,0.0,0,6.7720871,0.0,0.23596872,74.881691,6.8049817,409.3194,-9.2623615
3416,3416,178.9392,7.4609928,3.1805799,0.0,0,6.7452798,0.0,0.238626,74.881546,6.7757196,409.57816,-9.262064
3427,3427,178.9414,7.4464149,3.2122843,0.0,0,6.718924,0.0,0.24057424,74.54718,6.7487869,409.83694,-9.261075
3438,3438,178.9436,7.4616227,3.2333059,0.0,0,6.6925678,0.0,0.24314401,74.52887,6.7227988,410.09573,-9.2602787
3449,3449,178.9458,7.4982247,3.2681997,0.0,0,6.6662121,0.0,0.24522524,74.73735,6.693511,410.32681,-9.2599363
3460,3460,178.948,7.5308557,3.2870753,0.0,0,6.6398559,0.0,0.24764441,74.818588,6.6678553,410.52588,-9.2612133
3471,3471,178.9502,7.5262003,3.3156278,0.0,0,6.6135001,0.0,0.24953623,74.67099,6.6389198,410.72491,-9.2603312
3482,3482,178.9524,7.5390067,3.3395636,0.0,0,6.5871439,0.0,0.25220338,74.674309,6.6138897,410.92398,-9.2610121
3493,3493,178.9546,7.5522957,3.3738401,0.0,0,6.5607882,0.0,0.25429329,74.555847,6.5887451,411.12305,-9.2616167
3504,3504,178.9568,7.5480742,3.3917024,0.0,0,6.5344319,0.0,0.25660118,74.377182,6.5632353,411.34052,-9.2617712
3515,3515,178.959,7.5543041,3.4208529,0.0,0,6.5080762,0.0,0.25854471,74.265305,6.5351682,411.55945,-9.2600832
3526,3526,178.9612,7.5784144,3.4421108,0.0,0,6.48172,0.0,0.26102081,74.312157,6.510251,411.77838,-9.2621641
3537,3537,178.9634,7.604948,3.4761171,0.0,0,6.4553642,0.0,0.26310962,74.429962,6.4856815,411.99731,-9.2620916
3548,3548,178.9656,7.649941,3.494215,0.0,0,6.4290085,0.0,0.26555952,74.756264,6.4591699,412.18768,-9.2623243
3559,3559,178.9678,7.6902204,3.5257556,0.0,0,6.4026518,0.0,0.26768389,74.878677,6.4323635,412.33362,-9.2630816
3570,3570,178.97,7.7126813,3.547673,0.0,0,6.376296,0.0,0.27019945,74.91317,6.4034171,412.47952,-9.2621899
3581,3581,178.9722,7.7257056,3.5853627,0.0,0,6.3499398,0.0,0.272607,74.852654,6.3768654,412.62546,-9.2610273
3592,3592,178.9744,7.7231145,3.6031697,0.0,0,6.3235841,0.0,0.27507895,74.677353,6.3464384,412.77139,-9.2613192
3603,3603,178.9766,7.7237358,3.6341851,0.0,0,6.2972283,0.0,0.277087,74.54998,6.3212485,412.79828,-9.2615595
3614,3614,178.9788,7.7465625,3.657584,0.0,0,6.2708726,0.0,0.27986702,74.53392,6.2914009,412.8049,-9.2610569
3625,3625,178.981,7.7488956,3.6924188,0.0,0,6.2445164,0.0,0.28218022,74.419586,6.2681484,412.81152,-9.2619925
3636,3636,178.9832,7.7531886,3.7092168,0.0,0,6.2181602,0.0,0.28439644,74.305809,6.2422314,412.81815,-9.2617569
3647,3647,178.9854,7.7891579,3.7390008,0.0,0,6.1918044,0.0,0.28648701,74.384644,6.2164936,412.75513,-9.2627592
3658,3658,178.9876,7.802784,3.7584727,0.0,0,6.1654482,0.0,0.28869447,74.426811,6.1950727,412.54285,-9.2615805
3669,3669,178.9898,7.8061466,3.7926912,0.0,0,6.1403008,0.0,0.29102823,74.279549,6.165606,412.33057,-9.2605562
3680,3680,178.992,7.823638,3.8120055,0.0,0,6.1152344,0.0,0.29338244,74.25795,6.1395869,412.11829,-9.2610359
3691,3691,178.9942,7.8544173,3.8394606,0.0,0,6.0901675,0.0,0.29538709,74.380081,6.1145134,411.90601,-9.262351
3702,3702,178.9964,7.8538227,3.8618729,0.0,0,6.0651007,0.0,0.29790986,74.2621,6.0885258,411.23721,-9.2623568
3713,3713,178.9986,7.8715377,3.8969035,0.0,0,6.0400338,0.0,0.30052525,74.167213,6.0658946,410.44104,-9.2624197
3724,3724,179.0008,7.8959374,3.9160748,0.0,0,6.014967,0.0,0.30269712,74.238602,6.0372162,409.64487,-9.2610989
3735,3735,179.003,7.910296,3.944114,0.0,0,5.9899006,0.0,0.30480754,74.22506,6.0087099,408.84866,-9.2613039
3746,3746,179.0052,7.9361162,3.9647708,0.0,0,5.9648333,0.0,0.30705121,74.342453,5.9857254,408.03619,-9.2615662
3757,3757,179.0074,7.9461422,3.9970222,0.0,0,5.9397664,0.0,0.3096059,74.285965,5.9597073,407.17361,-9.2611609
3768,3768,179.0096,7.9532409,4.0156403,0.0,0,5.9147,0.0,0.31162131,74.171585,5.9338479,406.311,-9.2612505
3779,3779,179.0118,7.9518423,4.0429211,0.0,0,5.8896332,0.0,0.3139011,74.015434,5.9073658,405.44843,-9.2618122
3790,3790,179.014,7.9673347,4.0643539,0.0,0,5.8645663,0.0,0.31609738,73.985771,5.8829765,404.58585,-9.2611389
3801,3801,179.0162,7.9744539,4.0962195,0.0,0,5.8394995,0.0,0.31874782,73.839264,5.8584628,404.53723,-9.2629995
3812,3812,179.0184,7.9914112,4.1156316,0.0,0,5.8144326,0.0,0.32070655,73.834648,5.8361273,404.82254,-9.262208
3823,3823,179.0206,8.0276728,4.1400771,0.0,0,5.7893653,0.0,0.32287166,73.956787,5.8082833,405.10785,-9.2616711
3834,3834,179.0228,8.075839,4.1617541,0.0,0,5.7642989,0.0,0.32493696,74.245857,5.7834644,405.39319,-9.2607794
3845,3845,179.025,8.1135254,4.1956968,0.0,0,5.7392321,0.0,0.32796681,74.440384,5.7598972,405.74496,-9.2610703
3856,3856,179.0272,8.1233225,4.2181845,0.0,0,5.7141652,0.0,0.33008841,74.433014,5.7309461,406.41513,-9.2619505
3867,3867,179.0294,8.123024,4.2457395,0.0,0,5.6890984,0.0,0.33272544,74.220413,5.706635,407.0853,-9.2608042
3878,3878,179.0316,8.1327257,4.266439,0.0,0,5.6640315,0.0,0.33466178,74.08242,5.6776099,407.75546,-9.261673
3889,3889,179.0338,8.148736,4.299891,0.0,0,5.6389647,0.0,0.33775219,73.982483,5.6528192,408.42563,-9.2609129
3900,3900,179.036,8.163888,4.3217688,0.0,0,5.6138978,0.0,0.3397027,73.974922,5.6277003,408.80865,-9.2607279
3911,3911,179.0382,8.1726475,4.3464212,0.0,0,5.589088,0.0,0.34219509,73.876328,5.6042356,409.02762,-9.2614107
3922,3922,179.0404,8.1912718,4.3669224,0.0,0,5.5652399,0.0,0.34400097,73.906311,5.579277,409.24658,-9.2618742
3933,3933,179.0426,8.223506,4.3979592,0.0,0,5.5413914,0.0,0.34704039,74.014503,5.552834,409.46555,-9.2618389
3944,3944,179.0448,8.2203426,4.4192185,0.0,0,5.5175438,0.0,0.34881082,73.843086,5.5291262,409.68982,-9.2611523
3955,3955,179.047,8.2220669,4.4419332,0.0,0,5.4936957,0.0,0.35125208,73.700455,5.5054278,409.96185,-9.2616501
3966,3966,179.0492,8.2181225,4.4653397,0.0,0,5.4698477,0.0,0.35322487,73.502373,5.4814301,410.23392,-9.2617626
3977,3977,179.0514,8.226265,4.4947581,0.0,0,5.4459996,0.0,0.35630462,73.309341,5.459065,410.50595,-9.2622089
3988,3988,179.0536,8.2241707,4.5142126,0.0,0,5.4221516,0.0,0.35781449,73.287682,5.4375229,410.77802,-9.2625055
3999,3999,179.0558,8.2510042,4.5356588,0.0,0,5.3983035,0.0,0.36016849,73.258125,5.4148011,411.04257,-9.2624922
4010,4010,179.058,8.2655935,4.5559249,0.0,0,5.3744559,0.0,0.36179641,73.206154,5.3879471,411.30136,-9.2615795
4021,4021,179.0602,8.2920675,4.5819302,0.0,0,5.3506079,0.0,0.36474496,73.293808,5.367157,411.56012,-9.2603931
4032,4032,179.0624,8.3108063,4.6042142,0.0,0,5.3267598,0.0,0.36630172,73.373589,5.3444943,411.81891,-9.2617769
4043,4043,179.0646,8.3597221,4.6260128,0.0,0,5.3029118,0.0,0.36901551,73.604179,5.3248978,412.07712,-9.261816
4054,4054,179.0668,8.4031553,4.650826,0.0,0,5.2790637,0.0,0.37087959,73.916618,5.299686,412.31573,-9.2624874
4065,4065,179.069,8.4362984,4.6792731,0.0,0,5.2552156,0.0,0.37425366,73.843155,5.2698064,412.55435,-9.2616711
4076,4076,179.0712,8.4674702,4.7078733,0.0,0,5.2313676,0.0,0.37627566,74.009125,5.2442231,412.79297,-9.2625771
4087,4087,179.0734,8.4951258,4.7283945,0.0,0,5.20752,0.0,0.3788937,74.063713,5.215528,413.03159,-9.261898
4098,4098,179.0756,8.472846,4.7544789,0.0,0,5.1836715,0.0,0.38076192,73.695015,5.1942873,413.26688,-9.2623262
4109,4109,179.0778,8.4894943,4.7798076,0.0,0,5.1598234,0.0,0.38405076,73.592369,5.1674566,413.49866,-9.2613297
4120,4120,179.08,8.4982653,4.8072915,0.0,0,5.1359754,0.0,0.38593602,73.58223,5.1452794,413.73047,-9.2604494
4131,4131,179.0822,8.4989471,4.8252211,0.0,0,5.1121278,0.0,0.38844702,73.417274,5.1217179,413.96225,-9.2609301
4142,4142,179.0844,8.5072794,4.8474884,0.0,0,5.0882797,0.0,0.38986731,73.30191,5.0973053,414.19406,-9.2619028
4153,4153,179.0866,8.5037136,4.8698702,0.0,0,5.0644317,0.0,0.39301851,73.119942,5.0763459,414.30573,-9.2618818
4164,4164,179.0888,8.5065517,4.8985953,0.0,0,5.0411468,0.0,0.39493299,72.936646,5.0523829,414.41168,-9.2617846
4175,4175,179.091,8.5585766,4.9156008,0.0,0,5.0184646,0.0,0.39753836,73.182205,5.0295258,414.51764,-9.261548
4186,4186,179.0932,8.6040955,4.9412751,0.0,0,4.9957829,0.0,0.39923176,73.463951,5.0089202,414.6236,-9.2619524
4197,4197,179.0954,8.6324844,4.9631262,0.0,0,4.9731011,0.0,0.402343,73.473808,4.9841185,414.43292,-9.2612724
4208,4208,179.0976,8.6691313,4.9934535,0.0,0,4.9504189,0.0,0.40417862,73.630226,4.9561515,413.82956,-9.2614355
4219,4219,179.0998,8.7038975,5.0122933,0.0,0,4.9277368,0.0,0.40705675,73.723152,4.9323869,413.22617,-9.2611647
4230,4230,179.102,8.6812744,5.0399771,0.0,0,4.9050546,0.0,0.40905151,73.474037,4.9101768,412.6228,-9.2623568
4241,4241,179.1042,8.6604128,5.0602908,0.0,0,4.8823729,0.0,0.41205171,73.096474,4.8874788,412.01944,-9.2624846
4252,4252,179.1064,8.6619196,5.0884671,0.0,0,4.8596911,0.0,0.41371262,72.926659,4.8656921,411.17032,-9.2625942
4263,4263,179.1086,8.6722279,5.1020031,0.0,0,4.8370085,0.0,0.41616857,72.764679,4.8422713,410.2883,-9.2625742
4274,4274,179.1108,8.6996593,5.1276908,0.0,0,4.8143268,0.0,0.41793606,72.930351,4.8212271,409.40625,-9.2625046
4285,4285,179.113,8.7407227,5.1471839,0.0,0,4.7916451,0.0,0.42081103,73.045822,4.801003,408.52423,-9.2626286
4296,4296,179.1152,8.7717047,5.1767817,0.0,0,4.7689629,0.0,0.42260909,73.117546,4.7760301,407.81165,-9.2615652
4307,4307,179.1174,8.807641,5.1928234,0.0,0,4.7462807,0.0,0.42538437,73.15316,4.7531862,407.42017,-9.2609234
4318,4318,179.1196,8.8098707,5.2211313,0.0,0,4.7235985,0.0,0.4273909,73.203911,4.7292042,407.02869,-9.262558
4329,4329,179.1218,8.8068457,5.239635,0.0,0,4.7009168,0.0,0.43021587,72.913811,4.7088075,406.63721,-9.2618504
4340,4340,179.124,8.7965193,5.2677712,0.0,0,4.6782351,0.0,0.43203413,72.711899,4.6883402,406.24573,-9.2622366
4351,4351,179.1262,8.8213434,5.2820954,0.0,0,4.6555529,0.0,0.43443882,72.764557,4.6635737,406.20859,-9.2615461
4362,4362,179.1284,8.8579025,5.3076029,0.0,0,4.6328707,0.0,0.43623936,72.871002,4.6423211,406.25504,-9.2622795
4373,4373,179.1306,8.8817787,5.3255119,0.0,0,4.610189,0.0,0.43906981,72.956284,4.6197906,406.30148,-9.2627783
4384,4384,179.1328,8.9002562,5.3583741,0.0,0,4.5875068,0.0,0.44118261,72.883392,4.5978584,406.34793,-9.2610378
4395,4395,179.135,8.9289722,5.371377,0.0,0,4.5648251,0.0,0.44368398,72.964752,4.5753994,406.42514,-9.2622232
4406,4406,179.1372,8.9583311,5.3964825,0.0,0,4.5421429,0.0,0.44557381,73.011215,4.553823,406.58438,-9.262393
4417,4417,179.1394,8.9688873,5.4152184,0.0,0,4.5202951,0.0,0.44837227,72.982849,4.532413,406.74362,-9.2624359
4428,4428,179.1416,8.9883337,5.4469194,0.0,0,4.4987173,0.0,0.45062846,72.943031,4.5051217,406.90286,-9.2616014
4439,4439,179.1438,9.0151081,5.4619131,0.0,0,4.4771399,0.0,0.45315403,72.940186,4.48283,407.0621,-9.2630615
4450,4450,179.146,9.0508871,5.4898572,0.0,0,4.4555626,0.0,0.4552646,73.048737,4.4624109,407.10898,-9.262105
4461,4461,179.1482,9.0738993,5.5066223,0.0,0,4.4339848,0.0,0.45787013,73.049339,4.4378324,407.1156,-9.2625532
4472,4472,179.1504,9.0916538,5.53649,0.0,0,4.4124074,0.0,0.46007913,73.080261,4.4158158,407.12225,-9.2611208
4483,4483,179.1526,9.1057291,5.5513444,0.0,0,4.3908296,0.0,0.46251917,72.945732,4.3925238,407.12888,-9.2615519
4494,4494,179.1548,9.084095,5.5788336,0.0,0,4.3692517,0.0,0.46480051,72.654449,4.3720946,407.17532,-9.2615242
4505,4505,179.157,9.0716076,5.5949759,0.0,0,4.3476744,0.0,0.46707898,72.417435,4.3525643,407.38101,-9.2621708
4516,4516,179.1592,9.0645332,5.6209874,0.0,0,4.326097,0.0,0.46911052,72.18644,4.3327198,407.5867,-9.261466
4527,4527,179.1614,9.0758028,5.6343122,0.0,0,4.3045192,0.0,0.47132421,72.108032,4.3134031,407.79242,-9.2616653
4538,4538,179.1636,9.120429,5.6601353,0.0,0,4.2829418,0.0,0.47343597,72.332474,4.2896171,407.99811,-9.2616339
4549,4549,179.1658,9.1775236,5.6758695,0.0,0,4.261364,0.0,0.47565347,72.60305,4.2728395,408.30948,-9.2625504
4560,4560,179.168,9.2290783,5.7070465,0.0,0,4.2397861,0.0,0.47838271,72.818466,4.2472577,408.67444,-9.2625751
4571,4571,179.1702,9.2612963,5.7194018,0.0,0,4.2182088,0.0,0.48038363,72.930489,4.2285299,409.03937,-9.2617655
4582,4582,179.1724,9.2830238,5.7456541,0.0,0,4.196631,0.0,0.48275915,72.901756,4.2076335,409.40433,-9.2614584
4593,4593,179.1746,9.3574572,5.7639732,0.0,0,4.1750536,0.0,0.48506036,73.310287,4.184267,409.75067,-9.2619038
4604,4604,179.1768,9.4096956,5.7973065,0.0,0,4.1534758,0.0,0.48822847,73.494339,4.1587067,409.96964,-9.2634678
4615,4615,179.179,9.4271345,5.8145823,0.0,0,4.1318984,0.0,0.49054667,73.531799,4.1365175,410.18863,-9.2624054
4626,4626,179.1812,9.4201546,5.8403716,0.0,0,4.1103206,0.0,0.49316603,73.272614,4.1115961,410.40759,-9.262002
4637,4637,179.1834,9.4072924,5.8615947,0.0,0,4.0887432,0.0,0.49563608,73.008827,4.0845051,410.62656,-9.2614632
4648,4648,179.1856,9.4196844,5.8905392,0.0,0,4.0671659,0.0,0.49852315,72.805252,4.0650072,410.68869,-9.2612753
4659,4659,179.1878,9.43507,5.9029393,0.0,0,4.0456276,0.0,0.50018901,72.824234,4.0461464,410.64224,-9.2604151
4670,4670,179.19,9.4306955,5.9257774,0.0,0,4.0250959,0.0,0.50249416,72.61908,4.024374,410.59579,-9.2609816
4681,4681,179.1922,9.4424162,5.9417229,0.0,0,4.0045748,0.0,0.50438416,72.610611,4.0054879,410.54935,-9.2627296
4692,4692,179.1944,9.4400959,5.970355,0.0,0,3.9840529,0.0,0.50745106,72.366653,3.9834192,410.4924,-9.2623682
4703,4703,179.1966,9.4723024,5.9847012,0.0,0,3.9635313,0.0,0.50922287,72.472397,3.9654479,410.25354,-9.2615147
4714,4714,179.1988,9.4785728,6.0077043,0.0,0,3.9430099,0.0,0.51162487,72.374062,3.9448829,410.01465,-9.2624035
4725,4725,179.201,9.4971046,6.0248489,0.0,0,3.9224882,0.0,0.51353931,72.425072,3.9241064,409.77579,-9.2630301
4736,4736,179.2032,9.572752,6.0513144,0.0,0,3.9019666,0.0,0.51657975,72.671783,3.9024687,409.5369,-9.2627459
4747,4747,179.2054,9.6037388,6.0683036,0.0,0,3.8814449,0.0,0.5183326,72.779877,3.880533,409.28427,-9.2628603
4758,4758,179.2076,9.6335535,6.0913606,0.0,0,3.8609233,0.0,0.52114421,72.830872,3.8605051,409.01886,-9.263051
4769,4769,179.2098,9.6258078,6.1088586,0.0,0,3.8404016,0.0,0.52278745,72.560303,3.8421195,408.75345,-9.2608271
4780,4780,179.212,9.6263313,6.1327963,0.0,0,3.8198802,0.0,0.52581704,72.482384,3.8200817,408.48801,-9.2606144
4791,4791,179.2142,9.6392298,6.1513686,0.0,0,3.7993586,0.0,0.52744985,72.402306,3.8025358,408.2226,-9.2628956
4802,4802,179.2164,9.6383123,6.1686935,0.0,0,3.778837,0.0,0.52989882,72.288437,3.7826338,408.12006,-9.2622843
4813,4813,179.2186,9.6786041,6.1878047,0.0,0,3.7583156,0.0,0.53165448,72.410103,3.761363,408.02054,-9.262269
4824,4824,179.2208,9.7255745,6.2129059,0.0,0,3.7377939,0.0,0.53509873,72.48365,3.7403481,407.92102,-9.2616482
4835,4835,179.223,9.7760096,6.2334332,0.0,0,3.7172723,0.0,0.53684014,72.693825,3.721998,407.82147,-9.2619972
4846,4846,179.2252,9.8201389,6.2512083,0.0,0,3.6967506,0.0,0.53924221,72.892433,3.7002668,407.77518,-9.2615175
4857,4857,179.2274,9.8620882,6.270915,0.0,0,3.676229,0.0,0.54095656,73.089699,3.67888,407.79507,-9.2608061
4868,4868,179.2296,9.844039,6.2937355,0.0,0,3.6557074,0.0,0.54434192,72.777611,3.6562655,407.81497,-9.2606745
4879,4879,179.2318,9.8687658,6.3159037,0.0,0,3.635186,0.0,0.54615062,72.82193,3.638711,407.83487,-9.2606592
4890,4890,179.234,9.8895435,6.3342552,0.0,0,3.6146641,0.0,0.54898888,72.726334,3.618119,407.8548,-9.2616949
4901,4901,179.2362,9.9279823,6.3546252,0.0,0,3.5941427,0.0,0.55061734,72.918945,3.5957472,407.68167,-9.2630005
4912,4912,179.2384,9.9608574,6.3768263,0.0,0,3.5739219,0.0,0.55403394,72.901688,3.5751743,407.48926,-9.2619734
4923,4923,179.2406,10.006956,6.4001026,0.0,0,3.554399,0.0,0.55574489,73.130478,3.5546572,407.29681,-9.2628765
4934,4934,179.2428,10.054587,6.4191236,0.0,0,3.5348763,0.0,0.55893946,73.152039,3.5315835,407.1044,-9.2616024
4945,4945,179.245,10.062556,6.4419899,0.0,0,3.5153534,0.0,0.56062931,73.116463,3.509568,406.9837,-9.2617989
4956,4956,179.2472,10.059967,6.4601202,0.0,0,3.4958305,0.0,0.56379288,72.843521,3.490591,406.9837,-9.2623768
4967,4967,179.2494,10.04077,6.4816351,0.0,0,3.4763079,0.0,0.5651803,72.646133,3.4709258,406.9837,-9.2616138
4978,4978,179.2516,10.042053,6.4955606,0.0,0,3.4567852,0.0,0.5679152,72.487907,3.4532926,406.9837,-9.2613306
4989,4989,179.2538,10.022537,6.5164123,0.0,0,3.4372621,0.0,0.5694114,72.284943,3.4343274,406.9837,-9.2617846
5000,5000,179.256,10.034478,6.5329518,0.0,0,3.4177396,0.0,0.57246536,72.091148,3.4159322,407.29446,-9.2618761
5011,5011,179.2582,10.06631,6.5564899,0.0,0,3.3982165,0.0,0.57403469,72.233253,3.3980405,407.66605,-9.2623024
5022,5022,179.2604,10.137663,6.5696797,0.0,0,3.3786941,0.0,0.57672262,72.438797,3.3787549,408.03763,-9.2615604
5033,5033,179.2626,10.19855,6.5922465,0.0,0,3.3591712,0.0,0.57826835,72.803802,3.3606231,408.40921,-9.2608318
5044,5044,179.2648,10.259113,6.6098466,0.0,0,3.339648,0.0,0.58163822,73.019417,3.3386877,408.7569,-9.2609482
5055,5055,179.267,10.302375,6.636991,0.0,0,3.3201256,0.0,0.58344424,73.19838,3.321326,409.04886,-9.2616196
5066,5066,179.2692,10.302326,6.6508732,0.0,0,3.3006024,0.0,0.58660871,72.996307,3.3017461,409.34079,-9.2620068
5077,5077,179.2714,10.334923,6.6738143,0.0,0,3.2810795,0.0,0.588081,73.078247,3.2810674,409.63275,-9.2623901
5088,5088,179.2736,10.358771,6.6908998,0.0,0,3.2615571,0.0,0.59133524,72.996178,3.2570384,409.92471,-9.2615852
5099,5099,179.2758,10.375614,6.7186751,0.0,0,3.242034,0.0,0.59318763,72.964897,3.2377174,410.11533,-9.2619171
5110,5110,179.278,10.401982,6.7311392,0.0,0,3.2225113,0.0,0.59623617,72.918365,3.221714,410.27457,-9.261672
5121,5121,179.2802,10.441067,6.7539191,0.0,0,3.2029886,0.0,0.5976882,73.110321,3.2015998,410.43381,-9.2610369
5132,5132,179.2824,10.472539,6.7686672,0.0,0,3.1834657,0.0,0.60079944,73.088409,3.1816072,410.59308,-9.2621717
5143,5143,179.2846,10.484436,6.7970524,0.0,0,3.1639431,0.0,0.60258311,73.129662,3.1599741,410.3949,-9.2621555
5154,5154,179.2868,10.492126,6.8072791,0.0,0,3.1444204,0.0,0.60544765,72.946144,3.1418769,408.9816,-9.261591
5165,5165,179.289,10.498041,6.8295412,0.0,0,3.1254427,0.0,0.60695076,72.852806,3.1230695,407.56827,-9.2629385
5176,5176,179.2912,10.512609,6.8460512,0.0,0,3.1068702,0.0,0.61020529,72.717171,3.1072664,406.15494,-9.2632685
5187,5187,179.2934,10.553546,6.872241,0.0,0,3.0882978,0.0,0.61191732,72.87191,3.0902646,404.74161,-9.2608204
5198,5198,179.2956,10.597963,6.8820271,0.0,0,3.0697253,0.0,0.61450094,72.98777,3.071106,403.3237,-9.2607098
5209,5209,179.2978,10.642484,6.9048624,0.0,0,3.0511529,0.0,0.61625075,73.144066,3.0522063,401.90375,-9.2608614
5220,5220,179.3,10.709765,6.9184113,0.0,0,3.0325809,0.0,0.61910629,73.418114,3.0290487,400.4838,-9.2625113
5231,5231,179.3022,10.725493,6.9488215,0.0,0,3.0140083,0.0,0.62134278,73.376884,3.0115364,399.06384,-9.2628994
5242,5242,179.3044,10.753265,6.9587092,0.0,0,2.995436,0.0,0.62400436,73.31752,2.992918,397.91974,-9.2624598
5253,5253,179.3066,10.764782,6.9843769,0.0,0,2.9768634,0.0,0.62615472,73.252663,2.9731584,398.2847,-9.2629032
5264,5264,179.3088,10.765507,6.9980726,0.0,0,2.9582911,0.0,0.62891096,73.126205,2.953938,398.64963,-9.2627096
5275,5275,179.311,10.799659,7.025846,0.0,0,2.9397185,0.0,0.63108987,73.135872,2.9379604,399.01459,-9.2627831
5286,5286,179.3132,10.827109,7.0351772,0.0,0,2.9211462,0.0,0.63346958,73.206886,2.9171238,399.37952,-9.2618055
5297,5297,179.3154,10.883455,7.0584035,0.0,0,2.9025741,0.0,0.63542217,73.341995,2.8982437,399.72806,-9.2616577
5308,5308,179.3176,10.89477,7.0726037,0.0,0,2.8840015,0.0,0.638322,73.27549,2.8788002,400.06644,-9.261405
5319,5319,179.3198,10.927035,7.0992069,0.0,0,2.8654292,0.0,0.64047289,73.3069,2.861912,400.40485,-9.2615519
5330,5330,179.322,10.920331,7.1097398,0.0,0,2.8468566,0.0,0.64284343,73.122673,2.8458889,400.74326,-9.2608595
5341,5341,179.3242,10.942061,7.1316156,0.0,0,2.8282843,0.0,0.64485031,73.097359,2.8264773,401.08707,-9.2614708
5352,5352,179.3264,10.969778,7.1429739,0.0,0,2.8097117,0.0,0.64708048,73.117958,2.807322,401.49182,-9.2616158
5363,5363,179.3286,11.029106,7.1706228,0.0,0,2.7911394,0.0,0.64951229,73.295311,2.7896738,401.89658,-9.2614002
5374,5374,179.3308,11.085649,7.1817389,0.0,0,2.772567,0.0,0.65205353,73.586761,2.7717934,402.30133,-9.2621641
5385,5385,179.333,11.167051,7.2074771,0.0,0,2.7539945,0.0,0.65453994,73.854561,2.7496715,402.70609,-9.2613926
5396,5396,179.3352,11.198511,7.221766,0.0,0,2.7354224,0.0,0.65704721,73.885757,2.7352352,403.37506,-9.2610483
5407,5407,179.3374,11.245399,7.2483063,0.0,0,2.7168498,0.0,0.65970087,74.043915,2.7130797,404.26419,-9.2615948
5418,5418,179.3396,11.274752,7.2591996,0.0,0,2.6990449,0.0,0.66183984,74.033165,2.6943595,405.15332,-9.2620411
5429,5429,179.3418,11.270416,7.285141,0.0,0,2.6813788,0.0,0.66459119,73.784698,2.6712036,406.04245,-9.2607193
5440,5440,179.344,11.254802,7.2973666,0.0,0,2.663713,0.0,0.66677189,73.604897,2.6583157,406.92789,-9.2613382
5451,5451,179.3462,11.221477,7.3214216,0.0,0,2.6460469,0.0,0.66931409,73.220871,2.6395729,407.41226,-9.262228
5462,5462,179.3484,11.251495,7.3318691,0.0,0,2.6283808,0.0,0.67108268,73.201706,2.6249108,407.89664,-9.26262
5473,5473,179.3506,11.288628,7.3523116,0.0,0,2.6107149,0.0,0.67340189,73.263168,2.6068165,408.38101,-9.2621508
5484,5484,179.3528,11.398571,7.3641191,0.0,0,2.5930488,0.0,0.675295,73.88353,2.5864639,408.86539,-9.2614775
5495,5495,179.355,11.452368,7.3909192,0.0,0,2.5753827,0.0,0.67847788,73.966881,2.5711303,409.01102,-9.2618856
5506,5506,179.3572,11.500212,7.40346,0.0,0,2.5577168,0.0,0.68052572,74.127647,2.5529983,408.77878,-9.2615452
5517,5517,179.3594,11.530508,7.4261169,0.0,0,2.540051,0.0,0.68319952,74.158104,2.5324495,408.54654,-9.2610617
5528,5528,179.3616,11.496339,7.4400468,0.0,0,2.5223849,0.0,0.68516749,73.792252,2.5171969,408.3143,-9.2613258
5539,5539,179.3638,11.489665,7.463017,0.0,0,2.5047188,0.0,0.68814754,73.51561,2.5014887,408.08206,-9.2613354
5550,5550,179.366,11.514978,7.4745846,0.0,0,2.4870529,0.0,0.68971932,73.58046,2.4834757,408.06729,-9.2615929
5561,5561,179.3682,11.575886,7.4924655,0.0,0,2.4693868,0.0,0.69225752,73.735794,2.4669414,408.06729,-9.2617588
5572,5572,179.3704,11.63389,7.5075202,0.0,0,2.451721,0.0,0.69407648,73.98465,2.4465961,408.06729,-9.2621889
5583,5583,179.3726,11.692882,7.530097,0.0,0,2.4340549,0.0,0.69722414,74.14463,2.4333012,408.06729,-9.2616234
5594,5594,179.3748,11.772002,7.5452046,0.0,0,2.4163888,0.0,0.6989485,74.476135,2.4132011,407.95581,-9.2617693
5605,5605,179.377,11.810114,7.5660448,0.0,0,2.3987229,0.0,0.70206332,74.538155,2.3941462,407.67712,-9.2622032
5616,5616,179.3792,11.893213,7.5831285,0.0,0,2.3810568,0.0,0.7040109,74.866425,2.3751953,407.39847,-9.2613907
5627,5627,179.3814,11.88123,7.6057014,0.0,0,2.3633907,0.0,0.70753974,74.613319,2.3576293,407.11978,-9.262084
5638,5638,179.3836,11.890392,7.6207976,0.0,0,2.3457248,0.0,0.70903701,74.538834,2.3380437,406.84109,-9.2617102
5649,5649,179.3858,11.906596,7.640296,0.0,0,2.3280587,0.0,0.71222639,74.342636,2.3189297,406.2587,-9.2617903
5660,5660,179.388,11.928053,7.6559854,0.0,0,2.3104959,0.0,0.71376622,74.366562,2.3053646,405.62833,-9.2630739
5671,5671,179.3902,11.946406,7.6728463,0.0,0,2.2936921,0.0,0.71688652,74.269287,2.2867193,404.99799,-9.2610989
5682,5682,179.3924,11.974818,7.6887722,0.0,0,2.2768884,0.0,0.71813112,74.310509,2.2697318,404.36761,-9.2621651
5693,5693,179.3946,12.007056,7.7039471,0.0,0,2.2600849,0.0,0.72110635,74.324768,2.2557259,403.93054,-9.2622604
5704,5704,179.3968,12.055316,7.7215638,0.0,0,2.2432811,0.0,0.7226758,74.496696,2.2367117,403.89072,-9.262928
5715,5715,179.399,12.066307,7.7410045,0.0,0,2.2264779,0.0,0.72621393,74.338051,2.2231231,403.85092,-9.2623425
5726,5726,179.4012,12.101752,7.754725,0.0,0,2.2096741,0.0,0.72715074,74.452225,2.2073588,403.8111,-9.2618904
5737,5737,179.4034,12.133609,7.7698131,0.0,0,2.1928706,0.0,0.73023856,74.441879,2.1879334,403.7713,-9.2622395
5748,5748,179.4056,12.197822,7.78861,0.0,0,2.1760669,0.0,0.7319023,74.678299,2.1713967,403.97815,-9.2611494
5759,5759,179.4078,12.265881,7.8064132,0.0,0,2.1592634,0.0,0.73552305,74.903648,2.1538818,404.25018,-9.2606812
5770,5770,179.41,12.312598,7.8254757,0.0,0,2.1424596,0.0,0.73689699,75.047653,2.1366825,404.52222,-9.2603922
5781,5781,179.4122,12.352023,7.8401432,0.0,0,2.1256561,0.0,0.73996317,75.027641,2.1190972,404.79428,-9.262599
5792,5792,179.4144,12.384366,7.858345,0.0,0,2.1088524,0.0,0.74139947,75.132607,2.1017442,405.08151,-9.2621603
5803,5803,179.4166,12.425373,7.8734436,0.0,0,2.0920489,0.0,0.7448799,75.14888,2.0861177,405.4133,-9.2631216
5814,5814,179.4188,12.463507,7.8929491,0.0,0,2.0752454,0.0,0.74617052,75.238686,2.0708711,405.74506,-9.2630253
5825,5825,179.421,12.510572,7.9066525,0.0,0,2.0584419,0.0,0.7494576,75.295479,2.0513864,406.07681,-9.2616739
5836,5836,179.4232,12.533679,7.9287443,0.0,0,2.0416381,0.0,0.75129873,75.286888,2.0364556,406.40857,-9.2613077
5847,5847,179.4254,12.608356,7.9425735,0.0,0,2.0248346,0.0,0.75470734,75.419899,2.0194509,406.42584,-9.2600842
5858,5858,179.4276,12.651976,7.962029,0.0,0,2.0080309,0.0,0.75599802,75.645721,2.0001199,406.31967,-9.261281
5869,5869,179.4298,12.680767,7.9743876,0.0,0,1.9912274,0.0,0.75921357,75.585823,1.9855977,406.21353,-9.2623281
5880,5880,179.432,12.726807,7.9945636,0.0,0,1.9744238,0.0,0.76057792,75.760353,1.9703674,406.10736,-9.2618275
5891,5891,179.4342,12.802221,8.0106373,0.0,0,1.9576201,0.0,0.76442623,75.90567,1.9513052,405.95416,-9.2622614
5902,5902,179.4364,12.82688,8.0366392,0.0,0,1.9408166,0.0,0.76642525,75.918427,1.9349802,405.5892,-9.262207
5913,5913,179.4386,12.864232,8.0478411,0.0,0,1.9243339,0.0,0.76983857,75.810402,1.9168605,405.22427,-9.2620754
5924,5924,179.4408,12.870394,8.0655336,0.0,0,1.9083487,0.0,0.77071291,75.80732,1.8985907,404.85931,-9.2614689
5935,5935,179.443,12.923419,8.0789652,0.0,0,1.8923634,0.0,0.77441949,75.798325,1.8821313,404.49438,-9.261364
5946,5946,179.4452,12.991808,8.1037607,0.0,0,1.8763782,0.0,0.77606261,76.117126,1.8652294,404.22794,-9.2626066
5957,5957,179.4474,13.040566,8.111721,0.0,0,1.860393,0.0,0.77914631,76.181206,1.8464515,404.01559,-9.262229
5968,5968,179.4496,13.057708,8.1324711,0.0,0,1.8444078,0.0,0.78042555,76.217384,1.8360831,403.80325,-9.2615881
5979,5979,179.4518,13.060015,8.1460934,0.0,0,1.8284227,0.0,0.78410393,75.958992,1.8160414,403.59094,-9.2603426
5990,5990,179.454,13.041867,8.1696901,0.0,0,1.8124374,0.0,0.78557307,75.71241,1.8021699,403.41406,-9.2616262
6001,6001,179.4562,13.057203,8.1753902,0.0,0,1.7964523,0.0,0.78838074,75.546501,1.7848982,403.52686,-9.262207
6012,6012,179.4584,13.068483,8.1951885,0.0,0,1.780467,0.0,0.78968257,75.541161,1.7697836,403.63968,-9.2610693
6023,6023,179.4606,13.113579,8.2067356,0.0,0,1.7644818,0.0,0.7930249,75.55732,1.758646,403.75247,-9.261981
6034,6034,179.4628,13.168261,8.2279196,0.0,0,1.7484967,0.0,0.79410762,75.727112,1.7429888,403.86526,-9.26229
6045,6045,179.465,13.256037,8.2337103,0.0,0,1.7325114,0.0,0.79689288,76.022568,1.7260855,403.89825,-9.2628431
6056,6056,179.4672,13.310781,8.2555294,0.0,0,1.7165262,0.0,0.79860693,76.246834,1.7103177,403.87173,-9.2620277
6067,6067,179.4694,13.360639,8.2651491,0.0,0,1.700541,0.0,0.80160248,76.336472,1.6949105,403.84518,-9.2621946
6078,6078,179.4716,13.414389,8.2906542,0.0,0,1.6845558,0.0,0.8034777,76.499794,1.676944,403.81866,-9.2629023
6089,6089,179.4738,13.493414,8.2959995,0.0,0,1.6685706,0.0,0.80611318,76.701546,1.6602559,403.7832,-9.2629261
6100,6100,179.476,13.545982,8.3182173,0.0,0,1.6525854,0.0,0.80813402,76.886368,1.6425591,403.51114,-9.2623577
6111,6111,179.4782,13.612443,8.3307323,0.0,0,1.6366003,0.0,0.81130171,76.985176,1.6308109,403.23911,-9.2624979
6122,6122,179.4804,13.642802,8.3565168,0.0,0,1.620615,0.0,0.81338292,76.985748,1.6166705,402.96704,-9.2614002
6133,6133,179.4826,13.694398,8.3625441,0.0,0,1.6046298,0.0,0.81580496,77.036682,1.5974311,402.69498,-9.2617102
6144,6144,179.4848,13.749945,8.3832512,0.0,0,1.5886445,0.0,0.8178671,77.284378,1.5837179,402.50256,-9.2622662
6155,6155,179.487,13.803576,8.3931551,0.0,0,1.5726594,0.0,0.82061607,77.355911,1.5658611,402.38974,-9.2620153
6166,6166,179.4892,13.831929,8.4202299,0.0,0,1.5571918,0.0,0.82324737,77.315002,1.5500014,402.27695,-9.2615252
6177,6177,179.4914,13.89275,8.4275627,0.0,0,1.5419855,0.0,0.82569921,77.477798,1.5320193,402.16415,-9.2623892
6188,6188,179.4936,13.929142,8.4484901,0.0,0,1.5267792,0.0,0.82794106,77.478134,1.5190874,402.05133,-9.2617455
6199,6199,179.4958,13.957589,8.4581079,0.0,0,1.5115727,0.0,0.83057022,77.404251,1.5044712,401.86182,-9.2620554
6210,6210,179.498,13.999579,8.483532,0.0,0,1.4963663,0.0,0.83300269,77.453949,1.4886439,401.6694,-9.2613344
6221,6221,179.5002,14.055156,8.4905214,0.0,0,1.4811599,0.0,0.83521229,77.646309,1.4715053,401.47699,-9.2610703
6232,6232,179.5024,14.107419,8.509943,0.0,0,1.4659536,0.0,0.83727735,77.723579,1.4560434,401.28458,-9.261178
6243,6243,179.5046,14.125402,8.5195799,0.0,0,1.4507471,0.0,0.83956659,77.734192,1.4463481,401.16586,-9.260664
6254,6254,179.5068,14.150907,8.5450935,0.0,0,1.4355407,0.0,0.84252477,77.623405,1.4303056,401.14597,-9.2615986
6265,6265,179.509,14.184554,8.5501242,0.0,0,1.4203343,0.0,0.8443169,77.656731,1.4136919,401.12604,-9.2616463
6276,6276,179.5112,14.262173,8.5702982,0.0,0,1.4051279,0.0,0.84678411,77.850037,1.3979294,401.10614,-9.2621117
6287,6287,179.5134,14.308171,8.5797825,0.0,0,1.3899214,0.0,0.84885502,78.001038,1.3822227,401.08621,-9.2612162
6298,6298,179.5156,14.37563,8.6065283,0.0,0,1.3747151,0.0,0.85227507,78.065628,1.3654861,401.04858,-9.2618465
6309,6309,179.5178,14.446287,8.6129904,0.0,0,1.3595088,0.0,0.85405719,78.292854,1.3508571,401.00876,-9.262434
6320,6320,179.52,14.54083,8.6313362,0.0,0,1.3443023,0.0,0.85648805,78.617897,1.3386388,400.96896,-9.260232
6331,6331,179.5222,14.623001,8.6425495,0.0,0,1.3290958,0.0,0.85852766,78.892494,1.3212743,400.92914,-9.2609549
6342,6342,179.5244,14.683517,8.6654701,0.0,0,1.3138895,0.0,0.86179286,78.981133,1.30246,400.88696,-9.2615967
6353,6353,179.5266,14.724825,8.6772079,0.0,0,1.2986832,0.0,0.86402839,79.011086,1.284354,400.84052,-9.2620087
6364,6364,179.5288,14.745755,8.6967783,0.0,0,1.2834768,0.0,0.86704469,78.881287,1.2693287,400.7941,-9.2609386
6375,6375,179.531,14.742643,8.7067995,0.0,0,1.2682704,0.0,0.86858976,78.751259,1.2586404,400.74765,-9.2602396
6386,6386,179.5332,14.786279,8.7285109,0.0,0,1.2530639,0.0,0.87199807,78.710236,1.2414966,400.7012,-9.2609663
6397,6397,179.5354,14.817744,8.735858,0.0,0,1.2378575,0.0,0.87305832,78.789825,1.2275734,400.80133,-9.2610703
6408,6408,179.5376,14.872407,8.7526493,0.0,0,1.2226511,0.0,0.87610167,78.777512,1.2126272,400.93402,-9.2621346
6419,6419,179.5398,14.904602,8.7627335,0.0,0,1.2081418,0.0,0.87723809,78.904572,1.1982962,401.06674,-9.261548
6430,6430,179.542,14.93454,8.7843161,0.0,0,1.193679,0.0,0.8811627,78.765686,1.1850271,401.19943,-9.2612667
6441,6441,179.5442,14.925911,8.7947369,0.0,0,1.1792163,0.0,0.88232404,78.635582,1.1675601,401.34897,-9.2607031
6452,6452,179.5464,14.917726,8.8074818,0.0,0,1.1647533,0.0,0.88493478,78.429459,1.1558764,401.54141,-9.2615566
6463,6463,179.5486,14.942073,8.8182898,0.0,0,1.1502906,0.0,0.8860774,78.455429,1.1476461,401.73383,-9.260148
6474,6474,179.5508,15.023364,8.8363647,0.0,0,1.1358278,0.0,0.88976443,78.559441,1.1322315,401.92627,-9.2608995
6485,6485,179.553,15.149179,8.8478107,0.0,0,1.121365,0.0,0.89074254,79.126785,1.1160412,402.11868,-9.2603617
6496,6496,179.5552,15.278425,8.8615589,0.0,0,1.1069021,0.0,0.89382452,79.541939,1.1048198,402.41498,-9.2609081
6507,6507,179.5574,15.383555,8.8761568,0.0,0,1.0924393,0.0,0.89537835,79.996254,1.084675,402.74673,-9.260705
6518,6518,179.5596,15.464326,8.8930197,0.0,0,1.0779766,0.0,0.89918697,80.126099,1.0727856,403.07852,-9.2626467
6529,6529,179.5618,15.496762,8.9068813,0.0,0,1.0635136,0.0,0.90019971,80.217308,1.0564871,403.41028,-9.2626238
6540,6540,179.564,15.520724,8.9199505,0.0,0,1.0490509,0.0,0.90355492,80.065765,1.0407838,403.71152,-9.2616987
6551,6551,179.5662,15.525501,8.9337883,0.0,0,1.0345882,0.0,0.9047206,80.014465,1.0291586,403.89731,-9.2606859
6562,6562,179.5684,15.56051,8.9512749,0.0,0,1.0201254,0.0,0.90897954,79.808876,1.0126932,404.0831,-9.2606516
6573,6573,179.5706,15.624834,8.9653397,0.0,0,1.0056624,0.0,0.90965366,80.061722,0.99900931,404.26889,-9.260129
6584,6584,179.5728,15.730536,8.9730844,0.0,0,0.99119979,0.0,0.91250694,80.394707,0.98432457,404.45468,-9.259059
6595,6595,179.575,15.815585,8.9910822,0.0,0,0.97673696,0.0,0.91390377,80.706596,0.97248507,404.48422,-9.2605505
6606,6606,179.5772,15.928206,9.005847,0.0,0,0.96227413,0.0,0.9180873,80.946831,0.95493931,404.43777,-9.261014
6617,6617,179.5794,16.015726,9.0244188,0.0,0,0.94781131,0.0,0.91950053,81.295731,0.93911815,404.39133,-9.2605476
6628,6628,179.5816,16.059849,9.034544,0.0,0,0.93334854,0.0,0.92268819,81.281937,0.92472321,404.34488,-9.2606878
6639,6639,179.5838,16.079855,9.0514078,0.0,0,0.91888577,0.0,0.92408448,81.269203,0.90942669,404.20502,-9.2601681
6650,6650,179.586,16.100874,9.0670509,0.0,0,0.90442294,0.0,0.92838311,81.033089,0.89484531,403.47345,-9.2599678
6661,6661,179.5882,16.142796,9.0829601,0.0,0,0.89010906,0.0,0.92928433,81.124481,0.88326919,402.74188,-9.2615185
6672,6672,179.5904,16.180338,9.0930548,0.0,0,0.87635463,0.0,0.93264991,81.039146,0.8700332,402.01028,-9.262805
6683,6683,179.5926,16.237104,9.1090746,0.0,0,0.86260027,0.0,0.93355221,81.242401,0.85446668,401.27872,-9.2621584
6694,6694,179.5948,16.312269,9.1189289,0.0,0,0.84884584,0.0,0.93734962,81.309639,0.83782613,400.7601,-9.2616129
6705,6705,179.597,16.376045,9.1351299,0.0,0,0.83509147,0.0,0.93806195,81.589729,0.83106804,400.61411,-9.2607803
6716,6716,179.5992,16.426861,9.1435537,0.0,0,0.82133704,0.0,0.94144571,81.608025,0.81498963,400.46811,-9.2600346
6727,6727,179.6014,16.451427,9.1635571,0.0,0,0.80758262,0.0,0.94297433,81.589638,0.80349225,400.32214,-9.2616358
6738,6738,179.6036,16.512709,9.1750078,0.0,0,0.79382825,0.0,0.94711518,81.533981,0.78683984,400.17615,-9.2611723
6749,6749,179.6058,16.600782,9.1944294,0.0,0,0.78007382,0.0,0.94781584,81.899185,0.77414173,400.59555,-9.2613249
6760,6760,179.608,16.692972,9.197751,0.0,0,0.76631945,0.0,0.95086652,82.109337,0.75952083,401.13303,-9.2615967
6771,6771,179.6102,16.803223,9.2195377,0.0,0,0.75256503,0.0,0.95252627,82.494698,0.74615306,401.67047,-9.2609577
6782,6782,179.6124,16.872881,9.2281542,0.0,0,0.73881066,0.0,0.95625478,82.550415,0.73146701,402.20795,-9.2609024
6793,6793,179.6146,16.929701,9.2514114,0.0,0,0.72505623,0.0,0.95783502,82.696182,0.71493441,402.64117,-9.2599735
6804,6804,179.6168,16.979017,9.2552538,0.0,0,0.7113018,0.0,0.96085155,82.698631,0.70167428,402.82031,-9.2608995
6815,6815,179.619,17.017366,9.2747564,0.0,0,0.69754744,0.0,0.96221447,82.788414,0.68711358,402.99948,-9.2618189
6826,6826,179.6212,17.02043,9.284008,0.0,0,0.68379307,0.0,0.96585619,82.489693,0.67598295,403.17862,-9.2606812
6837,6837,179.6234,17.04385,9.3044701,0.0,0,0.67003864,0.0,0.96705323,82.536392,0.66428965,403.35779,-9.2609491
6848,6848,179.6256,17.111403,9.3072777,0.0,0,0.65628421,0.0,0.96985358,82.605553,0.64732111,403.62207,-9.2611446
6859,6859,179.6278,17.209211,9.3241491,0.0,0,0.64252985,0.0,0.97096688,82.943428,0.63435131,403.91403,-9.2600822
6870,6870,179.63,17.31209,9.3333282,0.0,0,0.62877542,0.0,0.97465551,83.133904,0.61904776,404.20596,-9.2609158
6881,6881,179.6322,17.429066,9.3579836,0.0,0,0.61502105,0.0,0.97659737,83.566734,0.60876596,404.49792,-9.2608852
6892,6892,179.6344,17.499496,9.3608913,0.0,0,0.60126662,0.0,0.97920215,83.688835,0.59366542,404.71173,-9.2595282
6903,6903,179.6366,17.577087,9.378026,0.0,0,0.58751225,0.0,0.98048973,83.958694,0.57938331,404.64536,-9.2605448
6914,6914,179.6388,17.62969,9.3854713,0.0,0,0.57407868,0.0,0.98389196,83.939682,0.56551838,404.57901,-9.2608795
6925,6925,179.641,17.693975,9.4107132,0.0,0,0.56098866,0.0,0.98599529,84.058861,0.55064708,404.51263,-9.2602749
6936,6936,179.6432,17.719511,9.4155674,0.0,0,0.54789871,0.0,0.98897541,83.885414,0.53591275,404.44629,-9.2610912
6940,6940,179.644,17.796343,9.4253941,0.0,0,0.54313868,0.0,0.99017912,84.193291,0.53482163,404.39261,-9.2616034