File: clean data/testID_0226.csv
level_0,index,Time(sec),Force(kN),Jaw(mm),PowAngle(deg),Power(W),Pram,PTemp,Strain,Stress(MPa),Stroke(mm),TC1(C),wedge(mm)
2273,2273,195.3439,0.91466522,0.029233288,0.0,0,9.0337009,0.0,0.0015587667,10.913823,10.046773,451.67755,-9.2361765
2275,2275,195.3443,3.3495741,0.058723655,0.0,0,8.975173,0.0,0.0036508879,38.862007,9.9711351,451.77914,-9.235446
2277,2277,195.3447,4.6920424,0.12081429,0.0,0,8.9166451,0.0,0.0077346927,58.516827,9.9134007,451.88074,-9.2345362
2279,2279,195.3451,5.2434483,0.19153906,0.0,0,8.8581161,0.0,0.011916001,65.055458,9.8393993,451.98236,-9.2328224
2281,2281,195.3455,5.0248461,0.33844462,0.0,0,8.7995882,0.0,0.021968259,63.362103,9.7478294,452.08395,-9.2316561
2283,2283,195.3459,5.2248211,0.43877155,0.0,0,8.7416477,0.0,0.029036019,63.563137,9.6372395,452.18555,-9.2328758
2285,2285,195.3463,5.3669848,0.53658527,0.0,0,8.6858435,0.0,0.035524253,66.242004,9.5340824,452.28714,-9.2342863
2287,2287,195.3467,5.6933503,0.60883951,0.0,0,8.6301794,0.0,0.041435435,68.853622,9.4466648,452.38876,-9.2335434
2289,2289,195.3471,5.5042262,0.62121862,0.0,0,8.5745163,0.0,0.041878,68.296097,9.3680191,452.49036,-9.2319565
2291,2291,195.3475,5.2288194,0.70457107,0.0,0,8.5188513,0.0,0.047689606,62.839737,9.3063231,452.59195,-9.233017
2293,2293,195.3479,6.0079103,0.74625289,0.0,0,8.4631872,0.0,0.050959699,72.157753,9.2483902,452.69354,-9.2325954
2295,2295,195.3483,6.015461,0.82184613,0.0,0,8.4075241,0.0,0.055374287,72.398277,9.1824083,452.75497,-9.2311583
2297,2297,195.3487,5.9459119,0.94788444,0.0,0,8.3518591,0.0,0.064712375,71.391068,9.0944014,452.58878,-9.2310209
2299,2299,195.3491,5.5695534,1.0289052,0.0,0,8.296196,0.0,0.070381254,66.351456,9.0118389,452.42258,-9.2333794
2301,2301,195.3495,5.8445511,1.1154696,0.0,0,8.2405319,0.0,0.076591536,68.531281,8.9284716,452.25641,-9.2328348
2303,2303,195.3499,5.9051242,1.1563731,0.0,0,8.1848679,0.0,0.080425821,69.445976,8.8514795,452.09021,-9.2319822
2305,2305,195.3503,6.0026212,1.1938177,0.0,0,8.1292038,0.0,0.082231641,70.370865,8.7876978,451.92401,-9.231288
2307,2307,195.3507,5.7566156,1.2584406,0.0,0,8.0735397,0.0,0.087251745,67.516624,8.7339859,451.75784,-9.2310944
2309,2309,195.3511,6.0799375,1.2926608,0.0,0,8.0196571,0.0,0.090038791,70.043579,8.6845388,451.59164,-9.2316561
2311,2311,195.3515,6.3276386,1.3719032,0.0,0,7.9666901,0.0,0.094807684,73.352219,8.6236401,451.42545,-9.2303629
2313,2313,195.3519,6.1076169,1.4543229,0.0,0,7.9137306,0.0,0.10168195,70.388329,8.5569983,451.25928,-9.2293205
2315,2315,195.3523,6.0805054,1.5184877,0.0,0,7.8607702,0.0,0.10621469,69.720978,8.4851322,451.09308,-9.2300863
2317,2317,195.3527,5.9592376,1.5993626,0.0,0,7.8078103,0.0,0.11198037,67.755989,8.4140558,450.92688,-9.2316141
2319,2319,195.3531,6.1969323,1.6228318,0.0,0,7.7548499,0.0,0.11465882,70.122177,8.3542995,450.76071,-9.2319279
2321,2321,195.3535,6.1000662,1.6706227,0.0,0,7.70189,0.0,0.11741669,69.319847,8.3005991,450.59451,-9.2309895
2323,2323,195.3539,6.149169,1.7339635,0.0,0,7.6489296,0.0,0.12238292,69.083679,8.2495327,450.42831,-9.2305088
2325,2325,195.3543,6.2490411,1.7636344,0.0,0,7.5959702,0.0,0.12501431,70.077408,8.199769,450.26215,-9.2307358
2327,2327,195.3547,6.3937941,1.8344699,0.0,0,7.5430098,0.0,0.129595,71.445663,8.1464243,450.09595,-9.2295895
2329,2329,195.3551,6.299654,1.8977351,0.0,0,7.4900503,0.0,0.13500404,70.238098,8.0896368,449.92975,-9.2307615
2331,2331,195.3555,6.2659488,1.9528453,0.0,0,7.4370899,0.0,0.13905397,69.464714,8.0321512,449.76358,-9.2313251
2333,2333,195.3559,6.2219062,2.0118425,0.0,0,7.3846612,0.0,0.14345945,68.549706,7.9770885,449.59738,-9.2314177
2335,2335,195.3563,6.3952198,2.0401342,0.0,0,7.3341675,0.0,0.1462912,70.141792,7.9245648,449.43118,-9.2307034
2337,2337,195.3567,6.3246942,2.0938175,0.0,0,7.2837992,0.0,0.14971454,69.506844,7.8755641,449.26501,-9.2296305
2339,2339,195.3571,6.3041749,2.1410129,0.0,0,7.2334309,0.0,0.15352291,68.671188,7.8266492,449.09882,-9.2309227
2341,2341,195.3575,6.4287329,2.1787255,0.0,0,7.1830626,0.0,0.15695725,69.856331,7.7835426,448.93262,-9.2319012
2343,2343,195.3579,6.5203576,2.2428923,0.0,0,7.1326947,0.0,0.16121952,70.528557,7.7331905,448.76645,-9.2318134
2345,2345,195.3583,6.538537,2.2895033,0.0,0,7.0823264,0.0,0.16523424,70.625275,7.6816616,448.58264,-9.2306242
2347,2347,195.3587,6.4026852,2.3432245,0.0,0,7.0319586,0.0,0.16967966,68.950928,7.6291804,448.24063,-9.2304001
2349,2349,195.3591,6.4391708,2.3961225,0.0,0,6.9815903,0.0,0.17331026,68.871933,7.5802841,447.89862,-9.2303553
2351,2351,195.3595,6.5493345,2.4275382,0.0,0,6.9312229,0.0,0.17637874,69.819649,7.5295472,447.55658,-9.2318497
2353,2353,195.3599,6.5709295,2.4792054,0.0,0,6.8808546,0.0,0.18024081,69.874763,7.4845042,447.21457,-9.2313404
2355,2355,195.3603,6.5174375,2.5263786,0.0,0,6.8304873,0.0,0.18374096,69.03756,7.4396644,446.87256,-9.2318048
2357,2357,195.3607,6.5994225,2.565244,0.0,0,6.7801185,0.0,0.18740094,69.498512,7.394299,446.53052,-9.2311363
2359,2359,195.3611,6.6439338,2.6169295,0.0,0,6.7313623,0.0,0.1911689,69.76693,7.3458829,446.18851,-9.2299261
2361,2361,195.3615,6.6645026,2.667155,0.0,0,6.6834369,0.0,0.1951458,69.839134,7.2986946,445.8465,-9.2303228
2363,2363,195.3619,6.6538358,2.7125478,0.0,0,6.6355171,0.0,0.19936515,69.388954,7.2520285,445.50446,-9.2308283
2365,2365,195.3623,6.6804414,2.7559254,0.0,0,6.5875969,0.0,0.20244262,69.344261,7.2030334,445.16245,-9.2319145
2367,2367,195.3627,6.7483745,2.8022761,0.0,0,6.5396771,0.0,0.20644104,69.817741,7.155272,444.82043,-9.2320127
2369,2369,195.3631,6.7460618,2.8470948,0.0,0,6.4917574,0.0,0.21030374,69.622353,7.1094956,444.47839,-9.2306728
2371,2371,195.3635,6.782043,2.8925431,0.0,0,6.4438376,0.0,0.21355546,69.651199,7.0616755,444.13638,-9.2303696
2373,2373,195.3639,6.8621016,2.9431899,0.0,0,6.3959169,0.0,0.21837321,70.150291,7.016706,443.79437,-9.2303619
2375,2375,195.3643,6.8850865,2.987752,0.0,0,6.3479972,0.0,0.2218146,70.184685,6.969079,443.45236,-9.2303791
2377,2377,195.3647,6.8891206,3.0371339,0.0,0,6.3000774,0.0,0.22558202,69.982811,6.9198337,443.11032,-9.2319794
2379,2379,195.3651,6.8599486,3.0836077,0.0,0,6.2521577,0.0,0.23019156,69.401825,6.8747792,442.76831,-9.233283
2381,2381,195.3655,6.929224,3.12887,0.0,0,6.2042375,0.0,0.2332909,69.804382,6.8261189,442.4263,-9.2325363
2383,2383,195.3659,6.9922056,3.1783881,0.0,0,6.1567979,0.0,0.23769934,70.217438,6.777535,442.08426,-9.2307901
2385,2385,195.3663,6.9989243,3.2220457,0.0,0,6.1111078,0.0,0.2418482,69.983696,6.7298613,441.74225,-9.2314386
2387,2387,195.3667,6.9914446,3.2736201,0.0,0,6.0655317,0.0,0.24533613,69.685623,6.6823153,441.40024,-9.2319555
2389,2389,195.3671,7.0322652,3.3175166,0.0,0,6.0199556,0.0,0.24978212,69.717369,6.6376352,441.0582,-9.2327833
2391,2391,195.3675,7.1224308,3.358669,0.0,0,5.9743791,0.0,0.25324979,70.228928,6.5901537,440.71619,-9.2313919
2393,2393,195.3679,7.1510234,3.4179871,0.0,0,5.9288034,0.0,0.25759727,70.354858,6.5430899,440.37418,-9.230587
2395,2395,195.3683,7.1345253,3.4593256,0.0,0,5.8832278,0.0,0.26220003,69.912811,6.4928775,440.04172,-9.2304058
2397,2397,195.3687,7.146625,3.5085142,0.0,0,5.8376513,0.0,0.26585695,69.713577,6.4462171,439.8909,-9.2325068
2399,2399,195.3691,7.1847439,3.5666966,0.0,0,5.7920747,0.0,0.27079892,69.79583,6.3963594,439.74005,-9.2334185
2401,2401,195.3695,7.2717657,3.6036062,0.0,0,5.7464995,0.0,0.27480707,70.267761,6.346746,439.5892,-9.2327557
2403,2403,195.3699,7.2869987,3.6528738,0.0,0,5.7009234,0.0,0.27831957,70.174545,6.3008771,439.43835,-9.2313528
2405,2405,195.3703,7.2966356,3.7041159,0.0,0,5.6553473,0.0,0.28324142,69.905464,6.2484169,439.28751,-9.2312288
2407,2407,195.3707,7.330235,3.7442741,0.0,0,5.6097713,0.0,0.28706238,69.962097,6.2020059,439.13669,-9.2310743
2409,2409,195.3711,7.3806553,3.8004894,0.0,0,5.5656543,0.0,0.29133403,70.155563,6.1562943,438.98584,-9.2312012
2411,2411,195.3715,7.4237909,3.8480141,0.0,0,5.5222898,0.0,0.29638228,70.252426,6.1079693,438.83499,-9.2316637
2413,2413,195.3719,7.4531388,3.8940387,0.0,0,5.4789295,0.0,0.30017215,70.254517,6.0572586,438.68414,-9.2307758
2415,2415,195.3723,7.4629569,3.9446816,0.0,0,5.4355693,0.0,0.30441359,70.083,6.0087166,438.53329,-9.23102
2417,2417,195.3727,7.4850554,3.988384,0.0,0,5.3922095,0.0,0.30916572,69.902542,5.9623427,438.38248,-9.2318735
2419,2419,195.3731,7.5213895,4.0396891,0.0,0,5.3488493,0.0,0.31300294,69.920807,5.9128594,438.23163,-9.2326565
2421,2421,195.3735,7.5729361,4.0858541,0.0,0,5.3054895,0.0,0.31746241,70.148972,5.8660827,438.08078,-9.2325506
2423,2423,195.3739,7.6190171,4.1301179,0.0,0,5.2621293,0.0,0.32206076,70.295441,5.8197656,437.92993,-9.2310553
2425,2425,195.3743,7.6194572,4.1846614,0.0,0,5.2187696,0.0,0.32615611,70.014336,5.7710867,437.77908,-9.2303038
2427,2427,195.3747,7.6567297,4.2276473,0.0,0,5.1754098,0.0,0.33075687,69.998169,5.7228136,437.62827,-9.2305689
2429,2429,195.3751,7.7050791,4.2741022,0.0,0,5.1320496,0.0,0.3350738,70.145332,5.6739807,437.47742,-9.2311411
2431,2431,195.3755,7.7504497,4.3305445,0.0,0,5.0886893,0.0,0.33961233,70.229454,5.627665,437.32657,-9.2310467
2433,2433,195.3759,7.7657156,4.3711567,0.0,0,5.045764,0.0,0.34440073,70.08313,5.5794163,437.17572,-9.2314568
2435,2435,195.3763,7.7842407,4.4189086,0.0,0,5.0044203,0.0,0.34848431,70.001137,5.5309682,437.02487,-9.2307777
2437,2437,195.3767,7.8095832,4.470161,0.0,0,4.9631801,0.0,0.35299775,69.846977,5.4863605,436.87405,-9.2310305
2439,2439,195.3771,7.8488245,4.5071063,0.0,0,4.9219403,0.0,0.35741815,69.907272,5.4365835,436.72321,-9.2313232
2441,2441,195.3775,7.9012308,4.5559916,0.0,0,4.8807001,0.0,0.36131978,70.025055,5.3894877,436.57236,-9.2310667
2443,2443,195.3779,7.9243245,4.6098633,0.0,0,4.8394604,0.0,0.36667502,69.925583,5.3466859,436.42151,-9.2303429
2445,2445,195.3783,7.9415045,4.6506896,0.0,0,4.7982202,0.0,0.371075,69.733337,5.2982001,436.27063,-9.2312431
2447,2447,195.3787,7.9775577,4.6993113,0.0,0,4.7569804,0.0,0.37499845,69.750999,5.2517185,435.55823,-9.2321272
2449,2449,195.3791,8.0212479,4.7448254,0.0,0,4.7157402,0.0,0.38022116,69.821632,5.2069287,434.84579,-9.2321301
2451,2451,195.3795,8.052948,4.7866039,0.0,0,4.6745005,0.0,0.38405398,69.825264,5.1616726,434.13339,-9.2321377
2453,2453,195.3799,8.0855427,4.8348088,0.0,0,4.6332603,0.0,0.38832471,69.777824,5.1110487,433.42099,-9.2311039
2455,2455,195.3803,8.1095686,4.87925,0.0,0,4.59202,0.0,0.3936041,69.660675,5.06949,432.70859,-9.2317085
2457,2457,195.3807,8.1144953,4.923914,0.0,0,4.5507803,0.0,0.39727798,69.41877,5.0268011,431.99619,-9.2320204
2459,2459,195.3811,8.1666412,4.9710689,0.0,0,4.5108619,0.0,0.40196389,69.551003,4.9807973,431.28378,-9.2334013
2461,2461,195.3815,8.2052908,5.0105147,0.0,0,4.4716258,0.0,0.40669683,69.529076,4.9369016,430.57135,-9.2331524
2463,2463,195.3819,8.2336044,5.0600147,0.0,0,4.432394,0.0,0.41046014,69.608589,4.8942275,429.85895,-9.2318764
2465,2465,195.3823,8.2515106,5.1027584,0.0,0,4.3931618,0.0,0.41544914,69.359688,4.853097,429.14655,-9.2313108
2467,2467,195.3827,8.2706804,5.1415648,0.0,0,4.35393,0.0,0.41964906,69.249107,4.8044648,428.43414,-9.2313051
2469,2469,195.3831,8.3198605,5.1941409,0.0,0,4.3146982,0.0,0.42389861,69.307297,4.7637086,427.72174,-9.2318296
2471,2471,195.3835,8.3817062,5.2280927,0.0,0,4.275466,0.0,0.42850113,69.50145,4.7167864,427.00934,-9.232234
2473,2473,195.3839,8.4033527,5.2675099,0.0,0,4.2362337,0.0,0.43225747,69.474007,4.6772819,426.29694,-9.2319174
2475,2475,195.3843,8.4067726,5.321537,0.0,0,4.1970015,0.0,0.43719581,69.118324,4.6322331,425.5845,-9.2305536
2477,2477,195.3847,8.4312563,5.355783,0.0,0,4.1577697,0.0,0.44174683,68.976593,4.5908608,424.8721,-9.2309361
2479,2479,195.3851,8.4720201,5.399004,0.0,0,4.1185379,0.0,0.44552729,69.057762,4.5482883,424.1597,-9.2306747
2481,2481,195.3855,8.5313807,5.4477291,0.0,0,4.0793056,0.0,0.45061916,69.206268,4.5068555,423.4473,-9.2314243
2483,2483,195.3859,8.5526438,5.4785662,0.0,0,4.0404677,0.0,0.4545846,69.090294,4.4667554,422.73489,-9.2313042
2485,2485,195.3863,8.55126,5.5217199,0.0,0,4.0030622,0.0,0.45813745,68.814919,4.425859,422.02249,-9.2312574
2487,2487,195.3867,8.5801287,5.5627699,0.0,0,3.9657497,0.0,0.46322498,68.687866,4.3841662,421.31006,-9.231225
2489,2489,195.3871,8.6622114,5.5989337,0.0,0,3.9284377,0.0,0.46702114,69.0429,4.3418026,420.59766,-9.2304544
2491,2491,195.3875,8.7008848,5.6436934,0.0,0,3.8911257,0.0,0.47110704,69.126724,4.3016086,419.88525,-9.2302818
2493,2493,195.3879,8.7059469,5.6805758,0.0,0,3.8538139,0.0,0.47607103,68.843727,4.2629876,419.17285,-9.2310848
2495,2495,195.3883,8.7317572,5.7203841,0.0,0,3.8165019,0.0,0.47969344,68.778122,4.2235813,418.46045,-9.2323742
2497,2497,195.3887,8.7640467,5.762444,0.0,0,3.7791896,0.0,0.48414105,68.748863,4.1868706,418.13229,-9.2320108
2499,2499,195.3891,8.8271275,5.7973242,0.0,0,3.7418776,0.0,0.48877758,68.866364,4.1452627,417.82428,-9.2312078
2501,2501,195.3895,8.8558273,5.8420844,0.0,0,3.7045658,0.0,0.49247631,68.885437,4.1044855,417.5163,-9.230526
2503,2503,195.3899,8.8835621,5.8789811,0.0,0,3.6672537,0.0,0.49703673,68.813171,4.067328,417.20831,-9.2299471
2505,2505,195.3903,8.904233,5.9127169,0.0,0,3.6299417,0.0,0.50124705,68.665024,4.0288858,416.90033,-9.2315674
2507,2507,195.3907,8.9439964,5.9604678,0.0,0,3.5926297,0.0,0.5052098,68.68499,3.9907477,416.59235,-9.2323112
2509,2509,195.3911,9.003397,5.9907365,0.0,0,3.5565133,0.0,0.50977474,68.831856,3.9532955,416.28436,-9.2321157
2511,2511,195.3915,9.0530396,6.0285625,0.0,0,3.5210135,0.0,0.51363868,68.953056,3.9164734,415.97638,-9.2319584
2513,2513,195.3919,9.0541029,6.076417,0.0,0,3.4855173,0.0,0.51828039,68.650276,3.8786902,415.6684,-9.2311993
2515,2515,195.3923,9.074502,6.1057253,0.0,0,3.4500215,0.0,0.52277911,68.496635,3.8393021,415.36041,-9.2304564
2517,2517,195.3927,9.119091,6.144773,0.0,0,3.4145255,0.0,0.52633357,68.58387,3.8031068,415.05243,-9.2310076
2519,2519,195.3931,9.1846008,6.1894441,0.0,0,3.3790293,0.0,0.53131849,68.735962,3.7621622,414.74442,-9.231945
2521,2521,195.3935,9.2238798,6.2182617,0.0,0,3.3435335,0.0,0.53555548,68.756927,3.7270794,414.43643,-9.2308388
2523,2523,195.3939,9.2484055,6.2606778,0.0,0,3.3080375,0.0,0.53926486,68.677711,3.6889622,414.12845,-9.2315426
2525,2525,195.3943,9.2798662,6.3001847,0.0,0,3.2725413,0.0,0.54448926,68.489967,3.6513686,413.82047,-9.231617
2527,2527,195.3947,9.3305407,6.3301907,0.0,0,3.2370453,0.0,0.54813373,68.642319,3.6117306,413.51248,-9.2316637
2529,2529,195.3951,9.3903856,6.3728423,0.0,0,3.2015493,0.0,0.55218267,68.775352,3.575747,413.2045,-9.2303038
2531,2531,195.3955,9.4190435,6.4073539,0.0,0,3.1660533,0.0,0.55716825,68.719185,3.5413668,412.89651,-9.2310257
2533,2533,195.3959,9.4562016,6.4423289,0.0,0,3.1309118,0.0,0.56079662,68.660187,3.5035229,412.58853,-9.2298985
2535,2535,195.3963,9.4859352,6.4814711,0.0,0,3.0970592,0.0,0.56501675,68.612198,3.468025,412.28055,-9.2305536
2537,2537,195.3967,9.5364771,6.5144024,0.0,0,3.0632911,0.0,0.56999242,68.606247,3.4330306,411.97256,-9.2310705
2539,2539,195.3971,9.5898733,6.5534987,0.0,0,3.0295231,0.0,0.57338071,68.777138,3.3914337,411.66458,-9.2308168
2541,2541,195.3975,9.638483,6.5898743,0.0,0,2.9957552,0.0,0.57813948,68.791847,3.3579845,411.35657,-9.2305927
2543,2543,195.3979,9.6733541,6.6194572,0.0,0,2.9619873,0.0,0.58241373,68.756233,3.3238511,411.04858,-9.2304726
2545,2545,195.3983,9.705637,6.6635604,0.0,0,2.9282191,0.0,0.58620107,68.727608,3.2858002,410.7406,-9.2302866
2547,2547,195.3987,9.7570181,6.6938472,0.0,0,2.8944509,0.0,0.59090865,68.769547,3.2524178,410.42499,-9.2305145
2549,2549,195.3991,9.8295517,6.7277713,0.0,0,2.860683,0.0,0.59484482,68.994232,3.2164865,410.10852,-9.2319365
2551,2551,195.3995,9.8745546,6.7738385,0.0,0,2.826915,0.0,0.59936893,68.998955,3.184633,409.79205,-9.231061
2553,2553,195.3999,9.9017019,6.8011646,0.0,0,2.7931471,0.0,0.60428488,68.860573,3.1456988,409.47559,-9.2308903
2555,2555,195.4003,9.9302311,6.8366532,0.0,0,2.7593791,0.0,0.60780096,68.828804,3.1124754,409.15912,-9.2298498
2557,2557,195.4007,9.9852543,6.8772149,0.0,0,2.7256112,0.0,0.61250395,68.867462,3.0771141,408.84265,-9.2304764
2559,2559,195.4011,10.048627,6.9013476,0.0,0,2.6929281,0.0,0.61665964,69.015671,3.0415373,408.52618,-9.2307138
2561,2561,195.4015,10.102455,6.9427948,0.0,0,2.6608045,0.0,0.62045109,69.168221,3.0060847,408.20972,-9.2303114
2563,2563,195.4019,10.133484,6.9831886,0.0,0,2.6286843,0.0,0.62612641,68.998596,2.9728322,407.89325,-9.2298603
2565,2565,195.4023,10.170006,7.0106001,0.0,0,2.5965643,0.0,0.62989879,68.93528,2.9377618,407.57678,-9.2313509
2567,2567,195.4027,10.248567,7.0490446,0.0,0,2.5644443,0.0,0.63375825,69.175217,2.9012268,407.26031,-9.2310286
2569,2569,195.4031,10.32851,7.0821571,0.0,0,2.5323241,0.0,0.63912934,69.348694,2.8683827,406.94385,-9.230442
2571,2571,195.4035,10.373034,7.1146517,0.0,0,2.5002043,0.0,0.6426912,69.432243,2.8307922,406.62738,-9.2297907
2573,2573,195.4039,10.386333,7.1526003,0.0,0,2.4680843,0.0,0.64706862,69.268547,2.7995613,406.31091,-9.2303505
2575,2575,195.4043,10.431395,7.1838202,0.0,0,2.4359643,0.0,0.65221077,69.090782,2.7650278,405.99445,-9.2304316
2577,2577,195.4047,10.494667,7.2227783,0.0,0,2.4038444,0.0,0.65587717,69.281319,2.7299304,405.67798,-9.2298498
2579,2579,195.4051,10.589343,7.2577019,0.0,0,2.3717244,0.0,0.66070402,69.611076,2.6955733,405.36151,-9.2289553
2581,2581,195.4055,10.627437,7.2845764,0.0,0,2.3396041,0.0,0.66516262,69.585358,2.6623805,405.04504,-9.2293682
2583,2583,195.4059,10.650205,7.3265061,0.0,0,2.307806,0.0,0.66899216,69.394783,2.6282952,404.72858,-9.2302027
2585,2585,195.4063,10.697728,7.3541622,0.0,0,2.2771773,0.0,0.67376924,69.40583,2.5928774,404.41211,-9.2304077
2587,2587,195.4067,10.773342,7.3849187,0.0,0,2.2466252,0.0,0.6777125,69.598083,2.5595584,404.09564,-9.2303391
2589,2589,195.4071,10.859607,7.4279613,0.0,0,2.2160735,0.0,0.68215543,69.812546,2.5259221,403.77917,-9.229744
2591,2591,195.4075,10.900528,7.454628,0.0,0,2.1855214,0.0,0.68740249,69.775482,2.4932313,403.46271,-9.2294083
2593,2593,195.4079,10.923557,7.4889073,0.0,0,2.1549692,0.0,0.6910429,69.650208,2.4600174,403.14624,-9.2292261
2595,2595,195.4083,10.975993,7.5289497,0.0,0,2.1244173,0.0,0.69602102,69.639343,2.4278121,402.82977,-9.2288523
2597,2597,195.4087,11.056849,7.5501738,0.0,0,2.0938654,0.0,0.70027077,69.816078,2.3962035,401.94043,-9.2295561
2599,2599,195.4091,11.128707,7.5865507,0.0,0,2.0633135,0.0,0.70365196,70.141113,2.3616197,400.95004,-9.2300911
2601,2601,195.4095,11.167154,7.6244364,0.0,0,2.0327616,0.0,0.70940965,69.987617,2.3274469,399.95966,-9.2300367
2603,2603,195.4099,11.203661,7.649734,0.0,0,2.0022092,0.0,0.71340507,69.900124,2.2986157,398.96924,-9.2303696
2605,2605,195.4103,11.280117,7.6871943,0.0,0,1.9716572,0.0,0.71725953,70.051849,2.265209,397.97885,-9.2296848
2607,2607,195.4107,11.364336,7.719378,0.0,0,1.9411051,0.0,0.7228514,70.204514,2.2328126,396.98846,-9.2291288
2609,2609,195.4111,11.431712,7.7468758,0.0,0,1.9115326,0.0,0.72637773,70.372299,2.2003045,395.99808,-9.2291002
2611,2611,195.4115,11.480683,7.7855616,0.0,0,1.8824656,0.0,0.73086953,70.314194,2.1700084,395.00769,-9.2300529
2613,2613,195.4119,11.521415,7.8130651,0.0,0,1.8534015,0.0,0.73609948,70.161171,2.1364105,394.0173,-9.2304506
2615,2615,195.4123,11.580363,7.8450241,0.0,0,1.8243376,0.0,0.73947227,70.35746,2.1048226,393.02692,-9.230197
2617,2617,195.4127,11.666102,7.8777556,0.0,0,1.7952735,0.0,0.74420381,70.534279,2.0731614,392.03653,-9.228919
2619,2619,195.4131,11.72754,7.9037056,0.0,0,1.7662096,0.0,0.7489087,70.607063,2.0424609,391.04614,-9.2284765
2621,2621,195.4135,11.783222,7.9414411,0.0,0,1.7371455,0.0,0.75260532,70.657127,2.009639,390.05576,-9.2310152
2623,2623,195.4139,11.846538,7.9713516,0.0,0,1.7080816,0.0,0.7578122,70.6082,1.9781613,389.06534,-9.2306271
2625,2625,195.4143,11.921044,7.9993963,0.0,0,1.6790177,0.0,0.76204419,70.77037,1.9483294,388.07495,-9.2305746
2627,2627,195.4147,12.016995,8.0398788,0.0,0,1.6499536,0.0,0.76637274,71.015038,1.9187945,387.08456,-9.2288885
2629,2629,195.4151,12.082128,8.0630856,0.0,0,1.6208895,0.0,0.77138925,71.136665,1.8877399,386.09418,-9.2289686
2631,2631,195.4155,12.132195,8.0920029,0.0,0,1.5918256,0.0,0.77490747,71.153473,1.8564067,385.10379,-9.2294846
2633,2633,195.4159,12.178633,8.1330385,0.0,0,1.5630522,0.0,0.78000486,71.06749,1.825039,384.1134,-9.2300301
2635,2635,195.4163,12.250302,8.1540508,0.0,0,1.5353347,0.0,0.78481656,71.131126,1.7934574,383.12302,-9.2289391
2637,2637,195.4167,12.342051,8.1866579,0.0,0,1.5076866,0.0,0.78822207,71.396645,1.7635862,382.13263,-9.2291985
2639,2639,195.4171,12.427723,8.2221279,0.0,0,1.4800386,0.0,0.79372174,71.525101,1.7339815,381.14224,-9.2287588
2641,2641,195.4175,12.475992,8.2420969,0.0,0,1.4523906,0.0,0.79765183,71.520622,1.7046165,380.15186,-9.2287369
2643,2643,195.4179,12.537127,8.2772207,0.0,0,1.4247426,0.0,0.80122572,71.570404,1.6758323,379.16147,-9.2290907
2645,2645,195.4183,12.611218,8.3073463,0.0,0,1.3970947,0.0,0.8070848,71.615135,1.6492808,378.17105,-9.2287407
2647,2647,195.4187,12.705909,8.3338575,0.0,0,1.3694466,0.0,0.81092674,71.893639,1.6204977,377.62268,-9.227788
2649,2649,195.4191,12.793537,8.3702278,0.0,0,1.3417987,0.0,0.81525534,72.041534,1.5872486,377.18472,-9.2285376
2651,2651,195.4195,12.847538,8.3950777,0.0,0,1.3141507,0.0,0.82072914,71.956184,1.5593162,376.74677,-9.2277575
2653,2653,195.4199,12.914078,8.4241276,0.0,0,1.2865027,0.0,0.82389712,72.110168,1.5271558,376.30881,-9.2276688
2655,2655,195.4203,12.987034,8.4558964,0.0,0,1.2588546,0.0,0.82853711,72.182411,1.499423,375.87088,-9.2282705
2657,2657,195.4207,13.090072,8.4779482,0.0,0,1.2312068,0.0,0.83356535,72.352562,1.4691241,375.43292,-9.2289248
2659,2659,195.4211,13.18543,8.5144053,0.0,0,1.2044488,0.0,0.83719683,72.659157,1.4393132,374.99496,-9.2280235
2661,2661,195.4215,13.253983,8.5423632,0.0,0,1.1781499,0.0,0.84248143,72.659233,1.4071267,374.55701,-9.2277069
2663,2663,195.4219,13.318184,8.5670023,0.0,0,1.1518539,0.0,0.84681159,72.645828,1.3829492,374.11905,-9.2293997
2665,2665,195.4223,13.410365,8.6053257,0.0,0,1.1255579,0.0,0.85096955,72.835518,1.3510906,373.68112,-9.2290974
2667,2667,195.4227,13.524437,8.6264524,0.0,0,1.0992619,0.0,0.85610604,73.088043,1.3236951,373.24316,-9.2287569
2669,2669,195.4231,13.618417,8.6535959,0.0,0,1.0729659,0.0,0.85979426,73.357285,1.2932664,372.80521,-9.2267933
2671,2671,195.4235,13.669315,8.6916246,0.0,0,1.0466698,0.0,0.86474645,73.295242,1.2665509,372.36725,-9.2271891
2673,2673,195.4239,13.731774,8.7096701,0.0,0,1.0203738,0.0,0.86967683,73.281464,1.2412419,371.92929,-9.2285376
2675,2675,195.4243,13.837955,8.7395554,0.0,0,0.9940778,0.0,0.87279987,73.540627,1.2102823,371.49133,-9.2294569
2677,2677,195.4247,13.952521,8.7738609,0.0,0,0.96778184,0.0,0.878295,73.744888,1.1838404,371.05341,-9.2294846
2679,2679,195.4251,14.033651,8.7916555,0.0,0,0.94148582,0.0,0.88252157,73.890266,1.1547711,370.61545,-9.2280254
2681,2681,195.4255,14.101272,8.824769,0.0,0,0.91518986,0.0,0.88608968,73.972198,1.1314918,370.17749,-9.2282867
2683,2683,195.4259,14.177156,8.8553371,0.0,0,0.88915813,0.0,0.89235294,73.909821,1.1017985,369.73953,-9.2272844
2685,2685,195.4263,14.278922,8.8765144,0.0,0,0.86408705,0.0,0.89600211,74.148033,1.0750543,369.30157,-9.2279854
2687,2687,195.4267,14.393107,8.9081306,0.0,0,0.83907896,0.0,0.89993316,74.434166,1.0441728,368.86365,-9.229291
2689,2689,195.4271,14.46664,8.9325533,0.0,0,0.81407094,0.0,0.90569896,74.44735,1.0187196,368.42569,-9.2289734
2691,2691,195.4275,14.533674,8.958951,0.0,0,0.78906298,0.0,0.90882927,74.516983,0.99230099,367.98773,-9.2284317
2693,2693,195.4279,14.623762,8.9882317,0.0,0,0.76405495,0.0,0.91328895,74.619186,0.96413887,367.54977,-9.2274656
2695,2695,195.4283,14.724689,9.0085068,0.0,0,0.73904693,0.0,0.91851056,74.773628,0.93892348,367.11182,-9.2269564
2697,2697,195.4287,14.847854,9.041317,0.0,0,0.71403897,0.0,0.92181951,75.134056,0.91004103,366.96887,-9.2265358
2699,2699,195.4291,14.945932,9.0670204,0.0,0,0.68903095,0.0,0.92718703,75.187988,0.88462871,366.92422,-9.2263575
2701,2701,195.4295,15.019,9.0889492,0.0,0,0.66402298,0.0,0.93172204,75.297226,0.85595536,366.87958,-9.2272139
2703,2703,195.4299,15.115892,9.1243544,0.0,0,0.63901496,0.0,0.93552488,75.469574,0.82788748,366.83493,-9.2281237
2705,2705,195.4303,15.235437,9.143919,0.0,0,0.61400694,0.0,0.94057983,75.653145,0.80248785,366.79028,-9.2276144
2707,2707,195.4307,15.344893,9.16675,0.0,0,0.58899897,0.0,0.94421959,75.957291,0.777771,366.74561,-9.226819
2709,2709,195.4311,15.433632,9.201828,0.0,0,0.5647862,0.0,0.94885474,76.053329,0.75033981,366.70096,-9.2279301
2711,2711,195.4315,15.504444,9.2181215,0.0,0,0.54098368,0.0,0.95388621,76.026649,0.72261316,366.65631,-9.2286472
2713,2713,195.4319,15.599278,9.2422304,0.0,0,0.5171836,0.0,0.95683312,76.247955,0.69866228,366.61166,-9.2273836
2715,2715,195.4323,15.718949,9.2773714,0.0,0,0.49338362,0.0,0.96237689,76.417809,0.67372841,366.56702,-9.2263641
2717,2717,195.4327,15.837656,9.2922306,0.0,0,0.46958363,0.0,0.96684158,76.655891,0.64835173,366.52237,-9.2260027
2719,2719,195.4331,15.922447,9.3217554,0.0,0,0.44578362,0.0,0.97003716,76.801842,0.62441808,366.47769,-9.227685
2721,2721,195.4335,16.004,9.3493376,0.0,0,0.42198363,0.0,0.97609913,76.758224,0.59864128,366.43304,-9.2275686
2723,2723,195.4339,16.112513,9.3669977,0.0,0,0.39818361,0.0,0.97955966,77.015808,0.5736298,366.3884,-9.227272
2725,2725,195.4343,16.246382,9.3975191,0.0,0,0.3743836,0.0,0.98329347,77.34185,0.55155402,366.34375,-9.2272291