File: clean data/testID_0245.csv
level_0,index,Time(sec),Force(kN),Jaw(mm),PowAngle(deg),Power(W),Pram,PTemp,Strain,Stress(MPa),Stroke(mm),TC1(C),wedge(mm)
2248,2248,178.7056,1.6227682,0.012118792,0.0,0,9.9638634,0.0,0.0010044904,20.331347,10.064975,399.59134,-9.2652025
2259,2259,178.7078,2.7262118,0.02309089,0.0,0,9.9308634,0.0,0.0013485744,34.422108,10.036452,400.2919,-9.2628241
2270,2270,178.71,3.7200587,0.034919318,0.0,0,9.8978634,0.0,0.0024866182,47.021538,10.00747,400.99243,-9.2606993
2281,2281,178.7122,4.051724,0.069671564,0.0,0,9.8648634,0.0,0.0044694794,51.312946,9.9718571,401.69296,-9.2621469
2292,2292,178.7144,4.266449,0.10485426,0.0,0,9.8318634,0.0,0.0071682539,53.84391,9.9362459,402.72156,-9.2609587
2303,2303,178.7166,4.4057417,0.14509819,0.0,0,9.7988634,0.0,0.0093839085,55.566582,9.8966656,403.8847,-9.2602901
2314,2314,178.7188,4.5012512,0.17536421,0.0,0,9.7658634,0.0,0.011897066,56.649693,9.8541832,405.04785,-9.2608662
2325,2325,178.721,4.5963173,0.2123711,0.0,0,9.7328634,0.0,0.014121108,57.647362,9.8223076,406.211,-9.2603073
2336,2336,178.7232,4.6399455,0.24545649,0.0,0,9.6998634,0.0,0.016646137,58.127445,9.7862549,407.2955,-9.2616158
2347,2347,178.7254,4.7089143,0.28309843,0.0,0,9.6668634,0.0,0.018761808,58.830471,9.7532864,407.9498,-9.2617416
2358,2358,178.7276,4.7268209,0.30931464,0.0,0,9.6338634,0.0,0.020968251,58.96497,9.7161703,408.60406,-9.2619534
2369,2369,178.7298,4.7706952,0.34432298,0.0,0,9.6008635,0.0,0.023063477,59.362339,9.6847734,409.25833,-9.2610054
2380,2380,178.732,4.7944655,0.37501448,0.0,0,9.5678635,0.0,0.025419736,59.627045,9.6525822,409.9126,-9.2613106
2391,2391,178.7342,4.8166666,0.41235909,0.0,0,9.5348635,0.0,0.027660899,59.631607,9.6185141,410.24966,-9.2618608
2402,2402,178.7364,4.8251848,0.43884623,0.0,0,9.5018635,0.0,0.029765297,59.562794,9.5835867,410.37521,-9.2641783
2413,2413,178.7386,4.8355055,0.47322923,0.0,0,9.4691811,0.0,0.031903386,59.577713,9.5488472,410.50079,-9.2627001
2424,2424,178.7408,4.8448477,0.50031829,0.0,0,9.4369907,0.0,0.03397375,59.658051,9.5194349,410.62634,-9.2616463
2435,2435,178.743,4.8903527,0.53753483,0.0,0,9.4048004,0.0,0.03631404,60.073624,9.4878588,410.8035,-9.261673
2446,2446,178.7452,4.9462748,0.56450593,0.0,0,9.3726101,0.0,0.038394321,60.547894,9.4553413,412.06366,-9.2617779
2457,2457,178.7474,4.9546294,0.59858477,0.0,0,9.3404198,0.0,0.040659752,60.576958,9.4228153,413.32385,-9.2618742
2468,2468,178.7496,4.9906974,0.62973613,0.0,0,9.3082294,0.0,0.04287485,60.878578,9.3886833,414.58401,-9.2628002
2479,2479,178.7518,5.014215,0.67094386,0.0,0,9.2760391,0.0,0.045648441,60.904713,9.3547077,415.84418,-9.2624102
2490,2490,178.754,5.0154786,0.70096219,0.0,0,9.2438488,0.0,0.04780015,60.897064,9.3129234,417.79669,-9.2616701
2501,2501,178.7562,5.0261788,0.73611313,0.0,0,9.2116575,0.0,0.050299987,60.891781,9.2840376,420.46722,-9.2626734
2512,2512,178.7584,5.0201254,0.76851773,0.0,0,9.1794672,0.0,0.05252457,60.601402,9.2442141,423.13773,-9.2625608
2523,2523,178.7606,5.0273504,0.80351669,0.0,0,9.1472769,0.0,0.05510902,60.502144,9.2160234,425.80823,-9.2632408
2534,2534,178.7628,5.0226231,0.83036959,0.0,0,9.1150866,0.0,0.056796819,60.357899,9.1814861,428.47876,-9.2626104
2545,2545,178.765,5.0497074,0.85896057,0.0,0,9.0828962,0.0,0.05903269,60.626244,9.1550827,430.12936,-9.2616587
2556,2556,178.7672,5.0578918,0.88886672,0.0,0,9.0507059,0.0,0.060873888,60.618763,9.1244154,431.71066,-9.2614918
2567,2567,178.7694,5.0770931,0.9217872,0.0,0,9.0185156,0.0,0.063575417,60.658768,9.0907469,433.29199,-9.2629118
2578,2578,178.7716,5.0891018,0.95461422,0.0,0,8.9863253,0.0,0.065515131,60.746788,9.0561485,434.87329,-9.2638931
2589,2589,178.7738,5.1204691,0.9837752,0.0,0,8.9541349,0.0,0.067944229,60.951637,9.0280352,436.14749,-9.2624063
2600,2600,178.776,5.1312709,1.0180088,0.0,0,8.9219446,0.0,0.070061766,60.861408,8.9948673,436.92444,-9.2623787
2611,2611,178.7782,5.1539726,1.0514951,0.0,0,8.8897533,0.0,0.072856538,60.997883,8.9578733,437.70142,-9.2631149
2622,2622,178.7804,5.1754951,1.0872345,0.0,0,8.857563,0.0,0.074955255,61.063343,8.9225512,438.47836,-9.2624912
2633,2633,178.7826,5.2191653,1.1159395,0.0,0,8.8253727,0.0,0.077479772,61.378838,8.8926353,439.25534,-9.2629251
2644,2644,178.7848,5.2154198,1.1478596,0.0,0,8.7931824,0.0,0.079413854,61.327305,8.8575697,440.0213,-9.2626963
2655,2655,178.787,5.2165275,1.1779913,0.0,0,8.7609921,0.0,0.08203695,61.214157,8.8253078,440.785,-9.261467
2666,2666,178.7892,5.210053,1.2158309,0.0,0,8.7298489,0.0,0.084174782,61.008579,8.7930832,441.54871,-9.2605286
2677,2677,178.7914,5.2227325,1.2431833,0.0,0,8.6992331,0.0,0.086654961,61.080425,8.7631378,442.31241,-9.2617426
2688,2688,178.7936,5.2256088,1.2757049,0.0,0,8.6686182,0.0,0.088635534,60.952553,8.7317038,442.97726,-9.2633629
2699,2699,178.7958,5.2196426,1.3044254,0.0,0,8.6380024,0.0,0.091229968,60.688644,8.6977501,443.37854,-9.2635422
2710,2710,178.798,5.2415142,1.3417258,0.0,0,8.6073875,0.0,0.093338579,60.731346,8.6642551,443.77982,-9.263773
2721,2721,178.8002,5.2609506,1.3652319,0.0,0,8.5767736,0.0,0.095585361,60.852627,8.635952,444.18109,-9.2622013
2732,2732,178.8024,5.2618966,1.3971484,0.0,0,8.5461569,0.0,0.097505324,60.798702,8.6057138,444.58234,-9.2615767
2743,2743,178.8046,5.2852044,1.4206419,0.0,0,8.515542,0.0,0.099699073,60.873623,8.5802469,444.75681,-9.2612839
2754,2754,178.8068,5.2819748,1.458316,0.0,0,8.4849262,0.0,0.10198394,60.765617,8.5468035,444.84229,-9.2620716
2765,2765,178.809,5.3199329,1.4826945,0.0,0,8.4543123,0.0,0.10421133,61.106125,8.5131741,444.92773,-9.2622204
2776,2776,178.8112,5.3325481,1.5162352,0.0,0,8.4236965,0.0,0.10641549,61.091732,8.4819546,445.01321,-9.2621946
2787,2787,178.8134,5.3370237,1.5460662,0.0,0,8.3930817,0.0,0.10889719,61.005718,8.4485521,445.09866,-9.2628775
2798,2798,178.8156,5.3334446,1.5830798,0.0,0,8.3624659,0.0,0.11137628,60.744232,8.4199696,445.18414,-9.2634058
2809,2809,178.8178,5.3601184,1.6075674,0.0,0,8.331852,0.0,0.11337509,60.908493,8.3869982,445.26959,-9.2628803
2820,2820,178.82,5.3754807,1.6371263,0.0,0,8.3012362,0.0,0.11544926,60.874035,8.3600044,445.35507,-9.2625046
2831,2831,178.8222,5.3937721,1.6646414,0.0,0,8.2706213,0.0,0.11762336,61.075241,8.3304367,445.44052,-9.262804
2842,2842,178.8244,5.4087133,1.700206,0.0,0,8.2400064,0.0,0.12024435,60.980476,8.2971306,445.67416,-9.2610483
2853,2853,178.8266,5.4215093,1.7265618,0.0,0,8.2093916,0.0,0.12223044,61.191837,8.270853,446.00287,-9.2634125
2864,2864,178.8288,5.4206796,1.7578825,0.0,0,8.1787748,0.0,0.12468341,60.989132,8.2397699,446.33157,-9.2629919
2875,2875,178.831,5.4373622,1.7868656,0.0,0,8.14816,0.0,0.12676093,61.041912,8.2082596,446.66028,-9.2615604
2886,2886,178.8332,5.4605184,1.8228414,0.0,0,8.1175451,0.0,0.12959409,60.972843,8.1749573,446.98721,-9.2612476
2897,2897,178.8354,5.4835453,1.8541954,0.0,0,8.0869303,0.0,0.13177672,61.201683,8.1427221,447.28305,-9.2618446
2908,2908,178.8376,5.5070009,1.8841747,0.0,0,8.0563145,0.0,0.134239,61.380386,8.1143694,447.57889,-9.2627916
2919,2919,178.8398,5.5318279,1.912257,0.0,0,8.0270939,0.0,0.13620526,61.452408,8.0771694,447.87473,-9.2607298
2930,2930,178.842,5.5438013,1.9469724,0.0,0,7.9979653,0.0,0.13914734,61.450871,8.0469151,448.17056,-9.2620859
2941,2941,178.8442,5.5295005,1.9797162,0.0,0,7.9688373,0.0,0.14123526,61.134228,8.0153971,448.41708,-9.2616491
2952,2952,178.8464,5.5198231,2.0045795,0.0,0,7.9397097,0.0,0.14357132,60.909607,7.9848809,448.61432,-9.2609816
2963,2963,178.8486,5.5142183,2.0318635,0.0,0,7.9105816,0.0,0.14533076,60.706013,7.9563479,448.81152,-9.2624826
2974,2974,178.8508,5.5169554,2.0635195,0.0,0,7.881453,0.0,0.14824785,60.60815,7.9270372,449.00876,-9.262639
2985,2985,178.853,5.5336032,2.0952582,0.0,0,7.8523254,0.0,0.15010417,60.576145,7.8992915,449.20599,-9.2626333
2996,2996,178.8552,5.5624342,2.1184707,0.0,0,7.8231974,0.0,0.15241073,60.814972,7.867106,449.26025,-9.2617836
3007,3007,178.8574,5.6045218,2.1483974,0.0,0,7.7940698,0.0,0.15434156,61.120213,7.8436608,449.30627,-9.2613935
3018,3018,178.8596,5.627008,2.1764767,0.0,0,7.7649412,0.0,0.15701085,61.107536,7.8060236,449.35229,-9.2607632
3029,3029,178.8618,5.6363363,2.2110329,0.0,0,7.7358131,0.0,0.15903659,61.19912,7.779469,449.39832,-9.2609091
3040,3040,178.864,5.6314526,2.2347531,0.0,0,7.7066855,0.0,0.16156003,60.960342,7.7463369,449.43661,-9.2614422
3051,3051,178.8662,5.6342244,2.2678285,0.0,0,7.6775575,0.0,0.16362499,60.938026,7.7184558,449.46292,-9.2623692
3062,3062,178.8684,5.6339741,2.2953343,0.0,0,7.6484294,0.0,0.16637702,60.76553,7.6882019,449.4892,-9.2630491
3073,3073,178.8706,5.6524439,2.3296325,0.0,0,7.6193013,0.0,0.16833705,60.796688,7.6590772,449.5155,-9.2616539
3084,3084,178.8728,5.661674,2.3514254,0.0,0,7.5901732,0.0,0.17067687,60.800323,7.6291852,449.54181,-9.2613602
3095,3095,178.875,5.6863661,2.3819976,0.0,0,7.5610456,0.0,0.17267215,60.77663,7.6010785,449.08426,-9.2622309
3106,3106,178.8772,5.7252989,2.4071803,0.0,0,7.5319176,0.0,0.17523739,61.161079,7.5700364,448.53201,-9.2603931
3117,3117,178.8794,5.7535787,2.4434414,0.0,0,7.5027895,0.0,0.17746994,61.341766,7.5438933,447.97977,-9.2618408
3128,3128,178.8816,5.7304578,2.4683912,0.0,0,7.4736614,0.0,0.17994249,60.944958,7.5117989,447.42755,-9.2618828
3139,3139,178.8838,5.7247486,2.4986694,0.0,0,7.4445333,0.0,0.18203872,60.79982,7.4825091,446.83084,-9.2618275
3150,3150,178.886,5.7337613,2.5241408,0.0,0,7.4154053,0.0,0.18440577,60.731529,7.4532123,446.12082,-9.2618017
3161,3161,178.8882,5.7289977,2.5582619,0.0,0,7.3865771,0.0,0.18675311,60.486439,7.4265699,445.41077,-9.262105
3172,3172,178.8904,5.7679887,2.5814769,0.0,0,7.3588748,0.0,0.18895108,60.745403,7.3975148,444.70074,-9.2631874
3183,3183,178.8926,5.7808156,2.60852,0.0,0,7.3311725,0.0,0.1908917,60.769947,7.367507,443.99069,-9.2634726
3194,3194,178.8948,5.8232169,2.635314,0.0,0,7.3034697,0.0,0.19325435,61.065739,7.3394737,443.73969,-9.2621365
3205,3205,178.897,5.8561087,2.6732929,0.0,0,7.2757673,0.0,0.1961188,61.297195,7.3088679,443.6608,-9.2626371
3216,3216,178.8992,5.8767815,2.6987081,0.0,0,7.248065,0.0,0.19833858,61.277622,7.2791586,443.58191,-9.2616024
3227,3227,178.9014,5.8361034,2.7274706,0.0,0,7.2203627,0.0,0.2006595,60.842319,7.2497573,443.50302,-9.2625017
3238,3238,178.9036,5.8050861,2.7506144,0.0,0,7.1926603,0.0,0.20258296,60.410767,7.2232709,443.46729,-9.261632
3249,3249,178.9058,5.796515,2.7826912,0.0,0,7.1649575,0.0,0.20521787,60.006512,7.1992192,443.63821,-9.2627096
3260,3260,178.908,5.8080864,2.8061612,0.0,0,7.1372557,0.0,0.20696647,60.071777,7.1751561,443.80917,-9.2626562
3271,3271,178.9102,5.8499017,2.8314531,0.0,0,7.1095533,0.0,0.20923872,60.352665,7.1460538,443.98013,-9.2623453
3282,3282,178.9124,5.8922391,2.8560948,0.0,0,7.0818505,0.0,0.21106528,60.71936,7.116375,444.15109,-9.2610445
3293,3293,178.9146,5.913075,2.8874443,0.0,0,7.0541482,0.0,0.21396846,60.750694,7.0891461,444.36267,-9.262188
3304,3304,178.9168,5.9384694,2.9168799,0.0,0,7.0264459,0.0,0.21595381,60.924274,7.0636854,444.59933,-9.2623444
3315,3315,178.919,5.9412284,2.9415081,0.0,0,6.9987435,0.0,0.21846011,60.862442,7.0341558,444.836,-9.2621803
3326,3326,178.9212,5.9367771,2.9690461,0.0,0,6.9710412,0.0,0.22037461,60.60952,7.0035,445.07266,-9.2616386
3337,3337,178.9234,5.9391136,2.9983816,0.0,0,6.9433384,0.0,0.22320856,60.395531,6.9769049,445.30893,-9.2601423
3348,3348,178.9256,5.9455118,3.0279527,0.0,0,6.9156365,0.0,0.22517142,60.457783,6.9510994,445.53903,-9.2607937
3359,3359,178.9278,5.9655457,3.0515938,0.0,0,6.8879337,0.0,0.22767136,60.378635,6.9253855,445.76913,-9.2619371
3370,3370,178.93,6.0046897,3.0826807,0.0,0,6.8602314,0.0,0.22974406,60.681705,6.8911915,445.99924,-9.2610359
3381,3381,178.9322,6.0231419,3.1092112,0.0,0,6.8325291,0.0,0.232501,60.727707,6.8632627,446.22934,-9.2618761
3392,3392,178.9344,6.0359778,3.1403615,0.0,0,6.8048267,0.0,0.23453477,60.764008,6.8367066,446.41592,-9.2601862
3403,3403,178.9366,6.0398784,3.1624243,0.0,0,6.7771239,0.0,0.23701081,60.626427,6.8095918,446.56055,-9.2611332
3414,3414,178.9388,6.0326467,3.1902347,0.0,0,6.750072,0.0,0.23890807,60.538486,6.7810807,446.70517,-9.2601461
3425,3425,178.941,6.0353627,3.2155154,0.0,0,6.7237158,0.0,0.24155739,60.348976,6.7567763,446.84979,-9.2610226
3436,3436,178.9432,6.0535336,3.2496324,0.0,0,6.69736,0.0,0.24356464,60.446758,6.7261996,446.99445,-9.2617445
3447,3447,178.9454,6.0780177,3.2717431,0.0,0,6.6710038,0.0,0.24629948,60.512779,6.6979232,447.22064,-9.2618265
3458,3458,178.9476,6.0819125,3.2998955,0.0,0,6.6446481,0.0,0.24827243,60.435005,6.6674447,447.45074,-9.2612858
3469,3469,178.9498,6.0821962,3.3243575,0.0,0,6.6182923,0.0,0.25088638,60.181595,6.6444211,447.68085,-9.2623224
3480,3480,178.952,6.0804114,3.3565619,0.0,0,6.5919356,0.0,0.25293842,60.082455,6.6170669,447.91095,-9.261754
3491,3491,178.9542,6.1057487,3.3761418,0.0,0,6.5655799,0.0,0.25523108,60.235001,6.5911064,448.16998,-9.2616396
3502,3502,178.9564,6.1114917,3.4017873,0.0,0,6.5392241,0.0,0.25697169,60.15033,6.5645618,448.47238,-9.2601976
3513,3513,178.9586,6.1190662,3.4240196,0.0,0,6.5128679,0.0,0.25935486,60.084358,6.5407262,448.77478,-9.2616234
3524,3524,178.9608,6.103343,3.4572184,0.0,0,6.4865122,0.0,0.26170671,59.771801,6.5125966,449.07718,-9.2624788
3535,3535,178.963,6.1110315,3.4759698,0.0,0,6.460156,0.0,0.26373765,59.737602,6.4892936,449.37961,-9.2628508
3546,3546,178.9652,6.1592174,3.5077097,0.0,0,6.4338002,0.0,0.2662335,60.046711,6.4601455,449.55972,-9.262145
3557,3557,178.9674,6.1957531,3.5299468,0.0,0,6.407444,0.0,0.26831037,60.229668,6.4368873,449.7175,-9.2607937
3568,3568,178.9696,6.2154784,3.5591123,0.0,0,6.3810883,0.0,0.27059749,60.36013,6.4105716,449.87531,-9.2609386
3579,3579,178.9718,6.2419419,3.5820122,0.0,0,6.354732,0.0,0.2729266,60.513695,6.3842525,450.03308,-9.2611399
3590,3590,178.974,6.2745233,3.6137438,0.0,0,6.3283763,0.0,0.27556059,60.624104,6.3514304,450.19086,-9.2612095
3601,3601,178.9762,6.2734656,3.6382799,0.0,0,6.3020205,0.0,0.27769864,60.444695,6.3272257,450.34863,-9.2610874
3612,3612,178.9784,6.2708287,3.6707711,0.0,0,6.2756648,0.0,0.28067857,60.349857,6.2972765,450.50644,-9.2600832
3623,3623,178.9806,6.2497087,3.6946723,0.0,0,6.2493086,0.0,0.28268656,60.030582,6.2703781,450.66422,-9.2599678
3634,3634,178.9828,6.2261934,3.7190814,0.0,0,6.2229524,0.0,0.28493431,59.700264,6.2442842,450.82199,-9.2618971
3645,3645,178.985,6.2637615,3.7421632,0.0,0,6.1965966,0.0,0.28684169,59.839642,6.2183466,450.78128,-9.261549
3656,3656,178.9872,6.3056884,3.770494,0.0,0,6.1702404,0.0,0.2895999,60.081158,6.1942806,450.66953,-9.2602739
3667,3667,178.9894,6.339911,3.7965713,0.0,0,6.1448588,0.0,0.29159671,60.327667,6.1677017,450.55777,-9.2603035
3678,3678,178.9916,6.3648129,3.822098,0.0,0,6.119792,0.0,0.29430106,60.371185,6.1381693,450.44598,-9.2613964
3689,3689,178.9938,6.3642955,3.8488717,0.0,0,6.0947251,0.0,0.29626486,60.291687,6.1134963,449.98486,-9.2630882
3700,3700,178.996,6.3466473,3.8778586,0.0,0,6.0696583,0.0,0.29941764,59.940067,6.0884871,447.95166,-9.2622786
3711,3711,178.9982,6.3435183,3.904608,0.0,0,6.0445914,0.0,0.30114138,59.715187,6.05972,445.91846,-9.2626371
3722,3722,179.0004,6.3037515,3.9234784,0.0,0,6.0195251,0.0,0.30349231,59.260101,6.0364442,443.88522,-9.2622738
3733,3733,179.0026,6.321557,3.9487996,0.0,0,5.9944577,0.0,0.30521259,59.359493,6.0143213,441.85202,-9.2622747
3744,3744,179.0048,6.3563809,3.9722507,0.0,0,5.9693913,0.0,0.30798376,59.442551,5.9879074,439.9425,-9.2615614
3755,3755,179.007,6.4001169,4.0005221,0.0,0,5.944324,0.0,0.30973437,59.732533,5.9660096,438.10648,-9.2631636
3766,3766,179.0092,6.3962398,4.0190806,0.0,0,5.9192576,0.0,0.31222728,59.652344,5.9400258,436.27048,-9.2609215
3777,3777,179.0114,6.4259505,4.0478125,0.0,0,5.8941908,0.0,0.31416014,59.781479,5.9182763,434.43445,-9.2607908
3788,3788,179.0136,6.4602962,4.0711126,0.0,0,5.8691239,0.0,0.3170886,59.861691,5.8867316,432.71713,-9.2610922
3799,3799,179.0158,6.4808354,4.1021857,0.0,0,5.8440571,0.0,0.31889537,59.917496,5.8632207,432.513,-9.2627573
3810,3810,179.018,6.4636884,4.1203356,0.0,0,5.8189898,0.0,0.32153761,59.754578,5.8399611,432.3089,-9.2617121
3821,3821,179.0202,6.4534631,4.1494288,0.0,0,5.7939234,0.0,0.32358453,59.402973,5.8118062,432.10477,-9.2628975
3832,3832,179.0224,6.4778118,4.1727972,0.0,0,5.7688565,0.0,0.32636964,59.453331,5.7883925,431.90067,-9.2619333
3843,3843,179.0246,6.539957,4.2048278,0.0,0,5.7437897,0.0,0.32849067,59.959644,5.7590241,431.85349,-9.2616673
3854,3854,179.0268,6.5503712,4.2231469,0.0,0,5.7187228,0.0,0.33093622,59.916103,5.736002,431.95224,-9.2615118
3865,3865,179.029,6.5307922,4.2518916,0.0,0,5.693656,0.0,0.33297345,59.66375,5.712225,432.05103,-9.2628536
3876,3876,179.0312,6.5310106,4.2714481,0.0,0,5.6685896,0.0,0.33544448,59.408886,5.6824584,432.14978,-9.2626352
3887,3887,179.0334,6.5206099,4.3034067,0.0,0,5.6435223,0.0,0.33770168,59.300468,5.6621428,432.24854,-9.2610064
3898,3898,179.0356,6.50214,4.3204589,0.0,0,5.6184554,0.0,0.33985069,59.044991,5.6422977,432.6709,-9.2616787
3909,3909,179.0378,6.5484557,4.3490915,0.0,0,5.5934343,0.0,0.34215352,59.260525,5.6135888,433.10547,-9.2609034
3920,3920,179.04,6.5870962,4.3659902,0.0,0,5.5695753,0.0,0.34413326,59.417023,5.5878429,433.54004,-9.2614965
3931,3931,179.0422,6.6476421,4.3987002,0.0,0,5.5457277,0.0,0.34683871,59.771107,5.5673108,433.97461,-9.2617302
3942,3942,179.0444,6.6668401,4.4209914,0.0,0,5.5218797,0.0,0.34926972,59.901928,5.5352273,434.54388,-9.2603903
3953,3953,179.0466,6.6876979,4.4482608,0.0,0,5.4980316,0.0,0.35162738,59.874332,5.5112753,435.30768,-9.2603922
3964,3964,179.0488,6.6367803,4.4700198,0.0,0,5.4741836,0.0,0.35386765,59.240482,5.4862862,436.07147,-9.2604208
3975,3975,179.051,6.628623,4.4987564,0.0,0,5.4503355,0.0,0.35648364,59.153709,5.4620781,436.83527,-9.2607737
3986,3986,179.0532,6.6095195,4.5167117,0.0,0,5.4264879,0.0,0.35819799,58.818211,5.4406638,437.59906,-9.2626839
3997,3997,179.0554,6.6412992,4.5409703,0.0,0,5.4026399,0.0,0.36058369,58.969872,5.4185596,438.17154,-9.262332
4008,4008,179.0576,6.6625409,4.5626063,0.0,0,5.3787913,0.0,0.36258346,58.99728,5.3895907,438.71146,-9.2611799
4019,4019,179.0598,6.6857128,4.5903811,0.0,0,5.3549438,0.0,0.36540818,58.990932,5.3686247,439.25137,-9.261178
4030,4030,179.062,6.6980553,4.612535,0.0,0,5.3310957,0.0,0.36725014,59.10244,5.3448195,439.79129,-9.2616234
4041,4041,179.0642,6.7236886,4.6340933,0.0,0,5.3072476,0.0,0.36963871,59.140522,5.3216038,440.1337,-9.2614098
4052,4052,179.0664,6.7478385,4.6581354,0.0,0,5.2833996,0.0,0.37159351,59.249519,5.3003035,440.01517,-9.2621489
4063,4063,179.0686,6.7553148,4.6848803,0.0,0,5.2595515,0.0,0.37467948,59.130814,5.2726684,439.89667,-9.2617922
4074,4074,179.0708,6.7719922,4.7068348,0.0,0,5.2357039,0.0,0.37624246,59.19738,5.2523103,439.77814,-9.2607117
4085,4085,179.073,6.7759175,4.7278514,0.0,0,5.2118554,0.0,0.37890294,59.067337,5.2278066,439.65964,-9.2614107
4096,4096,179.0752,6.7671528,4.7547159,0.0,0,5.1880078,0.0,0.38094574,58.910503,5.201086,439.72272,-9.2615757
4107,4107,179.0774,6.7852507,4.7786517,0.0,0,5.1641598,0.0,0.38393188,58.825912,5.1772361,439.84781,-9.2610435
4118,4118,179.0796,6.8273535,4.8034182,0.0,0,5.1403117,0.0,0.38548943,59.095528,5.155076,439.9729,-9.2606945
4129,4129,179.0818,6.8900056,4.823194,0.0,0,5.1164637,0.0,0.38828734,59.45211,5.1279178,440.09799,-9.2609606
4140,4140,179.084,6.8964314,4.8528204,0.0,0,5.0926156,0.0,0.39039516,59.402126,5.1036439,440.27338,-9.2621622
4151,4151,179.0862,6.8968849,4.874198,0.0,0,5.0687675,0.0,0.39336017,59.290863,5.0831747,440.66187,-9.2615509
4162,4162,179.0884,6.8820152,4.9036465,0.0,0,5.0452709,0.0,0.39533716,59.034634,5.0584044,441.05035,-9.2614136
4173,4173,179.0906,6.8960838,4.9196644,0.0,0,5.0225892,0.0,0.39794001,58.898376,5.0323772,441.43881,-9.2615614
4184,4184,179.0928,6.871767,4.9477973,0.0,0,4.9999065,0.0,0.399804,58.617439,5.0110464,441.8273,-9.2616472
4195,4195,179.095,6.8765264,4.9646297,0.0,0,4.9772248,0.0,0.40245104,58.534103,4.99084,442.24075,-9.2617168
4206,4206,179.0972,6.9176178,4.995501,0.0,0,4.9545431,0.0,0.40443173,58.779591,4.9680462,442.66849,-9.2606831
4217,4217,179.0994,6.9493456,5.0108252,0.0,0,4.9318609,0.0,0.40692466,58.906174,4.9427309,443.09619,-9.2602282
4228,4228,179.1016,6.9816933,5.0385942,0.0,0,4.9091787,0.0,0.40897265,59.017365,4.919487,443.52393,-9.2609091
4239,4239,179.1038,6.9949002,5.058497,0.0,0,4.886497,0.0,0.41179594,59.063488,4.8959355,443.94839,-9.2615919
4250,4250,179.106,6.9830732,5.0891418,0.0,0,4.8638148,0.0,0.4139342,58.902378,4.8715644,444.33633,-9.261467
4261,4261,179.1082,6.9479861,5.104351,0.0,0,4.8411331,0.0,0.41625714,58.33604,4.8515635,444.72427,-9.26159
4272,4272,179.1104,6.9564042,5.1283574,0.0,0,4.8184505,0.0,0.41810933,58.305477,4.8293815,445.11221,-9.2616348
4283,4283,179.1126,6.9984655,5.145936,0.0,0,4.7957687,0.0,0.42037362,58.514557,4.8077874,445.50015,-9.2636509
4294,4294,179.1148,7.0420327,5.1769323,0.0,0,4.773087,0.0,0.42302361,58.72163,4.7808733,445.81525,-9.2623787
4305,4305,179.117,7.0628495,5.1945868,0.0,0,4.7504048,0.0,0.42525494,58.768295,4.7564545,446.06506,-9.2625971
4316,4316,179.1192,7.1116028,5.2215724,0.0,0,4.7277226,0.0,0.42776531,59.037991,4.7359939,446.31491,-9.2632923
4327,4327,179.1214,7.1297612,5.2411852,0.0,0,4.7050409,0.0,0.42991993,58.972771,4.7113929,446.56473,-9.2621498
4338,4338,179.1236,7.1269507,5.2706399,0.0,0,4.6823587,0.0,0.43271577,58.890926,4.6892099,446.81454,-9.2601681
4349,4349,179.1258,7.1156855,5.2887282,0.0,0,4.659677,0.0,0.4346877,58.723137,4.6673512,447.00681,-9.2613077
4360,4360,179.128,7.0710001,5.311379,0.0,0,4.6369944,0.0,0.43709984,58.220203,4.6440916,447.19745,-9.2616377
4371,4371,179.1302,7.0789075,5.3310008,0.0,0,4.6143126,0.0,0.4391264,58.105938,4.6243243,447.38812,-9.2617197
4382,4382,179.1324,7.1138763,5.3595948,0.0,0,4.5916309,0.0,0.44205067,58.258739,4.6044407,447.57877,-9.2638664
4393,4393,179.1346,7.1639833,5.3783584,0.0,0,4.5689487,0.0,0.44384235,58.499084,4.5781627,447.77219,-9.2633867
4404,4404,179.1368,7.1837153,5.3971443,0.0,0,4.546267,0.0,0.44620407,58.591309,4.5535269,447.96939,-9.2607574
4415,4415,179.139,7.2289762,5.4210162,0.0,0,4.5242186,0.0,0.44825312,58.745239,4.5334439,448.16663,-9.2595396
4426,4426,179.1412,7.2552142,5.446363,0.0,0,4.5026407,0.0,0.45143297,58.81427,4.5094595,448.36383,-9.258544
4437,4437,179.1434,7.2442927,5.4684677,0.0,0,4.4810629,0.0,0.45320246,58.673889,4.4896612,448.56107,-9.260087
4448,4448,179.1456,7.2748461,5.4909644,0.0,0,4.4594855,0.0,0.45594567,58.688229,4.4656982,447.83804,-9.2615366
4459,4459,179.1478,7.2446923,5.5140333,0.0,0,4.4379077,0.0,0.45791396,58.368801,4.4383273,446.96976,-9.2620773
4470,4470,179.15,7.244525,5.5361037,0.0,0,4.4163303,0.0,0.46092156,58.175568,4.4202967,446.10147,-9.2610149
4481,4481,179.1522,7.2372751,5.5594149,0.0,0,4.3947525,0.0,0.46253002,57.990276,4.4014301,445.23315,-9.2620115
4492,4492,179.1544,7.2748938,5.5737123,0.0,0,4.3731751,0.0,0.46495163,58.180332,4.3779387,444.31198,-9.261013
4503,4503,179.1566,7.2880297,5.5969887,0.0,0,4.3515973,0.0,0.46668613,58.167267,4.3591175,443.27261,-9.2615843
4514,4514,179.1588,7.3403573,5.6187682,0.0,0,4.33002,0.0,0.46985203,58.46312,4.331182,442.23322,-9.2604055
4525,4525,179.161,7.3453274,5.645546,0.0,0,4.3084426,0.0,0.47145599,58.383045,4.3128862,441.19385,-9.2616224
4536,4536,179.1632,7.3494482,5.6590905,0.0,0,4.2868648,0.0,0.47416958,58.270645,4.2939019,440.15448,-9.2607193
4547,4547,179.1654,7.3551679,5.6841917,0.0,0,4.2652874,0.0,0.47585133,58.175648,4.2702751,439.95401,-9.2622194
4558,4558,179.1676,7.3725138,5.7039771,0.0,0,4.2437096,0.0,0.47904509,58.145092,4.2482796,440.02643,-9.2627716
4569,4569,179.1698,7.4079022,5.7339621,0.0,0,4.2221322,0.0,0.48087493,58.400551,4.2278852,440.09885,-9.2622395
4580,4580,179.172,7.4489474,5.7452526,0.0,0,4.2005544,0.0,0.48337144,58.462097,4.2063689,440.17126,-9.2614202
4591,4591,179.1742,7.4675355,5.7704124,0.0,0,4.178977,0.0,0.4853307,58.543987,4.1802583,440.30823,-9.2610445
4602,4602,179.1764,7.4910107,5.7894092,0.0,0,4.1573992,0.0,0.48822549,58.551998,4.161303,440.70331,-9.2620144
4613,4613,179.1786,7.496469,5.8216534,0.0,0,4.1358213,0.0,0.49068642,58.463203,4.1405854,441.09836,-9.2621984
4624,4624,179.1808,7.4956317,5.8338099,0.0,0,4.114244,0.0,0.4928917,58.315006,4.1175351,441.49344,-9.261528
4635,4635,179.183,7.5030584,5.8596444,0.0,0,4.0926666,0.0,0.49495661,58.268841,4.0982637,441.88849,-9.2602148
4646,4646,179.1852,7.5177965,5.875762,0.0,0,4.0710883,0.0,0.49741399,58.188473,4.0765352,442.30038,-9.2609406
4657,4657,179.1874,7.539536,5.9068675,0.0,0,4.0495114,0.0,0.50015688,58.205631,4.0535364,442.72156,-9.2610025
4668,4668,179.1896,7.5858612,5.9212193,0.0,0,4.0288277,0.0,0.50230473,58.455715,4.031527,443.1427,-9.2609987
4679,4679,179.1918,7.6313534,5.9462223,0.0,0,4.008306,0.0,0.50459141,58.688412,4.0074658,443.56384,-9.2614231
4690,4690,179.194,7.6342831,5.9644251,0.0,0,3.9877841,0.0,0.50699008,58.532204,3.9861684,443.98077,-9.2613344
4701,4701,179.1962,7.6405368,5.9914694,0.0,0,3.9672625,0.0,0.50964874,58.457191,3.9677157,444.35556,-9.2610168
4712,4712,179.1984,7.6194959,6.0060534,0.0,0,3.9467409,0.0,0.5116443,58.233856,3.9469743,444.73032,-9.2604361
4723,4723,179.2006,7.6151013,6.0294938,0.0,0,3.9262192,0.0,0.51397371,58.050003,3.925678,445.10507,-9.2603283
4734,4734,179.2028,7.6065111,6.0465035,0.0,0,3.9056978,0.0,0.51594454,57.870007,3.9046593,445.47983,-9.2609425
4745,4745,179.205,7.6068058,6.0726428,0.0,0,3.8851764,0.0,0.51880074,57.660732,3.8873703,445.77701,-9.2609959
4756,4756,179.2072,7.6347709,6.0874271,0.0,0,3.8646545,0.0,0.52048022,57.744415,3.868089,446.00711,-9.2608929
4767,4767,179.2094,7.7054858,6.1060352,0.0,0,3.8441329,0.0,0.52283537,58.133881,3.8489923,446.23721,-9.2608891
4778,4778,179.2116,7.7649646,6.1257734,0.0,0,3.8236115,0.0,0.52474004,58.497906,3.8275723,446.46732,-9.2615843
4789,4789,179.2138,7.7966714,6.153656,0.0,0,3.8030899,0.0,0.52825665,58.523014,3.8085756,446.69742,-9.2607956
4800,4800,179.216,7.8043027,6.1734285,0.0,0,3.7825682,0.0,0.52991837,58.509533,3.7835181,446.79843,-9.2601385
4811,4811,179.2182,7.8486447,6.1926084,0.0,0,3.7620466,0.0,0.53264886,58.642139,3.7583218,446.89703,-9.2603178
4822,4822,179.2204,7.8304129,6.2154202,0.0,0,3.7415249,0.0,0.53461045,58.39658,3.7396185,446.99564,-9.2618217
4833,4833,179.2226,7.8178024,6.2361083,0.0,0,3.7210035,0.0,0.53780264,58.142139,3.7227478,447.09424,-9.2621918
4844,4844,179.2248,7.7881703,6.2596121,0.0,0,3.7004819,0.0,0.53964734,57.837971,3.7000027,447.25748,-9.2609825
4855,4855,179.227,7.7956734,6.2736382,0.0,0,3.67996,0.0,0.54212356,57.714619,3.6819816,447.50726,-9.2604284
4866,4866,179.2292,7.8070464,6.2933202,0.0,0,3.6594386,0.0,0.54354465,57.660309,3.6622522,447.75708,-9.2616682
4877,4877,179.2314,7.8870869,6.3112741,0.0,0,3.638917,0.0,0.54649723,58.136345,3.6440315,448.0069,-9.2613926
4888,4888,179.2336,7.9229684,6.3342457,0.0,0,3.6183956,0.0,0.54812664,58.266037,3.6228468,448.25671,-9.2619219
4899,4899,179.2358,7.9916201,6.3516898,0.0,0,3.5978739,0.0,0.5512566,58.648148,3.601378,448.66718,-9.2612343
4910,4910,179.238,8.0471191,6.3797951,0.0,0,3.577472,0.0,0.55346328,58.903584,3.5751278,449.10107,-9.260437
4921,4921,179.2402,8.0484219,6.3975258,0.0,0,3.5579486,0.0,0.55658174,58.77832,3.549669,449.53497,-9.2600327
4932,4932,179.2424,8.0029163,6.4241157,0.0,0,3.5384259,0.0,0.5582487,58.325939,3.5339923,449.96887,-9.260747
4943,4943,179.2446,7.9976945,6.4344788,0.0,0,3.518903,0.0,0.56093109,58.106625,3.5142694,450.39648,-9.2619219
4954,4954,179.2468,8.0205154,6.4619842,0.0,0,3.4993801,0.0,0.56299651,58.054787,3.4965248,450.81067,-9.2602654
4965,4965,179.249,8.039155,6.4791226,0.0,0,3.4798574,0.0,0.56592751,58.094646,3.4768114,451.22485,-9.2594299
4976,4976,179.2512,8.0503302,6.5032501,0.0,0,3.4603345,0.0,0.56755084,58.119968,3.4592152,451.63904,-9.2602663
4987,4987,179.2534,8.0701008,6.5120931,0.0,0,3.4408119,0.0,0.56976849,58.177864,3.4401836,452.05322,-9.2608576
4998,4998,179.2556,8.1025438,6.5365086,0.0,0,3.4212892,0.0,0.57190651,58.249615,3.4197602,452.34692,-9.261344
5009,5009,179.2578,8.1344452,6.5539255,0.0,0,3.4017661,0.0,0.57473105,58.309681,3.3994782,452.6033,-9.2614527
5020,5020,179.26,8.147254,6.5819869,0.0,0,3.3822436,0.0,0.57712734,58.243736,3.3792577,452.85968,-9.2614021
5031,5031,179.2622,8.1667099,6.5949354,0.0,0,3.3627205,0.0,0.57954603,58.22514,3.3616452,453.11606,-9.2610741
5042,5042,179.2644,8.1634254,6.6178975,0.0,0,3.3431976,0.0,0.58165872,58.082047,3.3411348,453.33948,-9.2615919
5053,5053,179.2666,8.1925726,6.6324301,0.0,0,3.3236752,0.0,0.58394939,58.104225,3.3230238,453.43808,-9.2607431
5064,5064,179.2688,8.2148094,6.6577845,0.0,0,3.304152,0.0,0.58627909,58.192608,3.3039465,453.53671,-9.2617025
5075,5075,179.271,8.2572308,6.6714497,0.0,0,3.2846293,0.0,0.588516,58.330799,3.2838118,453.63531,-9.2613811
5086,5086,179.2732,8.292902,6.6948242,0.0,0,3.2651067,0.0,0.59112281,58.459164,3.2622576,453.73395,-9.2615881
5097,5097,179.2754,8.32827,6.713398,0.0,0,3.2455838,0.0,0.59335238,58.583157,3.2436373,453.72928,-9.2612801
5108,5108,179.2776,8.3322868,6.7394218,0.0,0,3.2260611,0.0,0.59651792,58.427818,3.2226737,453.6701,-9.2624445
5119,5119,179.2798,8.3321609,6.75316,0.0,0,3.2065382,0.0,0.59807962,58.360374,3.2021024,453.61096,-9.2618933
5130,5130,179.282,8.3421717,6.7735786,0.0,0,3.1870155,0.0,0.60073739,58.213047,3.1814446,453.55179,-9.2611589
5141,5141,179.2842,8.3775692,6.7918663,0.0,0,3.1674926,0.0,0.60286307,58.332321,3.1622775,453.50446,-9.2607841
5152,5152,179.2864,8.4159775,6.8151922,0.0,0,3.1479697,0.0,0.60587698,58.442394,3.1441734,453.56363,-9.2609711
5163,5163,179.2886,8.4504404,6.8308182,0.0,0,3.1288195,0.0,0.60735029,58.58321,3.1257474,453.62277,-9.2608891
5174,5174,179.2908,8.4773483,6.8493567,0.0,0,3.1102469,0.0,0.61027282,58.633606,3.1053243,453.68195,-9.2615643
5185,5185,179.293,8.4808168,6.871727,0.0,0,3.0916746,0.0,0.6122992,58.552399,3.0874004,453.74112,-9.2610016
5196,5196,179.2952,8.4674988,6.8934798,0.0,0,3.0731022,0.0,0.61577904,58.247108,3.066926,453.81464,-9.2603121
5207,5207,179.2974,8.497716,6.912076,0.0,0,3.0545297,0.0,0.6171661,58.364571,3.0510056,453.90009,-9.2601519
5218,5218,179.2996,8.4977551,6.9255762,0.0,0,3.0359576,0.0,0.61974436,58.195007,3.0296278,453.98557,-9.2613802
5229,5229,179.3018,8.5219584,6.9447837,0.0,0,3.017385,0.0,0.6211822,58.30761,3.0122249,454.07101,-9.2616682
5240,5240,179.304,8.5412874,6.9617138,0.0,0,2.9988127,0.0,0.6244843,58.269711,2.9934509,454.15649,-9.2615767
5251,5251,179.3062,8.5991344,6.9862933,0.0,0,2.9802401,0.0,0.62631345,58.468651,2.976877,454.11816,-9.2605314
5262,5262,179.3084,8.5996876,6.9986854,0.0,0,2.9616678,0.0,0.62900031,58.383812,2.9568198,454.07874,-9.2609653
5273,5273,179.3106,8.602437,7.0204496,0.0,0,2.9430954,0.0,0.63050312,58.310272,2.9381232,454.03928,-9.2611723
5284,5284,179.3128,8.6132803,7.0340576,0.0,0,2.9245229,0.0,0.63347864,58.218151,2.921257,453.99985,-9.2609138
5295,5295,179.315,8.61831,7.0593076,0.0,0,2.9059508,0.0,0.63529366,58.16708,2.9052014,453.91162,-9.2623787
5306,5306,179.3172,8.6281157,7.0708332,0.0,0,2.8873782,0.0,0.6380797,58.055069,2.8874726,453.76041,-9.2615633
5317,5317,179.3194,8.647974,7.0930433,0.0,0,2.8688059,0.0,0.63965774,58.029675,2.8672979,453.60922,-9.2616615
5328,5328,179.3216,8.7248154,7.1053247,0.0,0,2.8502333,0.0,0.64254695,58.401855,2.8516107,453.45801,-9.2609816
5339,5339,179.3238,8.8287649,7.1306033,0.0,0,2.831661,0.0,0.64419687,58.98325,2.8350289,453.30682,-9.2616339
5350,5350,179.326,8.9213095,7.1430402,0.0,0,2.8130884,0.0,0.64721954,59.476654,2.8100328,453.03967,-9.2609634
5361,5361,179.3282,8.9422121,7.1700134,0.0,0,2.7945161,0.0,0.64960951,59.462963,2.7894619,452.75696,-9.2597933
5372,5372,179.3304,8.9231672,7.1872463,0.0,0,2.7759438,0.0,0.65287423,59.158222,2.7733545,452.47427,-9.2618761
5383,5383,179.3326,8.8993797,7.2137198,0.0,0,2.7573714,0.0,0.65503395,58.879467,2.756422,452.19159,-9.2621298
5394,5394,179.3348,8.8930006,7.2232304,0.0,0,2.7387993,0.0,0.65722549,58.723213,2.7363942,451.88907,-9.2615433
5405,5405,179.337,8.9140425,7.2455444,0.0,0,2.7202265,0.0,0.65945601,58.691341,2.7185273,451.54584,-9.2613258
5416,5416,179.3392,8.9389162,7.2601423,0.0,0,2.7022569,0.0,0.66191316,58.678867,2.6999304,451.20258,-9.2598667
5427,5427,179.3414,8.9522696,7.2859097,0.0,0,2.6845908,0.0,0.66445327,58.63858,2.681716,450.85934,-9.2611904
5438,5438,179.3436,9.0059633,7.2988024,0.0,0,2.6669247,0.0,0.66689241,58.799721,2.6617446,450.46835,-9.2600088
5449,5449,179.3458,9.054183,7.3209167,0.0,0,2.6492589,0.0,0.66930151,59.034016,2.6445608,449.91501,-9.2601051
5460,5460,179.348,9.0945578,7.3331504,0.0,0,2.631593,0.0,0.67132056,59.207603,2.6259356,449.36166,-9.2614346
5471,5471,179.3502,9.0964108,7.3590984,0.0,0,2.6139269,0.0,0.67435503,59.071812,2.6074526,448.80832,-9.2606173
5482,5482,179.3524,9.1227961,7.372014,0.0,0,2.5962608,0.0,0.67612505,59.077389,2.5887451,448.25497,-9.2604561
5493,5493,179.3546,9.1046209,7.3906803,0.0,0,2.5785949,0.0,0.67871088,58.834057,2.570147,447.79147,-9.2602644
5504,5504,179.3568,9.1279011,7.4055362,0.0,0,2.5609288,0.0,0.68043774,58.81353,2.5509458,447.36987,-9.260807
5515,5515,179.359,9.1317873,7.4285502,0.0,0,2.543263,0.0,0.683761,58.6511,2.5367692,446.9483,-9.2610865
5526,5526,179.3612,9.1559772,7.4427428,0.0,0,2.5255969,0.0,0.68521029,58.725101,2.5181828,446.5267,-9.2599688
5537,5537,179.3634,9.2028742,7.459002,0.0,0,2.5079308,0.0,0.68795311,58.832035,2.5024414,446.18414,-9.2597904
5548,5548,179.3656,9.2333088,7.475462,0.0,0,2.4902649,0.0,0.68958944,59.00037,2.4847863,446.34225,-9.2602262
5559,5559,179.3678,9.214756,7.4923954,0.0,0,2.4725988,0.0,0.69247425,58.737968,2.4683506,446.50037,-9.2592688
5570,5570,179.37,9.2356825,7.5097022,0.0,0,2.4549327,0.0,0.69402629,58.765476,2.4563804,446.65845,-9.2605648
5581,5581,179.3722,9.2789049,7.5246592,0.0,0,2.4372668,0.0,0.69693696,58.818607,2.4336038,446.81656,-9.2604122
5592,5592,179.3744,9.3650427,7.5448637,0.0,0,2.4196007,0.0,0.69870961,59.273689,2.4154935,447.0564,-9.2599602
5603,5603,179.3766,9.4206181,7.5624409,0.0,0,2.4019349,0.0,0.70214313,59.420578,2.3996401,447.35281,-9.2610273
5614,5614,179.3788,9.4780836,7.5845165,0.0,0,2.3842688,0.0,0.70391428,59.705223,2.3808134,447.64926,-9.261797
5625,5625,179.381,9.5252666,7.598105,0.0,0,2.3666029,0.0,0.70692325,59.797909,2.3618824,447.94568,-9.2614412
5636,5636,179.3832,9.5774021,7.6208692,0.0,0,2.3489368,0.0,0.7087245,60.023254,2.3417563,448.22147,-9.2599812
5647,5647,179.3854,9.5885592,7.6371832,0.0,0,2.3312709,0.0,0.71238852,59.931103,2.3225403,448.06335,-9.2604008
5658,5658,179.3876,9.5568018,7.6610374,0.0,0,2.3136048,0.0,0.71380901,59.639591,2.3056417,447.90524,-9.261651
5669,5669,179.3898,9.5206757,7.6725469,0.0,0,2.2967472,0.0,0.71708888,59.201973,2.2895834,447.74716,-9.2612753
5680,5680,179.392,9.5509844,7.6928144,0.0,0,2.2799437,0.0,0.71855772,59.274258,2.2719672,447.58905,-9.2617407
5691,5691,179.3942,9.6013498,7.7042108,0.0,0,2.26314,0.0,0.72153729,59.400089,2.2554448,447.36838,-9.2618732
5702,5702,179.3964,9.6268587,7.7309232,0.0,0,2.2463365,0.0,0.72341835,59.426884,2.2366786,447.08514,-9.260129
5713,5713,179.3986,9.6300917,7.7383485,0.0,0,2.229533,0.0,0.72610593,59.327225,2.2211702,446.80188,-9.2610159
5724,5724,179.4008,9.6205711,7.7579546,0.0,0,2.2127295,0.0,0.72760743,59.197563,2.208235,446.51865,-9.2620821
5735,5735,179.403,9.6504469,7.7681818,0.0,0,2.1959257,0.0,0.73021424,59.195354,2.1922178,446.23538,-9.2615662
5746,5746,179.4052,9.6878424,7.7937837,0.0,0,2.1791222,0.0,0.73230267,59.336803,2.1776776,446.33569,-9.2607613
5757,5757,179.4074,9.6954422,7.8025475,0.0,0,2.1623185,0.0,0.73477608,59.241047,2.1588421,446.45425,-9.2620134
5768,5768,179.4096,9.7395449,7.8230386,0.0,0,2.145515,0.0,0.73673809,59.330994,2.1421337,446.57285,-9.2606459
5779,5779,179.4118,9.7710419,7.8347673,0.0,0,2.1287112,0.0,0.7393319,59.408459,2.1256788,446.69141,-9.2617655
5790,5790,179.414,9.8513012,7.860878,0.0,0,2.1119077,0.0,0.74187905,59.703964,2.1105709,446.8558,-9.2601347
5801,5801,179.4162,9.9496117,7.87044,0.0,0,2.095104,0.0,0.74413288,60.183395,2.0889895,447.08633,-9.2608662
5812,5812,179.4184,10.033676,7.8922243,0.0,0,2.0783007,0.0,0.74644142,60.508968,2.0699918,447.31689,-9.261322
5823,5823,179.4206,10.049265,7.9044628,0.0,0,2.061497,0.0,0.74880874,60.482769,2.0560658,447.54745,-9.2606573
5834,5834,179.4228,10.047062,7.930367,0.0,0,2.0446935,0.0,0.75201035,60.346169,2.0390615,447.77802,-9.2594824
5845,5845,179.425,10.067064,7.9419265,0.0,0,2.0278897,0.0,0.75398433,60.316189,2.0200815,447.91754,-9.2598133
5856,5856,179.4272,10.069983,7.9611015,0.0,0,2.0110862,0.0,0.75663668,60.206486,2.0041764,448.04269,-9.2608614
5867,5867,179.4294,10.080079,7.975316,0.0,0,1.9942826,0.0,0.75854832,60.079891,1.9853847,448.16785,-9.2611113
5878,5878,179.4316,10.099819,7.9988599,0.0,0,1.977479,0.0,0.76201266,60.021996,1.9681613,448.29303,-9.260911
5889,5889,179.4338,10.144896,8.0113783,0.0,0,1.9606754,0.0,0.76354021,60.146103,1.9546201,448.49155,-9.2602367
5900,5900,179.436,10.182339,8.0265923,0.0,0,1.9438719,0.0,0.76614386,60.215267,1.9387692,448.84726,-9.2594662
5911,5911,179.4382,10.206776,8.0412636,0.0,0,1.9272404,0.0,0.76769966,60.306599,1.92159,449.20297,-9.260087
5922,5922,179.4404,10.255312,8.0621424,0.0,0,1.911255,0.0,0.77140814,60.359432,1.9032294,449.55869,-9.2606258
5933,5933,179.4426,10.284762,8.0776234,0.0,0,1.8952699,0.0,0.77272588,60.449169,1.8883747,449.9144,-9.2610283
5944,5944,179.4448,10.274391,8.0911217,0.0,0,1.8792846,0.0,0.77569431,60.293156,1.8713157,450.20395,-9.2606974
5955,5955,179.447,10.25632,8.107605,0.0,0,1.8632994,0.0,0.77708972,60.042061,1.8572369,450.47403,-9.2615519
5966,5966,179.4492,10.262723,8.1235619,0.0,0,1.8473142,0.0,0.78042734,59.873135,1.8434207,450.74411,-9.2613077
5977,5977,179.4514,10.316802,8.1399708,0.0,0,1.8313291,0.0,0.78164774,60.107304,1.8264724,451.01419,-9.2613764
5988,5988,179.4536,10.408611,8.1526184,0.0,0,1.8153439,0.0,0.78471857,60.472889,1.8100719,451.22888,-9.2610273
5999,5999,179.4558,10.484526,8.169693,0.0,0,1.7993586,0.0,0.78595197,60.834789,1.7914379,451.25522,-9.261405
6010,6010,179.458,10.529835,8.1836863,0.0,0,1.7833734,0.0,0.78955853,60.875862,1.780149,451.28159,-9.2616291
6021,6021,179.4602,10.575905,8.2080507,0.0,0,1.7673882,0.0,0.79138589,61.045734,1.7592585,451.30792,-9.2616119
6032,6032,179.4624,10.601257,8.2183151,0.0,0,1.751403,0.0,0.79450017,60.984261,1.7437841,451.33426,-9.2602539
6043,6043,179.4646,10.616946,8.2395668,0.0,0,1.7354178,0.0,0.79621989,60.965115,1.7265173,451.18546,-9.2600603
6054,6054,179.4668,10.612342,8.2500305,0.0,0,1.7194326,0.0,0.79935527,60.775307,1.7116196,450.9549,-9.2603312
6065,6065,179.469,10.654865,8.2748013,0.0,0,1.7034475,0.0,0.80109429,60.847424,1.6976744,450.72433,-9.2602739
6076,6076,179.4712,10.6984,8.2811241,0.0,0,1.6874622,0.0,0.80382466,60.899143,1.6807473,450.4938,-9.261097
6087,6087,179.4734,10.748826,8.3017693,0.0,0,1.6714771,0.0,0.80548769,61.164387,1.6651682,450.23361,-9.2610054
6098,6098,179.4756,10.790833,8.311861,0.0,0,1.6554918,0.0,0.8084482,61.218201,1.6484574,449.78568,-9.2603149
6109,6109,179.4778,10.848166,8.3391399,0.0,0,1.6395066,0.0,0.81080824,61.420826,1.6379411,449.33774,-9.2597713
6120,6120,179.48,10.878265,8.345048,0.0,0,1.6235213,0.0,0.81342781,61.423759,1.6190102,448.8898,-9.2609968
6131,6131,179.4822,10.929695,8.3670244,0.0,0,1.6075362,0.0,0.8154707,61.585728,1.603862,448.44186,-9.260663
6142,6142,179.4844,10.951736,8.3769178,0.0,0,1.5915509,0.0,0.81803596,61.559013,1.5885388,448.21579,-9.259284
6153,6153,179.4866,10.982848,8.4048271,0.0,0,1.5755658,0.0,0.82096708,61.506561,1.569607,448.14331,-9.2598944
6164,6164,179.4888,11.033097,8.4132748,0.0,0,1.5599567,0.0,0.82324564,61.630306,1.5507588,448.07086,-9.2598715
6175,6175,179.491,11.113269,8.4312239,0.0,0,1.5447503,0.0,0.82522601,61.959755,1.5340397,447.99841,-9.2608242
6186,6186,179.4932,11.137642,8.4416227,0.0,0,1.5295439,0.0,0.82762998,61.989956,1.5160526,447.91785,-9.2602272
6197,6197,179.4954,11.16113,8.4705725,0.0,0,1.5143375,0.0,0.83117175,61.93375,1.5028052,447.66754,-9.2601795
6208,6208,179.4976,11.16724,8.4796171,0.0,0,1.4991311,0.0,0.83322859,61.7668,1.4859987,447.41721,-9.2594509
6219,6219,179.4998,11.193969,8.4969931,0.0,0,1.4839247,0.0,0.83562344,61.813999,1.4716734,447.1669,-9.2602806
6230,6230,179.502,11.174536,8.5050678,0.0,0,1.4687183,0.0,0.83699292,61.601654,1.4581611,446.91656,-9.2610312
6241,6241,179.5042,11.147891,8.5267324,0.0,0,1.4535118,0.0,0.8403247,61.305008,1.4414673,446.40918,-9.2607927
6252,6252,179.5064,11.145566,8.53862,0.0,0,1.4383055,0.0,0.84213626,61.147297,1.4264574,445.64471,-9.2612953
6263,6263,179.5086,11.19103,8.552906,0.0,0,1.423099,0.0,0.84459507,61.201565,1.4142529,444.88028,-9.2607937
6274,6274,179.5108,11.260621,8.5635214,0.0,0,1.4078927,0.0,0.84575987,61.522717,1.4003912,444.11581,-9.2612371
6285,6285,179.513,11.3323,8.5826464,0.0,0,1.3926864,0.0,0.84928632,61.710163,1.385569,443.35135,-9.2601528
6296,6296,179.5152,11.387564,8.5947304,0.0,0,1.3774799,0.0,0.85052288,61.954834,1.3692796,443.29773,-9.2616272
6307,6307,179.5174,11.439557,8.6099453,0.0,0,1.3622735,0.0,0.85358322,62.036774,1.3581513,443.27798,-9.2600279
6318,6318,179.5196,11.498784,8.6248732,0.0,0,1.3470671,0.0,0.85504574,62.267578,1.3407869,443.25821,-9.2600651
6329,6329,179.5218,11.544433,8.6407471,0.0,0,1.3318607,0.0,0.85869199,62.280727,1.3255022,443.23846,-9.2602348
6340,6340,179.524,11.568637,8.6592188,0.0,0,1.3166543,0.0,0.86028469,62.319283,1.3102669,443.42093,-9.2611561
6351,6351,179.5262,11.652207,8.6689835,0.0,0,1.3014479,0.0,0.86317766,62.555618,1.2929915,443.89554,-9.2617817
6362,6362,179.5284,11.721402,8.6877213,0.0,0,1.2862415,0.0,0.86480963,62.815228,1.2814659,444.37015,-9.2611227
6373,6373,179.5306,11.796593,8.7034912,0.0,0,1.2710352,0.0,0.8687833,63.001038,1.2656971,444.84476,-9.2600193
6384,6384,179.5328,11.835404,8.7243233,0.0,0,1.2558287,0.0,0.87031698,63.119259,1.2458861,445.31937,-9.2602415
6395,6395,179.535,11.820641,8.7302923,0.0,0,1.2406223,0.0,0.87306064,62.853832,1.2317379,445.04248,-9.2597637
6406,6406,179.5372,11.838819,8.7496386,0.0,0,1.2254159,0.0,0.87466502,62.853378,1.2164514,444.64694,-9.2601776
6417,6417,179.5394,11.893783,8.7640934,0.0,0,1.2107713,0.0,0.87857825,62.905464,1.2005045,444.25137,-9.2602205
6428,6428,179.5416,11.927422,8.7847967,0.0,0,1.1963085,0.0,0.87993687,62.975609,1.1859188,443.8558,-9.2596216
6439,6439,179.5438,11.96212,8.7889585,0.0,0,1.1818458,0.0,0.88249183,63.006638,1.1717539,443.55469,-9.2608433
6450,6450,179.546,12.020396,8.8092318,0.0,0,1.167383,0.0,0.88428932,63.174072,1.1599684,443.45587,-9.2615843
6461,6461,179.5482,12.066248,8.8202076,0.0,0,1.1529201,0.0,0.88766974,63.198093,1.145355,443.35706,-9.2607431
6472,6472,179.5504,12.121026,8.8458185,0.0,0,1.1384574,0.0,0.88975477,63.403713,1.1261082,443.25827,-9.2615404
6483,6483,179.5526,12.139091,8.8482876,0.0,0,1.1239946,0.0,0.89215666,63.359291,1.1122217,443.15945,-9.2603531
6494,6494,179.5548,12.166719,8.8689022,0.0,0,1.1095318,0.0,0.89397627,63.372215,1.1020658,443.27466,-9.2600756
6505,6505,179.557,12.18623,8.8773966,0.0,0,1.0950689,0.0,0.89685053,63.268101,1.08533,443.45279,-9.2606802
6516,6516,179.5592,12.21664,8.9012575,0.0,0,1.0806062,0.0,0.89910632,63.321598,1.0702506,443.63092,-9.2606297
6527,6527,179.5614,12.235829,8.9064837,0.0,0,1.0661434,0.0,0.90133494,63.27713,1.0551219,443.80905,-9.2598991
6538,6538,179.5636,12.29063,8.9259005,0.0,0,1.0516806,0.0,0.90346646,63.392277,1.0448401,443.9093,-9.2592573
6549,6549,179.5658,12.365289,8.9330168,0.0,0,1.0372177,0.0,0.90567368,63.629364,1.0310074,443.7446,-9.2594757
6560,6560,179.568,12.446506,8.9568014,0.0,0,1.022755,0.0,0.90849173,63.883133,1.0139205,443.5799,-9.260046
6571,6571,179.5702,12.495527,8.9651995,0.0,0,1.0082921,0.0,0.91071963,63.996296,0.99908727,443.41522,-9.2597933
6582,6582,179.5724,12.536459,8.9832983,0.0,0,0.99382937,0.0,0.91325498,64.077003,0.98574597,443.25052,-9.2599506
6593,6593,179.5746,12.546405,8.989295,0.0,0,0.97936654,0.0,0.91457331,64.046852,0.97385973,443.36432,-9.2594347
6604,6604,179.5768,12.586366,9.0127001,0.0,0,0.96490371,0.0,0.91822428,63.977383,0.95560527,443.60809,-9.258482
6615,6615,179.579,12.615243,9.0246725,0.0,0,0.95044094,0.0,0.92045385,64.005371,0.9396925,443.85187,-9.2590532
6626,6626,179.5812,12.674049,9.0373163,0.0,0,0.93597806,0.0,0.92269295,64.086021,0.92968732,444.09564,-9.2587214
6637,6637,179.5834,12.720494,9.0477295,0.0,0,0.92151535,0.0,0.92409903,64.283928,0.91361183,444.36548,-9.2590828
6648,6648,179.5856,12.795244,9.0695782,0.0,0,0.90705252,0.0,0.92812699,64.381813,0.89823031,444.80023,-9.2594862
6659,6659,179.5878,12.854489,9.0825701,0.0,0,0.89261615,0.0,0.92980355,64.55201,0.88315636,445.23499,-9.2593307
6670,6670,179.59,12.886162,9.0927553,0.0,0,0.87885547,0.0,0.93218559,64.62249,0.87070012,445.66977,-9.2602367
6681,6681,179.5922,12.90289,9.1047888,0.0,0,0.86510104,0.0,0.93351394,64.602997,0.85848135,446.10452,-9.2595243
6692,6692,179.5944,12.956779,9.1224298,0.0,0,0.85134661,0.0,0.93747568,64.593887,0.8411721,446.50424,-9.2596817
6703,6703,179.5966,12.984868,9.1391001,0.0,0,0.83759224,0.0,0.93902373,64.635941,0.82514054,446.87973,-9.2600031
6714,6714,179.5988,13.037724,9.1476488,0.0,0,0.82383782,0.0,0.94178903,64.725899,0.81361192,447.25522,-9.2582922
6725,6725,179.601,13.063404,9.1608772,0.0,0,0.81008345,0.0,0.94265968,64.782066,0.80268329,447.63068,-9.2600651
6736,6736,179.6032,13.111712,9.1756144,0.0,0,0.79632908,0.0,0.94690645,64.733131,0.78581452,447.99869,-9.2597332
6747,6747,179.6054,13.151011,9.193141,0.0,0,0.78257465,0.0,0.947945,64.885178,0.77317536,448.20947,-9.2600479
6758,6758,179.6076,13.172472,9.1999102,0.0,0,0.76882023,0.0,0.95108747,64.795547,0.76292568,448.42029,-9.2590132
6769,6769,179.6098,13.217309,9.2168474,0.0,0,0.7550658,0.0,0.95211315,64.941483,0.74564725,448.63107,-9.259903
6780,6780,179.612,13.258324,9.2253246,0.0,0,0.74131143,0.0,0.95549715,64.90905,0.73145211,448.84186,-9.2600441
6791,6791,179.6142,13.281926,9.2440825,0.0,0,0.72755706,0.0,0.95666027,64.985275,0.71940404,448.98019,-9.259366
6802,6802,179.6164,13.337094,9.2515841,0.0,0,0.71380264,0.0,0.96008992,65.02002,0.70839924,449.04608,-9.2591467
6813,6813,179.6186,13.423128,9.2702055,0.0,0,0.70004821,0.0,0.96153396,65.301331,0.69254822,449.11197,-9.2589254
6824,6824,179.6208,13.506257,9.2788038,0.0,0,0.68629384,0.0,0.96491724,65.484261,0.67794865,449.17783,-9.2601337
6835,6835,179.623,13.566642,9.3012581,0.0,0,0.67253947,0.0,0.96649265,65.68,0.66818249,449.24371,-9.260745
6846,6846,179.6252,13.636791,9.3029366,0.0,0,0.65878505,0.0,0.96897453,65.864754,0.65412176,449.32843,-9.2613821
6857,6857,179.6274,13.666287,9.3217735,0.0,0,0.64503068,0.0,0.97065616,65.920944,0.64063758,449.41406,-9.2593737
6868,6868,179.6296,13.697042,9.3314486,0.0,0,0.63127625,0.0,0.97410905,65.8536,0.62740421,449.49969,-9.2592659
6879,6879,179.6318,13.736775,9.3536119,0.0,0,0.61752182,0.0,0.97588706,65.925919,0.61247545,449.58533,-9.2585611
6890,6890,179.634,13.795563,9.3564348,0.0,0,0.60376745,0.0,0.97819746,66.065872,0.59900665,449.29086,-9.2595415
6901,6901,179.6362,13.880546,9.3757095,0.0,0,0.59001309,0.0,0.9801985,66.253555,0.58529383,448.44742,-9.259244
6912,6912,179.6384,13.9726,9.3837147,0.0,0,0.57645869,0.0,0.98317522,66.53334,0.57064444,447.60394,-9.2597208
6923,6923,179.6406,14.022279,9.4064913,0.0,0,0.56336868,0.0,0.98559785,66.598351,0.55842,446.7605,-9.2612429
6934,6934,179.6428,14.100701,9.4145212,0.0,0,0.55027872,0.0,0.98813397,66.832771,0.54501843,445.91702,-9.259079
6943,6943,179.6446,14.11492,9.4266405,0.0,0,0.53956872,0.0,0.98939788,66.785126,0.53133804,444.61072,-9.2597828