File: clean data/testID_0128.csv
level_0,index,Time(sec),Force(kN),Jaw(mm),PowAngle(deg),Power(W),Pram,PTemp,Strain,Stress(MPa),Stroke(mm),TC1(C),wedge(mm)
1773,1773,145.3455,0.20206134,0.02216297,0.0,0,9.0337057,0.0,0.0014074122,2.4905496,10.054817,317.15628,-9.3225737
1775,1775,145.3459,2.3544743,0.052861769,0.0,0,8.9751778,0.0,0.0034290382,25.303391,9.9820814,317.43176,-9.3228035
1777,1777,145.3463,5.3607507,0.1166369,0.0,0,8.9166498,0.0,0.0072672456,65.194794,9.9376106,317.70721,-9.3216457
1779,1779,145.3467,6.2160854,0.16263261,0.0,0,8.8581219,0.0,0.010469375,77.463043,9.8694,317.9827,-9.319725
1781,1781,145.3471,6.9603004,0.29585072,0.0,0,8.7995939,0.0,0.019090505,86.260773,9.789381,318.25815,-9.3180943
1783,1783,145.3475,7.3570576,0.37496316,0.0,0,8.7416534,0.0,0.02473281,90.439255,9.6973448,318.53363,-9.3180504
1785,1785,145.3479,8.0871792,0.44200253,0.0,0,8.6858492,0.0,0.029322566,99.48349,9.6080151,318.80908,-9.3181505
1787,1787,145.3483,8.682375,0.52415437,0.0,0,8.6301851,0.0,0.035292827,105.55794,9.5265265,319.08862,-9.317318
1789,1789,145.3487,8.8559933,0.53609043,0.0,0,8.5745211,0.0,0.035971671,109.31962,9.45362,319.44559,-9.3153582
1791,1791,145.3491,8.5688601,0.6205762,0.0,0,8.518857,0.0,0.041761477,104.32635,9.3948717,319.80255,-9.3158464
1793,1793,145.3495,9.2619295,0.67718643,0.0,0,8.4631929,0.0,0.045881379,112.02937,9.3339376,320.15952,-9.3170404
1795,1795,145.3499,9.4344234,0.7357235,0.0,0,8.4075289,0.0,0.04956552,113.95612,9.2628155,320.51648,-9.3162613
1797,1797,145.3503,9.5811663,0.83589554,0.0,0,8.3518648,0.0,0.056869429,115.49976,9.1895733,320.87344,-9.315156
1799,1799,145.3507,9.3478336,0.90998578,0.0,0,8.2962008,0.0,0.061918445,111.79398,9.1137295,321.23041,-9.3150187
1801,1801,145.3511,9.820158,0.9865672,0.0,0,8.2405367,0.0,0.067581706,116.46179,9.0287142,321.58737,-9.3159885
1803,1803,145.3515,9.7750483,1.0362104,0.0,0,8.1848736,0.0,0.071389034,115.94075,8.9583063,321.94434,-9.3161716
1805,1805,145.3519,10.08486,1.0818173,0.0,0,8.1292095,0.0,0.07423576,118.89756,8.8948717,322.3013,-9.3164167
1807,1807,145.3523,9.836441,1.1515244,0.0,0,8.0735445,0.0,0.079599746,116.10883,8.8359079,322.65826,-9.3161812
1809,1809,145.3527,10.16033,1.2050501,0.0,0,8.0196619,0.0,0.083409451,118.18311,8.7785368,323.01523,-9.3153267
1811,1811,145.3531,10.376104,1.270101,0.0,0,7.9666953,0.0,0.087724119,121.21696,8.7132788,323.37219,-9.3137732
1813,1813,145.3535,10.232169,1.356642,0.0,0,7.9137354,0.0,0.094499297,118.4886,8.6463976,323.72916,-9.3141212
1815,1815,145.3539,10.292136,1.4203268,0.0,0,7.860775,0.0,0.098840475,118.79254,8.5752439,324.08612,-9.3154898
1817,1817,145.3543,10.255066,1.4888161,0.0,0,7.8078156,0.0,0.1040088,117.42741,8.5095425,324.44308,-9.3162203
1819,1819,145.3547,10.602777,1.5284463,0.0,0,7.7548552,0.0,0.10751843,120.97454,8.4440269,324.80005,-9.3149986
1821,1821,145.3551,10.545729,1.5767556,0.0,0,7.7018952,0.0,0.11030245,120.41978,8.3885984,325.15698,-9.3147964
1823,1823,145.3555,10.563396,1.6410153,0.0,0,7.6489348,0.0,0.11553208,119.70208,8.3359747,325.51395,-9.3150949
1825,1825,145.3559,10.634315,1.682781,0.0,0,7.5959754,0.0,0.1187636,120.15068,8.2807617,325.87091,-9.3158445
1827,1827,145.3563,10.8511,1.7505757,0.0,0,7.543015,0.0,0.12312802,122.02338,8.2245827,326.22787,-9.3155489
1829,1829,145.3567,10.787808,1.8130404,0.0,0,7.4900556,0.0,0.12865549,120.91234,8.1603842,326.58484,-9.3155947
1831,1831,145.3571,10.841446,1.8701493,0.0,0,7.4370952,0.0,0.13267289,120.80164,8.0993671,326.9418,-9.3154116
1833,1833,145.3575,10.817694,1.935563,0.0,0,7.384666,0.0,0.13753572,120.12384,8.0409317,327.29877,-9.3155127
1835,1835,145.3579,10.967612,1.9691062,0.0,0,7.3341718,0.0,0.14078371,121.02966,7.9840689,327.65573,-9.314909
1837,1837,145.3583,11.048606,2.0202518,0.0,0,7.2838035,0.0,0.14400601,121.94984,7.9302726,328.0127,-9.3156452
1839,1839,145.3587,10.998349,2.0837977,0.0,0,7.2334356,0.0,0.14912111,120.63212,7.8831692,328.11612,-9.3151617
1841,1841,145.3591,11.146846,2.1194792,0.0,0,7.1830673,0.0,0.15224707,121.78087,7.8321624,328.21951,-9.3152723
1843,1843,145.3595,11.197383,2.181608,0.0,0,7.132699,0.0,0.15640248,121.8415,7.7748337,328.32294,-9.3152809
1845,1845,145.3599,11.270795,2.2407343,0.0,0,7.0823312,0.0,0.16153124,122.15798,7.7192364,328.42633,-9.3154793
1847,1847,145.3603,11.219711,2.2907884,0.0,0,7.0319633,0.0,0.16535455,121.13268,7.6661391,328.52975,-9.3147182
1849,1849,145.3607,11.329184,2.34747,0.0,0,6.981595,0.0,0.16958335,121.57584,7.6091375,328.63318,-9.3144426
1851,1851,145.3611,11.398238,2.3855007,0.0,0,6.9312272,0.0,0.17322819,121.96676,7.558929,328.73657,-9.3157501
1853,1853,145.3615,11.46708,2.437978,0.0,0,6.8808589,0.0,0.17687644,122.24611,7.5112925,328.84,-9.3156776
1855,1855,145.3619,11.421556,2.4902947,0.0,0,6.8304915,0.0,0.18104419,121.39384,7.4594369,328.94339,-9.3151941
1857,1857,145.3623,11.523431,2.5289693,0.0,0,6.7801232,0.0,0.18459366,121.73848,7.4095306,329.04681,-9.3149996
1859,1859,145.3627,11.660517,2.5880349,0.0,0,6.7313666,0.0,0.18858768,122.9435,7.3611298,329.15021,-9.3160486
1861,1861,145.3631,11.635626,2.6357527,0.0,0,6.6834412,0.0,0.19285068,122.13582,7.3105125,329.25363,-9.3164663
1863,1863,145.3635,11.666158,2.682647,0.0,0,6.6355214,0.0,0.19695407,122.00462,7.2620263,329.35706,-9.3162928
1865,1865,145.3639,11.685287,2.7384562,0.0,0,6.5876012,0.0,0.20077999,121.5973,7.209074,329.46045,-9.315732
1867,1867,145.3643,11.827026,2.7731745,0.0,0,6.5396814,0.0,0.20421819,122.64501,7.1595039,329.56387,-9.3151083
1869,1869,145.3647,11.868717,2.8214157,0.0,0,6.4917617,0.0,0.20802198,122.68496,7.1126218,329.66727,-9.3157148
1871,1871,145.3651,11.878183,2.8777595,0.0,0,6.4438419,0.0,0.21218249,122.25262,7.0652771,329.77069,-9.3159742
1873,1873,145.3655,11.936681,2.9180574,0.0,0,6.3959212,0.0,0.21626019,122.36556,7.016705,329.87411,-9.3165121
1875,1875,145.3659,12.004195,2.9709218,0.0,0,6.3480015,0.0,0.22024365,122.58543,6.9691749,329.97751,-9.3164997
1877,1877,145.3663,12.053376,3.0239697,0.0,0,6.3000817,0.0,0.22444713,122.60505,6.9207973,330.08093,-9.3155546
1879,1879,145.3667,12.09889,3.0664411,0.0,0,6.252162,0.0,0.22862107,122.56306,6.8696728,330.18433,-9.3149824
1881,1881,145.3671,12.130629,3.1119978,0.0,0,6.2042418,0.0,0.23197849,122.47265,6.8227472,330.28775,-9.3148041
1883,1883,145.3675,12.207823,3.1594503,0.0,0,6.1568022,0.0,0.23606621,122.67876,6.7739677,330.39114,-9.3159618
1885,1885,145.3679,12.239449,3.2035394,0.0,0,6.1111116,0.0,0.24008065,122.59766,6.7246799,330.49457,-9.3161173
1887,1887,145.3683,12.304245,3.2508836,0.0,0,6.0655355,0.0,0.24358386,122.59291,6.6753869,330.59799,-9.3156919
1889,1889,145.3687,12.387367,3.301276,0.0,0,6.0199599,0.0,0.24844575,122.93473,6.6301875,330.32898,-9.3150749
1891,1891,145.3691,12.439863,3.3495796,0.0,0,5.9743834,0.0,0.25236797,122.99387,6.581625,330.04037,-9.3156385
1893,1893,145.3695,12.449239,3.3985584,0.0,0,5.9288073,0.0,0.25628594,122.66602,6.5341783,329.75177,-9.315587
1895,1895,145.3699,12.488713,3.4463999,0.0,0,5.8832316,0.0,0.26103202,122.41122,6.4813476,329.46317,-9.3154325
1897,1897,145.3703,12.596533,3.493907,0.0,0,5.8376555,0.0,0.26457199,122.96808,6.436604,329.17456,-9.3164759
1899,1899,145.3707,12.652785,3.5407636,0.0,0,5.792079,0.0,0.26867792,123.18294,6.3877544,328.88599,-9.316184
1901,1901,145.3711,12.692381,3.5873034,0.0,0,5.7465034,0.0,0.27333358,122.83974,6.3365207,328.59738,-9.3153973
1903,1903,145.3715,12.712467,3.6386743,0.0,0,5.7009273,0.0,0.27703065,122.6823,6.2893562,328.30878,-9.3155441
1905,1905,145.3719,12.759233,3.6852655,0.0,0,5.6553516,0.0,0.28158879,122.56457,6.241046,328.02017,-9.315567
1907,1907,145.3723,12.86779,3.7279541,0.0,0,5.6097751,0.0,0.28558505,122.99948,6.1944518,327.73157,-9.3164654
1909,1909,145.3727,12.919403,3.7814686,0.0,0,5.5656581,0.0,0.2895599,123.14365,6.1480951,327.44296,-9.3172808
1911,1911,145.3731,12.924212,3.8263323,0.0,0,5.5222936,0.0,0.29420269,122.57702,6.1016598,327.15439,-9.3167839
1913,1913,145.3735,12.970685,3.8717263,0.0,0,5.4789333,0.0,0.29818565,122.48615,6.0528455,326.86578,-9.315733
1915,1915,145.3739,13.052155,3.9270244,0.0,0,5.4355731,0.0,0.30276167,122.72491,6.0046673,326.57718,-9.3165493
1917,1917,145.3743,13.116366,3.9652946,0.0,0,5.3922133,0.0,0.30701089,122.75331,5.9573665,326.28857,-9.3157635
1919,1919,145.3747,13.161291,4.0107231,0.0,0,5.3488531,0.0,0.31054819,122.81117,5.9084525,325.99997,-9.3160906
1921,1921,145.3751,13.186913,4.0660377,0.0,0,5.3054934,0.0,0.31550717,122.41509,5.8613358,325.71136,-9.3165092
1923,1923,145.3755,13.255588,4.1047983,0.0,0,5.2621331,0.0,0.31964844,122.5863,5.8121991,325.42276,-9.3162994
1925,1925,145.3759,13.320472,4.1544309,0.0,0,5.2187734,0.0,0.32348779,122.7011,5.768878,325.13419,-9.3157988
1927,1927,145.3763,13.391827,4.2027903,0.0,0,5.1754136,0.0,0.32839429,122.71463,5.7179842,324.84558,-9.3148079
1929,1929,145.3767,13.435559,4.2444611,0.0,0,5.1320534,0.0,0.33239204,122.76002,5.674592,324.55698,-9.3158188
1931,1931,145.3771,13.476371,4.2948308,0.0,0,5.0886931,0.0,0.33653468,122.49831,5.6264181,324.26837,-9.3163433
1933,1933,145.3775,13.528767,4.3398843,0.0,0,5.0457678,0.0,0.34150904,122.35788,5.5802889,323.97977,-9.3170147
1935,1935,145.3779,13.587287,4.3835106,0.0,0,5.0044241,0.0,0.34523693,122.45152,5.5343661,323.69116,-9.3169279
1937,1937,145.3783,13.657524,4.4304953,0.0,0,4.9631839,0.0,0.34939677,122.58817,5.487896,323.40259,-9.314764
1939,1939,145.3787,13.708463,4.4732122,0.0,0,4.9219437,0.0,0.35420689,122.51786,5.4407787,322.97229,-9.3136292
1941,1941,145.3791,13.756344,4.5218229,0.0,0,4.8807039,0.0,0.35802418,122.37095,5.3953376,322.52628,-9.3158083
1943,1943,145.3795,13.803195,4.5681252,0.0,0,4.8394637,0.0,0.3626467,122.19323,5.3496981,322.08026,-9.3163452
1945,1945,145.3799,13.863527,4.609097,0.0,0,4.798224,0.0,0.36719409,122.17106,5.3066034,321.63422,-9.3165302
1947,1947,145.3803,13.934011,4.6623287,0.0,0,4.7569838,0.0,0.3713682,122.33374,5.2606521,321.1882,-9.3164272
1949,1949,145.3807,13.987248,4.702589,0.0,0,4.7157435,0.0,0.3758482,122.25545,5.2185717,320.74219,-9.3163319
1951,1951,145.3811,14.024712,4.7434626,0.0,0,4.6745038,0.0,0.37995413,122.08483,5.1717415,320.29617,-9.3160324
1953,1953,145.3815,14.069573,4.7955317,0.0,0,4.6332641,0.0,0.38418126,121.94036,5.1260519,319.85016,-9.3159876
1955,1955,145.3819,14.153996,4.8333783,0.0,0,4.5920234,0.0,0.38875997,122.03349,5.0838027,319.40411,-9.3161135
1957,1957,145.3823,14.22968,4.878057,0.0,0,4.5507836,0.0,0.39288718,122.25249,5.0363998,318.9581,-9.3162336
1959,1959,145.3827,14.26684,4.9308777,0.0,0,4.5108657,0.0,0.39774284,122.04605,4.9930782,318.51208,-9.3161449
1961,1961,145.3831,14.299958,4.9660568,0.0,0,4.4716296,0.0,0.40213978,121.83952,4.9485316,318.06607,-9.3151999
1963,1963,145.3835,14.349673,5.0091023,0.0,0,4.4323974,0.0,0.4056983,121.78403,4.9045329,317.62006,-9.3153162
1965,1965,145.3839,14.427171,5.0566964,0.0,0,4.3931651,0.0,0.41056174,121.78588,4.8635359,317.17401,-9.3166332
1967,1967,145.3843,14.50726,5.0939651,0.0,0,4.3539338,0.0,0.41480756,121.93793,4.8206005,316.728,-9.3159981
1969,1969,145.3847,14.563496,5.1402035,0.0,0,4.3147016,0.0,0.41876391,121.97079,4.7753077,316.28198,-9.3155851
1971,1971,145.3851,14.600572,5.1856389,0.0,0,4.2754693,0.0,0.42396945,121.60506,4.7348747,315.83597,-9.3156586
1973,1973,145.3855,14.653243,5.2227144,0.0,0,4.236237,0.0,0.42781186,121.57623,4.6916733,315.38995,-9.3157005
1975,1975,145.3859,14.73377,5.268609,0.0,0,4.1970053,0.0,0.43197659,121.69759,4.6449194,314.94391,-9.31633
1977,1977,145.3863,14.819022,5.3123989,0.0,0,4.1577735,0.0,0.43718794,121.74097,4.6034255,314.49789,-9.3158903
1979,1979,145.3867,14.853702,5.3528996,0.0,0,4.1185412,0.0,0.44090301,121.68674,4.5588655,314.05188,-9.3152485
1981,1981,145.3871,14.904063,5.3959217,0.0,0,4.0793095,0.0,0.44519693,121.57939,4.5161276,313.60587,-9.3162689
1983,1983,145.3875,14.964646,5.4336944,0.0,0,4.0404716,0.0,0.44993505,121.40041,4.4763865,313.15982,-9.3171139
1985,1985,145.3879,15.059175,5.4782987,0.0,0,4.0030656,0.0,0.45365626,121.69687,4.4346414,312.71381,-9.3170948
1987,1987,145.3883,15.128291,5.5200601,0.0,0,3.9657531,0.0,0.45840037,121.71861,4.3929553,312.26779,-9.3165026
1989,1989,145.3887,15.177887,5.5560036,0.0,0,3.928441,0.0,0.46275082,121.62296,4.3538451,312.15421,-9.3157825
1991,1991,145.3891,15.209,5.604187,0.0,0,3.8911293,0.0,0.46682423,121.44041,4.3129764,312.09927,-9.315382
1993,1993,145.3895,15.27165,5.6397724,0.0,0,3.8538172,0.0,0.47134712,121.25555,4.2732353,312.04434,-9.3156347
1995,1995,145.3899,15.366763,5.6756248,0.0,0,3.8165052,0.0,0.47519577,121.56513,4.2340813,311.98941,-9.317131
1997,1997,145.3903,15.445481,5.7225699,0.0,0,3.7791932,0.0,0.47932947,121.74076,4.1978869,311.93445,-9.3170118
1999,1999,145.3907,15.478781,5.7532353,0.0,0,3.7418811,0.0,0.48377526,121.42281,4.1556196,311.87952,-9.3157539
2001,2001,145.3911,15.532796,5.7926402,0.0,0,3.7045693,0.0,0.48756987,121.41605,4.1187921,311.82458,-9.3154669
2003,2003,145.3915,15.60328,5.8419385,0.0,0,3.6672573,0.0,0.49238837,121.34052,4.0755992,311.76965,-9.3151684
2005,2005,145.3919,15.707378,5.8718085,0.0,0,3.629945,0.0,0.49672118,121.62343,4.0394917,311.71472,-9.3156681
2007,2007,145.3923,15.7617,5.912189,0.0,0,3.5926332,0.0,0.50037223,121.63718,4.0008817,311.65979,-9.3163691
2009,2009,145.3927,15.803577,5.9537306,0.0,0,3.5565164,0.0,0.50522989,121.38363,3.9613748,311.60486,-9.3159142
2011,2011,145.3931,15.85992,5.9844642,0.0,0,3.5210166,0.0,0.50909859,121.3849,3.922298,311.54993,-9.3171387
2013,2013,145.3935,15.942915,6.0263019,0.0,0,3.4855206,0.0,0.51287228,121.47105,3.8851831,311.49496,-9.3159142
2015,2015,145.3939,16.032717,6.0642824,0.0,0,3.4500246,0.0,0.51788455,121.52476,3.8458343,311.44003,-9.3149281
2017,2017,145.3943,16.097336,6.0990767,0.0,0,3.4145288,0.0,0.52158743,121.61192,3.8093841,311.3851,-9.3149004
2019,2019,145.3947,16.15307,6.1411848,0.0,0,3.3790326,0.0,0.52577955,121.51527,3.7723038,311.33017,-9.3157816
2021,2021,145.3951,16.212093,6.1773295,0.0,0,3.3435366,0.0,0.53077859,121.35873,3.7350345,311.27524,-9.3157415
2023,2023,145.3955,16.301773,6.2146821,0.0,0,3.3080406,0.0,0.53446335,121.50634,3.6972136,311.22031,-9.3157177
2025,2025,145.3959,16.385777,6.253119,0.0,0,3.2725446,0.0,0.53860193,121.71057,3.6600533,311.16537,-9.315443
2027,2027,145.3963,16.473322,6.2852669,0.0,0,3.2370486,0.0,0.54335225,121.73106,3.6223135,311.11044,-9.3155537
2029,2029,145.3967,16.534405,6.32762,0.0,0,3.2015524,0.0,0.54692727,121.77985,3.5817077,311.05548,-9.3162661
2031,2031,145.3971,16.60338,6.3628778,0.0,0,3.1660566,0.0,0.55168205,121.69889,3.5484912,311.00055,-9.3159246
2033,2033,145.3975,16.678679,6.3976898,0.0,0,3.1309149,0.0,0.55610365,121.75684,3.5118937,310.94562,-9.315156
2035,2035,145.3979,16.775103,6.4443979,0.0,0,3.0970623,0.0,0.56022024,121.88903,3.4734719,310.89069,-9.3154612
2037,2037,145.3983,16.86721,6.4743314,0.0,0,3.0632942,0.0,0.5648858,122.0095,3.4364722,310.83575,-9.3155575
2039,2039,145.3987,16.926798,6.5091672,0.0,0,3.0295262,0.0,0.5687691,121.94622,3.3984516,310.74466,-9.3148899
2041,2041,145.3991,16.996281,6.5528612,0.0,0,2.9957583,0.0,0.57311064,121.98711,3.365056,310.64456,-9.3149767
2043,2043,145.3995,17.079851,6.580781,0.0,0,2.9619904,0.0,0.57765406,122.00051,3.329268,310.54443,-9.3150225
2045,2045,145.3999,17.185518,6.6163812,0.0,0,2.9282222,0.0,0.5812428,122.27335,3.2919786,310.44431,-9.3134756
2047,2047,145.4003,17.26255,6.6616063,0.0,0,2.894454,0.0,0.58635902,122.28708,3.2547753,310.34418,-9.3141537
2049,2049,145.4007,17.341618,6.6925097,0.0,0,2.8606861,0.0,0.59102321,122.23907,3.2178783,310.24405,-9.3154812
2051,2051,145.4011,17.407516,6.7340231,0.0,0,2.8269181,0.0,0.59496254,122.16257,3.1831932,310.14395,-9.3165007
2053,2053,145.4015,17.495237,6.7725968,0.0,0,2.7931502,0.0,0.60018712,122.16946,3.1444256,310.04382,-9.3153429
2055,2055,145.4019,17.610283,6.7994919,0.0,0,2.7593822,0.0,0.60389775,122.49356,3.1117616,309.9437,-9.3144083
2057,2057,145.4023,17.704685,6.8382421,0.0,0,2.7256143,0.0,0.60757065,122.66817,3.0730295,309.84357,-9.3130627
2059,2059,145.4027,17.776243,6.8728418,0.0,0,2.6929309,0.0,0.61286932,122.60551,3.0394704,309.74344,-9.3142042
2061,2061,145.4031,17.844446,6.9062877,0.0,0,2.6608074,0.0,0.6165936,122.60385,3.0048943,309.64334,-9.3160372
2063,2063,145.4035,17.944025,6.9478598,0.0,0,2.6286871,0.0,0.62120402,122.70034,2.9693179,309.54321,-9.315691
2065,2065,145.4039,18.06255,6.9790401,0.0,0,2.5965672,0.0,0.62634963,122.81919,2.9309521,309.44308,-9.3155022
2067,2067,145.4043,18.158819,7.0152941,0.0,0,2.5644472,0.0,0.62975669,123.10159,2.8957801,309.34296,-9.3144608
2069,2069,145.4047,18.218752,7.0519409,0.0,0,2.5323269,0.0,0.6342957,122.97656,2.8641169,309.24283,-9.3146038
2071,2071,145.4051,18.301212,7.0816784,0.0,0,2.5002072,0.0,0.63918024,122.90379,2.8274968,309.14273,-9.3144703
2073,2073,145.4055,18.407465,7.1238313,0.0,0,2.4680872,0.0,0.64313525,123.12263,2.7931039,309.0426,-9.3149242
2075,2075,145.4059,18.531143,7.156126,0.0,0,2.4359672,0.0,0.64809531,123.30791,2.757067,308.94247,-9.3146477
2077,2077,145.4063,18.615681,7.1868858,0.0,0,2.4038472,0.0,0.65229297,123.40675,2.7220848,308.84235,-9.3134108
2079,2079,145.4067,18.689507,7.2289419,0.0,0,2.3717272,0.0,0.65635455,123.36538,2.6858547,308.74222,-9.3141346
2081,2081,145.4071,18.770338,7.2549767,0.0,0,2.339607,0.0,0.66092622,123.34953,2.6528552,308.64212,-9.3153067
2083,2083,145.4075,18.887068,7.2881699,0.0,0,2.3078086,0.0,0.66490662,123.54025,2.6227446,308.54199,-9.3150425
2085,2085,145.4079,19.009777,7.3332467,0.0,0,2.2771802,0.0,0.66983336,123.81553,2.5881803,308.44186,-9.3149214
2087,2087,145.4083,19.09952,7.3584981,0.0,0,2.2466278,0.0,0.6747731,123.84183,2.5540271,308.34174,-9.313405
2089,2089,145.4087,19.173231,7.3922062,0.0,0,2.2160761,0.0,0.67812169,123.82797,2.5207229,308.18396,-9.3139982
2091,2091,145.4091,19.274975,7.4293766,0.0,0,2.185524,0.0,0.6830253,123.89635,2.4874446,308.00693,-9.3142281
2093,2093,145.4095,19.397587,7.4522653,0.0,0,2.1549721,0.0,0.68707621,124.12061,2.4557815,307.82993,-9.3147116
2095,2095,145.4099,19.516117,7.4896855,0.0,0,2.1244199,0.0,0.69062608,124.49609,2.4234967,307.65289,-9.3134251
2097,2097,145.4103,19.594885,7.5255318,0.0,0,2.093868,0.0,0.69632834,124.32772,2.3862033,307.47589,-9.312561
2099,2099,145.4107,19.680138,7.5542059,0.0,0,2.0633161,0.0,0.7003175,124.35135,2.355556,307.29889,-9.3131104
2101,2101,145.4111,19.779345,7.5916219,0.0,0,2.0327642,0.0,0.70439738,124.40973,2.3260887,307.12186,-9.3141031
2103,2103,145.4115,19.922777,7.6214671,0.0,0,2.002212,0.0,0.70960259,124.64616,2.2905519,306.94485,-9.3141098
2105,2105,145.4119,20.040173,7.6496029,0.0,0,1.9716599,0.0,0.7128644,124.99816,2.2603362,306.76782,-9.3131952
2107,2107,145.4123,20.123316,7.6843224,0.0,0,1.941108,0.0,0.71712267,125.04436,2.224896,306.59082,-9.3131542
2109,2109,145.4127,20.20743,7.7132583,0.0,0,1.9115354,0.0,0.72239727,124.87222,2.1944861,306.41382,-9.3125658
2111,2111,145.4131,20.321924,7.7490435,0.0,0,1.8824683,0.0,0.72596467,125.08195,2.1626904,306.23679,-9.313343
2113,2113,145.4135,20.458616,7.782249,0.0,0,1.8534042,0.0,0.73090672,125.31385,2.1292284,306.05978,-9.3138905
2115,2115,145.4139,20.567446,7.8081837,0.0,0,1.8243402,0.0,0.73544276,125.42704,2.0988569,305.88275,-9.3133984
2117,2117,145.4143,20.662714,7.8443384,0.0,0,1.7952763,0.0,0.73878664,125.59727,2.0701292,305.70575,-9.3125963
2119,2119,145.4147,20.768538,7.8701725,0.0,0,1.7662122,0.0,0.74360234,125.5593,2.0395489,305.52875,-9.3130989
2121,2121,145.4151,20.893414,7.8977041,0.0,0,1.7371483,0.0,0.74760044,125.85791,2.0088854,305.35172,-9.3133249
2123,2123,145.4155,21.014761,7.9380231,0.0,0,1.7080842,0.0,0.75192398,126.05243,1.9826285,305.17471,-9.3128195
2125,2125,145.4159,21.139652,7.9619899,0.0,0,1.6790203,0.0,0.75687027,126.20635,1.9510964,304.99768,-9.3124046
2127,2127,145.4163,21.236443,7.9927764,0.0,0,1.6499562,0.0,0.7605533,126.32869,1.91975,304.82068,-9.3115759
2129,2129,145.4167,21.337566,8.0317755,0.0,0,1.6208922,0.0,0.76564145,126.30177,1.8921645,304.64368,-9.3127708
2131,2131,145.4171,21.455893,8.0509176,0.0,0,1.5918282,0.0,0.76991326,126.42387,1.8622296,304.46664,-9.3130217
2133,2133,145.4175,21.594263,8.081356,0.0,0,1.5630547,0.0,0.7729283,126.82248,1.8313737,304.28964,-9.313098
2135,2135,145.4179,21.724215,8.1168652,0.0,0,1.5353372,0.0,0.77829182,126.91665,1.8021667,304.11261,-9.3131018
2137,2137,145.4183,21.847078,8.1376162,0.0,0,1.5076891,0.0,0.78226364,127.11463,1.7720401,303.93561,-9.3118515
2139,2139,145.4187,21.956779,8.1731863,0.0,0,1.4800411,0.0,0.78603673,127.25848,1.7416302,303.76495,-9.3127384
2141,2141,145.4191,22.082439,8.2049894,0.0,0,1.4523932,0.0,0.79179496,127.30093,1.7125723,303.59702,-9.3133936
2143,2143,145.4195,22.227951,8.2286215,0.0,0,1.4247452,0.0,0.79525721,127.71117,1.6825166,303.42911,-9.3132267
2145,2145,145.4199,22.361877,8.2620344,0.0,0,1.3970972,0.0,0.79911858,127.96227,1.6517516,303.26117,-9.3125744
2147,2147,145.4203,22.485126,8.2876863,0.0,0,1.3694493,0.0,0.80441189,128.00716,1.6219363,303.09323,-9.3118458
2149,2149,145.4207,22.593245,8.3160772,0.0,0,1.3418012,0.0,0.80787581,128.17703,1.5937688,302.92532,-9.3118792
2151,2151,145.4211,22.724894,8.3481426,0.0,0,1.3141533,0.0,0.81230128,128.35402,1.5651712,302.75739,-9.3132973
2153,2153,145.4215,22.884104,8.3726139,0.0,0,1.2865052,0.0,0.81746191,128.58804,1.5339439,302.58945,-9.3126917
2155,2155,145.4219,23.025541,8.407176,0.0,0,1.2588573,0.0,0.82093686,128.90663,1.5043277,302.42154,-9.3126154
2157,2157,145.4223,23.137955,8.4350147,0.0,0,1.2312093,0.0,0.82573128,128.94054,1.4771988,302.2536,-9.3118267
2159,2159,145.4227,23.257929,8.4569521,0.0,0,1.2044512,0.0,0.83005458,129.07986,1.45061,302.08566,-9.3109035
2161,2161,145.4231,23.39662,8.4934015,0.0,0,1.1781523,0.0,0.83378816,129.29781,1.4216355,301.91776,-9.311101
2163,2163,145.4235,23.556932,8.5154009,0.0,0,1.1518563,0.0,0.83870137,129.55846,1.3923171,301.74982,-9.3117304
2165,2165,145.4239,23.699226,8.5408697,0.0,0,1.1255603,0.0,0.84243071,129.85747,1.3677157,301.58188,-9.3119459
2167,2167,145.4243,23.817261,8.5774965,0.0,0,1.0992643,0.0,0.84667486,130.00577,1.3402641,301.41397,-9.3122282
2169,2169,145.4247,23.952593,8.594779,0.0,0,1.0729682,0.0,0.85139847,130.08972,1.3117783,301.24603,-9.3109455
2171,2171,145.4251,24.098328,8.6214857,0.0,0,1.0466722,0.0,0.85448742,130.46448,1.2841561,301.07809,-9.3101778
2173,2173,145.4255,24.269234,8.6575222,0.0,0,1.0203762,0.0,0.85966349,130.69427,1.2554632,300.91019,-9.3102274
2175,2175,145.4259,24.422287,8.6755276,0.0,0,0.99408025,0.0,0.86413324,130.96291,1.2291278,300.74225,-9.3111601
2177,2177,145.4263,24.539808,8.705368,0.0,0,0.96778423,0.0,0.86737138,131.20174,1.2053045,300.57431,-9.3124018
2179,2179,145.4267,24.67049,8.7373886,0.0,0,0.94148827,0.0,0.87301648,131.15651,1.1755973,300.4064,-9.312665
2181,2181,145.4271,24.837381,8.7543297,0.0,0,0.91519231,0.0,0.87648922,131.53241,1.1482499,300.23846,-9.3108873
2183,2183,145.4275,25.018932,8.785346,0.0,0,0.88916039,0.0,0.87980586,132.08046,1.1212336,300.07053,-9.3101244
2185,2185,145.4279,25.165012,8.8109922,0.0,0,0.86408937,0.0,0.88549894,132.10007,1.0937063,299.90262,-9.3101664
2187,2187,145.4283,25.279263,8.8334637,0.0,0,0.83908123,0.0,0.88864994,132.315,1.0662915,299.73468,-9.3104076
2189,2189,145.4287,25.429262,8.8651495,0.0,0,0.8140732,0.0,0.89294654,132.4577,1.0416036,299.46555,-9.3110781
2191,2191,145.4291,25.592455,8.8873138,0.0,0,0.78906524,0.0,0.89826787,132.63181,1.011906,299.14194,-9.3102818
2193,2193,145.4295,25.776255,8.9119406,0.0,0,0.76405728,0.0,0.90112066,133.17151,0.98602092,298.81833,-9.3103313
2195,2195,145.4299,25.915066,8.9379082,0.0,0,0.73904926,0.0,0.90523374,133.3679,0.96268874,298.49469,-9.3110046
2197,2197,145.4303,26.052429,8.9591141,0.0,0,0.71404123,0.0,0.91009754,133.45343,0.9348191,298.17108,-9.3117065
2199,2199,145.4307,26.200193,8.9918594,0.0,0,0.68903327,0.0,0.91369128,133.68503,0.90908307,297.84747,-9.3109398
2201,2201,145.4311,26.374779,9.0147886,0.0,0,0.66402531,0.0,0.91839004,133.93427,0.88692677,297.52383,-9.3097134
2203,2203,145.4315,26.558233,9.0325241,0.0,0,0.63901722,0.0,0.92220157,134.35236,0.86046463,297.20023,-9.310071
2205,2205,145.4319,26.687675,9.0650473,0.0,0,0.61400926,0.0,0.92558837,134.61238,0.83878541,296.87662,-9.3087587
2207,2207,145.4323,26.817062,9.081892,0.0,0,0.58900124,0.0,0.93024355,134.60709,0.81418872,296.55301,-9.3108435
2209,2209,145.4327,26.980989,9.1043777,0.0,0,0.56478834,0.0,0.93362617,134.97208,0.78764272,296.22937,-9.3101072
2211,2211,145.4331,27.167038,9.139699,0.0,0,0.54098582,0.0,0.93827593,135.24716,0.7624867,295.90576,-9.310113
2213,2213,145.4335,27.329905,9.1552763,0.0,0,0.51718581,0.0,0.9431411,135.44353,0.74044663,295.58215,-9.3096189
2215,2215,145.4339,27.490152,9.1802921,0.0,0,0.49338579,0.0,0.94598466,135.81656,0.71733522,295.25854,-9.3088045
2217,2217,145.4343,27.637178,9.2105255,0.0,0,0.46958581,0.0,0.95109659,135.89868,0.69006115,294.93491,-9.3100662
2219,2219,145.4347,27.80311,9.2218285,0.0,0,0.44578579,0.0,0.95458758,136.19438,0.66835046,294.6113,-9.3100042
2221,2221,145.4351,27.988577,9.2480583,0.0,0,0.42198581,0.0,0.95720196,136.71288,0.6443103,294.28769,-9.3092651
2223,2223,145.4355,28.175274,9.2742968,0.0,0,0.39818579,0.0,0.96286017,136.84918,0.61902738,293.96405,-9.3098297
2225,2225,145.4359,28.328863,9.29249,0.0,0,0.37438577,0.0,0.96660733,137.13808,0.59574312,293.64044,-9.3074818
2227,2227,145.4363,28.479105,9.3224916,0.0,0,0.35058579,0.0,0.97014296,137.35324,0.57331687,293.31683,-9.308095
2229,2229,145.4367,28.657524,9.3442984,0.0,0,0.3267858,0.0,0.97578323,137.40276,0.54784691,292.99323,-9.3086882
2231,2231,145.4371,28.837961,9.361536,0.0,0,0.30298579,0.0,0.97835594,137.93607,0.52697229,292.66959,-9.3086557