File: clean data/testID_0189.csv
level_0,index,Time(sec),Force(kN),Jaw(mm),PowAngle(deg),Power(W),Pram,PTemp,Strain,Stress(MPa),Stroke(mm),TC1(C),wedge(mm)
1773,1773,145.3439,0.35393128,0.011412545,0.0,0,9.0337009,0.0,0.00078619545,4.07584,10.056586,301.8837,-9.3209171
1775,1775,145.3443,2.9032261,0.048947934,0.0,0,8.975173,0.0,0.0029687993,31.891806,9.9884005,302.02591,-9.3210335
1777,1777,145.3447,6.0053201,0.11970638,0.0,0,8.9166451,0.0,0.0073651476,73.323784,9.9311657,302.16812,-9.3201752
1779,1779,145.3451,7.0163698,0.18326521,0.0,0,8.8581161,0.0,0.011657521,87.052826,9.8498335,302.3103,-9.3178129
1781,1781,145.3455,7.7792516,0.33178923,0.0,0,8.7995882,0.0,0.021406384,96.448586,9.7586546,302.45251,-9.3155193
1783,1783,145.3459,8.3472624,0.41942498,0.0,0,8.7416477,0.0,0.027670074,102.16488,9.6526222,302.59473,-9.316967
1785,1785,145.3463,9.0797262,0.5078246,0.0,0,8.6858435,0.0,0.033809014,111.1467,9.5461931,302.73694,-9.3166132
1787,1787,145.3467,9.840867,0.58790141,0.0,0,8.6301794,0.0,0.039661292,119.32829,9.4493513,302.87912,-9.3154202
1789,1789,145.3471,9.7956867,0.61265177,0.0,0,8.5745163,0.0,0.0412145,120.38771,9.3692131,303.02133,-9.3139811
1791,1791,145.3475,9.6966286,0.69870597,0.0,0,8.5188513,0.0,0.047211818,117.1378,9.2982283,303.16354,-9.3147802
1793,1793,145.3479,10.327063,0.75331414,0.0,0,8.4631872,0.0,0.051159173,124.54551,9.2296925,303.30573,-9.3153038
1795,1795,145.3483,10.569646,0.82335305,0.0,0,8.4075241,0.0,0.055784121,126.78899,9.1575718,303.44794,-9.3137417
1797,1797,145.3487,10.604038,0.92358863,0.0,0,8.3518591,0.0,0.063070431,127.25227,9.0813713,303.59015,-9.3134928
1799,1799,145.3491,10.438113,1.0001397,0.0,0,8.296196,0.0,0.068274982,123.72739,8.999383,303.69318,-9.3144522
1801,1801,145.3495,10.866286,1.0756201,0.0,0,8.2405319,0.0,0.074054271,128.30952,8.9170513,303.75705,-9.3136396
1803,1803,145.3499,10.869194,1.1229693,0.0,0,8.1848679,0.0,0.077633269,127.83228,8.8478832,303.82089,-9.3131638
1805,1805,145.3503,11.225971,1.1663727,0.0,0,8.1292038,0.0,0.080380775,131.68817,8.7850008,303.88477,-9.3134842
1807,1807,145.3507,10.912686,1.2352401,0.0,0,8.0735397,0.0,0.085730523,127.74438,8.7300577,303.94864,-9.3140554
1809,1809,145.3511,11.347396,1.2814696,0.0,0,8.0196571,0.0,0.088871382,131.45314,8.6747522,304.01251,-9.314188
1811,1811,145.3515,11.399454,1.3510095,0.0,0,7.9666901,0.0,0.093666099,132.31366,8.6118612,304.07639,-9.3128901
1813,1813,145.3519,11.368818,1.4262459,0.0,0,7.9137306,0.0,0.099697784,130.88686,8.5470934,304.14023,-9.3126707
1815,1815,145.3523,11.344615,1.485266,0.0,0,7.8607702,0.0,0.10362391,130.40819,8.4851828,304.2041,-9.3134899
1817,1817,145.3527,11.474097,1.5454344,0.0,0,7.8078103,0.0,0.10832154,130.71414,8.4217367,304.26797,-9.3135281
1819,1819,145.3531,11.700952,1.5704027,0.0,0,7.7548499,0.0,0.11067838,133.32111,8.3666162,304.33185,-9.3130684
1821,1821,145.3535,11.664156,1.6249977,0.0,0,7.70189,0.0,0.11384913,132.49789,8.3192072,304.39572,-9.3131008
1823,1823,145.3539,11.692172,1.6790065,0.0,0,7.6489296,0.0,0.11847019,132.28355,8.2678318,304.45956,-9.3135767
1825,1825,145.3543,11.803009,1.7152658,0.0,0,7.5959702,0.0,0.12121138,132.79063,8.2199001,304.52344,-9.3132858
1827,1827,145.3547,12.003407,1.7850755,0.0,0,7.5430098,0.0,0.12583929,134.72455,8.1644001,304.58731,-9.3132629
1829,1829,145.3551,11.899848,1.8368466,0.0,0,7.4900503,0.0,0.1304986,133.03117,8.1072502,304.65118,-9.3138304
1831,1831,145.3555,11.99805,1.8925656,0.0,0,7.4370899,0.0,0.13438009,133.57556,8.0531273,304.71506,-9.3135166
1833,1833,145.3559,11.958276,1.9507382,0.0,0,7.3846612,0.0,0.13878624,132.41722,7.9988928,304.7789,-9.3136349
1835,1835,145.3563,12.216094,1.9767625,0.0,0,7.3341675,0.0,0.14134759,134.72383,7.9502554,304.84277,-9.3131208
1837,1837,145.3567,12.189178,2.0302484,0.0,0,7.2837992,0.0,0.14473429,134.36201,7.9006,304.90665,-9.3129053
1839,1839,145.3571,12.2327,2.0815215,0.0,0,7.2334309,0.0,0.14900407,134.03166,7.8575521,304.97052,-9.3127966
1841,1841,145.3575,12.294272,2.1176615,0.0,0,7.1830626,0.0,0.15206096,134.40414,7.8098774,305.03439,-9.3132982
1843,1843,145.3579,12.416492,2.1776583,0.0,0,7.1326947,0.0,0.15616331,135.04733,7.7579656,305.09824,-9.3135948
1845,1845,145.3583,12.442512,2.2263279,0.0,0,7.0823264,0.0,0.16037422,135.0159,7.7089982,305.16211,-9.3136892
1847,1847,145.3587,12.449042,2.2733977,0.0,0,7.0319586,0.0,0.16411816,134.28786,7.6554737,305.22598,-9.3128033
1849,1849,145.3591,12.538389,2.3193023,0.0,0,6.9815903,0.0,0.16752063,134.98615,7.6085386,305.20645,-9.312501
1851,1851,145.3595,12.644938,2.3571126,0.0,0,6.9312229,0.0,0.17089505,135.54944,7.5636964,305.10355,-9.3137293
1853,1853,145.3599,12.68571,2.4122441,0.0,0,6.8808546,0.0,0.17483535,135.61453,7.5183892,305.00064,-9.3143921
1855,1855,145.3603,12.673506,2.4560516,0.0,0,6.8304873,0.0,0.17837536,134.98862,7.4697638,304.89774,-9.3136158
1857,1857,145.3607,12.822587,2.5010419,0.0,0,6.7801185,0.0,0.18237145,135.89203,7.4244051,304.79483,-9.3138876
1859,1859,145.3611,12.891481,2.5545075,0.0,0,6.7313623,0.0,0.1861209,136.18964,7.3712196,304.69193,-9.3137617
1861,1861,145.3615,12.917687,2.5978298,0.0,0,6.6834369,0.0,0.18976556,136.02861,7.3241725,304.58905,-9.3134613
1863,1863,145.3619,12.923203,2.6442845,0.0,0,6.6355171,0.0,0.19386986,135.44279,7.2767982,304.48615,-9.3138056
1865,1865,145.3623,13.025687,2.6925905,0.0,0,6.5875969,0.0,0.19714996,135.96576,7.2265673,304.38324,-9.3135786
1867,1867,145.3627,13.143948,2.7359729,0.0,0,6.5396771,0.0,0.2010418,136.86969,7.1812758,304.28033,-9.3127537
1869,1869,145.3631,13.182352,2.7846463,0.0,0,6.4917574,0.0,0.20510542,136.63373,7.1382623,304.17743,-9.3128681
1871,1871,145.3635,13.181738,2.8347106,0.0,0,6.4438376,0.0,0.20867899,136.19748,7.0864592,304.07452,-9.3136911
1873,1873,145.3639,13.291189,2.8769829,0.0,0,6.3959169,0.0,0.21279362,136.62958,7.0360832,303.97162,-9.313694
1875,1875,145.3643,13.381299,2.9230111,0.0,0,6.3479972,0.0,0.2163242,137.18105,6.9917493,303.86874,-9.3134527
1877,1877,145.3647,13.450597,2.9785156,0.0,0,6.3000774,0.0,0.22054821,137.31528,6.9412904,303.76584,-9.3135738
1879,1879,145.3651,13.467866,3.0233846,0.0,0,6.2521577,0.0,0.22505105,136.95171,6.8921037,303.66293,-9.3138208
1881,1881,145.3655,13.526464,3.0681944,0.0,0,6.2042375,0.0,0.22834329,136.97954,6.8456826,303.56003,-9.3138809
1883,1883,145.3659,13.633533,3.1229737,0.0,0,6.1567979,0.0,0.23283207,137.41835,6.7961974,303.45712,-9.3140087
1885,1885,145.3663,13.679527,3.1617079,0.0,0,6.1111078,0.0,0.23665932,137.49463,6.7478585,303.35422,-9.3134851
1887,1887,145.3667,13.765881,3.208154,0.0,0,6.0655317,0.0,0.23992519,137.77748,6.7000728,303.25134,-9.3127966
1889,1889,145.3671,13.828101,3.2624638,0.0,0,6.0199556,0.0,0.24493302,137.80412,6.651566,303.14844,-9.3129454
1891,1891,145.3675,13.883513,3.3066537,0.0,0,5.9743791,0.0,0.24884956,137.79605,6.5989356,303.04553,-9.312974
1893,1893,145.3679,13.941974,3.3600347,0.0,0,5.9288034,0.0,0.25285551,137.82492,6.5483923,302.94263,-9.3132734
1895,1895,145.3683,14.020352,3.4088151,0.0,0,5.8832278,0.0,0.25772855,137.883,6.5012498,302.83972,-9.3132496
1897,1897,145.3687,14.124652,3.4531183,0.0,0,5.8376513,0.0,0.26129246,138.33377,6.4547343,302.73682,-9.3134365
1899,1899,145.3691,14.177032,3.507108,0.0,0,5.7920747,0.0,0.26566577,138.33044,6.4055958,302.68292,-9.3129501
1901,1901,145.3695,14.225111,3.5516112,0.0,0,5.7464995,0.0,0.27024338,138.20444,6.35604,302.67801,-9.3127985
1903,1903,145.3699,14.274396,3.6014972,0.0,0,5.7009234,0.0,0.27388486,138.13519,6.3079634,302.6731,-9.3132544
1905,1905,145.3703,14.370061,3.6496775,0.0,0,5.6553473,0.0,0.2782813,138.42197,6.2523885,302.66818,-9.3136997
1907,1907,145.3707,14.465214,3.6942666,0.0,0,5.6097713,0.0,0.28269869,138.67758,6.2060246,302.66327,-9.3130007
1909,1909,145.3711,14.511313,3.7503479,0.0,0,5.5656543,0.0,0.28686658,138.54373,6.1597943,302.65836,-9.3130102
1911,1911,145.3715,14.537425,3.7946105,0.0,0,5.5222898,0.0,0.29132363,138.32437,6.1102643,302.65344,-9.3134861
1913,1913,145.3719,14.63433,3.8384097,0.0,0,5.4789295,0.0,0.29535967,138.58339,6.0652552,302.64853,-9.3134699
1915,1915,145.3723,14.724981,3.8941774,0.0,0,5.4355693,0.0,0.29956734,138.85248,6.0150437,302.64362,-9.3133574
1917,1917,145.3727,14.793856,3.9344013,0.0,0,5.3922095,0.0,0.30406547,138.92296,5.9682102,302.6387,-9.3130741
1919,1919,145.3731,14.840359,3.9816556,0.0,0,5.3488493,0.0,0.3080458,138.79897,5.9182768,302.63379,-9.3117704
1921,1921,145.3735,14.90051,4.0371213,0.0,0,5.3054895,0.0,0.31267816,138.76077,5.8696265,302.62888,-9.3134375
1923,1923,145.3739,14.996882,4.07511,0.0,0,5.2621293,0.0,0.31689939,139.04742,5.8245316,302.62396,-9.3138247
1925,1925,145.3743,15.070601,4.1228948,0.0,0,5.2187696,0.0,0.32082167,139.13403,5.7731633,302.61905,-9.3133793
1927,1927,145.3747,15.146484,4.1757402,0.0,0,5.1754098,0.0,0.32553998,139.21317,5.7258959,302.61414,-9.3133726
1929,1929,145.3751,15.185553,4.2162566,0.0,0,5.1320496,0.0,0.32991275,138.96524,5.6810427,302.60922,-9.3130932
1931,1931,145.3755,15.26606,4.2660484,0.0,0,5.0886893,0.0,0.33387846,139.0547,5.6334553,302.60431,-9.3130932
1933,1933,145.3759,15.343851,4.3165836,0.0,0,5.045764,0.0,0.33889577,139.15646,5.5854731,302.5994,-9.3132973
1935,1935,145.3763,15.407931,4.3561645,0.0,0,5.0044203,0.0,0.34286359,139.14317,5.538815,302.59448,-9.3130398
1937,1937,145.3767,15.484287,4.4040055,0.0,0,4.9631801,0.0,0.34674665,139.24867,5.4912081,302.58957,-9.3131361
1939,1939,145.3771,15.550694,4.4499965,0.0,0,4.9219403,0.0,0.35175422,139.18764,5.4424539,302.58466,-9.3132706
1941,1941,145.3775,15.603369,4.4936852,0.0,0,4.8807001,0.0,0.35576621,139.11621,5.397109,302.57974,-9.3136196
1943,1943,145.3779,15.668162,4.5422101,0.0,0,4.8394604,0.0,0.36000007,139.10022,5.3519521,302.57483,-9.3130188
1945,1945,145.3783,15.758402,4.5860109,0.0,0,4.7982202,0.0,0.36493412,139.18732,5.3077984,302.56992,-9.3129826
1947,1947,145.3787,15.827971,4.6301837,0.0,0,4.7569804,0.0,0.3686032,139.29723,5.2583838,302.565,-9.3122683
1949,1949,145.3791,15.888907,4.6770549,0.0,0,4.7157402,0.0,0.37307107,139.24568,5.2168183,302.3367,-9.3118305
1951,1951,145.3795,15.93442,4.717773,0.0,0,4.6745005,0.0,0.37780976,138.98624,5.1729307,301.88507,-9.3122082
1953,1953,145.3799,16.01078,4.7668653,0.0,0,4.6332603,0.0,0.38166621,139.11952,5.1269917,301.43347,-9.3131218
1955,1955,145.3803,16.10919,4.8080478,0.0,0,4.59202,0.0,0.38604236,139.31567,5.0840402,300.98187,-9.3129654
1957,1957,145.3807,16.170666,4.8468528,0.0,0,4.5507803,0.0,0.39022279,139.24254,5.0389123,300.53027,-9.312892
1959,1959,145.3811,16.206337,4.8993835,0.0,0,4.5108619,0.0,0.394474,139.04941,4.9944835,300.07864,-9.3128443
1961,1961,145.3815,16.268915,4.9383445,0.0,0,4.4716258,0.0,0.3991057,138.86638,4.9524498,299.62704,-9.312602
1963,1963,145.3819,16.355377,4.9785447,0.0,0,4.432394,0.0,0.40305379,139.05922,4.9106116,299.17545,-9.3123055
1965,1965,145.3823,16.432201,5.0297699,0.0,0,4.3931618,0.0,0.40744126,139.18826,4.8667002,298.72382,-9.3124971
1967,1967,145.3827,16.496738,5.0650172,0.0,0,4.35393,0.0,0.41201472,139.15024,4.8245058,298.27222,-9.3125248
1969,1969,145.3831,16.545191,5.1082082,0.0,0,4.3146982,0.0,0.41577074,138.93257,4.7798076,297.82062,-9.312562
1971,1971,145.3835,16.610826,5.1568065,0.0,0,4.275466,0.0,0.42054266,138.8107,4.7422662,297.36902,-9.3128223
1973,1973,145.3839,16.696196,5.1913519,0.0,0,4.2362337,0.0,0.42479417,138.90799,4.697041,296.91739,-9.312458
1975,1975,145.3843,16.773579,5.2352123,0.0,0,4.1970015,0.0,0.42841122,139.16145,4.6535621,296.46579,-9.313014
1977,1977,145.3847,16.844938,5.2805223,0.0,0,4.1577697,0.0,0.43338874,138.99434,4.6124182,296.01419,-9.3122206
1979,1979,145.3851,16.886728,5.3150468,0.0,0,4.1185379,0.0,0.43746269,138.81328,4.5706253,295.56256,-9.3126068
1981,1981,145.3855,16.962448,5.3598194,0.0,0,4.0793056,0.0,0.44118497,138.9014,4.52668,295.11096,-9.3125086
1983,1983,145.3859,17.040083,5.4014306,0.0,0,4.0404677,0.0,0.44626656,138.74966,4.4880199,294.65936,-9.3116846
1985,1985,145.3863,17.133631,5.4366584,0.0,0,4.0030622,0.0,0.44991529,139.09525,4.4470601,294.20776,-9.3115358
1987,1987,145.3867,17.202787,5.4810658,0.0,0,3.9657497,0.0,0.45392239,139.02005,4.405653,293.75613,-9.3122978
1989,1989,145.3871,17.25642,5.5199184,0.0,0,3.9284377,0.0,0.45895737,138.76915,4.3643303,293.30453,-9.3128462
1991,1991,145.3875,17.315458,5.5598745,0.0,0,3.8911257,0.0,0.46255365,138.80334,4.3234601,292.85294,-9.3123341
1993,1993,145.3879,17.411036,5.6013284,0.0,0,3.8538139,0.0,0.46678296,138.91283,4.284306,292.40134,-9.3120737
1995,1995,145.3883,17.503866,5.6378126,0.0,0,3.8165019,0.0,0.47146931,138.95119,4.2454729,291.94971,-9.3113556
1997,1997,145.3887,17.561583,5.6813765,0.0,0,3.7791896,0.0,0.47516012,139.02571,4.2082858,291.49811,-9.3122778
1999,1999,145.3891,17.610695,5.7183266,0.0,0,3.7418776,0.0,0.47962394,138.67725,4.1662512,291.23676,-9.3132582
2001,2001,145.3895,17.681772,5.7527795,0.0,0,3.7045658,0.0,0.48381931,138.73184,4.1260371,291.1655,-9.3136034
2003,2003,145.3899,17.788834,5.7974534,0.0,0,3.6672537,0.0,0.48757666,138.9789,4.0870261,291.09427,-9.3118181
2005,2005,145.3903,17.864445,5.8330059,0.0,0,3.6299417,0.0,0.49219966,138.96014,4.0498228,291.02304,-9.3115587
2007,2007,145.3907,17.918694,5.8696351,0.0,0,3.5926297,0.0,0.49616975,138.87161,4.0096841,290.95178,-9.3120995
2009,2009,145.3911,17.979952,5.9173894,0.0,0,3.5565133,0.0,0.50053114,138.73866,3.9730885,290.88055,-9.3131857
2011,2011,145.3915,18.067711,5.949471,0.0,0,3.5210135,0.0,0.50526828,138.71234,3.933176,290.80933,-9.3138666
2013,2013,145.3919,18.150291,5.9853783,0.0,0,3.4855173,0.0,0.50877059,138.85474,3.8954439,290.7381,-9.3136816
2015,2015,145.3923,18.234507,6.0302415,0.0,0,3.4500215,0.0,0.51327467,138.94792,3.8565185,290.66684,-9.3115969
2017,2017,145.3927,18.292707,6.0591364,0.0,0,3.4145255,0.0,0.51764387,138.74173,3.8199069,290.59561,-9.31036
2019,2019,145.3931,18.36585,6.0993128,0.0,0,3.3790293,0.0,0.52116376,138.83676,3.7864211,290.52438,-9.3120823
2021,2021,145.3935,18.440466,6.1426721,0.0,0,3.3435335,0.0,0.52622211,138.71098,3.7488542,290.45313,-9.3131161
2023,2023,145.3939,18.532242,6.1731181,0.0,0,3.3080375,0.0,0.53025526,138.82234,3.7094216,290.3819,-9.3135777
2025,2025,145.3943,18.631416,6.2133102,0.0,0,3.2725413,0.0,0.53389096,139.01042,3.6748209,290.31067,-9.3123646
2027,2027,145.3947,18.701141,6.2527556,0.0,0,3.2370453,0.0,0.53913367,138.82039,3.6328847,290.23944,-9.3113823
2029,2029,145.3951,18.767324,6.2856088,0.0,0,3.2015493,0.0,0.54297292,138.75757,3.5958507,290.16818,-9.3116426
2031,2031,145.3955,18.842295,6.326962,0.0,0,3.1660533,0.0,0.5469535,138.7753,3.5603948,290.09695,-9.3129082
2033,2033,145.3959,18.946535,6.3625507,0.0,0,3.1309118,0.0,0.55198759,138.81197,3.5211384,290.02573,-9.3122787
2035,2035,145.3963,19.030437,6.397356,0.0,0,3.0970592,0.0,0.55556548,139.00243,3.4844415,289.95447,-9.3122044
2037,2037,145.3967,19.086979,6.437099,0.0,0,3.0632911,0.0,0.55973619,138.86964,3.4477634,289.88324,-9.311676
2039,2039,145.3971,19.17799,6.4710484,0.0,0,3.0295231,0.0,0.5647648,138.77962,3.408277,289.81201,-9.3109312
2041,2041,145.3975,19.259123,6.5117493,0.0,0,2.9957552,0.0,0.56855559,138.83286,3.3731561,289.74078,-9.3122129
2043,2043,145.3979,19.363125,6.5479755,0.0,0,2.9619873,0.0,0.57300377,138.9166,3.3370588,289.66953,-9.31213
2045,2045,145.3983,19.458267,6.579452,0.0,0,2.9282191,0.0,0.57757306,138.98883,3.3021111,289.5983,-9.3122501
2047,2047,145.3987,19.525724,6.6229339,0.0,0,2.8944509,0.0,0.58158517,138.92834,3.2634025,289.52707,-9.3117447
2049,2049,145.3991,19.612423,6.6561122,0.0,0,2.860683,0.0,0.58619952,138.9026,3.2277679,289.55688,-9.3110361
2051,2051,145.3995,19.698885,6.6906271,0.0,0,2.826915,0.0,0.59055054,138.92183,3.1952159,289.68771,-9.311512
2053,2053,145.3999,19.805119,6.7349796,0.0,0,2.7931471,0.0,0.59484619,139.02351,3.1583555,289.81854,-9.3112183
2055,2055,145.4003,19.90119,6.7636604,0.0,0,2.7593791,0.0,0.59942931,139.06956,3.1208541,289.9494,-9.3110495
2057,2057,145.4007,19.979166,6.7979808,0.0,0,2.7256112,0.0,0.6032061,139.09181,3.0867925,290.08023,-9.3108912
2059,2059,145.4011,20.051014,6.8425775,0.0,0,2.6929281,0.0,0.6080609,138.91682,3.0498593,290.21106,-9.3114491
2061,2061,145.4015,20.134865,6.869792,0.0,0,2.6608045,0.0,0.61261547,138.90797,3.0162539,290.34189,-9.3122282
2063,2063,145.4019,20.250505,6.9054885,0.0,0,2.6286843,0.0,0.61623943,139.11694,2.9781749,290.47272,-9.3113174
2065,2065,145.4023,20.347605,6.9467793,0.0,0,2.5965643,0.0,0.62118912,139.07744,2.943136,290.60355,-9.3111477
2067,2067,145.4027,20.411806,6.9739184,0.0,0,2.5644443,0.0,0.62546974,138.96207,2.9102368,290.73438,-9.3120995
2069,2069,145.4031,20.493876,7.0127382,0.0,0,2.5323241,0.0,0.62922907,139.02905,2.874563,290.8652,-9.3109779
2071,2071,145.4035,20.597023,7.0512729,0.0,0,2.5002043,0.0,0.63473004,138.96344,2.8398938,290.99606,-9.3106384
2073,2073,145.4039,20.704987,7.0797243,0.0,0,2.4680843,0.0,0.63855571,139.10591,2.8018568,291.12689,-9.310709
2075,2075,145.4043,20.808167,7.1187491,0.0,0,2.4359643,0.0,0.64257681,139.27885,2.7685256,291.25772,-9.3114538
2077,2077,145.4047,20.872597,7.1521292,0.0,0,2.4038444,0.0,0.64784265,138.9771,2.7342043,291.38855,-9.3118515
2079,2079,145.4051,20.953396,7.1831751,0.0,0,2.3717244,0.0,0.65153211,138.99319,2.6999595,291.51938,-9.3115292
2081,2081,145.4055,21.055365,7.2207894,0.0,0,2.3396041,0.0,0.65569925,139.09305,2.6672742,291.65021,-9.3102999
2083,2083,145.4059,21.174927,7.2513766,0.0,0,2.307806,0.0,0.66079342,139.13091,2.6335542,291.78104,-9.3100157
2085,2085,145.4063,21.268074,7.286767,0.0,0,2.2771773,0.0,0.66434795,139.31041,2.600174,291.91187,-9.3100901
2087,2087,145.4067,21.333344,7.3211761,0.0,0,2.2466252,0.0,0.66884333,139.09087,2.5672107,292.04269,-9.3111572
2089,2089,145.4071,21.426615,7.350296,0.0,0,2.2160735,0.0,0.67373019,139.03181,2.5349827,292.17355,-9.3110323
2091,2091,145.4075,21.524263,7.3897452,0.0,0,2.1855214,0.0,0.67739767,139.15263,2.5039041,292.30438,-9.3114977
2093,2093,145.4079,21.658627,7.4206352,0.0,0,2.1549692,0.0,0.68228048,139.27509,2.4681237,292.43521,-9.3107014
2095,2095,145.4083,21.734236,7.4489722,0.0,0,2.1244173,0.0,0.68656212,139.24768,2.4359982,292.56604,-9.3100758
2097,2097,145.4087,21.805758,7.4907684,0.0,0,2.0938654,0.0,0.69061762,139.11076,2.4029722,292.69687,-9.3097706
2099,2099,145.4091,21.901405,7.5171976,0.0,0,2.0633135,0.0,0.69537503,139.04079,2.3696151,292.59924,-9.3105984
2101,2101,145.4095,22.021152,7.5488753,0.0,0,2.0327616,0.0,0.69932044,139.2567,2.3391433,292.27325,-9.3122253
2103,2103,145.4099,22.13798,7.5912571,0.0,0,2.0022092,0.0,0.70404041,139.34193,2.301399,291.9473,-9.3111267
2105,2105,145.4103,22.215225,7.6147852,0.0,0,1.9716572,0.0,0.70875788,139.18213,2.271292,291.62134,-9.3099051
2107,2107,145.4107,22.294117,7.6458998,0.0,0,1.9411051,0.0,0.71215928,139.17384,2.2366514,291.29538,-9.3091745
2109,2109,145.4111,22.403122,7.6850495,0.0,0,1.9115326,0.0,0.7171756,139.18762,2.2065566,290.96939,-9.3092918
2111,2111,145.4115,22.509113,7.7073011,0.0,0,1.8824656,0.0,0.72155046,139.24922,2.1749697,290.64343,-9.3099842
2113,2113,145.4119,22.611959,7.7437487,0.0,0,1.8534015,0.0,0.72520602,139.3199,2.1437094,290.31747,-9.3101616
2115,2115,145.4123,22.709169,7.7804322,0.0,0,1.8243376,0.0,0.7308774,139.14059,2.1091475,289.99152,-9.3102388
2117,2117,145.4127,22.783154,7.8040957,0.0,0,1.7952735,0.0,0.73471284,139.12114,2.0806348,289.66553,-9.310585
2119,2119,145.4131,22.904345,7.8378706,0.0,0,1.7662096,0.0,0.73811537,139.26939,2.0492616,289.33957,-9.3105001
2121,2121,145.4135,23.014008,7.8686285,0.0,0,1.7371455,0.0,0.74360764,139.18454,2.0227199,289.01361,-9.3106251
2123,2123,145.4139,23.126564,7.8965635,0.0,0,1.7080816,0.0,0.74715269,139.42757,1.9906484,288.68762,-9.3096333
2125,2125,145.4143,23.210386,7.9323812,0.0,0,1.6790177,0.0,0.75145119,139.37013,1.9604582,288.36166,-9.30937
2127,2127,145.4147,23.297522,7.9627657,0.0,0,1.6499536,0.0,0.75709075,139.12097,1.9320091,288.03571,-9.3100023
2129,2129,145.4151,23.406818,7.994575,0.0,0,1.6208895,0.0,0.76072991,139.21399,1.8998673,287.70975,-9.3105326
2131,2131,145.4155,23.522705,8.0249949,0.0,0,1.5918256,0.0,0.76501471,139.27605,1.8691214,287.38376,-9.3105402
2133,2133,145.4159,23.630579,8.0486765,0.0,0,1.5630522,0.0,0.76953173,139.29707,1.8380908,287.0578,-9.31075
2135,2135,145.4163,23.724714,8.0834188,0.0,0,1.5353347,0.0,0.7730273,139.40509,1.8074805,286.73184,-9.3100109
2137,2137,145.4167,23.818626,8.1135626,0.0,0,1.5076866,0.0,0.77795386,139.24953,1.7786466,286.40585,-9.310298
2139,2139,145.4171,23.932268,8.1409187,0.0,0,1.4800386,0.0,0.78277439,139.20412,1.7492537,286.0799,-9.3097134
2141,2141,145.4175,24.054585,8.1806393,0.0,0,1.4523906,0.0,0.78683293,139.38167,1.7165729,285.75394,-9.3101015
2143,2143,145.4179,24.174246,8.2046795,0.0,0,1.4247426,0.0,0.79175264,139.38173,1.6897907,285.42798,-9.3100204
2145,2145,145.4183,24.268501,8.2306843,0.0,0,1.3970947,0.0,0.7955147,139.41602,1.6614318,285.10199,-9.3098946
2147,2147,145.4187,24.36367,8.2684116,0.0,0,1.3694466,0.0,0.79979581,139.38354,1.6283321,284.77603,-9.3097782
2149,2149,145.4191,24.474001,8.2889862,0.0,0,1.3417987,0.0,0.80460602,139.34264,1.5981454,284.5242,-9.3091774
2151,2151,145.4195,24.598654,8.317584,0.0,0,1.3141507,0.0,0.80803502,139.50909,1.5697389,284.34647,-9.3089151
2153,2153,145.4199,24.718645,8.3576126,0.0,0,1.2865027,0.0,0.81340915,139.46417,1.5406344,284.16873,-9.3083744
2155,2155,145.4203,24.812645,8.3782787,0.0,0,1.2588546,0.0,0.81807762,139.37299,1.5089177,283.991,-9.3091421
2157,2157,145.4207,24.909014,8.4095631,0.0,0,1.2312068,0.0,0.82147187,139.39778,1.4838524,283.81326,-9.3100357
2159,2159,145.4211,25.017738,8.4437695,0.0,0,1.2044488,0.0,0.82699633,139.24342,1.4548664,283.63553,-9.3096104
2161,2161,145.4215,25.145988,8.462079,0.0,0,1.1781499,0.0,0.8307277,139.44659,1.4270796,283.45779,-9.309041
2163,2163,145.4219,25.269955,8.4947872,0.0,0,1.1518539,0.0,0.83423394,139.63696,1.398279,283.28006,-9.3080311
2165,2165,145.4223,25.366495,8.5252924,0.0,0,1.1255579,0.0,0.84011829,139.3703,1.3700379,283.10233,-9.3071384
2167,2167,145.4227,25.458963,8.5488377,0.0,0,1.0992619,0.0,0.84379417,139.30145,1.3417869,282.92459,-9.3087788
2169,2169,145.4231,25.5767,8.5811176,0.0,0,1.0729659,0.0,0.84770882,139.45282,1.3146666,282.74686,-9.3105001
2171,2171,145.4235,25.707108,8.6061907,0.0,0,1.0466698,0.0,0.85309732,139.39047,1.2867013,282.56912,-9.3100424
2173,2173,145.4239,25.844404,8.6325092,0.0,0,1.0203738,0.0,0.85614675,139.78407,1.258616,282.39139,-9.3082457
2175,2175,145.4243,25.939045,8.6631823,0.0,0,0.9940778,0.0,0.86067325,139.61865,1.2308334,282.21365,-9.3077536
2177,2177,145.4247,26.052753,8.6860723,0.0,0,0.96778184,0.0,0.86590576,139.4772,1.2007216,282.03592,-9.308198
2179,2179,145.4251,26.191381,8.7175016,0.0,0,0.94148582,0.0,0.86932814,139.76303,1.1714195,281.85818,-9.3089561
2181,2181,145.4255,26.333584,8.7451353,0.0,0,0.91518986,0.0,0.87411195,139.79198,1.1469299,281.68045,-9.3106842
2183,2183,145.4259,26.465199,8.7674332,0.0,0,0.88915813,0.0,0.87872475,139.91145,1.1173075,281.50272,-9.309516
2185,2185,145.4263,26.569078,8.8005047,0.0,0,0.86408705,0.0,0.8822751,139.92938,1.092914,281.32498,-9.3077869
2187,2187,145.4267,26.68676,8.8239679,0.0,0,0.83907896,0.0,0.8871327,139.84665,1.0628269,281.14725,-9.3075676
2189,2189,145.4271,26.808542,8.846796,0.0,0,0.81407094,0.0,0.89113992,139.9384,1.0397797,280.96951,-9.3076324
2191,2191,145.4275,26.96269,8.8831139,0.0,0,0.78906298,0.0,0.89530313,140.15652,1.0095673,280.79178,-9.3089256
2193,2193,145.4279,27.078384,8.900794,0.0,0,0.76405495,0.0,0.90014189,140.11972,0.9846555,280.61404,-9.3087883
2195,2195,145.4283,27.191034,8.9262629,0.0,0,0.73904693,0.0,0.9036091,140.22314,0.95807993,280.43631,-9.3079929
2197,2197,145.4287,27.312927,8.9595175,0.0,0,0.71403897,0.0,0.90824676,140.17714,0.92787445,280.25858,-9.3070908
2199,2199,145.4291,27.455801,8.9753361,0.0,0,0.68903095,0.0,0.91274548,140.25514,0.90928376,280.22958,-9.3078823
2201,2201,145.4295,27.61685,9.0030165,0.0,0,0.66402298,0.0,0.91590667,140.58559,0.88036245,280.34918,-9.3083038
2203,2203,145.4299,27.741241,9.0344658,0.0,0,0.63901496,0.0,0.92119908,140.50246,0.85637337,280.46881,-9.3089571
2205,2205,145.4303,27.838713,9.0513954,0.0,0,0.61400694,0.0,0.92535514,140.46088,0.83368301,280.58844,-9.3077011
2207,2207,145.4307,27.974642,9.0808706,0.0,0,0.58899897,0.0,0.92871386,140.6398,0.80532146,280.70807,-9.3075047
2209,2209,145.4311,28.122017,9.1095467,0.0,0,0.5647862,0.0,0.93445599,140.58386,0.77860266,280.8277,-9.3064003
2211,2211,145.4315,28.267342,9.127429,0.0,0,0.54098368,0.0,0.9379521,140.8606,0.75734389,280.94733,-9.3072157
2213,2213,145.4319,28.413986,9.1563377,0.0,0,0.5171836,0.0,0.94142991,141.03154,0.73262566,281.06696,-9.3073654
2215,2215,145.4323,28.537617,9.1795225,0.0,0,0.49338362,0.0,0.94709039,140.86359,0.70590389,281.18658,-9.3082561
2217,2217,145.4327,28.681816,9.2007952,0.0,0,0.46958363,0.0,0.95014924,141.18596,0.68102336,281.30621,-9.3079834
2219,2219,145.4331,28.84127,9.2293224,0.0,0,0.44578362,0.0,0.95413458,141.34872,0.65488678,281.42584,-9.3063059
2221,2221,145.4335,29.003975,9.2497549,0.0,0,0.42198363,0.0,0.95959938,141.35138,0.63329458,281.54547,-9.3065853
2223,2223,145.4339,29.140379,9.2764044,0.0,0,0.39818361,0.0,0.96257979,141.65239,0.60872203,281.6651,-9.3073435
2225,2225,145.4343,29.266037,9.3039446,0.0,0,0.3743836,0.0,0.96746111,141.54024,0.58264101,281.78473,-9.3076143
2227,2227,145.4347,29.416311,9.322072,0.0,0,0.35058361,0.0,0.97204244,141.6102,0.55916917,281.90433,-9.3074999
2229,2229,145.4351,29.56225,9.3503151,0.0,0,0.32678363,0.0,0.97501355,141.89842,0.53076953,282.02396,-9.3070173
2231,2231,145.4355,29.720922,9.3699703,0.0,0,0.30298361,0.0,0.97973216,141.99712,0.51098239,282.14359,-9.3066158