File: clean data/testID_0101.csv
level_0,index,Time(sec),Force(kN),Jaw(mm),PowAngle(deg),Power(W),Pram,PTemp,Strain,Stress(MPa),Stroke(mm),TC1(C),wedge(mm)
2272,2272,195.3437,0.62426877,0.0096086515,0.0,0,9.0629702,0.0,0.00033578544,7.7094393,10.107512,451.05548,-9.2360926
2273,2273,195.3439,1.1974726,0.0089465836,0.0,0,9.0337057,0.0,0.00065017567,13.000048,10.072902,451.09747,-9.2357368
2274,2274,195.3441,2.7465622,0.026696758,0.0,0,9.0044422,0.0,0.0016229453,30.429173,10.043694,451.1395,-9.2357216
2275,2275,195.3443,4.3916869,0.058384728,0.0,0,8.9751778,0.0,0.0032179882,51.926434,10.022394,451.18149,-9.2352276
2276,2276,195.3445,5.2871127,0.076787084,0.0,0,8.9459143,0.0,0.0048884023,65.349678,9.9986219,451.22351,-9.2345381
2277,2277,195.3447,5.5815344,0.096238784,0.0,0,8.9166498,0.0,0.0063201888,70.185341,9.9719515,451.2655,-9.2332344
2278,2278,195.3449,5.7153349,0.12834397,0.0,0,8.8873854,0.0,0.0078638317,71.878838,9.9394903,451.3075,-9.2321033
2279,2279,195.3451,5.8983588,0.17151894,0.0,0,8.8581219,0.0,0.010722454,73.914673,9.9001751,451.34952,-9.2314434
2280,2280,195.3453,5.8870268,0.23934856,0.0,0,8.8288574,0.0,0.015312769,74.110588,9.8620167,451.39151,-9.2313919
2281,2281,195.3455,5.7165346,0.30422997,0.0,0,8.7995939,0.0,0.019486908,71.858467,9.8236189,451.4335,-9.2320795
2282,2282,195.3457,5.8085589,0.3328678,0.0,0,8.7703295,0.0,0.021945957,71.832062,9.7794151,451.47552,-9.2323828
2283,2283,195.3459,6.1889029,0.35817063,0.0,0,8.7416534,0.0,0.024037911,75.957176,9.7300701,451.51752,-9.232317
2284,2284,195.3461,6.3672943,0.40514565,0.0,0,8.7136869,0.0,0.026565086,78.735291,9.6827288,451.55954,-9.2327728
2285,2285,195.3463,6.3689709,0.45464599,0.0,0,8.6858492,0.0,0.029861052,78.722839,9.6397991,451.60153,-9.232213
2286,2286,195.3465,6.5353446,0.49682012,0.0,0,8.6580172,0.0,0.033403125,79.920036,9.6005974,451.64352,-9.2309828
2287,2287,195.3467,6.7274141,0.51754171,0.0,0,8.6301851,0.0,0.034880806,82.371239,9.5626316,451.68555,-9.230835
2288,2288,195.3469,6.6309543,0.51523727,0.0,0,8.6023531,0.0,0.034725029,82.056175,9.5274668,451.72754,-9.2307844
2289,2289,195.3471,6.2808223,0.53342533,0.0,0,8.5745211,0.0,0.036052968,78.049347,9.4965029,451.76953,-9.2309227
2290,2290,195.3473,6.1271653,0.58395278,0.0,0,8.546689,0.0,0.039035231,75.159355,9.4649515,451.81155,-9.2315321
2291,2291,195.3475,6.3976216,0.62725711,0.0,0,8.518857,0.0,0.041951913,77.180969,9.4360943,451.85355,-9.2321692
2292,2292,195.3477,6.7949915,0.65109354,0.0,0,8.491025,0.0,0.044318605,81.916847,9.4081078,451.89557,-9.2324343
2293,2293,195.3479,7.0004687,0.66768593,0.0,0,8.4631929,0.0,0.045498617,84.968422,9.3761597,451.93756,-9.2318354
2294,2294,195.3481,7.0265598,0.69030762,0.0,0,8.4353609,0.0,0.04648868,85.459152,9.3427391,451.97955,-9.2310076
2295,2295,195.3483,7.027894,0.7389043,0.0,0,8.4075289,0.0,0.049852356,85.12825,9.3073692,452.02158,-9.2308464
2296,2296,195.3485,7.0038028,0.80342048,0.0,0,8.3796968,0.0,0.054388478,84.546944,9.2702665,452.06357,-9.2309961
2297,2297,195.3487,6.9024229,0.85307056,0.0,0,8.3518648,0.0,0.057738218,83.201027,9.2295008,452.10556,-9.2314539
2298,2298,195.3489,6.7918863,0.8877787,0.0,0,8.3240328,0.0,0.060571324,81.54306,9.1861725,452.14758,-9.2320213
2299,2299,195.3491,6.7806859,0.9237783,0.0,0,8.2962008,0.0,0.063266575,80.960426,9.1436243,452.18958,-9.2324352
2300,2300,195.3493,6.8828096,0.96575963,0.0,0,8.2683687,0.0,0.065758638,81.732712,9.1046534,452.2316,-9.2323008
2301,2301,195.3495,7.0017819,1.0067276,0.0,0,8.2405367,0.0,0.06884174,82.955666,9.0658216,452.27359,-9.2316389
2302,2302,195.3497,7.0467429,1.0362929,0.0,0,8.2127056,0.0,0.071471296,83.460823,9.0277147,452.31558,-9.2310677
2303,2303,195.3499,7.0584145,1.0573386,0.0,0,8.1848736,0.0,0.072702512,83.501877,8.9913435,452.3576,-9.2310066
2304,2304,195.3501,7.0866714,1.0791786,0.0,0,8.1570406,0.0,0.074175246,83.755249,8.9585438,452.3996,-9.2315865
2305,2305,195.3503,7.0807548,1.1082662,0.0,0,8.1292095,0.0,0.076533034,83.546814,8.9259424,452.4386,-9.2321024
2306,2306,195.3505,7.0118546,1.1446078,0.0,0,8.1013775,0.0,0.078762583,82.539482,8.8928242,452.47461,-9.2316341
2307,2307,195.3507,6.9878845,1.1723517,0.0,0,8.0735445,0.0,0.08080335,81.9673,8.8638744,452.51062,-9.2317848
2308,2308,195.3509,7.1024933,1.1884153,0.0,0,8.0462675,0.0,0.082576528,82.867058,8.8370848,452.5466,-9.2323999
2309,2309,195.3511,7.2841172,1.2155334,0.0,0,8.0196619,0.0,0.084139057,84.837708,8.8076477,452.58261,-9.2316074
2310,2310,195.3513,7.4037557,1.2538382,0.0,0,7.993176,0.0,0.086507015,86.274445,8.7752905,452.61862,-9.2308655
2311,2311,195.3515,7.4216981,1.2912737,0.0,0,7.9666953,0.0,0.089652553,86.390015,8.7435665,452.65463,-9.2308273
2312,2312,195.3517,7.3718834,1.3339499,0.0,0,7.9402156,0.0,0.092601076,85.71209,8.7107267,452.69061,-9.2307701
2313,2313,195.3519,7.3142729,1.3724797,0.0,0,7.9137354,0.0,0.09509106,84.793495,8.6766329,452.72662,-9.2305613
2314,2314,195.3521,7.2941465,1.4000332,0.0,0,7.8872552,0.0,0.097615182,84.280304,8.6423197,452.76263,-9.230608
2315,2315,195.3523,7.3102126,1.4393179,0.0,0,7.860775,0.0,0.10042515,84.173004,8.6065273,452.79861,-9.231389
2316,2316,195.3525,7.3400149,1.4828528,0.0,0,7.8342953,0.0,0.10313894,84.223038,8.5702085,452.83463,-9.2314501
2317,2317,195.3527,7.3677473,1.5071901,0.0,0,7.8078156,0.0,0.10554805,84.336975,8.5343819,452.87064,-9.2314281
2318,2318,195.3529,7.3878584,1.5318245,0.0,0,7.7813349,0.0,0.10761881,84.469284,8.4998837,452.90665,-9.231576
2319,2319,195.3531,7.4066763,1.5611897,0.0,0,7.7548552,0.0,0.1092235,84.617889,8.4682188,452.94263,-9.2310457
2320,2320,195.3533,7.4188485,1.5826458,0.0,0,7.728375,0.0,0.11109416,84.666595,8.4360065,452.97864,-9.2308569
2321,2321,195.3535,7.4003158,1.6171584,0.0,0,7.7018952,0.0,0.11384027,84.26609,8.4049339,453.01465,-9.2305765
2322,2322,195.3537,7.3848667,1.6563964,0.0,0,7.675415,0.0,0.11630063,83.739433,8.3758974,453.05066,-9.2301655
2323,2323,195.3539,7.4270525,1.6761669,0.0,0,7.6489348,0.0,0.11808686,83.882034,8.3465929,453.08664,-9.2293262
2324,2324,195.3541,7.5301657,1.6981658,0.0,0,7.6224551,0.0,0.12011117,84.764206,8.3180647,453.12265,-9.2289267
2325,2325,195.3543,7.6331177,1.728947,0.0,0,7.5959754,0.0,0.12186314,85.854469,8.2879143,453.15866,-9.229248
2326,2326,195.3545,7.6690664,1.754187,0.0,0,7.5694952,0.0,0.12368155,86.318283,8.2575169,453.19467,-9.2294674
2327,2327,195.3547,7.6539702,1.7893229,0.0,0,7.543015,0.0,0.12675212,85.942566,8.2291479,453.23065,-9.2300777
2328,2328,195.3549,7.6441979,1.8318968,0.0,0,7.5165353,0.0,0.12962487,85.499855,8.1982632,453.26666,-9.2309608
2329,2329,195.3551,7.6648259,1.8595518,0.0,0,7.4900556,0.0,0.13168471,85.468811,8.1656857,453.30267,-9.2316847
2330,2330,195.3553,7.6760597,1.887604,0.0,0,7.4635754,0.0,0.13431297,85.414574,8.1338205,453.33868,-9.231883
2331,2331,195.3555,7.6496205,1.9236,0.0,0,7.4370952,0.0,0.13676046,85.013069,8.1028595,453.37466,-9.2315454
2332,2332,195.3557,7.6411686,1.9509007,0.0,0,7.410615,0.0,0.1386103,84.610954,8.0698023,453.41068,-9.2316523
2333,2333,195.3559,7.6802559,1.9779329,0.0,0,7.384666,0.0,0.14128807,84.751114,8.0365,453.44669,-9.2309256
2334,2334,195.3561,7.7388983,2.009254,0.0,0,7.3593607,0.0,0.14368321,85.276337,8.0088568,453.4827,-9.2293806
2335,2335,195.3563,7.7726426,2.0319777,0.0,0,7.3341718,0.0,0.14496689,85.554062,7.9805541,453.51868,-9.2288342
2336,2336,195.3565,7.7563481,2.0544369,0.0,0,7.3089876,0.0,0.14704241,85.310249,7.9514174,453.55469,-9.2285948
2337,2337,195.3567,7.7303843,2.0845084,0.0,0,7.2838035,0.0,0.1494334,84.858963,7.9237347,453.5907,-9.2288637
2338,2338,195.3569,7.7263908,2.1121345,0.0,0,7.2586198,0.0,0.15112005,84.575264,7.8954029,453.62668,-9.2297316
2339,2339,195.3571,7.7436285,2.1357574,0.0,0,7.2334356,0.0,0.1533003,84.462624,7.870234,453.66269,-9.2306404
2340,2340,195.3573,7.7756414,2.1588242,0.0,0,7.2082515,0.0,0.15541661,84.633713,7.8456659,453.6987,-9.2316465
2341,2341,195.3575,7.8263745,2.1828451,0.0,0,7.1830673,0.0,0.15670271,85.051666,7.8191848,453.73471,-9.2320194
2342,2342,195.3577,7.8967509,2.2085855,0.0,0,7.1578832,0.0,0.15873918,85.612488,7.7909579,453.77069,-9.2323446
2343,2343,195.3579,7.9501433,2.2377849,0.0,0,7.132699,0.0,0.16145456,86.050072,7.7634602,453.8067,-9.2324867
2344,2344,195.3581,7.9697909,2.2716684,0.0,0,7.1075149,0.0,0.16360109,86.125618,7.7356572,453.84271,-9.2319384
2345,2345,195.3583,7.9692664,2.3017685,0.0,0,7.0823312,0.0,0.16591248,85.927841,7.707078,453.87872,-9.2313261
2346,2346,195.3585,7.9480042,2.3276093,0.0,0,7.0571475,0.0,0.16850127,85.54747,7.6791921,453.9147,-9.2308474
2347,2347,195.3587,7.9175663,2.3596263,0.0,0,7.0319633,0.0,0.17054226,85.045288,7.6513987,453.95071,-9.230649
2348,2348,195.3589,7.9180765,2.3890975,0.0,0,7.0067787,0.0,0.17271127,84.795692,7.6243367,453.98672,-9.2302122
2349,2349,195.3591,7.9567618,2.4097979,0.0,0,6.981595,0.0,0.17508362,84.967239,7.5970531,454.02274,-9.2298355
2350,2350,195.3593,7.9920282,2.4355979,0.0,0,6.9564114,0.0,0.17684123,85.229027,7.5684571,454.05872,-9.2302523
2351,2351,195.3595,8.0097427,2.4606984,0.0,0,6.9312272,0.0,0.17847562,85.2696,7.5404739,454.09473,-9.2307796
2352,2352,195.3597,8.0128651,2.4799349,0.0,0,6.9060431,0.0,0.18061052,85.080406,7.5136781,454.13074,-9.2308054
2353,2353,195.3599,8.0151129,2.5096698,0.0,0,6.8808589,0.0,0.18277614,84.986397,7.4883375,454.16675,-9.2311239
2354,2354,195.3601,8.0287294,2.5389533,0.0,0,6.8556757,0.0,0.1846403,84.987793,7.4607835,454.20273,-9.231884
2355,2355,195.3603,8.0418015,2.5539939,0.0,0,6.8304915,0.0,0.18646435,84.950333,7.4345856,454.2049,-9.2323666
2356,2356,195.3605,8.0617371,2.5784073,0.0,0,6.8053074,0.0,0.18840367,84.971008,7.4133744,454.18448,-9.2330732
2357,2357,195.3607,8.0950127,2.6095178,0.0,0,6.7801232,0.0,0.19025989,85.126183,7.3894329,454.16409,-9.2324209
2358,2358,195.3609,8.1271448,2.628793,0.0,0,6.7554412,0.0,0.19228899,85.326027,7.3623848,454.14368,-9.2310352
2359,2359,195.3611,8.1480837,2.6562715,0.0,0,6.7313666,0.0,0.19467923,85.342529,7.3370562,454.12329,-9.230381
2360,2360,195.3613,8.1462593,2.6887231,0.0,0,6.7074018,0.0,0.19664934,85.159332,7.3126259,454.10287,-9.2296877
2361,2361,195.3615,8.1362467,2.7056642,0.0,0,6.6834412,0.0,0.19845921,84.994781,7.28689,454.08249,-9.2294741
2362,2362,195.3617,8.1529799,2.7306321,0.0,0,6.6594815,0.0,0.20087183,84.957481,7.263299,454.06207,-9.229949
2363,2363,195.3619,8.1834621,2.7636197,0.0,0,6.6355214,0.0,0.20289883,85.093636,7.2379618,454.04169,-9.2306242
2364,2364,195.3621,8.2046995,2.7820132,0.0,0,6.6115613,0.0,0.20463826,85.106735,7.2134762,454.02127,-9.2310276
2365,2365,195.3623,8.2253504,2.8049161,0.0,0,6.5876012,0.0,0.20704846,85.021622,7.1895857,454.00089,-9.2311583
2366,2366,195.3625,8.2413645,2.834456,0.0,0,6.5636415,0.0,0.20884012,85.075874,7.1625237,453.98047,-9.2316446
2367,2367,195.3627,8.2555523,2.8517969,0.0,0,6.5396814,0.0,0.21021645,85.19796,7.1369524,453.96008,-9.2321367
2368,2368,195.3629,8.2694902,2.8752112,0.0,0,6.5157218,0.0,0.21268633,85.14492,7.1100907,453.93967,-9.2320595
2369,2369,195.3631,8.2589207,2.9073615,0.0,0,6.4917617,0.0,0.21492137,84.839706,7.0848975,453.91928,-9.2318277
2370,2370,195.3633,8.2477121,2.9270608,0.0,0,6.467802,0.0,0.21643141,84.560669,7.0640745,453.89886,-9.2315645
2371,2371,195.3635,8.2767286,2.9474702,0.0,0,6.4438419,0.0,0.21869358,84.591026,7.0403509,453.87848,-9.230917
2372,2372,195.3637,8.339098,2.9758544,0.0,0,6.4198813,0.0,0.22076735,85.055367,7.0171342,453.85806,-9.2300196
2373,2373,195.3639,8.3858099,2.9967232,0.0,0,6.3959212,0.0,0.22213157,85.480171,6.9935756,453.83765,-9.2302036
2374,2374,195.3641,8.3967714,3.0188723,0.0,0,6.3719611,0.0,0.22450314,85.402679,6.9677777,453.81726,-9.2305641
2375,2375,195.3643,8.4056149,3.0477371,0.0,0,6.3480015,0.0,0.2269754,85.240303,6.9411073,453.79684,-9.2308064
2376,2376,195.3645,8.4133205,3.0704801,0.0,0,6.3240414,0.0,0.228383,85.233032,6.9161477,453.77646,-9.2314644
2377,2377,195.3647,8.4045572,3.0920668,0.0,0,6.3000817,0.0,0.23054947,85.005692,6.8931952,453.75604,-9.2321215
2378,2378,195.3649,8.3980656,3.1187277,0.0,0,6.2761216,0.0,0.23298183,84.653702,6.8697395,453.73566,-9.2323246
2379,2379,195.3651,8.398715,3.1438093,0.0,0,6.252162,0.0,0.23451811,84.522179,6.8451319,453.71524,-9.2324228
2380,2380,195.3653,8.4219942,3.1665106,0.0,0,6.2282019,0.0,0.23677102,84.536873,6.8189797,453.69485,-9.2322969
2381,2381,195.3655,8.4682312,3.1909313,0.0,0,6.2042418,0.0,0.23919438,84.735893,6.7928181,453.67444,-9.2321568
2382,2382,195.3657,8.5050459,3.2159796,0.0,0,6.1802816,0.0,0.24066211,85.047173,6.7681632,453.65405,-9.2310467
2383,2383,195.3659,8.5338554,3.2379704,0.0,0,6.1568022,0.0,0.24267863,85.221703,6.7441664,453.63364,-9.2295828
2384,2384,195.3661,8.5451756,3.260433,0.0,0,6.1339045,0.0,0.24512365,85.123459,6.719604,453.61325,-9.2293034
2385,2385,195.3663,8.5391808,3.2874112,0.0,0,6.1111116,0.0,0.24671981,84.912079,6.6954851,453.59283,-9.2293386
2386,2386,195.3665,8.5340376,3.3108382,0.0,0,6.0883236,0.0,0.24865739,84.739838,6.6736059,453.57245,-9.2298841
2387,2387,195.3667,8.5411615,3.3305597,0.0,0,6.0655355,0.0,0.25108978,84.604103,6.6502323,453.55203,-9.2307444
2388,2388,195.3669,8.5664043,3.3573854,0.0,0,6.042748,0.0,0.25285169,84.655212,6.624464,453.53165,-9.2312632
2389,2389,195.3671,8.593359,3.3823328,0.0,0,6.0199599,0.0,0.25478023,84.772331,6.5997567,453.51123,-9.2318516
2390,2390,195.3673,8.6180115,3.4003448,0.0,0,5.9971714,0.0,0.25713336,84.804962,6.5766068,453.49084,-9.2318068
2391,2391,195.3675,8.6453934,3.4277747,0.0,0,5.9743834,0.0,0.25909716,84.877075,6.5547462,453.47043,-9.2316818
2392,2392,195.3677,8.6762476,3.4545951,0.0,0,5.9515953,0.0,0.26099044,85.02932,6.5297894,453.45004,-9.2314091
2393,2393,195.3679,8.6923599,3.4709446,0.0,0,5.9288073,0.0,0.26318321,85.056335,6.5017986,453.42963,-9.2311897
2394,2394,195.3681,8.6923399,3.4973342,0.0,0,5.9060197,0.0,0.26517937,84.937737,6.4790339,453.40924,-9.2305498
2395,2395,195.3683,8.6915092,3.5261176,0.0,0,5.8832316,0.0,0.26698259,84.777718,6.4575343,453.38882,-9.2294159
2396,2396,195.3685,8.6924381,3.5419736,0.0,0,5.8604436,0.0,0.26912767,84.572693,6.4339075,453.36844,-9.2300062
2397,2397,195.3687,8.7076931,3.5671811,0.0,0,5.8376555,0.0,0.27140135,84.476135,6.4105129,453.34802,-9.2300348
2398,2398,195.3689,8.7308693,3.5970657,0.0,0,5.814867,0.0,0.27328885,84.495773,6.3870802,453.32764,-9.229393
2399,2399,195.3691,8.7550163,3.6123838,0.0,0,5.792079,0.0,0.2752234,84.569633,6.3631558,453.30722,-9.2300692
2400,2400,195.3693,8.7730074,3.6367588,0.0,0,5.7692914,0.0,0.27757704,84.582695,6.3390055,453.28683,-9.2307892
2401,2401,195.3695,8.7901983,3.6674883,0.0,0,5.7465034,0.0,0.27951759,84.555771,6.3162508,453.26642,-9.2308397
2402,2402,195.3697,8.8078299,3.6829417,0.0,0,5.7237153,0.0,0.28130421,84.629784,6.2926941,453.246,-9.2315292
2403,2403,195.3699,8.8216648,3.7050443,0.0,0,5.7009273,0.0,0.28374597,84.656097,6.2712164,453.22562,-9.2323008
2404,2404,195.3701,8.8374128,3.7350926,0.0,0,5.6781397,0.0,0.28562093,84.639236,6.2498693,453.2052,-9.2323914
2405,2405,195.3703,8.8523617,3.7517502,0.0,0,5.6553516,0.0,0.28720486,84.583977,6.2246842,453.24069,-9.2323179
2406,2406,195.3705,8.8695993,3.7753828,0.0,0,5.6325636,0.0,0.28986731,84.520645,6.1998482,453.30008,-9.2320442
2407,2407,195.3707,8.8813705,3.8076575,0.0,0,5.6097751,0.0,0.2921133,84.464432,6.1773181,453.35947,-9.231555
2408,2408,195.3709,8.8942928,3.8252048,0.0,0,5.5874414,0.0,0.29370373,84.421585,6.1531682,453.41885,-9.2310534
2409,2409,195.3711,8.9100227,3.8461883,0.0,0,5.5656581,0.0,0.29623356,84.324585,6.130466,453.47824,-9.2302446
2410,2410,195.3713,8.9288549,3.8760526,0.0,0,5.5439734,0.0,0.29849261,84.273705,6.1069827,453.53763,-9.2295904
2411,2411,195.3715,8.9516535,3.8948958,0.0,0,5.5222936,0.0,0.29991913,84.347595,6.0839853,453.59702,-9.2295122
2412,2412,195.3717,8.9774637,3.9140472,0.0,0,5.5006132,0.0,0.30229184,84.410614,6.0615792,453.6564,-9.2300367
2413,2413,195.3719,9.0004187,3.9409592,0.0,0,5.4789333,0.0,0.30456701,84.453232,6.0373936,453.71579,-9.2311287
2414,2414,195.3721,9.0116606,3.9617627,0.0,0,5.457253,0.0,0.30591017,84.470161,6.0133505,453.77518,-9.232089
2415,2415,195.3723,9.024231,3.9825163,0.0,0,5.4355731,0.0,0.30833688,84.382034,5.9911633,453.83459,-9.2324619
2416,2416,195.3725,9.0288095,4.0101113,0.0,0,5.4138932,0.0,0.31093594,84.221252,5.969348,453.89398,-9.2325802
2417,2417,195.3727,9.0298052,4.0324044,0.0,0,5.3922133,0.0,0.31241906,84.116554,5.94524,453.95337,-9.2325535
2418,2418,195.3729,9.0453377,4.0527263,0.0,0,5.370533,0.0,0.3147341,84.046272,5.9207621,454.01276,-9.2323771
2419,2419,195.3731,9.0639877,4.0783734,0.0,0,5.3488531,0.0,0.3172752,84.01889,5.8977194,454.07214,-9.2319727
2420,2420,195.3733,9.0878572,4.1019158,0.0,0,5.3271732,0.0,0.31872526,84.102997,5.8750744,454.13153,-9.2319288
2421,2421,195.3735,9.1192627,4.1221395,0.0,0,5.3054934,0.0,0.32089469,84.161919,5.851294,454.19092,-9.2310638
2422,2422,195.3737,9.1459265,4.1452579,0.0,0,5.283813,0.0,0.32346445,84.249146,5.8282046,454.25031,-9.2299623
2423,2423,195.3739,9.1640291,4.1708937,0.0,0,5.2621331,0.0,0.32511792,84.359024,5.8055744,454.30969,-9.2304029
2424,2424,195.3741,9.1869202,4.1927252,0.0,0,5.2404532,0.0,0.32728481,84.287453,5.783144,454.36908,-9.230587
2425,2425,195.3743,9.2076864,4.212657,0.0,0,5.2187734,0.0,0.32978532,84.172966,5.7597985,454.42847,-9.2304392
2426,2426,195.3745,9.2230167,4.2373481,0.0,0,5.1970935,0.0,0.33141601,84.183113,5.7355714,454.48788,-9.2306252
2427,2427,195.3747,9.2324915,4.2596087,0.0,0,5.1754136,0.0,0.3333649,84.164131,5.7117391,454.54727,-9.2315607
2428,2428,195.3749,9.2384377,4.278399,0.0,0,5.1537333,0.0,0.33588541,84.06221,5.6880937,454.60666,-9.2323122
2429,2429,195.3751,9.2542801,4.3061767,0.0,0,5.1320534,0.0,0.33783805,84.006531,5.6635675,454.66605,-9.2322102
2430,2430,195.3753,9.2811422,4.330781,0.0,0,5.110373,0.0,0.3397831,84.058609,5.6409698,454.72543,-9.2315979
2431,2431,195.3755,9.3126001,4.3476944,0.0,0,5.0886931,0.0,0.34225285,84.178055,5.6190825,454.78482,-9.2309456
2432,2432,195.3757,9.3393717,4.3755527,0.0,0,5.0670133,0.0,0.34446841,84.224358,5.5951262,454.84421,-9.230649
2433,2433,195.3759,9.3533421,4.4026756,0.0,0,5.0457678,0.0,0.34650362,84.15303,5.5703635,454.90359,-9.230134
2434,2434,195.3761,9.3653603,4.4186993,0.0,0,5.0250483,0.0,0.34887078,84.035034,5.5472565,454.96298,-9.2303085
2435,2435,195.3763,9.3826818,4.4444041,0.0,0,5.0044241,0.0,0.3511416,83.992592,5.5253725,455.02237,-9.2304554
2436,2436,195.3765,9.388648,4.4723468,0.0,0,4.9838037,0.0,0.35302919,83.917091,5.5018473,455.08176,-9.2305956
2437,2437,195.3767,9.3978138,4.4864845,0.0,0,4.9631839,0.0,0.35515407,83.827087,5.4795408,455.14117,-9.231041
2438,2438,195.3769,9.4100933,4.509963,0.0,0,4.9425635,0.0,0.35751528,83.785446,5.4582891,455.20056,-9.2309284
2439,2439,195.3771,9.426302,4.5392542,0.0,0,4.9219437,0.0,0.35937759,83.813446,5.4353037,455.25995,-9.23104
2440,2440,195.3773,9.458149,4.5531878,0.0,0,4.9013238,0.0,0.3613286,83.893776,5.412324,455.31934,-9.2310019
2441,2441,195.3775,9.4973097,4.5761542,0.0,0,4.8807039,0.0,0.36392337,83.96405,5.3885603,455.37872,-9.2305489
2442,2442,195.3777,9.5241842,4.6066275,0.0,0,4.8600836,0.0,0.36593696,84.0634,5.3664393,455.43811,-9.2302427
2443,2443,195.3779,9.5314207,4.6215525,0.0,0,4.8394637,0.0,0.36777195,84.046516,5.3448243,455.4975,-9.2304325
2444,2444,195.3781,9.5441513,4.6448488,0.0,0,4.8188438,0.0,0.3705442,83.915703,5.3217473,455.55688,-9.2308016
2445,2445,195.3783,9.5626793,4.6759915,0.0,0,4.798224,0.0,0.3728022,83.863922,5.2994366,455.61627,-9.2312164
2446,2446,195.3785,9.5729694,4.6913757,0.0,0,4.7776036,0.0,0.37451857,83.792587,5.2766814,455.67566,-9.2314272
2447,2447,195.3787,9.5830832,4.7129388,0.0,0,4.7569838,0.0,0.37726724,83.677567,5.2527127,455.73505,-9.2311239
2448,2448,195.3789,9.6010323,4.7433624,0.0,0,4.7363639,0.0,0.37951276,83.652077,5.2303238,455.79446,-9.2302303
2449,2449,195.3791,9.6255245,4.7595825,0.0,0,4.7157435,0.0,0.38098758,83.696762,5.2090373,455.85385,-9.2301378
2450,2450,195.3793,9.6558657,4.7794466,0.0,0,4.6951237,0.0,0.38367897,83.738335,5.187005,455.91324,-9.2302103
2451,2451,195.3795,9.6919489,4.8097744,0.0,0,4.6745038,0.0,0.38610497,83.805779,5.1659236,455.97263,-9.2302704
2452,2452,195.3797,9.7138519,4.8287258,0.0,0,4.6538839,0.0,0.38759199,83.881607,5.1440654,456.03201,-9.2313881
2453,2453,195.3799,9.7296753,4.8477488,0.0,0,4.6332641,0.0,0.39024824,83.831406,5.1206398,456.0914,-9.2320614
2454,2454,195.3801,9.7415199,4.8758736,0.0,0,4.6126437,0.0,0.39282078,83.737808,5.0979104,456.15079,-9.2315636
2455,2455,195.3803,9.7490072,4.8964262,0.0,0,4.5920234,0.0,0.39429176,83.693283,5.0755601,456.15451,-9.2309179
2456,2456,195.3805,9.7633505,4.9156475,0.0,0,4.5714035,0.0,0.39683062,83.54953,5.0509148,456.14429,-9.2311029
2457,2457,195.3807,9.7729435,4.9423771,0.0,0,4.5507836,0.0,0.39947316,83.396721,5.0286441,456.13409,-9.2311096
2458,2458,195.3809,9.7841043,4.9646416,0.0,0,4.5305758,0.0,0.40095106,83.385872,5.0087304,456.1239,-9.2309637
2459,2459,195.3811,9.8088131,4.9838276,0.0,0,4.5108657,0.0,0.40346909,83.374763,4.9868345,456.11368,-9.2316542
2460,2460,195.3813,9.840848,5.0073767,0.0,0,4.4912457,0.0,0.40624592,83.417824,4.9646707,456.10349,-9.2322578
2461,2461,195.3815,9.8687906,5.0297055,0.0,0,4.4716296,0.0,0.40770188,83.549522,4.9402614,456.09329,-9.2316465
2462,2462,195.3817,9.8985567,5.0492444,0.0,0,4.4520135,0.0,0.4100301,83.570709,4.917151,456.0831,-9.2311392
2463,2463,195.3819,9.9265118,5.0714746,0.0,0,4.4323974,0.0,0.4128378,83.56163,4.8976736,456.07288,-9.2309875
2464,2464,195.3821,9.9385157,5.0958071,0.0,0,4.4127812,0.0,0.41446152,83.579521,4.8757997,456.06268,-9.2307024
2465,2465,195.3823,9.9391069,5.1154499,0.0,0,4.3931651,0.0,0.41651294,83.446747,4.8526464,456.05249,-9.2307997
2466,2466,195.3825,9.9408255,5.1336999,0.0,0,4.3735495,0.0,0.41909695,83.272797,4.8316097,456.0423,-9.2313118
2467,2467,195.3827,9.9511118,5.1589327,0.0,0,4.3539338,0.0,0.42082995,83.130447,4.8093524,456.03207,-9.2320375
2468,2468,195.3829,9.9754534,5.1807671,0.0,0,4.3343177,0.0,0.42286611,83.091873,4.7854438,456.02188,-9.2316332
2469,2469,195.3831,10.008419,5.1973176,0.0,0,4.3147016,0.0,0.42551965,83.17749,4.7657204,456.01169,-9.2308407
2470,2470,195.3833,10.040552,5.2223067,0.0,0,4.2950859,0.0,0.42747524,83.296295,4.7462239,456.0015,-9.2305355
2471,2471,195.3835,10.069563,5.2450628,0.0,0,4.2754693,0.0,0.42944658,83.407867,4.7224588,455.99127,-9.2305222
2472,2472,195.3837,10.092149,5.2606091,0.0,0,4.2558532,0.0,0.43198684,83.34951,4.7018199,455.98108,-9.2302713
2473,2473,195.3839,10.106227,5.2870069,0.0,0,4.236237,0.0,0.43419316,83.274155,4.6827674,455.97089,-9.23036
2474,2474,195.3841,10.115804,5.3136878,0.0,0,4.2166214,0.0,0.43625492,83.244072,4.659936,455.96066,-9.2308578
2475,2475,195.3843,10.12168,5.3283768,0.0,0,4.1970053,0.0,0.43873754,83.117912,4.6386895,455.95047,-9.2314777
2476,2476,195.3845,10.129134,5.3528934,0.0,0,4.1773891,0.0,0.44110626,82.998611,4.618268,455.94028,-9.2317429
2477,2477,195.3847,10.142357,5.3795929,0.0,0,4.1577735,0.0,0.44303265,82.950829,4.5976405,455.93008,-9.231102
2478,2478,195.3849,10.166291,5.3915911,0.0,0,4.1381574,0.0,0.44521704,82.875427,4.5756669,455.91986,-9.2310648
2479,2479,195.3851,10.195898,5.4132972,0.0,0,4.1185412,0.0,0.4476606,82.886078,4.5539231,455.90967,-9.2310886
2480,2480,195.3853,10.226224,5.4405413,0.0,0,4.0989256,0.0,0.44946235,83.027641,4.5323181,455.89948,-9.2309504
2481,2481,195.3855,10.257438,5.4517298,0.0,0,4.0793095,0.0,0.4512772,83.105225,4.509366,455.88928,-9.229476
2482,2482,195.3857,10.285284,5.4723487,0.0,0,4.0596933,0.0,0.45391685,83.126198,4.4887819,455.87906,-9.2285967
2483,2483,195.3859,10.307687,5.5014009,0.0,0,4.0404716,0.0,0.45595315,83.132164,4.4695463,455.86887,-9.2292366
2484,2484,195.3861,10.31918,5.515132,0.0,0,4.0217257,0.0,0.45776653,83.096207,4.4491558,455.85867,-9.2298861
2485,2485,195.3863,10.321863,5.5367098,0.0,0,4.0030656,0.0,0.46066108,82.92215,4.42802,455.84845,-9.2309275
2486,2486,195.3865,10.337049,5.5669994,0.0,0,3.9844091,0.0,0.46291,82.818428,4.4072208,455.83826,-9.2310982
2487,2487,195.3867,10.366911,5.5812602,0.0,0,3.9657531,0.0,0.46457317,82.885689,4.3832026,455.82806,-9.2308464
2488,2488,195.3869,10.394819,5.6002212,0.0,0,3.9470971,0.0,0.46743435,82.941635,4.3599825,455.81787,-9.2308321
2489,2489,195.3871,10.422869,5.6293473,0.0,0,3.928441,0.0,0.46977103,82.972397,4.3409057,455.80765,-9.2308416
2490,2490,195.3873,10.457006,5.6444783,0.0,0,3.9097853,0.0,0.47119632,83.056267,4.3207917,455.79745,-9.2308521
2491,2491,195.3875,10.479897,5.6612086,0.0,0,3.8911293,0.0,0.4738633,83.084503,4.3008637,455.78726,-9.2308416
2492,2492,195.3877,10.501925,5.6883535,0.0,0,3.8724732,0.0,0.47627553,83.07901,4.2798529,455.77707,-9.2310991
2493,2493,195.3879,10.524581,5.7051792,0.0,0,3.8538172,0.0,0.47767273,83.095222,4.2576084,455.76685,-9.2310801
2494,2494,195.3881,10.533781,5.7220731,0.0,0,3.8351612,0.0,0.48044211,82.975822,4.237699,455.75665,-9.2308111
2495,2495,195.3883,10.543559,5.7482114,0.0,0,3.8165052,0.0,0.48303667,82.810394,4.218266,455.74646,-9.2305899
2496,2496,195.3885,10.554673,5.7664127,0.0,0,3.7978492,0.0,0.48428223,82.750313,4.1970673,455.73627,-9.2304192
2497,2497,195.3887,10.569277,5.7822061,0.0,0,3.7791932,0.0,0.48683453,82.693344,4.1746993,455.72604,-9.230895
2498,2498,195.3889,10.597625,5.8065062,0.0,0,3.7605371,0.0,0.48953512,82.639938,4.1542773,455.71585,-9.231081
2499,2499,195.3891,10.630765,5.8276038,0.0,0,3.7418811,0.0,0.49089849,82.801109,4.135355,455.70566,-9.231266
2500,2500,195.3893,10.659647,5.8448148,0.0,0,3.7232251,0.0,0.49330786,82.894257,4.1177115,455.69543,-9.2312288
2501,2501,195.3895,10.688666,5.8657947,0.0,0,3.7045693,0.0,0.49610755,82.851707,4.0987964,455.68524,-9.2305183
2502,2502,195.3897,10.708988,5.8860831,0.0,0,3.6859133,0.0,0.49744841,82.884865,4.076942,455.67505,-9.230258
2503,2503,195.3899,10.726658,5.9031487,0.0,0,3.6672573,0.0,0.49961188,82.854866,4.0559316,455.66486,-9.2300816
2504,2504,195.3901,10.74157,5.9228678,0.0,0,3.6486013,0.0,0.50250053,82.75032,4.0358262,455.65463,-9.2300768
2505,2505,195.3903,10.755954,5.9462833,0.0,0,3.629945,0.0,0.50414437,82.664085,4.0159173,455.61853,-9.2305403
2506,2506,195.3905,10.772523,5.964376,0.0,0,3.611289,0.0,0.50622201,82.603806,3.9981158,455.57953,-9.2308292
2507,2507,195.3907,10.791959,5.9807696,0.0,0,3.5926332,0.0,0.50897002,82.567169,3.9786825,455.54056,-9.2308407
2508,2508,195.3909,10.816863,6.0046611,0.0,0,3.5743496,0.0,0.51074946,82.631638,3.9562836,455.50156,-9.2310867
2509,2509,195.3911,10.849002,6.0245409,0.0,0,3.5565164,0.0,0.51267284,82.684639,3.9363971,455.46259,-9.2311096
2510,2510,195.3913,10.881903,6.0389581,0.0,0,3.5387647,0.0,0.51530468,82.6642,3.9181628,455.42358,-9.2305937
2511,2511,195.3915,10.908682,6.0627503,0.0,0,3.5210166,0.0,0.51731843,82.726189,3.8989885,455.38461,-9.2305593
2512,2512,195.3917,10.928988,6.0836859,0.0,0,3.5032687,0.0,0.51919836,82.742439,3.8805943,455.34561,-9.2301416
2513,2513,195.3919,10.94275,6.0963669,0.0,0,3.4855206,0.0,0.52179033,82.636108,3.8613989,455.30664,-9.230093
2514,2514,195.3921,10.949347,6.1197386,0.0,0,3.4677725,0.0,0.52400827,82.543648,3.8422902,455.26764,-9.2306957
2515,2515,195.3923,10.957427,6.1431293,0.0,0,3.4500246,0.0,0.52575809,82.492485,3.8235776,455.22864,-9.2307444
2516,2516,195.3925,10.977991,6.1542377,0.0,0,3.4322767,0.0,0.52806818,82.420143,3.8031824,455.18967,-9.2305365
2517,2517,195.3927,10.99736,6.1756811,0.0,0,3.4145288,0.0,0.53042161,82.323997,3.7845423,455.15067,-9.2302589
2518,2518,195.3929,11.027296,6.2006521,0.0,0,3.3967807,0.0,0.53214574,82.363838,3.7674856,455.11169,-9.2299032
2519,2519,195.3931,11.065655,6.2106385,0.0,0,3.3790326,0.0,0.53416872,82.481537,3.7465978,455.07269,-9.2301369
2520,2520,195.3933,11.095991,6.2309599,0.0,0,3.3612847,0.0,0.53673816,82.522507,3.7264533,455.03372,-9.2304525
2521,2521,195.3935,11.123827,6.257864,0.0,0,3.3435366,0.0,0.5386976,82.576424,3.7086205,454.99472,-9.2304888
2522,2522,195.3937,11.148917,6.2680106,0.0,0,3.3257885,0.0,0.54064447,82.636192,3.691607,454.95575,-9.2313423
2523,2523,195.3939,11.169245,6.2868876,0.0,0,3.3080406,0.0,0.54341811,82.546844,3.6727183,454.91675,-9.2313566
2524,2524,195.3941,11.17876,6.3145642,0.0,0,3.2902927,0.0,0.54540551,82.473053,3.6530073,454.87775,-9.2305603
2525,2525,195.3943,11.187695,6.3253946,0.0,0,3.2725446,0.0,0.54700035,82.450417,3.6347387,454.83878,-9.2300014
2526,2526,195.3945,11.20961,6.343061,0.0,0,3.2547965,0.0,0.54983783,82.32962,3.6151884,454.79977,-9.2302456
2527,2527,195.3947,11.237578,6.3709197,0.0,0,3.2370486,0.0,0.55199605,82.348412,3.5985239,454.7608,-9.2304916
2528,2528,195.3949,11.26616,6.3824239,0.0,0,3.2193005,0.0,0.55353308,82.46315,3.5794504,454.7218,-9.2306328
2529,2529,195.3951,11.302142,6.3980503,0.0,0,3.2015524,0.0,0.55637932,82.464355,3.5603614,454.68283,-9.2310095
2530,2530,195.3953,11.339508,6.4249277,0.0,0,3.1838045,0.0,0.55855191,82.537544,3.5433433,454.64383,-9.230464
2531,2531,195.3955,11.371064,6.4381657,0.0,0,3.1660566,0.0,0.55978566,82.664268,3.5239899,454.60486,-9.2305317
2532,2532,195.3957,11.387178,6.4532099,0.0,0,3.1483085,0.0,0.56259817,82.593559,3.5055485,454.56586,-9.2309208
2533,2533,195.3959,11.40045,6.4793935,0.0,0,3.1309149,0.0,0.56516683,82.467567,3.4875824,454.52686,-9.2301922
2534,2534,195.3961,11.426576,6.4947162,0.0,0,3.1139498,0.0,0.56633711,82.52919,3.4685624,454.48788,-9.2299891
2535,2535,195.3963,11.450213,6.5086975,0.0,0,3.0970623,0.0,0.56894255,82.530029,3.4494064,454.44888,-9.2302923
2536,2536,195.3965,11.467173,6.5318899,0.0,0,3.0801783,0.0,0.57156903,82.438812,3.4322391,454.40991,-9.2305336
2537,2537,195.3967,11.486881,6.5487161,0.0,0,3.0632942,0.0,0.57271761,82.475685,3.4155118,454.37091,-9.2308674
2538,2538,195.3969,11.522803,6.5626702,0.0,0,3.0464103,0.0,0.57528681,82.487198,3.3961661,454.33194,-9.2304344
2539,2539,195.3971,11.565652,6.5844212,0.0,0,3.0295262,0.0,0.57799149,82.528358,3.3778193,454.29294,-9.2298918
2540,2540,195.3973,11.601932,6.6033144,0.0,0,3.0126421,0.0,0.57915694,82.711174,3.3604531,454.25397,-9.2302742
2541,2541,195.3975,11.627055,6.6181598,0.0,0,2.9957583,0.0,0.58162737,82.762375,3.3417439,454.21497,-9.2302961
2542,2542,195.3977,11.652162,6.6381421,0.0,0,2.9788742,0.0,0.58454365,82.70089,3.3230617,454.17596,-9.2296438
2543,2543,195.3979,11.679065,6.6583457,0.0,0,2.9619904,0.0,0.58590579,82.747559,3.3046491,454.13699,-9.229475
2544,2544,195.3981,11.703101,6.6738472,0.0,0,2.9451063,0.0,0.58807743,82.742645,3.2878475,454.09799,-9.2300348
2545,2545,195.3983,11.717692,6.6905537,0.0,0,2.9282222,0.0,0.59097928,82.630882,3.2697432,454.05902,-9.2299242
2546,2546,195.3985,11.728813,6.711719,0.0,0,2.9113381,0.0,0.59254402,82.600739,3.2495918,454.02002,-9.2298412
2547,2547,195.3987,11.750648,6.7287216,0.0,0,2.894454,0.0,0.59450507,82.553261,3.2321103,453.98105,-9.2304106
2548,2548,195.3989,11.78809,6.7426777,0.0,0,2.8775702,0.0,0.59727865,82.558853,3.2136834,453.94205,-9.2303524
2549,2549,195.3991,11.832757,6.764204,0.0,0,2.8606861,0.0,0.59892547,82.728752,3.1938262,453.90308,-9.2302656
2550,2550,195.3993,11.878317,6.7822123,0.0,0,2.8438022,0.0,0.60071915,82.852074,3.1767843,453.86407,-9.2305746
2551,2551,195.3995,11.918696,6.7929101,0.0,0,2.8269181,0.0,0.60342276,82.934258,3.1604435,453.82507,-9.2308493
2552,2552,195.3997,11.945624,6.8144321,0.0,0,2.810034,0.0,0.60540456,82.964828,3.1420348,453.7861,-9.230299
2553,2553,195.3999,11.958571,6.8348427,0.0,0,2.7931502,0.0,0.60712588,82.902969,3.1241539,453.7471,-9.2298317
2554,2554,195.4001,11.965472,6.8457685,0.0,0,2.7762663,0.0,0.60967135,82.77459,3.1082709,453.7081,-9.2303419
2555,2555,195.4003,11.987861,6.8684287,0.0,0,2.7593822,0.0,0.61204159,82.713211,3.0901196,453.59467,-9.230484
2556,2556,195.4005,12.016154,6.8916979,0.0,0,2.7424982,0.0,0.61393714,82.748871,3.0725038,453.4812,-9.2297602
2557,2557,195.4007,12.042984,6.9017563,0.0,0,2.7256143,0.0,0.61635357,82.779289,3.0562329,453.36774,-9.2288809
2558,2558,195.4009,12.080238,6.9216018,0.0,0,2.7090681,0.0,0.61880004,82.837563,3.0376549,453.25427,-9.228797
2559,2559,195.4011,12.118637,6.9441562,0.0,0,2.6929309,0.0,0.62051809,82.943909,3.0204091,453.14081,-9.2291145
2560,2560,195.4013,12.160583,6.951386,0.0,0,2.6768675,0.0,0.62241316,83.076408,3.0037453,453.02737,-9.2286224
2561,2561,195.4015,12.202027,6.9695807,0.0,0,2.6608074,0.0,0.6249119,83.143669,2.9849987,452.91391,-9.228673
2562,2562,195.4017,12.226367,6.9949694,0.0,0,2.6447473,0.0,0.62673688,83.165375,2.9674766,452.80045,-9.2296658
2563,2563,195.4019,12.240869,7.0030417,0.0,0,2.6286871,0.0,0.62854701,83.135323,2.9515457,452.68698,-9.2298193
2564,2564,195.4021,12.255932,7.0200782,0.0,0,2.6126273,0.0,0.63138026,83.008308,2.9338775,452.57352,-9.2300186
2565,2565,195.4023,12.275264,7.046433,0.0,0,2.5965672,0.0,0.63335299,82.939201,2.9159048,452.46008,-9.2298918
2566,2566,195.4025,12.300174,7.0554724,0.0,0,2.580507,0.0,0.63496393,82.934586,2.8982677,452.34662,-9.230423
2567,2567,195.4027,12.329422,7.0720119,0.0,0,2.5644472,0.0,0.63792151,82.905937,2.8795373,452.23315,-9.2305174
2568,2568,195.4029,12.372106,7.0986004,0.0,0,2.5483871,0.0,0.64005494,82.977638,2.8629134,452.11969,-9.2297602
2569,2569,195.4031,12.415339,7.1085653,0.0,0,2.5323269,0.0,0.64141732,83.120422,2.8476856,452.00623,-9.2288494
2570,2570,195.4033,12.450582,7.1229248,0.0,0,2.5162671,0.0,0.6442799,83.176201,2.832274,451.89279,-9.2283287
2571,2571,195.4035,12.485211,7.1476512,0.0,0,2.5002072,0.0,0.64656645,83.220619,2.8186843,451.77933,-9.2289095
2572,2572,195.4037,12.5049,7.1580672,0.0,0,2.4841471,0.0,0.64771116,83.249352,2.8043878,451.66586,-9.229022
2573,2573,195.4039,12.523566,7.1702971,0.0,0,2.4680872,0.0,0.65044355,83.17572,2.7854593,451.5524,-9.2296419
2574,2574,195.4041,12.541301,7.1940713,0.0,0,2.4520271,0.0,0.65290326,83.141685,2.7670302,451.43893,-9.2308445
2575,2575,195.4043,12.561772,7.2075815,0.0,0,2.4359672,0.0,0.65384889,83.186829,2.752553,451.3255,-9.2310171
2576,2576,195.4045,12.59093,7.2204237,0.0,0,2.4199073,0.0,0.65654719,83.127762,2.7375462,451.21204,-9.2304192
2577,2577,195.4047,12.619648,7.2430072,0.0,0,2.4038472,0.0,0.65939432,83.089134,2.7202075,451.09857,-9.2305479
2578,2578,195.4049,12.661552,7.2589426,0.0,0,2.3877871,0.0,0.66050178,83.258728,2.7038455,450.98511,-9.2305136
2579,2579,195.4051,12.717414,7.2716379,0.0,0,2.3717272,0.0,0.66299379,83.389656,2.6864023,450.87164,-9.2299337
2580,2580,195.4053,12.761479,7.2914171,0.0,0,2.3556671,0.0,0.66584951,83.430428,2.669719,450.75821,-9.2290859
2581,2581,195.4055,12.786535,7.308516,0.0,0,2.339607,0.0,0.66700613,83.547714,2.6546042,450.64474,-9.2282925
2582,2582,195.4057,12.811215,7.3206663,0.0,0,2.3235471,0.0,0.66924292,83.537422,2.6365659,450.53128,-9.2280674
2583,2583,195.4059,12.831936,7.3375263,0.0,0,2.3078086,0.0,0.67209113,83.437035,2.6183891,450.41782,-9.2282228
2584,2584,195.4061,12.846788,7.356401,0.0,0,2.2924592,0.0,0.67335296,83.424095,2.6011529,450.30438,-9.2285357
2585,2585,195.4063,12.875253,7.3702312,0.0,0,2.2771802,0.0,0.67545962,83.387711,2.5845225,450.19092,-9.2293005
2586,2586,195.4065,12.915422,7.3850279,0.0,0,2.261904,0.0,0.67835414,83.382645,2.571054,450.07745,-9.2295294
2587,2587,195.4067,12.957466,7.4054022,0.0,0,2.2466278,0.0,0.67983788,83.535713,2.5564334,449.96399,-9.2300215
2588,2588,195.4069,12.999015,7.4208493,0.0,0,2.2313521,0.0,0.68179059,83.641396,2.5397165,449.85052,-9.2302818
2589,2589,195.4071,13.042771,7.4327769,0.0,0,2.2160761,0.0,0.68467426,83.680199,2.5251935,449.73709,-9.2300692
2590,2590,195.4073,13.078156,7.453608,0.0,0,2.2008002,0.0,0.68645823,83.813957,2.5087321,449.62363,-9.2298832
2591,2591,195.4075,13.114209,7.4707069,0.0,0,2.185524,0.0,0.68825155,83.909798,2.490464,449.51016,-9.2301464
2592,2592,195.4077,13.140453,7.4806137,0.0,0,2.170248,0.0,0.69092387,83.826843,2.4753134,449.3967,-9.2300673
2593,2593,195.4079,13.158807,7.5011764,0.0,0,2.1549721,0.0,0.69289583,83.794609,2.4606152,449.28323,-9.229351
2594,2594,195.4081,13.19468,7.5198736,0.0,0,2.1396961,0.0,0.69452941,83.856728,2.4423866,449.1698,-9.229228
2595,2595,195.4083,13.231219,7.5278153,0.0,0,2.1244199,0.0,0.69692254,83.860497,2.425458,449.05634,-9.2289019
2596,2596,195.4085,13.263491,7.5462523,0.0,0,2.109144,0.0,0.69908834,83.904129,2.410665,448.94287,-9.2284298
2597,2597,195.4087,13.305872,7.5671897,0.0,0,2.093868,0.0,0.70071906,84.038025,2.3940964,448.82941,-9.228837
2598,2598,195.4089,13.348071,7.5750546,0.0,0,2.0785921,0.0,0.70309705,84.116432,2.3773179,448.71594,-9.2292042
2599,2599,195.4091,13.391237,7.5934186,0.0,0,2.0633161,0.0,0.70577627,84.139053,2.3606179,448.60251,-9.2289944
2600,2600,195.4093,13.441462,7.6163869,0.0,0,2.0480402,0.0,0.7074548,84.279739,2.3437552,448.48904,-9.2290936
2601,2601,195.4095,13.478792,7.6236115,0.0,0,2.0327642,0.0,0.70938987,84.372795,2.3277123,448.37558,-9.229064
2602,2602,195.4097,13.497766,7.6417727,0.0,0,2.0174882,0.0,0.71226352,84.278244,2.3126545,448.26212,-9.2287531
2603,2603,195.4099,13.516629,7.6662345,0.0,0,2.002212,0.0,0.71418828,84.211258,2.2988284,448.14865,-9.2285442
2604,2604,195.4101,13.544477,7.6728044,0.0,0,1.986936,0.0,0.71597731,84.230118,2.2842896,448.03455,-9.2291126
2605,2605,195.4103,13.583192,7.6868796,0.0,0,1.9716599,0.0,0.71887016,84.241417,2.2676947,447.91455,-9.2294569
2606,2606,195.4105,13.633951,7.7104201,0.0,0,1.9563839,0.0,0.7206319,84.389442,2.2513628,447.79453,-9.2293034
2607,2607,195.4107,13.679133,7.717648,0.0,0,1.941108,0.0,0.72187835,84.558472,2.2372277,447.67453,-9.2291136
2608,2608,195.4109,13.722102,7.7312922,0.0,0,1.9261372,0.0,0.72477913,84.591713,2.2210133,447.5545,-9.2282495
2609,2609,195.4111,13.776606,7.7563958,0.0,0,1.9115354,0.0,0.72698116,84.739014,2.2040722,447.43451,-9.2274933
2610,2610,195.4113,13.826511,7.7656569,0.0,0,1.8970003,0.0,0.72826892,84.962349,2.1888485,447.31448,-9.2275944
2611,2611,195.4115,13.860945,7.7786565,0.0,0,1.8824683,0.0,0.73131579,84.898796,2.1724992,447.19449,-9.2275925
2612,2612,195.4117,13.892135,7.8030453,0.0,0,1.8679363,0.0,0.73378468,84.831131,2.155565,447.07446,-9.2280817
2613,2613,195.4119,13.9219,7.8143072,0.0,0,1.8534042,0.0,0.73484606,84.964607,2.1402731,446.95447,-9.2282734
2614,2614,195.4121,13.952049,7.8267546,0.0,0,1.8388723,0.0,0.73788732,84.915771,2.1246903,446.83444,-9.2283335
2615,2615,195.4123,13.985906,7.8502216,0.0,0,1.8243402,0.0,0.74070227,84.867569,2.1091828,446.71445,-9.2289867
2616,2616,195.4125,14.026447,7.8638678,0.0,0,1.8098083,0.0,0.74171048,85.023415,2.0945394,446.59442,-9.2296333
2617,2617,195.4127,14.065953,7.8752642,0.0,0,1.7952763,0.0,0.74448937,85.033279,2.0796936,446.47443,-9.2297535
2618,2618,195.4129,14.111086,7.8954926,0.0,0,1.7807442,0.0,0.74728072,85.061539,2.0639203,446.3544,-9.2295618
2619,2619,195.4131,14.162202,7.9092331,0.0,0,1.7662122,0.0,0.74812776,85.281349,2.047965,446.23441,-9.2295465
2620,2620,195.4133,14.207378,7.9194379,0.0,0,1.7516803,0.0,0.75058991,85.349442,2.0326593,446.11438,-9.2287264
2621,2621,195.4135,14.250078,7.9372706,0.0,0,1.7371483,0.0,0.75342959,85.384018,2.0155418,445.99438,-9.2282095
2622,2622,195.4137,14.288733,7.9539208,0.0,0,1.7226163,0.0,0.75443631,85.534653,2.0007606,445.87436,-9.2285385
2623,2623,195.4139,14.318995,7.9660215,0.0,0,1.7080842,0.0,0.75685871,85.482597,1.9870048,445.75436,-9.2282038
2624,2624,195.4141,14.353857,7.9827805,0.0,0,1.6935523,0.0,0.76008201,85.431541,1.9702673,445.63434,-9.2275953
2625,2625,195.4143,14.396581,8.0019569,0.0,0,1.6790203,0.0,0.76145738,85.594872,1.9551934,445.51434,-9.2274914
2626,2626,195.4145,14.448184,8.0151052,0.0,0,1.6644882,0.0,0.76352769,85.708641,1.9404591,445.39432,-9.2285223
2627,2627,195.4147,14.507673,8.0289221,0.0,0,1.6499562,0.0,0.7666713,85.755516,1.9240478,445.27432,-9.2297144
2628,2628,195.4149,14.567099,8.0483198,0.0,0,1.6354243,0.0,0.76814407,85.965477,1.9090369,445.1543,-9.2296019
2629,2629,195.4151,14.625476,8.0619783,0.0,0,1.6208922,0.0,0.77002347,86.190559,1.8946487,445.0343,-9.228817
2630,2630,195.4153,14.671511,8.0725908,0.0,0,1.6063603,0.0,0.77315497,86.202843,1.8806795,444.91428,-9.2282524
2631,2631,195.4155,14.703978,8.0937672,0.0,0,1.5918282,0.0,0.77503341,86.228691,1.8650576,444.79428,-9.2279491
2632,2632,195.4157,14.735538,8.1103783,0.0,0,1.5772963,0.0,0.77689624,86.265305,1.8495517,444.67426,-9.2278662
2633,2633,195.4159,14.769965,8.1182203,0.0,0,1.5630547,0.0,0.77973408,86.234383,1.8360032,444.55426,-9.2276754
2634,2634,195.4161,14.80998,8.138814,0.0,0,1.5491643,0.0,0.78176045,86.273598,1.8197755,444.43427,-9.2274837
2635,2635,195.4163,14.850179,8.1575871,0.0,0,1.5353372,0.0,0.7834149,86.32251,1.8009442,444.31424,-9.227272
2636,2636,195.4165,14.888384,8.1635141,0.0,0,1.5215131,0.0,0.78603256,86.317055,1.7836164,444.19424,-9.2276993
2637,2637,195.4167,14.939594,8.1815701,0.0,0,1.5076891,0.0,0.7884087,86.410095,1.7724392,444.07422,-9.228384
2638,2638,195.4169,14.9978,8.2016191,0.0,0,1.4938651,0.0,0.78988433,86.602814,1.759939,443.95422,-9.2286301
2639,2639,195.4171,15.054687,8.206769,0.0,0,1.4800411,0.0,0.79212224,86.754082,1.7437218,443.8342,-9.2297678
2640,2640,195.4173,15.109234,8.2235384,0.0,0,1.4662172,0.0,0.7947973,86.84024,1.7274663,443.7142,-9.2294607
2641,2641,195.4175,15.154764,8.2455921,0.0,0,1.4523932,0.0,0.79642266,86.971848,1.7120949,443.59418,-9.2282753
2642,2642,195.4177,15.192092,8.2512712,0.0,0,1.4385692,0.0,0.79844904,87.044205,1.6970527,443.47418,-9.2283573
2643,2643,195.4179,15.234996,8.2677584,0.0,0,1.4247452,0.0,0.80154771,86.978264,1.6835234,443.35416,-9.2288609
2644,2644,195.4181,15.273211,8.2925758,0.0,0,1.4109212,0.0,0.80358672,86.964058,1.6701087,443.23416,-9.2284241
2645,2645,195.4183,15.309802,8.2997427,0.0,0,1.3970972,0.0,0.8054356,87.031799,1.6548393,443.11414,-9.2284842
2646,2646,195.4185,15.359724,8.3149767,0.0,0,1.3832732,0.0,0.80873239,87.048714,1.6395289,442.99414,-9.2291622
2647,2647,195.4187,15.417512,8.3397932,0.0,0,1.3694493,0.0,0.81075388,87.186966,1.6248058,442.87411,-9.2291956
2648,2648,195.4189,15.481277,8.3458004,0.0,0,1.3556252,0.0,0.81192762,87.409424,1.6115526,442.75412,-9.22826
2649,2649,195.4191,15.539561,8.3574018,0.0,0,1.3418012,0.0,0.81506199,87.505463,1.5982492,442.63409,-9.2269258
2650,2650,195.4193,15.587255,8.3808022,0.0,0,1.3279773,0.0,0.81730032,87.611595,1.5859876,442.5141,-9.2269955
2651,2651,195.4195,15.636744,8.3889208,0.0,0,1.3141533,0.0,0.81829596,87.766785,1.5688233,442.39407,-9.2269745
2652,2652,195.4197,15.679241,8.399725,0.0,0,1.3003292,0.0,0.82130212,87.750496,1.5526594,442.27408,-9.2276402
2653,2653,195.4199,15.717943,8.4223175,0.0,0,1.2865052,0.0,0.82375288,87.774277,1.5377668,442.15405,-9.2287741
2654,2654,195.4201,15.759668,8.4330645,0.0,0,1.2726812,0.0,0.82474798,87.930382,1.5211871,442.04254,-9.2282925
2655,2655,195.4203,15.802426,8.4432859,0.0,0,1.2588573,0.0,0.82778895,87.903618,1.5055028,441.96503,-9.2277269
2656,2656,195.4205,15.862045,8.4652824,0.0,0,1.2450333,0.0,0.83066756,87.93528,1.4890413,441.88751,-9.2277193
2657,2657,195.4207,15.929948,8.4787979,0.0,0,1.2312093,0.0,0.8317045,88.195953,1.4736853,441.80997,-9.2282648
2658,2658,195.4209,15.996337,8.4895439,0.0,0,1.2176626,0.0,0.8346765,88.34269,1.4603463,441.73245,-9.2280226
2659,2659,195.4211,16.061794,8.5103188,0.0,0,1.2044512,0.0,0.83787805,88.417824,1.4480544,441.65494,-9.2274342
2660,2660,195.4213,16.116791,8.5252237,0.0,0,1.1913005,0.0,0.83885348,88.637123,1.4332558,441.57739,-9.2276545
2661,2661,195.4215,16.160757,8.5349894,0.0,0,1.1781523,0.0,0.84143484,88.692596,1.4177854,441.49988,-9.2273607
2662,2662,195.4217,16.198925,8.5517874,0.0,0,1.1650044,0.0,0.84458143,88.618454,1.4028292,441.42233,-9.2266541
2663,2663,195.4219,16.234818,8.5677042,0.0,0,1.1518563,0.0,0.84546083,88.744095,1.3871449,441.34482,-9.2269096
2664,2664,195.4221,16.280703,8.5781651,0.0,0,1.1387082,0.0,0.84779537,88.796997,1.3737717,441.2673,-9.2270432
2665,2665,195.4223,16.339653,8.5920267,0.0,0,1.1255603,0.0,0.85111868,88.774155,1.3597649,441.18976,-9.2264395
2666,2666,195.4225,16.395214,8.6092978,0.0,0,1.1124123,0.0,0.85220438,88.973228,1.3443023,441.11224,-9.226347
2667,2667,195.4227,16.456871,8.6214323,0.0,0,1.0992643,0.0,0.85423434,89.121674,1.328379,441.03473,-9.226903
2668,2668,195.4229,16.520918,8.6332731,0.0,0,1.0861163,0.0,0.85747212,89.206665,1.3139302,440.95718,-9.2275667
2669,2669,195.4231,16.578632,8.6519127,0.0,0,1.0729682,0.0,0.85891598,89.416801,1.3012712,440.87967,-9.2273893
2670,2670,195.4233,16.635834,8.6652384,0.0,0,1.0598202,0.0,0.86083889,89.533012,1.2866565,440.80212,-9.227108
2671,2671,195.4235,16.685623,8.674778,0.0,0,1.0466722,0.0,0.86404115,89.483429,1.2727424,440.72461,-9.2272072
2672,2672,195.4237,16.725847,8.6949358,0.0,0,1.0335243,0.0,0.86596102,89.510094,1.2585558,440.64709,-9.2270317
2673,2673,195.4239,16.761799,8.7108984,0.0,0,1.0203762,0.0,0.8677991,89.582626,1.2443595,440.56955,-9.2265158
2674,2674,195.4241,16.804632,8.7181978,0.0,0,1.0072283,0.0,0.87086409,89.548965,1.2308973,440.49203,-9.2262993
2675,2675,195.4243,16.852354,8.7370701,0.0,0,0.99408025,0.0,0.87309062,89.599884,1.2148823,440.41449,-9.2263346
2676,2676,195.4245,16.916302,8.7542562,0.0,0,0.98093224,0.0,0.87462878,89.780411,1.2001348,440.33698,-9.226265
2677,2677,195.4247,16.987486,8.7585793,0.0,0,0.96778423,0.0,0.8770448,89.909393,1.1864893,440.25946,-9.2256517
2678,2678,195.4249,17.06074,8.7754974,0.0,0,0.95463622,0.0,0.87944663,90.079811,1.1710609,440.18192,-9.2256422
2679,2679,195.4251,17.129419,8.7955151,0.0,0,0.94148827,0.0,0.88104594,90.295692,1.1581826,440.1044,-9.2265701
2680,2680,195.4253,17.184362,8.7995348,0.0,0,0.92834032,0.0,0.88327134,90.370354,1.1467391,440.02689,-9.226614
2681,2681,195.4255,17.226139,8.8145475,0.0,0,0.91519231,0.0,0.88604426,90.343765,1.133526,439.94934,-9.2266216
2682,2682,195.4257,17.261068,8.8363085,0.0,0,0.9020443,0.0,0.8877399,90.384415,1.1175065,439.87183,-9.2267723
2683,2683,195.4259,17.300444,8.841548,0.0,0,0.88916039,0.0,0.88979971,90.417786,1.104457,439.79428,-9.2263813
2684,2684,195.4261,17.353052,8.8564129,0.0,0,0.87659597,0.0,0.89303911,90.406929,1.0910327,439.71677,-9.2263508
2685,2685,195.4263,17.415606,8.8797064,0.0,0,0.86408937,0.0,0.89504772,90.543945,1.0757769,439.63925,-9.2270632
2686,2686,195.4265,17.479881,8.8846254,0.0,0,0.85158527,0.0,0.89662421,90.718216,1.0614853,439.56171,-9.2273722
2687,2687,195.4267,17.547188,8.8967361,0.0,0,0.83908123,0.0,0.89976662,90.761795,1.0480447,439.48419,-9.2267141
2688,2688,195.4269,17.616634,8.9189405,0.0,0,0.82657719,0.0,0.90170521,90.941315,1.0344828,439.40668,-9.2269068
2689,2689,195.4271,17.68317,8.9241123,0.0,0,0.8140732,0.0,0.90287352,91.176315,1.0204908,439.32913,-9.2269211
2690,2690,195.4273,17.734009,8.9346495,0.0,0,0.80156928,0.0,0.90605229,91.172798,1.0072178,439.25162,-9.2262354
2691,2691,195.4275,17.766806,8.9574127,0.0,0,0.78906524,0.0,0.90826201,91.173965,0.99338341,439.17407,-9.2261524
2692,2692,195.4277,17.80488,8.9646378,0.0,0,0.77656126,0.0,0.90930641,91.270149,0.98107064,439.09656,-9.2261705
2693,2693,195.4279,17.864086,8.9740028,0.0,0,0.76405728,0.0,0.91265148,91.267075,0.96740448,439.01904,-9.2262487
2694,2694,195.4281,17.928867,8.9964218,0.0,0,0.75155324,0.0,0.91527611,91.345848,0.95251095,438.9415,-9.226244
2695,2695,195.4283,17.98737,9.0061884,0.0,0,0.73904926,0.0,0.91586226,91.569786,0.93806684,438.86398,-9.2264891
2696,2696,195.4285,18.049957,9.0155554,0.0,0,0.72654527,0.0,0.91903752,91.607079,0.92541665,438.78647,-9.2272282
2697,2697,195.4287,18.122257,9.0366802,0.0,0,0.71404123,0.0,0.92217517,91.680336,0.91369176,438.70892,-9.2269936
2698,2698,195.4289,18.198669,9.0483742,0.0,0,0.70153725,0.0,0.92286009,91.998352,0.89888746,438.63141,-9.2262449
2699,2699,195.4291,18.270844,9.0556526,0.0,0,0.68903327,0.0,0.92572516,92.105873,0.88578981,438.55386,-9.2261629
2700,2700,195.4293,18.331375,9.0729704,0.0,0,0.67652929,0.0,0.9288522,92.10405,0.87125331,438.47635,-9.2264271
2701,2701,195.4295,18.377228,9.0862265,0.0,0,0.66402531,0.0,0.92948663,92.272781,0.85740799,438.39883,-9.2261858
2702,2702,195.4297,18.418343,9.093956,0.0,0,0.65152127,0.0,0.93192977,92.285744,0.84659982,438.32129,-9.2258177
2703,2703,195.4299,18.473763,9.1089888,0.0,0,0.63901722,0.0,0.93513036,92.273911,0.83341557,438.24377,-9.2259636
2704,2704,195.4301,18.542135,9.1240644,0.0,0,0.62651324,0.0,0.93596381,92.531815,0.81789476,438.19763,-9.2259045
2705,2705,195.4303,18.605289,9.132782,0.0,0,0.61400926,0.0,0.93813753,92.647942,0.8068586,438.22461,-9.2259865
2706,2706,195.4305,18.67425,9.1451511,0.0,0,0.60150528,0.0,0.94155729,92.665749,0.79504567,438.25162,-9.2261438
2707,2707,195.4307,18.751686,9.1626005,0.0,0,0.58900124,0.0,0.94272721,92.944138,0.77743059,438.27863,-9.2264118
2708,2708,195.4309,18.822241,9.1743765,0.0,0,0.57674497,0.0,0.94474572,93.111603,0.76339316,438.30563,-9.2264023
2709,2709,195.4311,18.888006,9.1840773,0.0,0,0.56478834,0.0,0.94816113,93.125504,0.75034511,438.33264,-9.2267151
2710,2710,195.4313,18.941351,9.2015371,0.0,0,0.55288589,0.0,0.94958824,93.261971,0.73823923,438.35962,-9.2267504
2711,2711,195.4315,18.993931,9.2132702,0.0,0,0.54098582,0.0,0.95123225,93.37471,0.72766858,438.38663,-9.2261982
2712,2712,195.4317,19.052422,9.2197285,0.0,0,0.52908581,0.0,0.95432705,93.386253,0.71464217,438.41364,-9.2266827
2713,2713,195.4319,19.109886,9.2380438,0.0,0,0.51718581,0.0,0.95620561,93.472527,0.70089042,438.44064,-9.2265329
2714,2714,195.4321,19.175329,9.2513733,0.0,0,0.5052858,0.0,0.95761901,93.650932,0.68838209,438.46765,-9.2251921
2715,2715,195.4323,19.251991,9.2552795,0.0,0,0.49338579,0.0,0.96041256,93.729279,0.67555827,438.49466,-9.2250166
2716,2716,195.4325,19.327045,9.272892,0.0,0,0.48148578,0.0,0.96257019,93.860451,0.66241765,438.52164,-9.225668
2717,2717,195.4327,19.410595,9.2902336,0.0,0,0.46958581,0.0,0.96402454,94.125549,0.65028042,438.54865,-9.2258863
2718,2718,195.4329,19.490637,9.2940025,0.0,0,0.4576858,0.0,0.9667418,94.275818,0.63857949,438.57565,-9.2260599
2719,2719,195.4331,19.561296,9.3098288,0.0,0,0.44578579,0.0,0.96931577,94.397163,0.62456435,438.60266,-9.225872
2720,2720,195.4333,19.628416,9.3288317,0.0,0,0.43388578,0.0,0.97076982,94.582634,0.61002779,438.62967,-9.2257128
2721,2721,195.4335,19.685659,9.3319769,0.0,0,0.42198581,0.0,0.97312444,94.654961,0.59725517,438.65665,-9.2256317