File: clean data/testID_0155.csv
level_0,index,Time(sec),Force(kN),Jaw(mm),PowAngle(deg),Power(W),Pram,PTemp,Strain,Stress(MPa),Stroke(mm),TC1(C),wedge(mm)
2604,2604,212.0571,0.72097957,0.054138493,0.0,0,9.8948631,0.0,0.0033997025,8.8156281,9.9895372,499.7601,-9.2071657
2615,2615,212.0593,1.9162943,0.066236131,0.0,0,9.8618631,0.0,0.0046795732,23.920746,9.9577799,500.05615,-9.2064791
2626,2626,212.0615,2.856663,0.088239752,0.0,0,9.8288631,0.0,0.0056119901,36.036621,9.9314146,500.56174,-9.2062588
2637,2637,212.0637,3.1622596,0.11090663,0.0,0,9.7958632,0.0,0.0075842957,39.82056,9.8994226,501.06732,-9.2050743
2648,2648,212.0659,3.3550096,0.14826483,0.0,0,9.7628632,0.0,0.0097388532,42.190536,9.8524685,501.57288,-9.2045975
2659,2659,212.0681,3.4959137,0.18242924,0.0,0,9.7298632,0.0,0.012347902,43.904736,9.8187952,502.08502,-9.2059536
2670,2670,212.0703,3.5511141,0.22173314,0.0,0,9.6968632,0.0,0.01464108,44.617336,9.7856312,502.73499,-9.205471
2681,2681,212.0725,3.6072428,0.24923684,0.0,0,9.6638632,0.0,0.016870433,45.104656,9.7494411,503.38495,-9.2048407
2692,2692,212.0747,3.629267,0.28451544,0.0,0,9.6308632,0.0,0.019008219,45.344757,9.7153511,504.03488,-9.2040682
2703,2703,212.0769,3.6650209,0.31491524,0.0,0,9.5978632,0.0,0.021350706,45.5839,9.6795912,504.68484,-9.2032986
2714,2714,212.0791,3.6897564,0.35633951,0.0,0,9.5648632,0.0,0.023826219,45.921425,9.645833,505.14108,-9.2034159
2725,2725,212.0813,3.712712,0.38338405,0.0,0,9.5318632,0.0,0.025968697,46.098049,9.6153774,505.40359,-9.2048435
2736,2736,212.0835,3.7432089,0.41679373,0.0,0,9.4988632,0.0,0.028008154,46.192711,9.5816803,505.66611,-9.2054482
2747,2747,212.0857,3.7789133,0.44647393,0.0,0,9.4662552,0.0,0.030259898,46.612305,9.5510302,505.92862,-9.204236
2758,2758,212.0879,3.8101249,0.48401624,0.0,0,9.4340639,0.0,0.032625787,46.861885,9.5157804,506.19113,-9.2040033
2769,2769,212.0901,3.8148725,0.51130468,0.0,0,9.4018736,0.0,0.034743018,46.940678,9.4817314,506.39099,-9.2048931
2780,2780,212.0923,3.8005583,0.54449755,0.0,0,9.3696833,0.0,0.036858834,46.678249,9.4501858,506.58786,-9.2056046
2791,2791,212.0945,3.8165421,0.57382864,0.0,0,9.3374929,0.0,0.039034694,46.635258,9.4194021,506.78473,-9.2049828
2802,2802,212.0967,3.8280342,0.61277843,0.0,0,9.3053026,0.0,0.041515872,46.753036,9.3845291,506.9816,-9.2049074
2813,2813,212.0989,3.8632038,0.64094841,0.0,0,9.2731133,0.0,0.043701164,47.035088,9.3493099,507.15967,-9.203887
2824,2824,212.1011,3.8852096,0.67498332,0.0,0,9.240922,0.0,0.045988668,47.238743,9.3155022,507.31061,-9.2043533
2835,2835,212.1033,3.8897445,0.70488822,0.0,0,9.2087317,0.0,0.048121728,47.197338,9.285327,507.46155,-9.2042036
2846,2846,212.1055,3.9009144,0.74329704,0.0,0,9.1765404,0.0,0.050679307,47.205944,9.2526941,507.61249,-9.2049122
2857,2857,212.1077,3.9344356,0.77050102,0.0,0,9.144351,0.0,0.052790571,47.413269,9.2179594,507.76343,-9.2045851
2868,2868,212.1099,3.9101431,0.80355072,0.0,0,9.1121607,0.0,0.054975927,47.109268,9.1840134,507.84067,-9.2045326
2879,2879,212.1121,3.9130099,0.83190364,0.0,0,9.0799694,0.0,0.056999676,47.04488,9.1527967,507.90628,-9.2034302
2890,2890,212.1143,3.9170411,0.86961293,0.0,0,9.0477791,0.0,0.059610363,46.952126,9.1171885,507.97192,-9.2045555
2901,2901,212.1165,3.9215891,0.89651084,0.0,0,9.0155888,0.0,0.061614294,46.941387,9.088027,508.03754,-9.2049866
2912,2912,212.1187,3.9331255,0.92888397,0.0,0,8.9833984,0.0,0.063860968,47.02702,9.05474,508.07602,-9.2052345
2923,2923,212.1209,3.9703777,0.95957732,0.0,0,8.9512091,0.0,0.066057622,47.277649,9.0210276,508.05634,-9.2044821
2934,2934,212.1231,3.9722767,0.99439377,0.0,0,8.9190178,0.0,0.068574719,47.20097,8.9918041,508.03665,-9.2049284
2945,2945,212.1253,3.9928811,1.0225692,0.0,0,8.8868265,0.0,0.07047113,47.258961,8.9597387,508.01697,-9.2060986
2956,2956,212.1275,4.0122495,1.0561363,0.0,0,8.8546362,0.0,0.072988033,47.492874,8.9278526,507.99728,-9.2055454
2967,2967,212.1297,4.0019403,1.0858057,0.0,0,8.8224468,0.0,0.075067975,47.323956,8.8957939,507.96237,-9.2056055
2978,2978,212.1319,4.0196891,1.123632,0.0,0,8.7902565,0.0,0.077879637,47.395378,8.8603601,507.923,-9.2055397
2989,2989,212.1341,4.0438108,1.1568159,0.0,0,8.7580652,0.0,0.080154762,47.464584,8.822031,507.88364,-9.2055264
3000,3000,212.1363,4.0535274,1.1887656,0.0,0,8.7270651,0.0,0.082555279,47.440231,8.7899218,507.84427,-9.2046633
3011,3011,212.1385,4.0518937,1.2207923,0.0,0,8.6964502,0.0,0.084759302,47.333591,8.7564583,507.81235,-9.2053823
3022,3022,212.1407,4.0571146,1.2547998,0.0,0,8.6658354,0.0,0.087454937,47.375389,8.7239113,507.80579,-9.2056999
3033,3033,212.1429,4.0630779,1.2843705,0.0,0,8.6352196,0.0,0.089319848,47.329266,8.6932354,507.79922,-9.2037687
3044,3044,212.1451,4.0676289,1.3147768,0.0,0,8.6046047,0.0,0.091806792,47.275288,8.6566172,507.79266,-9.2034616
3055,3055,212.1473,4.0435567,1.3444685,0.0,0,8.5739899,0.0,0.093751997,46.904446,8.630393,507.78607,-9.2049017
3066,3066,212.1495,4.033309,1.3755957,0.0,0,8.5433741,0.0,0.096267648,46.650639,8.5994711,507.57819,-9.2056065
3077,3077,212.1517,4.0275602,1.4040724,0.0,0,8.5127592,0.0,0.098066397,46.486805,8.5686293,507.27631,-9.2056084
3088,3088,212.1539,4.0482717,1.431034,0.0,0,8.4821434,0.0,0.10037307,46.605434,8.5440016,506.97443,-9.2049055
3099,3099,212.1561,4.0848956,1.4589505,0.0,0,8.4515295,0.0,0.10215122,47.021305,8.5127354,506.67258,-9.2047138
3110,3110,212.1583,4.1113367,1.4914527,0.0,0,8.4209127,0.0,0.10490089,47.086895,8.4815578,506.37695,-9.204834
3121,3121,212.1605,4.1267161,1.5248556,0.0,0,8.3902988,0.0,0.10695965,47.154995,8.4484682,506.12103,-9.206171
3132,3132,212.1627,4.1311436,1.55167,0.0,0,8.359683,0.0,0.10932174,47.090008,8.4212599,505.86511,-9.2061024
3143,3143,212.1649,4.1267266,1.5808953,0.0,0,8.3290682,0.0,0.11121406,47.130821,8.3928995,505.60916,-9.2059135
3154,3154,212.1671,4.1485438,1.6149173,0.0,0,8.2984524,0.0,0.11407871,47.093796,8.3616467,505.35324,-9.2053089
3165,3165,212.1693,4.1403823,1.6470491,0.0,0,8.2678375,0.0,0.11605629,47.076248,8.3269939,505.28732,-9.2037849
3176,3176,212.1715,4.1691518,1.6758666,0.0,0,8.2372227,0.0,0.11862756,47.160057,8.2918119,505.35294,-9.2047291
3187,3187,212.1737,4.1886082,1.7085209,0.0,0,8.2066088,0.0,0.12064697,47.267349,8.2623901,505.41855,-9.2047071
3198,3198,212.1759,4.214047,1.7405808,0.0,0,8.175992,0.0,0.12357727,47.319965,8.2318964,505.48416,-9.2047205
3209,3209,212.1781,4.2249703,1.7743205,0.0,0,8.1453772,0.0,0.12556404,47.400414,8.1966753,505.51727,-9.2037239
3220,3220,212.1803,4.2206664,1.8018781,0.0,0,8.1147623,0.0,0.12819584,47.323368,8.1658554,504.86731,-9.2032728
3231,3231,212.1825,4.2109013,1.8332806,0.0,0,8.0841465,0.0,0.13010181,47.052967,8.1353846,504.21732,-9.2036037
3242,3242,212.1847,4.204401,1.8629029,0.0,0,8.053587,0.0,0.13283712,46.914623,8.1066103,503.56735,-9.2049265
3253,3253,212.1869,4.2027631,1.8966882,0.0,0,8.0244465,0.0,0.13478483,46.763721,8.0734606,502.91739,-9.2048483
3264,3264,212.1891,4.2013025,1.9197927,0.0,0,7.9953175,0.0,0.13717528,46.598991,8.0427809,502.15909,-9.2046127
3275,3275,212.1913,4.2158532,1.9511746,0.0,0,7.9661894,0.0,0.13905093,46.712048,8.0150433,501.29245,-9.2034283
3286,3286,212.1935,4.2369504,1.9784473,0.0,0,7.9370618,0.0,0.14171578,46.656204,7.9852228,500.42581,-9.2060452
3297,3297,212.1957,4.2397895,2.00969,0.0,0,7.9079332,0.0,0.14341174,46.774094,7.9571805,499.55917,-9.2064333
3308,3308,212.1979,4.2529664,2.0350718,0.0,0,7.8788056,0.0,0.14600271,46.868824,7.9225521,498.69254,-9.2056808
3319,3319,212.2001,4.2624373,2.0672092,0.0,0,7.8496776,0.0,0.14797223,46.83902,7.8977566,498.54034,-9.2054234
3330,3330,212.2023,4.2520661,2.0911064,0.0,0,7.8205495,0.0,0.15042929,46.648155,7.8653083,498.42215,-9.2043161
3341,3341,212.2045,4.2616119,2.1243374,0.0,0,7.7914219,0.0,0.1523234,46.59977,7.838058,498.30399,-9.203392
3352,3352,212.2067,4.266046,2.1487076,0.0,0,7.7622933,0.0,0.15486872,46.566238,7.8105831,498.18579,-9.2040596
3363,3363,212.2089,4.2639184,2.179445,0.0,0,7.7331653,0.0,0.15672763,46.496044,7.7832007,498.22342,-9.2051601
3374,3374,212.2111,4.2959418,2.2059228,0.0,0,7.7040377,0.0,0.15939987,46.618343,7.7540436,498.48605,-9.2052517
3385,3385,212.2133,4.3310509,2.2403228,0.0,0,7.6749096,0.0,0.16124864,46.976379,7.7238379,498.74869,-9.2059326
3396,3396,212.2155,4.3654041,2.2637227,0.0,0,7.6457815,0.0,0.16381736,47.105492,7.6949897,499.01132,-9.20543
3407,3407,212.2177,4.3695478,2.2967186,0.0,0,7.6166534,0.0,0.16591859,47.141056,7.6622567,499.27393,-9.2037153
3418,3418,212.2199,4.3643818,2.3230467,0.0,0,7.5875254,0.0,0.16862752,46.907391,7.6313086,499.58762,-9.2039318
3429,3429,212.2221,4.3522325,2.3610568,0.0,0,7.5583973,0.0,0.17074992,46.724068,7.6024094,499.90933,-9.2040749
3440,3440,212.2243,4.3586469,2.3820195,0.0,0,7.5292697,0.0,0.1732353,46.664337,7.5720835,500.23108,-9.2040854
3451,3451,212.2265,4.3523026,2.4145725,0.0,0,7.5001411,0.0,0.17524424,46.463619,7.5420732,500.5528,-9.2044315
3462,3462,212.2287,4.3721709,2.4414871,0.0,0,7.4710135,0.0,0.17790419,46.592979,7.5123849,500.85571,-9.2039671
3473,3473,212.2309,4.3941422,2.4751744,0.0,0,7.4418855,0.0,0.17993645,46.721355,7.4822311,501.11835,-9.204895
3484,3484,212.2331,4.4460392,2.4972878,0.0,0,7.4127569,0.0,0.18237725,47.087372,7.4567399,501.38098,-9.204278
3495,3495,212.2353,4.4408116,2.5311513,0.0,0,7.3840585,0.0,0.18458842,47.049652,7.4233441,501.64362,-9.2049551
3506,3506,212.2375,4.4387088,2.5582044,0.0,0,7.3563566,0.0,0.18732502,46.87199,7.3972058,501.90625,-9.2041044
3517,3517,212.2397,4.4440832,2.5959361,0.0,0,7.3286538,0.0,0.18964519,46.891212,7.3659606,502.14352,-9.2041416
3528,3528,212.2419,4.443274,2.6175215,0.0,0,7.3009515,0.0,0.19197609,46.716351,7.3358808,502.37332,-9.2044477
3539,3539,212.2441,4.4372716,2.6480539,0.0,0,7.2732491,0.0,0.19399095,46.522469,7.3034034,502.60315,-9.2050133
3550,3550,212.2463,4.4378052,2.6713121,0.0,0,7.2455468,0.0,0.19642125,46.397991,7.2748079,502.83295,-9.2052097
3561,3561,212.2485,4.4220753,2.7075968,0.0,0,7.217844,0.0,0.19872272,46.147465,7.2493687,503.04782,-9.2050762
3572,3572,212.2507,4.4312048,2.7257307,0.0,0,7.1901417,0.0,0.20077395,46.133305,7.2232714,503.21198,-9.2055149
3583,3583,212.2529,4.4326386,2.7563756,0.0,0,7.1624393,0.0,0.20284379,46.132359,7.1975436,503.37613,-9.206377
3594,3594,212.2551,4.4434357,2.7777038,0.0,0,7.134737,0.0,0.20502993,46.117905,7.1717639,503.54028,-9.2043324
3605,3605,212.2573,4.4762645,2.8111384,0.0,0,7.1070347,0.0,0.20717607,46.313793,7.1445704,503.70444,-9.2046251
3616,3616,212.2595,4.4908314,2.8315306,0.0,0,7.0793324,0.0,0.2094,46.40913,7.1181989,503.86856,-9.2044687
3627,3627,212.2617,4.4912357,2.8636656,0.0,0,7.05163,0.0,0.21168694,46.269871,7.0884342,504.03265,-9.2055292
3638,3638,212.2639,4.5107474,2.88889,0.0,0,7.0239277,0.0,0.21407527,46.36071,7.0609255,504.19678,-9.2056236
3649,3649,212.2661,4.5485888,2.9241447,0.0,0,6.9962254,0.0,0.21654962,46.601345,7.0306644,504.3609,-9.2052402
3660,3660,212.2683,4.5770898,2.9465313,0.0,0,6.9685221,0.0,0.2188402,46.801506,6.9997177,504.52499,-9.203969
3671,3671,212.2705,4.5970259,2.9796569,0.0,0,6.9408202,0.0,0.2212714,46.789104,6.9680328,504.68912,-9.2047119
3682,3682,212.2727,4.5901542,3.0065906,0.0,0,6.9131179,0.0,0.22375134,46.707561,6.9397864,504.85321,-9.2038774
3693,3693,212.2749,4.5527258,3.0378797,0.0,0,6.8854156,0.0,0.22601485,46.230568,6.9135904,505.0173,-9.2037039
3704,3704,212.2771,4.5308471,3.0560892,0.0,0,6.8577132,0.0,0.22791637,45.98838,6.8862643,505.1814,-9.2038145
3715,3715,212.2793,4.5388927,3.086359,0.0,0,6.8300109,0.0,0.23031421,45.921459,6.8608265,504.71313,-9.2047415
3726,3726,212.2815,4.5512171,3.1093771,0.0,0,6.8023081,0.0,0.23234266,45.891697,6.8326826,503.80707,-9.2048016
3737,3737,212.2837,4.5423455,3.1415629,0.0,0,6.7746053,0.0,0.23484437,45.747772,6.8096004,502.901,-9.2058201
3748,3748,212.2859,4.5839362,3.1599731,0.0,0,6.7476759,0.0,0.23663287,45.963943,6.7839179,501.99493,-9.2051477
3759,3759,212.2881,4.6342888,3.1904116,0.0,0,6.7213197,0.0,0.23902439,46.430313,6.7536893,501.07993,-9.2037411
3770,3770,212.2903,4.6690617,3.2159033,0.0,0,6.6949639,0.0,0.2412255,46.666279,6.7287455,499.9769,-9.204278
3781,3781,212.2925,4.6847534,3.2514358,0.0,0,6.6686077,0.0,0.24425793,46.724026,6.697504,498.87387,-9.2039146
3792,3792,212.2947,4.6639652,3.2754226,0.0,0,6.642252,0.0,0.2463069,46.438484,6.667666,497.77087,-9.2049866
3803,3803,212.2969,4.6512408,3.3034139,0.0,0,6.6158962,0.0,0.24872869,46.115791,6.6404438,496.66785,-9.2043085
3814,3814,212.2991,4.6364956,3.3269312,0.0,0,6.58954,0.0,0.25068998,45.952374,6.6134429,495.99158,-9.2047586
3825,3825,212.3013,4.6068258,3.3575358,0.0,0,6.5631843,0.0,0.25336662,45.548809,6.5871887,495.7421,-9.2055521
3836,3836,212.3035,4.6336055,3.37866,0.0,0,6.536828,0.0,0.25509781,45.67654,6.560679,495.49258,-9.2048149
3847,3847,212.3057,4.6790862,3.4044962,0.0,0,6.5104718,0.0,0.2574898,45.992981,6.5387268,495.24307,-9.2046642
3858,3858,212.3079,4.6950817,3.428483,0.0,0,6.4841161,0.0,0.25947967,46.101944,6.5091453,494.99359,-9.2046728
3869,3869,212.3101,4.7156024,3.4583654,0.0,0,6.4577599,0.0,0.26215351,46.186131,6.4868197,495.2392,-9.2045317
3880,3880,212.3123,4.7219939,3.4814279,0.0,0,6.4314041,0.0,0.26397833,46.153305,6.4583063,495.50839,-9.2039232
3891,3891,212.3145,4.7194581,3.5098996,0.0,0,6.4050479,0.0,0.26662913,46.050465,6.4290099,495.77759,-9.2034283
3902,3902,212.3167,4.7172799,3.5347648,0.0,0,6.3786922,0.0,0.26860973,45.927402,6.4041944,496.04681,-9.2035046
3913,3913,212.3189,4.6969662,3.563833,0.0,0,6.3523359,0.0,0.27142334,45.609123,6.37922,496.49329,-9.2043495
3924,3924,212.3211,4.709084,3.5862539,0.0,0,6.3259802,0.0,0.27300751,45.581192,6.3533211,497.19583,-9.205759
3935,3935,212.3233,4.7347779,3.6115205,0.0,0,6.2996244,0.0,0.2756049,45.765244,6.325913,497.89838,-9.2064247
3946,3946,212.3255,4.7636933,3.6368322,0.0,0,6.2732687,0.0,0.27743179,45.910423,6.3027835,498.60095,-9.2048378
3957,3957,212.3277,4.7815137,3.6665103,0.0,0,6.2469125,0.0,0.28048733,46.067043,6.2748075,499.3035,-9.2044249
3968,3968,212.3299,4.7969232,3.692687,0.0,0,6.2205563,0.0,0.28224167,46.078712,6.2483029,499.83594,-9.2044106
3979,3979,212.3321,4.7848024,3.7149632,0.0,0,6.1942005,0.0,0.2846939,45.893974,6.2228718,500.34149,-9.2056408
3990,3990,212.3343,4.8035245,3.7429755,0.0,0,6.1678443,0.0,0.28674024,45.932541,6.1984549,500.84708,-9.2044697
4001,4001,212.3365,4.8419943,3.773129,0.0,0,6.14258,0.0,0.29001039,46.07848,6.1704626,501.35266,-9.2050304
4012,4012,212.3387,4.8424983,3.8015654,0.0,0,6.1175132,0.0,0.29198205,46.070255,6.138886,501.79138,-9.2055149
4023,4023,212.3409,4.8504186,3.824554,0.0,0,6.0924463,0.0,0.2945067,45.971809,6.1099467,502.08682,-9.2048435
4034,4034,212.3431,4.8355966,3.8519995,0.0,0,6.0673795,0.0,0.29647464,45.722187,6.0871077,502.38229,-9.2043695
4045,4045,212.3453,4.8438797,3.8777843,0.0,0,6.0423131,0.0,0.29935241,45.724697,6.0611401,502.67776,-9.2056198
4056,4056,212.3475,4.8428121,3.9026103,0.0,0,6.0172458,0.0,0.30095929,45.669632,6.0355983,502.97324,-9.2055883
4067,4067,212.3497,4.8312054,3.9235644,0.0,0,5.9921789,0.0,0.30350056,45.514732,6.0145407,503.24332,-9.2039509
4078,4078,212.3519,4.8419709,3.9509132,0.0,0,5.9671125,0.0,0.30536807,45.428974,5.988153,503.50592,-9.2039146
4089,4089,212.3541,4.8527436,3.9754136,0.0,0,5.9420452,0.0,0.3082585,45.417923,5.9614739,503.76852,-9.2047119
4100,4100,212.3563,4.8626323,4.0023093,0.0,0,5.9169788,0.0,0.30991554,45.350525,5.9375463,504.03113,-9.2041502
4111,4111,212.3585,4.8987794,4.021647,0.0,0,5.891912,0.0,0.31242815,45.595589,5.9121051,504.29224,-9.2029648
4122,4122,212.3607,4.9053078,4.0500326,0.0,0,5.8668451,0.0,0.31438544,45.587204,5.8875594,504.54825,-9.2032299
4133,4133,212.3629,4.9222727,4.0745997,0.0,0,5.8417783,0.0,0.31729153,45.623486,5.8596578,504.80423,-9.2046461
4144,4144,212.3651,4.9390645,4.1022558,0.0,0,5.8167109,0.0,0.31898215,45.734932,5.8349562,505.06021,-9.2037725
4155,4155,212.3673,4.9296341,4.1204515,0.0,0,5.7916446,0.0,0.32156211,45.488045,5.8121099,505.31619,-9.2038889
4166,4166,212.3695,4.9056997,4.1499467,0.0,0,5.7665777,0.0,0.32344872,45.146801,5.7889099,505.55426,-9.2033272
4177,4177,212.3717,4.9313807,4.1736517,0.0,0,5.7415109,0.0,0.32639179,45.209358,5.759624,505.78394,-9.2039976
4188,4188,212.3739,4.9469972,4.2019572,0.0,0,5.716444,0.0,0.32815456,45.394699,5.7376566,506.01361,-9.2035904
4199,4199,212.3761,4.9694891,4.2203512,0.0,0,5.6913776,0.0,0.33078599,45.444263,5.7114401,506.24332,-9.205349
4210,4210,212.3783,4.994698,4.2496681,0.0,0,5.6663103,0.0,0.33268744,45.583794,5.6865902,506.47659,-9.2050591
4221,4221,212.3805,5.0196853,4.2736592,0.0,0,5.6412435,0.0,0.33574459,45.69297,5.6606894,506.73251,-9.2055683
4232,4232,212.3827,5.0412002,4.3060169,0.0,0,5.6161766,0.0,0.33776215,45.755749,5.6319089,506.98846,-9.2048826
4243,4243,212.3849,5.052959,4.3242455,0.0,0,5.5912561,0.0,0.34039143,45.782379,5.6057849,507.24438,-9.2042809
4254,4254,212.3871,5.0238304,4.3547697,0.0,0,5.5674076,0.0,0.34257823,45.455894,5.581512,507.50034,-9.2047157
4265,4265,212.3893,4.9801326,4.3758426,0.0,0,5.5435596,0.0,0.34538406,44.874809,5.5571365,507.77179,-9.204895
4276,4276,212.3915,4.969182,4.4052606,0.0,0,5.519712,0.0,0.34719211,44.694313,5.5350142,508.05399,-9.2056932
4287,4287,212.3937,5.0049615,4.4221969,0.0,0,5.4958634,0.0,0.34971625,44.917934,5.5087771,508.33615,-9.2049732
4298,4298,212.3959,5.0355725,4.4473763,0.0,0,5.4720159,0.0,0.35133705,45.124744,5.4885201,508.61835,-9.2044506
4309,4309,212.3981,5.052814,4.4665322,0.0,0,5.4481678,0.0,0.35390764,45.139446,5.4626527,508.89783,-9.2053289
4320,4320,212.4003,5.0778885,4.5011559,0.0,0,5.4243197,0.0,0.35614759,45.275482,5.439177,509.12097,-9.2062073
4331,4331,212.4025,5.0737767,4.5168357,0.0,0,5.4004722,0.0,0.35858449,45.098339,5.4179769,509.34409,-9.2041683
4342,4342,212.4047,5.0656533,4.5445895,0.0,0,5.3766236,0.0,0.36058336,45.004944,5.3916836,509.5672,-9.2048922
4353,4353,212.4069,5.0668378,4.563457,0.0,0,5.3527756,0.0,0.36312985,44.881886,5.3667078,509.79031,-9.2041159
4364,4364,212.4091,5.0527978,4.5946426,0.0,0,5.328928,0.0,0.3651253,44.656731,5.344986,509.96094,-9.2044554
4375,4375,212.4113,5.0641069,4.6082025,0.0,0,5.3050799,0.0,0.3674463,44.700016,5.3239188,510.07907,-9.2041969
4386,4386,212.4135,5.1054606,4.637774,0.0,0,5.2812319,0.0,0.36944348,44.92215,5.2963772,510.1972,-9.2050123
4397,4397,212.4157,5.1420794,4.6569767,0.0,0,5.2573838,0.0,0.37220114,45.014149,5.2735,510.31531,-9.2049646
4408,4408,212.4179,5.16046,4.6892443,0.0,0,5.2335358,0.0,0.37429112,45.191372,5.2489972,510.43344,-9.2052145
4419,4419,212.4201,5.1802392,4.7022834,0.0,0,5.2096877,0.0,0.37646219,45.325977,5.2217226,510.51398,-9.2038908
4430,4430,212.4223,5.1877203,4.7320271,0.0,0,5.1858397,0.0,0.37872729,45.222004,5.2018685,510.59271,-9.20436
4441,4441,212.4245,5.1688499,4.7552481,0.0,0,5.1619916,0.0,0.38175169,44.928715,5.1793051,510.67148,-9.2045441
4452,4452,212.4267,5.1928897,4.7876902,0.0,0,5.1381435,0.0,0.38396588,45.05204,5.1529942,510.75021,-9.2042809
4463,4463,212.4289,5.2129655,4.8021183,0.0,0,5.1142955,0.0,0.38607121,45.106884,5.1304526,510.83435,-9.2054014
4474,4474,212.4311,5.2194791,4.8331313,0.0,0,5.0904479,0.0,0.38856536,45.060158,5.101615,510.92621,-9.2050714
4485,4485,212.4333,5.2452655,4.8522096,0.0,0,5.0665994,0.0,0.39106908,45.100357,5.0772796,511.0181,-9.2053871
4496,4496,212.4355,5.2331662,4.8855395,0.0,0,5.0432091,0.0,0.39362749,44.940823,5.0528359,511.10995,-9.2054396
4507,4507,212.4377,5.2079883,4.9002309,0.0,0,5.0205269,0.0,0.39572099,44.599953,5.0334816,511.20181,-9.2040329
4518,4518,212.4399,5.2359977,4.9262304,0.0,0,4.9978447,0.0,0.39783084,44.764145,5.0072012,511.2597,-9.2033653
4529,4529,212.4421,5.2345529,4.9439878,0.0,0,4.975163,0.0,0.39998084,44.717911,4.985796,511.31219,-9.2042637
4540,4540,212.4443,5.239975,4.9746232,0.0,0,4.9524813,0.0,0.40251133,44.667629,4.9619398,511.36472,-9.2051802
4551,4551,212.4465,5.2409554,4.9906173,0.0,0,4.9297986,0.0,0.40476698,44.535877,4.9423814,511.41721,-9.2064619
4562,4562,212.4487,5.2371931,5.0177226,0.0,0,4.9071169,0.0,0.40699136,44.314201,4.9187469,511.46344,-9.2069759
4573,4573,212.4509,5.2846689,5.0354533,0.0,0,4.8844347,0.0,0.40908277,44.65601,4.8967233,511.49625,-9.2056866
4584,4584,212.4531,5.3183765,5.0651751,0.0,0,4.861753,0.0,0.41177318,44.91256,4.8715625,511.52905,-9.2042761
4595,4595,212.4553,5.3233767,5.0822167,0.0,0,4.8390708,0.0,0.41380721,44.784851,4.8489313,511.56189,-9.2047234
4606,4606,212.4575,5.3364177,5.1093469,0.0,0,4.8163886,0.0,0.41629389,44.807289,4.8280582,511.5947,-9.204855
4617,4617,212.4597,5.3314366,5.1282096,0.0,0,4.7937069,0.0,0.41842377,44.713169,4.8069906,511.62244,-9.2047491
4628,4628,212.4619,5.3409858,5.1580086,0.0,0,4.7710247,0.0,0.42114159,44.62886,4.7831697,511.64868,-9.2051582
4639,4639,212.4641,5.3307247,5.1735072,0.0,0,4.748343,0.0,0.42299747,44.469448,4.7556906,511.6749,-9.2035904
4650,4650,212.4663,5.3347502,5.2005777,0.0,0,4.7256608,0.0,0.42566592,44.383713,4.7342072,511.70114,-9.2056656
4661,4661,212.4685,5.3419838,5.2177987,0.0,0,4.7029786,0.0,0.42750859,44.29562,4.7131138,511.70206,-9.2055359
4672,4672,212.4707,5.3654847,5.2473326,0.0,0,4.6802969,0.0,0.43034601,44.408459,4.6912408,511.61673,-9.2047653
4683,4683,212.4729,5.4139438,5.2637372,0.0,0,4.6576152,0.0,0.4322271,44.681137,4.6677561,511.53143,-9.2045336
4694,4694,212.4751,5.4191098,5.2901158,0.0,0,4.6349325,0.0,0.43488625,44.689289,4.6419606,511.44614,-9.2058926
4705,4705,212.4773,5.425343,5.3095388,0.0,0,4.6122508,0.0,0.43680155,44.646294,4.6215682,511.36081,-9.2048922
4716,4716,212.4795,5.4156055,5.3397865,0.0,0,4.5895686,0.0,0.44010356,44.41655,4.6002331,511.23972,-9.2044344
4727,4727,212.4817,5.4231958,5.356781,0.0,0,4.5668869,0.0,0.44169348,44.419224,4.5782137,511.1019,-9.2041264
4738,4738,212.4839,5.4331002,5.3782306,0.0,0,4.5442047,0.0,0.44410685,44.321823,4.5517335,510.96411,-9.2045689
4749,4749,212.4861,5.4353585,5.3975306,0.0,0,4.5222569,0.0,0.44599494,44.32077,4.5299711,510.82629,-9.2033157
4760,4760,212.4883,5.4718857,5.426682,0.0,0,4.500679,0.0,0.44919926,44.435143,4.5103593,510.64999,-9.2047577
4771,4771,212.4905,5.4962311,5.4478064,0.0,0,4.4791017,0.0,0.45112318,44.531372,4.489213,510.23001,-9.204999
4782,4782,212.4927,5.5183988,5.4682546,0.0,0,4.4575238,0.0,0.45360813,44.644962,4.4653931,509.81003,-9.2049551
4793,4793,212.4949,5.5243053,5.4910488,0.0,0,4.4359465,0.0,0.45555353,44.580677,4.4396944,509.39001,-9.2046413
4804,4804,212.4971,5.5130019,5.5185061,0.0,0,4.4143691,0.0,0.4588415,44.370403,4.417407,508.97003,-9.204916
4815,4815,212.4993,5.5197191,5.5384054,0.0,0,4.3927913,0.0,0.46047997,44.377907,4.3940487,508.4841,-9.2040405
4826,4826,212.5015,5.4951634,5.5572495,0.0,0,4.3712134,0.0,0.46295458,44.050663,4.372231,507.95255,-9.2049427
4837,4837,212.5037,5.4609704,5.5789566,0.0,0,4.3496361,0.0,0.46476367,43.670456,4.3546696,507.42099,-9.2045841
4848,4848,212.5059,5.480576,5.6022291,0.0,0,4.3280582,0.0,0.46787736,43.743111,4.333992,506.88943,-9.2033806
4859,4859,212.5081,5.5226326,5.6217909,0.0,0,4.3064809,0.0,0.46930563,43.914799,4.3124089,506.36322,-9.2048893
4870,4870,212.5103,5.5745163,5.6379247,0.0,0,4.284903,0.0,0.47165048,44.241119,4.2932572,505.94974,-9.2051611
4881,4881,212.5125,5.5980401,5.6609497,0.0,0,4.2633252,0.0,0.4734832,44.384235,4.271915,505.53622,-9.2054672
4892,4892,212.5147,5.5904341,5.6845555,0.0,0,4.2417479,0.0,0.47677925,44.157871,4.2489266,505.12274,-9.2047729
4903,4903,212.5169,5.6100674,5.7093763,0.0,0,4.2201705,0.0,0.47853962,44.213932,4.2292452,504.70926,-9.2052965
4914,4914,212.5191,5.6460028,5.7277932,0.0,0,4.1985927,0.0,0.48135656,44.484798,4.2071104,504.41718,-9.204813
4925,4925,212.5213,5.6516595,5.7494712,0.0,0,4.1770153,0.0,0.48293588,44.417339,4.1806054,504.24652,-9.2043056
4936,4936,212.5235,5.6606789,5.7736044,0.0,0,4.1554375,0.0,0.48638201,44.299431,4.1612153,504.07587,-9.2057524
4947,4947,212.5257,5.6876426,5.7996287,0.0,0,4.1338601,0.0,0.48831299,44.409542,4.1389751,503.90521,-9.2058973
4958,4958,212.5279,5.7284393,5.8189869,0.0,0,4.1122823,0.0,0.491317,44.605038,4.115705,503.73456,-9.2048054
4969,4969,212.5301,5.7323985,5.84304,0.0,0,4.0907049,0.0,0.49306893,44.534241,4.0903463,504.08392,-9.2046633
4980,4980,212.5323,5.7347088,5.8643999,0.0,0,4.0691271,0.0,0.49634546,44.452381,4.0700803,504.45807,-9.2039061
4991,4991,212.5345,5.7057557,5.8886714,0.0,0,4.0475497,0.0,0.49805743,44.220032,4.0466037,504.83218,-9.2038975
5002,5002,212.5367,5.7144742,5.9048142,0.0,0,4.0269618,0.0,0.50075835,44.123047,4.0284114,505.20633,-9.2051153
5013,5013,212.5389,5.7353797,5.931643,0.0,0,4.0064402,0.0,0.50268227,44.132378,4.0076394,505.54822,-9.2034092
5024,5024,212.5411,5.7310743,5.9504905,0.0,0,3.9859188,0.0,0.50586039,43.958782,3.984093,505.84357,-9.2033205
5035,5035,212.5433,5.7323518,5.9775019,0.0,0,3.9653969,0.0,0.50772345,43.907116,3.9616392,506.13889,-9.2034092
5046,5046,212.5455,5.7588301,5.9913177,0.0,0,3.9448752,0.0,0.51041502,44.034595,3.9413807,506.43423,-9.2050877
5057,5057,212.5477,5.7769327,6.0154243,0.0,0,3.9243536,0.0,0.51197267,44.064049,3.9229996,506.72955,-9.205184
5068,5068,212.5499,5.7626824,6.0315809,0.0,0,3.9038324,0.0,0.51492095,43.862888,3.9023635,506.64514,-9.205369
5079,5079,212.5521,5.759305,6.057797,0.0,0,3.8833106,0.0,0.51655895,43.766399,3.8807344,506.50076,-9.2049217
5090,5090,212.5543,5.7443051,6.0702763,0.0,0,3.8627889,0.0,0.51914471,43.514629,3.8651474,506.35638,-9.2042875
5101,5101,212.5565,5.7638841,6.0928106,0.0,0,3.8422673,0.0,0.52066976,43.575073,3.8471417,506.21204,-9.2050667
5112,5112,212.5587,5.7673678,6.1077919,0.0,0,3.8217459,0.0,0.52351582,43.545284,3.8267155,505.76266,-9.2051458
5123,5123,212.5609,5.7902102,6.1366105,0.0,0,3.8012242,0.0,0.52527338,43.556503,3.8073425,504.6597,-9.2058582
5134,5134,212.5631,5.8159256,6.148705,0.0,0,3.7807026,0.0,0.52803582,43.661743,3.7873566,503.55676,-9.2051821
5145,5145,212.5653,5.8797641,6.1722031,0.0,0,3.760181,0.0,0.52964097,44.033367,3.7641521,502.45383,-9.2040653
5156,5156,212.5675,5.9150567,6.1883535,0.0,0,3.7396593,0.0,0.53265411,44.184174,3.7450082,501.35089,-9.2056017
5167,5167,212.5697,5.9270945,6.2190495,0.0,0,3.7191379,0.0,0.53466469,44.216743,3.7197804,500.07031,-9.2056875
5178,5178,212.5719,5.9324961,6.2322221,0.0,0,3.6986163,0.0,0.53742653,44.152508,3.7010643,498.73749,-9.2049685
5189,5189,212.5741,5.9653745,6.2593369,0.0,0,3.6780944,0.0,0.53954041,44.267014,3.679841,497.40466,-9.2037325
5200,5200,212.5763,5.9777985,6.2748542,0.0,0,3.657573,0.0,0.54239827,44.28223,3.6579771,496.07184,-9.2034063
5211,5211,212.5785,5.9843545,6.3052711,0.0,0,3.6370516,0.0,0.5444513,44.2262,3.638643,494.8912,-9.2042961
5222,5222,212.5807,5.9823251,6.3175817,0.0,0,3.6165297,0.0,0.54735845,44.087215,3.6158679,494.22806,-9.2046709
5233,5233,212.5829,5.9918242,6.3440194,0.0,0,3.5960083,0.0,0.54927951,44.013073,3.5970056,493.56491,-9.2048731
5244,5244,212.5851,5.9908037,6.3580208,0.0,0,3.5756967,0.0,0.55212969,43.919449,3.5766931,492.90173,-9.2044134
5255,5255,212.5873,6.0274858,6.3863187,0.0,0,3.556174,0.0,0.55405736,44.125996,3.5550957,492.23859,-9.2039843
5266,5266,212.5895,6.0291238,6.3975768,0.0,0,3.5366509,0.0,0.55654854,44.063282,3.5358644,491.62909,-9.2040386
5277,5277,212.5917,6.0391588,6.4232965,0.0,0,3.5171282,0.0,0.55854261,44.004189,3.5150802,491.04459,-9.2048683
5288,5288,212.5939,6.0294666,6.4392924,0.0,0,3.4976053,0.0,0.56137967,43.802559,3.4940424,490.46011,-9.2054129
5299,5299,212.5961,6.0465717,6.4684024,0.0,0,3.4780829,0.0,0.56353247,43.840454,3.4760728,489.87564,-9.2042646
5310,5310,212.5983,6.0798249,6.4777312,0.0,0,3.4585598,0.0,0.56574124,44.006321,3.4552641,489.39951,-9.2043743
5321,5321,212.6005,6.111239,6.5016804,0.0,0,3.4390368,0.0,0.56777763,44.097351,3.4337127,489.60959,-9.2034197
5332,5332,212.6027,6.1095648,6.5180888,0.0,0,3.4195144,0.0,0.57065642,43.993439,3.4158897,489.8197,-9.2037516
5343,5343,212.6049,6.1075239,6.548439,0.0,0,3.3999913,0.0,0.57301068,43.892834,3.3976998,490.02982,-9.2046852
5354,5354,212.6071,6.1265168,6.5586715,0.0,0,3.3804688,0.0,0.57531089,43.869911,3.3780658,490.23993,-9.2035561
5365,5365,212.6093,6.1323252,6.5819073,0.0,0,3.3609457,0.0,0.57727373,43.831745,3.3557279,490.78763,-9.2040129
5376,5376,212.6115,6.103272,6.5953016,0.0,0,3.3414228,0.0,0.57959825,43.550827,3.3365567,491.56909,-9.2042742
5387,5387,212.6137,6.1184301,6.6224103,0.0,0,3.3219004,0.0,0.58197039,43.572044,3.3198938,492.35056,-9.2059097
5398,5398,212.6159,6.1224909,6.6343584,0.0,0,3.3023772,0.0,0.5842486,43.454067,3.3040977,493.13202,-9.2066593
5409,5409,212.6181,6.1656766,6.6560869,0.0,0,3.2828543,0.0,0.58618444,43.660744,3.2821178,493.88394,-9.2063723
5420,5420,212.6203,6.2228398,6.671289,0.0,0,3.2633319,0.0,0.58871561,43.910492,3.2642155,494.01526,-9.2054548
5431,5431,212.6225,6.2694378,6.6998968,0.0,0,3.243809,0.0,0.59134287,44.207794,3.2426968,494.14658,-9.204421
5442,5442,212.6247,6.2974262,6.7120023,0.0,0,3.2242863,0.0,0.59349263,44.341503,3.2201231,494.27789,-9.2048168
5453,5453,212.6269,6.2765579,6.7355294,0.0,0,3.2047634,0.0,0.5957309,44.07008,3.2014658,494.40921,-9.2045813
5464,5464,212.6291,6.2486758,6.7500653,0.0,0,3.1852405,0.0,0.59809315,43.786819,3.1827424,494.56021,-9.2053747
5475,5475,212.6313,6.2803278,6.7772298,0.0,0,3.1657178,0.0,0.60077453,43.879944,3.1680002,494.73093,-9.2049999
5486,5486,212.6335,6.3305054,6.7915206,0.0,0,3.1461952,0.0,0.60301888,44.085796,3.1442921,494.90164,-9.2051182
5497,5497,212.6357,6.3577743,6.8146687,0.0,0,3.1271312,0.0,0.60548818,44.228733,3.1232603,495.07236,-9.2055607
5508,5508,212.6379,6.3965282,6.8301864,0.0,0,3.1085584,0.0,0.60770458,44.339207,3.1046758,495.24307,-9.2043591
5519,5519,212.6401,6.3936205,6.8579001,0.0,0,3.0899863,0.0,0.61068308,44.185089,3.0884044,496.20975,-9.2049456
5530,5530,212.6423,6.3875341,6.8709493,0.0,0,3.0714138,0.0,0.61275333,44.077068,3.0675368,497.21432,-9.2041292
5541,5541,212.6445,6.3745031,6.8903551,0.0,0,3.0528414,0.0,0.61494732,43.925873,3.0480711,498.2189,-9.2028379
5552,5552,212.6467,6.3845277,6.9055176,0.0,0,3.0342693,0.0,0.61692238,43.895016,3.0270138,499.22348,-9.2048006
5563,5563,212.6489,6.3746367,6.9322329,0.0,0,3.0156965,0.0,0.62011302,43.684357,3.0123208,500.03467,-9.2047901
5574,5574,212.6511,6.3900304,6.9464235,0.0,0,2.9971242,0.0,0.62201756,43.665047,2.9936824,500.56653,-9.204834
5585,5585,212.6533,6.4220304,6.9656506,0.0,0,2.9785516,0.0,0.6243664,43.75132,2.976434,501.09836,-9.2051668
5596,5596,212.6555,6.4588056,6.9800901,0.0,0,2.9599793,0.0,0.62603354,43.903259,2.9585199,501.63019,-9.2042103
5607,5607,212.6577,6.4932146,7.0062857,0.0,0,2.941407,0.0,0.62936223,44.092125,2.9411094,502.16205,-9.2040539
5618,5618,212.6599,6.5164547,7.0198689,0.0,0,2.9228346,0.0,0.63089979,44.175518,2.9215302,502.18918,-9.2053318
5629,5629,212.6621,6.5341139,7.0382519,0.0,0,2.9042623,0.0,0.63347179,44.126995,2.9034407,502.13666,-9.2046347
5640,5640,212.6643,6.5653706,7.0548778,0.0,0,2.88569,0.0,0.63528723,44.238262,2.8859918,502.08414,-9.2044659
5651,5651,212.6665,6.5856285,7.0800867,0.0,0,2.8671174,0.0,0.63880193,44.304279,2.8669372,502.03162,-9.2047777
5662,5662,212.6687,6.5977263,7.0964403,0.0,0,2.8485448,0.0,0.64047837,44.297874,2.8440309,502.03967,-9.204874
5673,5673,212.6709,6.6253791,7.1181955,0.0,0,2.8299725,0.0,0.64370447,44.289055,2.8254786,502.17755,-9.2054739
5684,5684,212.6731,6.6371336,7.1360273,0.0,0,2.8114002,0.0,0.64551228,44.332279,2.8062723,502.31543,-9.2049379
5695,5695,212.6753,6.6336708,7.1577897,0.0,0,2.7928278,0.0,0.64880365,44.144123,2.7890544,502.45334,-9.2049341
5706,5706,212.6775,6.6313872,7.1737609,0.0,0,2.7742555,0.0,0.65027392,44.0494,2.7694068,502.59122,-9.2046213
5717,5717,212.6797,6.6344433,7.1912608,0.0,0,2.7556829,0.0,0.65297478,43.97504,2.7532327,502.74432,-9.2052755
5728,5728,212.6819,6.6325364,7.2097054,0.0,0,2.7371109,0.0,0.65480328,43.925316,2.7352586,502.90189,-9.2049351
5739,5739,212.6841,6.6607542,7.2288375,0.0,0,2.7185383,0.0,0.65798527,43.931824,2.7184818,503.05948,-9.2041483
5750,5750,212.6863,6.6722031,7.2426257,0.0,0,2.7006512,0.0,0.65899944,43.972725,2.7000332,503.21704,-9.2057533
5761,5761,212.6885,6.7224331,7.2594333,0.0,0,2.6829851,0.0,0.66198599,44.124744,2.6809094,503.27316,-9.2058496
5772,5772,212.6907,6.7866936,7.280777,0.0,0,2.665319,0.0,0.66397262,44.458382,2.6603358,502.98425,-9.2055645
5783,5783,212.6929,6.8060894,7.3022423,0.0,0,2.6476531,0.0,0.66748416,44.451199,2.6434388,502.69534,-9.2056046
5794,5794,212.6951,6.826632,7.32023,0.0,0,2.629987,0.0,0.66891658,44.516605,2.6238599,502.40646,-9.2049427
5805,5805,212.6973,6.8163795,7.3347807,0.0,0,2.6123211,0.0,0.67174351,44.355343,2.6066766,502.11755,-9.2047558
5816,5816,212.6995,6.8208137,7.356133,0.0,0,2.594655,0.0,0.67360157,44.284889,2.5890305,501.58691,-9.204648
5827,5827,212.7017,6.83181,7.3738208,0.0,0,2.5769889,0.0,0.67703509,44.198025,2.5703337,500.94345,-9.2049046
5838,5838,212.7039,6.8233547,7.3927689,0.0,0,2.5593231,0.0,0.67835367,44.128803,2.5523529,500.29999,-9.2056265
5849,5849,212.7061,6.814362,7.4047589,0.0,0,2.541657,0.0,0.68103856,43.927349,2.5383062,499.65656,-9.2065105
5860,5860,212.7083,6.8467493,7.4254975,0.0,0,2.5239909,0.0,0.68264109,44.009872,2.5160694,499.08023,-9.2060871
5871,5871,212.7105,6.877193,7.4418955,0.0,0,2.506325,0.0,0.68603885,44.049438,2.503912,498.92923,-9.2051888
5882,5882,212.7127,6.9142718,7.4619951,0.0,0,2.4886589,0.0,0.68745524,44.27459,2.484741,498.7782,-9.2050791
5893,5893,212.7149,6.9447575,7.4719472,0.0,0,2.470993,0.0,0.69001514,44.333057,2.4696326,498.6272,-9.2051592
5904,5904,212.7171,6.9867191,7.4937863,0.0,0,2.4533269,0.0,0.69176871,44.541798,2.4541614,498.47617,-9.2051849
5915,5915,212.7193,7.0152569,7.5102482,0.0,0,2.4356608,0.0,0.69519442,44.563663,2.4363899,498.18936,-9.2049465
5926,5926,212.7215,7.0701933,7.5343857,0.0,0,2.417995,0.0,0.69685221,44.845871,2.4124095,497.80856,-9.2036676
5937,5937,212.7237,7.0742397,7.5460505,0.0,0,2.4003291,0.0,0.69993824,44.722095,2.3941851,497.42773,-9.2039595
5948,5948,212.7259,7.0821142,7.5679641,0.0,0,2.382663,0.0,0.70167249,44.718948,2.3765326,497.04691,-9.20399
5959,5959,212.7281,7.1000547,7.5844102,0.0,0,2.3649969,0.0,0.70531005,44.622089,2.3555675,496.67267,-9.2047138
5970,5970,212.7303,7.1022005,7.609879,0.0,0,2.347331,0.0,0.70708287,44.532948,2.3406696,496.43628,-9.2053432
5981,5981,212.7325,7.1196404,7.6189795,0.0,0,2.3296649,0.0,0.7098459,44.635517,2.326004,496.19989,-9.2050076
5992,5992,212.7347,7.1488142,7.640831,0.0,0,2.312031,0.0,0.71144807,44.713165,2.3060961,495.96353,-9.2032919
6003,6003,212.7369,7.1607652,7.6572537,0.0,0,2.2952197,0.0,0.71506357,44.598206,2.2886505,495.72714,-9.2041883
6014,6014,212.7391,7.1647658,7.6809645,0.0,0,2.2784159,0.0,0.71646082,44.572655,2.268075,495.84204,-9.2059307
6025,6025,212.7413,7.1674962,7.6891127,0.0,0,2.2616124,0.0,0.71939635,44.490627,2.2541616,496.30823,-9.2067394
6036,6036,212.7435,7.1625242,7.7110872,0.0,0,2.2448089,0.0,0.72096574,44.380474,2.2385802,496.77441,-9.2062893
6047,6047,212.7457,7.2136416,7.7224407,0.0,0,2.2280054,0.0,0.72416478,44.493038,2.2180307,497.2406,-9.2042542
6058,6058,212.7479,7.2472367,7.7488108,0.0,0,2.2112017,0.0,0.72595274,44.623367,2.2013612,497.70679,-9.2047815
6069,6069,212.7501,7.2737741,7.7553954,0.0,0,2.1943982,0.0,0.72858232,44.722713,2.1851308,497.86584,-9.20366
6080,6080,212.7523,7.2906308,7.7787151,0.0,0,2.1775944,0.0,0.7304163,44.737602,2.1695364,498.01028,-9.2046356
6091,6091,212.7545,7.2905555,7.7928448,0.0,0,2.1607909,0.0,0.73388779,44.525871,2.1495686,498.15475,-9.2036762
6102,6102,212.7567,7.2646894,7.8190074,0.0,0,2.1439872,0.0,0.73563862,44.362247,2.1343956,498.29919,-9.203661
6113,6113,212.7589,7.2600861,7.8247285,0.0,0,2.1271837,0.0,0.73813355,44.210049,2.1206582,498.32278,-9.2046671
6124,6124,212.7611,7.2769332,7.8431745,0.0,0,2.1103802,0.0,0.73939866,44.235741,2.10466,498.17175,-9.2058086
6135,6135,212.7633,7.3139906,7.8547916,0.0,0,2.0935764,0.0,0.74231011,44.278271,2.088058,498.02075,-9.205533
6146,6146,212.7655,7.3947616,7.8803201,0.0,0,2.0767729,0.0,0.74420393,44.703094,2.0703626,497.86972,-9.206274
6157,6157,212.7677,7.4508133,7.8911872,0.0,0,2.0599694,0.0,0.74733829,44.91964,2.0517149,497.71872,-9.2046099
6168,6168,212.7699,7.4934831,7.9138937,0.0,0,2.0431657,0.0,0.74925268,45.089935,2.0334859,497.8342,-9.204277
6179,6179,212.7721,7.5203695,7.9230523,0.0,0,2.0263622,0.0,0.75200045,45.115685,2.0173061,497.99179,-9.2043333
6190,6190,212.7743,7.5400724,7.9520025,0.0,0,2.0095587,0.0,0.75427938,45.154514,2.0013635,498.14938,-9.2059278
6201,6201,212.7765,7.5409632,7.9596949,0.0,0,1.9927549,0.0,0.75704813,45.042759,1.984046,498.30695,-9.2049952
6212,6212,212.7787,7.5338774,7.9825821,0.0,0,1.9759514,0.0,0.75912058,44.907829,1.9663608,498.61285,-9.2053347
6223,6223,212.7809,7.5415859,7.9956517,0.0,0,1.9591477,0.0,0.76218516,44.782303,1.9485599,499.23663,-9.2038288
6234,6234,212.7831,7.5375681,8.0218554,0.0,0,1.9423442,0.0,0.76436079,44.663288,1.931157,499.86041,-9.203907
6245,6245,212.7853,7.537653,8.025856,0.0,0,1.9257871,0.0,0.76625717,44.565281,1.91668,500.48416,-9.2049189
6256,6256,212.7875,7.571629,8.0474157,0.0,0,1.9098018,0.0,0.76833391,44.725132,1.902384,501.10794,-9.2061043
6267,6267,212.7897,7.6106911,8.0596447,0.0,0,1.8938167,0.0,0.77129537,44.782562,1.8843189,500.59518,-9.2056637
6278,6278,212.7919,7.6506586,8.083704,0.0,0,1.8778315,0.0,0.77351016,44.944584,1.8662416,499.74817,-9.2048416
6289,6289,212.7941,7.6849642,8.0924301,0.0,0,1.8618462,0.0,0.77572328,45.027981,1.8532257,498.90118,-9.2061987
6300,6300,212.7963,7.6756172,8.1155071,0.0,0,1.8458611,0.0,0.77833652,44.873898,1.8401895,498.05417,-9.2049103
6311,6311,212.7985,7.7075157,8.1248913,0.0,0,1.8298758,0.0,0.78056043,44.917015,1.8233579,497.00568,-9.2053537
6322,6322,212.8007,7.7410102,8.1492586,0.0,0,1.8138907,0.0,0.78312677,44.980389,1.8051916,495.27209,-9.2052231
6333,6333,212.8029,7.7592206,8.1577415,0.0,0,1.7979054,0.0,0.78536814,45.05238,1.7909545,493.53854,-9.2051697
6344,6344,212.8051,7.7864223,8.1785831,0.0,0,1.7819202,0.0,0.78758931,45.112995,1.7737393,491.80499,-9.203558
6355,6355,212.8073,7.8066878,8.1903515,0.0,0,1.7659351,0.0,0.79003954,45.108398,1.7616851,490.07141,-9.2049065
6366,6366,212.8095,7.8310485,8.2140255,0.0,0,1.7499498,0.0,0.7927807,45.127403,1.7456653,488.95993,-9.2058964
6377,6377,212.8117,7.8553991,8.2218199,0.0,0,1.7339647,0.0,0.79463118,45.191811,1.7295049,488.13873,-9.2055178
6388,6388,212.8139,7.8897462,8.2419376,0.0,0,1.7179794,0.0,0.79707372,45.271549,1.7098528,487.31754,-9.2037973
6399,6399,212.8161,7.9296083,8.2532396,0.0,0,1.7019943,0.0,0.79922825,45.372513,1.6952537,486.49634,-9.203907
6410,6410,212.8183,7.9565315,8.2791586,0.0,0,1.6860089,0.0,0.80246162,45.367447,1.6790563,485.77277,-9.2042646
6421,6421,212.8205,7.9742513,8.2892904,0.0,0,1.6700239,0.0,0.80455166,45.409954,1.6608032,485.66763,-9.2048626
6432,6432,212.8227,8.0207386,8.3088093,0.0,0,1.6540385,0.0,0.80698359,45.537785,1.6441377,485.56247,-9.2047958
6443,6443,212.8249,8.0589714,8.3228865,0.0,0,1.6380534,0.0,0.80925447,45.621578,1.6266021,485.45734,-9.203311
6454,6454,212.8271,8.0720425,8.3457603,0.0,0,1.6220682,0.0,0.81260586,45.589752,1.6105529,485.35217,-9.2033501
6465,6465,212.8293,8.0502691,8.3542862,0.0,0,1.6060829,0.0,0.81402326,45.432182,1.5965974,485.49167,-9.2054462
6476,6476,212.8315,8.0233412,8.3719053,0.0,0,1.5900977,0.0,0.81672239,45.160259,1.5813283,485.80054,-9.2064219
6487,6487,212.8337,8.0234785,8.3821936,0.0,0,1.5741127,0.0,0.81817698,45.090736,1.567537,486.10938,-9.2061892
6498,6498,212.8359,8.0484457,8.4051933,0.0,0,1.5585742,0.0,0.82176465,45.025967,1.551291,486.41824,-9.2047081
6509,6509,212.8381,8.1025047,8.4154272,0.0,0,1.5433679,0.0,0.82312161,45.297901,1.5356604,486.73694,-9.2048969
6520,6520,212.8403,8.1516609,8.4319038,0.0,0,1.5281615,0.0,0.82583785,45.375847,1.5170902,487.26245,-9.2043638
6531,6531,212.8425,8.1514769,8.4432774,0.0,0,1.5129551,0.0,0.82739532,45.394123,1.509446,487.78799,-9.2050638
6542,6542,212.8447,8.1812229,8.4647045,0.0,0,1.4977487,0.0,0.83097965,45.356453,1.4930048,488.31351,-9.2057161
6553,6553,212.8469,8.2399778,8.4759579,0.0,0,1.4825423,0.0,0.83220857,45.635487,1.4775091,488.83905,-9.2050505
6564,6564,212.8491,8.2658186,8.4917574,0.0,0,1.4673359,0.0,0.83515161,45.678673,1.4592681,489.87012,-9.2042923
6575,6575,212.8513,8.2749348,8.5055399,0.0,0,1.4521295,0.0,0.83678687,45.675411,1.4441543,491.40674,-9.2045927
6586,6586,212.8535,8.3170891,8.5255213,0.0,0,1.4369231,0.0,0.84052068,45.69112,1.4268124,492.94339,-9.2040997
6597,6597,212.8557,8.3463774,8.537096,0.0,0,1.4217167,0.0,0.84159505,45.766792,1.4132156,494.48001,-9.2048845
6608,6608,212.8579,8.3862219,8.5533438,0.0,0,1.4065104,0.0,0.84475285,45.866692,1.3979884,496.01663,-9.2045155
6619,6619,212.8601,8.4443102,8.5685263,0.0,0,1.3913039,0.0,0.84648049,46.092533,1.3829824,497.26477,-9.2055178
6630,6630,212.8623,8.4498291,8.5866375,0.0,0,1.3760974,0.0,0.85015523,46.015888,1.3666089,498.49915,-9.205431
6641,6641,212.8645,8.4532585,8.5989161,0.0,0,1.3608911,0.0,0.85107201,45.929222,1.350067,499.73355,-9.2043114
6652,6652,212.8667,8.4431,8.6123362,0.0,0,1.3456846,0.0,0.85410154,45.773251,1.338913,500.96796,-9.2050467
6663,6663,212.8689,8.4684048,8.6283636,0.0,0,1.3304783,0.0,0.85564572,45.843807,1.3227384,501.79675,-9.2041197
6674,6674,212.8711,8.5305948,8.6462355,0.0,0,1.315272,0.0,0.85969377,46.000858,1.3088021,502.03967,-9.2044849
6685,6685,212.8733,8.5839338,8.6609287,0.0,0,1.3000655,0.0,0.8605544,46.214001,1.2924397,502.28262,-9.2040682
6696,6696,212.8755,8.6316795,8.6720276,0.0,0,1.2848592,0.0,0.86358303,46.317646,1.2785066,502.52557,-9.2039909
6707,6707,212.8777,8.6667147,8.6896038,0.0,0,1.2696528,0.0,0.86512351,46.436634,1.263522,502.76849,-9.2040529
6718,6718,212.8799,8.7331247,8.7045393,0.0,0,1.2544463,0.0,0.86890495,46.668797,1.249005,503.02844,-9.2051191
6729,6729,212.8821,8.7793646,8.7217274,0.0,0,1.2392399,0.0,0.87012953,46.817081,1.2317574,503.29105,-9.2047043
6740,6740,212.8843,8.8207903,8.7342939,0.0,0,1.2240335,0.0,0.87368226,46.869537,1.2142743,503.55365,-9.2045174
6751,6751,212.8865,8.801074,8.7527142,0.0,0,1.2094566,0.0,0.87509555,46.773037,1.1978906,503.81628,-9.2053823
6762,6762,212.8887,8.7934856,8.7695551,0.0,0,1.1949937,0.0,0.87948209,46.471195,1.1815144,504.06216,-9.2049198
6773,6773,212.8909,8.8039923,8.7866411,0.0,0,1.180531,0.0,0.88047051,46.465462,1.1686233,504.27225,-9.2063351
6784,6784,212.8931,8.8473959,8.7968245,0.0,0,1.1660681,0.0,0.8837238,46.530155,1.1543313,504.48233,-9.2048979
6795,6795,212.8953,8.8721285,8.8135509,0.0,0,1.1516054,0.0,0.88471758,46.634174,1.1396834,504.69241,-9.2036028
6806,6806,212.8975,8.8994694,8.8259869,0.0,0,1.1371425,0.0,0.88864732,46.583385,1.1228402,504.90247,-9.2056942
6817,6817,212.8997,8.8890076,8.8442068,0.0,0,1.1226798,0.0,0.88979465,46.485069,1.1130242,504.95023,-9.2064552
6828,6828,212.9019,8.9022055,8.8532257,0.0,0,1.1082169,0.0,0.89308262,46.419991,1.0996479,504.95023,-9.2063646
6839,6839,212.9041,8.9049778,8.8706341,0.0,0,1.0937542,0.0,0.89401793,46.380447,1.0822589,504.95023,-9.2056656
6850,6850,212.9063,8.9014349,8.8793678,0.0,0,1.0792915,0.0,0.89754874,46.244736,1.0690703,504.95023,-9.2051468
6861,6861,212.9085,8.9337664,8.8993883,0.0,0,1.0648285,0.0,0.8985092,46.333004,1.0544373,504.92337,-9.203949
6872,6872,212.9107,8.9821739,8.9059572,0.0,0,1.0503657,0.0,0.90167195,46.386768,1.0418714,504.80521,-9.2042036
6883,6883,212.9129,9.0390463,8.9253922,0.0,0,1.035903,0.0,0.90288854,46.651196,1.0278203,504.68704,-9.2042418
6894,6894,212.9151,9.0835562,8.936305,0.0,0,1.0214401,0.0,0.90664691,46.703949,1.0138934,504.56891,-9.2049179
6905,6905,212.9173,9.1284895,8.9554291,0.0,0,1.0069773,0.0,0.90767926,46.867115,0.99963212,504.45074,-9.2047215
6916,6916,212.9195,9.1716089,8.9610167,0.0,0,0.99251461,0.0,0.91072917,46.951122,0.98427624,504.30573,-9.2054396
6927,6927,212.9217,9.1994553,8.9811602,0.0,0,0.97805184,0.0,0.91222036,47.086678,0.97236109,504.14816,-9.2049885
6938,6938,212.9239,9.237916,8.9925041,0.0,0,0.96358895,0.0,0.91608304,47.052044,0.95974702,503.9906,-9.2049408
6949,6949,212.9261,9.2890673,9.0143099,0.0,0,0.94912618,0.0,0.91739511,47.296722,0.94514483,503.83304,-9.2034912
6960,6960,212.9283,9.3537025,9.0198851,0.0,0,0.9346633,0.0,0.92049211,47.466557,0.92580497,503.70053,-9.2038622
6971,6971,212.9305,9.3709383,9.0401726,0.0,0,0.92020065,0.0,0.92204642,47.467663,0.91143024,503.72681,-9.2035055
6982,6982,212.9327,9.4202776,9.0515528,0.0,0,0.90573776,0.0,0.92595172,47.514256,0.89661705,503.75308,-9.2047701
6993,6993,212.9349,9.4584913,9.072752,0.0,0,0.89135975,0.0,0.92725968,47.624184,0.88192451,503.77933,-9.2047415
7004,7004,212.9371,9.4871712,9.0774097,0.0,0,0.87760508,0.0,0.93029523,47.642185,0.86880273,503.8056,-9.2038689
7015,7015,212.9393,9.4954386,9.0975046,0.0,0,0.86385065,0.0,0.93197358,47.619316,0.8523699,503.86292,-9.2040195
7026,7026,212.9415,9.496604,9.1072607,0.0,0,0.85009629,0.0,0.93533504,47.431633,0.83800846,503.94171,-9.2041931
7037,7037,212.9437,9.4629717,9.1322403,0.0,0,0.83634186,0.0,0.93718511,47.226009,0.82357931,504.02051,-9.2034149
7048,7048,212.9459,9.4847231,9.1305819,0.0,0,0.82258749,0.0,0.93928784,47.175983,0.81365603,504.09927,-9.2044134
7059,7059,212.9481,9.5044088,9.153553,0.0,0,0.80883306,0.0,0.94151628,47.195244,0.80127633,504.15451,-9.2043047
7070,7070,212.9503,9.5673532,9.1604099,0.0,0,0.79507869,0.0,0.94438899,47.338184,0.78431898,503.71457,-9.2047901
7081,7081,212.9525,9.6381168,9.1827641,0.0,0,0.78132427,0.0,0.9459849,47.620808,0.76816684,503.27466,-9.2045727
7092,7092,212.9547,9.6672621,9.184968,0.0,0,0.76756984,0.0,0.94850266,47.655277,0.75741583,502.83475,-9.205162
7103,7103,212.9569,9.6724205,9.2048941,0.0,0,0.75381547,0.0,0.95036805,47.665211,0.7452774,502.39484,-9.2060213
7114,7114,212.9591,9.7116518,9.2128506,0.0,0,0.7400611,0.0,0.95340407,47.680843,0.73269439,501.7612,-9.2048197
7125,7125,212.9613,9.7412348,9.2380333,0.0,0,0.72630668,0.0,0.95563257,47.728916,0.72101718,500.9339,-9.2036762
7136,7136,212.9635,9.7860641,9.2415924,0.0,0,0.71255225,0.0,0.95799613,47.807457,0.7045818,500.1066,-9.2043276
7147,7147,212.9657,9.8541765,9.2595816,0.0,0,0.69879782,0.0,0.95970261,48.03064,0.69390607,499.2793,-9.2046499
7158,7158,212.9679,9.9349718,9.2660828,0.0,0,0.68504345,0.0,0.9626025,48.278194,0.67970818,498.452,-9.2040625
7169,7169,212.9701,10.004598,9.2927713,0.0,0,0.67128909,0.0,0.96551615,48.445255,0.66439867,497.90045,-9.205409
7180,7180,212.9723,10.050081,9.2993717,0.0,0,0.65753466,0.0,0.96807706,48.600201,0.65120482,497.36206,-9.2058897
7191,7191,212.9745,10.080416,9.3165913,0.0,0,0.64378029,0.0,0.96990407,48.63818,0.63608325,496.82367,-9.2042294
7202,7202,212.9767,10.082547,9.3241138,0.0,0,0.63002586,0.0,0.97241288,48.555405,0.62022316,496.28525,-9.204361
7213,7213,212.9789,10.079497,9.3486567,0.0,0,0.6162715,0.0,0.97542077,48.404404,0.60638463,496.00201,-9.2048759
7224,7224,212.9811,10.07042,9.3531981,0.0,0,0.60251707,0.0,0.97747207,48.277775,0.59347117,496.08737,-9.206275
7235,7235,212.9833,10.097925,9.3710852,0.0,0,0.5887627,0.0,0.97958517,48.25238,0.5817548,496.17273,-9.2052479
7246,7246,212.9855,10.170592,9.3774815,0.0,0,0.57526875,0.0,0.98169327,48.507107,0.56513005,496.25809,-9.2047825
7257,7257,212.9877,10.249575,9.4028473,0.0,0,0.56217867,0.0,0.98515302,48.741276,0.55506498,496.34348,-9.2042732
7268,7268,212.9899,10.284795,9.4078579,0.0,0,0.54908878,0.0,0.98708177,48.781788,0.5400002,496.70099,-9.2053623
7279,7279,212.9921,10.277012,9.4245501,0.0,0,0.53599876,0.0,0.98933363,48.665508,0.52723855,497.10153,-9.2062483
7290,7290,212.9943,10.266822,9.4310398,0.0,0,0.52290875,0.0,0.99113941,48.484127,0.51394904,497.50204,-9.2049999
7301,7301,212.9965,10.284547,9.4537096,0.0,0,0.50981867,0.0,0.99451685,48.406487,0.5005095,497.90256,-9.2048712
7312,7312,212.9987,10.277312,9.4573565,0.0,0,0.49672872,0.0,0.99574405,48.352833,0.48986703,498.23621,-9.2044058
7323,7323,213.0009,10.31053,9.4736662,0.0,0,0.4836387,0.0,0.99847305,48.355751,0.47845313,498.42664,-9.2048063
7334,7334,213.0031,10.351651,9.4795504,0.0,0,0.47054869,0.0,0.99978191,48.485207,0.46552026,498.61703,-9.2048817
7345,7345,213.0053,10.470447,9.5020237,0.0,0,0.4574587,0.0,1.0033412,48.873787,0.44982943,498.80746,-9.2048903
7356,7356,213.0075,10.56651,9.5086594,0.0,0,0.44436872,0.0,1.0050831,49.221336,0.43697324,498.99786,-9.2042418
7367,7367,213.0097,10.623751,9.524188,0.0,0,0.43127871,0.0,1.0077319,49.380356,0.42496645,499.13248,-9.2044573
7375,7375,213.0113,10.629527,9.528038,0.0,0,0.42175868,0.0,1.0085579,49.346298,0.41266322,499.21841,-9.2041016