File: clean data/testID_0211.csv
level_0,index,Time(sec),Force(kN),Jaw(mm),PowAngle(deg),Power(W),Pram,PTemp,Strain,Stress(MPa),Stroke(mm),TC1(C),wedge(mm)
2104,2104,178.6791,0.98852962,0.010924893,0.0,0,9.0922346,0.0,0.00050894293,12.023601,10.151217,405.80988,-9.2671289
2106,2106,178.6795,3.3546772,0.04427065,0.0,0,9.0337067,0.0,0.002629095,38.493298,10.08127,406.36072,-9.2662086
2108,2108,178.6799,5.0713634,0.089952856,0.0,0,8.9751787,0.0,0.0058961245,63.247936,10.028522,406.91156,-9.2648211
2110,2110,178.6803,5.4546065,0.15301339,0.0,0,8.9166508,0.0,0.0093735307,68.211281,9.9544411,407.4624,-9.262145
2112,2112,178.6807,5.4286189,0.29491696,0.0,0,8.8581219,0.0,0.019069897,68.275337,9.8730946,408.01324,-9.262702
2114,2114,178.6811,5.4678512,0.39808971,0.0,0,8.7995939,0.0,0.026374226,67.182297,9.7663994,408.56409,-9.2642632
2116,2116,178.6815,5.6420465,0.51220435,0.0,0,8.7416534,0.0,0.033743814,69.63192,9.6563883,409.1149,-9.2648335
2118,2118,178.6819,5.9701328,0.59167719,0.0,0,8.6858492,0.0,0.040193025,72.297165,9.5563765,409.66574,-9.262949
2120,2120,178.6823,5.7617087,0.63301021,0.0,0,8.6301851,0.0,0.042564113,71.291626,9.4714136,410.21658,-9.2624359
2122,2122,178.6827,5.647738,0.71194977,0.0,0,8.574522,0.0,0.048008226,67.779091,9.4007235,410.76743,-9.2626867
2124,2124,178.6831,6.1156816,0.74629807,0.0,0,8.518857,0.0,0.051075991,73.812988,9.3328762,411.31827,-9.2633724
2126,2126,178.6835,6.239193,0.82492739,0.0,0,8.4631929,0.0,0.055572346,74.774078,9.2661715,411.86911,-9.2635937
2128,2128,178.6839,6.2107191,0.9305768,0.0,0,8.4075298,0.0,0.063404545,74.705185,9.1855469,412.41995,-9.2627888
2130,2130,178.6843,5.9477925,1.0147281,0.0,0,8.3518648,0.0,0.069596067,70.44529,9.1014624,412.97079,-9.2630548
2132,2132,178.6847,6.2166982,1.1141694,0.0,0,8.2962017,0.0,0.076159284,73.401642,9.01262,413.52164,-9.2628918
2134,2134,178.6851,6.0546403,1.1623576,0.0,0,8.2405376,0.0,0.080633,71.051643,8.9339113,414.07248,-9.2629948
2136,2136,178.6855,6.3000722,1.2073283,0.0,0,8.1848736,0.0,0.083444349,73.703598,8.8638077,414.89084,-9.2631207
2138,2138,178.6859,6.0216231,1.2768552,0.0,0,8.1292095,0.0,0.088299751,70.453606,8.8077221,415.7092,-9.2626734
2140,2140,178.6863,6.4715567,1.3110479,0.0,0,8.0735455,0.0,0.091482468,74.485107,8.7490778,416.52753,-9.2623606
2142,2142,178.6867,6.4822445,1.3892367,0.0,0,8.0196619,0.0,0.096372679,75.30587,8.6833286,417.34589,-9.2626114
2144,2144,178.6871,6.4436998,1.4773141,0.0,0,7.9666953,0.0,0.10306786,73.865074,8.6182165,418.16425,-9.2637787
2146,2146,178.6875,6.3597217,1.5445368,0.0,0,7.9137359,0.0,0.10827368,72.889359,8.5471401,418.9826,-9.2630234
2148,2148,178.6879,6.3616982,1.6191143,0.0,0,7.8607755,0.0,0.11356598,72.079735,8.475316,419.80093,-9.2631474
2150,2150,178.6883,6.4935727,1.6601704,0.0,0,7.8078156,0.0,0.11719967,73.622444,8.4085474,420.61929,-9.262126
2152,2152,178.6887,6.4057951,1.7118988,0.0,0,7.7548552,0.0,0.12077326,72.303993,8.3518095,421.43765,-9.2620964
2154,2154,178.6891,6.4159513,1.7663087,0.0,0,7.7018952,0.0,0.12473828,72.154205,8.2981234,422.25601,-9.2628756
2156,2156,178.6895,6.5275836,1.8047848,0.0,0,7.6489348,0.0,0.12812409,72.788963,8.2443542,423.07434,-9.2641602
2158,2158,178.6899,6.7128849,1.870062,0.0,0,7.5959754,0.0,0.13247383,74.967636,8.1930914,423.8927,-9.2643776
2160,2160,178.6903,6.6006155,1.9304783,0.0,0,7.543015,0.0,0.13719748,73.307343,8.1334047,424.71106,-9.2636509
2162,2162,178.6907,6.6247892,1.9888651,0.0,0,7.4900556,0.0,0.14211987,73.221252,8.0746679,425.52942,-9.2627192
2164,2164,178.6911,6.5027461,2.0489807,0.0,0,7.4370952,0.0,0.14626034,71.548859,8.0162697,426.34775,-9.2625084
2166,2166,178.6915,6.6987572,2.0834467,0.0,0,7.3846664,0.0,0.14924495,73.266708,7.9652858,427.16611,-9.2629919
2168,2168,178.6919,6.63486,2.1343622,0.0,0,7.3341722,0.0,0.153249,72.717194,7.911932,427.98447,-9.263032
2170,2170,178.6923,6.6627941,2.1872973,0.0,0,7.2838039,0.0,0.15682504,72.471115,7.86766,428.80283,-9.2627115
2172,2172,178.6927,6.7027707,2.2252612,0.0,0,7.2334356,0.0,0.1603788,72.69976,7.818716,429.62119,-9.2642527
2174,2174,178.6931,6.8045468,2.2793653,0.0,0,7.1830673,0.0,0.16441797,73.343353,7.7714825,430.43951,-9.2641878
2176,2176,178.6935,6.7983093,2.3356123,0.0,0,7.1326995,0.0,0.16840231,73.393478,7.7227244,431.25787,-9.2636051
2178,2178,178.6939,6.7698898,2.3846319,0.0,0,7.0823312,0.0,0.17298594,72.52124,7.669241,432.07623,-9.2627058
2180,2180,178.6943,6.7989173,2.4291959,0.0,0,7.0319633,0.0,0.17622255,72.628937,7.6154232,432.89459,-9.2623129
2182,2182,178.6947,6.8269625,2.4766879,0.0,0,6.981595,0.0,0.17990097,72.61911,7.5710769,433.71292,-9.2627287
2184,2184,178.6951,6.837944,2.5200133,0.0,0,6.9312277,0.0,0.18386582,72.533363,7.5229154,434.53125,-9.2634296
2186,2186,178.6955,6.8219743,2.5633359,0.0,0,6.8808594,0.0,0.18680722,71.905708,7.4773808,434.6824,-9.2636051
2188,2188,178.6959,6.9364901,2.6112278,0.0,0,6.830492,0.0,0.19097921,73.007942,7.4334021,434.83356,-9.2636871
2190,2190,178.6963,6.9489665,2.6534181,0.0,0,6.7801232,0.0,0.19448075,72.842514,7.3879495,434.98471,-9.2624264
2192,2192,178.6967,6.9590921,2.7018082,0.0,0,6.7313671,0.0,0.19798291,72.767632,7.3369918,435.13583,-9.2625732
2194,2194,178.6971,6.9098873,2.7525766,0.0,0,6.6834416,0.0,0.20268539,71.798187,7.2947598,435.28699,-9.2631588
2196,2196,178.6975,7.0021086,2.7917922,0.0,0,6.6355219,0.0,0.20555571,72.426262,7.2475448,435.43814,-9.2627325
2198,2198,178.6979,7.0583034,2.8374,0.0,0,6.5876017,0.0,0.20912445,72.850586,7.2014899,435.58929,-9.2622881
2200,2200,178.6983,7.0603967,2.8809345,0.0,0,6.5396819,0.0,0.21333118,72.547859,7.1523485,435.74045,-9.2634649
2202,2202,178.6987,7.0669746,2.9274297,0.0,0,6.4917622,0.0,0.21647736,72.385796,7.1084809,435.89157,-9.2637587
2204,2204,178.6991,7.1172333,2.97595,0.0,0,6.4438419,0.0,0.22071084,72.486969,7.0612836,436.04272,-9.2631168
2206,2206,178.6995,7.1848216,3.0159402,0.0,0,6.3959212,0.0,0.22450402,73.005463,7.0145473,436.19388,-9.2633686
2208,2208,178.6999,7.232101,3.0724308,0.0,0,6.3480015,0.0,0.22830823,73.207993,6.9681754,436.34503,-9.2622347
2210,2210,178.7003,7.1939793,3.1178303,0.0,0,6.3000817,0.0,0.23275881,72.656555,6.9215956,436.49619,-9.2632484
2212,2212,178.7007,7.2153211,3.1597011,0.0,0,6.252162,0.0,0.23625477,72.575554,6.8752961,436.64731,-9.2635918
2214,2214,178.7011,7.273972,3.2160063,0.0,0,6.2042422,0.0,0.24038938,72.767563,6.8293338,436.79846,-9.2630701
2216,2216,178.7015,7.3174667,3.2518055,0.0,0,6.1568027,0.0,0.24439287,72.871986,6.7767348,436.94962,-9.2638397
2218,2218,178.7019,7.3522949,3.2989066,0.0,0,6.1111121,0.0,0.24778517,73.041473,6.7285843,437.10077,-9.2629137
2220,2220,178.7023,7.3694057,3.3562248,0.0,0,6.065536,0.0,0.25257784,72.884254,6.6857262,437.25192,-9.2627039
2222,2222,178.7027,7.4014297,3.3933284,0.0,0,6.0199599,0.0,0.25642973,72.937263,6.6379037,437.40305,-9.2633905
2224,2224,178.7031,7.4331717,3.4468718,0.0,0,5.9743834,0.0,0.26030815,72.971657,6.5901628,437.5542,-9.2634192
2226,2226,178.7035,7.4715548,3.4980385,0.0,0,5.9288077,0.0,0.26516607,72.94313,6.5406322,437.70535,-9.2632856
2228,2228,178.7039,7.504683,3.5395482,0.0,0,5.8832321,0.0,0.26895577,73.003799,6.4925971,437.85651,-9.2639551
2230,2230,178.7043,7.5287709,3.5936832,0.0,0,5.8376555,0.0,0.27313632,72.934738,6.4411855,438.00766,-9.2636557
2232,2232,178.7047,7.5510511,3.6382084,0.0,0,5.792079,0.0,0.27780235,72.862038,6.392745,438.15878,-9.2620611
2234,2234,178.7051,7.5731444,3.6849275,0.0,0,5.7465038,0.0,0.28147486,72.743431,6.3476458,438.30994,-9.2635622
2236,2236,178.7055,7.6343389,3.7334409,0.0,0,5.7009277,0.0,0.28554532,72.998253,6.2977886,438.37949,-9.2639618
2238,2238,178.7059,7.6893153,3.7790909,0.0,0,5.6553516,0.0,0.29032329,73.237991,6.247643,438.44901,-9.2635374
2240,2240,178.7063,7.6970873,3.8317146,0.0,0,5.6097755,0.0,0.2942965,73.041679,6.2045193,438.51855,-9.2618141
2242,2242,178.7067,7.7194824,3.8792808,0.0,0,5.5656581,0.0,0.29874524,72.897797,6.153729,438.58807,-9.2630892
2244,2244,178.7071,7.7442307,3.9237661,0.0,0,5.5222936,0.0,0.30322334,72.807838,6.1076546,438.65759,-9.2635508
2246,2246,178.7075,7.7972922,3.9764915,0.0,0,5.4789333,0.0,0.30721807,72.928154,6.0574975,438.72714,-9.2634468
2248,2248,178.7079,7.8558259,4.0186505,0.0,0,5.4355736,0.0,0.31160009,73.180283,6.0086946,438.79666,-9.2624378
2250,2250,178.7083,7.8609891,4.0652356,0.0,0,5.3922133,0.0,0.31583312,73.044991,5.9631438,438.86621,-9.2625198
2252,2252,178.7087,7.8729863,4.1210928,0.0,0,5.3488536,0.0,0.32016733,72.776581,5.9137964,438.93573,-9.2634392
2254,2254,178.7091,7.9204736,4.1643887,0.0,0,5.3054934,0.0,0.32501155,72.839966,5.8685098,439.00528,-9.2635183
2256,2256,178.7095,7.9700394,4.2113543,0.0,0,5.2621331,0.0,0.32898775,72.980225,5.8189487,439.0748,-9.2636271
2258,2258,178.7099,8.0102844,4.2615533,0.0,0,5.2187734,0.0,0.33346066,73.023216,5.7736931,439.14435,-9.2631083
2260,2260,178.7103,8.0203609,4.3010473,0.0,0,5.1754136,0.0,0.33791977,72.884956,5.7249374,439.21387,-9.2618742
2262,2262,178.7107,8.0364923,4.3497481,0.0,0,5.1320534,0.0,0.34172291,72.65033,5.6764569,439.28342,-9.2621641
2264,2264,178.7111,8.0921402,4.4031281,0.0,0,5.0886931,0.0,0.34690595,72.763947,5.6288066,439.35294,-9.2627831
2266,2266,178.7115,8.1532888,4.4450564,0.0,0,5.0457683,0.0,0.35134143,73.022186,5.5809302,439.42249,-9.2633238
2268,2268,178.7119,8.1760321,4.4950991,0.0,0,5.0044241,0.0,0.35539752,73.029465,5.5323911,439.492,-9.2638607
2270,2270,178.7123,8.1897449,4.543735,0.0,0,4.9631839,0.0,0.36071837,72.637772,5.4873943,439.56155,-9.2619562
2272,2272,178.7127,8.2105093,4.5847678,0.0,0,4.9219441,0.0,0.36448374,72.557014,5.4416065,439.63107,-9.2617722
2274,2274,178.7131,8.2638626,4.6329875,0.0,0,4.8807039,0.0,0.36858854,72.683174,5.3933296,439.70062,-9.261487
2276,2276,178.7135,8.3095989,4.6758666,0.0,0,4.8394642,0.0,0.37375107,72.716537,5.348609,439.77014,-9.2627497
2278,2278,178.7139,8.3423586,4.7223783,0.0,0,4.798224,0.0,0.377489,72.768707,5.3008766,439.83969,-9.2634468
2280,2280,178.7143,8.3555279,4.7729778,0.0,0,4.7569842,0.0,0.38230705,72.567741,5.2546272,439.90921,-9.2631731
2282,2282,178.7147,8.3783255,4.8154993,0.0,0,4.715744,0.0,0.3872534,72.384407,5.2090745,439.97876,-9.2619123
2284,2284,178.7151,8.4319124,4.8664889,0.0,0,4.6745043,0.0,0.39130116,72.512718,5.1640649,440.04831,-9.2617111
2286,2286,178.7155,8.4875154,4.9092832,0.0,0,4.6332641,0.0,0.39602232,72.645027,5.117341,440.4809,-9.2619686
2288,2288,178.7159,8.5103931,4.9483867,0.0,0,4.5920238,0.0,0.40024489,72.645081,5.0748553,440.91351,-9.2628984
2290,2290,178.7163,8.5179243,5.0005774,0.0,0,4.5507841,0.0,0.40446615,72.354446,5.0277662,441.34613,-9.2636003
2292,2292,178.7167,8.542491,5.0394468,0.0,0,4.5108657,0.0,0.40925241,72.231766,4.9847379,441.77875,-9.2621574
2294,2294,178.7171,8.5834808,5.0837359,0.0,0,4.4716296,0.0,0.41333705,72.248207,4.9444046,442.21136,-9.261797
2296,2296,178.7175,8.6459904,5.1375375,0.0,0,4.4323978,0.0,0.41834375,72.393089,4.8957281,442.64398,-9.2617216
2298,2298,178.7179,8.6607285,5.1730967,0.0,0,4.3931656,0.0,0.42295879,72.234985,4.8538871,443.07657,-9.2619619
2300,2300,178.7183,8.6733122,5.2176595,0.0,0,4.3539338,0.0,0.42684799,72.026703,4.8076859,443.50919,-9.262289
2302,2302,178.7187,8.7101336,5.2660871,0.0,0,4.314702,0.0,0.43184072,71.93058,4.7648993,443.9418,-9.2631731
2304,2304,178.7191,8.772398,5.3005576,0.0,0,4.2754698,0.0,0.43595254,72.239937,4.7233133,444.37442,-9.262043
2306,2306,178.7195,8.8158951,5.3483548,0.0,0,4.2362375,0.0,0.44004819,72.320168,4.6809912,444.80704,-9.261775
2308,2308,178.7199,8.8320332,5.3950281,0.0,0,4.1970053,0.0,0.44553241,72.045242,4.63585,445.23965,-9.2618055
2310,2310,178.7203,8.8473587,5.4324937,0.0,0,4.1577735,0.0,0.44950286,71.843666,4.5948601,445.67224,-9.2618208
2312,2312,178.7207,8.8910999,5.4766297,0.0,0,4.1185417,0.0,0.45347983,71.891891,4.5507336,446.10486,-9.2613926
2314,2314,178.7211,8.9354696,5.5155768,0.0,0,4.0793095,0.0,0.45847121,71.918457,4.5061069,446.53748,-9.2620459
2316,2316,178.7215,8.9774017,5.5578489,0.0,0,4.0404716,0.0,0.46230388,71.929962,4.4676361,446.97009,-9.2633963
2318,2318,178.7219,8.9998646,5.6020737,0.0,0,4.0030656,0.0,0.46670249,71.844383,4.4275289,447.40271,-9.2623358
2320,2320,178.7223,9.0259018,5.6387086,0.0,0,3.9657533,0.0,0.47155988,71.701004,4.3807878,447.83533,-9.2621269
2322,2322,178.7227,9.0621252,5.6841516,0.0,0,3.9284413,0.0,0.47546566,71.694824,4.3399782,448.26794,-9.2616014
2324,2324,178.7231,9.112669,5.7224779,0.0,0,3.8911293,0.0,0.47996259,71.724289,4.3021574,448.70053,-9.2621031
2326,2326,178.7235,9.1627235,5.7584066,0.0,0,3.8538175,0.0,0.48443305,71.736435,4.2626586,449.13315,-9.2621241
2328,2328,178.7239,9.1910048,5.807138,0.0,0,3.8165054,0.0,0.48848975,71.754967,4.2223263,449.56577,-9.2626076
2330,2330,178.7243,9.2040358,5.8387413,0.0,0,3.7791932,0.0,0.49303514,71.520859,4.1821718,449.99838,-9.2625523
2332,2332,178.7247,9.2387857,5.8753872,0.0,0,3.7418811,0.0,0.49677491,71.506561,4.1404953,450.431,-9.2625542
2334,2334,178.7251,9.2868252,5.9243069,0.0,0,3.7045693,0.0,0.50135809,71.55722,4.1028738,450.86359,-9.2607574
2336,2336,178.7255,9.3395548,5.9556527,0.0,0,3.6672573,0.0,0.50611937,71.647377,4.0620561,451.17377,-9.2622633
2338,2338,178.7259,9.3683672,5.9962482,0.0,0,3.6299453,0.0,0.5097608,71.634773,4.0250211,451.48392,-9.2630901
2340,2340,178.7263,9.389945,6.042532,0.0,0,3.5926332,0.0,0.51474935,71.442307,3.9863276,451.7941,-9.2625952
2342,2342,178.7267,9.4254522,6.0717454,0.0,0,3.5565166,0.0,0.51904196,71.499008,3.9481859,452.10425,-9.2618923
2344,2344,178.7271,9.4910641,6.1121063,0.0,0,3.5210168,0.0,0.52243489,71.669113,3.9127061,452.41443,-9.2619247
2346,2346,178.7275,9.5335131,6.1527681,0.0,0,3.4855206,0.0,0.52764571,71.618874,3.8741915,452.72458,-9.2616539
2348,2348,178.7279,9.5554199,6.1839318,0.0,0,3.4500248,0.0,0.53132057,71.46077,3.8387613,453.03473,-9.2620173
2350,2350,178.7283,9.5831356,6.226932,0.0,0,3.4145288,0.0,0.53539705,71.429947,3.8011177,453.34491,-9.2616463
2352,2352,178.7287,9.6177502,6.2645717,0.0,0,3.3790326,0.0,0.54070431,71.251877,3.7632174,453.65506,-9.262063
2354,2354,178.7291,9.6844206,6.2989106,0.0,0,3.3435369,0.0,0.54421562,71.546234,3.7227857,453.96524,-9.2608013
2356,2356,178.7295,9.7370939,6.338625,0.0,0,3.3080409,0.0,0.54838449,71.559624,3.6902137,454.27539,-9.2612104
2358,2358,178.7299,9.7654448,6.3691168,0.0,0,3.2725446,0.0,0.55307502,71.448982,3.6504567,454.58557,-9.2618761
2360,2360,178.7303,9.774682,6.4074326,0.0,0,3.2370486,0.0,0.55637664,71.380783,3.6123509,454.89572,-9.262105
2362,2362,178.7307,9.8250895,6.4445062,0.0,0,3.2015526,0.0,0.56102365,71.336967,3.5765605,455.2059,-9.2618828
2364,2364,178.7311,9.8967781,6.4761386,0.0,0,3.1660566,0.0,0.56550908,71.498695,3.5414972,455.51605,-9.2611055
2366,2366,178.7315,9.9567099,6.5206275,0.0,0,3.1309152,0.0,0.56920934,71.698753,3.5066531,455.8262,-9.2609262
2368,2368,178.7319,9.9699087,6.5536199,0.0,0,3.0970623,0.0,0.57413894,71.54348,3.472348,456.13638,-9.2617149
2370,2370,178.7323,9.9926062,6.5864406,0.0,0,3.0632944,0.0,0.57808143,71.335007,3.4349532,456.44653,-9.2626734
2372,2372,178.7327,10.066132,6.6293821,0.0,0,3.0295265,0.0,0.5821501,71.520996,3.3998573,456.75671,-9.2608595
2374,2374,178.7331,10.144506,6.6558609,0.0,0,2.9957583,0.0,0.5866546,71.781685,3.3647344,457.06686,-9.2604876
2376,2376,178.7335,10.197954,6.6911049,0.0,0,2.9619906,0.0,0.59007043,71.919205,3.327316,457.37704,-9.2609138
2378,2378,178.7339,10.219203,6.7360134,0.0,0,2.9282222,0.0,0.59517759,71.73056,3.2918799,457.68719,-9.2610998
2380,2380,178.7343,10.257474,6.7654886,0.0,0,2.8944542,0.0,0.59994823,71.655273,3.2569256,457.99738,-9.2617455
2382,2382,178.7347,10.327959,6.8042936,0.0,0,2.8606863,0.0,0.60347289,71.860947,3.2214482,458.30753,-9.2617283
2384,2384,178.7351,10.417934,6.8433332,0.0,0,2.8269184,0.0,0.60873967,72.105957,3.1862464,458.61765,-9.2607355
2386,2386,178.7355,10.466255,6.8711743,0.0,0,2.7931502,0.0,0.61265123,72.189194,3.1491826,458.11786,-9.260417
2388,2388,178.7359,10.487856,6.9121966,0.0,0,2.7593822,0.0,0.61657047,72.017784,3.1164484,457.61807,-9.261797
2390,2390,178.7363,10.527164,6.9483848,0.0,0,2.7256143,0.0,0.6222108,71.929794,3.0784564,457.11829,-9.2620373
2392,2392,178.7367,10.590543,6.9802618,0.0,0,2.6929309,0.0,0.62582278,72.094215,3.0437148,456.6185,-9.2613297
2394,2394,178.7371,10.659083,7.0203285,0.0,0,2.6608074,0.0,0.63018024,72.266853,3.0111897,456.11871,-9.2608156
2396,2396,178.7375,10.710066,7.0513105,0.0,0,2.6286874,0.0,0.63531345,72.251472,2.9727967,455.61893,-9.2616978
2398,2398,178.7379,10.744175,7.0869579,0.0,0,2.5965672,0.0,0.63890171,72.157295,2.9369671,455.11914,-9.261117
2400,2400,178.7383,10.802765,7.1228886,0.0,0,2.5644474,0.0,0.64347917,72.194786,2.9035761,454.61935,-9.2619915
2402,2402,178.7387,10.883526,7.1521473,0.0,0,2.5323272,0.0,0.64821166,72.420357,2.867744,454.11957,-9.2621365
2404,2404,178.7391,10.962597,7.1946859,0.0,0,2.5002072,0.0,0.65202874,72.664383,2.832593,453.61978,-9.2612009
2406,2406,178.7395,11.006843,7.2272949,0.0,0,2.4680872,0.0,0.65717489,72.609299,2.8026721,453.12,-9.2601452
2408,2408,178.7399,11.044825,7.2585907,0.0,0,2.4359674,0.0,0.66149509,72.531975,2.7650719,452.62021,-9.2606201
2410,2410,178.7403,11.096906,7.3040476,0.0,0,2.4038472,0.0,0.66591442,72.546562,2.730993,452.12042,-9.2607956
2412,2412,178.7407,11.166493,7.3282919,0.0,0,2.3717272,0.0,0.67078245,72.671707,2.7002957,451.62064,-9.262145
2414,2414,178.7411,11.25255,7.3599343,0.0,0,2.3396072,0.0,0.67414588,72.915352,2.6669245,451.12085,-9.2613192
2416,2416,178.7415,11.303463,7.4024291,0.0,0,2.3078089,0.0,0.67914438,72.89933,2.6267037,450.62106,-9.2605467
2418,2418,178.7419,11.346357,7.4269257,0.0,0,2.2771804,0.0,0.68379653,72.902626,2.5967896,450.12128,-9.2590952
2420,2420,178.7423,11.407402,7.4648614,0.0,0,2.246628,0.0,0.68748021,72.968872,2.563885,449.62149,-9.2589045
2422,2422,178.7427,11.477597,7.5051966,0.0,0,2.2160764,0.0,0.69309282,73.067383,2.5274451,449.1217,-9.2605515
2424,2424,178.7431,11.562286,7.5307317,0.0,0,2.1855242,0.0,0.69751072,73.253258,2.4965477,448.62192,-9.2608337
2426,2426,178.7435,11.629688,7.56987,0.0,0,2.1549723,0.0,0.70135695,73.371964,2.4602797,448.1221,-9.2619209
2428,2428,178.7439,11.673535,7.6033454,0.0,0,2.1244202,0.0,0.70694643,73.257721,2.4270799,447.62231,-9.2611237
2430,2430,178.7443,11.741219,7.630857,0.0,0,2.0938683,0.0,0.71053982,73.415901,2.3940058,447.12253,-9.2604084
2432,2432,178.7447,11.804824,7.6680579,0.0,0,2.0633163,0.0,0.7146458,73.53038,2.3598952,446.62274,-9.2594376
2434,2434,178.7451,11.89813,7.6987796,0.0,0,2.0327644,0.0,0.72034937,73.668076,2.3268535,446.12296,-9.2610188
2436,2436,178.7455,11.961573,7.7337632,0.0,0,2.0022123,0.0,0.7239365,73.802986,2.2941682,445.49136,-9.2598696
2438,2438,178.7459,12.004902,7.7688837,0.0,0,1.9716601,0.0,0.72882587,73.698837,2.2608182,444.85974,-9.2606497
2440,2440,178.7463,12.065496,7.7950368,0.0,0,1.9411081,0.0,0.7336849,73.710114,2.2285435,444.22815,-9.26056
2442,2442,178.7467,12.14879,7.8324175,0.0,0,1.9115355,0.0,0.73728359,73.989471,2.1975343,443.59653,-9.2594271
2444,2444,178.7471,12.238797,7.8619399,0.0,0,1.8824685,0.0,0.74225754,74.130806,2.1655459,442.96494,-9.260129
2446,2446,178.7475,12.290781,7.8903766,0.0,0,1.8534043,0.0,0.74677157,74.129959,2.1341588,442.33334,-9.2601089
2448,2448,178.7479,12.341912,7.9323115,0.0,0,1.8243403,0.0,0.75086188,74.156334,2.1004105,441.70172,-9.2603216
2450,2450,178.7483,12.41289,7.9562755,0.0,0,1.7952764,0.0,0.75589138,74.193146,2.0695205,441.07013,-9.2604952
2452,2452,178.7487,12.50558,7.9844317,0.0,0,1.7662123,0.0,0.7596187,74.439461,2.0392046,440.43851,-9.2604866
2454,2454,178.7491,12.596455,8.0236378,0.0,0,1.7371484,0.0,0.76427424,74.661758,2.0062034,439.80692,-9.2600651
2456,2456,178.7495,12.65811,8.0456533,0.0,0,1.7080843,0.0,0.76916194,74.63147,1.9745742,439.17529,-9.259738
2458,2458,178.7499,12.702814,8.0803413,0.0,0,1.6790204,0.0,0.77286553,74.669937,1.945882,438.5437,-9.2599525
2460,2460,178.7503,12.774739,8.1203871,0.0,0,1.6499563,0.0,0.77847672,74.617981,1.9135497,437.91208,-9.26056
2462,2462,178.7507,12.86729,8.1413889,0.0,0,1.6208923,0.0,0.78295648,74.861107,1.8854672,437.28049,-9.2596054
2464,2464,178.7511,12.957095,8.176652,0.0,0,1.5918283,0.0,0.78654951,75.126282,1.8543342,436.6489,-9.2598257
2466,2466,178.7515,13.017621,8.2085238,0.0,0,1.5630548,0.0,0.79219371,75.040649,1.8217564,436.01727,-9.2590122
2468,2468,178.7519,13.07295,8.2303133,0.0,0,1.5353373,0.0,0.79560155,75.083763,1.7936016,435.38568,-9.2584372
2470,2470,178.7523,13.16156,8.2648487,0.0,0,1.5076892,0.0,0.79952258,75.290016,1.7637551,434.75406,-9.2602196
2472,2472,178.7527,13.275593,8.2939949,0.0,0,1.4800413,0.0,0.80548841,75.474083,1.7319493,434.12247,-9.2598467
2474,2474,178.7531,13.380645,8.3241692,0.0,0,1.4523933,0.0,0.80907971,75.754097,1.7055365,433.49084,-9.2593832
2476,2476,178.7535,13.434046,8.3586216,0.0,0,1.4247453,0.0,0.81380469,75.827385,1.674879,432.85925,-9.259201
2478,2478,178.7539,13.506439,8.3834229,0.0,0,1.3970973,0.0,0.81909746,75.708458,1.646862,432.22763,-9.2598553
2480,2480,178.7543,13.60121,8.4164095,0.0,0,1.3694494,0.0,0.82230973,76.024612,1.6169368,431.59604,-9.2598143
2482,2482,178.7547,13.697365,8.4442377,0.0,0,1.3418013,0.0,0.82716286,76.232841,1.5848733,430.96445,-9.2589827
2484,2484,178.7551,13.796149,8.4685669,0.0,0,1.3141534,0.0,0.8317799,76.444031,1.5572886,430.33286,-9.2590694
2486,2486,178.7555,13.848802,8.5096092,0.0,0,1.2865053,0.0,0.83610916,76.40303,1.5255452,430.24887,-9.2584372
2488,2488,178.7559,13.919272,8.5324631,0.0,0,1.2588574,0.0,0.84129542,76.361862,1.4996308,430.16492,-9.2588568
2490,2490,178.7563,14.019761,8.5563726,0.0,0,1.2312094,0.0,0.84486246,76.638794,1.467778,430.08093,-9.259223
2492,2492,178.7567,14.134665,8.5939741,0.0,0,1.2044513,0.0,0.84919494,76.932991,1.4362962,429.99698,-9.2588625
2494,2494,178.7571,14.229018,8.6118908,0.0,0,1.1781524,0.0,0.85408151,77.041779,1.4101256,429.91299,-9.2597246
2496,2496,178.7575,14.290187,8.6419935,0.0,0,1.1518564,0.0,0.85766315,77.108711,1.3841574,429.82904,-9.2583914
2498,2498,178.7579,14.3673,8.6797514,0.0,0,1.1255604,0.0,0.86298037,77.12188,1.3543345,429.74506,-9.2581263
2500,2500,178.7583,14.466401,8.6983738,0.0,0,1.0992644,0.0,0.86769271,77.273323,1.3251448,429.66107,-9.2589111
2502,2502,178.7587,14.581172,8.7305031,0.0,0,1.0729684,0.0,0.87109095,77.639603,1.2993219,429.57712,-9.2591581
2504,2504,178.7591,14.677675,8.7631512,0.0,0,1.0466723,0.0,0.87715715,77.703339,1.2702448,429.49313,-9.2581091
2506,2506,178.7595,14.745251,8.7811623,0.0,0,1.0203763,0.0,0.88081145,77.801071,1.2422802,429.40918,-9.2586946
2508,2508,178.7599,14.837398,8.8123417,0.0,0,0.99408036,0.0,0.88420135,77.963036,1.2143661,429.3252,-9.2589226
2510,2510,178.7603,14.93681,8.8377934,0.0,0,0.96778435,0.0,0.88997018,78.064461,1.1885687,429.24124,-9.2595978
2512,2512,178.7607,15.050591,8.8620796,0.0,0,0.94148839,0.0,0.89320707,78.385986,1.1600628,429.15726,-9.2572899
2514,2514,178.7611,15.153931,8.8957367,0.0,0,0.91519243,0.0,0.89784926,78.604675,1.1363999,429.07327,-9.2577991
2516,2516,178.7615,15.233696,8.9199657,0.0,0,0.88916051,0.0,0.90370864,78.552567,1.1096812,428.98932,-9.2575083
2518,2518,178.7619,15.328936,8.9500217,0.0,0,0.86408949,0.0,0.9069773,78.753349,1.0824138,428.90533,-9.258647
2520,2520,178.7623,15.443598,8.9751854,0.0,0,0.83908135,0.0,0.91144574,78.972046,1.0543861,428.82138,-9.2574606
2522,2522,178.7627,15.565833,8.9930983,0.0,0,0.81407332,0.0,0.91580015,79.245842,1.0266652,428.7374,-9.25776
2524,2524,178.7631,15.677361,9.0275202,0.0,0,0.78906536,0.0,0.91933256,79.539993,0.999318,428.65344,-9.2584429
2526,2526,178.7635,15.76984,9.0544167,0.0,0,0.7640574,0.0,0.92523521,79.55629,0.96964747,428.56946,-9.258255
2528,2528,178.7639,15.876874,9.0785551,0.0,0,0.73904938,0.0,0.92950064,79.755791,0.94502795,428.4855,-9.2588329
2530,2530,178.7643,15.997031,9.1137705,0.0,0,0.71404135,0.0,0.9337163,80.010597,0.91805953,428.40152,-9.2579165
2532,2532,178.7647,16.129137,9.1306658,0.0,0,0.68903339,0.0,0.93874818,80.204102,0.89055562,428.31754,-9.257453
2534,2534,178.7651,16.236345,9.154953,0.0,0,0.66402543,0.0,0.94195199,80.526505,0.86540532,428.23355,-9.2573137
2536,2536,178.7655,16.338348,9.1902552,0.0,0,0.63901734,0.0,0.9472422,80.607727,0.83645821,427.6322,-9.2577648
2538,2538,178.7659,16.447788,9.2067938,0.0,0,0.61400938,0.0,0.95205039,80.773598,0.81315583,427.03082,-9.2588682
2540,2540,178.7663,16.572872,9.2375088,0.0,0,0.58900136,0.0,0.95559859,81.079704,0.78452605,426.42947,-9.2589579
2542,2542,178.7667,16.712128,9.2704325,0.0,0,0.56478846,0.0,0.96174783,81.25177,0.75751412,425.82809,-9.2575264
2544,2544,178.7671,16.829763,9.2872953,0.0,0,0.54098594,0.0,0.96570557,81.544144,0.73159695,425.22675,-9.2562666
2546,2546,178.7675,16.935696,9.3154507,0.0,0,0.51718587,0.0,0.96892345,81.764145,0.70562768,424.6254,-9.2565298
2548,2548,178.7679,17.042818,9.3411951,0.0,0,0.49338591,0.0,0.97507465,81.781647,0.67893857,424.02402,-9.2585068
2550,2550,178.7683,17.171497,9.363739,0.0,0,0.4695859,0.0,0.97856081,82.091469,0.6540786,423.42267,-9.2588682
2552,2552,178.7687,17.316467,9.3959618,0.0,0,0.44578591,0.0,0.98321527,82.40197,0.62583333,422.82129,-9.2576933
2554,2554,178.7691,17.42915,9.4188232,0.0,0,0.42198589,0.0,0.98935598,82.496483,0.60307705,422.21994,-9.2561893
2556,2556,178.7695,17.530296,9.4440928,0.0,0,0.39818591,0.0,0.9924705,82.677963,0.57702321,421.61856,-9.2572956
2557,2557,178.7697,17.58523,9.4541759,0.0,0,0.3862859,0.0,0.9959659,82.649307,0.56706721,421.3179,-9.2573347