File: clean data/testID_0190.csv
level_0,index,Time(sec),Force(kN),Jaw(mm),PowAngle(deg),Power(W),Pram,PTemp,Strain,Stress(MPa),Stroke(mm),TC1(C),wedge(mm)
1774,1774,145.3461,0.73432815,0.017657965,0.0,0,9.0044422,0.0,0.0011669908,8.7268381,10.025016,305.48056,-9.3244038
1776,1776,145.3465,3.4326689,0.050657909,0.0,0,8.9459143,0.0,0.0031606057,38.7505,9.9562721,305.74777,-9.3240833
1778,1778,145.3469,5.8141313,0.11427256,0.0,0,8.8873854,0.0,0.0070243133,71.804604,9.9066467,306.01495,-9.3233585
1780,1780,145.3473,6.7702131,0.16901247,0.0,0,8.8288574,0.0,0.010823509,83.715294,9.8332338,306.28214,-9.3199844
1782,1782,145.3477,7.7017407,0.30841219,0.0,0,8.7703295,0.0,0.019872358,95.595695,9.7441845,306.54935,-9.3182583
1784,1784,145.3481,8.2006617,0.39740682,0.0,0,8.7136869,0.0,0.026184889,100.44631,9.6396942,306.81653,-9.3187075
1786,1786,145.3485,9.0728073,0.47705609,0.0,0,8.6580172,0.0,0.031823032,111.2794,9.5405788,307.08374,-9.3186121
1788,1788,145.3489,9.6058931,0.55204082,0.0,0,8.6023531,0.0,0.037232876,117.00266,9.4528666,307.35092,-9.3179703
1790,1790,145.3493,9.7356443,0.57935888,0.0,0,8.546689,0.0,0.038890641,119.85372,9.3793249,307.61813,-9.3164444
1792,1792,145.3497,9.6229687,0.65693009,0.0,0,8.491025,0.0,0.044422138,116.6348,9.3153687,307.88531,-9.3163824
1794,1794,145.3501,10.260551,0.70574683,0.0,0,8.4353609,0.0,0.047760412,124.01694,9.2545509,308.15253,-9.316453
1796,1796,145.3505,10.562754,0.77468044,0.0,0,8.3796968,0.0,0.052299894,127.19776,9.1842632,308.41971,-9.3156843
1798,1798,145.3509,10.558308,0.87806678,0.0,0,8.3240328,0.0,0.059768878,126.96546,9.1019125,308.68692,-9.3168936
1800,1800,145.3513,10.404583,0.96817881,0.0,0,8.2683687,0.0,0.065896779,123.82114,9.0176229,308.9541,-9.3176584
1802,1802,145.3517,10.792358,1.0490632,0.0,0,8.2127056,0.0,0.072070397,127.4434,8.9327297,309.22131,-9.3180103
1804,1804,145.3521,10.975446,1.0963271,0.0,0,8.1570406,0.0,0.075739734,129.17572,8.8604879,309.48849,-9.3161306
1806,1806,145.3525,11.186985,1.134981,0.0,0,8.1013775,0.0,0.078141995,131.67206,8.797986,309.75571,-9.3153086
1808,1808,145.3529,10.937693,1.1964285,0.0,0,8.0462675,0.0,0.083028391,128.42159,8.7473412,310.02289,-9.3145638
1810,1810,145.3533,11.278127,1.2457763,0.0,0,7.993176,0.0,0.086340189,131.10675,8.690938,310.2901,-9.3160925
1812,1812,145.3537,11.469394,1.3145622,0.0,0,7.9402156,0.0,0.090967216,133.41496,8.6312008,310.55728,-9.3155556
1814,1814,145.3541,11.444788,1.3955332,0.0,0,7.8872552,0.0,0.0974603,132.14703,8.5655193,310.86957,-9.3144789
1816,1816,145.3545,11.396899,1.4673188,0.0,0,7.8342953,0.0,0.10228434,131.1776,8.494031,311.19308,-9.3146887
1818,1818,145.3549,11.460649,1.5306798,0.0,0,7.7813349,0.0,0.10729881,130.76711,8.4229364,311.51663,-9.3146544
1820,1820,145.3553,11.718107,1.5667278,0.0,0,7.728375,0.0,0.11044402,133.53578,8.3603086,311.84018,-9.3151855
1822,1822,145.3557,11.727404,1.6212078,0.0,0,7.675415,0.0,0.11361764,133.33144,8.3057795,312.16373,-9.3152094
1824,1824,145.3561,11.753783,1.6689823,0.0,0,7.6224551,0.0,0.11777048,133.08495,8.2559509,312.48724,-9.3162413
1826,1826,145.3565,11.879117,1.7089578,0.0,0,7.5694952,0.0,0.12076282,133.78114,8.2072515,312.81079,-9.3146238
1828,1828,145.3569,12.040517,1.7754977,0.0,0,7.5165353,0.0,0.12504201,135.20308,8.1504431,313.13434,-9.3140593
1830,1830,145.3573,11.995579,1.8360994,0.0,0,7.4635754,0.0,0.13036661,134.17093,8.0951099,313.45789,-9.3136854
1832,1832,145.3577,12.049965,1.8969311,0.0,0,7.410615,0.0,0.1346935,134.09138,8.0352831,313.7814,-9.3138952
1834,1834,145.3581,12.051575,1.9595402,0.0,0,7.3593607,0.0,0.1394334,133.38634,7.9739842,314.10495,-9.3149137
1836,1836,145.3585,12.27235,1.9912218,0.0,0,7.3089876,0.0,0.14246048,135.30852,7.9237108,314.4285,-9.3152103
1838,1838,145.3589,12.212917,2.039382,0.0,0,7.2586198,0.0,0.14558384,134.5929,7.8718591,314.75204,-9.3148346
1840,1840,145.3593,12.257652,2.0899441,0.0,0,7.2082515,0.0,0.14964555,134.24973,7.8272638,315.07556,-9.3146238
1842,1842,145.3597,12.344958,2.1242099,0.0,0,7.1578832,0.0,0.15260693,134.84773,7.7799225,315.39911,-9.3137379
1844,1844,145.3601,12.523933,2.182596,0.0,0,7.1075149,0.0,0.15651621,136.18713,7.7320514,315.72266,-9.3133574
1846,1846,145.3605,12.528096,2.2385666,0.0,0,7.0571475,0.0,0.16131321,135.82393,7.6809101,316.0462,-9.3149109
1848,1848,145.3609,12.475426,2.2894425,0.0,0,7.0067787,0.0,0.16539717,134.63976,7.6296701,316.36975,-9.3156395
1850,1850,145.3613,12.549067,2.3404393,0.0,0,6.9564114,0.0,0.16900572,134.88411,7.578207,316.69327,-9.3165321
1852,1852,145.3617,12.696596,2.3805478,0.0,0,6.9060431,0.0,0.17271757,135.75755,7.5270119,317.01682,-9.3148804
1854,1854,145.3621,12.742609,2.4263458,0.0,0,6.8556757,0.0,0.17602484,136.09903,7.4783025,317.34036,-9.3140221
1856,1856,145.3625,12.718669,2.4717095,0.0,0,6.8053074,0.0,0.17952359,135.33888,7.4340096,317.66391,-9.3145819
1858,1858,145.3629,12.780648,2.5126493,0.0,0,6.7554412,0.0,0.18337315,135.36884,7.3866715,317.98743,-9.3152313
1860,1860,145.3633,12.901097,2.5672059,0.0,0,6.7074018,0.0,0.18708076,136.12743,7.3386607,318.31097,-9.3150892
1862,1862,145.3637,12.969708,2.6150963,0.0,0,6.6594815,0.0,0.19107716,136.39406,7.2916465,318.63452,-9.3147068
1864,1864,145.3641,12.971336,2.6612546,0.0,0,6.6115613,0.0,0.19535093,135.89061,7.2444506,318.61951,-9.3147678
1866,1866,145.3645,13.025855,2.71417,0.0,0,6.5636415,0.0,0.19889691,135.90924,7.1944528,318.54474,-9.3147717
1868,1868,145.3649,13.100192,2.7546301,0.0,0,6.5157218,0.0,0.20263536,136.21204,7.1482968,318.46997,-9.3144369
1870,1870,145.3653,13.168159,2.7992094,0.0,0,6.467802,0.0,0.20637096,136.38368,7.0963869,318.3952,-9.3152876
1872,1872,145.3657,13.221158,2.8516285,0.0,0,6.4198813,0.0,0.21000187,136.37218,7.0514584,318.32043,-9.3141546
1874,1874,145.3661,13.297552,2.8934212,0.0,0,6.3719611,0.0,0.21412264,136.59509,7.0052123,318.24567,-9.3151979
1876,1876,145.3665,13.370493,2.9437938,0.0,0,6.3240414,0.0,0.21803547,136.82089,6.9560542,318.1709,-9.3146439
1878,1878,145.3669,13.411781,2.9997399,0.0,0,6.2761216,0.0,0.22242622,136.5995,6.9069958,318.09613,-9.3144283
1880,1880,145.3673,13.431433,3.0438075,0.0,0,6.2282019,0.0,0.22675072,136.29579,6.85286,318.02136,-9.3151531
1882,1882,145.3677,13.52816,3.0901382,0.0,0,6.1802816,0.0,0.23018081,136.70856,6.8058143,317.94659,-9.3152704
1884,1884,145.3681,13.606774,3.142616,0.0,0,6.1339045,0.0,0.2344833,136.96069,6.756423,317.87183,-9.3163328
1886,1886,145.3685,13.656715,3.1834562,0.0,0,6.0883236,0.0,0.23851614,136.91808,6.707931,317.79706,-9.3160105
1888,1888,145.3689,13.674672,3.2314541,0.0,0,6.042748,0.0,0.24184784,136.65443,6.6598444,317.72229,-9.3159599
1890,1890,145.3693,13.767474,3.2842722,0.0,0,5.9971714,0.0,0.24674477,136.87608,6.6128092,317.64752,-9.3146286
1892,1892,145.3697,13.8641,3.3275499,0.0,0,5.9515953,0.0,0.25065643,137.30342,6.5649281,317.57275,-9.3144999
1894,1894,145.3701,13.907187,3.3803847,0.0,0,5.9060197,0.0,0.25459284,137.27789,6.5128098,317.49799,-9.3151731
1896,1896,145.3705,13.926343,3.4311726,0.0,0,5.8604436,0.0,0.25967288,136.75325,6.4669275,317.42322,-9.3158865
1898,1898,145.3709,13.992875,3.4777095,0.0,0,5.814867,0.0,0.26338485,136.75887,6.4204578,317.34848,-9.3164072
1900,1900,145.3713,14.069618,3.5268562,0.0,0,5.7692914,0.0,0.26739776,137.03474,6.3709421,317.27371,-9.3155079
1902,1902,145.3717,14.153419,3.5720394,0.0,0,5.7237153,0.0,0.27204946,137.24001,6.3204951,317.19894,-9.3152218
1904,1904,145.3721,14.187556,3.618732,0.0,0,5.6781397,0.0,0.275473,137.09912,6.2755942,317.12418,-9.315732
1906,1906,145.3725,14.235055,3.6679015,0.0,0,5.6325636,0.0,0.27984184,136.9252,6.22472,317.04941,-9.3157473
1908,1908,145.3729,14.306272,3.7111623,0.0,0,5.5874414,0.0,0.28427479,137.052,6.1773157,316.97464,-9.3162193
1910,1910,145.3733,14.38496,3.7668614,0.0,0,5.5439734,0.0,0.28834644,137.24152,6.129178,316.89987,-9.3159962
1912,1912,145.3737,14.432542,3.8150434,0.0,0,5.5006132,0.0,0.29312888,137.05424,6.0837493,316.8251,-9.3148451
1914,1914,145.3741,14.495185,3.8607211,0.0,0,5.457253,0.0,0.29742277,137.06439,6.0332723,316.76361,-9.3150454
1916,1916,145.3745,14.553447,3.9148171,0.0,0,5.4138932,0.0,0.30151576,136.95224,5.984798,316.70358,-9.3153315
1918,1918,145.3749,14.612048,3.951777,0.0,0,5.370533,0.0,0.30567282,137.00229,5.9386129,316.64355,-9.3149958
1920,1920,145.3753,14.677281,3.9964261,0.0,0,5.3271732,0.0,0.30947557,137.09764,5.8911681,316.58356,-9.3153477
1922,1922,145.3757,14.753825,4.0525599,0.0,0,5.283813,0.0,0.31405595,137.16963,5.8409371,316.52353,-9.3146276
1924,1924,145.3761,14.835415,4.0922389,0.0,0,5.2404532,0.0,0.31852716,137.29485,5.7972322,316.4635,-9.3147039
1926,1926,145.3765,14.880284,4.1417651,0.0,0,5.1970935,0.0,0.32253352,137.11014,5.7487249,316.4035,-9.3153276
1928,1928,145.3769,14.925012,4.1971107,0.0,0,5.1537333,0.0,0.32746708,136.93712,5.7007909,316.34348,-9.3168621
1930,1930,145.3773,15.004958,4.2362447,0.0,0,5.110373,0.0,0.33182156,136.99034,5.653399,316.28345,-9.3160391
1932,1932,145.3777,15.09087,4.2853231,0.0,0,5.0670133,0.0,0.33559081,137.32121,5.6039047,316.22342,-9.3145885
1934,1934,145.3781,15.154899,4.3342009,0.0,0,5.0250483,0.0,0.34061658,137.19243,5.5561657,316.16342,-9.3136978
1936,1936,145.3785,15.182746,4.3747439,0.0,0,4.9838037,0.0,0.34465724,136.93597,5.509388,316.10339,-9.3149366
1938,1938,145.3789,15.236187,4.4244132,0.0,0,4.9425635,0.0,0.34865567,136.81715,5.4640155,316.04337,-9.3159113
1940,1940,145.3793,15.329197,4.4716244,0.0,0,4.9013238,0.0,0.35385251,136.95613,5.4148817,315.98334,-9.3166933
1942,1942,145.3797,15.412455,4.514184,0.0,0,4.8600836,0.0,0.35769179,137.14191,5.3721619,315.92334,-9.3162003
1944,1944,145.3801,15.457188,4.5620408,0.0,0,4.8188438,0.0,0.36183929,137.01888,5.3252263,315.86331,-9.3157349
1946,1946,145.3805,15.492994,4.604157,0.0,0,4.7776036,0.0,0.36660865,136.6671,5.2797122,315.80328,-9.3145866
1948,1948,145.3809,15.566606,4.6507583,0.0,0,4.7363639,0.0,0.37045926,136.79532,5.2340784,315.74326,-9.3153191
1950,1950,145.3813,15.643468,4.6966524,0.0,0,4.6951237,0.0,0.37499028,136.85481,5.1891003,315.68326,-9.3158731
1952,1952,145.3817,15.725862,4.7384739,0.0,0,4.6538839,0.0,0.3797012,136.93307,5.1469746,315.62323,-9.3161087
1954,1954,145.3821,15.77521,4.788064,0.0,0,4.6126437,0.0,0.38368946,136.81424,5.1015682,315.5632,-9.314805
1956,1956,145.3825,15.812318,4.8314977,0.0,0,4.5714035,0.0,0.38831973,136.52654,5.055305,315.5032,-9.3157578
1958,1958,145.3829,15.891399,4.8705702,0.0,0,4.5305758,0.0,0.39261773,136.58682,5.0181098,315.44318,-9.3159876
1960,1960,145.3833,15.965519,4.9185667,0.0,0,4.4912457,0.0,0.39629111,136.66292,4.9696231,315.38315,-9.3145342
1962,1962,145.3837,16.034676,4.9553552,0.0,0,4.4520135,0.0,0.40079907,136.75237,4.926321,315.32312,-9.3143988
1964,1964,145.3841,16.088278,4.997438,0.0,0,4.4127812,0.0,0.40485242,136.62318,4.8841786,315.42026,-9.3155384
1966,1966,145.3845,16.129246,5.0520062,0.0,0,4.3735495,0.0,0.40961134,136.29762,4.8367486,315.52567,-9.3161135
1968,1968,145.3849,16.187065,5.0896254,0.0,0,4.3343177,0.0,0.4145211,136.18236,4.7977123,315.63107,-9.3161888
1970,1970,145.3853,16.292259,5.1306853,0.0,0,4.2950859,0.0,0.41807991,136.43658,4.7535229,315.73648,-9.3160105
1972,1972,145.3857,16.369003,5.1777968,0.0,0,4.2558532,0.0,0.42262733,136.53888,4.7135653,315.84189,-9.3140154
1974,1974,145.3861,16.406736,5.2092462,0.0,0,4.2166214,0.0,0.42671877,136.27614,4.6703691,315.9473,-9.3139925
1976,1976,145.3865,16.445045,5.2544193,0.0,0,4.1773891,0.0,0.43039474,136.11867,4.6284533,316.0527,-9.313756
1978,1978,145.3869,16.531942,5.3023005,0.0,0,4.1381574,0.0,0.43565971,136.03239,4.5852256,316.15811,-9.3160429
1980,1980,145.3873,16.615921,5.3378224,0.0,0,4.0989256,0.0,0.4397777,136.19061,4.5457616,316.26352,-9.3161364
1982,1982,145.3877,16.692734,5.3836269,0.0,0,4.0596933,0.0,0.44369325,136.34105,4.5044308,316.36893,-9.3159161
1984,1984,145.3881,16.742031,5.4242516,0.0,0,4.0217257,0.0,0.44876522,136.03242,4.4618473,316.47433,-9.3152466
1986,1986,145.3885,16.79627,5.4589128,0.0,0,3.9844091,0.0,0.452315,136.02428,4.4226804,316.57974,-9.3146448
1988,1988,145.3889,16.899591,5.5029478,0.0,0,3.9470971,0.0,0.45625207,136.22964,4.3832231,316.68515,-9.3145638
1990,1990,145.3893,16.984938,5.5425553,0.0,0,3.9097853,0.0,0.46125636,136.28653,4.3395948,316.79056,-9.3146057
1992,1992,145.3897,17.056948,5.5843878,0.0,0,3.8724732,0.0,0.46505371,136.31558,4.2963576,316.89597,-9.3151178
1994,1994,145.3901,17.09654,5.6272311,0.0,0,3.8351612,0.0,0.46953264,136.09496,4.259409,317.00137,-9.31493
1996,1996,145.3905,17.157717,5.6616364,0.0,0,3.7978492,0.0,0.47423729,135.94786,4.2203469,317.10675,-9.3154068
1998,1998,145.3909,17.252016,5.7052422,0.0,0,3.7605371,0.0,0.477808,136.13495,4.177002,317.21216,-9.3157778
2000,2000,145.3913,17.33634,5.7435875,0.0,0,3.7232251,0.0,0.48232144,136.20811,4.1374907,317.31757,-9.3146687
2002,2002,145.3917,17.402691,5.7767229,0.0,0,3.6859133,0.0,0.48650247,136.17911,4.0972395,317.42297,-9.3132372
2004,2004,145.3921,17.46525,5.824719,0.0,0,3.6486013,0.0,0.49046284,136.11389,4.0595484,317.52838,-9.313797
2006,2006,145.3925,17.531021,5.8585901,0.0,0,3.611289,0.0,0.49507776,136.03749,4.0212455,317.63379,-9.3153172
2008,2008,145.3929,17.618031,5.8955183,0.0,0,3.5743496,0.0,0.49901256,136.19295,3.9812245,317.7392,-9.3161793
2010,2010,145.3933,17.713646,5.9449358,0.0,0,3.5387647,0.0,0.50357747,136.20901,3.9397509,317.8446,-9.3155746
2012,2012,145.3937,17.799314,5.9760237,0.0,0,3.5032687,0.0,0.5082379,136.27202,3.9030221,317.95001,-9.3138847
2014,2014,145.3941,17.855253,6.0153975,0.0,0,3.4677725,0.0,0.51206928,136.14775,3.8660414,317.93408,-9.3129969
2016,2016,145.3945,17.920795,6.0624137,0.0,0,3.4322767,0.0,0.51696557,136.01776,3.8262157,317.91815,-9.314765
2018,2018,145.3949,18.008953,6.09097,0.0,0,3.3967807,0.0,0.52123481,136.08342,3.7875285,317.90222,-9.3153706
2020,2020,145.3953,18.112694,6.1311932,0.0,0,3.3612847,0.0,0.52467757,136.38168,3.746716,317.88629,-9.3158131
2022,2022,145.3957,18.189253,6.1758361,0.0,0,3.3257885,0.0,0.52995193,136.21741,3.7115514,317.87036,-9.3143988
2024,2024,145.3961,18.260168,6.2066073,0.0,0,3.2902927,0.0,0.53406936,136.22954,3.6697226,317.8544,-9.3140097
2026,2026,145.3965,18.325634,6.2495089,0.0,0,3.2547965,0.0,0.53801596,136.16583,3.6342847,317.83847,-9.3131227
2028,2028,145.3969,18.41715,6.2864456,0.0,0,3.2193005,0.0,0.54306817,136.17172,3.596462,317.82254,-9.3146095
2030,2030,145.3973,18.526005,6.3180904,0.0,0,3.1838045,0.0,0.54679656,136.45155,3.5588253,317.80661,-9.3146086
2032,2032,145.3977,18.607952,6.3605013,0.0,0,3.1483085,0.0,0.55074263,136.53784,3.519721,317.79068,-9.3152637
2034,2034,145.3981,18.673582,6.3966475,0.0,0,3.1139498,0.0,0.55602896,136.27866,3.4870384,317.77475,-9.3152227
2036,2036,145.3985,18.746458,6.4327908,0.0,0,3.0801783,0.0,0.55967003,136.32182,3.4490237,317.75882,-9.3133469
2038,2038,145.3989,18.839611,6.4735026,0.0,0,3.0464103,0.0,0.5640831,136.40439,3.4119458,317.74289,-9.3131027
2040,2040,145.3993,18.956478,6.5061841,0.0,0,3.0126421,0.0,0.56897944,136.54677,3.3764524,317.72696,-9.313715
2042,2042,145.3997,19.038511,6.545053,0.0,0,2.9788742,0.0,0.57247519,136.68845,3.3389456,317.71103,-9.3137856
2044,2044,145.4001,19.105995,6.5819511,0.0,0,2.9451063,0.0,0.57708824,136.57553,3.3021204,317.6951,-9.314888
2046,2046,145.4005,19.186153,6.6125932,0.0,0,2.9113381,0.0,0.58156103,136.47508,3.2646794,317.67917,-9.3150482
2048,2048,145.4009,19.290356,6.6573997,0.0,0,2.8775702,0.0,0.58553767,136.67456,3.2280178,317.66321,-9.3140774
2050,2050,145.4013,19.411821,6.6887565,0.0,0,2.8438022,0.0,0.59013408,136.85808,3.1898265,317.64728,-9.3136692
2052,2052,145.4017,19.496084,6.7203445,0.0,0,2.810034,0.0,0.59420967,136.94751,3.1539431,317.63135,-9.3131161
2054,2054,145.4021,19.557714,6.7656226,0.0,0,2.7762663,0.0,0.59845454,136.8486,3.1187646,317.61542,-9.3141756
2056,2056,145.4025,19.642517,6.7937183,0.0,0,2.7424982,0.0,0.60312641,136.7307,3.085202,317.59949,-9.3143864
2058,2058,145.4029,19.745399,6.8272142,0.0,0,2.7090681,0.0,0.606803,136.93645,3.0505836,317.58356,-9.3142633
2060,2060,145.4033,19.875055,6.8725662,0.0,0,2.6768675,0.0,0.61162835,137.15958,3.0153706,317.56763,-9.3138332
2062,2062,145.4037,19.956089,6.8986001,0.0,0,2.6447473,0.0,0.61631221,137.10922,2.9788177,317.54678,-9.3136415
2064,2064,145.4041,20.020866,6.934083,0.0,0,2.6126273,0.0,0.61964422,137.1265,2.9457681,317.4328,-9.3139935
2066,2066,145.4045,20.113764,6.9737544,0.0,0,2.580507,0.0,0.62461507,137.0685,2.9107935,317.31882,-9.3146076
2068,2068,145.4049,20.231316,6.9995475,0.0,0,2.5483871,0.0,0.62872511,137.29721,2.8749213,317.20483,-9.3138609
2070,2070,145.4053,20.351013,7.0390701,0.0,0,2.5162671,0.0,0.63241607,137.63724,2.8427718,317.09085,-9.3121471
2072,2072,145.4057,20.433573,7.0775537,0.0,0,2.4841471,0.0,0.63794315,137.45961,2.8116817,316.97684,-9.3122625
2074,2074,145.4061,20.504763,7.1031613,0.0,0,2.4520271,0.0,0.64159095,137.34848,2.778091,316.86285,-9.3136148
2076,2076,145.4065,20.60918,7.1393452,0.0,0,2.4199073,0.0,0.64525861,137.54448,2.7432005,316.74887,-9.3146591
2078,2078,145.4069,20.725271,7.1706944,0.0,0,2.3877871,0.0,0.65035194,137.69586,2.7140415,316.63489,-9.31429
2080,2080,145.4073,20.843534,7.2021008,0.0,0,2.3556671,0.0,0.65378457,137.9678,2.6763911,316.5209,-9.313817
2082,2082,145.4077,20.924929,7.2404938,0.0,0,2.3235471,0.0,0.65822852,137.90504,2.6469409,316.40692,-9.3131723
2084,2084,145.4081,21.007286,7.2708154,0.0,0,2.2924592,0.0,0.6634658,137.76118,2.6121471,316.29294,-9.3138132
2086,2086,145.4085,21.131893,7.3069611,0.0,0,2.261904,0.0,0.66689444,138.00291,2.5777161,316.17892,-9.3129768
2088,2088,145.4089,21.259809,7.3388238,0.0,0,2.2313521,0.0,0.67110479,138.29283,2.5440779,316.06494,-9.3130045
2090,2090,145.4093,21.373926,7.3631282,0.0,0,2.2008002,0.0,0.67553681,138.42223,2.5123394,315.95096,-9.3137865
2092,2092,145.4097,21.458832,7.4014611,0.0,0,2.170248,0.0,0.67896414,138.51714,2.4814894,315.83698,-9.3134556
2094,2094,145.4101,21.555922,7.4332261,0.0,0,2.1396961,0.0,0.68396401,138.39165,2.4475143,315.72299,-9.3130379
2096,2096,145.4105,21.669962,7.4632034,0.0,0,2.109144,0.0,0.68832564,138.4977,2.4146206,315.60901,-9.3136377
2098,2098,145.4109,21.804527,7.5046577,0.0,0,2.0785921,0.0,0.69238281,138.83105,2.3815582,315.495,-9.3130655
2100,2100,145.4113,21.918972,7.5285997,0.0,0,2.0480402,0.0,0.69713646,138.90601,2.3493295,315.38101,-9.3128386
2102,2102,145.4117,22.005398,7.5571637,0.0,0,2.0174882,0.0,0.70050615,139.00191,2.3175774,315.26703,-9.3130369
2104,2104,145.4121,22.115875,7.596725,0.0,0,1.986936,0.0,0.70487267,139.08662,2.2886777,315.15305,-9.3133736
2106,2106,145.4125,22.24489,7.6193814,0.0,0,1.9563839,0.0,0.70966673,139.17358,2.2573764,315.03906,-9.3130627
2108,2108,145.4129,22.371214,7.6546173,0.0,0,1.9261372,0.0,0.71323746,139.51984,2.2253444,314.92508,-9.312624
2110,2110,145.4133,22.495253,7.6940813,0.0,0,1.8970003,0.0,0.71842003,139.55318,2.197036,314.8111,-9.3125544
2112,2112,145.4137,22.597305,7.7138271,0.0,0,1.8679363,0.0,0.72248346,139.65085,2.162514,314.70334,-9.3123102
2114,2114,145.4141,22.701633,7.7481384,0.0,0,1.8388723,0.0,0.72575992,139.83897,2.1326058,314.65186,-9.3130598
2116,2116,145.4145,22.835064,7.7826004,0.0,0,1.8098083,0.0,0.73121876,139.8622,2.0989063,314.6004,-9.313221
2118,2118,145.4149,22.966675,7.8037858,0.0,0,1.7807442,0.0,0.73468792,140.1835,2.0733161,314.54892,-9.3124142
2120,2120,145.4153,23.088669,7.8403702,0.0,0,1.7516803,0.0,0.73832768,140.45168,2.0412412,314.49744,-9.3122692
2122,2122,145.4157,23.209845,7.8716578,0.0,0,1.7226163,0.0,0.74401116,140.32895,2.011374,314.44595,-9.3129787
2124,2124,145.4161,23.323572,7.8983617,0.0,0,1.6935523,0.0,0.74756664,140.55728,1.9788692,314.39447,-9.31423
2126,2126,145.4165,23.446886,7.9322696,0.0,0,1.6644882,0.0,0.75153965,140.71976,1.950755,314.34302,-9.3125629
2128,2128,145.4169,23.608709,7.959733,0.0,0,1.6354243,0.0,0.75683892,140.93317,1.9172852,314.29153,-9.3122377
2130,2130,145.4173,23.731869,7.9922409,0.0,0,1.6063603,0.0,0.76011091,141.228,1.8890687,314.24005,-9.312048
2132,2132,145.4177,23.843735,8.0240812,0.0,0,1.5772963,0.0,0.76466936,141.25322,1.8567793,314.18857,-9.3115387
2134,2134,145.4181,23.954756,8.0476732,0.0,0,1.5491643,0.0,0.76943249,141.23622,1.8276557,314.13708,-9.3129368
2136,2136,145.4185,24.096771,8.0818539,0.0,0,1.5215131,0.0,0.77264947,141.57997,1.7974479,314.08563,-9.3131847
2138,2138,145.4189,24.25564,8.1085262,0.0,0,1.4938651,0.0,0.77738059,141.86176,1.7698551,314.03415,-9.3116693
2140,2140,145.4193,24.391541,8.1322451,0.0,0,1.4662172,0.0,0.78141874,142.0719,1.7394933,313.98267,-9.3112803
2142,2142,145.4197,24.51288,8.1712894,0.0,0,1.4385692,0.0,0.78546637,142.22014,1.7102331,313.93118,-9.3108768
2144,2144,145.4201,24.646994,8.1956615,0.0,0,1.4109212,0.0,0.79056889,142.24609,1.6810513,313.8797,-9.3115187
2146,2146,145.4205,24.786224,8.2232513,0.0,0,1.3832732,0.0,0.79443508,142.50037,1.6552075,313.82822,-9.3125143
2148,2148,145.4209,24.956656,8.2625475,0.0,0,1.3556252,0.0,0.79895091,142.83499,1.6264343,313.77676,-9.3134661
2150,2150,145.4213,25.094654,8.2824497,0.0,0,1.3279773,0.0,0.80368716,142.99124,1.597682,313.72528,-9.3121252
2152,2152,145.4217,25.211676,8.3096266,0.0,0,1.3003292,0.0,0.80685258,143.18921,1.5673155,313.6738,-9.3114843
2154,2154,145.4221,25.355631,8.344614,0.0,0,1.2726812,0.0,0.81153446,143.2677,1.5403767,313.62231,-9.3103495
2156,2156,145.4225,25.505682,8.362361,0.0,0,1.2450333,0.0,0.81579787,143.55634,1.5084343,313.57083,-9.3108654
2158,2158,145.4229,25.679003,8.3956518,0.0,0,1.2176626,0.0,0.81920183,144.0316,1.4843253,313.51938,-9.311636
2160,2160,145.4233,25.827993,8.431138,0.0,0,1.1913005,0.0,0.82509679,144.06285,1.4530118,313.4679,-9.3117666
2162,2162,145.4237,25.94405,8.4509678,0.0,0,1.1650044,0.0,0.82904416,144.10971,1.4275054,313.41235,-9.3109093
2164,2164,145.4241,26.090504,8.4832172,0.0,0,1.1387082,0.0,0.83239031,144.46544,1.3954037,313.33392,-9.3108034
2166,2166,145.4245,26.263685,8.5106144,0.0,0,1.1124123,0.0,0.83787197,144.57314,1.3690864,313.25549,-9.3106079
2168,2168,145.4249,26.444021,8.5308695,0.0,0,1.0861163,0.0,0.84104699,145.09639,1.3407744,313.17703,-9.3100824
2170,2170,145.4253,26.583673,8.5630922,0.0,0,1.0598202,0.0,0.84476793,145.38145,1.3135917,313.0986,-9.3110409
2172,2172,145.4257,26.714024,8.5892553,0.0,0,1.0335243,0.0,0.85057628,145.22986,1.2847729,313.02014,-9.3104086
2174,2174,145.4261,26.851458,8.6158171,0.0,0,1.0072283,0.0,0.85364163,145.48929,1.2589328,312.94171,-9.3111315
2176,2176,145.4265,27.029665,8.646306,0.0,0,0.98093224,0.0,0.85825908,145.80417,1.2316771,312.86325,-9.3113117
2178,2178,145.4269,27.212749,8.6675692,0.0,0,0.95463622,0.0,0.86311436,146.08487,1.2017429,312.78482,-9.3103733
2180,2180,145.4273,27.351385,8.6996603,0.0,0,0.92834032,0.0,0.86632419,146.38885,1.1747466,312.70639,-9.309742
2182,2182,145.4277,27.488037,8.7242479,0.0,0,0.9020443,0.0,0.87089354,146.42494,1.1480987,312.62793,-9.3099136
2184,2184,145.4281,27.662199,8.7437944,0.0,0,0.87659597,0.0,0.87498438,146.70529,1.1248044,312.5495,-9.3106594
2186,2186,145.4285,27.842627,8.7774401,0.0,0,0.85158527,0.0,0.87827659,147.16841,1.0977612,312.47104,-9.3102131
2188,2188,145.4289,28.034754,8.7985487,0.0,0,0.82657719,0.0,0.88324362,147.48151,1.0726329,312.39261,-9.3107166
2190,2190,145.4293,28.172565,8.8221426,0.0,0,0.80156928,0.0,0.88706219,147.66246,1.0453995,312.31418,-9.3099499
2192,2192,145.4297,28.320955,8.8598814,0.0,0,0.77656126,0.0,0.89154488,147.76865,1.0181215,312.23572,-9.3090324
2194,2194,145.4301,28.494631,8.8771114,0.0,0,0.75155324,0.0,0.89628482,147.9606,0.99292916,312.15729,-9.3096657
2196,2196,145.4305,28.682417,8.9011374,0.0,0,0.72654527,0.0,0.89948869,148.48909,0.96617109,312.07883,-9.3100195
2198,2198,145.4309,28.869753,8.9342165,0.0,0,0.70153725,0.0,0.9041031,148.74696,0.93959856,312.0004,-9.311347
2200,2200,145.4313,29.022421,8.9486952,0.0,0,0.67652929,0.0,0.90834808,148.9082,0.91322309,311.92194,-9.3105326
2202,2202,145.4317,29.180084,8.9760971,0.0,0,0.65152127,0.0,0.91133744,149.2823,0.88785088,311.84351,-9.3087473
2204,2204,145.4321,29.355772,9.0087204,0.0,0,0.62651324,0.0,0.91683775,149.3315,0.86376798,311.76508,-9.3084021
2206,2206,145.4325,29.541719,9.0237446,0.0,0,0.60150528,0.0,0.92078853,149.67104,0.83642113,311.68661,-9.3087263
2208,2208,145.4329,29.730394,9.0541677,0.0,0,0.57674497,0.0,0.92391449,150.18231,0.81275755,311.60818,-9.3106213
2210,2210,145.4333,29.89687,9.0787621,0.0,0,0.55288589,0.0,0.92952538,150.17442,0.787503,311.52972,-9.3102474
2212,2212,145.4337,30.064964,9.0968132,0.0,0,0.52908581,0.0,0.93266881,150.55266,0.76257598,311.47827,-9.3098135
2214,2214,145.4341,30.245213,9.1254158,0.0,0,0.5052858,0.0,0.93605876,150.89449,0.73662454,311.53464,-9.3089304
2216,2216,145.4345,30.438189,9.1465759,0.0,0,0.48148578,0.0,0.94159865,151.02396,0.71474773,311.591,-9.3078871
2218,2218,145.4349,30.637627,9.16994,0.0,0,0.4576858,0.0,0.9446038,151.57254,0.68613541,311.6474,-9.3080158
2220,2220,145.4353,30.794399,9.1979618,0.0,0,0.43388578,0.0,0.94859856,151.77538,0.66252089,311.70377,-9.3084879
2222,2222,145.4357,30.973139,9.2167435,0.0,0,0.4100858,0.0,0.95399505,151.82057,0.63980281,311.76016,-9.309145
2224,2224,145.4361,31.163694,9.2437229,0.0,0,0.38628578,0.0,0.95663804,152.33266,0.61624366,311.81653,-9.3094482
2226,2226,145.4365,31.36698,9.267395,0.0,0,0.36248577,0.0,0.96113098,152.64221,0.59333795,311.87292,-9.3079214
2228,2228,145.4369,31.572678,9.283927,0.0,0,0.33868581,0.0,0.96537697,152.99542,0.56633002,311.92929,-9.308322
2230,2230,145.4373,31.746607,9.3139791,0.0,0,0.3148858,0.0,0.96858978,153.37349,0.54516959,311.98569,-9.307703
2232,2232,145.4377,31.911678,9.3361721,0.0,0,0.29108578,0.0,0.97369325,153.39697,0.52252585,312.04205,-9.3078651
2233,2233,145.4379,32.011585,9.3529654,0.0,0,0.27942529,0.0,0.97515184,153.60817,0.51159656,312.07025,-9.3080158