File: clean data/testID_0254.csv
level_0,index,Time(sec),Force(kN),Jaw(mm),PowAngle(deg),Power(W),Pram,PTemp,Strain,Stress(MPa),Stroke(mm),TC1(C),wedge(mm)
2495,2495,195.3883,1.2281023,0.025307821,0.0,0,9.7238636,0.0,0.0016649452,15.422551,9.8171225,449.10056,-9.236783
2506,2506,195.3905,1.8275402,0.038623918,0.0,0,9.6908636,0.0,0.0025209896,23.24111,9.7868519,449.06104,-9.2363882
2517,2517,195.3927,1.9232024,0.029040258,0.0,0,9.6578636,0.0,0.0019522818,24.415167,9.7547102,449.02151,-9.2353573
2528,2528,195.3949,2.9383664,0.042815827,0.0,0,9.6248636,0.0,0.0029129717,37.066647,9.723134,448.98618,-9.2351074
2539,2539,195.3971,3.3879523,0.071185395,0.0,0,9.5918636,0.0,0.0047406536,42.762505,9.6896524,448.95325,-9.2341461
2550,2550,195.3993,3.5741286,0.11396642,0.0,0,9.5588636,0.0,0.0075433478,45.194382,9.6541567,448.92032,-9.2345715
2561,2561,195.4015,3.711412,0.14556386,0.0,0,9.5258636,0.0,0.0097202314,46.669384,9.6178837,448.88736,-9.2341108
2572,2572,195.4037,3.8346732,0.17884286,0.0,0,9.4928637,0.0,0.012029639,48.168423,9.5773716,448.85263,-9.2341413
2583,2583,195.4059,3.911073,0.21473967,0.0,0,9.4604025,0.0,0.014320526,49.110855,9.5408306,448.79993,-9.2331762
2594,2594,195.4081,3.9824636,0.25247511,0.0,0,9.4282112,0.0,0.016968047,49.832596,9.5072994,448.74725,-9.2341013
2605,2605,195.4103,4.0221462,0.28262314,0.0,0,9.3960209,0.0,0.018928928,50.255005,9.4698572,448.69455,-9.2340689
2616,2616,195.4125,4.0709476,0.31593549,0.0,0,9.3638315,0.0,0.021282194,50.611763,9.444396,448.64188,-9.2343817
2627,2627,195.4147,4.0978661,0.34365627,0.0,0,9.3316412,0.0,0.023169598,50.951508,9.4089603,448.60715,-9.2346325
2638,2638,195.4169,4.1214256,0.37969071,0.0,0,9.2994499,0.0,0.025636295,51.185726,9.3753586,448.58737,-9.2342024
2649,2649,195.4191,4.1109729,0.4060086,0.0,0,9.2672586,0.0,0.027420424,50.894325,9.3460531,448.5676,-9.2343302
2660,2660,195.4213,4.1355176,0.43574175,0.0,0,9.2350683,0.0,0.029434595,51.135944,9.3122263,448.54785,-9.2347574
2671,2671,195.4235,4.1681638,0.46601591,0.0,0,9.202879,0.0,0.031491291,51.370937,9.2836466,448.52808,-9.2328835
2682,2682,195.4257,4.1850834,0.50204444,0.0,0,9.1706886,0.0,0.034166511,51.620979,9.2482023,448.50174,-9.2343721
2693,2693,195.4279,4.2468944,0.53309065,0.0,0,9.1384983,0.0,0.036088955,52.156414,9.2192268,448.47537,-9.2340021
2704,2704,195.4301,4.2790432,0.5684163,0.0,0,9.106307,0.0,0.038655736,52.326286,9.1776237,448.44904,-9.234025
2715,2715,195.4323,4.3016367,0.60066998,0.0,0,9.0741167,0.0,0.040763449,52.558342,9.1429787,448.4227,-9.2339296
2726,2726,195.4345,4.3117356,0.63689327,0.0,0,9.0419264,0.0,0.043411534,52.538902,9.114234,448.39633,-9.2343311
2737,2737,195.4367,4.3067594,0.66999936,0.0,0,9.009737,0.0,0.04550745,52.41888,9.0797653,448.37,-9.2338095
2748,2748,195.4389,4.3051915,0.69841886,0.0,0,8.9775457,0.0,0.04768084,52.245228,9.0481024,448.34363,-9.234745
2759,2759,195.4411,4.3048463,0.72988826,0.0,0,8.9453554,0.0,0.049814358,52.098122,9.0160303,448.31729,-9.2345238
2770,2770,195.4433,4.3230548,0.7657783,0.0,0,8.9131651,0.0,0.052521955,52.306107,8.9822731,448.29092,-9.2340355
2781,2781,195.4455,4.3425326,0.7964626,0.0,0,8.8809748,0.0,0.054401617,52.312267,8.947526,448.21069,-9.2345619
2792,2792,195.4477,4.3549194,0.82607752,0.0,0,8.8487844,0.0,0.056667816,52.388428,8.9151173,448.12506,-9.2350588
2803,2803,195.4499,4.3868642,0.85604978,0.0,0,8.8165941,0.0,0.058657005,52.688019,8.8833656,448.03943,-9.2349348
2814,2814,195.4521,4.412982,0.89230978,0.0,0,8.7844028,0.0,0.061431866,52.834846,8.8509445,447.9538,-9.2346992
2825,2825,195.4543,4.3972359,0.92170328,0.0,0,8.7522125,0.0,0.063203327,52.668468,8.8213453,447.8418,-9.2353354
2836,2836,195.4565,4.4129639,0.94834441,0.0,0,8.7214985,0.0,0.065303966,52.604427,8.7914371,447.68372,-9.2350035
2847,2847,195.4587,4.4091029,0.98050356,0.0,0,8.6908836,0.0,0.067458674,52.449265,8.7604647,447.5256,-9.2345734
2858,2858,195.4609,4.4381213,1.0155964,0.0,0,8.6602697,0.0,0.070281729,52.670189,8.7245331,447.36749,-9.2343998
2869,2869,195.4631,4.4696722,1.0475039,0.0,0,8.629653,0.0,0.072218649,52.945885,8.6916571,447.20941,-9.2342701
2880,2880,195.4653,4.4763999,1.0758656,0.0,0,8.5990381,0.0,0.074575119,52.825645,8.659297,446.99203,-9.2337952
2891,2891,195.4675,4.483182,1.1069206,0.0,0,8.5684223,0.0,0.076481968,52.997066,8.6315413,446.76147,-9.2344036
2902,2902,195.4697,4.505537,1.1395955,0.0,0,8.5378084,0.0,0.079137228,53.1385,8.5986462,446.53091,-9.2347441
2913,2913,195.4719,4.531611,1.1714003,0.0,0,8.5071926,0.0,0.081064269,53.325222,8.5713367,446.30035,-9.2343893
2924,2924,195.4741,4.5253887,1.1987977,0.0,0,8.4765778,0.0,0.083427273,52.986557,8.5375252,446.04825,-9.2337961
2935,2935,195.4763,4.5471091,1.2307541,0.0,0,8.445962,0.0,0.085403718,53.207027,8.5049267,445.73865,-9.23353
2946,2946,195.4785,4.5411229,1.2650975,0.0,0,8.4153471,0.0,0.088273689,53.007298,8.4748573,445.42905,-9.2334814
2957,2957,195.4807,4.5504203,1.2984408,0.0,0,8.3847322,0.0,0.09029673,52.962486,8.4420958,445.11945,-9.2339115
2968,2968,195.4829,4.5936093,1.3261664,0.0,0,8.3541164,0.0,0.092680074,53.266357,8.4098215,444.80984,-9.2338095
2979,2979,195.4851,4.6075668,1.3558669,0.0,0,8.3235025,0.0,0.09451557,53.354057,8.3800335,444.41376,-9.2342949
2990,2990,195.4873,4.6165848,1.3868744,0.0,0,8.2928858,0.0,0.097163305,53.258137,8.3494244,443.98529,-9.2338009
3001,3001,195.4895,4.6276331,1.4175521,0.0,0,8.2622709,0.0,0.099066876,53.382488,8.3213425,443.55679,-9.2338495
3012,3012,195.4917,4.6528401,1.4434875,0.0,0,8.2316561,0.0,0.1012786,53.50267,8.2904053,443.1283,-9.2340984
3023,3023,195.4939,4.671545,1.4737796,0.0,0,8.2010412,0.0,0.10318518,53.655434,8.2596016,442.71655,-9.2340078
3034,3034,195.4961,4.7008457,1.5049238,0.0,0,8.1704264,0.0,0.10591772,53.918926,8.2266798,442.38019,-9.2349863
3045,3045,195.4983,4.7160535,1.5399934,0.0,0,8.1398106,0.0,0.10806859,53.897434,8.1946602,442.04385,-9.2351904
3056,3056,195.5005,4.7573485,1.5676186,0.0,0,8.1091957,0.0,0.1106071,54.116379,8.1608744,441.70749,-9.234539
3067,3067,195.5027,4.7880611,1.6021498,0.0,0,8.0785799,0.0,0.11274742,54.35759,8.1307297,441.37115,-9.2346058
3078,3078,195.5049,4.8027806,1.6335095,0.0,0,8.0482779,0.0,0.11557266,54.464371,8.0967932,441.06412,-9.2347374
3089,3089,195.5071,4.8083515,1.6664441,0.0,0,8.0191498,0.0,0.11744672,54.505119,8.0638618,440.7738,-9.2344933
3100,3100,195.5093,4.827744,1.6926764,0.0,0,7.9900212,0.0,0.11991059,54.54488,8.0341053,440.48352,-9.2351751
3111,3111,195.5115,4.8174586,1.7241247,0.0,0,7.9608936,0.0,0.12180361,54.322975,8.0022144,440.19324,-9.2336435
3122,3122,195.5137,4.8045359,1.7521608,0.0,0,7.9317656,0.0,0.12444591,54.074776,7.9779124,439.90353,-9.2338991
3133,3133,195.5159,4.7938414,1.7796632,0.0,0,7.9026375,0.0,0.12602538,53.820679,7.9521775,439.61984,-9.2350779
3144,3144,195.5181,4.8150101,1.8022268,0.0,0,7.8735094,0.0,0.12817024,53.952892,7.9226842,439.33615,-9.2350483
3155,3155,195.5203,4.8463268,1.8305881,0.0,0,7.8443813,0.0,0.12993549,54.231133,7.8917289,439.05246,-9.2348652
3166,3166,195.5225,4.8918905,1.8596561,0.0,0,7.8152533,0.0,0.13265355,54.498264,7.8673263,438.76874,-9.2342386
3177,3177,195.5247,4.9263277,1.8936918,0.0,0,7.7861252,0.0,0.13462861,54.78828,7.8358126,438.6254,-9.2341566
3188,3188,195.5269,4.9500194,1.9183333,0.0,0,7.7569971,0.0,0.13707325,54.977955,7.8080692,438.599,-9.2335968
3199,3199,195.5291,4.9848719,1.9508132,0.0,0,7.7278695,0.0,0.13904959,55.235458,7.7764673,438.57263,-9.2333088
3210,3210,195.5313,4.9767079,1.97703,0.0,0,7.6987414,0.0,0.1415922,55.116547,7.7452288,438.54623,-9.2337952
3221,3221,195.5335,4.9849195,2.0115621,0.0,0,7.6696134,0.0,0.14358875,54.980305,7.7153726,438.51984,-9.2347393
3232,3232,195.5357,4.9981647,2.0352647,0.0,0,7.6404853,0.0,0.14608674,55.03022,7.6871524,438.6452,-9.2334003
3243,3243,195.5379,5.0084014,2.0671947,0.0,0,7.6113577,0.0,0.14789946,54.953098,7.6530676,438.77054,-9.2352209
3254,3254,195.5401,5.0385246,2.093822,0.0,0,7.5822296,0.0,0.15064304,55.174545,7.6288943,438.8959,-9.2343855
3265,3265,195.5423,5.0537596,2.1264381,0.0,0,7.5531015,0.0,0.15249693,55.357536,7.6000366,439.02124,-9.2343292
3276,3276,195.5445,5.0742822,2.1485248,0.0,0,7.523973,0.0,0.15485682,55.345459,7.5718513,439.17661,-9.2343922
3287,3287,195.5467,5.1045022,2.1804168,0.0,0,7.4948454,0.0,0.1567681,55.552834,7.5439825,439.36792,-9.2343931
3298,3298,195.5489,5.1245713,2.206877,0.0,0,7.4657173,0.0,0.15946752,55.583084,7.5161633,439.55923,-9.2341824
3309,3309,195.5511,5.1483746,2.2414308,0.0,0,7.4365897,0.0,0.16146332,55.838104,7.4843154,439.75058,-9.2340355
3320,3320,195.5533,5.1571169,2.2664104,0.0,0,7.4074612,0.0,0.16411422,55.725544,7.4523125,439.94189,-9.2350454
3331,3331,195.5555,5.1710601,2.2977777,0.0,0,7.3790221,0.0,0.16597392,55.76115,7.4245229,440.02527,-9.2343369
3342,3342,195.5577,5.1960797,2.3246179,0.0,0,7.3513193,0.0,0.16873339,55.915779,7.3932548,440.09784,-9.2341461
3353,3353,195.5599,5.2508354,2.3604202,0.0,0,7.323617,0.0,0.17075266,56.347919,7.3654141,440.17041,-9.2343206
3364,3364,195.5621,5.2600794,2.3838377,0.0,0,7.2959146,0.0,0.17331828,56.380573,7.3331561,440.24301,-9.2345266
3375,3375,195.5643,5.2653522,2.4157591,0.0,0,7.2682123,0.0,0.17531922,56.266201,7.304985,440.25079,-9.2347898
3386,3386,195.5665,5.2542768,2.4414258,0.0,0,7.24051,0.0,0.17797378,56.028267,7.2747812,440.14523,-9.2344303
3397,3397,195.5687,5.2794137,2.4752443,0.0,0,7.2128077,0.0,0.17987184,56.150799,7.2450256,440.0397,-9.2345133
3408,3408,195.5709,5.2821946,2.4969454,0.0,0,7.1851048,0.0,0.18228795,56.047974,7.2209949,439.93414,-9.2347403
3419,3419,195.5731,5.2900171,2.5267892,0.0,0,7.157403,0.0,0.18421674,56.052448,7.190846,439.82858,-9.2344866
3430,3430,195.5753,5.3289318,2.5534296,0.0,0,7.1297007,0.0,0.18691166,56.247581,7.1637421,439.66904,-9.2330446
3441,3441,195.5775,5.3574486,2.5875933,0.0,0,7.1019974,0.0,0.18891992,56.421391,7.1314554,439.4975,-9.233696
3452,3452,195.5797,5.377347,2.6082442,0.0,0,7.0742955,0.0,0.19129649,56.589214,7.1049418,439.32596,-9.2337894
3463,3463,195.5819,5.3690934,2.6386187,0.0,0,7.0465932,0.0,0.19310422,56.376713,7.0760736,439.15442,-9.2340622
3474,3474,195.5841,5.3699565,2.6619174,0.0,0,7.0188909,0.0,0.1956806,56.238384,7.0501037,438.9541,-9.2346821
3485,3485,195.5863,5.3897157,2.6964474,0.0,0,6.991188,0.0,0.19767009,56.307632,7.0219164,438.677,-9.2340879
3496,3496,195.5885,5.3977475,2.7135463,0.0,0,6.9634857,0.0,0.19982873,56.314442,6.9977965,438.3999,-9.2337608
3507,3507,195.5907,5.4027519,2.7406695,0.0,0,6.9357834,0.0,0.20156762,56.2957,6.9728603,438.1228,-9.2346115
3518,3518,195.5929,5.4207668,2.7649245,0.0,0,6.9080811,0.0,0.20409663,56.24522,6.9450665,437.8457,-9.233882
3529,3529,195.5951,5.462801,2.8002245,0.0,0,6.8803787,0.0,0.2062054,56.595173,6.9163628,437.58301,-9.2338181
3540,3540,195.5973,5.5240517,2.8208859,0.0,0,6.8526764,0.0,0.20858167,56.991348,6.8870311,437.32568,-9.2335138
3551,3551,195.5995,5.5591736,2.850543,0.0,0,6.8249741,0.0,0.21049175,57.381828,6.8567953,437.06839,-9.2349319
3562,3562,195.6017,5.5664496,2.8780084,0.0,0,6.7972713,0.0,0.21331759,57.326382,6.8304472,436.81107,-9.2348976
3573,3573,195.6039,5.5784383,2.9147069,0.0,0,6.7695689,0.0,0.21555482,57.279556,6.803237,436.5058,-9.2340059
3584,3584,195.6061,5.5884757,2.9359498,0.0,0,6.7428842,0.0,0.21803004,57.161869,6.7750802,435.98459,-9.2346373
3595,3595,195.6083,5.6056209,2.9642606,0.0,0,6.7165279,0.0,0.21986778,57.316322,6.744679,435.46338,-9.2346735
3606,3606,195.6105,5.603446,2.9892457,0.0,0,6.6901722,0.0,0.22258388,57.152298,6.7180824,434.94217,-9.2340117
3617,3617,195.6127,5.6186776,3.0250709,0.0,0,6.663816,0.0,0.22481462,57.126518,6.6883783,434.42096,-9.234664
3628,3628,195.6149,5.6534429,3.0434575,0.0,0,6.6374598,0.0,0.22691517,57.367821,6.6618705,433.89554,-9.233264
3639,3639,195.6171,5.6820641,3.0732448,0.0,0,6.611104,0.0,0.22906581,57.551102,6.6329789,433.36774,-9.2340593
3650,3650,195.6193,5.6934037,3.0976026,0.0,0,6.5847478,0.0,0.23161231,57.435459,6.6105599,432.8399,-9.2353039
3661,3661,195.6215,5.6824136,3.1321733,0.0,0,6.558392,0.0,0.23371813,57.286232,6.5815706,432.3121,-9.2342882
3672,3672,195.6237,5.703095,3.1483836,0.0,0,6.5320363,0.0,0.23581365,57.301762,6.5561271,431.83167,-9.2341137
3683,3683,195.6259,5.7012043,3.1767395,0.0,0,6.5056801,0.0,0.23770112,57.186085,6.5310879,431.82507,-9.2354164
3694,3694,195.6281,5.7231712,3.1996832,0.0,0,6.4793239,0.0,0.24024741,57.355801,6.5057421,431.81848,-9.2340946
3705,3705,195.6303,5.746686,3.2316453,0.0,0,6.4529681,0.0,0.24221148,57.4067,6.4782352,431.81189,-9.2351103
3716,3716,195.6325,5.760385,3.250963,0.0,0,6.4266124,0.0,0.24448983,57.396427,6.4542856,431.8053,-9.234971
3727,3727,195.6347,5.8006067,3.2798917,0.0,0,6.4002562,0.0,0.24647221,57.727623,6.4300103,431.88867,-9.2330847
3738,3738,195.6369,5.8281646,3.300559,0.0,0,6.3738999,0.0,0.24885592,57.850182,6.4053545,432.04703,-9.2343445
3749,3749,195.6391,5.8568826,3.3353508,0.0,0,6.3475442,0.0,0.25108203,58.061031,6.3743272,432.20535,-9.2335787
3760,3760,195.6413,5.8760319,3.3550081,0.0,0,6.3211884,0.0,0.25340462,58.134384,6.34937,432.36371,-9.2337923
3771,3771,195.6435,5.9114146,3.3856897,0.0,0,6.2948327,0.0,0.25553873,58.323246,6.3205371,432.52203,-9.2336617
3782,3782,195.6457,5.9315834,3.4104016,0.0,0,6.2684765,0.0,0.25821689,58.337444,6.2918897,432.621,-9.2342787
3793,3793,195.6479,5.9426446,3.4473064,0.0,0,6.2421203,0.0,0.26077032,58.222893,6.2649784,432.71997,-9.2346811
3804,3804,195.6501,5.9601417,3.4683118,0.0,0,6.2157645,0.0,0.26311213,58.274536,6.2366538,432.81891,-9.2344637
3815,3815,195.6523,5.9625797,3.4945905,0.0,0,6.1894083,0.0,0.26503688,58.222546,6.2117167,432.91788,-9.2342672
3826,3826,195.6545,5.9852538,3.5170412,0.0,0,6.1631007,0.0,0.26738495,58.278931,6.186594,432.98987,-9.232543
3837,3837,195.6567,5.9993887,3.5500891,0.0,0,6.1380219,0.0,0.26973626,58.394459,6.1604824,433.02945,-9.2343149
3848,3848,195.6589,5.9946885,3.5681789,0.0,0,6.1129556,0.0,0.27181706,58.174568,6.1335616,433.06903,-9.2351389
3859,3859,195.6611,6.0034032,3.5946226,0.0,0,6.0878887,0.0,0.27379569,58.208324,6.1144404,433.10861,-9.234292
3870,3870,195.6633,6.0512142,3.616384,0.0,0,6.0628219,0.0,0.2761046,58.459717,6.0853915,433.14819,-9.2341537
3881,3881,195.6655,6.0777159,3.6501272,0.0,0,6.037755,0.0,0.27848661,58.581341,6.0573363,433.1398,-9.2327843
3892,3892,195.6677,6.0952363,3.6709173,0.0,0,6.0126886,0.0,0.28075752,58.70602,6.0341239,433.12662,-9.2349386
3903,3903,195.6699,6.0948515,3.6979537,0.0,0,5.9876213,0.0,0.28284007,58.475666,6.0039549,433.1134,-9.2350807
3914,3914,195.6721,6.1239681,3.7191057,0.0,0,5.9625545,0.0,0.28518105,58.567204,5.9838171,433.10022,-9.2336884
3925,3925,195.6743,6.1528258,3.7496321,0.0,0,5.9374876,0.0,0.28735793,58.757175,5.9574957,433.06064,-9.2330704
3936,3936,195.6765,6.1652231,3.7682126,0.0,0,5.9124212,0.0,0.28948429,58.791264,5.9303837,432.97485,-9.2337265
3947,3947,195.6787,6.1630254,3.7954259,0.0,0,5.8873544,0.0,0.29149416,58.684711,5.9091549,432.8891,-9.2352037
3958,3958,195.6809,6.1797471,3.8142009,0.0,0,5.8622875,0.0,0.29353264,58.687653,5.8853793,432.80331,-9.2342958
3969,3969,195.6831,6.2022734,3.8474374,0.0,0,5.8372207,0.0,0.29604584,58.810581,5.8585973,432.71756,-9.2347221
3980,3980,195.6853,6.2301888,3.8665161,0.0,0,5.8121538,0.0,0.29819682,58.803444,5.8348083,432.69116,-9.2353277
3991,3991,195.6875,6.26056,3.8950427,0.0,0,5.787087,0.0,0.30042961,59.081146,5.8090816,432.67798,-9.2345161
4002,4002,195.6897,6.2976952,3.9160762,0.0,0,5.7620201,0.0,0.30256566,59.169979,5.7832594,432.66479,-9.2332268
4013,4013,195.6919,6.3260589,3.9453552,0.0,0,5.7369533,0.0,0.30492678,59.351681,5.7587304,432.65158,-9.2326422
4024,4024,195.6941,6.3554835,3.9655046,0.0,0,5.7118864,0.0,0.30722609,59.524117,5.7322111,432.6456,-9.2326317
4035,4035,195.6963,6.3706574,3.9931669,0.0,0,5.6868196,0.0,0.30934888,59.658611,5.7067251,432.65878,-9.2340498
4046,4046,195.6985,6.360095,4.0125642,0.0,0,5.6617532,0.0,0.31145495,59.264366,5.6860514,432.672,-9.2337952
4057,4057,195.7007,6.3891277,4.0458312,0.0,0,5.6366854,0.0,0.31409785,59.400909,5.6567192,432.68518,-9.2325783
4068,4068,195.7029,6.4171557,4.0669546,0.0,0,5.6116195,0.0,0.31628415,59.556034,5.6319799,432.69836,-9.2322865
4079,4079,195.7051,6.4609294,4.0945773,0.0,0,5.5869198,0.0,0.31868252,59.862988,5.6098728,432.71637,-9.233737
4090,4090,195.7073,6.4926629,4.1173511,0.0,0,5.5630717,0.0,0.32097572,59.928802,5.5786543,432.73615,-9.2334709
4101,4101,195.7095,6.5287285,4.1507258,0.0,0,5.5392232,0.0,0.3236534,60.234608,5.553391,432.75595,-9.233716
4112,4112,195.7117,6.5643883,4.1703811,0.0,0,5.5153751,0.0,0.32574806,60.364117,5.5246892,432.77573,-9.2348251
4123,4123,195.7139,6.570179,4.1987481,0.0,0,5.4915276,0.0,0.32823378,60.228947,5.5018415,432.78952,-9.2343054
4134,4134,195.7161,6.5547309,4.2201986,0.0,0,5.4676795,0.0,0.3303999,59.996166,5.4790182,432.77634,-9.2339058
4145,4145,195.7183,6.5381193,4.2501597,0.0,0,5.4438314,0.0,0.3329969,59.647976,5.4536409,432.76315,-9.2337923
4156,4156,195.7205,6.5454388,4.2685819,0.0,0,5.4199839,0.0,0.3349123,59.501865,5.4274535,432.74994,-9.2334585
4167,4167,195.7227,6.5598774,4.2938371,0.0,0,5.3961358,0.0,0.33716321,59.602348,5.4031258,432.73676,-9.2338209
4178,4178,195.7249,6.5909967,4.3130288,0.0,0,5.3722878,0.0,0.33906022,59.713295,5.3844547,432.66898,-9.2338409
4189,4189,195.7271,6.6172452,4.3420143,0.0,0,5.3484397,0.0,0.34163764,59.822495,5.3616066,432.57001,-9.2345858
4200,4200,195.7293,6.6640506,4.3590569,0.0,0,5.3245916,0.0,0.34338069,60.111526,5.3411632,432.47104,-9.2332249
4211,4211,195.7315,6.6967893,4.3849688,0.0,0,5.3007436,0.0,0.34573308,60.337177,5.3160648,432.37207,-9.2341814
4222,4222,195.7337,6.7298245,4.406796,0.0,0,5.276896,0.0,0.34779653,60.454605,5.2891483,432.2677,-9.2331753
4233,4233,195.7359,6.7249546,4.4370446,0.0,0,5.2530475,0.0,0.3505643,60.336357,5.2671204,432.10938,-9.2331762
4244,4244,195.7381,6.7155256,4.4542336,0.0,0,5.2291994,0.0,0.35230321,60.074005,5.2433577,431.95102,-9.2345133
4255,4255,195.7403,6.7471943,4.4810047,0.0,0,5.2053518,0.0,0.35482526,60.297951,5.2218962,431.79269,-9.2342262
4266,4266,195.7425,6.7907143,4.5012574,0.0,0,5.1815038,0.0,0.35677198,60.527489,5.2003889,431.63434,-9.2333107
4277,4277,195.7447,6.8436303,4.5306954,0.0,0,5.1576557,0.0,0.35961884,60.784416,5.1681395,431.48682,-9.2329311
4288,4288,195.7469,6.8771291,4.5516086,0.0,0,5.1338077,0.0,0.36160925,61.019161,5.1452994,431.34827,-9.2337179
4299,4299,195.7491,6.9032431,4.5759845,0.0,0,5.1099596,0.0,0.36394444,61.077721,5.1217265,431.20972,-9.2343931
4310,4310,195.7513,6.9096322,4.5974131,0.0,0,5.0861115,0.0,0.36600199,61.046082,5.0999684,431.07117,-9.2334938
4321,4321,195.7535,6.9068489,4.629065,0.0,0,5.062264,0.0,0.36896712,60.862911,5.0761786,430.93262,-9.233057
4332,4332,195.7557,6.9169488,4.6470313,0.0,0,5.0390849,0.0,0.37071049,60.769192,5.0488811,430.85345,-9.2329473
4343,4343,195.7579,6.9180326,4.672245,0.0,0,5.0164027,0.0,0.37320471,60.678265,5.0274954,430.77429,-9.2343559
4354,4354,195.7601,6.9407463,4.691515,0.0,0,4.993721,0.0,0.37501946,60.706078,5.0037475,430.6951,-9.2343149
4365,4365,195.7623,6.9996076,4.7202935,0.0,0,4.9710388,0.0,0.37789541,61.064613,4.9815249,430.61594,-9.2337503
4376,4376,195.7645,7.0254793,4.740489,0.0,0,4.9483566,0.0,0.37963906,61.109261,4.9575706,430.51578,-9.2324228
4387,4387,195.7667,7.0243006,4.7612295,0.0,0,4.9256749,0.0,0.38197348,61.018005,4.9365082,430.39041,-9.233057
4398,4398,195.7689,7.0477996,4.7831626,0.0,0,4.9029927,0.0,0.38391086,61.098156,4.9116502,430.26508,-9.2327824
4409,4409,195.7711,7.0766454,4.8098226,0.0,0,4.880311,0.0,0.38671821,61.164391,4.8911562,430.13971,-9.2328987
4420,4420,195.7733,7.1050034,4.8301034,0.0,0,4.8576288,0.0,0.38848901,61.274975,4.8694143,430.01434,-9.2337837
4431,4431,195.7755,7.1227093,4.8534689,0.0,0,4.8349466,0.0,0.39093792,61.334343,4.8485584,429.89499,-9.2337732
4442,4442,195.7777,7.1370182,4.8746071,0.0,0,4.8122649,0.0,0.39289218,61.434208,4.823627,429.77625,-9.2325363
4453,4453,195.7799,7.1668057,4.9023566,0.0,0,4.7895827,0.0,0.395827,61.410294,4.797348,429.6575,-9.2330503
4464,4464,195.7821,7.202713,4.9241533,0.0,0,4.766901,0.0,0.39768997,61.543762,4.7787638,429.53873,-9.2335768
4475,4475,195.7843,7.2063456,4.9454575,0.0,0,4.7442188,0.0,0.40014076,61.492336,4.7537556,429.43439,-9.2333193
4486,4486,195.7865,7.2259188,4.9667439,0.0,0,4.7215366,0.0,0.40196714,61.536888,4.7285662,429.35519,-9.2321291
4497,4497,195.7887,7.2471833,4.9901247,0.0,0,4.6988549,0.0,0.40463158,61.550541,4.7080035,429.27603,-9.2333927
4508,4508,195.7909,7.2545271,5.0101418,0.0,0,4.6761732,0.0,0.40627217,61.585419,4.6879678,429.19687,-9.2341318
4519,4519,195.7931,7.2702398,5.0311313,0.0,0,4.6534905,0.0,0.40877852,61.546745,4.6666074,429.11771,-9.234045
4530,4530,195.7953,7.272337,5.0500569,0.0,0,4.6308088,0.0,0.41025978,61.418495,4.646986,429.01694,-9.233901
4541,4541,195.7975,7.3074198,5.0765576,0.0,0,4.6081266,0.0,0.41344512,61.477734,4.626781,428.91138,-9.2347212
4552,4552,195.7997,7.3872461,5.0992627,0.0,0,4.5854449,0.0,0.41508418,62.038097,4.6007352,428.80582,-9.2337732
4563,4563,195.8019,7.45294,5.1203094,0.0,0,4.5627627,0.0,0.41774121,62.492142,4.5758018,428.70026,-9.2339077
4574,4574,195.8041,7.4718757,5.1415353,0.0,0,4.5400805,0.0,0.4194555,62.497868,4.5534964,428.57666,-9.2338743
4585,4585,195.8063,7.492559,5.1691566,0.0,0,4.5183334,0.0,0.42276475,62.522591,4.5284696,428.405,-9.2335749
4596,4596,195.8085,7.5357733,5.1928096,0.0,0,4.4967556,0.0,0.42466733,62.682808,4.5059128,428.23334,-9.2346344
4607,4607,195.8107,7.5582204,5.2140207,0.0,0,4.4751782,0.0,0.4272404,62.73571,4.4799552,428.06171,-9.2326412
4618,4618,195.8129,7.5407681,5.2391696,0.0,0,4.4536009,0.0,0.4293161,62.510399,4.4556479,427.89005,-9.2337008
4629,4629,195.8151,7.528501,5.2649722,0.0,0,4.432023,0.0,0.43262768,62.168098,4.4314613,426.68488,-9.2348614
4640,4640,195.8173,7.5231013,5.2854662,0.0,0,4.4104452,0.0,0.4339996,61.962757,4.4168687,425.09213,-9.2344532
4651,4651,195.8195,7.5466089,5.3024001,0.0,0,4.3888679,0.0,0.43638,62.108307,4.395277,423.49939,-9.2333117
4662,4662,195.8217,7.5778861,5.3229222,0.0,0,4.36729,0.0,0.4379448,62.272182,4.3762546,421.90665,-9.2338524
4673,4673,195.8239,7.6104832,5.3462253,0.0,0,4.3457127,0.0,0.4409591,62.304478,4.3518915,420.24527,-9.2336121
4684,4684,195.8261,7.6431546,5.3669276,0.0,0,4.3241353,0.0,0.44240075,62.556202,4.3325782,418.27505,-9.2344236
4695,4695,195.8283,7.694798,5.3874626,0.0,0,4.3025579,0.0,0.44521067,62.736168,4.3124638,416.30484,-9.2343664
4706,4706,195.8305,7.7096992,5.4098721,0.0,0,4.2809801,0.0,0.44697726,62.799988,4.2875409,414.33466,-9.2349005
4717,4717,195.8327,7.7116632,5.4324121,0.0,0,4.2594023,0.0,0.45000607,62.657085,4.2618728,412.36444,-9.2338629
4728,4728,195.8349,7.7431192,5.4556422,0.0,0,4.2378249,0.0,0.45163614,62.724934,4.2453523,411.27734,-9.2330799
4739,4739,195.8371,7.769969,5.4747305,0.0,0,4.2162471,0.0,0.45435297,62.696953,4.2247272,410.69489,-9.2333775
4750,4750,195.8393,7.8338547,5.4958539,0.0,0,4.1946697,0.0,0.45590019,63.217857,4.205976,410.1124,-9.2339077
4761,4761,195.8415,7.8493352,5.5188394,0.0,0,4.1730919,0.0,0.45912898,63.066994,4.1820893,409.52994,-9.2339687
4772,4772,195.8437,7.8725152,5.5438237,0.0,0,4.1515145,0.0,0.4609184,63.171566,4.1619487,408.99622,-9.2329512
4783,4783,195.8459,7.8921013,5.5616264,0.0,0,4.1299367,0.0,0.46357065,63.25914,4.1391411,408.94986,-9.2330246
4794,4794,195.8481,7.9159551,5.5851688,0.0,0,4.1083593,0.0,0.46528026,63.316006,4.1174192,408.9035,-9.2340775
4805,4805,195.8503,7.9349933,5.6054111,0.0,0,4.0867815,0.0,0.46829656,63.226501,4.0928946,408.85715,-9.233182
4816,4816,195.8525,7.9515219,5.6311984,0.0,0,4.0652041,0.0,0.47021458,63.253105,4.0714889,408.81079,-9.2345858
4827,4827,195.8547,8.0065451,5.6485543,0.0,0,4.0437527,0.0,0.47285235,63.485619,4.0500274,409.06418,-9.233674
4838,4838,195.8569,8.0386362,5.6725373,0.0,0,4.0232306,0.0,0.47458011,63.670219,4.0302706,409.56732,-9.2331629
4849,4849,195.8591,8.0780993,5.6939726,0.0,0,4.0027089,0.0,0.47776514,63.719368,4.0047531,410.0705,-9.2323875
4860,4860,195.8613,8.0768938,5.7192731,0.0,0,3.9821873,0.0,0.47949949,63.708057,3.9835849,410.57364,-9.2336159
4871,4871,195.8635,8.0861168,5.7332792,0.0,0,3.9616656,0.0,0.48207831,63.59959,3.9662404,411.07678,-9.2338676
4882,4882,195.8657,8.1066885,5.7561107,0.0,0,3.9411442,0.0,0.48366082,63.649235,3.9463973,411.63272,-9.2337675
4893,4893,195.8679,8.1335268,5.7768326,0.0,0,3.9206226,0.0,0.48687536,63.640976,3.9228525,412.18866,-9.2330484
4904,4904,195.8701,8.1611242,5.8042078,0.0,0,3.9001009,0.0,0.48868096,63.744358,3.8980641,412.7446,-9.2337637
4915,4915,195.8723,8.1884003,5.8197827,0.0,0,3.8795795,0.0,0.49143425,63.793365,3.880476,413.30054,-9.2337646
4926,4926,195.8745,8.1972332,5.840909,0.0,0,3.8590579,0.0,0.49281281,63.779152,3.8590989,413.60977,-9.2340498
4937,4937,195.8767,8.2277889,5.8597131,0.0,0,3.8385363,0.0,0.49585626,63.73262,3.8378987,413.62299,-9.2349882
4948,4948,195.8789,8.2486763,5.884316,0.0,0,3.8180146,0.0,0.49748495,63.873291,3.8173673,413.6362,-9.2344637
4959,4959,195.8811,8.2774487,5.8993049,0.0,0,3.797493,0.0,0.50016588,63.946888,3.7990735,413.64941,-9.2343636
4970,4970,195.8833,8.2876091,5.9221849,0.0,0,3.7769713,0.0,0.50178468,63.921608,3.7811992,413.66263,-9.233716
4981,4981,195.8855,8.3309479,5.9425707,0.0,0,3.7564499,0.0,0.50509685,63.962502,3.7597747,413.63379,-9.2331324
4992,4992,195.8877,8.3779039,5.967917,0.0,0,3.7359283,0.0,0.5066523,64.281113,3.739264,413.60074,-9.2336645
5003,5003,195.8899,8.4023752,5.9829693,0.0,0,3.7154067,0.0,0.50932091,64.292419,3.7163436,413.56769,-9.2340183
5014,5014,195.8921,8.4417076,6.007813,0.0,0,3.694885,0.0,0.51113093,64.448647,3.6942108,413.53464,-9.2346363
5025,5025,195.8943,8.4739857,6.0266867,0.0,0,3.6743636,0.0,0.51435584,64.503807,3.6726072,413.48956,-9.2344227
5036,5036,195.8965,8.5197506,6.0542569,0.0,0,3.6538417,0.0,0.51618052,64.692749,3.6504059,413.42349,-9.2350321
5047,5047,195.8987,8.5193987,6.0666304,0.0,0,3.6333201,0.0,0.51886076,64.62957,3.6350045,413.35739,-9.2343464
5058,5058,195.9009,8.5326405,6.0914736,0.0,0,3.6127987,0.0,0.52053112,64.55574,3.6125278,413.29129,-9.2331104
5069,5069,195.9031,8.5284815,6.1104403,0.0,0,3.5922771,0.0,0.52386755,64.275276,3.5934319,413.22522,-9.2331238
5080,5080,195.9053,8.5329142,6.137445,0.0,0,3.5721471,0.0,0.525455,64.240067,3.5729673,413.08881,-9.2342834
5091,5091,195.9075,8.5542679,6.1473174,0.0,0,3.5526242,0.0,0.52782661,64.276878,3.5576043,412.93677,-9.2345753
5102,5102,195.9097,8.5808125,6.1683426,0.0,0,3.5331016,0.0,0.52911657,64.350113,3.5358126,412.7847,-9.2337036
5113,5113,195.9119,8.6298447,6.1838155,0.0,0,3.5135787,0.0,0.53203958,64.534836,3.5153334,412.63266,-9.2347488
5124,5124,195.9141,8.6848364,6.2117062,0.0,0,3.4940557,0.0,0.53375703,64.789566,3.4956474,412.47876,-9.2344666
5135,5135,195.9163,8.7551126,6.224978,0.0,0,3.4745328,0.0,0.53664124,65.247803,3.4762609,412.31982,-9.2336893
5146,5146,195.9185,8.7768135,6.2507348,0.0,0,3.4550104,0.0,0.5385589,65.173645,3.4576714,412.16092,-9.2338037
5157,5157,195.9207,8.7832384,6.2687478,0.0,0,3.4354873,0.0,0.54166871,65.005508,3.4334605,412.00201,-9.2334986
5168,5168,195.9229,8.7923927,6.2955585,0.0,0,3.4159648,0.0,0.54335338,64.998444,3.4086077,411.84308,-9.2343721
5179,5179,195.9251,8.8228512,6.3065686,0.0,0,3.3964417,0.0,0.54594761,65.013565,3.3917921,411.47226,-9.2344542
5190,5190,195.9273,8.8469257,6.3321471,0.0,0,3.376919,0.0,0.54791498,65.026154,3.3720984,411.02194,-9.2334642
5201,5201,195.9295,8.850337,6.3480682,0.0,0,3.3573964,0.0,0.55087709,64.932259,3.352782,410.57166,-9.2343416
5212,5212,195.9317,8.8763857,6.3759465,0.0,0,3.3378732,0.0,0.55268866,65.027863,3.3351183,410.12137,-9.2331924
5223,5223,195.9339,8.8965139,6.3842521,0.0,0,3.3183508,0.0,0.55499655,65.077713,3.3170578,409.67105,-9.2327909
5234,5234,195.9361,8.9305611,6.405488,0.0,0,3.2988276,0.0,0.55654407,65.203957,3.2996678,409.22076,-9.2337065
5245,5245,195.9383,8.9320841,6.4222422,0.0,0,3.2793047,0.0,0.55941617,65.009689,3.279779,408.77045,-9.2330112
5256,5256,195.9405,8.9562454,6.4482856,0.0,0,3.2597823,0.0,0.561068,65.061646,3.2598274,408.32016,-9.233057
5267,5267,195.9427,8.9745245,6.4602642,0.0,0,3.2402592,0.0,0.56386793,65.025276,3.2419815,407.86987,-9.2331152
5278,5278,195.9449,9.0211821,6.4846787,0.0,0,3.2207365,0.0,0.56575221,65.269859,3.2231569,407.77774,-9.2341557
5289,5289,195.9471,9.082407,6.4980917,0.0,0,3.2012138,0.0,0.56826437,65.516808,3.2048106,407.89032,-9.2322512
5300,5300,195.9493,9.1279354,6.5269399,0.0,0,3.1816909,0.0,0.57032597,65.711456,3.1842611,408.0029,-9.2327051
5311,5311,195.9515,9.1920729,6.5374284,0.0,0,3.1621683,0.0,0.57294124,65.979111,3.1635833,408.11548,-9.2328815
5322,5322,195.9537,9.2198238,6.5620289,0.0,0,3.1426454,0.0,0.57480371,66.068794,3.1479542,408.22141,-9.2335968
5333,5333,195.9559,9.2564602,6.5786242,0.0,0,3.1237545,0.0,0.57798564,66.205093,3.1239367,408.26114,-9.2331877
5344,5344,195.9581,9.2759228,6.6074529,0.0,0,3.1051819,0.0,0.5799008,66.135414,3.1059415,408.30087,-9.2329826
5355,5355,195.9603,9.3272696,6.6188111,0.0,0,3.0866094,0.0,0.58250296,66.315544,3.0823843,408.34061,-9.2345877
5366,5366,195.9625,9.353754,6.6435714,0.0,0,3.0680368,0.0,0.58453578,66.397293,3.0617142,408.38034,-9.2325296
5377,5377,195.9647,9.3833637,6.6642356,0.0,0,3.0494645,0.0,0.58813775,66.326866,3.0427926,408.27921,-9.2328863
5388,5388,195.9669,9.3999939,6.6940203,0.0,0,3.0308924,0.0,0.5902372,66.332733,3.0210433,408.06067,-9.2339106
5399,5399,195.9691,9.4067535,6.7033896,0.0,0,3.0123198,0.0,0.5926795,66.205376,3.002151,407.84216,-9.2333603
5410,5410,195.9713,9.4062738,6.7232223,0.0,0,2.9937477,0.0,0.59417665,66.161484,2.983197,407.62363,-9.2326088
5421,5421,195.9735,9.4061413,6.7380214,0.0,0,2.9751751,0.0,0.597004,65.940834,2.9664965,407.40509,-9.2329979
5432,5432,195.9757,9.3852768,6.7639413,0.0,0,2.9566026,0.0,0.59881455,65.680862,2.9487367,406.8356,-9.2337656
5443,5443,195.9779,9.361661,6.7717705,0.0,0,2.93803,0.0,0.60093153,65.381172,2.9307842,406.26608,-9.2346554
5454,5454,195.9801,9.3904905,6.7931557,0.0,0,2.9194577,0.0,0.60260928,65.439529,2.9172072,405.69659,-9.2331667
5465,5465,195.9823,9.4391088,6.8062673,0.0,0,2.9008856,0.0,0.60522032,65.594788,2.8984442,405.12711,-9.2315178
5476,5476,195.9845,9.4848194,6.830987,0.0,0,2.882313,0.0,0.60697186,65.826683,2.879844,404.78937,-9.2329569
5487,5487,195.9867,9.5450802,6.8395133,0.0,0,2.8637407,0.0,0.60913014,66.05555,2.8663607,404.7298,-9.2324095
5498,5498,195.9889,9.6061401,6.8633504,0.0,0,2.8451684,0.0,0.61119998,66.38028,2.8467183,404.6702,-9.2325373
5509,5509,195.9911,9.6740198,6.8773627,0.0,0,2.8265958,0.0,0.61402839,66.6259,2.8320966,404.6106,-9.2325773
5520,5520,195.9933,9.7196302,6.9079218,0.0,0,2.8080232,0.0,0.61647254,66.792229,2.8063867,404.55103,-9.2331133
5531,5531,195.9955,9.7690296,6.9186664,0.0,0,2.7894509,0.0,0.61883295,66.974937,2.7879965,404.52753,-9.2323351
5542,5542,195.9977,9.7581148,6.942944,0.0,0,2.7708786,0.0,0.62101716,66.7509,2.7703881,404.50766,-9.2337303
5553,5553,195.9999,9.7698946,6.9579067,0.0,0,2.7523062,0.0,0.6239363,66.661469,2.7529798,404.48779,-9.2340527
5564,5564,196.0021,9.8010063,6.98457,0.0,0,2.7337339,0.0,0.62599546,66.683914,2.7311635,404.4679,-9.2329025
5575,5575,196.0043,9.8498611,6.9937296,0.0,0,2.7151613,0.0,0.62820846,66.872932,2.7102468,404.2626,-9.233799
5586,5586,196.0065,9.8845749,7.0178843,0.0,0,2.697439,0.0,0.63041526,66.961349,2.6901038,403.73285,-9.234334
5597,5597,196.0087,9.9006348,7.0288005,0.0,0,2.6797729,0.0,0.6326912,66.939133,2.6781261,403.20309,-9.2332745
5608,5608,196.0109,9.940958,7.0579939,0.0,0,2.6621068,0.0,0.63523322,67.017654,2.6577322,402.67334,-9.2319736
5619,5619,196.0131,9.9715996,7.0681314,0.0,0,2.6444409,0.0,0.63756239,67.147285,2.6403503,402.14355,-9.2339916
5630,5630,196.0153,9.9908161,7.0917096,0.0,0,2.626775,0.0,0.6398204,67.132698,2.6242754,401.35864,-9.2341404
5641,5641,196.0175,10.009097,7.1045122,0.0,0,2.6091087,0.0,0.64226878,67.053055,2.6029551,400.51703,-9.2335768
5652,5652,196.0197,10.036916,7.1335301,0.0,0,2.5914428,0.0,0.64480019,67.081429,2.5868051,399.67538,-9.2341938
5663,5663,196.0219,10.087024,7.1425624,0.0,0,2.573777,0.0,0.64697862,67.234596,2.5667467,398.83377,-9.2337875
5674,5674,196.0241,10.084791,7.1628542,0.0,0,2.5561109,0.0,0.6487745,67.055176,2.551096,397.91614,-9.2331562
5685,5685,196.0263,10.098078,7.1763,0.0,0,2.538445,0.0,0.65122616,67.062302,2.5345042,396.79575,-9.2334766
5696,5696,196.0285,10.132621,7.2035999,0.0,0,2.5207789,0.0,0.65385753,67.08889,2.5130773,395.67538,-9.2334127
5707,5707,196.0307,10.17136,7.2112956,0.0,0,2.5031128,0.0,0.65576464,67.227089,2.4970477,394.55502,-9.2328243
5718,5718,196.0329,10.195653,7.2337313,0.0,0,2.4854469,0.0,0.65788025,67.303673,2.4814909,393.43463,-9.2337523
5729,5729,196.0351,10.21672,7.2447619,0.0,0,2.4677808,0.0,0.65999591,67.231781,2.4641638,393.10495,-9.2329226
5740,5740,196.0373,10.22371,7.2708588,0.0,0,2.4501147,0.0,0.66265446,67.102814,2.444582,393.07178,-9.2338066
5751,5751,196.0395,10.270271,7.2815309,0.0,0,2.4324489,0.0,0.66477931,67.165428,2.4286978,393.0386,-9.2330341
5762,5762,196.0417,10.319544,7.3023782,0.0,0,2.4147828,0.0,0.66682196,67.413567,2.4102712,393.00543,-9.2333546
5773,5773,196.0439,10.374844,7.3170023,0.0,0,2.3971167,0.0,0.66930151,67.596199,2.3936067,393.05789,-9.2336864
5784,5784,196.0461,10.426021,7.3441052,0.0,0,2.3794508,0.0,0.67213541,67.790062,2.3747332,393.49588,-9.2343264
5795,5795,196.0483,10.470362,7.3543873,0.0,0,2.3617849,0.0,0.67414111,67.933945,2.3568702,393.93387,-9.2340946
5806,5806,196.0505,10.511911,7.3765922,0.0,0,2.3441188,0.0,0.67662042,68.068626,2.3360569,394.37186,-9.2338028
5817,5817,196.0527,10.525599,7.3913956,0.0,0,2.3264527,0.0,0.67908132,67.954002,2.3200223,394.80981,-9.2353029
5828,5828,196.0549,10.559296,7.4183135,0.0,0,2.3089681,0.0,0.68191409,68.023026,2.3039358,395.01553,-9.2351637
5839,5839,196.0571,10.560461,7.4286399,0.0,0,2.2921643,0.0,0.68390596,67.823463,2.2838471,395.08853,-9.2344627
5850,5850,196.0593,10.593132,7.4475317,0.0,0,2.2753608,0.0,0.68584675,67.894409,2.2637935,395.16153,-9.2346458
5861,5861,196.0615,10.6269,7.4598327,0.0,0,2.2585571,0.0,0.68795156,68.004265,2.24737,395.23453,-9.2322102
5872,5872,196.0637,10.658916,7.4873633,0.0,0,2.2417536,0.0,0.69112962,68.016754,2.2327154,395.31778,-9.2322044
5883,5883,196.0659,10.663161,7.4987645,0.0,0,2.2249501,0.0,0.69319016,67.859779,2.2163341,395.50351,-9.2326488
5894,5894,196.0681,10.665432,7.5200968,0.0,0,2.2081466,0.0,0.69557476,67.728775,2.2011538,395.68924,-9.2346029
5905,5905,196.0703,10.675488,7.5300598,0.0,0,2.1913428,0.0,0.69724661,67.671898,2.1852686,395.875,-9.2343359
5916,5916,196.0725,10.685691,7.5529609,0.0,0,2.1745393,0.0,0.70000917,67.563705,2.1684875,396.06073,-9.232213
5927,5927,196.0747,10.713758,7.561614,0.0,0,2.1577358,0.0,0.70141792,67.644173,2.1504264,396.36938,-9.2326288
5938,5938,196.0769,10.738918,7.5815511,0.0,0,2.1409321,0.0,0.70399135,67.649979,2.1366849,396.78049,-9.2343693
5949,5949,196.0791,10.820233,7.5958524,0.0,0,2.1241283,0.0,0.70601034,67.987183,2.1189952,397.19159,-9.2344666
5960,5960,196.0813,10.883695,7.6166277,0.0,0,2.1073248,0.0,0.70853513,68.233139,2.1058102,397.60272,-9.2333879
5971,5971,196.0835,10.931605,7.6269956,0.0,0,2.0905213,0.0,0.71027529,68.451927,2.0818229,398.01382,-9.2326193
5982,5982,196.0857,10.946364,7.6500173,0.0,0,2.0737178,0.0,0.71327049,68.298279,2.0664973,397.90771,-9.2343512
5993,5993,196.0879,10.97337,7.6634679,0.0,0,2.0569141,0.0,0.71519297,68.326294,2.053319,397.80161,-9.2336102
6004,6004,196.0901,11.000351,7.685329,0.0,0,2.0401106,0.0,0.71785504,68.341171,2.0371313,397.6955,-9.2332964
6015,6015,196.0923,11.037303,7.6953368,0.0,0,2.0233071,0.0,0.71957141,68.437469,2.0190036,397.58939,-9.2326117
6026,6026,196.0945,11.087918,7.7188907,0.0,0,2.0065033,0.0,0.72281468,68.514336,2.0026236,397.38086,-9.2337894
6037,6037,196.0967,11.155868,7.7343278,0.0,0,1.9896998,0.0,0.72476929,68.783867,1.9856851,397.04938,-9.2339621
6048,6048,196.0989,11.20232,7.757,0.0,0,1.9728961,0.0,0.72798246,68.862106,1.9680035,396.7179,-9.2349586
6059,6059,196.1011,11.241148,7.7674737,0.0,0,1.9560926,0.0,0.72937328,68.974312,1.9480481,396.38641,-9.2335691
6070,6070,196.1033,11.234923,7.7864819,0.0,0,1.939289,0.0,0.7321524,68.841888,1.9334266,396.0549,-9.2326345
6081,6081,196.1055,11.226872,7.8012042,0.0,0,1.9228806,0.0,0.7340399,68.648994,1.9188234,395.99463,-9.232914
6092,6092,196.1077,11.259439,7.8225856,0.0,0,1.9068955,0.0,0.73716336,68.591667,1.902143,395.96143,-9.2327881
6103,6103,196.1099,11.273043,7.8341856,0.0,0,1.8909101,0.0,0.73862821,68.581841,1.8866622,395.92825,-9.2324095
6114,6114,196.1121,11.285591,7.8531451,0.0,0,1.874925,0.0,0.74151176,68.449097,1.8703696,395.89508,-9.2344446
6125,6125,196.1143,11.321153,7.8658533,0.0,0,1.8589398,0.0,0.74303657,68.534081,1.8543657,395.97525,-9.2343769
6136,6136,196.1165,11.393869,7.8887506,0.0,0,1.8429546,0.0,0.74641228,68.748871,1.8372798,396.25375,-9.2332268
6147,6147,196.1187,11.444632,7.9021254,0.0,0,1.8269695,0.0,0.74806321,68.998573,1.8195565,396.53226,-9.2335262
6158,6158,196.1209,11.498075,7.9197702,0.0,0,1.8109843,0.0,0.7508707,69.075424,1.8021225,396.81076,-9.233942
6169,6169,196.1231,11.519536,7.9306445,0.0,0,1.794999,0.0,0.75207472,69.126495,1.7868086,397.08926,-9.2337971
6180,6180,196.1253,11.542057,7.9531283,0.0,0,1.7790139,0.0,0.75562316,69.055542,1.7721421,397.39471,-9.235281
6191,6191,196.1275,11.559082,7.968812,0.0,0,1.7630286,0.0,0.75731486,69.027168,1.75576,397.70618,-9.2338619
6202,6202,196.1297,11.578462,7.984972,0.0,0,1.7470435,0.0,0.76022297,68.935028,1.7369468,398.01764,-9.2329903
6213,6213,196.1319,11.601292,7.998477,0.0,0,1.7310582,0.0,0.76172543,68.923889,1.7204285,398.3291,-9.232913
6224,6224,196.1341,11.624085,8.0178509,0.0,0,1.715073,0.0,0.76491678,68.892601,1.7063301,398.5231,-9.2353125
6235,6235,196.1363,11.683249,8.0323248,0.0,0,1.6990879,0.0,0.76641154,69.135918,1.6887931,398.40387,-9.2343302
6246,6246,196.1385,11.693219,8.045681,0.0,0,1.6831026,0.0,0.76898533,69.051353,1.6732227,398.28464,-9.2337885
6257,6257,196.1407,11.715257,8.0589142,0.0,0,1.6671174,0.0,0.7702722,69.059227,1.6614923,398.16541,-9.2330151
6268,6268,196.1429,11.730016,8.0796337,0.0,0,1.6511322,0.0,0.77397174,68.888603,1.6474279,398.04617,-9.234313
6279,6279,196.1451,11.761308,8.0958624,0.0,0,1.635147,0.0,0.77554148,68.948074,1.6314588,397.48309,-9.2339888
6290,6290,196.1473,11.813607,8.1094055,0.0,0,1.6191618,0.0,0.77810156,69.068588,1.6143379,396.75357,-9.2332258
6301,6301,196.1495,11.87524,8.1221457,0.0,0,1.6031766,0.0,0.77933383,69.323242,1.5962687,396.02405,-9.2338915
6312,6312,196.1517,11.919976,8.1420412,0.0,0,1.5871913,0.0,0.78304696,69.337463,1.5806518,395.29453,-9.2340708
6323,6323,196.1539,11.97928,8.1565342,0.0,0,1.5712062,0.0,0.78423876,69.586441,1.5638914,394.63971,-9.232852
6334,6334,196.1561,12.048352,8.1716557,0.0,0,1.5558095,0.0,0.78741223,69.767662,1.5491383,394.3212,-9.2336168
6345,6345,196.1583,12.065665,8.1883249,0.0,0,1.540603,0.0,0.78890032,69.800987,1.5345678,394.00266,-9.2351408
6356,6356,196.1605,12.07228,8.2076139,0.0,0,1.5253967,0.0,0.79267257,69.621033,1.5187137,393.68411,-9.2333117
6367,6367,196.1627,12.087109,8.222435,0.0,0,1.5101904,0.0,0.79395187,69.598236,1.5026375,393.3656,-9.2323246
6378,6378,196.1649,12.101591,8.2355318,0.0,0,1.4949839,0.0,0.79685491,69.493324,1.4851023,393.40176,-9.2327271
6389,6389,196.1671,12.135075,8.2515717,0.0,0,1.4797776,0.0,0.79813409,69.56321,1.4705375,393.64069,-9.2327824
6400,6400,196.1693,12.184934,8.2701197,0.0,0,1.4645711,0.0,0.80204588,69.546509,1.4609636,393.87958,-9.2328472
6411,6411,196.1715,12.233659,8.2869568,0.0,0,1.4493648,0.0,0.80326688,69.750809,1.4460959,394.11847,-9.2325144
6422,6422,196.1737,12.316794,8.2984781,0.0,0,1.4341583,0.0,0.80615354,70.016136,1.4259672,394.20169,-9.2338409
6433,6433,196.1759,12.382429,8.3188028,0.0,0,1.418952,0.0,0.80816972,70.256737,1.4088596,392.72824,-9.2330103
6444,6444,196.1781,12.377649,8.3341484,0.0,0,1.4037454,0.0,0.81158245,70.057083,1.3930193,391.25479,-9.2327185
6455,6455,196.1803,12.387031,8.3509922,0.0,0,1.3885391,0.0,0.81291097,69.943375,1.379968,389.78137,-9.2332239
6466,6466,196.1825,12.378283,8.3635387,0.0,0,1.3733326,0.0,0.81597918,69.697029,1.3643057,388.30792,-9.2337866
6477,6477,196.1847,12.382012,8.3760414,0.0,0,1.3581263,0.0,0.81681329,69.669167,1.3468708,386.79828,-9.2336044
6488,6488,196.1869,12.39399,8.393363,0.0,0,1.3429198,0.0,0.82054323,69.460167,1.333189,385.25845,-9.2336435
6499,6499,196.1891,12.441403,8.4084911,0.0,0,1.3277135,0.0,0.8215121,69.638535,1.3188499,383.7186,-9.2337761
6510,6510,196.1913,12.483452,8.4189854,0.0,0,1.3125072,0.0,0.82441539,69.673958,1.3043758,382.17877,-9.2345219
6521,6521,196.1935,12.542287,8.4336472,0.0,0,1.2973008,0.0,0.82538521,69.960022,1.2903816,380.63895,-9.2344685
6532,6532,196.1957,12.5913,8.4484262,0.0,0,1.2820944,0.0,0.82900774,70.013718,1.2761946,380.27313,-9.2334757
6543,6543,196.1979,12.618198,8.4686184,0.0,0,1.2668879,0.0,0.83048522,70.040474,1.2587897,379.90735,-9.2331238
6554,6554,196.2001,12.662589,8.4769793,0.0,0,1.2516814,0.0,0.83342165,70.072319,1.2469575,379.54153,-9.2325363
6565,6565,196.2023,12.706249,8.4947548,0.0,0,1.2364751,0.0,0.83474869,70.146812,1.2324544,379.17572,-9.2323179
6576,6576,196.2045,12.7576,8.5100613,0.0,0,1.2212964,0.0,0.83861744,70.199303,1.2153206,378.91876,-9.2335682
6587,6587,196.2067,12.825032,8.5296984,0.0,0,1.206827,0.0,0.83999401,70.547287,1.1998074,378.79239,-9.2336521
6598,6598,196.2089,12.899736,8.5403433,0.0,0,1.1923642,0.0,0.84320635,70.665794,1.1826427,378.66602,-9.234355
6609,6609,196.2111,12.934827,8.5591841,0.0,0,1.1779014,0.0,0.84467441,70.750824,1.1640849,378.53964,-9.2342939
6620,6620,196.2133,12.943537,8.5735292,0.0,0,1.1634386,0.0,0.84839946,70.550194,1.1486192,378.41327,-9.2335215
6631,6631,196.2155,12.924761,8.5906792,0.0,0,1.1489758,0.0,0.84950966,70.398613,1.1417438,378.49854,-9.2326708
6642,6642,196.2177,12.913074,8.5974855,0.0,0,1.134513,0.0,0.85199314,70.145111,1.1236087,378.60495,-9.2331095
6653,6653,196.2199,12.917093,8.6160984,0.0,0,1.1200502,0.0,0.85338527,70.076393,1.108025,378.71136,-9.2342005
6664,6664,196.2221,12.930231,8.6278248,0.0,0,1.1055874,0.0,0.85692406,69.893051,1.0960295,378.81778,-9.2330685
6675,6675,196.2243,12.966029,8.644372,0.0,0,1.0911245,0.0,0.85778654,69.991844,1.0809263,378.83954,-9.2340622
6686,6686,196.2265,13.005765,8.6516695,0.0,0,1.0766618,0.0,0.86060566,70.067368,1.069787,378.71317,-9.2330551
6697,6697,196.2287,13.055331,8.6680746,0.0,0,1.0621989,0.0,0.86158538,70.196915,1.0528634,378.58682,-9.2324419
6708,6708,196.2309,13.114234,8.6788969,0.0,0,1.0477362,0.0,0.86513764,70.312378,1.0419587,378.46045,-9.2319899
6719,6719,196.2331,13.191678,8.7009249,0.0,0,1.0332733,0.0,0.86670315,70.588318,1.0287926,378.33408,-9.2331142
6730,6730,196.2353,13.25785,8.7085714,0.0,0,1.0188106,0.0,0.86973834,70.720932,1.0133361,378.65384,-9.2329073
6741,6741,196.2375,13.281251,8.7277279,0.0,0,1.0043477,0.0,0.87112015,70.785339,0.99685162,379.07275,-9.2334366
6752,6752,196.2397,13.34186,8.737133,0.0,0,0.98988497,0.0,0.87450546,70.839371,0.98122358,379.49164,-9.2337904
6763,6763,196.2419,13.396668,8.7573624,0.0,0,0.97542214,0.0,0.87573826,71.041817,0.96730691,379.91055,-9.2320414
6774,6774,196.2441,13.449109,8.7676878,0.0,0,0.96095932,0.0,0.87919158,71.070122,0.95478678,380.22064,-9.2335577
6785,6785,196.2463,13.477602,8.7863913,0.0,0,0.94649649,0.0,0.88035107,71.147087,0.93734676,380.2406,-9.2327833
6796,6796,196.2485,13.504126,8.7961426,0.0,0,0.93203378,0.0,0.88382208,71.057053,0.92264259,380.26056,-9.2326021
6807,6807,196.2507,13.513789,8.8168116,0.0,0,0.91757095,0.0,0.88500983,71.054016,0.91028899,380.28052,-9.2323427
6818,6818,196.2529,13.557523,8.823101,0.0,0,0.90310812,0.0,0.88817132,70.997025,0.89941692,380.30048,-9.2324038
6829,6829,196.2551,13.591295,8.841959,0.0,0,0.88885862,0.0,0.88942945,71.146515,0.88435376,380.27213,-9.2322168
6840,6840,196.2573,13.632672,8.8527212,0.0,0,0.87510419,0.0,0.8930729,71.094093,0.86970419,380.22568,-9.2333593
6851,6851,196.2595,13.704934,8.8737059,0.0,0,0.86134988,0.0,0.89434808,71.361824,0.85600495,380.17923,-9.2322369
6862,6862,196.2617,13.786819,8.8820553,0.0,0,0.84759539,0.0,0.89769047,71.518478,0.8418377,380.13278,-9.2324905
6873,6873,196.2639,13.847814,8.9023552,0.0,0,0.83384103,0.0,0.89918953,71.723152,0.8252539,380.21957,-9.2325573
6884,6884,196.2661,13.90092,8.9126501,0.0,0,0.82008666,0.0,0.90274829,71.748314,0.80851018,380.90594,-9.2315359
6895,6895,196.2683,13.926805,8.9331608,0.0,0,0.80633223,0.0,0.903916,71.815392,0.79426831,381.59232,-9.2321367
6906,6906,196.2705,13.955615,8.9404945,0.0,0,0.79257786,0.0,0.90737426,71.696762,0.78299063,382.27866,-9.2324429
6917,6917,196.2727,13.963683,8.9620924,0.0,0,0.77882344,0.0,0.90903872,71.663506,0.76819247,382.95978,-9.2326145
6928,6928,196.2749,13.966466,8.9708767,0.0,0,0.76506907,0.0,0.91239834,71.444038,0.75051171,383.53046,-9.2322617
6939,6939,196.2771,13.956474,8.991086,0.0,0,0.75131464,0.0,0.91369933,71.252495,0.74078691,384.10117,-9.2326756
6950,6950,196.2793,13.983449,8.9942846,0.0,0,0.73756021,0.0,0.91641587,71.21273,0.72707295,384.67184,-9.2332344
6961,6961,196.2815,14.039351,9.0135756,0.0,0,0.72380584,0.0,0.91768104,71.361931,0.71588981,385.24255,-9.2328043
6972,6972,196.2837,14.092069,9.0218372,0.0,0,0.71005148,0.0,0.92092085,71.397408,0.69836968,385.75684,-9.2320004
6983,6983,196.2859,14.128274,9.0411921,0.0,0,0.69629705,0.0,0.921929,71.536705,0.68746382,386.21472,-9.2329836
6994,6994,196.2881,14.144972,9.0470762,0.0,0,0.68254262,0.0,0.92516387,71.460167,0.67557496,386.67261,-9.2337408
7005,7005,196.2903,14.196741,9.0658035,0.0,0,0.66878825,0.0,0.926458,71.556458,0.65954167,387.13049,-9.2326317
7016,7016,196.2925,14.204857,9.0725546,0.0,0,0.65503383,0.0,0.92945981,71.411034,0.65024614,387.58838,-9.2335281
7027,7027,196.2947,14.221981,9.0946159,0.0,0,0.64127946,0.0,0.93089467,71.397018,0.63926065,387.8309,-9.2328482
7038,7038,196.2969,14.258623,9.0977955,0.0,0,0.62752503,0.0,0.93355805,71.363747,0.62432915,388.06314,-9.2324181
7049,7049,196.2991,14.345957,9.1151237,0.0,0,0.61377066,0.0,0.93481362,71.689171,0.61187923,388.29541,-9.2310982
7060,7060,196.3013,14.465286,9.1236906,0.0,0,0.60001624,0.0,0.93822032,72.051804,0.59717822,388.52768,-9.2327137
7071,7071,196.3035,14.557702,9.146637,0.0,0,0.58626187,0.0,0.9397341,72.424782,0.58204758,388.66492,-9.2330036
7082,7082,196.3057,14.629669,9.1520252,0.0,0,0.57288873,0.0,0.94292367,72.568916,0.56770271,388.66492,-9.2330275
7093,7093,196.3079,14.666819,9.1723709,0.0,0,0.55979866,0.0,0.94472861,72.575935,0.55367535,388.66492,-9.2325726
7100,7100,196.3093,14.68291,9.1807194,0.0,0,0.55146873,0.0,0.94645166,72.551506,0.54576623,388.66492,-9.2322206