File: clean data/testID_0194.csv
level_0,index,Time(sec),Force(kN),Jaw(mm),PowAngle(deg),Power(W),Pram,PTemp,Strain,Stress(MPa),Stroke(mm),TC1(C),wedge(mm)
1774,1774,145.3565,0.95104998,0.023556355,0.0,0,9.0044422,0.0,0.001760872,11.419558,10.019138,300.57175,-9.3249521
1776,1776,145.3569,3.6655498,0.057178602,0.0,0,8.9459143,0.0,0.0033532665,42.127808,9.9434624,301.20016,-9.3241549
1778,1778,145.3573,5.6188426,0.1171593,0.0,0,8.8873863,0.0,0.0073420852,69.747581,9.8900089,301.82855,-9.3232412
1780,1780,145.3577,6.5294933,0.19516319,0.0,0,8.8288584,0.0,0.01261796,80.69799,9.8134098,302.45697,-9.3207712
1782,1782,145.3581,7.139379,0.34706253,0.0,0,8.7703304,0.0,0.02223869,88.603806,9.725565,303.08536,-9.3192635
1784,1784,145.3585,7.6372838,0.44028071,0.0,0,8.7136879,0.0,0.029273966,93.293442,9.6198845,303.71378,-9.319253
1786,1786,145.3589,8.124711,0.53824615,0.0,0,8.6580172,0.0,0.036047686,99.574921,9.5184202,304.34216,-9.3193951
1788,1788,145.3593,8.6734095,0.6065408,0.0,0,8.6023531,0.0,0.040733535,105.05553,9.4261789,304.97055,-9.319869
1790,1790,145.3597,8.575182,0.63662511,0.0,0,8.546689,0.0,0.043158144,105.35456,9.3542576,305.59897,-9.3183126
1792,1792,145.3601,8.6807499,0.70795965,0.0,0,8.4910259,0.0,0.047917686,104.55876,9.2950544,306.22736,-9.3177681
1794,1794,145.3605,9.0909271,0.76369083,0.0,0,8.4353609,0.0,0.051568106,109.72327,9.2350712,306.85577,-9.3181877
1796,1796,145.3609,9.3506727,0.8314743,0.0,0,8.3796968,0.0,0.056567874,112.26534,9.1620073,307.48416,-9.3175707
1798,1798,145.3613,9.1397514,0.94579405,0.0,0,8.3240337,0.0,0.064301893,109.71829,9.07792,308.11258,-9.3174934
1800,1800,145.3617,9.1827774,1.0351951,0.0,0,8.2683697,0.0,0.070845574,108.3924,8.9943542,308.74097,-9.3182535
1802,1802,145.3621,9.4532871,1.1053221,0.0,0,8.2127056,0.0,0.076285653,111.6272,8.9108572,309.36935,-9.3173199
1804,1804,145.3625,9.5505352,1.1417271,0.0,0,8.1570415,0.0,0.078802146,112.05086,8.8392963,309.99777,-9.3175583
1806,1806,145.3629,9.7007875,1.185024,0.0,0,8.1013775,0.0,0.081856571,114.08722,8.7771912,310.62616,-9.3179388
1808,1808,145.3633,9.4910555,1.2392274,0.0,0,8.0462685,0.0,0.086034924,110.72054,8.7244654,311.25458,-9.3170938
1810,1810,145.3637,9.9483747,1.2915684,0.0,0,7.993176,0.0,0.08933121,115.4461,8.67029,311.88297,-9.3174744
1812,1812,145.3641,9.9566965,1.3752768,0.0,0,7.9402156,0.0,0.095730931,115.3103,8.6091385,312.51138,-9.3172522
1814,1814,145.3645,9.9673643,1.4533311,0.0,0,7.8872557,0.0,0.10148896,114.78027,8.5386696,313.13977,-9.3181705
1816,1816,145.3649,9.8099222,1.5251921,0.0,0,7.8342957,0.0,0.10655152,112.37764,8.4666824,313.76819,-9.3184776
1818,1818,145.3653,9.98598,1.5844982,0.0,0,7.7813354,0.0,0.1116491,113.48179,8.4001522,314.39658,-9.3183069
1820,1820,145.3657,10.108277,1.6199905,0.0,0,7.7283754,0.0,0.11382426,114.59697,8.3379126,315.01642,-9.3164549
1822,1822,145.3661,10.205564,1.6749554,0.0,0,7.675415,0.0,0.11778368,115.49068,8.2897301,315.62775,-9.3168774
1824,1824,145.3665,10.124534,1.7259474,0.0,0,7.6224551,0.0,0.12223108,114.01798,8.2367687,316.23907,-9.3177595
1826,1826,145.3669,10.345064,1.7750915,0.0,0,7.5694952,0.0,0.12527037,115.9075,8.1884098,316.85037,-9.3177147
1828,1828,145.3673,10.329252,1.8387798,0.0,0,7.5165353,0.0,0.13034378,115.55437,8.1328239,317.4617,-9.3174906
1830,1830,145.3677,10.410671,1.8943388,0.0,0,7.4635754,0.0,0.13480872,115.67982,8.0718746,318.073,-9.3174171
1832,1832,145.3681,10.365975,1.9614388,0.0,0,7.410615,0.0,0.13926834,114.92625,8.0153198,318.68433,-9.3177195
1834,1834,145.3685,10.414545,2.0013955,0.0,0,7.3593612,0.0,0.14316531,114.77745,7.9577627,319.29562,-9.3171988
1836,1836,145.3689,10.541505,2.037276,0.0,0,7.3089881,0.0,0.14566869,115.91334,7.9072838,319.90695,-9.3173122
1838,1838,145.3693,10.533813,2.1004462,0.0,0,7.2586198,0.0,0.15004404,115.45943,7.8652272,320.51825,-9.3180466
1840,1840,145.3697,10.572932,2.1386697,0.0,0,7.2082515,0.0,0.15384583,115.32753,7.8128543,321.12958,-9.3173561
1842,1842,145.3701,10.692126,2.1865256,0.0,0,7.1578832,0.0,0.15698986,116.16917,7.7649117,321.74091,-9.3161516
1844,1844,145.3705,10.775398,2.2475197,0.0,0,7.1075153,0.0,0.16170785,116.69753,7.7121425,322.3522,-9.3159952
1846,1846,145.3709,10.757796,2.2886934,0.0,0,7.0571475,0.0,0.16546324,116.13988,7.6630802,322.96353,-9.3167591
1848,1848,145.3713,10.738339,2.3475294,0.0,0,7.0067792,0.0,0.16946967,115.38693,7.6099243,323.57483,-9.3175106
1850,1850,145.3717,10.835341,2.3920362,0.0,0,6.9564114,0.0,0.17349854,115.88821,7.5603309,324.18616,-9.3165426
1852,1852,145.3721,10.950244,2.4282281,0.0,0,6.9060431,0.0,0.17643212,116.79335,7.5121651,324.79745,-9.3172359
1854,1854,145.3725,10.940108,2.4812763,0.0,0,6.8556757,0.0,0.18012697,116.42535,7.4653616,325.40878,-9.3172178
1856,1856,145.3729,10.929739,2.5224683,0.0,0,6.8053074,0.0,0.18403645,115.70721,7.4180603,326.02011,-9.3161535
1858,1858,145.3733,11.030513,2.57002,0.0,0,6.7554417,0.0,0.18751185,116.3447,7.3721781,326.63141,-9.3165798
1860,1860,145.3737,11.117565,2.6216242,0.0,0,6.7074022,0.0,0.19156995,116.82256,7.3245945,327.24274,-9.3161592
1862,1862,145.3741,11.137827,2.6685045,0.0,0,6.6594815,0.0,0.19584703,116.61341,7.2774224,327.85403,-9.3176155
1864,1864,145.3745,11.123646,2.7218394,0.0,0,6.6115613,0.0,0.19960766,116.00134,7.2304158,328.46536,-9.3183384
1866,1866,145.3749,11.207923,2.7607508,0.0,0,6.5636415,0.0,0.20298626,116.3279,7.181942,329.07666,-9.318471
1868,1868,145.3753,11.292117,2.801456,0.0,0,6.5157218,0.0,0.20675114,116.8054,7.135613,329.68799,-9.3175106
1870,1870,145.3757,11.323376,2.8528559,0.0,0,6.467802,0.0,0.2102128,116.88517,7.0896454,329.82333,-9.3168106
1872,1872,145.3761,11.369983,2.8948867,0.0,0,6.4198818,0.0,0.21407236,116.7627,7.0422492,329.48279,-9.3170452
1874,1874,145.3765,11.438485,2.9431674,0.0,0,6.3719616,0.0,0.21818052,117.04562,6.9964395,329.14227,-9.3175087
1876,1876,145.3769,11.479833,2.9980886,0.0,0,6.3240418,0.0,0.22214356,117.003,6.9518108,328.80173,-9.3189354
1878,1878,145.3773,11.522015,3.0403378,0.0,0,6.2761221,0.0,0.22639297,116.9516,6.9016595,328.46118,-9.3192711
1880,1880,145.3777,11.557056,3.0853398,0.0,0,6.2282019,0.0,0.22991934,116.81543,6.851491,328.12064,-9.3179998
1882,1882,145.3781,11.643786,3.1362219,0.0,0,6.1802821,0.0,0.23382644,117.33675,6.8054299,327.78012,-9.3182726
1884,1884,145.3785,11.69524,3.1756752,0.0,0,6.1339049,0.0,0.23788491,117.26385,6.756711,327.43958,-9.3168373
1886,1886,145.3789,11.728411,3.2232144,0.0,0,6.0883236,0.0,0.24129809,117.30553,6.7108774,327.09903,-9.3175459
1888,1888,145.3793,11.764355,3.2777383,0.0,0,6.042748,0.0,0.24592668,117.10036,6.6628294,326.75848,-9.3174706
1890,1890,145.3797,11.852937,3.3202221,0.0,0,5.9971719,0.0,0.25007585,117.38298,6.6152539,326.41797,-9.3167038
1892,1892,145.3801,11.926579,3.3706622,0.0,0,5.9515953,0.0,0.25376701,117.77594,6.5675635,326.07742,-9.317584
1894,1894,145.3805,11.943063,3.4200318,0.0,0,5.9060202,0.0,0.25857034,117.42961,6.5185385,325.73688,-9.318119
1896,1896,145.3809,11.960402,3.4610527,0.0,0,5.8604436,0.0,0.26212266,117.15065,6.4734955,325.39633,-9.317008
1898,1898,145.3813,12.043261,3.5119195,0.0,0,5.8148675,0.0,0.26592425,117.42891,6.4255624,325.05582,-9.3168507
1900,1900,145.3817,12.120682,3.5606968,0.0,0,5.7692914,0.0,0.27093738,117.60109,6.3794804,324.71527,-9.3167391
1902,1902,145.3821,12.18144,3.6054766,0.0,0,5.7237153,0.0,0.27442625,117.83642,6.3290076,324.37473,-9.3166847
1904,1904,145.3825,12.20657,3.6575367,0.0,0,5.6781397,0.0,0.27879778,117.61272,6.2826743,324.03418,-9.3173018
1906,1906,145.3829,12.256318,3.7008698,0.0,0,5.6325636,0.0,0.28341234,117.4743,6.2324967,323.69366,-9.3173571
1908,1908,145.3833,12.333419,3.7528601,0.0,0,5.5874419,0.0,0.28717229,117.70111,6.1802468,323.35312,-9.3182297
1910,1910,145.3837,12.415532,3.8004353,0.0,0,5.5439739,0.0,0.29175916,117.97001,6.1345077,323.01257,-9.3170948
1912,1912,145.3841,12.456481,3.8422096,0.0,0,5.5006137,0.0,0.29589811,118.03828,6.0860686,322.67203,-9.3161507
1914,1914,145.3845,12.507672,3.8993199,0.0,0,5.4572535,0.0,0.30009627,117.84545,6.0398889,322.33151,-9.3168325
1916,1916,145.3849,12.533114,3.9425848,0.0,0,5.4138937,0.0,0.30469623,117.63137,5.9934392,321.99097,-9.3176336
1918,1918,145.3853,12.58743,3.9871299,0.0,0,5.3705335,0.0,0.30866441,117.74681,5.9432797,321.65042,-9.3175278
1920,1920,145.3857,12.684557,4.0420122,0.0,0,5.3271737,0.0,0.31304201,118.00148,5.8948684,321.40762,-9.3174629
1922,1922,145.3861,12.736136,4.0798402,0.0,0,5.2838135,0.0,0.31750372,118.1025,5.84549,321.26257,-9.3175306
1924,1924,145.3865,12.766759,4.1277771,0.0,0,5.2404532,0.0,0.32130471,117.81988,5.8023529,321.11749,-9.3182421
1926,1926,145.3869,12.803648,4.1835108,0.0,0,5.1970935,0.0,0.32614818,117.63353,5.7532926,320.97244,-9.3179274
1928,1928,145.3873,12.880668,4.2225776,0.0,0,5.1537337,0.0,0.33059382,117.73396,5.7080622,320.82736,-9.3168535
1930,1930,145.3877,12.964468,4.2736969,0.0,0,5.1103735,0.0,0.33457443,118.06396,5.6613078,320.68228,-9.3170671
1932,1932,145.3881,13.010406,4.3260632,0.0,0,5.0670133,0.0,0.33972749,117.89034,5.6132469,320.53723,-9.3174963
1934,1934,145.3885,13.047501,4.3660655,0.0,0,5.0250487,0.0,0.34393197,117.77956,5.5652637,320.39215,-9.3182688
1936,1936,145.3889,13.088636,4.4156847,0.0,0,4.9838042,0.0,0.34780997,117.68774,5.514277,320.2471,-9.3181925
1938,1938,145.3893,13.157854,4.4590521,0.0,0,4.942564,0.0,0.35256875,117.74437,5.4719896,320.10202,-9.318305
1940,1940,145.3897,13.238745,4.5009546,0.0,0,4.9013243,0.0,0.35649937,117.95847,5.4232421,319.95697,-9.317728
1942,1942,145.3901,13.292073,4.5512733,0.0,0,4.8600841,0.0,0.36085942,117.87143,5.3765945,319.81189,-9.3169889
1944,1944,145.3905,13.312939,4.5974994,0.0,0,4.8188443,0.0,0.36600119,117.52019,5.3298526,319.66684,-9.317584
1946,1946,145.3909,13.379434,4.6473174,0.0,0,4.7776041,0.0,0.37009442,117.54251,5.2845373,319.52176,-9.3180361
1948,1948,145.3913,13.455529,4.692647,0.0,0,4.7363639,0.0,0.37458691,117.77896,5.2392507,319.37671,-9.3175268
1950,1950,145.3917,13.516585,4.7337675,0.0,0,4.6951241,0.0,0.37924749,117.79359,5.1916294,319.23163,-9.3167753
1952,1952,145.3921,13.565066,4.7826548,0.0,0,4.6538844,0.0,0.38312754,117.75934,5.145824,319.08658,-9.3167305
1954,1954,145.3925,13.596639,4.8244967,0.0,0,4.6126437,0.0,0.38768703,117.4689,5.1018476,318.9415,-9.3171234
1956,1956,145.3929,13.65659,4.8646674,0.0,0,4.571404,0.0,0.39204067,117.44784,5.0578828,318.79645,-9.3178539
1958,1958,145.3933,13.735199,4.9186497,0.0,0,4.5305758,0.0,0.39624169,117.6039,5.0111837,318.65137,-9.3177319
1960,1960,145.3937,13.788702,4.9586239,0.0,0,4.4912457,0.0,0.40109062,117.51965,4.9718685,318.50632,-9.3166494
1962,1962,145.3941,13.836091,4.9989448,0.0,0,4.4520135,0.0,0.4050394,117.44099,4.9251699,318.36124,-9.3161993
1964,1964,145.3945,13.881004,5.0521154,0.0,0,4.4127817,0.0,0.40965819,117.26859,4.8819137,318.21619,-9.3160372
1966,1966,145.3949,13.927293,5.0869374,0.0,0,4.3735499,0.0,0.41429982,117.14152,4.8395004,318.07111,-9.3168106
1968,1968,145.3953,13.992255,5.1314244,0.0,0,4.3343177,0.0,0.41797704,117.228,4.7964597,317.92606,-9.3167686
1970,1970,145.3957,14.061883,5.1807261,0.0,0,4.2950859,0.0,0.42295152,117.23489,4.7517395,317.96527,-9.3172493
1972,1972,145.3961,14.124034,5.2140512,0.0,0,4.2558532,0.0,0.42714921,117.28936,4.709568,318.18878,-9.3175316
1974,1974,145.3965,14.154079,5.2591934,0.0,0,4.2166214,0.0,0.43082899,117.11124,4.6690578,318.41229,-9.3169889
1976,1976,145.3969,14.212384,5.3047752,0.0,0,4.1773896,0.0,0.43610471,116.96069,4.6262879,318.6358,-9.3170366
1978,1978,145.3973,14.278522,5.339756,0.0,0,4.1381574,0.0,0.43992814,117.06378,4.5816579,318.85931,-9.3175058
1980,1980,145.3977,14.34217,5.3864312,0.0,0,4.0989256,0.0,0.44396713,117.11584,4.5389438,319.08282,-9.3168993
1982,1982,145.3981,14.396031,5.4276662,0.0,0,4.0596938,0.0,0.44906169,117.0135,4.5003481,319.30634,-9.3169851
1984,1984,145.3985,14.44027,5.4665442,0.0,0,4.0217257,0.0,0.45280984,116.85567,4.4585924,319.52985,-9.3168278
1986,1986,145.3989,14.505428,5.5110745,0.0,0,3.9844093,0.0,0.45711246,116.85265,4.4188294,319.75336,-9.3168097
1988,1988,145.3993,14.578509,5.5473423,0.0,0,3.9470973,0.0,0.46190262,116.92933,4.3790464,319.97687,-9.31709
1990,1990,145.3997,14.66122,5.5895829,0.0,0,3.9097853,0.0,0.46538493,117.12028,4.3336711,320.20038,-9.3162889
1992,1992,145.4001,14.705181,5.6316314,0.0,0,3.8724735,0.0,0.47005135,116.96141,4.2942834,320.42389,-9.3170099
1994,1994,145.4005,14.74689,5.6673975,0.0,0,3.8351612,0.0,0.47478512,116.73716,4.2537699,320.6474,-9.3177252
1996,1996,145.4009,14.802109,5.7152619,0.0,0,3.7978494,0.0,0.47865805,116.73251,4.2140832,320.87091,-9.31674
1998,1998,145.4013,14.892866,5.7519789,0.0,0,3.7605371,0.0,0.48332459,116.84287,4.1744695,321.09442,-9.3170338
2000,2000,145.4017,14.963632,5.7855849,0.0,0,3.7232254,0.0,0.48721328,116.96865,4.1355319,321.31793,-9.3167152
2002,2002,145.4021,15.007342,5.8337812,0.0,0,3.6859133,0.0,0.49126676,116.87939,4.0926709,321.54144,-9.3161869
2004,2004,145.4025,15.056815,5.8663764,0.0,0,3.6486013,0.0,0.49602669,116.71098,4.0553451,321.76495,-9.3175068
2006,2006,145.4029,15.11897,5.9042954,0.0,0,3.6112893,0.0,0.49983472,116.7326,4.0184898,321.98846,-9.3171768
2008,2008,145.4033,15.217125,5.953701,0.0,0,3.5743496,0.0,0.50467712,116.89668,3.9786894,322.21198,-9.3169165
2010,2010,145.4037,15.289008,5.9825525,0.0,0,3.538765,0.0,0.50903916,116.98048,3.9390171,322.43549,-9.3165665
2012,2012,145.4041,15.346765,6.0217142,0.0,0,3.5032687,0.0,0.51251763,116.99986,3.8988175,322.659,-9.3159094
2014,2014,145.4045,15.388799,6.065259,0.0,0,3.4677727,0.0,0.51736206,116.74726,3.864131,322.88251,-9.3158035
2016,2016,145.4049,15.455005,6.0945344,0.0,0,3.432277,0.0,0.52146226,116.7792,3.826591,323.10602,-9.3161554
2018,2018,145.4053,15.550047,6.1383519,0.0,0,3.3967807,0.0,0.52527112,117.02059,3.7886589,323.32953,-9.3167543
2020,2020,145.4057,15.624816,6.1783924,0.0,0,3.3612847,0.0,0.53059816,117.03774,3.7503111,323.26462,-9.316226
2022,2022,145.4061,15.660336,6.2105989,0.0,0,3.3257887,0.0,0.53448284,116.85652,3.7127941,322.91129,-9.3157139
2024,2024,145.4065,15.724564,6.2530413,0.0,0,3.2902927,0.0,0.53843355,116.79343,3.675976,322.55798,-9.3161459
2026,2026,145.4069,15.802469,6.2870784,0.0,0,3.2547965,0.0,0.54336053,116.80165,3.6389568,322.20465,-9.3162231
2028,2028,145.4073,15.909542,6.3227634,0.0,0,3.2193007,0.0,0.5468964,117.1272,3.6007378,321.85135,-9.3153076
2030,2030,145.4077,15.974585,6.362042,0.0,0,3.1838048,0.0,0.5511173,117.21445,3.5649133,321.49802,-9.3161335
2032,2032,145.4081,16.020929,6.3946691,0.0,0,3.1483088,0.0,0.55601472,116.94746,3.5258489,321.14471,-9.316781
2034,2034,145.4085,16.086052,6.43681,0.0,0,3.11395,0.0,0.55968791,116.90005,3.4893827,320.79138,-9.3168449
2036,2036,145.4089,16.1745,6.4740844,0.0,0,3.0801783,0.0,0.56443948,117.00474,3.4537289,320.43808,-9.3153706
2038,2038,145.4093,16.2729,6.504827,0.0,0,3.0464106,0.0,0.56878465,117.25141,3.4171064,320.08475,-9.3158216
2040,2040,145.4097,16.3319,6.5515947,0.0,0,3.0126424,0.0,0.5728839,117.24174,3.3799827,319.73145,-9.3165588
2042,2042,145.4101,16.392176,6.5837851,0.0,0,2.9788744,0.0,0.57772386,117.07943,3.3433728,319.37811,-9.3178844
2044,2044,145.4105,16.47051,6.61411,0.0,0,2.9451065,0.0,0.58135509,117.16028,3.3078632,319.02481,-9.3162575
2046,2046,145.4109,16.560375,6.6561499,0.0,0,2.9113381,0.0,0.58526736,117.39417,3.2721286,318.67148,-9.3156424
2048,2048,145.4113,16.655291,6.6841416,0.0,0,2.8775704,0.0,0.58998805,117.49545,3.2368517,318.31818,-9.3151531
2050,2050,145.4117,16.722034,6.721643,0.0,0,2.8438022,0.0,0.59385324,117.51191,3.2003222,317.96484,-9.3151894
2052,2052,145.4121,16.769667,6.7693644,0.0,0,2.810034,0.0,0.59916377,117.2643,3.164196,317.61154,-9.3162756
2054,2054,145.4125,16.852324,6.7953143,0.0,0,2.7762663,0.0,0.60357571,117.32723,3.1273532,317.25821,-9.3165779
2056,2056,145.4129,16.940657,6.8293929,0.0,0,2.7424984,0.0,0.60667264,117.51991,3.0919509,316.90488,-9.3158064
2058,2058,145.4133,17.037342,6.8682747,0.0,0,2.7090683,0.0,0.61170071,117.58615,3.058393,316.55157,-9.3157415
2060,2060,145.4137,17.115244,6.8945045,0.0,0,2.6768677,0.0,0.61558884,117.64216,3.0247757,316.19824,-9.3152561
2062,2062,145.4141,17.185547,6.9362788,0.0,0,2.6447473,0.0,0.61964858,117.66882,2.9915261,315.84494,-9.3155394
2064,2064,145.4145,17.26371,6.9737549,0.0,0,2.6126273,0.0,0.62527722,117.57637,2.9548478,315.49161,-9.315568
2066,2066,145.4149,17.34761,7.0040927,0.0,0,2.5805073,0.0,0.62892884,117.72042,2.9189174,315.13831,-9.3144836
2068,2068,145.4153,17.460779,7.0403934,0.0,0,2.5483873,0.0,0.63278186,118.02245,2.8852725,314.78497,-9.3150387
2070,2070,145.4157,17.540657,7.0704999,0.0,0,2.5162673,0.0,0.63779306,118.00808,2.8520644,314.33298,-9.3153715
2072,2072,145.4161,17.594048,7.1042132,0.0,0,2.4841473,0.0,0.64112544,117.96244,2.8155475,313.78232,-9.3159523
2074,2074,145.4165,17.679155,7.1425157,0.0,0,2.4520273,0.0,0.64575303,117.93384,2.7815299,313.23163,-9.3155479
2076,2076,145.4169,17.775108,7.1730995,0.0,0,2.4199073,0.0,0.65084505,118.00317,2.7499077,312.68097,-9.3143835
2078,2078,145.4173,17.892302,7.2144861,0.0,0,2.3877873,0.0,0.65470642,118.32711,2.7182899,312.13028,-9.313674
2080,2080,145.4177,17.967224,7.2460532,0.0,0,2.3556671,0.0,0.65944511,118.25029,2.6818104,311.57962,-9.3133717
2082,2082,145.4181,18.032646,7.2705874,0.0,0,2.3235474,0.0,0.66330749,118.23815,2.6485205,311.02893,-9.3150616
2084,2084,145.4185,18.126097,7.3099456,0.0,0,2.2924595,0.0,0.66684794,118.39307,2.6178732,310.47824,-9.315196
2086,2086,145.4189,18.229733,7.3363085,0.0,0,2.2619042,0.0,0.67165309,118.52828,2.5850713,309.92758,-9.3148127
2088,2088,145.4193,18.341599,7.3677163,0.0,0,2.2313523,0.0,0.67539942,118.76948,2.5507171,309.37689,-9.3150091
2090,2090,145.4197,18.43236,7.4119763,0.0,0,2.2008004,0.0,0.68014634,118.79517,2.5178378,308.82623,-9.3150759
2092,2092,145.4201,18.506557,7.4375086,0.0,0,2.1702483,0.0,0.68517345,118.70969,2.4832287,308.27554,-9.3140345
2094,2094,145.4205,18.591867,7.4722023,0.0,0,2.1396964,0.0,0.68884397,118.81437,2.4510138,307.72488,-9.3143587
2096,2096,145.4209,18.709288,7.5139704,0.0,0,2.1091442,0.0,0.69399738,118.91229,2.4216297,307.17419,-9.3149424
2098,2098,145.4213,18.826757,7.5358639,0.0,0,2.0785923,0.0,0.69835794,119.17146,2.3880379,306.62354,-9.3145895
2100,2100,145.4217,18.906694,7.570179,0.0,0,2.0480404,0.0,0.70158231,119.37139,2.3537202,306.07285,-9.3146791
2102,2102,145.4221,18.994799,7.6051826,0.0,0,2.0174885,0.0,0.70684761,119.25491,2.3232863,305.52219,-9.3152237
2104,2104,145.4225,19.100063,7.6303654,0.0,0,1.9869361,0.0,0.71068501,119.36275,2.2890868,304.9715,-9.3149939
2106,2106,145.4229,19.21669,7.6677217,0.0,0,1.9563841,0.0,0.71457708,119.66673,2.2583888,304.42084,-9.3144283
2108,2108,145.4233,19.344683,7.700016,0.0,0,1.9261373,0.0,0.72027951,119.7825,2.2256188,303.87015,-9.314517
2110,2110,145.4237,19.428715,7.7289371,0.0,0,1.8970004,0.0,0.7238394,119.92786,2.1946223,303.31949,-9.3142719
2112,2112,145.4241,19.50655,7.7663426,0.0,0,1.8679364,0.0,0.72814888,119.89538,2.1607919,302.7688,-9.3148289
2114,2114,145.4245,19.608906,7.7923551,0.0,0,1.8388724,0.0,0.73332363,119.9045,2.1299205,302.21814,-9.3144941
2116,2116,145.4249,19.746019,7.8248386,0.0,0,1.8098084,0.0,0.73668182,120.28462,2.095665,301.66745,-9.3138771
2118,2118,145.4253,19.867878,7.8593783,0.0,0,1.7807443,0.0,0.74136382,120.47801,2.0667536,301.11679,-9.3131056
2120,2120,145.4257,19.960026,7.8847699,0.0,0,1.7516804,0.0,0.74632156,120.41187,2.0343122,300.73526,-9.3141708
2122,2122,145.4261,20.054953,7.9215069,0.0,0,1.7226164,0.0,0.74977362,120.58705,2.0034535,300.52283,-9.3143625
2124,2124,145.4265,20.169506,7.9502783,0.0,0,1.6935524,0.0,0.75476849,120.6758,1.9717941,300.31042,-9.3134203
2126,2126,145.4269,20.312464,7.9766068,0.0,0,1.6644883,0.0,0.75885767,120.97068,1.9407319,300.09799,-9.3128281
2128,2128,145.4273,20.434366,8.0171366,0.0,0,1.6354244,0.0,0.76305133,121.19851,1.9084994,299.88559,-9.3124905
2130,2130,145.4277,20.517038,8.0433655,0.0,0,1.6063604,0.0,0.76831639,121.10419,1.879271,299.67316,-9.3132439
2132,2132,145.4281,20.61265,8.0738707,0.0,0,1.5772964,0.0,0.77228063,121.1469,1.847182,299.46075,-9.3138733
2134,2134,145.4285,20.735386,8.1134272,0.0,0,1.5491644,0.0,0.77713859,121.31517,1.8174876,299.24832,-9.3138037
2136,2136,145.4289,20.874397,8.1309929,0.0,0,1.5215132,0.0,0.78151739,121.55744,1.7864487,299.03592,-9.3131132
2138,2138,145.4293,20.997154,8.1605816,0.0,0,1.4938653,0.0,0.78450084,121.94503,1.7566164,298.82352,-9.3134012
2140,2140,145.4297,21.090342,8.1978559,0.0,0,1.4662173,0.0,0.78980017,121.85052,1.728462,298.61108,-9.3127279
2142,2142,145.4301,21.211594,8.2189178,0.0,0,1.4385693,0.0,0.79423499,121.9567,1.6980293,298.39868,-9.3134928
2144,2144,145.4305,21.345335,8.2544584,0.0,0,1.4109213,0.0,0.7978729,122.30155,1.6705595,298.18625,-9.3137341
2146,2146,145.4309,21.486328,8.2879839,0.0,0,1.3832734,0.0,0.80399299,122.34981,1.6405095,297.97385,-9.3136129
2148,2148,145.4313,21.607639,8.3113384,0.0,0,1.3556253,0.0,0.80774742,122.56789,1.6113648,297.76141,-9.3134794
2150,2150,145.4317,21.698523,8.3454809,0.0,0,1.3279774,0.0,0.8115567,122.65879,1.5846968,297.54901,-9.3126621
2152,2152,145.4321,21.822573,8.3714199,0.0,0,1.3003293,0.0,0.8169803,122.68147,1.5534776,297.33661,-9.312315
2154,2154,145.4325,21.957752,8.3970957,0.0,0,1.2726814,0.0,0.8201502,123.04137,1.5248121,297.12418,-9.3127012
2156,2156,145.4329,22.101873,8.4294872,0.0,0,1.2450334,0.0,0.82438248,123.30135,1.495398,296.91177,-9.3134327
2158,2158,145.4333,22.222858,8.4529943,0.0,0,1.2176627,0.0,0.82958168,123.37914,1.469439,296.69934,-9.3139191
2160,2160,145.4337,22.339714,8.4853439,0.0,0,1.1913006,0.0,0.83296674,123.59798,1.437669,296.48694,-9.3139458
2162,2162,145.4341,22.472889,8.5172291,0.0,0,1.1650045,0.0,0.83807147,123.67357,1.4074887,296.27451,-9.3135471
2164,2164,145.4345,22.612762,8.5400696,0.0,0,1.1387084,0.0,0.84295911,123.85105,1.3806216,296.0621,-9.3128519
2166,2166,145.4349,22.767191,8.5765896,0.0,0,1.1124125,0.0,0.84655654,124.22513,1.3494,295.84967,-9.3127413
2168,2168,145.4353,22.906649,8.5991201,0.0,0,1.0861164,0.0,0.85153598,124.37054,1.3218437,295.63727,-9.3128681
2170,2170,145.4357,23.025253,8.6224442,0.0,0,1.0598203,0.0,0.85517102,124.58347,1.2922448,295.59863,-9.3130989
2172,2172,145.4361,23.155046,8.6583595,0.0,0,1.0335244,0.0,0.85929406,124.78411,1.2662638,295.73373,-9.3126211
2174,2174,145.4365,23.296522,8.6790838,0.0,0,1.0072284,0.0,0.86458284,124.88152,1.2345829,295.86884,-9.3114729
2176,2176,145.4369,23.448254,8.707428,0.0,0,0.98093235,0.0,0.86821461,125.25076,1.2112781,296.00394,-9.3111467
2178,2178,145.4373,23.603542,8.7449684,0.0,0,0.95463634,0.0,0.87335223,125.43045,1.1831961,296.13904,-9.3113279
2180,2180,145.4377,23.729687,8.7612371,0.0,0,0.92834044,0.0,0.87794203,125.47699,1.1543201,296.27414,-9.3127584
2182,2182,145.4381,23.863655,8.7894907,0.0,0,0.90204442,0.0,0.88078868,125.87746,1.1248672,296.40924,-9.3133249
2184,2184,145.4385,24.011065,8.8227949,0.0,0,0.87659609,0.0,0.88625461,125.96819,1.0979465,296.54434,-9.3125324
2186,2186,145.4389,24.180418,8.8409948,0.0,0,0.85158539,0.0,0.89053744,126.32602,1.0725334,296.67944,-9.3108244
2188,2188,145.4393,24.331646,8.8735228,0.0,0,0.82657731,0.0,0.89409733,126.63343,1.0479805,296.81454,-9.309948
2190,2190,145.4397,24.449926,8.9001884,0.0,0,0.8015694,0.0,0.89984661,126.50924,1.0189152,296.94965,-9.3111191
2192,2192,145.4401,24.573601,8.9211464,0.0,0,0.77656138,0.0,0.90326911,126.74522,0.99105942,297.08475,-9.3108311
2194,2194,145.4405,24.730722,8.95152,0.0,0,0.75155336,0.0,0.90697253,127.06567,0.967004,297.21985,-9.3113537
2196,2196,145.4409,24.908092,8.9738417,0.0,0,0.72654539,0.0,0.91235971,127.28822,0.94030511,297.35495,-9.3114986
2198,2198,145.4413,25.052458,8.9992828,0.0,0,0.70153737,0.0,0.91551548,127.6442,0.91411251,297.49005,-9.3109446
2200,2200,145.4417,25.183384,9.0297203,0.0,0,0.67652941,0.0,0.92017579,127.70664,0.88812566,297.62515,-9.3114853
2202,2202,145.4421,25.32189,9.049901,0.0,0,0.65152138,0.0,0.92536318,127.72482,0.86294836,297.76025,-9.3105612
2204,2204,145.4425,25.488075,9.0789051,0.0,0,0.62651336,0.0,0.92831922,128.17633,0.83641654,297.89536,-9.3117399
2206,2206,145.4429,25.662701,9.10291,0.0,0,0.6015054,0.0,0.93304086,128.43753,0.81065845,298.03046,-9.3117943
2208,2208,145.4433,25.803368,9.1216879,0.0,0,0.57674509,0.0,0.93729013,128.60332,0.78400981,298.16556,-9.311532
2210,2210,145.4437,25.935711,9.1563768,0.0,0,0.55288601,0.0,0.9411059,128.79453,0.75981313,298.30066,-9.3113947
2212,2212,145.4441,26.0924,9.1750507,0.0,0,0.52908593,0.0,0.94601858,128.88445,0.73305327,298.43579,-9.3114357
2214,2214,145.4445,26.265594,9.1934862,0.0,0,0.50528592,0.0,0.94906527,129.34187,0.71070623,298.57089,-9.3105679
2216,2216,145.4449,26.435806,9.2264795,0.0,0,0.4814859,0.0,0.95314419,129.69353,0.68480384,298.70599,-9.3112288
2218,2218,145.4453,26.581163,9.2430534,0.0,0,0.45768592,0.0,0.95821327,129.76132,0.6613186,298.84109,-9.3113394
2220,2220,145.4457,26.706764,9.2683153,0.0,0,0.4338859,0.0,0.96133262,129.94981,0.63575333,299.09009,-9.3108549
2222,2222,145.4461,26.860298,9.3007555,0.0,0,0.41008592,0.0,0.96640432,130.01096,0.61340451,299.45294,-9.3103495
2224,2224,145.4465,27.045452,9.3139305,0.0,0,0.3862859,0.0,0.97078842,130.38087,0.59088856,299.81583,-9.3092813
2226,2226,145.4469,27.234587,9.3403826,0.0,0,0.36248589,0.0,0.97355467,130.90723,0.57014412,300.17868,-9.3098822
2228,2228,145.4473,27.384916,9.3673763,0.0,0,0.3386859,0.0,0.97897309,130.93744,0.54459828,300.54156,-9.3106375
2230,2230,145.4477,27.524336,9.3812246,0.0,0,0.31488591,0.0,0.9823007,131.17441,0.52146816,300.90442,-9.3106775
2232,2232,145.4481,27.696964,9.408555,0.0,0,0.29108587,0.0,0.98547471,131.56888,0.49797374,301.2673,-9.3091946
2234,2234,145.4485,27.881937,9.4314632,0.0,0,0.26805463,0.0,0.99119419,131.66405,0.47597352,301.63019,-9.3087578