File: clean data/testID_0250.csv
index,Time(sec),Force(kN),Jaw(mm),PowAngle(deg),Power(W),Pram,PTemp,Strain,Stress(MPa),Stroke(mm),TC1(C),wedge(mm)
2426,195.3743,1.6006684,0.027698597,0.0,0,9.9338627,0.0,0.0019562817,19.977846,10.036023,451.17426,-9.2363138
2436,195.3763,2.6604257,0.032160163,0.0,0,9.903863,0.0,0.0020564727,33.5853,10.00562,451.32965,-9.234973
2446,195.3783,3.5297141,0.052079827,0.0,0,9.8738632,0.0,0.0032000374,44.697872,9.980587,451.48505,-9.2348566
2456,195.3803,3.8048451,0.076714605,0.0,0,9.8438625,0.0,0.0050530573,48.072727,9.9468203,453.29224,-9.234273
2466,195.3823,3.9607203,0.11153616,0.0,0,9.8138628,0.0,0.0075820843,50.003361,9.9109125,455.621,-9.2334337
2476,195.3843,4.077538,0.14354818,0.0,0,9.7838631,0.0,0.0097487392,51.438236,9.8752213,457.94974,-9.2333612
2486,195.3863,4.1589546,0.17760183,0.0,0,9.7538624,0.0,0.011924358,52.359917,9.842473,460.2785,-9.2347698
2496,195.3883,4.2196636,0.2117691,0.0,0,9.7238626,0.0,0.013909956,53.017548,9.8138418,462.60724,-9.2347679
2506,195.3903,4.2576723,0.23757932,0.0,0,9.6938629,0.0,0.015789634,53.372711,9.780158,465.29794,-9.2333879
2516,195.3923,4.2709541,0.2683005,0.0,0,9.6638622,0.0,0.018035809,53.373348,9.7451868,468.10928,-9.233613
2526,195.3943,4.265677,0.2938008,0.0,0,9.6338625,0.0,0.019956177,53.245399,9.7200718,470.92062,-9.2340698
2536,195.3963,4.2998409,0.32205915,0.0,0,9.6038628,0.0,0.021814374,53.599895,9.6898804,473.73196,-9.2339182
2546,195.3983,4.3171616,0.35586131,0.0,0,9.573863,0.0,0.023855951,53.575291,9.656971,476.5433,-9.2352619
2556,195.4003,4.3499002,0.38195553,0.0,0,9.5438633,0.0,0.025640141,53.963596,9.630949,477.89188,-9.2344398
2566,195.4023,4.3885188,0.41294357,0.0,0,9.5138626,0.0,0.027794512,54.32061,9.5974188,478.72656,-9.2363749
2576,195.4043,4.400208,0.4396188,0.0,0,9.4838629,0.0,0.029860774,54.371025,9.5678873,479.56125,-9.2353258
2586,195.4063,4.4126115,0.47140297,0.0,0,9.4545488,0.0,0.032053433,54.34404,9.5391178,480.39594,-9.2345314
2596,195.4083,4.4308581,0.50618249,0.0,0,9.4252844,0.0,0.034353707,54.593105,9.5031881,481.23062,-9.2333689
2606,195.4103,4.4274392,0.53323543,0.0,0,9.3960209,0.0,0.036068816,54.487465,9.4755907,481.7084,-9.2357359
2616,195.4123,4.4447603,0.56749356,0.0,0,9.3667564,0.0,0.038310982,54.532185,9.446887,482.0542,-9.2359819
2626,195.4143,4.4410343,0.59245002,0.0,0,9.3374929,0.0,0.04028523,54.29155,9.4138241,482.39999,-9.234417
2636,195.4163,4.4617558,0.62278897,0.0,0,9.3082285,0.0,0.042523183,54.473831,9.3848829,482.74579,-9.2343044
2646,195.4183,4.486764,0.65534645,0.0,0,9.278965,0.0,0.04484807,54.615959,9.3550129,483.09158,-9.2355585
2656,195.4203,4.5014291,0.6857872,0.0,0,9.2497005,0.0,0.04674482,54.733177,9.3219261,483.34726,-9.2348652
2666,195.4223,4.4981432,0.71946156,0.0,0,9.2204361,0.0,0.048853628,54.562981,9.2881641,483.56784,-9.2340517
2676,195.4243,4.4994178,0.74466926,0.0,0,9.1911726,0.0,0.050706364,54.4132,9.2569542,483.78842,-9.2340212
2686,195.4263,4.4985271,0.77451164,0.0,0,9.1619081,0.0,0.053032085,54.249107,9.2289391,484.00903,-9.2353039
2696,195.4283,4.489017,0.79988921,0.0,0,9.1326447,0.0,0.055040058,54.196022,9.2031898,484.22961,-9.237071
2706,195.4303,4.4892993,0.82881486,0.0,0,9.1033802,0.0,0.056927931,54.105801,9.1725454,484.40363,-9.2371588
2716,195.4323,4.5091109,0.8625589,0.0,0,9.0741158,0.0,0.059066869,54.0634,9.1407995,484.55865,-9.2357407
2726,195.4343,4.5227056,0.8869887,0.0,0,9.0448523,0.0,0.060759626,54.219585,9.115613,484.71365,-9.2360935
2736,195.4363,4.5430775,0.91716397,0.0,0,9.0155888,0.0,0.062925443,54.336796,9.0834208,484.86868,-9.2360859
2746,195.4383,4.5467143,0.94229126,0.0,0,8.9863243,0.0,0.064973988,54.172302,9.0560293,485.02368,-9.2345877
2756,195.4403,4.5537634,0.97258794,0.0,0,8.9570608,0.0,0.067216732,54.254585,9.0247135,485.16202,-9.2352352
2766,195.4423,4.5567498,1.0045149,0.0,0,8.9277964,0.0,0.069399096,54.235455,8.9946918,485.29318,-9.2354517
2776,195.4443,4.5747924,1.0321547,0.0,0,8.8985329,0.0,0.071150288,54.281651,8.9666367,485.42435,-9.2363605
2786,195.4463,4.58184,1.0623968,0.0,0,8.8692684,0.0,0.0731484,54.253849,8.9338341,485.55551,-9.2365551
2796,195.4483,4.5877738,1.0872623,0.0,0,8.840004,0.0,0.075185068,54.179966,8.9066067,485.68671,-9.2347689
2806,195.4503,4.6005907,1.1161666,0.0,0,8.8107405,0.0,0.077509023,54.158756,8.8766708,485.79318,-9.2348909
2816,195.4523,4.6190948,1.1455641,0.0,0,8.781476,0.0,0.079686776,54.317104,8.8489609,485.88858,-9.2360973
2826,195.4543,4.6263485,1.175441,0.0,0,8.7522125,0.0,0.081568122,54.324532,8.818119,485.98395,-9.237155
2836,195.4563,4.6437221,1.2094057,0.0,0,8.7242813,0.0,0.083693527,54.3703,8.7908421,486.07935,-9.2368202
2846,195.4583,4.6652994,1.2342185,0.0,0,8.6964493,0.0,0.085676454,54.454594,8.7591143,486.17474,-9.2333679
2856,195.4603,4.6831093,1.2640648,0.0,0,8.6686182,0.0,0.088062473,54.527962,8.7266779,486.21338,-9.2345943
2866,195.4623,4.6599298,1.2911804,0.0,0,8.6407852,0.0,0.090249807,54.214996,8.7009621,486.22531,-9.2369146
2876,195.4643,4.6580887,1.32129,0.0,0,8.6129532,0.0,0.092279352,54.030148,8.66959,486.23721,-9.2367544
2886,195.4663,4.6386552,1.353797,0.0,0,8.5851212,0.0,0.094361968,53.737488,8.6424885,486.24915,-9.2364845
2896,195.4683,4.6572046,1.3762316,0.0,0,8.5572891,0.0,0.096011236,53.78363,8.6139841,486.26108,-9.2354298
2906,195.4703,4.6619482,1.4017066,0.0,0,8.529458,0.0,0.097942568,53.779701,8.5877428,486.28101,-9.2335014
2916,195.4723,4.6722784,1.427197,0.0,0,8.5016251,0.0,0.10007926,53.850887,8.5622988,486.30484,-9.2359676
2926,195.4743,4.6922135,1.4525522,0.0,0,8.473794,0.0,0.10212015,53.85585,8.5350275,486.32867,-9.235158
2936,195.4763,4.7106304,1.485394,0.0,0,8.445961,0.0,0.10436668,54.070221,8.503705,486.35254,-9.2344189
2946,195.4783,4.7335777,1.5111655,0.0,0,8.418129,0.0,0.10605867,54.216442,8.472477,486.37637,-9.2348375
2956,195.4803,4.7425838,1.5416399,0.0,0,8.3902979,0.0,0.10813444,54.167274,8.4441214,486.44745,-9.2342577
2966,195.4823,4.7322326,1.5635331,0.0,0,8.3624649,0.0,0.11000637,53.932014,8.4157352,486.54285,-9.2349329
2976,195.4843,4.7584805,1.5915644,0.0,0,8.3346348,0.0,0.1123551,54.061573,8.3914881,486.63824,-9.235075
2986,195.4863,4.7636762,1.6221844,0.0,0,8.3068018,0.0,0.1146774,54.071262,8.3618765,486.73361,-9.2368584
2996,195.4883,4.7876549,1.6490495,0.0,0,8.2789698,0.0,0.11638272,54.209072,8.3370275,486.82901,-9.2347355
3006,195.4903,4.8066692,1.6805612,0.0,0,8.2511387,0.0,0.11839759,54.278576,8.3087559,486.92053,-9.2334614
3016,195.4923,4.8242025,1.7017891,0.0,0,8.2233057,0.0,0.12015737,54.489895,8.2782412,487.00995,-9.2347851
3026,195.4943,4.8300681,1.7315364,0.0,0,8.1954746,0.0,0.1226953,54.355259,8.2518272,487.09937,-9.2362795
3036,195.4963,4.8302655,1.7580671,0.0,0,8.1676416,0.0,0.12499443,54.265759,8.2264719,487.18881,-9.2363167
3046,195.4983,4.8329382,1.7870882,0.0,0,8.1398106,0.0,0.12691845,54.250347,8.1954517,487.27823,-9.2337513
3056,195.5003,4.8529963,1.8191739,0.0,0,8.1119785,0.0,0.12903582,54.244305,8.1676302,487.36768,-9.2349615
3066,195.5023,4.86097,1.8418864,0.0,0,8.0841455,0.0,0.13078447,54.259823,8.139535,487.45709,-9.235364
3076,195.5043,4.9020729,1.8717586,0.0,0,8.0563145,0.0,0.13310124,54.609753,8.1147423,487.54654,-9.2354946
3086,195.5063,4.9146967,1.8976887,0.0,0,8.0297422,0.0,0.13541976,54.643421,8.0838633,487.63596,-9.2343149
3096,195.5083,4.9403348,1.9275557,0.0,0,8.0032616,0.0,0.13772075,54.759914,8.054987,487.7254,-9.2353888
3106,195.5103,4.9380546,1.959354,0.0,0,7.9767814,0.0,0.13996349,54.638046,8.0194883,487.81107,-9.2352304
3116,195.5123,4.9327912,1.988507,0.0,0,7.9503016,0.0,0.14200172,54.511715,7.9923778,487.89453,-9.2354116
3126,195.5143,4.8961825,2.0154846,0.0,0,7.9238214,0.0,0.14398713,54.056908,7.9665999,487.978,-9.2345963
3136,195.5163,4.8962097,2.0375798,0.0,0,7.8973413,0.0,0.14594428,53.854546,7.9382997,488.06149,-9.2346601
3146,195.5183,4.883461,2.0618632,0.0,0,7.8708611,0.0,0.1480602,53.650566,7.9105463,488.14496,-9.2354345
3156,195.5203,4.8856006,2.0893457,0.0,0,7.8443813,0.0,0.15023918,53.586899,7.8902016,488.20624,-9.235219
3166,195.5223,4.8869934,2.1147115,0.0,0,7.8179016,0.0,0.15184377,53.382233,7.8654165,488.25394,-9.2349463
3176,195.5243,4.9305482,2.1411505,0.0,0,7.7914214,0.0,0.15360381,53.812351,7.8354378,488.30164,-9.2339993
3186,195.5263,4.9541698,2.1625872,0.0,0,7.7649412,0.0,0.1554791,53.962597,7.8138657,488.34933,-9.2349977
3196,195.5283,4.9611111,2.1886845,0.0,0,7.738461,0.0,0.15781765,53.998341,7.7875171,488.39703,-9.2360678
3206,195.5303,4.9800787,2.2158678,0.0,0,7.7119808,0.0,0.16017459,54.042614,7.7612166,488.43747,-9.2342529
3216,195.5323,4.9943137,2.2417877,0.0,0,7.6855011,0.0,0.16190132,54.104481,7.7307348,488.47324,-9.2346296
3226,195.5343,5.0045762,2.2739396,0.0,0,7.6590209,0.0,0.1641414,53.984909,7.7057571,488.509,-9.2347946
3236,195.5363,5.0025921,2.2976723,0.0,0,7.6325412,0.0,0.16598767,53.990627,7.6746378,488.54477,-9.2337332
3246,195.5383,5.0135689,2.3254969,0.0,0,7.6060615,0.0,0.1683652,54.005367,7.6504049,488.58054,-9.2347145
3256,195.5403,5.0226474,2.3477314,0.0,0,7.5795813,0.0,0.17042682,53.866131,7.6235828,488.62347,-9.23493
3266,195.5423,5.0255876,2.3762774,0.0,0,7.5531011,0.0,0.17267129,53.881027,7.5955629,488.67117,-9.2346201
3276,195.5443,5.0458617,2.4068859,0.0,0,7.5266213,0.0,0.17492053,54.013531,7.5695925,488.71887,-9.2352695
3286,195.5463,5.0403566,2.4308436,0.0,0,7.5001407,0.0,0.17660709,53.802616,7.5436411,488.76654,-9.2350464
3296,195.5483,5.0516706,2.4594257,0.0,0,7.4736609,0.0,0.17868716,53.773148,7.5172586,488.81424,-9.2352877
3306,195.5503,5.0445976,2.4805758,0.0,0,7.4471812,0.0,0.18067162,53.603329,7.4872622,488.82675,-9.2349224
3316,195.5523,5.0542626,2.5046806,0.0,0,7.420701,0.0,0.18295735,53.621037,7.4643321,488.81485,-9.2357283
3326,195.5543,5.0577264,2.5344994,0.0,0,7.3942208,0.0,0.18532807,53.541817,7.4373436,488.80292,-9.2352781
3336,195.5563,5.0869184,2.5607598,0.0,0,7.368948,0.0,0.18712179,53.697205,7.4101295,488.79099,-9.2351828
3346,195.5583,5.1103115,2.5921934,0.0,0,7.3437638,0.0,0.18926263,53.830864,7.3798366,488.77905,-9.2347488
3356,195.5603,5.1016049,2.61114,0.0,0,7.3185802,0.0,0.19102772,53.745045,7.3540092,488.7049,-9.2346821
3366,195.5623,5.0871243,2.6391306,0.0,0,7.293396,0.0,0.19358607,53.418789,7.329443,488.58566,-9.233922
3376,195.5643,5.1042032,2.663913,0.0,0,7.2682123,0.0,0.19583365,53.419994,7.2997589,488.4664,-9.2343807
3386,195.5663,5.1144748,2.6898758,0.0,0,7.2430282,0.0,0.19765531,53.440113,7.275352,488.34717,-9.2361584
3396,195.5683,5.1083002,2.7200651,0.0,0,7.217844,0.0,0.19980732,53.26432,7.2516055,488.22794,-9.2357359
3406,195.5703,5.1055436,2.7402141,0.0,0,7.1926599,0.0,0.20149741,53.141571,7.2267337,488.03732,-9.2349691
3416,195.5723,5.0821218,2.764205,0.0,0,7.1674757,0.0,0.20357831,52.770245,7.2042603,487.79291,-9.2352161
3426,195.5743,5.1016254,2.7850354,0.0,0,7.142292,0.0,0.20562656,52.817062,7.1813602,487.54846,-9.2350349
3436,195.5763,5.1216908,2.8119431,0.0,0,7.1171079,0.0,0.20779452,53.054512,7.1531644,487.30402,-9.2345619
3446,195.5783,5.1593308,2.8404891,0.0,0,7.0919242,0.0,0.20985146,53.239967,7.1301146,487.05957,-9.2341909
3456,195.5803,5.1743174,2.8617134,0.0,0,7.06674,0.0,0.21146964,53.324368,7.1033158,486.10721,-9.2345276
3466,195.5823,5.1772375,2.8907044,0.0,0,7.0415564,0.0,0.21377075,53.285355,7.0780916,484.59866,-9.23423
3476,195.5843,5.1862621,2.9120288,0.0,0,7.0163722,0.0,0.2157817,53.241093,7.0536509,483.09012,-9.2342644
3486,195.5863,5.1901708,2.9355545,0.0,0,6.9911876,0.0,0.21812624,53.097389,7.0280361,481.58157,-9.2348213
3496,195.5883,5.2046242,2.9646752,0.0,0,6.9660039,0.0,0.22042772,53.115726,7.002202,480.07306,-9.2354889
3506,195.5903,5.2214675,2.9900725,0.0,0,6.9408202,0.0,0.22214906,53.186909,6.9748697,478.43637,-9.2346716
3516,195.5923,5.2491646,3.0200181,0.0,0,6.9156361,0.0,0.22436514,53.372669,6.9482646,476.69489,-9.2349405
3526,195.5943,5.2473235,3.0397861,0.0,0,6.8904519,0.0,0.226248,53.27243,6.9244103,474.9534,-9.2353172
3536,195.5963,5.2804675,3.0652275,0.0,0,6.8652678,0.0,0.22865066,53.479801,6.8986001,473.21191,-9.2349949
3546,195.5983,5.2754645,3.0900977,0.0,0,6.8400841,0.0,0.23102476,53.326336,6.8685031,471.47043,-9.2359982
3556,195.6003,5.3031049,3.1171324,0.0,0,6.8148999,0.0,0.23304468,53.421726,6.8419318,470.50821,-9.2357616
3566,195.6023,5.2777448,3.1485906,0.0,0,6.7897158,0.0,0.2352526,53.100857,6.8185821,470.20978,-9.2355547
3576,195.6043,5.2755399,3.1681285,0.0,0,6.7645321,0.0,0.23693739,53.009502,6.7920208,469.91138,-9.2351389
3586,195.6063,5.2868276,3.191463,0.0,0,6.7404876,0.0,0.23917072,52.944523,6.7692876,469.61295,-9.2338648
3596,195.6083,5.2874017,3.2113137,0.0,0,6.7165279,0.0,0.24121784,52.860508,6.744462,469.31451,-9.2355423
3606,195.6103,5.3189468,3.2384014,0.0,0,6.6925678,0.0,0.24349971,53.061619,6.7232718,469.25018,-9.2353449
3616,195.6123,5.3298836,3.2644937,0.0,0,6.6686077,0.0,0.24541405,53.063736,6.6959429,469.39343,-9.2349768
3626,195.6143,5.3534741,3.2877324,0.0,0,6.6446476,0.0,0.24717319,53.190125,6.6686783,469.53665,-9.2331648
3636,195.6163,5.3580732,3.3156331,0.0,0,6.6206875,0.0,0.2494629,53.138889,6.6445284,469.6799,-9.2354059
3646,195.6183,5.3332024,3.3344009,0.0,0,6.5967274,0.0,0.25141063,52.884697,6.621706,469.82315,-9.2348928
3656,195.6203,5.3341608,3.3574746,0.0,0,6.5727677,0.0,0.25364262,52.679794,6.6004014,469.92914,-9.2355204
3666,195.6223,5.3361573,3.382848,0.0,0,6.5488076,0.0,0.25579375,52.646049,6.5754037,470.00076,-9.2344398
3676,195.6243,5.3606133,3.4058509,0.0,0,6.524848,0.0,0.25751323,52.794029,6.5509501,470.07239,-9.233675
3686,195.6263,5.3808241,3.4330237,0.0,0,6.5008879,0.0,0.25941288,52.816162,6.5294509,470.14401,-9.2351608
3696,195.6283,5.3890185,3.4517739,0.0,0,6.4769278,0.0,0.26131502,52.868988,6.5052137,470.21564,-9.2336941
3706,195.6303,5.4131651,3.4735763,0.0,0,6.4529681,0.0,0.26352218,52.927628,6.4804382,470.34207,-9.2349167
3716,195.6323,5.4360352,3.4970746,0.0,0,6.429008,0.0,0.26581258,53.006744,6.45608,470.52112,-9.2347603
3726,195.6343,5.4560513,3.5228326,0.0,0,6.4050479,0.0,0.26776254,53.026855,6.4320612,470.70016,-9.2340069
3736,195.6363,5.4664211,3.55265,0.0,0,6.3810878,0.0,0.26992819,53.142754,6.4089537,470.87924,-9.2324839
3746,195.6383,5.4731627,3.5730457,0.0,0,6.3571277,0.0,0.2716839,53.125973,6.3839488,471.05829,-9.2340155
3756,195.6403,5.4807415,3.5959995,0.0,0,6.3331676,0.0,0.2740407,52.958897,6.3555884,471.30899,-9.2352552
3766,195.6423,5.4965048,3.6196134,0.0,0,6.3092079,0.0,0.27643645,53.037319,6.3350139,471.63129,-9.2345676
3776,195.6443,5.4979711,3.644033,0.0,0,6.2852478,0.0,0.27847931,53.081169,6.3118496,471.95358,-9.2342358
3786,195.6463,5.5101914,3.6730034,0.0,0,6.2612882,0.0,0.28075698,53.060577,6.2829313,472.27591,-9.2349701
3796,195.6483,5.4979057,3.6943693,0.0,0,6.2373281,0.0,0.28243729,52.773636,6.2602463,472.59821,-9.2344084
3806,195.6503,5.4998846,3.7183857,0.0,0,6.2133679,0.0,0.28457907,52.667809,6.235393,472.92044,-9.2339211
3816,195.6523,5.4901547,3.7375307,0.0,0,6.1894078,0.0,0.2865907,52.536457,6.2137523,473.24261,-9.2342224
3826,195.6543,5.4927888,3.7593119,0.0,0,6.1654477,0.0,0.28880456,52.358929,6.1888804,473.56479,-9.2355003
3836,195.6563,5.520813,3.7844663,0.0,0,6.1425796,0.0,0.29100224,52.520252,6.1669168,473.88696,-9.2338476
3846,195.6583,5.5558672,3.8084686,0.0,0,6.1197915,0.0,0.29277277,52.789501,6.1427989,474.20914,-9.2345552
3856,195.6603,5.5809989,3.8383265,0.0,0,6.0970035,0.0,0.29504961,52.884689,6.1177044,474.53406,-9.2345419
3866,195.6623,5.567625,3.8553636,0.0,0,6.0742154,0.0,0.2968353,52.783516,6.097909,474.862,-9.234026
3876,195.6643,5.5775356,3.8769112,0.0,0,6.0514274,0.0,0.29917786,52.669876,6.072742,475.18997,-9.2341566
3886,195.6663,5.5740428,3.8999474,0.0,0,6.0286393,0.0,0.30148166,52.575764,6.0483489,475.51791,-9.2344398
3896,195.6683,5.5837564,3.9268525,0.0,0,6.0058513,0.0,0.30361432,52.553036,6.0244045,475.84586,-9.2339878
3906,195.6703,5.5867281,3.9536219,0.0,0,5.9830637,0.0,0.30565175,52.455467,6.0039577,476.19339,-9.2341547
3916,195.6723,5.6116438,3.9721682,0.0,0,5.9602752,0.0,0.30732042,52.612892,5.9801865,476.56305,-9.2347555
3926,195.6743,5.6060896,3.994765,0.0,0,5.9374871,0.0,0.30958024,52.380062,5.9557204,476.93268,-9.2361565
3936,195.6763,5.5990691,4.0152874,0.0,0,5.9146996,0.0,0.3119022,52.303761,5.9320178,477.30234,-9.2350082
3946,195.6783,5.6206689,4.0410933,0.0,0,5.8919115,0.0,0.31418845,52.316765,5.9111066,477.67197,-9.2350769
3956,195.6803,5.6282916,4.0682836,0.0,0,5.8691235,0.0,0.31625429,52.207321,5.8865995,478.05734,-9.2330999
3966,195.6823,5.6456261,4.0878382,0.0,0,5.8463354,0.0,0.31784204,52.296776,5.8614783,478.46118,-9.2340078
3976,195.6843,5.6428394,4.1129189,0.0,0,5.8235474,0.0,0.32015008,52.169209,5.838882,478.86499,-9.2360497
3986,195.6863,5.6575556,4.1289763,0.0,0,5.8007593,0.0,0.32198641,52.272152,5.8194785,479.2688,-9.2348185
3996,195.6883,5.6599898,4.1527233,0.0,0,5.7779708,0.0,0.32440954,52.085915,5.7956967,479.67264,-9.2338448
4006,195.6903,5.6926847,4.1798773,0.0,0,5.7551832,0.0,0.32688192,52.268669,5.7701998,480.03003,-9.2338896
4016,195.6923,5.6921844,4.2030458,0.0,0,5.7323952,0.0,0.32865644,52.174702,5.746099,480.37582,-9.2341309
4026,195.6943,5.685216,4.2289138,0.0,0,5.7096071,0.0,0.33062649,52.027519,5.7254763,480.72162,-9.2348261
4036,195.6963,5.6794047,4.2443323,0.0,0,5.6868191,0.0,0.33247322,51.806236,5.7021527,481.06741,-9.2349148
4046,195.6983,5.661644,4.2653799,0.0,0,5.664031,0.0,0.33475679,51.602859,5.68014,481.41324,-9.2346487
4056,195.7003,5.6803575,4.2873449,0.0,0,5.641243,0.0,0.33704031,51.591686,5.660646,481.71191,-9.2353773
4066,195.7023,5.6922355,4.3096004,0.0,0,5.6184549,0.0,0.33876809,51.642941,5.6395574,481.99811,-9.2349138
4076,195.7043,5.7366281,4.3353715,0.0,0,5.5956669,0.0,0.34066209,51.941582,5.6155219,482.28427,-9.2353535
4086,195.7063,5.744658,4.3542171,0.0,0,5.5739112,0.0,0.34250322,51.949413,5.5951014,482.57047,-9.234828
4096,195.7083,5.7783694,4.3783441,0.0,0,5.5522313,0.0,0.34503135,52.126663,5.5727363,482.85663,-9.2340736
4106,195.7103,5.7993512,4.397944,0.0,0,5.530551,0.0,0.3472864,52.16333,5.5495501,483.07306,-9.2340546
4116,195.7123,5.821847,4.4219761,0.0,0,5.5088711,0.0,0.34956414,52.289288,5.5212665,483.26981,-9.2344446
4126,195.7143,5.8287287,4.4529238,0.0,0,5.4871912,0.0,0.35200626,52.188011,5.4983535,483.46652,-9.234971
4136,195.7163,5.8162594,4.471374,0.0,0,5.4655113,0.0,0.35369703,51.975552,5.474905,483.66327,-9.2346182
4146,195.7183,5.8027067,4.4953799,0.0,0,5.443831,0.0,0.35592082,51.7505,5.4551377,483.86002,-9.2343521
4156,195.7203,5.7855344,4.5087018,0.0,0,5.4221511,0.0,0.35757479,51.500385,5.4301734,484.02463,-9.234169
4166,195.7223,5.793612,4.5291009,0.0,0,5.4004717,0.0,0.35986304,51.41217,5.4106288,484.17966,-9.2342863
4176,195.7243,5.7905483,4.5579157,0.0,0,5.3787909,0.0,0.36243004,51.335098,5.3903027,484.33469,-9.2361784
4186,195.7263,5.81148,4.5758629,0.0,0,5.357111,0.0,0.36372679,51.378738,5.3728447,484.48969,-9.2340822
4196,195.7283,5.8432646,4.6002789,0.0,0,5.3354311,0.0,0.36575633,51.579594,5.3489699,484.64471,-9.2352152
4206,195.7303,5.8671536,4.6168995,0.0,0,5.3137512,0.0,0.3677012,51.682121,5.3269172,484.76801,-9.2343225
4216,195.7323,5.8944192,4.6375704,0.0,0,5.2920713,0.0,0.37010837,51.78804,5.3042774,484.88129,-9.2340059
4226,195.7343,5.9088979,4.6596193,0.0,0,5.270391,0.0,0.37237203,51.796177,5.2844548,484.99457,-9.2340126
4236,195.7363,5.9431438,4.6835656,0.0,0,5.2487116,0.0,0.37438452,52.005531,5.2600327,485.10785,-9.2351789
4246,195.7383,5.9422884,4.7099938,0.0,0,5.2270312,0.0,0.37641042,51.9412,5.2411094,485.22113,-9.2347383
4256,195.7403,5.9456306,4.7275939,0.0,0,5.2053514,0.0,0.37821403,51.873074,5.2156801,485.34781,-9.2338343
4266,195.7423,5.9499874,4.746995,0.0,0,5.183671,0.0,0.38033035,51.757526,5.1972947,485.47897,-9.2338066
4276,195.7443,5.9550638,4.7671065,0.0,0,5.1619911,0.0,0.38288903,51.715439,5.1754584,485.61014,-9.2348099
4286,195.7463,5.973866,4.7898459,0.0,0,5.1403112,0.0,0.38495231,51.715092,5.1548429,485.7413,-9.233511
4296,195.7483,6.0054879,4.8175025,0.0,0,5.1186314,0.0,0.38713136,51.876427,5.129426,485.87247,-9.2350807
4306,195.7503,6.0422487,4.8365746,0.0,0,5.096951,0.0,0.38895014,52.149876,5.1074829,485.96832,-9.233325
4316,195.7523,6.0500307,4.8602648,0.0,0,5.0752711,0.0,0.39126024,52.09404,5.0831728,486.05182,-9.2343369
4326,195.7543,6.0493321,4.8784599,0.0,0,5.0535917,0.0,0.39342609,51.976112,5.0625644,486.13528,-9.233964
4336,195.7563,6.0556026,4.8983345,0.0,0,5.0328984,0.0,0.39570811,51.806805,5.0393333,486.21875,-9.2336874
4346,195.7583,6.0709252,4.9253268,0.0,0,5.0122786,0.0,0.39821738,51.914669,5.01895,486.30222,-9.2340336
4356,195.7603,6.0619144,4.9449425,0.0,0,4.9916587,0.0,0.39977419,51.807606,5.0019846,486.21161,-9.2336779
4366,195.7623,6.0928164,4.971416,0.0,0,4.9710383,0.0,0.40203577,51.863281,4.977026,486.05661,-9.2338028
4376,195.7643,6.0906534,4.9878716,0.0,0,4.9504185,0.0,0.40412506,51.750481,4.9579768,485.90158,-9.2342501
4386,195.7663,6.0819511,5.0053906,0.0,0,4.9297981,0.0,0.40627167,51.525089,4.9332399,485.74658,-9.2354631
4396,195.7683,6.0875096,5.0283246,0.0,0,4.9091783,0.0,0.40869147,51.485329,4.9131131,485.59155,-9.2345476
4406,195.7703,6.1020398,5.0500469,0.0,0,4.8885584,0.0,0.41048348,51.568363,4.8958035,485.41937,-9.234087
4416,195.7723,6.1239176,5.0758195,0.0,0,4.8679385,0.0,0.41255578,51.647339,4.8718352,485.24051,-9.2340679
4426,195.7743,6.0973892,5.0903864,0.0,0,4.8473182,0.0,0.41420397,51.292633,4.8533096,485.06165,-9.2333221
4436,195.7763,6.0965362,5.1082253,0.0,0,4.8266983,0.0,0.41639134,51.157017,4.8356528,484.88278,-9.2334986
4446,195.7783,6.1060753,5.127665,0.0,0,4.8060784,0.0,0.41870478,51.171215,4.8169255,484.70392,-9.2350559
4456,195.7803,6.1237235,5.1486959,0.0,0,4.7854586,0.0,0.42065018,51.22356,4.7943549,484.57159,-9.2353687
4466,195.7823,6.1332259,5.172339,0.0,0,4.7648382,0.0,0.42257798,51.20084,4.7762761,484.45831,-9.2329903
4476,195.7843,6.1568236,5.1896009,0.0,0,4.7442183,0.0,0.42431605,51.331131,4.7549076,484.34506,-9.2348967
4486,195.7863,6.1909294,5.2133245,0.0,0,4.723598,0.0,0.42665964,51.486935,4.7348509,484.23178,-9.2352676
4496,195.7883,6.2065783,5.2271276,0.0,0,4.7029781,0.0,0.42868808,51.486759,4.7110705,484.1185,-9.2324734
4506,195.7903,6.2429276,5.2507758,0.0,0,4.6823583,0.0,0.43118784,51.625721,4.6893926,484.16797,-9.2338276
4516,195.7923,6.2451138,5.2748141,0.0,0,4.6617384,0.0,0.43357086,51.570499,4.6690526,484.2872,-9.2342043
4526,195.7943,6.2428002,5.2943001,0.0,0,4.6411185,0.0,0.43513,51.459774,4.6493983,484.40643,-9.2342739
4536,195.7963,6.2186966,5.3188047,0.0,0,4.6204987,0.0,0.43736446,51.102558,4.6319799,484.5257,-9.2332602
4546,195.7983,6.2332444,5.3336267,0.0,0,4.5998783,0.0,0.4392198,51.065521,4.6089578,484.64493,-9.2347059
4556,195.8003,6.2404804,5.3533134,0.0,0,4.579258,0.0,0.44181758,51.068851,4.5918374,484.81354,-9.2355804
4566,195.8023,6.2733898,5.3746715,0.0,0,4.5586381,0.0,0.44407448,51.262218,4.5719318,485.00433,-9.2350111
4576,195.8043,6.3136649,5.3966961,0.0,0,4.5380182,0.0,0.44592068,51.550339,4.549149,485.19513,-9.2344351
4586,195.8063,6.3692694,5.4258623,0.0,0,4.518333,0.0,0.44842678,51.773548,4.5225186,485.38593,-9.2341461
4596,195.8083,6.3875642,5.44278,0.0,0,4.4987168,0.0,0.45031527,51.85548,4.5003047,485.57669,-9.2330151
4606,195.8103,6.381803,5.4604807,0.0,0,4.4791012,0.0,0.45266807,51.704288,4.4779019,485.70264,-9.2334557
4616,195.8123,6.3610692,5.4834633,0.0,0,4.4594851,0.0,0.45540553,51.348843,4.458025,485.798,-9.2349682
4626,195.8143,6.2902336,5.5041361,0.0,0,4.4398689,0.0,0.45749834,50.713875,4.4345903,485.8934,-9.2355728
4636,195.8163,6.2645354,5.5274091,0.0,0,4.4202533,0.0,0.45938358,50.430893,4.4203243,485.9888,-9.2347631
4646,195.8183,6.242485,5.5404911,0.0,0,4.4006371,0.0,0.46068007,50.110649,4.403409,486.0842,-9.2347355
4656,195.8203,6.2503409,5.5596046,0.0,0,4.381021,0.0,0.46273464,50.083256,4.3873639,485.94388,-9.2339907
4666,195.8223,6.2798414,5.5721126,0.0,0,4.3614054,0.0,0.46446967,50.196793,4.3669257,485.68753,-9.2340698
4676,195.8243,6.3283734,5.5902452,0.0,0,4.3417892,0.0,0.46674508,50.531273,4.3533616,485.43115,-9.2350378
4686,195.8263,6.3554025,5.6153631,0.0,0,4.3221731,0.0,0.46913025,50.627178,4.3320889,485.17477,-9.2342548
4696,195.8283,6.394454,5.6324878,0.0,0,4.3025575,0.0,0.47052005,50.78479,4.3161173,484.9184,-9.2334976
4706,195.8303,6.441258,5.656713,0.0,0,4.2829413,0.0,0.47283947,51.164833,4.2917156,483.7449,-9.2333679
4716,195.8323,6.4806747,5.6692801,0.0,0,4.2633247,0.0,0.47461247,51.308712,4.2676272,482.09897,-9.2339163
4726,195.8343,6.4862742,5.6899967,0.0,0,4.2437091,0.0,0.47729269,51.213856,4.2521615,480.45303,-9.2340956
4736,195.8363,6.5112553,5.7124219,0.0,0,4.224093,0.0,0.47985706,51.284786,4.2260871,478.80707,-9.2344904
4746,195.8383,6.5278521,5.73563,0.0,0,4.2044768,0.0,0.48181212,51.332088,4.2068558,477.16113,-9.2352343
4756,195.8403,6.5341501,5.760849,0.0,0,4.1848607,0.0,0.48384857,51.257954,4.1862235,475.86411,-9.2346754
4766,195.8423,6.5147285,5.7753081,0.0,0,4.1652451,0.0,0.48571083,51.025356,4.1675224,474.75494,-9.2345457
4776,195.8443,6.4989738,5.7920108,0.0,0,4.1456289,0.0,0.48804665,50.820251,4.1484799,473.64581,-9.2339373
4786,195.8463,6.505456,5.8067183,0.0,0,4.1260128,0.0,0.49004287,50.750969,4.1299663,472.53665,-9.2330742
4796,195.8483,6.5261559,5.8290067,0.0,0,4.1063972,0.0,0.49228638,50.734962,4.1118908,471.42749,-9.2351151
4806,195.8503,6.5451374,5.8565822,0.0,0,4.086781,0.0,0.49471712,50.790119,4.0934153,471.0282,-9.2342196
4816,195.8523,6.6031842,5.8696604,0.0,0,4.0671654,0.0,0.49604425,51.156368,4.0742469,471.0282,-9.2339697
4826,195.8543,6.6243238,5.8897877,0.0,0,4.0475492,0.0,0.49829793,51.21637,4.0487118,471.0282,-9.233572
4836,195.8563,6.6477375,5.9066925,0.0,0,4.0288272,0.0,0.50076318,51.301025,4.0348802,471.0282,-9.2333851
4846,195.8583,6.6417747,5.9260259,0.0,0,4.0101709,0.0,0.50310642,51.180321,4.0112605,471.0282,-9.2351074
4856,195.8603,6.6609268,5.9517069,0.0,0,3.9915152,0.0,0.50565255,51.141716,3.9933484,470.98306,-9.2345829
4866,195.8623,6.6749072,5.9708581,0.0,0,3.9728591,0.0,0.50726295,51.181801,3.9750755,470.91147,-9.2337799
4876,195.8643,6.6981821,5.9913263,0.0,0,3.9542034,0.0,0.50934207,51.242126,3.9537859,470.83984,-9.2342567
4886,195.8663,6.7057424,6.0059285,0.0,0,3.9355471,0.0,0.51141912,51.262543,3.9355283,470.76822,-9.2344646
4896,195.8683,6.7235322,6.023006,0.0,0,3.9168911,0.0,0.5138045,51.143967,3.9130056,470.69659,-9.2340183
4906,195.8703,6.7286291,6.0456347,0.0,0,3.8982351,0.0,0.51637822,51.037518,3.8976924,470.93948,-9.2353086
4916,195.8723,6.7242708,6.0636678,0.0,0,3.8795791,0.0,0.51793367,50.976051,3.8796909,471.37512,-9.2341843
4926,195.8743,6.7367258,6.0876961,0.0,0,3.8609231,0.0,0.52001858,50.977226,3.8631926,471.81079,-9.2339611
4936,195.8763,6.7670155,6.1000071,0.0,0,3.842267,0.0,0.521649,51.161716,3.8427184,472.24643,-9.2338285
4946,195.8783,6.799643,6.1167951,0.0,0,3.8236113,0.0,0.52397019,51.209476,3.8247225,472.6821,-9.2341681
4956,195.8803,6.8037124,6.13412,0.0,0,3.8049552,0.0,0.52645665,51.165367,3.8065891,473.20859,-9.2345171
4966,195.8823,6.8183708,6.1568151,0.0,0,3.7862992,0.0,0.52858925,51.203587,3.7887776,473.79315,-9.2337971
4976,195.8843,6.8753381,6.1839614,0.0,0,3.767643,0.0,0.53110284,51.44873,3.7701514,474.37775,-9.2331791
4986,195.8863,6.8959975,6.1973915,0.0,0,3.748987,0.0,0.53246528,51.509094,3.7456689,474.96231,-9.2328472
4996,195.8883,6.9188538,6.2169085,0.0,0,3.7303312,0.0,0.53493732,51.614002,3.7265029,475.54688,-9.2342691
5006,195.8903,6.9069376,6.2316132,0.0,0,3.7116749,0.0,0.53724223,51.397743,3.7120047,476.142,-9.2347193
5016,195.8923,6.9023485,6.2525797,0.0,0,3.6930192,0.0,0.53982711,51.20364,3.68945,476.74417,-9.2351236
5026,195.8943,6.8704786,6.2750535,0.0,0,3.6743634,0.0,0.54202956,50.905094,3.6716385,477.34634,-9.2340307
5036,195.8963,6.8695431,6.2898231,0.0,0,3.6557071,0.0,0.54318357,50.819698,3.6522048,477.94849,-9.2339516
5046,195.8983,6.8969855,6.3101768,0.0,0,3.6370513,0.0,0.54526806,50.963516,3.6356547,478.55066,-9.2348509
5056,195.9003,6.9213171,6.3222699,0.0,0,3.6183951,0.0,0.54719633,50.979145,3.6180811,479.0051,-9.2337246
5066,195.9023,6.9633708,6.3402071,0.0,0,3.5997391,0.0,0.5498659,51.225426,3.6029725,479.35684,-9.2332335
5076,195.9043,7.0066814,6.3608751,0.0,0,3.5810831,0.0,0.55227995,51.324608,3.5791507,479.70862,-9.2340508
5086,195.9063,7.0197544,6.3817124,0.0,0,3.5632727,0.0,0.5541032,51.363338,3.5614414,480.06036,-9.2339659
5096,195.9083,7.0477314,6.4063706,0.0,0,3.5455251,0.0,0.55626124,51.4715,3.5416045,480.41214,-9.2339067
5106,195.9103,7.0545206,6.4183145,0.0,0,3.5277767,0.0,0.55802667,51.417652,3.5257478,480.63251,-9.2339659
5116,195.9123,7.0498967,6.4349346,0.0,0,3.5100291,0.0,0.56049323,51.256287,3.5070205,480.75769,-9.2347202
5126,195.9143,7.0387988,6.4534793,0.0,0,3.4922807,0.0,0.56310129,51.020088,3.4855349,480.8829,-9.233427
5136,195.9163,7.0488234,6.472064,0.0,0,3.4745326,0.0,0.56489515,51.05822,3.4705656,481.00809,-9.2324896
5146,195.9183,7.0484333,6.4951634,0.0,0,3.456785,0.0,0.56693959,50.946041,3.4542518,481.1333,-9.2337236
5156,195.9203,7.0896964,6.5084548,0.0,0,3.4390366,0.0,0.56848168,51.184021,3.4370751,481.32648,-9.2341452
5166,195.9223,7.0956893,6.5266433,0.0,0,3.421289,0.0,0.57080376,51.017803,3.4168761,481.57092,-9.2341356
5176,195.9243,7.1119108,6.5401111,0.0,0,3.4035406,0.0,0.57305044,51.047241,3.4015224,481.81537,-9.2346992
5186,195.9263,7.1234756,6.5585766,0.0,0,3.385793,0.0,0.575472,51.043022,3.3848124,482.05981,-9.2337856
5196,195.9283,7.1442676,6.5835748,0.0,0,3.3680446,0.0,0.57793778,51.041042,3.3639295,482.30426,-9.232645
5206,195.9303,7.1533256,6.5991483,0.0,0,3.350297,0.0,0.57929522,51.026546,3.347698,482.51532,-9.2340975
5216,195.9323,7.1556087,6.6164894,0.0,0,3.3325489,0.0,0.58128667,50.969269,3.3298891,482.70013,-9.2332287
5226,195.9343,7.1633854,6.630178,0.0,0,3.3148007,0.0,0.58337551,50.88065,3.3134344,482.88495,-9.2336617
5236,195.9363,7.1953092,6.6471992,0.0,0,3.2970529,0.0,0.58589965,51.048096,3.2973382,483.06976,-9.2334614
5246,195.9383,7.2237077,6.6676683,0.0,0,3.2793045,0.0,0.58842403,51.06414,3.2768283,483.25461,-9.2340145
5256,195.9403,7.2171669,6.687016,0.0,0,3.2615569,0.0,0.59017849,50.951614,3.2598352,483.39679,-9.234807
5266,195.9423,7.2346206,6.7081709,0.0,0,3.2438087,0.0,0.59201515,50.977921,3.2426023,483.50412,-9.2340622
5276,195.9443,7.2337856,6.7188597,0.0,0,3.2260609,0.0,0.59366959,50.861534,3.2251515,483.61142,-9.2329845
5286,195.9463,7.2703934,6.7329745,0.0,0,3.2083127,0.0,0.59598672,51.044884,3.205981,483.71875,-9.2325058
5296,195.9483,7.296248,6.7525826,0.0,0,3.1905646,0.0,0.59879547,51.030289,3.1896613,483.82605,-9.2341928
5306,195.9503,7.3333545,6.7714562,0.0,0,3.1728168,0.0,0.60065639,51.247055,3.1703656,483.92694,-9.2342253
5316,195.9523,7.359869,6.7942662,0.0,0,3.1550686,0.0,0.60282928,51.281212,3.1551123,484.02234,-9.2334356
5326,195.9543,7.3648744,6.8091617,0.0,0,3.1373208,0.0,0.60454798,51.269897,3.1351187,484.11771,-9.2339382
5336,195.9563,7.3903913,6.8285537,0.0,0,3.1203773,0.0,0.60710025,51.264366,3.1184878,484.2131,-9.2340031
5346,195.9583,7.3889856,6.8405218,0.0,0,3.1034932,0.0,0.60928768,51.137161,3.0993235,484.3085,-9.2346029
5356,195.9603,7.4269152,6.856926,0.0,0,3.0866091,0.0,0.61150175,51.276867,3.0875263,484.41653,-9.2355976
5366,195.9623,7.4601226,6.8827977,0.0,0,3.069725,0.0,0.61417902,51.352444,3.0641043,484.53577,-9.2352314
5376,195.9643,7.4791408,6.8991032,0.0,0,3.0528412,0.0,0.61560684,51.407997,3.0489032,484.65503,-9.2356958
5386,195.9663,7.4763761,6.9148684,0.0,0,3.0359573,0.0,0.61739349,51.325493,3.0297163,484.77426,-9.2339182
5396,195.9683,7.4893851,6.9278946,0.0,0,3.019073,0.0,0.61965966,51.291992,3.0163815,484.89349,-9.2319241
5406,195.9703,7.4900789,6.9454131,0.0,0,3.0021892,0.0,0.62233919,51.173389,3.0001159,485.04996,-9.2339201
5416,195.9723,7.5098906,6.9646392,0.0,0,2.9853053,0.0,0.62469018,51.217197,2.9799907,485.24072,-9.2337074
5426,195.9743,7.5338407,6.9821496,0.0,0,2.9684212,0.0,0.62627918,51.24548,2.964406,485.43152,-9.2336693
5436,195.9763,7.5643368,7.0043764,0.0,0,2.9515374,0.0,0.62832892,51.385071,2.946615,485.62228,-9.2339001
5446,195.9783,7.5676174,7.0146031,0.0,0,2.9346533,0.0,0.62997609,51.309074,2.9285994,485.81308,-9.2341213
5456,195.9803,7.5704193,7.0285912,0.0,0,2.9177692,0.0,0.63234043,51.162697,2.9121156,485.99777,-9.2339849
5466,195.9823,7.5919175,7.0445156,0.0,0,2.9008853,0.0,0.63483346,51.249813,2.8973591,486.17664,-9.2334309
5476,195.9843,7.6359396,7.0623879,0.0,0,2.8840013,0.0,0.63680488,51.427505,2.8800683,486.3555,-9.2330809
5486,195.9863,7.6805015,7.0866656,0.0,0,2.8671172,0.0,0.63905996,51.576389,2.8645749,486.53436,-9.2335415
5496,195.9883,7.7099738,7.0984674,0.0,0,2.8502331,0.0,0.64036137,51.70705,2.8477647,486.71326,-9.2336817
5506,195.9903,7.7324991,7.1159768,0.0,0,2.8333492,0.0,0.64297372,51.755959,2.8294418,486.77286,-9.2337761
5516,195.9923,7.7555323,7.1283212,0.0,0,2.8164651,0.0,0.64526469,51.752068,2.8156352,486.71323,-9.235527
5526,195.9943,7.7899752,7.1474299,0.0,0,2.7995811,0.0,0.64777124,51.90416,2.7986577,486.65363,-9.2340622
5536,195.9963,7.8230681,7.1717315,0.0,0,2.7826972,0.0,0.65031773,51.955605,2.7798381,486.59399,-9.2339926
5546,195.9983,7.8378787,7.1851835,0.0,0,2.7658134,0.0,0.65162677,52.019688,2.7638237,486.53436,-9.233429
5556,196.0003,7.8651967,7.2042141,0.0,0,2.748929,0.0,0.65374029,52.121433,2.7460473,483.93753,-9.2330704
5566,196.0023,7.8596387,7.2176113,0.0,0,2.7320454,0.0,0.6562252,51.977371,2.7289484,478.69998,-9.23423
5576,196.0043,7.8865161,7.2329741,0.0,0,2.7151611,0.0,0.6585502,51.926373,2.7100005,473.46246,-9.2345324
5586,196.0063,7.9180307,7.2526364,0.0,0,2.6990447,0.0,0.66118699,52.034416,2.6965797,468.22491,-9.234067
5596,196.0083,7.9551005,7.2740993,0.0,0,2.6829846,0.0,0.66323668,52.197571,2.6798334,462.9874,-9.2342844
5606,196.0103,7.9677358,7.2937584,0.0,0,2.6669245,0.0,0.6652025,52.180866,2.6617126,458.28683,-9.2325811
5616,196.0123,7.968205,7.302598,0.0,0,2.6508646,0.0,0.66677201,52.047958,2.6442568,454.16797,-9.2339802
5626,196.0143,7.9725666,7.3177223,0.0,0,2.6348047,0.0,0.66939098,51.959316,2.6306689,450.0491,-9.2344818
5636,196.0163,7.9556909,7.3329153,0.0,0,2.6187446,0.0,0.67183501,51.725056,2.6124475,445.93024,-9.2338247
5646,196.0183,7.9812775,7.3506145,0.0,0,2.6026847,0.0,0.67361271,51.827415,2.59658,441.81137,-9.2346802
5656,196.0203,7.9782944,7.3743773,0.0,0,2.5866246,0.0,0.67598563,51.744003,2.5798442,440.46051,-9.2335072
5666,196.0223,7.988493,7.3842463,0.0,0,2.5705645,0.0,0.67719626,51.690937,2.5641615,442.23093,-9.2318459
5676,196.0243,8.0032883,7.3974214,0.0,0,2.5545046,0.0,0.67936653,51.731228,2.5514283,444.00134,-9.2338886
5686,196.0263,8.0287209,7.409399,0.0,0,2.5384448,0.0,0.68173641,51.686489,2.5361872,445.77173,-9.2341108
5696,196.0283,8.0740242,7.4266491,0.0,0,2.5223846,0.0,0.6841042,51.863003,2.5219769,447.54214,-9.234621
5706,196.0303,8.1099472,7.4484882,0.0,0,2.5063245,0.0,0.68629795,51.999527,2.5055771,449.14694,-9.2332287
5716,196.0323,8.1589651,7.4611259,0.0,0,2.4902647,0.0,0.6874491,52.205238,2.4855404,450.5574,-9.2333813
5726,196.0343,8.1711349,7.480092,0.0,0,2.4742045,0.0,0.68995464,52.234268,2.4729917,451.96783,-9.2331963
5736,196.0363,8.2055016,7.4914994,0.0,0,2.4581447,0.0,0.69201934,52.261471,2.4536912,453.3783,-9.2338552
5746,196.0383,8.2083979,7.5047927,0.0,0,2.4420846,0.0,0.69442856,52.216377,2.4396303,454.78873,-9.2339106
5756,196.0403,8.2413788,7.524096,0.0,0,2.4260244,0.0,0.6968928,52.284084,2.4218771,456.01874,-9.2320833
5766,196.0423,8.2893705,7.5443621,0.0,0,2.4099646,0.0,0.69884104,52.473137,2.4074144,457.02829,-9.2319231
5776,196.0443,8.3174973,7.5658607,0.0,0,2.3939047,0.0,0.70094979,52.550304,2.3909862,458.03781,-9.2324095
5786,196.0463,8.3342428,7.5749397,0.0,0,2.3778446,0.0,0.70275784,52.609688,2.3741798,459.04733,-9.233882
5796,196.0483,8.3610544,7.5910201,0.0,0,2.3617847,0.0,0.70556778,52.592831,2.3561859,460.05685,-9.2351637
5806,196.0503,8.3800449,7.6081305,0.0,0,2.3457246,0.0,0.70832354,52.547928,2.3405833,460.85593,-9.2339334
5816,196.0523,8.3855038,7.6245708,0.0,0,2.3296645,0.0,0.71006912,52.46487,2.3239055,461.38712,-9.234046
5826,196.0543,8.3868361,7.646275,0.0,0,2.3136046,0.0,0.71229637,52.355885,2.3086419,461.91833,-9.2329445
5836,196.0563,8.4184847,7.6588411,0.0,0,2.2982745,0.0,0.71386319,52.51469,2.2905967,462.44952,-9.2323999
5846,196.0583,8.4442425,7.674787,0.0,0,2.2829986,0.0,0.71647233,52.545448,2.2767205,462.98074,-9.2336102
5856,196.0603,8.4340973,7.6857471,0.0,0,2.2677226,0.0,0.71882975,52.363182,2.262363,463.11411,-9.2325697
5866,196.0623,8.4319458,7.7033834,0.0,0,2.2524467,0.0,0.72115511,52.247959,2.2454858,462.72015,-9.2343321
5876,196.0643,8.4415569,7.7240467,0.0,0,2.2371705,0.0,0.72333866,52.16996,2.2298882,462.32623,-9.2339602
5886,196.0663,8.4508724,7.7355533,0.0,0,2.2218947,0.0,0.72455639,52.201622,2.214993,461.93228,-9.2331734
5896,196.0683,8.4934216,7.751802,0.0,0,2.2066188,0.0,0.72660029,52.335346,2.2034152,461.53833,-9.23244
5906,196.0703,8.4992399,7.7621756,0.0,0,2.1913426,0.0,0.72872061,52.238625,2.1872544,461.21207,-9.2338476
5916,196.0723,8.5492601,7.7770305,0.0,0,2.1760666,0.0,0.7313875,52.365391,2.1695316,460.97931,-9.234498
5926,196.0743,8.5499821,7.7956147,0.0,0,2.1607907,0.0,0.73379821,52.272102,2.1556375,460.74655,-9.2347126
5936,196.0763,8.5776043,7.813292,0.0,0,2.1455147,0.0,0.735461,52.330975,2.1410975,460.51376,-9.2320738
5946,196.0783,8.614727,7.8300114,0.0,0,2.1302385,0.0,0.73715478,52.46772,2.1257312,460.28101,-9.2322998
5956,196.0803,8.6523914,7.8379583,0.0,0,2.1149626,0.0,0.73886055,52.569572,2.1110365,460.39328,-9.2329607
5966,196.0823,8.6875153,7.8521657,0.0,0,2.0996866,0.0,0.74153531,52.730072,2.0965695,461.00211,-9.2327852
5976,196.0843,8.7366199,7.866559,0.0,0,2.0844107,0.0,0.74402928,52.836685,2.0805776,461.6109,-9.2333422
5986,196.0863,8.7697859,7.8852944,0.0,0,2.0691347,0.0,0.74608248,52.900284,2.0631671,462.2197,-9.2333612
5996,196.0883,8.7839775,7.9077001,0.0,0,2.0538588,0.0,0.74828714,52.926422,2.0459948,462.82852,-9.2326384
6006,196.0903,8.8325253,7.9179988,0.0,0,2.0385828,0.0,0.74971104,53.10928,2.0318246,463.28928,-9.2332268
6016,196.0923,8.8612709,7.9319706,0.0,0,2.0233068,0.0,0.75228423,53.143169,2.0195446,463.52802,-9.2322016
6026,196.0943,8.881875,7.9429369,0.0,0,2.0080307,0.0,0.75459725,53.139507,2.0021477,463.76678,-9.2332067
6036,196.0963,8.9113016,7.9637437,0.0,0,1.9927547,0.0,0.75767815,53.135296,1.9867023,464.00552,-9.2352161
6046,196.0983,8.9203348,7.9831076,0.0,0,1.9774787,0.0,0.75964636,53.122765,1.9704623,464.24426,-9.2347527
6056,196.1003,8.934516,7.9941587,0.0,0,1.9622028,0.0,0.76080316,53.097126,1.9571617,464.65991,-9.2334442
6066,196.1023,8.9488754,8.0118618,0.0,0,1.9469268,0.0,0.76314646,53.113651,1.943527,465.35226,-9.2321911
6076,196.1043,8.9803972,8.0196447,0.0,0,1.9316506,0.0,0.76508427,53.147148,1.927752,466.04462,-9.2324648
6086,196.1063,8.9962921,8.0348721,0.0,0,1.9170676,0.0,0.76780969,53.119633,1.9148352,466.73697,-9.234005
6096,196.1083,9.0427999,8.0525713,0.0,0,1.9025356,0.0,0.7701478,53.34341,1.8971188,467.42932,-9.2331076
6106,196.1103,9.0750418,8.0680408,0.0,0,1.8880036,0.0,0.77159899,53.415165,1.8827564,468.21695,-9.2324038
6116,196.1123,9.1119356,8.0871058,0.0,0,1.8734715,0.0,0.77364093,53.475544,1.8660488,469.15997,-9.2323132
6126,196.1143,9.1374512,8.0960846,0.0,0,1.8589395,0.0,0.77560025,53.53344,1.8502407,470.103,-9.2339058
6136,196.1163,9.1329603,8.1095562,0.0,0,1.8444076,0.0,0.77834535,53.387794,1.8396204,471.04602,-9.2352495
6146,196.1183,9.1707478,8.1233816,0.0,0,1.8298756,0.0,0.78065753,53.461796,1.8220247,471.98904,-9.2336683
6156,196.1203,9.2066202,8.1379557,0.0,0,1.8153436,0.0,0.78228712,53.59412,1.8095632,472.56546,-9.2333555
6166,196.1223,9.2695122,8.1592789,0.0,0,1.8008115,0.0,0.78443384,53.884636,1.795338,472.51773,-9.2326336
6176,196.1243,9.3319664,8.1730165,0.0,0,1.7862796,0.0,0.78631842,54.114918,1.7800329,472.46997,-9.2323685
6186,196.1263,9.3688965,8.1856594,0.0,0,1.7717476,0.0,0.78879172,54.187252,1.765305,472.42224,-9.2330656
6196,196.1283,9.3621922,8.1965733,0.0,0,1.7572156,0.0,0.79135066,54.021011,1.7460785,472.37448,-9.233716
6206,196.1303,9.3853588,8.2127314,0.0,0,1.7426836,0.0,0.79362381,54.00771,1.7341394,472.15915,-9.2328491
6216,196.1323,9.4224424,8.2352695,0.0,0,1.7281516,0.0,0.79608202,54.108353,1.720727,471.64584,-9.2337704
6226,196.1343,9.4597874,8.2462778,0.0,0,1.7136196,0.0,0.79742801,54.251995,1.7043041,471.13254,-9.2327757
6236,196.1363,9.4926004,8.2623386,0.0,0,1.6990876,0.0,0.79951119,54.307468,1.6888658,470.61923,-9.233139
6246,196.1383,9.5188274,8.2712965,0.0,0,1.6845555,0.0,0.80188423,54.311863,1.6773677,470.10596,-9.2333746
6256,196.1403,9.5287113,8.2848101,0.0,0,1.6700237,0.0,0.80440271,54.326183,1.6647704,469.73471,-9.2338533
6266,196.1423,9.569582,8.30515,0.0,0,1.6554916,0.0,0.80716252,54.330395,1.6514522,469.62726,-9.2342014
6276,196.1443,9.6387978,8.320632,0.0,0,1.6409596,0.0,0.8086887,54.696129,1.6341301,469.51984,-9.2329397
6286,196.1463,9.6892996,8.3394871,0.0,0,1.6264275,0.0,0.81072122,54.844978,1.6189619,469.41241,-9.2316885
6296,196.1483,9.7373018,8.350441,0.0,0,1.6118956,0.0,0.81311285,54.983295,1.6064475,469.30496,-9.2329798
6306,196.1503,9.7612762,8.3630123,0.0,0,1.5973636,0.0,0.81573147,54.971947,1.5913955,469.25436,-9.2331934
6316,196.1523,9.7638292,8.3781967,0.0,0,1.5828315,0.0,0.81856298,54.852978,1.5752983,469.31406,-9.2330818
6326,196.1543,9.7656212,8.3959074,0.0,0,1.5682995,0.0,0.8205052,54.788704,1.5593126,469.37372,-9.2337828
6336,196.1563,9.7580051,8.4155254,0.0,0,1.554427,0.0,0.8224684,54.633968,1.5420847,469.43341,-9.2339087
6346,196.1583,9.7622728,8.4243422,0.0,0,1.5406029,0.0,0.82395661,54.512108,1.5312014,469.4931,-9.233242
6356,196.1603,9.7302408,8.4354305,0.0,0,1.5267789,0.0,0.82641751,54.253056,1.5211167,469.53308,-9.2337008
6366,196.1623,9.736783,8.4468985,0.0,0,1.512955,0.0,0.82888371,54.147793,1.5046593,469.53308,-9.2326679
6376,196.1643,9.7667065,8.4592276,0.0,0,1.499131,0.0,0.83062863,54.217957,1.4905038,469.53308,-9.2339716
6386,196.1663,9.8146009,8.4797897,0.0,0,1.4853069,0.0,0.83285511,54.335079,1.4784962,469.53308,-9.2325802
6396,196.1683,9.8567705,8.490551,0.0,0,1.4714829,0.0,0.83406109,54.526936,1.4652486,469.53308,-9.2322302
6406,196.1703,9.8971052,8.5032692,0.0,0,1.4576589,0.0,0.83602118,54.614857,1.4499884,469.60565,-9.2335739
6416,196.1723,9.9472189,8.5123205,0.0,0,1.4438349,0.0,0.83837146,54.734856,1.4393386,469.83246,-9.2340794
6426,196.1743,9.9832268,8.5253725,0.0,0,1.4300108,0.0,0.84097308,54.808712,1.4281549,470.05927,-9.2335882
6436,196.1763,10.046302,8.545516,0.0,0,1.4161869,0.0,0.84375656,55.04565,1.4100014,470.28607,-9.2339888
6446,196.1783,10.099185,8.559207,0.0,0,1.4023628,0.0,0.84493566,55.238274,1.392861,470.51288,-9.2338037
6456,196.1803,10.16572,8.5779591,0.0,0,1.388539,0.0,0.84723103,55.490433,1.3805076,470.73969,-9.2333117
6466,196.1823,10.194246,8.5859146,0.0,0,1.374715,0.0,0.84924668,55.517269,1.3672264,470.96649,-9.2328606
6476,196.1843,10.23493,8.6015263,0.0,0,1.3608909,0.0,0.85252047,55.562054,1.3547324,471.1933,-9.2332125
6486,196.1863,10.254417,8.613286,0.0,0,1.3470669,0.0,0.85465848,55.531544,1.3370255,471.4201,-9.2338886
6496,196.1883,10.272227,8.631773,0.0,0,1.3332429,0.0,0.85695255,55.517242,1.3210269,471.64691,-9.2339001
6506,196.1903,10.271685,8.6541929,0.0,0,1.3194189,0.0,0.85930997,55.412617,1.3060505,471.86475,-9.2327452
6516,196.1923,10.238678,8.6601019,0.0,0,1.3055949,0.0,0.86046368,55.120327,1.2951357,472.06171,-9.2333841
6526,196.1943,10.215886,8.6695032,0.0,0,1.2917709,0.0,0.8626982,54.893581,1.282244,472.25867,-9.2331419
6536,196.1963,10.217949,8.6799212,0.0,0,1.2779469,0.0,0.86515528,54.779202,1.269104,472.45566,-9.2339077
6546,196.1983,10.270608,8.6942081,0.0,0,1.2641228,0.0,0.86721861,54.962872,1.2614639,472.65262,-9.2326832
6556,196.2003,10.349345,8.7138653,0.0,0,1.2502989,0.0,0.86932927,55.226803,1.2443081,472.75262,-9.2315235
6566,196.2023,10.417862,8.7216911,0.0,0,1.2364749,0.0,0.87022901,55.550785,1.2288072,472.61536,-9.2320385
6576,196.2043,10.466157,8.7362261,0.0,0,1.2226509,0.0,0.87262827,55.685661,1.2167685,472.47809,-9.2336454
6586,196.2063,10.524174,8.7465897,0.0,0,1.2094564,0.0,0.87517917,55.763069,1.2038031,472.34079,-9.234067
6596,196.2083,10.562136,8.7581596,0.0,0,1.1963084,0.0,0.87763876,55.870083,1.1893253,472.20352,-9.2326784
6606,196.2103,10.625314,8.7785549,0.0,0,1.1831605,0.0,0.88042611,56.080212,1.1754318,471.94592,-9.2338114
6616,196.2123,10.66721,8.7900782,0.0,0,1.1700124,0.0,0.88138819,56.245323,1.1624964,471.37891,-9.2332067
6626,196.2143,10.697622,8.8077679,0.0,0,1.1568644,0.0,0.88369173,56.277397,1.149399,470.81189,-9.2330399
6636,196.2163,10.7412,8.8157597,0.0,0,1.1437163,0.0,0.88571692,56.34988,1.1397954,470.2449,-9.232584
6646,196.2183,10.734384,8.8261852,0.0,0,1.1305684,0.0,0.88826257,56.222672,1.12155,469.67789,-9.2339706
6656,196.2203,10.792119,8.8431559,0.0,0,1.1174203,0.0,0.89138544,56.325878,1.1094415,469.29138,-9.2339792
6666,196.2223,10.82483,8.8573847,0.0,0,1.1042725,0.0,0.89279974,56.436844,1.0962216,469.39285,-9.2335491
6676,196.2243,10.867037,8.8760977,0.0,0,1.0911243,0.0,0.89490312,56.506462,1.0862588,469.49432,-9.2321024
6686,196.2263,10.899558,8.8838863,0.0,0,1.0779763,0.0,0.89631402,56.60313,1.0726092,469.59579,-9.232666
6696,196.2283,10.919393,8.8939781,0.0,0,1.0648283,0.0,0.89871782,56.556664,1.0585811,469.69727,-9.2325754
6706,196.2303,10.967296,8.9057274,0.0,0,1.0516803,0.0,0.90155447,56.668121,1.0444587,469.99884,-9.2324677
6716,196.2323,11.015947,8.922039,0.0,0,1.0385324,0.0,0.90404993,56.757244,1.0341678,470.87,-9.232398
6726,196.2343,11.059704,8.9400911,0.0,0,1.0253844,0.0,0.90594727,56.894516,1.01717,471.74115,-9.2310581
6736,196.2363,11.0994,8.9496174,0.0,0,1.0122362,0.0,0.90721858,57.009315,1.0030073,472.61227,-9.232687
6746,196.2383,11.149328,8.9649239,0.0,0,0.99908841,0.0,0.90965843,57.132286,0.98595703,473.48343,-9.2316904
6756,196.2403,11.182893,8.9732084,0.0,0,0.98594034,0.0,0.91227609,57.177532,0.9803825,474.20541,-9.232996
6766,196.2423,11.239402,8.9849405,0.0,0,0.97279239,0.0,0.9146378,57.309383,0.96262848,474.47989,-9.2332716
6776,196.2443,11.28618,9.0042677,0.0,0,0.95964432,0.0,0.9173612,57.365627,0.95227087,474.75436,-9.2332497
6786,196.2463,11.327085,9.0151672,0.0,0,0.94649631,0.0,0.91829354,57.507629,0.93756425,475.02884,-9.2330694
6796,196.2483,11.354374,9.0322018,0.0,0,0.93334836,0.0,0.92053908,57.547523,0.92398012,475.30331,-9.2322855
6806,196.2503,11.395797,9.0397148,0.0,0,0.92020041,0.0,0.92275244,57.648056,0.91222715,475.53052,-9.2330341
6816,196.2523,11.429474,9.0511608,0.0,0,0.90705234,0.0,0.92548597,57.653019,0.89931655,475.608,-9.2338991
6826,196.2543,11.44552,9.0636616,0.0,0,0.89390439,0.0,0.92783916,57.611542,0.88393968,475.68552,-9.2331457
6836,196.2563,11.492161,9.0788145,0.0,0,0.88135606,0.0,0.92968732,57.699772,0.87108052,475.76303,-9.2337894
6846,196.2583,11.524358,9.0964499,0.0,0,0.86885208,0.0,0.93148786,57.829643,0.86252809,475.84052,-9.2321873
6856,196.2603,11.557727,9.1042557,0.0,0,0.85634804,0.0,0.93313372,57.871346,0.84837425,475.95779,-9.2321405
6866,196.2623,11.558609,9.1116762,0.0,0,0.84384406,0.0,0.93520373,57.760937,0.83405495,476.20819,-9.2324591
6876,196.2643,11.584239,9.1211243,0.0,0,0.83134007,0.0,0.937711,57.723991,0.8245334,476.45862,-9.2339258
6886,196.2663,11.619745,9.1369247,0.0,0,0.81883603,0.0,0.94010311,57.830841,0.81243068,476.70901,-9.2325134
6896,196.2683,11.665135,9.157856,0.0,0,0.80633205,0.0,0.94242257,57.873245,0.79738748,476.95941,-9.2325764
6906,196.2703,11.706996,9.1631126,0.0,0,0.79382807,0.0,0.94306707,58.057678,0.78574699,477.16391,-9.2324018
6916,196.2723,11.741644,9.1784134,0.0,0,0.78132403,0.0,0.94574243,58.098907,0.77383649,477.20566,-9.2331467
6926,196.2743,11.77732,9.1830864,0.0,0,0.76882005,0.0,0.9477517,58.127182,0.76145643,477.24738,-9.2322311
6936,196.2763,11.82644,9.1956062,0.0,0,0.75631601,0.0,0.95054322,58.218945,0.75205833,477.28912,-9.2316723
6946,196.2783,11.898551,9.2164745,0.0,0,0.74381208,0.0,0.95331949,58.438744,0.73757517,477.33087,-9.2319317
6956,196.2803,11.980263,9.2275391,0.0,0,0.7313081,0.0,0.95433438,58.767014,0.72129154,477.39389,-9.2331734
6966,196.2823,12.035875,9.2408705,0.0,0,0.71880406,0.0,0.95608431,58.906578,0.70974225,477.53696,-9.2323074
6976,196.2843,12.055238,9.2462883,0.0,0,0.70630008,0.0,0.9580068,58.900867,0.69853657,477.68005,-9.2319431
6986,196.2863,12.079624,9.2578154,0.0,0,0.69379604,0.0,0.96094948,58.836876,0.6860891,477.82315,-9.2326374
6996,196.2883,12.137804,9.2728758,0.0,0,0.68129206,0.0,0.96382588,58.946514,0.6745553,477.96622,-9.2313309
7006,196.2903,12.209937,9.2878036,0.0,0,0.66878808,0.0,0.96540666,59.19109,0.65892428,478.10931,-9.2314072
7016,196.2923,12.264077,9.3064079,0.0,0,0.65628403,0.0,0.96739531,59.365849,0.64366955,478.25238,-9.231472
7026,196.2943,12.298532,9.3130245,0.0,0,0.64378005,0.0,0.96905553,59.422939,0.63429904,478.39548,-9.2319298
7036,196.2963,12.326956,9.3229532,0.0,0,0.63127607,0.0,0.97169113,59.376133,0.62218326,478.53857,-9.2330694
7046,196.2983,12.324404,9.3331919,0.0,0,0.61877209,0.0,0.97435182,59.221413,0.61186355,478.68164,-9.2314701
7056,196.3003,12.333887,9.3456717,0.0,0,0.60626805,0.0,0.97622687,59.187149,0.59784079,478.72278,-9.2334814
7066,196.3023,12.354425,9.3668213,0.0,0,0.59376407,0.0,0.9786483,59.087128,0.58588219,478.32928,-9.2331791
7076,196.3043,12.407888,9.3740549,0.0,0,0.58126009,0.0,0.97980642,59.332813,0.57260668,477.93579,-9.232501
7086,196.3063,12.45156,9.3861704,0.0,0,0.56931847,0.0,0.98206627,59.346184,0.56195474,477.54233,-9.2316542
7096,196.3083,12.494759,9.3918657,0.0,0,0.55741853,0.0,0.98426449,59.446262,0.54904455,477.14883,-9.232667
7106,196.3103,12.534783,9.4033813,0.0,0,0.54551852,0.0,0.9868632,59.509884,0.53636438,476.68015,-9.2324562
7110,196.3111,12.581295,9.4169712,0.0,0,0.54075855,0.0,0.98786199,59.584393,0.53432041,476.35568,-9.231802