File: clean data/testID_0089.csv
level_0,index,Time(sec),Force(kN),Jaw(mm),PowAngle(deg),Power(W),Pram,PTemp,Strain,Stress(MPa),Stroke(mm),TC1(C),wedge(mm)
1773,1773,145.3439,0.75438148,0.014118327,0.0,0,9.0337019,0.0,0.00063973351,9.4104795,10.063327,299.59357,-9.3238392
1775,1775,145.3443,2.8688614,0.029554395,0.0,0,8.975174,0.0,0.0017941759,31.544209,9.9958134,299.5788,-9.3239794
1777,1777,145.3447,7.1429362,0.077194177,0.0,0,8.916646,0.0,0.0049549947,86.035286,9.951314,299.56403,-9.3225813
1779,1779,145.3451,8.6030102,0.11475939,0.0,0,8.8581171,0.0,0.0070821866,107.92476,9.8980627,299.54926,-9.3180332
1781,1781,145.3455,9.1635494,0.20799023,0.0,0,8.7995892,0.0,0.013295542,114.464,9.8281736,299.53448,-9.3143396
1783,1783,145.3459,9.511054,0.28946543,0.0,0,8.7416487,0.0,0.019199744,118.34647,9.7552586,299.51971,-9.3155174
1785,1785,145.3463,10.221169,0.35028204,0.0,0,8.6858444,0.0,0.022829009,126.28544,9.667799,299.50494,-9.3170729
1787,1787,145.3467,10.983299,0.44290683,0.0,0,8.6301804,0.0,0.029654685,134.69937,9.5896673,299.49017,-9.3159046
1789,1789,145.3471,11.415926,0.46551001,0.0,0,8.5745173,0.0,0.031289801,140.97038,9.5178614,299.47543,-9.3120794
1791,1791,145.3475,11.010474,0.54606658,0.0,0,8.5188522,0.0,0.036258925,135.41762,9.4514246,299.46066,-9.3129797
1793,1793,145.3479,11.567461,0.62205493,0.0,0,8.4631882,0.0,0.042302791,140.23938,9.39112,299.44589,-9.3139391
1795,1795,145.3483,12.003471,0.65490144,0.0,0,8.4075251,0.0,0.044044334,145.89647,9.3194628,299.43112,-9.3148537
1797,1797,145.3487,12.205935,0.75478911,0.0,0,8.35186,0.0,0.051028252,147.57208,9.249589,299.41635,-9.3139067
1799,1799,145.3491,12.066684,0.82815653,0.0,0,8.2961969,0.0,0.056433063,145.34796,9.1714449,299.40158,-9.3128004
1801,1801,145.3495,12.286815,0.89944655,0.0,0,8.2405329,0.0,0.061025806,146.70166,9.0965548,299.38681,-9.3116856
1803,1803,145.3499,12.538749,0.96685034,0.0,0,8.1848688,0.0,0.066509269,149.15849,9.0255499,299.37204,-9.3108244
1805,1805,145.3503,12.798075,1.0085778,0.0,0,8.1292048,0.0,0.069189489,151.69505,8.9598856,299.35727,-9.3114357
1807,1807,145.3507,12.786608,1.0756149,0.0,0,8.0735407,0.0,0.073746458,151.51944,8.8941298,299.3425,-9.3117628
1809,1809,145.3511,12.802616,1.1364394,0.0,0,8.0196581,0.0,0.078709505,150.30548,8.8326015,299.32773,-9.3130398
1811,1811,145.3515,13.251568,1.1973999,0.0,0,7.966691,0.0,0.082425945,154.96393,8.7722979,299.31296,-9.3127203
1813,1813,145.3519,13.237052,1.2721984,0.0,0,7.9137316,0.0,0.088091761,154.57962,8.7056293,299.31342,-9.3120708
1815,1815,145.3523,13.243125,1.3364506,0.0,0,7.8607712,0.0,0.093100332,153.46696,8.6332722,299.32202,-9.3111525
1817,1817,145.3527,13.321779,1.410683,0.0,0,7.8078113,0.0,0.097909115,153.7422,8.565938,299.33063,-9.3112488
1819,1819,145.3531,13.555742,1.4629447,0.0,0,7.7548509,0.0,0.10248233,155.39819,8.4987888,299.33923,-9.3117104
1821,1821,145.3535,13.750731,1.5032285,0.0,0,7.7018909,0.0,0.10522922,157.67303,8.4384136,299.34787,-9.3116159
1823,1823,145.3539,13.657526,1.5827613,0.0,0,7.6489305,0.0,0.11055816,155.73322,8.378273,299.35648,-9.3131256
1825,1825,145.3543,13.836017,1.6292183,0.0,0,7.5959711,0.0,0.11497458,156.69754,8.3224974,299.36508,-9.3122091
1827,1827,145.3547,14.006263,1.6800684,0.0,0,7.5430107,0.0,0.11816963,158.28505,8.2640276,299.37372,-9.3122883
1829,1829,145.3551,14.124177,1.7580695,0.0,0,7.4900513,0.0,0.12396753,158.83244,8.2014399,299.38232,-9.3122787
1831,1831,145.3555,14.169043,1.8047112,0.0,0,7.4370909,0.0,0.12803686,158.74319,8.1395712,299.39093,-9.3107901
1833,1833,145.3559,14.188275,1.8717622,0.0,0,7.3846622,0.0,0.13251816,158.18497,8.0803413,299.39954,-9.3107414
1835,1835,145.3563,14.363849,1.9288335,0.0,0,7.334168,0.0,0.13744842,159.24474,8.0179377,299.40817,-9.3117466
1837,1837,145.3567,14.496958,1.9705451,0.0,0,7.2837996,0.0,0.14058946,160.33618,7.9622078,299.41678,-9.3116808
1839,1839,145.3571,14.588449,2.0397031,0.0,0,7.2334318,0.0,0.14539827,160.4973,7.9017863,299.42538,-9.3106737
1841,1841,145.3575,14.611217,2.0895693,0.0,0,7.1830635,0.0,0.1499428,160.07465,7.8464527,299.43402,-9.309968
1843,1843,145.3579,14.743402,2.1391771,0.0,0,7.1326952,0.0,0.15342188,160.86229,7.7904849,299.44263,-9.3105059
1845,1845,145.3583,14.870373,2.2014873,0.0,0,7.0823274,0.0,0.15810844,161.54593,7.7326665,299.45123,-9.3110685
1847,1847,145.3587,14.92807,2.2516286,0.0,0,7.0319595,0.0,0.16257186,161.48744,7.6752872,299.45984,-9.3115664
1849,1849,145.3591,15.000465,2.3148327,0.0,0,6.9815912,0.0,0.16692111,161.54971,7.6194835,299.46848,-9.3097191
1851,1851,145.3595,15.084,2.3626573,0.0,0,6.9312234,0.0,0.17105265,161.77556,7.5653152,299.47708,-9.3106432
1853,1853,145.3599,15.209699,2.4070184,0.0,0,6.8808551,0.0,0.17483675,162.54034,7.5111599,299.48569,-9.3115711
1855,1855,145.3603,15.243608,2.4693661,0.0,0,6.8304877,0.0,0.17910603,162.17853,7.4599009,299.49429,-9.3114796
1857,1857,145.3607,15.345144,2.5100126,0.0,0,6.7801194,0.0,0.18291318,162.63011,7.4050956,299.50293,-9.3103447
1859,1859,145.3611,15.464876,2.5598395,0.0,0,6.7313633,0.0,0.18671572,163.31084,7.352406,299.51154,-9.3098068
1861,1861,145.3615,15.539767,2.6205165,0.0,0,6.6834378,0.0,0.1911578,163.42464,7.3009825,299.52014,-9.3104239
1863,1863,145.3619,15.575339,2.6638494,0.0,0,6.6355181,0.0,0.195292,163.05312,7.2494664,299.57788,-9.3120775
1865,1865,145.3623,15.647515,2.7190201,0.0,0,6.5875978,0.0,0.19952491,163.11258,7.1981096,299.65665,-9.3131123
1867,1867,145.3627,15.762642,2.7695765,0.0,0,6.5396781,0.0,0.20352124,163.62782,7.14676,299.73541,-9.3118181
1869,1869,145.3631,15.874876,2.8104303,0.0,0,6.4917583,0.0,0.20737372,164.20486,7.0961471,299.81418,-9.3115711
1871,1871,145.3635,15.900231,2.8648391,0.0,0,6.4438381,0.0,0.21132772,163.84911,7.0458412,299.89294,-9.3109608
1873,1873,145.3639,15.963334,2.9134905,0.0,0,6.3959174,0.0,0.2155343,163.75124,6.9985247,299.97171,-9.3103256
1875,1875,145.3643,16.058176,2.9565728,0.0,0,6.3479977,0.0,0.21943623,164.09357,6.9496117,300.05048,-9.3120966
1877,1877,145.3647,16.18037,3.0078683,0.0,0,6.3000779,0.0,0.22317071,164.6794,6.9013958,300.12921,-9.3123474
1879,1879,145.3651,16.241386,3.0570171,0.0,0,6.2521582,0.0,0.2276957,164.6427,6.8491502,300.20798,-9.3119688
1881,1881,145.3655,16.248289,3.1039686,0.0,0,6.2042384,0.0,0.23162319,164.02153,6.8030267,300.28674,-9.3121586
1883,1883,145.3659,16.344561,3.1503866,0.0,0,6.1567988,0.0,0.23508823,164.37712,6.7557425,300.36551,-9.3117723
1885,1885,145.3663,16.433798,3.1966615,0.0,0,6.1111083,0.0,0.2396656,164.5188,6.7073264,300.44427,-9.3103895
1887,1887,145.3667,16.514002,3.2466836,0.0,0,6.0655322,0.0,0.24344575,164.7747,6.6570578,300.52304,-9.3105307
1889,1889,145.3671,16.570894,3.2916892,0.0,0,6.0199566,0.0,0.24720126,164.74071,6.6079621,300.60181,-9.3115005
1891,1891,145.3675,16.625259,3.3361647,0.0,0,5.97438,0.0,0.25164115,164.51505,6.5619049,300.68057,-9.3121071
1893,1893,145.3679,16.715223,3.3836789,0.0,0,5.9288039,0.0,0.25505751,164.86212,6.5138321,300.75934,-9.3121977
1895,1895,145.3683,16.792604,3.4290793,0.0,0,5.8832283,0.0,0.2591235,164.95906,6.4677114,300.8381,-9.3115129
1897,1897,145.3687,16.862942,3.4723701,0.0,0,5.8376522,0.0,0.2632181,164.98785,6.420671,300.91687,-9.3101568
1899,1899,145.3691,16.942841,3.524441,0.0,0,5.7920756,0.0,0.26693577,165.07701,6.3723416,300.99564,-9.3116865
1901,1901,145.3695,17.0068,3.5692229,0.0,0,5.7465,0.0,0.27154857,165.0367,6.3269567,301.0744,-9.3119678
1903,1903,145.3699,17.055813,3.613796,0.0,0,5.7009239,0.0,0.27534476,164.85213,6.2783346,301.15314,-9.311039
1905,1905,145.3703,17.155989,3.6673245,0.0,0,5.6553483,0.0,0.27945599,165.06444,6.2307935,301.2319,-9.3107309
1907,1907,145.3707,17.248505,3.70474,0.0,0,5.6097717,0.0,0.28370234,165.27023,6.1875205,301.31067,-9.3103523
1909,1909,145.3711,17.322784,3.749465,0.0,0,5.5656548,0.0,0.28707686,165.3665,6.138185,301.38943,-9.310236
1911,1911,145.3715,17.364073,3.8049858,0.0,0,5.5222902,0.0,0.29185975,165.08887,6.0950093,301.4682,-9.3127003
1913,1913,145.3719,17.418625,3.8432753,0.0,0,5.47893,0.0,0.29598317,164.91731,6.0479383,301.57361,-9.3129997
1915,1915,145.3723,17.540874,3.8906314,0.0,0,5.4355698,0.0,0.29949293,165.44365,6.0011015,301.68793,-9.3118305
1917,1917,145.3727,17.602152,3.9414096,0.0,0,5.39221,0.0,0.30451396,165.26675,5.9547873,301.80222,-9.3102179
1919,1919,145.3731,17.662022,3.9803681,0.0,0,5.3488498,0.0,0.30819106,165.21788,5.9088736,301.9165,-9.3095741
1921,1921,145.3735,17.727949,4.0297203,0.0,0,5.30549,0.0,0.31197244,165.20715,5.8624463,302.03082,-9.3120041
1923,1923,145.3739,17.799906,4.0757189,0.0,0,5.2621298,0.0,0.31693998,164.9689,5.8197455,302.14511,-9.3130007
1925,1925,145.3743,17.890097,4.1159325,0.0,0,5.21877,0.0,0.32036182,165.21408,5.7717681,302.2594,-9.3134546
1927,1927,145.3747,17.976393,4.1661787,0.0,0,5.1754103,0.0,0.32460901,165.39514,5.7271681,302.37372,-9.311841
1929,1929,145.3751,18.041576,4.2089086,0.0,0,5.13205,0.0,0.32936618,165.15846,5.6778741,302.48801,-9.3112879
1931,1931,145.3755,18.103193,4.255795,0.0,0,5.0886898,0.0,0.33301672,165.20688,5.6330862,302.60229,-9.3116055
1933,1933,145.3759,18.173834,4.3031883,0.0,0,5.0457649,0.0,0.33759049,165.02536,5.5854445,302.71658,-9.3122034
1935,1935,145.3763,18.273836,4.3433061,0.0,0,5.0044208,0.0,0.34199682,165.18613,5.5425978,302.8309,-9.3123569
1937,1937,145.3767,18.372517,4.3967624,0.0,0,4.9631805,0.0,0.34600714,165.37825,5.4943695,302.94519,-9.3125763
1939,1939,145.3771,18.42832,4.4374709,0.0,0,4.9219408,0.0,0.35042027,165.21532,5.4494791,303.05948,-9.3117647
1941,1941,145.3775,18.487684,4.479353,0.0,0,4.8807006,0.0,0.35453612,165.09607,5.4019251,303.1738,-9.3125534
1943,1943,145.3779,18.554771,4.534193,0.0,0,4.8394608,0.0,0.3588908,164.93361,5.3595243,303.28809,-9.3125858
1945,1945,145.3783,18.670935,4.5705919,0.0,0,4.7982206,0.0,0.36337504,165.17722,5.3131504,303.40237,-9.312006
1947,1947,145.3787,18.750767,4.6159143,0.0,0,4.7569809,0.0,0.36735502,165.31583,5.2688842,303.51666,-9.3119717
1949,1949,145.3791,18.815228,4.6679015,0.0,0,4.7157407,0.0,0.37192804,165.12735,5.2242732,303.63098,-9.3122377
1951,1951,145.3795,18.871004,4.7044635,0.0,0,4.6745009,0.0,0.37637714,164.90225,5.177093,303.74527,-9.3117447
1953,1953,145.3799,18.960329,4.7536964,0.0,0,4.6332607,0.0,0.38040808,164.91989,5.1324673,303.85956,-9.3123302
1955,1955,145.3803,19.072208,4.8039064,0.0,0,4.5920205,0.0,0.38536102,165.04681,5.0855641,303.97388,-9.3115101
1957,1957,145.3807,19.169104,4.8414402,0.0,0,4.5507808,0.0,0.38969445,165.26114,5.0434861,304.08817,-9.3109207
1959,1959,145.3811,19.204628,4.8895669,0.0,0,4.5108628,0.0,0.39362177,164.93373,5.0005407,304.20245,-9.3117743
1961,1961,145.3815,19.273924,4.9344854,0.0,0,4.4716268,0.0,0.39871234,164.63902,4.9530749,304.31674,-9.3116055
1963,1963,145.3819,19.361334,4.9744167,0.0,0,4.4323945,0.0,0.40271565,164.71019,4.911273,304.42401,-9.3117104
1965,1965,145.3823,19.471699,5.0198598,0.0,0,4.3931623,0.0,0.40656769,164.94362,4.866353,304.52951,-9.3114433
1967,1967,145.3827,19.564058,5.0599318,0.0,0,4.353931,0.0,0.41150105,165.02286,4.8197899,304.63501,-9.3108654
1969,1969,145.3831,19.605246,5.1029301,0.0,0,4.3146987,0.0,0.41535783,164.71445,4.7801609,304.74048,-9.3111973
1971,1971,145.3835,19.683395,5.1484346,0.0,0,4.2754664,0.0,0.41964757,164.63574,4.7361274,304.84598,-9.3113222
1973,1973,145.3839,19.772404,5.1892776,0.0,0,4.2362342,0.0,0.42475927,164.51823,4.6896229,304.95148,-9.3106956
1975,1975,145.3843,19.886311,5.2364736,0.0,0,4.1970024,0.0,0.42854905,164.89613,4.6514654,305.05698,-9.3109865
1977,1977,145.3847,19.961298,5.2774744,0.0,0,4.1577706,0.0,0.43311638,164.80482,4.6062322,305.16245,-9.3110065
1979,1979,145.3851,20.031233,5.3140125,0.0,0,4.1185384,0.0,0.43749574,164.59457,4.5640588,305.26794,-9.3109713
1981,1981,145.3855,20.092897,5.363626,0.0,0,4.0793066,0.0,0.44149688,164.48262,4.520916,305.37344,-9.3113403
1983,1983,145.3859,20.188187,5.3999214,0.0,0,4.0404687,0.0,0.44610524,164.48761,4.4803948,305.47894,-9.3124876
1985,1985,145.3863,20.296873,5.4393592,0.0,0,4.0030627,0.0,0.45003217,164.67191,4.4344459,305.58444,-9.3111563
1987,1987,145.3867,20.379944,5.4886556,0.0,0,3.9657502,0.0,0.45442891,164.66896,4.3951683,305.68991,-9.3107872
1989,1989,145.3871,20.448782,5.5243416,0.0,0,3.9284382,0.0,0.45929298,164.41565,4.3557711,305.79541,-9.3111486
1991,1991,145.3875,20.510651,5.5665035,0.0,0,3.8911264,0.0,0.46318969,164.36186,4.3115983,305.90091,-9.3124065
1993,1993,145.3879,20.621042,5.6135855,0.0,0,3.8538144,0.0,0.46794492,164.35104,4.2750039,306.00641,-9.3129826
1995,1995,145.3883,20.716204,5.6439238,0.0,0,3.8165023,0.0,0.47218409,164.45224,4.2314701,306.11191,-9.3129864
1997,1997,145.3887,20.816273,5.6854143,0.0,0,3.7791903,0.0,0.475537,164.68051,4.191308,306.21738,-9.3119059
1999,1999,145.3891,20.876574,5.7298265,0.0,0,3.7418783,0.0,0.48072502,164.31142,4.1519351,306.32288,-9.3105764
2001,2001,145.3895,20.963255,5.7626796,0.0,0,3.7045665,0.0,0.48478046,164.32318,4.1127,306.42838,-9.3107157
2003,2003,145.3899,21.058386,5.8063912,0.0,0,3.6672544,0.0,0.48861605,164.38846,4.069551,306.53387,-9.3110828
2005,2005,145.3903,21.176977,5.8450418,0.0,0,3.6299422,0.0,0.4937917,164.48793,4.0290666,306.63937,-9.3120718
2007,2007,145.3907,21.248116,5.8810763,0.0,0,3.5926304,0.0,0.49746487,164.48824,3.9889283,306.74484,-9.3117962
2009,2009,145.3911,21.328024,5.9250631,0.0,0,3.5565138,0.0,0.50171334,164.39323,3.9493868,306.85034,-9.3103676
2011,2011,145.3915,21.398457,5.9628072,0.0,0,3.521014,0.0,0.50692379,164.09451,3.9102995,306.95584,-9.3098898
2013,2013,145.3919,21.506166,6.0012546,0.0,0,3.4855177,0.0,0.51034939,164.25612,3.873656,307.08731,-9.3101416
2015,2015,145.3923,21.612518,6.039237,0.0,0,3.450022,0.0,0.51456875,164.37033,3.8364284,307.22336,-9.3118534
2017,2017,145.3927,21.692501,6.0695896,0.0,0,3.414526,0.0,0.51888114,164.33951,3.7980134,307.35941,-9.3112974
2019,2019,145.3931,21.782894,6.1147838,0.0,0,3.3790298,0.0,0.52263147,164.42029,3.7602277,307.49545,-9.3100567
2021,2021,145.3935,21.856153,6.1510105,0.0,0,3.343534,0.0,0.52744269,164.1274,3.7239544,307.6315,-9.3096523
2023,2023,145.3939,21.959179,6.1840186,0.0,0,3.308038,0.0,0.53149259,164.26849,3.6837144,307.76755,-9.3112288
2025,2025,145.3943,22.079548,6.229619,0.0,0,3.2725418,0.0,0.5354799,164.48598,3.6477604,307.90359,-9.3108234
2027,2027,145.3947,22.170866,6.2585649,0.0,0,3.2370458,0.0,0.54001325,164.47182,3.6101692,308.03967,-9.3105669
2029,2029,145.3951,22.249632,6.294004,0.0,0,3.2015498,0.0,0.54368848,164.40529,3.5738196,308.17572,-9.310729
2031,2031,145.3955,22.324907,6.3414259,0.0,0,3.1660538,0.0,0.54829025,164.24825,3.5342479,308.31177,-9.3101053
2033,2033,145.3959,22.43623,6.3689251,0.0,0,3.1309123,0.0,0.55290794,164.25253,3.5004494,308.44781,-9.3101358
2035,2035,145.3963,22.548672,6.4042668,0.0,0,3.0970597,0.0,0.55607039,164.57954,3.4653611,308.58386,-9.3102884
2037,2037,145.3967,22.645552,6.4449701,0.0,0,3.0632915,0.0,0.56081939,164.49388,3.4307866,308.71991,-9.3106422
2039,2039,145.3971,22.710724,6.4705372,0.0,0,3.0295236,0.0,0.56457609,164.31676,3.395144,308.85596,-9.3103943
2041,2041,145.3975,22.794483,6.5098653,0.0,0,2.9957557,0.0,0.56816465,164.41701,3.3635788,308.992,-9.310833
2043,2043,145.3979,22.916002,6.5491157,0.0,0,2.9619877,0.0,0.5735873,164.34889,3.3240683,309.12805,-9.3105822
2045,2045,145.3983,23.03623,6.5805721,0.0,0,2.9282196,0.0,0.57733029,164.55376,3.2905927,309.2641,-9.3098774
2047,2047,145.3987,23.134218,6.6190977,0.0,0,2.8944514,0.0,0.58104825,164.64752,3.2503042,309.40015,-9.3100843
2049,2049,145.3991,23.201241,6.6512341,0.0,0,2.8606834,0.0,0.58610588,164.36119,3.2154257,309.53619,-9.3109293
2051,2051,145.3995,23.292816,6.6836324,0.0,0,2.8269155,0.0,0.58937764,164.46115,3.1860132,309.67224,-9.3113108
2053,2053,145.3999,23.419012,6.7193551,0.0,0,2.7931476,0.0,0.59331256,164.6274,3.1448085,309.80832,-9.3108358
2055,2055,145.4003,23.553848,6.7495327,0.0,0,2.7593796,0.0,0.5981003,164.80148,3.1117697,309.94437,-9.3100595
2057,2057,145.4007,23.629641,6.7872314,0.0,0,2.7256117,0.0,0.60150874,164.81232,3.0816617,310.08041,-9.3100548
2059,2059,145.4011,23.704195,6.821856,0.0,0,2.6929286,0.0,0.60611105,164.60837,3.0457783,310.21646,-9.3108139
2061,2061,145.4015,23.80377,6.8518829,0.0,0,2.660805,0.0,0.61053914,164.5352,3.0104802,310.35251,-9.3101864
2063,2063,145.4019,23.950993,6.8946199,0.0,0,2.6286848,0.0,0.61441648,164.82925,2.9757431,310.3374,-9.3087521
2065,2065,145.4023,24.078398,6.920805,0.0,0,2.5965648,0.0,0.61867809,165.04594,2.9433413,310.30554,-9.3095284
2067,2067,145.4027,24.15723,6.950521,0.0,0,2.5644448,0.0,0.62232041,165.03058,2.9049656,310.27368,-9.3101034
2069,2069,145.4031,24.257034,6.9938006,0.0,0,2.5323246,0.0,0.62651724,164.98944,2.8775222,310.24179,-9.3110466
2071,2071,145.4035,24.36484,7.0189605,0.0,0,2.5002048,0.0,0.63107842,164.96516,2.8425312,310.20993,-9.3106976
2073,2073,145.4039,24.511398,7.0518112,0.0,0,2.4680848,0.0,0.63458443,165.345,2.8068697,310.17807,-9.3092966
2075,2075,145.4043,24.623569,7.0938196,0.0,0,2.4359648,0.0,0.63945669,165.38078,2.7740271,310.14621,-9.3087521
2077,2077,145.4047,24.70859,7.1172028,0.0,0,2.4038448,0.0,0.64367551,165.26703,2.7440627,310.11432,-9.3088236
2079,2079,145.4051,24.804497,7.1536736,0.0,0,2.3717248,0.0,0.64708304,165.31813,2.7119181,310.08246,-9.3092728
2081,2081,145.4055,24.924908,7.1902184,0.0,0,2.3396046,0.0,0.65213674,165.2438,2.6755538,310.0506,-9.3095999
2083,2083,145.4059,25.060957,7.2128386,0.0,0,2.3078065,0.0,0.65573299,165.56758,2.6457024,310.01874,-9.3092699
2085,2085,145.4063,25.184456,7.2484679,0.0,0,2.2771778,0.0,0.65914541,165.82224,2.6152163,309.98685,-9.3086681
2087,2087,145.4067,25.283319,7.2824297,0.0,0,2.2466257,0.0,0.66446137,165.55154,2.5816941,309.95499,-9.3094435
2089,2089,145.4071,25.378681,7.309742,0.0,0,2.216074,0.0,0.66788459,165.63615,2.5479877,309.92313,-9.3093996
2091,2091,145.4075,25.515266,7.3450799,0.0,0,2.1855218,0.0,0.67166775,165.85353,2.51406,309.89127,-9.3100443
2093,2093,145.4079,25.651737,7.3753247,0.0,0,2.1549697,0.0,0.67702645,165.89227,2.4816909,309.85938,-9.3099995
2095,2095,145.4083,25.776815,7.4081974,0.0,0,2.1244178,0.0,0.68032825,166.11411,2.4508994,309.82751,-9.309761
2097,2097,145.4087,25.87566,7.4417505,0.0,0,2.0938659,0.0,0.68466753,166.06226,2.4188409,309.79565,-9.3091965
2099,2099,145.4091,25.978079,7.466157,0.0,0,2.063314,0.0,0.68908882,165.97058,2.3876956,309.76379,-9.3098221
2101,2101,145.4095,26.10989,7.5014353,0.0,0,2.0327621,0.0,0.6922431,166.29376,2.3564215,309.7319,-9.3096428
2103,2103,145.4099,26.24626,7.5304456,0.0,0,2.0022097,0.0,0.69689411,166.33127,2.3265095,309.70004,-9.3087234
2105,2105,145.4103,26.377831,7.5581698,0.0,0,1.9716576,0.0,0.70107204,166.51933,2.2961755,309.66818,-9.3079777
2107,2107,145.4107,26.481045,7.5978703,0.0,0,1.9411056,0.0,0.70488524,166.50418,2.2665026,309.63632,-9.3088293
2109,2109,145.4111,26.592703,7.6221623,0.0,0,1.9115331,0.0,0.70963317,166.48256,2.2357526,309.60443,-9.3097649
2111,2111,145.4115,26.715141,7.6502652,0.0,0,1.8824661,0.0,0.71318609,166.58382,2.2050979,309.57257,-9.3103313
2113,2113,145.4119,26.858795,7.6874428,0.0,0,1.8534019,0.0,0.71723408,166.85454,2.1735585,309.39859,-9.309577
2115,2115,145.4123,26.988895,7.7071185,0.0,0,1.824338,0.0,0.72151023,166.9313,2.1417739,309.21716,-9.3079376
2117,2117,145.4127,27.096878,7.7376156,0.0,0,1.795274,0.0,0.72469127,167.12344,2.1154523,309.03574,-9.3068838
2119,2119,145.4131,27.214607,7.7776451,0.0,0,1.76621,0.0,0.73003602,166.95682,2.0841873,308.85431,-9.3072653
2121,2121,145.4135,27.362188,7.7971754,0.0,0,1.737146,0.0,0.73391795,167.14264,2.0515842,308.67288,-9.3092422
2123,2123,145.4139,27.520624,7.8306947,0.0,0,1.708082,0.0,0.73719144,167.55093,2.0205576,308.49146,-9.3091145
2125,2125,145.4143,27.645399,7.8630238,0.0,0,1.679018,0.0,0.74251556,167.43733,1.9926572,308.31003,-9.3096828
2127,2127,145.4147,27.765408,7.8852768,0.0,0,1.649954,0.0,0.74589789,167.62723,1.9613669,308.1286,-9.307436
2129,2129,145.4151,27.880836,7.9176159,0.0,0,1.6208899,0.0,0.74946076,167.71132,1.93382,307.94717,-9.3070259
2131,2131,145.4155,28.019587,7.9461675,0.0,0,1.591826,0.0,0.7547425,167.63274,1.9021102,307.76575,-9.3070745
2133,2133,145.4159,28.183784,7.9730382,0.0,0,1.5630525,0.0,0.75788337,168.06468,1.875883,307.58429,-9.3077965
2135,2135,145.4163,28.32527,8.0047293,0.0,0,1.5353351,0.0,0.76193631,168.24023,1.8420321,307.40286,-9.3084936
2137,2137,145.4167,28.438902,8.0283442,0.0,0,1.507687,0.0,0.76674294,168.14595,1.8164294,307.22144,-9.3085947
2139,2139,145.4171,28.564556,8.0592766,0.0,0,1.480039,0.0,0.7697593,168.34393,1.7857027,307.04001,-9.3085546
2141,2141,145.4175,28.717358,8.0883369,0.0,0,1.452391,0.0,0.77417982,168.45943,1.7590344,306.85858,-9.3065987
2143,2143,145.4179,28.878914,8.1101074,0.0,0,1.4247431,0.0,0.77846372,168.70035,1.7300909,306.67715,-9.3066196
2145,2145,145.4183,29.025166,8.1460276,0.0,0,1.3970951,0.0,0.78189528,169.01617,1.7028861,306.49573,-9.3069553
2147,2147,145.4187,29.137407,8.1713181,0.0,0,1.3694471,0.0,0.78683758,168.86223,1.6758705,306.3143,-9.3069429
2149,2149,145.4191,29.270584,8.1964684,0.0,0,1.341799,0.0,0.79065794,168.95189,1.6490682,306.13287,-9.3081141
2151,2151,145.4195,29.430101,8.2322903,0.0,0,1.3141512,0.0,0.79439223,169.22057,1.6196194,305.95145,-9.3077669
2153,2153,145.4199,29.614515,8.250844,0.0,0,1.2865031,0.0,0.7989704,169.5347,1.5974424,305.77002,-9.3071136
2155,2155,145.4203,29.759769,8.2772446,0.0,0,1.2588551,0.0,0.80212468,169.82407,1.5642757,305.58856,-9.3069544
2157,2157,145.4207,29.892254,8.3148575,0.0,0,1.2312071,0.0,0.8069073,169.77193,1.5364779,305.40714,-9.3070211
2159,2159,145.4211,30.035824,8.3326063,0.0,0,1.2044492,0.0,0.81128001,169.79918,1.5095954,305.22571,-9.3075342
2161,2161,145.4215,30.201164,8.3644142,0.0,0,1.1781503,0.0,0.81466168,170.21362,1.4822963,305.04428,-9.3079205
2163,2163,145.4219,30.389574,8.3982067,0.0,0,1.1518543,0.0,0.82003903,170.28159,1.4523057,304.76389,-9.308507
2165,2165,145.4223,30.52774,8.4139948,0.0,0,1.1255583,0.0,0.82362217,170.50539,1.4269096,304.48352,-9.3072062
2167,2167,145.4227,30.648819,8.4444551,0.0,0,1.0992622,0.0,0.82659084,170.72194,1.3964359,304.20313,-9.3073483
2169,2169,145.4231,30.815878,8.4733744,0.0,0,1.0729662,0.0,0.83216059,170.63272,1.368911,303.92276,-9.3070145
2171,2171,145.4235,30.998346,8.4958143,0.0,0,1.0466702,0.0,0.83555335,171.07901,1.3412331,303.6424,-9.3062601
2173,2173,145.4239,31.193243,8.5280466,0.0,0,1.0203742,0.0,0.83943063,171.45981,1.3134083,303.362,-9.305644
2175,2175,145.4243,31.345058,8.5537271,0.0,0,0.99407822,0.0,0.84503138,171.36429,1.2835469,303.08163,-9.3057709
2177,2177,145.4247,31.495129,8.5806217,0.0,0,0.9677822,0.0,0.84815729,171.65277,1.2585415,302.80124,-9.3062344
2179,2179,145.4251,31.666706,8.6103687,0.0,0,0.94148624,0.0,0.85247409,171.8002,1.2299459,302.52087,-9.3067989
2181,2181,145.4255,31.864508,8.6311989,0.0,0,0.91519028,0.0,0.85732222,172.03592,1.2006181,302.24051,-9.305666
2183,2183,145.4259,32.044121,8.6639318,0.0,0,0.88915849,0.0,0.86050922,172.4991,1.1722066,301.96011,-9.305604
2185,2185,145.4263,32.202087,8.6911068,0.0,0,0.86408746,0.0,0.86572307,172.42348,1.1498708,301.67975,-9.3059921
2187,2187,145.4267,32.358326,8.7124434,0.0,0,0.83907932,0.0,0.86993486,172.50296,1.1199957,301.39935,-9.3051758
2189,2189,145.4271,32.541378,8.7466192,0.0,0,0.8140713,0.0,0.87349433,172.88396,1.0945822,301.11899,-9.3059177
2191,2191,145.4275,32.738277,8.7661057,0.0,0,0.78906333,0.0,0.87817442,173.09651,1.0678211,300.83859,-9.305829
2193,2193,145.4279,32.932182,8.7888012,0.0,0,0.76405537,0.0,0.88148224,173.54973,1.0405674,300.55823,-9.3057508
2195,2195,145.4283,33.110344,8.8257732,0.0,0,0.73904735,0.0,0.88613385,173.72728,1.0113482,300.27786,-9.3051109
2197,2197,145.4287,33.276073,8.8458319,0.0,0,0.71403933,0.0,0.89146793,173.63976,0.98576015,299.99747,-9.304347
2199,2199,145.4291,33.473118,8.8740788,0.0,0,0.68903136,0.0,0.89497459,174.07541,0.95726132,299.7171,-9.3049097
2201,2201,145.4295,33.673912,8.9083147,0.0,0,0.6640234,0.0,0.90009618,174.20732,0.93028963,299.43671,-9.3049154
2203,2203,145.4299,33.880299,8.9228363,0.0,0,0.63901532,0.0,0.90420896,174.54707,0.89969802,299.15634,-9.305336
2205,2205,145.4303,34.06321,8.9520302,0.0,0,0.61400735,0.0,0.90719968,174.99313,0.87554038,298.87598,-9.3053274
2207,2207,145.4307,34.252117,8.9812803,0.0,0,0.58899933,0.0,0.91269016,174.97864,0.85013056,298.59558,-9.304965
2209,2209,145.4311,34.454662,8.9978857,0.0,0,0.56478655,0.0,0.91632926,175.36023,0.81988055,298.31522,-9.3049688
2211,2211,145.4315,34.667988,9.0310841,0.0,0,0.54098403,0.0,0.92007631,175.78783,0.79574829,298.05142,-9.3041725
2213,2213,145.4319,34.879364,9.0591898,0.0,0,0.51718396,0.0,0.92644507,175.73602,0.76999676,298.10168,-9.3044939
2215,2215,145.4323,35.064995,9.0800724,0.0,0,0.49338397,0.0,0.92961115,176.12115,0.74275684,298.15198,-9.3036766
2217,2217,145.4327,35.262043,9.1098032,0.0,0,0.46958399,0.0,0.93361241,176.38817,0.71807456,298.20227,-9.3044024
2219,2219,145.4331,35.468777,9.1276693,0.0,0,0.44578397,0.0,0.9385978,176.54929,0.68716401,298.25253,-9.3052568
2221,2221,145.4335,35.726151,9.1551838,0.0,0,0.42198399,0.0,0.94140154,177.27591,0.66473919,298.30283,-9.3050137
2223,2223,145.4339,35.981586,9.182888,0.0,0,0.39818397,0.0,0.94654083,177.64571,0.6359092,298.35312,-9.3041983
2225,2225,145.4343,36.209476,9.2044868,0.0,0,0.37438396,0.0,0.95169151,177.88817,0.60863316,298.40338,-9.3041925
2227,2227,145.4347,36.420467,9.2399349,0.0,0,0.35058397,0.0,0.9557659,178.21169,0.58489907,298.45367,-9.3038254
2229,2229,145.4351,36.654255,9.2651339,0.0,0,0.32678398,0.0,0.96115094,178.34547,0.55531979,298.50397,-9.3036985
2231,2231,145.4355,36.90078,9.2848167,0.0,0,0.30298397,0.0,0.96512818,178.85542,0.52856863,298.55423,-9.3036633
2233,2233,145.4359,37.164055,9.3164291,0.0,0,0.27942356,0.0,0.96878272,179.48207,0.50468647,298.60452,-9.3037148