File: clean data/testID_0206.csv
level_0,index,Time(sec),Force(kN),Jaw(mm),PowAngle(deg),Power(W),Pram,PTemp,Strain,Stress(MPa),Stroke(mm),TC1(C),wedge(mm)
1972,1972,165.3441,0.46902633,0.047403127,0.0,0,9.0629702,0.0,0.0029489517,4.6424656,10.102717,362.15677,-9.2884197
1974,1974,165.3445,3.6265306,0.096364781,0.0,0,9.0044422,0.0,0.0062861745,40.642391,10.04257,362.31912,-9.2874727
1976,1976,165.3449,6.016592,0.14724204,0.0,0,8.9459143,0.0,0.0094221625,74.602669,9.9840984,362.48148,-9.2866774
1978,1978,165.3453,6.4075317,0.22940317,0.0,0,8.8873854,0.0,0.014554522,79.75444,9.902504,362.6438,-9.2834482
1980,1980,165.3457,6.8180022,0.36367857,0.0,0,8.8288574,0.0,0.023959823,84.730515,9.8088465,362.80615,-9.2830458
1982,1982,165.3461,7.1553884,0.44016802,0.0,0,8.7703295,0.0,0.028930103,87.797043,9.7072659,362.96851,-9.2824011
1984,1984,165.3465,7.6270957,0.54279757,0.0,0,8.7136869,0.0,0.036253139,93.202248,9.6053181,363.13086,-9.2825937
1986,1986,165.3469,8.1463556,0.59415436,0.0,0,8.6580172,0.0,0.040318795,99.291153,9.5190163,363.29318,-9.2819424
1988,1988,165.3473,7.7783499,0.64907724,0.0,0,8.6023531,0.0,0.043338727,95.64283,9.4473963,363.45554,-9.2812061
1990,1990,165.3477,7.8839951,0.72637314,0.0,0,8.546689,0.0,0.049479328,94.815826,9.3768787,363.61789,-9.2813559
1992,1992,165.3481,8.3579645,0.76153475,0.0,0,8.491025,0.0,0.051660426,100.77556,9.307024,363.78024,-9.2816095
1994,1994,165.3485,8.6186905,0.85323191,0.0,0,8.4353609,0.0,0.057611108,103.25597,9.2324018,363.9426,-9.2816277
1996,1996,165.3489,8.3476906,0.94209987,0.0,0,8.3796968,0.0,0.064503632,100.24011,9.1509638,364.08252,-9.2812977
1998,1998,165.3493,8.3191814,1.0280577,0.0,0,8.3240328,0.0,0.070123747,98.217766,9.0726633,364.15524,-9.2811785
2000,2000,165.3497,8.5923004,1.1113127,0.0,0,8.2683687,0.0,0.076560467,101.40056,8.9905205,364.228,-9.2815771
2002,2002,165.3501,8.6501637,1.1458596,0.0,0,8.2127056,0.0,0.079399861,101.36172,8.9201899,364.30072,-9.2809229
2004,2004,165.3505,8.8552046,1.2063302,0.0,0,8.1570406,0.0,0.083055876,103.99014,8.8509674,364.37344,-9.2815237
2006,2006,165.3509,8.5165291,1.2722085,0.0,0,8.1013775,0.0,0.088500068,99.346954,8.793355,364.44617,-9.281559
2008,2008,165.3513,8.9750366,1.3170056,0.0,0,8.0462675,0.0,0.091543309,103.83982,8.7361994,364.51892,-9.281189
2010,2010,165.3517,9.0021019,1.4023683,0.0,0,7.993176,0.0,0.097285941,104.12285,8.6691513,364.59164,-9.2805805
2012,2012,165.3521,9.0136957,1.4741971,0.0,0,7.9402156,0.0,0.10337456,103.4554,8.6032324,364.66437,-9.2800274
2014,2014,165.3525,8.8790359,1.5486374,0.0,0,7.8872552,0.0,0.10815344,101.70351,8.5345154,364.73709,-9.2804537
2016,2016,165.3529,9.0112791,1.6119119,0.0,0,7.8342953,0.0,0.11328153,102.12714,8.4641809,364.80984,-9.2812939
2018,2018,165.3533,9.1277332,1.6413349,0.0,0,7.7813349,0.0,0.11586591,103.55202,8.4065809,364.88257,-9.2810898
2020,2020,165.3537,9.1060543,1.7071047,0.0,0,7.728375,0.0,0.12003327,102.82752,8.3509979,364.95529,-9.2810869
2022,2022,165.3541,9.1326761,1.7503864,0.0,0,7.675415,0.0,0.12387969,102.71384,8.2971582,365.02805,-9.280364
2024,2024,165.3545,9.3011408,1.7924478,0.0,0,7.6224551,0.0,0.12699902,103.91167,8.2497206,365.10077,-9.2796631
2026,2026,165.3549,9.3865557,1.8641496,0.0,0,7.5694952,0.0,0.13176765,104.849,8.1903639,365.17349,-9.2798929
2028,2028,165.3553,9.3177071,1.9136668,0.0,0,7.5165353,0.0,0.13630395,103.44981,8.1344204,365.24622,-9.2805462
2030,2030,165.3557,9.3564968,1.9773269,0.0,0,7.4635754,0.0,0.14084049,103.53722,8.0753155,365.31897,-9.2800503
2032,2032,165.3561,9.3548508,2.0329483,0.0,0,7.410615,0.0,0.14508003,102.79987,8.0175972,365.39169,-9.2798824
2034,2034,165.3565,9.5509624,2.0646586,0.0,0,7.3593607,0.0,0.14804237,104.81681,7.9632072,365.46442,-9.2797213
2036,2036,165.3569,9.4105072,2.1246326,0.0,0,7.3089876,0.0,0.15210283,102.96977,7.9127798,365.53717,-9.281517
2038,2038,165.3573,9.4855528,2.1696458,0.0,0,7.2586198,0.0,0.15585202,103.30172,7.8660998,365.60989,-9.2810383
2040,2040,165.3577,9.5509481,2.2070918,0.0,0,7.2082515,0.0,0.15902677,103.56561,7.8184061,365.68262,-9.279521
2042,2042,165.3581,9.7375107,2.2638175,0.0,0,7.1578832,0.0,0.16294451,105.15466,7.7712231,365.75534,-9.2793941
2044,2044,165.3585,9.6769657,2.3157885,0.0,0,7.1075149,0.0,0.16741799,104.33652,7.7179451,365.82809,-9.2808294
2046,2046,165.3589,9.622057,2.3698926,0.0,0,7.0571475,0.0,0.17171392,103.1505,7.6654425,365.79596,-9.2813444
2048,2048,165.3593,9.700983,2.4152932,0.0,0,7.0067787,0.0,0.17498994,103.53708,7.6213126,365.44934,-9.2806683
2050,2050,165.3597,9.8189402,2.4591498,0.0,0,6.9564114,0.0,0.17900425,104.39774,7.5684128,365.10275,-9.2810411
2052,2052,165.3601,9.8323488,2.5113904,0.0,0,6.9060431,0.0,0.18280269,104.32588,7.5165868,364.75613,-9.281249
2054,2054,165.3605,9.7964497,2.5535824,0.0,0,6.8556757,0.0,0.18611519,103.50667,7.472765,364.40955,-9.2807655
2056,2056,165.3609,9.8922682,2.5991147,0.0,0,6.8053074,0.0,0.19020891,104.03064,7.4263444,364.06296,-9.2801085
2058,2058,165.3613,9.9397516,2.6487651,0.0,0,6.7554412,0.0,0.1936058,104.28347,7.3791361,363.71634,-9.280303
2060,2060,165.3617,10.008364,2.6966069,0.0,0,6.7074018,0.0,0.1977402,104.47826,7.329823,363.36975,-9.2804117
2062,2062,165.3621,9.9811163,2.7443442,0.0,0,6.6594815,0.0,0.20205925,103.83533,7.283782,363.02313,-9.2810698
2064,2064,165.3625,10.047844,2.7915676,0.0,0,6.6115613,0.0,0.2051453,104.12956,7.2356534,362.67654,-9.2816057
2066,2066,165.3629,10.101338,2.8321829,0.0,0,6.5636415,0.0,0.20907444,104.30569,7.1850452,362.32993,-9.2817879
2068,2068,165.3633,10.140677,2.8767183,0.0,0,6.5157218,0.0,0.21264754,104.30799,7.1404614,361.98334,-9.2812843
2070,2070,165.3637,10.185932,2.9283233,0.0,0,6.467802,0.0,0.21631782,104.39383,7.0929875,361.63672,-9.2798223
2072,2072,165.3641,10.233072,2.9721174,0.0,0,6.4198813,0.0,0.22070073,104.53873,7.0484962,361.29013,-9.2810001
2074,2074,165.3645,10.304301,3.0170369,0.0,0,6.3719611,0.0,0.2240804,104.80119,6.9995079,360.94351,-9.2811222
2076,2076,165.3649,10.30858,3.0751939,0.0,0,6.3240414,0.0,0.22870505,104.45902,6.9523296,360.59692,-9.2813139
2078,2078,165.3653,10.326315,3.1164691,0.0,0,6.2761216,0.0,0.23292284,104.19324,6.9007998,360.25031,-9.2810326
2080,2080,165.3657,10.423338,3.1618164,0.0,0,6.2282019,0.0,0.23604843,104.74789,6.8524013,359.90372,-9.2801924
2082,2082,165.3661,10.487896,3.2162549,0.0,0,6.1802816,0.0,0.24086621,104.90655,6.8060393,359.5571,-9.2801752
2084,2084,165.3665,10.504513,3.2540333,0.0,0,6.1339045,0.0,0.24442196,104.73067,6.756546,359.21051,-9.2815504
2086,2086,165.3669,10.533859,3.3055937,0.0,0,6.0883236,0.0,0.24812904,104.66237,6.7058153,358.86389,-9.2818785
2088,2088,165.3673,10.577689,3.3541818,0.0,0,6.042748,0.0,0.25294611,104.56912,6.6616817,358.5173,-9.2802944
2090,2090,165.3677,10.668866,3.3982668,0.0,0,5.9971714,0.0,0.2565653,105.13123,6.6158109,358.17068,-9.2808018
2092,2092,165.3681,10.705683,3.4526787,0.0,0,5.9515953,0.0,0.26086971,105.01722,6.5653701,357.8241,-9.2808008
2094,2094,165.3685,10.717522,3.4975772,0.0,0,5.9060197,0.0,0.26547089,104.66354,6.5194497,357.47748,-9.2815952
2096,2096,165.3689,10.755714,3.5462236,0.0,0,5.8604436,0.0,0.26917154,104.63544,6.4705172,357.08218,-9.2810059
2098,2098,165.3693,10.824144,3.5946231,0.0,0,5.814867,0.0,0.27338687,104.75276,6.4223461,356.54077,-9.2813377
2100,2100,165.3697,10.904971,3.6358354,0.0,0,5.7692914,0.0,0.27764887,105.10729,6.373239,355.99939,-9.2811384
2102,2102,165.3701,10.919067,3.6903899,0.0,0,5.7237153,0.0,0.2815513,104.92745,6.3247542,355.45798,-9.2805386
2104,2104,165.3705,10.958427,3.7360914,0.0,0,5.6781397,0.0,0.28608036,104.76477,6.2797356,354.91656,-9.2808151
2106,2106,165.3709,11.016429,3.7796056,0.0,0,5.6325636,0.0,0.29019365,104.84782,6.2285376,354.37518,-9.2821512
2108,2108,165.3713,11.060369,3.8356142,0.0,0,5.5874414,0.0,0.2943069,104.89747,6.1791143,353.83377,-9.2813816
2110,2110,165.3717,11.1178,3.8756776,0.0,0,5.5439734,0.0,0.29870641,104.95513,6.1311688,353.29239,-9.2806826
2112,2112,165.3721,11.163635,3.9244444,0.0,0,5.5006132,0.0,0.30287912,104.9737,6.0842133,352.75098,-9.2799902
2114,2114,165.3725,11.194687,3.9805646,0.0,0,5.457253,0.0,0.30751431,104.81756,6.036499,352.20956,-9.2804165
2116,2116,165.3729,11.248119,4.0190096,0.0,0,5.4138932,0.0,0.31191462,104.77169,5.9886947,351.66818,-9.2813435
2118,2118,165.3733,11.286723,4.0681152,0.0,0,5.370533,0.0,0.31580809,104.795,5.9407344,351.12677,-9.280858
2120,2120,165.3737,11.351583,4.1197357,0.0,0,5.3271732,0.0,0.32045072,104.87714,5.8934064,350.58539,-9.2814188
2122,2122,165.3741,11.423458,4.1588755,0.0,0,5.283813,0.0,0.32466355,105.05614,5.8480129,350.04398,-9.2804527
2124,2124,165.3745,11.453073,4.2093353,0.0,0,5.2404532,0.0,0.32857412,104.8824,5.7995605,349.50256,-9.2800188
2126,2126,165.3749,11.488488,4.258503,0.0,0,5.1970935,0.0,0.33356196,104.76978,5.7502975,348.96118,-9.2801085
2128,2128,165.3753,11.539036,4.3027902,0.0,0,5.1537333,0.0,0.33788618,104.75723,5.7057133,348.41977,-9.2812996
2130,2130,165.3757,11.621318,4.3524294,0.0,0,5.110373,0.0,0.3419354,105.05708,5.6592631,347.87839,-9.2810583
2132,2132,165.3761,11.676733,4.3979869,0.0,0,5.0670133,0.0,0.34698805,105.02065,5.609282,347.33698,-9.2820663
2134,2134,165.3765,11.677021,4.4423194,0.0,0,5.0250483,0.0,0.35087174,104.71846,5.5643225,346.79556,-9.2810555
2136,2136,165.3769,11.720208,4.4910741,0.0,0,4.9838037,0.0,0.35502192,104.54935,5.5170183,346.25418,-9.2803354
2138,2138,165.3773,11.790969,4.5337934,0.0,0,4.9425635,0.0,0.36001071,104.6646,5.4717207,345.71277,-9.2807961
2140,2140,165.3777,11.868489,4.5827003,0.0,0,4.9013238,0.0,0.36385256,104.95313,5.4223704,345.17139,-9.2812757
2142,2142,165.3781,11.898832,4.6294131,0.0,0,4.8600836,0.0,0.36852345,104.80299,5.3780541,344.62997,-9.2821293
2144,2144,165.3785,11.905666,4.6705351,0.0,0,4.8188438,0.0,0.37316304,104.38251,5.3330545,344.08856,-9.281332
2146,2146,165.3789,11.980247,4.7239046,0.0,0,4.7776036,0.0,0.37726966,104.511,5.2874303,343.61295,-9.2809992
2148,2148,165.3793,12.053651,4.7651639,0.0,0,4.7363639,0.0,0.38199908,104.65845,5.240243,343.33463,-9.2799282
2150,2150,165.3797,12.108624,4.8064013,0.0,0,4.6951237,0.0,0.38621262,104.76385,5.1940603,343.0563,-9.2801876
2152,2152,165.3801,12.136633,4.8607092,0.0,0,4.6538839,0.0,0.39049819,104.55035,5.1519542,342.77795,-9.2804222
2154,2154,165.3805,12.177851,4.8982444,0.0,0,4.6126437,0.0,0.39527127,104.39646,5.1054912,342.49963,-9.2817888
2156,2156,165.3809,12.233321,4.9429717,0.0,0,4.5714035,0.0,0.39927608,104.48906,5.0606484,342.22128,-9.2818775
2158,2158,165.3813,12.291407,4.9954605,0.0,0,4.5305758,0.0,0.40405145,104.45191,5.0161581,341.94296,-9.2808084
2160,2160,165.3817,12.347825,5.0317278,0.0,0,4.4912457,0.0,0.40871942,104.44218,4.9714046,341.66464,-9.2815132
2162,2162,165.3821,12.401687,5.0770993,0.0,0,4.4520135,0.0,0.4124155,104.45782,4.9280114,341.38629,-9.2810278
2164,2164,165.3825,12.428696,5.1274037,0.0,0,4.4127812,0.0,0.41770315,104.19465,4.8823485,341.10797,-9.280757
2166,2166,165.3829,12.465833,5.1623292,0.0,0,4.3735495,0.0,0.42192027,104.05727,4.8405652,340.82962,-9.2806301
2168,2168,165.3833,12.5489,5.209363,0.0,0,4.3343177,0.0,0.42576468,104.34,4.7969947,340.5513,-9.281291
2170,2170,165.3837,12.608656,5.2525764,0.0,0,4.2950859,0.0,0.4308694,104.31032,4.753149,340.27298,-9.281641
2172,2172,165.3841,12.641014,5.2905183,0.0,0,4.2558532,0.0,0.43472919,104.21258,4.7109013,339.99463,-9.2817612
2174,2174,165.3845,12.66328,5.3393745,0.0,0,4.2166214,0.0,0.43916804,103.86765,4.6681404,339.71631,-9.281168
2176,2176,165.3849,12.71969,5.380177,0.0,0,4.1773891,0.0,0.44436306,103.8188,4.6270576,339.43796,-9.280962
2178,2178,165.3853,12.810284,5.4210677,0.0,0,4.1381574,0.0,0.44787169,104.22142,4.5835323,339.15964,-9.2800388
2180,2180,165.3857,12.865872,5.4643021,0.0,0,4.0989256,0.0,0.45228592,104.19798,4.5447841,338.88132,-9.280241
2182,2182,165.3861,12.891202,5.5015645,0.0,0,4.0596933,0.0,0.45708022,103.89898,4.4997129,338.60297,-9.2809963
2184,2184,165.3865,12.94578,5.5466852,0.0,0,4.0217257,0.0,0.4608674,103.95953,4.459281,338.32465,-9.2820768
2186,2186,165.3869,13.027583,5.5862741,0.0,0,3.9844091,0.0,0.46547025,104.04202,4.4173074,338.0463,-9.282546
2188,2188,165.3873,13.092475,5.6231976,0.0,0,3.9470971,0.0,0.46996126,104.17057,4.3737211,337.76797,-9.2816343
2190,2190,165.3877,13.147504,5.6750331,0.0,0,3.9097853,0.0,0.47420216,104.17171,4.3311296,337.48965,-9.2789965
2192,2192,165.3881,13.191301,5.7115345,0.0,0,3.8724732,0.0,0.4790763,103.98103,4.2898755,337.2113,-9.277524
2194,2194,165.3885,13.2341,5.7493668,0.0,0,3.8351612,0.0,0.48313603,103.85899,4.2505159,336.93298,-9.2799263
2196,2196,165.3889,13.294073,5.7975321,0.0,0,3.7978492,0.0,0.48742199,103.9048,4.2096357,336.75577,-9.2814198
2198,2198,165.3893,13.36305,5.8277774,0.0,0,3.7605371,0.0,0.4919557,104.02812,4.1696405,336.88181,-9.2826605
2200,2200,165.3897,13.430299,5.866353,0.0,0,3.7232251,0.0,0.49561796,104.11009,4.1307917,337.00784,-9.2804775
2202,2202,165.3901,13.475477,5.9134746,0.0,0,3.6859133,0.0,0.50045717,103.98715,4.0922599,337.13391,-9.2793932
2204,2204,165.3905,13.527814,5.9444084,0.0,0,3.6486013,0.0,0.50480163,103.86546,4.0475764,337.25995,-9.2789469
2206,2206,165.3909,13.578048,5.9878206,0.0,0,3.611289,0.0,0.50852698,103.8878,4.0112557,337.38599,-9.280036
2208,2208,165.3913,13.667365,6.0316939,0.0,0,3.5743496,0.0,0.51395667,103.99112,3.9725702,337.51202,-9.2799454
2210,2210,165.3917,13.719929,6.0639939,0.0,0,3.5387647,0.0,0.51804233,104.02666,3.9351287,337.63809,-9.2809772
2212,2212,165.3921,13.7685,6.1067786,0.0,0,3.5032687,0.0,0.52175421,104.02048,3.8944032,337.76413,-9.2816401
2214,2214,165.3925,13.812374,6.1444473,0.0,0,3.4677725,0.0,0.52703393,103.77235,3.8577213,337.89017,-9.2804003
2216,2216,165.3929,13.873223,6.1771946,0.0,0,3.4322767,0.0,0.5304299,103.84905,3.8193789,338.0162,-9.2799101
2218,2218,165.3933,13.957922,6.2177558,0.0,0,3.3967807,0.0,0.53445029,104.06754,3.7813494,338.14227,-9.2794456
2220,2220,165.3937,14.033773,6.2559419,0.0,0,3.3612847,0.0,0.53981847,104.07147,3.7443421,338.26831,-9.2786446
2222,2222,165.3941,14.077338,6.2961822,0.0,0,3.3257885,0.0,0.54347855,104.04494,3.7086587,338.39435,-9.2801819
2224,2224,165.3945,14.138701,6.3354383,0.0,0,3.2902927,0.0,0.54805034,104.0211,3.6730101,338.52039,-9.2804985
2226,2226,165.3949,14.207463,6.3648143,0.0,0,3.2547965,0.0,0.55255264,104.04354,3.6336882,338.64645,-9.2803764
2228,2228,165.3953,14.298101,6.4063139,0.0,0,3.2193005,0.0,0.55609226,104.34299,3.5956461,338.77249,-9.2788534
2230,2230,165.3957,14.371539,6.4415627,0.0,0,3.1838045,0.0,0.5607577,104.41142,3.5576673,338.89853,-9.2786951
2232,2232,165.3961,14.40532,6.4739676,0.0,0,3.1483085,0.0,0.56497216,104.24671,3.5225465,339.02457,-9.2790346
2234,2234,165.3965,14.467955,6.5231323,0.0,0,3.1139498,0.0,0.56935501,104.16532,3.4849572,339.15063,-9.2809572
2236,2236,165.3969,14.539989,6.5535235,0.0,0,3.0801783,0.0,0.57439089,104.16426,3.4481902,339.27667,-9.2817202
2238,2238,165.3973,14.639752,6.5886621,0.0,0,3.0464103,0.0,0.57812852,104.46366,3.4108973,339.40271,-9.2805586
2240,2240,165.3977,14.721957,6.6337123,0.0,0,3.0126421,0.0,0.58266211,104.57548,3.3733504,339.52875,-9.279314
2242,2242,165.3981,14.750709,6.6594057,0.0,0,2.9788742,0.0,0.58717847,104.38505,3.3356707,339.65482,-9.2792253
2244,2244,165.3985,14.815789,6.6963959,0.0,0,2.9451063,0.0,0.590657,104.46387,3.3016114,339.78085,-9.2799644
2246,2246,165.3989,14.918094,6.7403941,0.0,0,2.9113381,0.0,0.59580874,104.59265,3.2636957,339.90689,-9.2803698
2248,2248,165.3993,15.012943,6.7675414,0.0,0,2.8775702,0.0,0.60010874,104.83286,3.2286394,340.03293,-9.2804003
2250,2250,165.3997,15.061739,6.8074517,0.0,0,2.8438022,0.0,0.60386747,104.82946,3.1930175,340.21585,-9.280386
2252,2252,165.4001,15.119411,6.8457694,0.0,0,2.810034,0.0,0.60916173,104.6749,3.1572058,340.56934,-9.2788143
2254,2254,165.4005,15.197163,6.874227,0.0,0,2.7762663,0.0,0.61295217,104.70831,3.1210635,340.92282,-9.2790642
2256,2256,165.4009,15.297463,6.9130869,0.0,0,2.7424982,0.0,0.61686349,105.0451,3.0859809,341.27631,-9.2788067
2258,2258,165.4013,15.380155,6.9469671,0.0,0,2.7090681,0.0,0.622181,105.10079,3.0545449,341.62979,-9.2799616
2260,2260,165.4017,15.452664,6.9816041,0.0,0,2.6768675,0.0,0.62593341,105.18112,3.0168684,341.98331,-9.2809172
2262,2262,165.4021,15.515053,7.0200596,0.0,0,2.6447473,0.0,0.6301893,105.08264,2.9816844,342.33679,-9.2809591
2264,2264,165.4025,15.583066,7.0503173,0.0,0,2.6126273,0.0,0.63533187,105.06037,2.9457283,342.69028,-9.2794065
2266,2266,165.4029,15.689775,7.0867229,0.0,0,2.580507,0.0,0.63875484,105.39517,2.913223,343.04376,-9.2784309
2268,2268,165.4033,15.790429,7.1213527,0.0,0,2.5483871,0.0,0.6432541,105.58659,2.8785865,343.39725,-9.2777777
2270,2270,165.4037,15.856354,7.1508169,0.0,0,2.5162671,0.0,0.64793348,105.57743,2.8448818,343.75073,-9.2782946
2272,2272,165.4041,15.904984,7.1935987,0.0,0,2.4841471,0.0,0.65188515,105.51263,2.8094435,344.10425,-9.2800589
2274,2274,165.4045,15.987066,7.2232533,0.0,0,2.4520271,0.0,0.65680116,105.51357,2.7817998,344.45773,-9.2805281
2276,2276,165.4049,16.090513,7.2516828,0.0,0,2.4199073,0.0,0.66050971,105.74664,2.7474606,344.81122,-9.279912
2278,2278,165.4053,16.18532,7.2936869,0.0,0,2.3877871,0.0,0.66458875,106.01465,2.7107275,345.1647,-9.2786932
2280,2280,165.4057,16.247217,7.3188777,0.0,0,2.3556671,0.0,0.66955245,105.91241,2.6772983,345.51819,-9.2779007
2282,2282,165.4061,16.328381,7.3534784,0.0,0,2.3235471,0.0,0.67321807,105.96877,2.6436541,345.87167,-9.2793827
2284,2284,165.4065,16.427212,7.3961353,0.0,0,2.2924592,0.0,0.67833257,106.04923,2.6106489,346.22519,-9.2794828
2286,2286,165.4069,16.527063,7.4187536,0.0,0,2.261904,0.0,0.68285733,106.25034,2.5764959,346.57867,-9.2802849
2288,2288,165.4073,16.633865,7.4533057,0.0,0,2.2313521,0.0,0.68606222,106.58785,2.5443039,346.93216,-9.2787008
2290,2290,165.4077,16.703796,7.4932566,0.0,0,2.2008002,0.0,0.69155729,106.43349,2.5110862,347.28564,-9.2784605
2292,2292,165.4081,16.793337,7.517467,0.0,0,2.170248,0.0,0.69564837,106.5137,2.4756596,347.63913,-9.2778997
2294,2294,165.4085,16.8715,7.5549593,0.0,0,2.1396961,0.0,0.6994493,106.69135,2.4443254,347.99261,-9.2805004
2296,2296,165.4089,16.973927,7.5892673,0.0,0,2.109144,0.0,0.70513874,106.69948,2.414187,348.34613,-9.2797403
2298,2298,165.4093,17.086071,7.6162176,0.0,0,2.0785921,0.0,0.7086677,107.04609,2.3795817,348.69962,-9.2794952
2300,2300,165.4097,17.169743,7.6522722,0.0,0,2.0480402,0.0,0.71269053,107.12389,2.3464489,348.88773,-9.2779837
2302,2302,165.4101,17.24939,7.681016,0.0,0,2.0174882,0.0,0.71794134,107.13974,2.3169153,348.5798,-9.2777805
2304,2304,165.4105,17.343323,7.7136211,0.0,0,1.986936,0.0,0.72142357,107.28519,2.2848215,348.27188,-9.27808
2306,2306,165.4109,17.463604,7.7490406,0.0,0,1.9563839,0.0,0.7259832,107.48328,2.2516446,347.96393,-9.2796612
2308,2308,165.4113,17.578779,7.7756872,0.0,0,1.9261372,0.0,0.73111719,107.69545,2.2205627,347.65601,-9.2792654
2310,2310,165.4117,17.674709,7.8138499,0.0,0,1.8970003,0.0,0.73478997,107.84631,2.1871915,347.34808,-9.2779446
2312,2312,165.4121,17.741714,7.8434911,0.0,0,1.8679363,0.0,0.73963952,107.74834,2.1553173,347.04013,-9.277174
2314,2314,165.4125,17.83227,7.8685389,0.0,0,1.8388723,0.0,0.74397266,107.81938,2.1246142,346.73221,-9.2776909
2316,2316,165.4129,17.956621,7.9089303,0.0,0,1.8098083,0.0,0.74772674,108.16208,2.0937326,346.42429,-9.2779913
2318,2318,165.4133,18.074736,7.9346666,0.0,0,1.7807442,0.0,0.75268531,108.39674,2.0621514,346.11633,-9.2798948
2320,2320,165.4137,18.161919,7.9630542,0.0,0,1.7516803,0.0,0.75659305,108.46067,2.0290506,345.80841,-9.2792377
2322,2322,165.4141,18.249298,8.003603,0.0,0,1.7226163,0.0,0.76118958,108.45849,2.0014727,345.50049,-9.2791033
2324,2324,165.4145,18.367952,8.0249643,0.0,0,1.6935523,0.0,0.76601481,108.62315,1.9691725,345.19257,-9.2782202
2326,2326,165.4149,18.499083,8.056284,0.0,0,1.6644882,0.0,0.76961827,109.04588,1.9361271,344.88461,-9.2776051
2328,2328,165.4153,18.615965,8.0964108,0.0,0,1.6354243,0.0,0.77503562,109.12844,1.9096208,344.57669,-9.2771606
2330,2330,165.4157,18.708015,8.1177864,0.0,0,1.6063603,0.0,0.77959257,109.18184,1.8749802,344.26877,-9.2778473
2332,2332,165.4161,18.796696,8.1507187,0.0,0,1.5772963,0.0,0.78282905,109.36993,1.8438096,343.96082,-9.2778978
2334,2334,165.4165,18.909679,8.1848307,0.0,0,1.5491643,0.0,0.78848088,109.37856,1.8151473,343.65289,-9.2789326
2336,2336,165.4169,19.055288,8.2058907,0.0,0,1.5215131,0.0,0.79226643,109.7739,1.7860342,343.34497,-9.2792816
2338,2338,165.4173,19.177864,8.2430096,0.0,0,1.4938651,0.0,0.79612809,110.1289,1.756496,343.03702,-9.2783747
2340,2340,165.4177,19.267319,8.2719173,0.0,0,1.4662172,0.0,0.80189854,109.95888,1.7272335,342.7291,-9.2770987
2342,2342,165.4181,19.378538,8.2977571,0.0,0,1.4385692,0.0,0.80537862,110.22339,1.7000911,342.42117,-9.2785549
2344,2344,165.4185,19.501556,8.3317604,0.0,0,1.4109212,0.0,0.80947608,110.48268,1.6711575,342.11322,-9.2786274
2346,2346,165.4189,19.645674,8.358202,0.0,0,1.3832732,0.0,0.81513751,110.60001,1.640421,341.8053,-9.2785368
2348,2348,165.4193,19.762411,8.3906279,0.0,0,1.3556252,0.0,0.81859738,110.90223,1.6071903,341.49738,-9.2774277
2350,2350,165.4197,19.856592,8.4214811,0.0,0,1.3279773,0.0,0.82335597,110.92751,1.5821984,341.04166,-9.2771606
2352,2352,165.4201,19.968296,8.4442329,0.0,0,1.3003292,0.0,0.82820863,111.01109,1.5521259,340.1427,-9.2769394
2354,2354,165.4205,20.110703,8.4775906,0.0,0,1.2726812,0.0,0.83153015,111.36639,1.5260779,339.24371,-9.2771797
2356,2356,165.4209,20.265377,8.5027113,0.0,0,1.2450333,0.0,0.83641708,111.70888,1.4930333,338.34473,-9.2765617
2358,2358,165.4213,20.384933,8.5282736,0.0,0,1.2176626,0.0,0.84069675,111.90031,1.4667902,337.44574,-9.2770081
2360,2360,165.4217,20.499189,8.5688152,0.0,0,1.1913005,0.0,0.84527475,112.02255,1.4356898,336.54675,-9.2776508
2362,2362,165.4221,20.617365,8.591527,0.0,0,1.1650044,0.0,0.85060173,112.07209,1.4049448,335.64777,-9.2777586
2364,2364,165.4225,20.766886,8.617651,0.0,0,1.1387082,0.0,0.85427994,112.43071,1.3773954,334.74881,-9.2761497
2366,2366,165.4229,20.927986,8.6536694,0.0,0,1.1124123,0.0,0.85872042,112.84074,1.347919,333.84982,-9.2749071
2368,2368,165.4233,21.048704,8.6711721,0.0,0,1.0861163,0.0,0.86348379,112.93254,1.3199006,332.95084,-9.2756767
2370,2370,165.4237,21.150991,8.7011156,0.0,0,1.0598202,0.0,0.86668253,113.16036,1.2893685,332.05185,-9.2763386
2372,2372,165.4241,21.285246,8.7368212,0.0,0,1.0335243,0.0,0.87233412,113.18779,1.2627435,331.15286,-9.2771158
2374,2374,165.4245,21.431015,8.7550993,0.0,0,1.0072283,0.0,0.87680393,113.50254,1.2344732,330.25388,-9.2767887
2376,2376,165.4249,21.590853,8.7892036,0.0,0,0.98093224,0.0,0.88037002,113.8962,1.2104189,329.35489,-9.2769213
2378,2378,165.4253,21.719294,8.8202085,0.0,0,0.95463622,0.0,0.88653755,113.86725,1.1785989,328.45593,-9.2772055
2380,2380,165.4257,21.848587,8.8400087,0.0,0,0.92834032,0.0,0.89021736,114.15043,1.1534948,327.55695,-9.2754707
2382,2382,165.4261,21.986471,8.8706474,0.0,0,0.9020443,0.0,0.89367491,114.44776,1.1258481,326.65796,-9.2752705
2384,2384,165.4265,22.146126,8.8944759,0.0,0,0.87659597,0.0,0.89936006,114.6199,1.0981634,325.75897,-9.2754288
2386,2386,165.4269,22.311333,8.9203968,0.0,0,0.85158527,0.0,0.90264577,115.1263,1.0700638,324.85999,-9.2765827
2388,2388,165.4273,22.455637,8.952342,0.0,0,0.82657719,0.0,0.9072485,115.32363,1.0446866,323.961,-9.2764349
2390,2390,165.4277,22.579788,8.9749737,0.0,0,0.80156928,0.0,0.91281366,115.31157,1.01784,323.06204,-9.2765913
2392,2392,165.4281,22.727814,9.0056009,0.0,0,0.77656126,0.0,0.91601002,115.72751,0.98933923,322.16306,-9.2755585
2394,2394,165.4285,22.883238,9.0312777,0.0,0,0.75155324,0.0,0.92098117,115.90604,0.96536285,321.26407,-9.2755556
2396,2396,165.4289,23.058979,9.0513706,0.0,0,0.72654527,0.0,0.92558503,116.25349,0.9334324,320.36508,-9.2748709
2398,2398,165.4293,23.197336,9.0876017,0.0,0,0.70153725,0.0,0.92928827,116.55865,0.91034567,319.46609,-9.2755556
2400,2400,165.4297,23.337507,9.1102562,0.0,0,0.67652929,0.0,0.93488389,116.57941,0.88031793,318.81259,-9.2757139
2402,2402,165.4301,23.489313,9.1326351,0.0,0,0.65152127,0.0,0.93875074,116.85743,0.85485685,318.89548,-9.2764645
2404,2404,165.4305,23.658497,9.1665392,0.0,0,0.62651324,0.0,0.94265789,117.26665,0.82886022,318.97839,-9.2762775
2406,2406,165.4309,23.831856,9.1829243,0.0,0,0.60150528,0.0,0.94765419,117.50928,0.80218935,319.06128,-9.2750025
2408,2408,165.4313,23.970478,9.2072735,0.0,0,0.57674497,0.0,0.95082313,117.85861,0.77474236,319.14417,-9.2747526
2410,2410,165.4317,24.100798,9.2433519,0.0,0,0.55288589,0.0,0.95634705,117.83395,0.74923885,319.22708,-9.2744713
2412,2412,165.4321,24.24538,9.2580061,0.0,0,0.52908581,0.0,0.96089381,118.02832,0.72237021,319.30997,-9.2744274
2414,2414,165.4325,24.420151,9.2849131,0.0,0,0.5052858,0.0,0.96389478,118.50346,0.69760376,319.39285,-9.274951
2416,2416,165.4329,24.591665,9.3159237,0.0,0,0.48148578,0.0,0.96965212,118.66309,0.67169744,319.47577,-9.2750854
2418,2418,165.4333,24.744427,9.3298216,0.0,0,0.4576858,0.0,0.97328925,118.94865,0.64697325,319.55865,-9.2741594
2420,2420,165.4337,24.882769,9.3598623,0.0,0,0.43388578,0.0,0.97676361,119.20726,0.6250869,319.64154,-9.2743988
2422,2422,165.4341,25.024979,9.3850298,0.0,0,0.4100858,0.0,0.98275793,119.18147,0.59931958,319.72446,-9.2733192
2424,2424,165.4345,25.213224,9.4055901,0.0,0,0.38628578,0.0,0.98623782,119.62302,0.57462943,319.80734,-9.2743034
2426,2426,165.4349,25.385843,9.43328,0.0,0,0.36248577,0.0,0.99000531,120.01779,0.55411249,319.89023,-9.2741766
2427,2427,165.4351,25.462711,9.4398279,0.0,0,0.35058579,0.0,0.99221307,120.12254,0.54053915,319.93167,-9.2747679