File: clean data/testID_0193.csv
level_0,index,Time(sec),Force(kN),Jaw(mm),PowAngle(deg),Power(W),Pram,PTemp,Strain,Stress(MPa),Stroke(mm),TC1(C),wedge(mm)
1773,1773,145.344,0.23975359,0.024506604,0.0,0,9.0337057,0.0,0.0014372726,2.9616592,10.069864,297.0473,-9.3270226
1775,1775,145.3444,2.1631949,0.049269363,0.0,0,8.9751778,0.0,0.0032104224,22.963528,9.9982567,297.33145,-9.3259602
1777,1777,145.3448,5.43332,0.10671946,0.0,0,8.9166498,0.0,0.0067349165,65.958214,9.946373,297.6156,-9.3254757
1779,1779,145.3452,6.3569407,0.16099629,0.0,0,8.8581219,0.0,0.010148327,79.13736,9.8769016,297.89975,-9.3230429
1781,1781,145.3456,7.3267646,0.29482281,0.0,0,8.7995939,0.0,0.019113019,90.571579,9.7908669,298.1839,-9.3217516
1783,1783,145.346,7.7762637,0.3895314,0.0,0,8.7416534,0.0,0.025681039,95.620819,9.693017,298.46805,-9.3208256
1785,1785,145.3464,8.6234789,0.47342542,0.0,0,8.6858492,0.0,0.031301249,105.64162,9.590601,298.7522,-9.3217506
1787,1787,145.3468,9.2731981,0.5559299,0.0,0,8.6301851,0.0,0.037709825,112.67986,9.4965296,299.03635,-9.3203831
1789,1789,145.3472,9.4947176,0.58704484,0.0,0,8.5745211,0.0,0.039309215,116.703,9.4174271,299.3205,-9.3191042
1791,1791,145.3476,9.2330933,0.66460198,0.0,0,8.518857,0.0,0.04482374,112.10602,9.3489609,299.63373,-9.3194036
1793,1793,145.348,9.8928461,0.71991271,0.0,0,8.4631929,0.0,0.04896114,119.2053,9.2790155,300.06314,-9.3193951
1795,1795,145.3484,10.181137,0.78880799,0.0,0,8.4075289,0.0,0.05311083,122.6112,9.2121534,300.49255,-9.3173561
1797,1797,145.3488,10.287655,0.88365239,0.0,0,8.3518648,0.0,0.060197625,123.68961,9.13134,300.922,-9.3183212
1799,1799,145.3492,10.025558,0.9719578,0.0,0,8.2962008,0.0,0.066340491,119.40154,9.0457335,301.35141,-9.3180189
1801,1801,145.3496,10.435887,1.0542206,0.0,0,8.2405367,0.0,0.072135657,123.22778,8.9635935,301.78085,-9.3176537
1803,1803,145.35,10.502933,1.1050317,0.0,0,8.1848736,0.0,0.076477222,123.72523,8.8881111,302.21027,-9.3172808
1805,1805,145.3504,10.89937,1.1494901,0.0,0,8.1292095,0.0,0.079090528,127.8892,8.820384,302.63971,-9.3168688
1807,1807,145.3508,10.616399,1.2202802,0.0,0,8.0735445,0.0,0.084366769,124.61309,8.7612543,303.06912,-9.3167858
1809,1809,145.3512,10.909953,1.2679989,0.0,0,8.0196619,0.0,0.088165604,126.50885,8.7065191,303.49854,-9.3178587
1811,1811,145.3516,11.06525,1.3412689,0.0,0,7.9666953,0.0,0.092832141,128.55331,8.645298,303.92798,-9.3179359
1813,1813,145.352,11.10371,1.4243093,0.0,0,7.9137354,0.0,0.099438041,127.82006,8.5769596,304.35739,-9.3172951
1815,1815,145.3524,11.030787,1.4900789,0.0,0,7.860775,0.0,0.10420182,126.77687,8.5036287,304.78683,-9.3164949
1817,1817,145.3528,11.118885,1.555563,0.0,0,7.8078156,0.0,0.10884453,126.65689,8.4349031,305.21625,-9.3165102
1819,1819,145.3532,11.288161,1.594844,0.0,0,7.7548552,0.0,0.11253296,128.46021,8.3768616,305.64566,-9.3160686
1821,1821,145.3536,11.360223,1.643968,0.0,0,7.7018952,0.0,0.11550308,128.70374,8.3210449,306.0751,-9.3168306
1823,1823,145.354,11.381575,1.7030371,0.0,0,7.6489348,0.0,0.11997525,128.6608,8.2678795,306.50452,-9.3157015
1825,1825,145.3544,11.478761,1.743004,0.0,0,7.5959754,0.0,0.1235049,128.89442,8.2183504,306.93396,-9.3155785
1827,1827,145.3548,11.679995,1.8051536,0.0,0,7.543015,0.0,0.12745959,130.87997,8.1609707,307.36337,-9.3165674
1829,1829,145.3552,11.547763,1.8655978,0.0,0,7.4900556,0.0,0.13244617,128.86534,8.1060581,307.79282,-9.3169985
1831,1831,145.3556,11.659518,1.9213616,0.0,0,7.4370952,0.0,0.13684541,129.41183,8.0446529,308.22223,-9.3178968
1833,1833,145.356,11.626838,1.9834509,0.0,0,7.384666,0.0,0.14109027,128.45531,7.9857917,308.65164,-9.3178196
1835,1835,145.3564,11.87861,2.0162377,0.0,0,7.3341718,0.0,0.14422272,130.70486,7.9320478,309.08109,-9.3169327
1837,1837,145.3568,11.823426,2.0641074,0.0,0,7.2838035,0.0,0.1476527,130.01831,7.8827295,309.5105,-9.3155251
1839,1839,145.3572,11.871933,2.1202328,0.0,0,7.2334356,0.0,0.15171725,129.84763,7.836647,309.93994,-9.3155222
1841,1841,145.3576,11.906272,2.1549711,0.0,0,7.1830673,0.0,0.15511563,129.75162,7.7881603,310.32855,-9.3166237
1843,1843,145.358,12.090897,2.2088089,0.0,0,7.132699,0.0,0.15870912,131.16185,7.7420011,310.48602,-9.3167839
1845,1845,145.3584,12.110036,2.2710731,0.0,0,7.0823312,0.0,0.16351517,131.02631,7.6880083,310.64352,-9.3165836
1847,1847,145.3588,12.068388,2.3186159,0.0,0,7.0319633,0.0,0.16778415,129.907,7.6392426,310.80099,-9.3170528
1849,1849,145.3592,12.115225,2.3682821,0.0,0,6.981595,0.0,0.17125918,129.85204,7.586031,310.95847,-9.316783
1851,1851,145.3596,12.249002,2.4084337,0.0,0,6.9312272,0.0,0.17475545,130.77103,7.5374384,311.11597,-9.3170099
1853,1853,145.36,12.312301,2.4499676,0.0,0,6.8808589,0.0,0.17812887,131.22134,7.4899564,311.27344,-9.3167505
1855,1855,145.3604,12.325645,2.4983768,0.0,0,6.8304915,0.0,0.18156694,130.90034,7.4474783,311.43091,-9.3165035
1857,1857,145.3608,12.374099,2.5444703,0.0,0,6.7801232,0.0,0.18575232,130.79457,7.3995996,311.58841,-9.3168373
1859,1859,145.3612,12.456163,2.5948467,0.0,0,6.7313666,0.0,0.18960464,131.16722,7.3518062,311.74588,-9.3169889
1861,1861,145.3616,12.512208,2.645865,0.0,0,6.6834412,0.0,0.19343486,131.19429,7.3009272,311.90335,-9.3154526
1863,1863,145.362,12.512239,2.6935525,0.0,0,6.6355214,0.0,0.19789134,130.71002,7.2531981,312.06085,-9.3155317
1865,1865,145.3624,12.582638,2.7399468,0.0,0,6.5876012,0.0,0.20119236,130.86295,7.2062216,312.21832,-9.3161087
1867,1867,145.3628,12.669183,2.7822073,0.0,0,6.5396814,0.0,0.20466663,131.35762,7.1540313,312.37579,-9.3162899
1869,1869,145.3632,12.717009,2.8264904,0.0,0,6.4917617,0.0,0.20880525,131.40511,7.1078701,312.53329,-9.3174562
1871,1871,145.3636,12.754585,2.8768353,0.0,0,6.4438419,0.0,0.21213347,131.31834,7.0656967,312.69077,-9.3183002
1873,1873,145.364,12.839679,2.9236052,0.0,0,6.3959212,0.0,0.21641487,131.57251,7.0187941,312.84824,-9.3167543
1875,1875,145.3644,12.913368,2.9678288,0.0,0,6.3480015,0.0,0.22026658,131.84406,6.9712796,313.00574,-9.3156891
1877,1877,145.3648,12.946798,3.0233552,0.0,0,6.3000817,0.0,0.22414957,131.74097,6.9223375,313.16321,-9.3151817
1879,1879,145.3652,12.96089,3.0685415,0.0,0,6.252162,0.0,0.22866571,131.27579,6.8750458,313.32068,-9.3162508
1881,1881,145.3656,13.036553,3.1146309,0.0,0,6.2042418,0.0,0.2323558,131.46565,6.822681,313.47818,-9.3188391
1883,1883,145.366,13.128008,3.1675124,0.0,0,6.1568022,0.0,0.23640338,131.89272,6.7739081,313.63565,-9.3184166
1885,1885,145.3664,13.174656,3.2052605,0.0,0,6.1111116,0.0,0.2405009,131.83659,6.7268634,313.79312,-9.3174171
1887,1887,145.3668,13.21415,3.250315,0.0,0,6.0655355,0.0,0.24363527,131.77992,6.6780601,313.95059,-9.3165302
1889,1889,145.3672,13.256336,3.3046463,0.0,0,6.0199599,0.0,0.24817848,131.60986,6.6322279,314.10809,-9.3165131
1891,1891,145.3676,13.349018,3.3447912,0.0,0,5.9743834,0.0,0.25222558,131.95476,6.5835853,314.25165,-9.3172607
1893,1893,145.368,13.414143,3.3965461,0.0,0,5.9288073,0.0,0.25597116,132.18419,6.5374756,314.26996,-9.3177376
1895,1895,145.3684,13.433565,3.4496274,0.0,0,5.8832316,0.0,0.26103625,131.73648,6.4904795,314.28827,-9.3175774
1897,1897,145.3688,13.49587,3.4917591,0.0,0,5.8376555,0.0,0.26483256,131.78569,6.4408789,314.30658,-9.3172951
1899,1899,145.3692,13.541556,3.5426972,0.0,0,5.792079,0.0,0.26864541,131.72546,6.39573,314.32489,-9.3176432
1901,1901,145.3696,13.621584,3.5876977,0.0,0,5.7465034,0.0,0.2732352,131.89607,6.3473482,314.3432,-9.3163471
1903,1903,145.37,13.685803,3.6313288,0.0,0,5.7009273,0.0,0.27670714,132.10098,6.2991629,314.36151,-9.3173761
1905,1905,145.3704,13.7413,3.6834042,0.0,0,5.6553516,0.0,0.28110197,131.99626,6.2497501,314.37982,-9.3187866
1907,1907,145.3708,13.801561,3.7274289,0.0,0,5.6097751,0.0,0.28578028,131.96951,6.203939,314.39813,-9.318717
1909,1909,145.3712,13.858059,3.7814295,0.0,0,5.5656581,0.0,0.28975168,131.92989,6.1543336,314.41644,-9.3175268
1911,1911,145.3716,13.908143,3.8288994,0.0,0,5.5222936,0.0,0.29419392,131.84131,6.1092243,314.43475,-9.3161516
1913,1913,145.372,13.99117,3.8706756,0.0,0,5.4789333,0.0,0.29852146,132.06656,6.0590858,314.45306,-9.3158016
1915,1915,145.3724,14.046823,3.9237168,0.0,0,5.4355731,0.0,0.30234355,132.17447,6.0125785,314.47137,-9.3171997
1917,1917,145.3728,14.092593,3.9654045,0.0,0,5.3922133,0.0,0.30677399,131.93181,5.9648423,314.48969,-9.3172092
1919,1919,145.3732,14.142672,4.0111828,0.0,0,5.3488531,0.0,0.31096971,131.8914,5.9167738,314.508,-9.3181171
1921,1921,145.3736,14.225495,4.0681291,0.0,0,5.3054934,0.0,0.31534868,131.97388,5.8670812,314.52631,-9.3175039
1923,1923,145.374,14.29936,4.1094913,0.0,0,5.2621331,0.0,0.32017532,132.12915,5.822422,314.54462,-9.316143
1925,1925,145.3744,14.336042,4.1572838,0.0,0,5.2187734,0.0,0.32407779,132.07816,5.771245,314.56293,-9.3169346
1927,1927,145.3748,14.386536,4.2119021,0.0,0,5.1754136,0.0,0.32873371,131.83086,5.7234473,314.58124,-9.3167992
1929,1929,145.3752,14.441667,4.2481561,0.0,0,5.1320534,0.0,0.33303255,131.68736,5.6766958,314.59955,-9.3171597
1931,1931,145.3756,14.529799,4.2975507,0.0,0,5.0886931,0.0,0.3368963,132.06065,5.6286516,314.61786,-9.3164625
1933,1933,145.376,14.606987,4.3505821,0.0,0,5.0457678,0.0,0.34192166,132.05856,5.5799465,314.63617,-9.3170481
1935,1935,145.3764,14.648271,4.3921571,0.0,0,5.0044241,0.0,0.34640005,131.90898,5.5331163,314.65448,-9.3172131
1937,1937,145.3768,14.692,4.4437027,0.0,0,4.9631839,0.0,0.3505393,131.69887,5.4865689,314.67279,-9.3169479
1939,1939,145.3772,14.768898,4.4925065,0.0,0,4.9219437,0.0,0.35574526,131.62364,5.440412,314.6911,-9.3172264
1941,1941,145.3776,14.836315,4.5354552,0.0,0,4.8807039,0.0,0.35983732,131.74251,5.3912096,314.70886,-9.3178301
1943,1943,145.378,14.91242,4.5843105,0.0,0,4.8394637,0.0,0.36392915,131.88954,5.3429565,314.71619,-9.3172102
1945,1945,145.3784,14.950828,4.6275663,0.0,0,4.798224,0.0,0.36899707,131.62898,5.2972326,314.72351,-9.3169775
1947,1947,145.3788,14.998036,4.6712127,0.0,0,4.7569838,0.0,0.3726871,131.53493,5.2546029,314.73083,-9.3178511
1949,1949,145.3792,15.065519,4.7216487,0.0,0,4.7157435,0.0,0.37725222,131.45091,5.2103391,314.73816,-9.3180389
1951,1951,145.3796,15.154464,4.764267,0.0,0,4.6745038,0.0,0.38227165,131.55229,5.1607342,314.74548,-9.3185091
1953,1953,145.38,15.212867,4.8121324,0.0,0,4.6332641,0.0,0.38606998,131.6395,5.1179929,314.75281,-9.3176689
1955,1955,145.3804,15.25835,4.8554368,0.0,0,4.5920234,0.0,0.3907381,131.40454,5.0744209,314.76013,-9.316658
1957,1957,145.3808,15.315836,4.8942819,0.0,0,4.5507836,0.0,0.3950187,131.29576,5.0305748,314.76746,-9.3171387
1959,1959,145.3812,15.355075,4.9448977,0.0,0,4.5108657,0.0,0.39889321,131.1611,4.9874592,314.77478,-9.317277
1961,1961,145.3816,15.453974,4.9853139,0.0,0,4.4716296,0.0,0.40370607,131.24428,4.9416218,314.7821,-9.3181181
1963,1963,145.382,15.517515,5.028121,0.0,0,4.4323974,0.0,0.40798134,131.27036,4.8984962,314.78943,-9.3184042
1965,1965,145.3824,15.555605,5.0817161,0.0,0,4.3931651,0.0,0.41262445,131.05447,4.854022,314.79675,-9.3170624
1967,1967,145.3828,15.610418,5.1180768,0.0,0,4.3539338,0.0,0.41739216,130.84769,4.8081102,314.80411,-9.3170176
1969,1969,145.3832,15.693191,5.1583786,0.0,0,4.3147016,0.0,0.42090851,131.09578,4.7665229,314.81143,-9.315753
1971,1971,145.3836,15.774522,5.2054949,0.0,0,4.2754693,0.0,0.42547438,131.17516,4.7233715,314.81876,-9.3164492
1973,1973,145.384,15.828952,5.2392788,0.0,0,4.236237,0.0,0.42986259,131.11778,4.6778297,314.82608,-9.3176422
1975,1975,145.3844,15.87518,5.286459,0.0,0,4.1970053,0.0,0.43356818,130.95146,4.6347566,314.8334,-9.3166246
1977,1977,145.3848,15.939333,5.33462,0.0,0,4.1577735,0.0,0.43886465,130.76959,4.5956178,314.84073,-9.3176613
1979,1979,145.3852,16.015036,5.3687477,0.0,0,4.1185412,0.0,0.44305357,130.79785,4.5565324,314.84805,-9.3179035
1981,1981,145.3856,16.08017,5.4131761,0.0,0,4.0793095,0.0,0.4467901,130.90479,4.5140295,314.85538,-9.3164291
1983,1983,145.386,16.14459,5.4523506,0.0,0,4.0404716,0.0,0.45162895,130.86134,4.4719272,314.8627,-9.3170662
1985,1985,145.3864,16.203585,5.4883451,0.0,0,4.0030656,0.0,0.45525724,130.79346,4.4294949,314.87003,-9.3170433
1987,1987,145.3868,16.247618,5.5336423,0.0,0,3.9657531,0.0,0.45946077,130.68329,4.3909965,314.87735,-9.3169603
1989,1989,145.3872,16.334494,5.5718594,0.0,0,3.928441,0.0,0.46452716,130.6989,4.3500619,314.88467,-9.3171663
1991,1991,145.3876,16.405025,5.6139054,0.0,0,3.8911293,0.0,0.46821398,130.70767,4.308979,314.892,-9.3179331
1993,1993,145.388,16.475882,5.6549263,0.0,0,3.8538172,0.0,0.47252023,130.72327,4.270721,314.65018,-9.3168535
1995,1995,145.3884,16.531292,5.6878328,0.0,0,3.8165052,0.0,0.47702459,130.59991,4.2323151,314.40839,-9.3161058
1997,1997,145.3888,16.584717,5.7306757,0.0,0,3.7791932,0.0,0.48046708,130.58206,4.191174,314.16656,-9.3165693
1999,1999,145.3892,16.658463,5.7664371,0.0,0,3.7418811,0.0,0.48486909,130.58833,4.1519289,313.92474,-9.3181105
2001,2001,145.3896,16.750996,5.8023262,0.0,0,3.7045693,0.0,0.48917213,130.66193,4.1148467,313.68295,-9.3184214
2003,2003,145.39,16.811079,5.849781,0.0,0,3.6672573,0.0,0.49324718,130.68155,4.0755405,313.44113,-9.3179035
2005,2005,145.3904,16.866816,5.8848929,0.0,0,3.629945,0.0,0.49790129,130.49422,4.0381384,313.19934,-9.3170328
2007,2007,145.3908,16.930468,5.9203911,0.0,0,3.5926332,0.0,0.5017547,130.4733,3.9984529,312.95752,-9.3158865
2009,2009,145.3912,17.014601,5.9667645,0.0,0,3.5565164,0.0,0.50599313,130.51619,3.9613786,312.71573,-9.3156672
2011,2011,145.3916,17.114634,5.9960017,0.0,0,3.5210166,0.0,0.51052797,130.71744,3.9213655,312.47391,-9.3170385
2013,2013,145.392,17.173897,6.0333829,0.0,0,3.4855206,0.0,0.51395792,130.73268,3.8848655,312.23209,-9.3180523
2015,2015,145.3924,17.232119,6.0777678,0.0,0,3.4500246,0.0,0.5186013,130.54344,3.8490939,311.9903,-9.3180294
2017,2017,145.3928,17.293375,6.1078753,0.0,0,3.4145288,0.0,0.52308506,130.46623,3.8101635,311.74847,-9.3176317
2019,2019,145.3932,17.394285,6.1491017,0.0,0,3.3790326,0.0,0.52662319,130.70221,3.7720933,311.50668,-9.3167887
2021,2021,145.3936,17.486065,6.1909914,0.0,0,3.3435366,0.0,0.53185791,130.68094,3.7359831,311.26486,-9.3171568
2023,2023,145.394,17.556419,6.2203774,0.0,0,3.3080406,0.0,0.53563619,130.72002,3.6975396,311.02304,-9.3161325
2025,2025,145.3944,17.607555,6.261065,0.0,0,3.2725446,0.0,0.53919071,130.70546,3.6593621,310.78125,-9.3165541
2027,2027,145.3948,17.682455,6.2968183,0.0,0,3.2370486,0.0,0.54443061,130.54625,3.6223693,310.53943,-9.3172617
2029,2029,145.3952,17.789555,6.330471,0.0,0,3.2015524,0.0,0.54792112,130.87033,3.5864472,310.29764,-9.3177538
2031,2031,145.3956,17.877394,6.3724685,0.0,0,3.1660566,0.0,0.55218399,130.95302,3.5505786,310.05582,-9.3165007
2033,2033,145.396,17.948551,6.4060464,0.0,0,3.1309149,0.0,0.55728519,130.8441,3.5142946,309.814,-9.3158522
2035,2035,145.3964,18.005035,6.4445977,0.0,0,3.0970623,0.0,0.56082565,130.81676,3.4768121,309.5722,-9.3161201
2037,2037,145.3968,18.092823,6.4823842,0.0,0,3.0632942,0.0,0.56521535,130.838,3.4405036,309.33038,-9.3178949
2039,2039,145.3972,18.189034,6.5119381,0.0,0,3.0295262,0.0,0.56974316,130.91808,3.4068601,309.08859,-9.3173075
2041,2041,145.3976,18.294905,6.554543,0.0,0,2.9957583,0.0,0.5733422,131.23346,3.3701153,308.84677,-9.3164701
2043,2043,145.398,18.361483,6.5873356,0.0,0,2.9619904,0.0,0.57798809,131.10117,3.3357401,308.56073,-9.3158627
2045,2045,145.3984,18.43952,6.6184363,0.0,0,2.9282222,0.0,0.5820753,131.0932,3.2972696,308.27234,-9.316412
2047,2047,145.3988,18.520678,6.6640334,0.0,0,2.894454,0.0,0.58616775,131.1631,3.2626123,307.98395,-9.3155651
2049,2049,145.3992,18.630688,6.6940722,0.0,0,2.8606861,0.0,0.59112728,131.26546,3.2267389,307.69556,-9.3168974
2051,2051,145.3996,18.74337,6.7283907,0.0,0,2.8269181,0.0,0.59475464,131.60934,3.1892698,307.4072,-9.316823
2053,2053,145.4,18.804085,6.7722402,0.0,0,2.7931502,0.0,0.59944296,131.50186,3.1560981,307.1188,-9.3166237
2055,2055,145.4004,18.879305,6.798306,0.0,0,2.7593822,0.0,0.60400659,131.2883,3.1186714,306.83041,-9.3167763
2057,2057,145.4008,18.96887,6.8358874,0.0,0,2.7256143,0.0,0.60754991,131.50851,3.0842543,306.54205,-9.3159428
2059,2059,145.4012,19.088196,6.8789921,0.0,0,2.6929309,0.0,0.61278677,131.5985,3.0491943,306.25366,-9.3163242
2061,2061,145.4016,19.19315,6.9048824,0.0,0,2.6608074,0.0,0.61696684,131.71681,3.0101752,305.96527,-9.3170204
2063,2063,145.402,19.25724,6.9432859,0.0,0,2.6286871,0.0,0.62062621,131.76311,2.9794555,305.67691,-9.3171701
2065,2065,145.4024,19.327248,6.9817867,0.0,0,2.5965672,0.0,0.62612981,131.54797,2.9409335,305.38852,-9.3169489
2067,2067,145.4028,19.431858,7.0084767,0.0,0,2.5644472,0.0,0.62969965,131.71472,2.9053483,305.10013,-9.3164711
2069,2069,145.4032,19.565418,7.0469213,0.0,0,2.5323269,0.0,0.633452,132.17018,2.8727241,304.81174,-9.3154945
2071,2071,145.4036,19.656172,7.081665,0.0,0,2.5002072,0.0,0.63890553,132.03761,2.8412702,304.52338,-9.3155117
2073,2073,145.404,19.723272,7.114243,0.0,0,2.4680872,0.0,0.64262414,132.03368,2.8063574,304.23499,-9.3155499
2075,2075,145.4044,19.824282,7.1513481,0.0,0,2.4359672,0.0,0.64688879,132.09427,2.7706683,303.94659,-9.3168087
2077,2077,145.4048,19.930067,7.1814079,0.0,0,2.4038472,0.0,0.65191066,132.14037,2.7369251,303.65823,-9.3170891
2079,2079,145.4052,20.041893,7.2190962,0.0,0,2.3717272,0.0,0.65545946,132.43724,2.7027273,303.36984,-9.3163214
2081,2081,145.4056,20.145311,7.2533813,0.0,0,2.339607,0.0,0.66016567,132.54178,2.6688728,303.08145,-9.3151894
2083,2083,145.406,20.229296,7.2793698,0.0,0,2.3078086,0.0,0.66465163,132.4545,2.6371684,302.79309,-9.3149824
2085,2085,145.4064,20.333986,7.3226376,0.0,0,2.2771802,0.0,0.66861522,132.61685,2.6039364,302.5047,-9.3149242
2087,2087,145.4068,20.446156,7.3512354,0.0,0,2.2466278,0.0,0.6733492,132.68987,2.5676074,302.21631,-9.3154736
2089,2089,145.4072,20.571606,7.3796029,0.0,0,2.2160761,0.0,0.67728925,132.98164,2.5344169,301.92792,-9.315609
2091,2091,145.4076,20.675385,7.422174,0.0,0,2.185524,0.0,0.68145877,133.14502,2.5023851,301.63956,-9.3152504
2093,2093,145.408,20.768246,7.447988,0.0,0,2.1549721,0.0,0.68627036,133.08279,2.4692023,301.45074,-9.3148909
2095,2095,145.4084,20.867472,7.4813676,0.0,0,2.1244199,0.0,0.69024432,133.17859,2.4360161,301.27301,-9.3154192
2097,2097,145.4088,20.9757,7.5246625,0.0,0,2.093868,0.0,0.69536692,133.18361,2.4000983,301.09528,-9.3154268
2099,2099,145.4092,21.10243,7.5470543,0.0,0,2.0633161,0.0,0.69986296,133.37059,2.3704681,300.91754,-9.3154278
2101,2101,145.4096,21.225704,7.5806231,0.0,0,2.0327642,0.0,0.70297807,133.7527,2.3367934,300.73981,-9.3145113
2103,2103,145.41,21.317135,7.6190968,0.0,0,2.002212,0.0,0.7083165,133.62106,2.3054893,300.56207,-9.3145008
2105,2105,145.4104,21.413395,7.6422405,0.0,0,1.9716599,0.0,0.71260029,133.64539,2.2723634,300.38434,-9.3147221
2107,2107,145.4108,21.543163,7.6785464,0.0,0,1.941108,0.0,0.71610296,133.94722,2.2436657,300.2066,-9.3155365
2109,2109,145.4112,21.67869,7.7130146,0.0,0,1.9115354,0.0,0.72188145,134.00525,2.209753,300.02887,-9.3157148
2111,2111,145.4116,21.796314,7.7385297,0.0,0,1.8824683,0.0,0.72541368,134.25693,2.1769972,299.85114,-9.3160028
2113,2113,145.412,21.903557,7.7741399,0.0,0,1.8534042,0.0,0.72924751,134.40216,2.1431112,299.6734,-9.3148117
2115,2115,145.4124,21.99861,7.8032508,0.0,0,1.8243402,0.0,0.73479837,134.30336,2.1154222,299.49567,-9.3139582
2117,2117,145.4128,22.131361,7.8335643,0.0,0,1.7952763,0.0,0.73808074,134.64301,2.0832515,299.31793,-9.3138494
2119,2119,145.4132,22.281683,7.8685641,0.0,0,1.7662122,0.0,0.74263704,134.93954,2.0501218,299.1402,-9.3154478
2121,2121,145.4136,22.393347,7.8956752,0.0,0,1.7371483,0.0,0.74789178,134.92682,2.0214863,298.96246,-9.3159838
2123,2123,145.414,22.501293,7.9324026,0.0,0,1.7080842,0.0,0.75137317,135.11436,1.990379,298.78473,-9.3156271
2125,2125,145.4144,22.613365,7.961946,0.0,0,1.6790203,0.0,0.75623852,135.09175,1.9600463,298.60699,-9.3147554
2127,2127,145.4148,22.755098,7.9857759,0.0,0,1.6499562,0.0,0.76049364,135.34579,1.9266969,298.42926,-9.3140364
2129,2129,145.4152,22.9175,8.0241747,0.0,0,1.6208922,0.0,0.76415682,135.79807,1.8968973,298.25153,-9.3138733
2131,2131,145.4156,23.027344,8.0499239,0.0,0,1.5918282,0.0,0.76916862,135.85605,1.8650078,298.07379,-9.3147554
2133,2133,145.416,23.132385,8.0776749,0.0,0,1.5630547,0.0,0.77328682,135.86005,1.8371865,297.89606,-9.3147621
2135,2135,145.4164,23.254641,8.1181898,0.0,0,1.5353372,0.0,0.77761388,135.96057,1.8055587,297.71832,-9.314455
2137,2137,145.4168,23.401142,8.1394501,0.0,0,1.5076891,0.0,0.78245461,136.15704,1.7757424,297.54059,-9.3140268
2139,2139,145.4172,23.572811,8.1688595,0.0,0,1.4800411,0.0,0.78601199,136.64626,1.7469157,297.36285,-9.3128595
2141,2141,145.4176,23.688055,8.2064037,0.0,0,1.4523932,0.0,0.79091322,136.70239,1.7181417,297.18509,-9.3131514
2143,2143,145.418,23.799572,8.2251654,0.0,0,1.4247452,0.0,0.79533374,136.707,1.6840578,297.00946,-9.3129711
2145,2145,145.4184,23.935671,8.2572708,0.0,0,1.3970972,0.0,0.79849029,137.05678,1.6581321,296.83417,-9.3143988
2147,2147,145.4188,24.08815,8.2927103,0.0,0,1.3694493,0.0,0.8041932,137.09357,1.6287705,296.65887,-9.3152504
2149,2149,145.4192,24.246035,8.3119822,0.0,0,1.3418012,0.0,0.80814856,137.46751,1.602721,296.48361,-9.3134317
2151,2151,145.4196,24.363329,8.3464584,0.0,0,1.3141533,0.0,0.81154835,137.7023,1.5721761,296.30832,-9.3122206
2153,2153,145.42,24.474485,8.3752909,0.0,0,1.2865052,0.0,0.81726414,137.55249,1.5432252,296.13303,-9.3134804
2155,2155,145.4204,24.622849,8.3988171,0.0,0,1.2588573,0.0,0.8205688,137.90645,1.5134023,295.95773,-9.3137369
2157,2157,145.4208,24.787579,8.4318247,0.0,0,1.2312093,0.0,0.82464886,138.22411,1.4856672,295.78247,-9.3135519
2159,2159,145.4212,24.939411,8.4581976,0.0,0,1.2044512,0.0,0.83028603,138.34886,1.4557979,295.60718,-9.3129921
2161,2161,145.4216,25.055084,8.4865465,0.0,0,1.1781523,0.0,0.83349961,138.56335,1.4274461,295.43188,-9.3125572
2163,2163,145.422,25.188692,8.5169382,0.0,0,1.1518563,0.0,0.83776695,138.67322,1.3997306,295.25662,-9.3129196
2165,2165,145.4224,25.337561,8.5379591,0.0,0,1.1255603,0.0,0.84270686,138.78963,1.371701,295.08133,-9.3124275
2167,2167,145.4228,25.5077,8.5715866,0.0,0,1.0992643,0.0,0.84605187,139.25591,1.3459349,294.90604,-9.3124876
2169,2169,145.4232,25.672449,8.5981359,0.0,0,1.0729682,0.0,0.85104465,139.49043,1.3166646,294.73074,-9.3129835
2171,2171,145.4236,25.801983,8.6190929,0.0,0,1.0466722,0.0,0.85534251,139.60959,1.2893368,294.55548,-9.3131847
2173,2173,145.424,25.935637,8.6540937,0.0,0,1.0203762,0.0,0.85877061,139.85318,1.2638302,294.38019,-9.3140564
2175,2175,145.4244,26.098673,8.6741991,0.0,0,0.99408025,0.0,0.86347908,140.0267,1.2343819,294.2049,-9.3130655
2177,2177,145.4248,26.269958,8.698103,0.0,0,0.96778423,0.0,0.86703694,140.43558,1.210158,294.02963,-9.3117647
2179,2179,145.4252,26.425888,8.73699,0.0,0,0.94148827,0.0,0.87179703,140.62106,1.180721,293.85434,-9.3108788
2181,2181,145.4256,26.568556,8.7551193,0.0,0,0.91519231,0.0,0.87684637,140.68506,1.1540357,293.67905,-9.3134422
2183,2183,145.426,26.719593,8.7817354,0.0,0,0.88916039,0.0,0.87992334,141.02483,1.1278228,293.50375,-9.3132763
2185,2185,145.4264,26.87598,8.8146,0.0,0,0.86408937,0.0,0.88482326,141.17181,1.1034971,293.32849,-9.3127918
2187,2187,145.4268,27.059103,8.8278522,0.0,0,0.83908123,0.0,0.88851589,141.5434,1.077028,293.1532,-9.3117056
2189,2189,145.4272,27.221117,8.8558846,0.0,0,0.8140732,0.0,0.89139563,142.0105,1.0503696,292.97791,-9.3120594
2191,2191,145.4276,27.364931,8.8874054,0.0,0,0.78906524,0.0,0.89720339,141.99796,1.0228449,292.80264,-9.3113174
2193,2193,145.428,27.518927,8.9079361,0.0,0,0.76405728,0.0,0.90142292,142.17126,0.9958477,292.7558,-9.3110495
2195,2195,145.4284,27.685335,8.9395638,0.0,0,0.73904926,0.0,0.9050253,142.51328,0.97056556,292.74109,-9.3123331
2197,2197,145.4288,27.876537,8.9634933,0.0,0,0.71404123,0.0,0.91050357,142.66348,0.94641531,292.72638,-9.3126669
2199,2199,145.4292,28.054226,8.9826918,0.0,0,0.68903327,0.0,0.91327971,143.19057,0.91843683,292.71167,-9.3114357
2201,2201,145.4296,28.205866,9.0134106,0.0,0,0.66402531,0.0,0.91723007,143.4258,0.89450377,292.69696,-9.3108177
2203,2203,145.43,28.357117,9.0342321,0.0,0,0.63901722,0.0,0.92278248,143.40744,0.86821729,292.68225,-9.3110514
2205,2205,145.4304,28.529783,9.0591917,0.0,0,0.61400926,0.0,0.92538917,143.90466,0.84170872,292.66754,-9.3105631
2207,2207,145.4308,28.729904,9.0850325,0.0,0,0.58900124,0.0,0.92958379,144.23401,0.8165555,292.65283,-9.3104382
2209,2209,145.4312,28.903879,9.102417,0.0,0,0.56478834,0.0,0.93436098,144.49266,0.79291189,292.63812,-9.3105211
2211,2211,145.4316,29.05571,9.1352921,0.0,0,0.54098582,0.0,0.93762439,144.78729,0.76770544,292.62341,-9.310214
2213,2213,145.432,29.216114,9.1599798,0.0,0,0.51718581,0.0,0.94303679,144.7793,0.74385768,292.6087,-9.3109064
2215,2215,145.4324,29.38574,9.1776142,0.0,0,0.49338579,0.0,0.94690096,145.05341,0.72020429,292.59399,-9.3108187
2217,2217,145.4328,29.600962,9.2093039,0.0,0,0.46958581,0.0,0.95002288,145.66934,0.69833934,292.57928,-9.310545
2219,2219,145.4332,29.784098,9.2224865,0.0,0,0.44578579,0.0,0.95442182,145.95055,0.66964859,292.56458,-9.3112803
2221,2221,145.4336,29.951025,9.2440529,0.0,0,0.42198581,0.0,0.95749533,146.30711,0.64773387,292.54987,-9.3102894
2223,2223,145.434,30.114637,9.2800484,0.0,0,0.39818579,0.0,0.96236622,146.35579,0.62291557,292.53516,-9.3107653
2225,2225,145.4344,30.295799,9.2957506,0.0,0,0.37438577,0.0,0.96760881,146.4883,0.5982393,292.52045,-9.310833
2227,2227,145.4348,30.508949,9.3212032,0.0,0,0.35058579,0.0,0.97056234,147.05893,0.57579321,292.50574,-9.3102312
2229,2229,145.4352,30.690367,9.3500595,0.0,0,0.3267858,0.0,0.97538948,147.24263,0.55369699,292.49103,-9.3095503
2231,2231,145.4356,30.848219,9.3600712,0.0,0,0.30298579,0.0,0.97904408,147.50174,0.53166938,292.47632,-9.3098145