File: clean data/testID_0249.csv
level_0,index,Time(sec),Force(kN),Jaw(mm),PowAngle(deg),Power(W),Pram,PTemp,Strain,Stress(MPa),Stroke(mm),TC1(C),wedge(mm)
2306,2306,178.7215,1.1167189,0.024205079,0.0,0,9.7898636,0.0,0.0017463334,14.045982,9.877718,400.00043,-9.26439
2317,2317,178.7237,1.6916337,0.034674734,0.0,0,9.7568636,0.0,0.0021628803,21.493189,9.8475199,400.00043,-9.2638083
2328,2328,178.7259,1.8155674,0.031723287,0.0,0,9.7238636,0.0,0.0023364455,23.029182,9.8185692,400.00043,-9.2643766
2339,2339,178.7281,2.7710505,0.053561576,0.0,0,9.6908636,0.0,0.0033803966,34.960888,9.7806454,400.00043,-9.2627745
2350,2350,178.7303,3.4146991,0.078160465,0.0,0,9.6578636,0.0,0.0053099338,43.08493,9.7554054,400.01474,-9.2628345
2361,2361,178.7325,3.7627487,0.11434651,0.0,0,9.6248636,0.0,0.0074468143,47.472637,9.7204094,400.12708,-9.2622948
2372,2372,178.7347,4.0132966,0.15025212,0.0,0,9.5918636,0.0,0.010233435,50.552677,9.6818619,400.23944,-9.2617168
2383,2383,178.7369,4.2289982,0.18784258,0.0,0,9.5588636,0.0,0.01235185,53.125523,9.6460505,400.35178,-9.2623968
2394,2394,178.7391,4.3718772,0.22254506,0.0,0,9.5258636,0.0,0.015018783,54.697369,9.6076412,400.46414,-9.2620745
2405,2405,178.7413,4.4305615,0.25974277,0.0,0,9.4928637,0.0,0.017223945,55.434048,9.5681467,400.67111,-9.262207
2416,2416,178.7435,4.2906294,0.29468837,0.0,0,9.4604025,0.0,0.020065922,53.573978,9.5308352,400.9487,-9.2626343
2427,2427,178.7457,4.1851125,0.33339939,0.0,0,9.4282112,0.0,0.022234464,52.13792,9.4976568,401.22626,-9.2620773
2438,2438,178.7479,4.1361599,0.35940424,0.0,0,9.3960209,0.0,0.024458241,51.390995,9.4689331,401.50385,-9.2629499
2449,2449,178.7501,4.1198587,0.39080724,0.0,0,9.3638315,0.0,0.026223173,51.097855,9.4386063,401.77927,-9.2623167
2460,2460,178.7523,4.1309237,0.42085779,0.0,0,9.3316412,0.0,0.028665679,51.052105,9.4060268,401.93787,-9.261282
2471,2471,178.7545,4.223382,0.45158175,0.0,0,9.2994499,0.0,0.030255748,52.167713,9.3769875,402.09647,-9.2612839
2482,2482,178.7567,4.3379369,0.47636911,0.0,0,9.2672586,0.0,0.032404456,53.353477,9.3465662,402.25507,-9.2628851
2493,2493,178.7589,4.4248447,0.50889528,0.0,0,9.2350683,0.0,0.034289919,54.479092,9.3139725,402.41367,-9.2635145
2504,2504,178.7611,4.5277553,0.53893799,0.0,0,9.202879,0.0,0.036758937,55.55069,9.2804823,402.50488,-9.2634697
2515,2515,178.7633,4.5712533,0.57888716,0.0,0,9.1706886,0.0,0.039003886,55.957111,9.2487059,402.5181,-9.2620926
2526,2526,178.7655,4.5615873,0.60664564,0.0,0,9.1384983,0.0,0.041455213,55.649216,9.2145967,402.53131,-9.2628546
2537,2537,178.7677,4.417738,0.64078563,0.0,0,9.106307,0.0,0.043444496,53.782001,9.1773643,402.54453,-9.2626333
2548,2548,178.7699,4.3780713,0.67159635,0.0,0,9.0741167,0.0,0.046069611,53.290257,9.1453266,402.55777,-9.2622833
2559,2559,178.7721,4.5195541,0.70728314,0.0,0,9.0419264,0.0,0.047933515,54.750164,9.1134396,402.62506,-9.2636833
2570,2570,178.7743,4.5895452,0.73274237,0.0,0,9.009737,0.0,0.050210088,55.520329,9.0784216,402.69775,-9.2643356
2581,2581,178.7765,4.6377497,0.76884341,0.0,0,8.9775457,0.0,0.052448608,55.966042,9.0489225,402.77045,-9.2623138
2592,2592,178.7787,4.7158308,0.79671192,0.0,0,8.9453554,0.0,0.054833151,56.818386,9.0131721,402.84314,-9.2618494
2603,2603,178.7809,4.7740612,0.83464152,0.0,0,8.9131651,0.0,0.056881197,57.38427,8.9854832,402.91351,-9.2628088
2614,2614,178.7831,4.8330727,0.85936773,0.0,0,8.8809748,0.0,0.059183814,57.961578,8.9486866,402.97958,-9.2621613
2625,2625,178.7853,4.9170485,0.89486629,0.0,0,8.8487844,0.0,0.06130458,58.767403,8.9137173,403.04568,-9.2615795
2636,2636,178.7875,4.999506,0.92311543,0.0,0,8.8165941,0.0,0.063702665,59.671398,8.8851004,403.11176,-9.2624969
2647,2647,178.7897,5.0541301,0.96295792,0.0,0,8.7844028,0.0,0.065980367,60.267132,8.849925,403.17786,-9.2628622
2658,2658,178.7919,5.0781236,0.98920488,0.0,0,8.7522125,0.0,0.068382181,60.417767,8.8133926,403.19107,-9.2631531
2669,2669,178.7941,5.1343737,1.0235218,0.0,0,8.7214985,0.0,0.070468105,60.90667,8.7840166,403.19107,-9.2620945
2680,2680,178.7963,5.1449327,1.0510992,0.0,0,8.6908836,0.0,0.072880082,61.053505,8.7530041,403.19107,-9.2625618
2691,2691,178.7985,5.1797628,1.0900549,0.0,0,8.6602697,0.0,0.075127825,61.207317,8.7201757,403.19107,-9.2628632
2702,2702,178.8007,5.1940217,1.1144035,0.0,0,8.629653,0.0,0.077291988,61.328316,8.6913071,403.09048,-9.2633018
2713,2713,178.8029,5.2201324,1.1443532,0.0,0,8.5990381,0.0,0.079173513,61.422794,8.6657686,402.68076,-9.2623558
2724,2724,178.8051,5.2929654,1.1729242,0.0,0,8.5684223,0.0,0.081586897,62.090931,8.6297894,402.271,-9.2636051
2735,2735,178.8073,5.3403883,1.2108065,0.0,0,8.5378084,0.0,0.083898112,62.492702,8.5989037,401.86127,-9.2622089
2746,2746,178.8095,5.3836417,1.2367122,0.0,0,8.5071926,0.0,0.086142242,62.907318,8.5694304,401.45151,-9.2614241
2757,2757,178.8117,5.407227,1.2704874,0.0,0,8.4765778,0.0,0.088379465,63.020153,8.5336523,401.09656,-9.2620649
2768,2768,178.8139,5.4319906,1.2991835,0.0,0,8.445962,0.0,0.090701938,63.281212,8.505022,400.76611,-9.2626896
2779,2779,178.8161,5.4405317,1.3364292,0.0,0,8.4153471,0.0,0.093046062,63.078033,8.468029,400.43567,-9.2632399
2790,2790,178.8183,5.4680471,1.3617002,0.0,0,8.3847322,0.0,0.095217817,63.249672,8.4418507,400.10522,-9.261961
2801,2801,178.8205,5.488276,1.3950934,0.0,0,8.3541164,0.0,0.09747342,63.337986,8.4075851,399.83063,-9.2620468
2812,2812,178.8227,5.5146642,1.4235551,0.0,0,8.3235025,0.0,0.099740699,63.446541,8.376956,399.90994,-9.2625608
2823,2823,178.8249,5.5528383,1.4601167,0.0,0,8.2928858,0.0,0.10222131,63.819572,8.3466492,399.98926,-9.2630949
2834,2834,178.8271,5.5947495,1.4854079,0.0,0,8.2622709,0.0,0.10434335,64.190987,8.3139715,400.06857,-9.2628822
2845,2845,178.8293,5.6284552,1.5193709,0.0,0,8.2316561,0.0,0.10669345,64.393867,8.2807398,400.14786,-9.2630367
2856,2856,178.8315,5.6339412,1.5472679,0.0,0,8.2010412,0.0,0.10893299,64.392632,8.2513018,400.22333,-9.2626858
2867,2867,178.8337,5.6487341,1.5843009,0.0,0,8.1704264,0.0,0.11139553,64.384277,8.2200241,400.29602,-9.2617025
2878,2878,178.8359,5.6662917,1.6109829,0.0,0,8.1398106,0.0,0.11364858,64.371315,8.1876984,400.36874,-9.262948
2889,2889,178.8381,5.6666532,1.6427035,0.0,0,8.1091957,0.0,0.1159279,64.23204,8.1563778,400.44144,-9.2642622
2900,2900,178.8403,5.6704316,1.6678488,0.0,0,8.0785799,0.0,0.11785486,64.082001,8.129921,400.50925,-9.2642517
2911,2911,178.8425,5.713706,1.7012491,0.0,0,8.0482779,0.0,0.12029544,64.418419,8.0999575,400.4035,-9.2622795
2922,2922,178.8447,5.7557821,1.7261639,0.0,0,8.0191498,0.0,0.12224281,64.791885,8.0680151,400.29776,-9.2614956
2933,2933,178.8469,5.780489,1.7576003,0.0,0,7.9900212,0.0,0.12463325,65.103844,8.0414658,400.19202,-9.2621851
2944,2944,178.8491,5.8019652,1.7836554,0.0,0,7.9608936,0.0,0.12650867,65.045326,8.0090666,400.08627,-9.2613001
2955,2955,178.8513,5.8043923,1.8191533,0.0,0,7.9317656,0.0,0.12927713,65.003143,7.9802299,399.89618,-9.2613659
2966,2966,178.8535,5.8271008,1.8461962,0.0,0,7.9026375,0.0,0.13125429,65.044472,7.9501891,399.612,-9.2620564
2977,2977,178.8557,5.8298616,1.8755237,0.0,0,7.8735094,0.0,0.13356856,65.013481,7.9211068,399.32782,-9.2624636
2988,2988,178.8579,5.8335471,1.9004279,0.0,0,7.8443813,0.0,0.13537131,64.933662,7.8930411,399.04364,-9.2624102
2999,2999,178.8601,5.86696,1.9340148,0.0,0,7.8152533,0.0,0.13807088,65.01046,7.8660989,398.75946,-9.2617722
3010,3010,178.8623,5.9169612,1.9603643,0.0,0,7.7861252,0.0,0.13991474,65.492889,7.8317184,398.56024,-9.2623215
3021,3021,178.8645,5.9618788,1.9882061,0.0,0,7.7569971,0.0,0.14221963,65.794357,7.8039393,398.36859,-9.2613173
3032,3032,178.8667,5.9921536,2.0175245,0.0,0,7.7278695,0.0,0.14436422,66.097511,7.7741308,398.17694,-9.2613935
3043,3043,178.8689,6.003819,2.0519304,0.0,0,7.6987414,0.0,0.14716491,65.952316,7.7401805,397.98529,-9.2633047
3054,3054,178.8711,5.9937119,2.0788851,0.0,0,7.6696134,0.0,0.14900662,65.744316,7.7122951,397.85132,-9.2625704
3065,3065,178.8733,6.0159616,2.1066546,0.0,0,7.6404853,0.0,0.15134679,65.78804,7.6830177,397.81827,-9.2632065
3076,3076,178.8755,6.0311022,2.1345017,0.0,0,7.6113577,0.0,0.15336418,65.837494,7.6514621,397.78522,-9.2613153
3087,3087,178.8777,6.0477667,2.1667986,0.0,0,7.5822296,0.0,0.15616605,65.892151,7.6223178,397.7522,-9.2618322
3098,3098,178.8799,6.0593333,2.1944246,0.0,0,7.5531015,0.0,0.15794459,65.814751,7.5989676,397.71915,-9.2627783
3109,3109,178.8821,6.0789666,2.2211463,0.0,0,7.523973,0.0,0.1603367,65.888107,7.5711546,397.80908,-9.2621374
3120,3120,178.8843,6.123425,2.2467489,0.0,0,7.4948454,0.0,0.16199878,66.303993,7.5413876,397.92804,-9.2627897
3131,3131,178.8865,6.1601682,2.2762032,0.0,0,7.4657173,0.0,0.16471356,66.500938,7.5143681,398.047,-9.2627449
3142,3142,178.8887,6.1786604,2.3070488,0.0,0,7.4365897,0.0,0.16680722,66.661545,7.4818878,398.16595,-9.2615204
3153,3153,178.8909,6.1959352,2.3332498,0.0,0,7.4074612,0.0,0.1691674,66.634178,7.4542489,398.27988,-9.2615948
3164,3164,178.8931,6.2243938,2.3635275,0.0,0,7.3790221,0.0,0.1712479,66.719429,7.4238482,398.379,-9.2621136
3175,3175,178.8953,6.252202,2.397248,0.0,0,7.3513193,0.0,0.17434126,66.816185,7.3911529,398.47812,-9.2619009
3186,3186,178.8975,6.2800007,2.428504,0.0,0,7.323617,0.0,0.1763546,67.062157,7.3636737,398.57724,-9.2619114
3197,3197,178.8997,6.3162837,2.4557614,0.0,0,7.2959146,0.0,0.17902967,67.191971,7.3318348,398.67639,-9.2616396
3208,3208,178.9019,6.3343225,2.485147,0.0,0,7.2682123,0.0,0.18085682,67.287445,7.3013868,398.77087,-9.2625675
3219,3219,178.9041,6.3317213,2.5148218,0.0,0,7.24051,0.0,0.18370749,67.096947,7.2740192,398.8634,-9.2621193
3230,3230,178.9063,6.3179026,2.5426142,0.0,0,7.2128077,0.0,0.18548453,66.82769,7.2458072,398.95593,-9.2613564
3241,3241,178.9085,6.3237228,2.5650194,0.0,0,7.1851048,0.0,0.18778248,66.727119,7.2198343,399.04846,-9.2618332
3252,3252,178.9107,6.332644,2.5944803,0.0,0,7.157403,0.0,0.18957275,66.664772,7.1896253,399.14099,-9.2615356
3263,3263,178.9129,6.3771639,2.6197999,0.0,0,7.1297007,0.0,0.19224536,66.965378,7.1663961,399.23352,-9.2620354
3274,3274,178.9151,6.3752227,2.6481907,0.0,0,7.1019974,0.0,0.19385208,66.906609,7.1408129,399.32605,-9.2620373
3285,3285,178.9173,6.414072,2.6690586,0.0,0,7.0742955,0.0,0.19615233,67.096199,7.113596,399.41858,-9.2611189
3296,3296,178.9195,6.4573145,2.6997616,0.0,0,7.0465932,0.0,0.19812778,67.452843,7.0800738,399.51111,-9.2621202
3307,3307,178.9217,6.5061498,2.727392,0.0,0,7.0188909,0.0,0.20096955,67.741066,7.0546613,399.56848,-9.2614927
3318,3318,178.9239,6.5203552,2.7604425,0.0,0,6.991188,0.0,0.20291018,67.805763,7.029634,399.60153,-9.2620382
3329,3329,178.9261,6.533802,2.7823768,0.0,0,6.9634857,0.0,0.20545048,67.67067,6.9987636,399.63458,-9.2615633
3340,3340,178.9283,6.530231,2.8121536,0.0,0,6.9357834,0.0,0.20729651,67.591591,6.972671,399.66763,-9.2629776
3351,3351,178.9305,6.5713868,2.8377433,0.0,0,6.9080811,0.0,0.21003689,67.75061,6.9415374,399.69995,-9.2624216
3362,3362,178.9327,6.6045775,2.8719614,0.0,0,6.8803787,0.0,0.21206392,67.993629,6.914021,399.71317,-9.26192
3373,3373,178.9349,6.6433206,2.8943205,0.0,0,6.8526764,0.0,0.21460494,68.25399,6.8851643,399.72638,-9.2622862
3384,3384,178.9371,6.6536169,2.9269812,0.0,0,6.8249741,0.0,0.21675587,68.196098,6.8529282,399.73959,-9.2618475
3395,3395,178.9393,6.6675353,2.9518676,0.0,0,6.7972713,0.0,0.21939014,68.046623,6.8283601,399.75281,-9.2613916
3406,3406,178.9415,6.6827025,2.9826298,0.0,0,6.7695689,0.0,0.22118029,68.221054,6.8023486,399.73737,-9.2616844
3417,3417,178.9437,6.6912794,3.0039115,0.0,0,6.7428842,0.0,0.22376494,68.167389,6.7749481,399.6911,-9.2613907
3428,3428,178.9459,6.722589,3.0345836,0.0,0,6.7165279,0.0,0.22575215,68.29332,6.7425008,399.64484,-9.2616758
3439,3439,178.9481,6.7277517,3.0588763,0.0,0,6.6901722,0.0,0.22844778,68.186714,6.7174969,399.59857,-9.262455
3450,3450,178.9503,6.7411737,3.0919878,0.0,0,6.663816,0.0,0.2303291,68.227509,6.6945419,399.55231,-9.2629347
3461,3461,178.9525,6.7700229,3.1103582,0.0,0,6.6374598,0.0,0.23265576,68.309494,6.6688538,399.14417,-9.2599525
3472,3472,178.9547,6.7910366,3.1393757,0.0,0,6.611104,0.0,0.23456046,68.364426,6.6398511,398.70764,-9.261117
3483,3483,178.9569,6.8241181,3.1621873,0.0,0,6.5847478,0.0,0.23701683,68.571579,6.6126862,398.27112,-9.259758
3494,3494,178.9591,6.8601995,3.1960733,0.0,0,6.558392,0.0,0.2390819,68.80703,6.5867977,397.83459,-9.2617245
3505,3505,178.9613,6.8898139,3.2165983,0.0,0,6.5320363,0.0,0.24166198,68.994301,6.5604868,397.36102,-9.2614746
3516,3516,178.9635,6.9092736,3.2470047,0.0,0,6.5056801,0.0,0.24373583,68.977348,6.532033,396.8251,-9.2621698
3527,3527,178.9657,6.9218631,3.2703791,0.0,0,6.4793239,0.0,0.2462959,68.910721,6.5048666,396.28918,-9.2613258
3538,3538,178.9679,6.9438701,3.307699,0.0,0,6.4529681,0.0,0.24865529,68.887756,6.4773312,395.75327,-9.261302
3549,3549,178.9701,6.9683728,3.3269489,0.0,0,6.4266124,0.0,0.25093386,69.022888,6.4486265,395.21735,-9.2620802
3560,3560,178.9723,6.9910631,3.3570986,0.0,0,6.4002562,0.0,0.25305676,69.051903,6.4213352,394.99527,-9.2614384
3571,3571,178.9745,7.0017366,3.3774369,0.0,0,6.3738999,0.0,0.25536636,69.045341,6.3997912,394.84296,-9.2624578
3582,3582,178.9767,7.0143795,3.4096131,0.0,0,6.3475442,0.0,0.25748199,69.027168,6.3725805,394.69064,-9.2625551
3593,3593,178.9789,7.0344872,3.4277177,0.0,0,6.3211884,0.0,0.25963613,69.152077,6.3434625,394.5383,-9.2620697
3604,3604,178.9811,7.0541115,3.4567509,0.0,0,6.2948327,0.0,0.26171446,69.159966,6.3201523,394.41391,-9.2619591
3615,3615,178.9833,7.0555968,3.477489,0.0,0,6.2684765,0.0,0.26392323,69.034645,6.2956424,394.36755,-9.2621212
3626,3626,178.9855,7.0771279,3.5092094,0.0,0,6.2421203,0.0,0.26618686,69.042191,6.2722702,394.3212,-9.2628727
3637,3637,178.9877,7.1157546,3.5283782,0.0,0,6.2157645,0.0,0.26834622,69.366371,6.2438965,394.27484,-9.2615204
3648,3648,178.9899,7.1765399,3.5580702,0.0,0,6.1894083,0.0,0.27056506,69.663422,6.2187362,394.22849,-9.2619896
3659,3659,178.9921,7.2184453,3.5808969,0.0,0,6.1631007,0.0,0.27293971,69.932838,6.1928234,394.2056,-9.2604504
3670,3670,178.9943,7.2577419,3.6162307,0.0,0,6.1380219,0.0,0.27550176,70.133987,6.162477,394.19235,-9.2605152
3681,3681,178.9965,7.2778983,3.6380098,0.0,0,6.1129556,0.0,0.27785632,70.159111,6.1343427,394.17911,-9.2621918
3692,3692,178.9987,7.2982373,3.6673715,0.0,0,6.0878887,0.0,0.2802321,70.272232,6.1076727,394.16586,-9.2626266
3703,3703,179.0009,7.3122125,3.6919379,0.0,0,6.0628219,0.0,0.28256708,70.20005,6.0800056,394.15363,-9.2620125
3714,3714,179.0031,7.2808838,3.724947,0.0,0,6.037755,0.0,0.28520194,69.761215,6.0547738,394.14703,-9.2605867
3725,3725,179.0053,7.2711082,3.7430654,0.0,0,6.0126886,0.0,0.28710276,69.445992,6.0302486,394.14041,-9.2612181
3736,3736,179.0075,7.2736354,3.7672694,0.0,0,5.9876213,0.0,0.28908283,69.407005,6.0092635,394.13379,-9.2612505
3747,3747,179.0097,7.3243012,3.7866938,0.0,0,5.9625545,0.0,0.29100949,69.71608,5.9855576,394.12717,-9.2621355
3758,3758,179.0119,7.3525872,3.8176899,0.0,0,5.9374876,0.0,0.2935333,69.816971,5.9608064,394.10522,-9.2605324
3769,3769,179.0141,7.3794255,3.8354592,0.0,0,5.9124212,0.0,0.29531756,69.853363,5.9365635,394.07306,-9.260993
3780,3780,179.0163,7.389327,3.8605669,0.0,0,5.8873544,0.0,0.29752305,69.903442,5.9098892,394.04092,-9.2614803
3791,3791,179.0185,7.4281697,3.8813848,0.0,0,5.8622875,0.0,0.29941523,70.198875,5.89218,394.00876,-9.2633238
3802,3802,179.0207,7.4559116,3.9133475,0.0,0,5.8372207,0.0,0.30221853,70.219429,5.8641357,393.97662,-9.2625809
3813,3813,179.0229,7.4768386,3.9346611,0.0,0,5.8121538,0.0,0.30428854,70.255219,5.8359966,393.94962,-9.2614403
3824,3824,179.0251,7.5277796,3.9604168,0.0,0,5.787087,0.0,0.30652964,70.433601,5.8125663,393.92313,-9.2614803
3835,3835,179.0273,7.565011,3.9844213,0.0,0,5.7620201,0.0,0.30861554,70.700569,5.7861323,393.89661,-9.2605915
3846,3846,179.0295,7.6159067,4.0179162,0.0,0,5.7369533,0.0,0.31175452,70.934753,5.758811,393.87012,-9.2600918
3857,3857,179.0317,7.6440091,4.038126,0.0,0,5.7118864,0.0,0.31358263,71.146561,5.7332926,393.81546,-9.260397
3868,3868,179.0339,7.6650009,4.063848,0.0,0,5.6868196,0.0,0.31600729,71.231773,5.7059193,393.7095,-9.2607145
3879,3879,179.0361,7.6826248,4.0893254,0.0,0,5.6617532,0.0,0.31816265,71.176437,5.6793966,393.60355,-9.2605371
3890,3890,179.0383,7.6920977,4.1212783,0.0,0,5.6366854,0.0,0.32135543,71.01252,5.6506562,393.49759,-9.2613087
3901,3901,179.0405,7.6963983,4.1432223,0.0,0,5.6116195,0.0,0.32311964,70.954445,5.6272287,393.3916,-9.2611351
3912,3912,179.0427,7.6944499,4.165874,0.0,0,5.5869198,0.0,0.32545337,70.800789,5.6061697,393.29623,-9.2627354
3923,3923,179.0449,7.7431741,4.1885595,0.0,0,5.5630717,0.0,0.32719919,71.024887,5.5795617,393.20352,-9.2614813
3934,3934,179.0471,7.8048286,4.2171321,0.0,0,5.5392232,0.0,0.3303268,71.36911,5.5510497,393.11081,-9.2625723
3945,3945,179.0493,7.813128,4.2418914,0.0,0,5.5153751,0.0,0.33212203,71.424599,5.5307703,393.0181,-9.2620077
3956,3956,179.0515,7.8309479,4.2644787,0.0,0,5.4915276,0.0,0.33465803,71.359848,5.5071001,392.94324,-9.2620487
3967,3967,179.0537,7.8345981,4.2882776,0.0,0,5.4676795,0.0,0.33650303,71.237869,5.4790263,392.92337,-9.261672
3978,3978,179.0559,7.8544369,4.3150105,0.0,0,5.4438314,0.0,0.33940011,71.213875,5.4595776,392.9035,-9.2611694
3989,3989,179.0581,7.8569031,4.336894,0.0,0,5.4199839,0.0,0.34088013,71.143227,5.4354005,392.88364,-9.2609081
4000,4000,179.0603,7.8845787,4.355711,0.0,0,5.3961358,0.0,0.34317759,71.264595,5.4085107,392.86377,-9.2613201
4011,4011,179.0625,7.9012871,4.3814325,0.0,0,5.3722878,0.0,0.34511885,71.182388,5.3879275,392.80273,-9.2613411
4022,4022,179.0647,7.935091,4.4061584,0.0,0,5.3484397,0.0,0.34809425,71.228409,5.3657789,392.72327,-9.2621183
4033,4033,179.0669,7.9852228,4.4314847,0.0,0,5.3245916,0.0,0.34979513,71.690552,5.3461065,392.64377,-9.2606487
4044,4044,179.0691,8.0344934,4.4516492,0.0,0,5.3007436,0.0,0.35233119,72.011009,5.3179011,392.5643,-9.2604246
4055,4055,179.0713,8.0579224,4.4755244,0.0,0,5.276896,0.0,0.35401917,72.021469,5.294044,392.48572,-9.2608185
4066,4066,179.0735,8.0784798,4.5010986,0.0,0,5.2530475,0.0,0.35711831,71.975601,5.2686176,392.41287,-9.2605686
4077,4077,179.0757,8.0833588,4.5289664,0.0,0,5.2291994,0.0,0.35905856,71.908363,5.2440457,392.34003,-9.2619925
4088,4088,179.0779,8.123992,4.5495214,0.0,0,5.2053518,0.0,0.36168417,72.045586,5.2204657,392.26718,-9.2613287
4099,4099,179.0801,8.1806459,4.5776153,0.0,0,5.1815038,0.0,0.36367232,72.297714,5.194416,392.19434,-9.2608013
4110,4110,179.0823,8.2106266,4.6028185,0.0,0,5.1576557,0.0,0.36687642,72.404312,5.1666107,392.10608,-9.2620134
4121,4121,179.0845,8.243825,4.6319318,0.0,0,5.1338077,0.0,0.36880431,72.568817,5.1417236,392.00674,-9.2621498
4132,4132,179.0867,8.2846889,4.6513643,0.0,0,5.1099596,0.0,0.37149292,72.712997,5.1200891,391.90741,-9.2611752
4143,4143,179.0889,8.2749004,4.677443,0.0,0,5.0861115,0.0,0.37345535,72.509369,5.0944233,391.80804,-9.2614632
4154,4154,179.0911,8.2637882,4.6990561,0.0,0,5.062264,0.0,0.3762396,72.348373,5.0715613,391.70728,-9.2611876
4165,4165,179.0933,8.2686234,4.7249022,0.0,0,5.0390849,0.0,0.37782031,72.145714,5.0470948,391.55496,-9.2610788
4176,4176,179.0955,8.2658587,4.7411966,0.0,0,5.0164027,0.0,0.38037348,71.88044,5.0282078,391.40262,-9.2597771
4187,4187,179.0977,8.2733831,4.765286,0.0,0,4.993721,0.0,0.38185757,71.917793,5.0053844,391.25031,-9.2611275
4198,4198,179.0999,8.3123541,4.7842259,0.0,0,4.9710388,0.0,0.38445255,72.030922,4.9824023,391.09799,-9.2623672
4209,4209,179.1021,8.375144,4.8132505,0.0,0,4.9483566,0.0,0.3862949,72.505905,4.962317,390.96759,-9.2621899
4220,4220,179.1043,8.4294186,4.83002,0.0,0,4.9256749,0.0,0.38892925,72.683891,4.9407201,390.8616,-9.2610912
4231,4231,179.1065,8.4893761,4.8569007,0.0,0,4.9029927,0.0,0.39093235,73.014984,4.9146643,390.75565,-9.2608929
4242,4242,179.1087,8.4997091,4.877594,0.0,0,4.880311,0.0,0.39366463,73.017662,4.89047,390.64966,-9.2621593
4253,4253,179.1109,8.5085697,4.9075956,0.0,0,4.8576288,0.0,0.39566103,72.90731,4.8688331,390.5437,-9.2615547
4264,4264,179.1131,8.5315952,4.9240246,0.0,0,4.8349466,0.0,0.39831364,72.924385,4.8426752,390.46207,-9.2626371
4275,4275,179.1153,8.5447731,4.9505515,0.0,0,4.8122649,0.0,0.40016633,72.944473,4.8186569,390.3826,-9.2612619
4286,4286,179.1175,8.5478258,4.9693317,0.0,0,4.7895827,0.0,0.40288913,72.746605,4.7972221,390.30313,-9.2601719
4297,4297,179.1197,8.5684862,4.9994798,0.0,0,4.766901,0.0,0.40485913,72.729134,4.776298,390.22366,-9.2606649
4308,4308,179.1219,8.6212444,5.0134721,0.0,0,4.7442188,0.0,0.40715018,73.019867,4.7533259,390.12012,-9.25951
4319,4319,179.1241,8.6618013,5.0398068,0.0,0,4.7215366,0.0,0.40908951,73.19915,4.7296324,389.9744,-9.2611074
4330,4330,179.1263,8.6870995,5.060051,0.0,0,4.6988549,0.0,0.41192386,73.222237,4.7075739,389.8287,-9.2590561
4341,4341,179.1285,8.7022114,5.0896659,0.0,0,4.6761732,0.0,0.41382822,73.307549,4.684258,389.68298,-9.2610083
4352,4352,179.1307,8.7340555,5.1032104,0.0,0,4.6534905,0.0,0.41622442,73.351891,4.6635056,389.53729,-9.2613106
4363,4363,179.1329,8.7580271,5.1282582,0.0,0,4.6308088,0.0,0.41801906,73.431763,4.6424303,389.38623,-9.2607479
4374,4374,179.1351,8.7984343,5.1493831,0.0,0,4.6081266,0.0,0.4209339,73.503654,4.618928,389.23392,-9.2612104
4385,4385,179.1373,8.8217506,5.1808782,0.0,0,4.5854449,0.0,0.42313772,73.591461,4.5950193,389.0816,-9.2607231
4396,4396,179.1395,8.8656645,5.1960502,0.0,0,4.5627627,0.0,0.42567801,73.712349,4.5701551,388.92929,-9.2614212
4407,4407,179.1417,8.9043798,5.2226086,0.0,0,4.5400805,0.0,0.42774436,73.932312,4.5488214,388.78876,-9.2616644
4418,4418,179.1439,8.9190254,5.2410436,0.0,0,4.5183334,0.0,0.43027875,73.871109,4.5262876,388.6828,-9.260849
4429,4429,179.1461,8.9349203,5.2718778,0.0,0,4.4967556,0.0,0.43254891,73.86937,4.5029688,388.57684,-9.2614336
4440,4440,179.1483,8.9511518,5.2859383,0.0,0,4.4751782,0.0,0.43475714,73.780777,4.4783902,388.47089,-9.2619209
4451,4451,179.1505,8.9699621,5.3129616,0.0,0,4.4536009,0.0,0.43697721,73.753761,4.4587779,388.36493,-9.2610025
4462,4462,179.1527,8.9902096,5.3291874,0.0,0,4.432023,0.0,0.43925363,73.760269,4.4383349,388.24042,-9.2612152
4473,4473,179.1549,9.0064974,5.3591323,0.0,0,4.4104452,0.0,0.44154069,73.700218,4.417726,388.10797,-9.2602291
4484,4484,179.1571,9.0226374,5.3715796,0.0,0,4.3888679,0.0,0.44357461,73.676643,4.3942833,387.97549,-9.2612858
4495,4495,179.1593,9.054389,5.3959126,0.0,0,4.36729,0.0,0.44557303,73.842751,4.3723102,387.84305,-9.2603655
4506,4506,179.1615,9.1306896,5.4150209,0.0,0,4.3457127,0.0,0.44803622,74.225906,4.3531156,387.69904,-9.2594805
4517,4517,179.1637,9.1744747,5.4444566,0.0,0,4.3241353,0.0,0.45050308,74.450195,4.3305669,387.48709,-9.2609053
4528,4528,179.1659,9.212265,5.4607706,0.0,0,4.3025579,0.0,0.45283875,74.553917,4.3102479,387.27515,-9.2606926
4539,4539,179.1681,9.2148466,5.4874587,0.0,0,4.2809801,0.0,0.45522663,74.43158,4.2839866,387.06323,-9.2603407
4550,4550,179.1703,9.2230511,5.5063562,0.0,0,4.2594023,0.0,0.45755726,74.300888,4.2639685,386.85129,-9.2602758
4561,4561,179.1725,9.2286558,5.5335412,0.0,0,4.2378249,0.0,0.45985061,74.202065,4.2437501,386.65109,-9.2614365
4572,4572,179.1747,9.2539368,5.5468268,0.0,0,4.2162471,0.0,0.46183103,74.228714,4.2206593,386.45905,-9.2608929
4583,4583,179.1769,9.3035822,5.5719948,0.0,0,4.1946697,0.0,0.46420729,74.438843,4.2020121,386.267,-9.2613716
4594,4594,179.1791,9.3540316,5.5901613,0.0,0,4.1730919,0.0,0.46629992,74.666,4.18086,386.07492,-9.2603197
4605,4605,179.1813,9.3902035,5.6207032,0.0,0,4.1515145,0.0,0.46922261,74.756958,4.16114,385.88745,-9.2592449
4616,4616,179.1835,9.4130812,5.6356854,0.0,0,4.1299367,0.0,0.47120646,74.792641,4.1364403,385.82123,-9.2592669
4627,4627,179.1857,9.433033,5.6605558,0.0,0,4.1083593,0.0,0.47368687,74.85997,4.1145196,385.755,-9.2599115
4638,4638,179.1879,9.4750252,5.6783743,0.0,0,4.0867815,0.0,0.47575906,74.989922,4.0922356,385.68878,-9.2598486
4649,4649,179.1901,9.5201616,5.7075658,0.0,0,4.0652041,0.0,0.47864208,75.037079,4.0701332,385.62256,-9.2599697
4660,4660,179.1923,9.5633125,5.726378,0.0,0,4.0437527,0.0,0.48086593,75.242966,4.0463347,385.54993,-9.2612915
4671,4671,179.1945,9.5972605,5.7522268,0.0,0,4.0232306,0.0,0.48370057,75.290291,4.0198498,385.47046,-9.2608376
4682,4682,179.1967,9.6145945,5.7685857,0.0,0,4.0027089,0.0,0.48534238,75.2864,4.0023704,385.39099,-9.2600241
4693,4693,179.1989,9.6330853,5.7954655,0.0,0,3.9821873,0.0,0.48825991,75.249763,3.9782424,385.31152,-9.2610397
4704,4704,179.2011,9.6221609,5.8124113,0.0,0,3.9616656,0.0,0.49012282,75.088959,3.9598386,385.23203,-9.2603874
4715,4715,179.2033,9.6278677,5.8322845,0.0,0,3.9411442,0.0,0.49243736,74.930237,3.9407804,385.11572,-9.2612829
4726,4726,179.2055,9.6238146,5.848711,0.0,0,3.9206226,0.0,0.49401823,74.788933,3.9190979,384.99652,-9.2593651
4737,4737,179.2077,9.6374722,5.8737397,0.0,0,3.9001009,0.0,0.49699757,74.649399,3.9046078,384.87729,-9.2597094
4748,4748,179.2099,9.676506,5.8890576,0.0,0,3.8795795,0.0,0.49837139,74.800957,3.8809292,384.75809,-9.2613516
4759,4759,179.2121,9.7246017,5.9065876,0.0,0,3.8590579,0.0,0.50063938,75.046371,3.865242,384.65369,-9.2612972
4770,4770,179.2143,9.8146086,5.9275007,0.0,0,3.8385363,0.0,0.50259012,75.544106,3.8457499,384.57422,-9.2611923
4781,4781,179.2165,9.8470001,5.9539695,0.0,0,3.8180146,0.0,0.50590366,75.547562,3.8197782,384.49475,-9.2604904
4792,4792,179.2187,9.8828468,5.973496,0.0,0,3.797493,0.0,0.50764412,75.724899,3.7990344,384.41528,-9.260849
4803,4803,179.2209,9.9143858,5.9932771,0.0,0,3.7769713,0.0,0.51023799,75.770912,3.7805822,384.33582,-9.2609024
4814,4814,179.2231,9.9319839,6.0135965,0.0,0,3.7564499,0.0,0.5120002,75.789154,3.7589605,384.23465,-9.2602673
4825,4825,179.2253,9.9393749,6.0389781,0.0,0,3.7359283,0.0,0.5154255,75.533585,3.7397029,384.12869,-9.2605114
4836,4836,179.2275,9.9720554,6.0581179,0.0,0,3.7154067,0.0,0.51687896,75.736496,3.7190166,384.02274,-9.260561
4847,4847,179.2297,10.023465,6.0754609,0.0,0,3.694885,0.0,0.51951224,75.923424,3.6989899,383.91678,-9.2596169
4858,4858,179.2319,10.102108,6.0983658,0.0,0,3.6743636,0.0,0.52142507,76.358559,3.6751859,383.80209,-9.2603817
4869,4869,179.2341,10.140166,6.1234565,0.0,0,3.6538417,0.0,0.52495688,76.363602,3.6544254,383.66299,-9.2600832
4880,4880,179.2363,10.152781,6.1460791,0.0,0,3.6333201,0.0,0.52669436,76.371696,3.6314199,383.52393,-9.2610388
4891,4891,179.2385,10.177747,6.1634808,0.0,0,3.6127987,0.0,0.52934492,76.303307,3.6122012,383.38486,-9.2606611
4902,4902,179.2407,10.190392,6.1841254,0.0,0,3.5922771,0.0,0.53103364,76.318779,3.5892494,383.24579,-9.260232
4913,4913,179.2429,10.190083,6.2058697,0.0,0,3.5721471,0.0,0.53433812,76.043808,3.5703011,383.12079,-9.2589521
4924,4924,179.2451,10.18982,6.2259774,0.0,0,3.5526242,0.0,0.5357784,75.888313,3.5535953,383.00159,-9.2611818
4935,4935,179.2473,10.200664,6.2409706,0.0,0,3.5331016,0.0,0.53826219,75.843849,3.5329795,382.88235,-9.2594366
4946,4946,179.2495,10.251649,6.2610373,0.0,0,3.5135787,0.0,0.53970873,76.012268,3.5132234,382.76315,-9.260623
4957,4957,179.2517,10.299546,6.2791615,0.0,0,3.4940557,0.0,0.54283667,76.175247,3.492871,382.64496,-9.2597437
4968,4968,179.2539,10.346275,6.3039389,0.0,0,3.4745328,0.0,0.54469228,76.409386,3.4730692,382.53238,-9.2598772
4979,4979,179.2561,10.350126,6.3200259,0.0,0,3.4550104,0.0,0.54749066,76.242279,3.4568777,382.4198,-9.2595682
4990,4990,179.2583,10.396779,6.3411446,0.0,0,3.4354873,0.0,0.54891831,76.500221,3.4348922,382.30722,-9.2594366
5001,5001,179.2605,10.429456,6.3574729,0.0,0,3.4159648,0.0,0.5518322,76.480522,3.4141726,382.19464,-9.2592907
5012,5012,179.2627,10.427026,6.3804393,0.0,0,3.3964417,0.0,0.55345404,76.281837,3.3986232,382.05811,-9.2594118
5023,5023,179.2649,10.440366,6.3956294,0.0,0,3.376919,0.0,0.55638146,76.2481,3.377357,381.90558,-9.2604961
5034,5034,179.2671,10.494865,6.4186792,0.0,0,3.3573964,0.0,0.55792475,76.426743,3.3604813,381.75308,-9.2608862
5045,5045,179.2693,10.568377,6.4357944,0.0,0,3.3378732,0.0,0.56102079,76.727051,3.3407266,381.60059,-9.2609367
5056,5056,179.2715,10.61732,6.4603543,0.0,0,3.3183508,0.0,0.56267411,77.021912,3.3205423,381.44778,-9.2599001
5067,5067,179.2737,10.670052,6.4744601,0.0,0,3.2988276,0.0,0.56551629,77.136887,3.2978873,381.28851,-9.259305
5078,5078,179.2759,10.694431,6.4988303,0.0,0,3.2793047,0.0,0.5671981,77.192024,3.2757947,381.12924,-9.2598886
5089,5089,179.2781,10.710939,6.5158739,0.0,0,3.2597823,0.0,0.57038015,77.119751,3.258152,380.97,-9.2603188
5100,5100,179.2803,10.712983,6.5431123,0.0,0,3.2402592,0.0,0.57230449,76.993179,3.2402434,380.81073,-9.2606001
5111,5111,179.2825,10.7149,6.5550051,0.0,0,3.2207365,0.0,0.57493526,76.798332,3.219105,380.6156,-9.2607346
5122,5122,179.2847,10.724072,6.5766306,0.0,0,3.2012138,0.0,0.57650822,76.722206,3.2015138,380.38327,-9.2604265
5133,5133,179.2869,10.794624,6.5916505,0.0,0,3.1816909,0.0,0.57944751,76.963051,3.1830249,380.15094,-9.2610579
5144,5144,179.2891,10.861724,6.6191015,0.0,0,3.1621683,0.0,0.58132839,77.360985,3.1644368,379.91861,-9.2598238
5155,5155,179.2913,10.908864,6.6315308,0.0,0,3.1426454,0.0,0.58419305,77.436302,3.1456835,379.68628,-9.2603807
5166,5166,179.2935,10.954851,6.6567154,0.0,0,3.1237545,0.0,0.58607286,77.65641,3.1274467,379.39804,-9.2611685
5177,5177,179.2957,10.979681,6.6730466,0.0,0,3.1051819,0.0,0.58920926,77.609833,3.1068995,379.10599,-9.260498
5188,5188,179.2979,11.017173,6.7000122,0.0,0,3.0866094,0.0,0.59106839,77.684357,3.0876606,378.8139,-9.2599363
5199,5199,179.3001,11.01024,6.7123604,0.0,0,3.0680368,0.0,0.59375858,77.388718,3.0669005,378.52185,-9.2604427
5210,5210,179.3023,11.01114,6.7345371,0.0,0,3.0494645,0.0,0.59556717,77.236511,3.0478408,378.28049,-9.2599878
5221,5221,179.3045,11.033358,6.748486,0.0,0,3.0308924,0.0,0.59827107,77.223129,3.0318031,378.12119,-9.2606096
5232,5232,179.3067,11.090516,6.7747698,0.0,0,3.0123198,0.0,0.59999317,77.475601,3.0113354,377.96188,-9.2610817
5243,5243,179.3089,11.13552,6.7851143,0.0,0,2.9937477,0.0,0.60264379,77.600075,2.9901695,377.80258,-9.2599115
5254,5254,179.3111,11.172358,6.8083596,0.0,0,2.9751751,0.0,0.60443759,77.757195,2.9759765,377.64331,-9.2605429
5265,5265,179.3133,11.199608,6.8230562,0.0,0,2.9566026,0.0,0.60729766,77.67437,2.955425,377.51144,-9.2605762
5276,5276,179.3155,11.22543,6.8501611,0.0,0,2.93803,0.0,0.60924023,77.739616,2.9396002,377.38535,-9.2601976
5287,5287,179.3177,11.255239,6.8599381,0.0,0,2.9194577,0.0,0.61166602,77.73513,2.9188673,377.25922,-9.2610464
5298,5298,179.3199,11.282411,6.884059,0.0,0,2.9008856,0.0,0.61374354,77.753372,2.9010274,377.13312,-9.261301
5309,5309,179.3221,11.324135,6.8978424,0.0,0,2.882313,0.0,0.61640728,77.817398,2.8838947,376.91104,-9.2608423
5320,5320,179.3243,11.38193,6.9246783,0.0,0,2.8637407,0.0,0.61855572,78.048279,2.8637631,376.43314,-9.261611
5331,5331,179.3265,11.446628,6.9359679,0.0,0,2.8451684,0.0,0.62110865,78.319221,2.8420978,375.9552,-9.2606668
5342,5342,179.3287,11.481386,6.9607711,0.0,0,2.8265958,0.0,0.62335223,78.369736,2.820056,375.47729,-9.260273
5353,5353,179.3309,11.493287,6.9747806,0.0,0,2.8080232,0.0,0.62583405,78.234093,2.80405,374.99936,-9.2598867
5364,5364,179.3331,11.506786,7.0026317,0.0,0,2.7894509,0.0,0.6282559,78.183136,2.7905169,374.46426,-9.2606506
5375,5375,179.3353,11.529046,7.0117354,0.0,0,2.7708786,0.0,0.63034099,78.144737,2.7681448,373.90668,-9.2609148
5386,5386,179.3375,11.554239,7.034307,0.0,0,2.7523062,0.0,0.63256037,78.127785,2.7496798,373.34909,-9.2613611
5397,5397,179.3397,11.581112,7.0477495,0.0,0,2.7337339,0.0,0.6348877,78.127754,2.736238,372.79153,-9.2605343
5408,5408,179.3419,11.644012,7.0759625,0.0,0,2.7151613,0.0,0.63762116,78.290833,2.7146914,372.24481,-9.2598515
5419,5419,179.3441,11.689895,7.0859904,0.0,0,2.6974392,0.0,0.63967675,78.510468,2.6975596,371.75363,-9.2602043
5430,5430,179.3463,11.779146,7.108954,0.0,0,2.6797731,0.0,0.6420061,78.863182,2.6758344,371.26245,-9.2612429
5441,5441,179.3485,11.803772,7.125443,0.0,0,2.662107,0.0,0.64451796,78.883072,2.6609025,370.77124,-9.260663
5452,5452,179.3507,11.827177,7.1533585,0.0,0,2.6444409,0.0,0.64760947,78.780205,2.6406393,370.28006,-9.2607861
5463,5463,179.3529,11.849593,7.1626415,0.0,0,2.626775,0.0,0.64913672,78.849739,2.6207719,369.84546,-9.2605381
5474,5474,179.3551,11.863589,7.183135,0.0,0,2.6091089,0.0,0.65143031,78.798622,2.6025362,369.4472,-9.2606544
5485,5485,179.3573,11.87087,7.1961222,0.0,0,2.5914431,0.0,0.65347904,78.637802,2.5864279,369.04895,-9.261488
5496,5496,179.3595,11.902246,7.2247605,0.0,0,2.573777,0.0,0.65677035,78.535957,2.5680544,368.6507,-9.262001
5507,5507,179.3617,11.94959,7.2362852,0.0,0,2.5561111,0.0,0.65862042,78.699379,2.5468743,368.27124,-9.2605457
5518,5518,179.3639,11.993043,7.2550025,0.0,0,2.538445,0.0,0.66098529,78.838745,2.5343473,368.21814,-9.2605391
5529,5529,179.3661,11.995518,7.2671409,0.0,0,2.5207791,0.0,0.66260421,78.776169,2.515837,368.16504,-9.2593784
5540,5540,179.3683,12.040259,7.2921662,0.0,0,2.503113,0.0,0.66561162,78.791321,2.4973555,368.11194,-9.2600012
5551,5551,179.3705,12.052178,7.3044333,0.0,0,2.4854469,0.0,0.66745156,78.757957,2.4801221,368.05884,-9.2606363
5562,5562,179.3727,12.082637,7.3239574,0.0,0,2.4677811,0.0,0.66997558,78.730385,2.4637325,368.04889,-9.2613325
5573,5573,179.3749,12.132906,7.3360724,0.0,0,2.450115,0.0,0.67138648,78.909317,2.4468033,368.08206,-9.262022
5584,5584,179.3771,12.169611,7.3604817,0.0,0,2.4324489,0.0,0.67463356,78.883614,2.4306016,368.11523,-9.2613125
5595,5595,179.3793,12.21859,7.3740025,0.0,0,2.414783,0.0,0.67619395,79.127083,2.4104903,368.14841,-9.2610788
5606,5606,179.3815,12.291761,7.3934498,0.0,0,2.3971169,0.0,0.67913628,79.327827,2.3967481,368.18161,-9.2600737
5617,5617,179.3837,12.343978,7.407948,0.0,0,2.379451,0.0,0.68085951,79.528847,2.3772609,368.16458,-9.2590218
5628,5628,179.3859,12.387217,7.4310846,0.0,0,2.3617849,0.0,0.68410546,79.568115,2.3590062,368.14468,-9.2603388
5639,5639,179.3881,12.412622,7.4464822,0.0,0,2.3441188,0.0,0.68577564,79.64016,2.3409476,368.12479,-9.2606144
5650,5650,179.3903,12.453249,7.4660826,0.0,0,2.326453,0.0,0.68882763,79.617958,2.3211439,368.10486,-9.2604218
5661,5661,179.3925,12.487679,7.4827805,0.0,0,2.3089681,0.0,0.69042999,79.743683,2.30545,368.07718,-9.2612009
5672,5672,179.3947,12.536237,7.5049968,0.0,0,2.2921643,0.0,0.69414514,79.725685,2.2847795,368.03735,-9.2600012
5683,5683,179.3969,12.566702,7.5210824,0.0,0,2.2753608,0.0,0.6955806,79.75856,2.2683458,367.99753,-9.2601414
5694,5694,179.3991,12.588342,7.5391455,0.0,0,2.2585571,0.0,0.69867545,79.726791,2.249505,367.9577,-9.2597055
5705,5705,179.4013,12.616654,7.5565367,0.0,0,2.2417536,0.0,0.70037204,79.748505,2.2315016,367.91788,-9.2597532
5716,5716,179.4035,12.616769,7.5740767,0.0,0,2.2249501,0.0,0.70345652,79.455864,2.2142539,367.77255,-9.2597408
5727,5727,179.4057,12.627101,7.589314,0.0,0,2.2081466,0.0,0.70460081,79.457344,2.1997945,367.60663,-9.2604332
5738,5738,179.4079,12.639028,7.6020784,0.0,0,2.1913428,0.0,0.70726043,79.352707,2.1875057,367.44067,-9.2597399
5749,5749,179.4101,12.672627,7.6197805,0.0,0,2.1745393,0.0,0.70873904,79.377075,2.1666172,367.27472,-9.2597742
5760,5760,179.4123,12.697308,7.6379457,0.0,0,2.1577358,0.0,0.71220827,79.313293,2.1536779,367.05066,-9.2612839
5771,5771,179.4145,12.74762,7.6541548,0.0,0,2.1409321,0.0,0.71324652,79.531364,2.137197,366.6785,-9.2611265
5782,5782,179.4167,12.792067,7.6653695,0.0,0,2.1241283,0.0,0.71591711,79.584427,2.1215539,366.3063,-9.2605457
5793,5793,179.4189,12.848875,7.6838536,0.0,0,2.1073248,0.0,0.71751386,79.816315,2.1048536,365.93414,-9.2598677
5804,5804,179.4211,12.925239,7.701067,0.0,0,2.0905213,0.0,0.72082937,80.020523,2.0866194,365.56195,-9.259161
5815,5815,179.4233,12.971906,7.7204022,0.0,0,2.0737178,0.0,0.72235215,80.219536,2.0712824,365.07333,-9.2596521
5826,5826,179.4255,13.013456,7.7361832,0.0,0,2.0569141,0.0,0.72555977,80.212318,2.0548055,364.54108,-9.2598352
5837,5837,179.4277,13.059688,7.7547302,0.0,0,2.0401106,0.0,0.72707057,80.39267,2.0347598,364.00879,-9.2609024
5848,5848,179.4299,13.096174,7.7712145,0.0,0,2.0233071,0.0,0.73063141,80.310768,2.0191422,363.47653,-9.2601299
5859,5859,179.4321,13.145635,7.791162,0.0,0,2.0065033,0.0,0.7319684,80.505234,2.0041146,362.9454,-9.2603722
5870,5870,179.4343,13.223244,7.8043022,0.0,0,1.9896998,0.0,0.73506755,80.700157,1.9873133,362.41974,-9.2598457
5881,5881,179.4365,13.270889,7.8274546,0.0,0,1.9728961,0.0,0.73701328,80.820877,1.9638014,361.8941,-9.2599754
5892,5892,179.4387,13.307702,7.8430114,0.0,0,1.9560926,0.0,0.74066997,80.774117,1.9479872,361.36844,-9.2597294
5903,5903,179.4409,13.344503,7.8643212,0.0,0,1.939289,0.0,0.74212575,80.878616,1.9327242,360.8428,-9.2591724
5914,5914,179.4431,13.385907,7.875361,0.0,0,1.9228806,0.0,0.74511313,80.877113,1.9130458,360.35004,-9.2589779
5925,5925,179.4453,13.379801,7.8978438,0.0,0,1.9068955,0.0,0.74685401,80.715408,1.8984197,359.87762,-9.2592392
5936,5936,179.4475,13.399974,7.9118567,0.0,0,1.8909101,0.0,0.7503162,80.535759,1.8806951,359.40518,-9.2612505
5947,5947,179.4497,13.412644,7.933187,0.0,0,1.874925,0.0,0.75167215,80.545837,1.8685585,358.93277,-9.2615948
5958,5958,179.4519,13.439332,7.9411478,0.0,0,1.8589398,0.0,0.7545597,80.431931,1.8504411,358.46625,-9.2606058
5969,5969,179.4541,13.464899,7.9605017,0.0,0,1.8429546,0.0,0.7557832,80.531242,1.8320447,358.08698,-9.2600241
5980,5980,179.4563,13.5029,7.9720817,0.0,0,1.8269695,0.0,0.75897497,80.489388,1.8176625,357.7077,-9.2594185
5991,5991,179.4585,13.553791,7.9974537,0.0,0,1.8109843,0.0,0.76055187,80.608551,1.8059335,357.32843,-9.2596598
6002,6002,179.4607,13.607106,8.0044918,0.0,0,1.794999,0.0,0.76359236,80.744057,1.7883542,356.94916,-9.2594833
6013,6013,179.4629,13.648499,8.0247602,0.0,0,1.7790139,0.0,0.76493675,80.880264,1.7693911,356.7562,-9.2590809
6024,6024,179.4651,13.704013,8.0372858,0.0,0,1.7630286,0.0,0.76838934,80.881416,1.7566082,356.74289,-9.259717
6035,6035,179.4673,13.718192,8.0619745,0.0,0,1.7470435,0.0,0.77010709,80.875114,1.7397934,356.72958,-9.2610769
6046,6046,179.4695,13.758093,8.0687895,0.0,0,1.7310582,0.0,0.77275997,80.872589,1.7206936,356.71628,-9.2594223
6057,6057,179.4717,13.799266,8.0903988,0.0,0,1.715073,0.0,0.77431852,80.974762,1.707417,356.70297,-9.2603722
6068,6068,179.4739,13.848136,8.1012869,0.0,0,1.6990879,0.0,0.7775774,80.987259,1.6928934,356.59439,-9.2593365
6079,6079,179.4761,13.884369,8.1251297,0.0,0,1.6831026,0.0,0.7791633,81.056229,1.6760404,356.48129,-9.260766
6090,6090,179.4783,13.918986,8.1298466,0.0,0,1.6671174,0.0,0.78165776,81.111427,1.6594318,356.36816,-9.2605915
6101,6101,179.4805,13.963116,8.1510458,0.0,0,1.6511322,0.0,0.78331685,81.217918,1.6433389,356.25507,-9.2611046
6112,6112,179.4827,13.98596,8.1619425,0.0,0,1.635147,0.0,0.78628689,81.134087,1.6259646,356.03815,-9.2606964
6123,6123,179.4849,14.016894,8.1865005,0.0,0,1.6191618,0.0,0.78823531,81.204803,1.6137902,355.66553,-9.26122
6134,6134,179.4871,14.077556,8.1941147,0.0,0,1.6031766,0.0,0.79083318,81.262459,1.597371,355.29291,-9.2600307
6145,6145,179.4893,14.128832,8.2157478,0.0,0,1.5871913,0.0,0.79292041,81.377541,1.5790738,354.92026,-9.2603245
6156,6156,179.4915,14.181783,8.2266798,0.0,0,1.5712062,0.0,0.79573184,81.464592,1.5655361,354.54764,-9.2603102
6167,6167,179.4937,14.230556,8.2526255,0.0,0,1.5558095,0.0,0.79798776,81.560173,1.5503051,353.98352,-9.2596655
6178,6178,179.4959,14.266966,8.2573786,0.0,0,1.540603,0.0,0.80026817,81.562233,1.5339564,353.3844,-9.2591524
6189,6189,179.4981,14.297153,8.280282,0.0,0,1.5253967,0.0,0.80234849,81.582352,1.5173641,352.78525,-9.2597647
6200,6200,179.5003,14.340659,8.2892284,0.0,0,1.5101904,0.0,0.80495358,81.656929,1.5009798,352.18613,-9.2596712
6211,6211,179.5025,14.366186,8.3135509,0.0,0,1.4949839,0.0,0.80728495,81.630699,1.4879344,351.5636,-9.2606583
6222,6222,179.5047,14.395394,8.3209276,0.0,0,1.4797776,0.0,0.80955726,81.578667,1.4725907,350.88397,-9.2595644
6233,6233,179.5069,14.454709,8.3411074,0.0,0,1.4645711,0.0,0.81164259,81.712166,1.4577614,350.20435,-9.2599659
6244,6244,179.5091,14.50967,8.3517685,0.0,0,1.4493648,0.0,0.81416893,81.844131,1.44186,349.52472,-9.2600956
6255,6255,179.5113,14.583107,8.3775063,0.0,0,1.4341583,0.0,0.81692213,81.986435,1.4239799,348.84509,-9.2597885
6266,6266,179.5135,14.618559,8.3843822,0.0,0,1.418952,0.0,0.81906819,82.028023,1.4105141,348.28766,-9.259306
6277,6277,179.5157,14.652452,8.4080095,0.0,0,1.4037454,0.0,0.82162029,81.981232,1.3940923,347.77393,-9.2600584
6288,6288,179.5179,14.643521,8.4143629,0.0,0,1.3885391,0.0,0.82352644,81.848022,1.3809785,347.26022,-9.2603493
6299,6299,179.5201,14.661881,8.4368715,0.0,0,1.3733326,0.0,0.82594573,81.735672,1.3653723,346.74652,-9.2604017
6310,6310,179.5223,14.693202,8.4446173,0.0,0,1.3581263,0.0,0.82816893,81.710922,1.3490502,346.24615,-9.2612782
6321,6321,179.5245,14.74288,8.4662151,0.0,0,1.3429198,0.0,0.83076882,81.794334,1.3310419,345.80582,-9.260582
6332,6332,179.5267,14.815735,8.4760122,0.0,0,1.3277135,0.0,0.83274323,82.046165,1.3237627,345.36551,-9.2591248
6343,6343,179.5289,14.866366,8.4975853,0.0,0,1.3125072,0.0,0.83535105,82.06881,1.3051317,344.92517,-9.2599144
6354,6354,179.5311,14.920048,8.5048685,0.0,0,1.2973008,0.0,0.83715779,82.295418,1.2891947,344.48486,-9.260726
6365,6365,179.5333,14.955105,8.5256596,0.0,0,1.2820944,0.0,0.84007949,82.210289,1.2732885,344.18265,-9.2599688
6376,6376,179.5355,14.964768,8.5341883,0.0,0,1.2668879,0.0,0.84159279,82.130127,1.2591107,343.96246,-9.2603636
6387,6387,179.5377,14.977209,8.5565538,0.0,0,1.2516814,0.0,0.84472823,81.911232,1.2452576,343.74231,-9.2607889
6398,6398,179.5399,15.010443,8.5628672,0.0,0,1.2364751,0.0,0.8460086,82.020531,1.2335573,343.52216,-9.2598066
6409,6409,179.5421,15.053234,8.5799704,0.0,0,1.2212964,0.0,0.84864968,82.045876,1.2158717,343.30975,-9.25986
6420,6420,179.5443,15.130151,8.5929089,0.0,0,1.206827,0.0,0.85048628,82.285301,1.2006637,343.19632,-9.2603617
6431,6431,179.5465,15.191181,8.6152706,0.0,0,1.1923642,0.0,0.85403019,82.301247,1.1865234,343.08292,-9.2604914
6442,6442,179.5487,15.270421,8.6249704,0.0,0,1.1779014,0.0,0.85553521,82.645119,1.1705134,342.96951,-9.2599926
6453,6453,179.5509,15.330857,8.6413746,0.0,0,1.1634386,0.0,0.85826856,82.761505,1.156579,342.85611,-9.2603617
6464,6464,179.5531,15.39351,8.6534891,0.0,0,1.1489758,0.0,0.86006188,82.965652,1.1407019,342.677,-9.2590075
6475,6475,179.5553,15.434331,8.6769276,0.0,0,1.134513,0.0,0.86397433,82.846107,1.1229899,342.4368,-9.2603817
6486,6486,179.5575,15.454571,8.6876059,0.0,0,1.1200502,0.0,0.86517102,82.88588,1.1056578,342.19662,-9.2604828
6497,6497,179.5597,15.444762,8.7017593,0.0,0,1.1055874,0.0,0.86808801,82.563866,1.095413,341.95645,-9.2596645
6508,6508,179.5619,15.444342,8.7152691,0.0,0,1.0911245,0.0,0.86962819,82.400459,1.0799772,341.71625,-9.2592583
6519,6519,179.5641,15.469089,8.7350111,0.0,0,1.0766618,0.0,0.87343067,82.200302,1.0656998,341.53394,-9.2587433
6530,6530,179.5663,15.508621,8.742569,0.0,0,1.0621989,0.0,0.87386364,82.405922,1.0522554,341.35382,-9.2596865
6541,6541,179.5685,15.567918,8.7561064,0.0,0,1.0477362,0.0,0.87673825,82.495995,1.0392408,341.17368,-9.2597055
6552,6552,179.5707,15.627859,8.7692938,0.0,0,1.0332733,0.0,0.87816584,82.687027,1.0265424,340.99356,-9.2591944
6563,6563,179.5729,15.687574,8.7881832,0.0,0,1.0188106,0.0,0.88211346,82.680656,1.010184,340.78613,-9.2603168
6574,6574,179.5751,15.749139,8.8011684,0.0,0,1.0043477,0.0,0.88297594,82.917633,0.99436849,340.53928,-9.2598295
6585,6585,179.5773,15.797474,8.8145323,0.0,0,0.98988503,0.0,0.88633358,82.883263,0.98643619,340.29242,-9.2605066
6596,6596,179.5795,15.839443,8.8297052,0.0,0,0.9754222,0.0,0.88764226,83.010246,0.9667145,340.04556,-9.2593079
6607,6607,179.5817,15.875485,8.8467808,0.0,0,0.96095937,0.0,0.8917132,82.873039,0.95141327,339.79874,-9.2601671
6618,6618,179.5839,15.915182,8.8591137,0.0,0,0.94649655,0.0,0.89237094,82.965874,0.93530339,339.53479,-9.2593536
6629,6629,179.5861,15.960315,8.8682489,0.0,0,0.93203384,0.0,0.89516366,83.013092,0.92252481,339.26791,-9.2582874
6640,6640,179.5883,16.002449,8.8830719,0.0,0,0.91757101,0.0,0.89628112,83.145439,0.90965599,339.00107,-9.260006
6651,6651,179.5905,16.027678,8.900423,0.0,0,0.90310818,0.0,0.90032649,82.939667,0.89634669,338.73419,-9.258955
6662,6662,179.5927,16.079315,8.9140816,0.0,0,0.88885868,0.0,0.90128297,83.13945,0.88167214,338.58344,-9.2594805
6673,6673,179.5949,16.161522,8.9255152,0.0,0,0.87510425,0.0,0.90463305,83.264107,0.86954981,338.70352,-9.2602043
6684,6684,179.5971,16.215147,8.9412327,0.0,0,0.86134988,0.0,0.90570998,83.476173,0.85599071,338.82361,-9.2589006
6695,6695,179.5993,16.260536,8.9546776,0.0,0,0.84759545,0.0,0.9096756,83.371185,0.84030759,338.9437,-9.2582102
6706,6706,179.6015,16.305902,8.9740553,0.0,0,0.83384109,0.0,0.91108561,83.455315,0.82684088,339.06378,-9.258235
6717,6717,179.6037,16.362099,8.9824581,0.0,0,0.82008672,0.0,0.91416097,83.492142,0.81065512,339.23361,-9.2586794
6728,6728,179.6059,16.393152,8.9990396,0.0,0,0.80633229,0.0,0.9153015,83.550743,0.79631561,339.42041,-9.2581406
6739,6739,179.6081,16.419136,9.0116615,0.0,0,0.79257792,0.0,0.91927731,83.373978,0.78060722,339.60721,-9.2594967
6750,6750,179.6103,16.407366,9.031352,0.0,0,0.77882349,0.0,0.92042625,83.232254,0.77254605,339.79401,-9.2595711
6761,6761,179.6125,16.407368,9.036459,0.0,0,0.76506907,0.0,0.92330891,83.026237,0.75782114,339.92734,-9.259161
6772,6772,179.6147,16.443241,9.0539532,0.0,0,0.7513147,0.0,0.92447805,83.053314,0.74645448,339.83392,-9.2596426
6783,6783,179.6169,16.5215,9.0648298,0.0,0,0.73756027,0.0,0.92817485,83.119568,0.73340374,339.74054,-9.2588596
6794,6794,179.6191,16.58131,9.0836411,0.0,0,0.7238059,0.0,0.92915446,83.393562,0.71821755,339.64713,-9.2598524
6805,6805,179.6213,16.670126,9.0895109,0.0,0,0.71005148,0.0,0.93218642,83.56134,0.7036016,339.55374,-9.2591982
6816,6816,179.6235,16.736223,9.1079245,0.0,0,0.69629705,0.0,0.93356353,83.779213,0.68774521,339.29053,-9.2597284
6827,6827,179.6257,16.794733,9.1189404,0.0,0,0.68254268,0.0,0.93727022,83.720985,0.67775679,338.93024,-9.260334
6838,6838,179.6279,16.804626,9.1374722,0.0,0,0.66878825,0.0,0.93815327,83.770592,0.66248077,338.56998,-9.2604952
6849,6849,179.6301,16.817976,9.1432114,0.0,0,0.65503389,0.0,0.94137657,83.55468,0.64963096,338.20972,-9.2587595
6860,6860,179.6323,16.843163,9.1620216,0.0,0,0.64127946,0.0,0.9427352,83.589645,0.63388634,337.86908,-9.2593145
6871,6871,179.6345,16.891281,9.1690216,0.0,0,0.62752509,0.0,0.94576055,83.510071,0.62389141,337.74899,-9.2590485
6882,6882,179.6367,16.942301,9.1911516,0.0,0,0.61377066,0.0,0.9473573,83.637207,0.60836679,337.62891,-9.259779
6893,6893,179.6389,17.000729,9.1931076,0.0,0,0.6000163,0.0,0.94994164,83.687866,0.59741521,337.50882,-9.2601709
6904,6904,179.6411,17.09515,9.2121496,0.0,0,0.58626187,0.0,0.95146376,84.03981,0.57880318,337.38873,-9.2598381
6915,6915,179.6433,17.179943,9.2230349,0.0,0,0.57288873,0.0,0.95542443,84.096191,0.56592858,337.40936,-9.2598562
6926,6926,179.6455,17.247467,9.2467022,0.0,0,0.55979872,0.0,0.95688826,84.365509,0.55896205,337.55612,-9.2596025
6937,6937,179.6477,17.30757,9.2503395,0.0,0,0.5467087,0.0,0.95976859,84.381973,0.53853923,337.70291,-9.2595377
6944,6944,179.6491,17.349253,9.2665348,0.0,0,0.53837872,0.0,0.9622395,84.386917,0.52858865,337.7963,-9.2583933