File: clean data/testID_0092.csv
level_0,index,Time(sec),Force(kN),Jaw(mm),PowAngle(deg),Power(W),Pram,PTemp,Strain,Stress(MPa),Stroke(mm),TC1(C),wedge(mm)
1872,1872,155.3437,0.954175,0.0078465901,0.0,0,9.0629625,0.0,0.00041126678,10.751819,10.107893,330.16354,-9.3063345
1874,1874,155.3441,4.0801554,0.037278421,0.0,0,9.0044346,0.0,0.0023214717,46.63554,10.050154,330.28201,-9.3045187
1876,1876,155.3445,6.8228812,0.083553277,0.0,0,8.9459066,0.0,0.005226416,84.609131,10.009466,330.40048,-9.3027773
1878,1878,155.3449,7.4476724,0.13775234,0.0,0,8.8873787,0.0,0.0087726796,93.335823,9.9400883,330.51895,-9.3002462
1880,1880,155.3453,7.8606353,0.25224444,0.0,0,8.8288507,0.0,0.016257871,98.201691,9.8709135,330.63742,-9.3004065
1882,1882,155.3457,8.3248978,0.31160256,0.0,0,8.7703228,0.0,0.020555209,102.87985,9.7879295,330.75589,-9.3010025
1884,1884,155.3461,8.956995,0.38901505,0.0,0,8.7136803,0.0,0.025755411,110.6568,9.7000904,330.87436,-9.3008251
1886,1886,155.3465,9.4777746,0.47148183,0.0,0,8.6580105,0.0,0.031627379,116.28967,9.6243343,330.99283,-9.2978258
1888,1888,155.3469,9.4000177,0.49002674,0.0,0,8.6023464,0.0,0.032814715,116.4557,9.5534525,331.1113,-9.2969713
1890,1890,155.3473,9.2484503,0.58592671,0.0,0,8.5466824,0.0,0.039369594,112.58132,9.4927931,331.22977,-9.2976494
1892,1892,155.3477,9.9949818,0.64001179,0.0,0,8.4910183,0.0,0.043279927,121.09178,9.4287949,331.34824,-9.2982817
1894,1894,155.3481,10.18326,0.6877895,0.0,0,8.4353542,0.0,0.046318203,123.72627,9.3574924,331.46674,-9.2971087
1896,1896,155.3485,10.136705,0.79827964,0.0,0,8.3796902,0.0,0.054269779,122.32807,9.2824831,331.58521,-9.2964211
1898,1898,155.3489,10.000803,0.86554283,0.0,0,8.3240261,0.0,0.058698297,120.03154,9.2016335,331.70367,-9.2956362
1900,1900,155.3493,10.33114,0.93979418,0.0,0,8.268362,0.0,0.064120367,122.86783,9.1244421,331.82214,-9.2964096
1902,1902,155.3497,10.585655,0.99757957,0.0,0,8.2126989,0.0,0.068611637,125.67995,9.0535393,331.94061,-9.2965384
1904,1904,155.3501,10.667793,1.0492945,0.0,0,8.1570339,0.0,0.071734518,126.42876,8.9908314,332.05908,-9.2967319
1906,1906,155.3505,10.538364,1.1168097,0.0,0,8.1013708,0.0,0.077065095,124.38232,8.9272699,332.17755,-9.2967691
1908,1908,155.3509,10.767479,1.1674505,0.0,0,8.0462608,0.0,0.080586545,125.94424,8.8648891,332.29602,-9.2963486
1910,1910,155.3513,11.102272,1.2409127,0.0,0,7.9931693,0.0,0.085593864,129.57678,8.799736,332.41449,-9.2954588
1912,1912,155.3517,10.995275,1.313201,0.0,0,7.9402089,0.0,0.09133897,127.95808,8.728076,332.5556,-9.2953653
1914,1914,155.3521,11.025032,1.3815278,0.0,0,7.887249,0.0,0.095939972,127.53542,8.6614561,332.71185,-9.2966814
1916,1916,155.3525,11.087709,1.4554895,0.0,0,7.8342891,0.0,0.10154247,127.4339,8.5899105,332.86807,-9.2967453
1918,1918,155.3529,11.309092,1.4995322,0.0,0,7.7813287,0.0,0.10523876,129.24911,8.5200148,333.02429,-9.2968178
1920,1920,155.3533,11.374548,1.556601,0.0,0,7.7283688,0.0,0.10884293,130.03558,8.4564171,333.18051,-9.2965431
1922,1922,155.3537,11.342711,1.6279206,0.0,0,7.6754084,0.0,0.11459558,128.70761,8.3971949,333.33673,-9.2962742
1924,1924,155.3541,11.563705,1.6744055,0.0,0,7.6224484,0.0,0.11808483,130.64568,8.3403511,333.49295,-9.2959347
1926,1926,155.3545,11.641873,1.7388785,0.0,0,7.5694885,0.0,0.12246656,131.11798,8.28127,333.64917,-9.2966328
1928,1928,155.3549,11.682508,1.8109832,0.0,0,7.5165286,0.0,0.12849362,130.71936,8.2159996,333.80539,-9.2969494
1930,1930,155.3553,11.73388,1.8673459,0.0,0,7.4635687,0.0,0.1323701,130.88435,8.1535969,333.96161,-9.2955456
1932,1932,155.3557,11.783826,1.934689,0.0,0,7.4106083,0.0,0.13749819,130.60168,8.0868797,334.11786,-9.295599
1934,1934,155.3561,11.953671,1.9780457,0.0,0,7.3593545,0.0,0.14148663,131.90396,8.025485,334.27408,-9.2957611
1936,1936,155.3565,11.947868,2.0346622,0.0,0,7.3089814,0.0,0.14505351,131.62411,7.9654169,334.4303,-9.2967825
1938,1938,155.3569,11.993144,2.0967147,0.0,0,7.2586136,0.0,0.15018621,131.27008,7.9083085,334.58652,-9.2975492
1940,1940,155.3573,12.093856,2.1387346,0.0,0,7.2082453,0.0,0.15373166,131.90073,7.8572645,334.74274,-9.296134
1942,1942,155.3577,12.243361,2.2057049,0.0,0,7.157877,0.0,0.1580469,132.85576,7.799068,334.89896,-9.295372
1944,1944,155.3581,12.282254,2.2606549,0.0,0,7.1075087,0.0,0.16314673,132.83205,7.7420096,335.05518,-9.2951279
1946,1946,155.3585,12.256342,2.317626,0.0,0,7.0571413,0.0,0.16740884,132.02597,7.6850977,335.2114,-9.2955303
1948,1948,155.3589,12.337087,2.3813858,0.0,0,7.0067725,0.0,0.17214441,132.11333,7.6228266,335.36765,-9.295866
1950,1950,155.3593,12.4711,2.4185545,0.0,0,6.9564052,0.0,0.17579964,132.92068,7.5706463,335.52386,-9.2957993
1952,1952,155.3597,12.537862,2.4737623,0.0,0,6.9060369,0.0,0.17960028,133.38623,7.5148444,335.68008,-9.2967176
1954,1954,155.3601,12.522796,2.53497,0.0,0,6.8556695,0.0,0.18449472,132.5591,7.4615779,335.8363,-9.2959518
1956,1956,155.3605,12.597006,2.5725033,0.0,0,6.8053012,0.0,0.18804589,132.82681,7.4087381,335.99252,-9.2959518
1958,1958,155.3609,12.68739,2.6293533,0.0,0,6.7554355,0.0,0.19192553,133.34238,7.3550086,336.14874,-9.295413
1960,1960,155.3613,12.75996,2.6816795,0.0,0,6.707396,0.0,0.19667564,133.384,7.3033042,336.30496,-9.2950373
1962,1962,155.3617,12.797411,2.7294476,0.0,0,6.6594758,0.0,0.20057225,133.24907,7.2497315,336.56863,-9.2947865
1964,1964,155.3621,12.816541,2.7839885,0.0,0,6.6115556,0.0,0.20459537,132.94783,7.2012696,336.89011,-9.2957478
1966,1966,155.3625,12.901131,2.8269763,0.0,0,6.5636358,0.0,0.20881318,133.13115,7.1514959,337.21161,-9.2962961
1968,1968,155.3629,12.972835,2.8784351,0.0,0,6.5157161,0.0,0.21256304,133.51294,7.1007886,337.53308,-9.2966404
1970,1970,155.3633,13.015153,2.9292879,0.0,0,6.4677963,0.0,0.2167248,133.30144,7.0511312,337.85455,-9.2966843
1972,1972,155.3637,13.099613,2.9714067,0.0,0,6.4198756,0.0,0.22080666,133.66399,7.0001073,338.17606,-9.2956915
1974,1974,155.3641,13.131223,3.0251102,0.0,0,6.3719554,0.0,0.22465332,133.5275,6.9480391,338.49753,-9.2948866
1976,1976,155.3645,13.1914,3.0717523,0.0,0,6.3240356,0.0,0.228701,133.59784,6.9010124,338.819,-9.2961502
1978,1978,155.3649,13.224908,3.116467,0.0,0,6.2761159,0.0,0.23284936,133.41394,6.8521438,339.14047,-9.2964764
1980,1980,155.3653,13.288286,3.1702418,0.0,0,6.2281961,0.0,0.23665461,133.41293,6.8029256,339.46198,-9.2961636
1982,1982,155.3657,13.389478,3.2103465,0.0,0,6.1802759,0.0,0.24057055,133.85416,6.7553425,339.78345,-9.2961712
1984,1984,155.3661,13.409066,3.2568059,0.0,0,6.1338992,0.0,0.24454495,133.62166,6.7060871,340.10492,-9.2967844
1986,1986,155.3665,13.455241,3.3119133,0.0,0,6.0883179,0.0,0.24848987,133.56151,6.6594114,340.42639,-9.2974892
1988,1988,155.3669,13.512025,3.3507581,0.0,0,6.0427423,0.0,0.25270519,133.6132,6.61272,340.74789,-9.2963696
1990,1990,155.3673,13.583473,3.3962793,0.0,0,5.9971662,0.0,0.25631827,133.79115,6.5636568,341.06937,-9.295867
1992,1992,155.3677,13.658338,3.4478397,0.0,0,5.9515896,0.0,0.26045489,133.96367,6.5160909,341.39084,-9.2961016
1994,1994,155.3681,13.672898,3.4875193,0.0,0,5.9060144,0.0,0.26456276,133.62744,6.4701033,341.71231,-9.2965031
1996,1996,155.3685,13.714354,3.5345292,0.0,0,5.8604379,0.0,0.2680999,133.47214,6.4229836,342.03381,-9.2972746
1998,1998,155.3689,13.777243,3.5866086,0.0,0,5.8148618,0.0,0.27275592,133.49623,6.3783312,342.35529,-9.2975969
2000,2000,155.3693,13.860965,3.6274509,0.0,0,5.7692857,0.0,0.27680457,133.77046,6.3334746,342.67676,-9.2960482
2002,2002,155.3697,13.90541,3.6741877,0.0,0,5.7237096,0.0,0.28021544,133.79755,6.2869864,342.99826,-9.2949915
2004,2004,155.3701,13.958058,3.7206798,0.0,0,5.678134,0.0,0.28491712,133.61522,6.2386045,343.31973,-9.2956772
2006,2006,155.3705,13.989233,3.7604625,0.0,0,5.6325579,0.0,0.28840601,133.47943,6.1925154,343.6412,-9.2958889
2008,2008,155.3709,14.050014,3.8071566,0.0,0,5.5874362,0.0,0.29211766,133.56619,6.1473475,343.96268,-9.297226
2010,2010,155.3713,14.12055,3.853544,0.0,0,5.5439682,0.0,0.29688123,133.63403,6.0994205,344.28418,-9.2962694
2012,2012,155.3717,14.177404,3.8991838,0.0,0,5.500608,0.0,0.30049783,133.61356,6.056138,344.60132,-9.2958117
2014,2014,155.3721,14.221135,3.947273,0.0,0,5.4572477,0.0,0.30479768,133.48186,6.0091033,344.91663,-9.2952585
2016,2016,155.3725,14.257133,3.9871025,0.0,0,5.413888,0.0,0.30907777,133.22516,5.9648972,345.23193,-9.2954702
2018,2018,155.3729,14.326549,4.034451,0.0,0,5.3705277,0.0,0.31258631,133.41396,5.9175096,345.54724,-9.2958593
2020,2020,155.3733,14.398013,4.0766401,0.0,0,5.327168,0.0,0.31672829,133.45711,5.8733597,345.86255,-9.2964525
2022,2022,155.3737,14.467751,4.1170425,0.0,0,5.2838078,0.0,0.3208676,133.55492,5.827641,346.17786,-9.2960386
2024,2024,155.3741,14.49532,4.1716995,0.0,0,5.240448,0.0,0.32483307,133.32617,5.7826562,346.49316,-9.2956715
2026,2026,155.3745,14.536182,4.2120051,0.0,0,5.1970882,0.0,0.32943985,133.09187,5.7409124,346.80847,-9.295126
2028,2028,155.3749,14.603986,4.253118,0.0,0,5.153728,0.0,0.33317646,133.21568,5.6933722,347.12378,-9.2955999
2030,2030,155.3753,14.684826,4.3058782,0.0,0,5.1103678,0.0,0.33743182,133.39583,5.6481547,347.43909,-9.2964973
2032,2032,155.3757,14.739548,4.3413577,0.0,0,5.067008,0.0,0.34169048,133.35406,5.5994816,347.75439,-9.2979774
2034,2034,155.3761,14.761488,4.3854685,0.0,0,5.0250435,0.0,0.34527448,133.04138,5.5554047,348.0697,-9.2965193
2036,2036,155.3765,14.824185,4.4392505,0.0,0,4.983799,0.0,0.35011593,132.97823,5.5129662,348.38501,-9.2971821
2038,2038,155.3769,14.896405,4.475904,0.0,0,4.9425588,0.0,0.35440671,133.01836,5.4662209,348.70032,-9.2971716
2040,2040,155.3773,14.985872,4.5235868,0.0,0,4.901319,0.0,0.35807011,133.29564,5.4254766,349.01559,-9.2972059
2042,2042,155.3777,15.025059,4.5719771,0.0,0,4.8600788,0.0,0.36312437,132.99629,5.3780632,349.3309,-9.297226
2044,2044,155.3781,15.070704,4.6085796,0.0,0,4.8188391,0.0,0.36698434,132.8932,5.3332863,349.64621,-9.2970181
2046,2046,155.3785,15.119274,4.6561513,0.0,0,4.7775989,0.0,0.37082595,132.81815,5.2892461,349.96152,-9.2972069
2048,2048,155.3789,15.213707,4.6989903,0.0,0,4.7363586,0.0,0.37578088,132.95111,5.2435989,350.27682,-9.2971115
2050,2050,155.3793,15.276115,4.7429166,0.0,0,4.6951189,0.0,0.37970227,133.03752,5.1987901,350.59213,-9.2963648
2052,2052,155.3797,15.318956,4.792407,0.0,0,4.6538792,0.0,0.38414231,132.76601,5.1536784,350.90744,-9.2955303
2054,2054,155.3801,15.381612,4.8336902,0.0,0,4.6126385,0.0,0.3890608,132.66032,5.1129208,351.22275,-9.296299
2056,2056,155.3805,15.439183,4.8799329,0.0,0,4.5713987,0.0,0.39281499,132.66058,5.0643454,351.53806,-9.2967691
2058,2058,155.3809,15.513445,4.9215913,0.0,0,4.530571,0.0,0.39711663,132.70641,5.0227056,351.85336,-9.2964907
2060,2060,155.3813,15.5795,4.9597545,0.0,0,4.491241,0.0,0.40162396,132.70947,4.9800692,352.16867,-9.2963276
2062,2062,155.3817,15.638842,5.0112491,0.0,0,4.4520087,0.0,0.40563616,132.6702,4.9330068,352.28754,-9.2961817
2064,2064,155.3821,15.680682,5.0516238,0.0,0,4.4127765,0.0,0.41035163,132.39267,4.8892698,352.34097,-9.2960949
2066,2066,155.3825,15.738204,5.0912929,0.0,0,4.3735447,0.0,0.41452214,132.37282,4.8435264,352.39441,-9.2958698
2068,2068,155.3829,15.81833,5.1419916,0.0,0,4.3343129,0.0,0.41869482,132.41782,4.8031635,352.44788,-9.2951097
2070,2070,155.3833,15.898966,5.1768394,0.0,0,4.2950811,0.0,0.42321932,132.51233,4.7598825,352.50131,-9.2953882
2072,2072,155.3837,15.947285,5.2188706,0.0,0,4.2558484,0.0,0.42714918,132.45139,4.7170796,352.55475,-9.296876
2074,2074,155.3841,16.000246,5.270082,0.0,0,4.2166166,0.0,0.43188438,132.15527,4.6736107,352.60822,-9.2971249
2076,2076,155.3845,16.061554,5.3049374,0.0,0,4.1773844,0.0,0.43653741,132.07133,4.6339364,352.66165,-9.2961807
2078,2078,155.3849,16.146626,5.3484678,0.0,0,4.1381526,0.0,0.4402751,132.33147,4.5921187,352.71509,-9.2942915
2080,2080,155.3853,16.227272,5.3951063,0.0,0,4.0989208,0.0,0.44511265,132.3793,4.547276,352.76855,-9.2954035
2082,2082,155.3857,16.280087,5.4287505,0.0,0,4.0596886,0.0,0.44930872,132.25308,4.5061035,352.82199,-9.2965117
2084,2084,155.3861,16.339123,5.4748359,0.0,0,4.0217209,0.0,0.45309675,132.21376,4.465508,352.87543,-9.296339
2086,2086,155.3865,16.402775,5.5204344,0.0,0,3.9844046,0.0,0.4585472,131.96979,4.4242697,352.92886,-9.2958632
2088,2088,155.3869,16.494017,5.5566626,0.0,0,3.9470925,0.0,0.46256971,132.13297,4.3785524,352.98233,-9.2957678
2090,2090,155.3873,16.55751,5.5997729,0.0,0,3.9097805,0.0,0.46644464,132.1584,4.3397169,353.03577,-9.2963839
2092,2092,155.3877,16.612053,5.6381302,0.0,0,3.8724687,0.0,0.47150758,131.95151,4.2976046,353.0892,-9.2968531
2094,2094,155.3881,16.676844,5.6758657,0.0,0,3.8351564,0.0,0.47493985,131.99791,4.2582312,353.14267,-9.295826
2096,2096,155.3885,16.737202,5.7172899,0.0,0,3.7978446,0.0,0.47920266,131.93509,4.2191644,353.19611,-9.2953997
2098,2098,155.3889,16.826139,5.7545996,0.0,0,3.7605324,0.0,0.48418435,131.95654,4.175025,353.24954,-9.2950983
2100,2100,155.3893,16.887608,5.8010359,0.0,0,3.7232206,0.0,0.48806691,131.91507,4.1338778,353.30301,-9.2961226
2102,2102,155.3897,16.96261,5.8395352,0.0,0,3.6859086,0.0,0.49265352,131.86148,4.0972772,353.35645,-9.296854
2104,2104,155.3901,17.010025,5.8743052,0.0,0,3.6485965,0.0,0.49708608,131.72798,4.0555534,353.40988,-9.2964487
2106,2106,155.3905,17.069939,5.9198322,0.0,0,3.6112845,0.0,0.50091285,131.6545,4.0191817,353.46332,-9.296299
2108,2108,155.3909,17.170204,5.9546285,0.0,0,3.5743451,0.0,0.50559169,131.73885,3.979115,353.51678,-9.2955732
2110,2110,155.3913,17.261482,5.990593,0.0,0,3.5387604,0.0,0.50954378,131.99077,3.9368646,353.57022,-9.295661
2112,2112,155.3917,17.311981,6.0375843,0.0,0,3.5032644,0.0,0.51382023,131.79488,3.8992136,353.68878,-9.2957773
2114,2114,155.3921,17.361012,6.0683403,0.0,0,3.4677682,0.0,0.51852721,131.55907,3.862257,353.82361,-9.2960405
2116,2116,155.3925,17.437841,6.1066732,0.0,0,3.4322724,0.0,0.52222204,131.65947,3.8236625,353.95844,-9.2967377
2118,2118,155.3929,17.533373,6.1525297,0.0,0,3.3967764,0.0,0.5270263,131.76863,3.7853475,354.09326,-9.2959538
2120,2120,155.3933,17.623594,6.1815386,0.0,0,3.3612804,0.0,0.53138119,131.81961,3.7452893,354.22809,-9.2956667
2122,2122,155.3937,17.671837,6.2204838,0.0,0,3.3257842,0.0,0.53485662,131.80237,3.7086563,354.36292,-9.2943058
2124,2124,155.3941,17.730211,6.2635164,0.0,0,3.2902884,0.0,0.54003036,131.49818,3.6709912,354.49774,-9.2947044
2126,2126,155.3945,17.816357,6.2932072,0.0,0,3.2547922,0.0,0.54403389,131.56018,3.6326094,354.63257,-9.2960806
2128,2128,155.3949,17.921,6.3341465,0.0,0,3.2192962,0.0,0.54780185,131.84132,3.5965536,354.7674,-9.2966623
2130,2130,155.3953,17.981739,6.3737264,0.0,0,3.1838002,0.0,0.55313826,131.66313,3.5595315,354.90222,-9.296236
2132,2132,155.3957,18.030504,6.4054861,0.0,0,3.1483042,0.0,0.55670989,131.55829,3.5220675,355.03705,-9.2949095
2134,2134,155.3961,18.098991,6.4447594,0.0,0,3.1139457,0.0,0.56059188,131.48032,3.4862309,355.17188,-9.293416
2136,2136,155.3965,18.192728,6.4784913,0.0,0,3.080174,0.0,0.56562161,131.53876,3.4487538,355.3067,-9.2941513
2138,2138,155.3969,18.301096,6.5154896,0.0,0,3.0464063,0.0,0.56923997,131.80273,3.4114544,355.44153,-9.2956238
2140,2140,155.3973,18.374325,6.5549278,0.0,0,3.0126381,0.0,0.57382685,131.71382,3.3750508,355.57635,-9.2954016
2142,2142,155.3977,18.429754,6.5877557,0.0,0,2.9788702,0.0,0.5786503,131.49864,3.337646,355.71118,-9.2962255
2144,2144,155.3981,18.513863,6.6287684,0.0,0,2.9451022,0.0,0.58230335,131.60001,3.3038208,355.84601,-9.2950354
2146,2146,155.3985,18.598841,6.6613021,0.0,0,2.9113338,0.0,0.58677709,131.6158,3.2702668,355.98083,-9.2947159
2148,2148,155.3989,18.715157,6.6904125,0.0,0,2.8775661,0.0,0.59076154,131.89523,3.234149,356.11566,-9.2941303
2150,2150,155.3993,18.791323,6.7358885,0.0,0,2.8437979,0.0,0.59484249,131.93102,3.1978149,356.25049,-9.296133
2152,2152,155.3997,18.845627,6.7646942,0.0,0,2.8100297,0.0,0.59945643,131.7319,3.1641669,356.38531,-9.2968111
2154,2154,155.4001,18.92198,6.7985625,0.0,0,2.776262,0.0,0.60335767,131.75131,3.1281025,356.52014,-9.2961178
2156,2156,155.4005,19.029482,6.844636,0.0,0,2.7424941,0.0,0.60809666,131.80849,3.0922236,356.65497,-9.2947254
2158,2158,155.4009,19.133753,6.8689833,0.0,0,2.7090642,0.0,0.61262929,131.94321,3.0527489,356.78979,-9.2939625
2160,2160,155.4013,19.209435,6.901969,0.0,0,2.6768637,0.0,0.61587429,132.07784,3.0197151,356.92462,-9.294796
2162,2162,155.4017,19.275795,6.943305,0.0,0,2.6447432,0.0,0.62071604,131.89374,2.989069,357.05637,-9.2965899
2164,2164,155.4021,19.376322,6.9683619,0.0,0,2.6126232,0.0,0.62495267,131.91681,2.9524732,357.18753,-9.2964687
2166,2166,155.4025,19.479033,7.006351,0.0,0,2.5805032,0.0,0.62842262,132.2227,2.9213505,357.31873,-9.2961788
2168,2168,155.4029,19.578421,7.044601,0.0,0,2.5483832,0.0,0.63388604,132.17419,2.8863575,357.44989,-9.2959547
2170,2170,155.4033,19.652081,7.0728827,0.0,0,2.5162632,0.0,0.63768172,132.17935,2.8520334,357.58109,-9.295146
2172,2172,155.4037,19.732172,7.1116967,0.0,0,2.4841433,0.0,0.64163882,132.17972,2.8176839,357.71225,-9.2942772
2174,2174,155.4041,19.824284,7.1427865,0.0,0,2.4520233,0.0,0.64666456,132.1599,2.7845485,357.84344,-9.2940311
2176,2176,155.4045,19.926313,7.1727419,0.0,0,2.4199033,0.0,0.65006346,132.3535,2.7547808,357.97461,-9.2948484
2178,2178,155.4049,20.03923,7.2093844,0.0,0,2.3877833,0.0,0.65417635,132.61314,2.7204447,358.1058,-9.2945681
2180,2180,155.4053,20.12549,7.2391691,0.0,0,2.3556631,0.0,0.65935981,132.47328,2.6868274,358.237,-9.2948418
2182,2182,155.4057,20.217722,7.2764568,0.0,0,2.3235433,0.0,0.66293651,132.64323,2.6537549,358.36816,-9.2954473
2184,2184,155.4061,20.319481,7.3100977,0.0,0,2.2924554,0.0,0.6676265,132.64301,2.61707,358.49936,-9.2947721
2186,2186,155.4065,20.428783,7.3374057,0.0,0,2.2619002,0.0,0.67212826,132.72566,2.583364,358.63052,-9.2929554
2188,2188,155.4069,20.549055,7.3781962,0.0,0,2.2313483,0.0,0.67583948,133.05417,2.5511689,358.76172,-9.2924423
2190,2190,155.4073,20.638643,7.4071608,0.0,0,2.2007964,0.0,0.68063635,133.01457,2.5153375,358.89288,-9.2932806
2192,2192,155.4077,20.728645,7.4361739,0.0,0,2.1702442,0.0,0.68467802,133.01721,2.4816544,359.02408,-9.2940969
2194,2194,155.4081,20.822117,7.4777904,0.0,0,2.1396923,0.0,0.68881971,133.00613,2.45134,359.15524,-9.2943239
2196,2196,155.4085,20.931223,7.5022535,0.0,0,2.1091404,0.0,0.6935845,133.07852,2.4194391,359.28644,-9.2945471
2198,2198,155.4089,21.060883,7.5336199,0.0,0,2.0785885,0.0,0.69699365,133.42123,2.3876612,359.41763,-9.2941103
2200,2200,155.4093,21.158848,7.5740275,0.0,0,2.0480366,0.0,0.70193535,133.46953,2.3539224,359.5488,-9.2935467
2202,2202,155.4097,21.238159,7.5974803,0.0,0,2.0174844,0.0,0.70660782,133.36987,2.3249345,359.67999,-9.2946768
2204,2204,155.4101,21.348064,7.6308799,0.0,0,1.9869323,0.0,0.70987433,133.56784,2.2915819,359.81116,-9.2935266
2206,2206,155.4105,21.479584,7.6679435,0.0,0,1.9563802,0.0,0.71506155,133.66443,2.259227,359.94235,-9.2940531
2208,2208,155.4109,21.601866,7.6913695,0.0,0,1.9261335,0.0,0.71930903,133.89064,2.229811,360.07352,-9.2936459
2210,2210,155.4113,21.703943,7.7304492,0.0,0,1.8969967,0.0,0.72312415,134.02145,2.1977768,360.20471,-9.2934723
2212,2212,155.4117,21.79022,7.764647,0.0,0,1.8679327,0.0,0.72905415,133.74182,2.1642032,360.267,-9.2939434
2214,2214,155.4121,21.895584,7.7895875,0.0,0,1.8388687,0.0,0.73248267,133.94948,2.1321056,360.32166,-9.294138
2216,2216,155.4125,22.037224,7.8232927,0.0,0,1.8098047,0.0,0.73614717,134.25693,2.0970156,360.37631,-9.2948761
2218,2218,155.4129,22.175741,7.8508577,0.0,0,1.7807406,0.0,0.74134982,134.44786,2.0706375,360.43097,-9.2941351
2220,2220,155.4133,22.275974,7.881928,0.0,0,1.7516767,0.0,0.74478054,134.59373,2.0375795,360.48566,-9.293334
2222,2222,155.4137,22.371542,7.9176364,0.0,0,1.7226127,0.0,0.74950898,134.54987,2.0086937,360.54031,-9.2928457
2224,2224,155.4141,22.492088,7.944602,0.0,0,1.6935487,0.0,0.75480402,134.54131,1.9746151,360.59497,-9.2933254
2226,2226,155.4145,22.636074,7.9811583,0.0,0,1.6644846,0.0,0.75834852,134.85509,1.9431336,360.64963,-9.2937222
2228,2228,155.4149,22.771181,8.0104303,0.0,0,1.6354207,0.0,0.76325935,135.09322,1.9146013,360.70428,-9.2936516
2230,2230,155.4153,22.870895,8.0363693,0.0,0,1.6063567,0.0,0.76771623,135.07089,1.8800278,360.75894,-9.2931461
2232,2232,155.4157,22.978897,8.0741663,0.0,0,1.5772927,0.0,0.77136391,135.22629,1.8495177,360.8136,-9.2931976
2234,2234,155.4161,23.098974,8.0967503,0.0,0,1.5491608,0.0,0.77600783,135.32928,1.8210251,360.86826,-9.2926397
2236,2236,155.4165,23.250408,8.1236649,0.0,0,1.5215098,0.0,0.77971268,135.64732,1.7898031,360.92291,-9.293313
2238,2238,155.4169,23.382196,8.1627808,0.0,0,1.4938618,0.0,0.78426367,135.84218,1.7584316,360.97757,-9.2925558
2240,2240,155.4173,23.482126,8.1863813,0.0,0,1.4662137,0.0,0.78947264,135.74628,1.7288911,361.03223,-9.2929707
2242,2242,155.4177,23.594772,8.2188625,0.0,0,1.4385657,0.0,0.7933315,135.81326,1.7013185,361.08688,-9.2938776
2244,2244,155.4181,23.734732,8.2568035,0.0,0,1.4109179,0.0,0.79848248,135.9239,1.6699064,361.14154,-9.2927246
2246,2246,155.4185,23.894047,8.2728148,0.0,0,1.3832699,0.0,0.80245477,136.27002,1.6398946,361.1962,-9.2916145
2248,2248,155.4189,24.024487,8.3031445,0.0,0,1.3556218,0.0,0.80530006,136.66689,1.6127486,361.25085,-9.2909927
2250,2250,155.4193,24.128477,8.3373547,0.0,0,1.3279738,0.0,0.81104314,136.429,1.5850968,361.30551,-9.2919321
2252,2252,155.4197,24.247965,8.3586016,0.0,0,1.3003259,0.0,0.81484395,136.57295,1.5558789,361.3602,-9.2938633
2254,2254,155.4201,24.395205,8.3936796,0.0,0,1.2726779,0.0,0.8187508,136.90309,1.5248392,361.41486,-9.2941675
2256,2256,155.4205,24.545177,8.4223146,0.0,0,1.2450298,0.0,0.82451785,136.9612,1.4988434,361.46951,-9.2933941
2258,2258,155.4209,24.685715,8.444787,0.0,0,1.2176594,0.0,0.82776076,137.28014,1.4703826,361.52417,-9.2920256
2260,2260,155.4213,24.787014,8.4777794,0.0,0,1.1912973,0.0,0.83171076,137.32909,1.4429175,361.57883,-9.2910032
2262,2262,155.4217,24.919933,8.5011263,0.0,0,1.1650012,0.0,0.83706117,137.27162,1.4147077,361.49384,-9.2912455
2264,2264,155.4221,25.061338,8.5306234,0.0,0,1.138705,0.0,0.84024769,137.63539,1.3885188,361.40152,-9.2934313
2266,2266,155.4225,25.221703,8.5594912,0.0,0,1.1124091,0.0,0.84466565,137.92215,1.3558921,361.3092,-9.2940311
2268,2268,155.4229,25.350937,8.580821,0.0,0,1.0861131,0.0,0.84946001,137.98497,1.3308381,361.21689,-9.2925463
2270,2270,155.4233,25.479965,8.6140738,0.0,0,1.059817,0.0,0.85265863,138.20049,1.3013536,361.12457,-9.2919416
2272,2272,155.4237,25.612074,8.6386776,0.0,0,1.0335211,0.0,0.85753518,138.27277,1.2752309,361.03226,-9.2909479
2274,2274,155.4241,25.765461,8.6599045,0.0,0,1.007225,0.0,0.86150151,138.53273,1.2493948,360.93994,-9.2915249
2276,2276,155.4245,25.926577,8.6949711,0.0,0,0.98092902,0.0,0.86507916,138.90129,1.2233287,360.84763,-9.292552
2278,2278,155.4249,26.07538,8.7145939,0.0,0,0.954633,0.0,0.87008232,139.01428,1.1936044,360.75531,-9.2933235
2280,2280,155.4253,26.208847,8.7418041,0.0,0,0.9283371,0.0,0.87382811,139.21791,1.1677341,360.66299,-9.2933531
2282,2282,155.4257,26.343491,8.7792997,0.0,0,0.90204108,0.0,0.87871301,139.24321,1.1407114,360.57068,-9.2911873
2284,2284,155.4261,26.491692,8.7947569,0.0,0,0.87659293,0.0,0.88326508,139.37163,1.1148095,360.47839,-9.2909613
2286,2286,155.4265,26.654776,8.8193598,0.0,0,0.85158223,0.0,0.88584906,139.91605,1.0882521,360.38608,-9.2903728
2288,2288,155.4269,26.806238,8.851265,0.0,0,0.82657415,0.0,0.89083558,140.0152,1.0601259,360.29376,-9.2909021
2290,2290,155.4273,26.93364,8.8666372,0.0,0,0.80156624,0.0,0.89490479,140.09618,1.0377089,360.20145,-9.2913389
2292,2292,155.4277,27.0763,8.8974705,0.0,0,0.77655822,0.0,0.89795655,140.34308,1.0117713,360.10913,-9.2912855
2294,2294,155.4281,27.237749,8.9256811,0.0,0,0.7515502,0.0,0.90380299,140.37645,0.98653227,360.01682,-9.2903528
2296,2296,155.4285,27.41271,8.9439154,0.0,0,0.72654223,0.0,0.90717012,140.82159,0.96100378,359.9245,-9.2897463
2298,2298,155.4289,27.575113,8.9737549,0.0,0,0.70153421,0.0,0.91059273,141.17387,0.93490416,359.83218,-9.2902956
2300,2300,155.4293,27.718967,8.9963951,0.0,0,0.67652625,0.0,0.91622251,141.13605,0.91071165,359.73987,-9.2893705
2302,2302,155.4297,27.872162,9.0185118,0.0,0,0.65151823,0.0,0.91904527,141.47058,0.88290936,359.64755,-9.289835
2304,2304,155.4301,28.045551,9.0469894,0.0,0,0.6265102,0.0,0.92293304,141.79109,0.85791802,359.55524,-9.2902222
2306,2306,155.4305,28.232212,9.0659637,0.0,0,0.60150224,0.0,0.92811191,141.98468,0.83299047,359.46292,-9.2901821
2308,2308,155.4309,28.388245,9.0935631,0.0,0,0.57674205,0.0,0.93103045,142.39645,0.80939573,359.37061,-9.2903585
2310,2310,155.4313,28.514982,9.1194334,0.0,0,0.55288297,0.0,0.93586063,142.31345,0.780743,359.27832,-9.2897434
2312,2312,155.4317,28.673498,9.1381512,0.0,0,0.52908289,0.0,0.94029063,142.46355,0.75723058,359.21759,-9.2897749
2314,2314,155.4321,28.864313,9.1693144,0.0,0,0.50528288,0.0,0.94340628,142.95602,0.73260784,359.15686,-9.289465
2316,2316,155.4325,29.046215,9.1868544,0.0,0,0.48148289,0.0,0.94779009,143.25587,0.71360493,359.0961,-9.2894993
2318,2318,155.4329,29.216745,9.2052851,0.0,0,0.45768291,0.0,0.95125157,143.59676,0.68313861,359.03537,-9.2902584
2320,2320,155.4333,29.362808,9.2398853,0.0,0,0.43388289,0.0,0.9553178,143.77905,0.65897942,358.97464,-9.2901974
2322,2322,155.4337,29.534271,9.2557001,0.0,0,0.41008291,0.0,0.96034765,143.81963,0.63913274,358.91391,-9.2900209
2324,2324,155.4341,29.721432,9.2804708,0.0,0,0.38628289,0.0,0.96353996,144.30754,0.61399424,358.85318,-9.28969
2326,2326,155.4345,29.933456,9.3137131,0.0,0,0.36248288,0.0,0.96870232,144.5993,0.59113401,358.79245,-9.2891226
2328,2328,155.4349,30.082834,9.3245993,0.0,0,0.33868289,0.0,0.97278279,144.74236,0.56725812,358.73172,-9.2894249
2329,2329,155.4351,30.15913,9.344326,0.0,0,0.32678291,0.0,0.97441506,144.8486,0.55754459,358.70135,-9.2894392