File: clean data/testID_0196.csv
level_0,index,Time(sec),Force(kN),Jaw(mm),PowAngle(deg),Power(W),Pram,PTemp,Strain,Stress(MPa),Stroke(mm),TC1(C),wedge(mm)
1773,1773,145.3439,0.99684083,0.014358155,0.0,0,9.0337057,0.0,0.0011885894,11.252268,10.060841,302.58438,-9.3243532
1775,1775,145.3443,3.9476888,0.055361249,0.0,0,8.9751778,0.0,0.0031670853,45.844048,9.9928007,303.14075,-9.3255367
1777,1777,145.3447,5.6732154,0.10124569,0.0,0,8.9166498,0.0,0.0065472513,70.51545,9.9363718,303.69711,-9.3234844
1779,1779,145.3451,6.6133919,0.17730929,0.0,0,8.8581219,0.0,0.011330585,81.789619,9.8660927,304.25348,-9.3203745
1781,1781,145.3455,7.0738258,0.31552055,0.0,0,8.7995939,0.0,0.020087518,88.157913,9.7798958,304.80984,-9.318223
1783,1783,145.3459,7.6234608,0.39724499,0.0,0,8.7416534,0.0,0.02647399,93.424347,9.6802225,305.36621,-9.3181839
1785,1785,145.3463,8.2355213,0.48137325,0.0,0,8.6858492,0.0,0.032118063,101.0078,9.5802107,305.92258,-9.3186655
1787,1787,145.3467,8.7627878,0.53728086,0.0,0,8.6301851,0.0,0.036022604,107.17171,9.4991102,306.47894,-9.3190184
1789,1789,145.3471,8.5617561,0.57275522,0.0,0,8.5745211,0.0,0.038821846,105.40973,9.4339876,307.03531,-9.317956
1791,1791,145.3475,8.7102947,0.63966107,0.0,0,8.518857,0.0,0.043047417,105.65583,9.3746719,307.59167,-9.3179283
1793,1793,145.3479,9.1235399,0.69672716,0.0,0,8.4631929,0.0,0.047037881,110.42272,9.3157024,308.14804,-9.3163776
1795,1795,145.3483,9.4851418,0.77321392,0.0,0,8.4075289,0.0,0.052442458,114.32391,9.2398396,308.70441,-9.3147783
1797,1797,145.3487,9.2236214,0.87695891,0.0,0,8.3518648,0.0,0.059362214,111.16483,9.1601028,309.26077,-9.3159571
1799,1799,145.3491,9.2737274,0.96701026,0.0,0,8.2962008,0.0,0.066175625,110.19865,9.0736046,309.81714,-9.3180704
1801,1801,145.3495,9.4544544,1.0369492,0.0,0,8.2405367,0.0,0.071358256,112.0583,8.9929323,310.3735,-9.3169212
1803,1803,145.3499,9.7084942,1.0744059,0.0,0,8.1848736,0.0,0.073925011,114.3575,8.9205866,310.92987,-9.3158188
1805,1805,145.3503,9.8120556,1.1231735,0.0,0,8.1292095,0.0,0.077638291,115.83846,8.8644247,311.48624,-9.3153534
1807,1807,145.3507,9.6915503,1.1787857,0.0,0,8.0735445,0.0,0.081484124,113.57811,8.8118496,312.0426,-9.3149633
1809,1809,145.3511,9.9949179,1.2323327,0.0,0,8.0196619,0.0,0.085091554,116.64039,8.7559357,312.59894,-9.3163843
1811,1811,145.3515,10.060137,1.3126506,0.0,0,7.9666953,0.0,0.091271654,116.89731,8.6914349,313.1553,-9.316864
1813,1813,145.3519,10.081388,1.3941383,0.0,0,7.9137354,0.0,0.096798852,116.63216,8.6219053,313.71167,-9.3158445
1815,1815,145.3523,10.016067,1.4667103,0.0,0,7.860775,0.0,0.10234992,115.02708,8.550046,314.26804,-9.3153267
1817,1817,145.3527,10.144939,1.5200653,0.0,0,7.8078156,0.0,0.10684966,115.91179,8.4826231,314.8244,-9.3150263
1819,1819,145.3531,10.231807,1.5621867,0.0,0,7.7548552,0.0,0.10931623,116.72289,8.4187918,315.38077,-9.3160086
1821,1821,145.3535,10.339453,1.6134318,0.0,0,7.7018952,0.0,0.11342546,117.64837,8.3689671,315.93713,-9.3156443
1823,1823,145.3539,10.318884,1.661952,0.0,0,7.6489348,0.0,0.11717302,116.7071,8.3127546,316.4935,-9.317173
1825,1825,145.3543,10.530892,1.7237426,0.0,0,7.5959754,0.0,0.12114327,118.53709,8.2620955,317.00912,-9.3174887
1827,1827,145.3547,10.544686,1.7852887,0.0,0,7.543015,0.0,0.1264803,118.33459,8.2006865,317.52475,-9.3155756
1829,1829,145.3551,10.591701,1.8486934,0.0,0,7.4900556,0.0,0.13092665,118.18101,8.1433897,318.04037,-9.3156118
1831,1831,145.3555,10.530579,1.9214642,0.0,0,7.4370952,0.0,0.13636579,117.09222,8.0786762,318.556,-9.3155737
1833,1833,145.3559,10.622217,1.9599217,0.0,0,7.384666,0.0,0.14007463,117.3506,8.0186462,319.07162,-9.3161182
1835,1835,145.3563,10.772949,2.002943,0.0,0,7.3341718,0.0,0.14274029,118.93213,7.9669585,319.58725,-9.3162441
1837,1837,145.3567,10.771791,2.0615945,0.0,0,7.2838035,0.0,0.14741489,118.44149,7.9125457,320.10287,-9.3166561
1839,1839,145.3571,10.773079,2.1007712,0.0,0,7.2334356,0.0,0.15081051,117.97729,7.8665619,320.6185,-9.3177376
1841,1841,145.3575,10.874061,2.1597495,0.0,0,7.1830673,0.0,0.15474024,118.43728,7.8156977,321.13412,-9.3167906
1843,1843,145.3579,11.019658,2.2155316,0.0,0,7.132699,0.0,0.15965959,119.43729,7.7623844,321.64975,-9.3154593
1845,1845,145.3583,11.024551,2.2655792,0.0,0,7.0823312,0.0,0.16343106,119.24834,7.705246,322.16537,-9.3151503
1847,1847,145.3587,10.989154,2.3260128,0.0,0,7.0319633,0.0,0.16784829,118.28453,7.6521764,322.681,-9.3154945
1849,1849,145.3591,11.040163,2.3671479,0.0,0,6.981595,0.0,0.17177162,118.2893,7.5998502,323.19662,-9.3166971
1851,1851,145.3595,11.18285,2.4150057,0.0,0,6.9312272,0.0,0.17506699,119.4406,7.5491681,323.71225,-9.3165894
1853,1853,145.3599,11.210382,2.465533,0.0,0,6.8808589,0.0,0.17910503,119.328,7.5006881,324.22787,-9.3164129
1855,1855,145.3603,11.229193,2.5063937,0.0,0,6.8304915,0.0,0.18285601,119.01313,7.4512005,324.74347,-9.3158474
1857,1857,145.3607,11.26559,2.5654666,0.0,0,6.7801232,0.0,0.1868062,119.00837,7.4027185,325.25909,-9.3160839
1859,1859,145.3611,11.363402,2.6121039,0.0,0,6.7313666,0.0,0.1910165,119.44229,7.3518219,325.77472,-9.315938
1861,1861,145.3615,11.387363,2.6601329,0.0,0,6.6834412,0.0,0.19499174,119.27725,7.3000321,326.29034,-9.3156433
1863,1863,145.3619,11.401547,2.7195988,0.0,0,6.6355214,0.0,0.1991436,118.97726,7.2495146,326.80597,-9.3172674
1865,1865,145.3623,11.487036,2.7563233,0.0,0,6.5876012,0.0,0.20281935,119.30952,7.2026277,327.32159,-9.3165455
1867,1867,145.3627,11.557514,2.8036666,0.0,0,6.5396814,0.0,0.20651127,119.58524,7.1539636,327.83722,-9.3156433
1869,1869,145.3631,11.590442,2.8562346,0.0,0,6.4917617,0.0,0.21047196,119.5202,7.1101036,328.35284,-9.3157845
1871,1871,145.3635,11.620131,2.8971517,0.0,0,6.4438419,0.0,0.21449259,119.39561,7.0598397,328.86847,-9.3150282
1873,1873,145.3639,11.704879,2.9476833,0.0,0,6.3959212,0.0,0.21827397,119.73654,7.011714,329.38409,-9.3158569
1875,1875,145.3643,11.778524,3.0001447,0.0,0,6.3480015,0.0,0.22254303,120.00369,6.9615216,329.21585,-9.3163662
1877,1877,145.3647,11.789231,3.0453861,0.0,0,6.3000817,0.0,0.22680219,119.59839,6.9129887,329.04764,-9.3169422
1879,1879,145.3651,11.795928,3.0957727,0.0,0,6.252162,0.0,0.23046817,119.24435,6.8638406,328.87943,-9.3171091
1881,1881,145.3655,11.886463,3.1442068,0.0,0,6.2042418,0.0,0.23495288,119.50498,6.8164544,328.71118,-9.3167162
1883,1883,145.3659,11.964602,3.1859319,0.0,0,6.1568022,0.0,0.23858151,119.9614,6.7675238,328.54297,-9.3161221
1885,1885,145.3663,12.012954,3.2306759,0.0,0,6.1111116,0.0,0.24190734,120.09204,6.7209744,328.37473,-9.3162727
1887,1887,145.3667,12.044488,3.2778521,0.0,0,6.0655355,0.0,0.24651764,119.77011,6.6736827,328.20651,-9.3172722
1889,1889,145.3671,12.083421,3.3259172,0.0,0,6.0199599,0.0,0.25024804,119.75752,6.6254892,328.03827,-9.3172617
1891,1891,145.3675,12.167576,3.3779004,0.0,0,5.9743834,0.0,0.25436148,120.01451,6.5764046,327.87006,-9.3169727
1893,1893,145.3679,12.222545,3.4268713,0.0,0,5.9288073,0.0,0.25930139,120.05116,6.5249987,327.70181,-9.3156958
1895,1895,145.3683,12.251731,3.4753075,0.0,0,5.8832316,0.0,0.26289305,119.86026,6.478065,327.5336,-9.3169203
1897,1897,145.3687,12.282863,3.5217319,0.0,0,5.8376555,0.0,0.2671653,119.67073,6.4316211,327.36536,-9.3176336
1899,1899,145.3691,12.329823,3.5623264,0.0,0,5.792079,0.0,0.27122363,119.65034,6.3861861,327.19714,-9.3163929
1901,1901,145.3695,12.420952,3.6129751,0.0,0,5.7465034,0.0,0.27474555,120.02396,6.3381252,327.0289,-9.3169527
1903,1903,145.3699,12.47622,3.6576021,0.0,0,5.7009273,0.0,0.27924025,120.09336,6.2937088,326.86069,-9.3152819
1905,1905,145.3703,12.523118,3.7022493,0.0,0,5.6553516,0.0,0.2832157,120.03575,6.2439122,326.69244,-9.315465
1907,1907,145.3707,12.560338,3.7595983,0.0,0,5.6097751,0.0,0.2875438,119.97257,6.1972513,326.52423,-9.3164349
1909,1909,145.3711,12.615284,3.799077,0.0,0,5.5656581,0.0,0.29202884,119.8229,6.1505213,326.35599,-9.316678
1911,1911,145.3715,12.685905,3.8435771,0.0,0,5.5222936,0.0,0.29551598,120.02142,6.1042714,326.18777,-9.3171968
1913,1913,145.3719,12.737455,3.8978133,0.0,0,5.4789333,0.0,0.30014464,120.07807,6.0565848,326.01953,-9.3167067
1915,1915,145.3723,12.79149,3.9349244,0.0,0,5.4355731,0.0,0.30434549,120.09615,6.0106735,325.85132,-9.3156281
1917,1917,145.3727,12.828111,3.9841511,0.0,0,5.3922133,0.0,0.30799493,120.01974,5.9631724,325.68307,-9.3154516
1919,1919,145.3731,12.867433,4.0347185,0.0,0,5.3488531,0.0,0.31282884,119.8376,5.9177856,325.51486,-9.3164234
1921,1921,145.3735,12.940159,4.0710778,0.0,0,5.3054934,0.0,0.31668985,119.9927,5.8736811,325.34662,-9.3161249
1923,1923,145.3739,13.027418,4.1228085,0.0,0,5.2621331,0.0,0.32049039,120.32871,5.8261471,325.17841,-9.3167448
1925,1925,145.3743,13.062036,4.1698213,0.0,0,5.2187734,0.0,0.32546851,120.04523,5.779861,325.07602,-9.3163919
1927,1927,145.3747,13.094335,4.2131462,0.0,0,5.1754136,0.0,0.32939789,119.88299,5.734479,324.9736,-9.3158903
1929,1929,145.3751,13.149541,4.2630239,0.0,0,5.1320534,0.0,0.33352897,119.88479,5.6853437,324.87122,-9.3157616
1931,1931,145.3755,13.234346,4.3057661,0.0,0,5.0886931,0.0,0.33843279,120.03489,5.6422834,324.7688,-9.316968
1933,1933,145.3759,13.308756,4.3529115,0.0,0,5.0457678,0.0,0.34228617,120.29664,5.5920291,324.66641,-9.3175116
1935,1935,145.3763,13.322314,4.3996649,0.0,0,5.0044241,0.0,0.34648654,119.95483,5.5484266,324.564,-9.3177805
1937,1937,145.3767,13.360602,4.4386144,0.0,0,4.9631839,0.0,0.35097599,119.70789,5.5030899,324.46161,-9.3167744
1939,1939,145.3771,13.432499,4.4896712,0.0,0,4.9219437,0.0,0.35487744,119.82937,5.4577413,324.35919,-9.3162603
1941,1941,145.3775,13.523581,4.5315628,0.0,0,4.8807039,0.0,0.35939577,120.14884,5.40905,324.25681,-9.3160973
1943,1943,145.3779,13.574006,4.5737219,0.0,0,4.8394637,0.0,0.36365235,120.12756,5.364327,324.15442,-9.3163595
1945,1945,145.3783,13.611441,4.6295023,0.0,0,4.798224,0.0,0.36798435,119.87697,5.31917,324.052,-9.3178282
1947,1947,145.3787,13.679436,4.6692467,0.0,0,4.7569838,0.0,0.37268409,119.90139,5.2751756,323.94962,-9.3185329
1949,1949,145.3791,13.743117,4.7146807,0.0,0,4.7157435,0.0,0.37695119,119.95428,5.2324471,323.8472,-9.3179579
1951,1951,145.3795,13.823997,4.7684426,0.0,0,4.6745038,0.0,0.38156471,120.14436,5.1884007,323.74481,-9.3163786
1953,1953,145.3799,13.872299,4.8050132,0.0,0,4.6332641,0.0,0.38614529,120.03749,5.1408672,323.6424,-9.3163671
1955,1955,145.3803,13.931006,4.8512464,0.0,0,4.5920234,0.0,0.39006835,120.04048,5.093554,323.54001,-9.3162451
1957,1957,145.3807,13.969457,4.9013929,0.0,0,4.5507836,0.0,0.3949036,119.79569,5.0504403,323.43759,-9.3174267
1959,1959,145.3811,14.03414,4.9393311,0.0,0,4.5108657,0.0,0.39947784,119.79444,5.0020585,323.33521,-9.316946
1961,1961,145.3815,14.110134,4.9859223,0.0,0,4.4716296,0.0,0.40317813,119.98695,4.9612288,323.23282,-9.3169327
1963,1963,145.3819,14.169462,5.033196,0.0,0,4.4323974,0.0,0.40842035,119.92369,4.9159098,323.1304,-9.3160572
1965,1965,145.3823,14.204756,5.0725875,0.0,0,4.3931651,0.0,0.41262072,119.72543,4.8710589,323.02802,-9.3160563
1967,1967,145.3827,14.260831,5.1201596,0.0,0,4.3539338,0.0,0.41666046,119.6566,4.8290615,322.9256,-9.3166323
1969,1969,145.3831,14.323343,5.1638703,0.0,0,4.3147016,0.0,0.42202082,119.52101,4.7845855,322.82321,-9.3166676
1971,1971,145.3835,14.420362,5.2037039,0.0,0,4.2754693,0.0,0.42562529,119.90479,4.7409635,322.72079,-9.3165016
1973,1973,145.3839,14.467391,5.249083,0.0,0,4.236237,0.0,0.42990452,119.87028,4.6973028,322.61841,-9.3152657
1975,1975,145.3843,14.502306,5.2884545,0.0,0,4.1970053,0.0,0.43488193,119.48775,4.6539106,322.60501,-9.3152103
1977,1977,145.3847,14.561737,5.3328953,0.0,0,4.1577735,0.0,0.4385044,119.52063,4.6100297,322.59158,-9.3165655
1979,1979,145.3851,14.633571,5.3754148,0.0,0,4.1185412,0.0,0.44320598,119.60573,4.5700421,322.57819,-9.3172989
1981,1981,145.3855,14.716664,5.4132218,0.0,0,4.0793095,0.0,0.44788188,119.70923,4.5238566,322.56476,-9.3172693
1983,1983,145.3859,14.773417,5.4646091,0.0,0,4.0404716,0.0,0.45201233,119.65498,4.4822907,322.55136,-9.3156528
1985,1985,145.3863,14.815995,5.5029831,0.0,0,4.0030656,0.0,0.45682237,119.40952,4.4410663,322.53796,-9.3158407
1987,1987,145.3867,14.896736,5.5400295,0.0,0,3.9657531,0.0,0.46075568,119.55743,4.3977504,322.52454,-9.3166218
1989,1989,145.3871,14.96064,5.5894237,0.0,0,3.928441,0.0,0.46508208,119.54529,4.3567462,322.51114,-9.3170061
1991,1991,145.3875,15.034219,5.6221943,0.0,0,3.8911293,0.0,0.46976104,119.58803,4.3141603,322.49771,-9.3162479
1993,1993,145.3879,15.089769,5.6625757,0.0,0,3.8538172,0.0,0.47345975,119.58887,4.2769704,322.48431,-9.3171558
1995,1995,145.3883,15.132727,5.7138686,0.0,0,3.8165052,0.0,0.47855899,119.35249,4.2324767,322.47092,-9.3175659
1997,1997,145.3887,15.179865,5.7451625,0.0,0,3.7791932,0.0,0.48310465,119.16451,4.196178,322.45749,-9.3171597
1999,1999,145.3891,15.246789,5.7865853,0.0,0,3.7418811,0.0,0.48661155,119.27986,4.1569128,322.44409,-9.3169565
2001,2001,145.3895,15.335347,5.8302894,0.0,0,3.7045693,0.0,0.49159482,119.35957,4.1143031,322.43066,-9.3155212
2003,2003,145.3899,15.4085,5.8608303,0.0,0,3.6672573,0.0,0.4955177,119.39104,4.0762882,322.41727,-9.3156557
2005,2005,145.3903,15.443518,5.9046898,0.0,0,3.629945,0.0,0.4993377,119.38155,4.0378866,322.40387,-9.316802
2007,2007,145.3907,15.497922,5.9463754,0.0,0,3.5926332,0.0,0.50471085,119.0776,3.9980893,322.39044,-9.3172531
2009,2009,145.3911,15.582376,5.9803281,0.0,0,3.5565164,0.0,0.50844783,119.25408,3.9589837,322.37704,-9.3171663
2011,2011,145.3915,15.672082,6.0226078,0.0,0,3.5210166,0.0,0.51239944,119.4561,3.9234564,322.36362,-9.3158073
2013,2013,145.3919,15.737318,6.0587096,0.0,0,3.4855206,0.0,0.51747465,119.39239,3.8841982,322.35022,-9.3155546
2015,2015,145.3923,15.760478,6.0963988,0.0,0,3.4500246,0.0,0.52100706,119.13121,3.8464262,322.33682,-9.3155613
2017,2017,145.3927,15.819454,6.1375175,0.0,0,3.4145288,0.0,0.52546275,119.04189,3.8071084,322.32339,-9.3163471
2019,2019,145.3931,15.916949,6.1711631,0.0,0,3.3790326,0.0,0.53031158,119.15562,3.7677355,322.31,-9.3161039
2021,2021,145.3935,16.012749,6.212553,0.0,0,3.3435366,0.0,0.5337972,119.49932,3.7284255,322.29657,-9.3163767
2023,2023,145.3939,16.060844,6.2479267,0.0,0,3.3080406,0.0,0.53832042,119.28668,3.693583,322.28317,-9.3156281
2025,2025,145.3943,16.104517,6.2786074,0.0,0,3.2725446,0.0,0.54252452,119.07585,3.6532199,322.31488,-9.315959
2027,2027,145.3947,16.178083,6.3264194,0.0,0,3.2370486,0.0,0.54642099,119.17784,3.6142488,322.34656,-9.3148727
2029,2029,145.3951,16.271656,6.3581753,0.0,0,3.2015524,0.0,0.55133092,119.33311,3.5807862,322.37827,-9.3150501
2031,2031,145.3955,16.361265,6.3934774,0.0,0,3.1660566,0.0,0.55519396,119.54317,3.5434334,322.40994,-9.3161335
2033,2033,145.3959,16.413845,6.4387693,0.0,0,3.1309149,0.0,0.5597055,119.38123,3.5099523,322.44165,-9.3155718
2035,2035,145.3963,16.469578,6.4642677,0.0,0,3.0970623,0.0,0.56398672,119.259,3.4728956,322.47336,-9.3157396
2037,2037,145.3967,16.544121,6.5002489,0.0,0,3.0632942,0.0,0.56742245,119.35021,3.4366241,322.50504,-9.3152351
2039,2039,145.3971,16.651691,6.5455399,0.0,0,3.0295262,0.0,0.57255805,119.51158,3.4004269,322.53674,-9.3151503
2041,2041,145.3975,16.739187,6.5746412,0.0,0,2.9957583,0.0,0.57691288,119.69636,3.3664882,322.56842,-9.3153706
2043,2043,145.3979,16.796093,6.615416,0.0,0,2.9619904,0.0,0.58077759,119.62173,3.3291121,322.60013,-9.3149729
2045,2045,145.3983,16.854351,6.6539273,0.0,0,2.9282222,0.0,0.58602929,119.39377,3.2919261,322.63184,-9.3149071
2047,2047,145.3987,16.940342,6.6810827,0.0,0,2.894454,0.0,0.58955956,119.53233,3.255075,322.66351,-9.3153038
2049,2049,145.3991,17.059893,6.7215815,0.0,0,2.8606861,0.0,0.59327531,119.93015,3.2196164,322.69522,-9.3158112
2051,2051,145.3995,17.149906,6.7564597,0.0,0,2.8269181,0.0,0.59873629,119.88099,3.185118,322.7269,-9.3165369
2053,2053,145.3999,17.200579,6.7909679,0.0,0,2.7931502,0.0,0.60239667,119.88089,3.1477704,322.75861,-9.3150082
2055,2055,145.4003,17.262848,6.8302002,0.0,0,2.7593822,0.0,0.60669714,119.74873,3.1121526,322.79031,-9.3154163
2057,2057,145.4007,17.351881,6.8618321,0.0,0,2.7256143,0.0,0.61182475,119.77294,3.0804,322.82199,-9.3140678
2059,2059,145.4011,17.465851,6.8989086,0.0,0,2.6929309,0.0,0.61534607,120.08518,3.0421948,322.8537,-9.3149223
2061,2061,145.4015,17.556585,6.9349141,0.0,0,2.6608074,0.0,0.61986548,120.16966,3.0081859,322.88538,-9.3155222
2063,2063,145.4019,17.614149,6.9637375,0.0,0,2.6286871,0.0,0.62439066,120.03992,2.9705379,322.91708,-9.3162527
2065,2065,145.4023,17.696354,7.0054159,0.0,0,2.5965672,0.0,0.62814254,120.15311,2.9375789,322.94879,-9.3153706
2067,2067,145.4027,17.795132,7.0361338,0.0,0,2.5644472,0.0,0.63289165,120.26772,2.903379,322.98047,-9.3149099
2069,2069,145.4031,17.893526,7.068398,0.0,0,2.5323269,0.0,0.63719696,120.43374,2.8690956,323.01218,-9.3142776
2071,2071,145.4035,17.979727,7.1134539,0.0,0,2.5002072,0.0,0.64152187,120.48254,2.8354032,323.04385,-9.3149548
2073,2073,145.4039,18.052494,7.1392403,0.0,0,2.4680872,0.0,0.64629155,120.3997,2.7994337,323.07556,-9.31637
2075,2075,145.4043,18.140839,7.1724176,0.0,0,2.4359672,0.0,0.64986616,120.52869,2.7663579,323.0108,-9.316268
2077,2077,145.4047,18.234108,7.2155652,0.0,0,2.4038472,0.0,0.65469414,120.60695,2.7325838,322.94608,-9.3149719
2079,2079,145.4051,18.341936,7.2386312,0.0,0,2.3717272,0.0,0.65922678,120.77708,2.6971307,322.88132,-9.3136158
2081,2081,145.4055,18.451185,7.2738652,0.0,0,2.339607,0.0,0.66256851,121.06746,2.6656992,322.81656,-9.3134556
2083,2083,145.4059,18.542044,7.3149629,0.0,0,2.3078086,0.0,0.66801286,120.94572,2.6324184,322.75183,-9.3132858
2085,2085,145.4063,18.622263,7.3411517,0.0,0,2.2771802,0.0,0.67238951,120.99354,2.5971603,322.68707,-9.3148432
2087,2087,145.4067,18.714945,7.378541,0.0,0,2.2466278,0.0,0.6759463,121.16376,2.5635591,322.62234,-9.3158035
2089,2089,145.4071,18.827759,7.4125466,0.0,0,2.2160761,0.0,0.681346,121.23253,2.5304093,322.55759,-9.3142042
2091,2091,145.4075,18.940277,7.4398437,0.0,0,2.185524,0.0,0.6850841,121.50343,2.4985704,322.49283,-9.3144855
2093,2093,145.4079,19.025364,7.4768815,0.0,0,2.1549721,0.0,0.68908072,121.56489,2.4656985,322.4281,-9.3139839
2095,2095,145.4083,19.10516,7.5095458,0.0,0,2.1244199,0.0,0.69472587,121.39521,2.431093,322.36334,-9.3133707
2097,2097,145.4087,19.206116,7.544147,0.0,0,2.093868,0.0,0.69852763,121.56441,2.3975189,322.29858,-9.3137741
2099,2099,145.4091,19.338058,7.57829,0.0,0,2.0633161,0.0,0.70278776,121.8984,2.3667796,322.23386,-9.3139029
2101,2101,145.4095,19.454262,7.6041117,0.0,0,2.0327642,0.0,0.70764065,122.00742,2.3335938,322.1691,-9.3137665
2103,2103,145.4099,19.531229,7.641511,0.0,0,2.002212,0.0,0.71116233,122.07722,2.2989807,322.10434,-9.3138466
2105,2105,145.4103,19.617783,7.6731443,0.0,0,1.9716599,0.0,0.71604997,122.00712,2.2654564,322.03961,-9.3151197
2107,2107,145.4107,19.726837,7.6990733,0.0,0,1.941108,0.0,0.72043645,122.13141,2.235858,321.97485,-9.3150368
2109,2109,145.4111,19.863373,7.7406812,0.0,0,1.9115354,0.0,0.72427279,122.49981,2.2043438,321.9101,-9.3135185
2111,2111,145.4115,19.970875,7.7676415,0.0,0,1.8824683,0.0,0.72948164,122.53248,2.1688139,321.84537,-9.3137283
2113,2113,145.4119,20.051792,7.797596,0.0,0,1.8534042,0.0,0.73339695,122.55772,2.139034,321.78061,-9.3138609
2115,2115,145.4123,20.146982,7.8395181,0.0,0,1.8243402,0.0,0.73810923,122.59919,2.1070235,321.71588,-9.3147774
2117,2117,145.4127,20.276707,7.8603716,0.0,0,1.7952763,0.0,0.74276739,122.76019,2.0751493,321.65112,-9.3139267
2119,2119,145.4131,20.413696,7.8905926,0.0,0,1.7662122,0.0,0.74598134,123.1749,2.0449827,321.58636,-9.313468
2121,2121,145.4135,20.508448,7.9295425,0.0,0,1.7371483,0.0,0.75101763,123.20075,2.0138624,321.52164,-9.3140793
2123,2123,145.4139,20.597237,7.949862,0.0,0,1.7080842,0.0,0.75544184,123.15569,1.9822322,321.45688,-9.3138285
2125,2125,145.4143,20.698345,7.9839187,0.0,0,1.6790203,0.0,0.75873071,123.35014,1.9529116,320.63327,-9.3139915
2127,2127,145.4147,20.839218,8.0208025,0.0,0,1.6499562,0.0,0.76457232,123.41663,1.922138,319.80966,-9.3132858
2129,2129,145.4151,20.980247,8.0449371,0.0,0,1.6208922,0.0,0.76872987,123.7693,1.8913225,318.98605,-9.3128223
2131,2131,145.4155,21.082993,8.0800076,0.0,0,1.5918282,0.0,0.7724542,123.93645,1.8603041,318.16245,-9.3120584
2133,2133,145.4159,21.173475,8.1071806,0.0,0,1.5630547,0.0,0.77789056,123.78534,1.8322023,317.33887,-9.3133183
2135,2135,145.4163,21.297792,8.1330299,0.0,0,1.5353372,0.0,0.78106576,124.11198,1.8005759,316.51526,-9.3120689
2137,2137,145.4167,21.426689,8.1659994,0.0,0,1.5076891,0.0,0.78522855,124.28656,1.7745905,315.69165,-9.3128653
2139,2139,145.4171,21.566141,8.1928225,0.0,0,1.4800411,0.0,0.79059416,124.45746,1.7421864,314.86804,-9.3122501
2141,2141,145.4175,21.667353,8.2246847,0.0,0,1.4523932,0.0,0.79388964,124.67791,1.7159892,314.04443,-9.3117523
2143,2143,145.4179,21.772547,8.2566099,0.0,0,1.4247452,0.0,0.79871941,124.64861,1.6855667,313.22083,-9.3121338
2145,2145,145.4183,21.894598,8.2801752,0.0,0,1.3970972,0.0,0.80351734,124.72705,1.6571569,312.39725,-9.312974
2147,2147,145.4187,22.035976,8.3160553,0.0,0,1.3694493,0.0,0.80708379,125.09177,1.6284248,311.57364,-9.3132505
2149,2149,145.4191,22.181374,8.3417406,0.0,0,1.3418012,0.0,0.81202191,125.30495,1.5981072,310.75003,-9.3132849
2151,2151,145.4195,22.28841,8.3652105,0.0,0,1.3141533,0.0,0.81579858,125.48499,1.572119,309.92642,-9.3126621
2153,2153,145.4199,22.388432,8.4035549,0.0,0,1.2865052,0.0,0.81998444,125.47961,1.5410328,309.10281,-9.3118277
2155,2155,145.4203,22.530464,8.4243622,0.0,0,1.2588573,0.0,0.82480949,125.6718,1.5114324,308.27921,-9.3123846
2157,2157,145.4207,22.680655,8.4509125,0.0,0,1.2312093,0.0,0.82827151,126.0499,1.4806377,307.45563,-9.3129444
2159,2159,145.4211,22.825773,8.4885559,0.0,0,1.2044512,0.0,0.83321279,126.26215,1.4546226,306.63202,-9.3137951
2161,2161,145.4215,22.941534,8.5074644,0.0,0,1.1781523,0.0,0.8380295,126.31355,1.4251237,305.80841,-9.3133621
2163,2163,145.4219,23.063648,8.5383177,0.0,0,1.1518563,0.0,0.84117007,126.55089,1.3995564,304.9848,-9.3132677
2165,2165,145.4223,23.194376,8.5740061,0.0,0,1.1255603,0.0,0.84684658,126.55535,1.369543,304.16119,-9.311614
2167,2167,145.4227,23.347811,8.592267,0.0,0,1.0992643,0.0,0.85093725,126.86691,1.3419316,303.33759,-9.3118219
2169,2169,145.4231,23.499573,8.6243076,0.0,0,1.0729682,0.0,0.85429436,127.23478,1.3130831,302.51398,-9.3122597
2171,2171,145.4235,23.62023,8.652379,0.0,0,1.0466722,0.0,0.85987389,127.21339,1.2860245,301.6904,-9.3124828
2173,2173,145.4239,23.75305,8.6736116,0.0,0,1.0203762,0.0,0.86329812,127.4666,1.2585198,300.86679,-9.3124094
2175,2175,145.4243,23.900908,8.7064695,0.0,0,0.99408025,0.0,0.86730188,127.75261,1.230572,300.74936,-9.3129091
2177,2177,145.4247,24.059282,8.7331295,0.0,0,0.96778423,0.0,0.87320042,127.82459,1.2037474,300.63193,-9.312047
2179,2179,145.4251,24.217943,8.7589808,0.0,0,0.94148827,0.0,0.87639606,128.23926,1.1771668,300.5145,-9.3113537
2181,2181,145.4255,24.339729,8.7887669,0.0,0,0.91519231,0.0,0.88073868,128.3896,1.1507592,300.39706,-9.3114071
2183,2183,145.4259,24.479109,8.808815,0.0,0,0.88916039,0.0,0.88564044,128.50061,1.1230457,300.27963,-9.312067
2185,2185,145.4263,24.62546,8.8407145,0.0,0,0.86408937,0.0,0.88882113,128.80605,1.094834,300.1622,-9.3126554
2187,2187,145.4267,24.790684,8.8667841,0.0,0,0.83908123,0.0,0.89375216,129.02565,1.0684508,300.0448,-9.3118706
2189,2189,145.4271,24.945194,8.8884993,0.0,0,0.8140732,0.0,0.89833122,129.26067,1.0431947,299.92737,-9.3111038
2191,2191,145.4275,25.07736,8.9246111,0.0,0,0.78906524,0.0,0.90217769,129.49043,1.0101575,299.80994,-9.3095074
2193,2193,145.4279,25.213358,8.9452868,0.0,0,0.76405728,0.0,0.90732068,129.53345,0.98747379,299.6925,-9.310462
2195,2195,145.4283,25.356037,8.9664116,0.0,0,0.73904926,0.0,0.91066867,129.79373,0.95731592,299.57507,-9.3118448
2197,2197,145.4287,25.535978,9.0022879,0.0,0,0.71404123,0.0,0.91489083,130.16277,0.93408108,299.45764,-9.3119078
2199,2199,145.4291,25.716579,9.0179596,0.0,0,0.68903327,0.0,0.9198187,130.39653,0.90653414,299.34021,-9.3106146
2201,2201,145.4295,25.860893,9.0444326,0.0,0,0.66402531,0.0,0.92320186,130.70123,0.88128966,299.22278,-9.3098593
2203,2203,145.4299,25.987467,9.0781479,0.0,0,0.63901722,0.0,0.92816722,130.74945,0.85592419,299.10535,-9.3098183
2205,2205,145.4303,26.154758,9.0926218,0.0,0,0.61400926,0.0,0.93247521,130.94514,0.83080274,298.98792,-9.3108091
2207,2207,145.4307,26.333244,9.1211748,0.0,0,0.58900124,0.0,0.93534404,131.48131,0.80394095,298.87048,-9.3102179
2209,2209,145.4311,26.499197,9.15096,0.0,0,0.56478834,0.0,0.94126165,131.53671,0.77942771,298.75305,-9.310688
2211,2211,145.4315,26.637079,9.1664352,0.0,0,0.54098582,0.0,0.94482154,131.78204,0.75453955,298.63562,-9.3105431
2213,2213,145.4319,26.771227,9.1953545,0.0,0,0.51718581,0.0,0.94793046,132.01913,0.73261178,298.51822,-9.3101807
2215,2215,145.4323,26.934269,9.2207136,0.0,0,0.49338579,0.0,0.95399618,131.99591,0.70752686,298.40079,-9.3103876
2217,2217,145.4327,27.119635,9.2409487,0.0,0,0.46958581,0.0,0.95704371,132.53941,0.68092924,298.28336,-9.3107033
2219,2219,145.4331,27.296324,9.269846,0.0,0,0.44578579,0.0,0.96108031,132.84827,0.66021168,298.16592,-9.3110304
2221,2221,145.4335,27.427204,9.2887049,0.0,0,0.42198581,0.0,0.96636075,132.81094,0.63359761,298.04849,-9.3102016
2223,2223,145.4339,27.584877,9.3120928,0.0,0,0.39818579,0.0,0.96880972,133.22058,0.60834831,297.93106,-9.3094444
2225,2225,145.4343,27.765734,9.3374043,0.0,0,0.37438577,0.0,0.97330874,133.45171,0.58645308,298.74979,-9.3094797
2227,2227,145.4347,27.951742,9.3541355,0.0,0,0.35058579,0.0,0.97799361,133.74738,0.5659852,299.56851,-9.3100758
2229,2229,145.4351,28.112759,9.3849621,0.0,0,0.3267858,0.0,0.98117536,134.13556,0.54316902,300.38724,-9.3109131