File: clean data/testID_0207.csv
level_0,index,Time(sec),Force(kN),Jaw(mm),PowAngle(deg),Power(W),Pram,PTemp,Strain,Stress(MPa),Stroke(mm),TC1(C),wedge(mm)
1972,1972,165.3484,0.44321486,0.024256613,0.0,0,9.0629702,0.0,0.0016815994,4.7608452,10.106321,360.15503,-9.2895823
1974,1974,165.3488,3.0472307,0.066672489,0.0,0,9.0044422,0.0,0.0040580686,34.153854,10.04432,360.3887,-9.2883749
1976,1976,165.3492,5.3251891,0.1234983,0.0,0,8.9459143,0.0,0.0077787796,65.74115,9.9846611,360.62241,-9.2877607
1978,1978,165.3496,5.8598194,0.19545016,0.0,0,8.8873863,0.0,0.01254996,73.070984,9.9096823,360.85608,-9.2855835
1980,1980,165.35,6.3559127,0.33408934,0.0,0,8.8288584,0.0,0.021562841,78.861031,9.8202105,361.08978,-9.2852793
1982,1982,165.3504,6.7532268,0.4228273,0.0,0,8.7703304,0.0,0.028022368,82.927849,9.7142582,361.32346,-9.2854424
1984,1984,165.3508,7.1754136,0.52340394,0.0,0,8.7136879,0.0,0.034981746,87.827255,9.6121511,361.55716,-9.2847252
1986,1986,165.3512,7.6916022,0.58355552,0.0,0,8.6580172,0.0,0.0392453,93.830872,9.5210705,361.79083,-9.28337
1988,1988,165.3516,7.3552794,0.63556141,0.0,0,8.6023531,0.0,0.042932745,90.315674,9.4437933,362.02454,-9.2825117
1990,1990,165.352,7.5533824,0.71087867,0.0,0,8.546689,0.0,0.048218839,90.847496,9.3724689,362.25824,-9.28403
1992,1992,165.3524,7.9465537,0.75763011,0.0,0,8.4910259,0.0,0.051278651,95.915939,9.3019762,362.49191,-9.2839632
1994,1994,165.3528,8.2363338,0.84413284,0.0,0,8.4353609,0.0,0.057443496,98.77372,9.2264719,362.72562,-9.2831926
1996,1996,165.3532,7.9450746,0.93958265,0.0,0,8.3796968,0.0,0.064012811,95.491974,9.1421967,362.95929,-9.2830572
1998,1998,165.3536,7.9426522,1.0257906,0.0,0,8.3240337,0.0,0.070040345,93.834755,9.0571651,363.19299,-9.2827406
2000,2000,165.354,8.1679611,1.0993704,0.0,0,8.2683697,0.0,0.07598377,96.455536,8.974906,363.42667,-9.2829618
2002,2002,165.3544,8.2558222,1.1450454,0.0,0,8.2127056,0.0,0.078864023,96.714462,8.9060841,363.66037,-9.2835903
2004,2004,165.3548,8.4161739,1.1965483,0.0,0,8.1570415,0.0,0.082665622,98.924438,8.8447857,363.89404,-9.2838783
2006,2006,165.3552,8.1483154,1.255556,0.0,0,8.1013775,0.0,0.087267749,94.983879,8.7896204,364.12775,-9.2836943
2008,2008,165.3556,8.5948286,1.3130916,0.0,0,8.0462685,0.0,0.090760298,99.558968,8.7287111,364.36145,-9.2827454
2010,2010,165.356,8.5506792,1.3920362,0.0,0,7.993176,0.0,0.096849404,98.928093,8.6632166,364.59512,-9.2816334
2012,2012,165.3564,8.6222706,1.4652716,0.0,0,7.9402156,0.0,0.10235944,99.077942,8.5945187,364.82883,-9.2821856
2014,2014,165.3568,8.4212303,1.5433496,0.0,0,7.8872557,0.0,0.10764617,96.509872,8.5245094,365.0625,-9.2823133
2016,2016,165.3572,8.6098289,1.5907166,0.0,0,7.8342957,0.0,0.11209244,97.644272,8.4594679,365.2962,-9.2820549
2018,2018,165.3576,8.6613569,1.6262712,0.0,0,7.7813354,0.0,0.11431484,98.470779,8.4037962,365.52988,-9.281703
2020,2020,165.358,8.7036228,1.6877396,0.0,0,7.7283754,0.0,0.11873,98.37989,8.3536491,365.76358,-9.2823277
2022,2022,165.3584,8.6906223,1.7274815,0.0,0,7.675415,0.0,0.12235446,97.9505,8.3045483,366.00967,-9.2820148
2024,2024,165.3588,8.9012909,1.7779872,0.0,0,7.6224551,0.0,0.12553848,99.601799,8.25175,366.29294,-9.2826509
2026,2026,165.3592,8.9194393,1.8482152,0.0,0,7.5694952,0.0,0.13105857,99.814392,8.1905918,366.5762,-9.2817764
2028,2028,165.3596,8.8889313,1.8994547,0.0,0,7.5165353,0.0,0.13521904,98.710884,8.1325989,366.85947,-9.2814302
2030,2030,165.36,8.885541,1.9652786,0.0,0,7.4635754,0.0,0.13969126,98.542267,8.0715151,367.14273,-9.2814646
2032,2032,165.3604,8.9229069,2.0104587,0.0,0,7.410615,0.0,0.14386317,98.05558,8.0141954,367.42599,-9.2820749
2034,2034,165.3608,9.0881577,2.0472865,0.0,0,7.3593612,0.0,0.14638644,99.964958,7.965064,367.70926,-9.2831478
2036,2036,165.3612,8.9483576,2.1029119,0.0,0,7.3089881,0.0,0.15047553,98.034714,7.91607,367.99252,-9.2824783
2038,2038,165.3616,9.0558729,2.1419168,0.0,0,7.2586198,0.0,0.15414396,98.711166,7.8695912,368.27579,-9.2829952
2040,2040,165.362,9.1086731,2.192188,0.0,0,7.2082515,0.0,0.15739486,98.973694,7.8221798,368.55905,-9.2814198
2042,2042,165.3624,9.2690182,2.2475019,0.0,0,7.1578832,0.0,0.16181456,100.19614,7.7704759,368.84232,-9.2809095
2044,2044,165.3628,9.1736946,2.2985415,0.0,0,7.1075153,0.0,0.16622587,99.041634,7.7188311,369.12561,-9.2821007
2046,2046,165.3632,9.1578503,2.3610089,0.0,0,7.0571475,0.0,0.17053859,98.352936,7.6653085,369.40887,-9.2818546
2048,2048,165.3636,9.216115,2.3968973,0.0,0,7.0067792,0.0,0.17389069,98.529663,7.6166005,369.69214,-9.2832041
2050,2050,165.364,9.336235,2.4366903,0.0,0,6.9564114,0.0,0.17712376,99.531715,7.572196,369.9754,-9.2834215
2052,2052,165.3644,9.3072815,2.491873,0.0,0,6.9060431,0.0,0.18089674,98.987343,7.5241342,370.25867,-9.2820177
2054,2054,165.3648,9.3430395,2.5248406,0.0,0,6.8556757,0.0,0.18430498,98.784981,7.4781222,370.54193,-9.2819271
2056,2056,165.3652,9.4165001,2.5769269,0.0,0,6.8053074,0.0,0.18803242,99.302841,7.4330316,370.8252,-9.2830963
2058,2058,165.3656,9.4802933,2.6335144,0.0,0,6.7554417,0.0,0.19228423,99.590477,7.3861332,371.10846,-9.2832775
2060,2060,165.366,9.4841452,2.6781933,0.0,0,6.7074022,0.0,0.19659261,99.177246,7.337863,371.39172,-9.2825327
2062,2062,165.3664,9.4819174,2.7271075,0.0,0,6.6594815,0.0,0.20011319,98.758812,7.286345,371.67499,-9.2816906
2064,2064,165.3668,9.5818014,2.7730591,0.0,0,6.6115613,0.0,0.2038762,99.444443,7.2372785,371.95825,-9.2816715
2066,2066,165.3672,9.6183491,2.8124509,0.0,0,6.5636415,0.0,0.20759271,99.556038,7.1893334,372.24152,-9.2832136
2068,2068,165.3676,9.6308975,2.8604319,0.0,0,6.5157218,0.0,0.21090464,99.323639,7.1421566,372.52481,-9.2833881
2070,2070,165.368,9.6896219,2.9085116,0.0,0,6.467802,0.0,0.215261,99.398499,7.0965343,372.80807,-9.283391
2072,2072,165.3684,9.7816114,2.9541764,0.0,0,6.4198818,0.0,0.21915603,99.909599,7.0527453,372.94269,-9.2817497
2074,2074,165.3688,9.8239279,3.0074162,0.0,0,6.3719616,0.0,0.22302163,100.06963,6.9982605,372.63141,-9.2829065
2076,2076,165.3692,9.8272829,3.0587838,0.0,0,6.3240418,0.0,0.22793187,99.595459,6.9519668,372.32013,-9.2820625
2078,2078,165.3696,9.8204632,3.10343,0.0,0,6.2761221,0.0,0.23151532,99.166313,6.9012356,372.00888,-9.2832956
2080,2080,165.37,9.9240055,3.148185,0.0,0,6.2282019,0.0,0.23490967,99.775589,6.8538632,371.6976,-9.2831802
2082,2082,165.3704,9.9888058,3.1928425,0.0,0,6.1802821,0.0,0.23939657,99.971939,6.8066368,371.38632,-9.2827854
2084,2084,165.3708,10.007228,3.2415082,0.0,0,6.1339049,0.0,0.24284668,99.990791,6.7566142,371.07504,-9.282795
2086,2086,165.3712,10.029976,3.290415,0.0,0,6.0883236,0.0,0.24709098,99.660408,6.7101092,370.76379,-9.2830544
2088,2088,165.3716,10.081161,3.3351107,0.0,0,6.042748,0.0,0.25147316,99.72155,6.6626582,370.45251,-9.283124
2090,2090,165.372,10.171479,3.390743,0.0,0,5.9971719,0.0,0.25542736,100.26732,6.6140304,370.14124,-9.2827435
2092,2092,165.3724,10.209881,3.4392068,0.0,0,5.9515953,0.0,0.2600815,100.23639,6.5652857,369.82996,-9.2822275
2094,2094,165.3728,10.224125,3.4823086,0.0,0,5.9060202,0.0,0.26393917,99.989082,6.5163112,369.51871,-9.2829056
2096,2096,165.3732,10.264509,3.5384333,0.0,0,5.8604436,0.0,0.26806059,99.93531,6.4685965,369.20743,-9.282403
2098,2098,165.3736,10.312131,3.5798297,0.0,0,5.8148675,0.0,0.27258676,100.00195,6.4179163,368.89615,-9.2830944
2100,2100,165.374,10.387546,3.6264608,0.0,0,5.7692914,0.0,0.27624151,100.29845,6.3684149,368.58487,-9.2830143
2102,2102,165.3744,10.429181,3.6844671,0.0,0,5.7237153,0.0,0.28104162,100.1817,6.3228321,368.27359,-9.2833748
2104,2104,165.3748,10.463237,3.7215452,0.0,0,5.6781397,0.0,0.28519005,100.15463,6.2721109,367.96234,-9.2832832
2106,2106,165.3752,10.494476,3.7713394,0.0,0,5.6325636,0.0,0.28888747,100.05312,6.2222261,367.65106,-9.2838402
2108,2108,165.3756,10.552784,3.8265836,0.0,0,5.5874419,0.0,0.29397562,100.13654,6.1772671,367.33978,-9.2838745
2110,2110,165.376,10.612677,3.8667319,0.0,0,5.5439739,0.0,0.29802915,100.22066,6.1299601,367.0285,-9.2836571
2112,2112,165.3764,10.667119,3.9195356,0.0,0,5.5006137,0.0,0.30203128,100.36957,6.080924,366.71725,-9.2830238
2114,2114,165.3768,10.691205,3.9683828,0.0,0,5.4572535,0.0,0.30708256,100.10198,6.0307651,366.40598,-9.2832499
2116,2116,165.3772,10.725204,4.0108476,0.0,0,5.4138937,0.0,0.31090191,100.0118,5.983459,366.0947,-9.2839756
2118,2118,165.3776,10.783994,4.0641418,0.0,0,5.3705335,0.0,0.31525007,100.10414,5.9367003,365.78342,-9.2834826
2120,2120,165.378,10.857932,4.1107297,0.0,0,5.3271737,0.0,0.32026148,100.23144,5.8855767,365.47217,-9.2830706
2122,2122,165.3784,10.897891,4.1583166,0.0,0,5.2838135,0.0,0.32412994,100.35613,5.8404322,365.10785,-9.28339
2124,2124,165.3788,10.924113,4.2064633,0.0,0,5.2404532,0.0,0.32842547,100.12989,5.7886477,364.58441,-9.2833242
2126,2126,165.3792,10.964886,4.2500553,0.0,0,5.1970935,0.0,0.3332586,99.986206,5.7409377,364.061,-9.283721
2128,2128,165.3796,11.023153,4.3027864,0.0,0,5.1537337,0.0,0.33728138,100.10748,5.6945906,363.53757,-9.2836847
2130,2130,165.38,11.095766,4.3484926,0.0,0,5.1103735,0.0,0.34188408,100.3434,5.6455112,363.01413,-9.2817984
2132,2132,165.3804,11.131657,4.3925133,0.0,0,5.0670133,0.0,0.34644854,100.19713,5.5960102,362.49072,-9.2821465
2134,2134,165.3808,11.16497,4.4473038,0.0,0,5.0250487,0.0,0.35069445,100.0143,5.551826,361.96729,-9.2840738
2136,2136,165.3812,11.205388,4.4884334,0.0,0,4.9838042,0.0,0.35531241,99.96479,5.5054722,361.44388,-9.2843237
2138,2138,165.3816,11.26604,4.5329304,0.0,0,4.942564,0.0,0.35947949,100.059,5.4570346,360.92044,-9.2833996
2140,2140,165.382,11.321702,4.5876031,0.0,0,4.9013243,0.0,0.36411098,100.16965,5.4104691,360.397,-9.2825146
2142,2142,165.3824,11.35834,4.6270018,0.0,0,4.8600841,0.0,0.36886221,100.00156,5.3642826,359.8736,-9.2821989
2144,2144,165.3828,11.378335,4.6727886,0.0,0,4.8188443,0.0,0.37274379,99.760368,5.3152947,359.35016,-9.2827015
2146,2146,165.3832,11.431341,4.7257094,0.0,0,4.7776041,0.0,0.37754968,99.753494,5.2707191,358.82675,-9.2827816
2148,2148,165.3836,11.486151,4.7636375,0.0,0,4.7363639,0.0,0.38209087,99.775002,5.2250066,358.30331,-9.283556
2150,2150,165.384,11.552513,4.8123431,0.0,0,4.6951241,0.0,0.38602418,100.02355,5.1792192,357.77988,-9.2828722
2152,2152,165.3844,11.588263,4.8627076,0.0,0,4.6538844,0.0,0.39134598,99.684235,5.1338711,357.25647,-9.282156
2154,2154,165.3848,11.628441,4.8992991,0.0,0,4.6126437,0.0,0.39534214,99.654526,5.0875683,356.73303,-9.2819538
2156,2156,165.3852,11.666703,4.9483528,0.0,0,4.571404,0.0,0.39934915,99.613213,5.047173,356.20963,-9.2830772
2158,2158,165.3856,11.731062,4.9930048,0.0,0,4.5305758,0.0,0.40470091,99.510933,5.0000901,355.68619,-9.2836037
2160,2160,165.386,11.78159,5.0365887,0.0,0,4.4912457,0.0,0.40875325,99.639008,4.9547443,355.16275,-9.2837381
2162,2162,165.3864,11.812115,5.0833449,0.0,0,4.4520135,0.0,0.4130016,99.514618,4.9133492,354.63934,-9.2829027
2164,2164,165.3868,11.8498,5.1240106,0.0,0,4.4127817,0.0,0.41809675,99.306625,4.8640232,354.11591,-9.2820539
2166,2166,165.3872,11.889773,5.1677098,0.0,0,4.3735499,0.0,0.42172849,99.264702,4.8234348,353.5925,-9.2830591
2168,2168,165.3876,11.94761,5.2117047,0.0,0,4.3343177,0.0,0.4261927,99.292854,4.7792878,353.06906,-9.2830982
2170,2170,165.388,12.022843,5.2510982,0.0,0,4.2950859,0.0,0.43104583,99.398422,4.737082,352.54562,-9.2823076
2172,2172,165.3884,12.051209,5.2997961,0.0,0,4.2558532,0.0,0.43499154,99.337029,4.6959882,352.16672,-9.2825994
2174,2174,165.3888,12.07388,5.3395653,0.0,0,4.2166214,0.0,0.43964177,99.091667,4.6561069,352.22125,-9.2824106
2176,2176,165.3892,12.12467,5.3768935,0.0,0,4.1773896,0.0,0.44393906,98.984787,4.6082249,352.27582,-9.2827301
2178,2178,165.3896,12.178336,5.4271994,0.0,0,4.1381574,0.0,0.44796023,99.032166,4.5686154,352.33035,-9.2834969
2180,2180,165.39,12.249639,5.4623094,0.0,0,4.0989256,0.0,0.45259249,99.134254,4.5244641,352.38492,-9.2838888
2182,2182,165.3904,12.287881,5.5010672,0.0,0,4.0596938,0.0,0.45645207,99.143379,4.4859366,352.43948,-9.2838621
2184,2184,165.3908,12.318392,5.5496821,0.0,0,4.0217257,0.0,0.46102723,98.921127,4.4433184,352.49402,-9.2830648
2186,2186,165.3912,12.371579,5.5813527,0.0,0,3.9844093,0.0,0.46543425,98.866875,4.4030333,352.54858,-9.2828979
2188,2188,165.3916,12.434897,5.6255403,0.0,0,3.9470973,0.0,0.46933556,98.991104,4.3614368,352.60312,-9.2823744
2190,2190,165.392,12.498688,5.6721482,0.0,0,3.9097853,0.0,0.47437075,98.968102,4.3198814,352.65768,-9.2829113
2192,2192,165.3924,12.538792,5.7036428,0.0,0,3.8724735,0.0,0.47855037,98.920479,4.2796984,352.71222,-9.2832584
2194,2194,165.3928,12.563729,5.7450786,0.0,0,3.8351612,0.0,0.48210585,98.702316,4.243217,352.76678,-9.2823973
2196,2196,165.3932,12.620973,5.7858634,0.0,0,3.7978494,0.0,0.48698133,98.673607,4.2016096,352.82132,-9.2818689
2198,2198,165.3936,12.687029,5.8191757,0.0,0,3.7605371,0.0,0.49081567,98.825806,4.1617618,352.87589,-9.2802534
2200,2200,165.394,12.748721,5.8631048,0.0,0,3.7232254,0.0,0.49478915,98.953629,4.1230655,352.93042,-9.2811308
2202,2202,165.3944,12.789682,5.9015837,0.0,0,3.6859133,0.0,0.49995929,98.774284,4.0849948,352.98499,-9.2828407
2204,2204,165.3948,12.811005,5.937645,0.0,0,3.6486013,0.0,0.50355059,98.548492,4.0477734,353.03952,-9.283555
2206,2206,165.3952,12.867221,5.9786286,0.0,0,3.6112893,0.0,0.50771433,98.597168,4.008039,353.09409,-9.2833443
2208,2208,165.3956,12.95612,6.013617,0.0,0,3.5743496,0.0,0.5125286,98.744553,3.9705925,353.14862,-9.2824326
2210,2210,165.396,13.012402,6.0533061,0.0,0,3.538765,0.0,0.51602173,98.828255,3.9333777,353.20319,-9.2817202
2212,2212,165.3964,13.04421,6.0898609,0.0,0,3.5032687,0.0,0.52031565,98.704765,3.8984487,353.25772,-9.2815037
2214,2214,165.3968,13.076921,6.1223011,0.0,0,3.4677727,0.0,0.52472824,98.472702,3.8604388,353.31229,-9.2814369
2216,2216,165.3972,13.142976,6.1674824,0.0,0,3.432277,0.0,0.5286023,98.554527,3.8248439,353.36682,-9.2813606
2218,2218,165.3976,13.22668,6.2029686,0.0,0,3.3967807,0.0,0.53336453,98.70652,3.7845669,353.42139,-9.2826881
2220,2220,165.398,13.280515,6.2370319,0.0,0,3.3612847,0.0,0.53754056,98.768906,3.747927,353.47592,-9.2831621
2222,2222,165.3984,13.313065,6.2825799,0.0,0,3.3257887,0.0,0.54158062,98.599983,3.7138617,353.49466,-9.282897
2224,2224,165.3988,13.356668,6.309782,0.0,0,3.2902927,0.0,0.54592323,98.515274,3.6772072,353.40594,-9.2813339
2226,2226,165.3992,13.433819,6.3428965,0.0,0,3.2547965,0.0,0.54928988,98.716537,3.6391056,353.3172,-9.2822504
2228,2228,165.3996,13.512396,6.3879032,0.0,0,3.2193007,0.0,0.55384713,98.885834,3.6041636,353.22849,-9.2826033
2230,2230,165.4,13.567795,6.4182301,0.0,0,3.1838048,0.0,0.55857074,98.788101,3.5665123,353.13974,-9.2832699
2232,2232,165.4004,13.620713,6.4585977,0.0,0,3.1483088,0.0,0.56230372,98.767021,3.5316668,353.05103,-9.2832413
2234,2234,165.4008,13.664595,6.5011516,0.0,0,3.11395,0.0,0.56740445,98.620926,3.493634,352.96228,-9.2828836
2236,2236,165.4012,13.737769,6.5281234,0.0,0,3.0801783,0.0,0.57143569,98.756355,3.4573448,352.87357,-9.2815914
2238,2238,165.4016,13.817574,6.5650816,0.0,0,3.0464106,0.0,0.57468134,98.969475,3.4212434,352.78485,-9.2803011
2240,2240,165.402,13.873271,6.6005864,0.0,0,3.0126424,0.0,0.57969296,98.915237,3.3847849,352.69611,-9.2813425
2242,2242,165.4024,13.924852,6.6307583,0.0,0,2.9788744,0.0,0.58327693,98.872932,3.3503878,352.60739,-9.2810993
2244,2244,165.4028,13.981308,6.6731668,0.0,0,2.9451065,0.0,0.58759874,98.875,3.3140087,352.51865,-9.2836704
2246,2246,165.4032,14.052099,6.7085862,0.0,0,2.9113381,0.0,0.59301233,98.820518,3.2803938,352.42993,-9.28263
2248,2248,165.4036,14.149694,6.7434225,0.0,0,2.8775704,0.0,0.59650904,99.199661,3.2440088,352.34119,-9.2816362
2250,2250,165.404,14.210246,6.780725,0.0,0,2.8438022,0.0,0.60082281,99.206299,3.2122355,352.25247,-9.2809334
2252,2252,165.4044,14.258979,6.8106766,0.0,0,2.810034,0.0,0.60549945,99.105225,3.1739163,352.16373,-9.2820759
2254,2254,165.4048,14.320144,6.8514366,0.0,0,2.7762663,0.0,0.60919386,99.054474,3.1384978,352.07501,-9.2821426
2256,2256,165.4052,14.403036,6.8854303,0.0,0,2.7424984,0.0,0.61402631,99.195511,3.1013107,351.9863,-9.2820616
2258,2258,165.4056,14.488688,6.9155345,0.0,0,2.7090683,0.0,0.61829448,99.358627,3.0664322,351.89755,-9.2815094
2260,2260,165.406,14.56148,6.9608254,0.0,0,2.6768677,0.0,0.62253129,99.425362,3.0336485,351.80884,-9.2812338
2262,2262,165.4064,14.61904,6.9926291,0.0,0,2.6447473,0.0,0.62747842,99.299248,2.9956336,351.72009,-9.2821054
2264,2264,165.4068,14.676076,7.0230765,0.0,0,2.6126273,0.0,0.63135952,99.30574,2.9609921,351.63138,-9.2823448
2266,2266,165.4072,14.770391,7.0660734,0.0,0,2.5805073,0.0,0.63559312,99.483986,2.9276562,351.54263,-9.2824707
2268,2268,165.4076,14.855058,7.0914063,0.0,0,2.5483873,0.0,0.64024484,99.659607,2.8953395,351.45392,-9.2815084
2270,2270,165.408,14.936192,7.1260033,0.0,0,2.5162673,0.0,0.64395189,99.839363,2.8617368,351.3652,-9.2813272
2272,2272,165.4084,14.977265,7.1697474,0.0,0,2.4841473,0.0,0.64912987,99.621048,2.8275988,351.24344,-9.2807827
2274,2274,165.4088,15.045046,7.1968207,0.0,0,2.4520273,0.0,0.65380985,99.602699,2.7954724,351.02267,-9.2820654
2276,2276,165.4092,15.134692,7.2349076,0.0,0,2.4199073,0.0,0.65746528,99.840637,2.7556806,350.80188,-9.2822666
2278,2278,165.4096,15.222186,7.2731709,0.0,0,2.3877873,0.0,0.66281956,99.840691,2.7250297,350.58112,-9.2829275
2280,2280,165.41,15.305148,7.2972054,0.0,0,2.3556671,0.0,0.66659778,100.01643,2.6933815,350.36035,-9.2814465
2282,2282,165.4104,15.372399,7.3349833,0.0,0,2.3235474,0.0,0.67030621,100.04244,2.6571929,350.13956,-9.2809238
2284,2284,165.4108,15.428188,7.3680806,0.0,0,2.2924595,0.0,0.67575526,99.922043,2.6213684,349.91879,-9.282443
2286,2286,165.4112,15.52889,7.3982067,0.0,0,2.2619042,0.0,0.67949522,100.1473,2.5885365,349.698,-9.2828636
2288,2288,165.4116,15.629004,7.4386263,0.0,0,2.2313523,0.0,0.68395579,100.36277,2.5527446,349.47723,-9.2812233
2290,2290,165.412,15.728165,7.4689293,0.0,0,2.2008004,0.0,0.6893698,100.44956,2.5177386,349.25647,-9.280715
2292,2292,165.4124,15.784534,7.5046668,0.0,0,2.1702483,0.0,0.69300389,100.45269,2.4854724,349.03568,-9.2806997
2294,2294,165.4128,15.864138,7.5407228,0.0,0,2.1396964,0.0,0.69783366,100.47855,2.4516077,348.81491,-9.2814837
2296,2296,165.4132,15.970274,7.5668993,0.0,0,2.1091442,0.0,0.70266479,100.62228,2.4175959,348.59412,-9.2819586
2298,2298,165.4136,16.07403,7.6063099,0.0,0,2.0785923,0.0,0.70634735,100.97084,2.3849845,348.37335,-9.2824621
2300,2300,165.414,16.156672,7.6377091,0.0,0,2.0480404,0.0,0.71138728,101.03007,2.3511465,348.15259,-9.280858
2302,2302,165.4144,16.212055,7.6655612,0.0,0,2.0174885,0.0,0.71571201,100.92388,2.3203807,347.93179,-9.2808027
2304,2304,165.4148,16.304386,7.7096095,0.0,0,1.9869361,0.0,0.72004622,100.97844,2.2889452,347.71103,-9.2815857
2306,2306,165.4152,16.414978,7.7358227,0.0,0,1.9563841,0.0,0.72508359,101.13683,2.2538588,347.49023,-9.2807865
2308,2308,165.4156,16.52405,7.7649498,0.0,0,1.9261373,0.0,0.72886699,101.50446,2.2206481,347.26947,-9.2803631
2310,2310,165.416,16.599653,7.807106,0.0,0,1.8970004,0.0,0.73351675,101.45034,2.1909368,347.04871,-9.2807646
2312,2312,165.4164,16.665495,7.8293762,0.0,0,1.8679364,0.0,0.73858988,101.36479,2.1574924,346.82791,-9.2809448
2314,2314,165.4168,16.768484,7.8607559,0.0,0,1.8388724,0.0,0.74185163,101.59825,2.1242456,346.60715,-9.2806311
2316,2316,165.4172,16.893854,7.9005141,0.0,0,1.8098084,0.0,0.74697739,101.83369,2.0915339,346.38635,-9.2801514
2318,2318,165.4176,16.999365,7.9251356,0.0,0,1.7807443,0.0,0.75179344,102.00166,2.0621202,346.16559,-9.2795057
2320,2320,165.418,17.071255,7.9619088,0.0,0,1.7516804,0.0,0.75558275,102.04675,2.0293398,345.94482,-9.2800875
2322,2322,165.4184,17.1647,7.9968295,0.0,0,1.7226164,0.0,0.76128995,102.00922,1.9944583,345.8269,-9.2794476
2324,2324,165.4188,17.268852,8.0197773,0.0,0,1.6935524,0.0,0.76513654,102.24307,1.9647187,346.01761,-9.2804499
2326,2326,165.4192,17.386034,8.0564556,0.0,0,1.6644883,0.0,0.7690112,102.50719,1.934709,346.20831,-9.2804337
2328,2328,165.4196,17.489611,8.0853662,0.0,0,1.6354244,0.0,0.7746821,102.58121,1.89992,346.39899,-9.2802086
2330,2330,165.42,17.57019,8.1134949,0.0,0,1.6063604,0.0,0.77826726,102.64668,1.8692631,346.58969,-9.2792473
2332,2332,165.4204,17.656048,8.1509848,0.0,0,1.5772964,0.0,0.78292811,102.67799,1.8379322,346.78036,-9.2787161
2334,2334,165.4208,17.764711,8.1776285,0.0,0,1.5491644,0.0,0.78842968,102.746,1.8075676,346.97107,-9.2796459
2336,2336,165.4212,17.890182,8.2101784,0.0,0,1.5215132,0.0,0.79169875,103.12701,1.7791303,347.16177,-9.280407
2338,2338,165.4216,18.004963,8.2407017,0.0,0,1.4938653,0.0,0.79641569,103.29327,1.7489178,347.35245,-9.2800417
2340,2340,165.422,18.089855,8.2636099,0.0,0,1.4662173,0.0,0.80105734,103.31362,1.7200102,347.54315,-9.2806959
2342,2342,165.4224,18.169607,8.3010759,0.0,0,1.4385693,0.0,0.80485433,103.43303,1.6947596,347.73386,-9.2799406
2344,2344,165.4228,18.279331,8.3285551,0.0,0,1.4109213,0.0,0.80997324,103.45106,1.6622511,347.92453,-9.2794609
2346,2346,165.4232,18.409855,8.3535938,0.0,0,1.3832734,0.0,0.8139782,103.8238,1.6314352,348.11523,-9.2799616
2348,2348,165.4236,18.516945,8.3932695,0.0,0,1.3556253,0.0,0.81838399,103.91552,1.6025856,348.30594,-9.2804985
2350,2350,165.424,18.599009,8.414794,0.0,0,1.3279774,0.0,0.82345265,103.92158,1.5734365,348.49661,-9.2806187
2352,2352,165.4244,18.709745,8.4422588,0.0,0,1.3003293,0.0,0.82692736,104.15624,1.5453787,348.68732,-9.2798767
2354,2354,165.4248,18.828232,8.4797449,0.0,0,1.2726814,0.0,0.83180207,104.32108,1.5159024,348.87802,-9.2795124
2356,2356,165.4252,18.963596,8.4976444,0.0,0,1.2450334,0.0,0.8365072,104.5752,1.4900111,349.0687,-9.2794371
2358,2358,165.4256,19.082695,8.5285826,0.0,0,1.2176627,0.0,0.83971024,104.86832,1.4579999,349.2594,-9.2796392
2360,2360,165.426,19.176575,8.5638838,0.0,0,1.1913006,0.0,0.84535205,104.79212,1.4318478,349.45007,-9.2785873
2362,2362,165.4264,19.298433,8.5841322,0.0,0,1.1650045,0.0,0.84962463,104.98111,1.4030674,349.64078,-9.2792702
2364,2364,165.4268,19.411556,8.6174326,0.0,0,1.1387084,0.0,0.85314,105.24738,1.3736937,349.83148,-9.2790184
2366,2366,165.4272,19.550503,8.6473265,0.0,0,1.1124125,0.0,0.85909951,105.32518,1.3428329,350.02216,-9.2801533
2368,2368,165.4276,19.664543,8.6672134,0.0,0,1.0861164,0.0,0.86242175,105.62319,1.3142543,350.21286,-9.2786636
2370,2370,165.428,19.772861,8.7007694,0.0,0,1.0598203,0.0,0.86627209,105.81156,1.2862251,350.40356,-9.2778893
2372,2372,165.4284,19.88756,8.7270632,0.0,0,1.0335244,0.0,0.87219179,105.78073,1.2552241,350.55994,-9.2781563
2374,2374,165.4288,19.998791,8.7520618,0.0,0,1.0072284,0.0,0.87535292,106.05189,1.2322648,350.61343,-9.2787285
2376,2376,165.4292,20.146896,8.7837143,0.0,0,0.98093235,0.0,0.87978601,106.31609,1.2042997,350.6669,-9.2794914
2378,2378,165.4296,20.282192,8.8057861,0.0,0,0.95463634,0.0,0.88514298,106.47385,1.1762915,350.72037,-9.2792406
2380,2380,165.43,20.384048,8.8354235,0.0,0,0.92834044,0.0,0.88816094,106.71999,1.1504728,350.77386,-9.2793102
2382,2382,165.4304,20.498077,8.8621836,0.0,0,0.90204442,0.0,0.89295852,106.78536,1.1252718,350.82733,-9.279192
2384,2384,165.4308,20.62512,8.8841085,0.0,0,0.87659609,0.0,0.89769524,106.96522,1.0962473,350.88083,-9.2775707
2386,2386,165.4312,20.784079,8.9213905,0.0,0,0.85158539,0.0,0.90163398,107.32743,1.0696399,350.9343,-9.2770681
2388,2388,165.4316,20.909117,8.9433613,0.0,0,0.82657731,0.0,0.90702069,107.47316,1.0448726,350.98776,-9.2776499
2390,2390,165.432,21.025867,8.9651146,0.0,0,0.8015694,0.0,0.91053885,107.64695,1.0169924,351.04126,-9.278964
2392,2392,165.4324,21.147718,9.0011053,0.0,0,0.77656138,0.0,0.91477418,107.7939,0.98701423,351.09473,-9.2797928
2394,2394,165.4328,21.294628,9.0191107,0.0,0,0.75155336,0.0,0.91987854,108.00796,0.96282458,351.14822,-9.2789898
2396,2396,165.4332,21.458103,9.0454111,0.0,0,0.72654539,0.0,0.92318356,108.4929,0.93746853,351.20169,-9.2776127
2398,2398,165.4336,21.602736,9.0810108,0.0,0,0.70153737,0.0,0.92852032,108.62884,0.90951777,351.25516,-9.2770853
2400,2400,165.434,21.711182,9.0964146,0.0,0,0.67652941,0.0,0.93309379,108.67892,0.88203055,351.30865,-9.2780256
2402,2402,165.4344,21.845596,9.1245785,0.0,0,0.65152138,0.0,0.93621886,108.99679,0.85663772,351.36212,-9.2790346
2404,2404,165.4348,21.996403,9.1559458,0.0,0,0.62651336,0.0,0.94204038,109.09291,0.83049697,351.41562,-9.2786579
2406,2406,165.4352,22.178253,9.1715088,0.0,0,0.6015054,0.0,0.94577956,109.60992,0.8053751,351.46909,-9.277668
2408,2408,165.4356,22.30604,9.2044992,0.0,0,0.57674509,0.0,0.94954002,109.8484,0.77405059,351.52255,-9.2772036
2410,2410,165.436,22.415777,9.2326756,0.0,0,0.55288601,0.0,0.95605475,109.70109,0.7508682,351.57605,-9.2776299
2412,2412,165.4364,22.559212,9.2534065,0.0,0,0.52908593,0.0,0.9593451,110.01012,0.72461265,351.62952,-9.2783413
2414,2414,165.4368,22.725979,9.2804375,0.0,0,0.50528592,0.0,0.96301228,110.37376,0.69605762,351.68301,-9.2776995
2416,2416,165.4372,22.905159,9.3014278,0.0,0,0.4814859,0.0,0.96850663,110.61289,0.67112678,351.73648,-9.2777805
2418,2418,165.4376,23.033262,9.3271646,0.0,0,0.45768592,0.0,0.97165745,110.9257,0.6480819,351.78995,-9.2764254
2420,2420,165.438,23.154453,9.3565407,0.0,0,0.4338859,0.0,0.97644538,110.96458,0.62078565,351.84344,-9.2771416
2422,2422,165.4384,23.302368,9.3753691,0.0,0,0.41008592,0.0,0.98182547,111.07042,0.59640896,351.82858,-9.2770882
2424,2424,165.4388,23.472679,9.4047794,0.0,0,0.3862859,0.0,0.98481947,111.55369,0.57694948,351.6087,-9.2773991
2426,2426,165.4392,23.648438,9.4280243,0.0,0,0.36248589,0.0,0.99003851,111.78749,0.54989487,351.38885,-9.2761412