File: clean data/testID_0216.csv
level_0,index,Time(sec),Force(kN),Jaw(mm),PowAngle(deg),Power(W),Pram,PTemp,Strain,Stress(MPa),Stroke(mm),TC1(C),wedge(mm)
2105,2105,178.6774,1.1616814,0.019568127,0.0,0,9.0629702,0.0,0.00092572276,12.768612,10.102651,391.41608,-9.2636976
2106,2106,178.6776,2.3388424,0.037014101,0.0,0,9.0337067,0.0,0.002339225,26.487375,10.067891,391.19647,-9.264616
2107,2107,178.6778,3.294322,0.069545425,0.0,0,9.0044422,0.0,0.004232638,39.786602,10.041567,390.97684,-9.2641001
2108,2108,178.678,3.647615,0.089952298,0.0,0,8.9751787,0.0,0.0054880907,45.707592,10.016812,390.75723,-9.2631693
2109,2109,178.6782,3.7650023,0.10903859,0.0,0,8.9459143,0.0,0.0071260454,47.410793,9.9849787,390.53763,-9.2617474
2110,2110,178.6784,3.8477933,0.14849289,0.0,0,8.9166508,0.0,0.009430158,48.311234,9.9481115,390.31802,-9.2607937
2111,2111,178.6786,3.885253,0.20680198,0.0,0,8.8873863,0.0,0.012758312,48.982777,9.9082308,390.09839,-9.2606506
2112,2112,178.6788,3.7021449,0.2773028,0.0,0,8.8581219,0.0,0.017807528,46.889599,9.8657923,389.87878,-9.260582
2113,2113,178.679,3.57318,0.33940932,0.0,0,8.8288584,0.0,0.022305042,44.662827,9.8189297,389.65918,-9.2613068
2114,2114,178.6792,3.7216477,0.38105527,0.0,0,8.7995939,0.0,0.024962073,45.710613,9.7666349,389.43958,-9.2613115
2115,2115,178.6794,3.8563297,0.42608342,0.0,0,8.7703304,0.0,0.028170913,47.60585,9.7140102,389.21994,-9.2606916
2116,2116,178.6796,3.7420969,0.48807293,0.0,0,8.7416534,0.0,0.032448102,46.512608,9.6643505,389.66962,-9.2611513
2117,2117,178.6798,3.7009945,0.54565984,0.0,0,8.7136879,0.0,0.036190674,45.405418,9.615057,390.78833,-9.2612495
2118,2118,178.68,3.9725089,0.57878333,0.0,0,8.6858492,0.0,0.038989462,47.898323,9.5703459,391.90701,-9.2612534
2119,2119,178.6802,4.1416583,0.59284806,0.0,0,8.6580172,0.0,0.040417034,50.527359,9.5317707,393.0257,-9.2612076
2120,2120,178.6804,3.8893588,0.61214167,0.0,0,8.6301851,0.0,0.041177802,48.512428,9.4929485,394.14438,-9.2610674
2121,2121,178.6806,3.5236461,0.64898485,0.0,0,8.6023531,0.0,0.043534193,43.734333,9.4547243,395.26309,-9.2610588
2122,2122,178.6808,3.5523376,0.69028926,0.0,0,8.574522,0.0,0.046832744,42.657719,9.4193134,396.38177,-9.2612591
2123,2123,178.681,3.8713479,0.71899253,0.0,0,8.546689,0.0,0.048704609,46.083519,9.3878117,397.50046,-9.2618876
2124,2124,178.6812,4.0878639,0.72843379,0.0,0,8.518857,0.0,0.049477305,49.185032,9.3566132,398.61914,-9.2617149
2125,2125,178.6814,4.1538963,0.73797959,0.0,0,8.4910259,0.0,0.050480645,50.09906,9.325778,399.73785,-9.2609434
2126,2126,178.6816,4.2323771,0.77846724,0.0,0,8.4631929,0.0,0.052598625,50.848015,9.2929268,400.85654,-9.2603321
2127,2127,178.6818,4.3161516,0.83771688,0.0,0,8.4353609,0.0,0.056337371,51.802952,9.2565718,401.97522,-9.2597046
2128,2128,178.682,4.2208629,0.8877812,0.0,0,8.4075298,0.0,0.060516655,50.968086,9.2179031,403.0939,-9.2594995
2129,2129,178.6822,4.005816,0.93306446,0.0,0,8.3796968,0.0,0.063699782,48.301571,9.1772661,404.21262,-9.2594957
2130,2130,178.6824,3.9134505,0.97216451,0.0,0,8.3518648,0.0,0.066148303,46.693531,9.136837,405.3313,-9.2597103
2131,2131,178.6826,3.9952648,1.0082924,0.0,0,8.3240337,0.0,0.069098257,47.19519,9.0945368,406.44998,-9.2608614
2132,2132,178.6828,4.0756569,1.0605434,0.0,0,8.2962017,0.0,0.072698653,48.104313,9.0516605,407.56866,-9.2616615
2133,2133,178.683,4.0374069,1.108682,0.0,0,8.2683697,0.0,0.07586579,47.798512,9.0104303,408.68738,-9.2618113
2134,2134,178.6832,4.012888,1.1298269,0.0,0,8.2405376,0.0,0.078046195,47.195602,8.9719105,409.80606,-9.2618113
2135,2135,178.6834,4.1396494,1.1502451,0.0,0,8.2127056,0.0,0.079630643,48.28157,8.936842,410.92474,-9.2613659
2136,2136,178.6836,4.2205925,1.179498,0.0,0,8.1848736,0.0,0.081137724,49.485237,8.9025793,412.04346,-9.2606363
2137,2137,178.6838,4.0896544,1.2036477,0.0,0,8.1570415,0.0,0.083215423,48.382641,8.8707829,413.16214,-9.2603779
2138,2138,178.684,3.9238272,1.2350597,0.0,0,8.1292095,0.0,0.085763425,46.203083,8.8422613,414.28082,-9.2607288
2139,2139,178.6842,3.9486048,1.2648703,0.0,0,8.1013775,0.0,0.087500207,45.805935,8.8113155,415.39951,-9.2607851
2140,2140,178.6844,4.1576872,1.277379,0.0,0,8.0735455,0.0,0.088651195,47.868042,8.7828321,416.51822,-9.2605476
2141,2141,178.6846,4.3440356,1.3027678,0.0,0,8.0462685,0.0,0.09068276,50.168552,8.7562914,417.6369,-9.2604933
2142,2142,178.6848,4.393033,1.3452909,0.0,0,8.0196619,0.0,0.093185581,50.896515,8.7279758,418.75558,-9.2603369
2143,2143,178.685,4.3711472,1.3811973,0.0,0,7.993176,0.0,0.095878631,50.637699,8.696537,419.87427,-9.2603045
2144,2144,178.6852,4.3322992,1.4202789,0.0,0,7.9666953,0.0,0.09914954,50.095383,8.6634836,420.99298,-9.2601328
2145,2145,178.6854,4.2787328,1.4614154,0.0,0,7.9402156,0.0,0.10177771,49.390491,8.6318483,422.11166,-9.2604437
2146,2146,178.6856,4.2324982,1.4928234,0.0,0,7.9137359,0.0,0.1040289,48.62846,8.5970373,423.23035,-9.2606678
2147,2147,178.6858,4.2045579,1.5316492,0.0,0,7.8872557,0.0,0.10731906,48.033279,8.5610294,424.34903,-9.2603855
2148,2148,178.686,4.1865664,1.5762941,0.0,0,7.8607755,0.0,0.11042086,47.735855,8.5249786,425.46774,-9.2609167
2149,2149,178.6862,4.181725,1.6028676,0.0,0,7.8342957,0.0,0.11234517,47.551216,8.4899569,426.58643,-9.2606716
2150,2150,178.6864,4.2145419,1.6215982,0.0,0,7.8078156,0.0,0.11430281,47.723335,8.4556656,427.70511,-9.2600756
2151,2151,178.6866,4.2668085,1.6468363,0.0,0,7.7813354,0.0,0.11606693,48.242546,8.4235239,428.82379,-9.2597618
2152,2152,178.6868,4.2670584,1.6727164,0.0,0,7.7548552,0.0,0.11754555,48.337379,8.3953209,429.9425,-9.2597914
2153,2153,178.687,4.1974154,1.7027826,0.0,0,7.7283754,0.0,0.12018553,47.526779,8.3651342,431.06119,-9.2605
2154,2154,178.6872,4.1581879,1.7336177,0.0,0,7.7018952,0.0,0.12266482,46.865509,8.3360786,432.17987,-9.2608309
2155,2155,178.6874,4.222537,1.7526619,0.0,0,7.675415,0.0,0.1237449,47.314636,8.3091717,433.29855,-9.2606926
2156,2156,178.6876,4.33286,1.7686526,0.0,0,7.6489348,0.0,0.12525262,48.453243,8.2823143,434.41727,-9.2607641
2157,2157,178.6878,4.3975215,1.7955838,0.0,0,7.6224551,0.0,0.12741119,49.231415,8.2580271,435.53595,-9.2608671
2158,2158,178.688,4.3971734,1.829761,0.0,0,7.5959754,0.0,0.12943308,49.218254,8.2314301,436.65463,-9.2608719
2159,2159,178.6882,4.3940296,1.8618894,0.0,0,7.5694952,0.0,0.13204864,49.035099,8.2004251,437.77332,-9.2603807
2160,2160,178.6884,4.4160671,1.8905821,0.0,0,7.543015,0.0,0.13462082,49.117844,8.1726189,438.89203,-9.259407
2161,2161,178.6886,4.4157777,1.9213421,0.0,0,7.5165353,0.0,0.13641177,49.118176,8.1446991,440.01071,-9.2588482
2162,2162,178.6888,4.3617301,1.9532062,0.0,0,7.4900556,0.0,0.13885477,48.545082,8.1119013,441.12939,-9.2589178
2163,2163,178.689,4.2982755,1.9842539,0.0,0,7.4635754,0.0,0.14176266,47.666073,8.0824795,442.24811,-9.2598124
2164,2164,178.6892,4.3020086,2.0163965,0.0,0,7.4370952,0.0,0.14384072,47.377914,8.0526266,443.36679,-9.2602758
2165,2165,178.6894,4.3655424,2.040175,0.0,0,7.410615,0.0,0.14562833,47.843819,8.0240602,444.48547,-9.260293
2166,2166,178.6896,4.4209309,2.05668,0.0,0,7.3846664,0.0,0.14747475,48.477955,7.9987054,445.85001,-9.2606716
2167,2167,178.6898,4.4300098,2.0842481,0.0,0,7.3593612,0.0,0.14917742,48.656017,7.9701676,447.4603,-9.2612524
2168,2168,178.69,4.3826733,2.1141574,0.0,0,7.3341722,0.0,0.15115879,48.057007,7.9432888,449.07056,-9.2614975
2169,2169,178.6902,4.3239322,2.1349955,0.0,0,7.3089881,0.0,0.15342414,47.309452,7.9176245,450.68082,-9.2614937
2170,2170,178.6904,4.306757,2.1597762,0.0,0,7.2838039,0.0,0.15527135,46.966759,7.893333,452.29111,-9.2616014
2171,2171,178.6906,4.332202,2.1819799,0.0,0,7.2586198,0.0,0.15660799,47.099636,7.8690166,453.90137,-9.2616167
2172,2172,178.6908,4.3920751,2.1968956,0.0,0,7.2334356,0.0,0.15824403,47.603519,7.8414516,455.51166,-9.2608452
2173,2173,178.691,4.4648671,2.2273304,0.0,0,7.2082515,0.0,0.16044335,48.213474,7.8160515,457.12192,-9.2602739
2174,2174,178.6912,4.5158348,2.261704,0.0,0,7.1830673,0.0,0.16254404,48.733921,7.7928863,458.73221,-9.2597075
2175,2175,178.6914,4.54211,2.2799928,0.0,0,7.1578832,0.0,0.16453873,48.981659,7.7672849,460.34247,-9.2598095
2176,2176,178.6916,4.5457854,2.3055236,0.0,0,7.1326995,0.0,0.16664402,49.011333,7.7423639,461.95276,-9.2601299
2177,2177,178.6918,4.5188098,2.3391201,0.0,0,7.1075153,0.0,0.16863541,48.725922,7.7179127,463.56302,-9.259757
2178,2178,178.692,4.4651585,2.3626034,0.0,0,7.0823312,0.0,0.17094342,48.075954,7.6913867,465.17331,-9.2602282
2179,2179,178.6922,4.4222364,2.3913991,0.0,0,7.0571475,0.0,0.17359076,47.463097,7.6654963,466.78357,-9.2605343
2180,2180,178.6924,4.4218216,2.4209168,0.0,0,7.0319633,0.0,0.17539188,47.249996,7.6392612,468.39383,-9.2609596
2181,2181,178.6926,4.472899,2.4333463,0.0,0,7.0067792,0.0,0.17664018,47.626026,7.6137028,470.00412,-9.261528
2182,2182,178.6928,4.5318747,2.4542742,0.0,0,6.981595,0.0,0.17864786,48.165955,7.5905809,471.61438,-9.2609348
2183,2183,178.693,4.5519667,2.4873805,0.0,0,6.9564114,0.0,0.1806412,48.364929,7.5652242,473.22467,-9.2598896
2184,2184,178.6932,4.5335393,2.5083544,0.0,0,6.9312277,0.0,0.18239002,48.15229,7.5385017,474.83493,-9.2593994
2185,2185,178.6934,4.5011768,2.5306852,0.0,0,6.9060431,0.0,0.18477915,47.710594,7.5118685,476.44522,-9.2595863
2186,2186,178.6936,4.4893894,2.5582204,0.0,0,6.8808594,0.0,0.18651985,47.447941,7.4877086,478.05548,-9.2599878
2187,2187,178.6938,4.4925647,2.5745018,0.0,0,6.8556757,0.0,0.18764029,47.447056,7.4648905,479.66577,-9.260232
2188,2188,178.694,4.5131359,2.5961134,0.0,0,6.830492,0.0,0.18994078,47.480186,7.4368019,481.27603,-9.2603292
2189,2189,178.6942,4.551538,2.6282039,0.0,0,6.8053074,0.0,0.19225551,47.685551,7.4151578,482.88632,-9.2610312
2190,2190,178.6944,4.5783911,2.6495697,0.0,0,6.7801232,0.0,0.1937245,47.972744,7.3952122,484.49658,-9.2613544
2191,2191,178.6946,4.59585,2.6694982,0.0,0,6.7554417,0.0,0.1958437,48.085197,7.3715253,486.10687,-9.2606592
2192,2192,178.6948,4.6098161,2.698169,0.0,0,6.7313671,0.0,0.19801989,48.128838,7.3484874,487.71713,-9.2603283
2193,2193,178.695,4.608129,2.723335,0.0,0,6.7074022,0.0,0.19959204,48.089283,7.3225474,489.32739,-9.2603264
2194,2194,178.6952,4.6013608,2.7490442,0.0,0,6.6834416,0.0,0.20210503,47.920841,7.2959051,490.93768,-9.2603302
2195,2195,178.6954,4.5996022,2.778235,0.0,0,6.6594815,0.0,0.20464943,47.708408,7.2718821,492.54794,-9.2602224
2196,2196,178.6956,4.602828,2.8001647,0.0,0,6.6355219,0.0,0.20597431,47.582176,7.2492647,494.15823,-9.2603674
2197,2197,178.6958,4.6201291,2.819742,0.0,0,6.6115613,0.0,0.20790045,47.664314,7.2234926,495.76849,-9.2604847
2198,2198,178.696,4.6506414,2.8454194,0.0,0,6.5876017,0.0,0.21023922,47.932854,7.1963735,497.37878,-9.2608767
2199,2199,178.6962,4.6634221,2.8726707,0.0,0,6.5636415,0.0,0.21189912,48.036198,7.1715145,498.98904,-9.2606907
2200,2200,178.6964,4.6544237,2.8962107,0.0,0,6.5396819,0.0,0.21409914,47.865463,7.1471715,500.59933,-9.2598743
2201,2201,178.6966,4.6343675,2.9171062,0.0,0,6.5157218,0.0,0.21632974,47.561333,7.1213899,502.20959,-9.2600307
2202,2202,178.6968,4.6422362,2.94014,0.0,0,6.4917622,0.0,0.21762022,47.510796,7.0958495,503.81989,-9.2602673
2203,2203,178.697,4.6883316,2.9628246,0.0,0,6.467802,0.0,0.21948195,47.839947,7.0735812,505.43015,-9.2602682
2204,2204,178.6972,4.723948,2.985647,0.0,0,6.4438419,0.0,0.22193316,48.123451,7.0497642,507.04044,-9.2603874
2205,2205,178.6974,4.7406921,3.0146251,0.0,0,6.4198818,0.0,0.22376917,48.17347,7.0251355,508.6507,-9.2604475
2206,2206,178.6976,4.7511978,3.0388258,0.0,0,6.3959212,0.0,0.22566554,48.174839,7.002296,510.26096,-9.260952
2207,2207,178.6978,4.7603335,3.056613,0.0,0,6.3719616,0.0,0.22786692,48.145061,6.9781055,511.87125,-9.2609406
2208,2208,178.698,4.7551255,3.0853033,0.0,0,6.3480015,0.0,0.22979303,48.041245,6.9541521,513.48151,-9.2603569
2209,2209,178.6982,4.735374,3.1152351,0.0,0,6.3240418,0.0,0.23195355,47.846134,6.9299793,515.0918,-9.2603245
2210,2210,178.6984,4.7208571,3.1358466,0.0,0,6.3000817,0.0,0.23446903,47.57859,6.9054627,516.70209,-9.2601795
2211,2211,178.6986,4.727581,3.1624575,0.0,0,6.2761221,0.0,0.23652044,47.550957,6.8796411,518.31232,-9.2599554
2212,2212,178.6988,4.7609859,3.1887586,0.0,0,6.252162,0.0,0.23817718,47.756203,6.8560576,519.92261,-9.2603168
2213,2213,178.699,4.808219,3.2053568,0.0,0,6.2282019,0.0,0.24021189,48.113083,6.832128,521.5329,-9.260582
2214,2214,178.6992,4.8393445,3.2329831,0.0,0,6.2042422,0.0,0.24256028,48.3284,6.805131,523.14319,-9.2604151
2215,2215,178.6994,4.8367929,3.2640355,0.0,0,6.1802821,0.0,0.24447767,48.212292,6.7806787,524.75342,-9.2604246
2216,2216,178.6996,4.8167524,3.2791245,0.0,0,6.1568027,0.0,0.24636559,48.021179,6.758719,525.70935,-9.2610521
2217,2217,178.6998,4.8066545,3.3026197,0.0,0,6.1339049,0.0,0.24859717,47.744995,6.7335496,526.01111,-9.2611923
2218,2218,178.7,4.8073473,3.332885,0.0,0,6.1111121,0.0,0.25035989,47.578121,6.7082911,526.31293,-9.2611942
2219,2219,178.7002,4.8066397,3.3493736,0.0,0,6.0883236,0.0,0.25219625,47.543591,6.6849561,526.61469,-9.2614632
2220,2220,178.7004,4.8169894,3.3742149,0.0,0,6.065536,0.0,0.25472039,47.542915,6.6591887,526.9165,-9.2610073
2221,2221,178.7006,4.8544216,3.4053547,0.0,0,6.042748,0.0,0.25664541,47.741768,6.6335425,527.21826,-9.2605639
2222,2222,178.7008,4.8979635,3.4213514,0.0,0,6.0199599,0.0,0.25829995,48.039452,6.6110592,527.52008,-9.2601509
2223,2223,178.701,4.9259253,3.4453547,0.0,0,5.9971719,0.0,0.26092887,48.264767,6.5853877,527.8219,-9.2596493
2224,2224,178.7012,4.9327612,3.4799535,0.0,0,5.9743834,0.0,0.26322916,48.294678,6.5594869,528.12366,-9.2598219
2225,2225,178.7014,4.9204826,3.5011795,0.0,0,5.9515953,0.0,0.26511127,48.117229,6.5363188,528.42548,-9.2603474
2226,2226,178.7016,4.9026961,3.5238523,0.0,0,5.9288077,0.0,0.2678093,47.808247,6.5095544,528.72723,-9.2604094
2227,2227,178.7018,4.8965893,3.5546684,0.0,0,5.9060202,0.0,0.269945,47.587738,6.4857063,529.02905,-9.2610273
2228,2228,178.702,4.9103422,3.5736973,0.0,0,5.8832321,0.0,0.27138036,47.634251,6.4646468,529.33081,-9.2616644
2229,2229,178.7022,4.9330144,3.5960045,0.0,0,5.8604436,0.0,0.2739858,47.717415,6.4382472,529.63263,-9.261035
2230,2230,178.7024,4.9498205,3.6289425,0.0,0,5.8376555,0.0,0.2765792,47.758457,6.4126773,529.93439,-9.2603741
2231,2231,178.7026,4.972569,3.6499758,0.0,0,5.8148675,0.0,0.27807653,47.913887,6.3897505,530.23621,-9.2600765
2232,2232,178.7028,5.0025983,3.6695189,0.0,0,5.792079,0.0,0.28038284,48.078018,6.3653388,530.53796,-9.2600365
2233,2233,178.703,5.011096,3.6973946,0.0,0,5.7692914,0.0,0.28277475,48.084381,6.3408256,530.83978,-9.2602568
2234,2234,178.7032,5.0027723,3.7203031,0.0,0,5.7465038,0.0,0.28421545,47.965862,6.3168073,531.14154,-9.2608118
2235,2235,178.7034,5.000998,3.7417974,0.0,0,5.7237153,0.0,0.28666657,47.814529,6.2922864,531.44336,-9.2609243
2236,2236,178.7036,5.0114908,3.7691572,0.0,0,5.7009277,0.0,0.28929934,47.718945,6.2663307,531.74518,-9.2609844
2237,2237,178.7038,5.0235958,3.7923415,0.0,0,5.6781397,0.0,0.29070684,47.784195,6.241982,532.04694,-9.2613659
2238,2238,178.704,5.0388021,3.8133867,0.0,0,5.6553516,0.0,0.29294133,47.84568,6.217998,532.34875,-9.2613325
2239,2239,178.7042,5.0599809,3.840565,0.0,0,5.6325636,0.0,0.29570103,47.846958,6.1926513,532.65051,-9.2611771
2240,2240,178.7044,5.0745578,3.8684354,0.0,0,5.6097755,0.0,0.29749906,47.910313,6.168735,532.95233,-9.2606392
2241,2241,178.7046,5.0807567,3.8915331,0.0,0,5.5874419,0.0,0.29980367,47.9184,6.145185,533.25409,-9.2602587
2242,2242,178.7048,5.0902972,3.9141316,0.0,0,5.5656581,0.0,0.30243891,47.886639,6.120182,533.55591,-9.2602949
2243,2243,178.705,5.1036601,3.9405942,0.0,0,5.5439739,0.0,0.30415067,47.902435,6.0970354,533.85767,-9.2597151
2244,2244,178.7052,5.1156659,3.9640424,0.0,0,5.5222936,0.0,0.3062914,47.857681,6.0733972,534.15948,-9.2590752
2245,2245,178.7054,5.1161771,3.9853315,0.0,0,5.5006137,0.0,0.30893075,47.765079,6.0501518,534.46124,-9.2597733
2246,2246,178.7056,5.1207199,4.0132899,0.0,0,5.4789333,0.0,0.31081012,47.760963,6.0271845,534.76306,-9.2608004
2247,2247,178.7058,5.1280799,4.0368714,0.0,0,5.4572535,0.0,0.31274632,47.716656,6.0006757,535.06488,-9.2610903
2248,2248,178.706,5.1302867,4.0536633,0.0,0,5.4355736,0.0,0.31512257,47.66711,5.97436,535.36664,-9.261096
2249,2249,178.7062,5.1445546,4.0814862,0.0,0,5.4138937,0.0,0.31715935,47.744366,5.950922,535.66846,-9.2607946
2250,2250,178.7064,5.1545062,4.1080976,0.0,0,5.3922133,0.0,0.31917387,47.7262,5.9271517,535.97021,-9.2609682
2251,2251,178.7066,5.1570587,4.1247373,0.0,0,5.3705335,0.0,0.32160231,47.596367,5.9010544,536.27203,-9.2608204
2252,2252,178.7068,5.1695132,4.1515541,0.0,0,5.3488536,0.0,0.32379767,47.565655,5.8782849,536.57379,-9.2602024
2253,2253,178.707,5.1990905,4.1800971,0.0,0,5.3271737,0.0,0.32571328,47.721962,5.8571696,536.87561,-9.2604504
2254,2254,178.7072,5.2206645,4.1980414,0.0,0,5.3054934,0.0,0.32809311,47.82822,5.8320279,537.17737,-9.2604094
2255,2255,178.7074,5.2274146,4.2257838,0.0,0,5.2838135,0.0,0.33068416,47.77039,5.8052669,537.47919,-9.2608271
2256,2256,178.7076,5.2240338,4.2563858,0.0,0,5.2621331,0.0,0.33275446,47.635571,5.7833548,537.78094,-9.261076
2257,2257,178.7078,5.2181301,4.2713795,0.0,0,5.2404532,0.0,0.33477539,47.481705,5.7619424,538.08276,-9.2610826
2258,2258,178.708,5.229897,4.2949486,0.0,0,5.2187734,0.0,0.3371971,47.4548,5.7375989,538.38452,-9.2612524
2259,2259,178.7082,5.2471795,4.3247356,0.0,0,5.1970935,0.0,0.33915284,47.542252,5.7098951,538.68634,-9.261508
2260,2260,178.7084,5.2616005,4.3387423,0.0,0,5.1754136,0.0,0.34099954,47.565601,5.6854405,538.98816,-9.2617598
2261,2261,178.7086,5.2812829,4.3626823,0.0,0,5.1537337,0.0,0.34368095,47.567265,5.6646895,539.28992,-9.2613783
2262,2262,178.7088,5.298995,4.3942518,0.0,0,5.1320534,0.0,0.34574619,47.64151,5.6401658,539.59174,-9.2608891
2263,2263,178.709,5.3137379,4.409153,0.0,0,5.1103735,0.0,0.34748209,47.732693,5.6154804,539.89349,-9.2610197
2264,2264,178.7092,5.318418,4.4322271,0.0,0,5.0886931,0.0,0.3503229,47.736969,5.5936236,540.19531,-9.2615271
2265,2265,178.7094,5.3188424,4.4656897,0.0,0,5.0670133,0.0,0.35260773,47.642609,5.5711021,540.49707,-9.261735
2266,2266,178.7096,5.3259339,4.4844127,0.0,0,5.0457683,0.0,0.35438499,47.550232,5.5460987,540.67688,-9.2611275
2267,2267,178.7098,5.3205605,4.505878,0.0,0,5.0250487,0.0,0.3572461,47.405689,5.5228076,540.73474,-9.2603817
2268,2268,178.71,5.3272443,4.5367007,0.0,0,5.0044241,0.0,0.35957268,47.354008,5.4998999,540.7926,-9.2603397
2269,2269,178.7102,5.3467984,4.5549707,0.0,0,4.9838042,0.0,0.36104986,47.425606,5.4778743,540.85046,-9.2610579
2270,2270,178.7104,5.351614,4.5742631,0.0,0,4.9631839,0.0,0.36374635,47.434284,5.4536982,540.90833,-9.2611046
2271,2271,178.7106,5.3641653,4.6038504,0.0,0,4.942564,0.0,0.36623544,47.401955,5.4301028,540.96619,-9.2603769
2272,2272,178.7108,5.3813891,4.6234808,0.0,0,4.9219441,0.0,0.36759436,47.416569,5.4083424,541.02405,-9.2607832
2273,2273,178.711,5.3901734,4.6411595,0.0,0,4.9013243,0.0,0.37003204,47.408821,5.3868294,541.08191,-9.2608824
2274,2274,178.7112,5.4040051,4.6674848,0.0,0,4.8807039,0.0,0.37250945,47.41267,5.3645992,541.13977,-9.2602253
2275,2275,178.7114,5.4112144,4.6890202,0.0,0,4.8600841,0.0,0.37391287,47.409721,5.3406978,541.19763,-9.2606487
2276,2276,178.7116,5.4085598,4.708456,0.0,0,4.8394642,0.0,0.37643561,47.280621,5.3185086,541.25549,-9.2608747
2277,2277,178.7118,5.408319,4.7340426,0.0,0,4.8188443,0.0,0.379199,47.133186,5.2980556,541.31335,-9.2606411
2278,2278,178.712,5.4137831,4.7572703,0.0,0,4.798224,0.0,0.38069722,47.08252,5.2759151,541.37122,-9.2610102
2279,2279,178.7122,5.4304218,4.776957,0.0,0,4.7776041,0.0,0.38304055,47.109032,5.2504005,541.42908,-9.2608366
2280,2280,178.7124,5.4515128,4.8012085,0.0,0,4.7569842,0.0,0.38581908,47.169163,5.2269874,541.48694,-9.2604723
2281,2281,178.7126,5.4722705,4.8267331,0.0,0,4.7363639,0.0,0.38750157,47.208881,5.2041693,541.5448,-9.2605495
2282,2282,178.7128,5.4893031,4.8479633,0.0,0,4.715744,0.0,0.3898204,47.227333,5.182487,541.60266,-9.2608051
2283,2283,178.713,5.5022674,4.8680034,0.0,0,4.6951241,0.0,0.39248273,47.335789,5.1620417,541.66052,-9.2606354
2284,2284,178.7132,5.5172954,4.8928246,0.0,0,4.6745043,0.0,0.39415523,47.425789,5.137547,541.71838,-9.2603312
2285,2285,178.7134,5.5234814,4.9153962,0.0,0,4.6538844,0.0,0.39631304,47.359436,5.1150723,541.77625,-9.2595968
2286,2286,178.7136,5.5200062,4.9343009,0.0,0,4.6332641,0.0,0.39904389,47.203514,5.0934529,541.83411,-9.2595806
2287,2287,178.7138,5.5084586,4.9594674,0.0,0,4.6126437,0.0,0.40088499,46.981991,5.0723209,541.89197,-9.2600002
2288,2288,178.714,5.5069199,4.980134,0.0,0,4.5920238,0.0,0.40266186,46.848221,5.0521345,541.94983,-9.2600145
2289,2289,178.7142,5.5160761,4.9949994,0.0,0,4.571404,0.0,0.40515605,46.761757,5.0290446,542.00769,-9.260293
2290,2290,178.7144,5.5244269,5.0225115,0.0,0,4.5507841,0.0,0.40729955,46.755207,5.007009,542.06555,-9.260581
2291,2291,178.7146,5.5426149,5.0486317,0.0,0,4.5305758,0.0,0.40923047,46.881653,4.987,542.12341,-9.2606077
2292,2292,178.7148,5.5684657,5.0631166,0.0,0,4.5108657,0.0,0.41169775,46.971649,4.9650273,542.18127,-9.2603416
2293,2293,178.715,5.593298,5.0872421,0.0,0,4.4912457,0.0,0.41394004,47.06723,4.9429045,542.23914,-9.2609005
2294,2294,178.7152,5.6071429,5.1126165,0.0,0,4.4716296,0.0,0.41569242,47.085335,4.9228816,542.297,-9.2609406
2295,2295,178.7154,5.605124,5.1265674,0.0,0,4.4520135,0.0,0.41798753,46.985687,4.8996701,542.35486,-9.260376
2296,2296,178.7156,5.5896215,5.1511683,0.0,0,4.4323978,0.0,0.42054716,46.770786,4.8766847,542.41266,-9.2608709
2297,2297,178.7158,5.5838842,5.1790605,0.0,0,4.4127817,0.0,0.4224667,46.593662,4.8564038,542.47052,-9.2608919
2298,2298,178.716,5.599237,5.1908464,0.0,0,4.3931656,0.0,0.42444345,46.576897,4.8359823,542.52838,-9.2603512
2299,2299,178.7162,5.6234999,5.2132711,0.0,0,4.3735499,0.0,0.42697838,46.675018,4.814733,542.58624,-9.2600431
2300,2300,178.7164,5.6514773,5.2430916,0.0,0,4.3539338,0.0,0.42901397,46.837421,4.792912,542.6441,-9.259491
2301,2301,178.7166,5.6794615,5.2565145,0.0,0,4.3343177,0.0,0.4309524,46.977745,4.7704525,542.70197,-9.258997
2302,2302,178.7168,5.7042708,5.2777109,0.0,0,4.314702,0.0,0.43367246,47.052101,4.750495,542.75983,-9.2588797
2303,2303,178.717,5.7189136,5.3059416,0.0,0,4.2950859,0.0,0.43562946,47.086163,4.7300787,542.81769,-9.2595329
2304,2304,178.7172,5.719769,5.3191471,0.0,0,4.2754698,0.0,0.43723246,47.039627,4.7090268,542.87555,-9.2602062
2305,2305,178.7174,5.7071919,5.3393431,0.0,0,4.2558532,0.0,0.44007173,46.82597,4.6887097,542.93341,-9.2608805
2306,2306,178.7176,5.6966534,5.3687954,0.0,0,4.2362375,0.0,0.44224718,46.631317,4.6671987,542.99127,-9.2610817
2307,2307,178.7178,5.7029319,5.3837738,0.0,0,4.2166214,0.0,0.44375807,46.611019,4.647018,543.04913,-9.2610941
2308,2308,178.718,5.7161818,5.4019465,0.0,0,4.1970053,0.0,0.4465884,46.58976,4.6256981,543.10699,-9.2611275
2309,2309,178.7182,5.735209,5.4311819,0.0,0,4.1773896,0.0,0.44899639,46.582745,4.602282,543.16486,-9.2607374
2310,2310,178.7184,5.7530761,5.4484134,0.0,0,4.1577735,0.0,0.45047632,46.637878,4.5807037,543.22272,-9.2606668
2311,2311,178.7186,5.7723851,5.4666238,0.0,0,4.1381574,0.0,0.4532387,46.72176,4.5611591,543.28058,-9.2610331
2312,2312,178.7188,5.7939782,5.4934287,0.0,0,4.1185417,0.0,0.45573241,46.81778,4.5416985,543.33844,-9.2608204
2313,2313,178.719,5.8001475,5.5100646,0.0,0,4.0989256,0.0,0.4569371,46.785999,4.5218873,543.3963,-9.260541
2314,2314,178.7192,5.7952023,5.5258827,0.0,0,4.0793095,0.0,0.45944911,46.646919,4.5018358,543.45416,-9.2600689
2315,2315,178.7194,5.7949772,5.5511436,0.0,0,4.0596938,0.0,0.46205533,46.539707,4.4823737,543.51202,-9.2591143
2316,2316,178.7196,5.7995486,5.5714226,0.0,0,4.0404716,0.0,0.46334067,46.469116,4.460813,543.54095,-9.2590637
2317,2317,178.7198,5.8127222,5.5883164,0.0,0,4.0217257,0.0,0.46580842,46.422314,4.4387197,543.54095,-9.2597361
2318,2318,178.72,5.8309283,5.6112618,0.0,0,4.0030656,0.0,0.46857184,46.474903,4.4190464,543.54095,-9.2603207
2319,2319,178.7202,5.8488817,5.6319432,0.0,0,3.9844093,0.0,0.46990064,46.575848,4.399682,543.54095,-9.2603416
2320,2320,178.7204,5.8745532,5.6495118,0.0,0,3.9657533,0.0,0.4721846,46.698807,4.3802595,543.54095,-9.2605982
2321,2321,178.7206,5.898746,5.6712704,0.0,0,3.9470973,0.0,0.47499704,46.761951,4.3590245,543.54095,-9.2603836
2322,2322,178.7208,5.9133625,5.6945248,0.0,0,3.9284413,0.0,0.47650948,46.748463,4.3375912,543.54095,-9.260108
2323,2323,178.721,5.920639,5.7124448,0.0,0,3.9097853,0.0,0.47870612,46.700748,4.3185201,543.54095,-9.2603321
2324,2324,178.7212,5.9239278,5.7298021,0.0,0,3.8911293,0.0,0.48145682,46.608456,4.299119,543.54095,-9.2602959
2325,2325,178.7214,5.9215784,5.7527456,0.0,0,3.8724735,0.0,0.48301676,46.529938,4.2796645,543.54095,-9.2595367
2326,2326,178.7216,5.9263644,5.771771,0.0,0,3.8538175,0.0,0.48499084,46.419331,4.2598047,543.54095,-9.2592564
2327,2327,178.7218,5.9361091,5.786458,0.0,0,3.8351612,0.0,0.48762548,46.355579,4.2411981,543.54095,-9.2595444
2328,2328,178.722,5.9499502,5.8104267,0.0,0,3.8165054,0.0,0.4894118,46.453224,4.2201638,543.54095,-9.2603836
2329,2329,178.7222,5.9729109,5.8316545,0.0,0,3.7978494,0.0,0.49129075,46.521809,4.1984992,543.54095,-9.2608643
2330,2330,178.7224,5.9951692,5.8451238,0.0,0,3.7791932,0.0,0.49389604,46.525425,4.1764622,543.54095,-9.2601376
2331,2331,178.7226,6.0160022,5.869432,0.0,0,3.7605371,0.0,0.49608034,46.591152,4.156146,543.54095,-9.2601051
2332,2332,178.7228,6.0321832,5.8930264,0.0,0,3.7418811,0.0,0.498007,46.695923,4.139956,543.54095,-9.2602644
2333,2333,178.723,6.0361505,5.9054933,0.0,0,3.7232254,0.0,0.5004825,46.677052,4.122684,543.54095,-9.2604685
2334,2334,178.7232,6.0416069,5.9283447,0.0,0,3.7045693,0.0,0.50276369,46.567604,4.1017771,543.54095,-9.26021
2335,2335,178.7234,6.0460677,5.9534173,0.0,0,3.6859133,0.0,0.50448173,46.469299,4.0796614,543.54095,-9.260006
2336,2336,178.7236,6.0511198,5.9647183,0.0,0,3.6672573,0.0,0.50671959,46.364597,4.0601931,543.54095,-9.2608538
2337,2337,178.7238,6.066113,5.9868784,0.0,0,3.6486013,0.0,0.5093025,46.3139,4.0415473,543.54095,-9.2609367
2338,2338,178.724,6.0786119,6.013855,0.0,0,3.6299453,0.0,0.51112241,46.366695,4.0226984,543.54095,-9.2601795
2339,2339,178.7242,6.1021323,6.0239882,0.0,0,3.6112893,0.0,0.51315665,46.462788,4.003212,543.54095,-9.2605305
2340,2340,178.7244,6.1289883,6.0431585,0.0,0,3.5926332,0.0,0.51577079,46.533718,3.9847071,543.54095,-9.2613831
2341,2341,178.7246,6.1463404,6.0696745,0.0,0,3.5743496,0.0,0.51750767,46.644981,3.966145,543.54095,-9.2609444
2342,2342,178.7248,6.1624713,6.0795202,0.0,0,3.5565166,0.0,0.51921284,46.674564,3.9458199,543.54095,-9.2601871
2343,2343,178.725,6.1734085,6.098124,0.0,0,3.538765,0.0,0.52204573,46.629623,3.9260151,543.54095,-9.2596445
2344,2344,178.7252,6.1823034,6.1268702,0.0,0,3.5210168,0.0,0.52408707,46.631416,3.9092925,543.54095,-9.2592154
2345,2345,178.7254,6.1856093,6.1397648,0.0,0,3.5032687,0.0,0.52573109,46.576958,3.8901808,543.54095,-9.2592154
2346,2346,178.7256,6.1866255,6.1571116,0.0,0,3.4855206,0.0,0.52867043,46.459061,3.8698556,543.54095,-9.2590084
2347,2347,178.7258,6.2022867,6.1843624,0.0,0,3.4677727,0.0,0.5308457,46.458328,3.8515098,543.54095,-9.2601099
2348,2348,178.726,6.2181582,6.197762,0.0,0,3.4500248,0.0,0.53222507,46.473236,3.8326831,543.54095,-9.2606335
2349,2349,178.7262,6.2284861,6.2145534,0.0,0,3.432277,0.0,0.53509766,46.392857,3.8138232,543.54095,-9.2607212
2350,2350,178.7264,6.2462583,6.24224,0.0,0,3.4145288,0.0,0.53753483,46.430405,3.7941406,543.54095,-9.2610149
2351,2351,178.7266,6.2672081,6.2572265,0.0,0,3.3967807,0.0,0.53883028,46.55653,3.7743623,543.54095,-9.260376
2352,2352,178.7268,6.2889333,6.2722158,0.0,0,3.3790326,0.0,0.5415321,46.590248,3.7564936,543.54095,-9.2603188
2353,2353,178.727,6.3030477,6.297143,0.0,0,3.3612847,0.0,0.54418129,46.558201,3.7374444,543.54095,-9.2600422
2354,2354,178.7272,6.3132544,6.3142147,0.0,0,3.3435369,0.0,0.54548186,46.529602,3.7175565,543.54095,-9.2592897
2355,2355,178.7274,6.3235621,6.3302641,0.0,0,3.3257887,0.0,0.54807091,46.470051,3.69853,543.54095,-9.2587185
2356,2356,178.7276,6.3322744,6.3546052,0.0,0,3.3080409,0.0,0.55089968,46.418114,3.6801684,543.54095,-9.2587032
2357,2357,178.7278,6.3450642,6.3728933,0.0,0,3.2902927,0.0,0.55217928,46.449112,3.6615429,543.54095,-9.2592535
2358,2358,178.728,6.350069,6.3871245,0.0,0,3.2725446,0.0,0.55455869,46.464077,3.644434,543.54095,-9.2606649
2359,2359,178.7282,6.3646259,6.4089408,0.0,0,3.2547965,0.0,0.55737102,46.446335,3.6267297,543.54095,-9.2611227
2360,2360,178.7284,6.3952575,6.4295716,0.0,0,3.2370486,0.0,0.55879569,46.530247,3.6059468,543.54095,-9.2604856
2361,2361,178.7286,6.4241438,6.4446788,0.0,0,3.2193007,0.0,0.56115901,46.650829,3.5876265,543.54095,-9.2601376
2362,2362,178.7288,6.4488416,6.4633985,0.0,0,3.2015526,0.0,0.56396919,46.715649,3.5704799,543.54095,-9.2593784
2363,2363,178.729,6.4601111,6.4843965,0.0,0,3.1838048,0.0,0.56530178,46.754604,3.5491529,543.54095,-9.259057
2364,2364,178.7292,6.4598536,6.5005612,0.0,0,3.1660566,0.0,0.56731546,46.644497,3.5295348,543.54095,-9.2591934
2365,2365,178.7294,6.4593577,6.5166121,0.0,0,3.1483088,0.0,0.57022274,46.48436,3.5151391,543.54095,-9.2596779
2366,2366,178.7296,6.4696884,6.5392342,0.0,0,3.1309152,0.0,0.57190418,46.493824,3.4981427,543.51532,-9.259757
2367,2367,178.7298,6.4862809,6.557827,0.0,0,3.11395,0.0,0.57388896,46.517727,3.4784546,543.46399,-9.2596703
2368,2368,178.73,6.4996991,6.5718756,0.0,0,3.0970623,0.0,0.57676756,46.460392,3.4596283,543.41272,-9.2604647
2369,2369,178.7302,6.5152783,6.5949054,0.0,0,3.0801783,0.0,0.57869488,46.50293,3.4404328,543.36139,-9.2605534
2370,2370,178.7304,6.5416183,6.6152945,0.0,0,3.0632944,0.0,0.58061409,46.591892,3.4205146,543.31012,-9.2602911
2371,2371,178.7306,6.5712352,6.6277819,0.0,0,3.0464106,0.0,0.5833801,46.629349,3.4018924,543.25879,-9.260335
2372,2372,178.7308,6.5973506,6.6514978,0.0,0,3.0295265,0.0,0.58564949,46.685623,3.3841209,543.20752,-9.2603502
2373,2373,178.731,6.6122103,6.6738305,0.0,0,3.0126424,0.0,0.58747393,46.745125,3.3629448,543.15619,-9.2603512
2374,2374,178.7312,6.6098852,6.6843195,0.0,0,2.9957583,0.0,0.58992338,46.684105,3.3434608,543.10492,-9.2604914
2375,2375,178.7314,6.6068592,6.7063913,0.0,0,2.9788744,0.0,0.59235567,46.54958,3.3278022,543.05359,-9.2599487
2376,2376,178.7316,6.6185007,6.7306285,0.0,0,2.9619906,0.0,0.59422576,46.51173,3.3095369,543.00232,-9.2597551
2377,2377,178.7318,6.6331286,6.7402949,0.0,0,2.9451065,0.0,0.59643877,46.514214,3.2908137,542.95099,-9.2591066
2378,2378,178.732,6.6575112,6.7603846,0.0,0,2.9282222,0.0,0.59907871,46.55872,3.2727284,542.89972,-9.2582064
2379,2379,178.7322,6.6942325,6.7853403,0.0,0,2.9113381,0.0,0.60094386,46.721107,3.2517629,542.84839,-9.2586384
2380,2380,178.7324,6.7260365,6.793313,0.0,0,2.8944542,0.0,0.60286242,46.854107,3.2332201,542.79712,-9.2585411
2381,2381,178.7326,6.7514906,6.8120604,0.0,0,2.8775704,0.0,0.60563082,46.852921,3.2184918,542.74579,-9.2585907
2382,2382,178.7328,6.7661538,6.8391557,0.0,0,2.8606863,0.0,0.60754675,46.887157,3.2001824,542.69452,-9.2594671
2383,2383,178.733,6.772572,6.8490272,0.0,0,2.8438022,0.0,0.60930735,46.90205,3.1812894,542.64325,-9.2595425
2384,2384,178.7332,6.7777987,6.8667426,0.0,0,2.8269184,0.0,0.61239022,46.755554,3.1612494,542.59192,-9.2586823
2385,2385,178.7334,6.7780156,6.8943429,0.0,0,2.810034,0.0,0.61458421,46.639839,3.1421816,542.54065,-9.2592402
2386,2386,178.7336,6.7758584,6.9060206,0.0,0,2.7931502,0.0,0.61612308,46.574085,3.1269619,542.48932,-9.2602587
2387,2387,178.7338,6.7944393,6.9228158,0.0,0,2.7762663,0.0,0.61913645,46.547825,3.1093445,542.43805,-9.2597046
2388,2388,178.734,6.8252573,6.9492087,0.0,0,2.7593822,0.0,0.62134206,46.648338,3.0913441,542.38672,-9.2596483
2389,2389,178.7342,6.8538227,6.9617896,0.0,0,2.7424984,0.0,0.62277776,46.787956,3.0731091,542.33545,-9.2602558
2390,2390,178.7344,6.878377,6.977026,0.0,0,2.7256143,0.0,0.62588596,46.810184,3.053658,542.28412,-9.2602358
2391,2391,178.7346,6.8989153,7.0024905,0.0,0,2.7090683,0.0,0.62843961,46.817192,3.0368781,542.23285,-9.2602377
2392,2392,178.7348,6.9147601,7.0158424,0.0,0,2.6929309,0.0,0.6296044,46.897018,3.0206521,542.18152,-9.2595863
2393,2393,178.735,6.9279771,7.0285277,0.0,0,2.6768677,0.0,0.63228899,46.838249,3.0032806,542.13025,-9.2594824
2394,2394,178.7352,6.9373913,7.0522652,0.0,0,2.6608074,0.0,0.63494122,46.774597,2.9852571,542.07892,-9.2594662
2395,2395,178.7354,6.941709,7.0683627,0.0,0,2.6447473,0.0,0.63607043,46.78199,2.9664383,542.02765,-9.2589455
2396,2396,178.7356,6.9465914,7.0819068,0.0,0,2.6286874,0.0,0.63876331,46.706722,2.9481347,541.97632,-9.2590771
2397,2397,178.7358,6.9621329,7.1043491,0.0,0,2.6126273,0.0,0.64176631,46.699165,2.9306352,541.92505,-9.259244
2398,2398,178.736,6.9940476,7.1221566,0.0,0,2.5965672,0.0,0.64297283,46.82658,2.9126012,541.87372,-9.2598648
2399,2399,178.7362,7.0290728,7.1354861,0.0,0,2.5805073,0.0,0.64540625,46.888607,2.8933685,541.82245,-9.2600479
2400,2400,178.7364,7.0614142,7.1550412,0.0,0,2.5644474,0.0,0.64832091,46.968246,2.8775139,541.77112,-9.2600298
2401,2401,178.7366,7.0866075,7.1739345,0.0,0,2.5483873,0.0,0.64953089,47.103954,2.8633487,541.71985,-9.2602301
2402,2402,178.7368,7.1006899,7.1879373,0.0,0,2.5323272,0.0,0.65192497,47.097252,2.8460698,541.66852,-9.2595539
2403,2403,178.737,7.1045008,7.2051196,0.0,0,2.5162673,0.0,0.65502906,46.980953,2.8283432,541.61725,-9.2594814
2404,2404,178.7372,7.1072297,7.2257581,0.0,0,2.5002072,0.0,0.65635186,46.920094,2.8109171,541.56592,-9.2595005
2405,2405,178.7374,7.1147656,7.2405214,0.0,0,2.4841473,0.0,0.65829504,46.87598,2.7944829,541.51465,-9.258728
2406,2406,178.7376,7.1270723,7.2542577,0.0,0,2.4680872,0.0,0.66128749,46.840858,2.778841,541.46332,-9.2586002
2407,2407,178.7378,7.1498723,7.275887,0.0,0,2.4520273,0.0,0.66297507,46.897221,2.762116,541.41205,-9.2590141
2408,2408,178.738,7.1785064,7.2929993,0.0,0,2.4359674,0.0,0.66497499,46.949226,2.7442267,541.36078,-9.2590513
2409,2409,178.7382,7.2117701,7.3063002,0.0,0,2.4199073,0.0,0.66800255,47.002544,2.7267129,541.30945,-9.2586308
2410,2410,178.7384,7.243247,7.3294454,0.0,0,2.4038472,0.0,0.67006683,47.127384,2.7090073,541.25818,-9.2592602
2411,2411,178.7386,7.2681603,7.3477659,0.0,0,2.3877873,0.0,0.67199898,47.200241,2.6913435,541.20685,-9.2597361
2412,2412,178.7388,7.2849956,7.3578439,0.0,0,2.3717272,0.0,0.67473364,47.216915,2.673723,541.15558,-9.2598257
2413,2413,178.739,7.2846999,7.3798885,0.0,0,2.3556671,0.0,0.67694664,47.155914,2.6591742,541.10425,-9.2596951
2414,2414,178.7392,7.2826781,7.4009242,0.0,0,2.3396072,0.0,0.67867959,47.082203,2.6434476,541.05298,-9.2591152
2415,2415,178.7394,7.2951293,7.4091086,0.0,0,2.3235474,0.0,0.68118894,47.037987,2.6270943,541.00165,-9.2591419
2416,2416,178.7396,7.3159385,7.4284558,0.0,0,2.3078089,0.0,0.68359751,47.019447,2.6092579,540.79791,-9.2590942
2417,2417,178.7398,7.3429575,7.4506221,0.0,0,2.2924595,0.0,0.68525815,47.088665,2.589896,540.44183,-9.2583885
2418,2418,178.74,7.3789573,7.4576221,0.0,0,2.2771804,0.0,0.68742269,47.178509,2.5721695,540.08575,-9.2584143
2419,2419,178.7402,7.4198914,7.4760108,0.0,0,2.2619042,0.0,0.69003856,47.305988,2.5546353,539.72968,-9.2589607
2420,2420,178.7404,7.4549017,7.5007939,0.0,0,2.246628,0.0,0.69187647,47.429821,2.5391421,539.3736,-9.2595739
2421,2421,178.7406,7.4718947,7.5087948,0.0,0,2.2313523,0.0,0.69386852,47.48344,2.5223224,539.01752,-9.2595882
2422,2422,178.7408,7.4744935,7.5265551,0.0,0,2.2160764,0.0,0.69683862,47.409328,2.5055032,538.66144,-9.2588377
2423,2423,178.741,7.4760609,7.5525031,0.0,0,2.2008004,0.0,0.69890612,47.305191,2.4864709,538.30536,-9.2587824
2424,2424,178.7412,7.4866643,7.5610113,0.0,0,2.1855242,0.0,0.70071113,47.246521,2.4682028,537.94928,-9.2588129
2425,2425,178.7414,7.5060768,7.577734,0.0,0,2.1702483,0.0,0.70389569,47.190079,2.4546723,537.5932,-9.2593336
2426,2426,178.7416,7.5249729,7.6045609,0.0,0,2.1549723,0.0,0.70606673,47.226078,2.4400473,537.23712,-9.2594223
2427,2427,178.7418,7.5522509,7.6132188,0.0,0,2.1396964,0.0,0.70749563,47.325481,2.4237993,536.88104,-9.2596312
2428,2428,178.742,7.57797,7.6265998,0.0,0,2.1244202,0.0,0.71064824,47.35593,2.4084039,536.52496,-9.2602968
2429,2429,178.7422,7.6064825,7.6517792,0.0,0,2.1091442,0.0,0.71298569,47.445618,2.3914309,536.16888,-9.2600117
2430,2430,178.7424,7.642199,7.6622519,0.0,0,2.0938683,0.0,0.71405762,47.578102,2.3738234,535.81281,-9.259284
2431,2431,178.7426,7.6608505,7.6740351,0.0,0,2.0785923,0.0,0.71695721,47.569237,2.3564699,535.45673,-9.2588549
2432,2432,178.7428,7.6637077,7.6971793,0.0,0,2.0633163,0.0,0.71944535,47.50956,2.3415186,535.10065,-9.2587996
2433,2433,178.743,7.6664801,7.7090693,0.0,0,2.0480404,0.0,0.72035408,47.507286,2.3264949,534.74457,-9.2586632
2434,2434,178.7432,7.6833835,7.7205443,0.0,0,2.0327644,0.0,0.72313786,47.473743,2.3108256,534.38849,-9.258646
2435,2435,178.7434,7.7084823,7.7436008,0.0,0,2.0174885,0.0,0.72591758,47.480591,2.2954311,534.03241,-9.2588625
2436,2436,178.7436,7.7368288,7.7585211,0.0,0,2.0022123,0.0,0.72699326,47.613758,2.2793674,533.67633,-9.2589302
2437,2437,178.7438,7.7688031,7.7703342,0.0,0,1.9869361,0.0,0.72980154,47.680386,2.2631354,533.32025,-9.2592802
2438,2438,178.744,7.7972169,7.7915144,0.0,0,1.9716601,0.0,0.73285347,47.720921,2.2442088,532.96417,-9.2598333
2439,2439,178.7442,7.8240867,7.8087463,0.0,0,1.9563841,0.0,0.73403043,47.820816,2.2265632,532.60809,-9.2597637
2440,2440,178.7444,7.849834,7.8217058,0.0,0,1.9411081,0.0,0.73670495,47.818401,2.2133846,532.25201,-9.2596579
2441,2441,178.7446,7.8692989,7.8403006,0.0,0,1.9261373,0.0,0.73983151,47.755268,2.2006626,531.89594,-9.259553
2442,2442,178.7448,7.8800755,7.857625,0.0,0,1.9115355,0.0,0.74092185,47.773197,2.1849649,531.53986,-9.2594929
2443,2443,178.745,7.8881564,7.8690624,0.0,0,1.8970004,0.0,0.7431199,47.737438,2.168072,531.18378,-9.2591858
2444,2444,178.7452,7.9021091,7.883399,0.0,0,1.8824685,0.0,0.74603337,47.678947,2.1511998,530.8277,-9.2587509
2445,2445,178.7454,7.9173779,7.901762,0.0,0,1.8679364,0.0,0.74716616,47.742996,2.1361492,530.47162,-9.2581062
2446,2446,178.7456,7.9404974,7.9151258,0.0,0,1.8534043,0.0,0.74919736,47.771217,2.1212893,530.11554,-9.2581129
2447,2447,178.7458,7.963448,7.9275875,0.0,0,1.8388724,0.0,0.75240237,47.74614,2.1056409,529.75946,-9.2587671
2448,2448,178.746,7.9899726,7.9482751,0.0,0,1.8243403,0.0,0.75406533,47.854321,2.0904586,529.40338,-9.2590132
2449,2449,178.7462,8.0256748,7.9647641,0.0,0,1.8098084,0.0,0.75594258,47.94009,2.0754344,529.0473,-9.2583265
2450,2450,178.7464,8.0526419,7.9751549,0.0,0,1.7952764,0.0,0.75893837,47.908844,2.0585825,528.69122,-9.2580137
2451,2451,178.7466,8.0811434,7.9951086,0.0,0,1.7807443,0.0,0.76088619,47.987022,2.0436602,528.33514,-9.2584286
2452,2452,178.7468,8.1071291,8.0116291,0.0,0,1.7662123,0.0,0.76265049,48.076183,2.0292504,527.97906,-9.2584782
2453,2453,178.747,8.1167774,8.019393,0.0,0,1.7516804,0.0,0.76531351,48.03178,2.0140953,527.62299,-9.2590237
2454,2454,178.7472,8.1263933,8.0396051,0.0,0,1.7371484,0.0,0.76755255,48.020485,1.9989306,527.26691,-9.2597027
2455,2455,178.7474,8.139679,8.0584135,0.0,0,1.7226164,0.0,0.76920992,48.060028,1.982614,526.91083,-9.2594652
2456,2456,178.7476,8.1653538,8.0641499,0.0,0,1.7080843,0.0,0.77157438,48.077389,1.9671085,526.55475,-9.2588015
2457,2457,178.7478,8.1986732,8.08181,0.0,0,1.6935524,0.0,0.77396113,48.091072,1.9524547,526.19867,-9.2587814
2458,2458,178.748,8.2250986,8.1035395,0.0,0,1.6790204,0.0,0.7755425,48.137497,1.9361986,525.84259,-9.2583923
2459,2459,178.7482,8.2560911,8.1098881,0.0,0,1.6644883,0.0,0.77779257,48.214924,1.9191755,525.48651,-9.2576513
2460,2460,178.7484,8.2914066,8.127491,0.0,0,1.6499563,0.0,0.78070587,48.281986,1.9040329,525.13043,-9.2572584
2461,2461,178.7486,8.3091049,8.1520395,0.0,0,1.6354244,0.0,0.78257942,48.336067,1.8893104,524.77435,-9.2572241
2462,2462,178.7488,8.3153362,8.157897,0.0,0,1.6208923,0.0,0.78453422,48.341621,1.878897,524.41821,-9.2572985
2463,2463,178.749,8.3251877,8.1728735,0.0,0,1.6063604,0.0,0.7875008,48.260574,1.8674785,524.06213,-9.2578764
2464,2464,178.7492,8.3444271,8.1965885,0.0,0,1.5918283,0.0,0.78935796,48.258766,1.8493974,523.70605,-9.2585602
2465,2465,178.7494,8.3693657,8.2024002,0.0,0,1.5772964,0.0,0.7908811,48.279625,1.8321588,523.34998,-9.2590132
2466,2466,178.7496,8.3906031,8.2155495,0.0,0,1.5630548,0.0,0.79388696,48.196186,1.8169874,522.92377,-9.2594624
2467,2467,178.7498,8.4196558,8.2397146,0.0,0,1.5491644,0.0,0.79588479,48.28252,1.8003964,522.42743,-9.2593899
2468,2468,178.75,8.456193,8.2470188,0.0,0,1.5353373,0.0,0.79709733,48.455193,1.7853506,521.93103,-9.2589693
2469,2469,178.7502,8.4996223,8.2586708,0.0,0,1.5215132,0.0,0.80021137,48.537022,1.7718837,521.43469,-9.2586832
2470,2470,178.7504,8.5385523,8.2819395,0.0,0,1.5076892,0.0,0.8024261,48.667374,1.7566257,520.93835,-9.2581959
2471,2471,178.7506,8.5526457,8.2912912,0.0,0,1.4938653,0.0,0.80347151,48.748569,1.7426442,520.44202,-9.2583418
2472,2472,178.7508,8.5600815,8.3019018,0.0,0,1.4800413,0.0,0.80652374,48.654335,1.731061,519.94562,-9.2580757
2473,2473,178.751,8.5777693,8.3246021,0.0,0,1.4662173,0.0,0.80915213,48.590767,1.7166369,519.44928,-9.2579737
2474,2474,178.7512,8.595418,8.3362761,0.0,0,1.4523933,0.0,0.81015861,48.628056,1.7023038,518.95294,-9.2578268
2475,2475,178.7514,8.618166,8.3468552,0.0,0,1.4385693,0.0,0.81316477,48.62244,1.6885813,518.45654,-9.2576847
2476,2476,178.7516,8.6391106,8.3681889,0.0,0,1.4247453,0.0,0.8161726,48.650837,1.6752193,517.96021,-9.2584152
2477,2477,178.7518,8.6686335,8.3805428,0.0,0,1.4109213,0.0,0.81691009,48.779995,1.6624225,517.46387,-9.2585993
2478,2478,178.752,8.7046194,8.3896418,0.0,0,1.3970973,0.0,0.81944245,48.876595,1.649312,516.96747,-9.2581806
2479,2479,178.7522,8.7455797,8.4081964,0.0,0,1.3832734,0.0,0.82245594,48.94632,1.6343194,516.47113,-9.2576294
2480,2480,178.7524,8.7868814,8.4231815,0.0,0,1.3694494,0.0,0.82336169,49.083912,1.6186211,515.97479,-9.2581396
2481,2481,178.7526,8.8128681,8.4331789,0.0,0,1.3556253,0.0,0.82584339,49.123554,1.6038164,515.47845,-9.2584248
2482,2482,178.7528,8.830225,8.450016,0.0,0,1.3418013,0.0,0.82907885,49.056244,1.590376,514.98206,-9.258193
2483,2483,178.753,8.8437223,8.4680481,0.0,0,1.3279774,0.0,0.8302139,49.059898,1.5774673,514.48572,-9.2582579
2484,2484,178.7532,8.8674631,8.4802036,0.0,0,1.3141534,0.0,0.8324911,49.063839,1.5623887,513.98938,-9.2587004
2485,2485,178.7534,8.8953762,8.4946795,0.0,0,1.3003293,0.0,0.83594537,49.059425,1.548355,513.49298,-9.2584362
2486,2486,178.7536,8.9205132,8.5137568,0.0,0,1.2865053,0.0,0.83742839,49.140396,1.5353383,512.99664,-9.257555
2487,2487,178.7538,8.9485149,8.5255537,0.0,0,1.2726814,0.0,0.83923805,49.204353,1.520043,512.50031,-9.2574625
2488,2488,178.754,8.9822254,8.5345364,0.0,0,1.2588574,0.0,0.8422358,49.243176,1.5036408,512.00391,-9.257596
2489,2489,178.7542,9.0163307,8.5529909,0.0,0,1.2450334,0.0,0.84376645,49.350067,1.4900215,511.50757,-9.2574377
2490,2490,178.7544,9.0541468,8.5670853,0.0,0,1.2312094,0.0,0.8453564,49.468891,1.4765936,511.01123,-9.258007
2491,2491,178.7546,9.0873299,8.5742741,0.0,0,1.2176627,0.0,0.84826148,49.484131,1.4617178,510.51486,-9.2581673
2492,2492,178.7548,9.1023159,8.5927544,0.0,0,1.2044513,0.0,0.8501575,49.446239,1.446043,510.01849,-9.2581339
2493,2493,178.755,9.1125813,8.6087275,0.0,0,1.1913006,0.0,0.851749,49.462803,1.4295064,509.52216,-9.257884
2494,2494,178.7552,9.1380863,8.6149254,0.0,0,1.1781524,0.0,0.85456139,49.48233,1.4157487,509.02579,-9.2578278
2495,2495,178.7554,9.167964,8.634634,0.0,0,1.1650045,0.0,0.85692054,49.503426,1.4053496,508.52945,-9.2579269
2496,2496,178.7556,9.1972752,8.6541166,0.0,0,1.1518564,0.0,0.85861081,49.581959,1.3923901,508.03308,-9.2574224
2497,2497,178.7558,9.2381535,8.6594257,0.0,0,1.1387084,0.0,0.86125088,49.662544,1.3773607,507.53671,-9.2573681
2498,2498,178.756,9.2916441,8.6777172,0.0,0,1.1255604,0.0,0.86409444,49.787815,1.3630505,507.04037,-9.25737
2499,2499,178.7562,9.3377819,8.7001791,0.0,0,1.1124125,0.0,0.86595434,49.961113,1.3474183,506.54401,-9.2574654
2500,2500,178.7564,9.3730564,8.7052393,0.0,0,1.0992644,0.0,0.86816615,50.047306,1.3312614,506.04767,-9.2573166
2501,2501,178.7566,9.3956909,8.7207413,0.0,0,1.0861164,0.0,0.87110472,50.037987,1.3181962,505.5513,-9.2575245
2502,2502,178.7568,9.4072084,8.7430582,0.0,0,1.0729684,0.0,0.87288737,50.025543,1.3042016,505.05493,-9.2582645
2503,2503,178.757,9.4244442,8.7470102,0.0,0,1.0598203,0.0,0.87459409,50.026714,1.2902153,504.55859,-9.2592688
2504,2504,178.7572,9.4544563,8.7598715,0.0,0,1.0466723,0.0,0.87758064,50.021938,1.2777714,504.06223,-9.2593985
2505,2505,178.7574,9.4884567,8.7818232,0.0,0,1.0335244,0.0,0.87923884,50.108376,1.2627639,503.56589,-9.2591324
2506,2506,178.7576,9.5245771,8.7862406,0.0,0,1.0203763,0.0,0.8805694,50.244419,1.2464285,503.06952,-9.2593107
2507,2507,178.7578,9.5771017,8.7985468,0.0,0,1.0072284,0.0,0.88385224,50.32571,1.2310605,502.57318,-9.2588425
2508,2508,178.758,9.6250057,8.8223038,0.0,0,0.99408036,0.0,0.88596874,50.456791,1.2185527,502.07681,-9.2577953
2509,2509,178.7582,9.6648436,8.8295126,0.0,0,0.98093235,0.0,0.88723165,50.609924,1.2055446,501.58044,-9.2573633
2510,2510,178.7584,9.6966839,8.8418369,0.0,0,0.96778435,0.0,0.89074153,50.622963,1.1924176,501.08411,-9.2570744
2511,2511,178.7586,9.7152681,8.8660192,0.0,0,0.95463634,0.0,0.89328384,50.621346,1.1787584,500.58774,-9.256361
2512,2512,178.7588,9.7352333,8.875824,0.0,0,0.94148839,0.0,0.89450467,50.654057,1.1648445,500.0914,-9.2565451
2513,2513,178.759,9.7592754,8.8873091,0.0,0,0.92834044,0.0,0.89813435,50.585438,1.1515868,499.59503,-9.2576466
2514,2514,178.7592,9.7816944,8.9100866,0.0,0,0.91519243,0.0,0.90105361,50.553379,1.1413633,499.09866,-9.2583065
2515,2515,178.7594,9.8090296,8.9205713,0.0,0,0.90204442,0.0,0.90181392,50.645065,1.1269883,498.60233,-9.2582922
2516,2516,178.7596,9.8567905,8.928318,0.0,0,0.88916051,0.0,0.90476525,50.731014,1.1101013,498.26553,-9.2579212
2517,2517,178.7598,9.9122143,8.9468718,0.0,0,0.87659609,0.0,0.90760237,50.873161,1.0955113,498.08826,-9.2576885
2518,2518,178.76,9.9552383,8.9586868,0.0,0,0.86408949,0.0,0.90808874,51.097267,1.0822268,497.91098,-9.2582569
2519,2519,178.7602,9.9968481,8.9668732,0.0,0,0.85158539,0.0,0.91081423,51.177895,1.0691531,497.7337,-9.2580671
2520,2520,178.7604,10.024717,8.9839602,0.0,0,0.83908135,0.0,0.91407859,51.144249,1.0571415,497.55646,-9.2573128
2521,2521,178.7606,10.044832,8.9981518,0.0,0,0.82657731,0.0,0.91480124,51.202709,1.0422939,497.37918,-9.256999
2522,2522,178.7608,10.069651,9.006815,0.0,0,0.81407332,0.0,0.9172309,51.208099,1.0260028,497.2019,-9.2563944
2523,2523,178.761,10.09414,9.0224838,0.0,0,0.8015694,0.0,0.92071021,51.168148,1.0130048,497.02463,-9.2557859
2524,2524,178.7612,10.125026,9.0406637,0.0,0,0.78906536,0.0,0.92191535,51.268734,0.99831706,496.84735,-9.255681
2525,2525,178.7614,10.166284,9.0520983,0.0,0,0.77656138,0.0,0.92431921,51.339561,0.9845987,496.67007,-9.2561951
2526,2526,178.7616,10.207721,9.0654478,0.0,0,0.7640574,0.0,0.92790222,51.365032,0.97127336,496.4928,-9.2566328
2527,2527,178.7618,10.253564,9.0844536,0.0,0,0.75155336,0.0,0.92938298,51.49612,0.95683151,496.31555,-9.2569523
2528,2528,178.762,10.303804,9.0963888,0.0,0,0.73904938,0.0,0.93145227,51.615097,0.94213706,496.13828,-9.257967
2529,2529,178.7622,10.340074,9.1051302,0.0,0,0.72654539,0.0,0.93484479,51.67318,0.93119532,495.961,-9.2580128
2530,2530,178.7624,10.372531,9.1239367,0.0,0,0.71404135,0.0,0.93641871,51.772659,0.91896707,495.78372,-9.257349
2531,2531,178.7626,10.402903,9.1372929,0.0,0,0.70153737,0.0,0.93798429,51.827225,0.90306205,495.60645,-9.2575569
2532,2532,178.7628,10.430053,9.1433735,0.0,0,0.68903339,0.0,0.94116402,51.788803,0.88783354,495.42917,-9.2573462
2533,2533,178.763,10.464442,9.1607819,0.0,0,0.67652941,0.0,0.94317979,51.809952,0.87619674,495.25189,-9.2560959
2534,2534,178.7632,10.506302,9.1755047,0.0,0,0.66402543,0.0,0.94459158,51.89732,0.86471456,495.07465,-9.2560921
2535,2535,178.7634,10.542286,9.1805563,0.0,0,0.65152138,0.0,0.94734883,51.986225,0.84982574,494.89737,-9.2557936
2536,2536,178.7636,10.583102,9.1986103,0.0,0,0.63901734,0.0,0.94970113,52.09396,0.83345282,494.72009,-9.2558327
2537,2537,178.7638,10.633167,9.2186537,0.0,0,0.62651336,0.0,0.95142543,52.221878,0.82090068,494.54282,-9.2568407
2538,2538,178.764,10.678114,9.2242527,0.0,0,0.61400938,0.0,0.95433545,52.33078,0.80863255,494.36554,-9.2569218
2539,2539,178.7642,10.722172,9.2407713,0.0,0,0.6015054,0.0,0.95732647,52.390026,0.79382253,494.18826,-9.2566147
2540,2540,178.7644,10.761733,9.26157,0.0,0,0.58900136,0.0,0.95909107,52.471375,0.77889127,494.01099,-9.2566013
2541,2541,178.7646,10.782521,9.265686,0.0,0,0.57674509,0.0,0.96134746,52.478542,0.76654124,493.83371,-9.2571869
2542,2542,178.7648,10.804014,9.2793694,0.0,0,0.56478846,0.0,0.96442515,52.426296,0.75511551,493.65646,-9.2572451
2543,2543,178.765,10.841729,9.3001041,0.0,0,0.55288601,0.0,0.96605599,52.525047,0.74208707,493.47919,-9.2572412
2544,2544,178.7652,10.888169,9.3029976,0.0,0,0.54098594,0.0,0.96763182,52.647724,0.72872633,493.30191,-9.2577419
2545,2545,178.7654,10.933491,9.3156452,0.0,0,0.52908593,0.0,0.97099233,52.644817,0.71572036,493.12463,-9.257762
2546,2546,178.7656,10.973909,9.3379602,0.0,0,0.51718587,0.0,0.97290188,52.755188,0.70172244,492.94736,-9.2566833
2547,2547,178.7658,11.025901,9.3412857,0.0,0,0.50528592,0.0,0.97413874,52.949982,0.68754518,492.77008,-9.2560902
2548,2548,178.766,11.078746,9.3525953,0.0,0,0.49338591,0.0,0.97763932,52.987625,0.67520642,492.5928,-9.2558804
2549,2549,178.7662,11.122177,9.3758917,0.0,0,0.4814859,0.0,0.97991145,53.097004,0.66186368,492.41556,-9.2559423
2550,2550,178.7664,11.158181,9.382576,0.0,0,0.4695859,0.0,0.98103809,53.226158,0.65014756,492.23828,-9.2563515
2551,2551,178.7666,11.183475,9.3930788,0.0,0,0.45768592,0.0,0.98461384,53.170822,0.637218,492.061,-9.2564182
2552,2552,178.7668,11.213334,9.4158297,0.0,0,0.44578591,0.0,0.9872703,53.166126,0.62187117,491.88373,-9.2565918
2553,2553,178.767,11.253633,9.4240808,0.0,0,0.4338859,0.0,0.9881621,53.288887,0.60945326,491.70645,-9.2570229
2554,2554,178.7672,11.290547,9.4329424,0.0,0,0.42198589,0.0,0.99162591,53.300259,0.59969878,491.52917,-9.2575846
2555,2555,178.7674,11.32598,9.4541035,0.0,0,0.41008592,0.0,0.99467355,53.311882,0.58790338,491.3519,-9.2581863
2556,2556,178.7676,11.375666,9.4638605,0.0,0,0.39818591,0.0,0.99519187,53.490669,0.57398826,491.17465,-9.257618