File: clean data/testID_0134.csv
level_0,index,Time(sec),Force(kN),Jaw(mm),PowAngle(deg),Power(W),Pram,PTemp,Strain,Stress(MPa),Stroke(mm),TC1(C),wedge(mm)
1872,1872,155.3437,0.2507098,0.011850791,0.0,0,9.0629511,0.0,0.00060683209,2.5367334,10.078559,347.49557,-9.3079863
1874,1874,155.3441,3.0198476,0.053982168,0.0,0,9.0044231,0.0,0.0033861995,33.487473,10.014858,347.58414,-9.3074265
1876,1876,155.3445,5.6601539,0.11036611,0.0,0,8.9458952,0.0,0.006951075,69.524109,9.9623013,347.87796,-9.3053207
1878,1878,155.3449,6.329668,0.16967206,0.0,0,8.8873672,0.0,0.010734553,79.037582,9.8875246,348.42233,-9.3029423
1880,1880,155.3453,6.6778631,0.30990875,0.0,0,8.8288393,0.0,0.020178337,83.229973,9.8061371,348.96671,-9.3024282
1882,1882,155.3457,7.1065993,0.37436572,0.0,0,8.7703114,0.0,0.02469644,87.358055,9.7119532,349.51111,-9.3022547
1884,1884,155.3461,7.4568591,0.4587194,0.0,0,8.7136698,0.0,0.030373875,91.933678,9.6252604,350.05548,-9.3023863
1886,1886,155.3465,8.0284853,0.52496052,0.0,0,8.657999,0.0,0.035566542,97.896751,9.5408926,350.59985,-9.3016567
1888,1888,155.3469,7.7499809,0.54541343,0.0,0,8.602335,0.0,0.036405355,96.09584,9.4741592,351.14423,-9.30019
1890,1890,155.3473,7.6789203,0.63976645,0.0,0,8.5466709,0.0,0.043128107,92.761482,9.4121227,351.6886,-9.3015509
1892,1892,155.3477,8.2996664,0.67958927,0.0,0,8.4910078,0.0,0.046128415,100.61575,9.3440847,352.23297,-9.3016806
1894,1894,155.3481,8.407218,0.75138462,0.0,0,8.4353428,0.0,0.050507203,101.56203,9.2786064,352.77734,-9.2997532
1896,1896,155.3485,8.3415785,0.85010326,0.0,0,8.3796787,0.0,0.05794077,100.74342,9.1995173,353.32172,-9.2999868
1898,1898,155.3489,8.1109047,0.92266488,0.0,0,8.3240156,0.0,0.062762275,96.702805,9.1224823,353.86609,-9.3006573
1900,1900,155.3493,8.5590725,1.0052421,0.0,0,8.2683516,0.0,0.068890169,101.43726,9.0450268,354.41046,-9.301446
1902,1902,155.3497,8.518671,1.0477718,0.0,0,8.2126875,0.0,0.07233572,100.75665,8.9744034,354.95483,-9.3010159
1904,1904,155.3501,8.7386923,1.1017066,0.0,0,8.1570234,0.0,0.075587071,103.11736,8.9130077,355.49921,-9.3005714
1906,1906,155.3505,8.3980532,1.1730052,0.0,0,8.1013594,0.0,0.081117265,99.049484,8.8482523,356.04361,-9.3009682
1908,1908,155.3509,8.7859554,1.2231424,0.0,0,8.0462503,0.0,0.084765159,102.06585,8.7900639,356.58798,-9.3000708
1910,1910,155.3513,8.9669313,1.2950747,0.0,0,7.9931588,0.0,0.08944685,104.64267,8.7254124,357.13235,-9.2999001
1912,1912,155.3517,8.8357744,1.378269,0.0,0,7.9401984,0.0,0.096107095,102.23028,8.6599178,357.67673,-9.2993288
1914,1914,155.3521,8.8072681,1.4421847,0.0,0,7.8872385,0.0,0.10047031,101.5595,8.586524,358.2211,-9.3006659
1916,1916,155.3525,8.8031378,1.5079347,0.0,0,7.8342786,0.0,0.10540438,100.62784,8.5256681,358.76547,-9.3002329
1918,1918,155.3529,9.075057,1.5434084,0.0,0,7.7813182,0.0,0.10864923,103.48393,8.4658899,359.30984,-9.2995987
1920,1920,155.3533,9.0073957,1.5984608,0.0,0,7.7283583,0.0,0.11189335,102.68835,8.4074183,359.85422,-9.3000116
1922,1922,155.3537,8.9988956,1.6603315,0.0,0,7.6753979,0.0,0.11701655,101.8518,8.352705,360.39859,-9.299489
1924,1924,155.3541,9.139327,1.700034,0.0,0,7.622438,0.0,0.12013661,103.04897,8.2938499,360.94296,-9.2990122
1926,1926,155.3545,9.2569399,1.7752883,0.0,0,7.569478,0.0,0.12493666,103.99224,8.2365828,361.37454,-9.3004265
1928,1928,155.3549,9.2223644,1.8332421,0.0,0,7.5165181,0.0,0.13007282,103.14355,8.1743736,361.63712,-9.3001938
1930,1930,155.3553,9.244895,1.8905357,0.0,0,7.4635582,0.0,0.13427655,102.90093,8.1134472,361.89969,-9.3000746
1932,1932,155.3557,9.252099,1.9553784,0.0,0,7.4105978,0.0,0.13896821,102.46172,8.0556908,362.16226,-9.3006592
1934,1934,155.3561,9.3711061,1.9897354,0.0,0,7.3593445,0.0,0.14228238,103.36102,7.9963894,362.42484,-9.2996445
1936,1936,155.3565,9.3815222,2.046371,0.0,0,7.3089714,0.0,0.14608563,103.27277,7.9456143,362.68741,-9.2990046
1938,1938,155.3569,9.3458605,2.1037934,0.0,0,7.2586036,0.0,0.1506386,102.36707,7.89364,362.94998,-9.299818
1940,1940,155.3573,9.4829378,2.1428792,0.0,0,7.2082353,0.0,0.15402363,103.39998,7.8417516,363.21255,-9.3007965
1942,1942,155.3577,9.5912333,2.2031412,0.0,0,7.157867,0.0,0.15810007,104.15755,7.78859,363.47513,-9.2997856
1944,1944,155.3581,9.5928335,2.2606196,0.0,0,7.1074986,0.0,0.16299674,103.81606,7.7301874,363.7377,-9.3000584
1946,1946,155.3585,9.5425081,2.3123646,0.0,0,7.0571313,0.0,0.16715783,102.87435,7.6790638,364.00027,-9.2997856
1948,1948,155.3589,9.6100636,2.3682184,0.0,0,7.0067625,0.0,0.17121488,102.93328,7.6220241,364.26285,-9.2991714
1950,1950,155.3593,9.7459869,2.4114103,0.0,0,6.9563951,0.0,0.17520081,104.02784,7.5722289,364.52542,-9.3000526
1952,1952,155.3597,9.7541971,2.4647315,0.0,0,6.9060268,0.0,0.17910625,103.90049,7.5236135,364.78799,-9.3004808
1954,1954,155.3601,9.6982126,2.5147555,0.0,0,6.8556595,0.0,0.18301703,102.87474,7.472806,365.05057,-9.3011255
1956,1956,155.3605,9.7767115,2.559078,0.0,0,6.8052912,0.0,0.18704231,103.07104,7.4209509,365.31314,-9.3009768
1958,1958,155.3609,9.8871307,2.6139007,0.0,0,6.7554259,0.0,0.19085518,104.03223,7.3734908,365.57571,-9.2999916
1960,1960,155.3613,9.8959646,2.6609933,0.0,0,6.7073865,0.0,0.1947926,103.74036,7.3218565,365.83829,-9.2980309
1962,1962,155.3617,9.9201345,2.7093458,0.0,0,6.6594663,0.0,0.19913407,103.46415,7.2728014,366.10086,-9.2991076
1964,1964,155.3621,9.9086561,2.7625871,0.0,0,6.611546,0.0,0.20280094,103.02496,7.2213922,366.36343,-9.3001595
1966,1966,155.3625,10.016849,2.8052874,0.0,0,6.5636263,0.0,0.20674649,103.55695,7.1691785,366.62601,-9.3002281
1968,1968,155.3629,10.057971,2.8525078,0.0,0,6.5157065,0.0,0.21074066,103.74454,7.1226897,366.88858,-9.3003674
1970,1970,155.3633,10.077126,2.9047914,0.0,0,6.4677868,0.0,0.21441616,103.50949,7.0730186,367.15115,-9.2985735
1972,1972,155.3637,10.145298,2.9470322,0.0,0,6.4198661,0.0,0.21854956,103.75969,7.0230794,367.41373,-9.2993374
1974,1974,155.3641,10.169455,2.9966235,0.0,0,6.3719459,0.0,0.22249867,103.59211,6.973485,367.6763,-9.3005829
1976,1976,155.3645,10.215622,3.0523546,0.0,0,6.3240261,0.0,0.22680083,103.64019,6.9252801,367.78513,-9.300704
1978,1978,155.3649,10.239891,3.0949457,0.0,0,6.2761064,0.0,0.23097335,103.35835,6.8768144,367.6088,-9.3004656
1980,1980,155.3653,10.304748,3.1413243,0.0,0,6.2281866,0.0,0.23435427,103.74194,6.8256726,367.4325,-9.3003817
1982,1982,155.3657,10.344894,3.191102,0.0,0,6.1802664,0.0,0.2386312,103.75294,6.7799354,367.25616,-9.2999992
1984,1984,155.3661,10.365946,3.2324049,0.0,0,6.1338902,0.0,0.24261135,103.51754,6.7317433,367.07986,-9.2992964
1986,1986,155.3665,10.384947,3.279438,0.0,0,6.0883088,0.0,0.24604206,103.32517,6.6837974,366.90353,-9.2999687
1988,1988,155.3669,10.476538,3.3318729,0.0,0,6.0427332,0.0,0.25082991,103.67271,6.6370606,366.72723,-9.3000345
1990,1990,155.3673,10.543083,3.3748589,0.0,0,5.9971571,0.0,0.25469583,104.10955,6.5900021,366.5509,-9.2990952
1992,1992,155.3677,10.550259,3.4254527,0.0,0,5.9515805,0.0,0.25854695,103.7142,6.5427375,366.3746,-9.3006945
1994,1994,155.3681,10.559037,3.4739628,0.0,0,5.9060054,0.0,0.26327553,103.28249,6.4933224,366.19827,-9.2995577
1996,1996,155.3685,10.605609,3.5169303,0.0,0,5.8604288,0.0,0.26678279,103.31998,6.447094,366.02197,-9.3000574
1998,1998,155.3689,10.692474,3.5664666,0.0,0,5.8148527,0.0,0.27083862,103.77111,6.4008632,365.84564,-9.3008242
2000,2000,155.3693,10.72751,3.6101046,0.0,0,5.7692766,0.0,0.27530596,103.73257,6.3522339,365.66934,-9.3000622
2002,2002,155.3697,10.735974,3.6579549,0.0,0,5.7237005,0.0,0.27885449,103.45327,6.3063011,365.49301,-9.3000803
2004,2004,155.3701,10.762344,3.7059031,0.0,0,5.6781249,0.0,0.28320208,103.25542,6.2601399,365.31671,-9.2993898
2006,2006,155.3705,10.835413,3.7475064,0.0,0,5.6325488,0.0,0.28748021,103.50723,6.2098846,365.14038,-9.2998552
2008,2008,155.3709,10.898171,3.8010311,0.0,0,5.5874276,0.0,0.29141459,103.58868,6.1657767,364.96405,-9.2999926
2010,2010,155.3713,10.915689,3.8440688,0.0,0,5.5439596,0.0,0.29573223,103.41364,6.1195292,364.78775,-9.2999449
2012,2012,155.3717,10.942768,3.8856492,0.0,0,5.5005994,0.0,0.29964212,103.16624,6.0724158,364.61142,-9.2999277
2014,2014,155.3721,10.984541,3.9399683,0.0,0,5.4572392,0.0,0.30376318,103.19659,6.0241308,364.43512,-9.3004007
2016,2016,155.3725,11.041276,3.9796989,0.0,0,5.4138794,0.0,0.30823195,103.32339,5.9793835,364.25879,-9.3001699
2018,2018,155.3729,11.091446,4.0238318,0.0,0,5.3705192,0.0,0.31185335,103.38,5.9359336,364.08249,-9.2987852
2020,2020,155.3733,11.136251,4.0776558,0.0,0,5.3271594,0.0,0.31643718,103.30032,5.882864,363.90616,-9.2993927
2022,2022,155.3737,11.177187,4.1156454,0.0,0,5.2837992,0.0,0.32066759,103.23229,5.8399444,363.72986,-9.2999802
2024,2024,155.3741,11.212812,4.1614261,0.0,0,5.2404394,0.0,0.32429725,103.20992,5.7959185,363.55353,-9.2998047
2026,2026,155.3745,11.249275,4.2141471,0.0,0,5.1970797,0.0,0.3291868,103.05637,5.7448659,363.37021,-9.299964
2028,2028,155.3749,11.327718,4.2529287,0.0,0,5.1537194,0.0,0.3333222,103.2508,5.6998463,363.17059,-9.2999315
2030,2030,155.3753,11.362166,4.3015394,0.0,0,5.1103592,0.0,0.33708298,103.24734,5.6546211,362.97098,-9.2990408
2032,2032,155.3757,11.414149,4.3499112,0.0,0,5.0669994,0.0,0.34211463,103.12355,5.6090193,362.77136,-9.3000402
2034,2034,155.3761,11.4272,4.3904033,0.0,0,5.0250354,0.0,0.34604955,102.97116,5.5632701,362.57175,-9.3009338
2036,2036,155.3765,11.462659,4.4392886,0.0,0,4.9837909,0.0,0.35009322,102.82081,5.5159979,362.37213,-9.3005018
2038,2038,155.3769,11.542749,4.480092,0.0,0,4.9425507,0.0,0.35476577,102.97116,5.4749269,362.17252,-9.299861
2040,2040,155.3773,11.581293,4.5252213,0.0,0,4.9013109,0.0,0.3586325,102.99924,5.4275804,361.9729,-9.2995329
2042,2042,155.3777,11.603549,4.5733237,0.0,0,4.8600707,0.0,0.36293188,102.76559,5.3835855,361.77328,-9.2992897
2044,2044,155.3781,11.632975,4.6157136,0.0,0,4.818831,0.0,0.36786854,102.505,5.3401346,361.57367,-9.2994843
2046,2046,155.3785,11.685349,4.6641083,0.0,0,4.7775908,0.0,0.37169573,102.5582,5.2951546,361.37405,-9.3001614
2048,2048,155.3789,11.768556,4.7054238,0.0,0,4.7363505,0.0,0.37598836,102.79904,5.2491941,361.17444,-9.3015623
2050,2050,155.3793,11.815533,4.7466006,0.0,0,4.6951108,0.0,0.38048553,102.76942,5.2050152,360.97482,-9.3012362
2052,2052,155.3797,11.844864,4.7975121,0.0,0,4.6538711,0.0,0.38452744,102.61781,5.1620941,360.77521,-9.3001194
2054,2054,155.3801,11.873923,4.8378148,0.0,0,4.6126304,0.0,0.38916072,102.44413,5.1179619,360.57559,-9.2991209
2056,2056,155.3805,11.938003,4.879631,0.0,0,4.5713906,0.0,0.39322647,102.551,5.0742035,360.37598,-9.298604
2058,2058,155.3809,11.997428,4.930984,0.0,0,4.5305629,0.0,0.3975046,102.61868,5.0284972,360.17636,-9.2986298
2060,2060,155.3813,12.02861,4.9674749,0.0,0,4.4912333,0.0,0.40216759,102.39857,4.9862509,359.97675,-9.2995338
2062,2062,155.3817,12.061749,5.0094934,0.0,0,4.4520011,0.0,0.40603158,102.25204,4.9416556,359.77713,-9.3013134
2064,2064,155.3821,12.092246,5.0611825,0.0,0,4.4127688,0.0,0.41075578,102.003,4.8969841,359.57751,-9.3014975
2066,2066,155.3825,12.163464,5.0961962,0.0,0,4.3735371,0.0,0.41515619,102.14776,4.8551435,359.3779,-9.3006182
2068,2068,155.3829,12.242179,5.1413026,0.0,0,4.3343053,0.0,0.41901675,102.43949,4.8101039,359.17828,-9.298789
2070,2070,155.3833,12.280128,5.1907768,0.0,0,4.2950735,0.0,0.4240644,102.24375,4.7634339,358.97867,-9.2995634
2072,2072,155.3837,12.301481,5.2262287,0.0,0,4.2558408,0.0,0.42837691,101.99426,4.723268,358.77905,-9.3006172
2074,2074,155.3841,12.342408,5.2729526,0.0,0,4.216609,0.0,0.43216267,101.92445,4.6817451,358.57944,-9.3007488
2076,2076,155.3845,12.406889,5.3177118,0.0,0,4.1773767,0.0,0.43739656,101.9477,4.6376109,358.36859,-9.3009386
2078,2078,155.3849,12.492329,5.3546553,0.0,0,4.138145,0.0,0.44125789,102.2524,4.5921907,358.12421,-9.2986345
2080,2080,155.3853,12.517031,5.4002056,0.0,0,4.0989132,0.0,0.44551286,102.02483,4.5522923,357.87985,-9.2985258
2082,2082,155.3857,12.542316,5.4408364,0.0,0,4.0596809,0.0,0.45061937,101.74033,4.5116625,357.63547,-9.2991409
2084,2084,155.3861,12.589298,5.4821458,0.0,0,4.0217133,0.0,0.45436487,101.69128,4.4690862,357.39108,-9.3002167
2086,2086,155.3865,12.670246,5.5255466,0.0,0,3.9843972,0.0,0.45877343,101.9184,4.4256697,357.1467,-9.3000946
2088,2088,155.3869,12.746873,5.5630774,0.0,0,3.9470851,0.0,0.46357974,102.05829,4.3859172,356.90231,-9.3000889
2090,2090,155.3873,12.775477,5.6085939,0.0,0,3.9097731,0.0,0.46747878,101.90026,4.344707,356.65796,-9.299305
2092,2092,155.3877,12.805153,5.6490693,0.0,0,3.8724613,0.0,0.47209483,101.65194,4.3011107,356.41357,-9.2997789
2094,2094,155.3881,12.868143,5.6845489,0.0,0,3.835149,0.0,0.47648701,101.67471,4.2618513,356.16919,-9.2992401
2096,2096,155.3885,12.940906,5.7334704,0.0,0,3.7978373,0.0,0.48056602,101.84116,4.2225823,355.9248,-9.29879
2098,2098,155.3889,12.996328,5.7685232,0.0,0,3.760525,0.0,0.48521522,101.78999,4.1836534,355.68042,-9.2986956
2100,2100,155.3893,13.023138,5.8054533,0.0,0,3.7232132,0.0,0.48924544,101.63255,4.142705,355.43604,-9.2998295
2102,2102,155.3897,13.073656,5.8544407,0.0,0,3.6859012,0.0,0.49362043,101.51578,4.1007204,355.19168,-9.299366
2104,2104,155.3901,13.140283,5.8858871,0.0,0,3.6485891,0.0,0.49822304,101.57845,4.0601616,354.9473,-9.2987146
2106,2106,155.3905,13.204655,5.9243011,0.0,0,3.6112771,0.0,0.50195855,101.71726,4.0214381,354.70291,-9.2999392
2108,2108,155.3909,13.271152,5.9719615,0.0,0,3.5743382,0.0,0.50675511,101.70865,3.9811676,354.45853,-9.2987413
2110,2110,155.3913,13.317183,6.0024061,0.0,0,3.5387533,0.0,0.51116425,101.61022,3.9400094,354.21414,-9.2994051
2112,2112,155.3917,13.349173,6.0427289,0.0,0,3.5032573,0.0,0.51481068,101.47566,3.9027224,353.96976,-9.3006907
2114,2114,155.3921,13.41794,6.0867038,0.0,0,3.467761,0.0,0.51984328,101.49846,3.8657129,353.7254,-9.2994337
2116,2116,155.3925,13.482696,6.119627,0.0,0,3.4322653,0.0,0.52418321,101.51894,3.8258548,353.48102,-9.2986889
2118,2118,155.3929,13.556008,6.1642737,0.0,0,3.3967693,0.0,0.52818632,101.73975,3.7879064,353.23663,-9.298316
2120,2120,155.3933,13.592671,6.2030735,0.0,0,3.3612733,0.0,0.53343242,101.53271,3.7492397,352.99225,-9.2986126
2122,2122,155.3937,13.644287,6.2334509,0.0,0,3.3257771,0.0,0.53691608,101.52603,3.7119229,352.74786,-9.2993298
2124,2124,155.3941,13.703339,6.2730064,0.0,0,3.2902813,0.0,0.54078853,101.59303,3.6750278,352.50351,-9.3006124
2126,2126,155.3945,13.777665,6.3080525,0.0,0,3.2547851,0.0,0.54581553,101.58945,3.6340022,352.2157,-9.2987595
2128,2128,155.3949,13.853943,6.3461757,0.0,0,3.2192891,0.0,0.54948699,101.77707,3.6018372,351.75455,-9.2982626
2130,2130,155.3953,13.892802,6.3870726,0.0,0,3.1837931,0.0,0.55409569,101.592,3.5642569,351.2934,-9.2982454
2132,2132,155.3957,13.947952,6.4215045,0.0,0,3.1482971,0.0,0.55900675,101.50478,3.5259984,350.83228,-9.2987604
2134,2134,155.3961,14.015156,6.4635844,0.0,0,3.113939,0.0,0.56282532,101.55431,3.4876626,350.37112,-9.2986145
2136,2136,155.3965,14.094182,6.4996443,0.0,0,3.0801673,0.0,0.56751025,101.68512,3.45418,349.91,-9.2986479
2138,2138,155.3969,14.162514,6.5286036,0.0,0,3.0463996,0.0,0.57158518,101.77464,3.4167016,349.44885,-9.2988071
2140,2140,155.3973,14.217633,6.5732512,0.0,0,3.0126314,0.0,0.57559311,101.80135,3.3767622,348.9877,-9.2992802
2142,2142,155.3977,14.25537,6.6054468,0.0,0,2.9788635,0.0,0.5802179,101.60255,3.3407211,348.52658,-9.2993698
2144,2144,155.3981,14.324426,6.6387491,0.0,0,2.9450955,0.0,0.58427382,101.60963,3.3060677,348.06543,-9.2986107
2146,2146,155.3985,14.411433,6.6842532,0.0,0,2.9113271,0.0,0.58870798,101.79532,3.2700007,347.60431,-9.2986612
2148,2148,155.3989,14.491286,6.7122293,0.0,0,2.8775594,0.0,0.59342623,101.89003,3.2314184,347.14316,-9.2985334
2150,2150,155.3993,14.548139,6.7488351,0.0,0,2.8437912,0.0,0.59721076,101.90755,3.1967969,346.68201,-9.298543
2152,2152,155.3997,14.598366,6.7933593,0.0,0,2.8100231,0.0,0.60220563,101.75845,3.1596851,346.22089,-9.2985287
2154,2154,155.4001,14.679185,6.8190455,0.0,0,2.7762554,0.0,0.60657781,101.83996,3.1260247,345.75974,-9.2985373
2156,2156,155.4005,14.763642,6.8539515,0.0,0,2.7424874,0.0,0.60980028,102.10651,3.0921841,345.29858,-9.2987175
2158,2158,155.4009,14.835435,6.8947415,0.0,0,2.7090578,0.0,0.6148541,102.12515,3.0560379,344.83746,-9.2995024
2160,2160,155.4013,14.8799,6.9234715,0.0,0,2.6768572,0.0,0.6191805,101.97638,3.0195909,344.37631,-9.298358
2162,2162,155.4017,14.935026,6.9645247,0.0,0,2.644737,0.0,0.6231274,101.95046,2.9882803,343.91519,-9.2985697
2164,2164,155.4021,15.019231,7.000865,0.0,0,2.612617,0.0,0.62858468,101.91455,2.9538455,343.45404,-9.2977924
2166,2166,155.4025,15.129718,7.0297632,0.0,0,2.5804968,0.0,0.63219219,102.30503,2.9202099,342.99289,-9.2979517
2168,2168,155.4029,15.197016,7.0659733,0.0,0,2.5483768,0.0,0.63587695,102.45071,2.8794334,342.53177,-9.2982941
2170,2170,155.4033,15.237503,7.0977097,0.0,0,2.5162568,0.0,0.64113516,102.1532,2.8463795,342.07062,-9.2985382
2172,2172,155.4037,15.306067,7.1354532,0.0,0,2.4841368,0.0,0.64489955,102.15318,2.8136611,341.60947,-9.2985792
2174,2174,155.4041,15.384955,7.1719241,0.0,0,2.4520168,0.0,0.64948803,102.25409,2.7767749,341.14835,-9.2977943
2176,2176,155.4045,15.489522,7.2017584,0.0,0,2.4198971,0.0,0.65439594,102.46173,2.7449856,340.68845,-9.2969532
2178,2178,155.4049,15.563874,7.2393117,0.0,0,2.3877769,0.0,0.6580925,102.53963,2.7134411,340.23569,-9.2971029
2180,2180,155.4053,15.610412,7.2716823,0.0,0,2.3556569,0.0,0.66264284,102.3849,2.6803904,339.78293,-9.2972202
2182,2182,155.4057,15.690836,7.299531,0.0,0,2.3235369,0.0,0.66704518,102.49891,2.6437042,339.33014,-9.2985373
2184,2184,155.4061,15.784829,7.3412671,0.0,0,2.2924495,0.0,0.67086923,102.7461,2.6121812,338.87738,-9.2982807
2186,2186,155.4065,15.894705,7.3705177,0.0,0,2.2618942,0.0,0.67590195,102.88755,2.5789952,338.42459,-9.2970972
2188,2188,155.4069,15.95693,7.4027333,0.0,0,2.2313423,0.0,0.68006271,102.85585,2.5447598,337.97183,-9.297101
2190,2190,155.4073,16.014112,7.4462776,0.0,0,2.2007904,0.0,0.68464798,102.79345,2.5074248,337.51904,-9.296854
2192,2192,155.4077,16.102739,7.4703302,0.0,0,2.1702383,0.0,0.68945438,102.8404,2.4773571,337.06628,-9.2984381
2194,2194,155.4081,16.198093,7.5014439,0.0,0,2.1396863,0.0,0.69293785,103.08891,2.4446824,336.61349,-9.2993879
2196,2196,155.4085,16.288284,7.5417705,0.0,0,2.1091342,0.0,0.69772047,103.17357,2.409446,336.16074,-9.2986488
2198,2198,155.4089,16.34922,7.5649676,0.0,0,2.0785823,0.0,0.70217085,103.1356,2.3787854,335.70798,-9.2967129
2200,2200,155.4093,16.417871,7.6003456,0.0,0,2.0480304,0.0,0.70568365,103.17994,2.3443565,335.25519,-9.296401
2202,2202,155.4097,16.504478,7.6380277,0.0,0,2.0174785,0.0,0.71112067,103.12463,2.3129001,334.80243,-9.2980728
2204,2204,155.4101,16.610233,7.6630187,0.0,0,1.9869262,0.0,0.71529323,103.30919,2.2811511,334.34964,-9.2981567
2206,2206,155.4105,16.714548,7.6991348,0.0,0,1.9563742,0.0,0.71902412,103.58479,2.249428,333.89688,-9.2985258
2208,2208,155.4109,16.784529,7.7324963,0.0,0,1.9261278,0.0,0.72450674,103.51756,2.2176518,333.44409,-9.2969847
2210,2210,155.4113,16.860069,7.7592554,0.0,0,1.896991,0.0,0.72803515,103.57727,2.1820972,332.99133,-9.296443
2212,2212,155.4117,16.961,7.7930565,0.0,0,1.8679268,0.0,0.73193753,103.82058,2.153486,332.53854,-9.2967567
2214,2214,155.4121,17.065008,7.822515,0.0,0,1.8388629,0.0,0.73722976,103.85857,2.1244209,332.08578,-9.2975521
2216,2216,155.4125,17.184574,7.8539991,0.0,0,1.8097988,0.0,0.74092764,104.22164,2.0898173,331.633,-9.2982807
2218,2218,155.4129,17.258749,7.8886838,0.0,0,1.7807349,0.0,0.74563503,104.23776,2.0598173,331.18024,-9.2979984
2220,2220,155.4133,17.344252,7.9171586,0.0,0,1.751671,0.0,0.75080162,104.1304,2.0298164,330.72748,-9.2968893
2222,2222,155.4137,17.442535,7.954771,0.0,0,1.7226069,0.0,0.75461501,104.386,1.9985758,330.27469,-9.2955046
2224,2224,155.4141,17.552402,7.9838266,0.0,0,1.693543,0.0,0.7593866,104.49342,1.9703692,329.82193,-9.2955799
2226,2226,155.4145,17.663923,8.0081787,0.0,0,1.6644789,0.0,0.76359648,104.7803,1.9376651,329.34598,-9.2972021
2228,2228,155.4149,17.746445,8.0470448,0.0,0,1.6354148,0.0,0.76750022,104.84133,1.9089684,328.66238,-9.2972889
2230,2230,155.4153,17.836658,8.0711956,0.0,0,1.6063509,0.0,0.77235711,104.85603,1.8735729,327.97879,-9.2974129
2232,2232,155.4157,17.934925,8.0999804,0.0,0,1.5772868,0.0,0.77631736,105.0029,1.8448526,327.29517,-9.2971344
2234,2234,155.4161,18.048391,8.1403675,0.0,0,1.5491554,0.0,0.78098923,105.17603,1.8170788,326.61157,-9.2963915
2236,2236,155.4165,18.165342,8.1635618,0.0,0,1.5215043,0.0,0.78602606,105.32557,1.7840753,325.92798,-9.2959557
2238,2238,155.4169,18.263525,8.1934233,0.0,0,1.4938563,0.0,0.78946495,105.54223,1.7524301,325.24435,-9.2954407
2240,2240,155.4173,18.348043,8.2299395,0.0,0,1.4662082,0.0,0.79443949,105.51685,1.7228397,324.56076,-9.2963324
2242,2242,155.4177,18.448961,8.2490082,0.0,0,1.4385602,0.0,0.79875398,105.60399,1.6925379,323.87714,-9.2967834
2244,2244,155.4181,18.571142,8.2823877,0.0,0,1.4109124,0.0,0.80217665,105.95112,1.662631,323.19354,-9.2976189
2246,2246,155.4185,18.71372,8.3184738,0.0,0,1.3832644,0.0,0.80820227,106.1215,1.6315104,322.50995,-9.2957039
2248,2248,155.4189,18.803246,8.3416348,0.0,0,1.3556163,0.0,0.81241059,106.20394,1.6052455,321.82632,-9.295332
2250,2250,155.4193,18.887705,8.3748207,0.0,0,1.3279684,0.0,0.81605464,106.26907,1.5745525,321.14273,-9.2960901
2252,2252,155.4197,19.001778,8.4036951,0.0,0,1.3003204,0.0,0.82150573,106.32841,1.5460354,320.45914,-9.2962198
2254,2254,155.4201,19.144489,8.4250717,0.0,0,1.2726724,0.0,0.82460129,106.75701,1.517826,319.77551,-9.2960243
2256,2256,155.4205,19.264544,8.4568501,0.0,0,1.2450243,0.0,0.82851732,107.03056,1.4880891,319.09192,-9.2958136
2258,2258,155.4209,19.356567,8.4851484,0.0,0,1.217654,0.0,0.83441627,106.92453,1.4574952,318.40833,-9.2956524
2260,2260,155.4213,19.43808,8.5165243,0.0,0,1.191292,0.0,0.83807397,107.0071,1.4303397,317.7247,-9.2954845
2262,2262,155.4217,19.567408,8.5493822,0.0,0,1.1649959,0.0,0.84298754,107.15726,1.4049658,317.04111,-9.2958498
2264,2264,155.4221,19.710943,8.5715818,0.0,0,1.1386998,0.0,0.84794086,107.38422,1.3768038,316.35748,-9.2961893
2266,2266,155.4225,19.83218,8.60357,0.0,0,1.1124039,0.0,0.85117584,107.77523,1.34606,315.67389,-9.294795
2268,2268,155.4229,19.928314,8.6294279,0.0,0,1.0861079,0.0,0.85596478,107.72421,1.3171301,314.9903,-9.2953568
2270,2270,155.4233,20.032793,8.650444,0.0,0,1.0598118,0.0,0.85998893,107.8655,1.2889913,314.30667,-9.2959929
2272,2272,155.4237,20.162203,8.6870966,0.0,0,1.0335158,0.0,0.86387706,108.15838,1.2588395,313.62308,-9.2968874
2274,2274,155.4241,20.312164,8.7096081,0.0,0,1.0072198,0.0,0.86905134,108.40701,1.2346913,312.93948,-9.2976532
2276,2276,155.4245,20.435534,8.7364235,0.0,0,0.98092377,0.0,0.8730374,108.61879,1.2041851,312.26895,-9.2960682
2278,2278,155.4249,20.532377,8.7748241,0.0,0,0.95462781,0.0,0.87795663,108.61663,1.1727446,311.84525,-9.2948847
2280,2280,155.4253,20.660828,8.7926579,0.0,0,0.92833185,0.0,0.88285774,108.77812,1.1467172,311.42154,-9.2948627
2282,2282,155.4257,20.79995,8.816947,0.0,0,0.90203583,0.0,0.88563931,109.12374,1.1190214,310.99783,-9.2940845
2284,2284,155.4261,20.959307,8.8519392,0.0,0,0.87658799,0.0,0.89074343,109.41634,1.0891377,310.57413,-9.2957983
2286,2286,155.4265,21.076906,8.8703947,0.0,0,0.85157722,0.0,0.89536333,109.57596,1.060768,310.15042,-9.2955332
2288,2288,155.4269,21.184662,8.9020014,0.0,0,0.8265692,0.0,0.89894265,109.70087,1.0349853,309.72668,-9.2958622
2290,2290,155.4273,21.290413,8.9342813,0.0,0,0.80156124,0.0,0.90482098,109.61774,1.007615,309.30298,-9.2948103
2292,2292,155.4277,21.427362,8.9516401,0.0,0,0.77655327,0.0,0.90853333,109.88221,0.97966409,308.87927,-9.2950315
2294,2294,155.4281,21.576965,8.9798307,0.0,0,0.75154519,0.0,0.91177893,110.32309,0.95560956,308.45557,-9.2945223
2296,2296,155.4285,21.71137,9.0060406,0.0,0,0.72653723,0.0,0.91739428,110.37682,0.92739964,308.03186,-9.2942171
2298,2298,155.4289,21.821947,9.028861,0.0,0,0.7015292,0.0,0.92096758,110.56029,0.90249723,307.60815,-9.2952929
2300,2300,155.4293,21.962442,9.0596409,0.0,0,0.67652124,0.0,0.92508763,110.79794,0.87503022,307.18445,-9.295104
2302,2302,155.4297,22.115135,9.0815325,0.0,0,0.65151328,0.0,0.93056601,110.92587,0.84938759,306.76074,-9.295558
2304,2304,155.4301,22.271744,9.1078768,0.0,0,0.6265052,0.0,0.93369848,111.39108,0.82644618,306.33704,-9.2945261
2306,2306,155.4305,22.404726,9.1371136,0.0,0,0.60149723,0.0,0.93856245,111.51762,0.79995227,305.91333,-9.2934189
2308,2308,155.4309,22.519573,9.1581383,0.0,0,0.57673728,0.0,0.94357812,111.53753,0.77578032,305.48959,-9.2938557
2310,2310,155.4313,22.670712,9.1879721,0.0,0,0.55287826,0.0,0.94690871,111.89424,0.7491551,305.06589,-9.2945156
2312,2312,155.4317,22.81662,9.2102938,0.0,0,0.52907819,0.0,0.95160824,112.08437,0.7257356,304.64218,-9.2952557
2314,2314,155.4321,22.975424,9.2286501,0.0,0,0.50527817,0.0,0.95554888,112.42294,0.69838583,304.21848,-9.294384
2316,2316,155.4325,23.10552,9.2635345,0.0,0,0.48147815,0.0,0.9594205,112.64378,0.6712752,303.79477,-9.293848
2318,2318,155.4329,23.222481,9.2836533,0.0,0,0.45767817,0.0,0.96487594,112.63367,0.646716,303.37106,-9.2941217
2320,2320,155.4333,23.361986,9.3060465,0.0,0,0.43387815,0.0,0.96839577,112.87656,0.6227802,302.94736,-9.2930517
2322,2322,155.4337,23.513037,9.3383837,0.0,0,0.41007817,0.0,0.97255248,113.1197,0.59871,302.52365,-9.2930708
2324,2324,155.4341,23.673222,9.3519096,0.0,0,0.38627815,0.0,0.97737318,113.33747,0.5724687,302.09995,-9.2937899
2326,2326,155.4345,23.808975,9.374464,0.0,0,0.36247814,0.0,0.98003644,113.71695,0.54678428,301.67624,-9.2932444