File: clean data/testID_0099.csv
level_0,index,Time(sec),Force(kN),Jaw(mm),PowAngle(deg),Power(W),Pram,PTemp,Strain,Stress(MPa),Stroke(mm),TC1(C),wedge(mm)
2272,2272,195.3472,0.8410868,0.017981397,0.0,0,9.0629702,0.0,0.0010300012,9.5976896,10.111928,454.34476,-9.2380161
2273,2273,195.3474,1.8703681,0.024902852,0.0,0,9.0337067,0.0,0.0013390308,20.404528,10.076974,454.43579,-9.2381201
2274,2274,195.3476,3.3799698,0.050976045,0.0,0,9.0044422,0.0,0.0031858368,39.002113,10.046556,454.52679,-9.2373791
2275,2275,195.3478,4.4708271,0.085987456,0.0,0,8.9751787,0.0,0.0053045307,54.308613,10.025369,454.6178,-9.2365656
2276,2276,195.348,4.9271941,0.10539004,0.0,0,8.9459143,0.0,0.0065962831,61.505787,10.001901,454.70883,-9.2357969
2277,2277,195.3482,5.0948868,0.12657766,0.0,0,8.9166508,0.0,0.0082703605,64.049332,9.9702911,454.79984,-9.2346926
2278,2278,195.3484,5.2204432,0.17033735,0.0,0,8.8873863,0.0,0.010836039,65.446014,9.9333467,455.02383,-9.2338257
2279,2279,195.3486,5.2267957,0.23278782,0.0,0,8.8581219,0.0,0.014580264,65.728668,9.8955774,455.38086,-9.2340479
2280,2280,195.3488,5.0502009,0.30057985,0.0,0,8.8288584,0.0,0.019501708,63.524624,9.8559952,455.73788,-9.2339706
2281,2281,195.349,4.983036,0.34948167,0.0,0,8.7995939,0.0,0.023174647,61.931065,9.810935,456.09491,-9.2341232
2282,2282,195.3492,5.2544656,0.3740631,0.0,0,8.7703304,0.0,0.024750289,64.49778,9.7643948,456.45193,-9.2349472
2283,2283,195.3494,5.4687819,0.40470919,0.0,0,8.7416534,0.0,0.026857371,67.476891,9.7177305,456.80893,-9.2348881
2284,2284,195.3496,5.430028,0.45746234,0.0,0,8.7136879,0.0,0.030371835,67.265419,9.6707821,457.16595,-9.2342901
2285,2285,195.3498,5.4838533,0.51225501,0.0,0,8.6858492,0.0,0.033925902,67.172005,9.6301126,457.52298,-9.2334929
2286,2286,195.35,5.7229548,0.54437208,0.0,0,8.6580172,0.0,0.036628652,69.635124,9.5917358,457.88,-9.232646
2287,2287,195.3502,5.8036904,0.55186117,0.0,0,8.6301851,0.0,0.037624277,71.258522,9.5543308,458.23703,-9.2319975
2288,2288,195.3504,5.5562372,0.561225,0.0,0,8.6023531,0.0,0.037805561,68.991379,9.5204,458.59402,-9.2318811
2289,2289,195.3506,5.286869,0.59526855,0.0,0,8.574522,0.0,0.039827235,65.227066,9.4872904,458.95105,-9.2332716
2290,2290,195.3508,5.3619695,0.6448769,0.0,0,8.546689,0.0,0.043452267,64.899101,9.4538851,459.30807,-9.2341681
2291,2291,195.351,5.7285862,0.68633866,0.0,0,8.518857,0.0,0.046289101,68.738586,9.423234,459.6651,-9.2340603
2292,2292,195.3512,6.0247564,0.70471323,0.0,0,8.4910259,0.0,0.047789555,72.625076,9.3941565,460.02209,-9.2340784
2293,2293,195.3514,6.0746789,0.71646541,0.0,0,8.4631929,0.0,0.048916824,73.740448,9.3595753,460.37912,-9.2341518
2294,2294,195.3516,6.0180635,0.75648201,0.0,0,8.4353609,0.0,0.051044565,73.021912,9.3241091,460.73615,-9.2333326
2295,2295,195.3518,5.9958525,0.81917804,0.0,0,8.4075298,0.0,0.054987133,72.321136,9.2869234,461.09317,-9.2331114
2296,2296,195.352,5.9483395,0.87436366,0.0,0,8.3796968,0.0,0.059458751,71.582497,9.2469759,461.4502,-9.233285
2297,2297,195.3522,5.8659,0.91921878,0.0,0,8.3518648,0.0,0.062745929,70.359085,9.2065792,461.80719,-9.2340155
2298,2298,195.3524,5.825572,0.95306861,0.0,0,8.3240337,0.0,0.064959258,69.531639,9.1651897,462.16422,-9.2345438
2299,2299,195.3526,5.8685045,0.98182905,0.0,0,8.2962017,0.0,0.067350663,69.714409,9.1223459,462.52124,-9.2331467
2300,2300,195.3528,5.9693766,1.0266302,0.0,0,8.2683697,0.0,0.070331849,70.608421,9.0814466,462.87827,-9.2321939
2301,2301,195.353,6.0526052,1.0710391,0.0,0,8.2405376,0.0,0.073203124,71.515381,9.0428238,463.23526,-9.2322378
2302,2302,195.3532,6.070323,1.09084,0.0,0,8.2127056,0.0,0.075276546,71.70713,9.0053139,463.59229,-9.2322245
2303,2303,195.3534,6.0444226,1.1114563,0.0,0,8.1848736,0.0,0.076864026,71.434715,8.9694014,463.94931,-9.2322378
2304,2304,195.3536,6.0032125,1.1434617,0.0,0,8.1570415,0.0,0.0785418,70.839302,8.9339161,464.30634,-9.2319794
2305,2305,195.3538,5.9378595,1.1711936,0.0,0,8.1292095,0.0,0.080765486,69.914665,8.9034433,464.66336,-9.2323208
2306,2306,195.354,5.9094014,1.2038981,0.0,0,8.1013775,0.0,0.083399355,69.269211,8.8743362,465.02036,-9.2334499
2307,2307,195.3542,6.0198803,1.2330934,0.0,0,8.0735455,0.0,0.085222051,70.016144,8.8454094,465.37738,-9.233902
2308,2308,195.3544,6.2159109,1.2474409,0.0,0,8.0462685,0.0,0.086519197,72.074387,8.8172474,465.73441,-9.2341127
2309,2309,195.3546,6.3587089,1.2768112,0.0,0,8.0196619,0.0,0.088740945,73.782066,8.7871923,466.09143,-9.2334471
2310,2310,195.3548,6.3833451,1.3237367,0.0,0,7.993176,0.0,0.091557719,74.163513,8.7573643,466.44843,-9.2325201
2311,2311,195.355,6.3331032,1.3611003,0.0,0,7.9666953,0.0,0.094397798,73.500763,8.7232924,466.80545,-9.2324429
2312,2312,195.3552,6.2645302,1.3981385,0.0,0,7.9402156,0.0,0.097512014,72.485519,8.6880608,467.16248,-9.2320385
2313,2313,195.3554,6.2101669,1.4372346,0.0,0,7.9137359,0.0,0.10003418,71.666779,8.6539316,467.5195,-9.2320118
2314,2314,195.3556,6.1840911,1.4671353,0.0,0,7.8872557,0.0,0.10223369,71.149101,8.6172094,467.87653,-9.2323456
2315,2315,195.3558,6.2069974,1.5038639,0.0,0,7.8607755,0.0,0.10536432,71.04113,8.5810137,468.23352,-9.232317
2316,2316,195.356,6.2731738,1.5444667,0.0,0,7.8342957,0.0,0.10822947,71.520615,8.5458403,468.59055,-9.2319126
2317,2317,195.3562,6.3251367,1.5686088,0.0,0,7.8078156,0.0,0.10995173,72.076897,8.5088291,468.94757,-9.2314816
2318,2318,195.3564,6.3507514,1.5878699,0.0,0,7.7813354,0.0,0.11179625,72.260117,8.47647,469.3046,-9.2320118
2319,2319,195.3566,6.3448095,1.6159664,0.0,0,7.7548552,0.0,0.11369994,72.060905,8.4464388,469.66159,-9.2327681
2320,2320,195.3568,6.3203564,1.6461605,0.0,0,7.7283754,0.0,0.11551508,71.669098,8.4147224,470.01862,-9.2329063
2321,2321,195.357,6.2845879,1.6786314,0.0,0,7.7018952,0.0,0.11828113,71.13797,8.3866348,470.37564,-9.2326717
2322,2322,195.3572,6.2696543,1.7102472,0.0,0,7.675415,0.0,0.12082206,70.749992,8.3578205,470.73267,-9.2327156
2323,2323,195.3574,6.3246355,1.7315187,0.0,0,7.6489348,0.0,0.12216639,71.164627,8.3292408,471.08969,-9.2332869
2324,2324,195.3576,6.4204803,1.7527105,0.0,0,7.6224551,0.0,0.12393512,72.101547,8.301342,471.44669,-9.2333212
2325,2325,195.3578,6.4962311,1.7821342,0.0,0,7.5959754,0.0,0.126187,72.78447,8.273262,471.80371,-9.232996
2326,2326,195.358,6.5282793,1.815272,0.0,0,7.5694952,0.0,0.12828392,73.093918,8.2449112,472.16074,-9.2328615
2327,2327,195.3582,6.5307555,1.8506216,0.0,0,7.543015,0.0,0.13111748,72.965813,8.2162457,472.51776,-9.2326107
2328,2328,195.3584,6.5424905,1.8843958,0.0,0,7.5165353,0.0,0.13400006,72.843346,8.1871843,472.80237,-9.2325573
2329,2329,195.3586,6.5529771,1.9163402,0.0,0,7.4900556,0.0,0.13603306,72.820618,8.1552954,473.01462,-9.2331572
2330,2330,195.3588,6.5264573,1.9461573,0.0,0,7.4635754,0.0,0.13835377,72.378693,8.1240721,473.22684,-9.2336893
2331,2331,195.359,6.4915233,1.9730409,0.0,0,7.4370952,0.0,0.14090802,71.798859,8.093112,473.43909,-9.233242
2332,2332,195.3592,6.4909272,2.0041049,0.0,0,7.410615,0.0,0.14293195,71.636353,8.0605488,473.65131,-9.2334929
2333,2333,195.3594,6.5276127,2.032671,0.0,0,7.3846664,0.0,0.14502285,71.87265,8.0309553,473.86353,-9.2333937
2334,2334,195.3596,6.5684638,2.0547032,0.0,0,7.3593612,0.0,0.14724676,72.141785,8.0021744,474.07578,-9.2326574
2335,2335,195.3598,6.5804992,2.0836966,0.0,0,7.3341722,0.0,0.14918557,72.171707,7.9737077,474.28799,-9.2320242
2336,2336,195.36,6.5668125,2.113137,0.0,0,7.3089881,0.0,0.15121071,71.872223,7.9458976,474.50024,-9.2326231
2337,2337,195.3602,6.5562439,2.1361845,0.0,0,7.2838039,0.0,0.1534908,71.572197,7.9169455,474.71246,-9.2335262
2338,2338,195.3604,6.5666213,2.1666114,0.0,0,7.2586198,0.0,0.15561105,71.538696,7.8895359,474.92471,-9.2336187
2339,2339,195.3606,6.6036291,2.1949422,0.0,0,7.2334356,0.0,0.15744674,71.77903,7.8642998,475.13693,-9.2335482
2340,2340,195.3608,6.6546946,2.210927,0.0,0,7.2082515,0.0,0.15924847,72.186378,7.8384147,475.34918,-9.2328663
2341,2341,195.361,6.6875138,2.2359874,0.0,0,7.1830673,0.0,0.16109861,72.456932,7.8122945,475.5614,-9.2326002
2342,2342,195.3612,6.7065516,2.268002,0.0,0,7.1578832,0.0,0.16306785,72.568001,7.7861457,475.77362,-9.2333345
2343,2343,195.3614,6.7282729,2.2912023,0.0,0,7.1326995,0.0,0.16535003,72.674667,7.7589369,475.98587,-9.2339058
2344,2344,195.3616,6.7443275,2.321831,0.0,0,7.1075153,0.0,0.16787636,72.630989,7.7289901,476.19809,-9.2338858
2345,2345,195.3618,6.7346244,2.3565474,0.0,0,7.0823312,0.0,0.1701045,72.449898,7.7011247,476.41034,-9.2335196
2346,2346,195.362,6.7204647,2.377244,0.0,0,7.0571475,0.0,0.17211495,72.156067,7.6757755,476.62256,-9.2330112
2347,2347,195.3622,6.7288408,2.4046488,0.0,0,7.0319633,0.0,0.17455642,71.943016,7.6472139,476.83481,-9.233119
2348,2348,195.3624,6.7591715,2.4385047,0.0,0,7.0067792,0.0,0.17670117,72.060883,7.6199732,477.04703,-9.232914
2349,2349,195.3626,6.7961917,2.4578514,0.0,0,6.981595,0.0,0.17847164,72.349617,7.5930915,477.25928,-9.2323322
2350,2350,195.3628,6.8167968,2.4827478,0.0,0,6.9564114,0.0,0.18082304,72.495323,7.5654922,477.4715,-9.2322645
2351,2351,195.363,6.8106422,2.5145094,0.0,0,6.9312277,0.0,0.18289539,72.258118,7.5370207,477.68372,-9.2330961
2352,2352,195.3632,6.786757,2.534786,0.0,0,6.9060431,0.0,0.18459992,71.885086,7.5114512,477.89597,-9.2329073
2353,2353,195.3634,6.7735577,2.5601728,0.0,0,6.8808594,0.0,0.18700537,71.561447,7.4872227,478.10818,-9.232398
2354,2354,195.3636,6.7785802,2.589,0.0,0,6.8556757,0.0,0.18895367,71.420547,7.4614296,478.32043,-9.2326498
2355,2355,195.3638,6.8044677,2.6046438,0.0,0,6.830492,0.0,0.19020277,71.581093,7.4354367,478.53265,-9.2325869
2356,2356,195.364,6.8522792,2.6241522,0.0,0,6.8053074,0.0,0.19221899,71.841431,7.4085097,478.7449,-9.2330141
2357,2357,195.3642,6.9036913,2.6534982,0.0,0,6.7801232,0.0,0.19428712,72.207947,7.3801146,478.95712,-9.2330217
2358,2358,195.3644,6.9323759,2.6763523,0.0,0,6.7554417,0.0,0.19587497,72.488541,7.3549929,479.16934,-9.2331362
2359,2359,195.3646,6.9382501,2.701128,0.0,0,6.7313671,0.0,0.19830574,72.428917,7.3323469,479.38159,-9.2333441
2360,2360,195.3648,6.9313993,2.7319527,0.0,0,6.7074022,0.0,0.20069703,72.196648,7.3090587,479.59381,-9.2329569
2361,2361,195.365,6.9268327,2.7555678,0.0,0,6.6834416,0.0,0.20228243,72.000694,7.2835498,479.80606,-9.2334442
2362,2362,195.3652,6.9302273,2.7797787,0.0,0,6.6594815,0.0,0.20468421,71.868645,7.256937,480.01828,-9.2333927
2363,2363,195.3654,6.937613,2.809293,0.0,0,6.6355219,0.0,0.20718162,71.794205,7.2325845,480.23053,-9.2333364
2364,2364,195.3656,6.9486876,2.8332508,0.0,0,6.6115613,0.0,0.20879453,71.761795,7.2087283,480.44275,-9.2337103
2365,2365,195.3658,6.9676595,2.8553069,0.0,0,6.5876017,0.0,0.21090659,71.7509,7.1846075,480.655,-9.2325449
2366,2366,195.366,6.9980135,2.8793659,0.0,0,6.5636415,0.0,0.21301575,71.913338,7.160399,480.86722,-9.2318678
2367,2367,195.3662,7.0301375,2.9021647,0.0,0,6.5396819,0.0,0.2144078,72.177963,7.1372118,481.07944,-9.2322893
2368,2368,195.3664,7.0457563,2.9256177,0.0,0,6.5157218,0.0,0.21649526,72.242844,7.112226,481.29169,-9.2324696
2369,2369,195.3666,7.0380158,2.9492784,0.0,0,6.4917622,0.0,0.21883759,72.03968,7.0869288,481.50391,-9.2320223
2370,2370,195.3668,7.0382876,2.9728765,0.0,0,6.467802,0.0,0.22038148,71.95118,7.0606647,481.71616,-9.2325706
2371,2371,195.367,7.0577273,2.9939919,0.0,0,6.4438419,0.0,0.22217421,72.016777,7.0358911,481.92838,-9.2338734
2372,2372,195.3672,7.0824003,3.0141082,0.0,0,6.4198818,0.0,0.22434172,72.004547,7.0145292,482.14063,-9.2346535
2373,2373,195.3674,7.102972,3.0411272,0.0,0,6.3959212,0.0,0.22608414,72.063622,6.9918633,482.35284,-9.2352238
2374,2374,195.3676,7.1146278,3.0681515,0.0,0,6.3719616,0.0,0.22814772,72.067451,6.9662957,482.56509,-9.2346792
2375,2375,195.3678,7.1253648,3.0897627,0.0,0,6.3480015,0.0,0.23061864,71.996872,6.9405141,482.77731,-9.2338524
2376,2376,195.368,7.1458879,3.1174269,0.0,0,6.3240418,0.0,0.23260176,72.074356,6.9188476,482.98953,-9.2328367
2377,2377,195.3682,7.1681743,3.1439614,0.0,0,6.3000817,0.0,0.23449862,72.133705,6.8956585,483.20178,-9.2328529
2378,2378,195.3684,7.1857963,3.1618469,0.0,0,6.2761221,0.0,0.23665942,72.224899,6.8695869,483.31625,-9.2329073
2379,2379,195.3686,7.1981711,3.1880319,0.0,0,6.252162,0.0,0.23863606,72.240852,6.8446403,483.33298,-9.2323885
2380,2380,195.3688,7.2078676,3.2157955,0.0,0,6.2282019,0.0,0.24050719,72.10788,6.8176808,483.3497,-9.2328176
2381,2381,195.369,7.207335,3.2322083,0.0,0,6.2042422,0.0,0.24251889,72.005661,6.7937393,483.36642,-9.2334385
2382,2382,195.3692,7.2083616,3.2569518,0.0,0,6.1802821,0.0,0.24452306,71.915291,6.773385,483.38315,-9.2334366
2383,2383,195.3694,7.2162123,3.2855651,0.0,0,6.1568027,0.0,0.24631454,71.812592,6.7501488,483.3999,-9.2334042
2384,2384,195.3696,7.2154675,3.3012309,0.0,0,6.1339049,0.0,0.24820529,71.645134,6.7240596,483.41663,-9.2338905
2385,2385,195.3698,7.2244248,3.3249593,0.0,0,6.1111121,0.0,0.25039494,71.552742,6.7004886,483.43335,-9.234086
2386,2386,195.37,7.2580957,3.3545544,0.0,0,6.0883236,0.0,0.25228801,71.70192,6.6793275,483.45007,-9.2342443
2387,2387,195.3702,7.3060918,3.3700144,0.0,0,6.065536,0.0,0.25407803,72.017197,6.6553378,483.4668,-9.2345123
2388,2388,195.3704,7.3396034,3.3924434,0.0,0,6.042748,0.0,0.25631267,72.263786,6.6297393,483.48352,-9.2344246
2389,2389,195.3706,7.3513451,3.4219916,0.0,0,6.0199599,0.0,0.25819078,72.313942,6.6066194,483.50024,-9.2346745
2390,2390,195.3708,7.346375,3.4392681,0.0,0,5.9971719,0.0,0.25992036,72.094681,6.5843391,483.51697,-9.2344141
2391,2391,195.371,7.3380666,3.4641759,0.0,0,5.9743834,0.0,0.26248655,71.766396,6.5617146,483.53369,-9.233716
2392,2392,195.3712,7.3386016,3.4954171,0.0,0,5.9515953,0.0,0.26458171,71.633003,6.5367179,483.55042,-9.2342205
2393,2393,195.3714,7.3410854,3.5126493,0.0,0,5.9288077,0.0,0.2661722,71.575539,6.5123048,483.56717,-9.2341394
2394,2394,195.3716,7.3560581,3.5340583,0.0,0,5.9060202,0.0,0.26857895,71.60437,6.4904022,483.58389,-9.2338676
2395,2395,195.3718,7.3900137,3.5634098,0.0,0,5.8832321,0.0,0.27065659,71.791878,6.4655313,483.60062,-9.2340975
2396,2396,195.372,7.4358377,3.5822611,0.0,0,5.8604436,0.0,0.27225053,72.046448,6.4417005,483.61734,-9.2335281
2397,2397,195.3722,7.4639101,3.6035945,0.0,0,5.8376555,0.0,0.27471352,72.146973,6.4206266,483.63406,-9.2329159
2398,2398,195.3724,7.4644876,3.6323247,0.0,0,5.8148675,0.0,0.27693826,72.076447,6.3944759,483.65079,-9.2333384
2399,2399,195.3726,7.4629803,3.6528287,0.0,0,5.792079,0.0,0.2783635,71.922874,6.3678045,483.66751,-9.2334108
2400,2400,195.3728,7.4605751,3.6741605,0.0,0,5.7692914,0.0,0.28077686,71.656166,6.3466182,483.68423,-9.2332802
2401,2401,195.373,7.4550562,3.7020462,0.0,0,5.7465038,0.0,0.283236,71.466949,6.3256717,483.70096,-9.2332706
2402,2402,195.3732,7.4600115,3.7234192,0.0,0,5.7237153,0.0,0.28464687,71.451935,6.3002186,483.71768,-9.2334566
2403,2403,195.3734,7.4837608,3.74387,0.0,0,5.7009277,0.0,0.28686842,71.492119,6.2743993,483.73444,-9.2339993
2404,2404,195.3736,7.5221257,3.7695737,0.0,0,5.6781397,0.0,0.28926632,71.605461,6.2519503,483.75116,-9.2339897
2405,2405,195.3738,7.5560927,3.7919056,0.0,0,5.6553516,0.0,0.29075474,71.81398,6.229126,483.76788,-9.2334881
2406,2406,195.374,7.5725145,3.8129792,0.0,0,5.6325636,0.0,0.29297388,71.884789,6.2066526,483.78461,-9.2335424
2407,2407,195.3742,7.5863943,3.8368964,0.0,0,5.6097755,0.0,0.29541475,71.845467,6.1819239,483.80133,-9.2342205
2408,2408,195.3744,7.5978303,3.860327,0.0,0,5.5874419,0.0,0.29696667,71.771446,6.1593285,483.81805,-9.234273
2409,2409,195.3746,7.5985246,3.8821304,0.0,0,5.5656581,0.0,0.29907119,71.72506,6.1371546,483.83478,-9.233861
2410,2410,195.3748,7.6011825,3.9039488,0.0,0,5.5439739,0.0,0.30145344,71.652954,6.1126819,483.8515,-9.2338533
2411,2411,195.375,7.6131883,3.928432,0.0,0,5.5222936,0.0,0.30304578,71.543205,6.0909739,483.86823,-9.2339678
2412,2412,195.3752,7.6291447,3.9511456,0.0,0,5.5006137,0.0,0.30507195,71.523132,6.0687513,483.88495,-9.2331104
2413,2413,195.3754,7.6511116,3.9712486,0.0,0,5.4789333,0.0,0.30750826,71.554474,6.0468554,483.9017,-9.232954
2414,2414,195.3756,7.6730466,3.9977992,0.0,0,5.4572535,0.0,0.30937126,71.638657,6.0236802,483.91843,-9.2332735
2415,2415,195.3758,7.6888571,4.0226536,0.0,0,5.4355736,0.0,0.31146097,71.702049,5.9992256,483.93515,-9.2329922
2416,2416,195.376,7.7060385,4.0415897,0.0,0,5.4138937,0.0,0.31397361,71.703453,5.9774122,483.95187,-9.2325039
2417,2417,195.3762,7.7288165,4.0689292,0.0,0,5.3922133,0.0,0.31601375,71.723869,5.9533172,483.9686,-9.2322922
2418,2418,195.3764,7.7452049,4.0946474,0.0,0,5.3705335,0.0,0.3179968,71.685928,5.9290004,483.98532,-9.2328196
2419,2419,195.3766,7.7526441,4.1115365,0.0,0,5.3488536,0.0,0.32034725,71.609718,5.9066639,484.00204,-9.233427
2420,2420,195.3768,7.7542081,4.136826,0.0,0,5.3271737,0.0,0.32239768,71.506477,5.8835688,484.01877,-9.2333736
2421,2421,195.377,7.7602768,4.1621161,0.0,0,5.3054934,0.0,0.32424486,71.398224,5.8607397,484.03549,-9.2335482
2422,2422,195.3772,7.7733335,4.1775479,0.0,0,5.2838135,0.0,0.32629508,71.353241,5.8386397,484.05222,-9.2334328
2423,2423,195.3774,7.7906814,4.2024608,0.0,0,5.2621331,0.0,0.32839409,71.351547,5.814518,484.06897,-9.2333689
2424,2424,195.3776,7.8151217,4.2300124,0.0,0,5.2404532,0.0,0.33035401,71.426788,5.7907681,484.08569,-9.2340441
2425,2425,195.3778,7.8334484,4.2449818,0.0,0,5.2187734,0.0,0.33241087,71.471443,5.7707133,484.10242,-9.2337637
2426,2426,195.378,7.8436756,4.2696338,0.0,0,5.1970935,0.0,0.3347429,71.464561,5.7483149,484.11914,-9.2330437
2427,2427,195.3782,7.8634477,4.299068,0.0,0,5.1754136,0.0,0.33672538,71.489563,5.7226877,484.13586,-9.2326336
2428,2428,195.3784,7.8854632,4.3143606,0.0,0,5.1537337,0.0,0.33871534,71.531097,5.6997633,484.16873,-9.2321205
2429,2429,195.3786,7.8976679,4.3383574,0.0,0,5.1320534,0.0,0.34128574,71.514366,5.6791067,484.21771,-9.232028
2430,2430,195.3788,7.9048986,4.3679876,0.0,0,5.1103735,0.0,0.34333649,71.44371,5.6564302,484.26669,-9.2325563
2431,2431,195.379,7.9045086,4.3831463,0.0,0,5.0886931,0.0,0.34509328,71.287354,5.6311245,484.31567,-9.2333965
2432,2432,195.3792,7.9151435,4.40483,0.0,0,5.0670133,0.0,0.34763893,71.198471,5.6076527,484.36465,-9.2345629
2433,2433,195.3794,7.9351382,4.4343448,0.0,0,5.0457683,0.0,0.34974721,71.214569,5.5842133,484.41367,-9.2353554
2434,2434,195.3796,7.9569654,4.451612,0.0,0,5.0250487,0.0,0.35145098,71.253395,5.5606737,484.46265,-9.2349558
2435,2435,195.3798,7.9871755,4.4730854,0.0,0,5.0044241,0.0,0.35409141,71.331047,5.5375166,484.51163,-9.2341967
2436,2436,195.38,8.0099468,4.5015273,0.0,0,4.9838042,0.0,0.35624781,71.392273,5.5139036,484.56061,-9.2334452
2437,2437,195.3802,8.0238609,4.5191455,0.0,0,4.9631839,0.0,0.35772851,71.393211,5.4927382,484.60959,-9.2326851
2438,2438,195.3804,8.0404835,4.5396538,0.0,0,4.942564,0.0,0.36034963,71.328873,5.4689341,484.6586,-9.2328644
2439,2439,195.3806,8.0496006,4.5684958,0.0,0,4.9219441,0.0,0.36284274,71.282722,5.4441209,484.70758,-9.2333899
2440,2440,195.3808,8.0525808,4.5886912,0.0,0,4.9013243,0.0,0.36439893,71.211082,5.4209795,484.75656,-9.2336855
2441,2441,195.381,8.0560465,4.6081762,0.0,0,4.8807039,0.0,0.36687919,71.05735,5.3990383,484.80554,-9.2343254
2442,2442,195.3812,8.0670576,4.6354403,0.0,0,4.8600841,0.0,0.36948088,70.965561,5.3787374,484.85452,-9.2346191
2443,2443,195.3814,8.0909576,4.6572061,0.0,0,4.8394642,0.0,0.37104675,71.062767,5.356461,484.90353,-9.2343845
2444,2444,195.3816,8.1178322,4.6777163,0.0,0,4.8188443,0.0,0.37348083,71.131927,5.3315234,484.95251,-9.2343502
2445,2445,195.3818,8.1382475,4.7032828,0.0,0,4.798224,0.0,0.37605971,71.096252,5.3092709,485.0015,-9.2344246
2446,2446,195.382,8.1531134,4.7251992,0.0,0,4.7776041,0.0,0.37754554,71.129562,5.2877126,485.05048,-9.2343731
2447,2447,195.3822,8.1734266,4.7451468,0.0,0,4.7569842,0.0,0.37992352,71.169029,5.2650471,485.09946,-9.2338486
2448,2448,195.3824,8.1900711,4.768487,0.0,0,4.7363639,0.0,0.38257405,71.105247,5.2420497,485.14847,-9.2331009
2449,2449,195.3826,8.1993141,4.7921662,0.0,0,4.715744,0.0,0.38418272,71.095146,5.2214999,485.19745,-9.2327766
2450,2450,195.3828,8.2081909,4.8133254,0.0,0,4.6951241,0.0,0.38644385,70.968079,5.2008309,485.24643,-9.2327948
2451,2451,195.383,8.209363,4.8349447,0.0,0,4.6745043,0.0,0.38916937,70.776146,5.1761646,485.29541,-9.2332077
2452,2452,195.3832,8.2174187,4.8604522,0.0,0,4.6538844,0.0,0.39100876,70.752373,5.1547198,485.34439,-9.233036
2453,2453,195.3834,8.2412319,4.8823719,0.0,0,4.6332641,0.0,0.39312997,70.757866,5.1316137,485.3934,-9.2328081
2454,2454,195.3836,8.2652426,4.9020267,0.0,0,4.6126437,0.0,0.39572304,70.788765,5.1065478,485.44238,-9.2336941
2455,2455,195.3838,8.2845411,4.9283204,0.0,0,4.5920238,0.0,0.39765894,70.860092,5.0848727,485.49136,-9.2338438
2456,2456,195.384,8.3087854,4.9509807,0.0,0,4.571404,0.0,0.39973429,70.89653,5.0621195,485.54034,-9.2338448
2457,2457,195.3842,8.3293228,4.9680462,0.0,0,4.5507841,0.0,0.40233618,70.86171,5.0413427,485.58932,-9.2342682
2458,2458,195.3844,8.3410168,4.9926085,0.0,0,4.5305758,0.0,0.40440834,70.858513,5.0189543,485.63834,-9.2342987
2459,2459,195.3846,8.3514681,5.0166736,0.0,0,4.5108657,0.0,0.40631485,70.830368,4.9964266,485.68732,-9.2346649
2460,2460,195.3848,8.3584404,5.0321875,0.0,0,4.4912457,0.0,0.4086341,70.72715,4.9762578,485.7363,-9.2346315
2461,2461,195.385,8.3655491,5.0567474,0.0,0,4.4716296,0.0,0.41080913,70.624237,4.9561744,485.78528,-9.233366
2462,2462,195.3852,8.3767729,5.0830054,0.0,0,4.4520135,0.0,0.41282955,70.571907,4.9356952,485.83426,-9.2326603
2463,2463,195.3854,8.3914585,5.0971484,0.0,0,4.4323978,0.0,0.41509724,70.547646,4.9103413,485.88327,-9.2326365
2464,2464,195.3856,8.415411,5.1212273,0.0,0,4.4127817,0.0,0.41741464,70.585152,4.8875532,485.93225,-9.232584
2465,2465,195.3858,8.4465246,5.1499906,0.0,0,4.3931656,0.0,0.41948754,70.694084,4.8670096,485.98123,-9.2330122
2466,2466,195.386,8.4767084,5.1644855,0.0,0,4.3735499,0.0,0.42172247,70.761429,4.8441181,486.03021,-9.233573
2467,2467,195.3862,8.5038242,5.1871085,0.0,0,4.3539338,0.0,0.424272,70.792572,4.8244882,486.07919,-9.2332001
2468,2468,195.3864,8.5209713,5.2159009,0.0,0,4.3343177,0.0,0.42625341,70.795746,4.8042083,486.1282,-9.2326965
2469,2469,195.3866,8.5255461,5.2298627,0.0,0,4.314702,0.0,0.42822358,70.729454,4.7779055,486.17719,-9.2327099
2470,2470,195.3868,8.5233307,5.2523208,0.0,0,4.2950859,0.0,0.43096548,70.554726,4.7544074,486.22617,-9.2332735
2471,2471,195.387,8.5279903,5.2821937,0.0,0,4.2754698,0.0,0.43323925,70.387405,4.7343249,486.27515,-9.2333832
2472,2472,195.3872,8.5374222,5.2959328,0.0,0,4.2558532,0.0,0.43504059,70.30732,4.7153211,486.32413,-9.2329483
2473,2473,195.3874,8.5579596,5.3166432,0.0,0,4.2362375,0.0,0.43765992,70.281326,4.694417,486.37314,-9.2330761
2474,2474,195.3876,8.586174,5.3452291,0.0,0,4.2166214,0.0,0.43978733,70.317909,4.6742339,486.42212,-9.2334471
2475,2475,195.3878,8.6093588,5.3598723,0.0,0,4.1970053,0.0,0.44137084,70.443947,4.6523843,486.4711,-9.2329988
2476,2476,195.388,8.6327419,5.3794742,0.0,0,4.1773896,0.0,0.44415283,70.47966,4.6284971,486.52008,-9.2314873
2477,2477,195.3882,8.655714,5.40697,0.0,0,4.1577735,0.0,0.44637913,70.491364,4.6082578,486.56906,-9.2311945
2478,2478,195.3884,8.6678839,5.4224253,0.0,0,4.1381574,0.0,0.4478198,70.513054,4.5859761,486.57684,-9.2320852
2479,2479,195.3886,8.6651373,5.4404569,0.0,0,4.1185417,0.0,0.45051709,70.317024,4.5636415,486.5434,-9.2325325
2480,2480,195.3888,8.6648846,5.4680009,0.0,0,4.0989256,0.0,0.45306385,70.114815,4.5437593,486.50992,-9.2328835
2481,2481,195.389,8.6716089,5.4863601,0.0,0,4.0793095,0.0,0.45453322,70.033966,4.5231366,486.47647,-9.2330236
2482,2482,195.3892,8.686758,5.50455,0.0,0,4.0596938,0.0,0.4570792,70.017357,4.5028372,486.44302,-9.2327442
2483,2483,195.3894,8.7152824,5.5304079,0.0,0,4.0404716,0.0,0.45969191,70.066704,4.481082,486.40958,-9.2327328
2484,2484,195.3896,8.747489,5.5499511,0.0,0,4.0217257,0.0,0.46110538,70.179688,4.459023,486.37613,-9.2327347
2485,2485,195.3898,8.779912,5.5672765,0.0,0,4.0030656,0.0,0.4636136,70.256233,4.4395914,486.34265,-9.232048
2486,2486,195.39,8.8116045,5.5905919,0.0,0,3.9844093,0.0,0.46632117,70.342583,4.4172115,486.3092,-9.2320127
2487,2487,195.3902,8.832612,5.6116505,0.0,0,3.9657533,0.0,0.467765,70.419708,4.3950801,486.27576,-9.2324686
2488,2488,195.3904,8.8330317,5.6297002,0.0,0,3.9470973,0.0,0.47009557,70.25238,4.3753238,486.24231,-9.2323742
2489,2489,195.3906,8.8226566,5.6510386,0.0,0,3.9284413,0.0,0.47274899,70.047081,4.3553596,486.20883,-9.2321653
2490,2490,195.3908,8.8261757,5.6728277,0.0,0,3.9097853,0.0,0.47431466,69.966827,4.3339124,486.17538,-9.2323656
2491,2491,195.391,8.8467808,5.6917429,0.0,0,3.8911293,0.0,0.47657859,69.892403,4.3130646,486.14194,-9.2332382
2492,2492,195.3912,8.8747272,5.7111917,0.0,0,3.8724735,0.0,0.47928029,69.872032,4.2933025,486.10849,-9.2338696
2493,2493,195.3914,8.8993664,5.7336493,0.0,0,3.8538175,0.0,0.48096782,69.944542,4.2735615,486.07504,-9.2340469
2494,2494,195.3916,8.9232435,5.7532248,0.0,0,3.8351612,0.0,0.48307148,70.047913,4.2540169,486.04156,-9.2339659
2495,2495,195.3918,8.9595118,5.7707376,0.0,0,3.8165054,0.0,0.48578855,70.128944,4.2327294,486.00812,-9.2337608
2496,2496,195.392,8.9870949,5.7941914,0.0,0,3.7978494,0.0,0.4876743,70.183105,4.2113423,485.97467,-9.2335005
2497,2497,195.3922,8.9930792,5.8156233,0.0,0,3.7791932,0.0,0.48967779,70.124786,4.1915598,485.94122,-9.233428
2498,2498,195.3924,8.9934235,5.8310513,0.0,0,3.7605371,0.0,0.49231365,69.958511,4.172071,485.90775,-9.2329578
2499,2499,195.3926,8.993268,5.8548722,0.0,0,3.7418811,0.0,0.49448401,69.862892,4.1493363,485.8743,-9.2326202
2500,2500,195.3928,9.0094118,5.8787169,0.0,0,3.7232254,0.0,0.49649554,69.846291,4.1288028,485.84085,-9.232729
2501,2501,195.393,9.0375385,5.8914471,0.0,0,3.7045693,0.0,0.49887657,69.854202,4.1107073,485.8074,-9.2334499
2502,2502,195.3932,9.0624762,5.9140892,0.0,0,3.6859133,0.0,0.50105542,69.892853,4.0897608,485.77396,-9.2335291
2503,2503,195.3934,9.0876722,5.9388881,0.0,0,3.6672573,0.0,0.50296795,69.888268,4.0687461,485.74048,-9.2327881
2504,2504,195.3936,9.1147823,5.9503136,0.0,0,3.6486013,0.0,0.50516331,69.926369,4.0498152,485.70703,-9.2328806
2505,2505,195.3938,9.1442604,5.9722528,0.0,0,3.6299453,0.0,0.50755572,70.018654,4.0312958,485.67358,-9.2337198
2506,2506,195.394,9.1598692,5.9989314,0.0,0,3.6112893,0.0,0.50956124,70.031265,4.0114684,485.64014,-9.2339687
2507,2507,195.3942,9.1656265,6.0109992,0.0,0,3.5926332,0.0,0.51161277,69.919655,3.9907408,485.60669,-9.2332344
2508,2508,195.3944,9.1746292,6.0321217,0.0,0,3.5743496,0.0,0.51420611,69.790428,3.971066,485.57321,-9.2330265
2509,2509,195.3946,9.1845856,6.0595679,0.0,0,3.5565166,0.0,0.51627564,69.756729,3.9540708,485.53976,-9.2331009
2510,2510,195.3948,9.1966705,6.071424,0.0,0,3.538765,0.0,0.51821619,69.737907,3.9338584,485.50632,-9.2329063
2511,2511,195.395,9.2129145,6.0905256,0.0,0,3.5210168,0.0,0.5208931,69.67849,3.9132011,485.47287,-9.2325249
2512,2512,195.3952,9.2388144,6.1171594,0.0,0,3.5032687,0.0,0.52294987,69.684067,3.8945954,485.43939,-9.2323446
2513,2513,195.3954,9.2678995,6.1293721,0.0,0,3.4855206,0.0,0.52470207,69.804466,3.8757565,485.40594,-9.2324476
2514,2514,195.3956,9.3002596,6.147656,0.0,0,3.4677727,0.0,0.52743006,69.838814,3.8569703,485.3725,-9.2327681
2515,2515,195.3958,9.3265743,6.1737089,0.0,0,3.4500248,0.0,0.52951419,69.848946,3.8388627,485.33905,-9.2330923
2516,2516,195.396,9.3464708,6.1866922,0.0,0,3.432277,0.0,0.53103477,69.923607,3.8201466,485.3056,-9.2330608
2517,2517,195.3962,9.3619347,6.2038341,0.0,0,3.4145288,0.0,0.53384274,69.877197,3.7978909,485.27213,-9.2327299
2518,2518,195.3964,9.3667736,6.2305183,0.0,0,3.3967807,0.0,0.53618842,69.790619,3.7765877,485.23868,-9.2325411
2519,2519,195.3966,9.3734503,6.2465177,0.0,0,3.3790326,0.0,0.53766853,69.733162,3.7571948,485.20523,-9.2319851
2520,2520,195.3968,9.3872252,6.264008,0.0,0,3.3612847,0.0,0.54052323,69.606842,3.737267,485.17178,-9.2313499
2521,2521,195.397,9.407093,6.289866,0.0,0,3.3435369,0.0,0.54317009,69.534737,3.7192199,485.13831,-9.2318554
2522,2522,195.3972,9.4276962,6.3063364,0.0,0,3.3257887,0.0,0.54455596,69.590523,3.7008476,485.10486,-9.2324953
2523,2523,195.3974,9.4536934,6.32231,0.0,0,3.3080409,0.0,0.54714,69.585266,3.6789186,485.07141,-9.2325249
2524,2524,195.3976,9.4838028,6.3456693,0.0,0,3.2902927,0.0,0.54975486,69.613258,3.6598666,485.03796,-9.2325706
2525,2525,195.3978,9.5153198,6.3628221,0.0,0,3.2725446,0.0,0.5510298,69.770531,3.64309,485.00452,-9.2328186
2526,2526,195.398,9.5432644,6.3782597,0.0,0,3.2547965,0.0,0.55350661,69.810051,3.6221745,484.97104,-9.2326984
2527,2527,195.3982,9.5559349,6.3998785,0.0,0,3.2370486,0.0,0.55632019,69.733994,3.6025195,484.93759,-9.2324266
2528,2528,195.3984,9.5571852,6.4181433,0.0,0,3.2193007,0.0,0.55764955,69.663933,3.5854781,484.8895,-9.2321272
2529,2529,195.3986,9.5623941,6.4346523,0.0,0,3.2015526,0.0,0.55994368,69.512207,3.5675924,484.82678,-9.2321587
2530,2530,195.3988,9.5756235,6.4556746,0.0,0,3.1838048,0.0,0.56286728,69.38176,3.5490689,484.76404,-9.232398
2531,2531,195.399,9.5966311,6.4770274,0.0,0,3.1660566,0.0,0.56444913,69.436714,3.5283809,484.70132,-9.2324629
2532,2532,195.3992,9.6239128,6.4937229,0.0,0,3.1483088,0.0,0.56667447,69.488243,3.5102055,484.63861,-9.2324896
2533,2533,195.3994,9.651823,6.5107188,0.0,0,3.1309152,0.0,0.56949347,69.47261,3.4912462,484.57587,-9.2322626
2534,2534,195.3996,9.6795864,6.5325303,0.0,0,3.11395,0.0,0.57108724,69.560928,3.4728968,484.51315,-9.2318039
2535,2535,195.3998,9.7102566,6.5505142,0.0,0,3.0970623,0.0,0.57316858,69.646248,3.4555531,484.45041,-9.2314234
2536,2536,195.4,9.7360954,6.5658393,0.0,0,3.0801783,0.0,0.57599247,69.653549,3.4377596,484.3877,-9.2315903
2537,2537,195.4002,9.7450914,6.5888968,0.0,0,3.0632944,0.0,0.57794785,69.611153,3.420681,484.32495,-9.2317076
2538,2538,195.4004,9.7449665,6.608346,0.0,0,3.0464106,0.0,0.57991791,69.481537,3.4013083,484.26224,-9.2314672
2539,2539,195.4006,9.7561312,6.6205387,0.0,0,3.0295265,0.0,0.58247888,69.337898,3.3816848,484.19952,-9.2317877
2540,2540,195.4008,9.7829542,6.6423645,0.0,0,3.0126424,0.0,0.58442819,69.359283,3.3636942,484.13678,-9.2316704
2541,2541,195.401,9.8099146,6.662971,0.0,0,2.9957583,0.0,0.58618534,69.472946,3.3471222,484.07407,-9.231739
2542,2542,195.4012,9.8291845,6.6730227,0.0,0,2.9788744,0.0,0.58857089,69.465271,3.3291159,484.01132,-9.2324667
2543,2543,195.4014,9.8577862,6.693408,0.0,0,2.9619906,0.0,0.59073794,69.492317,3.310745,483.94861,-9.2324429
2544,2544,195.4016,9.88867,6.716331,0.0,0,2.9451065,0.0,0.59254169,69.585281,3.2921262,483.88589,-9.2326698
2545,2545,195.4018,9.9136629,6.7266417,0.0,0,2.9282222,0.0,0.59483975,69.598373,3.2737479,483.82315,-9.2327127
2546,2546,195.402,9.9322548,6.7460995,0.0,0,2.9113381,0.0,0.59732872,69.572502,3.2568185,483.76044,-9.2320051
2547,2547,195.4022,9.9444456,6.7705956,0.0,0,2.8944542,0.0,0.59907335,69.5672,3.2381582,483.69769,-9.2316313
2548,2548,195.4024,9.9525738,6.7804999,0.0,0,2.8775704,0.0,0.60110813,69.513634,3.2219102,483.63498,-9.2314825
2549,2549,195.4026,9.9649611,6.799531,0.0,0,2.8606863,0.0,0.60390913,69.382454,3.2068458,483.57224,-9.2315216
2550,2550,195.4028,9.9913445,6.8258228,0.0,0,2.8438022,0.0,0.60592848,69.409958,3.1879594,483.50952,-9.2316618
2551,2551,195.403,10.017077,6.8358908,0.0,0,2.8269184,0.0,0.60773736,69.486031,3.1695194,483.44681,-9.2316446
2552,2552,195.4032,10.038801,6.853662,0.0,0,2.810034,0.0,0.61059272,69.378754,3.1510994,483.38406,-9.2315769
2553,2553,195.4034,10.06086,6.8796706,0.0,0,2.7931502,0.0,0.61270702,69.396431,3.1324003,483.32135,-9.2320213
2554,2554,195.4036,10.092653,6.8897629,0.0,0,2.7762663,0.0,0.61426008,69.528046,3.1157622,483.25861,-9.2327518
2555,2555,195.4038,10.127841,6.9055181,0.0,0,2.7593822,0.0,0.61707562,69.538528,3.0989318,483.19589,-9.2324114
2556,2556,195.404,10.152443,6.9304338,0.0,0,2.7424984,0.0,0.61920136,69.568825,3.0798631,483.13318,-9.232358
2557,2557,195.4042,10.169964,6.9419403,0.0,0,2.7256143,0.0,0.62061769,69.604706,3.0638118,483.07043,-9.2326212
2558,2558,195.4044,10.182941,6.9570866,0.0,0,2.7090683,0.0,0.62352484,69.463737,3.0445421,483.00772,-9.232007
2559,2559,195.4046,10.190586,6.9820089,0.0,0,2.6929309,0.0,0.62586921,69.348885,3.0237823,482.94498,-9.2319231
2560,2560,195.4048,10.2097,6.9954634,0.0,0,2.6768677,0.0,0.62708926,69.38575,3.0078008,482.88226,-9.232008
2561,2561,195.405,10.231985,7.0090938,0.0,0,2.6608074,0.0,0.62980378,69.357483,2.9918664,482.81952,-9.2319441
2562,2562,195.4052,10.252954,7.0323586,0.0,0,2.6447473,0.0,0.63231611,69.325256,2.9738877,482.75681,-9.2317228
2563,2563,195.4054,10.277871,7.0478163,0.0,0,2.6286874,0.0,0.63353091,69.410751,2.9561522,482.69409,-9.2318306
2564,2564,195.4056,10.313238,7.0621686,0.0,0,2.6126273,0.0,0.63626152,69.468552,2.9392357,482.63135,-9.2324877
2565,2565,195.4058,10.359751,7.0835161,0.0,0,2.5965672,0.0,0.6390273,69.571266,2.9215987,482.56863,-9.2319708
2566,2566,195.406,10.395952,7.1005931,0.0,0,2.5805073,0.0,0.64026809,69.752762,2.9040198,482.50589,-9.2319584
2567,2567,195.4062,10.414711,7.1148458,0.0,0,2.5644474,0.0,0.64286786,69.723183,2.8863442,482.44318,-9.2319775
2568,2568,195.4064,10.418777,7.1342635,0.0,0,2.5483873,0.0,0.64575511,69.553978,2.8708253,482.38043,-9.2319269
2569,2569,195.4066,10.428252,7.1527395,0.0,0,2.5323272,0.0,0.64700192,69.506645,2.8549538,482.31772,-9.2318926
2570,2570,195.4068,10.441932,7.1672106,0.0,0,2.5162673,0.0,0.64919251,69.444633,2.8380115,482.255,-9.2312546
2571,2571,195.407,10.456912,7.1844759,0.0,0,2.5002072,0.0,0.65204573,69.373306,2.8222241,482.19226,-9.2313156
2572,2572,195.4072,10.489123,7.2037449,0.0,0,2.4841473,0.0,0.65359521,69.456863,2.8061085,482.12955,-9.2314701
2573,2573,195.4074,10.524661,7.2189889,0.0,0,2.4680872,0.0,0.65575761,69.53775,2.7887654,482.0668,-9.2312565
2574,2574,195.4076,10.569343,7.23384,0.0,0,2.4520273,0.0,0.65867561,69.623405,2.7716374,482.00409,-9.2310715
2575,2575,195.4078,10.6159,7.2551341,0.0,0,2.4359674,0.0,0.66035551,69.787613,2.7551911,481.94138,-9.2315722
2576,2576,195.408,10.636139,7.2725468,0.0,0,2.4199073,0.0,0.66236442,69.803146,2.7360284,481.87863,-9.2316008
2577,2577,195.4082,10.639614,7.2847552,0.0,0,2.4038472,0.0,0.66518217,69.625961,2.7178955,481.81592,-9.2310467
2578,2578,195.4084,10.640024,7.3052902,0.0,0,2.3877873,0.0,0.6670081,69.505867,2.7019045,481.71582,-9.2317505
2579,2579,195.4086,10.650633,7.3234811,0.0,0,2.3717272,0.0,0.6688267,69.460335,2.6842508,481.5784,-9.2319851
2580,2580,195.4088,10.677277,7.3342404,0.0,0,2.3556671,0.0,0.67150623,69.392166,2.6686018,481.44095,-9.2319498
2581,2581,195.409,10.709226,7.3549166,0.0,0,2.3396072,0.0,0.67362499,69.401299,2.6551173,481.3035,-9.2319107
2582,2582,195.4092,10.74618,7.3747163,0.0,0,2.3235474,0.0,0.67543322,69.550087,2.638921,481.16608,-9.2310925
2583,2583,195.4094,10.779346,7.3837423,0.0,0,2.3078089,0.0,0.67781782,69.644913,2.6208642,481.02863,-9.2308893
2584,2584,195.4096,10.811625,7.4019618,0.0,0,2.2924595,0.0,0.67995125,69.715927,2.6039617,480.89117,-9.2315454
2585,2585,195.4098,10.847133,7.4223499,0.0,0,2.2771804,0.0,0.68167925,69.834335,2.5869019,480.75375,-9.2315855
2586,2586,195.41,10.868568,7.4307632,0.0,0,2.2619042,0.0,0.6838398,69.828217,2.5698824,480.6163,-9.2310505
2587,2587,195.4102,10.879539,7.4497976,0.0,0,2.246628,0.0,0.68636775,69.716064,2.5522048,480.47888,-9.2310266
2588,2588,195.4104,10.884666,7.4731469,0.0,0,2.2313523,0.0,0.68830222,69.626587,2.5353479,480.34143,-9.2310247
2589,2589,195.4106,10.901455,7.4815607,0.0,0,2.2160764,0.0,0.69037062,69.596672,2.520535,480.20398,-9.230998
2590,2590,195.4108,10.933455,7.4997735,0.0,0,2.2008004,0.0,0.69311136,69.580307,2.5048108,480.06656,-9.2310085
2591,2591,195.411,10.970263,7.5238423,0.0,0,2.1855242,0.0,0.69505382,69.651878,2.490279,479.92911,-9.2310572
2592,2592,195.4112,11.005952,7.5317974,0.0,0,2.1702483,0.0,0.69682592,69.757271,2.4756751,479.79166,-9.2317905
2593,2593,195.4114,11.044868,7.5484934,0.0,0,2.1549723,0.0,0.69983113,69.797913,2.4570854,479.65424,-9.2320004
2594,2594,195.4116,11.086939,7.5734134,0.0,0,2.1396964,0.0,0.70191336,69.930199,2.4388597,479.51678,-9.2313128
2595,2595,195.4118,11.118074,7.5816917,0.0,0,2.1244202,0.0,0.70340574,70.029327,2.4220631,479.37936,-9.2314215
2596,2596,195.412,11.134934,7.595818,0.0,0,2.1091442,0.0,0.70640981,69.914597,2.407043,479.24191,-9.2313805
2597,2597,195.4122,11.142752,7.6201034,0.0,0,2.0938683,0.0,0.70858574,69.864838,2.391932,479.10446,-9.2310295
2598,2598,195.4124,11.159863,7.6307883,0.0,0,2.0785923,0.0,0.70991659,69.874458,2.3755624,478.96704,-9.2308626
2599,2599,195.4126,11.19126,7.6446986,0.0,0,2.0633163,0.0,0.71288162,69.820045,2.3575094,478.82959,-9.2307796
2600,2600,195.4128,11.221068,7.6686487,0.0,0,2.0480404,0.0,0.71529704,69.874008,2.3404043,478.69217,-9.2303686
2601,2601,195.413,11.251694,7.6803021,0.0,0,2.0327644,0.0,0.71643412,69.987251,2.3248305,478.55472,-9.2300234
2602,2602,195.4132,11.288382,7.6917839,0.0,0,2.0174885,0.0,0.71922427,69.985992,2.3085938,478.41727,-9.2303638
2603,2603,195.4134,11.334647,7.713635,0.0,0,2.0022123,0.0,0.7218461,70.057686,2.2930226,478.27985,-9.2304859
2604,2604,195.4136,11.376144,7.727541,0.0,0,1.9869361,0.0,0.72298479,70.24707,2.2760019,478.1424,-9.2306738
2605,2605,195.4138,11.403058,7.740284,0.0,0,1.9716601,0.0,0.72573322,70.244392,2.2580235,478.00494,-9.2314825
2606,2606,195.414,11.424241,7.7623429,0.0,0,1.9563841,0.0,0.72867423,70.18045,2.2432585,477.86752,-9.2322016
2607,2607,195.4142,11.436441,7.7779593,0.0,0,1.9411081,0.0,0.72984916,70.153671,2.2291403,477.73007,-9.2324629
2608,2608,195.4144,11.454503,7.7909331,0.0,0,1.9261373,0.0,0.73251313,70.068085,2.2136929,477.59265,-9.2322407
2609,2609,195.4146,11.48402,7.8102546,0.0,0,1.9115355,0.0,0.73549134,70.052505,2.1986525,477.4552,-9.232049
2610,2610,195.4148,11.516676,7.8261609,0.0,0,1.8970004,0.0,0.73663062,70.143158,2.1822174,477.31775,-9.2321615
2611,2611,195.415,11.556596,7.8384881,0.0,0,1.8824685,0.0,0.7389496,70.210159,2.1656299,477.18033,-9.2310705
2612,2612,195.4152,11.600641,7.8547807,0.0,0,1.8679364,0.0,0.74190211,70.254845,2.1488075,477.04288,-9.2299347
2613,2613,195.4154,11.635254,7.8727951,0.0,0,1.8534043,0.0,0.74326563,70.411491,2.1335111,476.90543,-9.2301655
2614,2614,195.4156,11.676564,7.8866682,0.0,0,1.8388724,0.0,0.74540538,70.524109,2.117651,476.76801,-9.2300196
2615,2615,195.4158,11.71379,7.9001107,0.0,0,1.8243403,0.0,0.74842101,70.520416,2.1020911,476.63055,-9.2297459
2616,2616,195.416,11.73009,7.9191213,0.0,0,1.8098084,0.0,0.75006163,70.573723,2.0871866,476.49313,-9.2300205
2617,2617,195.4162,11.752147,7.9348669,0.0,0,1.7952764,0.0,0.75204486,70.540985,2.0706282,476.35568,-9.2298546
2618,2618,195.4164,11.76867,7.94666,0.0,0,1.7807443,0.0,0.75493509,70.421516,2.0524294,476.21823,-9.2302637
2619,2619,195.4166,11.79419,7.9672341,0.0,0,1.7662123,0.0,0.75695509,70.450256,2.0375147,476.08081,-9.231041
2620,2620,195.4168,11.836616,7.9846582,0.0,0,1.7516804,0.0,0.75885409,70.536163,2.0242419,475.94336,-9.2316856
2621,2621,195.417,11.878931,7.9944539,0.0,0,1.7371484,0.0,0.76154423,70.607208,2.0084589,475.80594,-9.2324457
2622,2622,195.4172,11.920964,8.0147915,0.0,0,1.7226164,0.0,0.76382977,70.693871,1.9932169,475.66849,-9.2325277
2623,2623,195.4174,11.962369,8.0335083,0.0,0,1.7080843,0.0,0.76571465,70.79631,1.9772466,475.53104,-9.2325315
2624,2624,195.4176,12.00944,8.0416422,0.0,0,1.6935524,0.0,0.76829779,70.878891,1.9603138,475.39362,-9.2325993
2625,2625,195.4178,12.043662,8.0614538,0.0,0,1.6790204,0.0,0.77077925,70.904762,1.9455119,475.25616,-9.2318249
2626,2626,195.418,12.063335,8.0830917,0.0,0,1.6644883,0.0,0.77261573,70.914597,1.9291126,475.11871,-9.231039
2627,2627,195.4182,12.079246,8.089838,0.0,0,1.6499563,0.0,0.7748943,70.854073,1.9136204,474.98129,-9.2308235
2628,2628,195.4184,12.107183,8.1061592,0.0,0,1.6354244,0.0,0.77755052,70.792557,1.9003257,474.84561,-9.2305536
2629,2629,195.4186,12.142186,8.1289997,0.0,0,1.6208923,0.0,0.77943051,70.872917,1.8834524,474.7117,-9.2306995
2630,2630,195.4188,12.18509,8.13587,0.0,0,1.6063604,0.0,0.78143561,70.989159,1.8673419,474.57782,-9.2311363
2631,2631,195.419,12.224649,8.1509743,0.0,0,1.5918283,0.0,0.78418303,71.001465,1.8521463,474.44391,-9.2306204
2632,2632,195.4192,12.260632,8.1746168,0.0,0,1.5772964,0.0,0.78601646,71.050987,1.8353409,474.31,-9.2309732
2633,2633,195.4194,12.306013,8.1819887,0.0,0,1.5630548,0.0,0.78782618,71.177635,1.8220431,474.17609,-9.2317133
2634,2634,195.4196,12.345443,8.1966848,0.0,0,1.5491644,0.0,0.79093039,71.192856,1.8090329,474.04221,-9.231288
2635,2635,195.4198,12.37754,8.2204266,0.0,0,1.5353373,0.0,0.79304528,71.244034,1.7927412,473.90829,-9.230957
2636,2636,195.42,12.398284,8.2279921,0.0,0,1.5215132,0.0,0.79449803,71.313179,1.7774855,473.77438,-9.2302418
2637,2637,195.4202,12.422645,8.2409363,0.0,0,1.5076892,0.0,0.79755855,71.236092,1.7620682,473.64047,-9.2295647
2638,2638,195.4204,12.452742,8.2647419,0.0,0,1.4938653,0.0,0.79978096,71.241493,1.744285,473.50659,-9.2299461
2639,2639,195.4206,12.485936,8.2742519,0.0,0,1.4800413,0.0,0.8010242,71.347153,1.7284553,473.37268,-9.2301283
2640,2640,195.4208,12.529612,8.2861147,0.0,0,1.4662173,0.0,0.80411857,71.351433,1.7152131,473.23877,-9.2298012
2641,2641,195.421,12.576511,8.3097076,0.0,0,1.4523933,0.0,0.8067826,71.397865,1.6985178,473.10486,-9.2298193
2642,2642,195.4212,12.616548,8.3218517,0.0,0,1.4385693,0.0,0.80804551,71.511986,1.6831745,472.97098,-9.2300453
2643,2643,195.4214,12.659143,8.3339167,0.0,0,1.4247453,0.0,0.81112099,71.53466,1.6706089,472.83707,-9.230442
2644,2644,195.4216,12.703032,8.3552895,0.0,0,1.4109213,0.0,0.814004,71.612381,1.6558753,472.70316,-9.2300348
2645,2645,195.4218,12.739808,8.3679914,0.0,0,1.3970973,0.0,0.8150425,71.775131,1.6413395,472.56927,-9.2296867
2646,2646,195.422,12.776741,8.3785706,0.0,0,1.3832734,0.0,0.81776291,71.766518,1.6254538,472.43536,-9.2298441
2647,2647,195.4222,12.805676,8.3972197,0.0,0,1.3694494,0.0,0.82067388,71.693535,1.6085439,472.30145,-9.2299109
2648,2648,195.4224,12.824713,8.4117632,0.0,0,1.3556253,0.0,0.82157356,71.757156,1.5921495,472.16754,-9.229475
2649,2649,195.4226,12.847182,8.4224138,0.0,0,1.3418013,0.0,0.82409245,71.73053,1.5778105,472.03366,-9.2296801
2650,2650,195.4228,12.88532,8.4397163,0.0,0,1.3279774,0.0,0.82734799,71.704826,1.5659608,471.89975,-9.2307005
2651,2651,195.423,12.927882,8.4566393,0.0,0,1.3141534,0.0,0.82853073,71.848289,1.5511688,471.76584,-9.2310495
2652,2652,195.4232,12.97468,8.4680519,0.0,0,1.3003293,0.0,0.83083165,71.919342,1.537486,471.63193,-9.2307968
2653,2653,195.4234,13.027614,8.482255,0.0,0,1.2865053,0.0,0.83393425,71.96125,1.5238067,471.49805,-9.2306547
2654,2654,195.4236,13.069569,8.4997864,0.0,0,1.2726814,0.0,0.83534914,72.141006,1.5086457,471.36414,-9.230175
2655,2655,195.4238,13.100915,8.5132198,0.0,0,1.2588574,0.0,0.8375923,72.198135,1.4944018,471.23022,-9.2295227
2656,2656,195.424,13.128285,8.5257454,0.0,0,1.2450334,0.0,0.84069574,72.122025,1.4808091,471.09631,-9.2294931
2657,2657,195.4242,13.157133,8.5441666,0.0,0,1.2312094,0.0,0.84232807,72.143509,1.4662262,470.96243,-9.2296381
2658,2658,195.4244,13.184063,8.5586748,0.0,0,1.2176627,0.0,0.84437108,72.119232,1.4503822,470.82852,-9.2299976
2659,2659,195.4246,13.21981,8.5685253,0.0,0,1.2044513,0.0,0.8472591,72.064178,1.4350618,470.69461,-9.2303925
2660,2660,195.4248,13.263587,8.5874853,0.0,0,1.1913006,0.0,0.84910214,72.155212,1.4201541,470.5607,-9.2303791
2661,2661,195.425,13.309661,8.6029587,0.0,0,1.1781524,0.0,0.85105079,72.282333,1.4044667,470.42682,-9.2305593
2662,2662,195.4252,13.362111,8.609952,0.0,0,1.1650045,0.0,0.85389405,72.371658,1.3909196,470.29291,-9.2308655
2663,2663,195.4254,13.413129,8.6288576,0.0,0,1.1518564,0.0,0.85608417,72.521378,1.3777889,470.159,-9.2307501
2664,2664,195.4256,13.462558,8.6475601,0.0,0,1.1387084,0.0,0.8577826,72.68589,1.3625114,470.02509,-9.2300444
2665,2665,195.4258,13.504117,8.653944,0.0,0,1.1255604,0.0,0.86039555,72.710648,1.3473268,469.8912,-9.2299385
2666,2666,195.426,13.528921,8.6709185,0.0,0,1.1124125,0.0,0.86293751,72.652626,1.3343389,469.75729,-9.2304821
2667,2667,195.4262,13.557939,8.6910715,0.0,0,1.0992644,0.0,0.86456108,72.675064,1.3206415,469.62338,-9.2302523
2668,2668,195.4264,13.598678,8.6968222,0.0,0,1.0861164,0.0,0.86685479,72.717751,1.3058044,469.4895,-9.2302427
2669,2669,195.4266,13.638669,8.7128582,0.0,0,1.0729684,0.0,0.86963814,72.745064,1.2913568,469.35559,-9.2302313
2670,2670,195.4268,13.683456,8.7345896,0.0,0,1.0598203,0.0,0.87137723,72.853661,1.2771695,469.22168,-9.2298927
2671,2671,195.427,13.735291,8.7390566,0.0,0,1.0466723,0.0,0.87337232,72.968414,1.2643774,469.08777,-9.230341
2672,2672,195.4272,13.787139,8.7529898,0.0,0,1.0335244,0.0,0.8764022,73.005455,1.2492718,468.95389,-9.2303829
2673,2673,195.4274,13.832932,8.7759409,0.0,0,1.0203763,0.0,0.87831038,73.125946,1.2343812,468.81998,-9.2291327
2674,2674,195.4276,13.881051,8.7818146,0.0,0,1.0072284,0.0,0.87993616,73.278976,1.218539,468.68607,-9.2290745
2675,2675,195.4278,13.921536,8.7947388,0.0,0,0.99408036,0.0,0.88318563,73.223106,1.2065312,468.55215,-9.2295876
2676,2676,195.428,13.945817,8.817812,0.0,0,0.98093235,0.0,0.88528103,73.187363,1.1959972,468.41827,-9.2300472
2677,2677,195.4282,13.973907,8.8246994,0.0,0,0.96778435,0.0,0.88656902,73.255081,1.1797298,468.28436,-9.2300205
2678,2678,195.4284,14.006958,8.8364973,0.0,0,0.95463634,0.0,0.88989502,73.200089,1.1647834,468.11807,-9.2294283
2679,2679,195.4286,14.040855,8.8587551,0.0,0,0.94148839,0.0,0.89228725,73.241249,1.1526504,467.9194,-9.2295494
2680,2680,195.4288,14.086132,8.8668938,0.0,0,0.92834044,0.0,0.89335978,73.377296,1.1393081,467.72076,-9.2296114
2681,2681,195.429,14.139399,8.8768187,0.0,0,0.91519243,0.0,0.89643377,73.393005,1.124015,467.52209,-9.22995
2682,2682,195.4292,14.194763,8.8967257,0.0,0,0.90204442,0.0,0.89882183,73.536011,1.1103288,467.32343,-9.2299519
2683,2683,195.4294,14.250395,8.9052954,0.0,0,0.88916051,0.0,0.899584,73.774048,1.0973729,467.12476,-9.2295542
2684,2684,195.4296,14.301698,8.9150963,0.0,0,0.87659609,0.0,0.90249431,73.817375,1.0828675,466.92612,-9.2296515
2685,2685,195.4298,14.337546,8.9350605,0.0,0,0.86408949,0.0,0.90535015,73.793999,1.0707523,466.72745,-9.2296171
2686,2686,195.43,14.364059,8.9465046,0.0,0,0.85158539,0.0,0.9062264,73.849823,1.0580498,466.52878,-9.2294531
2687,2687,195.4302,14.397973,8.956687,0.0,0,0.83908135,0.0,0.90916932,73.798653,1.0430572,466.33014,-9.2294436
2688,2688,195.4304,14.438859,8.9757032,0.0,0,0.82657731,0.0,0.91241932,73.753197,1.0289614,466.13147,-9.229146
2689,2689,195.4306,14.479,8.9898443,0.0,0,0.81407332,0.0,0.91334563,73.914009,1.013199,465.9328,-9.2283926
2690,2690,195.4308,14.522057,8.9994087,0.0,0,0.8015694,0.0,0.91597885,73.9664,1.0001478,465.73413,-9.2284117
2691,2691,195.431,14.578513,9.0144882,0.0,0,0.78906536,0.0,0.91916519,73.989899,0.98828536,465.53549,-9.2284241
2692,2692,195.4312,14.643523,9.0283947,0.0,0,0.77656138,0.0,0.91996849,74.242958,0.97480369,465.33682,-9.2280989
2693,2693,195.4314,14.702329,9.03862,0.0,0,0.7640574,0.0,0.92217094,74.366997,0.96076208,465.13815,-9.2284288
2694,2694,195.4316,14.752025,9.0521269,0.0,0,0.75155336,0.0,0.92549342,74.386536,0.9463622,464.93951,-9.2284431
2695,2695,195.4318,14.788209,9.0689068,0.0,0,0.73904938,0.0,0.92675126,74.503159,0.93293333,464.74084,-9.2287636
2696,2696,195.432,14.819776,9.0813675,0.0,0,0.72654539,0.0,0.92899704,74.485939,0.91865075,464.54218,-9.2294035
2697,2697,195.4322,14.863305,9.0925522,0.0,0,0.71404135,0.0,0.93243408,74.427055,0.90567774,464.34351,-9.229497
2698,2698,195.4324,14.907062,9.1097689,0.0,0,0.70153737,0.0,0.93400621,74.527641,0.8925575,464.14487,-9.2292585
2699,2699,195.4326,14.949455,9.1221552,0.0,0,0.68903339,0.0,0.93584281,74.606506,0.87835687,463.9462,-9.2292643
2700,2700,195.4328,14.999748,9.1294937,0.0,0,0.67652941,0.0,0.93879813,74.646179,0.86558694,463.74753,-9.2290783
2701,2701,195.433,15.063225,9.1462889,0.0,0,0.66402543,0.0,0.94053322,74.818192,0.85210162,463.54889,-9.2277765
2702,2702,195.4332,15.128632,9.1605806,0.0,0,0.65152138,0.0,0.94219595,75.020103,0.83883739,463.35022,-9.2277689
2703,2703,195.4334,15.180282,9.1667671,0.0,0,0.63901734,0.0,0.94496751,75.094414,0.82510978,463.15155,-9.2288342
2704,2704,195.4336,15.219518,9.1845331,0.0,0,0.62651336,0.0,0.94713926,75.133568,0.81250906,462.95288,-9.2284679
2705,2705,195.4338,15.252443,9.2015934,0.0,0,0.61400938,0.0,0.94886976,75.152809,0.799335,462.75424,-9.2286282
2706,2706,195.434,15.282976,9.2061043,0.0,0,0.6015054,0.0,0.95148504,75.088982,0.78499192,462.55557,-9.2293797
2707,2707,195.4342,15.311052,9.2221584,0.0,0,0.58900136,0.0,0.95410091,75.063797,0.77181184,462.3569,-9.2294521
2708,2708,195.4344,15.352719,9.241065,0.0,0,0.57674509,0.0,0.95561081,75.164818,0.7600683,462.15823,-9.229455
2709,2709,195.4346,15.408021,9.2446766,0.0,0,0.56478846,0.0,0.9576444,75.253235,0.74785471,461.95959,-9.2294531
2710,2710,195.4348,15.464017,9.2583218,0.0,0,0.55288601,0.0,0.96055073,75.294998,0.73509657,461.76093,-9.2294102
2711,2711,195.435,15.522617,9.2793436,0.0,0,0.54098594,0.0,0.96243042,75.425789,0.72392386,461.56226,-9.2297859
2712,2712,195.4352,15.576414,9.2845249,0.0,0,0.52908593,0.0,0.96446377,75.519318,0.70998561,461.36362,-9.229723
2713,2713,195.4354,15.629096,9.2980623,0.0,0,0.51718587,0.0,0.96762562,75.546333,0.69569784,461.16495,-9.2293386
2714,2714,195.4356,15.677787,9.3192921,0.0,0,0.50528592,0.0,0.96965289,75.677582,0.68297845,460.96628,-9.2292919
2715,2715,195.4358,15.718878,9.3234911,0.0,0,0.49338591,0.0,0.9711377,75.758438,0.67074281,460.76761,-9.2286339
2716,2716,195.436,15.755057,9.3343477,0.0,0,0.4814859,0.0,0.97420096,75.667427,0.65807188,460.56897,-9.2280884
2717,2717,195.4362,15.799241,9.3552256,0.0,0,0.4695859,0.0,0.97615147,75.715034,0.64612716,460.3703,-9.2281494
2718,2718,195.4364,15.845717,9.3595295,0.0,0,0.45768592,0.0,0.97708935,75.877754,0.6363309,460.17163,-9.2281275
2719,2719,195.4366,15.899635,9.3685102,0.0,0,0.44578591,0.0,0.98018432,75.923088,0.62304693,459.97299,-9.2285042
2720,2720,195.4368,15.955051,9.3893957,0.0,0,0.4338859,0.0,0.9824636,76.020287,0.60666782,459.77432,-9.2292185
2721,2721,195.437,16.007298,9.3955526,0.0,0,0.42198589,0.0,0.98328757,76.211296,0.59422976,459.57565,-9.2298479
2722,2722,195.4372,16.068287,9.4043903,0.0,0,0.41008592,0.0,0.98652124,76.244331,0.58115536,459.37698,-9.229661
2723,2723,195.4374,16.115421,9.4247828,0.0,0,0.39818591,0.0,0.98928314,76.279762,0.56919736,459.17834,-9.2297735