File: clean data/testID_0107.csv
level_0,index,Time(sec),Force(kN),Jaw(mm),PowAngle(deg),Power(W),Pram,PTemp,Strain,Stress(MPa),Stroke(mm),TC1(C),wedge(mm)
2419,2419,195.3731,0.80820888,0.014107643,0.0,0,9.9518623,0.0,0.0011684081,10.048194,10.055478,448.74963,-9.2363787
2430,2430,195.3753,2.1468399,0.029983114,0.0,0,9.9188633,0.0,0.0016962771,26.855639,10.025496,448.80902,-9.2356682
2441,2441,195.3775,3.513047,0.037001684,0.0,0,9.8858624,0.0,0.0026690362,44.335522,9.9960651,448.86844,-9.2350407
2452,2452,195.3797,4.3019333,0.06371367,0.0,0,9.8528633,0.0,0.0041162237,54.537285,9.9597712,448.92783,-9.2334118
2463,2463,195.3819,4.6939297,0.09619759,0.0,0,9.8198624,0.0,0.0066154944,59.242321,9.922554,449.2048,-9.2318907
2474,2474,195.3841,4.9603624,0.14009413,0.0,0,9.7868633,0.0,0.0090539046,62.508141,9.8820314,449.58765,-9.2320004
2485,2485,195.3863,5.1411829,0.17223182,0.0,0,9.7538624,0.0,0.011692818,64.574219,9.8420782,449.97049,-9.2323856
2496,2496,195.3885,5.2503166,0.21052469,0.0,0,9.7208633,0.0,0.014029623,65.890793,9.8010759,450.3533,-9.2314034
2507,2507,195.3907,5.3061337,0.2420785,0.0,0,9.6878624,0.0,0.016430194,66.4617,9.7641497,450.73615,-9.2322989
2518,2518,195.3929,5.350893,0.28174639,0.0,0,9.6548634,0.0,0.018723669,66.835381,9.734108,451.11896,-9.2317801
2529,2529,195.3951,5.3631825,0.30381048,0.0,0,9.6218624,0.0,0.020489452,66.940964,9.6997414,451.5018,-9.2325163
2540,2540,195.3973,5.3828406,0.33315778,0.0,0,9.5888634,0.0,0.022409584,67.018204,9.6698132,451.88464,-9.2323103
2551,2551,195.3995,5.4219103,0.36190343,0.0,0,9.5558634,0.0,0.024422411,67.303146,9.637888,452.26746,-9.2326651
2562,2562,195.4017,5.463264,0.39868826,0.0,0,9.5228634,0.0,0.026808256,67.720192,9.6091528,452.50772,-9.2333307
2573,2573,195.4039,5.5415215,0.42703331,0.0,0,9.4898624,0.0,0.028833214,68.393341,9.577035,452.65292,-9.2328529
2584,2584,195.4061,5.5869942,0.46113542,0.0,0,9.4574747,0.0,0.031210542,68.924896,9.5381432,452.79813,-9.2321043
2595,2595,195.4083,5.6238079,0.49252829,0.0,0,9.4252844,0.0,0.03328824,69.353195,9.5076742,452.94336,-9.2323065
2606,2606,195.4105,5.6371784,0.53015184,0.0,0,9.3930941,0.0,0.036036801,69.273369,9.4756966,453.08856,-9.2334318
2617,2617,195.4127,5.6606851,0.5610652,0.0,0,9.3609037,0.0,0.037955906,69.38961,9.4418583,453.23376,-9.2327604
2628,2628,195.4149,5.6745787,0.59274679,0.0,0,9.3287134,0.0,0.040338386,69.35994,9.4059162,453.37897,-9.233326
2639,2639,195.4171,5.6709156,0.62606633,0.0,0,9.2965231,0.0,0.042417046,69.28788,9.3740168,453.5242,-9.2333803
2650,2650,195.4193,5.6920857,0.66259205,0.0,0,9.2643328,0.0,0.045331903,69.25103,9.3392286,453.6694,-9.2334528
2661,2661,195.4215,5.7176766,0.6956296,0.0,0,9.2321424,0.0,0.047224812,69.352341,9.3087206,453.75891,-9.2334719
2672,2672,195.4237,5.7556248,0.72203964,0.0,0,9.1999521,0.0,0.049460877,69.650215,9.274478,453.79852,-9.2347889
2683,2683,195.4259,5.7649159,0.75338376,0.0,0,9.1677618,0.0,0.051337201,69.726799,9.2443333,453.83813,-9.2341299
2694,2694,195.4281,5.784646,0.78505301,0.0,0,9.1355705,0.0,0.053945925,69.742142,9.209774,453.87775,-9.2333317
2705,2705,195.4303,5.7794967,0.82155973,0.0,0,9.1033802,0.0,0.055991709,69.59919,9.1773205,453.91736,-9.2346392
2716,2716,195.4325,5.8054805,0.84796858,0.0,0,9.0711899,0.0,0.058389921,69.683411,9.1450262,453.90463,-9.2340288
2727,2727,195.4347,5.8230619,0.88073999,0.0,0,9.0389996,0.0,0.060326759,69.748672,9.113903,453.89142,-9.2345114
2738,2738,195.4369,5.8255634,0.9107911,0.0,0,9.0068092,0.0,0.062851369,69.682968,9.0824041,453.87823,-9.2339659
2749,2749,195.4391,5.8523393,0.9497866,0.0,0,8.9746189,0.0,0.065036587,69.743813,9.0479813,453.86502,-9.2328691
2760,2760,195.4413,5.8893061,0.9745813,0.0,0,8.9424286,0.0,0.067281015,70.074165,9.0143156,453.74982,-9.2348232
2771,2771,195.4435,5.9256887,1.00842,0.0,0,8.9102383,0.0,0.069450185,70.40155,8.9792557,453.51221,-9.2337227
2782,2782,195.4457,5.9398856,1.038622,0.0,0,8.8780479,0.0,0.07199125,70.399719,8.9467468,453.27457,-9.2342844
2793,2793,195.4479,5.9565654,1.0770818,0.0,0,8.8458576,0.0,0.074281484,70.467415,8.9135962,453.03696,-9.2335596
2804,2804,195.4501,5.9705024,1.1047608,0.0,0,8.8136663,0.0,0.076538906,70.450302,8.8823595,452.79935,-9.2339592
2815,2815,195.4523,5.9924021,1.1382531,0.0,0,8.781476,0.0,0.078813069,70.567719,8.8457737,452.64658,-9.2331686
2826,2826,195.4545,5.9950714,1.1697192,0.0,0,8.7493448,0.0,0.081175022,70.398727,8.8119593,452.50134,-9.2327347
2837,2837,195.4567,5.9871988,1.2076983,0.0,0,8.7187147,0.0,0.083796099,70.20607,8.7806902,452.35614,-9.2329588
2848,2848,195.4589,6.0150356,1.2349349,0.0,0,8.6880999,0.0,0.085913509,70.266853,8.7505293,452.21094,-9.2333136
2859,2859,195.4611,6.0448165,1.2669884,0.0,0,8.657485,0.0,0.088295609,70.44519,8.7167482,452.20685,-9.2323475
2870,2870,195.4633,6.0674739,1.2947953,0.0,0,8.6268692,0.0,0.090204008,70.49765,8.6823254,452.43127,-9.2342291
2881,2881,195.4655,6.0521922,1.3295246,0.0,0,8.5962543,0.0,0.092924148,70.289223,8.6555185,452.6557,-9.232893
2892,2892,195.4677,6.0870771,1.3607858,0.0,0,8.5656385,0.0,0.094953425,70.433525,8.6240444,452.88013,-9.2337456
2903,2903,195.4699,6.0865211,1.3895202,0.0,0,8.5350246,0.0,0.097265325,70.363602,8.5889854,453.10455,-9.2334423
2914,2914,195.4721,6.1061549,1.4204428,0.0,0,8.5044088,0.0,0.099316075,70.438377,8.5589418,453.29547,-9.2332239
2925,2925,195.4743,6.1103616,1.4542611,0.0,0,8.473794,0.0,0.10210741,70.270912,8.526185,453.48029,-9.2339611
2936,2936,195.4765,6.1140447,1.4877852,0.0,0,8.4431782,0.0,0.10420585,70.194008,8.4938517,453.6651,-9.234129
2947,2947,195.4787,6.1149716,1.5136176,0.0,0,8.4125633,0.0,0.10657638,69.946808,8.4589014,453.84991,-9.2340384
2958,2958,195.4809,6.1328335,1.5430644,0.0,0,8.3819485,0.0,0.10834295,70.088318,8.4329376,454.00412,-9.2339249
2969,2969,195.4831,6.1447511,1.5689567,0.0,0,8.3513327,0.0,0.11075564,70.046227,8.4051962,454.08994,-9.2331085
2980,2980,195.4853,6.1590543,1.6006213,0.0,0,8.3207178,0.0,0.11248262,69.98864,8.3782454,454.17575,-9.2319803
2991,2991,195.4875,6.1793575,1.6239351,0.0,0,8.290102,0.0,0.11488318,70.049171,8.3500137,454.26154,-9.2327156
3002,3002,195.4897,6.1933565,1.6585637,0.0,0,8.2594872,0.0,0.11694579,70.178162,8.3182268,454.34735,-9.2332058
3013,3013,195.4919,6.233161,1.6880404,0.0,0,8.2288723,0.0,0.11962563,70.37339,8.2894001,454.31073,-9.2332687
3024,3024,195.4941,6.266376,1.7246476,0.0,0,8.1982574,0.0,0.12173299,70.517029,8.2553501,454.23813,-9.2325497
3035,3035,195.4963,6.2777882,1.7483059,0.0,0,8.1676416,0.0,0.12409502,70.554184,8.2222471,454.16553,-9.2325802
3046,3046,195.4985,6.3133254,1.782277,0.0,0,8.1370268,0.0,0.12630314,70.846733,8.1934376,454.09293,-9.2321062
3057,3057,195.5007,6.3512077,1.8118392,0.0,0,8.1064119,0.0,0.12891582,71.029434,8.1588163,454.00159,-9.2322416
3068,3068,195.5029,6.3722687,1.8514205,0.0,0,8.0757961,0.0,0.13148519,71.174683,8.1292458,453.84979,-9.2327414
3079,3079,195.5051,6.3660831,1.87664,0.0,0,8.0456295,0.0,0.13378052,70.811523,8.0924997,453.69797,-9.2333107
3090,3090,195.5073,6.3465724,1.9097437,0.0,0,8.0165014,0.0,0.13604474,70.577675,8.0653067,453.54617,-9.2332945
3101,3101,195.5095,6.3590074,1.9362282,0.0,0,7.9873734,0.0,0.13819993,70.617249,8.0332556,453.39435,-9.2332325
3112,3112,195.5117,6.3524165,1.9726422,0.0,0,7.9582453,0.0,0.14084359,70.287277,8.004406,453.37653,-9.234621
3123,3123,195.5139,6.3694487,1.998668,0.0,0,7.9291167,0.0,0.14299159,70.336891,7.9710479,453.41614,-9.2344685
3134,3134,195.5161,6.3797431,2.0287361,0.0,0,7.8999891,0.0,0.14528844,70.270683,7.941227,453.45575,-9.2334299
3145,3145,195.5183,6.3869562,2.0527112,0.0,0,7.8708611,0.0,0.14709704,70.169945,7.9131026,453.49536,-9.2327805
3156,3156,195.5205,6.4143801,2.0835469,0.0,0,7.841733,0.0,0.1496112,70.296112,7.8845654,453.56195,-9.2337723
3167,3167,195.5227,6.4585738,2.1134386,0.0,0,7.8126049,0.0,0.15174799,70.652664,7.8578272,453.76657,-9.2328014
3178,3178,195.5249,6.4156423,2.1391885,0.0,0,7.7834768,0.0,0.15395758,70.079872,7.8251433,453.97119,-9.2334509
3189,3189,195.5271,6.4309835,2.166399,0.0,0,7.7543492,0.0,0.15580325,70.085754,7.7967,454.17578,-9.2336597
3200,3200,195.5293,6.4285355,2.1953824,0.0,0,7.7252212,0.0,0.1584357,69.828758,7.7701073,454.3804,-9.2334633
3211,3211,195.5315,6.4621005,2.2251246,0.0,0,7.6960936,0.0,0.16028833,69.955917,7.7413154,454.59744,-9.2335119
3222,3222,195.5337,6.4749594,2.2500019,0.0,0,7.6669645,0.0,0.16273612,70.082619,7.712894,454.82187,-9.2342033
3233,3233,195.5359,6.5380721,2.2805941,0.0,0,7.6378374,0.0,0.16465007,70.611923,7.6838093,455.0463,-9.2317858
3244,3244,195.5381,6.5529828,2.3070114,0.0,0,7.6087093,0.0,0.16734897,70.571976,7.6533804,455.27072,-9.2326593
3255,3255,195.5403,6.5825944,2.3417418,0.0,0,7.5795813,0.0,0.16931359,70.712524,7.6227665,455.48975,-9.2331171
3266,3266,195.5425,6.5950351,2.3643363,0.0,0,7.5504527,0.0,0.17178835,70.72863,7.5981588,455.65475,-9.2336779
3277,3277,195.5447,6.60601,2.3982255,0.0,0,7.5213251,0.0,0.17396009,70.748444,7.5660963,455.81976,-9.2339859
3288,3288,195.5469,6.6018147,2.4248405,0.0,0,7.492197,0.0,0.17661703,70.385155,7.5323753,455.98477,-9.2329769
3299,3299,195.5491,6.6044631,2.4618325,0.0,0,7.4630694,0.0,0.17888618,70.380959,7.5056314,456.14978,-9.2332726
3310,3310,195.5513,6.6095777,2.4824874,0.0,0,7.4339409,0.0,0.18108538,70.223862,7.476264,456.28549,-9.2332602
3321,3321,195.5535,6.6357517,2.5140746,0.0,0,7.4048128,0.0,0.18324322,70.316544,7.4480939,456.39771,-9.2326479
3332,3332,195.5557,6.6692209,2.5388153,0.0,0,7.3765035,0.0,0.18568441,70.565262,7.4163575,456.50992,-9.2338181
3343,3343,195.5579,6.6996775,2.575598,0.0,0,7.3488007,0.0,0.18809816,70.694054,7.3880363,456.62213,-9.2334671
3354,3354,195.5601,6.7186747,2.5980575,0.0,0,7.3210988,0.0,0.19031914,70.680687,7.3622975,456.73434,-9.2322121
3365,3365,195.5623,6.7482514,2.6307199,0.0,0,7.293396,0.0,0.1925571,70.863029,7.3259454,456.84656,-9.2325602
3376,3376,195.5645,6.7289453,2.6567779,0.0,0,7.2656941,0.0,0.19500577,70.432426,7.2945991,456.95877,-9.2335558
3387,3387,195.5667,6.7071548,2.6915956,0.0,0,7.2379909,0.0,0.19764148,70.054504,7.2681398,457.07098,-9.2346869
3398,3398,195.5689,6.7025313,2.7146482,0.0,0,7.210289,0.0,0.19961418,69.803955,7.2416053,457.1832,-9.2334356
3409,3409,195.5711,6.6931252,2.7415729,0.0,0,7.1825862,0.0,0.20183666,69.596275,7.2181821,457.28586,-9.2327671
3420,3420,195.5733,6.7132411,2.7630262,0.0,0,7.1548843,0.0,0.20351256,69.644302,7.1878567,457.37827,-9.2325945
3431,3431,195.5755,6.7499256,2.7914124,0.0,0,7.1271815,0.0,0.20599879,69.926682,7.1628575,457.47067,-9.2336397
3442,3442,195.5777,6.7730031,2.8175879,0.0,0,7.0994792,0.0,0.20781597,69.981079,7.1356583,457.56308,-9.2338219
3453,3453,195.5799,6.801918,2.8462508,0.0,0,7.0717769,0.0,0.21051982,70.116074,7.1132474,457.65549,-9.2346506
3464,3464,195.5821,6.805337,2.8731394,0.0,0,7.0440745,0.0,0.21236537,70.114731,7.0812721,457.71667,-9.2334251
3475,3475,195.5843,6.819726,2.9015756,0.0,0,7.0163722,0.0,0.21516174,70.083267,7.0558701,457.77609,-9.2319145
3486,3486,195.5865,6.8340578,2.9303358,0.0,0,6.9886694,0.0,0.21699767,70.117752,7.026926,457.83548,-9.2334423
3497,3497,195.5887,6.8815327,2.9553876,0.0,0,6.9609671,0.0,0.21964408,70.397324,6.9956489,457.8949,-9.2335157
3508,3508,195.5909,6.9068618,2.9864614,0.0,0,6.9332652,0.0,0.22167528,70.337166,6.9646001,457.95428,-9.2326584
3519,3519,195.5931,6.9170299,3.0128732,0.0,0,6.9055624,0.0,0.22458771,70.410675,6.9356022,458.0137,-9.2322302
3530,3530,195.5953,6.9188519,3.0487819,0.0,0,6.8778601,0.0,0.22682969,70.240974,6.9071383,458.07309,-9.2329206
3541,3541,195.5975,6.8975763,3.0710421,0.0,0,6.8501582,0.0,0.22936964,69.824165,6.8812075,458.13251,-9.2332497
3552,3552,195.5997,6.9148617,3.0977132,0.0,0,6.8224549,0.0,0.23102394,69.87822,6.8560004,458.19189,-9.2328634
3563,3563,195.6019,6.9031157,3.1184473,0.0,0,6.7947526,0.0,0.23341544,69.646599,6.8284807,458.22827,-9.2325621
3574,3574,195.6041,6.9167252,3.1530285,0.0,0,6.7670503,0.0,0.23556273,69.579948,6.8020205,458.26126,-9.2318468
3585,3585,195.6063,6.9680314,3.1749141,0.0,0,6.7404876,0.0,0.23806381,69.905998,6.7731352,458.29428,-9.2329826
3596,3596,195.6085,6.9891095,3.2047162,0.0,0,6.7141318,0.0,0.24009041,70.016464,6.740766,458.32727,-9.2314119
3607,3607,195.6107,7.0110221,3.2272832,0.0,0,6.6877756,0.0,0.2425772,70.010963,6.7186761,458.32477,-9.2316656
3618,3618,195.6129,7.0166192,3.2625396,0.0,0,6.6614199,0.0,0.24491628,69.881569,6.6874986,458.25217,-9.2330141
3629,3629,195.6151,7.0291748,3.2839706,0.0,0,6.6350632,0.0,0.24721777,69.890663,6.6628137,458.17957,-9.2328796
3640,3640,195.6173,7.0446501,3.3138475,0.0,0,6.6087079,0.0,0.24948092,69.918549,6.6375632,458.10696,-9.2332783
3651,3651,195.6195,7.0544734,3.3366652,0.0,0,6.5823517,0.0,0.25168338,69.941956,6.6070256,458.03436,-9.2328796
3662,3662,195.6217,7.0419779,3.368264,0.0,0,6.5559955,0.0,0.25407639,69.603004,6.581378,457.90894,-9.2333364
3673,3673,195.6239,7.0282574,3.3904078,0.0,0,6.5296397,0.0,0.2562781,69.332237,6.5550723,457.77032,-9.2333908
3684,3684,195.6261,7.0313621,3.4177697,0.0,0,6.503284,0.0,0.25856158,69.096558,6.5300102,457.63171,-9.2341166
3695,3695,195.6283,7.0879579,3.4394073,0.0,0,6.4769278,0.0,0.26036963,69.527176,6.5052552,457.4931,-9.2341118
3706,3706,195.6305,7.1055427,3.4691255,0.0,0,6.450572,0.0,0.26301935,69.526299,6.4769816,457.35974,-9.2326698
3717,3717,195.6327,7.1364551,3.4927704,0.0,0,6.4242158,0.0,0.26489267,69.739647,6.4495034,457.24091,-9.2328577
3728,3728,195.6349,7.1653709,3.5199366,0.0,0,6.3978601,0.0,0.26755756,69.838539,6.4234128,457.1221,-9.2339563
3739,3739,195.6371,7.1735182,3.5452685,0.0,0,6.3715038,0.0,0.26937312,69.845764,6.3996353,457.0033,-9.2333803
3750,3750,195.6393,7.1759219,3.5742571,0.0,0,6.3451476,0.0,0.272403,69.614136,6.3668818,456.88449,-9.2329664
3761,3761,195.6415,7.1615319,3.6022422,0.0,0,6.3187919,0.0,0.27428713,69.311081,6.3431726,456.80887,-9.2326546
3772,3772,195.6437,7.1684341,3.623337,0.0,0,6.2924361,0.0,0.27673513,69.181267,6.3212481,456.74945,-9.2319307
3783,3783,195.6459,7.2013407,3.6507926,0.0,0,6.2660799,0.0,0.27858615,69.36367,6.2913241,456.69006,-9.2320356
3794,3794,195.6481,7.2299256,3.6748803,0.0,0,6.2397242,0.0,0.28134927,69.477478,6.2672768,456.63065,-9.2319603
3805,3805,195.6503,7.2442832,3.7070494,0.0,0,6.2133679,0.0,0.28336787,69.48584,6.2345724,456.57376,-9.2318201
3816,3816,195.6525,7.2572722,3.7274482,0.0,0,6.1870122,0.0,0.28600445,69.467979,6.2133141,456.52756,-9.232172
3827,3827,195.6547,7.2748861,3.755827,0.0,0,6.1608105,0.0,0.28792492,69.460411,6.1885557,456.48135,-9.2334633
3838,3838,195.6569,7.279067,3.7774825,0.0,0,6.1357431,0.0,0.29048979,69.293953,6.1592445,456.43515,-9.233181
3849,3849,195.6591,7.2941399,3.8084683,0.0,0,6.1106758,0.0,0.29243606,69.29007,6.1323671,456.38895,-9.2331705
3860,3860,195.6613,7.2996564,3.8310914,0.0,0,6.0856094,0.0,0.29522899,69.244263,6.1086679,456.41187,-9.2327003
3871,3871,195.6635,7.3277316,3.8608825,0.0,0,6.0605426,0.0,0.29731089,69.273773,6.083622,456.47128,-9.2324362
3882,3882,195.6657,7.3375454,3.8807411,0.0,0,6.0354757,0.0,0.29965493,69.203499,6.0550604,456.53067,-9.2320776
3893,3893,195.6679,7.3822656,3.9130363,0.0,0,6.0104089,0.0,0.30188781,69.490868,6.0317349,456.59009,-9.2321968
3904,3904,195.6701,7.3818831,3.9326546,0.0,0,5.985342,0.0,0.30423468,69.387672,6.0063291,456.65103,-9.2316313
3915,3915,195.6723,7.3745184,3.9613733,0.0,0,5.9602752,0.0,0.30646393,69.080719,5.9785213,456.72366,-9.2320776
3926,3926,195.6745,7.3845367,3.9826574,0.0,0,5.9352083,0.0,0.30870497,69.070145,5.9542184,456.79626,-9.2328062
3937,3937,195.6767,7.366179,4.0138636,0.0,0,5.9101419,0.0,0.31117398,68.677986,5.9291902,456.8689,-9.2323771
3948,3948,195.6789,7.3695669,4.0322733,0.0,0,5.8850751,0.0,0.31316099,68.675789,5.9046845,456.9415,-9.2319756
3959,3959,195.6811,7.3960996,4.0573497,0.0,0,5.8600082,0.0,0.315384,68.688789,5.8801718,456.97571,-9.2324533
3970,3970,195.6833,7.4607058,4.0807719,0.0,0,5.8349414,0.0,0.31746483,69.066025,5.8544765,456.9823,-9.2318726
3981,3981,195.6855,7.4829164,4.1118178,0.0,0,5.8098745,0.0,0.32046029,69.124992,5.8281679,456.98889,-9.2307987
3992,3992,195.6877,7.5121255,4.1355801,0.0,0,5.7848077,0.0,0.32239714,69.337517,5.804265,456.99548,-9.2324495
4003,4003,195.6899,7.5345449,4.15904,0.0,0,5.7597408,0.0,0.32481363,69.341911,5.7770648,457.00598,-9.2336578
4014,4014,195.6921,7.5269547,4.1835327,0.0,0,5.734674,0.0,0.32676667,69.111206,5.7527966,457.09839,-9.2318211
4025,4025,195.6943,7.5231376,4.2113357,0.0,0,5.7096071,0.0,0.32979363,68.883675,5.728251,457.1908,-9.2330332
4036,4036,195.6965,7.5255871,4.2378416,0.0,0,5.6845407,0.0,0.33159611,68.786301,5.7003593,457.2832,-9.233675
4047,4047,195.6987,7.532383,4.2579961,0.0,0,5.6594739,0.0,0.33414772,68.667007,5.6767998,457.37561,-9.2339897
4058,4058,195.7009,7.5578561,4.284481,0.0,0,5.6344066,0.0,0.33597973,68.711456,5.652566,457.45792,-9.2336187
4069,4069,195.7031,7.6099763,4.307703,0.0,0,5.6093402,0.0,0.33883384,68.983475,5.6259475,457.53055,-9.2323065
4080,4080,195.7053,7.6416092,4.3380818,0.0,0,5.5847511,0.0,0.34091175,69.159851,5.6020923,457.60315,-9.2329645
4091,4091,195.7075,7.6633782,4.357944,0.0,0,5.5609031,0.0,0.34360301,69.164368,5.5728631,457.67578,-9.2314587
4102,4102,195.7097,7.6694551,4.3868604,0.0,0,5.537055,0.0,0.34555656,69.12352,5.5505843,457.74838,-9.2325239
4113,4113,195.7119,7.6722102,4.4075236,0.0,0,5.513207,0.0,0.34830225,69.073616,5.5261841,457.75677,-9.2339001
4124,4124,195.7141,7.6701074,4.4416099,0.0,0,5.4893589,0.0,0.3505502,68.788406,5.4991689,457.76337,-9.2333984
4135,4135,195.7163,7.6372237,4.4569011,0.0,0,5.4655113,0.0,0.35284317,68.326103,5.4760795,457.76996,-9.2331457
4146,4146,195.7185,7.6205831,4.4837394,0.0,0,5.4416628,0.0,0.35484174,67.982872,5.4521713,457.77655,-9.232748
4157,4157,195.7207,7.6066542,4.5019717,0.0,0,5.4178152,0.0,0.35726127,67.797531,5.4313421,457.80331,-9.2319918
4168,4168,195.7229,7.6807752,4.5312943,0.0,0,5.3939676,0.0,0.3592189,68.258263,5.4103341,457.85614,-9.2329569
4179,4179,195.7251,7.7147284,4.5466146,0.0,0,5.3701191,0.0,0.36133209,68.40802,5.3838058,457.90894,-9.2330799
4190,4190,195.7273,7.7408285,4.5726166,0.0,0,5.3462715,0.0,0.36342439,68.527191,5.3616562,457.96176,-9.2320814
4201,4201,195.7295,7.7386012,4.5916681,0.0,0,5.322423,0.0,0.36552399,68.358009,5.337533,458.01456,-9.2321758
4212,4212,195.7317,7.7513595,4.621695,0.0,0,5.2985754,0.0,0.36812717,68.281105,5.3180304,457.02774,-9.2319498
4223,4223,195.7339,7.7657981,4.6400814,0.0,0,5.2747278,0.0,0.37014198,68.379402,5.2892132,455.92548,-9.23314
4234,4234,195.7361,7.7984028,4.6670933,0.0,0,5.2508793,0.0,0.3727617,68.425438,5.2656074,454.82318,-9.2336311
4245,4245,195.7383,7.8036375,4.6879187,0.0,0,5.2270312,0.0,0.37464246,68.293999,5.2440248,453.72089,-9.2326622
4256,4256,195.7405,7.8462491,4.7189255,0.0,0,5.2031832,0.0,0.37776083,68.427071,5.2176566,452.71701,-9.2316685
4267,4267,195.7427,7.8874655,4.7365489,0.0,0,5.1793356,0.0,0.3793098,68.816963,5.1945,451.88535,-9.232213
4278,4278,195.7449,7.9116902,4.7611551,0.0,0,5.1554875,0.0,0.3819356,68.784584,5.170321,451.05368,-9.2311707
4289,4289,195.7471,7.9193621,4.7869139,0.0,0,5.1316395,0.0,0.38412189,68.682419,5.1436834,450.22202,-9.2318916
4300,4300,195.7493,7.9116993,4.8125529,0.0,0,5.1077914,0.0,0.38714719,68.40551,5.1212854,449.39035,-9.2324085
4311,4311,195.7515,7.8992739,4.8361526,0.0,0,5.0839434,0.0,0.38878381,68.234596,5.0980406,449.57434,-9.2319784
4322,4322,195.7537,7.9410081,4.8556123,0.0,0,5.0600953,0.0,0.39144644,68.338486,5.0768309,449.97037,-9.2334919
4333,4333,195.7559,7.9716372,4.8820643,0.0,0,5.0370221,0.0,0.39341229,68.516747,5.0496287,450.36639,-9.2324924
4344,4344,195.7581,7.9914665,4.9064393,0.0,0,5.0143404,0.0,0.39651066,68.466888,5.0275097,450.76239,-9.2326221
4355,4355,195.7603,8.029644,4.935132,0.0,0,4.9916587,0.0,0.39846197,68.578041,5.0045333,451.08163,-9.2322073
4366,4366,195.7625,8.0532827,4.9502878,0.0,0,4.9689765,0.0,0.40090469,68.674744,4.9797773,451.21362,-9.2317858
4377,4377,195.7647,8.0477676,4.9791665,0.0,0,4.9462943,0.0,0.40296039,68.492493,4.9569759,451.34564,-9.2329044
4388,4388,195.7669,8.0418625,4.9988217,0.0,0,4.9236121,0.0,0.40584385,68.311729,4.9316111,451.47766,-9.2316484
4399,4399,195.7691,8.0310965,5.0271716,0.0,0,4.9009304,0.0,0.40758952,68.068161,4.9082232,451.60968,-9.2312746
4410,4410,195.7713,8.0567398,5.0425367,0.0,0,4.8782487,0.0,0.41001418,68.071846,4.8863096,451.7666,-9.2320547
4421,4421,195.7735,8.0803289,5.0681973,0.0,0,4.855566,0.0,0.41203293,68.103951,4.8650212,451.93161,-9.232914
4432,4432,195.7757,8.1198912,5.0878711,0.0,0,4.8328843,0.0,0.41472149,68.246552,4.837954,452.09662,-9.2326002
4443,4443,195.7779,8.128232,5.1189494,0.0,0,4.8102026,0.0,0.41700613,68.254311,4.8200955,452.26163,-9.2319651
4454,4454,195.7801,8.12883,5.1352067,0.0,0,4.7875204,0.0,0.41935951,68.022911,4.7932482,452.4108,-9.2323132
4465,4465,195.7823,8.1941109,5.1608119,0.0,0,4.7648382,0.0,0.42138347,68.407387,4.7725611,452.5032,-9.232337
4476,4476,195.7845,8.2088413,5.178421,0.0,0,4.742156,0.0,0.42357427,68.467392,4.7518897,452.59561,-9.2332058
4487,4487,195.7867,8.2168045,5.2108412,0.0,0,4.7194743,0.0,0.42647108,68.363358,4.7229447,452.68802,-9.2338371
4498,4498,195.7889,8.1876488,5.2269897,0.0,0,4.6967921,0.0,0.42844138,67.957451,4.7027535,452.78046,-9.2324362
4509,4509,195.7911,8.1656427,5.2510233,0.0,0,4.6741104,0.0,0.43089864,67.604065,4.6818614,452.87735,-9.2320948
4520,4520,195.7933,8.1902351,5.2685843,0.0,0,4.6514282,0.0,0.43264726,67.665688,4.6603432,452.97635,-9.2319412
4531,4531,195.7955,8.2214098,5.29739,0.0,0,4.6287465,0.0,0.43569964,67.744682,4.6384759,453.07535,-9.2318964
4542,4542,195.7977,8.2592831,5.316154,0.0,0,4.6060643,0.0,0.43746153,67.936584,4.6199012,453.17438,-9.2312441
4553,4553,195.7999,8.2953653,5.3390784,0.0,0,4.5833826,0.0,0.44006085,68.046783,4.5941319,453.2897,-9.2319317
4564,4564,195.8021,8.3854818,5.3601174,0.0,0,4.5606999,0.0,0.44188222,68.603516,4.5706372,453.50092,-9.2320461
4575,4575,195.8043,8.4089746,5.3853035,0.0,0,4.5380182,0.0,0.44498071,68.639191,4.5500121,453.71216,-9.2317333
4586,4586,195.8065,8.4049778,5.4106121,0.0,0,4.5163717,0.0,0.44697395,68.450546,4.5239472,453.92337,-9.2327099
4597,4597,195.8087,8.395175,5.430727,0.0,0,4.4947939,0.0,0.4498013,68.181816,4.4968357,454.13458,-9.2320356
4608,4608,195.8109,8.3782063,5.455308,0.0,0,4.4732161,0.0,0.45158136,67.942451,4.4763227,454.3056,-9.2318125
4619,4619,195.8131,8.3795719,5.4748349,0.0,0,4.4516387,0.0,0.45457518,67.713593,4.457387,454.45081,-9.2325506
4630,4630,195.8153,8.3868837,5.5014853,0.0,0,4.4300609,0.0,0.45637292,67.64727,4.4350882,454.59604,-9.2327557
4641,4641,195.8175,8.4322605,5.5159097,0.0,0,4.4084835,0.0,0.45891741,67.78614,4.4139128,454.74124,-9.2326508
4652,4652,195.8197,8.4695892,5.5412211,0.0,0,4.3869057,0.0,0.46068043,68.005234,4.3908572,454.87589,-9.2314034
4663,4663,195.8219,8.4947662,5.5591726,0.0,0,4.3653283,0.0,0.46351242,68.056847,4.3663363,454.87589,-9.2316666
4674,4674,195.8241,8.4656334,5.5856609,0.0,0,4.3437505,0.0,0.4652518,67.726982,4.3505955,454.87589,-9.2318716
4685,4685,195.8263,8.4757071,5.6004243,0.0,0,4.3221731,0.0,0.46777192,67.622246,4.3266253,454.87589,-9.2324715
4696,4696,195.8285,8.4899397,5.6267772,0.0,0,4.3005958,0.0,0.46979031,67.536743,4.3086224,454.87589,-9.2317133
4707,4707,195.8307,8.5232887,5.6420016,0.0,0,4.2790179,0.0,0.47228983,67.694397,4.2843156,454.3519,-9.2310343
4718,4718,195.8329,8.5591307,5.6740375,0.0,0,4.2574401,0.0,0.4746767,67.767517,4.2645435,453.37503,-9.2311096
4729,4729,195.8351,8.5977573,5.6858292,0.0,0,4.2358627,0.0,0.47675583,67.961296,4.2406926,452.39813,-9.2312565
4740,4740,195.8373,8.6099758,5.7092195,0.0,0,4.2142849,0.0,0.47877958,67.937653,4.2178984,451.42126,-9.2310734
4751,4751,195.8395,8.661046,5.730166,0.0,0,4.1927075,0.0,0.48141953,68.133514,4.1976008,450.4444,-9.2304077
4762,4762,195.8417,8.7052383,5.7600956,0.0,0,4.1711297,0.0,0.48420268,68.319771,4.1760449,449.67871,-9.2325411
4773,4773,195.8439,8.6844835,5.7726607,0.0,0,4.1495523,0.0,0.4860194,68.048592,4.1546621,448.91306,-9.2331514
4784,4784,195.8461,8.645853,5.7945824,0.0,0,4.1279745,0.0,0.48824012,67.592789,4.1310239,448.1474,-9.2326231
4795,4795,195.8483,8.6856289,5.8150525,0.0,0,4.1063972,0.0,0.4903025,67.728409,4.1140156,447.38174,-9.2326984
4806,4806,195.8505,8.7239094,5.8433709,0.0,0,4.0848198,0.0,0.49358755,67.739792,4.0885653,447.1149,-9.232605
4817,4817,195.8527,8.7612906,5.8596888,0.0,0,4.063242,0.0,0.49521181,67.99025,4.0687637,447.42514,-9.2316389
4828,4828,195.8549,8.7904797,5.8806014,0.0,0,4.0418859,0.0,0.49777403,68.032181,4.0490146,447.73535,-9.2316446
4839,4839,195.8571,8.8274555,5.9010839,0.0,0,4.0213642,0.0,0.49961442,68.172241,4.0258822,448.04556,-9.2316704
4850,4850,195.8593,8.8652115,5.9254932,0.0,0,4.000843,0.0,0.50292373,68.233742,4.0059156,448.3558,-9.230485
4861,4861,195.8615,8.8874178,5.9494185,0.0,0,3.9803216,0.0,0.50470483,68.304787,3.9820702,448.78842,-9.2316799
4872,4872,195.8637,8.8718071,5.9658036,0.0,0,3.9598,0.0,0.50734615,68.06797,3.961597,449.23068,-9.2306414
4883,4883,195.8659,8.8636312,5.988605,0.0,0,3.9392784,0.0,0.50918502,67.846916,3.9400535,449.67291,-9.2304192
4894,4894,195.8681,8.8999262,6.0087614,0.0,0,3.9187567,0.0,0.51223499,67.886429,3.9189689,450.11514,-9.2309752
4905,4905,195.8703,8.9099112,6.0343194,0.0,0,3.8982351,0.0,0.51398993,67.82412,3.8973405,450.60123,-9.2318926
4916,4916,195.8725,8.9257174,6.048162,0.0,0,3.8777134,0.0,0.51673341,67.804085,3.883868,451.15567,-9.2321062
4927,4927,195.8747,8.9704437,6.071949,0.0,0,3.8571918,0.0,0.51835304,68.024887,3.8637223,451.71014,-9.2311077
4938,4938,195.8769,9.0146484,6.0914397,0.0,0,3.8366702,0.0,0.52156198,68.180023,3.8401058,452.26459,-9.2309275
4949,4949,195.8791,9.0813885,6.1199455,0.0,0,3.8161488,0.0,0.52359611,68.495766,3.8168557,452.81903,-9.2316551
4960,4960,195.8813,9.1083307,6.1340494,0.0,0,3.7956274,0.0,0.52628493,68.566223,3.7961295,453.15912,-9.2313929
4971,4971,195.8835,9.097846,6.1614294,0.0,0,3.7751055,0.0,0.52854311,68.244041,3.7716351,453.46277,-9.2317505
4982,4982,195.8857,9.0546894,6.1765065,0.0,0,3.7545838,0.0,0.53117406,67.814453,3.7530355,453.76639,-9.2314005
4993,4993,195.8879,9.0581207,6.2034802,0.0,0,3.7340622,0.0,0.53316152,67.614479,3.7330179,454.07004,-9.2312365
5004,5004,195.8901,9.0545578,6.216939,0.0,0,3.7135406,0.0,0.53556949,67.437622,3.7138364,454.31696,-9.2312021
5015,5015,195.8923,9.0770779,6.237566,0.0,0,3.6930192,0.0,0.53732347,67.496529,3.6953297,454.44235,-9.2311049
5026,5026,195.8945,9.1079321,6.2512875,0.0,0,3.6724977,0.0,0.53942883,67.653496,3.6764019,454.56778,-9.2318602
5037,5037,195.8967,9.1696768,6.2802415,0.0,0,3.6519756,0.0,0.54220283,67.919022,3.6564581,454.69318,-9.2321739
5048,5048,195.8989,9.2135763,6.2949023,0.0,0,3.6314542,0.0,0.54425454,68.077568,3.638206,454.81857,-9.2324944
5059,5059,195.9011,9.2652912,6.3184938,0.0,0,3.6109326,0.0,0.54674536,68.26342,3.6154246,454.86142,-9.2326565
5070,5070,195.9033,9.3082371,6.3357282,0.0,0,3.5904109,0.0,0.54883212,68.408836,3.5964775,454.88123,-9.2321329
5081,5081,195.9055,9.326395,6.3654456,0.0,0,3.5703721,0.0,0.55213875,68.401825,3.5713482,454.90103,-9.2306967
5092,5092,195.9077,9.3944206,6.3809195,0.0,0,3.5508494,0.0,0.55387354,68.693939,3.5514879,454.92081,-9.2317467
5103,5103,195.9099,9.4174204,6.4021688,0.0,0,3.5313263,0.0,0.55676001,68.685997,3.5289645,454.94061,-9.2304373
5114,5114,195.9121,9.4052267,6.4222283,0.0,0,3.5118036,0.0,0.55862772,68.464317,3.5088413,454.96042,-9.2308435
5125,5125,195.9143,9.3755856,6.4461279,0.0,0,3.4922807,0.0,0.56193054,68.10482,3.4873369,454.98022,-9.231554
5136,5136,195.9165,9.3599672,6.4642963,0.0,0,3.4727581,0.0,0.56332213,67.861397,3.4710426,455.00003,-9.2313614
5147,5147,195.9187,9.3564806,6.4788566,0.0,0,3.4532354,0.0,0.56593454,67.650673,3.4544923,455.01981,-9.2309418
5158,5158,195.9209,9.3710585,6.4978218,0.0,0,3.4337122,0.0,0.56720906,67.691811,3.4348416,454.68857,-9.2313433
5169,5169,195.9231,9.4071484,6.5177722,0.0,0,3.4141896,0.0,0.57062232,67.744133,3.4168599,454.21335,-9.2318764
5180,5180,195.9253,9.4882584,6.5423741,0.0,0,3.3946669,0.0,0.57228893,68.117073,3.3977187,453.7381,-9.2324486
5191,5191,195.9275,9.5727577,6.5553837,0.0,0,3.3751438,0.0,0.57502353,68.573051,3.3777325,453.26288,-9.2317295
5202,5202,195.9297,9.5969982,6.5776558,0.0,0,3.3556213,0.0,0.57667059,68.605087,3.3547072,452.55716,-9.2318525
5213,5213,195.9319,9.6031542,6.5957146,0.0,0,3.3360982,0.0,0.57983518,68.474388,3.338594,450.74789,-9.2306709
5224,5224,195.9341,9.6295557,6.6217513,0.0,0,3.3165758,0.0,0.58155042,68.514603,3.3139653,448.9386,-9.2305546
5235,5235,195.9363,9.6414843,6.6316648,0.0,0,3.2970529,0.0,0.58425838,68.47435,3.2974842,447.1293,-9.231041
5246,5246,195.9385,9.6640139,6.6560221,0.0,0,3.2775297,0.0,0.58617777,68.466995,3.278945,445.32001,-9.2313938
5257,5257,195.9407,9.6929274,6.6731148,0.0,0,3.2580073,0.0,0.58926159,68.471336,3.2576056,444.25046,-9.2333345
5268,5268,195.9429,9.729702,6.7019835,0.0,0,3.2384841,0.0,0.59145939,68.546745,3.2357538,443.60361,-9.2318382
5279,5279,195.9451,9.7448206,6.7116151,0.0,0,3.2189617,0.0,0.59341681,68.476768,3.2165329,442.95676,-9.2316875
5290,5290,195.9473,9.7831898,6.7354927,0.0,0,3.1994388,0.0,0.59567392,68.612099,3.1995537,442.30988,-9.231142
5301,5301,195.9495,9.8113651,6.7507367,0.0,0,3.1799159,0.0,0.59813702,68.68148,3.1782401,441.81625,-9.230998
5312,5312,195.9517,9.8434219,6.776732,0.0,0,3.1603932,0.0,0.60079873,68.734657,3.1607828,442.70148,-9.229764
5323,5323,195.9539,9.8589849,6.7887616,0.0,0,3.1408703,0.0,0.60280555,68.677818,3.1394222,443.5867,-9.2305393
5334,5334,195.9561,9.8660049,6.8139071,0.0,0,3.1220658,0.0,0.60549992,68.557632,3.1232789,444.47192,-9.2315273
5345,5345,195.9583,9.8896751,6.8295507,0.0,0,3.1034932,0.0,0.60733771,68.579933,3.1043873,445.35715,-9.2298679
5356,5356,195.9605,9.9099598,6.854115,0.0,0,3.0849209,0.0,0.61052608,68.534714,3.0838096,446.04105,-9.2308693
5367,5367,195.9627,9.9448557,6.8681011,0.0,0,3.0663483,0.0,0.61206877,68.634491,3.0624397,446.56909,-9.2311945
5378,5378,195.9649,9.9884167,6.8868914,0.0,0,3.047776,0.0,0.6146481,68.734344,3.0468175,447.09714,-9.231102
5389,5389,195.9671,10.037118,6.9045415,0.0,0,3.0292037,0.0,0.61644667,68.945038,3.0273981,447.62518,-9.2315655
5400,5400,195.9693,10.06182,6.9292769,0.0,0,3.0106311,0.0,0.62009954,68.870071,3.0070662,448.15341,-9.232152
5411,5411,195.9715,10.060909,6.9466519,0.0,0,2.992059,0.0,0.6214453,68.781944,2.9873378,448.68805,-9.231019
5422,5422,195.9737,10.063742,6.9620814,0.0,0,2.9734864,0.0,0.62418252,68.68084,2.9683681,449.22269,-9.2321663
5433,5433,195.9759,10.074173,6.9788342,0.0,0,2.9549141,0.0,0.6254437,68.668709,2.9526832,449.75732,-9.231492
5444,5444,195.9781,10.095265,6.9957266,0.0,0,2.9363415,0.0,0.62874746,68.585869,2.9347034,450.29199,-9.2311029
5455,5455,195.9803,10.109219,7.0179305,0.0,0,2.9177692,0.0,0.63018107,68.546974,2.9169643,450.76828,-9.2311954
5466,5466,195.9825,10.15223,7.0304875,0.0,0,2.8991966,0.0,0.63303721,68.595451,2.8990774,451.18414,-9.2324982
5477,5477,195.9847,10.213902,7.0534034,0.0,0,2.8806243,0.0,0.63466269,68.943275,2.8817158,451.59998,-9.2318039
5488,5488,195.9869,10.278516,7.0693398,0.0,0,2.8620522,0.0,0.63805997,69.129425,2.8614631,452.01581,-9.2316971
5499,5499,195.9891,10.345171,7.0974283,0.0,0,2.8434796,0.0,0.64005959,69.450195,2.8442607,452.43164,-9.2302408
5510,5510,195.9913,10.375888,7.1069212,0.0,0,2.8249073,0.0,0.64270616,69.522461,2.822943,452.70255,-9.2322969
5521,5521,195.9935,10.405508,7.1315265,0.0,0,2.8063347,0.0,0.64466548,69.539413,2.8070354,452.96658,-9.2327499
5532,5532,195.9957,10.414249,7.1466789,0.0,0,2.7877624,0.0,0.64775145,69.362511,2.7843373,453.23059,-9.2324162
5543,5543,195.9979,10.403302,7.1718445,0.0,0,2.7691898,0.0,0.6497075,69.150383,2.7696109,453.49463,-9.2314873
5554,5554,196.0001,10.406737,7.1810422,0.0,0,2.7506175,0.0,0.65185541,69.023773,2.7509906,453.75037,-9.2319489
5565,5565,196.0023,10.458597,7.2042894,0.0,0,2.7320454,0.0,0.65426165,69.198586,2.7368081,453.99457,-9.2325592
5576,5576,196.0045,10.516095,7.2192478,0.0,0,2.7135067,0.0,0.65672439,69.378807,2.7146053,454.2388,-9.2318907
5587,5587,196.0067,10.59972,7.246079,0.0,0,2.6958327,0.0,0.65924561,69.758698,2.6959858,454.48303,-9.2308493
5598,5598,196.0089,10.646957,7.2565222,0.0,0,2.6781666,0.0,0.6613977,69.968704,2.6772933,454.72723,-9.2309675
5609,5609,196.0111,10.662226,7.2803345,0.0,0,2.6605008,0.0,0.66409826,69.83535,2.6576209,454.65717,-9.2318344
5620,5620,196.0133,10.699088,7.2948027,0.0,0,2.6428347,0.0,0.66623127,69.960182,2.6393938,454.54495,-9.2314548
5631,5631,196.0155,10.698518,7.3213835,0.0,0,2.6251688,0.0,0.66952521,69.773239,2.620105,454.43274,-9.2315674
5642,5642,196.0177,10.744826,7.3350101,0.0,0,2.6075027,0.0,0.67116392,69.911194,2.5992279,454.32053,-9.2309275
5653,5653,196.0199,10.764472,7.3532009,0.0,0,2.5898366,0.0,0.67387909,69.89267,2.5801606,454.1741,-9.231164
5664,5664,196.0221,10.796259,7.37111,0.0,0,2.5721707,0.0,0.67591381,69.895889,2.5613954,453.96289,-9.2309847
5675,5675,196.0243,10.820539,7.3936996,0.0,0,2.5545046,0.0,0.6793828,69.767372,2.5447505,453.75168,-9.231884
5686,5686,196.0265,10.842437,7.4093041,0.0,0,2.5368385,0.0,0.68053681,69.926575,2.5304692,453.54047,-9.2305136
5697,5697,196.0287,10.842253,7.4219666,0.0,0,2.5191727,0.0,0.68321598,69.706192,2.5106099,453.32925,-9.2305355
5708,5708,196.0309,10.823049,7.4420896,0.0,0,2.5015066,0.0,0.68496466,69.494385,2.4937437,453.39041,-9.2315483
5719,5719,196.0331,10.814237,7.4580789,0.0,0,2.4838405,0.0,0.68818426,69.231331,2.4766583,453.51581,-9.2324572
5730,5730,196.0353,10.849241,7.4777598,0.0,0,2.4661746,0.0,0.68957299,69.363991,2.4596844,453.64124,-9.2318516
5741,5741,196.0375,10.880234,7.4894094,0.0,0,2.4485085,0.0,0.69239032,69.322296,2.4443281,453.76663,-9.2312107
5752,5752,196.0397,10.946056,7.5091038,0.0,0,2.4308424,0.0,0.69382179,69.618668,2.4275129,453.89386,-9.2313013
5763,5763,196.0419,11.007864,7.5232182,0.0,0,2.4131765,0.0,0.69699723,69.793259,2.4121816,454.02585,-9.2317247
5774,5774,196.0441,11.079026,7.5464449,0.0,0,2.3955107,0.0,0.69838136,70.131546,2.3936212,454.15787,-9.2297974
5785,5785,196.0463,11.124208,7.5557055,0.0,0,2.3778446,0.0,0.70121592,70.251785,2.3790712,454.28986,-9.2310486
5796,5796,196.0485,11.179938,7.5779037,0.0,0,2.3601787,0.0,0.70299137,70.446289,2.3612127,454.42188,-9.2310753
5807,5807,196.0507,11.222376,7.5897093,0.0,0,2.3425126,0.0,0.70589304,70.500137,2.3426418,452.54977,-9.231245
5818,5818,196.0529,11.272821,7.6201024,0.0,0,2.3248465,0.0,0.70843267,70.676445,2.3228657,449.96021,-9.2311831
5829,5829,196.0551,11.296707,7.6278577,0.0,0,2.3074403,0.0,0.71095759,70.592773,2.3025343,447.37067,-9.2308588
5840,5840,196.0573,11.319922,7.6516042,0.0,0,2.2906365,0.0,0.71313328,70.621841,2.2885618,444.78113,-9.2315874
5851,5851,196.0595,11.349715,7.6635652,0.0,0,2.273833,0.0,0.71554774,70.663818,2.2718151,442.36612,-9.2303181
5862,5862,196.0617,11.410532,7.6907306,0.0,0,2.2570293,0.0,0.71826845,70.893463,2.253953,440.64923,-9.2316046
5873,5873,196.0639,11.487013,7.6999226,0.0,0,2.2402258,0.0,0.7202512,71.157135,2.2346869,438.93237,-9.2310705
5884,5884,196.0661,11.535673,7.7223325,0.0,0,2.2234223,0.0,0.72306675,71.304207,2.2169523,437.21548,-9.2302094
5895,5895,196.0683,11.523608,7.7349424,0.0,0,2.2066188,0.0,0.7251128,71.058182,2.1997368,435.4986,-9.229847
5906,5906,196.0705,11.526329,7.7606936,0.0,0,2.189815,0.0,0.7283715,70.891365,2.1809716,435.95636,-9.231142
5917,5917,196.0727,11.559624,7.7728176,0.0,0,2.1730115,0.0,0.73004174,70.918274,2.1626682,437.5162,-9.2309847
5928,5928,196.0749,11.581624,7.7873216,0.0,0,2.1562078,0.0,0.73234552,70.911171,2.1443906,439.07608,-9.2314663
5939,5939,196.0771,11.588796,7.8020253,0.0,0,2.1394043,0.0,0.73397595,70.812378,2.1328812,440.63596,-9.2303782
5950,5950,196.0793,11.604555,7.8246646,0.0,0,2.1226006,0.0,0.7377854,70.654442,2.1120102,442.11835,-9.230484
5961,5961,196.0815,11.630381,7.8387704,0.0,0,2.1057971,0.0,0.73881555,70.732498,2.0985045,443.06955,-9.2308311
5972,5972,196.0837,11.669615,7.8525186,0.0,0,2.0889933,0.0,0.74168837,70.791847,2.084645,444.02078,-9.2310886
5983,5983,196.0859,11.715606,7.8681397,0.0,0,2.07219,0.0,0.74289125,70.983742,2.0688279,444.97198,-9.2308683
5994,5994,196.0881,11.764677,7.8835845,0.0,0,2.0553863,0.0,0.74629885,71.056183,2.0537884,445.92319,-9.2300053
6005,6005,196.0903,11.799993,7.9038854,0.0,0,2.0385828,0.0,0.74783856,71.118011,2.0338974,446.67114,-9.2310762
6016,6016,196.0925,11.811807,7.9140668,0.0,0,2.0217791,0.0,0.75061607,70.987556,2.0202706,447.27841,-9.2316818
6027,6027,196.0947,11.866206,7.9358301,0.0,0,2.0049756,0.0,0.75235158,71.195343,2.0038188,447.88565,-9.2302971
6038,6038,196.0969,11.91491,7.9474883,0.0,0,1.9881719,0.0,0.75550503,71.259506,1.9878334,448.49289,-9.2304525
6049,6049,196.0991,12.010668,7.9697032,0.0,0,1.9713683,0.0,0.75669241,71.732018,1.9713082,449.09296,-9.2319107
6060,6060,196.1013,12.111139,7.9788022,0.0,0,1.9545648,0.0,0.75978011,72.090141,1.9548109,449.56821,-9.2315283
6071,6071,196.1035,12.195223,8.0030746,0.0,0,1.9377612,0.0,0.76193279,72.457161,1.9377875,450.04343,-9.2312584
6082,6082,196.1057,12.224548,8.0148659,0.0,0,1.9214272,0.0,0.76506972,72.469856,1.91677,450.51868,-9.2306538
6093,6093,196.1079,12.245373,8.0433073,0.0,0,1.905442,0.0,0.76729441,72.417114,1.8991841,450.99393,-9.2294226
6104,6104,196.1101,12.276927,8.0491858,0.0,0,1.8894567,0.0,0.7696358,72.400429,1.8824202,451.40076,-9.2290049
6115,6115,196.1123,12.319629,8.0705767,0.0,0,1.8734715,0.0,0.77179974,72.46315,1.8644745,451.74399,-9.2305613
6126,6126,196.1145,12.353742,8.0838814,0.0,0,1.8574864,0.0,0.77474666,72.442726,1.8463548,452.08722,-9.2302704
6137,6137,196.1167,12.367114,8.1118221,0.0,0,1.8415012,0.0,0.77763855,72.36705,1.8345793,452.43045,-9.2296734
6148,6148,196.1189,12.357714,8.1184177,0.0,0,1.825516,0.0,0.7795155,72.186478,1.819048,452.77368,-9.2294531
6159,6159,196.1211,12.403413,8.1372137,0.0,0,1.8095309,0.0,0.78169543,72.255318,1.8042091,452.98727,-9.229434
6170,6170,196.1233,12.429955,8.1481934,0.0,0,1.7935456,0.0,0.78364724,72.294083,1.7865283,453.19849,-9.2300396
6181,6181,196.1255,12.488972,8.1710558,0.0,0,1.7775605,0.0,0.78670663,72.453384,1.7719991,453.4097,-9.2308617
6192,6192,196.1277,12.513367,8.180728,0.0,0,1.7615752,0.0,0.78809297,72.446548,1.7536423,453.62091,-9.2305765
6203,6203,196.1299,12.569777,8.1966915,0.0,0,1.74559,0.0,0.79070747,72.557686,1.7362398,453.75568,-9.2303352
6214,6214,196.1321,12.617749,8.2098255,0.0,0,1.7296047,0.0,0.79238862,72.692032,1.718639,453.79529,-9.2297649
6225,6225,196.1343,12.677047,8.2324982,0.0,0,1.7136196,0.0,0.79626924,72.778336,1.7056463,453.8349,-9.231245
6236,6236,196.1365,12.722693,8.2473965,0.0,0,1.6976343,0.0,0.79746687,72.959167,1.6933167,453.87451,-9.2307739
6247,6247,196.1387,12.754955,8.261838,0.0,0,1.6816492,0.0,0.8006869,72.962189,1.6766224,453.91412,-9.2303705
6258,6258,196.1409,12.823422,8.2763824,0.0,0,1.665664,0.0,0.80176878,73.262131,1.6635638,453.99573,-9.2297106
6269,6269,196.1431,12.853622,8.2925835,0.0,0,1.6496787,0.0,0.80547941,73.146515,1.6453376,454.08151,-9.2308426
6280,6280,196.1453,12.89533,8.313098,0.0,0,1.6336935,0.0,0.8070516,73.262352,1.6313426,454.16733,-9.2311525
6291,6291,196.1475,12.95793,8.3256521,0.0,0,1.6177083,0.0,0.81053263,73.328018,1.6128566,454.25311,-9.2305412
6302,6302,196.1497,13.014688,8.3436298,0.0,0,1.6017232,0.0,0.81170261,73.554451,1.5980978,454.35861,-9.2304859
6313,6313,196.1519,13.097655,8.3544054,0.0,0,1.5857379,0.0,0.81503326,73.794289,1.5837164,454.49722,-9.2306633
6324,6324,196.1541,13.204003,8.3802166,0.0,0,1.5697528,0.0,0.81690186,74.283783,1.5647475,454.63583,-9.2298517
6335,6335,196.1563,13.22306,8.3877125,0.0,0,1.554427,0.0,0.81981665,74.147095,1.5481927,454.77444,-9.2298117
6346,6346,196.1585,13.257091,8.4078531,0.0,0,1.5392206,0.0,0.82136899,74.205833,1.5317519,454.91306,-9.2296028
6357,6357,196.1607,13.307333,8.4191828,0.0,0,1.5240141,0.0,0.82477951,74.248222,1.5161321,455.02957,-9.2286034
6368,6368,196.1629,13.347315,8.4477434,0.0,0,1.5088077,0.0,0.82727993,74.325478,1.4996117,455.14178,-9.2306452
6379,6379,196.1651,13.364757,8.4525938,0.0,0,1.4936013,0.0,0.82953066,74.244087,1.4787606,455.254,-9.2315845
6390,6390,196.1673,13.357422,8.4722223,0.0,0,1.4783949,0.0,0.8314411,74.010612,1.4696361,455.36621,-9.2313061
6401,6401,196.1695,13.359051,8.4819775,0.0,0,1.4631884,0.0,0.83397275,73.856606,1.4573367,455.46655,-9.2311211
6412,6412,196.1717,13.414111,8.5057497,0.0,0,1.4479821,0.0,0.83662891,74.016273,1.4406799,455.53915,-9.2312517
6423,6423,196.1739,13.507803,8.511158,0.0,0,1.4327757,0.0,0.83829629,74.362167,1.4234827,455.61179,-9.2305202
6434,6434,196.1761,13.579699,8.5301161,0.0,0,1.4175693,0.0,0.84067047,74.54734,1.4088131,455.68439,-9.2292585
6445,6445,196.1783,13.627317,8.5425711,0.0,0,1.4023628,0.0,0.8427583,74.687981,1.3951094,455.75702,-9.2295437
6456,6456,196.1805,13.645192,8.5661612,0.0,0,1.3871565,0.0,0.84632963,74.528854,1.3785689,455.81448,-9.2293854
6467,6467,196.1827,13.667635,8.5731716,0.0,0,1.3719501,0.0,0.84755224,74.539658,1.3640907,455.86728,-9.2291489
6478,6478,196.1849,13.686074,8.5882511,0.0,0,1.3567437,0.0,0.85003126,74.398788,1.347877,455.92007,-9.2299004
6489,6489,196.1871,13.740333,8.5993338,0.0,0,1.3415372,0.0,0.85141724,74.640182,1.333495,455.97287,-9.2296286
6500,6500,196.1893,13.847943,8.6195545,0.0,0,1.3263309,0.0,0.85528558,74.93895,1.3191999,455.52731,-9.2300539
6511,6511,196.1915,13.943604,8.6356764,0.0,0,1.3111246,0.0,0.85671473,75.38073,1.3047134,453.38757,-9.2302532
6522,6522,196.1937,14.041718,8.6479692,0.0,0,1.2959181,0.0,0.8598116,75.680824,1.2903478,451.24783,-9.2299795
6533,6533,196.1959,14.111438,8.6621799,0.0,0,1.2807117,0.0,0.86087567,75.975479,1.2731793,449.10809,-9.229537
6544,6544,196.1981,14.155982,8.6787663,0.0,0,1.2655053,0.0,0.86490375,75.890442,1.2540567,446.96835,-9.2289047
6555,6555,196.2003,14.181346,8.6995144,0.0,0,1.2502989,0.0,0.8665064,75.929619,1.2395176,445.16205,-9.2302618
6566,6566,196.2025,14.185863,8.7082005,0.0,0,1.2350925,0.0,0.86959571,75.695793,1.2255553,443.50494,-9.2305202
6577,6577,196.2047,14.195214,8.7239027,0.0,0,1.2199751,0.0,0.87054265,75.652878,1.2130395,441.84784,-9.2308149
6588,6588,196.2069,14.254254,8.7352715,0.0,0,1.205512,0.0,0.87415004,75.649513,1.1940891,440.1907,-9.2311001
6599,6599,196.2091,14.351952,8.7584887,0.0,0,1.1910492,0.0,0.87559313,76.119133,1.1809689,438.90417,-9.2303915
6610,6610,196.2113,14.459508,8.7641287,0.0,0,1.1765864,0.0,0.87858307,76.456558,1.165897,439.64459,-9.2313318
6621,6621,196.2135,14.548345,8.7824202,0.0,0,1.1621237,0.0,0.87992418,76.856079,1.1540275,440.38498,-9.2290239
6632,6632,196.2157,14.561879,8.7956104,0.0,0,1.1476609,0.0,0.88368505,76.625946,1.1336272,441.1254,-9.2287827
6643,6643,196.2179,14.569218,8.8191338,0.0,0,1.133198,0.0,0.88559693,76.480011,1.1225374,441.86581,-9.2291288
6654,6654,196.2201,14.590904,8.8230658,0.0,0,1.1187352,0.0,0.88799638,76.517426,1.107726,442.67511,-9.229517
6665,6665,196.2223,14.611667,8.8415041,0.0,0,1.1042725,0.0,0.88953269,76.410881,1.097353,443.52698,-9.229682
6676,6676,196.2245,14.653259,8.8538237,0.0,0,1.0898095,0.0,0.89277589,76.367661,1.0811756,444.37881,-9.2287807
6687,6687,196.2267,14.752501,8.8754721,0.0,0,1.0753468,0.0,0.895163,76.726761,1.0689195,445.23068,-9.2298403
6698,6698,196.2289,14.848094,8.8807516,0.0,0,1.0608839,0.0,0.89690465,77.125351,1.0505613,446.08466,-9.2300844
6709,6709,196.2311,14.915243,8.8997555,0.0,0,1.0464213,0.0,0.89946115,77.258202,1.0388098,446.96255,-9.229558
6720,6720,196.2333,14.958407,8.9097347,0.0,0,1.0319583,0.0,0.90150195,77.339561,1.0236913,447.84045,-9.2297039
6731,6731,196.2355,14.980823,8.931612,0.0,0,1.0174956,0.0,0.90473622,77.213661,1.0104345,448.71832,-9.229598
6742,6742,196.2377,15.055421,8.9391098,0.0,0,1.0030328,0.0,0.90602624,77.470993,0.99601787,449.59622,-9.2305441
6753,6753,196.2399,15.15715,8.9528503,0.0,0,0.98856997,0.0,0.90864182,77.797768,0.97978061,450.17526,-9.2303553
6764,6764,196.2421,15.243221,8.9675627,0.0,0,0.97410721,0.0,0.91063333,78.044907,0.96482396,450.50528,-9.228899
6775,6775,196.2443,15.310795,8.9875402,0.0,0,0.95964432,0.0,0.91459441,78.09491,0.94906074,450.83533,-9.2287588
6786,6786,196.2465,15.388642,8.9985781,0.0,0,0.94518155,0.0,0.91542065,78.417862,0.93528563,451.16534,-9.2287025
6797,6797,196.2487,15.437797,9.0120258,0.0,0,0.93071878,0.0,0.91887265,78.386391,0.91927934,451.49316,-9.2303038
6808,6808,196.2509,15.436926,9.0300293,0.0,0,0.91625601,0.0,0.92056006,78.281723,0.90758759,451.57895,-9.2295189
6819,6819,196.2531,15.47212,9.0411415,0.0,0,0.90179312,0.0,0.92375052,78.210274,0.89154589,451.66476,-9.2300463
6830,6830,196.2553,15.486639,9.0546389,0.0,0,0.88760805,0.0,0.92458653,78.235092,0.88107771,451.75058,-9.2302895
6841,6841,196.2575,15.546503,9.0650597,0.0,0,0.87385368,0.0,0.92805696,78.282593,0.86386639,451.8364,-9.2295456
6852,6852,196.2597,15.655192,9.0842209,0.0,0,0.86009926,0.0,0.92957777,78.62793,0.85328978,451.68817,-9.2294178
6863,6863,196.2619,15.755679,9.0925598,0.0,0,0.84634483,0.0,0.93264264,78.890724,0.83653539,451.27893,-9.2298975
6874,6874,196.2641,15.860496,9.1135607,0.0,0,0.83259046,0.0,0.93409431,79.356506,0.82379353,450.86969,-9.230051
6885,6885,196.2663,15.926286,9.1212072,0.0,0,0.81883603,0.0,0.93772572,79.389488,0.80526108,450.46048,-9.2298288
6896,6896,196.2685,15.969316,9.1412306,0.0,0,0.80508167,0.0,0.93933135,79.507584,0.79089034,450.05124,-9.2288513
6907,6907,196.2707,15.950171,9.1461449,0.0,0,0.79132724,0.0,0.94205374,79.200455,0.77951795,449.82742,-9.2294788
6918,6918,196.2729,15.900513,9.1665478,0.0,0,0.77757287,0.0,0.9433921,78.827553,0.76852208,449.61621,-9.2299728
6929,6929,196.2751,15.937617,9.1701202,0.0,0,0.76381844,0.0,0.94581872,78.818016,0.75218213,449.405,-9.2293119
6940,6940,196.2773,16.000553,9.1892891,0.0,0,0.75006407,0.0,0.94779396,78.934692,0.74248254,449.19379,-9.2301769
6951,6951,196.2795,16.090923,9.195796,0.0,0,0.73630965,0.0,0.95004994,79.231079,0.72974646,449.23074,-9.2288389
6962,6962,196.2817,16.211649,9.2176952,0.0,0,0.72255528,0.0,0.95260769,79.580742,0.71737236,449.63998,-9.2300615
6973,6973,196.2839,16.328304,9.2221155,0.0,0,0.70880085,0.0,0.95452487,79.989861,0.70463371,450.04919,-9.2286978
6984,6984,196.2861,16.498646,9.2410517,0.0,0,0.69504642,0.0,0.95700967,80.634514,0.68652827,450.45844,-9.2283001
6995,6995,196.2883,16.650038,9.2514706,0.0,0,0.68129206,0.0,0.9593119,81.19516,0.67369056,450.86768,-9.2293291
7006,7006,196.2905,16.72965,9.2752571,0.0,0,0.66753769,0.0,0.96289557,81.336304,0.65470374,451.2085,-9.2284098
7017,7017,196.2927,16.728546,9.2829571,0.0,0,0.65378326,0.0,0.96452159,81.209778,0.64174747,451.53851,-9.2293301
7028,7028,196.2949,16.720732,9.3008003,0.0,0,0.64002883,0.0,0.96785516,80.90744,0.62870121,451.86856,-9.2299175
7039,7039,196.2971,16.728567,9.3101139,0.0,0,0.62627447,0.0,0.96911895,80.815887,0.61493486,452.19858,-9.22964
7050,7050,196.2993,16.748783,9.3288002,0.0,0,0.61252004,0.0,0.97300947,80.584282,0.59946048,452.48325,-9.2291756
7061,7061,196.3015,16.78672,9.3385658,0.0,0,0.59876567,0.0,0.9737342,80.67131,0.5878368,452.67465,-9.2289343
7072,7072,196.3037,16.799749,9.3467102,0.0,0,0.5850113,0.0,0.97623819,80.568886,0.57837248,452.86609,-9.2282572
7083,7083,196.3059,16.852346,9.358573,0.0,0,0.57169855,0.0,0.97711539,80.736107,0.56546926,453.0575,-9.2292128
7094,7094,196.3081,16.931688,9.3698616,0.0,0,0.55860847,0.0,0.98084956,80.831657,0.55324376,453.24893,-9.2293711
7105,7105,196.3103,17.016708,9.3871136,0.0,0,0.54551852,0.0,0.98203796,81.184784,0.54383242,453.39334,-9.2288914
7111,7111,196.3115,17.114891,9.3959885,0.0,0,0.53837854,0.0,0.98320436,81.492386,0.53615606,453.46536,-9.2293682