File: clean data/testID_0256.csv
level_0,index,Time(sec),Force(kN),Jaw(mm),PowAngle(deg),Power(W),Pram,PTemp,Strain,Stress(MPa),Stroke(mm),TC1(C),wedge(mm)
2626,2626,212.0496,1.5343035,0.011530369,0.0,0,9.8288631,0.0,0.00093964423,19.30402,9.9201317,509.66324,-9.2082577
2637,2637,212.0518,2.4769278,0.025093665,0.0,0,9.7958632,0.0,0.0014894434,31.3151,9.8871202,509.61969,-9.206975
2648,2648,212.054,2.9146454,0.041648045,0.0,0,9.7628632,0.0,0.0028814485,36.913177,9.8576155,509.46878,-9.2064857
2659,2659,212.0562,3.0697453,0.077621132,0.0,0,9.7298632,0.0,0.0050570853,38.764057,9.8283386,509.31784,-9.2070036
2670,2670,212.0584,3.1152918,0.10921114,0.0,0,9.6968632,0.0,0.0074321665,39.408287,9.7918491,509.1669,-9.205409
2681,2681,212.0606,3.1883254,0.15186346,0.0,0,9.6638632,0.0,0.0099396026,40.226536,9.7508259,509.01596,-9.2052717
2692,2692,212.0628,3.1924098,0.18097986,0.0,0,9.6308632,0.0,0.01223513,40.169365,9.7146702,509.12991,-9.2052774
2703,2703,212.065,3.1886611,0.21731642,0.0,0,9.5978632,0.0,0.014508509,40.038284,9.6808376,509.4646,-9.205719
2714,2714,212.0672,3.1816669,0.24814497,0.0,0,9.5648632,0.0,0.016849624,39.856831,9.6433372,509.79929,-9.2048817
2725,2725,212.0694,3.1857777,0.28806484,0.0,0,9.5318632,0.0,0.019174371,39.728184,9.6109915,510.13394,-9.2072239
2736,2736,212.0716,3.1978226,0.31283745,0.0,0,9.4988632,0.0,0.02111475,39.847412,9.580739,510.46863,-9.2066832
2747,2747,212.0738,3.2090135,0.34626687,0.0,0,9.4662552,0.0,0.023233205,39.945301,9.547411,511.47925,-9.2053156
2758,2758,212.076,3.22208,0.37644097,0.0,0,9.4340639,0.0,0.025602719,40.067245,9.5135994,512.48987,-9.205965
2769,2769,212.0782,3.2256446,0.41406524,0.0,0,9.4018736,0.0,0.027752478,39.944,9.480072,513.50049,-9.207325
2780,2780,212.0804,3.2413237,0.44027078,0.0,0,9.3696833,0.0,0.029881723,40.095306,9.453455,514.51111,-9.2070084
2791,2791,212.0826,3.271162,0.47412503,0.0,0,9.3374929,0.0,0.031998515,40.329483,9.4192362,515.47699,-9.2069435
2802,2802,212.0848,3.2617745,0.50710303,0.0,0,9.3053026,0.0,0.034452997,40.120064,9.3810034,516.3891,-9.2054462
2813,2813,212.087,3.2641342,0.54507917,0.0,0,9.2731133,0.0,0.036821589,40.087009,9.3488197,517.30121,-9.2054911
2824,2824,212.0892,3.2693198,0.57307833,0.0,0,9.240922,0.0,0.03903852,39.948833,9.3158579,518.21332,-9.2064562
2835,2835,212.0914,3.2749813,0.60658926,0.0,0,9.2087317,0.0,0.041189075,40.028828,9.284297,519.12549,-9.2062626
2846,2846,212.0936,3.2788801,0.63612819,0.0,0,9.1765404,0.0,0.043457966,39.902542,9.2521896,519.19049,-9.2065229
2857,2857,212.0958,3.2877104,0.6732195,0.0,0,9.144351,0.0,0.045651644,40.033924,9.2155981,519.17078,-9.2059422
2868,2868,212.098,3.311532,0.69872952,0.0,0,9.1121607,0.0,0.047786504,40.118187,9.1869316,519.15112,-9.2062826
2879,2879,212.1002,3.3045554,0.73124397,0.0,0,9.0799694,0.0,0.049825262,40.067593,9.1544666,519.13141,-9.2053099
2890,2890,212.1024,3.3013196,0.76037747,0.0,0,9.0477791,0.0,0.052137464,39.980083,9.122838,518.99243,-9.206605
2901,2901,212.1046,3.3043625,0.79918408,0.0,0,9.0155888,0.0,0.054502018,39.856133,9.0914707,518.64465,-9.2073812
2912,2912,212.1068,3.3280048,0.8259902,0.0,0,8.9833984,0.0,0.056760844,40.039444,9.0544147,518.29688,-9.2068148
2923,2923,212.109,3.3625221,0.86068124,0.0,0,8.9512091,0.0,0.058914579,40.25256,9.021944,517.94916,-9.2065172
2934,2934,212.1112,3.3805287,0.89270878,0.0,0,8.9190178,0.0,0.06150097,40.427639,8.9833002,517.60138,-9.2067337
2945,2945,212.1134,3.3836629,0.93235689,0.0,0,8.8868265,0.0,0.063947231,40.32925,8.951046,517.62946,-9.2062035
2956,2956,212.1156,3.3653245,0.95842791,0.0,0,8.8546362,0.0,0.066128403,40.13842,8.9207783,517.74103,-9.2053547
2967,2967,212.1178,3.3712409,0.99135602,0.0,0,8.8224468,0.0,0.068204612,40.099586,8.8868227,517.8526,-9.2059078
2978,2978,212.12,3.3700571,1.0201751,0.0,0,8.7902565,0.0,0.070534348,39.971867,8.8530712,517.96417,-9.2064447
2989,2989,212.1222,3.3699155,1.0552467,0.0,0,8.7580652,0.0,0.072654001,39.931831,8.8237972,518.12579,-9.2067099
3000,3000,212.1244,3.3586361,1.0812979,0.0,0,8.7270651,0.0,0.07494279,39.780716,8.7929821,518.42108,-9.2065992
3011,3011,212.1266,3.3683472,1.1156316,0.0,0,8.6964502,0.0,0.077116303,39.813065,8.7586641,518.71637,-9.2065601
3022,3022,212.1288,3.4236407,1.1448718,0.0,0,8.6658354,0.0,0.079552673,40.250717,8.7285681,519.01166,-9.207016
3033,3033,212.131,3.4301698,1.1835301,0.0,0,8.6352196,0.0,0.081927381,40.317673,8.6945982,519.30695,-9.206728
3044,3044,212.1332,3.4546633,1.2101172,0.0,0,8.6046047,0.0,0.084183738,40.318924,8.662467,519.5163,-9.2063704
3055,3055,212.1354,3.4357343,1.243353,0.0,0,8.5739899,0.0,0.08639954,40.043919,8.6276875,519.69348,-9.2065916
3066,3066,212.1376,3.4239509,1.2709944,0.0,0,8.5433741,0.0,0.088700704,39.871765,8.5977631,519.87061,-9.2058468
3077,3077,212.1398,3.4240823,1.3065058,0.0,0,8.5127592,0.0,0.090894386,39.785095,8.5711098,520.04779,-9.2073984
3088,3088,212.142,3.4102731,1.3309896,0.0,0,8.4821434,0.0,0.092994228,39.497963,8.535533,520.19275,-9.2059584
3099,3099,212.1442,3.3970137,1.3625274,0.0,0,8.4515295,0.0,0.095085517,39.339924,8.5095434,520.19275,-9.2067442
3110,3110,212.1464,3.4173698,1.3885615,0.0,0,8.4209127,0.0,0.09727405,39.476433,8.4782753,520.19275,-9.2071915
3121,3121,212.1486,3.4528148,1.4231951,0.0,0,8.3902988,0.0,0.09941221,39.726402,8.4510889,520.19275,-9.2072678
3132,3132,212.1508,3.4970233,1.449537,0.0,0,8.359683,0.0,0.10174501,40.193951,8.4187565,520.19275,-9.2071629
3143,3143,212.153,3.5158424,1.4822505,0.0,0,8.3290682,0.0,0.10386634,40.38105,8.3853502,520.43066,-9.2052946
3154,3154,212.1552,3.5222607,1.511848,0.0,0,8.2984524,0.0,0.10640244,40.221134,8.3545055,520.80457,-9.2055349
3165,3165,212.1574,3.5063131,1.5490898,0.0,0,8.2678375,0.0,0.10872877,40.088692,8.3231764,521.17847,-9.2050829
3176,3176,212.1596,3.5086544,1.576511,0.0,0,8.2372227,0.0,0.11110327,40.084064,8.2904053,521.55237,-9.2055435
3187,3187,212.1618,3.5016847,1.6094102,0.0,0,8.2066088,0.0,0.11332498,39.754929,8.2586193,521.94354,-9.2061167
3198,3198,212.164,3.5028315,1.6375821,0.0,0,8.175992,0.0,0.11579847,39.688255,8.2276268,522.50769,-9.2062445
3209,3209,212.1662,3.5176592,1.6735175,0.0,0,8.1453772,0.0,0.1180394,39.803894,8.1998968,523.07178,-9.2052135
3220,3220,212.1684,3.5702288,1.6983969,0.0,0,8.1147623,0.0,0.1202115,40.234413,8.1642933,523.63593,-9.2052288
3231,3231,212.1706,3.5674977,1.7302262,0.0,0,8.0841465,0.0,0.12237704,40.103996,8.1336555,524.20001,-9.2067175
3242,3242,212.1728,3.5751963,1.7591209,0.0,0,8.053587,0.0,0.12500679,40.311825,8.1050644,524.69257,-9.2066936
3253,3253,212.175,3.5660975,1.7959118,0.0,0,8.0244465,0.0,0.12733817,40.026485,8.0707531,525.12549,-9.2043753
3264,3264,212.1772,3.558233,1.820187,0.0,0,7.9953175,0.0,0.12946154,39.768974,8.0416069,525.55835,-9.2035751
3275,3275,212.1794,3.538708,1.8508514,0.0,0,7.9661894,0.0,0.13146022,39.530499,8.0132484,525.99127,-9.2054043
3286,3286,212.1816,3.5488346,1.876678,0.0,0,7.9370618,0.0,0.13382713,39.495781,7.9824948,526.42419,-9.2058039
3297,3297,212.1838,3.5520339,1.913056,0.0,0,7.9079332,0.0,0.13614419,39.43903,7.9568973,526.98901,-9.2055216
3308,3308,212.186,3.5927379,1.9357394,0.0,0,7.8788056,0.0,0.13832921,39.796379,7.9235497,527.55389,-9.2056646
3319,3319,212.1882,3.6042848,1.9674726,0.0,0,7.8496776,0.0,0.1404852,39.843609,7.8906708,528.11871,-9.2060375
3330,3330,212.1904,3.6001117,1.993816,0.0,0,7.8205495,0.0,0.14279199,39.701225,7.865798,528.68353,-9.2051401
3341,3341,212.1926,3.5953324,2.0281823,0.0,0,7.7914219,0.0,0.14494291,39.527397,7.8366747,529.25012,-9.2045021
3352,3352,212.1948,3.5924239,2.0496876,0.0,0,7.7622933,0.0,0.14705156,39.517799,7.8069677,529.83386,-9.2067204
3363,3363,212.197,3.6016405,2.0815508,0.0,0,7.7331653,0.0,0.14918703,39.513153,7.7765398,530.41766,-9.2064323
3374,3374,212.1992,3.6117191,2.1059494,0.0,0,7.7040377,0.0,0.1514139,39.545887,7.7521548,531.00146,-9.2066088
3385,3385,212.2014,3.6293786,2.139358,0.0,0,7.6749096,0.0,0.15359169,39.629589,7.7181759,531.58527,-9.2063265
3396,3396,212.2036,3.6466177,2.1651235,0.0,0,7.6457815,0.0,0.15598121,39.669693,7.6868939,531.47137,-9.2049189
3407,3407,212.2058,3.6571712,2.1978211,0.0,0,7.6166534,0.0,0.15824795,39.743969,7.6602659,530.77606,-9.2049913
3418,3418,212.208,3.6731319,2.2222929,0.0,0,7.5875254,0.0,0.16056295,39.833908,7.6280227,530.08081,-9.2038937
3429,3429,212.2102,3.675808,2.2587321,0.0,0,7.5583973,0.0,0.16288127,39.828289,7.6025667,529.3855,-9.2055235
3440,3440,212.2124,3.6887488,2.2801957,0.0,0,7.5292697,0.0,0.16501021,39.839504,7.5720339,528.69019,-9.2054472
3451,3451,212.2146,3.6813686,2.3107169,0.0,0,7.5001411,0.0,0.16711968,39.681656,7.5467653,527.93585,-9.2071981
3462,3462,212.2168,3.6975451,2.335721,0.0,0,7.4710135,0.0,0.16951403,39.71542,7.5157704,527.18158,-9.2066746
3473,3473,212.219,3.7106576,2.3748443,0.0,0,7.4418855,0.0,0.1720423,39.845249,7.480226,526.42725,-9.2067642
3484,3484,212.2212,3.72771,2.3985693,0.0,0,7.4127569,0.0,0.17440166,39.717159,7.45224,525.67291,-9.2066021
3495,3495,212.2234,3.7200971,2.4305127,0.0,0,7.3840585,0.0,0.17655101,39.691387,7.4234252,525.39563,-9.2051649
3506,3506,212.2256,3.7444143,2.4558938,0.0,0,7.3563566,0.0,0.17895404,39.886414,7.3941956,525.6908,-9.2049646
3517,3517,212.2278,3.7454813,2.4911528,0.0,0,7.3286538,0.0,0.18134084,39.718472,7.3635535,525.98596,-9.2047348
3528,3528,212.23,3.7405384,2.511363,0.0,0,7.3009515,0.0,0.18344462,39.661976,7.331357,526.28113,-9.2053318
3539,3539,212.2322,3.7167685,2.543416,0.0,0,7.2732491,0.0,0.18565051,39.323971,7.3071356,526.57629,-9.2048922
3550,3550,212.2344,3.7072031,2.5675464,0.0,0,7.2455468,0.0,0.18798292,39.156277,7.2795911,525.69067,-9.2049379
3561,3561,212.2366,3.7163415,2.5997622,0.0,0,7.217844,0.0,0.18997647,39.150917,7.2541094,524.68689,-9.2049532
3572,3572,212.2388,3.7320514,2.6208134,0.0,0,7.1901417,0.0,0.19218211,39.198265,7.2288566,523.68317,-9.2058926
3583,3583,212.241,3.7726469,2.6520035,0.0,0,7.1624393,0.0,0.19433841,39.478134,7.2020741,522.67938,-9.2061195
3594,3594,212.2432,3.7886908,2.6745341,0.0,0,7.134737,0.0,0.19663368,39.641308,7.1693144,521.50861,-9.2056694
3605,3605,212.2454,3.7981009,2.7101715,0.0,0,7.1070347,0.0,0.198982,39.600296,7.1425724,520.04559,-9.2051678
3616,3616,212.2476,3.8211682,2.7316918,0.0,0,7.0793324,0.0,0.20125927,39.819572,7.1122222,518.58252,-9.2055225
3627,3627,212.2498,3.8089087,2.7633929,0.0,0,7.05163,0.0,0.20337042,39.563446,7.0887194,517.11951,-9.2061653
3638,3638,212.252,3.8041651,2.7851808,0.0,0,7.0239277,0.0,0.20565465,39.400711,7.0589504,515.65643,-9.2062788
3649,3649,212.2542,3.8182728,2.8216369,0.0,0,6.9962254,0.0,0.20806034,39.515709,7.0315647,514.83203,-9.2050943
3660,3660,212.2564,3.8054924,2.8438094,0.0,0,6.9685221,0.0,0.21035935,39.229256,7.0019255,514.14954,-9.204071
3671,3671,212.2586,3.8414667,2.8740706,0.0,0,6.9408202,0.0,0.21248682,39.545361,6.9783597,513.46704,-9.2043581
3682,3682,212.2608,3.8345904,2.8968396,0.0,0,6.9131179,0.0,0.21481463,39.388859,6.9466386,512.78455,-9.2049303
3693,3693,212.263,3.8660979,2.9332831,0.0,0,6.8854156,0.0,0.21728224,39.626183,6.9217448,512.20764,-9.2065153
3704,3704,212.2652,3.8709557,2.9542592,0.0,0,6.8577132,0.0,0.21946254,39.545322,6.8879499,511.91235,-9.2069578
3715,3715,212.2674,3.9020798,2.9838769,0.0,0,6.8300109,0.0,0.22156832,39.783943,6.8606572,511.61707,-9.2055035
3726,3726,212.2696,3.890631,3.0087476,0.0,0,6.8023081,0.0,0.22414085,39.602104,6.8312488,511.32178,-9.2052937
3737,3737,212.2718,3.8843849,3.0440059,0.0,0,6.7746053,0.0,0.22651923,39.565712,6.8068986,511.02646,-9.205224
3748,3748,212.274,3.8787725,3.0660472,0.0,0,6.7476759,0.0,0.22887632,39.357857,6.7766938,510.99365,-9.2053795
3759,3759,212.2762,3.8995044,3.0961657,0.0,0,6.7213197,0.0,0.23096038,39.49522,6.7492566,511.05927,-9.2052517
3770,3770,212.2784,3.8919089,3.1187351,0.0,0,6.6949639,0.0,0.2333187,39.185791,6.7191124,511.12488,-9.2061424
3781,3781,212.2806,3.9088099,3.1541686,0.0,0,6.6686077,0.0,0.2357071,39.28426,6.6954322,511.19052,-9.2052746
3792,3792,212.2828,3.893966,3.1734943,0.0,0,6.642252,0.0,0.23788749,39.095272,6.6653504,511.36948,-9.2044277
3803,3803,212.285,3.9025037,3.2008371,0.0,0,6.6158962,0.0,0.23984846,39.063534,6.6418571,512.05853,-9.2063494
3814,3814,212.2872,3.9263933,3.224232,0.0,0,6.58954,0.0,0.24230002,39.199196,6.6164708,512.74762,-9.2062731
3825,3825,212.2894,3.919903,3.2583606,0.0,0,6.5631843,0.0,0.2445306,39.143459,6.589211,513.43665,-9.2053041
3836,3836,212.2916,3.9393797,3.2792273,0.0,0,6.536828,0.0,0.24685477,39.195709,6.5581064,514.12573,-9.20613
3847,3847,212.2938,3.9152238,3.306165,0.0,0,6.5104718,0.0,0.24877068,38.840687,6.5334625,514.98181,-9.2069845
3858,3858,212.296,3.9159467,3.3280251,0.0,0,6.4841161,0.0,0.25106809,38.837936,6.5101099,515.93335,-9.2059708
3869,3869,212.2982,3.9428515,3.3623571,0.0,0,6.4577599,0.0,0.25335908,38.919041,6.4835148,516.88495,-9.2055664
3880,3880,212.3004,3.9579129,3.3801985,0.0,0,6.4314041,0.0,0.25558767,39.087303,6.459403,517.83649,-9.2045937
3891,3891,212.3026,3.9854274,3.4080441,0.0,0,6.4050479,0.0,0.25749055,39.203323,6.4293652,518.77014,-9.2050581
3902,3902,212.3048,3.9965782,3.430136,0.0,0,6.3786922,0.0,0.25991637,39.231236,6.4057879,519.52454,-9.2058601
3913,3913,212.307,4.0085101,3.4655223,0.0,0,6.3523359,0.0,0.2623519,39.30788,6.3814106,520.27899,-9.2053995
3924,3924,212.3092,3.9838684,3.4843979,0.0,0,6.3259802,0.0,0.26455814,39.031384,6.3495665,521.03345,-9.2062855
3935,3935,212.3114,3.9997482,3.5133967,0.0,0,6.2996244,0.0,0.26662862,38.972004,6.320682,521.78784,-9.205802
3946,3946,212.3136,3.9926138,3.5349684,0.0,0,6.2732687,0.0,0.2690669,38.853344,6.2983384,522.61023,-9.2063379
3957,3957,212.3158,4.0332761,3.5704379,0.0,0,6.2469125,0.0,0.27146038,39.146267,6.2737851,523.4892,-9.2052422
3968,3968,212.318,4.0484891,3.5908735,0.0,0,6.2205563,0.0,0.27383739,39.25988,6.2462344,524.36816,-9.2051334
3979,3979,212.3202,4.0765963,3.6204209,0.0,0,6.1942005,0.0,0.27598515,39.385559,6.2155857,525.24713,-9.205164
3990,3990,212.3224,4.0614767,3.6423361,0.0,0,6.1678443,0.0,0.27845016,39.235577,6.1909599,526.1261,-9.2051105
4001,4001,212.3246,4.0828509,3.6768773,0.0,0,6.14258,0.0,0.28083852,39.221458,6.1616349,526.8476,-9.2053471
4012,4012,212.3268,4.0790911,3.6970491,0.0,0,6.1175132,0.0,0.28314412,39.177956,6.1330109,527.56915,-9.2067108
4023,4023,212.329,4.0405288,3.7252181,0.0,0,6.0924463,0.0,0.28525874,38.692001,6.1107202,528.29065,-9.2057209
4034,4034,212.3312,4.0103202,3.7457497,0.0,0,6.0673795,0.0,0.28756785,38.346626,6.088851,529.01221,-9.2048817
4045,4045,212.3334,4.039897,3.7801323,0.0,0,6.0423131,0.0,0.28993282,38.426662,6.0621452,529.68604,-9.2041206
4056,4056,212.3356,4.0664349,3.7964001,0.0,0,6.0172458,0.0,0.29201457,38.660255,6.0349612,530.30261,-9.2056427
4067,4067,212.3378,4.0786328,3.8247447,0.0,0,5.9921789,0.0,0.2941353,38.725742,6.0133348,530.91919,-9.2056112
4078,4078,212.34,4.0897698,3.8443904,0.0,0,5.9671125,0.0,0.29635966,38.772648,5.991087,531.53577,-9.2061472
4089,4089,212.3422,4.1066465,3.8786356,0.0,0,5.9420452,0.0,0.29880893,38.828705,5.9615393,532.1524,-9.2055273
4100,4100,212.3444,4.1078224,3.8946526,0.0,0,5.9169788,0.0,0.30081293,38.687511,5.9378862,532.56622,-9.2043657
4111,4111,212.3466,4.1073289,3.9210489,0.0,0,5.891912,0.0,0.30274567,38.610188,5.9141111,532.95978,-9.205761
4122,4122,212.3488,4.1070065,3.9421616,0.0,0,5.8668451,0.0,0.30522275,38.499355,5.8870296,533.35333,-9.2049541
4133,4133,212.351,4.1235552,3.9764874,0.0,0,5.8417783,0.0,0.30759838,38.565704,5.8637304,533.74695,-9.207303
4144,4144,212.3532,4.1433706,3.9945853,0.0,0,5.8167109,0.0,0.3098574,38.705982,5.8410482,534.12622,-9.2059422
4155,4155,212.3554,4.1606507,4.0220561,0.0,0,5.7916446,0.0,0.31196204,38.707329,5.8175254,534.48047,-9.2062864
4166,4166,212.3576,4.1820803,4.0442557,0.0,0,5.7665777,0.0,0.31446829,38.913307,5.7867165,534.83472,-9.2055721
4177,4177,212.3598,4.2027225,4.0785952,0.0,0,5.7415109,0.0,0.3168802,38.926151,5.7604761,535.18896,-9.2055016
4188,4188,212.362,4.2148638,4.0962415,0.0,0,5.716444,0.0,0.31914854,39.044716,5.7351575,535.54327,-9.2057533
4199,4199,212.3642,4.2251935,4.1232338,0.0,0,5.6913776,0.0,0.32112572,39.058323,5.711092,535.91901,-9.2061739
4210,4210,212.3664,4.2217841,4.1479449,0.0,0,5.6663103,0.0,0.32397532,38.83744,5.682641,536.29956,-9.2055712
4221,4221,212.3686,4.2055254,4.1815639,0.0,0,5.6412435,0.0,0.32638171,38.643448,5.6508708,536.68011,-9.2051353
4232,4232,212.3708,4.1964879,4.2005038,0.0,0,5.6161766,0.0,0.32886773,38.486771,5.6310358,537.06067,-9.2042217
4243,4243,212.373,4.2030878,4.226882,0.0,0,5.5912561,0.0,0.33074623,38.487141,5.6083465,537.42151,-9.2063131
4254,4254,212.3752,4.2423949,4.2468619,0.0,0,5.5674076,0.0,0.33309522,38.665432,5.5809755,537.72986,-9.2053909
4265,4265,212.3774,4.2190785,4.2778826,0.0,0,5.5435596,0.0,0.3353323,38.424171,5.5559406,538.03827,-9.2051334
4276,4276,212.3796,4.2448516,4.2959342,0.0,0,5.519712,0.0,0.33770034,38.570957,5.5331244,538.34668,-9.2043276
4287,4287,212.3818,4.2375035,4.3234086,0.0,0,5.4958634,0.0,0.33968315,38.439861,5.5094228,538.65503,-9.2042789
4298,4298,212.384,4.2287621,4.3429503,0.0,0,5.4720159,0.0,0.3422654,38.215279,5.4834146,538.87274,-9.2060108
4309,4309,212.3862,4.2088003,4.3735948,0.0,0,5.4481678,0.0,0.34429097,38.045258,5.4610987,539.05646,-9.2065783
4320,4320,212.3884,4.2229319,4.3884478,0.0,0,5.4243197,0.0,0.34638986,38.003799,5.440217,539.24017,-9.2048426
4331,4331,212.3906,4.2366381,4.4166589,0.0,0,5.4004722,0.0,0.34854493,38.067432,5.4158807,539.42389,-9.2042961
4342,4342,212.3928,4.2811971,4.4349284,0.0,0,5.3766236,0.0,0.35084715,38.374279,5.3915515,539.59448,-9.2052517
4353,4353,212.395,4.287488,4.4652791,0.0,0,5.3527756,0.0,0.35295832,38.304375,5.3684177,539.70605,-9.2058764
4364,4364,212.3972,4.3118472,4.4824686,0.0,0,5.328928,0.0,0.35527748,38.461456,5.348217,539.81763,-9.2066288
4375,4375,212.3994,4.3272662,4.5097075,0.0,0,5.3050799,0.0,0.35732886,38.533798,5.3211536,539.9292,-9.2063942
4386,4386,212.4016,4.3327332,4.5296001,0.0,0,5.2812319,0.0,0.35979086,38.455177,5.2940841,540.04071,-9.2053385
4397,4397,212.4038,4.3042192,4.5636969,0.0,0,5.2573838,0.0,0.36227852,38.20652,5.2706494,539.53857,-9.2041712
4408,4408,212.406,4.3195896,4.5809126,0.0,0,5.2335358,0.0,0.3646189,38.239437,5.2479701,538.68567,-9.2055798
4419,4419,212.4082,4.3279772,4.6060066,0.0,0,5.2096877,0.0,0.36655074,38.216957,5.2237873,537.83276,-9.2062798
4430,4430,212.4104,4.3637838,4.6250186,0.0,0,5.1858397,0.0,0.36900285,38.384109,5.2011151,536.97986,-9.2062664
4441,4441,212.4126,4.3708973,4.6570883,0.0,0,5.1619916,0.0,0.37137923,38.39156,5.1754894,536.11267,-9.2055798
4452,4452,212.4148,4.3838038,4.6716018,0.0,0,5.1381435,0.0,0.3734833,38.439789,5.1549921,535.10236,-9.2038794
4463,4463,212.417,4.3869104,4.7008548,0.0,0,5.1142955,0.0,0.37568015,38.309052,5.1275549,534.09204,-9.2054386
4474,4474,212.4192,4.4081578,4.7219901,0.0,0,5.0904479,0.0,0.37835512,38.395084,5.104949,533.08167,-9.2052994
4485,4485,212.4214,4.4160433,4.7542,0.0,0,5.0665994,0.0,0.38058987,38.445564,5.0800452,532.07135,-9.2061768
4496,4496,212.4236,4.4406352,4.771266,0.0,0,5.0432091,0.0,0.38312382,38.589943,5.0530767,531.63361,-9.2050858
4507,4507,212.4258,4.4383192,4.7992973,0.0,0,5.0205269,0.0,0.38532829,38.432098,5.032042,531.67297,-9.2048159
4518,4518,212.428,4.4675016,4.8201036,0.0,0,4.9978447,0.0,0.38801211,38.617561,5.0015244,531.71228,-9.2050867
4529,4529,212.4302,4.4717069,4.8543,0.0,0,4.975163,0.0,0.39044133,38.48151,4.9812264,531.75165,-9.2053099
4540,4540,212.4324,4.4804492,4.8692698,0.0,0,4.9524813,0.0,0.39278713,38.543655,4.9581227,531.79102,-9.2061605
4551,4551,212.4346,4.4554672,4.8953905,0.0,0,4.9297986,0.0,0.39475867,38.303463,4.9311013,532.02716,-9.2063694
4562,4562,212.4368,4.4225383,4.9139948,0.0,0,4.9071169,0.0,0.39719987,37.902351,4.9107256,532.26331,-9.2048759
4573,4573,212.439,4.4105215,4.9432974,0.0,0,4.8844347,0.0,0.39939833,37.650146,4.890501,532.49945,-9.2059593
4584,4584,212.4412,4.4142852,4.9592795,0.0,0,4.861753,0.0,0.40160337,37.644825,4.8677101,532.7356,-9.2057009
4595,4595,212.4434,4.3898983,4.9827523,0.0,0,4.8390708,0.0,0.40337926,37.332169,4.8500051,532.99554,-9.2061682
4606,4606,212.4456,4.4140396,4.9983621,0.0,0,4.8163886,0.0,0.4057174,37.438919,4.8264198,533.28418,-9.2053032
4617,4617,212.4478,4.4636798,5.0277705,0.0,0,4.7937069,0.0,0.40776256,37.761311,4.8065424,533.57281,-9.2057152
4628,4628,212.45,4.5273728,5.042028,0.0,0,4.7710247,0.0,0.40995219,38.164196,4.7840548,533.86139,-9.2055206
4639,4639,212.4522,4.5671964,5.0687294,0.0,0,4.748343,0.0,0.41205361,38.481949,4.7611842,534.15002,-9.2057457
4650,4650,212.4544,4.5724816,5.0877047,0.0,0,4.7256608,0.0,0.41471538,38.435577,4.7385135,534.51025,-9.2065973
4661,4661,212.4566,4.5695181,5.1227179,0.0,0,4.7029786,0.0,0.41728482,38.394062,4.712925,534.87762,-9.2064657
4672,4672,212.4588,4.5623007,5.1366544,0.0,0,4.6802969,0.0,0.41952917,38.241508,4.6874228,535.245,-9.2046442
4683,4683,212.461,4.5773902,5.1643872,0.0,0,4.6576152,0.0,0.42169803,38.237373,4.6629128,535.61243,-9.204381
4694,4694,212.4632,4.5345044,5.1832914,0.0,0,4.6349325,0.0,0.42445046,37.805668,4.6440005,535.98456,-9.2054968
4705,4705,212.4654,4.5366402,5.2122636,0.0,0,4.6122508,0.0,0.42638832,37.662376,4.6226025,536.36517,-9.204586
4716,4716,212.4676,4.5900903,5.2284894,0.0,0,4.5895686,0.0,0.42888024,38.03643,4.5961661,536.74573,-9.2056255
4727,4727,212.4698,4.620522,5.2528124,0.0,0,4.5668869,0.0,0.43072075,38.264252,4.5759149,537.12628,-9.2049227
4738,4738,212.472,4.6580429,5.2729607,0.0,0,4.5442047,0.0,0.4334904,38.457218,4.5525789,537.50684,-9.2051449
4749,4749,212.4742,4.6504645,5.3042936,0.0,0,4.5222569,0.0,0.43582827,38.318153,4.5281825,537.9411,-9.2060328
4760,4760,212.4764,4.6429796,5.3196325,0.0,0,4.500679,0.0,0.43828413,38.208748,4.5056357,538.38727,-9.2055655
4771,4771,212.4786,4.6151857,5.3463058,0.0,0,4.4791017,0.0,0.44035321,37.842949,4.4825611,538.83344,-9.2051001
4782,4782,212.4808,4.6111846,5.3648057,0.0,0,4.4575238,0.0,0.44302556,37.753532,4.4610596,539.27966,-9.2042265
4793,4793,212.483,4.6231337,5.3936701,0.0,0,4.4359465,0.0,0.44513413,37.778736,4.4365993,539.71149,-9.2049255
4804,4804,212.4852,4.6218381,5.4063616,0.0,0,4.4143691,0.0,0.44725397,37.610725,4.4167233,540.10516,-9.2065344
4815,4815,212.4874,4.644556,5.4304957,0.0,0,4.3927913,0.0,0.44915864,37.762524,4.3965383,540.49884,-9.2059669
4826,4826,212.4896,4.6353784,5.4474401,0.0,0,4.3712134,0.0,0.45162815,37.612686,4.3799996,540.89252,-9.2052774
4837,4837,212.4918,4.6672282,5.4757547,0.0,0,4.3496361,0.0,0.45366868,37.754868,4.3535132,541.28619,-9.2033901
4848,4848,212.494,4.6786256,5.4892182,0.0,0,4.3280582,0.0,0.45593694,37.698048,4.3326912,541.63214,-9.2042189
4859,4859,212.4962,4.7175665,5.5168729,0.0,0,4.3064809,0.0,0.45818302,38.006145,4.3118973,541.96027,-9.2044258
4870,4870,212.4984,4.6964874,5.5337815,0.0,0,4.284903,0.0,0.4606809,37.752434,4.2906742,542.28833,-9.2059069
4881,4881,212.5006,4.7189426,5.5636344,0.0,0,4.2633252,0.0,0.46295172,37.795254,4.2689576,542.61639,-9.2052393
4892,4892,212.5028,4.7336254,5.5755458,0.0,0,4.2417479,0.0,0.46512407,37.887615,4.2439713,542.92542,-9.2047148
4903,4903,212.505,4.7574453,5.6026096,0.0,0,4.2201705,0.0,0.46735585,37.969067,4.2228217,543.1485,-9.2051439
4914,4914,212.5072,4.7726288,5.6208687,0.0,0,4.1985927,0.0,0.47002971,37.981205,4.2013817,543.37158,-9.2042751
4925,4925,212.5094,4.7678585,5.6506195,0.0,0,4.1770153,0.0,0.47221902,37.899315,4.1813049,543.59467,-9.2061367
4936,4936,212.5116,4.7785921,5.6640396,0.0,0,4.1554375,0.0,0.47444397,37.848579,4.162055,543.81775,-9.2077236
4947,4947,212.5138,4.7727199,5.6865315,0.0,0,4.1338601,0.0,0.47623453,37.770164,4.1378937,543.94476,-9.2071114
4958,4958,212.516,4.7976217,5.7045507,0.0,0,4.1122823,0.0,0.47896844,37.807266,4.1182961,544.01697,-9.2057705
4969,4969,212.5182,4.8082232,5.7368574,0.0,0,4.0907049,0.0,0.48143676,37.803951,4.0951509,544.08911,-9.2057314
4980,4980,212.5204,4.8288374,5.7503004,0.0,0,4.0691271,0.0,0.48376569,37.86808,4.073153,544.16132,-9.2057505
4991,4991,212.5226,4.8586659,5.7750425,0.0,0,4.0475497,0.0,0.48579165,38.053913,4.0530605,544.22333,-9.2058592
5002,5002,212.5248,4.8817167,5.7899632,0.0,0,4.0269618,0.0,0.48824868,38.144844,4.0311418,544.18396,-9.205327
5013,5013,212.527,4.9155297,5.8240366,0.0,0,4.0064402,0.0,0.49089482,38.281055,4.0090208,544.14459,-9.2054129
5024,5024,212.5292,4.8896847,5.8389339,0.0,0,3.9859188,0.0,0.49344885,38.005268,3.9877548,544.10522,-9.2050505
5035,5035,212.5314,4.8601971,5.8639684,0.0,0,3.9653969,0.0,0.49548271,37.745247,3.9668789,544.06586,-9.2054491
5046,5046,212.5336,4.8398628,5.8795037,0.0,0,3.9448752,0.0,0.49797434,37.481529,3.9453676,544.0766,-9.2062502
5057,5057,212.5358,4.8813643,5.9076796,0.0,0,3.9243536,0.0,0.49997735,37.682381,3.9226029,544.12909,-9.2065468
5068,5068,212.538,4.8865786,5.9197803,0.0,0,3.9038324,0.0,0.50230318,37.602715,3.9037783,544.18164,-9.2050571
5079,5079,212.5402,4.89854,5.943954,0.0,0,3.8833106,0.0,0.50430387,37.67654,3.8848464,544.23413,-9.205142
5090,5090,212.5424,4.9145522,5.9597292,0.0,0,3.8627889,0.0,0.50689244,37.695625,3.8663299,544.28662,-9.2055416
5101,5101,212.5446,4.9484591,5.9889765,0.0,0,3.8422673,0.0,0.50906593,37.860752,3.8442173,544.41125,-9.2038517
5112,5112,212.5468,4.9819226,6.002912,0.0,0,3.8217459,0.0,0.5115602,37.992996,3.8266344,544.53595,-9.2033348
5123,5123,212.549,4.9906125,6.0276413,0.0,0,3.8012242,0.0,0.51352721,38.012447,3.7997122,544.66058,-9.2035866
5134,5134,212.5512,4.9712224,6.0439849,0.0,0,3.7807026,0.0,0.51627469,37.862785,3.7796717,544.78528,-9.203598
5145,5145,212.5534,4.9573488,6.0729389,0.0,0,3.760181,0.0,0.51833224,37.564487,3.76017,544.39697,-9.2045383
5156,5156,212.5556,4.9577351,6.0849581,0.0,0,3.7396593,0.0,0.52055782,37.544174,3.7414951,543.39307,-9.2066517
5167,5167,212.5578,4.985599,6.1069884,0.0,0,3.7191379,0.0,0.52249974,37.604053,3.7205412,542.3891,-9.205061
5178,5178,212.56,5.0247288,6.1236048,0.0,0,3.6986163,0.0,0.52510613,37.835091,3.6993685,541.38519,-9.204463
5189,5189,212.5622,5.0516396,6.1532164,0.0,0,3.6780944,0.0,0.52746791,37.921726,3.6774831,540.38129,-9.2038851
5200,5200,212.5644,5.0624933,6.1678944,0.0,0,3.657573,0.0,0.53008151,37.973537,3.6590359,539.42511,-9.2043638
5211,5211,212.5666,5.0756006,6.1933012,0.0,0,3.6370516,0.0,0.53216136,37.925159,3.6370921,538.47369,-9.2050638
5222,5222,212.5688,5.0797691,6.2072659,0.0,0,3.6165297,0.0,0.53464305,37.891613,3.6169779,537.52228,-9.2046194
5233,5233,212.571,5.1057587,6.2371392,0.0,0,3.5960083,0.0,0.53693289,38.014778,3.5922613,536.57092,-9.2049837
5244,5244,212.5732,5.1078119,6.2488379,0.0,0,3.5756967,0.0,0.53932697,37.898384,3.5755229,535.87482,-9.2042112
5255,5255,212.5754,5.1147199,6.2756457,0.0,0,3.556174,0.0,0.54157168,37.878891,3.5545695,535.62555,-9.2050924
5266,5266,212.5776,5.1598439,6.2924542,0.0,0,3.5366509,0.0,0.5444358,38.047115,3.5315113,535.37628,-9.2053328
5277,5277,212.5798,5.1741996,6.3228407,0.0,0,3.5171282,0.0,0.54672766,38.100891,3.5147667,535.12701,-9.2050848
5288,5288,212.582,5.182857,6.3333383,0.0,0,3.4976053,0.0,0.54893792,38.145351,3.4916632,534.87775,-9.2039585
5299,5299,212.5842,5.1750503,6.3572335,0.0,0,3.4780829,0.0,0.55104119,37.983196,3.4710042,534.7572,-9.2037716
5310,5310,212.5864,5.1610394,6.373363,0.0,0,3.4585598,0.0,0.55365252,37.779964,3.4537621,534.66534,-9.2054338
5321,5321,212.5886,5.1400061,6.4029918,0.0,0,3.4390368,0.0,0.55596858,37.594807,3.4375591,534.57349,-9.2048464
5332,5332,212.5908,5.1078796,6.4140606,0.0,0,3.4195144,0.0,0.55832165,37.191837,3.4177332,534.48163,-9.2046223
5343,5343,212.593,5.1294613,6.4343357,0.0,0,3.3999913,0.0,0.55989802,37.305527,3.398104,534.5293,-9.2048607
5354,5354,212.5952,5.175128,6.4470472,0.0,0,3.3804688,0.0,0.56237841,37.561291,3.3784363,534.94922,-9.2051611
5365,5365,212.5974,5.2012682,6.4751658,0.0,0,3.3609457,0.0,0.56445289,37.617496,3.3599243,535.36908,-9.205718
5376,5376,212.5996,5.2270293,6.4866276,0.0,0,3.3414228,0.0,0.56689191,37.758945,3.3421578,535.78894,-9.2046051
5387,5387,212.6018,5.2406859,6.5101671,0.0,0,3.3219004,0.0,0.5687269,37.782288,3.3215585,536.20886,-9.2054634
5398,5398,212.604,5.2709427,6.5256777,0.0,0,3.3023772,0.0,0.57159895,37.889442,3.3017266,536.60016,-9.2057447
5409,5409,212.6062,5.2757716,6.554637,0.0,0,3.2828543,0.0,0.57368666,37.846546,3.2823203,536.98071,-9.2047453
5420,5420,212.6084,5.2755346,6.5648975,0.0,0,3.2633319,0.0,0.57597381,37.759724,3.2597196,537.36127,-9.2046919
5431,5431,212.6106,5.2783675,6.5878572,0.0,0,3.243809,0.0,0.57793075,37.688049,3.2443662,537.74182,-9.2072926
5442,5442,212.6128,5.3069382,6.6022205,0.0,0,3.2242863,0.0,0.58062959,37.770264,3.2247066,538.09381,-9.2065601
5453,5453,212.615,5.3517938,6.6317244,0.0,0,3.2047634,0.0,0.58295864,38.060658,3.2063732,538.31689,-9.2045488
5464,5464,212.6172,5.3844919,6.6437502,0.0,0,3.1852405,0.0,0.58553439,38.152451,3.1823819,538.53998,-9.2046232
5475,5475,212.6194,5.4083056,6.668592,0.0,0,3.1657178,0.0,0.58752936,38.229816,3.1615331,538.76306,-9.2051487
5486,5486,212.6216,5.4057012,6.6830387,0.0,0,3.1461952,0.0,0.59033734,38.161911,3.1448479,538.98615,-9.2050238
5497,5497,212.6238,5.3840475,6.711359,0.0,0,3.1271312,0.0,0.59256184,37.908092,3.1274462,539.23425,-9.2056704
5508,5508,212.626,5.3884783,6.7225494,0.0,0,3.1085584,0.0,0.59495056,37.828209,3.1035171,539.49677,-9.2051039
5519,5519,212.6282,5.3757548,6.7440372,0.0,0,3.0899863,0.0,0.59660929,37.689934,3.0890644,539.75922,-9.2042437
5530,5530,212.6304,5.3711796,6.7574983,0.0,0,3.0714138,0.0,0.59930438,37.580788,3.0693018,540.02167,-9.2049856
5541,5541,212.6326,5.4010544,6.7851701,0.0,0,3.0528414,0.0,0.60146964,37.645596,3.0507779,540.29065,-9.2065725
5552,5552,212.6348,5.4509139,6.7969751,0.0,0,3.0342693,0.0,0.60401869,37.901405,3.0326211,540.62531,-9.2050486
5563,5563,212.637,5.471746,6.819778,0.0,0,3.0156965,0.0,0.60593742,37.985371,3.013659,540.95996,-9.2051334
5574,5574,212.6392,5.4855022,6.8324509,0.0,0,2.9971242,0.0,0.60846013,38.063759,2.9946668,541.29456,-9.2041121
5585,5585,212.6414,5.4755306,6.8582873,0.0,0,2.9785516,0.0,0.6104092,37.880997,2.9756615,541.62921,-9.2036304
5596,5596,212.6436,5.4765143,6.8695836,0.0,0,2.9599793,0.0,0.61282074,37.788391,2.9586287,541.74554,-9.2043848
5607,5607,212.6458,5.4782705,6.8908305,0.0,0,2.941407,0.0,0.61462271,37.693077,2.9408703,541.67987,-9.204627
5618,5618,212.648,5.5065589,6.905148,0.0,0,2.9228346,0.0,0.6174382,37.839077,2.9232075,541.61426,-9.2060537
5629,5629,212.6502,5.5403457,6.933785,0.0,0,2.9042623,0.0,0.61965173,37.985134,2.9013679,541.54865,-9.2048721
5640,5640,212.6524,5.6094413,6.9443135,0.0,0,2.88569,0.0,0.62215966,38.305374,2.8827877,541.48303,-9.2039499
5651,5651,212.6546,5.6293073,6.9658685,0.0,0,2.8671174,0.0,0.62383962,38.378757,2.8648202,541.20087,-9.2032423
5662,5662,212.6568,5.6444702,6.981216,0.0,0,2.8485448,0.0,0.62685341,38.363377,2.8471944,540.91876,-9.20362
5673,5673,212.659,5.6471868,7.0113335,0.0,0,2.8299725,0.0,0.62932092,38.290203,2.82846,540.6366,-9.2040396
5684,5684,212.6612,5.6588411,7.0235462,0.0,0,2.8114002,0.0,0.63198334,38.32938,2.8064282,540.35443,-9.2044077
5695,5695,212.6634,5.6502819,7.0443807,0.0,0,2.7928278,0.0,0.63373488,38.172626,2.7923036,540.16779,-9.205102
5706,5706,212.6656,5.6437531,7.0580549,0.0,0,2.7742555,0.0,0.63651031,38.039818,2.77406,540.09558,-9.2039042
5717,5717,212.6678,5.6621532,7.0866675,0.0,0,2.7556829,0.0,0.63874239,38.034393,2.7551692,540.02344,-9.20504
5728,5728,212.67,5.6971493,7.09553,0.0,0,2.7371109,0.0,0.64103764,38.139942,2.7386851,539.95123,-9.2049885
5739,5739,212.6722,5.7369232,7.1168633,0.0,0,2.7185383,0.0,0.64283013,38.419323,2.7176082,539.87909,-9.2041922
5750,5750,212.6744,5.7692299,7.1319098,0.0,0,2.7006512,0.0,0.64584249,38.513088,2.6978121,535.33276,-9.2051229
5761,5761,212.6766,5.7945004,7.1629248,0.0,0,2.6829851,0.0,0.64838403,38.583889,2.679605,530.33899,-9.2052364
5772,5772,212.6788,5.8022838,7.1712933,0.0,0,2.665319,0.0,0.65071845,38.535671,2.6595299,525.34521,-9.2046576
5783,5783,212.681,5.7983484,7.1926789,0.0,0,2.6476531,0.0,0.65252239,38.486183,2.6436031,520.3515,-9.2052927
5794,5794,212.6832,5.8105459,7.2067823,0.0,0,2.629987,0.0,0.65539932,38.401131,2.623862,515.48907,-9.2051506
5805,5805,212.6854,5.8056374,7.2359576,0.0,0,2.6123211,0.0,0.65793949,38.268433,2.6022749,510.85648,-9.2043009
5816,5816,212.6876,5.8020272,7.2457228,0.0,0,2.594655,0.0,0.66034043,38.147755,2.5873668,506.22385,-9.2054777
5827,5827,212.6898,5.7858415,7.2655144,0.0,0,2.5769889,0.0,0.66191941,38.014957,2.5704753,501.59125,-9.2044725
5838,5838,212.692,5.8036942,7.2787004,0.0,0,2.5593231,0.0,0.66455698,37.966274,2.5519283,496.95865,-9.2041578
5849,5849,212.6942,5.8585157,7.3037453,0.0,0,2.541657,0.0,0.66653234,38.259346,2.5343797,496.38495,-9.2034893
5860,5860,212.6964,5.8839808,7.3146043,0.0,0,2.5239909,0.0,0.66911691,38.388645,2.5174952,496.71323,-9.2042484
5871,5871,212.6986,5.9108467,7.3363361,0.0,0,2.506325,0.0,0.67109954,38.487,2.5005453,497.04153,-9.2051592
5882,5882,212.7008,5.9230299,7.3490543,0.0,0,2.4886589,0.0,0.67390811,38.420708,2.4795294,497.36981,-9.2065954
5893,5893,212.703,5.9578481,7.3763247,0.0,0,2.470993,0.0,0.67614245,38.61282,2.4642973,497.80377,-9.2055874
5904,5904,212.7052,5.962472,7.386951,0.0,0,2.4533269,0.0,0.67870778,38.557808,2.4459009,498.51944,-9.2052355
5915,5915,212.7074,5.9751925,7.4101887,0.0,0,2.4356608,0.0,0.68085265,38.538151,2.4251587,499.23514,-9.2059546
5926,5926,212.7096,5.9923553,7.4226613,0.0,0,2.417995,0.0,0.6834951,38.494522,2.406481,499.95084,-9.2045784
5937,5937,212.7118,6.0004892,7.4487343,0.0,0,2.4003291,0.0,0.6855045,38.481689,2.3892963,500.6665,-9.2042694
5948,5948,212.714,6.0186772,7.4554472,0.0,0,2.382663,0.0,0.68760955,38.52562,2.3741226,501.93106,-9.2034578
5959,5959,212.7162,6.0216289,7.4761834,0.0,0,2.3649969,0.0,0.68959516,38.465492,2.3576291,503.40146,-9.2037735
5970,5970,212.7184,5.9977555,7.490521,0.0,0,2.347331,0.0,0.69252956,38.2136,2.3404782,504.87186,-9.204093
5981,5981,212.7206,5.999897,7.5137076,0.0,0,2.3296649,0.0,0.69415605,38.144295,2.3254626,506.34225,-9.2042408
5992,5992,212.7228,6.0109243,7.5196128,0.0,0,2.312031,0.0,0.69633681,38.114788,2.3121493,507.81497,-9.2043314
6003,6003,212.725,6.0571151,7.5407286,0.0,0,2.2952197,0.0,0.69820684,38.371239,2.2953346,509.2981,-9.2043428
6014,6014,212.7272,6.12116,7.5544677,0.0,0,2.2784159,0.0,0.70127654,38.65134,2.2786477,510.78119,-9.2050591
6025,6025,212.7294,6.1975346,7.5838227,0.0,0,2.2616124,0.0,0.70357406,39.068939,2.2579005,512.26428,-9.2043753
6036,6036,212.7316,6.2544599,7.5911651,0.0,0,2.2448089,0.0,0.70591462,39.30685,2.2416768,513.74744,-9.2039108
6047,6047,212.7338,6.27214,7.615325,0.0,0,2.2280054,0.0,0.70815241,39.293941,2.2199399,514.98828,-9.2051353
6058,6058,212.736,6.2745538,7.6287303,0.0,0,2.2112017,0.0,0.71116608,39.253563,2.2025914,516.09076,-9.205637
6069,6069,212.7382,6.2495918,7.658144,0.0,0,2.1943982,0.0,0.71370876,39.001007,2.1852787,517.19318,-9.2045002
6080,6080,212.7404,6.2501822,7.6648769,0.0,0,2.1775944,0.0,0.71593773,38.884838,2.1649878,518.29565,-9.2034969
6091,6091,212.7426,6.238112,7.686965,0.0,0,2.1607909,0.0,0.71781385,38.767818,2.1477988,519.36761,-9.2038794
6102,6102,212.7448,6.2373347,7.6967974,0.0,0,2.1439872,0.0,0.72046167,38.629436,2.1333044,520.13519,-9.2054729
6113,6113,212.747,6.2503853,7.7233829,0.0,0,2.1271837,0.0,0.72250503,38.675659,2.1189954,520.90271,-9.2050686
6124,6124,212.7492,6.2823825,7.7315216,0.0,0,2.1103802,0.0,0.72499478,38.688217,2.1047215,521.67029,-9.2040777
6135,6135,212.7514,6.3059897,7.7525287,0.0,0,2.0935764,0.0,0.72688609,38.801498,2.0863514,522.43787,-9.2042484
6146,6146,212.7536,6.3322897,7.7634611,0.0,0,2.0767729,0.0,0.72968584,38.897346,2.0688093,523.20532,-9.2038507
6157,6157,212.7558,6.3508492,7.7892852,0.0,0,2.0599694,0.0,0.73156863,38.99477,2.0549459,523.97278,-9.2051172
6168,6168,212.758,6.3299284,7.7960739,0.0,0,2.0431657,0.0,0.73387998,38.673309,2.0371408,524.74023,-9.2066193
6179,6179,212.7602,6.3813744,7.8187876,0.0,0,2.0263622,0.0,0.73594761,38.891148,2.0177994,525.50769,-9.2052021
6190,6190,212.7624,6.4473205,7.8278823,0.0,0,2.0095587,0.0,0.73857367,39.203896,2.0043278,526.27515,-9.2036982
6201,6201,212.7646,6.5305076,7.8567162,0.0,0,1.9927549,0.0,0.74101061,39.61499,1.9861344,526.66217,-9.2035122
6212,6212,212.7668,6.5484324,7.8641357,0.0,0,1.9759514,0.0,0.74352807,39.61919,1.9685541,527.04913,-9.2048473
6223,6223,212.769,6.5581856,7.8879747,0.0,0,1.9591477,0.0,0.74574888,39.578838,1.9505067,527.43616,-9.2052002
6234,6234,212.7712,6.550477,7.9009418,0.0,0,1.9423442,0.0,0.74878812,39.459812,1.9376014,527.82312,-9.2053728
6245,6245,212.7734,6.5684943,7.9270196,0.0,0,1.9257871,0.0,0.75099301,39.479019,1.917237,528.20715,-9.2048674
6256,6256,212.7756,6.5466762,7.9334822,0.0,0,1.9098018,0.0,0.75335884,39.247395,1.902797,528.58765,-9.2035666
6267,6267,212.7778,6.5130711,7.9537663,0.0,0,1.8938167,0.0,0.75507772,38.996876,1.8845842,528.96808,-9.2035913
6278,6278,212.78,6.4951711,7.9625225,0.0,0,1.8778315,0.0,0.75763643,38.717815,1.8697375,529.34851,-9.2046661
6289,6289,212.7822,6.5345192,7.9881263,0.0,0,1.8618462,0.0,0.75959742,38.910439,1.8557664,529.72894,-9.2050829
6300,6300,212.7844,6.5605159,7.9963026,0.0,0,1.8458611,0.0,0.76223922,38.949799,1.8407006,530.34796,-9.2037001
6311,6311,212.7866,6.6248879,8.0167789,0.0,0,1.8298758,0.0,0.76407015,39.316242,1.8219732,530.99078,-9.205164
6322,6322,212.7888,6.7086334,8.0266609,0.0,0,1.8138907,0.0,0.76658738,39.666428,1.8097867,531.63361,-9.2049217
6333,6333,212.791,6.7266026,8.0535841,0.0,0,1.7979054,0.0,0.76898187,39.688435,1.7927834,532.27643,-9.2049789
6344,6344,212.7932,6.7379403,8.0610914,0.0,0,1.7819202,0.0,0.77146602,39.664593,1.7731544,532.91687,-9.2045298
6355,6355,212.7954,6.7307262,8.0817013,0.0,0,1.7659351,0.0,0.77326417,39.562172,1.756775,533.55322,-9.2055178
6366,6366,212.7976,6.7144198,8.0925779,0.0,0,1.7499498,0.0,0.77614754,39.311394,1.7439256,534.18951,-9.2046852
6377,6377,212.7998,6.7507815,8.1166706,0.0,0,1.7339647,0.0,0.77800953,39.469151,1.7245312,534.82587,-9.203618
6388,6388,212.802,6.7703433,8.123476,0.0,0,1.7179794,0.0,0.78061539,39.469315,1.7125007,535.46216,-9.2045555
6399,6399,212.8042,6.7980247,8.1448536,0.0,0,1.7019943,0.0,0.78248292,39.554039,1.695066,535.91071,-9.2052917
6410,6410,212.8064,6.8408537,8.1560135,0.0,0,1.6860089,0.0,0.78557605,39.748367,1.6819905,536.3175,-9.2041836
6421,6421,212.8086,6.9096565,8.1826267,0.0,0,1.6700239,0.0,0.78757131,40.006603,1.6660444,536.72424,-9.2043438
6432,6432,212.8108,6.9360991,8.1875038,0.0,0,1.6540385,0.0,0.78981936,40.104649,1.6480683,537.13104,-9.2042332
6443,6443,212.813,6.9480877,8.2089758,0.0,0,1.6380534,0.0,0.79191148,40.113098,1.6349881,536.71118,-9.2047606
6454,6454,212.8152,6.9591527,8.2226572,0.0,0,1.6220682,0.0,0.79530013,39.99651,1.6179401,534.08704,-9.2036858
6465,6465,212.8174,6.986928,8.2481976,0.0,0,1.6060829,0.0,0.7973032,40.057167,1.6005206,531.46289,-9.203681
6476,6476,212.8196,7.0358367,8.254488,0.0,0,1.5900977,0.0,0.79986995,40.256348,1.5829818,528.83868,-9.2035933
6487,6487,212.8218,7.1058187,8.2769079,0.0,0,1.5741127,0.0,0.80188435,40.538864,1.5653455,526.21454,-9.2044573
6498,6498,212.824,7.1502423,8.2873173,0.0,0,1.5585742,0.0,0.80493075,40.688721,1.5504985,523.46149,-9.2036428
6509,6509,212.8262,7.1559806,8.3153639,0.0,0,1.5433679,0.0,0.8072722,40.665485,1.5330582,520.66016,-9.2042093
6520,6520,212.8284,7.1623831,8.3246469,0.0,0,1.5281615,0.0,0.81035841,40.572227,1.5159907,517.85883,-9.205411
6531,6531,212.8306,7.1507807,8.3459997,0.0,0,1.5129551,0.0,0.81213486,40.403706,1.4977651,515.0575,-9.203352
6542,6542,212.8328,7.1125731,8.355093,0.0,0,1.4977487,0.0,0.81484973,40.095367,1.4811685,512.7774,-9.2037907
6553,6553,212.835,7.0580783,8.3775539,0.0,0,1.4825423,0.0,0.81660503,39.732803,1.4706359,512.84308,-9.2031155
6564,6564,212.8372,7.0591292,8.3818474,0.0,0,1.4673359,0.0,0.81888741,39.618984,1.4577754,512.90869,-9.205369
6575,6575,212.8394,7.0956292,8.402257,0.0,0,1.4521295,0.0,0.82076693,39.73922,1.4421704,512.9743,-9.204607
6586,6586,212.8416,7.1421523,8.4116488,0.0,0,1.4369231,0.0,0.82357484,39.834881,1.428079,513.03992,-9.2039194
6597,6597,212.8438,7.1805515,8.4357147,0.0,0,1.4217167,0.0,0.82560611,40.020329,1.41039,513.76526,-9.2038574
6608,6608,212.846,7.2261395,8.4405136,0.0,0,1.4065104,0.0,0.82779086,40.223759,1.3992724,514.86761,-9.2041502
6619,6619,212.8482,7.2723436,8.4599457,0.0,0,1.3913039,0.0,0.82948762,40.401909,1.3850456,515.96997,-9.2042732
6630,6630,212.8504,7.3089113,8.469449,0.0,0,1.3760974,0.0,0.83239895,40.501087,1.3689721,517.07233,-9.2043762
6641,6641,212.8526,7.3370976,8.4945335,0.0,0,1.3608911,0.0,0.83433217,40.59631,1.352057,518.2146,-9.2031145
6652,6652,212.8548,7.3731313,8.5025473,0.0,0,1.3456846,0.0,0.83720434,40.653019,1.3373278,519.75641,-9.2028351
6663,6663,212.857,7.3864899,8.5208197,0.0,0,1.3304783,0.0,0.83872801,40.624199,1.3228815,521.29816,-9.2035389
6674,6674,212.8592,7.419147,8.5321093,0.0,0,1.315272,0.0,0.84201407,40.655056,1.3067524,522.83997,-9.2038546
6685,6685,212.8614,7.4492435,8.5556879,0.0,0,1.3000655,0.0,0.84385461,40.744617,1.29216,524.38171,-9.2043486
6696,6696,212.8636,7.4750204,8.5616312,0.0,0,1.2848592,0.0,0.84641147,40.848553,1.2758222,525.57623,-9.2041473
6707,6707,212.8658,7.4907751,8.5824385,0.0,0,1.2696528,0.0,0.84845901,40.818874,1.2638853,526.48145,-9.2039165
6718,6718,212.868,7.4946799,8.5930405,0.0,0,1.2544463,0.0,0.85160619,40.724407,1.2470745,527.38666,-9.2037554
6729,6729,212.8702,7.5042415,8.6134567,0.0,0,1.2392399,0.0,0.85278612,40.777523,1.2353393,528.29181,-9.2050371
6740,6740,212.8724,7.5286565,8.6197262,0.0,0,1.2240335,0.0,0.85553259,40.780796,1.2222143,529.19702,-9.2053928
6751,6751,212.8746,7.591536,8.6400852,0.0,0,1.2094566,0.0,0.85738575,40.967812,1.202278,529.2298,-9.2048264
6762,6762,212.8768,7.6909413,8.6517124,0.0,0,1.1949937,0.0,0.86068225,41.349442,1.1890571,529.26263,-9.204545
6773,6773,212.879,7.7218318,8.6761875,0.0,0,1.180531,0.0,0.86271846,41.519226,1.1743484,529.29541,-9.2048836
6784,6784,212.8812,7.7493815,8.6810904,0.0,0,1.1660681,0.0,0.86521137,41.51313,1.1590765,529.32825,-9.2032661
6795,6795,212.8834,7.7584591,8.6994743,0.0,0,1.1516054,0.0,0.86672819,41.529552,1.1414875,529.22388,-9.2033482
6806,6806,212.8856,7.7381778,8.7115412,0.0,0,1.1371425,0.0,0.87030476,41.275105,1.1256268,528.95496,-9.204361
6817,6817,212.8878,7.7416592,8.7365351,0.0,0,1.1226798,0.0,0.87232608,41.259949,1.1103668,528.68597,-9.2042475
6828,6828,212.89,7.7265334,8.7437277,0.0,0,1.1082169,0.0,0.87522984,40.980297,1.1030372,528.41705,-9.2041845
6839,6839,212.8922,7.7361341,8.7590313,0.0,0,1.0937542,0.0,0.87614977,41.005852,1.0864767,528.14813,-9.2049103
6850,6850,212.8944,7.807857,8.7667484,0.0,0,1.0792915,0.0,0.8791821,41.209518,1.0701927,528.08191,-9.2050238
6861,6861,212.8966,7.8868432,8.7894659,0.0,0,1.0648285,0.0,0.88070458,41.62711,1.0603212,528.03601,-9.203661
6872,6872,212.8988,7.965517,8.7960644,0.0,0,1.0503657,0.0,0.88364887,41.892128,1.0455471,527.99011,-9.2042608
6883,6883,212.901,8.000886,8.8176727,0.0,0,1.035903,0.0,0.88569951,42.004311,1.0287246,527.94421,-9.2031116
6894,6894,212.9032,8.0303936,8.8291216,0.0,0,1.0214401,0.0,0.88909346,42.029713,1.0120413,527.9436,-9.2035494
6905,6905,212.9054,8.0342197,8.8527842,0.0,0,1.0069773,0.0,0.89098597,41.985359,0.99582231,528.02234,-9.2038698
6916,6916,212.9076,8.0631733,8.8574181,0.0,0,0.99251461,0.0,0.8935616,42.041203,0.98412979,528.10101,-9.2054081
6927,6927,212.9098,8.0511827,8.8774414,0.0,0,0.97805184,0.0,0.89542639,41.872612,0.96545178,528.17975,-9.2044764
6938,6938,212.912,8.0815601,8.8862915,0.0,0,0.96358895,0.0,0.89833802,41.909534,0.95015424,528.25848,-9.2034464
6949,6949,212.9142,8.0916786,8.9085369,0.0,0,0.94912618,0.0,0.89985222,41.883102,0.93944991,527.96149,-9.2036228
6960,6960,212.9164,8.1466427,8.913559,0.0,0,0.9346633,0.0,0.90273452,42.053543,0.92360348,527.58105,-9.2042856
6971,6971,212.9186,8.1987848,8.932415,0.0,0,0.92020065,0.0,0.90438861,42.238895,0.91224819,527.20062,-9.2042646
6982,6982,212.9208,8.2607431,8.9414682,0.0,0,0.90573776,0.0,0.90757632,42.408821,0.89546114,526.82013,-9.2044983
6993,6993,212.923,8.2584381,8.966012,0.0,0,0.89135975,0.0,0.9094944,42.337673,0.88145906,526.47729,-9.204443
7004,7004,212.9252,8.2317734,8.9716234,0.0,0,0.87760508,0.0,0.91221887,42.061108,0.86406022,526.23456,-9.2046566
7015,7015,212.9274,8.2299013,8.9881983,0.0,0,0.86385065,0.0,0.91355646,42.067902,0.8559925,525.99188,-9.2049332
7026,7026,212.9296,8.2470131,8.9975958,0.0,0,0.85009629,0.0,0.91691428,41.967567,0.84094101,525.74921,-9.2051764
7037,7037,212.9318,8.2907591,9.0214167,0.0,0,0.83634186,0.0,0.91863531,42.140896,0.82586998,525.50647,-9.2038183
7048,7048,212.934,8.3388119,9.0235701,0.0,0,0.82258749,0.0,0.92107689,42.231209,0.81289172,525.65979,-9.2030249
7059,7059,212.9362,8.4112206,9.0418015,0.0,0,0.80883306,0.0,0.9223814,42.539463,0.79844272,525.96149,-9.2040672
7070,7070,212.9384,8.4393263,9.0507126,0.0,0,0.79507869,0.0,0.92578685,42.577991,0.78539306,526.26324,-9.2037544
7081,7081,212.9406,8.4604702,9.0738411,0.0,0,0.78132427,0.0,0.92747599,42.644836,0.77076483,526.565,-9.2047806
7092,7092,212.9428,8.4663849,9.0772724,0.0,0,0.76756984,0.0,0.93016881,42.594971,0.75537288,526.50891,-9.2048035
7103,7103,212.945,8.4977732,9.0964756,0.0,0,0.75381547,0.0,0.93171239,42.612549,0.74370229,524.84235,-9.2030354
7114,7114,212.9472,8.5393085,9.1047497,0.0,0,0.7400611,0.0,0.93485278,42.715664,0.7321949,523.17584,-9.2036657
7125,7125,212.9494,8.5804729,9.1294804,0.0,0,0.72630668,0.0,0.93702143,42.799042,0.71752554,521.50934,-9.2049303
7136,7136,212.9516,8.6177626,9.1332321,0.0,0,0.71255225,0.0,0.9396978,42.844471,0.70487601,519.84283,-9.2049608
7147,7147,212.9538,8.6408148,9.1516628,0.0,0,0.69879782,0.0,0.94104749,42.886547,0.68901432,518.00092,-9.2033844
7158,7158,212.956,8.6727581,9.159646,0.0,0,0.68504345,0.0,0.94423532,42.983795,0.6752454,516.05878,-9.2041702
7169,7169,212.9582,8.7404785,9.1818829,0.0,0,0.67128909,0.0,0.94582015,43.22134,0.66587341,514.1167,-9.2043428
7180,7180,212.9604,8.7591896,9.1853695,0.0,0,0.65753466,0.0,0.94849926,43.210629,0.65028036,512.17456,-9.2052641
7191,7191,212.9626,8.7709522,9.2040768,0.0,0,0.64378029,0.0,0.95018578,43.197048,0.6354776,510.3714,-9.2039862
7202,7202,212.9648,8.8274565,9.2128906,0.0,0,0.63002586,0.0,0.95333791,43.344707,0.62105817,509.95798,-9.2046394
7213,7213,212.967,8.8918209,9.2347622,0.0,0,0.6162715,0.0,0.9551422,43.530174,0.60653663,509.54453,-9.2035999
7224,7224,212.9692,8.9264641,9.2393284,0.0,0,0.60251707,0.0,0.95796424,43.586227,0.59191525,509.1311,-9.2032528
7235,7235,212.9714,8.9692678,9.2598324,0.0,0,0.5887627,0.0,0.9598031,43.681511,0.57909358,508.71765,-9.203557
7246,7246,212.9736,8.9990358,9.2688828,0.0,0,0.57526875,0.0,0.96288031,43.756943,0.56435478,508.36865,-9.2042961