File: clean data/testID_0102.csv
level_0,index,Time(sec),Force(kN),Jaw(mm),PowAngle(deg),Power(W),Pram,PTemp,Strain,Stress(MPa),Stroke(mm),TC1(C),wedge(mm)
2438,2438,212.0119,0.67853731,0.035919294,0.0,0,9.0629702,0.0,0.0020613195,7.1067653,10.122408,499.72757,-9.2077799
2439,2439,212.0121,1.9261013,0.04612093,0.0,0,9.0337057,0.0,0.0028186408,20.571627,10.088667,499.72757,-9.2073612
2440,2440,212.0123,3.529479,0.07292445,0.0,0,9.0044422,0.0,0.0046408162,40.7659,10.062597,499.72757,-9.2071915
2441,2441,212.0125,4.5758238,0.10513018,0.0,0,8.9751778,0.0,0.0064575751,55.874916,10.042648,499.72757,-9.2068682
2442,2442,212.0127,4.9265552,0.12010527,0.0,0,8.9459143,0.0,0.0077486183,61.763618,10.018539,499.72757,-9.2058706
2443,2443,212.0129,4.9678183,0.14630707,0.0,0,8.9166498,0.0,0.0095701898,62.71796,9.9864655,499.72757,-9.2050266
2444,2444,212.0131,5.0119348,0.20092191,0.0,0,8.8873854,0.0,0.012515948,62.901878,9.9472523,499.72757,-9.2043638
2445,2445,212.0133,4.9782805,0.26464266,0.0,0,8.8581219,0.0,0.016752342,62.486656,9.905695,499.72757,-9.2036333
2446,2446,212.0135,4.7828159,0.32838261,0.0,0,8.8288574,0.0,0.021528969,60.032852,9.8661346,499.72757,-9.2035036
2447,2447,212.0137,4.7499466,0.37361234,0.0,0,8.7995939,0.0,0.024588997,58.726608,9.8233042,499.72757,-9.2040901
2448,2448,212.0139,5.0353312,0.39387473,0.0,0,8.7703295,0.0,0.026055522,61.587662,9.7739697,499.72757,-9.2048836
2449,2449,212.0141,5.2288709,0.43096694,0.0,0,8.7416534,0.0,0.028678335,64.360336,9.7257614,499.72757,-9.2056561
2450,2450,212.0143,5.241931,0.49217978,0.0,0,8.7136869,0.0,0.03244631,64.544563,9.6815186,499.72757,-9.2057266
2451,2451,212.0145,5.3532529,0.53851044,0.0,0,8.6858492,0.0,0.035749853,65.374893,9.642437,499.72757,-9.2051563
2452,2452,212.0147,5.5203567,0.55982518,0.0,0,8.6580172,0.0,0.037973836,67.428146,9.6054907,499.72757,-9.2045364
2453,2453,212.0149,5.4672894,0.56730062,0.0,0,8.6301851,0.0,0.038522266,67.317558,9.5676394,499.72757,-9.2037525
2454,2454,212.0151,5.1641583,0.57891095,0.0,0,8.6023531,0.0,0.038877841,64.036407,9.5323868,499.72757,-9.2034407
2455,2455,212.0153,4.9714026,0.61841613,0.0,0,8.5745211,0.0,0.04155986,60.919567,9.5006561,499.72757,-9.2039652
2456,2456,212.0155,5.1594734,0.67101485,0.0,0,8.546689,0.0,0.045196448,61.993301,9.4718246,499.72757,-9.2039928
2457,2457,212.0157,5.5190983,0.70121884,0.0,0,8.518857,0.0,0.047349997,66.119385,9.4404774,499.72757,-9.2034607
2458,2458,212.0159,5.7430544,0.71377033,0.0,0,8.491025,0.0,0.048671961,69.233208,9.4067249,499.72757,-9.2035875
2459,2459,212.0161,5.8015862,0.7344113,0.0,0,8.4631929,0.0,0.05005705,70.241837,9.3744106,499.72757,-9.2035856
2460,2460,212.0163,5.8012824,0.77782452,0.0,0,8.4353609,0.0,0.052375406,70.133087,9.3406248,499.72757,-9.2032804
2461,2461,212.0165,5.7643461,0.83965361,0.0,0,8.4075289,0.0,0.056714464,69.427307,9.3025913,499.72757,-9.2033148
2462,2462,212.0167,5.645803,0.89569443,0.0,0,8.3796968,0.0,0.061107688,67.878159,9.2620001,499.72757,-9.204154
2463,2463,212.0169,5.5170183,0.93333364,0.0,0,8.3518648,0.0,0.063651182,66.136978,9.2211676,499.72757,-9.204814
2464,2464,212.0171,5.4869647,0.961519,0.0,0,8.3240328,0.0,0.065749712,65.386574,9.1811638,499.72757,-9.2048569
2465,2465,212.0173,5.5618544,0.9938572,0.0,0,8.2962008,0.0,0.068291999,65.876297,9.1393766,499.72757,-9.2042007
2466,2466,212.0175,5.6723533,1.0366645,0.0,0,8.2683687,0.0,0.07090877,67.010017,9.0999174,499.71304,-9.2040501
2467,2467,212.0177,5.7319713,1.0742348,0.0,0,8.2405367,0.0,0.07363411,67.760475,9.0641966,499.6767,-9.2035666
2468,2468,212.0179,5.7479863,1.0954717,0.0,0,8.2127056,0.0,0.075788043,67.857086,9.0273666,499.64035,-9.2029686
2469,2469,212.0181,5.7667227,1.1178644,0.0,0,8.1848736,0.0,0.077108517,67.945755,8.9906912,499.60403,-9.2033091
2470,2470,212.0183,5.7545738,1.1473036,0.0,0,8.1570406,0.0,0.078886956,67.754761,8.9580603,499.56769,-9.2035036
2471,2471,212.0185,5.6862049,1.1788856,0.0,0,8.1292095,0.0,0.081556007,66.875504,8.9253788,499.53134,-9.2037745
2472,2472,212.0187,5.6581874,1.2164901,0.0,0,8.1013775,0.0,0.084090255,66.231216,8.8946676,499.495,-9.203804
2473,2473,212.0189,5.7572069,1.2454838,0.0,0,8.0735445,0.0,0.086037956,66.940636,8.86588,499.45868,-9.2042656
2474,2474,212.0191,5.920094,1.2625265,0.0,0,8.0462675,0.0,0.087792389,68.652664,8.8353424,499.42233,-9.2040911
2475,2475,212.0193,6.0487671,1.2954044,0.0,0,8.0196619,0.0,0.089867771,70.097374,8.8040867,499.38599,-9.2034445
2476,2476,212.0195,6.0744429,1.3402679,0.0,0,7.993176,0.0,0.092582211,70.510818,8.7722692,499.34964,-9.2031441
2477,2477,212.0197,6.0258994,1.3774227,0.0,0,7.9666953,0.0,0.095764786,69.923622,8.7376528,499.31332,-9.20294
2478,2478,212.0199,5.9639573,1.4183568,0.0,0,7.9402156,0.0,0.098925881,68.921051,8.7010498,499.27698,-9.2030315
2479,2479,212.0201,5.9240489,1.4589648,0.0,0,7.9137354,0.0,0.10150412,68.255974,8.6678028,499.24063,-9.2029543
2480,2480,212.0203,5.9368992,1.4881252,0.0,0,7.8872552,0.0,0.10397203,68.104607,8.6336622,499.20432,-9.202775
2481,2481,212.0205,5.9732938,1.5264753,0.0,0,7.860775,0.0,0.10696825,68.238022,8.5939932,499.16797,-9.2030478
2482,2482,212.0207,5.9928851,1.5675786,0.0,0,7.8342953,0.0,0.10959919,68.333527,8.5564814,499.13162,-9.2033997
2483,2483,212.0209,5.9937973,1.5904887,0.0,0,7.8078156,0.0,0.11165852,68.248009,8.5221128,499.09528,-9.2035837
2484,2484,212.0211,6.0036125,1.6159428,0.0,0,7.7813349,0.0,0.11386305,68.127136,8.4869003,499.05896,-9.2036438
2485,2485,212.0213,6.0110765,1.6492416,0.0,0,7.7548552,0.0,0.11585377,68.057472,8.4545832,499.02261,-9.2036047
2486,2486,212.0215,5.9906268,1.6758736,0.0,0,7.728375,0.0,0.11793437,67.85466,8.4250402,498.98627,-9.2034998
2487,2487,212.0217,5.9556627,1.7097713,0.0,0,7.7018952,0.0,0.1207274,67.25087,8.3963461,498.94995,-9.2029409
2488,2488,212.0219,5.969553,1.7438899,0.0,0,7.675415,0.0,0.12295882,67.071785,8.3674259,498.9136,-9.2016897
2489,2489,212.0221,6.0591874,1.7605609,0.0,0,7.6489348,0.0,0.12436885,67.909485,8.3393011,498.87726,-9.2013216
2490,2490,212.0223,6.1649852,1.7819102,0.0,0,7.6224551,0.0,0.12631999,69.010139,8.31073,498.84091,-9.2018394
2491,2491,212.0225,6.2180471,1.8156703,0.0,0,7.5959754,0.0,0.12846683,69.585533,8.2793894,498.8046,-9.202117
2492,2492,212.0227,6.2139735,1.8465922,0.0,0,7.5694952,0.0,0.13059585,69.479744,8.250226,498.76825,-9.2029963
2493,2493,212.0229,6.200913,1.8806173,0.0,0,7.543015,0.0,0.13362604,69.10228,8.2228146,498.7319,-9.2040005
2494,2494,212.0231,6.2054005,1.9178061,0.0,0,7.5165353,0.0,0.13637222,68.984375,8.1929779,498.69559,-9.2046919
2495,2495,212.0233,6.2035747,1.9451212,0.0,0,7.4900556,0.0,0.13816845,68.853134,8.1621046,498.65924,-9.2052479
2496,2496,212.0235,6.1785502,1.9722152,0.0,0,7.4635754,0.0,0.1406159,68.375031,8.1296415,498.62289,-9.2046385
2497,2497,212.0237,6.1745229,2.0044918,0.0,0,7.4370952,0.0,0.14317356,68.113403,8.0973902,498.58655,-9.2035484
2498,2498,212.0239,6.2145348,2.0318477,0.0,0,7.410615,0.0,0.14495678,68.380371,8.0671463,498.55023,-9.202899
2499,2499,212.0241,6.269496,2.0576794,0.0,0,7.384666,0.0,0.1472033,68.817322,8.0378456,498.51389,-9.2021103
2500,2500,212.0243,6.2862673,2.0843723,0.0,0,7.3593607,0.0,0.14936839,68.959633,8.0081015,498.47754,-9.2017965
2501,2501,212.0245,6.2547474,2.1094658,0.0,0,7.3341718,0.0,0.15090352,68.606575,7.9775729,498.44122,-9.2012815
2502,2502,212.0247,6.2303286,2.1382134,0.0,0,7.3089876,0.0,0.15326965,68.070923,7.9486542,498.40488,-9.2014666
2503,2503,212.0249,6.226953,2.1682673,0.0,0,7.2838035,0.0,0.15588415,67.752846,7.9198642,498.36853,-9.2027979
2504,2504,212.0251,6.221961,2.1948702,0.0,0,7.2586198,0.0,0.15764529,67.617218,7.8915596,498.33218,-9.2036314
2505,2505,212.0253,6.2265673,2.2180395,0.0,0,7.2334356,0.0,0.15954813,67.477699,7.8647552,498.29587,-9.2042942
2506,2506,212.0255,6.2814488,2.2390125,0.0,0,7.2082515,0.0,0.16159768,67.832191,7.8385401,498.25952,-9.2047901
2507,2507,212.0257,6.366395,2.2654872,0.0,0,7.1830673,0.0,0.16323043,68.677223,7.8150587,498.22318,-9.2049036
2508,2508,212.0259,6.4242311,2.2950649,0.0,0,7.1578832,0.0,0.16544732,69.247604,7.7876859,498.18683,-9.2051105
2509,2509,212.0261,6.4408078,2.3227217,0.0,0,7.132699,0.0,0.16810267,69.320183,7.7596288,498.15051,-9.2052212
2510,2510,212.0263,6.4240742,2.3552222,0.0,0,7.1075149,0.0,0.17024757,69.060547,7.7331963,498.11417,-9.2049131
2511,2511,212.0265,6.4014454,2.3848014,0.0,0,7.0823312,0.0,0.17242071,68.631325,7.7012568,498.07782,-9.2040491
2512,2512,212.0267,6.3805804,2.4071004,0.0,0,7.0571475,0.0,0.17476729,68.214806,7.6706219,498.0415,-9.202836
2513,2513,212.0269,6.3724937,2.4371541,0.0,0,7.0319633,0.0,0.17685276,67.965256,7.6449437,498.00516,-9.2027931
2514,2514,212.0271,6.3934793,2.4670126,0.0,0,7.0067787,0.0,0.17894724,67.98484,7.6198854,497.96881,-9.2032194
2515,2515,212.0273,6.4350863,2.4878321,0.0,0,6.981595,0.0,0.18118884,68.237953,7.5925937,497.93246,-9.2031851
2516,2516,212.0275,6.4732661,2.5158274,0.0,0,6.9564114,0.0,0.18325669,68.436554,7.5651541,497.89041,-9.2034073
2517,2517,212.0277,6.4763131,2.5462155,0.0,0,6.9312272,0.0,0.18518682,68.419815,7.5377641,497.83502,-9.2041845
2518,2518,212.0279,6.461699,2.5669425,0.0,0,6.9060431,0.0,0.18736963,68.170609,7.5102596,497.77963,-9.2054338
2519,2519,212.0281,6.45824,2.5955918,0.0,0,6.8808589,0.0,0.18967667,67.914055,7.4843955,497.72421,-9.2060823
2520,2520,212.0283,6.4653983,2.6265454,0.0,0,6.8556757,0.0,0.19163331,67.851776,7.457087,497.66882,-9.2057257
2521,2521,212.0285,6.4819975,2.6424401,0.0,0,6.8304915,0.0,0.19341707,67.928246,7.4310341,497.6134,-9.2051287
2522,2522,212.0287,6.5090408,2.6646996,0.0,0,6.8053074,0.0,0.1953849,68.071632,7.4068165,497.55801,-9.2049007
2523,2523,212.0289,6.5389905,2.6947308,0.0,0,6.7801232,0.0,0.19720288,68.247704,7.3818297,497.50262,-9.2043839
2524,2524,212.0291,6.5570455,2.7148418,0.0,0,6.7554412,0.0,0.19912569,68.332573,7.357986,497.4472,-9.2035713
2525,2525,212.0293,6.5557065,2.7410989,0.0,0,6.7313666,0.0,0.20161904,68.191681,7.3318505,497.39182,-9.2028055
2526,2526,212.0295,6.5487556,2.7726233,0.0,0,6.7074018,0.0,0.20369476,67.972672,7.3035703,497.33643,-9.2022085
2527,2527,212.0297,6.5548654,2.7913098,0.0,0,6.6834412,0.0,0.20540704,67.902176,7.2784123,497.28101,-9.2027168
2528,2528,212.0299,6.579484,2.8172226,0.0,0,6.6594815,0.0,0.20786236,68.002502,7.2561455,497.22562,-9.2033958
2529,2529,212.0301,6.6030955,2.8495603,0.0,0,6.6355214,0.0,0.21001957,68.102684,7.233036,497.17023,-9.2034492
2530,2530,212.0303,6.6189237,2.8684578,0.0,0,6.6115613,0.0,0.21170561,68.140274,7.2061405,497.11481,-9.2039843
2531,2531,212.0305,6.6292968,2.8913672,0.0,0,6.5876012,0.0,0.21409456,68.062439,7.1794877,497.05942,-9.2039909
2532,2532,212.0307,6.6324263,2.9217408,0.0,0,6.5636415,0.0,0.21614206,67.999947,7.1552873,497.004,-9.2041578
2533,2533,212.0309,6.6316948,2.9424849,0.0,0,6.5396814,0.0,0.21769062,67.961494,7.1311688,496.94861,-9.2045374
2534,2534,212.0311,6.6241975,2.9652908,0.0,0,6.5157218,0.0,0.2200827,67.719734,7.1055603,496.89322,-9.2044325
2535,2535,212.0313,6.6179013,2.9943349,0.0,0,6.4917617,0.0,0.2223078,67.522034,7.0815063,496.8378,-9.2046394
2536,2536,212.0315,6.6375484,3.013833,0.0,0,6.467802,0.0,0.22369365,67.571541,7.0576677,496.78241,-9.2046051
2537,2537,212.0317,6.6828322,3.033396,0.0,0,6.4438419,0.0,0.22577326,67.822823,7.0313807,496.72702,-9.204092
2538,2538,212.0319,6.7281594,3.0587757,0.0,0,6.4198813,0.0,0.22786203,68.155365,7.0068951,496.6716,-9.2035332
2539,2539,212.0321,6.7579184,3.079951,0.0,0,6.3959212,0.0,0.22922264,68.309067,6.9828248,496.61621,-9.2034283
2540,2540,212.0323,6.7583661,3.1038761,0.0,0,6.3719611,0.0,0.23154728,68.165993,6.959167,496.56079,-9.2032709
2541,2541,212.0325,6.741889,3.1324847,0.0,0,6.3480015,0.0,0.23407042,67.927917,6.9338102,496.5054,-9.2032452
2542,2542,212.0327,6.7326245,3.156286,0.0,0,6.3240414,0.0,0.23566666,67.783203,6.9083433,496.45001,-9.2033949
2543,2543,212.0329,6.7345276,3.1781952,0.0,0,6.3000817,0.0,0.23777913,67.581528,6.8857455,496.39459,-9.2034216
2544,2544,212.0331,6.7426844,3.2028236,0.0,0,6.2761216,0.0,0.24013951,67.433769,6.8608136,496.3392,-9.2039862
2545,2545,212.0333,6.7626858,3.2280374,0.0,0,6.252162,0.0,0.24173784,67.544952,6.8358083,496.28381,-9.2047567
2546,2546,212.0335,6.7962008,3.2513783,0.0,0,6.2282019,0.0,0.24382187,67.712006,6.812849,496.22839,-9.204915
2547,2547,212.0337,6.8266511,3.273277,0.0,0,6.2042418,0.0,0.24616706,67.850143,6.7879705,496.173,-9.2043762
2548,2548,212.0339,6.8430662,3.2969241,0.0,0,6.1802816,0.0,0.24766849,67.959412,6.762538,496.11761,-9.2041979
2549,2549,212.0341,6.8415027,3.3196673,0.0,0,6.1568022,0.0,0.24959917,67.856483,6.7398548,496.06219,-9.2040787
2550,2550,212.0343,6.8315983,3.3419471,0.0,0,6.1339045,0.0,0.25200126,67.59626,6.7158899,496.00681,-9.2035723
2551,2551,212.0345,6.8317862,3.3691595,0.0,0,6.1111116,0.0,0.25383249,67.491676,6.690176,495.95139,-9.20331
2552,2552,212.0347,6.848743,3.3931329,0.0,0,6.0883236,0.0,0.25578898,67.435455,6.6681986,495.896,-9.2031775
2553,2553,212.0349,6.8786254,3.4111462,0.0,0,6.0655355,0.0,0.25798807,67.542397,6.6476722,495.84061,-9.2032804
2554,2554,212.0351,6.9020057,3.4363184,0.0,0,6.042748,0.0,0.25977445,67.735939,6.6230183,495.78519,-9.2036285
2555,2555,212.0353,6.9134264,3.461658,0.0,0,6.0199599,0.0,0.26164266,67.748672,6.5955172,495.7298,-9.2036877
2556,2556,212.0355,6.9280119,3.4807639,0.0,0,5.9971714,0.0,0.26393411,67.725075,6.571178,495.67441,-9.2040138
2557,2557,212.0357,6.9462504,3.5084178,0.0,0,5.9743834,0.0,0.26608086,67.784691,6.5494504,495.61899,-9.2042398
2558,2558,212.0359,6.9627357,3.5354645,0.0,0,5.9515953,0.0,0.26799044,67.821434,6.5257025,495.5636,-9.2041492
2559,2559,212.0361,6.9724865,3.5519328,0.0,0,5.9288073,0.0,0.27006266,67.752823,6.5004978,495.50818,-9.2045565
2560,2560,212.0363,6.9786787,3.5772152,0.0,0,5.9060197,0.0,0.27221245,67.642731,6.4767394,495.45279,-9.2040815
2561,2561,212.0365,6.9886122,3.6072056,0.0,0,5.8832316,0.0,0.2741572,67.577049,6.4530582,495.3974,-9.2041168
2562,2562,212.0367,6.9974775,3.6246901,0.0,0,5.8604436,0.0,0.27621451,67.569359,6.4308634,495.34198,-9.2048683
2563,2563,212.0369,7.0115266,3.6485662,0.0,0,5.8376555,0.0,0.2784996,67.571709,6.4091325,495.28659,-9.2049704
2564,2564,212.0371,7.0222754,3.6770701,0.0,0,5.814867,0.0,0.2803722,67.548073,6.3854828,495.2312,-9.2044458
2565,2565,212.0373,7.0224376,3.6929944,0.0,0,5.792079,0.0,0.28219119,67.425186,6.3631749,495.17578,-9.2043886
2566,2566,212.0375,7.0259881,3.7164359,0.0,0,5.7692914,0.0,0.2845459,67.289322,6.3405237,495.11957,-9.2042398
2567,2567,212.0377,7.0415106,3.7455819,0.0,0,5.7465034,0.0,0.28652319,67.343353,6.3151746,495.06,-9.2041016
2568,2568,212.0379,7.0777326,3.7613704,0.0,0,5.7237153,0.0,0.28818941,67.561012,6.2910876,495.0004,-9.2039576
2569,2569,212.0381,7.1069202,3.7841423,0.0,0,5.7009273,0.0,0.29057044,67.631592,6.2670155,494.94083,-9.20403
2570,2570,212.0383,7.1098628,3.8139541,0.0,0,5.6781397,0.0,0.29263738,67.569519,6.243691,494.88126,-9.2041216
2571,2571,212.0385,7.1100092,3.8309293,0.0,0,5.6553516,0.0,0.29430756,67.460175,6.2195125,494.82169,-9.2041559
2572,2572,212.0387,7.1136203,3.8536007,0.0,0,5.6325636,0.0,0.29685217,67.324844,6.1962166,494.76212,-9.2046232
2573,2573,212.0389,7.1235209,3.8834112,0.0,0,5.6097751,0.0,0.29897767,67.2686,6.1745205,494.70255,-9.2051229
2574,2574,212.0391,7.1325741,3.9009819,0.0,0,5.5874414,0.0,0.30051532,67.227104,6.1521015,494.64297,-9.2054873
2575,2575,212.0393,7.1421843,3.9213381,0.0,0,5.5656581,0.0,0.30296233,67.127953,6.1318917,494.5834,-9.2051535
2576,2576,212.0395,7.162353,3.949981,0.0,0,5.5439734,0.0,0.30516434,67.143417,6.1093473,494.52383,-9.2050285
2577,2577,212.0397,7.1852293,3.9687066,0.0,0,5.5222936,0.0,0.30659252,67.325943,6.08425,494.46426,-9.2049513
2578,2578,212.0399,7.2103405,3.9886854,0.0,0,5.5006132,0.0,0.30890739,67.430832,6.0604825,494.40469,-9.2042933
2579,2579,212.0401,7.2316937,4.016151,0.0,0,5.4789333,0.0,0.31123856,67.404617,6.0389328,494.34512,-9.203908
2580,2580,212.0403,7.2388358,4.0371037,0.0,0,5.457253,0.0,0.31274444,67.375008,6.0171309,494.28555,-9.2038918
2581,2581,212.0405,7.2358932,4.0588961,0.0,0,5.4355731,0.0,0.31519443,67.160606,5.9915075,494.22598,-9.2040873
2582,2582,212.0407,7.2365913,4.0861149,0.0,0,5.4138932,0.0,0.31776717,66.924133,5.9661336,494.16641,-9.2042437
2583,2583,212.0409,7.2434187,4.1081705,0.0,0,5.3922133,0.0,0.31931266,66.901375,5.9437542,494.10684,-9.2043581
2584,2584,212.0411,7.2602305,4.1275835,0.0,0,5.370533,0.0,0.32151249,66.893654,5.9192538,494.04727,-9.2045898
2585,2585,212.0413,7.2884178,4.1514764,0.0,0,5.3488531,0.0,0.32392153,67.013954,5.8967805,493.9877,-9.2046089
2586,2586,212.0415,7.3199229,4.1751456,0.0,0,5.3271732,0.0,0.32549894,67.200027,5.8759789,493.92813,-9.2044563
2587,2587,212.0417,7.3442864,4.1974688,0.0,0,5.3054934,0.0,0.32783785,67.242966,5.8529167,493.86856,-9.2042933
2588,2588,212.0419,7.3619046,4.2213416,0.0,0,5.283813,0.0,0.33042192,67.321175,5.832252,493.80899,-9.2040033
2589,2589,212.0421,7.3793163,4.2448869,0.0,0,5.2621331,0.0,0.33200699,67.403229,5.8092256,493.74942,-9.2035284
2590,2590,212.0423,7.393609,4.2658272,0.0,0,5.2404532,0.0,0.33408532,67.336319,5.781353,493.68985,-9.2039366
2591,2591,212.0425,7.3971405,4.2865901,0.0,0,5.2187734,0.0,0.33655301,67.18219,5.7571645,493.63028,-9.2045641
2592,2592,212.0427,7.3983603,4.3119545,0.0,0,5.1970935,0.0,0.3383233,67.020714,5.7330861,493.57071,-9.2048702
2593,2593,212.0429,7.4064674,4.335022,0.0,0,5.1754136,0.0,0.3404429,66.96286,5.7087774,493.51114,-9.2043924
2594,2594,212.0431,7.4220352,4.3540912,0.0,0,5.1537333,0.0,0.34289688,67.00399,5.6875105,493.45157,-9.2043562
2595,2595,212.0433,7.4414487,4.3795948,0.0,0,5.1320534,0.0,0.34474301,67.056213,5.6624198,493.392,-9.2041054
2596,2596,212.0435,7.4610376,4.4048343,0.0,0,5.110373,0.0,0.34682858,67.107819,5.6390357,493.33243,-9.2028675
2597,2597,212.0437,7.4893441,4.4243317,0.0,0,5.0886931,0.0,0.34945354,67.200027,5.6156807,493.27286,-9.2027645
2598,2598,212.0439,7.5136189,4.4510102,0.0,0,5.0670133,0.0,0.35165989,67.280441,5.5912709,493.21329,-9.2032986
2599,2599,212.0441,7.5271916,4.4764309,0.0,0,5.0457678,0.0,0.35360673,67.265572,5.5710921,493.15372,-9.2034264
2600,2600,212.0443,7.5283518,4.4926186,0.0,0,5.0250483,0.0,0.35588941,67.125778,5.5481057,493.09415,-9.2034397
2601,2601,212.0445,7.5267844,4.5181379,0.0,0,5.0044241,0.0,0.35810497,66.990448,5.525033,493.03458,-9.2040148
2602,2602,212.0447,7.541461,4.5457249,0.0,0,4.9838037,0.0,0.36010572,66.94561,5.501164,492.97501,-9.2040339
2603,2603,212.0449,7.5543842,4.5616517,0.0,0,4.9631839,0.0,0.36231184,66.898643,5.4783282,492.91544,-9.2036438
2604,2604,212.0451,7.562716,4.5865245,0.0,0,4.9425635,0.0,0.3647083,66.851982,5.4557252,492.85587,-9.2039785
2605,2605,212.0453,7.5818696,4.6151443,0.0,0,4.9219437,0.0,0.36670369,66.840881,5.4320812,492.7963,-9.203187
2606,2606,212.0455,7.6102457,4.6298561,0.0,0,4.9013238,0.0,0.3687211,66.941277,5.4105802,492.73672,-9.2027969
2607,2607,212.0457,7.6428809,4.653481,0.0,0,4.8807039,0.0,0.37127498,67.085091,5.3879266,492.67715,-9.2034121
2608,2608,212.0459,7.6658831,4.6828365,0.0,0,4.8600836,0.0,0.37333703,67.147713,5.3664188,492.61758,-9.2032137
2609,2609,212.0461,7.6688685,4.6978884,0.0,0,4.8394637,0.0,0.37524471,67.040901,5.3428464,492.55801,-9.2032328
2610,2610,212.0463,7.6682315,4.7207651,0.0,0,4.8188438,0.0,0.37790418,66.905052,5.3189607,492.49844,-9.2039337
2611,2611,212.0465,7.6714106,4.7507167,0.0,0,4.798224,0.0,0.38002101,66.848236,5.2979994,492.43887,-9.2043886
2612,2612,212.0467,7.6831541,4.7667751,0.0,0,4.7776036,0.0,0.38178012,66.800377,5.2758422,492.3793,-9.2046509
2613,2613,212.0469,7.6942482,4.7886844,0.0,0,4.7569838,0.0,0.38448659,66.676392,5.2503314,492.31973,-9.20432
2614,2614,212.0471,7.7046027,4.8188376,0.0,0,4.7363639,0.0,0.38673514,66.606918,5.2259793,492.26016,-9.2035961
2615,2615,212.0473,7.7321649,4.8360329,0.0,0,4.7157435,0.0,0.38848987,66.718987,5.2068086,492.20059,-9.2031937
2616,2616,212.0475,7.7631269,4.8568254,0.0,0,4.6951237,0.0,0.39124519,66.818985,5.1842847,492.12335,-9.2025566
2617,2617,212.0477,7.7885637,4.8861499,0.0,0,4.6745038,0.0,0.39361152,66.89357,5.1611481,491.88727,-9.20224
2618,2618,212.0479,7.8029437,4.9048314,0.0,0,4.6538839,0.0,0.39522868,66.962601,5.1386385,491.65115,-9.2027016
2619,2619,212.0481,7.8120089,4.9253597,0.0,0,4.6332641,0.0,0.39794818,66.849464,5.1152349,491.41507,-9.2032547
2620,2620,212.0483,7.818913,4.9536724,0.0,0,4.6126437,0.0,0.40051544,66.656487,5.0932298,491.17899,-9.2034712
2621,2621,212.0485,7.8166471,4.9732275,0.0,0,4.5920234,0.0,0.40200725,66.548111,5.0707421,490.94287,-9.2042294
2622,2622,212.0487,7.8153396,4.991755,0.0,0,4.5714035,0.0,0.4044269,66.41922,5.0470347,490.70679,-9.205637
2623,2623,212.0489,7.8222837,5.0178819,0.0,0,4.5507836,0.0,0.40697065,66.30014,5.0237455,490.4707,-9.2058945
2624,2624,212.0491,7.8446651,5.0389905,0.0,0,4.5305758,0.0,0.40858957,66.371567,5.0041213,490.23459,-9.2056789
2625,2625,212.0493,7.8761711,5.0577526,0.0,0,4.5108657,0.0,0.41102424,66.422287,4.9825969,489.9985,-9.2053738
2626,2626,212.0495,7.9103179,5.0824299,0.0,0,4.4912457,0.0,0.41355214,66.451462,4.9598947,489.76242,-9.2047043
2627,2627,212.0497,7.9366875,5.1041331,0.0,0,4.4716296,0.0,0.41512102,66.615135,4.936553,489.52631,-9.2041616
2628,2628,212.0499,7.9470754,5.124022,0.0,0,4.4520135,0.0,0.41751459,66.610786,4.9143987,489.29022,-9.2036791
2629,2629,212.0501,7.9467549,5.1477637,0.0,0,4.4323974,0.0,0.42021975,66.477325,4.8940454,489.05414,-9.2035446
2630,2630,212.0503,7.941535,5.1716332,0.0,0,4.4127812,0.0,0.42197022,66.355202,4.872808,488.81802,-9.2036028
2631,2631,212.0505,7.9406443,5.1921673,0.0,0,4.3931651,0.0,0.42431104,66.180099,4.8476424,488.58194,-9.2037268
2632,2632,212.0507,7.9534588,5.2121568,0.0,0,4.3735495,0.0,0.42693263,66.084724,4.8264008,488.34586,-9.2035789
2633,2633,212.0509,7.9792509,5.2361851,0.0,0,4.3539338,0.0,0.42866886,66.150627,4.8070693,488.10977,-9.203474
2634,2634,212.0511,8.0090723,5.257586,0.0,0,4.3343177,0.0,0.43090835,66.226311,4.7833462,487.87366,-9.2035036
2635,2635,212.0513,8.042346,5.2758751,0.0,0,4.3147016,0.0,0.43352532,66.305679,4.7631583,487.63757,-9.2034817
2636,2636,212.0515,8.0663176,5.3002248,0.0,0,4.2950859,0.0,0.43534988,66.37561,4.7419496,487.40149,-9.2038679
2637,2637,212.0517,8.0781708,5.3221993,0.0,0,4.2754693,0.0,0.43736914,66.359261,4.7171721,487.16537,-9.2043295
2638,2638,212.0519,8.0797014,5.3382502,0.0,0,4.2558532,0.0,0.43985337,66.234833,4.6956005,486.92929,-9.2044106
2639,2639,212.0521,8.0773039,5.3635192,0.0,0,4.236237,0.0,0.44197875,66.103653,4.6760883,486.69321,-9.2045088
2640,2640,212.0523,8.0833769,5.388351,0.0,0,4.2166214,0.0,0.44414166,65.992325,4.6539407,486.45709,-9.2045126
2641,2641,212.0525,8.094451,5.4034162,0.0,0,4.1970053,0.0,0.44668183,65.919006,4.6340055,486.22101,-9.2045441
2642,2642,212.0527,8.1083851,5.4273639,0.0,0,4.1773891,0.0,0.44885704,65.887901,4.6137242,485.98492,-9.2046251
2643,2643,212.0529,8.1271553,5.4522843,0.0,0,4.1577735,0.0,0.45074418,65.883949,4.5916967,485.74881,-9.2040348
2644,2644,212.0531,8.1417065,5.4652977,0.0,0,4.1381574,0.0,0.45300567,65.855606,4.5697575,485.51273,-9.2034054
2645,2645,212.0533,8.1612825,5.488174,0.0,0,4.1185412,0.0,0.45533481,65.899117,4.5470061,485.27664,-9.2027664
2646,2646,212.0535,8.1890593,5.5151157,0.0,0,4.0989256,0.0,0.4573372,66.001648,4.5262337,485.04053,-9.2027073
2647,2647,212.0537,8.2034922,5.5278716,0.0,0,4.0793095,0.0,0.45941347,66.004646,4.5064077,484.80444,-9.2033377
2648,2648,212.0539,8.208602,5.5494766,0.0,0,4.0596933,0.0,0.46184596,65.896202,4.4857512,484.56836,-9.2034416
2649,2649,212.0541,8.2142897,5.5767016,0.0,0,4.0404716,0.0,0.46381408,65.768829,4.466187,484.33224,-9.204133
2650,2650,212.0543,8.2195015,5.5891595,0.0,0,4.0217257,0.0,0.46574721,65.664619,4.4456949,484.09616,-9.2043591
2651,2651,212.0545,8.2351398,5.6096821,0.0,0,4.0030656,0.0,0.46842885,65.587967,4.424706,483.86008,-9.2039289
2652,2652,212.0547,8.2582264,5.6371236,0.0,0,3.9844091,0.0,0.47047234,65.601913,4.4059978,483.62396,-9.2037249
2653,2653,212.0549,8.2710066,5.6503057,0.0,0,3.9657531,0.0,0.47214472,65.615608,4.3863921,483.38788,-9.2035217
2654,2654,212.0551,8.279067,5.6693902,0.0,0,3.9470971,0.0,0.47479114,65.534073,4.3675914,483.15179,-9.2034998
2655,2655,212.0553,8.302578,5.6971092,0.0,0,3.928441,0.0,0.47690919,65.519218,4.3472428,482.91568,-9.2029924
2656,2656,212.0555,8.3276834,5.7108145,0.0,0,3.9097853,0.0,0.47850823,65.629517,4.3268018,482.6796,-9.2022696
2657,2657,212.0557,8.3472586,5.7285466,0.0,0,3.8911293,0.0,0.48119056,65.660919,4.3053317,482.44351,-9.2015324
2658,2658,212.0559,8.3708191,5.7549796,0.0,0,3.8724732,0.0,0.48336408,65.717384,4.2824969,482.2074,-9.2011929
2659,2659,212.0561,8.3820257,5.7690988,0.0,0,3.8538172,0.0,0.48478323,65.718452,4.2637448,481.97131,-9.2017698
2660,2660,212.0563,8.3870468,5.7863035,0.0,0,3.8351612,0.0,0.4873746,65.589615,4.2441173,481.73523,-9.2027998
2661,2661,212.0565,8.3923435,5.8130302,0.0,0,3.8165052,0.0,0.48980325,65.506462,4.2231297,481.49911,-9.2040739
2662,2662,212.0567,8.3926888,5.8298388,0.0,0,3.7978492,0.0,0.49120137,65.42569,4.2042665,481.26303,-9.2042112
2663,2663,212.0569,8.4066477,5.8461447,0.0,0,3.7791932,0.0,0.49377263,65.324379,4.1850085,481.02695,-9.2036257
2664,2664,212.0571,8.4327374,5.8706336,0.0,0,3.7605371,0.0,0.49635026,65.339272,4.1645198,480.79083,-9.203599
2665,2665,212.0573,8.4674931,5.8879862,0.0,0,3.7418811,0.0,0.49760437,65.51162,4.1445999,480.55475,-9.2037525
2666,2666,212.0575,8.4955873,5.9047036,0.0,0,3.7232251,0.0,0.50009066,65.557983,4.1248384,480.31866,-9.2036695
2667,2667,212.0577,8.5134554,5.928031,0.0,0,3.7045693,0.0,0.50281078,65.520325,4.1055326,480.02936,-9.203867
2668,2668,212.0579,8.5289106,5.9468155,0.0,0,3.6859133,0.0,0.50412649,65.57531,4.0860724,479.74008,-9.2035027
2669,2669,212.0581,8.5324583,5.9631758,0.0,0,3.6672573,0.0,0.50635105,65.50502,4.0684056,479.45078,-9.2028494
2670,2670,212.0583,8.5319185,5.9836059,0.0,0,3.6486013,0.0,0.50898701,65.317719,4.050622,479.1615,-9.2033596
2671,2671,212.0585,8.5336037,6.0042572,0.0,0,3.629945,0.0,0.51049191,65.20784,4.0316544,478.87219,-9.2035589
2672,2672,212.0587,8.5517797,6.0223985,0.0,0,3.611289,0.0,0.51278627,65.177162,4.0086422,478.58292,-9.2031488
2673,2673,212.0589,8.574563,6.0410972,0.0,0,3.5926332,0.0,0.51550722,65.164009,3.9865172,478.29361,-9.2031326
2674,2674,212.0591,8.6033125,6.0616112,0.0,0,3.5743496,0.0,0.51701319,65.224396,3.9708877,478.00433,-9.203063
2675,2675,212.0593,8.6320095,6.0790691,0.0,0,3.5565164,0.0,0.51900285,65.313683,3.9527166,477.71503,-9.2033319
2676,2676,212.0595,8.6477623,6.0953012,0.0,0,3.5387647,0.0,0.52160007,65.354698,3.930285,477.42575,-9.2043896
2677,2677,212.0597,8.6697922,6.1176138,0.0,0,3.5210166,0.0,0.52332729,65.383537,3.9108608,477.13644,-9.2041759
2678,2678,212.0599,8.6869764,6.13696,0.0,0,3.5032687,0.0,0.52530831,65.385323,3.8949146,476.84717,-9.2034435
2679,2679,212.0601,8.6921539,6.1510816,0.0,0,3.4855206,0.0,0.52796316,65.2677,3.8780167,476.55786,-9.2033329
2680,2680,212.0603,8.6952381,6.1736584,0.0,0,3.4677725,0.0,0.52993482,65.173462,3.8590722,476.26859,-9.2033272
2681,2681,212.0605,8.7024794,6.1946096,0.0,0,3.4500246,0.0,0.53187263,65.116257,3.8400683,475.97928,-9.2038851
2682,2682,212.0607,8.722168,6.2078834,0.0,0,3.4322767,0.0,0.53443176,65.062531,3.8214333,475.69,-9.2039213
2683,2683,212.0609,8.7439394,6.2310009,0.0,0,3.4145288,0.0,0.53654629,65.078423,3.8033054,475.4007,-9.2029009
2684,2684,212.0611,8.7734785,6.2535729,0.0,0,3.3967807,0.0,0.53833675,65.166069,3.7848203,475.11142,-9.2022953
2685,2685,212.0613,8.8007984,6.2651253,0.0,0,3.3790326,0.0,0.54064649,65.221718,3.7645998,474.82214,-9.2020655
2686,2686,212.0615,8.8192654,6.286325,0.0,0,3.3612847,0.0,0.54292923,65.211807,3.746469,474.53284,-9.2026472
2687,2687,212.0617,8.8463211,6.3102088,0.0,0,3.3435366,0.0,0.54470772,65.291168,3.7286496,474.24356,-9.2036572
2688,2688,212.0619,8.8740168,6.3212962,0.0,0,3.3257885,0.0,0.54688215,65.360626,3.7094336,473.95425,-9.2042027
2689,2689,212.0621,8.8836222,6.3410711,0.0,0,3.3080406,0.0,0.54936546,65.319359,3.6909077,473.66498,-9.2045679
2690,2690,212.0623,8.8849792,6.3666415,0.0,0,3.2902927,0.0,0.55124491,65.219429,3.6723077,473.37567,-9.2047825
2691,2691,212.0625,8.8999615,6.3773308,0.0,0,3.2725446,0.0,0.55319971,65.145203,3.653682,473.0864,-9.204937
2692,2692,212.0627,8.9148092,6.3953757,0.0,0,3.2547965,0.0,0.55576986,65.094681,3.6343637,472.79709,-9.2048025
2693,2693,212.0629,8.9312935,6.4218121,0.0,0,3.2370486,0.0,0.55772763,65.076172,3.6157777,472.50781,-9.204072
2694,2694,212.0631,8.9529476,6.4335222,0.0,0,3.2193005,0.0,0.55961025,65.075775,3.5986953,472.21851,-9.2028942
2695,2695,212.0633,8.9798965,6.4516306,0.0,0,3.2015524,0.0,0.56245112,65.089134,3.5802159,471.92923,-9.2026911
2696,2696,212.0635,9.0159111,6.4777751,0.0,0,3.1838045,0.0,0.56449634,65.250046,3.5608709,471.63992,-9.2025146
2697,2697,212.0637,9.0434837,6.4890904,0.0,0,3.1660566,0.0,0.56605345,65.384323,3.5453296,471.35065,-9.2023296
2698,2698,212.0639,9.0617733,6.50563,0.0,0,3.1483085,0.0,0.56880307,65.290352,3.5267315,471.06134,-9.2024612
2699,2699,212.0641,9.0649958,6.5310373,0.0,0,3.1309149,0.0,0.57100302,65.21537,3.505168,470.77206,-9.2025223
2700,2700,212.0643,9.0701532,6.5442729,0.0,0,3.1139498,0.0,0.57241732,65.190971,3.4867404,470.48276,-9.2036943
2701,2701,212.0645,9.0882092,6.5609112,0.0,0,3.0970623,0.0,0.57525402,65.097603,3.4697976,470.19348,-9.2045574
2702,2702,212.0647,9.1060028,6.5866251,0.0,0,3.0801783,0.0,0.57776517,65.073929,3.4516506,469.90417,-9.2046442
2703,2703,212.0649,9.1254473,6.6014118,0.0,0,3.0632942,0.0,0.57912576,65.086411,3.4332423,469.6149,-9.2040863
2704,2704,212.0651,9.1557007,6.6170545,0.0,0,3.0464103,0.0,0.58190745,65.092133,3.4146338,469.32559,-9.2031002
2705,2705,212.0653,9.2046547,6.6419172,0.0,0,3.0295262,0.0,0.58450323,65.231224,3.3975875,469.03632,-9.2019119
2706,2706,212.0655,9.2410355,6.6579523,0.0,0,3.0126421,0.0,0.58574736,65.429245,3.3798981,468.74701,-9.200963
2707,2707,212.0657,9.2541294,6.672348,0.0,0,2.9957583,0.0,0.58833462,65.399864,3.3584104,468.45773,-9.2006092
2708,2708,212.0659,9.2594547,6.6948972,0.0,0,2.9788742,0.0,0.59110028,65.245285,3.3381543,468.16843,-9.2003298
2709,2709,212.0661,9.2660999,6.7126093,0.0,0,2.9619904,0.0,0.59243107,65.209808,3.3195281,467.87915,-9.2011595
2710,2710,212.0663,9.277029,6.7279463,0.0,0,2.9451063,0.0,0.59493494,65.122375,3.3024185,467.58984,-9.2026615
2711,2711,212.0665,9.2910414,6.7486911,0.0,0,2.9282222,0.0,0.59775966,65.048172,3.2864754,467.30057,-9.2033634
2712,2712,212.0667,9.3061571,6.7672453,0.0,0,2.9113381,0.0,0.59908181,65.083168,3.2708983,467.01129,-9.2036142
2713,2713,212.0669,9.3351889,6.7821493,0.0,0,2.894454,0.0,0.60137868,65.088036,3.2506313,466.72198,-9.2036247
2714,2714,212.0671,9.3783379,6.799974,0.0,0,2.8775702,0.0,0.60412675,65.186852,3.2291818,466.43271,-9.2039661
2715,2715,212.0673,9.4156961,6.8194928,0.0,0,2.8606861,0.0,0.60544717,65.399963,3.2121439,466.1434,-9.2033577
2716,2716,212.0675,9.4475107,6.8358097,0.0,0,2.8438022,0.0,0.60761338,65.48867,3.1942804,465.85413,-9.202343
2717,2717,212.0677,9.4657898,6.8524804,0.0,0,2.8269181,0.0,0.61054373,65.441582,3.1740718,465.84775,-9.2021303
2718,2718,212.0679,9.4699812,6.8748112,0.0,0,2.810034,0.0,0.612297,65.365875,3.1563957,465.87283,-9.201643
2719,2719,212.0681,9.4744644,6.8932662,0.0,0,2.7931502,0.0,0.61441672,65.219322,3.1406598,465.89789,-9.2017221
2720,2720,212.0683,9.4874353,6.9065552,0.0,0,2.7762663,0.0,0.6171844,65.110359,3.1227946,465.92297,-9.2019405
2721,2721,212.0685,9.5094738,6.9281774,0.0,0,2.7593822,0.0,0.61908132,65.133354,3.1041327,465.94803,-9.2026396
2722,2722,212.0687,9.5346546,6.9475641,0.0,0,2.7424982,0.0,0.62102163,65.195236,3.0861452,465.97311,-9.2036562
2723,2723,212.0689,9.5647516,6.9590774,0.0,0,2.7256143,0.0,0.62365812,65.226013,3.0690334,465.99817,-9.2035379
2724,2724,212.0691,9.5917158,6.9799948,0.0,0,2.7090681,0.0,0.62574881,65.308578,3.05374,466.02322,-9.2033453
2725,2725,212.0693,9.6206722,7.0004029,0.0,0,2.6929309,0.0,0.62762338,65.405426,3.0356019,466.04831,-9.2032061
2726,2726,212.0695,9.6555271,7.010406,0.0,0,2.6768675,0.0,0.63007832,65.434746,3.0171196,466.07336,-9.2029552
2727,2727,212.0697,9.6826534,7.0308909,0.0,0,2.6608074,0.0,0.63228148,65.456337,3.0001807,466.09845,-9.2024965
2728,2728,212.0699,9.696497,7.0530772,0.0,0,2.6447473,0.0,0.6340782,65.426155,2.9826481,466.1235,-9.2018957
2729,2729,212.0701,9.7070446,7.0624514,0.0,0,2.6286871,0.0,0.63639569,65.367966,2.9660306,466.14859,-9.2011728
2730,2730,212.0703,9.7159233,7.0818505,0.0,0,2.6126273,0.0,0.63888496,65.286179,2.9485013,466.17365,-9.2006474
2731,2731,212.0705,9.7335958,7.1057582,0.0,0,2.5965672,0.0,0.64069915,65.27636,2.9310248,466.1987,-9.201314
2732,2732,212.0707,9.7656031,7.1159439,0.0,0,2.580507,0.0,0.64283371,65.319756,2.9148695,466.22379,-9.2021523
2733,2733,212.0709,9.7960072,7.1353288,0.0,0,2.5644472,0.0,0.64565188,65.32753,2.8982024,466.24884,-9.2029333
2734,2734,212.0711,9.8252211,7.1607723,0.0,0,2.5483871,0.0,0.64773941,65.420914,2.8799405,466.27393,-9.2033453
2735,2735,212.0713,9.8586092,7.170011,0.0,0,2.5323269,0.0,0.64963889,65.489761,2.8630309,466.29898,-9.2040281
2736,2736,212.0715,9.8862619,7.1869521,0.0,0,2.5162671,0.0,0.65250725,65.458466,2.8478601,466.32407,-9.2035742
2737,2737,212.0717,9.9026842,7.2122164,0.0,0,2.5002072,0.0,0.65450722,65.494606,2.8293183,466.34912,-9.2021465
2738,2738,212.0719,9.9124784,7.2215843,0.0,0,2.4841471,0.0,0.65604854,65.498329,2.8124824,466.37421,-9.2014942
2739,2739,212.0721,9.9258566,7.2366414,0.0,0,2.4680872,0.0,0.65894604,65.38842,2.7948072,466.39926,-9.2014036
2740,2740,212.0723,9.9470377,7.2611217,0.0,0,2.4520271,0.0,0.66105741,65.353683,2.7785842,466.42432,-9.201704
2741,2741,212.0725,9.9661665,7.2718196,0.0,0,2.4359672,0.0,0.66241145,65.416153,2.7646654,466.4494,-9.2017727
2742,2742,212.0727,9.9884491,7.28653,0.0,0,2.4199073,0.0,0.66527009,65.409958,2.7461102,466.47446,-9.2018509
2743,2743,212.0729,10.015528,7.3108711,0.0,0,2.4038472,0.0,0.66763729,65.414932,2.7278521,466.49954,-9.2023735
2744,2744,212.0731,10.053247,7.3231564,0.0,0,2.3877871,0.0,0.66887116,65.567177,2.709728,466.5246,-9.20187
2745,2745,212.0733,10.0938,7.3371654,0.0,0,2.3717272,0.0,0.67169279,65.642502,2.6922653,466.54968,-9.2016611
2746,2746,212.0735,10.124096,7.360795,0.0,0,2.3556671,0.0,0.67438936,65.646278,2.6768699,466.57474,-9.2024488
2747,2747,212.0737,10.149602,7.3754554,0.0,0,2.339607,0.0,0.67565978,65.690643,2.6577227,466.59979,-9.2021971
2748,2748,212.0739,10.167669,7.3894253,0.0,0,2.3235471,0.0,0.67843091,65.630959,2.6411443,466.62488,-9.2021961
2749,2749,212.0741,10.180634,7.4117699,0.0,0,2.3078086,0.0,0.68137693,65.553299,2.6254292,466.64993,-9.2023573
2750,2750,212.0743,10.19241,7.4281898,0.0,0,2.2924592,0.0,0.68261695,65.54734,2.6080291,466.67502,-9.20224
2751,2751,212.0745,10.217258,7.4417939,0.0,0,2.2771802,0.0,0.68521279,65.49929,2.5936811,466.70007,-9.2027521
2752,2752,212.0747,10.249481,7.4606404,0.0,0,2.261904,0.0,0.68805569,65.50383,2.5785363,466.72516,-9.2026377
2753,2753,212.0749,10.280975,7.47755,0.0,0,2.2466278,0.0,0.68922073,65.614868,2.5607185,466.75021,-9.2018957
2754,2754,212.0751,10.316293,7.4915671,0.0,0,2.2313521,0.0,0.69159353,65.685219,2.5415075,466.77527,-9.2018471
2755,2755,212.0753,10.355066,7.5088959,0.0,0,2.2160761,0.0,0.69450217,65.757668,2.5241308,466.80035,-9.2018538
2756,2756,212.0755,10.386334,7.527513,0.0,0,2.2008002,0.0,0.69590718,65.866684,2.506376,466.82541,-9.2019939
2757,2757,212.0757,10.402812,7.5418139,0.0,0,2.185524,0.0,0.69814003,65.872704,2.4886215,466.85049,-9.2027569
2758,2758,212.0759,10.419064,7.5567636,0.0,0,2.170248,0.0,0.7011115,65.773872,2.4727144,466.87555,-9.2033453
2759,2759,212.0761,10.441216,7.5770102,0.0,0,2.1549721,0.0,0.7027092,65.771774,2.4582157,466.90063,-9.2027903
2760,2760,212.0763,10.464335,7.5935802,0.0,0,2.1396961,0.0,0.70482713,65.792366,2.4408753,466.92569,-9.2022209
2761,2761,212.0765,10.49219,7.6068783,0.0,0,2.1244199,0.0,0.70776129,65.770317,2.4226339,466.95078,-9.2020311
2762,2762,212.0767,10.530572,7.6284037,0.0,0,2.109144,0.0,0.709732,65.847282,2.4066408,466.97583,-9.2017698
2763,2763,212.0769,10.562963,7.6464472,0.0,0,2.093868,0.0,0.71185905,65.941544,2.3895698,467.00089,-9.2010136
2764,2764,212.0771,10.592954,7.6571407,0.0,0,2.0785921,0.0,0.71465164,65.980728,2.3730016,467.02597,-9.2003307
2765,2765,212.0773,10.626436,7.6769533,0.0,0,2.0633161,0.0,0.71668059,66.021965,2.3562071,467.05103,-9.2009964
2766,2766,212.0775,10.654757,7.6947546,0.0,0,2.0480402,0.0,0.71839827,66.090042,2.3385093,467.07611,-9.2018185
2767,2767,212.0777,10.680496,7.7032704,0.0,0,2.0327642,0.0,0.72089589,66.112328,2.3224087,467.08923,-9.2013454
2768,2768,212.0779,10.704791,7.7233834,0.0,0,2.0174882,0.0,0.72323459,66.109695,2.3060658,467.09937,-9.2012959
2769,2769,212.0781,10.715569,7.7445784,0.0,0,2.002212,0.0,0.72505814,66.054375,2.2926505,467.10953,-9.2018528
2770,2770,212.0783,10.731997,7.7526498,0.0,0,1.986936,0.0,0.7274121,66.000954,2.2778041,467.11966,-9.2018948
2771,2771,212.0785,10.760683,7.7709937,0.0,0,1.9716599,0.0,0.72982591,66.021095,2.2582817,467.12982,-9.2023067
2772,2772,212.0787,10.791416,7.7934055,0.0,0,1.9563839,0.0,0.73166496,66.116974,2.2420921,467.13995,-9.2022963
2773,2773,212.0789,10.83124,7.8013921,0.0,0,1.941108,0.0,0.73388457,66.194458,2.2280121,467.15012,-9.2018394
2774,2774,212.0791,10.874224,7.8195572,0.0,0,1.9261372,0.0,0.73674309,66.191528,2.2099698,467.16025,-9.20226
2775,2775,212.0793,10.916141,7.843802,0.0,0,1.9115354,0.0,0.73875666,66.317574,2.1946585,467.17041,-9.2023449
2776,2776,212.0795,10.946134,7.8516822,0.0,0,1.8970003,0.0,0.7407276,66.394203,2.1804228,467.18054,-9.2019053
2777,2777,212.0797,10.963887,7.8686051,0.0,0,1.8824683,0.0,0.74371392,66.308563,2.1632984,467.1907,-9.2015972
2778,2778,212.0799,10.985347,7.8930578,0.0,0,1.8679363,0.0,0.74580014,66.309937,2.1481261,467.20084,-9.2014952
2779,2779,212.0801,11.002919,7.9010496,0.0,0,1.8534042,0.0,0.74749196,66.304085,2.1329389,467.21097,-9.2018776
2780,2780,212.0803,11.023572,7.9160056,0.0,0,1.8388723,0.0,0.75045586,66.22654,2.1154778,467.22113,-9.2025099
2781,2781,212.0805,11.057149,7.939218,0.0,0,1.8243402,0.0,0.7525546,66.275101,2.1003778,467.23126,-9.2029209
2782,2782,212.0807,11.091918,7.9472733,0.0,0,1.8098083,0.0,0.75383079,66.386429,2.0833948,467.24142,-9.2024345
2783,2783,212.0809,11.129254,7.9614162,0.0,0,1.7952763,0.0,0.75682509,66.40049,2.0672741,467.25156,-9.2014446
2784,2784,212.0811,11.168167,7.9855242,0.0,0,1.7807442,0.0,0.75916815,66.491844,2.0544953,467.26172,-9.2014418
2785,2785,212.0813,11.204869,7.9956303,0.0,0,1.7662122,0.0,0.76040947,66.662941,2.0393229,467.27185,-9.2017508
2786,2786,212.0815,11.234076,8.0087156,0.0,0,1.7516803,0.0,0.76347435,66.664246,2.0226543,467.28201,-9.2013941
2787,2787,212.0817,11.258886,8.0317955,0.0,0,1.7371483,0.0,0.76612854,66.628471,2.0043485,467.29214,-9.2008419
2788,2788,212.0819,11.28336,8.044219,0.0,0,1.7226163,0.0,0.76733798,66.638222,1.9899533,467.30231,-9.2005787
2789,2789,212.0821,11.298169,8.0562716,0.0,0,1.7080842,0.0,0.77033663,66.540489,1.9769393,467.31244,-9.200778
2790,2790,212.0823,11.317279,8.0771637,0.0,0,1.6935523,0.0,0.77316076,66.50782,1.9614376,467.32257,-9.2014103
2791,2791,212.0825,11.348559,8.090663,0.0,0,1.6790203,0.0,0.77412921,66.6231,1.945931,467.33273,-9.2019138
2792,2792,212.0827,11.389235,8.1013031,0.0,0,1.6644882,0.0,0.77661389,66.668365,1.9295764,467.34286,-9.2021599
2793,2793,212.0829,11.430593,8.1201334,0.0,0,1.6499562,0.0,0.77948773,66.721588,1.9147609,467.35303,-9.2021723
2794,2794,212.0831,11.476418,8.1357899,0.0,0,1.6354243,0.0,0.78070664,66.905739,1.8992298,467.36316,-9.2018757
2795,2795,212.0833,11.523119,8.1477661,0.0,0,1.6208922,0.0,0.7832498,66.979187,1.8819863,467.37332,-9.201602
2796,2796,212.0835,11.54917,8.1650419,0.0,0,1.6063603,0.0,0.78625476,66.964828,1.8666571,467.38345,-9.201581
2797,2797,212.0837,11.567513,8.1818542,0.0,0,1.5918282,0.0,0.78743213,67.004219,1.851783,467.39362,-9.2013168
2798,2798,212.0839,11.582525,8.1949034,0.0,0,1.5772963,0.0,0.78983957,66.949669,1.8354499,467.40375,-9.2018843
2799,2799,212.0841,11.59983,8.2110138,0.0,0,1.5630547,0.0,0.79311913,66.83075,1.8194097,467.41391,-9.202445
2800,2800,212.0843,11.629824,8.2298784,0.0,0,1.5491643,0.0,0.79456991,66.839165,1.8036923,467.42404,-9.2020102
2801,2801,212.0845,11.667088,8.2430468,0.0,0,1.5353372,0.0,0.79668778,66.892853,1.790719,467.43417,-9.2020073
2802,2802,212.0847,11.711908,8.254611,0.0,0,1.5215131,0.0,0.79970485,66.949684,1.7769412,467.44434,-9.201602
2803,2803,212.0849,11.756915,8.2732544,0.0,0,1.5076891,0.0,0.80126548,67.103325,1.7601377,467.45447,-9.2015533
2804,2804,212.0851,11.798736,8.2879066,0.0,0,1.4938651,0.0,0.80323374,67.247643,1.7449411,467.46463,-9.2012539
2805,2805,212.0853,11.83795,8.2969561,0.0,0,1.4800411,0.0,0.80599731,67.316978,1.72824,467.47476,-9.200654
2806,2806,212.0855,11.869041,8.3157148,0.0,0,1.4662172,0.0,0.80777359,67.375572,1.7126921,467.48492,-9.2006884
2807,2807,212.0857,11.891416,8.3322506,0.0,0,1.4523932,0.0,0.80962753,67.37957,1.6991117,467.49506,-9.2012043
2808,2808,212.0859,11.917556,8.3405581,0.0,0,1.4385692,0.0,0.81242734,67.317451,1.6850755,467.50522,-9.2017736
2809,2809,212.0861,11.945954,8.361042,0.0,0,1.4247452,0.0,0.81475812,67.329376,1.6712159,467.51535,-9.2012663
2810,2810,212.0863,11.966852,8.38134,0.0,0,1.4109212,0.0,0.81670612,67.368568,1.6583841,467.52551,-9.2013779
2811,2811,212.0865,12.003989,8.3887625,0.0,0,1.3970972,0.0,0.81934917,67.352554,1.6447649,467.53564,-9.2019844
2812,2812,212.0867,12.052916,8.4067755,0.0,0,1.3832732,0.0,0.82186824,67.352142,1.6308126,467.54578,-9.2018242
2813,2813,212.0869,12.093785,8.4280615,0.0,0,1.3694493,0.0,0.82375658,67.481583,1.6157775,467.55594,-9.2018967
2814,2814,212.0871,12.135627,8.4337912,0.0,0,1.3556252,0.0,0.82593137,67.63443,1.5983944,467.56607,-9.2019186
2815,2815,212.0873,12.177771,8.4488659,0.0,0,1.3418012,0.0,0.82851219,67.649948,1.5812626,467.57623,-9.2017593
2816,2816,212.0875,12.204396,8.4699717,0.0,0,1.3279773,0.0,0.83013594,67.651161,1.567481,467.58636,-9.2013092
2817,2817,212.0877,12.224741,8.4750814,0.0,0,1.3141533,0.0,0.83192486,67.682243,1.554662,467.42932,-9.2011843
2818,2818,212.0879,12.245237,8.4896965,0.0,0,1.3003292,0.0,0.83488357,67.643677,1.5403544,467.20059,-9.2009172
2819,2819,212.0881,12.275511,8.512023,0.0,0,1.2865052,0.0,0.83681583,67.67971,1.5274041,466.97189,-9.2003469
2820,2820,212.0883,12.322573,8.5177946,0.0,0,1.2726812,0.0,0.83847946,67.780754,1.513914,466.74319,-9.1997681
2821,2821,212.0885,12.36493,8.5315542,0.0,0,1.2588573,0.0,0.84156811,67.794525,1.4976299,466.51447,-9.1997519
2822,2822,212.0887,12.409231,8.5543766,0.0,0,1.2450333,0.0,0.84357685,67.920395,1.4829503,466.28577,-9.2000113
2823,2823,212.0889,12.464245,8.5616655,0.0,0,1.2312093,0.0,0.84492898,68.115181,1.4682256,466.05707,-9.2002239
2824,2824,212.0891,12.512709,8.5752344,0.0,0,1.2176626,0.0,0.84819925,68.161301,1.4536983,465.82834,-9.2005062
2825,2825,212.0893,12.554116,8.5993137,0.0,0,1.2044512,0.0,0.85068226,68.22834,1.4400887,465.59964,-9.2004204
2826,2826,212.0895,12.590087,8.608634,0.0,0,1.1913005,0.0,0.8520304,68.329781,1.4251294,465.37094,-9.2004166
2827,2827,212.0897,12.615183,8.6206942,0.0,0,1.1781523,0.0,0.85528022,68.260406,1.4103706,465.14221,-9.2003622
2828,2828,212.0899,12.640088,8.642539,0.0,0,1.1650044,0.0,0.85788023,68.189568,1.3938386,464.91351,-9.2003918
2829,2829,212.0901,12.669354,8.6520157,0.0,0,1.1518563,0.0,0.85878593,68.257889,1.378352,464.68481,-9.2003393
2830,2830,212.0903,12.70184,8.662426,0.0,0,1.1387082,0.0,0.86175764,68.257446,1.3660312,464.45609,-9.2004566
2831,2831,212.0905,12.744257,8.6821003,0.0,0,1.1255603,0.0,0.86449814,68.313599,1.3538613,464.22739,-9.2004585
2832,2832,212.0907,12.791595,8.6931753,0.0,0,1.1124123,0.0,0.86529672,68.521561,1.3418181,463.99869,-9.2003069
2833,2833,212.0909,12.84489,8.7032661,0.0,0,1.0992643,0.0,0.86808515,68.588036,1.3269602,463.76996,-9.1997271
2834,2834,212.0911,12.891022,8.7222023,0.0,0,1.0861163,0.0,0.87109202,68.646057,1.3105533,463.54126,-9.1997232
2835,2835,212.0913,12.925305,8.7361355,0.0,0,1.0729682,0.0,0.87201005,68.799217,1.2967159,463.31256,-9.2002935
2836,2836,212.0915,12.953926,8.7472582,0.0,0,1.0598202,0.0,0.87474388,68.729156,1.2818019,463.08383,-9.2003193
2837,2837,212.0917,12.976755,8.7637968,0.0,0,1.0466722,0.0,0.87797379,68.607979,1.2653023,462.85513,-9.2000694
2838,2838,212.0919,13.010585,8.7780447,0.0,0,1.0335243,0.0,0.87900281,68.752678,1.2523782,462.62643,-9.2005138
2839,2839,212.0921,13.050984,8.7897434,0.0,0,1.0203762,0.0,0.88151777,68.814621,1.2384666,462.39771,-9.2007875
2840,2840,212.0923,13.0937,8.8050728,0.0,0,1.0072283,0.0,0.88482952,68.779167,1.2230933,462.16901,-9.1997881
2841,2841,212.0925,13.138217,8.8218346,0.0,0,0.99408025,0.0,0.88600737,68.920837,1.2090002,461.94031,-9.198741
2842,2842,212.0927,13.187739,8.8334007,0.0,0,0.98093224,0.0,0.88813549,69.047302,1.1963974,461.71158,-9.1984835
2843,2843,212.0929,13.243279,8.8440075,0.0,0,0.96778423,0.0,0.89125866,69.126358,1.1859852,461.48288,-9.1990843
2844,2844,212.0931,13.29545,8.8606405,0.0,0,0.95463622,0.0,0.89256728,69.276451,1.171196,461.25418,-9.2003679
2845,2845,212.0933,13.335962,8.8741388,0.0,0,0.94148827,0.0,0.89448726,69.336708,1.1538925,461.02545,-9.201355
2846,2846,212.0935,13.36565,8.8838367,0.0,0,0.92834032,0.0,0.89768207,69.274185,1.1398962,460.79675,-9.2016335
2847,2847,212.0937,13.395241,8.9026279,0.0,0,0.91519231,0.0,0.89953876,69.3246,1.1268736,460.56805,-9.2014647
2848,2848,212.0939,13.430752,8.9180365,0.0,0,0.9020443,0.0,0.90144318,69.401566,1.1136742,460.33932,-9.2013454
2849,2849,212.0941,13.464425,8.9254627,0.0,0,0.88916039,0.0,0.90446287,69.397057,1.1025817,460.11063,-9.201251
2850,2850,212.0943,13.501869,8.9437304,0.0,0,0.87659597,0.0,0.9065724,69.425713,1.090937,459.88193,-9.2006159
2851,2851,212.0945,13.54968,8.9605198,0.0,0,0.86408937,0.0,0.9082967,69.501244,1.0762213,459.6532,-9.2001104
2852,2852,212.0947,13.599811,8.9663258,0.0,0,0.85158527,0.0,0.910909,69.554329,1.0598459,459.4245,-9.2000818
2853,2853,212.0949,13.654756,8.9824562,0.0,0,0.83908123,0.0,0.91318393,69.665794,1.0461613,459.1958,-9.2002439
2854,2854,212.0951,13.707727,9.0004492,0.0,0,0.82657719,0.0,0.91477513,69.847473,1.0341433,458.96707,-9.2002993
2855,2855,212.0953,13.749807,9.0052328,0.0,0,0.8140732,0.0,0.91714603,69.907265,1.0200014,458.73837,-9.2003584
2856,2856,212.0955,13.783588,9.0213089,0.0,0,0.80156928,0.0,0.91991925,69.858376,1.0041702,458.50967,-9.2008953
2857,2857,212.0957,13.822342,9.041749,0.0,0,0.78906524,0.0,0.92165977,69.894577,0.9911713,458.28094,-9.2008953
2858,2858,212.0959,13.863691,9.0454273,0.0,0,0.77656126,0.0,0.92360032,70.003372,0.97893292,458.05225,-9.2003002
2859,2859,212.0961,13.906733,9.0590696,0.0,0,0.76405728,0.0,0.92642629,70.050987,0.96429253,457.82355,-9.2001314
2860,2860,212.0963,13.956091,9.0800772,0.0,0,0.75155324,0.0,0.92831683,70.134682,0.95105845,457.59482,-9.2003412
2861,2861,212.0965,14.000976,9.085,0.0,0,0.73904926,0.0,0.93010312,70.254852,0.93886435,457.36612,-9.2007685
2862,2862,212.0967,14.052732,9.0984316,0.0,0,0.72654527,0.0,0.93325073,70.298958,0.92392039,457.13742,-9.2005892
2863,2863,212.0969,14.108979,9.1202698,0.0,0,0.71404123,0.0,0.93524998,70.452293,0.91172481,456.90869,-9.1997242
2864,2864,212.0971,14.16519,9.1256351,0.0,0,0.70153725,0.0,0.93675959,70.631081,0.89924997,456.67999,-9.1996803
2865,2865,212.0973,14.21825,9.1382084,0.0,0,0.68903327,0.0,0.94021815,70.621452,0.88496608,456.45129,-9.1997881
2866,2866,212.0975,14.254533,9.1609421,0.0,0,0.67652929,0.0,0.94251174,70.660522,0.87171167,456.22256,-9.1992188
2867,2867,212.0977,14.286227,9.1670866,0.0,0,0.66402531,0.0,0.94361091,70.742126,0.85685647,456.13861,-9.1997843
2868,2868,212.0979,14.321868,9.1773415,0.0,0,0.65152127,0.0,0.94691694,70.695961,0.84309578,456.15115,-9.2004519
2869,2869,212.0981,14.363803,9.1995106,0.0,0,0.63901722,0.0,0.94949621,70.72541,0.8300516,456.1637,-9.2003727
2870,2870,212.0983,14.406777,9.2082396,0.0,0,0.62651324,0.0,0.95037472,70.882866,0.81504488,456.17624,-9.200386
2871,2871,212.0985,14.449631,9.2177782,0.0,0,0.61400926,0.0,0.95357138,70.878098,0.80290252,456.18875,-9.1999731
2872,2872,212.0987,14.503589,9.2374458,0.0,0,0.60150528,0.0,0.95636815,70.933365,0.79174352,456.20129,-9.1991329
2873,2873,212.0989,14.557865,9.2467833,0.0,0,0.58900124,0.0,0.95700097,71.138657,0.77731836,456.21384,-9.1987638
2874,2874,212.0991,14.611403,9.2548876,0.0,0,0.57674497,0.0,0.95985049,71.171356,0.76205844,456.22635,-9.1987343
2875,2875,212.0993,14.667024,9.2723875,0.0,0,0.56478834,0.0,0.96287435,71.229599,0.7492013,456.23889,-9.1987085
2876,2876,212.0995,14.712765,9.284337,0.0,0,0.55288589,0.0,0.96370912,71.396477,0.73752284,456.25143,-9.1983976
2877,2877,212.0997,14.743051,9.2930784,0.0,0,0.54098582,0.0,0.96634007,71.388786,0.72419155,456.26395,-9.1983957
2878,2878,212.0999,14.774775,9.308897,0.0,0,0.52908581,0.0,0.96951562,71.321472,0.71090573,456.27649,-9.1987133
2879,2879,212.1001,14.818358,9.3226433,0.0,0,0.51718581,0.0,0.97042823,71.437531,0.6976552,456.28903,-9.1990881
2880,2880,212.1003,14.867913,9.3323946,0.0,0,0.5052858,0.0,0.97295702,71.500038,0.68551654,456.30157,-9.2001772
2881,2881,212.1005,14.928675,9.346673,0.0,0,0.49338579,0.0,0.97643346,71.53315,0.67216802,456.31409,-9.2006922
2882,2882,212.1007,14.989902,9.3620501,0.0,0,0.48148578,0.0,0.9775179,71.743027,0.659141,456.32663,-9.2006817
2883,2883,212.1009,15.047168,9.372263,0.0,0,0.46958581,0.0,0.97968841,71.878769,0.64587504,456.33917,-9.2008181
2884,2884,212.1011,15.109096,9.3834133,0.0,0,0.4576858,0.0,0.98299962,71.931885,0.62970954,456.35168,-9.2010612
2885,2885,212.1013,15.163278,9.3987036,0.0,0,0.44578579,0.0,0.9842658,72.074921,0.6179629,456.36423,-9.2008591
2886,2886,212.1015,15.20374,9.4095507,0.0,0,0.43388578,0.0,0.98612231,72.122536,0.60783082,456.37677,-9.1990471
2887,2887,212.1017,15.239418,9.4185715,0.0,0,0.42198581,0.0,0.98926651,72.081459,0.59355372,456.38928,-9.1982145
2888,2888,212.1019,15.278303,9.4352713,0.0,0,0.4100858,0.0,0.9908129,72.157661,0.58115494,456.40182,-9.1987095