File: clean data/testID_0238.csv
level_0,index,Time(sec),Force(kN),Jaw(mm),PowAngle(deg),Power(W),Pram,PTemp,Strain,Stress(MPa),Stroke(mm),TC1(C),wedge(mm)
2442,2442,212.0112,0.49706507,0.015755629,0.0,0,8.9459143,0.0,0.0011265185,5.8909249,9.9451141,500.17419,-9.2109165
2443,2443,212.0114,0.95038056,0.028846215,0.0,0,8.9166498,0.0,0.001535838,10.597557,9.9030085,500.17776,-9.2108259
2444,2444,212.0116,1.7593372,0.059847001,0.0,0,8.8873854,0.0,0.0035562951,20.021589,9.8674698,500.18134,-9.2106867
2445,2445,212.0118,2.6776853,0.097417295,0.0,0,8.8581219,0.0,0.0062026805,31.57789,9.8358936,500.18491,-9.2108297
2446,2446,212.012,3.4644821,0.12357024,0.0,0,8.8288574,0.0,0.0078762705,41.966602,9.8046484,500.18848,-9.21029
2447,2447,212.0122,3.9044864,0.14999661,0.0,0,8.7995939,0.0,0.0096846912,48.297028,9.7665119,500.19205,-9.2093754
2448,2448,212.0124,4.019146,0.19848987,0.0,0,8.7703295,0.0,0.012735886,50.409264,9.7180433,500.19562,-9.2080498
2449,2449,212.0126,3.9485734,0.27677765,0.0,0,8.7416534,0.0,0.017355334,49.618156,9.6682177,500.19919,-9.2072229
2450,2450,212.0128,3.8869588,0.36280617,0.0,0,8.7136869,0.0,0.023322886,48.34156,9.6127806,500.20276,-9.2068186
2451,2451,212.013,3.9023073,0.42837533,0.0,0,8.6858492,0.0,0.028399397,48.117298,9.5525227,500.20633,-9.2073402
2452,2452,212.0132,3.9177265,0.479137,0.0,0,8.6580172,0.0,0.031685226,48.311852,9.4912682,500.20993,-9.2077169
2453,2453,212.0134,3.8374672,0.53448957,0.0,0,8.6301851,0.0,0.035332549,47.470604,9.4285517,500.2135,-9.2071953
2454,2454,212.0136,3.764684,0.598239,0.0,0,8.6023531,0.0,0.040001381,46.169312,9.3710585,500.21707,-9.2084045
2455,2455,212.0138,3.9327841,0.65942359,0.0,0,8.5745211,0.0,0.044166237,47.291855,9.3185616,500.22064,-9.2091846
2456,2456,212.014,4.2231364,0.69408572,0.0,0,8.546689,0.0,0.046858221,50.682148,9.2667933,500.22421,-9.2085371
2457,2457,212.0142,4.2575178,0.70355505,0.0,0,8.518857,0.0,0.048117731,51.768105,9.219841,500.22778,-9.208375
2458,2458,212.0144,4.028739,0.72613108,0.0,0,8.491025,0.0,0.049249884,49.430538,9.1770573,500.23135,-9.2078333
2459,2459,212.0146,3.8106432,0.768466,0.0,0,8.4631929,0.0,0.051751152,46.495766,9.1359053,500.23492,-9.2079706
2460,2460,212.0148,3.7888083,0.8070178,0.0,0,8.4353609,0.0,0.054960396,45.553741,9.093977,500.23849,-9.2085028
2461,2461,212.015,3.9326446,0.83647621,0.0,0,8.4075289,0.0,0.05713103,46.927448,9.0534258,500.2421,-9.2080488
2462,2462,212.0152,4.0480475,0.85458994,0.0,0,8.3796968,0.0,0.058212303,48.394444,9.0176687,500.24567,-9.2078257
2463,2463,212.0154,4.1415086,0.87195748,0.0,0,8.3518648,0.0,0.059666902,49.425579,8.9829578,500.24924,-9.2075357
2464,2464,212.0156,4.3195038,0.91638231,0.0,0,8.3240328,0.0,0.062376481,51.279327,8.9467344,500.25281,-9.2076969
2465,2465,212.0158,4.4221754,0.97365642,0.0,0,8.2962008,0.0,0.065931357,52.604977,8.9070368,500.25638,-9.2084293
2466,2466,212.016,4.33287,1.0168921,0.0,0,8.2683687,0.0,0.069568723,51.759289,8.8651524,500.25995,-9.208456
2467,2467,212.0162,4.206152,1.060681,0.0,0,8.2405367,0.0,0.072844833,50.022175,8.8260736,500.26352,-9.2084789
2468,2468,212.0164,4.1348028,1.1056823,0.0,0,8.2127056,0.0,0.07562834,48.867683,8.786747,500.26709,-9.2085247
2469,2469,212.0166,4.136703,1.1411465,0.0,0,8.1848736,0.0,0.078514032,48.704712,8.7455997,500.27066,-9.2085257
2470,2470,212.0168,4.1756592,1.1839589,0.0,0,8.1570406,0.0,0.081755057,48.908333,8.7059259,500.27426,-9.2085257
2471,2471,212.017,4.1881871,1.2276018,0.0,0,8.1292095,0.0,0.084541105,48.987873,8.6680441,500.27783,-9.2090616
2472,2472,212.0172,4.2135048,1.2537948,0.0,0,8.1013775,0.0,0.086840443,49.111923,8.6323519,500.2814,-9.2090712
2473,2473,212.0174,4.3119278,1.2819611,0.0,0,8.0735445,0.0,0.089175843,49.968651,8.5977182,500.28497,-9.2083416
2474,2474,212.0176,4.3830767,1.3137981,0.0,0,8.0462675,0.0,0.091007888,50.879635,8.5666151,500.28854,-9.2077274
2475,2475,212.0178,4.3084397,1.3352358,0.0,0,8.0196619,0.0,0.092721514,50.263622,8.5351839,500.29211,-9.2071505
2476,2476,212.018,4.1584935,1.3634876,0.0,0,7.993176,0.0,0.095107689,48.467716,8.504631,500.29156,-9.2075043
2477,2477,212.0182,4.0955315,1.3946308,0.0,0,7.9666953,0.0,0.097027406,47.336246,8.4774752,500.28146,-9.208107
2478,2478,212.0184,4.1827874,1.4110382,0.0,0,7.9402156,0.0,0.098331146,47.990726,8.4506855,500.27133,-9.2084246
2479,2479,212.0186,4.3560586,1.4333233,0.0,0,7.9137354,0.0,0.10027251,49.824409,8.4232693,500.2612,-9.2085752
2480,2480,212.0188,4.4890442,1.4662007,0.0,0,7.8872552,0.0,0.10227822,51.379585,8.3966684,500.25107,-9.2079716
2481,2481,212.019,4.5155935,1.4920821,0.0,0,7.860775,0.0,0.10410562,51.831577,8.3702679,500.24094,-9.2073727
2482,2482,212.0192,4.4778605,1.5204421,0.0,0,7.8342953,0.0,0.10665864,51.386745,8.3441162,500.2308,-9.2071342
2483,2483,212.0194,4.418581,1.5535452,0.0,0,7.8078156,0.0,0.10895883,50.577549,8.3200073,500.2207,-9.2069597
2484,2484,212.0196,4.3777986,1.5798503,0.0,0,7.7813349,0.0,0.11066639,49.941959,8.2912331,500.21057,-9.2063971
2485,2485,212.0198,4.3572059,1.6101235,0.0,0,7.7548552,0.0,0.11318646,49.587444,8.2594528,500.20044,-9.2063637
2486,2486,212.02,4.3267202,1.6456494,0.0,0,7.728375,0.0,0.11581342,49.167751,8.2305336,500.19031,-9.2069168
2487,2487,212.0202,4.3147998,1.6687248,0.0,0,7.7018952,0.0,0.11738861,48.819763,8.2027016,500.18018,-9.2069454
2488,2488,212.0204,4.36303,1.6842107,0.0,0,7.675415,0.0,0.11897307,49.148865,8.1752348,500.17004,-9.2069607
2489,2489,212.0206,4.425005,1.7026901,0.0,0,7.6489348,0.0,0.12040494,49.856995,8.1469736,500.15994,-9.2071447
2490,2490,212.0208,4.4092231,1.721946,0.0,0,7.6224551,0.0,0.12137719,49.858421,8.1220608,500.14981,-9.2076187
2491,2491,212.021,4.3313932,1.7457169,0.0,0,7.5959754,0.0,0.12340043,48.937965,8.0988646,500.13968,-9.2078314
2492,2492,212.0212,4.2970824,1.7700511,0.0,0,7.5694952,0.0,0.12550277,48.276714,8.0765181,500.12955,-9.2080612
2493,2493,212.0214,4.3310199,1.7858676,0.0,0,7.543015,0.0,0.12640274,48.502037,8.0539055,500.11942,-9.2077913
2494,2494,212.0216,4.3948102,1.7980076,0.0,0,7.5165353,0.0,0.12746641,49.116364,8.0310659,500.10928,-9.2073641
2495,2495,212.0218,4.4367919,1.8140777,0.0,0,7.4900556,0.0,0.12888318,49.53788,8.0112705,500.09918,-9.2072897
2496,2496,212.022,4.4656763,1.8355862,0.0,0,7.4635754,0.0,0.13009144,49.82814,7.9907956,500.08905,-9.2070045
2497,2497,212.0222,4.5200944,1.8582339,0.0,0,7.4370952,0.0,0.13184737,50.306492,7.9697952,500.07892,-9.2064323
2498,2498,212.0224,4.563446,1.8794358,0.0,0,7.410615,0.0,0.13385695,50.742817,7.9493585,500.06879,-9.2062559
2499,2499,212.0226,4.5572071,1.9040982,0.0,0,7.384666,0.0,0.13533072,50.712536,7.9265056,500.05865,-9.2060528
2500,2500,212.0228,4.5163732,1.9291079,0.0,0,7.3593607,0.0,0.13711146,50.260853,7.9032021,500.04852,-9.2054968
2501,2501,212.023,4.4781895,1.9523208,0.0,0,7.3341718,0.0,0.13930951,49.646152,7.8813949,500.03842,-9.2061462
2502,2502,212.0232,4.4676557,1.9810443,0.0,0,7.3089876,0.0,0.14115383,49.333145,7.8604774,500.02829,-9.2068729
2503,2503,212.0234,4.4961214,2.0052776,0.0,0,7.2838035,0.0,0.14291878,49.566406,7.8384385,500.01816,-9.2070065
2504,2504,212.0236,4.5206857,2.020309,0.0,0,7.2586198,0.0,0.14470936,49.700855,7.8132706,500.00803,-9.2070236
2505,2505,212.0238,4.5161443,2.0421319,0.0,0,7.2334356,0.0,0.14607261,49.647873,7.7898598,499.99789,-9.2069035
2506,2506,212.024,4.4959111,2.0650325,0.0,0,7.2082515,0.0,0.14748091,49.448566,7.769392,499.98776,-9.2069035
2507,2507,212.0242,4.4846458,2.0796134,0.0,0,7.1830673,0.0,0.14920965,49.138897,7.7505355,499.97766,-9.2077866
2508,2508,212.0244,4.4880037,2.1002455,0.0,0,7.1578832,0.0,0.15067612,49.088314,7.7311015,499.96753,-9.2086039
2509,2509,212.0246,4.4871373,2.1206756,0.0,0,7.132699,0.0,0.15182376,49.079685,7.7117167,499.9574,-9.208457
2510,2510,212.0248,4.5138922,2.1310542,0.0,0,7.1075149,0.0,0.1531135,49.189415,7.6921,499.94727,-9.208189
2511,2511,212.025,4.5718756,2.1524186,0.0,0,7.0823312,0.0,0.15470476,49.698402,7.6738272,499.93713,-9.2073355
2512,2512,212.0252,4.6285305,2.1788423,0.0,0,7.0571475,0.0,0.1562607,50.287643,7.6543164,499.927,-9.2068081
2513,2513,212.0254,4.6736016,2.1930058,0.0,0,7.0319633,0.0,0.15785034,50.690819,7.6334977,499.91687,-9.2070026
2514,2514,212.0256,4.6821356,2.2143633,0.0,0,7.0067787,0.0,0.15959202,50.742073,7.6148462,499.90677,-9.2070112
2515,2515,212.0258,4.6534386,2.2414119,0.0,0,6.981595,0.0,0.16113691,50.443371,7.5935864,499.89664,-9.2072401
2516,2516,212.026,4.6333599,2.2585518,0.0,0,6.9564114,0.0,0.16286021,50.162174,7.572329,499.88651,-9.2074099
2517,2517,212.0262,4.6402431,2.2832093,0.0,0,6.9312272,0.0,0.16506,50.028255,7.554667,499.87637,-9.2078934
2518,2518,212.0264,4.6662674,2.3109136,0.0,0,6.9060431,0.0,0.16672155,50.16404,7.5327368,499.86624,-9.2077122
2519,2519,212.0266,4.6992283,2.3240733,0.0,0,6.8808589,0.0,0.1680218,50.51173,7.5096693,499.85611,-9.2075834
2520,2520,212.0268,4.7236648,2.3447318,0.0,0,6.8556757,0.0,0.16995093,50.753498,7.488462,499.84601,-9.2082424
2521,2521,212.027,4.7394795,2.3740673,0.0,0,6.8304915,0.0,0.17164308,50.886127,7.4671359,499.83588,-9.2077913
2522,2522,212.0272,4.7449956,2.3918617,0.0,0,6.8053074,0.0,0.17318511,50.847759,7.4442091,499.82574,-9.2076874
2523,2523,212.0274,4.7316785,2.4132109,0.0,0,6.7801232,0.0,0.17537734,50.581055,7.4212136,499.81561,-9.207716
2524,2524,212.0276,4.7117972,2.4393802,0.0,0,6.7554412,0.0,0.17702565,50.323788,7.4019246,499.80548,-9.2071323
2525,2525,212.0278,4.7157483,2.4535201,0.0,0,6.7313666,0.0,0.1781494,50.229431,7.3816004,499.79535,-9.2069845
2526,2526,212.028,4.7405968,2.4721847,0.0,0,6.7074018,0.0,0.18008089,50.312435,7.3595839,499.77512,-9.2070551
2527,2527,212.0282,4.7688665,2.4997156,0.0,0,6.6834412,0.0,0.18186304,50.537971,7.3381901,499.71436,-9.2070494
2528,2528,212.0284,4.8039603,2.5175292,0.0,0,6.6594815,0.0,0.18309674,50.866684,7.3152237,499.65359,-9.2070971
2529,2529,212.0286,4.8395619,2.536057,0.0,0,6.6355214,0.0,0.18514128,51.156342,7.2920642,499.59283,-9.2078028
2530,2530,212.0288,4.8704824,2.5616179,0.0,0,6.6115613,0.0,0.18699323,51.399467,7.2712526,499.53207,-9.208992
2531,2531,212.029,4.88132,2.5808511,0.0,0,6.5876012,0.0,0.18819289,51.482582,7.248867,499.47128,-9.2085485
2532,2532,212.0292,4.8623266,2.6022666,0.0,0,6.5636415,0.0,0.19034562,51.273426,7.2279391,499.41052,-9.2078085
2533,2533,212.0294,4.8415518,2.6295519,0.0,0,6.5396814,0.0,0.19250689,50.929291,7.2073832,499.34976,-9.2075691
2534,2534,212.0296,4.8533778,2.6498525,0.0,0,6.5157218,0.0,0.19381335,50.867393,7.1833167,499.289,-9.207613
2535,2535,212.0298,4.8925433,2.6695883,0.0,0,6.4917617,0.0,0.19572486,51.132957,7.160233,499.22824,-9.2083502
2536,2536,212.03,4.9316812,2.6938403,0.0,0,6.467802,0.0,0.1977295,51.462814,7.1381617,499.16748,-9.2079229
2537,2537,212.0302,4.9608254,2.7158663,0.0,0,6.4438419,0.0,0.19914532,51.750393,7.1123958,499.10672,-9.2075977
2538,2538,212.0304,4.9740953,2.7380762,0.0,0,6.4198813,0.0,0.20124277,51.756508,7.0879445,499.04596,-9.2078161
2539,2539,212.0306,4.984077,2.7628627,0.0,0,6.3959212,0.0,0.20342422,51.712799,7.065712,498.9852,-9.2080183
2540,2540,212.0308,4.9910631,2.7861657,0.0,0,6.3719611,0.0,0.20490356,51.772453,7.041832,498.92444,-9.2081022
2541,2541,212.031,5.0059476,2.8083515,0.0,0,6.3480015,0.0,0.20692262,51.87513,7.0180373,498.86368,-9.2075377
2542,2542,212.0312,5.0334377,2.8325133,0.0,0,6.3240414,0.0,0.20920546,51.976547,6.9953756,498.80292,-9.2072439
2543,2543,212.0314,5.0589142,2.858566,0.0,0,6.3000817,0.0,0.21087021,52.061138,6.97155,498.74216,-9.2074232
2544,2544,212.0316,5.085248,2.8823402,0.0,0,6.2761216,0.0,0.21287347,52.184101,6.9482446,498.6814,-9.2077847
2545,2545,212.0318,5.1020389,2.9035969,0.0,0,6.252162,0.0,0.21510176,52.306881,6.9253263,498.62064,-9.2081327
2546,2546,212.032,5.1105838,2.9311597,0.0,0,6.2282019,0.0,0.21683602,52.338593,6.8990092,498.55988,-9.2081652
2547,2547,212.0322,5.1187286,2.9585695,0.0,0,6.2042418,0.0,0.21898809,52.342892,6.8746305,498.49911,-9.2081747
2548,2548,212.0324,5.1229267,2.9800353,0.0,0,6.1802816,0.0,0.22143242,52.278515,6.8500133,498.43832,-9.2079544
2549,2549,212.0326,5.1279607,3.0064306,0.0,0,6.1568022,0.0,0.22326259,52.195221,6.8250866,498.37756,-9.2081461
2550,2550,212.0328,5.1487446,3.0303757,0.0,0,6.1339045,0.0,0.22505488,52.290489,6.8024287,498.3168,-9.2083845
2551,2551,212.033,5.1892848,3.0480864,0.0,0,6.1111116,0.0,0.22716933,52.563663,6.77666,498.25604,-9.2078171
2552,2552,212.0332,5.2219028,3.07548,0.0,0,6.0883236,0.0,0.22908562,52.839996,6.7505102,498.19528,-9.207427
2553,2553,212.0334,5.2279973,3.1022341,0.0,0,6.0655355,0.0,0.23096417,52.891369,6.7262115,498.13452,-9.2077494
2554,2554,212.0336,5.2220044,3.1190083,0.0,0,6.042748,0.0,0.23303512,52.745556,6.7010021,498.07376,-9.2076855
2555,2555,212.0338,5.2357593,3.145901,0.0,0,6.0199599,0.0,0.23507829,52.688843,6.6763449,498.013,-9.2080183
2556,2556,212.034,5.2527995,3.1765113,0.0,0,5.9971714,0.0,0.23713242,52.721355,6.6522064,497.95224,-9.2084904
2557,2557,212.0342,5.2622194,3.1961772,0.0,0,5.9743834,0.0,0.23933695,52.725536,6.626843,497.89148,-9.2083397
2558,2558,212.0344,5.2832484,3.2233682,0.0,0,5.9515953,0.0,0.2416219,52.762211,6.6031041,497.83072,-9.2083969
2559,2559,212.0346,5.3110881,3.2540698,0.0,0,5.9288073,0.0,0.24367234,52.925961,6.5772905,497.76996,-9.2088337
2560,2560,212.0348,5.3417563,3.2722125,0.0,0,5.9060197,0.0,0.24572526,53.174274,6.5499897,497.7092,-9.2087307
2561,2561,212.035,5.3718514,3.2984831,0.0,0,5.8832316,0.0,0.24808198,53.347412,6.5250783,497.64844,-9.2077303
2562,2562,212.0352,5.3889813,3.33075,0.0,0,5.8604436,0.0,0.25019452,53.398434,6.5014729,497.58768,-9.2071953
2563,2563,212.0354,5.3891282,3.3508875,0.0,0,5.8376555,0.0,0.25232279,53.287304,6.4769597,497.52692,-9.2072868
2564,2564,212.0356,5.3823705,3.3778741,0.0,0,5.814867,0.0,0.25497082,53.099651,6.4540029,497.46616,-9.2079954
2565,2565,212.0358,5.3803225,3.4095109,0.0,0,5.792079,0.0,0.25712401,52.997356,6.4287057,497.40536,-9.2087269
2566,2566,212.036,5.3933535,3.4269743,0.0,0,5.7692914,0.0,0.25891468,53.005733,6.4010501,497.3446,-9.2086096
2567,2567,212.0362,5.419064,3.4513724,0.0,0,5.7465034,0.0,0.26138809,53.097771,6.3763041,497.28384,-9.2084255
2568,2568,212.0364,5.4536157,3.48278,0.0,0,5.7237153,0.0,0.26353326,53.30941,6.3502474,497.22308,-9.2084293
2569,2569,212.0366,5.4945002,3.5016198,0.0,0,5.7009273,0.0,0.26529229,53.586609,6.3236637,497.16232,-9.2083721
2570,2570,212.0368,5.515275,3.5257154,0.0,0,5.6781397,0.0,0.26784489,53.734314,6.2980385,497.10156,-9.2084618
2571,2571,212.037,5.5110035,3.5567729,0.0,0,5.6553516,0.0,0.27004907,53.605453,6.273005,497.0408,-9.2078114
2572,2572,212.0372,5.5047359,3.5766549,0.0,0,5.6325636,0.0,0.27175578,53.403019,6.2469935,496.98004,-9.2072554
2573,2573,212.0374,5.5062652,3.6011436,0.0,0,5.6097751,0.0,0.27444032,53.232037,6.2209921,496.91928,-9.2071648
2574,2574,212.0376,5.519712,3.633194,0.0,0,5.5874414,0.0,0.27683455,53.213345,6.1947641,496.85852,-9.2075233
2575,2575,212.0378,5.5357728,3.6535008,0.0,0,5.5656581,0.0,0.2784279,53.339211,6.1705947,496.79776,-9.2076807
2576,2576,212.038,5.5647674,3.6757958,0.0,0,5.5439734,0.0,0.28098193,53.453899,6.1458511,496.73407,-9.2073183
2577,2577,212.0382,5.602634,3.7067058,0.0,0,5.5222936,0.0,0.28349519,53.712757,6.1202865,496.64413,-9.2078962
2578,2578,212.0384,5.6334858,3.7305026,0.0,0,5.5006132,0.0,0.28521368,53.883186,6.0964231,496.55417,-9.2085752
2579,2579,212.0386,5.6523952,3.7544076,0.0,0,5.4789333,0.0,0.28778479,53.855751,6.0718622,496.46423,-9.208765
2580,2580,212.0388,5.6588688,3.7838356,0.0,0,5.457253,0.0,0.2903823,53.856422,6.0462594,496.37427,-9.2088957
2581,2581,212.039,5.6559172,3.807364,0.0,0,5.4355731,0.0,0.29206771,53.740364,6.0182691,496.2843,-9.2087402
2582,2582,212.0392,5.6621008,3.8301284,0.0,0,5.4138932,0.0,0.29459196,53.648605,5.9920492,496.19437,-9.2086849
2583,2583,212.0394,5.6791449,3.8573079,0.0,0,5.3922133,0.0,0.29718959,53.682064,5.9684424,496.1044,-9.2086496
2584,2584,212.0396,5.7010736,3.8811269,0.0,0,5.370533,0.0,0.29872659,53.732639,5.9429855,496.01447,-9.2084389
2585,2585,212.0398,5.7249432,3.9038775,0.0,0,5.3488531,0.0,0.30104262,53.859943,5.9180565,495.9245,-9.2078199
2586,2586,212.04,5.7384281,3.9299099,0.0,0,5.3271732,0.0,0.3036426,53.936314,5.8915668,495.83456,-9.207118
2587,2587,212.0402,5.7541909,3.9560406,0.0,0,5.3054934,0.0,0.30544713,53.981964,5.8649769,495.7446,-9.2069902
2588,2588,212.0404,5.7809825,3.9801254,0.0,0,5.283813,0.0,0.30789244,54.078339,5.8419771,495.65466,-9.2073593
2589,2589,212.0406,5.7983279,4.0043893,0.0,0,5.2621331,0.0,0.31054434,54.09568,5.8187013,495.5647,-9.2081156
2590,2590,212.0408,5.8092108,4.0310736,0.0,0,5.2404532,0.0,0.3123284,54.107857,5.7923937,495.47476,-9.2086754
2591,2591,212.041,5.8223028,4.0556064,0.0,0,5.2187734,0.0,0.31460238,54.091129,5.7662206,495.3848,-9.2083597
2592,2592,212.0412,5.8406444,4.0776815,0.0,0,5.1970935,0.0,0.31726411,54.044258,5.741086,495.29483,-9.2087574
2593,2593,212.0414,5.8562346,4.1043949,0.0,0,5.1754136,0.0,0.31917381,54.103508,5.7143784,495.2049,-9.2084208
2594,2594,212.0416,5.860373,4.1297207,0.0,0,5.1537333,0.0,0.32134965,54.058739,5.68927,495.11493,-9.2077036
2595,2595,212.0418,5.872746,4.1501322,0.0,0,5.1320534,0.0,0.32389501,54.016033,5.6673422,495.02499,-9.2085123
2596,2596,212.042,5.894166,4.1771102,0.0,0,5.110373,0.0,0.32592601,54.111351,5.6429133,494.93503,-9.2085791
2597,2597,212.0422,5.9121976,4.20294,0.0,0,5.0886931,0.0,0.32800186,54.160427,5.6188507,494.84509,-9.2077436
2598,2598,212.0424,5.9245296,4.2219214,0.0,0,5.0670133,0.0,0.33048439,54.189289,5.5949321,494.75513,-9.2070551
2599,2599,212.0426,5.9446416,4.2496071,0.0,0,5.0457678,0.0,0.33267534,54.242451,5.5678453,494.66519,-9.207015
2600,2600,212.0428,5.9637084,4.2769232,0.0,0,5.0250483,0.0,0.33474699,54.24155,5.5466075,494.57523,-9.2070494
2601,2601,212.043,5.9737425,4.29425,0.0,0,5.0044241,0.0,0.33717966,54.209309,5.5231905,494.48529,-9.2072163
2602,2602,212.0432,5.99119,4.320909,0.0,0,4.9838037,0.0,0.3394582,54.279434,5.4961982,494.39532,-9.2079163
2603,2603,212.0434,5.9966741,4.3502011,0.0,0,4.9631839,0.0,0.34155253,54.234619,5.472837,494.30536,-9.208478
2604,2604,212.0436,5.9886603,4.3669529,0.0,0,4.9425635,0.0,0.34388056,54.081451,5.4492364,494.21542,-9.2090683
2605,2605,212.0438,5.9972391,4.3914514,0.0,0,4.9219437,0.0,0.34617916,54.015903,5.4234929,494.12546,-9.2096777
2606,2606,212.044,6.0260344,4.4194045,0.0,0,4.9013238,0.0,0.34811029,54.11459,5.3989782,494.03552,-9.2095175
2607,2607,212.0442,6.0524025,4.4343672,0.0,0,4.8807039,0.0,0.35018101,54.292484,5.3790326,493.94556,-9.2089243
2608,2608,212.0444,6.0687132,4.458591,0.0,0,4.8600836,0.0,0.35258478,54.361633,5.358315,493.85562,-9.2078266
2609,2609,212.0446,6.088706,4.4884701,0.0,0,4.8394637,0.0,0.35458887,54.409809,5.3347769,493.76566,-9.2075891
2610,2610,212.0448,6.1052799,4.5035825,0.0,0,4.8188438,0.0,0.35657293,54.418827,5.310596,493.67572,-9.2076473
2611,2611,212.045,6.1171327,4.5264421,0.0,0,4.798224,0.0,0.35918796,54.391457,5.2863202,493.58575,-9.2064219
2612,2612,212.0452,6.120059,4.5570836,0.0,0,4.7776036,0.0,0.36135304,54.312481,5.2638717,493.49582,-9.2061186
2613,2613,212.0454,6.1242151,4.5741029,0.0,0,4.7569838,0.0,0.36328956,54.196404,5.2402434,493.40585,-9.2068577
2614,2614,212.0456,6.1352243,4.5973415,0.0,0,4.7363639,0.0,0.36599696,54.141579,5.2154408,493.31589,-9.2071848
2615,2615,212.0458,6.1503558,4.6274443,0.0,0,4.7157435,0.0,0.36813363,54.20557,5.1923304,493.22595,-9.207674
2616,2616,212.046,6.1747103,4.6436939,0.0,0,4.6951237,0.0,0.36981124,54.310421,5.1698523,493.13599,-9.2076807
2617,2617,212.0462,6.2063785,4.6654615,0.0,0,4.6745038,0.0,0.37252972,54.446045,5.1464496,493.04605,-9.2073431
2618,2618,212.0464,6.2313242,4.6952248,0.0,0,4.6538839,0.0,0.37479004,54.56823,5.1243892,492.95609,-9.2077351
2619,2619,212.0466,6.2442851,4.7119379,0.0,0,4.6332641,0.0,0.37634283,54.560642,5.1028805,492.86615,-9.2082787
2620,2620,212.0468,6.2444563,4.7309484,0.0,0,4.6126437,0.0,0.37887368,54.434448,5.0794034,492.77618,-9.2083807
2621,2621,212.047,6.2374701,4.7590995,0.0,0,4.5920234,0.0,0.38116631,54.240036,5.0582614,492.68625,-9.2083969
2622,2622,212.0472,6.2508388,4.7776852,0.0,0,4.5714035,0.0,0.3826825,54.191738,5.0362182,492.59628,-9.2087755
2623,2623,212.0474,6.2771912,4.7971439,0.0,0,4.5507836,0.0,0.38523746,54.268543,5.012825,492.50635,-9.2083282
2624,2624,212.0476,6.2976398,4.8237677,0.0,0,4.5305758,0.0,0.38766107,54.368073,4.9922004,492.41638,-9.2073116
2625,2625,212.0478,6.3184991,4.8424783,0.0,0,4.5108657,0.0,0.38906053,54.490379,4.9684038,492.32642,-9.2070265
2626,2626,212.048,6.3329768,4.8624063,0.0,0,4.4912457,0.0,0.3915678,54.485126,4.9456487,492.23648,-9.2070045
2627,2627,212.0482,6.3406487,4.8891768,0.0,0,4.4716296,0.0,0.39419562,54.396748,4.9259744,492.14828,-9.2074986
2628,2628,212.0484,6.3540363,4.9103971,0.0,0,4.4520135,0.0,0.39573511,54.421169,4.9046593,492.06009,-9.2079611
2629,2629,212.0486,6.364944,4.9301624,0.0,0,4.4323974,0.0,0.39816299,54.407566,4.8823729,491.97189,-9.2081909
2630,2630,212.0488,6.3760877,4.9549928,0.0,0,4.4127812,0.0,0.40080923,54.382145,4.8591881,491.8837,-9.2084141
2631,2631,212.049,6.396524,4.9765778,0.0,0,4.3931651,0.0,0.40233237,54.466194,4.8378282,491.7955,-9.2083759
2632,2632,212.0492,6.4124074,4.9946532,0.0,0,4.3735495,0.0,0.40463549,54.440933,4.8177576,491.70731,-9.2080059
2633,2633,212.0494,6.4243507,5.0166016,0.0,0,4.3539338,0.0,0.40718487,54.366817,4.7953515,491.61911,-9.2079945
2634,2634,212.0496,6.4329948,5.0395293,0.0,0,4.3343177,0.0,0.40867543,54.37706,4.7733979,491.53091,-9.2081861
2635,2635,212.0498,6.4400892,5.0590792,0.0,0,4.3147016,0.0,0.4108777,54.317524,4.7528243,491.44272,-9.2080755
2636,2636,212.05,6.446969,5.0792422,0.0,0,4.2950859,0.0,0.4134652,54.251534,4.7316256,491.35452,-9.2075949
2637,2637,212.0502,6.4584384,5.1032,0.0,0,4.2754693,0.0,0.4151018,54.289757,4.7102313,491.26633,-9.2069921
2638,2638,212.0504,6.4799666,5.1238489,0.0,0,4.2558532,0.0,0.41719353,54.345112,4.6897736,491.17813,-9.2072334
2639,2639,212.0506,6.5067496,5.1412253,0.0,0,4.236237,0.0,0.41972625,54.393768,4.6709929,491.08994,-9.2083721
2640,2640,212.0508,6.5313091,5.1649365,0.0,0,4.2166214,0.0,0.42140329,54.469109,4.6501255,491.00174,-9.2088661
2641,2641,212.051,6.5367193,5.1850538,0.0,0,4.1970053,0.0,0.42335629,54.45705,4.6273904,490.91354,-9.2082253
2642,2642,212.0512,6.5338831,5.1997614,0.0,0,4.1773891,0.0,0.42576039,54.362019,4.6055336,490.82535,-9.2076225
2643,2643,212.0514,6.5380988,5.2241507,0.0,0,4.1577735,0.0,0.42762873,54.30941,4.5861683,490.73715,-9.2073298
2644,2644,212.0516,6.5526319,5.2469535,0.0,0,4.1381574,0.0,0.42962965,54.285511,4.5674939,490.64896,-9.2077618
2645,2645,212.0518,6.5732808,5.2613392,0.0,0,4.1185412,0.0,0.43202233,54.308506,4.5485783,490.56076,-9.2075834
2646,2646,212.052,6.5946374,5.2856574,0.0,0,4.0989256,0.0,0.43408373,54.402889,4.527235,490.47256,-9.206996
2647,2647,212.0522,6.6202865,5.3089504,0.0,0,4.0793095,0.0,0.43594486,54.478848,4.5067296,490.38437,-9.2069664
2648,2648,212.0524,6.644762,5.3215709,0.0,0,4.0596933,0.0,0.43814573,54.475964,4.4864964,490.29614,-9.2071514
2649,2649,212.0526,6.6679449,5.3457756,0.0,0,4.0404716,0.0,0.44038391,54.526283,4.4645362,490.20795,-9.207159
2650,2650,212.0528,6.6848869,5.3715959,0.0,0,4.0217257,0.0,0.4423258,54.618225,4.4426455,490.11975,-9.207551
2651,2651,212.053,6.687675,5.3842578,0.0,0,4.0030656,0.0,0.44443151,54.566311,4.422914,490.03156,-9.2082949
2652,2652,212.0532,6.6850166,5.4064755,0.0,0,3.9844091,0.0,0.4467687,54.426243,4.4033909,489.94336,-9.2084827
2653,2653,212.0534,6.6863241,5.4324079,0.0,0,3.9657531,0.0,0.44866526,54.353474,4.3822031,489.85516,-9.2084551
2654,2654,212.0536,6.6950479,5.4444866,0.0,0,3.9470971,0.0,0.45062956,54.28281,4.3636484,489.76697,-9.2082672
2655,2655,212.0538,6.710433,5.4648871,0.0,0,3.928441,0.0,0.45303643,54.257366,4.3452282,489.67877,-9.2083111
2656,2656,212.054,6.7325215,5.49054,0.0,0,3.9097853,0.0,0.45484605,54.370861,4.3256173,489.59058,-9.2080393
2657,2657,212.0542,6.7564545,5.5018721,0.0,0,3.8911293,0.0,0.45659149,54.446014,4.306767,489.50238,-9.2074413
2658,2658,212.0544,6.7827883,5.5213919,0.0,0,3.8724732,0.0,0.45908237,54.493397,4.2861652,489.41418,-9.2078285
2659,2659,212.0546,6.7999935,5.5480504,0.0,0,3.8538172,0.0,0.46090063,54.585464,4.2658186,489.32599,-9.2075462
2660,2660,212.0548,6.8072944,5.5603762,0.0,0,3.8351612,0.0,0.46251965,54.581528,4.2476811,489.23779,-9.2074709
2661,2661,212.055,6.8152719,5.5789104,0.0,0,3.8165052,0.0,0.46516737,54.463608,4.2287207,489.1496,-9.2077618
2662,2662,212.0552,6.8221369,5.604722,0.0,0,3.7978492,0.0,0.46707767,54.406227,4.2102365,489.0614,-9.2071648
2663,2663,212.0554,6.8273897,5.6172137,0.0,0,3.7791932,0.0,0.46853265,54.408566,4.1909161,488.97321,-9.2069902
2664,2664,212.0556,6.8414702,5.6352434,0.0,0,3.7605371,0.0,0.47120604,54.391258,4.1715651,488.88501,-9.2071924
2665,2665,212.0558,6.8639174,5.6625423,0.0,0,3.7418811,0.0,0.47332433,54.421001,4.1524711,488.79681,-9.2072744
2666,2666,212.056,6.8858204,5.6770635,0.0,0,3.7232251,0.0,0.47476226,54.476707,4.1310205,488.70862,-9.2069378
2667,2667,212.0562,6.9101696,5.6938109,0.0,0,3.7045693,0.0,0.47745642,54.530773,4.1092029,488.62042,-9.2069092
2668,2668,212.0564,6.9305401,5.7206888,0.0,0,3.6859133,0.0,0.47983763,54.597004,4.0928912,488.53223,-9.2070255
2669,2669,212.0566,6.9412951,5.737411,0.0,0,3.6672573,0.0,0.48122647,54.623116,4.0757232,488.44403,-9.2069836
2670,2670,212.0568,6.9505501,5.753943,0.0,0,3.6486013,0.0,0.48377219,54.533436,4.0535278,488.35583,-9.2075081
2671,2671,212.057,6.9526715,5.7781672,0.0,0,3.629945,0.0,0.48619032,54.415043,4.0324626,488.26764,-9.2080822
2672,2672,212.0572,6.9591002,5.7940164,0.0,0,3.611289,0.0,0.48736757,54.396152,4.0146413,488.17944,-9.2081938
2673,2673,212.0574,6.9727793,5.8082185,0.0,0,3.5926332,0.0,0.48963219,54.39724,3.9962401,488.09125,-9.2078295
2674,2674,212.0576,6.9858608,5.8302569,0.0,0,3.5743496,0.0,0.49204603,54.408115,3.9767172,488.00305,-9.2074108
2675,2675,212.0578,7.0071521,5.8485842,0.0,0,3.5565164,0.0,0.49330014,54.486122,3.9585812,487.91486,-9.2071934
2676,2676,212.058,7.0355997,5.8646312,0.0,0,3.5387647,0.0,0.49559322,54.540588,3.9401424,487.82666,-9.2068224
2677,2677,212.0582,7.0546627,5.8859015,0.0,0,3.5210166,0.0,0.49818748,54.546768,3.9237535,487.72287,-9.2069559
2678,2678,212.0584,7.0722647,5.9051232,0.0,0,3.5032687,0.0,0.49952164,54.616081,3.9052658,487.61734,-9.2075367
2679,2679,212.0586,7.0945573,5.92169,0.0,0,3.4855206,0.0,0.50171912,54.637691,3.8826597,487.51184,-9.2074127
2680,2680,212.0588,7.1019444,5.9421229,0.0,0,3.4677725,0.0,0.50450236,54.532131,3.863193,487.40631,-9.2064533
2681,2681,212.059,7.107646,5.9639573,0.0,0,3.4500246,0.0,0.50610232,54.527115,3.8442233,487.30078,-9.2064342
2682,2682,212.0592,7.1199141,5.9816813,0.0,0,3.4322767,0.0,0.50825405,54.482658,3.8260767,487.19528,-9.2069616
2683,2683,212.0594,7.1298394,5.9987726,0.0,0,3.4145288,0.0,0.51081961,54.396843,3.8092558,487.08975,-9.2074289
2684,2684,212.0596,7.1409421,6.0190797,0.0,0,3.3967807,0.0,0.51224667,54.422974,3.7904053,486.98422,-9.2079868
2685,2685,212.0598,7.1570535,6.0361276,0.0,0,3.3790326,0.0,0.51419365,54.437122,3.7717204,486.87872,-9.2077408
2686,2686,212.06,7.1819167,6.0511527,0.0,0,3.3612847,0.0,0.51674694,54.498081,3.7556612,486.77319,-9.2072048
2687,2687,212.0602,7.2071991,6.0736766,0.0,0,3.3435366,0.0,0.51846445,54.607609,3.7373855,486.66766,-9.2069855
2688,2688,212.0604,7.2203393,6.0932732,0.0,0,3.3257885,0.0,0.52041751,54.621307,3.7164116,486.56213,-9.2066984
2689,2689,212.0606,7.2314849,6.1075435,0.0,0,3.3080406,0.0,0.52299786,54.593151,3.7001662,486.45663,-9.2066727
2690,2690,212.0608,7.2416053,6.1299868,0.0,0,3.2902927,0.0,0.52490258,54.576374,3.6820309,486.3511,-9.2069387
2691,2691,212.061,7.2568388,6.1511931,0.0,0,3.2725446,0.0,0.52682835,54.542934,3.6611686,486.24557,-9.2069855
2692,2692,212.0612,7.2651415,6.1646762,0.0,0,3.2547965,0.0,0.52936816,54.496632,3.6438441,486.14008,-9.2071772
2693,2693,212.0614,7.2727966,6.1868649,0.0,0,3.2370486,0.0,0.53142893,54.445229,3.6254449,486.03455,-9.2078648
2694,2694,212.0616,7.2964706,6.2089381,0.0,0,3.2193005,0.0,0.53321469,54.513802,3.6051958,485.92902,-9.2087173
2695,2695,212.0618,7.3236685,6.219779,0.0,0,3.2015524,0.0,0.53548205,54.588638,3.5863769,485.82352,-9.2087421
2696,2696,212.062,7.3461757,6.2398562,0.0,0,3.1838045,0.0,0.53764153,54.599403,3.5678411,485.71799,-9.2081652
2697,2697,212.0622,7.3673892,6.262146,0.0,0,3.1660566,0.0,0.53930748,54.655045,3.5524974,485.61246,-9.2074518
2698,2698,212.0624,7.3817248,6.2720075,0.0,0,3.1483085,0.0,0.54129314,54.665508,3.537349,485.50696,-9.2068834
2699,2699,212.0626,7.386199,6.2917752,0.0,0,3.1309149,0.0,0.54364401,54.591461,3.5164888,485.40143,-9.2068624
2700,2700,212.0628,7.3993955,6.3167892,0.0,0,3.1139498,0.0,0.54551983,54.568565,3.4974725,485.2959,-9.2074986
2701,2701,212.063,7.4125981,6.3282456,0.0,0,3.0970623,0.0,0.547557,54.555275,3.481967,485.1904,-9.2075224
2702,2702,212.0632,7.4241009,6.3477936,0.0,0,3.0801783,0.0,0.55019772,54.453964,3.4643745,485.08487,-9.2069893
2703,2703,212.0634,7.4385996,6.3730221,0.0,0,3.0632942,0.0,0.55212319,54.465767,3.4447062,484.97934,-9.2070103
2704,2704,212.0636,7.4506531,6.384129,0.0,0,3.0464103,0.0,0.55393153,54.47665,3.4250309,484.87384,-9.2070246
2705,2705,212.0638,7.4744124,6.403079,0.0,0,3.0295262,0.0,0.5566535,54.430164,3.4078805,484.76831,-9.2076683
2706,2706,212.064,7.5057859,6.4299746,0.0,0,3.0126421,0.0,0.55879527,54.546196,3.3879454,484.66278,-9.2076836
2707,2707,212.0642,7.5322094,6.4403181,0.0,0,2.9957583,0.0,0.5604673,54.67564,3.3677547,484.55725,-9.2077436
2708,2708,212.0644,7.5484328,6.4565783,0.0,0,2.9788742,0.0,0.56310648,54.678806,3.3493636,484.45175,-9.2084751
2709,2709,212.0646,7.5560737,6.4826245,0.0,0,2.9619904,0.0,0.56513178,54.629539,3.3332887,484.34622,-9.2077608
2710,2710,212.0648,7.5668817,6.4940395,0.0,0,2.9451063,0.0,0.56651813,54.607811,3.3185635,484.24069,-9.2073889
2711,2711,212.065,7.5755653,6.5097594,0.0,0,2.9282222,0.0,0.56926787,54.562767,3.3000054,484.13519,-9.2073708
2712,2712,212.0652,7.5864372,6.5349746,0.0,0,2.9113381,0.0,0.57151949,54.502686,3.2807004,484.02966,-9.2069664
2713,2713,212.0654,7.6051044,6.5479279,0.0,0,2.894454,0.0,0.57281595,54.530106,3.2625692,483.92413,-9.2063379
2714,2714,212.0656,7.6341949,6.5629244,0.0,0,2.8775702,0.0,0.57546991,54.58004,3.2445865,483.81863,-9.2057419
2715,2715,212.0658,7.6601682,6.5875392,0.0,0,2.8606861,0.0,0.57784629,54.652332,3.2274797,483.7131,-9.2056246
2716,2716,212.066,7.6773052,6.6019874,0.0,0,2.8438022,0.0,0.5791626,54.761871,3.2100713,483.60757,-9.2061462
2717,2717,212.0662,7.6987333,6.6170988,0.0,0,2.8269181,0.0,0.58183306,54.782421,3.1902044,483.50208,-9.206871
2718,2718,212.0664,7.7218919,6.6411753,0.0,0,2.810034,0.0,0.584405,54.78373,3.173384,483.39655,-9.2069731
2719,2719,212.0666,7.7379117,6.6572943,0.0,0,2.7931502,0.0,0.58569956,54.809807,3.1591156,483.29102,-9.2075253
2720,2720,212.0668,7.7494569,6.6726251,0.0,0,2.7762663,0.0,0.5883342,54.763691,3.1415899,483.18552,-9.2076139
2721,2721,212.067,7.7708521,6.6955447,0.0,0,2.7593822,0.0,0.5911532,54.770996,3.1231852,483.07999,-9.2072659
2722,2722,212.0672,7.7919722,6.7131596,0.0,0,2.7424982,0.0,0.59244734,54.847569,3.1050289,482.97446,-9.2071714
2723,2723,212.0674,7.8034115,6.7283635,0.0,0,2.7256143,0.0,0.595002,54.79073,3.0870373,482.86896,-9.2064161
2724,2724,212.0676,7.8117137,6.7501831,0.0,0,2.7090681,0.0,0.59792686,54.697403,3.0693657,482.76343,-9.2061882
2725,2725,212.0678,7.8333406,6.7687993,0.0,0,2.6929309,0.0,0.59922099,54.749096,3.0504797,482.6579,-9.2054529
2726,2726,212.068,7.8595839,6.7834821,0.0,0,2.6768675,0.0,0.60156286,54.788536,3.0318499,482.55237,-9.2048759
2727,2727,212.0682,7.8796387,6.8019557,0.0,0,2.6608074,0.0,0.60437888,54.810043,3.0146763,482.26343,-9.2052326
2728,2728,212.0684,7.8980393,6.821115,0.0,0,2.6447473,0.0,0.60574865,54.887737,2.998817,481.92862,-9.2057838
2729,2729,212.0686,7.9080381,6.8369141,0.0,0,2.6286871,0.0,0.60782522,54.833237,2.9795165,481.59384,-9.2061682
2730,2730,212.0688,7.9232411,6.852994,0.0,0,2.6126273,0.0,0.61054772,54.742443,2.9584916,481.25903,-9.2057104
2731,2731,212.069,7.9476094,6.8735313,0.0,0,2.5965672,0.0,0.61213928,54.815239,2.9424684,480.92422,-9.2055426
2732,2732,212.0692,7.9629927,6.890851,0.0,0,2.580507,0.0,0.61424541,54.840893,2.9250934,480.58942,-9.2056694
2733,2733,212.0694,7.9726176,6.9051371,0.0,0,2.5644472,0.0,0.61709213,54.739925,2.9077098,480.25464,-9.2063618
2734,2734,212.0696,7.9882584,6.9265347,0.0,0,2.5483871,0.0,0.61887228,54.723026,2.8927007,479.91983,-9.2069407
2735,2735,212.0698,8.0098696,6.9447308,0.0,0,2.5323269,0.0,0.62090707,54.797001,2.8760033,479.58502,-9.2069664
2736,2736,212.07,8.032196,6.9579468,0.0,0,2.5162671,0.0,0.62367469,54.825279,2.8591118,479.25021,-9.2069216
2737,2737,212.0702,8.0607777,6.9800639,0.0,0,2.5002072,0.0,0.6256572,54.85379,2.8406262,478.91544,-9.2069197
2738,2738,212.0704,8.0924673,6.9990463,0.0,0,2.4841471,0.0,0.62752634,54.957325,2.8234885,478.58063,-9.2062607
2739,2739,212.0706,8.1168165,7.0106015,0.0,0,2.4680872,0.0,0.63008898,54.967327,2.8061597,478.24582,-9.2056942
2740,2740,212.0708,8.1302166,7.0322881,0.0,0,2.4520271,0.0,0.63231725,54.944466,2.7868423,477.91101,-9.2062979
2741,2741,212.071,8.1323357,7.0542169,0.0,0,2.4359672,0.0,0.63414162,54.906338,2.7682865,477.57623,-9.2068624
2742,2742,212.0712,8.1386862,7.0647054,0.0,0,2.4199073,0.0,0.63656926,54.804604,2.7515314,477.24142,-9.2069607
2743,2743,212.0714,8.1561356,7.084188,0.0,0,2.4038472,0.0,0.63902301,54.79916,2.7343006,476.90662,-9.2068005
2744,2744,212.0716,8.1824827,7.1073675,0.0,0,2.3877871,0.0,0.64091033,54.844738,2.7149551,476.57181,-9.206255
2745,2745,212.0718,8.2113667,7.1179457,0.0,0,2.3717272,0.0,0.6431855,54.929752,2.6966615,476.237,-9.2060137
2746,2746,212.072,8.2344999,7.1377983,0.0,0,2.3556671,0.0,0.64584708,54.976688,2.6792343,475.90222,-9.2063303
2747,2747,212.0722,8.2597561,7.1622801,0.0,0,2.339607,0.0,0.64784509,54.99226,2.6609173,475.56741,-9.2067261
2748,2748,212.0724,8.2832317,7.1710334,0.0,0,2.3235471,0.0,0.64983022,55.021122,2.6430585,475.2326,-9.2069073
2749,2749,212.0726,8.2986479,7.1884165,0.0,0,2.3078086,0.0,0.65248942,54.997391,2.6279199,474.8978,-9.2066813
2750,2750,212.0728,8.313941,7.2124329,0.0,0,2.2924592,0.0,0.65438312,55.018044,2.6132278,474.56302,-9.2066927
2751,2751,212.073,8.3252916,7.2206917,0.0,0,2.2771802,0.0,0.65613425,55.002567,2.5955617,474.22821,-9.2069683
2752,2752,212.0732,8.3337908,7.2373648,0.0,0,2.261904,0.0,0.65900737,54.86705,2.578429,473.8934,-9.2069941
2753,2753,212.0734,8.3495646,7.2621698,0.0,0,2.2466278,0.0,0.66096401,54.838577,2.5633121,473.55859,-9.2070255
2754,2754,212.0736,8.3765049,7.2715249,0.0,0,2.2313521,0.0,0.6625129,54.925232,2.5467227,473.22382,-9.2065039
2755,2755,212.0738,8.4082251,7.2877293,0.0,0,2.2160761,0.0,0.66552758,54.972298,2.5270476,472.88901,-9.2063541
2756,2756,212.074,8.4415531,7.3128886,0.0,0,2.2008002,0.0,0.66757965,55.058025,2.5101686,472.5542,-9.2068062
2757,2757,212.0742,8.4669733,7.3237123,0.0,0,2.185524,0.0,0.66900241,55.167816,2.4944756,472.21939,-9.2062912
2758,2758,212.0744,8.4842024,7.3391771,0.0,0,2.170248,0.0,0.67207944,55.157761,2.4762871,471.88461,-9.2057352
2759,2759,212.0746,8.4966621,7.3645773,0.0,0,2.1549721,0.0,0.67446452,55.094795,2.4582419,471.5498,-9.2062893
2760,2760,212.0748,8.497571,7.3770957,0.0,0,2.1396961,0.0,0.67581218,55.081997,2.4409585,471.215,-9.2069235
2761,2761,212.075,8.5105715,7.3913231,0.0,0,2.1244199,0.0,0.67888492,54.995419,2.4251897,470.88019,-9.2069635
2762,2762,212.0752,8.5359354,7.415318,0.0,0,2.109144,0.0,0.68152553,54.911964,2.4082828,470.54541,-9.206274
2763,2763,212.0754,8.5513372,7.4291568,0.0,0,2.093868,0.0,0.68265247,54.953529,2.3918879,470.2106,-9.2056847
2764,2764,212.0756,8.5718489,7.4427409,0.0,0,2.0785921,0.0,0.68553644,54.945812,2.3755727,469.87579,-9.206501
2765,2765,212.0758,8.5992508,7.4648914,0.0,0,2.0633161,0.0,0.68827182,54.972214,2.3592379,469.54099,-9.2070799
2766,2766,212.076,8.626256,7.4795527,0.0,0,2.0480402,0.0,0.6893459,55.115063,2.3443978,469.20621,-9.206893
2767,2767,212.0762,8.6539545,7.491663,0.0,0,2.0327642,0.0,0.69191605,55.157742,2.3263843,468.8714,-9.2067366
2768,2768,212.0764,8.6719933,7.511447,0.0,0,2.0174882,0.0,0.69459713,55.135685,2.3088796,468.53659,-9.2067728
2769,2769,212.0766,8.6829557,7.5266495,0.0,0,2.002212,0.0,0.6956107,55.148598,2.2918832,468.20178,-9.2069826
2770,2770,212.0768,8.6945047,7.5385685,0.0,0,1.986936,0.0,0.69804978,55.053421,2.2745893,467.867,-9.2068529
2771,2771,212.077,8.7072868,7.5571685,0.0,0,1.9716599,0.0,0.70094335,54.946945,2.2599454,467.5322,-9.2067451
2772,2772,212.0772,8.7235422,7.5745969,0.0,0,1.9563839,0.0,0.70217472,55.028286,2.2434516,467.19739,-9.2067385
2773,2773,212.0774,8.7474718,7.5888829,0.0,0,1.941108,0.0,0.70455146,55.050518,2.2272136,466.86258,-9.2063656
2774,2774,212.0776,8.7801008,7.6062708,0.0,0,1.9261372,0.0,0.70764261,55.047901,2.2119584,466.52777,-9.2059727
2775,2775,212.0778,8.8149738,7.6248379,0.0,0,1.9115354,0.0,0.70909452,55.204292,2.1979673,466.19299,-9.2060022
2776,2776,212.078,8.8462133,7.6399016,0.0,0,1.8970003,0.0,0.71130711,55.27354,2.1808205,465.85818,-9.2064934
2777,2777,212.0782,8.8659754,7.6541638,0.0,0,1.8824683,0.0,0.7143302,55.248131,2.1610627,465.68509,-9.2068996
2778,2778,212.0784,8.8771505,7.6737094,0.0,0,1.8679363,0.0,0.71589082,55.236084,2.1448011,465.5813,-9.2062731
2779,2779,212.0786,8.8841619,7.6899166,0.0,0,1.8534042,0.0,0.71787995,55.173676,2.1307926,465.47751,-9.2062311
2780,2780,212.0788,8.8963032,7.7017832,0.0,0,1.8388723,0.0,0.72083139,55.080673,2.1154554,465.37372,-9.2067213
2781,2781,212.079,8.9127474,7.7217851,0.0,0,1.8243402,0.0,0.72263485,55.066544,2.1001177,465.26993,-9.2060547
2782,2782,212.0792,8.9267359,7.7379251,0.0,0,1.8098083,0.0,0.72443336,55.050297,2.0843229,465.16614,-9.205431
2783,2783,212.0794,8.9503899,7.7469497,0.0,0,1.7952763,0.0,0.72706813,55.046169,2.0670574,465.06235,-9.2051077
2784,2784,212.0796,8.9783201,7.7664275,0.0,0,1.7807442,0.0,0.72898775,55.107185,2.0525141,464.95856,-9.2057238
2785,2785,212.0798,9.0090303,7.7837491,0.0,0,1.7662122,0.0,0.73071319,55.185284,2.0390515,464.85477,-9.2061567
2786,2786,212.08,9.0402632,7.7915874,0.0,0,1.7516803,0.0,0.73317385,55.257404,2.0243306,464.75098,-9.2062016
2787,2787,212.0802,9.0571651,7.8104935,0.0,0,1.7371483,0.0,0.73521668,55.281124,2.0089693,464.64719,-9.2067852
2788,2788,212.0804,9.0680609,7.8302488,0.0,0,1.7226163,0.0,0.73690605,55.26025,1.9927617,464.5434,-9.2068968
2789,2789,212.0806,9.0799026,7.8381834,0.0,0,1.7080842,0.0,0.73935634,55.174316,1.9785326,464.43961,-9.206377
2790,2790,212.0808,9.0986452,7.8571725,0.0,0,1.6935523,0.0,0.7417345,55.13166,1.9659932,464.33582,-9.2063265
2791,2791,212.081,9.1226358,7.8788395,0.0,0,1.6790203,0.0,0.74359298,55.168133,1.9515885,464.23203,-9.2062712
2792,2792,212.0812,9.1440716,7.8865948,0.0,0,1.6644882,0.0,0.74597561,55.17186,1.9348029,464.12823,-9.2057972
2793,2793,212.0814,9.165225,7.9047732,0.0,0,1.6499562,0.0,0.74866945,55.160694,1.9180111,464.02444,-9.2056332
2794,2794,212.0816,9.1970844,7.927176,0.0,0,1.6354243,0.0,0.75047064,55.267044,1.9030898,463.92065,-9.2061148
2795,2795,212.0818,9.2339087,7.9334803,0.0,0,1.6208922,0.0,0.7523253,55.367233,1.8879938,463.81686,-9.2067881
2796,2796,212.082,9.2571707,7.9496145,0.0,0,1.6063603,0.0,0.755135,55.325829,1.8721681,463.71307,-9.2068272
2797,2797,212.0822,9.2673988,7.9737291,0.0,0,1.5918282,0.0,0.75712097,55.308861,1.8558216,463.60928,-9.2069082
2798,2798,212.0824,9.2816868,7.9814053,0.0,0,1.5772963,0.0,0.75891888,55.306892,1.8415837,463.50549,-9.2068052
2799,2799,212.0826,9.2948275,7.9968028,0.0,0,1.5630547,0.0,0.76202053,55.221596,1.8266152,463.4017,-9.2066469
2800,2800,212.0828,9.3056231,8.0205326,0.0,0,1.5491643,0.0,0.76404011,55.167385,1.8109137,463.29791,-9.2067633
2801,2801,212.083,9.3264236,8.0274515,0.0,0,1.5353372,0.0,0.76538038,55.197163,1.7964813,463.19412,-9.2061691
2802,2802,212.0832,9.3489161,8.0398836,0.0,0,1.5215131,0.0,0.76821071,55.202625,1.7838856,463.09033,-9.2059765
2803,2803,212.0834,9.3749466,8.0618238,0.0,0,1.5076891,0.0,0.77015358,55.245117,1.7694414,462.98654,-9.2060184
2804,2804,212.0836,9.4020157,8.0686588,0.0,0,1.4938651,0.0,0.77111846,55.324158,1.7523129,462.88275,-9.2052059
2805,2805,212.0838,9.4266748,8.0799007,0.0,0,1.4800411,0.0,0.77394849,55.304512,1.7351375,462.77896,-9.2056675
2806,2806,212.084,9.4493179,8.103302,0.0,0,1.4662172,0.0,0.77633047,55.334503,1.7202491,462.67517,-9.2063456
2807,2807,212.0842,9.4717979,8.1143379,0.0,0,1.4523932,0.0,0.77746844,55.39241,1.7079693,462.57138,-9.2065706
2808,2808,212.0844,9.4885311,8.1268826,0.0,0,1.4385692,0.0,0.78055745,55.309883,1.6940615,462.46759,-9.2069244
2809,2809,212.0846,9.5066013,8.1503344,0.0,0,1.4247452,0.0,0.78338957,55.256649,1.6774319,462.3638,-9.2069483
2810,2810,212.0848,9.5295725,8.1635275,0.0,0,1.4109212,0.0,0.78458643,55.310871,1.6608925,462.26001,-9.2069635
2811,2811,212.085,9.5580416,8.174881,0.0,0,1.3970972,0.0,0.78749347,55.334072,1.6486247,462.15622,-9.2069616
2812,2812,212.0852,9.5850058,8.1951017,0.0,0,1.3832732,0.0,0.79032063,55.31749,1.6351796,462.05243,-9.2069483
2813,2813,212.0854,9.6060076,8.2085581,0.0,0,1.3694493,0.0,0.79131198,55.383778,1.6200544,461.94864,-9.2059813
2814,2814,212.0856,9.6336069,8.2188005,0.0,0,1.3556252,0.0,0.79390383,55.401386,1.6049763,461.84485,-9.205162
2815,2815,212.0858,9.6597795,8.2369318,0.0,0,1.3418012,0.0,0.79675901,55.411064,1.5902439,461.74106,-9.2050829
2816,2816,212.086,9.6882277,8.2515364,0.0,0,1.3279773,0.0,0.7977019,55.543045,1.5762873,461.63727,-9.2051678
2817,2817,212.0862,9.7180672,8.2628603,0.0,0,1.3141533,0.0,0.8001157,55.574509,1.5622786,461.53348,-9.2052031
2818,2818,212.0864,9.7377501,8.2795248,0.0,0,1.3003292,0.0,0.80318028,55.538895,1.5479068,461.42969,-9.2051172
2819,2819,212.0866,9.7542362,8.295187,0.0,0,1.2865052,0.0,0.80433023,55.548496,1.5332294,461.3259,-9.2053375
2820,2820,212.0868,9.7677708,8.3069944,0.0,0,1.2726812,0.0,0.80656761,55.484203,1.519249,461.22211,-9.20502
2821,2821,212.087,9.7864237,8.3220119,0.0,0,1.2588573,0.0,0.80961162,55.444431,1.5059959,461.11832,-9.2056103
2822,2822,212.0872,9.8136482,8.3404627,0.0,0,1.2450333,0.0,0.81096941,55.530571,1.4905748,461.01453,-9.2060204
2823,2823,212.0874,9.8449411,8.3532486,0.0,0,1.2312093,0.0,0.81312484,55.549271,1.4765162,460.91074,-9.205492
2824,2824,212.0876,9.8753805,8.3648949,0.0,0,1.2176626,0.0,0.81616771,55.525433,1.4626751,460.80695,-9.2055283
2825,2825,212.0878,9.9024191,8.3827639,0.0,0,1.2044512,0.0,0.81759888,55.620388,1.4478742,460.70316,-9.2060652
2826,2826,212.088,9.9347782,8.3960419,0.0,0,1.1913005,0.0,0.81942201,55.731583,1.4334203,460.59937,-9.2061701
2827,2827,212.0882,9.9625635,8.4058008,0.0,0,1.1781523,0.0,0.82234639,55.732143,1.4176292,460.50586,-9.2061319
2828,2828,212.0884,9.9796219,8.4247417,0.0,0,1.1650044,0.0,0.82409114,55.716309,1.4048387,460.41919,-9.2059698
2829,2829,212.0886,9.999711,8.4403896,0.0,0,1.1518563,0.0,0.82597268,55.720856,1.3915923,460.33255,-9.205369
2830,2830,212.0888,10.020985,8.4494591,0.0,0,1.1387082,0.0,0.82895875,55.675549,1.3774636,460.24588,-9.2051954
2831,2831,212.089,10.041889,8.4690838,0.0,0,1.1255603,0.0,0.83113682,55.662216,1.3617214,460.15921,-9.2057791
2832,2832,212.0892,10.06587,8.4863625,0.0,0,1.1124123,0.0,0.83299261,55.692379,1.346702,460.07254,-9.205431
2833,2833,212.0894,10.09091,8.4933939,0.0,0,1.0992643,0.0,0.83560836,55.694153,1.3318367,459.9859,-9.2048779
2834,2834,212.0896,10.121801,8.5115652,0.0,0,1.0861163,0.0,0.83777606,55.74464,1.3170025,459.89923,-9.2048426
2835,2835,212.0898,10.154731,8.5296631,0.0,0,1.0729682,0.0,0.83943629,55.816143,1.3027567,459.81256,-9.2048225
2836,2836,212.09,10.184655,8.5350819,0.0,0,1.0598202,0.0,0.84177637,55.830753,1.2869238,459.72589,-9.2055092
2837,2837,212.0902,10.207582,8.5522137,0.0,0,1.0466722,0.0,0.84418696,55.842926,1.2725989,459.63925,-9.2054462
2838,2838,212.0904,10.229746,8.5725756,0.0,0,1.0335243,0.0,0.84593529,55.886639,1.2594337,459.55258,-9.2052794
2839,2839,212.0906,10.249565,8.578414,0.0,0,1.0203762,0.0,0.84819263,55.857361,1.2444403,459.46591,-9.2053862
2840,2840,212.0908,10.269512,8.5938921,0.0,0,1.0072283,0.0,0.85092497,55.838078,1.2277478,459.37924,-9.2053556
2841,2841,212.091,10.294438,8.6148062,0.0,0,0.99408025,0.0,0.85258144,55.890633,1.2148088,459.2926,-9.2050304
2842,2842,212.0912,10.316557,8.6199074,0.0,0,0.98093224,0.0,0.85441071,55.877079,1.2018856,459.20593,-9.2046051
2843,2843,212.0914,10.340162,8.6348581,0.0,0,0.96778423,0.0,0.85747939,55.827557,1.1883272,459.11926,-9.2047081
2844,2844,212.0916,10.375907,8.6575947,0.0,0,0.95463622,0.0,0.85938948,55.897663,1.1731946,459.03262,-9.204423
2845,2845,212.0918,10.413511,8.6628933,0.0,0,0.94148827,0.0,0.86097795,55.990253,1.1557053,458.94595,-9.2046061
2846,2846,212.092,10.441933,8.676034,0.0,0,0.92834032,0.0,0.86411488,56.008606,1.1435131,458.85928,-9.2057419
2847,2847,212.0922,10.466822,8.6985903,0.0,0,0.91519231,0.0,0.86613464,56.04137,1.1323127,458.77261,-9.2060137
2848,2848,212.0924,10.492876,8.7055607,0.0,0,0.9020443,0.0,0.86749911,56.082916,1.1170557,458.68597,-9.2059879
2849,2849,212.0926,10.514403,8.7182913,0.0,0,0.88916039,0.0,0.87068933,56.028416,1.101938,458.5993,-9.2061892
2850,2850,212.0928,10.53353,8.7414608,0.0,0,0.87659597,0.0,0.87303305,55.988335,1.0873873,458.51263,-9.2065887
2851,2851,212.093,10.55528,8.7502079,0.0,0,0.86408937,0.0,0.87440306,56.034111,1.0733433,458.42596,-9.2062435
2852,2852,212.0932,10.583872,8.7620821,0.0,0,0.85158527,0.0,0.8777439,56.003292,1.0596423,458.33932,-9.2055035
2853,2853,212.0934,10.612679,8.7844563,0.0,0,0.83908123,0.0,0.88025695,56.027325,1.0454918,458.25266,-9.2051516
2854,2854,212.0936,10.640653,8.7933226,0.0,0,0.82657719,0.0,0.88127178,56.117886,1.0325677,458.16599,-9.2049704
2855,2855,212.0938,10.676613,8.8026199,0.0,0,0.8140732,0.0,0.88426274,56.113842,1.0191274,458.07932,-9.2044992
2856,2856,212.094,10.704459,8.8227978,0.0,0,0.80156928,0.0,0.88682866,56.118969,1.0040518,457.99268,-9.2038879
2857,2857,212.0942,10.718562,8.8329735,0.0,0,0.78906524,0.0,0.8875823,56.150314,0.98966682,457.90601,-9.203845
2858,2858,212.0944,10.732882,8.8417759,0.0,0,0.77656126,0.0,0.89043182,56.08049,0.97533709,457.81934,-9.2040005
2859,2859,212.0946,10.745997,8.8609972,0.0,0,0.76405728,0.0,0.89329588,56.013081,0.96225983,457.73267,-9.2043343
2860,2860,212.0948,10.762729,8.8735971,0.0,0,0.75155324,0.0,0.89406735,56.033329,0.95002109,457.64603,-9.205472
2861,2861,212.095,10.789855,8.8825493,0.0,0,0.73904926,0.0,0.89685541,56.013065,0.93713349,457.55936,-9.206152
2862,2862,212.0952,10.823773,8.8997459,0.0,0,0.72654527,0.0,0.89998156,56.016083,0.92468214,457.47269,-9.2063475
2863,2863,212.0954,10.868801,8.9142284,0.0,0,0.71404123,0.0,0.90095502,56.15834,0.90979975,457.38602,-9.2061596
2864,2864,212.0956,10.905131,8.9244471,0.0,0,0.70153725,0.0,0.90361112,56.211185,0.89578825,457.29938,-9.2053003
2865,2865,212.0958,10.931449,8.941062,0.0,0,0.68903327,0.0,0.90699208,56.181435,0.88533902,457.21271,-9.2051888
2866,2866,212.096,10.965836,8.9579306,0.0,0,0.67652929,0.0,0.90819573,56.293915,0.87246239,457.12604,-9.2053356
2867,2867,212.0962,10.989393,8.9697514,0.0,0,0.66402531,0.0,0.91068369,56.300472,0.8558957,457.03937,-9.2048492
2868,2868,212.0964,11.007295,8.9838285,0.0,0,0.65152127,0.0,0.91403478,56.20314,0.8441866,456.95273,-9.2041254
2869,2869,212.0966,11.033421,8.999711,0.0,0,0.63901722,0.0,0.91520077,56.219017,0.83326137,456.86606,-9.2042418
2870,2870,212.0968,11.054628,9.0102081,0.0,0,0.62651324,0.0,0.91721082,56.215824,0.81786889,456.77939,-9.2044134
2871,2871,212.097,11.081399,9.020648,0.0,0,0.61400926,0.0,0.92037398,56.206703,0.80108696,456.69275,-9.2048244
2872,2872,212.0972,11.116164,9.0368376,0.0,0,0.60150528,0.0,0.92163771,56.275257,0.79022616,456.60608,-9.2059135
2873,2873,212.0974,11.151227,9.0486031,0.0,0,0.58900124,0.0,0.92327625,56.361797,0.77952754,456.51941,-9.2060156
2874,2874,212.0976,11.189027,9.0567322,0.0,0,0.57674497,0.0,0.92633224,56.377167,0.76343131,456.43274,-9.2055426
2875,2875,212.0978,11.221751,9.0743942,0.0,0,0.56478834,0.0,0.92820597,56.44936,0.74669254,456.3461,-9.204813
2876,2876,212.098,11.237977,9.0890493,0.0,0,0.55288589,0.0,0.93001878,56.452629,0.73241568,456.25943,-9.2047253
2877,2877,212.0982,11.249584,9.0965328,0.0,0,0.54098582,0.0,0.93301094,56.3288,0.72152203,456.20654,-9.2053623
2878,2878,212.0984,11.272723,9.1152515,0.0,0,0.52908581,0.0,0.93526793,56.301037,0.71003032,456.18744,-9.2051945
2879,2879,212.0986,11.297731,9.1318693,0.0,0,0.51718581,0.0,0.93712854,56.323757,0.69620878,456.16833,-9.2044563
2880,2880,212.0988,11.322015,9.137599,0.0,0,0.5052858,0.0,0.93993115,56.282688,0.68255782,456.14926,-9.2044134
2881,2881,212.099,11.345399,9.1547956,0.0,0,0.49338579,0.0,0.94227815,56.242867,0.67117041,456.13016,-9.2045364
2882,2882,212.0992,11.370706,9.1725044,0.0,0,0.48148578,0.0,0.94392538,56.290607,0.65875554,456.11105,-9.2040176
2883,2883,212.0994,11.412735,9.1767368,0.0,0,0.46958581,0.0,0.94634831,56.385475,0.6461609,456.09195,-9.2046547
2884,2884,212.0996,11.451086,9.192318,0.0,0,0.4576858,0.0,0.94889694,56.43227,0.63225102,456.07285,-9.2052603
2885,2885,212.0998,11.475559,9.2110348,0.0,0,0.44578579,0.0,0.95045286,56.464851,0.6183154,456.05374,-9.2052469
2886,2886,212.1,11.491815,9.2146378,0.0,0,0.43388578,0.0,0.9525705,56.457848,0.60639828,456.03464,-9.2052431
2887,2887,212.1002,11.510002,9.2280769,0.0,0,0.42198581,0.0,0.95540088,56.382221,0.592686,456.01556,-9.2052469
2888,2888,212.1004,11.53405,9.2478485,0.0,0,0.4100858,0.0,0.95696992,56.397316,0.58171421,455.99646,-9.2049255
2889,2889,212.1006,11.559332,9.2515202,0.0,0,0.39818579,0.0,0.9586705,56.407906,0.57123667,455.97736,-9.2047892