File: clean data/testID_0149.csv
level_0,index,Time(sec),Force(kN),Jaw(mm),PowAngle(deg),Power(W),Pram,PTemp,Strain,Stress(MPa),Stroke(mm),TC1(C),wedge(mm)
2184,2184,165.3909,0.69385934,0.028545592,0.0,0,9.7568636,0.0,0.0018536852,8.5747814,9.8422909,359.98016,-9.2863779
2195,2195,165.3931,1.807688,0.038969744,0.0,0,9.7238636,0.0,0.0027790309,22.80455,9.8155937,359.99353,-9.2848148
2206,2206,165.3953,2.8784652,0.055949848,0.0,0,9.6908636,0.0,0.0035188361,36.308605,9.7912817,360.01175,-9.2837429
2217,2217,165.3975,3.9109058,0.064467825,0.0,0,9.6578636,0.0,0.004387646,49.200489,9.7629471,360.07855,-9.2826538
2228,2228,165.3997,4.630302,0.090620302,0.0,0,9.6248636,0.0,0.0058559519,58.540363,9.7327623,360.14536,-9.2826147
2239,2239,165.4019,5.1746473,0.12219929,0.0,0,9.5918636,0.0,0.0082160868,65.153641,9.6956997,360.21216,-9.2837143
2250,2250,165.4041,5.5916929,0.16243944,0.0,0,9.5588636,0.0,0.010675782,70.334259,9.6567926,360.27896,-9.2832136
2261,2261,165.4063,5.9339933,0.19489066,0.0,0,9.5258636,0.0,0.013142884,74.55349,9.6137877,360.35687,-9.2822161
2272,2272,165.4085,6.1511621,0.23130183,0.0,0,9.4928637,0.0,0.015481029,77.131302,9.5789948,360.44373,-9.2816944
2283,2283,165.4107,6.3345246,0.26520854,0.0,0,9.4604025,0.0,0.017827287,79.331345,9.5386686,360.53058,-9.2810526
2294,2294,165.4129,6.4653153,0.30653259,0.0,0,9.4282112,0.0,0.020489043,80.617912,9.5074358,360.61743,-9.2824211
2305,2305,165.4151,6.5780888,0.33374938,0.0,0,9.3960209,0.0,0.022530334,81.793083,9.4717903,360.70343,-9.2810898
2316,2316,165.4173,6.6716361,0.36526778,0.0,0,9.3638315,0.0,0.024555635,82.883141,9.437232,360.7435,-9.2821217
2327,2327,165.4195,6.739934,0.39306742,0.0,0,9.3316412,0.0,0.026527965,83.547836,9.4050198,360.7836,-9.2825804
2338,2338,165.4217,6.8215537,0.42847693,0.0,0,9.2994499,0.0,0.02887813,84.299088,9.3753376,360.82367,-9.2818336
2349,2349,165.4239,6.8964272,0.45221427,0.0,0,9.2672586,0.0,0.03064248,85.128273,9.344861,360.86374,-9.283432
2360,2360,165.4261,6.9651313,0.48458537,0.0,0,9.2350683,0.0,0.032763861,85.766136,9.3122873,360.91672,-9.2833729
2371,2371,165.4283,7.0153384,0.51545477,0.0,0,9.202879,0.0,0.034917191,86.253777,9.2829933,360.98352,-9.2835541
2382,2382,165.4305,7.0679607,0.55369753,0.0,0,9.1706886,0.0,0.037530858,86.796814,9.2511568,361.05032,-9.2834692
2393,2393,165.4327,7.1100636,0.58294123,0.0,0,9.1384983,0.0,0.039559186,87.056854,9.2105341,361.11713,-9.2840614
2404,2404,165.4349,7.1599326,0.61522853,0.0,0,9.106307,0.0,0.041835137,87.409439,9.1808319,361.18393,-9.2845573
2415,2415,165.4371,7.2033625,0.64526439,0.0,0,9.0741167,0.0,0.043925468,87.793427,9.1440716,361.276,-9.284235
2426,2426,165.4393,7.246048,0.68195289,0.0,0,9.0419264,0.0,0.046526972,88.014183,9.1127377,361.36954,-9.2828293
2437,2437,165.4415,7.2812176,0.71145034,0.0,0,9.009737,0.0,0.048480153,88.389069,9.0820665,361.46307,-9.2831898
2448,2448,165.4437,7.3282247,0.74129182,0.0,0,8.9775457,0.0,0.05072695,88.684059,9.0504494,361.55661,-9.2832241
2459,2459,165.4459,7.3483801,0.77045447,0.0,0,8.9453554,0.0,0.05263431,88.851814,9.019371,361.61459,-9.2845354
2470,2470,165.4481,7.3756928,0.80694366,0.0,0,8.9131651,0.0,0.055385463,88.830673,8.9851341,361.62128,-9.2843027
2481,2481,165.4503,7.4103408,0.83853918,0.0,0,8.8809748,0.0,0.057347026,89.073471,8.9512072,361.62796,-9.284668
2492,2492,165.4525,7.4373145,0.86851889,0.0,0,8.8487844,0.0,0.059689142,89.160431,8.9218636,361.63461,-9.2839346
2503,2503,165.4547,7.4573073,0.89836937,0.0,0,8.8165941,0.0,0.061590362,89.335526,8.8896914,361.6413,-9.284523
2514,2514,165.4569,7.5059876,0.93427658,0.0,0,8.7844028,0.0,0.064406283,89.523247,8.8512068,361.5722,-9.2841969
2525,2525,165.4591,7.5476112,0.96611184,0.0,0,8.7522125,0.0,0.066346869,89.872139,8.8228703,361.49203,-9.2840033
2536,2536,165.4613,7.5849943,0.99312627,0.0,0,8.7214985,0.0,0.068641007,90.175293,8.7898216,361.41187,-9.2836351
2547,2547,165.4635,7.6150756,1.0260561,0.0,0,8.6908836,0.0,0.070674904,90.383827,8.7556257,361.3317,-9.2836485
2558,2558,165.4657,7.6301212,1.0622779,0.0,0,8.6602697,0.0,0.07363908,90.276657,8.7192068,361.2695,-9.284091
2569,2569,165.4679,7.6273303,1.0963542,0.0,0,8.629653,0.0,0.075665697,90.065323,8.6908245,361.2428,-9.2838154
2580,2580,165.4701,7.6475563,1.1231118,0.0,0,8.5990381,0.0,0.077893563,90.072983,8.6602516,361.21606,-9.2833433
2591,2591,165.4723,7.661572,1.1505015,0.0,0,8.5684223,0.0,0.0796014,89.983459,8.6273003,361.18933,-9.2833195
2602,2602,165.4745,7.6825891,1.1808555,0.0,0,8.5378084,0.0,0.082206376,90.009674,8.5942917,361.1626,-9.2835398
2613,2613,165.4767,7.7104368,1.2120674,0.0,0,8.5071926,0.0,0.083934464,90.215187,8.5690756,361.18933,-9.2830343
2624,2624,165.4789,7.7422304,1.2365659,0.0,0,8.4765778,0.0,0.086193815,90.366325,8.5386362,361.2294,-9.282752
2635,2635,165.4811,7.7713132,1.2671785,0.0,0,8.445962,0.0,0.08798939,90.570869,8.514183,361.2695,-9.2832355
2646,2646,165.4833,7.8065796,1.2989002,0.0,0,8.4153471,0.0,0.090826437,90.766754,8.4792633,361.3096,-9.283576
2657,2657,165.4855,7.8328052,1.3347704,0.0,0,8.3847322,0.0,0.09285707,90.904686,8.447999,361.35321,-9.2818804
2668,2668,165.4877,7.855638,1.3635308,0.0,0,8.3541164,0.0,0.095508099,90.923767,8.4131279,361.40665,-9.283349
2679,2679,165.4899,7.8883896,1.3974086,0.0,0,8.3235025,0.0,0.097605713,91.128029,8.3825903,361.46008,-9.2852087
2690,2690,165.4921,7.9077168,1.4266098,0.0,0,8.2928858,0.0,0.10015689,91.012535,8.3494873,361.51352,-9.2846165
2701,2701,165.4943,7.9415479,1.4616716,0.0,0,8.2622709,0.0,0.10214626,91.272026,8.3133354,361.56696,-9.2838898
2712,2712,165.4965,7.9679098,1.4890665,0.0,0,8.2316561,0.0,0.1048002,91.311852,8.2867155,361.61557,-9.2832956
2723,2723,165.4987,7.9971738,1.5221182,0.0,0,8.2010412,0.0,0.10675979,91.480217,8.2532358,361.66232,-9.2827587
2734,2734,165.5009,8.0016003,1.5492842,0.0,0,8.1704264,0.0,0.10929165,91.351181,8.2219667,361.70911,-9.283596
2745,2745,165.5031,7.9919229,1.5823824,0.0,0,8.1398106,0.0,0.11108784,91.181564,8.1965752,361.75586,-9.2831907
2756,2756,165.5053,8.0210428,1.6046407,0.0,0,8.1091957,0.0,0.11340601,91.253044,8.1664972,361.80646,-9.2837009
2767,2767,165.5075,8.0450745,1.6380073,0.0,0,8.0785799,0.0,0.1153916,91.246674,8.1320505,361.87326,-9.2832174
2778,2778,165.5097,8.0909452,1.6675048,0.0,0,8.0482779,0.0,0.11814512,91.466858,8.1034918,361.94006,-9.2833099
2789,2789,165.5119,8.1161079,1.704635,0.0,0,8.0191498,0.0,0.12019854,91.63504,8.0719767,362.00687,-9.284914
2800,2800,165.5141,8.1536465,1.7276801,0.0,0,7.9900212,0.0,0.12262767,91.744164,8.0407276,362.07367,-9.2845316
2811,2811,165.5163,8.1792049,1.7591319,0.0,0,7.9608936,0.0,0.12447501,91.904312,8.0106106,362.10986,-9.2845831
2822,2822,165.5185,8.1789951,1.7860804,0.0,0,7.9317656,0.0,0.12709008,91.705055,7.9810772,362.12991,-9.2837076
2833,2833,165.5207,8.1816654,1.8223917,0.0,0,7.9026375,0.0,0.12908939,91.557037,7.9532223,362.14993,-9.2834015
2844,2844,165.5229,8.1865025,1.8431525,0.0,0,7.8735094,0.0,0.13136144,91.452423,7.9219365,362.16998,-9.2841358
2855,2855,165.5251,8.1925316,1.874487,0.0,0,7.8443813,0.0,0.13328673,91.273178,7.890697,362.19083,-9.2838345
2866,2866,165.5273,8.215785,1.9003689,0.0,0,7.8152533,0.0,0.13580316,91.398148,7.864675,362.21753,-9.2836657
2877,2877,165.5295,8.2502184,1.93501,0.0,0,7.7861252,0.0,0.13769078,91.468933,7.8373733,362.24426,-9.2826996
2888,2888,165.5317,8.3009748,1.9571338,0.0,0,7.7569971,0.0,0.1400339,91.827934,7.802659,362.271,-9.282959
2899,2899,165.5339,8.3173466,1.9857475,0.0,0,7.7278695,0.0,0.14181168,91.889114,7.7752752,362.29773,-9.2827549
2910,2910,165.5361,8.3399534,2.0126889,0.0,0,7.6987414,0.0,0.14438953,91.900734,7.748136,362.34778,-9.2836132
2921,2921,165.5383,8.3688641,2.0495336,0.0,0,7.6696134,0.0,0.1465693,91.973267,7.7201371,362.41458,-9.2837315
2932,2932,165.5405,8.3834629,2.0691702,0.0,0,7.6404853,0.0,0.14864431,92.023499,7.6877632,362.48138,-9.2841196
2943,2943,165.5427,8.4071102,2.1046131,0.0,0,7.6113577,0.0,0.15093426,92.123047,7.6575809,362.54819,-9.2829771
2954,2954,165.5449,8.4206915,2.1332922,0.0,0,7.5822296,0.0,0.1536743,91.981293,7.6266308,362.61469,-9.2833433
2965,2965,165.5471,8.4469643,2.1691289,0.0,0,7.5531015,0.0,0.15589637,92.045914,7.5984101,362.6748,-9.2836885
2976,2976,165.5493,8.5019808,2.190376,0.0,0,7.523973,0.0,0.1580306,92.342552,7.5645094,362.73492,-9.2842665
2987,2987,165.5515,8.5217438,2.2229486,0.0,0,7.4948454,0.0,0.16023248,92.427559,7.5345917,362.79504,-9.2846489
2998,2998,165.5537,8.5382814,2.250701,0.0,0,7.4657173,0.0,0.16271667,92.407043,7.5057874,362.85519,-9.2832699
3009,3009,165.5559,8.5501299,2.2843356,0.0,0,7.4365897,0.0,0.16494004,92.291664,7.4769549,362.92551,-9.2844992
3020,3020,165.5581,8.556922,2.3074913,0.0,0,7.4074612,0.0,0.16707799,92.205482,7.4465899,363.00568,-9.28368
3031,3031,165.5603,8.5752296,2.3389597,0.0,0,7.3790221,0.0,0.16933578,92.117836,7.4201951,363.08585,-9.282711
3042,3042,165.5625,8.5843477,2.3628786,0.0,0,7.3513193,0.0,0.17153393,92.072899,7.3902164,363.16602,-9.2830133
3053,3053,165.5647,8.6114769,2.3991823,0.0,0,7.323617,0.0,0.17406121,92.070999,7.3642673,363.24615,-9.2826996
3064,3064,165.5669,8.6370487,2.4202907,0.0,0,7.2959146,0.0,0.17608136,92.22419,7.3353987,363.33282,-9.2843103
3075,3075,165.5691,8.6766939,2.4502451,0.0,0,7.2682123,0.0,0.17823014,92.375366,7.3073092,363.41968,-9.2846136
3086,3086,165.5713,8.6791525,2.4752316,0.0,0,7.24051,0.0,0.18030928,92.280991,7.2799401,363.50653,-9.2829018
3097,3097,165.5735,8.6947021,2.5084875,0.0,0,7.2128077,0.0,0.18275324,92.320992,7.2535362,363.59338,-9.2836008
3108,3108,165.5757,8.7068062,2.5298471,0.0,0,7.1851048,0.0,0.1847311,92.229111,7.2207232,363.3858,-9.2845907
3119,3119,165.5779,8.723134,2.5590141,0.0,0,7.157403,0.0,0.18697733,92.103477,7.1966205,362.79791,-9.2830896
3130,3130,165.5801,8.734024,2.5811853,0.0,0,7.1297007,0.0,0.1889101,92.031738,7.1668534,362.21002,-9.2827253
3141,3141,165.5823,8.7537079,2.6161182,0.0,0,7.1019974,0.0,0.19153425,92.079346,7.1441736,361.6221,-9.2842951
3152,3152,165.5845,8.7929945,2.6397388,0.0,0,7.0742955,0.0,0.19353411,92.243454,7.1136341,361.03421,-9.2836609
3163,3163,165.5867,8.8637552,2.6712143,0.0,0,7.0465932,0.0,0.19607569,92.744003,7.084219,360.25394,-9.2845879
3174,3174,165.5889,8.8970661,2.6962013,0.0,0,7.0188909,0.0,0.19805963,92.894295,7.0521531,359.45227,-9.2841978
3185,3185,165.5911,8.9101658,2.7303815,0.0,0,6.991188,0.0,0.20090596,92.781815,7.0242,358.6506,-9.2838535
3196,3196,165.5933,8.8971996,2.7547596,0.0,0,6.9634857,0.0,0.20283926,92.467438,6.9962649,357.84894,-9.2836742
3207,3207,165.5955,8.9078636,2.7816632,0.0,0,6.9357834,0.0,0.20518395,92.364502,6.9687643,357.35822,-9.2836065
3218,3218,165.5977,8.9155273,2.8072176,0.0,0,6.9080811,0.0,0.20718424,92.292526,6.9396973,357.41165,-9.2838011
3229,3229,165.5999,8.9161882,2.837081,0.0,0,6.8803787,0.0,0.20973086,91.992462,6.9138627,357.46512,-9.2829056
3240,3240,165.6021,8.9427481,2.8604746,0.0,0,6.8526764,0.0,0.21137939,92.093193,6.8857265,357.51855,-9.282712
3251,3251,165.6043,8.9867926,2.8884578,0.0,0,6.8249741,0.0,0.21397223,92.278641,6.8627481,357.57199,-9.2831831
3262,3262,165.6065,9.0283127,2.9131258,0.0,0,6.7972713,0.0,0.21575576,92.635071,6.8304415,358.11179,-9.2832546
3273,3273,165.6087,9.0772285,2.9449923,0.0,0,6.7695689,0.0,0.21866938,92.826218,6.8039417,358.75311,-9.2827892
3284,3284,165.6109,9.0948324,2.9727366,0.0,0,6.7428842,0.0,0.22070436,92.849411,6.7713184,359.39444,-9.2832232
3295,3295,165.6131,9.1064243,3.0023043,0.0,0,6.7165279,0.0,0.22345307,92.840836,6.7460561,360.03577,-9.283102
3306,3306,165.6153,9.1366072,3.0295842,0.0,0,6.6901722,0.0,0.22536418,92.853378,6.7142668,360.57993,-9.2833586
3317,3317,165.6175,9.1232176,3.0569832,0.0,0,6.663816,0.0,0.22806685,92.486366,6.687871,360.88724,-9.2834883
3328,3328,165.6197,9.1257792,3.0844183,0.0,0,6.6374598,0.0,0.22986747,92.367813,6.6612468,361.19455,-9.2839956
3339,3339,165.6219,9.1465864,3.1092155,0.0,0,6.611104,0.0,0.2324726,92.26387,6.6348629,361.50186,-9.283782
3350,3350,165.6241,9.1746988,3.1352837,0.0,0,6.5847478,0.0,0.23422039,92.433235,6.6100268,361.80917,-9.2833309
3361,3361,165.6263,9.2127762,3.1603179,0.0,0,6.558392,0.0,0.23680826,92.556816,6.5841436,361.78378,-9.2834368
3372,3372,165.6285,9.2201166,3.1868522,0.0,0,6.5320363,0.0,0.23842901,92.574951,6.5572839,361.65018,-9.2831955
3383,3383,165.6307,9.2313757,3.2109022,0.0,0,6.5056801,0.0,0.24108842,92.438942,6.5315318,361.51657,-9.2841234
3394,3394,165.6329,9.2502089,3.237571,0.0,0,6.4793239,0.0,0.24286564,92.446327,6.5057011,361.38297,-9.2846336
3405,3405,165.6351,9.2792168,3.263912,0.0,0,6.4529681,0.0,0.24569298,92.432411,6.4793663,361.2887,-9.2841845
3416,3416,165.6373,9.2946434,3.2922554,0.0,0,6.4266124,0.0,0.24739264,92.450607,6.4535122,361.33548,-9.2831573
3427,3427,165.6395,9.3176451,3.3166087,0.0,0,6.4002562,0.0,0.25016683,92.367119,6.4237423,361.38223,-9.2832603
3438,3438,165.6417,9.3226223,3.3443673,0.0,0,6.3738999,0.0,0.25195539,92.292572,6.397491,361.42899,-9.2819366
3449,3449,165.6439,9.3744841,3.3671546,0.0,0,6.3475442,0.0,0.25455078,92.493378,6.3738427,361.47574,-9.2827568
3460,3460,165.6461,9.382762,3.3954339,0.0,0,6.3211884,0.0,0.2562699,92.450363,6.3446345,361.38132,-9.2823963
3471,3471,165.6483,9.4057541,3.4165096,0.0,0,6.2948327,0.0,0.25876409,92.506577,6.323689,361.22098,-9.2835865
3482,3482,165.6505,9.4304695,3.4449992,0.0,0,6.2684765,0.0,0.26052541,92.567825,6.2984834,361.06064,-9.2836361
3493,3493,165.6527,9.4555664,3.4700553,0.0,0,6.2421203,0.0,0.26348382,92.480209,6.2728915,360.90033,-9.2846308
3504,3504,165.6549,9.4873505,3.5014219,0.0,0,6.2157645,0.0,0.26526308,92.655281,6.2407393,360.67392,-9.2832527
3515,3515,165.6571,9.5089188,3.5241365,0.0,0,6.1894083,0.0,0.26805177,92.550133,6.217526,360.0593,-9.2833824
3526,3526,165.6593,9.5404806,3.5533733,0.0,0,6.1631007,0.0,0.27001476,92.746681,6.1891899,359.44467,-9.2833519
3537,3537,165.6615,9.5914736,3.5769691,0.0,0,6.1380219,0.0,0.27273774,92.891113,6.1603785,358.83005,-9.2831621
3548,3548,165.6637,9.6175671,3.6111042,0.0,0,6.1129556,0.0,0.27483279,93.049156,6.1309543,358.21545,-9.2832422
3559,3559,165.6659,9.6159029,3.6302216,0.0,0,6.0878887,0.0,0.27737921,92.748779,6.1070976,357.68628,-9.2825203
3570,3570,165.6681,9.6011391,3.6588047,0.0,0,6.0628219,0.0,0.27926922,92.501976,6.0812058,357.21194,-9.2825422
3581,3581,165.6703,9.6016293,3.6786487,0.0,0,6.037755,0.0,0.28178138,92.268318,6.0535698,356.73764,-9.2829189
3592,3592,165.6725,9.6081123,3.7103624,0.0,0,6.0126886,0.0,0.28362933,92.091621,6.0313606,356.26331,-9.2848473
3603,3603,165.6747,9.624217,3.7271178,0.0,0,5.9876213,0.0,0.28605866,92.079536,6.0097847,355.82687,-9.283473
3614,3614,165.6769,9.6559505,3.7550104,0.0,0,5.9625545,0.0,0.28784388,92.164169,5.9811177,355.87366,-9.2838564
3625,3625,165.6791,9.6789341,3.7753751,0.0,0,5.9374876,0.0,0.29027113,92.186867,5.9593277,355.92041,-9.2844858
3636,3636,165.6813,9.73349,3.8043296,0.0,0,5.9124212,0.0,0.29198575,92.470978,5.9359589,355.96719,-9.2834091
3647,3647,165.6835,9.7874346,3.8238442,0.0,0,5.8873544,0.0,0.29456994,92.812584,5.9095283,356.01395,-9.2834558
3658,3658,165.6857,9.8010416,3.8557897,0.0,0,5.8622875,0.0,0.29678193,92.764259,5.8829832,356.18973,-9.2838688
3669,3669,165.6879,9.8099117,3.8770289,0.0,0,5.8372207,0.0,0.29941064,92.570786,5.8559866,356.47699,-9.2833033
3680,3680,165.6901,9.8133059,3.9123328,0.0,0,5.8121538,0.0,0.30168092,92.392769,5.8281865,356.76425,-9.2832699
3691,3691,165.6923,9.8393097,3.9295366,0.0,0,5.787087,0.0,0.30406836,92.452347,5.805644,357.05151,-9.2831116
3702,3702,165.6945,9.8399448,3.9580345,0.0,0,5.7620201,0.0,0.30607939,92.290947,5.7816253,357.33878,-9.2835979
3713,3713,165.6967,9.8793049,3.9774704,0.0,0,5.7369533,0.0,0.30850095,92.478226,5.7534771,357.42563,-9.2837877
3724,3724,165.6989,9.9037838,4.0100121,0.0,0,5.7118864,0.0,0.31057775,92.473221,5.7313085,357.51245,-9.2827168
3735,3735,165.7011,9.9539309,4.0289841,0.0,0,5.6868196,0.0,0.31310037,92.677887,5.7038584,357.5993,-9.2823362
3746,3746,165.7033,9.9705887,4.0560532,0.0,0,5.6617532,0.0,0.31500506,92.652405,5.6782856,357.68616,-9.2824202
3757,3757,165.7055,9.9878941,4.0771041,0.0,0,5.6366854,0.0,0.31748948,92.576828,5.6512399,357.83185,-9.2848167
3768,3768,165.7077,9.9756489,4.1110325,0.0,0,5.6116195,0.0,0.31994537,92.228226,5.6311622,358.04562,-9.284709
3779,3779,165.7099,10.004523,4.1269507,0.0,0,5.5869198,0.0,0.32196236,92.290573,5.603662,358.2594,-9.2839899
3790,3790,165.7121,10.049719,4.154839,0.0,0,5.5630717,0.0,0.32409307,92.537758,5.574563,358.47318,-9.283185
3801,3801,165.7143,10.081215,4.1764803,0.0,0,5.5392232,0.0,0.32657784,92.597519,5.5511551,358.68698,-9.2832603
3812,3812,165.7165,10.111587,4.2114339,0.0,0,5.5153751,0.0,0.32921377,92.588326,5.5279069,359.07419,-9.2829475
3823,3823,165.7187,10.116217,4.2273402,0.0,0,5.4915276,0.0,0.33118272,92.469185,5.5041733,359.47504,-9.2832146
3834,3834,165.7209,10.128633,4.2543678,0.0,0,5.4676795,0.0,0.33332822,92.364044,5.4771519,359.87585,-9.2829714
3845,3845,165.7231,10.119326,4.2720065,0.0,0,5.4438314,0.0,0.33527172,92.135674,5.4572129,360.2767,-9.2847815
3856,3856,165.7253,10.120129,4.3026233,0.0,0,5.4199839,0.0,0.33775404,92.001686,5.4347191,360.58353,-9.2831821
3867,3867,165.7275,10.143903,4.3201694,0.0,0,5.3961358,0.0,0.33991227,91.92691,5.4090171,360.74387,-9.2844343
3878,3878,165.7297,10.184869,4.3477664,0.0,0,5.3722878,0.0,0.34216097,92.071754,5.3881578,360.90417,-9.2839918
3889,3889,165.7319,10.242881,4.3682814,0.0,0,5.3484397,0.0,0.34430394,92.398575,5.3642621,361.06451,-9.2827034
3900,3900,165.7341,10.272582,4.3990517,0.0,0,5.3245916,0.0,0.3469041,92.445946,5.3397241,361.22485,-9.2834415
3911,3911,165.7363,10.306198,4.4163704,0.0,0,5.3007436,0.0,0.34883124,92.536758,5.3150754,361.26529,-9.2829971
3922,3922,165.7385,10.309241,4.4439673,0.0,0,5.276896,0.0,0.35128108,92.356018,5.2899404,361.28534,-9.2829819
3933,3933,165.7407,10.331288,4.4637694,0.0,0,5.2530475,0.0,0.35325751,92.399536,5.2659183,361.30539,-9.2840948
3944,3944,165.7429,10.337186,4.4922752,0.0,0,5.2291994,0.0,0.35577282,92.187553,5.241878,361.32544,-9.2836514
3955,3955,165.7451,10.34172,4.5124836,0.0,0,5.2053518,0.0,0.35779682,92.062523,5.2168622,361.354,-9.2842779
3966,3966,165.7473,10.357889,4.537662,0.0,0,5.1815038,0.0,0.36022335,91.960075,5.1973453,361.40076,-9.2835989
3977,3977,165.7495,10.401848,4.5568318,0.0,0,5.1576557,0.0,0.36206958,92.21653,5.1731491,361.44754,-9.2846079
3988,3988,165.7517,10.439753,4.5885596,0.0,0,5.1338077,0.0,0.36519554,92.253807,5.1490941,361.49429,-9.2842913
3999,3999,165.7539,10.46235,4.6072054,0.0,0,5.1099596,0.0,0.36684322,92.346252,5.1252279,361.54108,-9.2839508
4010,4010,165.7561,10.501889,4.6306162,0.0,0,5.0861115,0.0,0.36923876,92.426857,5.1006498,361.60349,-9.2830353
4021,4021,165.7583,10.533409,4.6520758,0.0,0,5.062264,0.0,0.37115431,92.52813,5.0779028,361.67029,-9.2833157
4032,4032,165.7605,10.559196,4.6829729,0.0,0,5.0390849,0.0,0.37435132,92.495903,5.051785,361.73709,-9.2844191
4043,4043,165.7627,10.56736,4.7039237,0.0,0,5.0164027,0.0,0.3760688,92.351639,5.0267186,361.80389,-9.2838421
4054,4054,165.7649,10.56424,4.7279453,0.0,0,4.993721,0.0,0.37873778,92.093704,5.0037642,361.83954,-9.2841282
4065,4065,165.7671,10.604899,4.7519469,0.0,0,4.9710388,0.0,0.38078657,92.240395,4.9787145,361.77942,-9.2842722
4076,4076,165.7693,10.640343,4.779357,0.0,0,4.9483566,0.0,0.38387558,92.261864,4.957592,361.7193,-9.2839718
4087,4087,165.7715,10.642024,4.8014197,0.0,0,4.9256749,0.0,0.38557199,92.075134,4.9303446,361.65915,-9.2840004
4098,4098,165.7737,10.664663,4.8200369,0.0,0,4.9029927,0.0,0.38781238,92.122459,4.9087348,361.59903,-9.2830038
4109,4109,165.7759,10.659974,4.8405819,0.0,0,4.880311,0.0,0.38936356,91.932808,4.8855124,360.97046,-9.2838039
4120,4120,165.7781,10.665473,4.8647141,0.0,0,4.8576288,0.0,0.39234531,91.716423,4.8672237,360.10867,-9.2833147
4131,4131,165.7803,10.676743,4.8889275,0.0,0,4.8349466,0.0,0.39400899,91.683235,4.8433642,359.24686,-9.2831831
4142,4142,165.7825,10.711033,4.9084482,0.0,0,4.8122649,0.0,0.39661422,91.722603,4.8233933,358.38507,-9.2831202
4153,4153,165.7847,10.727227,4.930594,0.0,0,4.7895827,0.0,0.39819428,91.716003,4.8067942,357.54059,-9.2836666
4164,4164,165.7869,10.788844,4.9535799,0.0,0,4.766901,0.0,0.40121964,91.956879,4.7773662,356.77902,-9.2832861
4175,4175,165.7891,10.868132,4.9780598,0.0,0,4.7442188,0.0,0.40284586,92.461884,4.7538919,356.01743,-9.2827244
4186,4186,165.7913,10.913473,5.0012064,0.0,0,4.7215366,0.0,0.40583149,92.566681,4.7301383,355.25583,-9.2831049
4197,4197,165.7935,10.920906,5.0255713,0.0,0,4.6988549,0.0,0.40761033,92.471863,4.7044144,354.49426,-9.2833481
4208,4208,165.7957,10.939931,5.0483451,0.0,0,4.6761732,0.0,0.41073027,92.389244,4.6819758,354.3576,-9.2834969
4219,4219,165.7979,10.917125,5.072732,0.0,0,4.6534905,0.0,0.41238055,92.072922,4.6586809,354.57806,-9.2834053
4230,4230,165.8001,10.915245,5.0900459,0.0,0,4.6308088,0.0,0.41485947,91.797119,4.6398306,354.79852,-9.2843542
4241,4241,165.8023,10.922592,5.1151814,0.0,0,4.6081266,0.0,0.41661254,91.692986,4.6165805,355.01898,-9.2821989
4252,4252,165.8045,10.95146,5.1369629,0.0,0,4.5854449,0.0,0.4197045,91.592957,4.5935473,355.2468,-9.2827806
4263,4263,165.8067,10.994525,5.1612368,0.0,0,4.5627627,0.0,0.42121533,91.837883,4.5724425,355.54074,-9.2846804
4274,4274,165.8089,11.039992,5.1791959,0.0,0,4.5400805,0.0,0.42396468,91.930878,4.5522761,355.83469,-9.2848101
4285,4285,165.8111,11.071681,5.2032442,0.0,0,4.5183334,0.0,0.42549583,92.119865,4.5314412,356.12863,-9.2852688
4296,4296,165.8133,11.122951,5.2232952,0.0,0,4.4967556,0.0,0.42855039,92.243134,4.5029392,356.42258,-9.2845535
4307,4307,165.8155,11.141768,5.2521229,0.0,0,4.4751782,0.0,0.43037194,92.304276,4.4852223,356.73911,-9.2833538
4318,4318,165.8177,11.154694,5.2695479,0.0,0,4.4536009,0.0,0.43324754,92.136383,4.4587831,357.07315,-9.2846079
4329,4329,165.8199,11.156921,5.2958016,0.0,0,4.432023,0.0,0.43502223,91.995216,4.436954,357.40717,-9.2827539
4340,4340,165.8221,11.175572,5.3134923,0.0,0,4.4104452,0.0,0.43780717,91.821655,4.4129014,357.74118,-9.2834101
4351,4351,165.8243,11.203039,5.3412719,0.0,0,4.3888679,0.0,0.43949279,91.889763,4.3935375,358.07413,-9.2845898
4362,4362,165.8265,11.260336,5.3566065,0.0,0,4.36729,0.0,0.44227359,92.084763,4.3692985,358.36807,-9.2833138
4373,4373,165.8287,11.289389,5.3842182,0.0,0,4.3457127,0.0,0.44425806,92.226387,4.3481584,358.66202,-9.2833166
4384,4384,165.8309,11.29849,5.4006243,0.0,0,4.3241353,0.0,0.44692716,92.018707,4.327878,358.95596,-9.2835197
4395,4395,165.8331,11.310403,5.4293151,0.0,0,4.3025579,0.0,0.44865134,91.916626,4.3066287,359.24991,-9.2848616
4406,4406,165.8353,11.326741,5.4414725,0.0,0,4.2809801,0.0,0.45107833,91.915985,4.2866535,359.47824,-9.2839403
4417,4417,165.8375,11.350472,5.4669242,0.0,0,4.2594023,0.0,0.45289513,91.927589,4.266685,359.63858,-9.2835264
4428,4428,165.8397,11.371264,5.4850626,0.0,0,4.2378249,0.0,0.45575339,91.804375,4.2418489,359.79892,-9.2838068
4439,4439,165.8419,11.408651,5.5132055,0.0,0,4.2162471,0.0,0.4574165,91.876648,4.2217684,359.95926,-9.2848511
4450,4450,165.8441,11.458502,5.526773,0.0,0,4.1946697,0.0,0.4600099,92.090385,4.1996059,360.1196,-9.2836332
4461,4461,165.8463,11.502978,5.5563731,0.0,0,4.1730919,0.0,0.46227506,92.204872,4.1797366,360.31183,-9.2833252
4472,4472,165.8485,11.532137,5.5720434,0.0,0,4.1515145,0.0,0.46485126,92.188957,4.1564245,360.50555,-9.2820253
4483,4483,165.8507,11.547409,5.6018353,0.0,0,4.1299367,0.0,0.46682107,92.243607,4.1338325,360.69928,-9.2832079
4494,4494,165.8529,11.571497,5.6129265,0.0,0,4.1083593,0.0,0.46918985,92.226517,4.1130915,360.89304,-9.2837162
4505,4505,165.8551,11.605837,5.6399698,0.0,0,4.0867815,0.0,0.4712328,92.252052,4.0888495,361.07278,-9.2847834
4516,4516,165.8573,11.620673,5.6604099,0.0,0,4.0652041,0.0,0.47427991,92.021431,4.06915,361.23312,-9.2837839
4527,4527,165.8595,11.620066,5.69065,0.0,0,4.0437527,0.0,0.47647971,91.817093,4.0480676,361.39346,-9.2822514
4538,4538,165.8617,11.672491,5.7011571,0.0,0,4.0232306,0.0,0.47846183,92.066086,4.0288386,361.5538,-9.2833176
4549,4549,165.8639,11.711611,5.7252493,0.0,0,4.0027089,0.0,0.48043957,92.205231,4.0089693,361.71414,-9.2836218
4560,4560,165.8661,11.746878,5.7427592,0.0,0,3.9821873,0.0,0.48308328,92.239517,3.9839463,361.72131,-9.2842236
4571,4571,165.8683,11.772657,5.7738085,0.0,0,3.9616656,0.0,0.4854376,92.305878,3.9629538,361.70795,-9.2847528
4582,4582,165.8705,11.798352,5.7891645,0.0,0,3.9411442,0.0,0.48794699,92.261955,3.9415479,361.69458,-9.2841005
4593,4593,165.8727,11.85075,5.8140759,0.0,0,3.9206226,0.0,0.48995391,92.389343,3.9223063,361.68124,-9.2833452
4604,4604,165.8749,11.847305,5.8290844,0.0,0,3.9001009,0.0,0.49231559,92.218872,3.8983934,361.5271,-9.2835197
4615,4615,165.8771,11.847628,5.8591981,0.0,0,3.8795795,0.0,0.49495998,92.00592,3.8783624,361.1062,-9.284894
4626,4626,165.8793,11.849272,5.871572,0.0,0,3.8590579,0.0,0.49687308,91.786339,3.8604646,360.68533,-9.2846231
4637,4637,165.8815,11.858768,5.8960066,0.0,0,3.8385363,0.0,0.4990496,91.636467,3.8390405,360.26443,-9.2827539
4648,4648,165.8837,11.912266,5.9106669,0.0,0,3.8180146,0.0,0.50116682,91.872688,3.8206213,359.84357,-9.2833242
4659,4659,165.8859,11.929592,5.9374571,0.0,0,3.797493,0.0,0.50355202,91.768509,3.8026624,359.31458,-9.2843599
4670,4670,165.8881,11.960033,5.9469895,0.0,0,3.7769713,0.0,0.50524515,91.928932,3.7826073,358.7601,-9.2840176
4681,4681,165.8903,11.991727,5.9714599,0.0,0,3.7564499,0.0,0.50744808,91.933975,3.7607689,358.2056,-9.2838249
4692,4692,165.8925,12.057139,5.9890609,0.0,0,3.7359283,0.0,0.50970602,92.199921,3.738162,357.65112,-9.2845583
4703,4703,165.8947,12.089694,6.0177312,0.0,0,3.7154067,0.0,0.51251227,92.143272,3.7182364,357.12579,-9.2833996
4714,4714,165.8969,12.123848,6.0307488,0.0,0,3.694885,0.0,0.514305,92.230141,3.6997933,356.67819,-9.2831717
4725,4725,165.8991,12.156837,6.0551105,0.0,0,3.6743636,0.0,0.51682395,92.278358,3.679105,356.23059,-9.2844906
4736,4736,165.9013,12.197687,6.0721698,0.0,0,3.6538417,0.0,0.51881891,92.464554,3.6604614,355.78299,-9.2835121
4747,4747,165.9035,12.266172,6.0995417,0.0,0,3.6333201,0.0,0.52186835,92.692169,3.6386826,355.33542,-9.2832508
4758,4758,165.9057,12.288932,6.1156468,0.0,0,3.6127987,0.0,0.5236631,92.657684,3.6141429,355.02554,-9.2823162
4769,4769,165.9079,12.325714,6.1381159,0.0,0,3.5922771,0.0,0.52637458,92.669739,3.5944178,354.76498,-9.2840204
4780,4780,165.9101,12.329187,6.1568928,0.0,0,3.5721471,0.0,0.52829695,92.562859,3.5742669,354.50446,-9.2841749
4791,4791,165.9123,12.355594,6.1853204,0.0,0,3.5526242,0.0,0.53162563,92.424919,3.5523069,354.2439,-9.284586
4802,4802,165.9145,12.390338,6.1999869,0.0,0,3.5331016,0.0,0.53316158,92.550301,3.532119,354.0408,-9.283989
4813,4813,165.9167,12.437747,6.2236776,0.0,0,3.5135787,0.0,0.53611487,92.606941,3.5092897,354.06754,-9.2826843
4824,4824,165.9189,12.446766,6.2410045,0.0,0,3.4940557,0.0,0.53784502,92.541138,3.4918587,354.09424,-9.2838411
4835,4835,165.9211,12.472496,6.2630949,0.0,0,3.4745328,0.0,0.5406906,92.501976,3.4735429,354.12097,-9.2826881
4846,4846,165.9233,12.49139,6.2787123,0.0,0,3.4550104,0.0,0.54202378,92.435669,3.4559765,354.14767,-9.2832699
4857,4857,165.9255,12.505232,6.3013401,0.0,0,3.4354873,0.0,0.54517633,92.29911,3.4339368,354.2764,-9.2836447
4868,4868,165.9277,12.52345,6.3190894,0.0,0,3.4159648,0.0,0.54667062,92.309998,3.4160945,354.45676,-9.2840052
4879,4879,165.9299,12.52938,6.3408747,0.0,0,3.3964417,0.0,0.5496884,92.123695,3.3979282,354.63715,-9.2840767
4890,4890,165.9321,12.55506,6.3577528,0.0,0,3.376919,0.0,0.55103236,92.102776,3.3767912,354.81754,-9.2845926
4901,4901,165.9343,12.592206,6.3754683,0.0,0,3.3573964,0.0,0.55363631,92.151817,3.3603933,355.00217,-9.2852926
4912,4912,165.9365,12.649933,6.3935056,0.0,0,3.3378732,0.0,0.55529898,92.41037,3.3384471,355.21594,-9.2840033
4923,4923,165.9387,12.703794,6.4161396,0.0,0,3.3183508,0.0,0.55853242,92.518059,3.3219233,355.42969,-9.2834358
4934,4934,165.9409,12.773953,6.4352026,0.0,0,3.2988276,0.0,0.55986339,92.873062,3.2993953,355.64346,-9.2847548
4945,4945,165.9431,12.800684,6.4528189,0.0,0,3.2793047,0.0,0.56282145,92.885872,3.2797549,355.85724,-9.2840261
4956,4956,165.9453,12.811075,6.4719415,0.0,0,3.2597823,0.0,0.56425661,92.822166,3.2624483,355.99207,-9.2844057
4967,4967,165.9475,12.850938,6.4955926,0.0,0,3.2402592,0.0,0.5680235,92.731033,3.2380054,356.07224,-9.2843428
4978,4978,165.9497,12.907313,6.5196233,0.0,0,3.2207365,0.0,0.56975102,92.957001,3.2172799,356.1524,-9.2845678
4989,4989,165.9519,12.943811,6.5330396,0.0,0,3.2012138,0.0,0.57227355,92.994003,3.1989017,356.23257,-9.2836552
5000,5000,165.9541,12.994056,6.554276,0.0,0,3.1816909,0.0,0.5739091,93.18972,3.1796746,356.31131,-9.2840757
5011,5011,165.9563,13.012524,6.575727,0.0,0,3.1621683,0.0,0.57737881,93.014488,3.1588228,356.36475,-9.2839489
5022,5022,165.9585,13.034969,6.5970745,0.0,0,3.1426454,0.0,0.57876915,93.030075,3.1373439,356.41818,-9.2834873
5033,5033,165.9607,13.071886,6.6097908,0.0,0,3.1237545,0.0,0.58150297,93.001663,3.1202905,356.47165,-9.2832994
5044,5044,165.9629,13.065031,6.6326184,0.0,0,3.1051819,0.0,0.58310539,92.923904,3.1016827,356.52509,-9.2832651
5055,5055,165.9651,13.064106,6.6492519,0.0,0,3.0866094,0.0,0.58638328,92.52079,3.0844502,356.61316,-9.2838421
5066,5066,165.9673,13.067369,6.6728063,0.0,0,3.0680368,0.0,0.58785009,92.411354,3.0630009,356.7334,-9.2844458
5077,5077,165.9695,13.093888,6.6819596,0.0,0,3.0494645,0.0,0.59019339,92.415489,3.0500937,356.85364,-9.2845106
5088,5088,165.9717,13.159549,6.7023163,0.0,0,3.0308924,0.0,0.59137654,92.702499,3.0323861,356.97388,-9.2841282
5099,5099,165.9739,13.253764,6.7197194,0.0,0,3.0123198,0.0,0.59485197,93.055611,3.0104449,357.09412,-9.2844391
5110,5110,165.9761,13.308378,6.7455778,0.0,0,2.9937477,0.0,0.59660703,93.314102,2.9919858,357.3259,-9.2837677
5121,5121,165.9783,13.345366,6.7592487,0.0,0,2.9751751,0.0,0.59962499,93.268913,2.974781,357.55972,-9.2832632
5132,5132,165.9805,13.385733,6.7824769,0.0,0,2.9566026,0.0,0.60121119,93.44297,2.9568074,357.79355,-9.2833328
5143,5143,165.9827,13.412927,6.7964025,0.0,0,2.93803,0.0,0.60416299,93.368782,2.9384232,358.02737,-9.2838402
5154,5154,165.9849,13.430892,6.8223996,0.0,0,2.9194577,0.0,0.60575789,93.284248,2.9177909,358.25824,-9.2840605
5165,5165,165.9871,13.461078,6.8332858,0.0,0,2.9008856,0.0,0.60864156,93.261467,2.8999364,358.48538,-9.2838898
5176,5176,165.9893,13.521293,6.8615012,0.0,0,2.882313,0.0,0.61087233,93.431313,2.8830245,358.71249,-9.2847528
5187,5187,165.9915,13.579998,6.873889,0.0,0,2.8637407,0.0,0.61374068,93.561089,2.8614874,358.93964,-9.2846851
5198,5198,165.9937,13.639044,6.902988,0.0,0,2.8451684,0.0,0.61562258,93.792435,2.8402534,359.16678,-9.2830811
5209,5209,165.9959,13.671782,6.9133053,0.0,0,2.8265958,0.0,0.61841589,93.757805,2.8244407,359.28461,-9.2837076
5220,5220,165.9981,13.668532,6.9360876,0.0,0,2.8080232,0.0,0.62008649,93.619141,2.8023739,359.39148,-9.2827263
5231,5231,166.0003,13.694915,6.9500623,0.0,0,2.7894509,0.0,0.62309533,93.525772,2.785794,359.49838,-9.2832432
5242,5242,166.0025,13.70997,6.9763684,0.0,0,2.7708786,0.0,0.62484324,93.429062,2.7680714,359.60526,-9.2842283
5253,5253,166.0047,13.721253,6.9849715,0.0,0,2.7523062,0.0,0.62724012,93.298912,2.748415,359.6723,-9.2834892
5264,5264,166.0069,13.768177,7.0075135,0.0,0,2.7337339,0.0,0.62898624,93.375145,2.7349904,359.6723,-9.2834692
5275,5275,166.0091,13.826005,7.0198789,0.0,0,2.7151613,0.0,0.631832,93.520523,2.7139046,359.6723,-9.2841434
5286,5286,166.0113,13.88588,7.0480003,0.0,0,2.6974392,0.0,0.63377863,93.785049,2.6987913,359.6723,-9.2832956
5297,5297,166.0135,13.94413,7.0558958,0.0,0,2.6797731,0.0,0.63619626,93.975143,2.6813924,359.6723,-9.2837706
5308,5308,166.0157,14.023597,7.0790482,0.0,0,2.662107,0.0,0.63809848,94.272415,2.6600773,359.74493,-9.2822361
5319,5319,166.0179,14.053248,7.0945711,0.0,0,2.6444409,0.0,0.64106238,94.228249,2.6405358,359.83179,-9.2834501
5330,5330,166.0201,14.079576,7.1242366,0.0,0,2.626775,0.0,0.64358145,94.206528,2.6210275,359.91864,-9.2834921
5341,5341,166.0223,14.08266,7.1324821,0.0,0,2.6091089,0.0,0.64573371,93.995934,2.6042316,360.00549,-9.2842379
5352,5352,166.0245,14.110142,7.1552501,0.0,0,2.5914431,0.0,0.64776373,93.945755,2.5850561,360.15848,-9.2840872
5363,5363,166.0267,14.134175,7.1672544,0.0,0,2.573777,0.0,0.65025699,93.922272,2.5635896,360.46579,-9.2837725
5374,5374,166.0289,14.204683,7.1945438,0.0,0,2.5561111,0.0,0.65252894,94.137352,2.5510011,360.77307,-9.2825489
5385,5385,166.0311,14.222519,7.2017994,0.0,0,2.538445,0.0,0.65452129,94.12484,2.5325782,361.08038,-9.283803
5396,5396,166.0333,14.274405,7.2248998,0.0,0,2.5207791,0.0,0.65667886,94.208275,2.5158257,361.3877,-9.2837124
5407,5407,166.0355,14.304556,7.2353282,0.0,0,2.503113,0.0,0.65884072,94.228355,2.4974172,361.59296,-9.2836695
5418,5418,166.0377,14.344015,7.2623854,0.0,0,2.4854469,0.0,0.66142249,94.27417,2.4800534,361.76666,-9.2833452
5429,5429,166.0399,14.364069,7.2721672,0.0,0,2.4677811,0.0,0.66355181,94.210472,2.4641948,361.94034,-9.2845869
5440,5440,166.0421,14.380139,7.2951789,0.0,0,2.450115,0.0,0.66598481,94.100098,2.4479985,362.11404,-9.2844715
5451,5451,166.0443,14.406628,7.3063211,0.0,0,2.4324489,0.0,0.66803038,94.00692,2.4306877,362.25888,-9.2842894
5462,5462,166.0465,14.49272,7.3313794,0.0,0,2.414783,0.0,0.67049086,94.377876,2.4158733,362.30566,-9.2845879
5473,5473,166.0487,14.596312,7.3422179,0.0,0,2.3971169,0.0,0.67251098,94.852531,2.3983181,362.35242,-9.2839355
5484,5484,166.0509,14.668265,7.363874,0.0,0,2.379451,0.0,0.67504334,95.10672,2.3798792,362.39917,-9.2832842
5495,5495,166.0531,14.71761,7.3771763,0.0,0,2.3617849,0.0,0.67701679,95.213837,2.3606789,362.44592,-9.2827044
5506,5506,166.0553,14.778867,7.4059343,0.0,0,2.3441188,0.0,0.68035311,95.325539,2.3413813,362.53424,-9.2847052
5517,5517,166.0575,14.804198,7.4179153,0.0,0,2.326453,0.0,0.68237334,95.264282,2.3242383,362.64114,-9.2847366
5528,5528,166.0597,14.798406,7.4388442,0.0,0,2.3089681,0.0,0.68491888,95.050941,2.3077312,362.74805,-9.2848015
5539,5539,166.0619,14.793734,7.4495635,0.0,0,2.2921643,0.0,0.6864658,94.785904,2.287698,362.85495,-9.2841702
5550,5550,166.0641,14.842931,7.4730911,0.0,0,2.2753608,0.0,0.68953133,94.802048,2.2708795,362.95874,-9.2842436
5561,5561,166.0663,14.9052,7.4846926,0.0,0,2.2585571,0.0,0.69117206,95.082771,2.254241,363.04556,-9.2845564
5572,5572,166.0685,14.987644,7.5051956,0.0,0,2.2417536,0.0,0.69387621,95.286034,2.2354336,363.13242,-9.2831249
5583,5583,166.0707,15.020557,7.5182972,0.0,0,2.2249501,0.0,0.6954326,95.412643,2.2193506,363.21927,-9.2832594
5594,5594,166.0729,15.082649,7.5421643,0.0,0,2.2081466,0.0,0.69880027,95.478188,2.2000644,363.30609,-9.2838659
5605,5605,166.0751,15.112627,7.5545683,0.0,0,2.1913428,0.0,0.70037413,95.556976,2.1818235,363.36404,-9.2834673
5616,5616,166.0773,15.142178,7.5719752,0.0,0,2.1745393,0.0,0.70294809,95.513573,2.1631825,363.40414,-9.2834988
5627,5627,166.0795,15.189445,7.5883002,0.0,0,2.1577358,0.0,0.70473349,95.575897,2.1488261,363.44421,-9.2841759
5638,5638,166.0817,15.260112,7.6097169,0.0,0,2.1409321,0.0,0.70814198,95.662384,2.1366191,363.48431,-9.2859287
5649,5649,166.0839,15.341451,7.6255069,0.0,0,2.1241283,0.0,0.70965958,96.015991,2.1142554,363.52222,-9.2835646
5660,5660,166.0861,15.417402,7.6436043,0.0,0,2.1073248,0.0,0.71271688,96.227448,2.0967655,363.53558,-9.2834816
5671,5671,166.0883,15.46787,7.6582761,0.0,0,2.0905213,0.0,0.71421045,96.405975,2.0780597,363.54892,-9.2832813
5682,5682,166.0905,15.465734,7.679626,0.0,0,2.0737178,0.0,0.71778923,96.064491,2.0620024,363.56229,-9.2826843
5693,5693,166.0927,15.466161,7.6966619,0.0,0,2.0569141,0.0,0.71923375,95.946785,2.0474749,363.57565,-9.2832556
5704,5704,166.0949,15.480266,7.7118921,0.0,0,2.0401106,0.0,0.72209275,95.814629,2.030622,363.60358,-9.2841406
5715,5715,166.0971,15.500122,7.7261376,0.0,0,2.0233071,0.0,0.72330081,95.76091,2.0127299,363.64368,-9.2842312
5726,5726,166.0993,15.536302,7.743906,0.0,0,2.0065033,0.0,0.72678393,95.648132,1.9994144,363.68375,-9.2840986
5737,5737,166.1015,15.602163,7.7591128,0.0,0,1.9896998,0.0,0.7277537,95.939575,1.9841933,363.72385,-9.2845154
5748,5748,166.1037,15.656644,7.7710238,0.0,0,1.9728961,0.0,0.73038793,95.983475,1.9706889,363.76422,-9.284008
5759,5759,166.1059,15.726709,7.7898054,0.0,0,1.9560926,0.0,0.73194832,96.313339,1.9533887,363.83771,-9.2841311
5770,5770,166.1081,15.800877,7.8042655,0.0,0,1.939289,0.0,0.73514706,96.440773,1.9379442,363.91119,-9.2832499
5781,5781,166.1103,15.88472,7.8240142,0.0,0,1.9228806,0.0,0.73663902,96.813004,1.9193945,363.98468,-9.2839413
5792,5792,166.1125,15.950017,7.8380747,0.0,0,1.9068955,0.0,0.73995447,96.939209,1.9018903,364.05817,-9.2824039
5803,5803,166.1147,16.001621,7.859086,0.0,0,1.8909101,0.0,0.74159592,97.071358,1.8830364,363.78427,-9.2828255
5814,5814,166.1169,16.02173,7.8752398,0.0,0,1.874925,0.0,0.74526221,96.843491,1.86832,363.12289,-9.2826366
5825,5825,166.1191,16.058304,7.8947558,0.0,0,1.8589398,0.0,0.74637508,96.884567,1.8496717,362.46152,-9.2835445
5836,5836,166.1213,16.094007,7.9027772,0.0,0,1.8429546,0.0,0.74909431,96.885742,1.8354797,361.80014,-9.283886
5847,5847,166.1235,16.134115,7.9224114,0.0,0,1.8269695,0.0,0.7504344,97.00235,1.8205816,361.13876,-9.2842436
5858,5858,166.1257,16.189922,7.937036,0.0,0,1.8109843,0.0,0.75392306,96.991348,1.8065126,359.73923,-9.2830849
5869,5869,166.1279,16.24334,7.9575677,0.0,0,1.794999,0.0,0.75517762,97.203232,1.7909498,358.28955,-9.2826042
5880,5880,166.1301,16.303061,7.9672852,0.0,0,1.7790139,0.0,0.7583971,97.250832,1.7751602,356.83987,-9.2838039
5891,5891,166.1323,16.387323,7.988719,0.0,0,1.7630286,0.0,0.75982893,97.593346,1.7561067,355.3902,-9.2843733
5902,5902,166.1345,16.437513,8.0018358,0.0,0,1.7470435,0.0,0.76338774,97.546143,1.7404441,353.87015,-9.2835999
5913,5913,166.1367,16.502522,8.0242949,0.0,0,1.7310582,0.0,0.76458663,97.811539,1.7262933,352.24457,-9.2838678
5924,5924,166.1389,16.546761,8.0326948,0.0,0,1.715073,0.0,0.7676267,97.757072,1.7069132,350.61899,-9.2847757
5935,5935,166.1411,16.615246,8.0531855,0.0,0,1.6990879,0.0,0.7690556,98.005844,1.690311,348.99341,-9.2847738
5946,5946,166.1433,16.650557,8.0664825,0.0,0,1.6831026,0.0,0.77252394,97.92057,1.6782762,347.36783,-9.2831087
5957,5957,166.1455,16.679338,8.0903816,0.0,0,1.6671174,0.0,0.77412897,97.947723,1.661949,346.37109,-9.2834511
5968,5968,166.1477,16.714224,8.0950279,0.0,0,1.6511322,0.0,0.77666038,97.888199,1.6444767,345.4736,-9.283392
5979,5979,166.1499,16.747776,8.1165924,0.0,0,1.635147,0.0,0.7782048,97.954941,1.632858,344.57614,-9.2844315
5990,5990,166.1521,16.81229,8.1289482,0.0,0,1.6191618,0.0,0.78170639,97.95327,1.6144596,343.67868,-9.2832747
6001,6001,166.1543,16.90579,8.1551218,0.0,0,1.6031766,0.0,0.78343755,98.282158,1.6000665,343.14508,-9.2834187
6012,6012,166.1565,17.010321,8.1586676,0.0,0,1.5871913,0.0,0.7857644,98.646065,1.5796978,343.35941,-9.2834101
6023,6023,166.1587,17.086699,8.182209,0.0,0,1.5712062,0.0,0.7877782,98.95388,1.5627307,343.57376,-9.282548
6034,6034,166.1609,17.160933,8.1933165,0.0,0,1.5558095,0.0,0.79102916,99.02507,1.5466436,343.78812,-9.2832117
6045,6045,166.1631,17.180994,8.2184649,0.0,0,1.540603,0.0,0.79281712,98.991508,1.5323497,344.00244,-9.2827911
6056,6056,166.1653,17.213089,8.2256069,0.0,0,1.5253967,0.0,0.79562336,98.93087,1.5153714,344.29626,-9.2833481
6067,6067,166.1675,17.261135,8.2442551,0.0,0,1.5101904,0.0,0.79703516,99.05407,1.499426,344.61108,-9.2831936
6078,6078,166.1697,17.288019,8.2535076,0.0,0,1.4949839,0.0,0.79979426,98.921494,1.4864002,344.9259,-9.2840023
6089,6089,166.1719,17.328953,8.2809343,0.0,0,1.4797776,0.0,0.80220515,98.923286,1.4696015,345.24072,-9.2835741
6100,6100,166.1741,17.379488,8.2865353,0.0,0,1.4645711,0.0,0.80469751,98.988182,1.4570189,345.57089,-9.283452
6111,6111,166.1763,17.445251,8.3062639,0.0,0,1.4493648,0.0,0.80625832,99.199425,1.4402035,345.94598,-9.282814
6122,6122,166.1785,17.502972,8.3177471,0.0,0,1.4341583,0.0,0.80921501,99.20253,1.4225749,346.32108,-9.2823668
6133,6133,166.1807,17.573862,8.3401976,0.0,0,1.418952,0.0,0.81112212,99.410957,1.4081916,346.6962,-9.2837591
6144,6144,166.1829,17.611324,8.3445721,0.0,0,1.4037454,0.0,0.81330979,99.482925,1.396452,347.07129,-9.2835493
6155,6155,166.1851,17.672312,8.3639002,0.0,0,1.3885391,0.0,0.8149386,99.638229,1.3790758,347.68182,-9.2835608
6166,6166,166.1873,17.736368,8.3737278,0.0,0,1.3733326,0.0,0.81751215,99.754547,1.3655876,348.3847,-9.2833128
6177,6177,166.1895,17.766485,8.3994236,0.0,0,1.3581263,0.0,0.8202374,99.608223,1.3485785,349.08762,-9.283658
6188,6188,166.1917,17.79398,8.4048738,0.0,0,1.3429198,0.0,0.82230705,99.537315,1.3362577,349.7905,-9.2819738
6199,6199,166.1939,17.864534,8.4230814,0.0,0,1.3277135,0.0,0.82397753,99.797485,1.3228301,350.53577,-9.2831345
6210,6210,166.1961,17.922861,8.433424,0.0,0,1.3125072,0.0,0.82645416,99.849518,1.3067529,351.47168,-9.2825575
6221,6221,166.1983,17.984636,8.4579287,0.0,0,1.2973008,0.0,0.82919586,99.921539,1.2929337,352.40762,-9.2832937
6232,6232,166.2005,18.05127,8.4625568,0.0,0,1.2820944,0.0,0.83088416,100.1368,1.2798083,353.34354,-9.2835312
6243,6243,166.2027,18.105074,8.4805555,0.0,0,1.2668879,0.0,0.83295184,100.22276,1.2672834,354.27945,-9.282958
6254,6254,166.2049,18.173296,8.4921074,0.0,0,1.2516814,0.0,0.83520991,100.37415,1.2520649,354.95624,-9.2828474
6265,6265,166.2071,18.223158,8.5156937,0.0,0,1.2364751,0.0,0.83817053,100.3754,1.2364099,355.49069,-9.2836323
6276,6276,166.2093,18.3318,8.5216274,0.0,0,1.2212964,0.0,0.83970582,100.73266,1.2201356,356.02515,-9.2826958
6287,6287,166.2115,18.48506,8.5423927,0.0,0,1.206827,0.0,0.84246445,101.3063,1.2016182,356.5596,-9.2817278
6298,6298,166.2137,18.589808,8.5538034,0.0,0,1.1923642,0.0,0.84460324,101.71265,1.1879815,357.05249,-9.2825212
6309,6309,166.2159,18.676527,8.5764017,0.0,0,1.1779014,0.0,0.84777617,101.85143,1.171385,357.20615,-9.2829227
6320,6320,166.2181,18.719086,8.5874681,0.0,0,1.1634386,0.0,0.84982699,101.89256,1.1541739,357.3598,-9.2817678
6331,6331,166.2203,18.763472,8.6065598,0.0,0,1.1489758,0.0,0.85282159,101.82018,1.1397483,357.51346,-9.2831688
6342,6342,166.2225,18.765726,8.6145725,0.0,0,1.134513,0.0,0.85401708,101.74293,1.1250606,357.66711,-9.2841291
6353,6353,166.2247,18.764128,8.6345167,0.0,0,1.1200502,0.0,0.857068,101.39165,1.1084784,357.97382,-9.2836714
6364,6364,166.2269,18.796503,8.6442146,0.0,0,1.1055874,0.0,0.85872447,101.39462,1.0958418,358.39468,-9.2825089
6375,6375,166.2291,18.845221,8.6607599,0.0,0,1.0911245,0.0,0.86144489,101.37144,1.0827869,358.81555,-9.282053
6386,6386,166.2313,18.909878,8.6704578,0.0,0,1.0766618,0.0,0.86284745,101.55103,1.0699965,359.23642,-9.2815628
6397,6397,166.2335,19.001472,8.689992,0.0,0,1.0621989,0.0,0.86612874,101.72233,1.0545729,359.6539,-9.2806845
6408,6408,166.2357,19.124945,8.7027864,0.0,0,1.0477362,0.0,0.86765403,102.2197,1.0408399,359.98126,-9.2826319
6419,6419,166.2379,19.197437,8.7164068,0.0,0,1.0332733,0.0,0.87028527,102.35722,1.0266036,360.30859,-9.2832327
6430,6430,166.2401,19.252201,8.7275581,0.0,0,1.0188106,0.0,0.87163877,102.54923,1.0102566,360.63593,-9.2831507
6441,6441,166.2423,19.290722,8.7480879,0.0,0,1.0043477,0.0,0.87548363,102.37628,0.99587351,360.96329,-9.2832403
6452,6452,166.2445,19.362423,8.7607231,0.0,0,0.98988503,0.0,0.87684816,102.59286,0.98124886,361.15692,-9.2832737
6463,6463,166.2467,19.451153,8.7728558,0.0,0,0.9754222,0.0,0.87955064,102.74312,0.96699655,361.21686,-9.2839165
6474,6474,166.2489,19.555077,8.785037,0.0,0,0.96095937,0.0,0.88071001,103.17648,0.95228028,361.27679,-9.2832928
6485,6485,166.2511,19.63262,8.8048105,0.0,0,0.94649655,0.0,0.88488656,103.10505,0.93614805,361.33673,-9.2824163
6496,6496,166.2533,19.720484,8.8186064,0.0,0,0.93203384,0.0,0.88597065,103.52291,0.92339182,361.25989,-9.2825661
6507,6507,166.2555,19.767466,8.8295822,0.0,0,0.91757101,0.0,0.88869995,103.5145,0.90826052,361.01889,-9.2818222
6518,6518,166.2577,19.804731,8.8445368,0.0,0,0.90310818,0.0,0.89007747,103.52855,0.8935591,360.77792,-9.283103
6529,6529,166.2599,19.832994,8.8617973,0.0,0,0.88885868,0.0,0.89408118,103.31723,0.8791886,360.53693,-9.2826147
6540,6540,166.2621,19.880619,8.8740492,0.0,0,0.87510425,0.0,0.89481252,103.47251,0.86690432,360.29593,-9.283247
6551,6551,166.2643,19.965595,8.8853569,0.0,0,0.86134988,0.0,0.89785558,103.54825,0.85313183,359.577,-9.2834282
6562,6562,166.2665,20.065617,8.8998089,0.0,0,0.84759545,0.0,0.89895767,103.98101,0.83759207,358.82059,-9.283308
6573,6573,166.2687,20.159937,8.9161854,0.0,0,0.83384109,0.0,0.90324533,104.01865,0.82278335,358.06418,-9.2832584
6584,6584,166.2709,20.234501,8.9334049,0.0,0,0.82008672,0.0,0.90435082,104.26295,0.80688542,357.30774,-9.2825689
6595,6595,166.2731,20.279173,8.9421234,0.0,0,0.80633229,0.0,0.90742749,104.20514,0.79492497,356.5647,-9.2830257
6606,6606,166.2753,20.295788,8.9568701,0.0,0,0.79257792,0.0,0.90827632,104.24891,0.78341252,355.84177,-9.2832708
6617,6617,166.2775,20.292793,8.9679775,0.0,0,0.77882349,0.0,0.91168493,103.83465,0.77101678,355.1188,-9.2827978
6628,6628,166.2797,20.313898,8.9835968,0.0,0,0.76506907,0.0,0.91260833,103.88976,0.75596213,354.39584,-9.2832708
6639,6639,166.2819,20.354813,8.9899263,0.0,0,0.7513147,0.0,0.91545159,103.75747,0.74692726,353.67288,-9.2832413
6650,6650,166.2841,20.447948,9.0058994,0.0,0,0.73756027,0.0,0.91635972,104.14265,0.734613,353.56335,-9.2827759
6661,6661,166.2863,20.593843,9.0137548,0.0,0,0.7238059,0.0,0.91955411,104.50626,0.72064441,353.54327,-9.2833977
6672,6672,166.2885,20.719723,9.0331001,0.0,0,0.71005148,0.0,0.92083216,105.01603,0.70842791,353.52319,-9.2824907
6683,6683,166.2907,20.852995,9.0406618,0.0,0,0.69629705,0.0,0.92408216,105.36607,0.69320774,353.50314,-9.282835
6694,6694,166.2929,20.993484,9.0601158,0.0,0,0.68254268,0.0,0.92547727,105.95564,0.68031669,353.39975,-9.2824907
6705,6705,166.2951,21.094604,9.0693054,0.0,0,0.66878825,0.0,0.92903155,106.08287,0.66665286,353.13858,-9.2827482
6716,6716,166.2973,21.184093,9.0931654,0.0,0,0.65503389,0.0,0.93066752,106.34442,0.65000677,352.87738,-9.2818651
6727,6727,166.2995,21.287397,9.1003799,0.0,0,0.64127946,0.0,0.93414581,106.54391,0.63484877,352.61618,-9.2808094
6738,6738,166.3017,21.382334,9.1190863,0.0,0,0.62752509,0.0,0.93556774,106.82722,0.61852741,352.35498,-9.2826271
6749,6749,166.3039,21.456991,9.1318521,0.0,0,0.61377066,0.0,0.93963116,106.73121,0.6007973,351.7757,-9.2819881
6760,6760,166.3061,21.491678,9.153615,0.0,0,0.6000163,0.0,0.94107187,106.75256,0.59052819,351.1257,-9.2816238
6771,6771,166.3083,21.536678,9.1562357,0.0,0,0.58626187,0.0,0.94373089,106.70022,0.57708907,350.47571,-9.2808714
6782,6782,166.3105,21.582693,9.1737146,0.0,0,0.57288873,0.0,0.9447571,106.85802,0.56302255,349.82571,-9.2822714
6793,6793,166.3127,21.628309,9.180275,0.0,0,0.55979872,0.0,0.94782925,106.77118,0.54869157,349.19885,-9.2819319
6804,6804,166.3149,21.715223,9.2034426,0.0,0,0.5467087,0.0,0.94951236,106.9704,0.53887725,348.62836,-9.2815161
6815,6815,166.3171,21.751554,9.2062874,0.0,0,0.53361875,0.0,0.95227528,106.87067,0.52399212,348.05786,-9.2826338
6826,6826,166.3193,21.832514,9.2273083,0.0,0,0.52052873,0.0,0.95403504,107.0872,0.50612479,347.48737,-9.2817507
6837,6837,166.3215,21.905979,9.2334566,0.0,0,0.50743872,0.0,0.95725632,107.07899,0.49958771,346.91687,-9.2820978
6848,6848,166.3237,22.006443,9.2557154,0.0,0,0.4943487,0.0,0.95855623,107.43065,0.48502177,346.52576,-9.2828465
6859,6859,166.3259,22.11866,9.2578382,0.0,0,0.48125869,0.0,0.96112275,107.68178,0.46851027,346.19016,-9.2827244
6870,6870,166.3281,22.181778,9.2778444,0.0,0,0.46816874,0.0,0.9629513,107.82162,0.45997053,345.85455,-9.2823534
6881,6881,166.3303,22.170937,9.2844944,0.0,0,0.45507869,0.0,0.96587229,107.46825,0.44720936,345.51898,-9.2826748
6892,6892,166.3325,22.166216,9.3051481,0.0,0,0.44198871,0.0,0.96723682,107.30848,0.43521565,345.23096,-9.2817383
6903,6903,166.3347,22.251333,9.3062363,0.0,0,0.42889869,0.0,0.96953791,107.45081,0.42312497,345.09674,-9.2829695
6914,6914,166.3369,22.330376,9.324851,0.0,0,0.41580874,0.0,0.97110116,107.66282,0.4124822,344.96249,-9.2824116
6925,6925,166.3391,22.446003,9.3282747,0.0,0,0.40271869,0.0,0.97343189,107.93728,0.39749616,344.82825,-9.2812061
6936,6936,166.3413,22.613758,9.3527374,0.0,0,0.38962871,0.0,0.9758845,108.45153,0.38398945,344.69403,-9.2810688
6947,6947,166.3435,22.748108,9.3566055,0.0,0,0.37653869,0.0,0.97819018,108.8897,0.37391782,344.42654,-9.2823772
6958,6958,166.3457,22.857735,9.3741798,0.0,0,0.36344871,0.0,0.98003948,109.20839,0.35767049,344.10437,-9.2825012
6969,6969,166.3479,22.945457,9.381381,0.0,0,0.35035869,0.0,0.98262149,109.3633,0.34448647,343.78223,-9.2827492
6980,6980,166.3501,23.019804,9.4049082,0.0,0,0.33726871,0.0,0.98537558,109.39656,0.33250332,343.46005,-9.2819757
6985,6985,166.3511,23.027649,9.3984966,0.0,0,0.33131871,0.0,0.98601818,109.38544,0.32669201,343.31363,-9.2825584