File: clean data/testID_0252.csv
level_0,index,Time(sec),Force(kN),Jaw(mm),PowAngle(deg),Power(W),Pram,PTemp,Strain,Stress(MPa),Stroke(mm),TC1(C),wedge(mm)
2537,2537,195.4096,2.1929855,0.037438348,0.0,0,9.5978632,0.0,0.0023451271,27.59794,9.6922894,449.97104,-9.2356615
2548,2548,195.4118,2.9012172,0.066039205,0.0,0,9.5648632,0.0,0.0045395242,36.7155,9.6619987,450.05652,-9.2342758
2559,2559,195.414,3.1930261,0.10410915,0.0,0,9.5318632,0.0,0.0067482237,40.31673,9.6275492,450.14197,-9.2322788
2570,2570,195.4162,3.375304,0.1355852,0.0,0,9.4988632,0.0,0.0090805059,42.482647,9.5884485,450.22745,-9.2318974
2581,2581,195.4184,3.4617403,0.17045707,0.0,0,9.4662552,0.0,0.01128726,43.666607,9.5546293,450.59824,-9.2328482
2592,2592,195.4206,3.5500667,0.20968349,0.0,0,9.4340639,0.0,0.014187265,44.585567,9.5149059,451.18991,-9.2345333
2603,2603,195.4228,3.6077406,0.24599345,0.0,0,9.4018736,0.0,0.01629365,45.193592,9.478961,451.78156,-9.2343769
2614,2614,195.425,3.6468172,0.27454612,0.0,0,9.3696833,0.0,0.01854774,45.491508,9.4440718,452.37323,-9.2339277
2625,2625,195.4272,3.6728992,0.30720744,0.0,0,9.3374929,0.0,0.020537212,45.920193,9.4098721,452.96671,-9.2333307
2636,2636,195.4294,3.6779349,0.33933139,0.0,0,9.3053026,0.0,0.022989223,45.651085,9.3800888,453.75562,-9.233798
2647,2647,195.4316,3.7134759,0.37061352,0.0,0,9.2731133,0.0,0.024817552,46.150967,9.352108,454.54453,-9.2332554
2658,2658,195.4338,3.7222362,0.3978366,0.0,0,9.240922,0.0,0.026913157,46.09874,9.3153572,455.33344,-9.2330256
2669,2669,195.436,3.7308662,0.42992216,0.0,0,9.2087317,0.0,0.028902132,46.141216,9.2866325,456.12234,-9.233243
2680,2680,195.4382,3.703691,0.46210104,0.0,0,9.1765404,0.0,0.031388182,45.731056,9.2533035,456.78864,-9.2332153
2691,2691,195.4404,3.703583,0.49396089,0.0,0,9.144351,0.0,0.033250183,45.590668,9.2230082,457.3078,-9.2338867
2702,2702,195.4426,3.7225196,0.52234143,0.0,0,9.1121607,0.0,0.03550797,45.721619,9.1882906,457.82697,-9.2325706
2713,2713,195.4448,3.7425044,0.55755985,0.0,0,9.0799694,0.0,0.037707537,45.854279,9.1532202,458.34616,-9.234416
2724,2724,195.447,3.7617056,0.59294003,0.0,0,9.0477791,0.0,0.040445309,46.002079,9.1235294,458.86533,-9.2354727
2735,2735,195.4492,3.770153,0.62713647,0.0,0,9.0155888,0.0,0.04249708,45.98616,9.0872183,459.31323,-9.233964
2746,2746,195.4514,3.7679613,0.65637875,0.0,0,8.9833984,0.0,0.04485096,45.778629,9.052804,459.75323,-9.2344189
2757,2757,195.4536,3.7718284,0.68795872,0.0,0,8.9512091,0.0,0.04674593,45.82555,9.0245132,460.19321,-9.2345686
2768,2768,195.4558,3.7742977,0.72307897,0.0,0,8.9190178,0.0,0.049519282,45.819664,8.9866009,460.63321,-9.2345848
2779,2779,195.458,3.7756145,0.75603217,0.0,0,8.8868265,0.0,0.05148536,45.670773,8.9586163,461.03687,-9.2354383
2790,2790,195.4602,3.7848322,0.78515697,0.0,0,8.8546362,0.0,0.05381519,45.656403,8.9213381,461.3717,-9.2339725
2801,2801,195.4624,3.8193111,0.81824809,0.0,0,8.8224468,0.0,0.055915441,45.981968,8.8887558,461.70654,-9.2347307
2812,2812,195.4646,3.8277185,0.85230303,0.0,0,8.7902565,0.0,0.058705311,45.990017,8.8586111,462.04138,-9.2351923
2823,2823,195.4668,3.8488951,0.88405216,0.0,0,8.7580652,0.0,0.060522929,46.166588,8.8235502,462.37622,-9.2349014
2834,2834,195.469,3.8727634,0.91421503,0.0,0,8.7270651,0.0,0.062929489,46.283253,8.787755,462.60721,-9.2350349
2845,2845,195.4712,3.8822436,0.94664496,0.0,0,8.6964502,0.0,0.065008506,46.274323,8.7556343,462.81073,-9.2345295
2856,2856,195.4734,3.8760581,0.98139018,0.0,0,8.6658354,0.0,0.067810237,46.115505,8.7227716,463.01425,-9.2344437
2867,2867,195.4756,3.8567519,1.0106914,0.0,0,8.6352196,0.0,0.069537841,45.830139,8.6971226,463.21777,-9.2337208
2878,2878,195.4778,3.8580205,1.0390303,0.0,0,8.6046047,0.0,0.071844332,45.699604,8.6662235,463.39804,-9.2345829
2889,2889,195.48,3.8846862,1.0681558,0.0,0,8.5739899,0.0,0.073688619,45.908283,8.6346445,463.50308,-9.234704
2900,2900,195.4822,3.9123905,1.1003296,0.0,0,8.5433741,0.0,0.076290108,46.122066,8.6056242,463.60812,-9.2337685
2911,2911,195.4844,3.9242339,1.1308366,0.0,0,8.5127592,0.0,0.078196026,46.192249,8.573247,463.71317,-9.2344475
2922,2922,195.4866,3.944231,1.1588281,0.0,0,8.4821434,0.0,0.080504544,46.301483,8.5405827,463.81821,-9.2350254
2933,2933,195.4888,3.9661648,1.1879584,0.0,0,8.4515295,0.0,0.082345419,46.575218,8.5152159,463.88745,-9.2353439
2944,2944,195.491,3.9935865,1.2195337,0.0,0,8.4209127,0.0,0.084933445,46.709515,8.4831581,463.93997,-9.2357445
2955,2955,195.4932,4.002346,1.2529461,0.0,0,8.3902988,0.0,0.086963341,46.750496,8.4518423,463.99249,-9.2336683
2966,2966,195.4954,3.9991765,1.279014,0.0,0,8.359683,0.0,0.089248128,46.606613,8.422287,464.04504,-9.2351904
2977,2977,195.4976,4.0257797,1.3090564,0.0,0,8.3290682,0.0,0.091156632,46.800529,8.389617,464.10092,-9.2339859
2988,2988,195.4998,4.0524459,1.3436776,0.0,0,8.2984524,0.0,0.094056867,46.955688,8.3549595,464.17969,-9.2345934
2999,2999,195.502,4.0910211,1.3785735,0.0,0,8.2678375,0.0,0.096157901,47.218018,8.3263483,464.25848,-9.2352009
3010,3010,195.5042,4.1115799,1.4078811,0.0,0,8.2372227,0.0,0.098655276,47.421761,8.2909479,464.33725,-9.2343931
3021,3021,195.5064,4.1342144,1.437373,0.0,0,8.2066088,0.0,0.10049555,47.55587,8.2571421,464.41605,-9.2340441
3032,3032,195.5086,4.1410217,1.4699219,0.0,0,8.175992,0.0,0.10325468,47.52243,8.227828,464.49484,-9.2344551
3043,3043,195.5108,4.154531,1.5012022,0.0,0,8.1453772,0.0,0.10526545,47.537174,8.197094,464.57361,-9.2355871
3054,3054,195.513,4.1375637,1.5289607,0.0,0,8.1147623,0.0,0.10759709,47.343872,8.167038,464.6524,-9.2345896
3065,3065,195.5152,4.1482439,1.5576216,0.0,0,8.0841465,0.0,0.10943806,47.400612,8.1351948,464.73117,-9.2357349
3076,3076,195.5174,4.1682119,1.5912418,0.0,0,8.053587,0.0,0.1123473,47.413948,8.1085615,464.80902,-9.2345409
3087,3087,195.5196,4.189527,1.6223772,0.0,0,8.0244465,0.0,0.11419246,47.554539,8.0749874,464.83527,-9.2336235
3098,3098,195.5218,4.2304249,1.6492175,0.0,0,7.9953175,0.0,0.11652561,47.965271,8.0422678,464.86154,-9.23382
3109,3109,195.524,4.2429709,1.6784776,0.0,0,7.9661894,0.0,0.11847624,47.860142,8.0130711,464.88779,-9.2346802
3120,3120,195.5262,4.2392077,1.7108717,0.0,0,7.9370618,0.0,0.12123472,47.784695,7.9821444,464.91403,-9.234149
3131,3131,195.5284,4.2469645,1.7405151,0.0,0,7.9079332,0.0,0.12307613,47.816288,7.9549117,464.93726,-9.2340069
3142,3142,195.5306,4.2533116,1.7649763,0.0,0,7.8788056,0.0,0.12532851,47.73431,7.9266171,464.95694,-9.2346048
3153,3153,195.5328,4.2469811,1.7941128,0.0,0,7.8496776,0.0,0.12719393,47.702335,7.9014168,464.97665,-9.2351923
3164,3164,195.535,4.2725196,1.8258058,0.0,0,7.8205495,0.0,0.1299915,47.810364,7.8693027,464.99634,-9.2343998
3175,3175,195.5372,4.3038087,1.8553641,0.0,0,7.7914219,0.0,0.13175724,48.069263,7.8360882,465.01602,-9.2354317
3186,3186,195.5394,4.3194366,1.8809844,0.0,0,7.7622933,0.0,0.13405745,48.088161,7.8097177,464.99396,-9.2345877
3197,3197,195.5416,4.3543477,1.9101093,0.0,0,7.7331653,0.0,0.13599965,48.351585,7.7782598,464.96768,-9.2345724
3208,3208,195.5438,4.3610892,1.9393928,0.0,0,7.7040377,0.0,0.1386445,48.409733,7.7512836,464.94144,-9.234313
3219,3219,195.546,4.3770232,1.9700917,0.0,0,7.6749096,0.0,0.14055772,48.404877,7.7223592,464.91516,-9.2346115
3230,3230,195.5482,4.396266,1.9956961,0.0,0,7.6457815,0.0,0.1429224,48.507935,7.6926675,464.86331,-9.2347412
3241,3241,195.5504,4.4227066,2.0246973,0.0,0,7.6166534,0.0,0.14480224,48.780682,7.6605706,464.76483,-9.2345858
3252,3252,195.5526,4.4186001,2.0568194,0.0,0,7.5875254,0.0,0.14762217,48.536301,7.6328154,464.66635,-9.2344131
3263,3263,195.5548,4.4175286,2.0866461,0.0,0,7.5583973,0.0,0.14948486,48.447464,7.6052322,464.56787,-9.234601
3274,3274,195.557,4.4510355,2.1129124,0.0,0,7.5292697,0.0,0.15191232,48.659931,7.5724564,464.46939,-9.2344675
3285,3285,195.5592,4.4835062,2.1405711,0.0,0,7.5001411,0.0,0.15377824,48.955273,7.5437574,464.39194,-9.2347879
3296,3296,195.5614,4.5156751,2.172169,0.0,0,7.4710135,0.0,0.15660144,49.170132,7.5166268,464.3197,-9.2345142
3307,3307,195.5636,4.5284572,2.2015128,0.0,0,7.4418855,0.0,0.15842336,49.195847,7.4837985,464.2475,-9.2337685
3318,3318,195.5658,4.5445671,2.2292976,0.0,0,7.4127569,0.0,0.16095267,49.281166,7.4575181,464.17529,-9.2337275
3329,3329,195.568,4.5506811,2.2595558,0.0,0,7.3840585,0.0,0.16295122,49.274117,7.427403,464.11755,-9.2345209
3340,3340,195.5702,4.5683165,2.290246,0.0,0,7.3563566,0.0,0.16580091,49.336922,7.3944378,464.10443,-9.2351246
3351,3351,195.5724,4.5712671,2.320519,0.0,0,7.3286538,0.0,0.16779175,49.255558,7.363924,464.09131,-9.2339859
3362,3362,195.5746,4.5729074,2.3452702,0.0,0,7.3009515,0.0,0.17014559,49.100063,7.3357263,464.07816,-9.2342548
3373,3373,195.5768,4.5950885,2.3723307,0.0,0,7.2732491,0.0,0.17191313,49.29705,7.3120027,464.06503,-9.2343445
3384,3384,195.579,4.6179848,2.4019718,0.0,0,7.2455468,0.0,0.17467158,49.426201,7.2818489,463.94757,-9.2347755
3395,3395,195.5812,4.6275764,2.4305255,0.0,0,7.217844,0.0,0.17653972,49.345654,7.2563553,463.78342,-9.2339935
3406,3406,195.5834,4.641191,2.4546192,0.0,0,7.1901417,0.0,0.17883629,49.381199,7.2256284,463.61929,-9.2343779
3417,3417,195.5856,4.6548071,2.4826725,0.0,0,7.1624393,0.0,0.18070193,49.525368,7.2023978,463.45514,-9.2335186
3428,3428,195.5878,4.659996,2.5107434,0.0,0,7.134737,0.0,0.18338105,49.450077,7.169889,463.26324,-9.2344151
3439,3439,195.59,4.683959,2.5401256,0.0,0,7.1070347,0.0,0.18518145,49.519375,7.1458082,462.8956,-9.2348175
3450,3450,195.5922,4.6885881,2.5631709,0.0,0,7.0793324,0.0,0.18756868,49.496113,7.117301,462.52792,-9.2339687
3461,3461,195.5944,4.7200761,2.5919015,0.0,0,7.05163,0.0,0.18944682,49.768364,7.0886297,462.16028,-9.2344875
3472,3472,195.5966,4.7655115,2.6209238,0.0,0,7.0239277,0.0,0.19224425,50.082256,7.0579591,461.7926,-9.2346449
3483,3483,195.5988,4.7997003,2.6511958,0.0,0,6.9962254,0.0,0.19413964,50.33329,7.0313582,461.53189,-9.2345238
3494,3494,195.601,4.8101258,2.6762366,0.0,0,6.9685221,0.0,0.19665021,50.318905,7.0010738,461.34805,-9.234623
3505,3505,195.6032,4.8285618,2.7038496,0.0,0,6.9408202,0.0,0.19853222,50.347111,6.9707856,461.16422,-9.2336035
3516,3516,195.6054,4.8196335,2.7330742,0.0,0,6.9131179,0.0,0.20134655,50.218216,6.945601,460.98041,-9.2338448
3527,3527,195.6076,4.8352461,2.7633929,0.0,0,6.8854156,0.0,0.20330611,50.272064,6.9195352,460.80194,-9.2340956
3538,3538,195.6098,4.8526068,2.7878327,0.0,0,6.8577132,0.0,0.20579286,50.31847,6.8889441,460.81506,-9.2344112
3549,3549,195.612,4.8666139,2.814852,0.0,0,6.8300109,0.0,0.20761362,50.316559,6.8619175,460.82819,-9.2346878
3560,3560,195.6142,4.91503,2.8441141,0.0,0,6.8023081,0.0,0.21047999,50.639687,6.8328223,460.84134,-9.2335243
3571,3571,195.6164,4.9392223,2.8724279,0.0,0,6.7746053,0.0,0.21234742,50.857342,6.8035803,460.85446,-9.2337551
3582,3582,195.6186,4.9458313,2.8981831,0.0,0,6.7476759,0.0,0.21482737,50.796429,6.7736173,460.87381,-9.2336798
3593,3593,195.6208,4.9277458,2.9247305,0.0,0,6.7213197,0.0,0.21670526,50.525108,6.7462921,460.90009,-9.2344522
3604,3604,195.623,4.9248414,2.9524512,0.0,0,6.6949639,0.0,0.21946259,50.453972,6.7225304,460.92633,-9.2329521
3615,3615,195.6252,4.9381757,2.9786878,0.0,0,6.6686077,0.0,0.22105959,50.418156,6.6986217,460.95261,-9.232522
3626,3626,195.6274,4.9609957,2.9998877,0.0,0,6.642252,0.0,0.22338638,50.475494,6.6688228,460.97888,-9.2338476
3637,3637,195.6296,4.9685059,3.0278296,0.0,0,6.6158962,0.0,0.22525737,50.581333,6.6456914,459.95514,-9.2343616
3648,3648,195.6318,5.0021248,3.055058,0.0,0,6.58954,0.0,0.22797674,50.71851,6.6229343,458.83786,-9.2327375
3659,3659,195.634,5.048295,3.0801044,0.0,0,6.5631843,0.0,0.22958152,51.087208,6.5915337,457.72058,-9.233098
3670,3670,195.6362,5.0855074,3.1044877,0.0,0,6.536828,0.0,0.23205765,51.339764,6.5657301,456.60327,-9.2337513
3681,3681,195.6384,5.0975804,3.13393,0.0,0,6.5104718,0.0,0.23413146,51.400986,6.5370708,455.56488,-9.2338581
3692,3692,195.6406,5.0941968,3.16467,0.0,0,6.4841161,0.0,0.23716459,51.215286,6.5114293,454.66458,-9.2337618
3703,3703,195.6428,5.1100016,3.1913474,0.0,0,6.4577599,0.0,0.23887148,51.270481,6.4815636,453.76428,-9.2346992
3714,3714,195.645,5.1174202,3.2146444,0.0,0,6.4314041,0.0,0.2413712,51.153713,6.4561477,452.86398,-9.2345552
3725,3725,195.6472,5.1112285,3.23874,0.0,0,6.4050479,0.0,0.24292605,51.015587,6.4329672,451.96368,-9.2330608
3736,3736,195.6494,5.142447,3.2647624,0.0,0,6.3786922,0.0,0.24571435,51.183655,6.4079108,451.86627,-9.2329597
3747,3747,195.6516,5.1824536,3.2942955,0.0,0,6.3523359,0.0,0.2476348,51.454834,6.3809223,451.95831,-9.2318821
3758,3758,195.6538,5.2358274,3.3176298,0.0,0,6.3259802,0.0,0.25010312,51.884361,6.3538532,452.05035,-9.2319145
3769,3769,195.656,5.25137,3.3448927,0.0,0,6.2996244,0.0,0.25200328,52.010792,6.3268151,452.1424,-9.2330856
3780,3780,195.6582,5.2654862,3.3735297,0.0,0,6.2732687,0.0,0.25496879,51.987976,6.297173,452.04367,-9.2343988
3791,3791,195.6604,5.2688556,3.4025731,0.0,0,6.2469125,0.0,0.25690234,51.918533,6.2709846,451.38623,-9.2325821
3802,3802,195.6626,5.2898483,3.4240339,0.0,0,6.2205563,0.0,0.25932693,51.892612,6.2429156,450.72882,-9.2329636
3813,3813,195.6648,5.2994838,3.4511318,0.0,0,6.1942005,0.0,0.26121897,51.96228,6.2183499,450.07138,-9.2329111
3824,3824,195.667,5.3275003,3.4777796,0.0,0,6.1678443,0.0,0.26405376,52.087288,6.1908851,449.41397,-9.2319937
3835,3835,195.6692,5.3501167,3.5054111,0.0,0,6.14258,0.0,0.26588565,52.164471,6.1651464,448.57706,-9.2328472
3846,3846,195.6714,5.3716726,3.5304847,0.0,0,6.1175132,0.0,0.26856795,52.265781,6.1398287,447.66324,-9.2338095
3857,3857,195.6736,5.3799081,3.5578203,0.0,0,6.0924463,0.0,0.27041376,52.275631,6.1124229,446.74939,-9.2346325
3868,3868,195.6758,5.3815794,3.5819976,0.0,0,6.0673795,0.0,0.27314037,52.100487,6.0887551,445.83557,-9.2330751
3879,3879,195.678,5.3901782,3.6083906,0.0,0,6.0423131,0.0,0.27486113,52.135536,6.0616517,445.02118,-9.2332964
3890,3890,195.6802,5.3852172,3.6291354,0.0,0,6.0172458,0.0,0.27718243,51.946552,6.037045,444.79108,-9.2340384
3901,3901,195.6824,5.3854237,3.6535814,0.0,0,5.9921789,0.0,0.27885982,51.850468,6.0105486,444.56097,-9.2337284
3912,3912,195.6846,5.4116998,3.6789756,0.0,0,5.9671125,0.0,0.28160912,52.006001,5.9920402,444.33087,-9.2343588
3923,3923,195.6868,5.4378033,3.7037749,0.0,0,5.9420452,0.0,0.28321478,52.144173,5.9640026,444.1008,-9.2337713
3934,3934,195.689,5.4876108,3.7248394,0.0,0,5.9169788,0.0,0.28566399,52.44537,5.9428473,444.16983,-9.2336626
3945,3945,195.6912,5.5377817,3.7519915,0.0,0,5.891912,0.0,0.28758469,52.840878,5.9170432,444.44595,-9.2353725
3956,3956,195.6934,5.5605488,3.7803028,0.0,0,5.8668451,0.0,0.29064572,53.001472,5.8888059,444.72211,-9.2334137
3967,3967,195.6956,5.6003194,3.8066363,0.0,0,5.8417783,0.0,0.29239482,53.187904,5.862421,444.99823,-9.2335911
3978,3978,195.6978,5.6150522,3.8313465,0.0,0,5.8167109,0.0,0.29514804,53.21516,5.8349919,445.27271,-9.2345257
3989,3989,195.7,5.6155314,3.8599629,0.0,0,5.7916446,0.0,0.29714686,53.11375,5.8101959,445.50281,-9.2345533
4000,4000,195.7022,5.635942,3.8874111,0.0,0,5.7665777,0.0,0.3001532,53.138474,5.7795906,445.73291,-9.2345276
4011,4011,195.7044,5.6607165,3.9124379,0.0,0,5.7415109,0.0,0.30188122,53.223797,5.7551584,445.96298,-9.2338314
4022,4022,195.7066,5.664537,3.9345806,0.0,0,5.716444,0.0,0.30444458,53.238388,5.72822,446.19308,-9.2339153
4033,4033,195.7088,5.6683283,3.9599223,0.0,0,5.6913776,0.0,0.30616438,53.063454,5.7026782,446.41684,-9.2332973
4044,4044,195.711,5.6852798,3.9854443,0.0,0,5.6663103,0.0,0.3091428,53.164001,5.6816545,446.63379,-9.2315025
4055,4055,195.7132,5.6915612,4.0109682,0.0,0,5.6412435,0.0,0.31075108,53.091625,5.6572003,446.85077,-9.2327242
4066,4066,195.7154,5.7061067,4.0308466,0.0,0,5.6161766,0.0,0.31315729,53.115993,5.6337023,447.06772,-9.234211
4077,4077,195.7176,5.7045565,4.0544224,0.0,0,5.5912561,0.0,0.31479844,53.068321,5.6100926,447.28467,-9.2344189
4088,4088,195.7198,5.7361159,4.0802417,0.0,0,5.5674076,0.0,0.31778765,53.148197,5.5872431,447.47113,-9.2337942
4099,4099,195.722,5.7584348,4.1044583,0.0,0,5.5435596,0.0,0.31936303,53.195847,5.5609398,447.65521,-9.2330732
4110,4110,195.7242,5.7881532,4.1232362,0.0,0,5.519712,0.0,0.32170179,53.305553,5.5366702,447.83929,-9.2328377
4121,4121,195.7264,5.8284183,4.1491804,0.0,0,5.4958634,0.0,0.3233965,53.718239,5.5166206,448.02335,-9.2327805
4132,4132,195.7286,5.8589602,4.1750612,0.0,0,5.4720159,0.0,0.3265011,53.746674,5.4898167,448.19272,-9.2330732
4143,4143,195.7308,5.8821077,4.2012029,0.0,0,5.4481678,0.0,0.3282575,54.009388,5.4618793,448.33737,-9.2330151
4154,4154,195.733,5.9015055,4.2217278,0.0,0,5.4243197,0.0,0.33070695,54.003765,5.4415159,448.48199,-9.2336626
4165,4165,195.7352,5.9265175,4.2480631,0.0,0,5.4004722,0.0,0.33265239,54.138783,5.4158516,448.62662,-9.2339306
4176,4176,195.7374,5.919014,4.2737765,0.0,0,5.3766236,0.0,0.33562315,53.893028,5.3911662,448.77124,-9.2327995
4187,4187,195.7396,5.9370437,4.29702,0.0,0,5.3527756,0.0,0.33721748,53.914715,5.364408,448.84058,-9.2341852
4198,4198,195.7418,5.9671416,4.3188176,0.0,0,5.328928,0.0,0.33976221,54.00742,5.3410964,448.89319,-9.2327728
4209,4209,195.744,5.9810419,4.3443265,0.0,0,5.3050799,0.0,0.34162286,54.082485,5.3193784,448.94577,-9.2333803
4220,4220,195.7462,6.0021801,4.3704319,0.0,0,5.2812319,0.0,0.34474969,54.148087,5.29632,448.99838,-9.2345018
4231,4231,195.7484,6.0338616,4.3954263,0.0,0,5.2573838,0.0,0.34637022,54.285179,5.272325,449.03192,-9.2330332
4242,4242,195.7506,6.0696359,4.4135513,0.0,0,5.2335358,0.0,0.34866697,54.509235,5.2462702,449.01218,-9.2338524
4253,4253,195.7528,6.0849605,4.4388242,0.0,0,5.2096877,0.0,0.35053736,54.582222,5.2235918,448.99246,-9.2343512
4264,4264,195.755,6.1095934,4.4665017,0.0,0,5.1858397,0.0,0.35384116,54.673981,5.2007084,448.97272,-9.2338076
4275,4275,195.7572,6.120306,4.49229,0.0,0,5.1619916,0.0,0.35553947,54.5602,5.1720705,448.953,-9.2324362
4286,4286,195.7594,6.1433778,4.5112638,0.0,0,5.1381435,0.0,0.35794446,54.686405,5.149096,448.90997,-9.2329569
4297,4297,195.7616,6.1651945,4.5365367,0.0,0,5.1142955,0.0,0.35985547,54.793751,5.1258478,448.85736,-9.2327747
4308,4308,195.7638,6.1804724,4.5613818,0.0,0,5.0904479,0.0,0.36282542,54.771065,5.1035666,448.80478,-9.2344313
4319,4319,195.766,6.194416,4.585741,0.0,0,5.0665994,0.0,0.36452761,54.73185,5.0746727,448.75217,-9.233139
4330,4330,195.7682,6.1995397,4.6042066,0.0,0,5.0432091,0.0,0.36696476,54.693024,5.0570803,448.66098,-9.2327776
4341,4341,195.7704,6.2200532,4.6297226,0.0,0,5.0205269,0.0,0.36876535,54.772461,5.0367217,448.35855,-9.2328548
4352,4352,195.7726,6.2556453,4.6530395,0.0,0,4.9978447,0.0,0.37164643,54.949429,5.0137095,448.05615,-9.2332735
4363,4363,195.7748,6.2814341,4.6759224,0.0,0,4.975163,0.0,0.37313685,55.054432,4.9867077,447.75375,-9.2334881
4374,4374,195.777,6.3009067,4.6948152,0.0,0,4.9524813,0.0,0.37574074,55.043736,4.9636898,447.45135,-9.2335768
4385,4385,195.7792,6.3262358,4.7215285,0.0,0,4.9297986,0.0,0.37771466,55.261974,4.9404097,447.05426,-9.2329168
4396,4396,195.7814,6.3615847,4.7492847,0.0,0,4.9071169,0.0,0.38105127,55.325485,4.9180789,446.59409,-9.2324762
4407,4407,195.7836,6.3884411,4.771069,0.0,0,4.8844347,0.0,0.38246164,55.469852,4.8934503,446.13388,-9.2328196
4418,4418,195.7858,6.3951778,4.7897072,0.0,0,4.861753,0.0,0.38484418,55.456577,4.8705239,445.67368,-9.2333603
4429,4429,195.788,6.4219747,4.8141379,0.0,0,4.8390708,0.0,0.38668305,55.622265,4.8502645,445.19733,-9.2338991
4440,4440,195.7902,6.4270058,4.8395691,0.0,0,4.8163886,0.0,0.38981262,55.454365,4.8254957,444.38132,-9.2347364
4451,4451,195.7924,6.4141335,4.8628144,0.0,0,4.7937069,0.0,0.39147997,55.213036,4.8027477,443.56534,-9.2331915
4462,4462,195.7946,6.427454,4.8782811,0.0,0,4.7710247,0.0,0.39363667,55.203541,4.7815967,442.74933,-9.2339258
4473,4473,195.7968,6.4587426,4.9005456,0.0,0,4.748343,0.0,0.39514327,55.373753,4.76016,441.93332,-9.2336779
4484,4484,195.799,6.5071154,4.9248252,0.0,0,4.7256608,0.0,0.39835262,55.580772,4.7373137,441.18185,-9.2334366
4495,4495,195.8012,6.5517421,4.9502177,0.0,0,4.7029786,0.0,0.40001306,55.911106,4.7165661,440.49725,-9.2325468
4506,4506,195.8034,6.5874047,4.9694028,0.0,0,4.6802969,0.0,0.402744,56.067028,4.6892104,439.81265,-9.2337475
4517,4517,195.8056,6.5872235,4.9920969,0.0,0,4.6576152,0.0,0.40433505,55.942001,4.6707764,439.12805,-9.2327337
4528,4528,195.8078,6.6144624,5.0154939,0.0,0,4.6349325,0.0,0.40730295,56.001747,4.6470814,438.44348,-9.2341566
4539,4539,195.81,6.6553559,5.0395927,0.0,0,4.6122508,0.0,0.40899062,56.261044,4.623631,438.31973,-9.2334299
4550,4550,195.8122,6.6865883,5.0604105,0.0,0,4.5895686,0.0,0.41178805,56.356033,4.5986681,438.23413,-9.2336121
4561,4561,195.8144,6.6960511,5.0855875,0.0,0,4.5668869,0.0,0.41378462,56.369431,4.5748119,438.14853,-9.2329836
4572,4572,195.8166,6.7437282,5.1102757,0.0,0,4.5442047,0.0,0.41686374,56.501915,4.5528083,438.06293,-9.232585
4583,4583,195.8188,6.770587,5.1361132,0.0,0,4.5222569,0.0,0.41875139,56.70929,4.5279641,438.10553,-9.2324114
4594,4594,195.821,6.7903976,5.1560149,0.0,0,4.500679,0.0,0.42149085,56.68034,4.5010586,438.35574,-9.2338848
4605,4605,195.8232,6.776546,5.1776466,0.0,0,4.4791017,0.0,0.42299747,56.523628,4.4840355,438.60596,-9.2337179
4616,4616,195.8254,6.7740922,5.1993341,0.0,0,4.4575238,0.0,0.42593464,56.370182,4.4628034,438.85617,-9.2324429
4627,4627,195.8276,6.7770944,5.2223454,0.0,0,4.4359465,0.0,0.42745236,56.300144,4.4427457,439.10638,-9.2343721
4638,4638,195.8298,6.7974648,5.2406259,0.0,0,4.4143691,0.0,0.4300929,56.332169,4.4207201,439.26398,-9.2341347
4649,4649,195.832,6.8132081,5.2627754,0.0,0,4.3927913,0.0,0.43172392,56.301937,4.3983259,439.40228,-9.2317848
4660,4660,195.8342,6.8380523,5.2831945,0.0,0,4.3712134,0.0,0.43460196,56.37022,4.3781896,439.54056,-9.2327566
4671,4671,195.8364,6.8857565,5.3051643,0.0,0,4.3496361,0.0,0.43601599,56.673676,4.3562303,439.67883,-9.2329893
4682,4682,195.8386,6.9355507,5.3235159,0.0,0,4.3280582,0.0,0.43869343,56.866409,4.3359594,439.71115,-9.2336721
4693,4693,195.8408,6.9609275,5.3460474,0.0,0,4.3064809,0.0,0.44028285,57.069679,4.3154221,439.46094,-9.2329817
4704,4704,195.843,6.9963627,5.3707385,0.0,0,4.284903,0.0,0.44352168,57.201759,4.2927313,439.21072,-9.2331228
4715,4715,195.8452,7.0261612,5.3939552,0.0,0,4.2633252,0.0,0.44526017,57.295277,4.2693725,438.96051,-9.2322874
4726,4726,195.8474,7.042058,5.412487,0.0,0,4.2417479,0.0,0.44785354,57.323547,4.2436767,438.71033,-9.2329903
4737,4737,195.8496,7.0540738,5.4360094,0.0,0,4.2201705,0.0,0.44961324,57.312275,4.2257738,438.51685,-9.2336693
4748,4748,195.8518,7.0774879,5.4583755,0.0,0,4.1985927,0.0,0.4528434,57.289936,4.2056413,438.34564,-9.2323132
4759,4759,195.854,7.090549,5.481461,0.0,0,4.1770153,0.0,0.45435199,57.234825,4.1828518,438.17447,-9.2328119
4770,4770,195.8562,7.1371164,5.5002465,0.0,0,4.1554375,0.0,0.45704478,57.490772,4.1629825,438.00327,-9.2329006
4781,4781,195.8584,7.1651754,5.5231166,0.0,0,4.1338601,0.0,0.45877439,57.66618,4.1424098,437.83206,-9.2337198
4792,4792,195.8606,7.1966314,5.545476,0.0,0,4.1122823,0.0,0.46198499,57.707123,4.1200237,437.66089,-9.2339373
4803,4803,195.8628,7.2275701,5.5700622,0.0,0,4.0907049,0.0,0.46371442,57.891098,4.095726,437.48969,-9.2331676
4814,4814,195.865,7.2643471,5.5892134,0.0,0,4.0691271,0.0,0.46647266,58.059711,4.0729942,437.31848,-9.2343006
4825,4825,195.8672,7.296937,5.6138663,0.0,0,4.0475497,0.0,0.46844161,58.12471,4.0539513,437.14731,-9.2330809
4836,4836,195.8694,7.2997928,5.6352634,0.0,0,4.0269618,0.0,0.47151136,58.002857,4.0291157,436.7836,-9.2317429
4847,4847,195.8716,7.2941213,5.6584334,0.0,0,4.0064402,0.0,0.4730882,57.784798,4.004406,436.29636,-9.2321711
4858,4858,195.8738,7.2826328,5.6766229,0.0,0,3.9859188,0.0,0.4758333,57.622581,3.9842732,435.80911,-9.2323036
4869,4869,195.876,7.3159852,5.6966672,0.0,0,3.9653969,0.0,0.47722298,57.795387,3.9686978,435.32187,-9.2321072
4880,4880,195.8782,7.3484154,5.7158532,0.0,0,3.9448752,0.0,0.48012847,57.952099,3.9450202,434.82315,-9.2315369
4891,4891,195.8804,7.349596,5.7385015,0.0,0,3.9243536,0.0,0.48174551,57.828156,3.9263864,434.12518,-9.2327108
4902,4902,195.8826,7.3453627,5.7552471,0.0,0,3.9038324,0.0,0.48442,57.625217,3.9079471,433.42725,-9.2327061
4913,4913,195.8848,7.3753133,5.7751784,0.0,0,3.8833106,0.0,0.48568928,57.83234,3.8897574,432.72931,-9.2337952
4924,4924,195.887,7.4337311,5.7954488,0.0,0,3.8627889,0.0,0.48879948,58.035057,3.8685555,432.03134,-9.2332191
4935,4935,195.8892,7.4719434,5.8187184,0.0,0,3.8422673,0.0,0.49040738,58.225887,3.8493321,431.47498,-9.2330151
4946,4946,195.8914,7.505795,5.8356028,0.0,0,3.8217459,0.0,0.49300641,58.357216,3.8259895,431.06015,-9.2317181
4957,4957,195.8936,7.5491748,5.8570862,0.0,0,3.8012242,0.0,0.49459618,58.603626,3.8077385,430.64532,-9.2324791
4968,4968,195.8958,7.6106038,5.8793807,0.0,0,3.7807026,0.0,0.49787787,58.879353,3.7864685,430.23047,-9.232873
4979,4979,195.898,7.6595659,5.9050717,0.0,0,3.760181,0.0,0.49980816,59.199192,3.7606096,429.81564,-9.2330656
4990,4990,195.9002,7.686408,5.923842,0.0,0,3.7396593,0.0,0.50273353,59.236286,3.7410877,429.7121,-9.2338257
5001,5001,195.9024,7.7114115,5.9462066,0.0,0,3.7191379,0.0,0.50445479,59.300629,3.7189317,429.62653,-9.2331228
5012,5012,195.9046,7.7213063,5.970016,0.0,0,3.6986163,0.0,0.50791031,59.194447,3.6980739,429.54092,-9.232851
5023,5023,195.9068,7.7384095,5.9924598,0.0,0,3.6780944,0.0,0.50959784,59.152668,3.672343,429.45532,-9.2320557
5034,5034,195.909,7.7385626,6.0115414,0.0,0,3.657573,0.0,0.51242304,59.041676,3.6500998,429.4418,-9.232585
5045,5045,195.9112,7.7464218,6.0342269,0.0,0,3.6370516,0.0,0.51418012,58.949749,3.6307018,429.54056,-9.2328749
5056,5056,195.9134,7.7608204,6.0531602,0.0,0,3.6165297,0.0,0.51719981,58.819115,3.612072,429.63934,-9.2329979
5067,5067,195.9156,7.7981973,6.0741105,0.0,0,3.5960083,0.0,0.51851219,59.094597,3.5925703,429.7381,-9.232213
5078,5078,195.9178,7.802402,6.0888987,0.0,0,3.5756967,0.0,0.52113926,58.985172,3.5742805,429.83685,-9.2329397
5089,5089,195.92,7.7912836,6.1096578,0.0,0,3.556174,0.0,0.52260637,58.824112,3.5563848,429.74838,-9.2321653
5100,5100,195.9222,7.8075504,6.1311188,0.0,0,3.5366509,0.0,0.52593493,58.703613,3.5367281,429.62329,-9.2312088
5111,5111,195.9244,7.8491907,6.1510806,0.0,0,3.5171282,0.0,0.52722317,59.009609,3.5182064,429.4982,-9.2316561
5122,5122,195.9266,7.8889375,6.1643171,0.0,0,3.4976053,0.0,0.52946854,59.185097,3.4986894,429.37308,-9.2321997
5133,5133,195.9288,7.9307642,6.1846895,0.0,0,3.4780829,0.0,0.53105366,59.363213,3.4804506,429.17926,-9.2332249
5144,5144,195.931,7.9781837,6.207552,0.0,0,3.4585598,0.0,0.53465509,59.488834,3.4607251,428.81033,-9.2327404
5155,5155,195.9332,8.0283718,6.2296534,0.0,0,3.4390368,0.0,0.53623509,59.786694,3.4392788,428.44141,-9.2328587
5166,5166,195.9354,8.0683308,6.2462435,0.0,0,3.4195144,0.0,0.53894484,59.931366,3.4181705,428.07245,-9.2333488
5177,5177,195.9376,8.076067,6.2671704,0.0,0,3.3999913,0.0,0.54053539,59.891899,3.3988776,427.70352,-9.2330065
5188,5188,195.9398,8.0919333,6.2876801,0.0,0,3.3804688,0.0,0.54375422,59.817211,3.3804352,427.3439,-9.2330179
5199,5199,195.942,8.1238642,6.3101063,0.0,0,3.3609457,0.0,0.54536474,59.963299,3.3592699,426.98779,-9.2333374
5210,5210,195.9442,8.1487198,6.3251472,0.0,0,3.3414228,0.0,0.54803938,59.93948,3.3383141,426.63168,-9.2335911
5221,5221,195.9464,8.1709003,6.345655,0.0,0,3.3219004,0.0,0.5494957,60.049274,3.3202744,426.27557,-9.2334461
5232,5232,195.9486,8.1914816,6.3670096,0.0,0,3.3023772,0.0,0.55287683,59.975185,3.2980416,425.93082,-9.2330227
5243,5243,195.9508,8.2201843,6.3884726,0.0,0,3.2828543,0.0,0.5543465,60.083668,3.277261,425.64059,-9.2322769
5254,5254,195.953,8.2270021,6.4039965,0.0,0,3.2633319,0.0,0.55721766,60.046337,3.2595239,425.35037,-9.2326698
5265,5265,195.9552,8.2588377,6.4234934,0.0,0,3.243809,0.0,0.55857086,60.097523,3.2435629,425.06015,-9.2316828
5276,5276,195.9574,8.2763424,6.4425435,0.0,0,3.2242863,0.0,0.56165868,60.100853,3.2231004,424.76993,-9.2329283
5287,5287,195.9596,8.2842512,6.4639692,0.0,0,3.2047634,0.0,0.56321681,60.069115,3.2049999,424.53271,-9.2326765
5298,5298,195.9618,8.3236866,6.4791117,0.0,0,3.1852405,0.0,0.56590551,60.164295,3.1882088,424.32825,-9.2335558
5309,5309,195.964,8.3798075,6.4989986,0.0,0,3.1657178,0.0,0.56739855,60.480938,3.1668155,424.12375,-9.2329483
5320,5320,195.9662,8.4511995,6.5182214,0.0,0,3.1461952,0.0,0.57059479,60.770954,3.1470184,423.91928,-9.2320366
5331,5331,195.9684,8.5023794,6.5431352,0.0,0,3.1271312,0.0,0.57246459,61.04166,3.1266515,423.70935,-9.2319527
5342,5342,195.9706,8.549181,6.5617461,0.0,0,3.1085584,0.0,0.57566655,61.198856,3.107326,423.41913,-9.2325277
5353,5353,195.9728,8.5695143,6.5836425,0.0,0,3.0899863,0.0,0.57735544,61.288795,3.0883138,423.12891,-9.2330904
5364,5364,195.975,8.5704079,6.6015892,0.0,0,3.0714138,0.0,0.58045959,61.027538,3.0693178,422.83868,-9.232954
5375,5375,195.9772,8.5854597,6.6229033,0.0,0,3.0528414,0.0,0.58200783,61.096397,3.047538,422.54846,-9.2322178
5386,5386,195.9794,8.6001225,6.6395035,0.0,0,3.0342693,0.0,0.5849818,61.030071,3.0331059,422.35562,-9.2328634
5397,5397,195.9816,8.6108179,6.6621842,0.0,0,3.0156965,0.0,0.58673054,60.936771,3.0112247,422.25665,-9.2335157
5408,5408,195.9838,8.6196556,6.6796474,0.0,0,2.9971242,0.0,0.58980542,60.791039,2.9929051,422.15771,-9.2325687
5419,5419,195.986,8.636797,6.6969318,0.0,0,2.9785516,0.0,0.59089857,60.893059,2.9749899,422.05878,-9.2322578
5430,5430,195.9882,8.6624489,6.71244,0.0,0,2.9599793,0.0,0.5936588,60.946739,2.9560378,421.95984,-9.2329779
5441,5441,195.9904,8.7057552,6.7330575,0.0,0,2.941407,0.0,0.59528363,61.085075,2.9397962,422.10016,-9.2332039
5452,5452,195.9926,8.7263365,6.7524438,0.0,0,2.9228346,0.0,0.59847397,61.057892,2.9243858,422.25186,-9.234334
5463,5463,195.9948,8.7651463,6.772275,0.0,0,2.9042623,0.0,0.59992576,61.310768,2.9047973,422.40356,-9.2322683
5474,5474,195.997,8.7975187,6.7861462,0.0,0,2.88569,0.0,0.60261232,61.326439,2.8856452,422.55527,-9.2329893
5485,5485,195.9992,8.8478928,6.8062654,0.0,0,2.8671174,0.0,0.60422677,61.550961,2.8678794,422.50119,-9.2318935
5496,5496,196.0014,8.9040613,6.8268194,0.0,0,2.8485448,0.0,0.60769385,61.732208,2.8449464,422.13843,-9.2325411
5507,5507,196.0036,8.9677906,6.847743,0.0,0,2.8299725,0.0,0.60922295,62.087292,2.8245893,421.77563,-9.2327948
5518,5518,196.0058,8.9911137,6.8646693,0.0,0,2.8114002,0.0,0.61224896,62.055523,2.8077989,421.41287,-9.2317371
5529,5529,196.008,9.010664,6.8859696,0.0,0,2.7928278,0.0,0.61390048,62.121288,2.7878778,421.05008,-9.2339106
5540,5540,196.0102,9.0265074,6.9043245,0.0,0,2.7742555,0.0,0.61722445,61.993896,2.7684894,419.59903,-9.2335825
5551,5551,196.0124,9.038332,6.9254241,0.0,0,2.7556829,0.0,0.61862665,61.97504,2.7457087,417.94904,-9.2332382
5562,5562,196.0146,8.9998703,6.9364581,0.0,0,2.7371109,0.0,0.62109613,61.602222,2.7318575,416.29904,-9.2329292
5573,5573,196.0168,8.9961081,6.9571147,0.0,0,2.7185383,0.0,0.62266278,61.415668,2.7179995,414.64908,-9.2327499
5584,5584,196.019,9.0229826,6.9745951,0.0,0,2.7006512,0.0,0.625884,61.428589,2.6990464,413.17569,-9.2328091
5595,5595,196.0212,9.1056318,6.996285,0.0,0,2.6829851,0.0,0.62756956,61.832813,2.6813402,412.13287,-9.2319899
5606,5606,196.0234,9.1825199,7.0102601,0.0,0,2.665319,0.0,0.63028497,62.252701,2.6635571,411.09006,-9.2316179
5617,5617,196.0256,9.2467976,7.0299611,0.0,0,2.6476531,0.0,0.63182425,62.575119,2.646749,410.04724,-9.2319174
5628,5628,196.0278,9.2902279,7.0489807,0.0,0,2.629987,0.0,0.63531268,62.611485,2.6267681,409.00443,-9.2321863
5639,5639,196.03,9.3174486,7.0702925,0.0,0,2.6123211,0.0,0.63670236,62.763924,2.6074171,409.02148,-9.2329884
5650,5650,196.0322,9.3153267,7.0829773,0.0,0,2.594655,0.0,0.6395027,62.608257,2.5883539,409.41803,-9.2329464
5661,5661,196.0344,9.3048382,7.1047873,0.0,0,2.5769889,0.0,0.64124328,62.403076,2.572526,409.81454,-9.2329454
5672,5672,196.0366,9.3286171,7.1239114,0.0,0,2.5593231,0.0,0.64472097,62.338772,2.5530412,410.21109,-9.2327738
5683,5683,196.0388,9.3492985,7.143105,0.0,0,2.541657,0.0,0.64593083,62.405991,2.535188,410.57639,-9.2326059
5694,5694,196.041,9.4028692,7.1516867,0.0,0,2.5239909,0.0,0.64818037,62.606197,2.5186172,410.80109,-9.2322321
5705,5705,196.0432,9.4412279,7.171844,0.0,0,2.506325,0.0,0.64976501,62.739883,2.5006678,411.02579,-9.2308588
5716,5716,196.0454,9.4725351,7.1925807,0.0,0,2.4886589,0.0,0.6535666,62.701767,2.4824438,411.25049,-9.2316751
5727,5727,196.0476,9.4884987,7.2115417,0.0,0,2.470993,0.0,0.65480739,62.736305,2.4637909,411.47519,-9.2302885
5738,5738,196.0498,9.5124416,7.2218986,0.0,0,2.4533269,0.0,0.65723228,62.758915,2.448446,411.55478,-9.2324152
5749,5749,196.052,9.5407686,7.2382903,0.0,0,2.4356608,0.0,0.65843809,62.935093,2.4349954,411.54816,-9.2334681
5760,5760,196.0542,9.5632162,7.258307,0.0,0,2.417995,0.0,0.66201186,62.766628,2.4173868,411.54156,-9.2340975
5771,5771,196.0564,9.6180134,7.2792482,0.0,0,2.4003291,0.0,0.66349155,63.086643,2.398098,411.53494,-9.2328653
5782,5782,196.0586,9.6673813,7.2931089,0.0,0,2.382663,0.0,0.66644156,63.177296,2.3822126,411.53842,-9.232933
5793,5793,196.0608,9.7384558,7.3129253,0.0,0,2.3649969,0.0,0.66796279,63.575794,2.3612611,411.67056,-9.2322226
5804,5804,196.063,9.7964697,7.3291755,0.0,0,2.347331,0.0,0.6712237,63.73386,2.3438792,411.8027,-9.2331505
5815,5815,196.0652,9.8501863,7.3514829,0.0,0,2.3296649,0.0,0.67287534,63.966171,2.3264973,411.93484,-9.2316914
5826,5826,196.0674,9.8801479,7.3664093,0.0,0,2.312031,0.0,0.67600024,63.981052,2.3090558,412.06699,-9.232275
5837,5837,196.0696,9.9138832,7.3864613,0.0,0,2.2952197,0.0,0.67751604,64.088013,2.2874403,412.08612,-9.2323742
5848,5848,196.0718,9.9073753,7.4063735,0.0,0,2.2784159,0.0,0.6812169,63.804779,2.2741425,412.00021,-9.2316246
5859,5859,196.074,9.9031343,7.4255509,0.0,0,2.2616124,0.0,0.68264771,63.688477,2.2532227,411.91431,-9.2333603
5870,5870,196.0762,9.9417515,7.4363899,0.0,0,2.2448089,0.0,0.68520653,63.784786,2.2392721,411.8284,-9.2318583
5881,5881,196.0784,9.9861412,7.4559569,0.0,0,2.2280054,0.0,0.68679762,63.949963,2.21843,411.74246,-9.2323122
5892,5892,196.0806,10.009857,7.4731817,0.0,0,2.2112017,0.0,0.69005245,63.89048,2.2063327,411.07706,-9.2331839
5903,5903,196.0828,10.00733,7.4897747,0.0,0,2.1943982,0.0,0.69108164,63.810978,2.1838653,410.38977,-9.2316046
5914,5914,196.085,10.020981,7.5042758,0.0,0,2.1775944,0.0,0.69416153,63.748222,2.1712804,409.70251,-9.2329178
5925,5925,196.0872,10.062674,7.5225234,0.0,0,2.1607909,0.0,0.69553244,63.936436,2.1570332,409.01523,-9.2329845
5936,5936,196.0894,10.105849,7.5382543,0.0,0,2.1439872,0.0,0.69886613,63.970974,2.1391993,408.42526,-9.2322369
5947,5947,196.0916,10.144256,7.5579133,0.0,0,2.1271837,0.0,0.70034772,64.128471,2.12132,407.97586,-9.2323809
5958,5958,196.0938,10.187902,7.5707097,0.0,0,2.1103802,0.0,0.70322073,64.181267,2.1035471,407.52646,-9.2316608
5969,5969,196.096,10.253986,7.5896363,0.0,0,2.0935764,0.0,0.70464432,64.472336,2.0895524,407.07706,-9.2315626
5980,5980,196.0982,10.317492,7.6090894,0.0,0,2.0767729,0.0,0.70834512,64.684814,2.0717349,406.62766,-9.2328329
5991,5991,196.1004,10.36113,7.6269608,0.0,0,2.0599694,0.0,0.7095986,64.864861,2.0516801,406.91245,-9.2316685
6002,6002,196.1026,10.384751,7.6385155,0.0,0,2.0431657,0.0,0.71228284,64.874374,2.0357592,407.3222,-9.2313662
6013,6013,196.1048,10.402359,7.6567154,0.0,0,2.0263622,0.0,0.71362734,64.869919,2.0184274,407.73193,-9.2325249
6024,6024,196.107,10.424089,7.6731353,0.0,0,2.0095587,0.0,0.71725577,64.748093,2.0045512,408.14169,-9.2319899
6035,6035,196.1092,10.465282,7.6938648,0.0,0,1.9927549,0.0,0.71867287,64.925941,1.9868797,408.55542,-9.2320604
6046,6046,196.1114,10.503165,7.706367,0.0,0,1.9759514,0.0,0.72157192,65.007523,1.9727837,408.97836,-9.233098
6057,6057,196.1136,10.543717,7.7234354,0.0,0,1.9591477,0.0,0.72282916,65.151382,1.9579228,409.40134,-9.2323008
6068,6068,196.1158,10.593821,7.7413154,0.0,0,1.9423442,0.0,0.72656941,65.192223,1.9397616,409.82428,-9.2317038
6079,6079,196.118,10.659285,7.7648649,0.0,0,1.9257871,0.0,0.72850889,65.454102,1.9218187,410.24725,-9.2315054
6090,6090,196.1202,10.695618,7.7760825,0.0,0,1.9098018,0.0,0.73121393,65.524025,1.9069004,410.32043,-9.2326202
6101,6101,196.1224,10.713183,7.7925482,0.0,0,1.8938167,0.0,0.73232663,65.628441,1.8877524,410.27417,-9.2314672
6112,6112,196.1246,10.738673,7.8110805,0.0,0,1.8778315,0.0,0.73611021,65.500618,1.8719602,410.22791,-9.2319813
6123,6123,196.1268,10.755396,7.830205,0.0,0,1.8618462,0.0,0.73745328,65.505379,1.8532898,410.18164,-9.2317934
6134,6134,196.129,10.78081,7.843225,0.0,0,1.8458611,0.0,0.74069262,65.403267,1.8371673,410.11646,-9.2321539
6145,6145,196.1312,10.805466,7.860023,0.0,0,1.8298758,0.0,0.74169379,65.53186,1.823431,409.97107,-9.2334089
6156,6156,196.1334,10.851919,7.8752642,0.0,0,1.8138907,0.0,0.74506032,65.587013,1.8063608,409.82568,-9.23281
6167,6167,196.1356,10.900129,7.8963904,0.0,0,1.7979054,0.0,0.74668574,65.764236,1.7914935,409.68027,-9.2324324
6178,6178,196.1378,10.96228,7.9074554,0.0,0,1.7819202,0.0,0.74960613,65.879532,1.7749826,409.53488,-9.2320309
6189,6189,196.14,10.982733,7.9254456,0.0,0,1.7659351,0.0,0.75086093,65.971741,1.760361,409.24649,-9.2316217
6200,6200,196.1422,10.991015,7.9413238,0.0,0,1.7499498,0.0,0.75438446,65.822609,1.7412986,408.8764,-9.2320147
6211,6211,196.1444,11.025049,7.9603152,0.0,0,1.7339647,0.0,0.75581819,65.952393,1.7241108,408.50629,-9.2316618
6222,6222,196.1466,11.06969,7.9720993,0.0,0,1.7179794,0.0,0.758757,66.003441,1.7114248,408.1362,-9.2313967
6233,6233,196.1488,11.106066,7.9886165,0.0,0,1.7019943,0.0,0.75993073,66.094856,1.6960434,407.75531,-9.2314196
6244,6244,196.151,11.173775,8.0043497,0.0,0,1.6860089,0.0,0.76342803,66.330833,1.6789433,407.25302,-9.2314863
6255,6255,196.1532,11.219871,8.0249643,0.0,0,1.6700239,0.0,0.76496178,66.443222,1.6637954,406.75076,-9.2315445
6266,6266,196.1554,11.272863,8.0350151,0.0,0,1.6540385,0.0,0.76777095,66.551987,1.6453588,406.2485,-9.2323265
6277,6277,196.1576,11.306828,8.0518351,0.0,0,1.6380534,0.0,0.7689665,66.71463,1.6297972,405.74622,-9.2321014
6288,6288,196.1598,11.311845,8.069788,0.0,0,1.6220682,0.0,0.7728368,66.555931,1.6126781,405.45651,-9.2330313
6299,6299,196.162,11.315136,8.0876083,0.0,0,1.6060829,0.0,0.77410483,66.432732,1.5985702,405.35739,-9.2323637
6310,6310,196.1642,11.348532,8.0981541,0.0,0,1.5900977,0.0,0.77680427,66.434433,1.5846306,405.25824,-9.2320852
6321,6321,196.1664,11.401616,8.1137638,0.0,0,1.5741127,0.0,0.77781773,66.642845,1.5702196,405.15912,-9.2321949
6332,6332,196.1686,11.467246,8.1279726,0.0,0,1.5585742,0.0,0.78127539,66.843834,1.5544016,405.06,-9.2312994
6343,6343,196.1708,11.576544,8.1497412,0.0,0,1.5433679,0.0,0.78299236,67.341286,1.5377935,405.17941,-9.232275
6354,6354,196.173,11.644654,8.162096,0.0,0,1.5281615,0.0,0.7861374,67.498062,1.519416,405.30499,-9.2313757
6365,6365,196.1752,11.692043,8.1815796,0.0,0,1.5129551,0.0,0.78771102,67.700371,1.5032835,405.43054,-9.2318048
6376,6376,196.1774,11.693743,8.1971731,0.0,0,1.4977487,0.0,0.79138488,67.542816,1.4894565,405.55612,-9.2321701
6387,6387,196.1796,11.700531,8.2163382,0.0,0,1.4825423,0.0,0.79291815,67.408867,1.470656,405.64023,-9.232029
6398,6398,196.1818,11.691245,8.2271881,0.0,0,1.4673359,0.0,0.79580444,67.186508,1.4546515,405.66666,-9.2324686
6409,6409,196.184,11.694522,8.2439079,0.0,0,1.4521295,0.0,0.79695439,67.087517,1.4427367,405.69312,-9.2319841
6420,6420,196.1862,11.691215,8.2556715,0.0,0,1.4369231,0.0,0.80012733,66.853088,1.4274496,405.71954,-9.2316322
6431,6431,196.1884,11.719096,8.2732763,0.0,0,1.4217167,0.0,0.8012144,66.968903,1.4174359,405.74597,-9.2321692
6442,6442,196.1906,11.754004,8.281332,0.0,0,1.4065104,0.0,0.80376881,66.936104,1.4020753,405.76669,-9.2314634
6453,6453,196.1928,11.83769,8.299345,0.0,0,1.3913039,0.0,0.80515331,67.302475,1.3867736,405.78653,-9.2316322
6464,6464,196.195,11.888265,8.3123198,0.0,0,1.3760974,0.0,0.80870384,67.437981,1.3755878,405.80637,-9.2310476
6475,6475,196.1972,11.940283,8.3320761,0.0,0,1.3608911,0.0,0.81002575,67.63813,1.3615129,405.8262,-9.2308731
6486,6486,196.1994,12.017042,8.3411999,0.0,0,1.3456846,0.0,0.81273615,67.895554,1.3421898,405.88077,-9.2316399
6497,6497,196.2016,12.080914,8.3583527,0.0,0,1.3304783,0.0,0.81395221,68.150642,1.3287681,406.01294,-9.2320671
6508,6508,196.2038,12.144718,8.3741884,0.0,0,1.315272,0.0,0.8177073,68.270134,1.3124064,406.14511,-9.2310619
6519,6519,196.206,12.226298,8.3933764,0.0,0,1.3000655,0.0,0.81922215,68.590477,1.2939284,406.27728,-9.2306433
6530,6530,196.2082,12.286277,8.4053659,0.0,0,1.2848592,0.0,0.8225767,68.723557,1.2793667,406.40945,-9.2313595
6541,6541,196.2104,12.332582,8.4228745,0.0,0,1.2696528,0.0,0.82393354,68.88356,1.2603356,406.33218,-9.2315035
6552,6552,196.2126,12.38675,8.4400282,0.0,0,1.2544463,0.0,0.82778263,68.949234,1.2481264,406.1868,-9.2327833
6563,6563,196.2148,12.413057,8.456831,0.0,0,1.2392399,0.0,0.828879,69.007599,1.2309799,406.04141,-9.2320108
6574,6574,196.217,12.445534,8.4662762,0.0,0,1.2240335,0.0,0.83175403,68.974648,1.2144152,405.896,-9.231678
6585,6585,196.2192,12.451762,8.4868526,0.0,0,1.2094566,0.0,0.83348876,68.900688,1.1985776,405.71097,-9.2328072
6596,6596,196.2214,12.463766,8.5032797,0.0,0,1.1949937,0.0,0.83743012,68.685287,1.1822482,405.36731,-9.233016
6607,6607,196.2236,12.503139,8.5211334,0.0,0,1.180531,0.0,0.83867681,68.823891,1.1676954,405.02365,-9.2332869
6618,6618,196.2258,12.565486,8.5257959,0.0,0,1.1660681,0.0,0.84089172,68.988464,1.154179,404.67999,-9.2321548
6629,6629,196.228,12.571317,8.5412865,0.0,0,1.1516054,0.0,0.84192681,68.919159,1.1412262,404.33633,-9.2320957
6640,6640,196.2302,12.580476,8.5595427,0.0,0,1.1371425,0.0,0.84626669,68.708504,1.1253619,404.09598,-9.2320623
6651,6651,196.2324,12.590232,8.5776482,0.0,0,1.1226798,0.0,0.8474974,68.659721,1.1131301,403.91235,-9.2318382
6662,6662,196.2346,12.619034,8.585434,0.0,0,1.1082169,0.0,0.85008472,68.694801,1.1001784,403.72876,-9.2314577
6673,6673,196.2368,12.693814,8.5990868,0.0,0,1.0937542,0.0,0.85088307,69.019203,1.0855548,403.54514,-9.2314959
6684,6684,196.239,12.756665,8.6141615,0.0,0,1.0792915,0.0,0.85468453,69.102036,1.0700181,403.36154,-9.2313299
6695,6695,196.2412,12.816402,8.6314917,0.0,0,1.0648285,0.0,0.85590309,69.349449,1.0535071,403.05673,-9.2327776
6706,6706,196.2434,12.873294,8.6425123,0.0,0,1.0503657,0.0,0.85887951,69.42897,1.0394779,402.70645,-9.2314358
6717,6717,196.2456,12.929585,8.65839,0.0,0,1.035903,0.0,0.86012262,69.657173,1.0268523,402.3562,-9.2327623
6728,6728,196.2478,12.987705,8.6725864,0.0,0,1.0214401,0.0,0.86394924,69.684494,1.011458,402.00592,-9.2320681
6739,6739,196.25,13.024421,8.6891813,0.0,0,1.0069773,0.0,0.86500698,69.847137,1.0000066,401.61343,-9.2304802
6750,6750,196.2522,13.035825,8.6968508,0.0,0,0.99251461,0.0,0.86761642,69.712059,0.98179251,401.01862,-9.231164
6761,6761,196.2544,13.042502,8.7130766,0.0,0,0.97805184,0.0,0.86874813,69.628601,0.97126478,400.42383,-9.2320967
6772,6772,196.2566,13.052162,8.7264462,0.0,0,0.96358895,0.0,0.87243187,69.47905,0.95494205,399.82904,-9.2320175
6783,6783,196.2588,13.086988,8.7429705,0.0,0,0.94912618,0.0,0.87340212,69.590073,0.94233733,399.23425,-9.2316809
6794,6794,196.261,13.184656,8.7517948,0.0,0,0.9346633,0.0,0.87647915,69.8564,0.93086785,398.8519,-9.2307692
6805,6805,196.2632,13.285697,8.7677031,0.0,0,0.92020065,0.0,0.87746078,70.3162,0.91663957,398.60077,-9.2307415
6816,6816,196.2654,13.363802,8.781826,0.0,0,0.90573776,0.0,0.88139814,70.462669,0.9001025,398.34964,-9.2304544
6827,6827,196.2676,13.44067,8.800786,0.0,0,0.89135975,0.0,0.88272017,70.797043,0.88411045,398.09851,-9.2320795
6838,6838,196.2698,13.492261,8.8098812,0.0,0,0.87760508,0.0,0.88581926,70.830971,0.87389207,397.86502,-9.2321939
6849,6849,196.272,13.528246,8.8271303,0.0,0,0.86385065,0.0,0.88710368,70.945778,0.8573373,397.89145,-9.2310944
6860,6860,196.2742,13.554758,8.8407364,0.0,0,0.85009629,0.0,0.89089817,70.815201,0.84386498,397.91788,-9.2317743
6871,6871,196.2764,13.577367,8.8598852,0.0,0,0.83634186,0.0,0.89228642,70.855591,0.83153832,397.94434,-9.2315435
6882,6882,196.2786,13.629206,8.8674459,0.0,0,0.82258749,0.0,0.89515942,70.92778,0.81689095,397.97076,-9.2316895
6893,6893,196.2808,13.696922,8.882472,0.0,0,0.80883306,0.0,0.89621079,71.171631,0.80370378,397.74451,-9.2328081
6904,6904,196.283,13.786485,8.8990097,0.0,0,0.79507869,0.0,0.90042943,71.279182,0.78653145,397.27457,-9.2306099
6915,6915,196.2852,13.84315,8.9188471,0.0,0,0.78132427,0.0,0.90192133,71.527336,0.77102488,396.80463,-9.2298145
6926,6926,196.2874,13.881835,8.9270411,0.0,0,0.76756984,0.0,0.90492904,71.525703,0.75534749,396.33469,-9.231081
6937,6937,196.2896,13.867092,8.9412384,0.0,0,0.75381547,0.0,0.90570652,71.383141,0.74652064,395.86475,-9.2308302
6948,6948,196.2918,13.876964,8.9527903,0.0,0,0.7400611,0.0,0.90924925,71.166504,0.73101801,395.98218,-9.231555
6959,6959,196.294,13.893004,8.9707584,0.0,0,0.72630668,0.0,0.9106192,71.174355,0.71878731,396.12756,-9.2325277
6970,6970,196.2962,13.950401,8.9802666,0.0,0,0.71255225,0.0,0.91375828,71.225197,0.70707643,396.27295,-9.2321196
6981,6981,196.2984,14.008104,8.9949322,0.0,0,0.69879782,0.0,0.91468161,71.475327,0.69091129,396.41833,-9.2321815
6992,6992,196.3006,14.078348,9.0060358,0.0,0,0.68504345,0.0,0.91814047,71.529282,0.67531544,396.75171,-9.2320204
7003,7003,196.3028,14.136394,9.0232878,0.0,0,0.67128909,0.0,0.91932791,71.753746,0.66327828,397.36703,-9.2314262
7014,7014,196.305,14.192594,9.0339842,0.0,0,0.65753466,0.0,0.92280161,71.79937,0.65069795,397.98236,-9.2305698
7025,7025,196.3072,14.219282,9.0511427,0.0,0,0.64378029,0.0,0.92400783,71.872383,0.63778174,398.59772,-9.2314148
7036,7036,196.3094,14.281157,9.0596972,0.0,0,0.63002586,0.0,0.92723441,71.949646,0.62143958,399.21304,-9.2306309
7047,7047,196.3116,14.327655,9.0763512,0.0,0,0.6162715,0.0,0.92831093,72.095406,0.61007375,399.49811,-9.2307386
7058,7058,196.3138,14.385796,9.0865088,0.0,0,0.60251707,0.0,0.93154699,72.168228,0.59863722,399.72281,-9.232029
7069,7069,196.316,14.471394,9.1018333,0.0,0,0.5887627,0.0,0.93240279,72.518066,0.58267218,399.94751,-9.2311554
7080,7080,196.3182,14.567657,9.1148033,0.0,0,0.57526875,0.0,0.93636471,72.723724,0.56663191,400.17221,-9.2311001
7091,7091,196.3204,14.624477,9.134285,0.0,0,0.56217867,0.0,0.93789464,72.896744,0.5532648,400.41806,-9.2309008
7102,7102,196.3226,14.666944,9.143115,0.0,0,0.54908878,0.0,0.94133729,72.861633,0.53966981,400.71545,-9.229826
7113,7113,196.3248,14.69386,9.1576948,0.0,0,0.53599876,0.0,0.94204932,72.946861,0.52587193,401.01285,-9.2316637
7124,7124,196.327,14.716413,9.1695032,0.0,0,0.52290875,0.0,0.94577712,72.791763,0.50852424,401.31024,-9.2315588
7131,7131,196.3284,14.753436,9.182312,0.0,0,0.5145787,0.0,0.94676185,72.889854,0.50339317,401.49948,-9.2303038