File: clean data/testID_0094.csv
level_0,index,Time(sec),Force(kN),Jaw(mm),PowAngle(deg),Power(W),Pram,PTemp,Strain,Stress(MPa),Stroke(mm),TC1(C),wedge(mm)
1872,1872,155.3437,0.94712895,0.0093648946,0.0,0,9.0629654,0.0,0.00077177578,11.787617,10.102712,331.28949,-9.3057756
1874,1874,155.3441,3.0757143,0.028844472,0.0,0,9.0044374,0.0,0.0016241164,34.466129,10.033305,331.34555,-9.3055983
1876,1876,155.3445,6.1654,0.085761085,0.0,0,8.9459095,0.0,0.0051776012,75.512085,9.989419,331.40164,-9.3048182
1878,1878,155.3449,7.0036049,0.12060957,0.0,0,8.8873816,0.0,0.0078996224,87.826912,9.9303951,331.4577,-9.3031578
1880,1880,155.3453,7.4677625,0.23398259,0.0,0,8.8288536,0.0,0.014712085,93.550941,9.8570738,331.51379,-9.3008766
1882,1882,155.3457,7.6337738,0.32837352,0.0,0,8.7703257,0.0,0.021640005,94.435097,9.774929,331.56985,-9.3021221
1884,1884,155.3461,8.3392572,0.38432762,0.0,0,8.7136831,0.0,0.025528526,102.93192,9.6848469,331.62595,-9.3013477
1886,1886,155.3465,8.7523346,0.48047525,0.0,0,8.6580124,0.0,0.031926643,106.99996,9.6087799,331.68201,-9.3001776
1888,1888,155.3469,9.0265837,0.50059968,0.0,0,8.6023483,0.0,0.033926945,111.46626,9.5354481,331.7381,-9.2982435
1890,1890,155.3473,8.5591116,0.57413363,0.0,0,8.5466843,0.0,0.038335059,105.03259,9.4704752,331.79416,-9.3008232
1892,1892,155.3477,9.1903038,0.65468436,0.0,0,8.4910212,0.0,0.044117562,111.09012,9.4079523,332.17151,-9.3012037
1894,1894,155.3481,9.4486389,0.69430017,0.0,0,8.4353561,0.0,0.047133572,114.6226,9.3392048,332.8699,-9.2994909
1896,1896,155.3485,9.5447512,0.80440778,0.0,0,8.3796921,0.0,0.054276574,115.05911,9.2638817,333.5683,-9.299077
1898,1898,155.3489,9.3499327,0.87701762,0.0,0,8.324029,0.0,0.059732724,112.34849,9.1866245,334.26669,-9.2992601
1900,1900,155.3493,9.551815,0.94513202,0.0,0,8.2683649,0.0,0.064812198,113.54811,9.1097221,334.96509,-9.3003635
1902,1902,155.3497,9.7691154,1.0128227,0.0,0,8.2127008,0.0,0.069373637,115.95866,9.033411,335.66348,-9.3006639
1904,1904,155.3501,9.8781404,1.0525091,0.0,0,8.1570368,0.0,0.072356313,116.81585,8.970808,336.36188,-9.3014431
1906,1906,155.3505,9.8825293,1.1214558,0.0,0,8.1013727,0.0,0.077433445,116.64176,8.9086657,337.06027,-9.3006725
1908,1908,155.3509,9.9371014,1.1869923,0.0,0,8.0462637,0.0,0.081720516,116.34835,8.8447828,337.75867,-9.3001909
1910,1910,155.3513,10.28171,1.2480174,0.0,0,7.9931717,0.0,0.086389661,119.76561,8.7805424,338.45706,-9.2995815
1912,1912,155.3517,10.203792,1.3251245,0.0,0,7.9402113,0.0,0.092031561,118.7345,8.7128801,339.15546,-9.2984486
1914,1914,155.3521,10.176443,1.3968921,0.0,0,7.8872514,0.0,0.096873835,117.53452,8.6416273,339.85385,-9.2980042
1916,1916,155.3525,10.310497,1.4577773,0.0,0,7.8342915,0.0,0.10191819,118.4424,8.5720615,340.55225,-9.2993546
1918,1918,155.3529,10.451543,1.5095786,0.0,0,7.7813311,0.0,0.10575774,119.47778,8.5061445,341.25064,-9.2993097
1920,1920,155.3533,10.5368,1.5658344,0.0,0,7.7283711,0.0,0.10950048,120.26304,8.4441576,341.94904,-9.2994566
1922,1922,155.3537,10.447017,1.631269,0.0,0,7.6754107,0.0,0.11496127,118.59288,8.3840847,342.64743,-9.3001423
1924,1924,155.3541,10.647851,1.686541,0.0,0,7.6224508,0.0,0.11884446,120.08353,8.3283672,343.34583,-9.2988749
1926,1926,155.3545,10.790377,1.7466,0.0,0,7.5694909,0.0,0.12320922,121.46512,8.269702,344.04422,-9.2991848
1928,1928,155.3549,10.785692,1.8118374,0.0,0,7.516531,0.0,0.12848617,120.74304,8.2048712,344.74261,-9.2991247
1930,1930,155.3553,10.817981,1.8692182,0.0,0,7.4635711,0.0,0.13247679,120.63078,8.1435223,345.44101,-9.2978134
1932,1932,155.3557,10.810738,1.9319489,0.0,0,7.4106107,0.0,0.13755003,119.93005,8.0830097,346.1394,-9.2999792
1934,1934,155.3561,11.008074,1.9806613,0.0,0,7.3593569,0.0,0.14144352,121.4705,8.0224028,346.8378,-9.3001814
1936,1936,155.3565,11.058695,2.0328865,0.0,0,7.3089838,0.0,0.14498267,121.81029,7.9661064,347.53622,-9.2989063
1938,1938,155.3569,11.066298,2.0977561,0.0,0,7.258616,0.0,0.15053691,121.14108,7.9107809,348.23462,-9.2987967
1940,1940,155.3573,11.100556,2.1468773,0.0,0,7.2082477,0.0,0.15409584,121.24043,7.8538055,348.93301,-9.2978735
1942,1942,155.3577,11.213812,2.2010009,0.0,0,7.1578794,0.0,0.157984,121.76125,7.7977371,349.70193,-9.2983742
1944,1944,155.3581,11.311622,2.2571547,0.0,0,7.107511,0.0,0.16304088,122.27732,7.7429996,350.54138,-9.2992325
1946,1946,155.3585,11.299909,2.3135557,0.0,0,7.0571437,0.0,0.16689816,121.73382,7.6819377,351.38083,-9.299798
1948,1948,155.3589,11.322134,2.3690412,0.0,0,7.0067749,0.0,0.17145859,121.47343,7.6298594,352.22028,-9.2992125
1950,1950,155.3593,11.41873,2.4121492,0.0,0,6.9564075,0.0,0.17530856,121.97018,7.5777512,353.05972,-9.2995415
1952,1952,155.3597,11.475679,2.4698064,0.0,0,6.9060392,0.0,0.17902111,122.12488,7.5240998,353.89917,-9.2992048
1954,1954,155.3601,11.501651,2.5179806,0.0,0,6.8556719,0.0,0.18349542,121.89538,7.4701543,354.73859,-9.2994547
1956,1956,155.3605,11.570942,2.5618598,0.0,0,6.8053036,0.0,0.1870206,122.01721,7.4183569,355.57803,-9.2998285
1958,1958,155.3609,11.644167,2.6208122,0.0,0,6.7554379,0.0,0.19112724,122.35789,7.3671865,356.41748,-9.3000793
1960,1960,155.3613,11.67006,2.6654241,0.0,0,6.7073984,0.0,0.19555409,122.134,7.3124347,357.25693,-9.2990847
1962,1962,155.3617,11.697991,2.7160974,0.0,0,6.6594777,0.0,0.19929323,121.95313,7.2630544,358.09637,-9.2993355
1964,1964,155.3621,11.74393,2.7752767,0.0,0,6.6115575,0.0,0.2038857,121.90381,7.2143025,358.93582,-9.3000689
1966,1966,155.3625,11.849584,2.8112459,0.0,0,6.5636377,0.0,0.20754267,122.489,7.167109,359.77527,-9.3001585
1968,1968,155.3629,11.900024,2.8631613,0.0,0,6.515718,0.0,0.21119414,122.6289,7.1161013,360.61472,-9.2986259
1970,1970,155.3633,11.910271,2.9189365,0.0,0,6.4677982,0.0,0.21601968,122.1508,7.0666208,361.45416,-9.2992439
1972,1972,155.3637,11.975036,2.9559779,0.0,0,6.419878,0.0,0.21942244,122.46602,7.0155363,362.29358,-9.2997532
1974,1974,155.3641,12.048491,3.0110497,0.0,0,6.3719578,0.0,0.22330782,122.64207,6.9659328,363.13303,-9.3005171
1976,1976,155.3645,12.13019,3.0617223,0.0,0,6.324038,0.0,0.22809513,122.84792,6.9172511,363.97247,-9.3005381
1978,1978,155.3649,12.135477,3.1069984,0.0,0,6.2761183,0.0,0.23179179,122.57963,6.8659353,364.81192,-9.299222
1980,1980,155.3653,12.16325,3.1579106,0.0,0,6.2281981,0.0,0.23569526,122.28962,6.8184676,365.65137,-9.2988005
1982,1982,155.3657,12.234866,3.201273,0.0,0,6.1802783,0.0,0.24007463,122.44521,6.7695761,366.49081,-9.2990513
1984,1984,155.3661,12.309923,3.2508624,0.0,0,6.1339011,0.0,0.24378344,122.77852,6.7224879,367.33026,-9.2993984
1986,1986,155.3665,12.347701,3.3002081,0.0,0,6.0883203,0.0,0.24793249,122.61974,6.6720467,368.16971,-9.2993469
1988,1988,155.3669,12.403237,3.3415687,0.0,0,6.0427446,0.0,0.25204569,122.72222,6.6248245,369.00912,-9.3000402
1990,1990,155.3673,12.427409,3.3940911,0.0,0,5.9971681,0.0,0.25575921,122.48683,6.5773048,369.84857,-9.2999868
1992,1992,155.3677,12.488102,3.4367845,0.0,0,5.951592,0.0,0.25994587,122.52221,6.5320339,370.44418,-9.2981939
1994,1994,155.3681,12.546865,3.479131,0.0,0,5.9060163,0.0,0.26384473,122.59093,6.4805875,370.79608,-9.2975893
1996,1996,155.3685,12.609242,3.5349777,0.0,0,5.8604403,0.0,0.26781353,122.71252,6.4329524,371.14798,-9.2981043
1998,1998,155.3689,12.652078,3.5746973,0.0,0,5.8148637,0.0,0.2720561,122.66155,6.3897667,371.49988,-9.299263
2000,2000,155.3693,12.679159,3.6219516,0.0,0,5.7692881,0.0,0.27598312,122.41201,6.3438482,371.85178,-9.3011522
2002,2002,155.3697,12.717562,3.6772079,0.0,0,5.723712,0.0,0.28036734,122.32182,6.2951698,372.20367,-9.300066
2004,2004,155.3701,12.804695,3.7126484,0.0,0,5.6781363,0.0,0.28433394,122.61314,6.2462683,372.55557,-9.2991724
2006,2006,155.3705,12.871644,3.7588935,0.0,0,5.6325603,0.0,0.28788269,122.84674,6.1986952,372.90747,-9.2991648
2008,2008,155.3709,12.89193,3.8106592,0.0,0,5.5874381,0.0,0.29244071,122.53687,6.1549306,373.25937,-9.2987709
2010,2010,155.3713,12.910198,3.8490357,0.0,0,5.5439701,0.0,0.29652938,122.17735,6.1063323,373.61127,-9.2995367
2012,2012,155.3717,12.990252,3.8994672,0.0,0,5.5006099,0.0,0.30035412,122.37857,6.0660052,373.96317,-9.3000212
2014,2014,155.3721,13.077886,3.9478314,0.0,0,5.4572496,0.0,0.30496302,122.72454,6.0176406,374.31509,-9.3001137
2016,2016,155.3725,13.103765,3.988236,0.0,0,5.4138899,0.0,0.30891535,122.51756,5.9687824,374.66699,-9.2995138
2018,2018,155.3729,13.126912,4.0368218,0.0,0,5.3705297,0.0,0.31278872,122.22447,5.9262638,375.01889,-9.2998219
2020,2020,155.3733,13.17388,4.0805755,0.0,0,5.3271699,0.0,0.31743461,121.97764,5.8816814,375.37079,-9.2995834
2022,2022,155.3737,13.247809,4.12396,0.0,0,5.2838097,0.0,0.32120901,122.24025,5.832943,375.72269,-9.2998295
2024,2024,155.3741,13.325824,4.1727366,0.0,0,5.2404499,0.0,0.32530642,122.49682,5.7869186,376.07458,-9.300498
2026,2026,155.3745,13.346101,4.2159724,0.0,0,5.1970901,0.0,0.3300541,122.14162,5.7421069,376.42648,-9.2996283
2028,2028,155.3749,13.402489,4.2623935,0.0,0,5.1537299,0.0,0.33362579,122.10148,5.6976228,376.77838,-9.2994967
2030,2030,155.3753,13.447615,4.3070302,0.0,0,5.1103697,0.0,0.33782783,122.07655,5.6512446,377.13028,-9.2998695
2032,2032,155.3757,13.518292,4.3488598,0.0,0,5.0670099,0.0,0.34245786,122.10058,5.6028113,377.48218,-9.3001194
2034,2034,155.3761,13.593261,4.401495,0.0,0,5.0250454,0.0,0.346439,122.33256,5.5565109,377.83408,-9.2995367
2036,2036,155.3765,13.621923,4.4446931,0.0,0,4.9838009,0.0,0.35098946,122.04165,5.5105543,378.18597,-9.2986383
2038,2038,155.3769,13.672871,4.4851193,0.0,0,4.9425607,0.0,0.35516268,121.97673,5.4634557,378.53787,-9.2990217
2040,2040,155.3773,13.717817,4.539155,0.0,0,4.9013209,0.0,0.35936543,121.87565,5.4200315,378.88977,-9.2999334
2042,2042,155.3777,13.784568,4.5776792,0.0,0,4.8600807,0.0,0.36398339,121.88739,5.3727288,379.07898,-9.2994566
2044,2044,155.3781,13.864954,4.6210003,0.0,0,4.818841,0.0,0.36787662,122.09161,5.3295054,379.10559,-9.2995157
2046,2046,155.3785,13.903691,4.6741443,0.0,0,4.7776008,0.0,0.37239999,121.8631,5.2826967,379.1322,-9.2999897
2048,2048,155.3789,13.948894,4.7100978,0.0,0,4.7363605,0.0,0.37695959,121.80002,5.2390614,379.15878,-9.2984066
2050,2050,155.3793,13.989998,4.7554603,0.0,0,4.6951208,0.0,0.38063994,121.70599,5.1915803,379.18539,-9.2984018
2052,2052,155.3797,14.06345,4.8068414,0.0,0,4.6538811,0.0,0.38556969,121.68688,5.1491146,379.21201,-9.2988253
2054,2054,155.3801,14.140513,4.8441343,0.0,0,4.6126404,0.0,0.38995501,121.80827,5.1026654,379.23862,-9.3002691
2056,2056,155.3805,14.187309,4.8925343,0.0,0,4.5714006,0.0,0.3939625,121.76546,5.0602002,379.2652,-9.2994223
2058,2058,155.3809,14.212609,4.9410448,0.0,0,4.5305729,0.0,0.39928386,121.33498,5.0174088,379.29181,-9.2996988
2060,2060,155.3813,14.260633,4.9790339,0.0,0,4.4912429,0.0,0.40315342,121.27534,4.9726725,379.31842,-9.2981329
2062,2062,155.3817,14.339337,5.0242648,0.0,0,4.4520106,0.0,0.40703189,121.43495,4.9291344,379.34503,-9.2977409
2064,2064,155.3821,14.396922,5.0666451,0.0,0,4.4127784,0.0,0.41206059,121.37573,4.8819437,379.37161,-9.2990255
2066,2066,155.3825,14.446291,5.1058393,0.0,0,4.3735466,0.0,0.41573039,121.34897,4.839684,379.39822,-9.2990999
2068,2068,155.3829,14.486823,5.153904,0.0,0,4.3343148,0.0,0.4202033,121.12223,4.7977691,379.42484,-9.2993412
2070,2070,155.3833,14.5514,5.1958828,0.0,0,4.295083,0.0,0.42538768,120.95327,4.7552161,379.45145,-9.3013353
2072,2072,155.3837,14.617472,5.2413287,0.0,0,4.2558503,0.0,0.42914349,121.18105,4.71066,379.47803,-9.3001728
2074,2074,155.3841,14.705403,5.2841759,0.0,0,4.2166185,0.0,0.43376055,121.30332,4.6696463,379.50464,-9.2987461
2076,2076,155.3845,14.751893,5.3207264,0.0,0,4.1773863,0.0,0.43824974,121.12846,4.6256542,379.53125,-9.2984858
2078,2078,155.3849,14.791246,5.370244,0.0,0,4.1381545,0.0,0.44216961,120.97221,4.5811019,379.55786,-9.2982779
2080,2080,155.3853,14.854395,5.4102859,0.0,0,4.0989227,0.0,0.44705126,120.8959,4.5401835,379.58444,-9.2992086
2082,2082,155.3857,14.921655,5.4505835,0.0,0,4.0596905,0.0,0.45134372,120.89384,4.4960561,379.61105,-9.2998104
2084,2084,155.3861,15.001248,5.5026031,0.0,0,4.0217228,0.0,0.45582354,120.99816,4.451107,379.63766,-9.299778
2086,2086,155.3865,15.048836,5.5359011,0.0,0,3.9844062,0.0,0.46047136,120.92815,4.410686,379.66428,-9.300005
2088,2088,155.3869,15.084418,5.5748148,0.0,0,3.9470942,0.0,0.46418789,120.70972,4.3677001,379.69086,-9.298564
2090,2090,155.3873,15.145808,5.6239772,0.0,0,3.9097824,0.0,0.46899542,120.52372,4.3223329,379.71747,-9.2989588
2092,2092,155.3877,15.231458,5.6552935,0.0,0,3.8724704,0.0,0.47332641,120.73323,4.2836704,379.62677,-9.2989445
2094,2094,155.3881,15.308011,5.6994805,0.0,0,3.8351583,0.0,0.47717065,120.89311,4.2419257,379.41882,-9.2990417
2096,2096,155.3885,15.361477,5.7477474,0.0,0,3.7978463,0.0,0.48245385,120.6291,4.2025199,379.21088,-9.298996
2098,2098,155.3889,15.400874,5.7804732,0.0,0,3.7605343,0.0,0.48676324,120.4511,4.1589494,379.00293,-9.2985487
2100,2100,155.3893,15.455558,5.8232403,0.0,0,3.7232223,0.0,0.49048781,120.39063,4.1196761,378.79498,-9.2986012
2102,2102,155.3897,15.559518,5.863934,0.0,0,3.6859105,0.0,0.49557635,120.57584,4.0785561,378.58704,-9.2986364
2104,2104,155.3901,15.62894,5.8965664,0.0,0,3.6485984,0.0,0.49922979,120.73622,4.0379639,378.37909,-9.2969198
2106,2106,155.3905,15.672362,5.9393215,0.0,0,3.6112862,0.0,0.5032112,120.63636,3.999315,378.17114,-9.2977076
2108,2108,155.3909,15.710651,5.9790969,0.0,0,3.5743468,0.0,0.50861967,120.27134,3.9621668,377.9632,-9.2992697
2110,2110,155.3913,15.795365,6.0190511,0.0,0,3.5387621,0.0,0.51241285,120.38384,3.9212897,377.75525,-9.2998877
2112,2112,155.3917,15.88907,6.0602794,0.0,0,3.5032659,0.0,0.51683104,120.59782,3.8863807,377.5473,-9.2993765
2114,2114,155.3921,15.957661,6.0947642,0.0,0,3.4677699,0.0,0.52165157,120.53881,3.8489671,377.33936,-9.2977552
2116,2116,155.3925,15.983258,6.1350355,0.0,0,3.4322741,0.0,0.52502823,120.32478,3.8079031,377.13141,-9.2977409
2118,2118,155.3929,16.032301,6.1725802,0.0,0,3.3967779,0.0,0.52964413,120.11568,3.7697613,376.92346,-9.297801
2120,2120,155.3933,16.10351,6.2054768,0.0,0,3.3612819,0.0,0.53406179,120.13837,3.7311423,376.71552,-9.2998753
2122,2122,155.3937,16.194054,6.2508521,0.0,0,3.3257859,0.0,0.5380742,120.3247,3.6914916,376.50757,-9.2999153
2124,2124,155.3941,16.26696,6.285255,0.0,0,3.2902899,0.0,0.54276139,120.30565,3.6540184,376.29962,-9.2980118
2126,2126,155.3945,16.301645,6.3186545,0.0,0,3.2547936,0.0,0.54670548,120.08234,3.618289,376.09167,-9.2989016
2128,2128,155.3949,16.364559,6.366014,0.0,0,3.2192979,0.0,0.55113637,120.02257,3.580153,375.88373,-9.2981873
2130,2130,155.3953,16.46302,6.3945255,0.0,0,3.1838019,0.0,0.55570346,120.14481,3.5426941,375.67578,-9.2987041
2132,2132,155.3957,16.546928,6.4281564,0.0,0,3.1483059,0.0,0.55903763,120.42078,3.5065196,375.46783,-9.2991133
2134,2134,155.3961,16.609938,6.4718385,0.0,0,3.1139472,0.0,0.56373084,120.28487,3.4691648,375.25989,-9.2990694
2136,2136,155.3965,16.656395,6.5006995,0.0,0,3.0801756,0.0,0.56815696,120.11261,3.4348369,375.05194,-9.298027
2138,2138,155.3969,16.713587,6.5391464,0.0,0,3.0464077,0.0,0.57167745,120.05112,3.396069,374.84399,-9.2988739
2140,2140,155.3973,16.788353,6.5809927,0.0,0,3.0126395,0.0,0.57705557,119.96608,3.3628516,374.63605,-9.2985601
2142,2142,155.3977,16.882351,6.6068282,0.0,0,2.9788716,0.0,0.58079845,120.20892,3.3292663,374.50912,-9.2992296
2144,2144,155.3981,16.940365,6.6455045,0.0,0,2.9451036,0.0,0.58422071,120.23336,3.2954669,374.46317,-9.2986517
2146,2146,155.3985,16.99814,6.67979,0.0,0,2.9113355,0.0,0.58933556,120.00622,3.2595987,374.41721,-9.2977657
2148,2148,155.3989,17.071365,6.7099428,0.0,0,2.8775675,0.0,0.59281158,120.12042,3.2252636,374.37128,-9.2976894
2150,2150,155.3993,17.151993,6.7490573,0.0,0,2.8437996,0.0,0.59675312,120.17979,3.1898627,374.32532,-9.2977648
2152,2152,155.3997,17.246935,6.7832203,0.0,0,2.8100314,0.0,0.60214484,120.21853,3.1532152,374.27936,-9.2978802
2154,2154,155.4001,17.325108,6.8164859,0.0,0,2.7762637,0.0,0.60537153,120.35876,3.1161005,374.2334,-9.2977896
2156,2156,155.4005,17.374802,6.8515759,0.0,0,2.7424955,0.0,0.60945779,120.26301,3.0844395,374.18747,-9.2983923
2158,2158,155.4009,17.451841,6.8809342,0.0,0,2.7090657,0.0,0.61410517,120.19308,3.0459442,374.14151,-9.2980347
2160,2160,155.4013,17.542461,6.9196248,0.0,0,2.6768651,0.0,0.61773729,120.3532,3.0178244,374.09555,-9.2992277
2162,2162,155.4017,17.638565,6.9527993,0.0,0,2.6447449,0.0,0.62225813,120.48537,2.9833624,374.04959,-9.2983189
2164,2164,155.4021,17.729012,6.9836936,0.0,0,2.6126249,0.0,0.62665856,120.57195,2.9464817,374.00366,-9.2971821
2166,2166,155.4025,17.782398,7.0252237,0.0,0,2.5805047,0.0,0.63051945,120.49531,2.9118071,373.9577,-9.296957
2168,2168,155.4029,17.853012,7.0514116,0.0,0,2.5483847,0.0,0.63498396,120.3773,2.8779294,373.91174,-9.2975082
2170,2170,155.4033,17.952454,7.082787,0.0,0,2.5162647,0.0,0.63872272,120.57198,2.847944,373.86578,-9.2978401
2172,2172,155.4037,18.049015,7.1257291,0.0,0,2.4841447,0.0,0.64321345,120.68996,2.8126616,373.81985,-9.2980099
2174,2174,155.4041,18.131248,7.1505675,0.0,0,2.4520247,0.0,0.64787167,120.71374,2.7815914,373.7739,-9.2984543
2176,2176,155.4045,18.196939,7.185082,0.0,0,2.4199049,0.0,0.65130609,120.71828,2.7475815,373.72794,-9.2970495
2178,2178,155.4049,18.261389,7.2241259,0.0,0,2.3877847,0.0,0.6560691,120.60515,2.7127273,373.68198,-9.2970934
2180,2180,155.4053,18.364208,7.2471128,0.0,0,2.3556647,0.0,0.6602326,120.76225,2.6821055,373.63602,-9.2976446
2182,2182,155.4057,18.475885,7.2846923,0.0,0,2.3235447,0.0,0.66382313,121.07278,2.6506014,373.59009,-9.2991562
2184,2184,155.4061,18.55872,7.3230028,0.0,0,2.2924569,0.0,0.66936111,120.9273,2.616987,373.54413,-9.2979403
2186,2186,155.4065,18.610928,7.3489881,0.0,0,2.2619016,0.0,0.6732558,120.85021,2.5810204,373.49817,-9.2975235
2188,2188,155.4069,18.700743,7.3850474,0.0,0,2.2313497,0.0,0.67684811,120.947,2.5495775,373.45221,-9.2972002
2190,2190,155.4073,18.817139,7.4158063,0.0,0,2.2007978,0.0,0.68206626,121.03938,2.5180292,373.40628,-9.2970028
2192,2192,155.4077,18.937874,7.442565,0.0,0,2.1702456,0.0,0.68525738,121.42391,2.4847715,373.41464,-9.2968254
2194,2194,155.4081,19.030483,7.4789419,0.0,0,2.1396937,0.0,0.68942934,121.55236,2.4537482,373.47729,-9.2977266
2196,2196,155.4085,19.091824,7.5117955,0.0,0,2.1091418,0.0,0.69508904,121.29932,2.4204631,373.53998,-9.2986851
2198,2198,155.4089,19.193069,7.5493708,0.0,0,2.0785899,0.0,0.69881469,121.47173,2.3872244,373.60263,-9.2972555
2200,2200,155.4093,19.321238,7.5839062,0.0,0,2.048038,0.0,0.70370567,121.62725,2.3543167,373.66528,-9.2957869
2202,2202,155.4097,19.446062,7.6105771,0.0,0,2.0174859,0.0,0.70831823,121.86219,2.3196328,373.72794,-9.2955637
2204,2204,155.4101,19.530563,7.6463947,0.0,0,1.9869336,0.0,0.71167731,121.99302,2.2844114,373.79062,-9.2965269
2206,2206,155.4105,19.607918,7.6751032,0.0,0,1.9563816,0.0,0.716515,121.90751,2.2543442,373.85327,-9.2977409
2208,2208,155.4109,19.705395,7.7046251,0.0,0,1.9261349,0.0,0.7209385,121.9428,2.2233715,373.91592,-9.298048
2210,2210,155.4113,19.84046,7.7476206,0.0,0,1.896998,0.0,0.7252177,122.22604,2.1868014,373.97861,-9.2970085
2212,2212,155.4117,19.961575,7.7733545,0.0,0,1.867934,0.0,0.73038924,122.37095,2.1547632,374.04126,-9.2956448
2214,2214,155.4121,20.039442,7.8041725,0.0,0,1.83887,0.0,0.73414642,122.42323,2.1257985,374.10391,-9.2956705
2216,2216,155.4125,20.111282,7.8446579,0.0,0,1.809806,0.0,0.73894507,122.24187,2.0962284,374.1666,-9.2972679
2218,2218,155.4129,20.2344,7.8666501,0.0,0,1.7807419,0.0,0.74355364,122.41121,2.0590994,374.22925,-9.2971125
2220,2220,155.4133,20.365746,7.8972368,0.0,0,1.751678,0.0,0.74675918,122.75061,2.0287242,374.2919,-9.2963772
2222,2222,155.4137,20.480885,7.9345398,0.0,0,1.722614,0.0,0.75194156,122.86229,1.9973648,374.35458,-9.2956009
2224,2224,155.4141,20.552471,7.95614,0.0,0,1.69355,0.0,0.75621825,122.80409,1.9653296,374.41724,-9.2959938
2226,2226,155.4145,20.649227,7.9918795,0.0,0,1.6644859,0.0,0.759839,122.93581,1.9334003,374.47989,-9.295599
2228,2228,155.4149,20.765839,8.0278673,0.0,0,1.635422,0.0,0.76580817,122.85056,1.9023058,374.54254,-9.296792
2230,2230,155.4153,20.901432,8.0529318,0.0,0,1.6063581,0.0,0.76983428,123.17136,1.873227,374.60522,-9.2958956
2232,2232,155.4157,21.020094,8.0885534,0.0,0,1.577294,0.0,0.77370161,123.4095,1.841687,374.66788,-9.2955875
2234,2234,155.4161,21.107737,8.115447,0.0,0,1.5491621,0.0,0.77897733,123.27734,1.8124293,374.73053,-9.2957487
2236,2236,155.4165,21.218899,8.1392212,0.0,0,1.521511,0.0,0.78191721,123.54652,1.7818722,374.79321,-9.2961197
2238,2238,155.4169,21.338909,8.1738901,0.0,0,1.493863,0.0,0.78616554,123.71707,1.7508525,374.85587,-9.2965469
2240,2240,155.4173,21.461981,8.2012587,0.0,0,1.466215,0.0,0.79169118,123.714,1.7215278,374.91852,-9.2970505
2242,2242,155.4177,21.582878,8.2350502,0.0,0,1.438567,0.0,0.79534429,123.99615,1.6916903,374.9812,-9.2968779
2244,2244,155.4181,21.696522,8.2674809,0.0,0,1.4109191,0.0,0.80042076,123.99406,1.6661929,375.04385,-9.2962036
2246,2246,155.4185,21.801579,8.2896538,0.0,0,1.3832711,0.0,0.80499297,124.05237,1.6356099,375.10651,-9.2958937
2248,2248,155.4189,21.924002,8.3238153,0.0,0,1.355623,0.0,0.80834883,124.2857,1.6080275,375.00372,-9.2947283
2250,2250,155.4193,22.070711,8.3494434,0.0,0,1.3279752,0.0,0.81299037,124.51512,1.5765486,374.90091,-9.2947521
2252,2252,155.4197,22.194618,8.3759041,0.0,0,1.3003271,0.0,0.81729054,124.6981,1.545782,374.79813,-9.2961588
2254,2254,155.4201,22.28594,8.4149094,0.0,0,1.2726791,0.0,0.82167816,124.73297,1.5177315,374.69534,-9.2967472
2256,2256,155.4205,22.398094,8.4344006,0.0,0,1.2450311,0.0,0.82636821,124.73756,1.4896566,374.59256,-9.296916
2258,2258,155.4209,22.521835,8.461359,0.0,0,1.2176605,0.0,0.82980871,124.99326,1.4599668,374.48978,-9.2948284
2260,2260,155.4213,22.655916,8.4988203,0.0,0,1.1912985,0.0,0.83472162,125.12457,1.4318581,374.38699,-9.2937403
2262,2262,155.4217,22.781231,8.5169725,0.0,0,1.1650023,0.0,0.8393296,125.22962,1.4024206,374.28418,-9.2944174
2264,2264,155.4221,22.90056,8.5468578,0.0,0,1.1387062,0.0,0.84257334,125.47266,1.3713907,374.1814,-9.2951241
2266,2266,155.4225,23.021471,8.5825138,0.0,0,1.1124103,0.0,0.84810096,125.43315,1.3428602,374.07861,-9.2953806
2268,2268,155.4229,23.155331,8.5999355,0.0,0,1.0861143,0.0,0.85208178,125.69215,1.3174418,373.97583,-9.295229
2270,2270,155.4233,23.30814,8.6313696,0.0,0,1.0598181,0.0,0.85538584,126.04903,1.2903426,373.87305,-9.2945395
2272,2272,155.4237,23.450447,8.6604214,0.0,0,1.0335222,0.0,0.86106884,126.13107,1.2604377,373.77026,-9.2945604
2274,2274,155.4241,23.562826,8.6820374,0.0,0,1.0072262,0.0,0.86452514,126.32208,1.2329752,373.66745,-9.2945786
2276,2276,155.4245,23.687483,8.7154808,0.0,0,0.98093021,0.0,0.86851567,126.48558,1.2054378,373.56467,-9.294322
2278,2278,155.4249,23.825457,8.7400751,0.0,0,0.95463419,0.0,0.87425983,126.48055,1.1796633,373.46188,-9.294589
2280,2280,155.4253,23.98811,8.7659636,0.0,0,0.92833829,0.0,0.87754035,126.9211,1.1493609,373.3591,-9.2945738
2282,2282,155.4257,24.125952,8.7953043,0.0,0,0.90204227,0.0,0.8816902,127.12727,1.1233788,373.25632,-9.2939901
2284,2284,155.4261,24.247824,8.8153238,0.0,0,0.87659407,0.0,0.88662219,127.13586,1.0972455,373.15353,-9.2942848
2286,2286,155.4265,24.366631,8.8459864,0.0,0,0.85158336,0.0,0.88985825,127.34486,1.0723624,373.05075,-9.2945719
2288,2288,155.4269,24.512165,8.8723812,0.0,0,0.82657528,0.0,0.89463198,127.45597,1.0444714,372.94794,-9.2938919
2290,2290,155.4273,24.686926,8.8932648,0.0,0,0.80156738,0.0,0.89915061,127.80895,1.0194223,372.84515,-9.2946091
2292,2292,155.4277,24.834341,8.9294205,0.0,0,0.77655935,0.0,0.90298903,128.09326,0.99118167,372.74237,-9.2941971
2294,2294,155.4281,24.94257,8.9499607,0.0,0,0.75155133,0.0,0.90788513,128.05684,0.96383071,372.63959,-9.2949734
2296,2296,155.4285,25.079971,8.9698162,0.0,0,0.72654337,0.0,0.91140312,128.29559,0.94035721,372.5368,-9.2945929
2298,2298,155.4289,25.248957,9.0035295,0.0,0,0.70153534,0.0,0.91528136,128.618,0.91291726,372.42191,-9.2941027
2300,2300,155.4293,25.425419,9.0207357,0.0,0,0.67652738,0.0,0.92016292,128.9221,0.8857308,372.30704,-9.2940426
2302,2302,155.4297,25.564447,9.0491428,0.0,0,0.65151936,0.0,0.92389274,129.14085,0.85868746,372.19217,-9.2938776
2304,2304,155.4301,25.687559,9.0860519,0.0,0,0.62651134,0.0,0.92954141,129.03207,0.83161587,372.07727,-9.2943926
2306,2306,155.4305,25.837397,9.1007624,0.0,0,0.60150337,0.0,0.93385631,129.22128,0.80601132,371.9624,-9.2931252
2308,2308,155.4309,26.001165,9.1255102,0.0,0,0.57674313,0.0,0.93636322,129.74428,0.77855736,371.8475,-9.2935905
2310,2310,155.4313,26.180122,9.1526403,0.0,0,0.5528841,0.0,0.94144481,129.91702,0.7556563,371.73264,-9.2927961
2312,2312,155.4317,26.323181,9.1663036,0.0,0,0.52908403,0.0,0.94486052,130.20108,0.72720778,371.61777,-9.2938871
2314,2314,155.4321,26.443607,9.1977558,0.0,0,0.50528395,0.0,0.94831294,130.3719,0.7057023,371.50287,-9.2930326
2316,2316,155.4325,26.596621,9.2261639,0.0,0,0.48148397,0.0,0.95481557,130.26503,0.6792078,371.388,-9.2920933
2318,2318,155.4329,26.780516,9.2473211,0.0,0,0.45768398,0.0,0.95834559,130.66957,0.65410382,371.2731,-9.2917032
2320,2320,155.4333,26.95533,9.2757969,0.0,0,0.43388397,0.0,0.96196038,131.10962,0.62822193,371.15823,-9.2927294
2322,2322,155.4337,27.104603,9.2947798,0.0,0,0.41008398,0.0,0.9671818,131.14142,0.6051355,371.04337,-9.2926855
2324,2324,155.4341,27.24489,9.3150434,0.0,0,0.38628396,0.0,0.96954024,131.49529,0.5787037,370.92847,-9.293273
2326,2326,155.4345,27.411655,9.341403,0.0,0,0.36248395,0.0,0.97386932,131.68294,0.55578357,370.8136,-9.2917786
2328,2328,155.4349,27.585144,9.3602476,0.0,0,0.33868399,0.0,0.97901368,131.86301,0.53295946,370.6987,-9.2920523