File: clean data/testID_0204.csv
level_0,index,Time(sec),Force(kN),Jaw(mm),PowAngle(deg),Power(W),Pram,PTemp,Strain,Stress(MPa),Stroke(mm),TC1(C),wedge(mm)
1874,1874,155.3461,0.62081689,0.051150892,0.0,0,9.0044422,0.0,0.0037213059,7.1705804,10.002477,335.19977,-9.3078632
1876,1876,155.3465,3.3759565,0.089376718,0.0,0,8.9459143,0.0,0.0054263799,37.892448,9.9332762,335.66815,-9.3067923
1878,1878,155.3469,5.7739515,0.13958691,0.0,0,8.8873863,0.0,0.0090687564,71.155449,9.8803244,336.13654,-9.3055515
1880,1880,155.3473,6.6665697,0.20201364,0.0,0,8.8288584,0.0,0.013133303,82.54142,9.8079062,336.60492,-9.3026381
1882,1882,155.3477,7.3203449,0.34383473,0.0,0,8.7703304,0.0,0.021963691,90.87394,9.7252913,337.0733,-9.3017311
1884,1884,155.3481,7.6687727,0.42732549,0.0,0,8.7136879,0.0,0.028527187,94.078529,9.6256933,337.54169,-9.301301
1886,1886,155.3485,8.2326088,0.51815724,0.0,0,8.6580172,0.0,0.034592196,100.80655,9.5290995,338.01007,-9.3018198
1888,1888,155.3489,8.8379173,0.58230668,0.0,0,8.6023531,0.0,0.039066184,107.25232,9.4462891,338.47845,-9.3017473
1890,1890,155.3493,8.7096329,0.6116125,0.0,0,8.546689,0.0,0.041521128,107.02061,9.3784695,338.94684,-9.3009005
1892,1892,155.3497,8.645647,0.68059623,0.0,0,8.4910259,0.0,0.045945842,104.62469,9.3170462,339.41522,-9.3015976
1894,1894,155.3501,9.0768757,0.7372002,0.0,0,8.4353609,0.0,0.049858674,109.49422,9.2589321,339.88361,-9.2996435
1896,1896,155.3505,9.5255079,0.80378288,0.0,0,8.3796968,0.0,0.054648399,114.41585,9.1933632,340.35199,-9.2979078
1898,1898,155.3509,9.281806,0.9112457,0.0,0,8.3240337,0.0,0.061744761,111.71741,9.1127348,340.82037,-9.2978849
1900,1900,155.3513,9.242012,0.99954993,0.0,0,8.2683697,0.0,0.068388775,109.58195,9.0262623,341.28876,-9.3005753
1902,1902,155.3517,9.411047,1.0712909,0.0,0,8.2127056,0.0,0.073846079,111.4184,8.9446917,341.75714,-9.3015509
1904,1904,155.3521,9.6309061,1.1109036,0.0,0,8.1570415,0.0,0.076558061,112.99187,8.8722105,342.21222,-9.299592
1906,1906,155.3525,9.8163767,1.159372,0.0,0,8.1013775,0.0,0.080201358,115.54799,8.8123264,342.6673,-9.2983446
1908,1908,155.3529,9.5883617,1.2207227,0.0,0,8.0462685,0.0,0.084611148,112.12296,8.7576036,343.12234,-9.2978821
1910,1910,155.3533,9.8685255,1.2742014,0.0,0,7.993176,0.0,0.088167228,114.70734,8.7014723,343.57742,-9.298665
1912,1912,155.3537,10.00895,1.3491505,0.0,0,7.9402156,0.0,0.09401986,115.79149,8.6366272,344.0325,-9.2995853
1914,1914,155.3541,10.066126,1.4274031,0.0,0,7.8872557,0.0,0.099305198,116.30671,8.5659342,344.48755,-9.2994394
1916,1916,155.3545,9.8800707,1.498829,0.0,0,7.8342957,0.0,0.10462843,113.40799,8.4995384,344.94263,-9.2996349
1918,1918,155.3549,10.009753,1.5572845,0.0,0,7.7813354,0.0,0.10961406,114.17962,8.4321079,345.39771,-9.2977152
1920,1920,155.3553,10.100621,1.5959458,0.0,0,7.7283754,0.0,0.11193667,114.72705,8.3719797,345.85275,-9.2968979
1922,1922,155.3557,10.228565,1.6460738,0.0,0,7.675415,0.0,0.11581607,116.02046,8.3179722,346.30783,-9.2986279
1924,1924,155.3561,10.136122,1.6944785,0.0,0,7.6224551,0.0,0.11976271,114.43827,8.2683039,346.76291,-9.29951
1926,1926,155.3565,10.348722,1.7498477,0.0,0,7.5694952,0.0,0.12320317,116.31064,8.2157984,347.21796,-9.2984352
1928,1928,155.3569,10.381589,1.8053066,0.0,0,7.5165353,0.0,0.12800047,116.3166,8.1638432,347.67303,-9.2986917
1930,1930,155.3573,10.426878,1.8638,0.0,0,7.4635754,0.0,0.13224141,116.34377,8.1019192,348.12811,-9.2980814
1932,1932,155.3577,10.359065,1.9377494,0.0,0,7.410615,0.0,0.13747002,115.04782,8.0466137,348.58319,-9.2975359
1934,1934,155.3581,10.419188,1.9783763,0.0,0,7.3593612,0.0,0.14148846,114.97662,7.9904613,349.03824,-9.2992716
1936,1936,155.3585,10.581248,2.0171216,0.0,0,7.3089881,0.0,0.14385116,116.48716,7.9319119,349.49332,-9.2991428
1938,1938,155.3589,10.558544,2.0736949,0.0,0,7.2586198,0.0,0.14827368,115.92529,7.8865433,349.94839,-9.2987232
1940,1940,155.3593,10.566522,2.1117406,0.0,0,7.2082515,0.0,0.15167738,115.55777,7.83955,350.40344,-9.2986288
1942,1942,155.3597,10.646651,2.1658354,0.0,0,7.1578832,0.0,0.15518485,115.94092,7.7893376,350.85852,-9.2976665
1944,1944,155.3601,10.794505,2.2215798,0.0,0,7.1075153,0.0,0.16005097,116.95628,7.7393103,351.3136,-9.2989159
1946,1946,155.3605,10.816401,2.2701261,0.0,0,7.0571475,0.0,0.16377427,116.95634,7.6882,351.76865,-9.2987261
1948,1948,155.3609,10.760108,2.3304658,0.0,0,7.0067792,0.0,0.16813543,115.73518,7.6335883,352.22372,-9.2997303
1950,1950,155.3613,10.785098,2.3712981,0.0,0,6.9564114,0.0,0.17209895,115.53977,7.5849447,352.6788,-9.3000851
1952,1952,155.3617,10.930621,2.4104536,0.0,0,6.9060431,0.0,0.17476483,116.61108,7.5339775,353.13385,-9.2982111
1954,1954,155.3621,10.983464,2.4607418,0.0,0,6.8556757,0.0,0.17867239,116.93358,7.4874249,352.81796,-9.2976608
1956,1956,155.3625,10.96591,2.5024254,0.0,0,6.8053074,0.0,0.18252091,116.29229,7.4373341,352.46149,-9.2977037
1958,1958,155.3629,10.998979,2.5606725,0.0,0,6.7554417,0.0,0.18642339,116.20868,7.3905096,352.10501,-9.2982988
1960,1960,155.3633,11.103851,2.6097248,0.0,0,6.7074022,0.0,0.1907492,116.74468,7.3394613,351.7485,-9.29916
1962,1962,155.3637,11.158134,2.6577904,0.0,0,6.6594815,0.0,0.19490853,116.93704,7.289578,351.39203,-9.298481
1964,1964,155.3641,11.152306,2.7175314,0.0,0,6.6115613,0.0,0.19904543,116.38471,7.2377782,351.03555,-9.2983179
1966,1966,155.3645,11.205836,2.7536175,0.0,0,6.5636415,0.0,0.20263255,116.50115,7.1920094,350.67908,-9.2981977
1968,1968,155.3649,11.277452,2.7990587,0.0,0,6.5157218,0.0,0.20618974,116.69408,7.140903,350.3226,-9.2976856
1970,1970,155.3653,11.334525,2.8525381,0.0,0,6.467802,0.0,0.21016908,116.93942,7.0934033,349.96613,-9.2987309
1972,1972,155.3657,11.372234,2.8941083,0.0,0,6.4198818,0.0,0.21423228,116.82682,7.0435767,349.60962,-9.2979898
1974,1974,155.3661,11.444034,2.94842,0.0,0,6.3719616,0.0,0.2183321,117.05338,6.9952812,349.25314,-9.2991638
1976,1976,155.3665,11.514226,3.0038693,0.0,0,6.3240418,0.0,0.22278814,117.24295,6.9480324,348.89667,-9.2996149
1978,1978,155.3669,11.534148,3.0462077,0.0,0,6.2761221,0.0,0.22690558,117.08971,6.8987646,348.54019,-9.2982845
1980,1980,155.3673,11.545212,3.0957887,0.0,0,6.2282019,0.0,0.23047923,116.69053,6.8465781,348.18372,-9.2970409
1982,1982,155.3677,11.628217,3.1445923,0.0,0,6.1802821,0.0,0.23490818,116.98177,6.7957673,347.82724,-9.2979116
1984,1984,155.3681,11.702422,3.1876335,0.0,0,6.1339049,0.0,0.23870149,117.32703,6.750895,347.47073,-9.2980938
1986,1986,155.3685,11.737237,3.2376902,0.0,0,6.0883236,0.0,0.24247022,117.25987,6.6992569,347.11426,-9.2997112
1988,1988,155.3689,11.762805,3.2883563,0.0,0,6.042748,0.0,0.24734125,116.95759,6.6504197,346.75778,-9.29953
1990,1990,155.3693,11.810204,3.3360853,0.0,0,5.9971719,0.0,0.25120309,116.83702,6.600225,346.40131,-9.3005171
1992,1992,155.3697,11.920573,3.3855641,0.0,0,5.9515953,0.0,0.25515455,117.52859,6.5531836,346.04483,-9.2992649
1994,1994,155.3701,11.951797,3.432653,0.0,0,5.9060202,0.0,0.2599127,117.39733,6.5040498,345.68835,-9.2981167
1996,1996,155.3705,11.962101,3.4816,0.0,0,5.8604436,0.0,0.26349705,116.99876,6.4556932,345.33188,-9.2974768
1998,1998,155.3709,12.006919,3.5317791,0.0,0,5.8148675,0.0,0.26789242,116.90538,6.4088807,344.97537,-9.2984886
2000,2000,155.3713,12.06239,3.5771399,0.0,0,5.7692914,0.0,0.27253127,116.9111,6.3598967,344.6189,-9.3000488
2002,2002,155.3717,12.137542,3.6300402,0.0,0,5.7237153,0.0,0.27628529,117.25514,6.3109426,344.26242,-9.3007059
2004,2004,155.3721,12.18225,3.6754277,0.0,0,5.6781397,0.0,0.28078005,117.08023,6.2609506,344.00089,-9.300209
2006,2006,155.3725,12.219129,3.7189267,0.0,0,5.6325636,0.0,0.28476009,116.9941,6.2144842,343.74991,-9.2995958
2008,2008,155.3729,12.274029,3.7745247,0.0,0,5.5874419,0.0,0.28887445,117.01967,6.1681905,343.49893,-9.2980213
2010,2010,155.3733,12.336711,3.8159788,0.0,0,5.5439739,0.0,0.29345906,117.07845,6.1185641,343.24796,-9.2979469
2012,2012,155.3737,12.392546,3.8624177,0.0,0,5.5006137,0.0,0.29732898,117.07487,6.0705428,342.99698,-9.2993755
2014,2014,155.3741,12.444046,3.9203706,0.0,0,5.4572535,0.0,0.30207095,117.09599,6.0224586,342.74597,-9.2992678
2016,2016,155.3745,12.483807,3.9589012,0.0,0,5.4138937,0.0,0.30650491,116.97984,5.9737887,342.495,-9.2993736
2018,2018,155.3749,12.533362,4.005321,0.0,0,5.3705335,0.0,0.31007436,117.05304,5.9250579,342.24402,-9.2981567
2020,2020,155.3753,12.580666,4.0605402,0.0,0,5.3271737,0.0,0.31502035,116.79557,5.878952,341.99304,-9.2983131
2022,2022,155.3757,12.643981,4.0986485,0.0,0,5.2838135,0.0,0.31911564,117.00823,5.828125,341.74207,-9.2983494
2024,2024,155.3761,12.70116,4.1506624,0.0,0,5.2404532,0.0,0.32313088,117.00707,5.7814336,341.49109,-9.2996168
2026,2026,155.3765,12.74277,4.1995993,0.0,0,5.1970935,0.0,0.32815689,116.83231,5.7362761,341.24011,-9.2987423
2028,2028,155.3769,12.769855,4.2406111,0.0,0,5.1537337,0.0,0.33202887,116.64972,5.691412,340.98911,-9.2986774
2030,2030,155.3773,12.834672,4.2910938,0.0,0,5.1103735,0.0,0.33620539,116.6665,5.6427441,340.73813,-9.2985535
2032,2032,155.3777,12.913969,4.3342519,0.0,0,5.0670133,0.0,0.34104437,116.87498,5.5948043,340.48715,-9.2979088
2034,2034,155.3781,12.971312,4.3810668,0.0,0,5.0250487,0.0,0.34494817,116.95973,5.5496154,340.23618,-9.2983313
2036,2036,155.3785,13.001382,4.4297442,0.0,0,4.9838042,0.0,0.34938541,116.69914,5.5016747,339.9852,-9.2996922
2038,2038,155.3789,13.02209,4.4702883,0.0,0,4.942564,0.0,0.35406119,116.3595,5.4578166,339.73422,-9.3000422
2040,2040,155.3793,13.096964,4.5226173,0.0,0,4.9013243,0.0,0.35794362,116.51337,5.4141383,339.48322,-9.2991018
2042,2042,155.3797,13.170274,4.5635428,0.0,0,4.8600841,0.0,0.3623386,116.67123,5.367074,339.23224,-9.2991858
2044,2044,155.3801,13.210182,4.602788,0.0,0,4.8188443,0.0,0.36661229,116.57578,5.3235884,338.98126,-9.2978249
2046,2046,155.3805,13.241219,4.6554966,0.0,0,4.7776041,0.0,0.37064898,116.36251,5.2771387,338.73029,-9.2993002
2048,2048,155.3809,13.289786,4.6949663,0.0,0,4.7363639,0.0,0.37517297,116.20649,5.2340932,338.47931,-9.2998476
2050,2050,155.3813,13.360204,4.7392225,0.0,0,4.6951241,0.0,0.37934726,116.33666,5.1909289,338.22833,-9.3013649
2052,2052,155.3817,13.440562,4.7929025,0.0,0,4.6538844,0.0,0.38391498,116.50751,5.1423264,337.97736,-9.300128
2054,2054,155.3821,13.477991,4.8291287,0.0,0,4.6126437,0.0,0.38856459,116.36894,5.0992389,337.70599,-9.2988768
2056,2056,155.3825,13.514462,4.8726401,0.0,0,4.571404,0.0,0.39232478,116.21967,5.0547972,337.43109,-9.2978907
2058,2058,155.3829,13.552156,4.9235272,0.0,0,4.5305758,0.0,0.39695948,116.01629,5.009182,337.15616,-9.2980118
2060,2060,155.3833,13.606437,4.9569011,0.0,0,4.4912457,0.0,0.40120962,115.94819,4.9697938,336.88123,-9.2995787
2062,2062,155.3837,13.676907,5.0015068,0.0,0,4.4520135,0.0,0.40480348,116.10783,4.9263806,336.60629,-9.2995195
2064,2064,155.3841,13.745994,5.0509391,0.0,0,4.4127817,0.0,0.41013196,116.05685,4.8796759,336.33136,-9.2990103
2066,2066,155.3845,13.773452,5.0892801,0.0,0,4.3735499,0.0,0.41436046,115.82169,4.8393135,336.05643,-9.2995977
2068,2068,155.3849,13.811857,5.1371679,0.0,0,4.3343177,0.0,0.41833156,115.6657,4.7973752,335.78149,-9.2986803
2070,2070,155.3853,13.907277,5.1790557,0.0,0,4.2950859,0.0,0.42348087,115.82159,4.7542701,335.50659,-9.2978497
2072,2072,155.3857,13.982502,5.2165647,0.0,0,4.2558532,0.0,0.42703566,116.11726,4.7108698,335.23166,-9.2983351
2074,2074,155.3861,14.01493,5.2596388,0.0,0,4.2166214,0.0,0.43096533,115.99029,4.6692281,334.95673,-9.2998781
2076,2076,155.3865,14.052677,5.3000612,0.0,0,4.1773896,0.0,0.43610507,115.72643,4.6265044,334.68179,-9.2992992
2078,2078,155.3869,14.102373,5.3439322,0.0,0,4.1381574,0.0,0.43969309,115.57618,4.5814114,334.40686,-9.2990017
2080,2080,155.3873,14.195828,5.3862953,0.0,0,4.0989256,0.0,0.44426918,115.82473,4.5453172,334.13193,-9.2976599
2082,2082,155.3877,14.258851,5.4226766,0.0,0,4.0596938,0.0,0.44878507,115.82554,4.5024152,333.85699,-9.2979097
2084,2084,155.3881,14.2915,5.4710288,0.0,0,4.0217257,0.0,0.45274654,115.67517,4.4616871,333.58206,-9.2980947
2086,2086,155.3885,14.329473,5.5099816,0.0,0,3.9844093,0.0,0.45751595,115.40629,4.4210443,333.30716,-9.2985725
2088,2088,155.3889,14.399157,5.5453372,0.0,0,3.9470973,0.0,0.46148092,115.44191,4.3812594,333.03223,-9.2980518
2090,2090,155.3893,14.478726,5.5945239,0.0,0,3.9097853,0.0,0.46554685,115.68333,4.3402624,332.75729,-9.2979813
2092,2092,155.3897,14.543955,5.6276884,0.0,0,3.8724735,0.0,0.47026196,115.63209,4.2973871,332.48236,-9.2979145
2094,2094,155.3901,14.593987,5.6668506,0.0,0,3.8351612,0.0,0.47406366,115.63788,4.2558885,332.20743,-9.2984381
2096,2096,155.3905,14.642636,5.7172971,0.0,0,3.7978494,0.0,0.47893187,115.43633,4.2153845,331.9325,-9.2988863
2098,2098,155.3909,14.695267,5.7472844,0.0,0,3.7605371,0.0,0.48334241,115.36553,4.1745944,331.65756,-9.2980051
2100,2100,155.3913,14.769244,5.7888198,0.0,0,3.7232254,0.0,0.48687673,115.50637,4.1350026,331.38266,-9.2979622
2102,2102,155.3917,14.839888,5.8327827,0.0,0,3.6859133,0.0,0.4918128,115.48104,4.0961947,331.10773,-9.2988138
2104,2104,155.3921,14.90045,5.8643188,0.0,0,3.6486013,0.0,0.49591541,115.51102,4.057611,331.05856,-9.2993708
2106,2106,155.3925,14.938913,5.9100332,0.0,0,3.6112893,0.0,0.49982572,115.41587,4.0170345,331.06583,-9.3006582
2108,2108,155.3929,15.011317,5.9499431,0.0,0,3.5743496,0.0,0.50517899,115.26948,3.978545,331.07312,-9.3000584
2110,2110,155.3933,15.089352,5.9827867,0.0,0,3.538765,0.0,0.50872189,115.45816,3.9399514,331.08038,-9.2988729
2112,2112,155.3937,15.16072,6.0249414,0.0,0,3.5032687,0.0,0.51272935,115.57686,3.9009631,331.08768,-9.2978525
2114,2114,155.3941,15.214616,6.0615048,0.0,0,3.4677727,0.0,0.51775414,115.37105,3.8651574,331.09494,-9.2979307
2116,2116,155.3945,15.267274,6.1000566,0.0,0,3.432277,0.0,0.52145088,115.35579,3.8275476,331.10223,-9.299016
2118,2118,155.3949,15.328919,6.1409497,0.0,0,3.3967807,0.0,0.52584493,115.30054,3.7882478,331.1095,-9.2999744
2120,2120,155.3953,15.416401,6.173924,0.0,0,3.3612847,0.0,0.53059465,115.41119,3.7523992,331.11679,-9.2994003
2122,2122,155.3957,15.486985,6.2165284,0.0,0,3.3257887,0.0,0.53420538,115.54981,3.7150409,331.12405,-9.2985106
2124,2124,155.3961,15.550058,6.2542005,0.0,0,3.2902927,0.0,0.53903025,115.48589,3.6767879,331.13135,-9.2966814
2126,2126,155.3965,15.586266,6.2874751,0.0,0,3.2547965,0.0,0.54345888,115.25127,3.6371603,331.13861,-9.2970905
2128,2128,155.3969,15.66092,6.3337245,0.0,0,3.2193007,0.0,0.54747224,115.30041,3.6015661,331.1459,-9.2985878
2130,2130,155.3973,15.769484,6.3656492,0.0,0,3.1838048,0.0,0.55223686,115.45947,3.5605729,331.15317,-9.2987099
2132,2132,155.3977,15.840642,6.3987379,0.0,0,3.1483088,0.0,0.55596483,115.69099,3.525111,331.16046,-9.2987566
2134,2134,155.3981,15.897858,6.4437728,0.0,0,3.11395,0.0,0.56029224,115.58964,3.4875576,331.16772,-9.2977991
2136,2136,155.3985,15.951632,6.4726315,0.0,0,3.0801783,0.0,0.56488425,115.39165,3.4502997,331.17502,-9.2964191
2138,2138,155.3989,16.028957,6.512383,0.0,0,3.0464106,0.0,0.56866294,115.53522,3.4143999,331.18228,-9.2967949
2140,2140,155.3993,16.118565,6.5584507,0.0,0,3.0126424,0.0,0.57395834,115.57057,3.3748212,331.18954,-9.2977295
2142,2142,155.3997,16.20505,6.5854077,0.0,0,2.9788744,0.0,0.57826316,115.6955,3.3408747,331.19684,-9.2980881
2144,2144,155.4001,16.260841,6.623476,0.0,0,2.9451065,0.0,0.581716,115.66526,3.3043559,331.2041,-9.2985106
2146,2146,155.4005,16.317377,6.6633387,0.0,0,2.9113381,0.0,0.58692968,115.43746,3.2678847,331.2114,-9.2979059
2148,2148,155.4009,16.404116,6.6909018,0.0,0,2.8775704,0.0,0.59076297,115.62988,3.233407,331.21866,-9.2966652
2150,2150,155.4013,16.504564,6.7311096,0.0,0,2.8438022,0.0,0.59450352,115.85468,3.1946189,331.22595,-9.2976656
2152,2152,155.4017,16.589499,6.7690372,0.0,0,2.810034,0.0,0.60013485,115.83781,3.159713,331.23322,-9.2975807
2154,2154,155.4021,16.640491,6.8021603,0.0,0,2.7762663,0.0,0.60384512,115.80071,3.1249342,331.298,-9.2979507
2156,2156,155.4025,16.688782,6.8419294,0.0,0,2.7424984,0.0,0.60811603,115.70047,3.0882661,331.38196,-9.2982635
2158,2158,155.4029,16.788691,6.8733697,0.0,0,2.7090683,0.0,0.61319888,115.7453,3.0537255,331.46591,-9.2998362
2160,2160,155.4033,16.90449,6.9097381,0.0,0,2.6768677,0.0,0.61663526,116.09513,3.0184267,331.54984,-9.298605
2162,2162,155.4037,16.976257,6.9458232,0.0,0,2.6447473,0.0,0.62120205,116.09186,2.9812126,331.63379,-9.2973785
2164,2164,155.4041,17.028357,6.9750152,0.0,0,2.6126273,0.0,0.62574077,115.8773,2.9478931,331.71774,-9.2976398
2166,2166,155.4045,17.09271,7.0162063,0.0,0,2.5805073,0.0,0.62956554,115.90184,2.9149718,331.8017,-9.2983971
2168,2168,155.4049,17.19965,7.0472808,0.0,0,2.5483873,0.0,0.63423389,116.02238,2.8785803,331.88562,-9.2985497
2170,2170,155.4053,17.318029,7.0771236,0.0,0,2.5162673,0.0,0.63821059,116.4164,2.8442848,331.96957,-9.2992144
2172,2172,155.4057,17.385279,7.1223588,0.0,0,2.4841473,0.0,0.64264512,116.36105,2.8097405,332.05353,-9.2975988
2174,2174,155.4061,17.451281,7.1498933,0.0,0,2.4520273,0.0,0.64770257,116.21069,2.7755859,332.13745,-9.2971554
2176,2176,155.4065,17.533331,7.1836829,0.0,0,2.4199073,0.0,0.6514436,116.33827,2.744067,332.22141,-9.2967196
2178,2178,155.4069,17.638199,7.2262583,0.0,0,2.3877873,0.0,0.65612841,116.50469,2.7124314,332.30536,-9.2967367
2180,2180,155.4073,17.750626,7.2500496,0.0,0,2.3556671,0.0,0.66072577,116.6321,2.6730847,332.38931,-9.2978601
2182,2182,155.4077,17.817818,7.2848644,0.0,0,2.3235474,0.0,0.6640234,116.76295,2.6432552,332.47324,-9.2982044
2184,2184,155.4081,17.894819,7.3255563,0.0,0,2.2924595,0.0,0.66935313,116.64196,2.6078184,332.55719,-9.2973709
2186,2186,155.4085,17.98777,7.3486152,0.0,0,2.2619042,0.0,0.67336702,116.71994,2.5726769,332.64114,-9.2966394
2188,2188,155.4089,18.098076,7.3859529,0.0,0,2.2313523,0.0,0.67704064,117.01218,2.5389779,332.7251,-9.2964926
2190,2190,155.4093,18.197523,7.4231439,0.0,0,2.2008004,0.0,0.68281496,116.98833,2.509804,332.80902,-9.2967806
2192,2192,155.4097,18.28653,7.4521408,0.0,0,2.1702483,0.0,0.68666685,117.07364,2.4731724,332.89297,-9.2962952
2194,2194,155.4101,18.357079,7.4908748,0.0,0,2.1396964,0.0,0.69079387,117.0849,2.4404855,332.97693,-9.2973366
2196,2196,155.4105,18.442133,7.520824,0.0,0,2.1091442,0.0,0.6961953,116.96236,2.4078999,333.06088,-9.2975836
2198,2198,155.4109,18.552969,7.5510001,0.0,0,2.0785923,0.0,0.69932008,117.366,2.3770969,333.14481,-9.2976227
2200,2200,155.4113,18.673035,7.584022,0.0,0,2.0480404,0.0,0.70356923,117.5842,2.3427713,333.22876,-9.2974854
2202,2202,155.4117,18.751076,7.6108308,0.0,0,2.0174885,0.0,0.70847654,117.52959,2.3080285,333.31271,-9.2972527
2204,2204,155.4121,18.835901,7.649333,0.0,0,1.9869361,0.0,0.7121408,117.59021,2.278585,333.2504,-9.2963676
2206,2206,155.4125,18.927391,7.6821647,0.0,0,1.9563841,0.0,0.71739024,117.56659,2.2465985,333.12543,-9.295804
2208,2208,155.4129,19.043268,7.708952,0.0,0,1.9261373,0.0,0.72179681,117.73283,2.2139544,333.00043,-9.2965832
2210,2210,155.4133,19.157606,7.7505956,0.0,0,1.8970004,0.0,0.72577059,118.02381,2.1830525,332.87543,-9.297555
2212,2212,155.4137,19.256582,7.7740378,0.0,0,1.8679364,0.0,0.73026186,118.07197,2.1521544,332.75046,-9.2973852
2214,2214,155.4141,19.334684,7.7997942,0.0,0,1.8388724,0.0,0.7337693,118.14699,2.1197643,332.62546,-9.2969875
2216,2216,155.4145,19.436909,7.8411975,0.0,0,1.8098084,0.0,0.73830324,118.19946,2.0901594,332.50049,-9.2963409
2218,2218,155.4149,19.544065,7.8639102,0.0,0,1.7807443,0.0,0.74327844,118.34109,2.0576541,332.37549,-9.2962551
2220,2220,155.4153,19.667309,7.8963594,0.0,0,1.7516804,0.0,0.74684048,118.61496,2.0305762,332.25052,-9.296236
2222,2222,155.4157,19.761122,7.9365973,0.0,0,1.7226164,0.0,0.75209212,118.5036,1.9931755,332.12552,-9.2963018
2224,2224,155.4161,19.852709,7.9567523,0.0,0,1.6935524,0.0,0.75637674,118.57307,1.9662553,332.00052,-9.2962284
2226,2226,155.4165,19.947289,7.9892869,0.0,0,1.6644883,0.0,0.75959647,118.76154,1.9358026,331.87555,-9.2972059
2228,2228,155.4169,20.080488,8.0229959,0.0,0,1.6354244,0.0,0.7650938,118.86656,1.903814,331.75055,-9.2974052
2230,2230,155.4173,20.221392,8.0459185,0.0,0,1.6063604,0.0,0.76890212,119.22903,1.8750871,331.62558,-9.2967377
2232,2232,155.4177,20.316101,8.0827732,0.0,0,1.5772964,0.0,0.7728073,119.37498,1.8445789,331.50058,-9.2963715
2234,2234,155.4181,20.408056,8.1138029,0.0,0,1.5491644,0.0,0.77875614,119.24489,1.8135438,331.37561,-9.2964191
2236,2236,155.4185,20.520119,8.1408405,0.0,0,1.5215132,0.0,0.78216666,119.44701,1.7871602,331.25061,-9.2953987
2238,2238,155.4189,20.668285,8.17348,0.0,0,1.4938653,0.0,0.78621435,119.81975,1.7557906,331.12561,-9.295805
2240,2240,155.4193,20.808689,8.1974669,0.0,0,1.4662173,0.0,0.79129899,120.0414,1.7257529,331.00064,-9.2962465
2242,2242,155.4197,20.909767,8.2286911,0.0,0,1.4385693,0.0,0.79444897,120.24545,1.6956683,330.87564,-9.2953796
2244,2244,155.4201,21.002445,8.2619839,0.0,0,1.4109213,0.0,0.79965085,120.17052,1.6648133,330.75067,-9.295702
2246,2246,155.4205,21.130728,8.2867804,0.0,0,1.3832734,0.0,0.8045277,120.21982,1.6381997,330.62567,-9.2963924
2248,2248,155.4209,21.260502,8.3226833,0.0,0,1.3556253,0.0,0.80811578,120.64506,1.6063707,330.5007,-9.294857
2250,2250,155.4213,21.400192,8.3477783,0.0,0,1.3279774,0.0,0.81290662,120.79083,1.5799618,330.3757,-9.2961264
2252,2252,155.4217,21.487307,8.3712912,0.0,0,1.3003293,0.0,0.81686264,120.83736,1.5506823,330.2507,-9.29494
2254,2254,155.4221,21.59936,8.4097328,0.0,0,1.2726814,0.0,0.82090878,120.94247,1.5233492,329.98111,-9.2949495
2256,2256,155.4225,21.738838,8.430768,0.0,0,1.2450334,0.0,0.82586831,121.08713,1.4939474,329.63364,-9.2956495
2258,2258,155.4229,21.883978,8.456459,0.0,0,1.2176627,0.0,0.82916898,121.53539,1.4666861,329.28613,-9.2949266
2260,2260,155.4233,22.015434,8.4954281,0.0,0,1.1913006,0.0,0.83413148,121.65126,1.4387716,328.93866,-9.2947092
2262,2262,155.4237,22.111887,8.5142088,0.0,0,1.1650045,0.0,0.8389706,121.61574,1.4066323,328.59119,-9.2953176
2264,2264,155.4241,22.22509,8.5448465,0.0,0,1.1387084,0.0,0.84222013,121.86285,1.3788658,328.24371,-9.2960882
2266,2266,155.4245,22.376852,8.5784435,0.0,0,1.1124125,0.0,0.84769446,121.98447,1.3497616,327.89621,-9.2957153
2268,2268,155.4249,22.546179,8.5964603,0.0,0,1.0861164,0.0,0.85161144,122.40675,1.3208596,327.54874,-9.2944307
2270,2270,155.4253,22.677101,8.628294,0.0,0,1.0598203,0.0,0.85497922,122.74806,1.2958953,327.20126,-9.2950039
2272,2272,155.4257,22.794024,8.6584005,0.0,0,1.0335244,0.0,0.86079729,122.6415,1.2667459,326.85376,-9.2947807
2274,2274,155.4261,22.922783,8.6805601,0.0,0,1.0072284,0.0,0.86437929,122.89294,1.2375464,326.50629,-9.2947111
2276,2276,155.4265,23.073496,8.7133713,0.0,0,0.98093235,0.0,0.86837488,123.19824,1.20986,326.15881,-9.2955399
2278,2278,155.4269,23.222963,8.7375822,0.0,0,0.95463634,0.0,0.87403297,123.29017,1.1815177,325.81134,-9.2945385
2280,2280,155.4273,23.353399,8.7642078,0.0,0,0.92834044,0.0,0.87713516,123.62686,1.160521,325.46384,-9.2947388
2282,2282,155.4277,23.470491,8.7952852,0.0,0,0.90204442,0.0,0.88174951,123.66262,1.1299523,325.11636,-9.2953167
2284,2284,155.4281,23.601025,8.8156424,0.0,0,0.87659609,0.0,0.88672912,123.74744,1.1019228,324.76889,-9.2950239
2286,2286,155.4285,23.760447,8.8471575,0.0,0,0.85158539,0.0,0.88995248,124.15065,1.0788666,324.42142,-9.2947931
2288,2288,155.4289,23.930038,8.8729086,0.0,0,0.82657731,0.0,0.8949104,124.4114,1.0517882,324.07391,-9.2939243
2290,2290,155.4293,24.060286,8.8928661,0.0,0,0.8015694,0.0,0.89908123,124.62698,1.0255569,323.72644,-9.2939825
2292,2292,155.4297,24.184925,8.9301062,0.0,0,0.77656138,0.0,0.90294743,124.73707,0.99596727,323.37897,-9.2945032
2294,2294,155.4301,24.320927,8.9504442,0.0,0,0.75155336,0.0,0.908113,124.85945,0.9724223,323.03149,-9.2940598
2296,2296,155.4305,24.48418,8.972846,0.0,0,0.72654539,0.0,0.91162372,125.19678,0.94132167,322.68399,-9.2940283
2298,2298,155.4309,24.641491,9.0082312,0.0,0,0.70153737,0.0,0.91610688,125.49948,0.91510224,322.33652,-9.2931814
2300,2300,155.4313,24.788,9.02491,0.0,0,0.67652941,0.0,0.9209832,125.59426,0.89227229,321.98904,-9.2924242
2302,2302,155.4317,24.927378,9.0510445,0.0,0,0.65152138,0.0,0.92410082,125.92076,0.86414486,321.64154,-9.2936335
2304,2304,155.4321,25.06061,9.0840578,0.0,0,0.62651336,0.0,0.92919582,125.96315,0.83602482,321.2673,-9.2935743
2306,2306,155.4325,25.226061,9.0986423,0.0,0,0.6015054,0.0,0.93350446,126.23613,0.81556261,320.87524,-9.293211
2308,2308,155.4329,25.397905,9.1307268,0.0,0,0.57674509,0.0,0.93688464,126.62666,0.78696966,320.48315,-9.2923689
2310,2310,155.4333,25.546314,9.1599731,0.0,0,0.55288601,0.0,0.94298244,126.59165,0.76057357,320.09109,-9.2922211
2312,2312,155.4337,25.68549,9.1741705,0.0,0,0.52908593,0.0,0.94613439,126.88022,0.73386419,319.69901,-9.2922831
2314,2314,155.4341,25.83045,9.2030859,0.0,0,0.50528592,0.0,0.94923586,127.19829,0.71129686,319.30692,-9.2930889
2316,2316,155.4345,26.000719,9.2263927,0.0,0,0.4814859,0.0,0.95511341,127.24047,0.6858269,318.91486,-9.2932749
2318,2318,155.4349,26.173546,9.2478428,0.0,0,0.45768592,0.0,0.95827073,127.73466,0.66076249,318.52277,-9.2925396
2320,2320,155.4353,26.319468,9.2766495,0.0,0,0.4338859,0.0,0.96226394,127.98803,0.63664091,318.13071,-9.2924833
2322,2322,155.4357,26.461304,9.296772,0.0,0,0.41008592,0.0,0.96789283,127.93388,0.61223286,317.73862,-9.2925568
2324,2324,155.4361,26.603224,9.3241129,0.0,0,0.3862859,0.0,0.97076988,128.24004,0.58803302,317.34656,-9.293272
2326,2326,155.4365,26.768969,9.3486443,0.0,0,0.36248589,0.0,0.97551423,128.41682,0.56439561,316.95447,-9.2930899
2328,2328,155.4369,26.951504,9.3646231,0.0,0,0.3386859,0.0,0.97987342,128.71925,0.5412029,316.56238,-9.2931423
2330,2330,155.4373,27.115812,9.3942518,0.0,0,0.31488591,0.0,0.98284066,129.11499,0.51831442,316.17032,-9.291604
2332,2332,155.4377,27.233196,9.41399,0.0,0,0.29108587,0.0,0.98764157,129.09375,0.4973945,315.77823,-9.2905684
2334,2334,155.4381,27.385324,9.4315825,0.0,0,0.26805463,0.0,0.99126434,129.30905,0.47432271,315.38617,-9.291605