File: clean data/testID_0150.csv
level_0,index,Time(sec),Force(kN),Jaw(mm),PowAngle(deg),Power(W),Pram,PTemp,Strain,Stress(MPa),Stroke(mm),TC1(C),wedge(mm)
2254,2254,178.7248,0.59070021,0.075997181,0.0,0,9.9458637,0.0,0.0053253858,7.2451754,10.046249,401.18579,-9.264452
2265,2265,178.727,1.9004158,0.099732511,0.0,0,9.9128637,0.0,0.0063417284,23.760044,10.010959,401.20566,-9.2644176
2276,2276,178.7292,2.9517879,0.10985595,0.0,0,9.8798637,0.0,0.007490553,37.116051,9.9756374,401.22552,-9.2632189
2287,2287,178.7314,3.6965172,0.13144946,0.0,0,9.8468628,0.0,0.0086771548,46.491249,9.9446096,401.36099,-9.2627716
2298,2298,178.7336,4.2641649,0.15607654,0.0,0,9.8138638,0.0,0.010673128,53.621651,9.9149656,401.59274,-9.2630501
2309,2309,178.7358,4.6178389,0.19655985,0.0,0,9.7808638,0.0,0.01292953,57.995052,9.8798561,401.82452,-9.2628584
2320,2320,178.738,4.9229031,0.22283201,0.0,0,9.7478638,0.0,0.015065825,61.669701,9.8414907,402.05627,-9.2611017
2331,2331,178.7402,5.1848769,0.25499392,0.0,0,9.7148628,0.0,0.017022029,64.9179,9.8079453,402.28806,-9.2610655
2342,2342,178.7424,5.3832259,0.28420112,0.0,0,9.6818638,0.0,0.019329526,67.158127,9.7727051,402.745,-9.2631512
2353,2353,178.7446,5.5078831,0.32594287,0.0,0,9.6488638,0.0,0.021703701,68.617485,9.7395325,403.2019,-9.2626801
2364,2364,178.7468,5.6194835,0.35233662,0.0,0,9.6158638,0.0,0.023884263,69.898819,9.7017469,403.65884,-9.2623377
2375,2375,178.749,5.6886363,0.38728213,0.0,0,9.5828629,0.0,0.026032479,70.594131,9.6698046,404.11575,-9.2627249
2386,2386,178.7512,5.7637362,0.42043272,0.0,0,9.5498638,0.0,0.028605027,71.280243,9.6392775,404.4884,-9.2620611
2397,2397,178.7534,5.8031721,0.4589335,0.0,0,9.5168638,0.0,0.030821426,71.657593,9.5972891,404.75992,-9.2610235
2408,2408,178.7556,5.878479,0.484992,0.0,0,9.4838638,0.0,0.032980435,72.397003,9.5665998,405.0314,-9.2612658
2419,2419,178.7578,5.924767,0.5211069,0.0,0,9.451623,0.0,0.035190329,72.742737,9.5325899,405.30292,-9.2624521
2430,2430,178.76,5.9699402,0.54934645,0.0,0,9.4194326,0.0,0.037365414,73.225182,9.5021429,405.5744,-9.262641
2441,2441,178.7622,6.0072503,0.58870935,0.0,0,9.3872423,0.0,0.039827008,73.453033,9.4677973,405.61115,-9.2621613
2452,2452,178.7644,6.0249305,0.61650252,0.0,0,9.355051,0.0,0.041981231,73.549355,9.4339428,405.62439,-9.261219
2463,2463,178.7666,6.0394487,0.64878345,0.0,0,9.3228617,0.0,0.044090886,73.666191,9.4000549,405.63763,-9.2617054
2474,2474,178.7688,6.0608644,0.67775255,0.0,0,9.2906713,0.0,0.046235878,73.691872,9.365468,405.65088,-9.2622824
2485,2485,178.771,6.0901809,0.71658576,0.0,0,9.258481,0.0,0.048754908,73.839226,9.3306103,405.65448,-9.2623329
2496,2496,178.7732,6.1253695,0.74273247,0.0,0,9.2262897,0.0,0.050825275,74.106407,9.3026714,405.64124,-9.2624779
2507,2507,178.7754,6.1690598,0.77713639,0.0,0,9.1940994,0.0,0.053169195,74.405296,9.269805,405.62799,-9.262517
2518,2518,178.7776,6.2011862,0.80827934,0.0,0,9.1619081,0.0,0.055407964,74.716675,9.2352161,405.61472,-9.2627697
2529,2529,178.7798,6.2085638,0.84615159,0.0,0,9.1297188,0.0,0.057942137,74.555,9.1999578,405.60147,-9.2624521
2540,2540,178.782,6.2181349,0.87331998,0.0,0,9.0975285,0.0,0.059930578,74.506607,9.1702814,405.56656,-9.2616014
2551,2551,178.7842,6.2382483,0.90459943,0.0,0,9.0653381,0.0,0.062164612,74.58197,9.1363173,405.52682,-9.260704
2562,2562,178.7864,6.2476239,0.9347021,0.0,0,9.0331469,0.0,0.064239651,74.714066,9.1054888,405.48709,-9.2609282
2573,2573,178.7886,6.266407,0.97095042,0.0,0,9.0009575,0.0,0.066860706,74.681358,9.0700502,405.44736,-9.2624006
2584,2584,178.7908,6.2872338,0.9975825,0.0,0,8.9687662,0.0,0.068793945,74.665619,9.0407743,405.40942,-9.2623243
2595,2595,178.793,6.3138366,1.030244,0.0,0,8.9365768,0.0,0.071205549,74.885109,9.0089169,405.37631,-9.2620935
2606,2606,178.7952,6.381598,1.0614691,0.0,0,8.9043856,0.0,0.073297009,75.454308,8.9749508,405.3432,-9.2616186
2617,2617,178.7974,6.3927326,1.0968841,0.0,0,8.8721952,0.0,0.075967111,75.39447,8.9390831,405.31012,-9.2619429
2628,2628,178.7996,6.391366,1.1281606,0.0,0,8.8400049,0.0,0.078111164,75.372673,8.9086571,405.27701,-9.2615385
2639,2639,178.8018,6.399982,1.1588316,0.0,0,8.8078146,0.0,0.080449268,75.254311,8.8768902,405.3017,-9.2617846
2650,2650,178.804,6.4179158,1.1892642,0.0,0,8.7756243,0.0,0.082518637,75.257973,8.8458567,405.34805,-9.2633581
2661,2661,178.8062,6.4234543,1.2238982,0.0,0,8.7437658,0.0,0.085178651,75.04657,8.8093538,405.39441,-9.2621984
2672,2672,178.8084,6.4354634,1.2525179,0.0,0,8.7131491,0.0,0.087024391,75.095901,8.7813578,405.44077,-9.2626553
2683,2683,178.8106,6.4674888,1.2847608,0.0,0,8.6825333,0.0,0.089517571,75.324585,8.7475061,405.4751,-9.262537
2694,2694,178.8128,6.5066876,1.3140099,0.0,0,8.6519194,0.0,0.091528334,75.52565,8.7150154,405.4552,-9.2621975
2705,2705,178.815,6.5343151,1.3493068,0.0,0,8.6213045,0.0,0.094359517,75.735374,8.6845665,405.43533,-9.2619724
2716,2716,178.8172,6.553997,1.3812853,0.0,0,8.5906887,0.0,0.096382424,75.810646,8.6513014,405.41547,-9.2624016
2727,2727,178.8194,6.5602837,1.4104769,0.0,0,8.5600729,0.0,0.09880773,75.630302,8.6221895,405.3956,-9.2618322
2738,2738,178.8216,6.5648041,1.4393097,0.0,0,8.529459,0.0,0.10070123,75.520859,8.5891962,405.29565,-9.262207
2749,2749,178.8238,6.5658717,1.4734824,0.0,0,8.4988432,0.0,0.10353354,75.417969,8.561389,405.14999,-9.2621841
2760,2760,178.826,6.5633545,1.5048953,0.0,0,8.4682283,0.0,0.10540516,75.261444,8.5308809,405.0043,-9.2628031
2771,2771,178.8282,6.5822306,1.530138,0.0,0,8.4376125,0.0,0.10768113,75.221901,8.4981031,404.85864,-9.261838
2782,2782,178.8304,6.6177964,1.560421,0.0,0,8.4069986,0.0,0.10963237,75.470039,8.4675884,404.7244,-9.2619257
2793,2793,178.8326,6.6725621,1.5934972,0.0,0,8.3763819,0.0,0.11250304,75.737358,8.4358835,404.70453,-9.2616911
2804,2804,178.8348,6.7002425,1.6248856,0.0,0,8.345767,0.0,0.11435108,76.036453,8.402626,404.68463,-9.261548
2815,2815,178.837,6.7026491,1.6518447,0.0,0,8.3151522,0.0,0.11677331,75.916786,8.3746901,404.66476,-9.2620125
2826,2826,178.8392,6.7233844,1.6858505,0.0,0,8.2845373,0.0,0.11897448,76.032715,8.3389168,404.6449,-9.2615471
2837,2837,178.8414,6.7369633,1.7190303,0.0,0,8.2539225,0.0,0.12197903,75.911766,8.3069744,404.69366,-9.2612963
2848,2848,178.8436,6.7456684,1.7533157,0.0,0,8.2233057,0.0,0.12392318,75.902359,8.2726564,404.79962,-9.2612906
2859,2859,178.8458,6.7392917,1.7787858,0.0,0,8.1926918,0.0,0.12646618,75.587791,8.2436638,404.90558,-9.262023
2870,2870,178.848,6.7479978,1.8108778,0.0,0,8.162076,0.0,0.12838709,75.541946,8.2142181,405.01154,-9.2623529
2881,2881,178.8502,6.7736683,1.8401036,0.0,0,8.1314611,0.0,0.13110654,75.598618,8.1835642,405.11749,-9.2626457
2892,2892,178.8524,6.8052254,1.8714952,0.0,0,8.1008453,0.0,0.13289443,75.916977,8.1556053,405.16385,-9.2624388
2903,2903,178.8546,6.8293667,1.8960644,0.0,0,8.0702305,0.0,0.13538688,75.990227,8.1219959,405.21021,-9.2614145
2914,2914,178.8568,6.8485589,1.9284625,0.0,0,8.0403337,0.0,0.13734037,76.022903,8.091836,405.25656,-9.2606936
2925,2925,178.859,6.8486452,1.9583266,0.0,0,8.0112057,0.0,0.14015295,75.810287,8.0612888,405.30292,-9.2612848
2936,2936,178.8612,6.8489418,1.9911053,0.0,0,7.9820776,0.0,0.14197043,75.649185,8.0314598,405.22284,-9.2612839
2947,2947,178.8634,6.8574758,2.0141923,0.0,0,7.95295,0.0,0.14439613,75.627838,8.0051575,404.99106,-9.2622871
2958,2958,178.8656,6.8698764,2.0472867,0.0,0,7.9238219,0.0,0.14647751,75.549149,7.9745345,404.75928,-9.2616072
2969,2969,178.8678,6.9127183,2.0732694,0.0,0,7.8946939,0.0,0.14898238,75.79512,7.9425082,404.5275,-9.2616959
2980,2980,178.87,6.9406505,2.1077824,0.0,0,7.8655658,0.0,0.15101942,75.924919,7.9123578,404.29572,-9.2627449
2991,2991,178.8722,6.9556475,2.1304321,0.0,0,7.8364377,0.0,0.15348358,76.033981,7.8830228,403.85928,-9.2624493
3002,3002,178.8744,6.9718523,2.16153,0.0,0,7.8073092,0.0,0.15535522,75.958199,7.8535337,403.40234,-9.2625599
3013,3013,178.8766,6.9755316,2.1884499,0.0,0,7.7781816,0.0,0.15807007,75.815987,7.8258462,402.94543,-9.2621155
3024,3024,178.8788,6.9788938,2.2244744,0.0,0,7.7490535,0.0,0.16006404,75.653633,7.7931671,402.48853,-9.2616463
3035,3035,178.881,6.9945979,2.2456577,0.0,0,7.7199254,0.0,0.16241924,75.694679,7.7666035,401.86987,-9.2623501
3046,3046,178.8832,7.0130544,2.2765164,0.0,0,7.6907973,0.0,0.16428964,75.700287,7.7347093,400.96826,-9.2617073
3057,3057,178.8854,7.0377526,2.3034091,0.0,0,7.6616693,0.0,0.16709295,75.819626,7.70818,400.06665,-9.262228
3068,3068,178.8876,7.0681186,2.3400743,0.0,0,7.6325412,0.0,0.16920239,75.953743,7.6771235,399.16504,-9.262187
3079,3079,178.8898,7.1033149,2.3629203,0.0,0,7.6034136,0.0,0.17165101,76.2173,7.6470246,398.26343,-9.2617235
3090,3090,178.892,7.1289811,2.3945067,0.0,0,7.574285,0.0,0.17362863,76.185188,7.6179581,397.65958,-9.2617149
3101,3101,178.8942,7.1124558,2.4202869,0.0,0,7.5451574,0.0,0.17628051,75.92263,7.5863619,397.06992,-9.2624369
3112,3112,178.8964,7.1109657,2.4553583,0.0,0,7.5160294,0.0,0.17832349,75.808876,7.5619297,396.48026,-9.2619133
3123,3123,178.8986,7.131403,2.4765246,0.0,0,7.4869013,0.0,0.18066096,75.716194,7.5334611,395.89063,-9.2627535
3134,3134,178.9008,7.1750779,2.5073624,0.0,0,7.4577727,0.0,0.1827414,76.100037,7.4999127,395.47702,-9.2628384
3145,3145,178.903,7.2134604,2.5376413,0.0,0,7.4286451,0.0,0.18563971,76.293243,7.4742684,395.31775,-9.2623463
3156,3156,178.9052,7.2428946,2.5756462,0.0,0,7.3995175,0.0,0.18800737,76.411926,7.4396596,395.15851,-9.2612743
3167,3167,178.9074,7.260582,2.5984972,0.0,0,7.3714666,0.0,0.19039255,76.413345,7.4032412,394.99924,-9.2612934
3178,3178,178.9096,7.2681866,2.6307423,0.0,0,7.3437643,0.0,0.19260173,76.299454,7.3774667,394.84,-9.26227
3189,3189,178.9118,7.2502189,2.6547186,0.0,0,7.316062,0.0,0.19504316,76.013306,7.3504562,394.90424,-9.2620096
3200,3200,178.914,7.2350225,2.6908545,0.0,0,7.2883596,0.0,0.19741358,75.630699,7.3235059,395.00378,-9.2623005
3211,3211,178.9162,7.2382345,2.7118351,0.0,0,7.2606573,0.0,0.1995945,75.525497,7.2940745,395.1033,-9.2627468
3222,3222,178.9184,7.2556558,2.7412741,0.0,0,7.232955,0.0,0.20154549,75.467102,7.2663865,395.20285,-9.2623978
3233,3233,178.9206,7.2833748,2.7628038,0.0,0,7.2052522,0.0,0.20371939,75.668747,7.2418981,395.51117,-9.2622986
3244,3244,178.9228,7.3232498,2.7981491,0.0,0,7.1775503,0.0,0.20615397,75.815727,7.2127624,396.26688,-9.2608471
3255,3255,178.925,7.3592501,2.8209419,0.0,0,7.1498475,0.0,0.20851526,76.050697,7.181488,397.02258,-9.2612047
3266,3266,178.9272,7.3678164,2.8535302,0.0,0,7.1221447,0.0,0.21079007,76.006683,7.1535506,397.77829,-9.260169
3277,3277,178.9294,7.37604,2.8752434,0.0,0,7.0944424,0.0,0.21287787,75.951241,7.1244035,398.534,-9.2608643
3288,3288,178.9316,7.3622079,2.9092867,0.0,0,7.0667405,0.0,0.21534355,75.57225,7.0993471,399.03329,-9.2609568
3299,3299,178.9338,7.3570957,2.9284966,0.0,0,7.0390377,0.0,0.2173364,75.399597,7.0689497,399.45721,-9.2609158
3310,3310,178.936,7.3400903,2.9579077,0.0,0,7.0113349,0.0,0.21951365,75.080261,7.0457826,399.8811,-9.2616749
3321,3321,178.9382,7.3659978,2.978034,0.0,0,6.983633,0.0,0.22140175,75.147957,7.023725,400.30502,-9.261631
3332,3332,178.9404,7.4060616,3.0101175,0.0,0,6.9559307,0.0,0.22376285,75.350693,6.9943051,400.65515,-9.2617292
3343,3343,178.9426,7.470005,3.0313108,0.0,0,6.9282284,0.0,0.22582591,75.81517,6.9671845,400.75446,-9.2623997
3354,3354,178.9448,7.4968166,3.0614762,0.0,0,6.9005256,0.0,0.22820279,75.950165,6.9362226,400.85379,-9.2617397
3365,3365,178.947,7.5442739,3.0873013,0.0,0,6.8728237,0.0,0.23042123,76.340126,6.9082932,400.95313,-9.261816
3376,3376,178.9492,7.554543,3.125258,0.0,0,6.8451209,0.0,0.23358677,76.175034,6.8808784,401.05243,-9.2613897
3387,3387,178.9514,7.546196,3.1479244,0.0,0,6.8174186,0.0,0.23555416,75.995438,6.8496652,401.215,-9.2614737
3398,3398,178.9536,7.557323,3.1781595,0.0,0,6.7897158,0.0,0.238134,75.840042,6.8193493,401.40701,-9.2622957
3409,3409,178.9558,7.5632811,3.2014232,0.0,0,6.762064,0.0,0.24005833,75.738571,6.7931371,401.59906,-9.2615137
3420,3420,178.958,7.5874882,3.2353756,0.0,0,6.7356958,0.0,0.24292152,75.745468,6.7682362,401.79111,-9.2611952
3431,3431,178.9602,7.5809588,3.256958,0.0,0,6.7093401,0.0,0.24471468,75.527519,6.7365894,401.99127,-9.2610598
3442,3442,178.9624,7.6093698,3.2845817,0.0,0,6.6829839,0.0,0.24722011,75.607018,6.7132988,402.24292,-9.2612286
3453,3453,178.9646,7.6369648,3.3105173,0.0,0,6.6566281,0.0,0.24931781,75.767807,6.6854057,402.49457,-9.2611418
3464,3464,178.9668,7.6640177,3.3427508,0.0,0,6.6302719,0.0,0.25219667,75.800011,6.6584196,402.74619,-9.2613173
3475,3475,178.969,7.6738691,3.3651259,0.0,0,6.6039157,0.0,0.25390887,75.773529,6.6316919,402.99783,-9.2617474
3486,3486,178.9712,7.6781816,3.3916769,0.0,0,6.5775599,0.0,0.25642669,75.618324,6.6046,403.2338,-9.2623901
3497,3497,178.9734,7.6710849,3.4173868,0.0,0,6.5512042,0.0,0.25840592,75.495232,6.5763893,403.45895,-9.2625294
3508,3508,178.9756,7.7002273,3.4506235,0.0,0,6.524848,0.0,0.26147664,75.415665,6.5479503,403.68408,-9.2623749
3519,3519,178.9778,7.7152991,3.4739635,0.0,0,6.4984918,0.0,0.26315951,75.469643,6.5223732,403.90924,-9.261858
3530,3530,178.98,7.7139382,3.4961841,0.0,0,6.472136,0.0,0.26551288,75.399857,6.4969816,404.12296,-9.2622318
3541,3541,178.9822,7.7479572,3.5207675,0.0,0,6.4457798,0.0,0.26733619,75.515312,6.4723916,404.09647,-9.2624454
3552,3552,178.9844,7.7460222,3.5497653,0.0,0,6.4194241,0.0,0.27019012,75.322777,6.451086,404.06998,-9.2625523
3563,3563,178.9866,7.8013072,3.5749531,0.0,0,6.3930678,0.0,0.2719498,75.698715,6.420547,404.04352,-9.262063
3574,3574,178.9888,7.8320384,3.6005754,0.0,0,6.3667121,0.0,0.27466324,75.808205,6.3948946,404.01703,-9.2621202
3585,3585,178.991,7.8548217,3.6285567,0.0,0,6.3403563,0.0,0.27664366,75.769958,6.3648634,403.98392,-9.2616491
3596,3596,178.9932,7.8538628,3.6596584,0.0,0,6.3140001,0.0,0.27989009,75.534431,6.336884,403.94418,-9.2624588
3607,3607,178.9954,7.8740253,3.6856546,0.0,0,6.2876444,0.0,0.2816433,75.582405,6.3062973,403.90445,-9.2620363
3618,3618,178.9976,7.8808808,3.7071741,0.0,0,6.2612886,0.0,0.28411713,75.577507,6.2833052,403.86472,-9.2602444
3629,3629,178.9998,7.9082389,3.7334526,0.0,0,6.2349324,0.0,0.28602666,75.658272,6.257165,403.82498,-9.2601719
3640,3640,179.002,7.9085193,3.7611141,0.0,0,6.2085767,0.0,0.289031,75.423019,6.2312379,404.00018,-9.2604694
3651,3651,179.0042,7.9229841,3.788434,0.0,0,6.1822205,0.0,0.2906656,75.482971,6.2054005,404.18558,-9.2622585
3662,3662,179.0064,7.9439034,3.8099689,0.0,0,6.1562529,0.0,0.29331136,75.544449,6.1799426,404.371,-9.2612638
3673,3673,179.0086,7.9439864,3.8385534,0.0,0,6.1311855,0.0,0.29524159,75.340179,6.1572118,404.55643,-9.2618628
3684,3684,179.0108,7.9630704,3.8649466,0.0,0,6.1061187,0.0,0.29829806,75.249741,6.1271167,404.75269,-9.2616434
3695,3695,179.013,8.0057325,3.8954737,0.0,0,6.0810523,0.0,0.30021399,75.531357,6.0995178,404.96457,-9.2609138
3706,3706,179.0152,8.0258627,3.915333,0.0,0,6.0559855,0.0,0.3028121,75.468987,6.0775828,405.17648,-9.2603092
3717,3717,179.0174,8.0284224,3.9431279,0.0,0,6.0309186,0.0,0.30456871,75.354408,6.0496192,405.38837,-9.262187
3728,3728,179.0196,8.0288124,3.9659765,0.0,0,6.0058517,0.0,0.30743471,75.240356,6.0256686,405.60028,-9.2624826
3739,3739,179.0218,8.0492926,3.9958053,0.0,0,5.9807849,0.0,0.30931643,75.222282,6.0011163,405.73785,-9.26159
3750,3750,179.024,8.0727959,4.0133557,0.0,0,5.9557185,0.0,0.31173357,75.294792,5.9751778,405.86365,-9.2609854
3761,3761,179.0262,8.0673847,4.041142,0.0,0,5.9306512,0.0,0.31358045,75.009514,5.9484544,405.98947,-9.2616062
3772,3772,179.0284,8.0721884,4.0646811,0.0,0,5.9055848,0.0,0.31650737,74.915581,5.9216628,406.1153,-9.2627144
3783,3783,179.0306,8.0985756,4.0958066,0.0,0,5.880518,0.0,0.31836781,74.988731,5.8998461,406.26007,-9.2608347
3794,3794,179.0328,8.1545715,4.1135135,0.0,0,5.8554511,0.0,0.32093,75.334267,5.8732939,406.4455,-9.2625103
3805,3805,179.035,8.1911011,4.1441345,0.0,0,5.8303843,0.0,0.32292458,75.576424,5.8461976,406.63092,-9.2617245
3816,3816,179.0372,8.2157269,4.1687102,0.0,0,5.8053174,0.0,0.32602182,75.486389,5.8176575,406.81631,-9.2605629
3827,3827,179.0394,8.2149792,4.2010803,0.0,0,5.7802501,0.0,0.32799819,75.36824,5.7909336,407.00174,-9.2596283
3838,3838,179.0416,8.2172527,4.2151995,0.0,0,5.7551837,0.0,0.33034962,75.206268,5.7709384,407.31509,-9.2609167
3849,3849,179.0438,8.2297697,4.2436771,0.0,0,5.7301168,0.0,0.3321363,75.143288,5.7471666,407.66608,-9.2613144
3860,3860,179.046,8.2226048,4.2647848,0.0,0,5.7050505,0.0,0.33493868,74.882622,5.7188048,408.01703,-9.2609358
3871,3871,179.0482,8.2116442,4.2992291,0.0,0,5.6799831,0.0,0.33705634,74.677834,5.6958237,408.36801,-9.2610931
3882,3882,179.0504,8.24547,4.3132706,0.0,0,5.6549168,0.0,0.33945668,74.770859,5.6745563,408.69339,-9.2610607
3893,3893,179.0526,8.266386,4.338119,0.0,0,5.6298494,0.0,0.34098116,74.859726,5.6481428,408.93179,-9.2616272
3904,3904,179.0548,8.310277,4.3603745,0.0,0,5.6047826,0.0,0.34395996,74.971535,5.6260853,409.1702,-9.26231
3915,3915,179.057,8.3606606,4.3944349,0.0,0,5.5804157,0.0,0.34609124,75.260773,5.5994549,409.4086,-9.2618723
3926,3926,179.0592,8.3947964,4.4123735,0.0,0,5.5565677,0.0,0.34867698,75.439384,5.5744004,409.64697,-9.2610054
3937,3937,179.0614,8.4110937,4.4396296,0.0,0,5.5327196,0.0,0.35053363,75.429634,5.5471296,409.6506,-9.2611198
3948,3948,179.0636,8.4133091,4.4623246,0.0,0,5.5088716,0.0,0.3534745,75.199371,5.5211902,409.54465,-9.2616787
3959,3959,179.0658,8.3948698,4.4970217,0.0,0,5.4850235,0.0,0.35583842,74.908943,5.4962177,409.43869,-9.2625761
3970,3970,179.068,8.3948288,4.5115948,0.0,0,5.4611754,0.0,0.35813475,74.739525,5.473156,409.33273,-9.2629471
3981,3981,179.0702,8.4213352,4.5381083,0.0,0,5.4373279,0.0,0.36009717,74.710121,5.4471812,409.15903,-9.2610874
3992,3992,179.0724,8.4462824,4.5598998,0.0,0,5.4134793,0.0,0.36268029,74.685234,5.4226232,408.55643,-9.2610245
4003,4003,179.0746,8.4514828,4.5913553,0.0,0,5.3896313,0.0,0.36501729,74.744904,5.4003587,407.95383,-9.2603931
4014,4014,179.0768,8.4695702,4.6065125,0.0,0,5.3657837,0.0,0.3671869,74.672615,5.3782535,407.3512,-9.2617207
4025,4025,179.079,8.4920368,4.6328773,0.0,0,5.3419356,0.0,0.36915842,74.779709,5.3526077,406.7486,-9.2621775
4036,4036,179.0812,8.5022316,4.6506104,0.0,0,5.3180876,0.0,0.37146056,74.688194,5.3317928,405.74292,-9.2617426
4047,4047,179.0834,8.5166044,4.6859236,0.0,0,5.2942395,0.0,0.37411654,74.607597,5.3089118,404.45819,-9.2622795
4058,4058,179.0856,8.5245495,4.7025199,0.0,0,5.2703915,0.0,0.37623215,74.473358,5.2848606,403.17346,-9.2619486
4069,4069,179.0878,8.5724916,4.7293081,0.0,0,5.2465439,0.0,0.378508,74.725914,5.2564754,401.88873,-9.2625046
4080,4080,179.09,8.6118221,4.7480874,0.0,0,5.2226958,0.0,0.38079002,74.912315,5.2339392,400.62628,-9.2622929
4091,4091,179.0922,8.622735,4.781775,0.0,0,5.1988478,0.0,0.38350224,74.808685,5.2124977,399.83163,-9.2614746
4102,4102,179.0944,8.6454659,4.7983837,0.0,0,5.1749997,0.0,0.38567933,74.832886,5.1881304,399.03699,-9.2615032
4113,4113,179.0966,8.6403809,4.8253274,0.0,0,5.1511517,0.0,0.38797221,74.636803,5.1613674,398.24234,-9.2614641
4124,4124,179.0988,8.665103,4.8445096,0.0,0,5.1273036,0.0,0.39007702,74.696907,5.1394076,397.44769,-9.2617073
4135,4135,179.101,8.6674404,4.8737488,0.0,0,5.1034555,0.0,0.39267418,74.583221,5.1180053,397.16959,-9.2615843
4146,4146,179.1032,8.6792812,4.8924346,0.0,0,5.079608,0.0,0.39490658,74.478645,5.0908008,397.40802,-9.2612019
4157,4157,179.1054,8.6887703,4.9210696,0.0,0,5.0557599,0.0,0.39736292,74.406975,5.0681181,397.64648,-9.2622433
4168,4168,179.1076,8.7563829,4.9402537,0.0,0,5.0328989,0.0,0.39960566,74.722878,5.0445805,397.88492,-9.2610226
4179,4179,179.1098,8.795393,4.9699407,0.0,0,5.0102167,0.0,0.40229329,74.845406,5.0214281,398.12338,-9.260994
4190,4190,179.112,8.8127041,4.9858308,0.0,0,4.987535,0.0,0.40404847,74.861122,4.9953103,397.93152,-9.2613077
4201,4201,179.1142,8.8268871,5.0137796,0.0,0,4.9648528,0.0,0.40686095,74.808083,4.9749475,397.71918,-9.2623539
4212,4212,179.1164,8.8016176,5.034493,0.0,0,4.9421706,0.0,0.4088915,74.489021,4.9518847,397.50684,-9.2624226
4223,4223,179.1186,8.8151064,5.0627975,0.0,0,4.9194889,0.0,0.41169602,74.374985,4.9282832,397.29449,-9.2620516
4234,4234,179.1208,8.8296995,5.0813904,0.0,0,4.8968072,0.0,0.41361022,74.387642,4.9035282,396.97101,-9.2624388
4245,4245,179.123,8.8509493,5.1056719,0.0,0,4.8741245,0.0,0.41619194,74.301949,4.8831353,396.48703,-9.2625952
4256,4256,179.1252,8.8614168,5.1265607,0.0,0,4.8514428,0.0,0.41805786,74.249939,4.8598585,396.00302,-9.2627401
4267,4267,179.1274,8.8946447,5.1557727,0.0,0,4.8287606,0.0,0.42121598,74.334267,4.8338957,395.51904,-9.262022
4278,4278,179.1296,8.9153891,5.1733899,0.0,0,4.8060789,0.0,0.42280945,74.394539,4.8121057,395.03506,-9.2617493
4289,4289,179.1318,8.9217396,5.1951861,0.0,0,4.7833967,0.0,0.42524198,74.254112,4.7891355,395.04929,-9.2618351
4300,4300,179.134,8.954957,5.2164531,0.0,0,4.7607145,0.0,0.4271498,74.32975,4.7713766,395.14221,-9.2611732
4311,4311,179.1362,8.9761114,5.2435317,0.0,0,4.7380328,0.0,0.43025836,74.335732,4.7468719,395.23511,-9.2618923
4322,4322,179.1384,8.9960709,5.2665524,0.0,0,4.7153511,0.0,0.43222323,74.310287,4.7191973,395.328,-9.2614565
4333,4333,179.1406,9.0111055,5.2877884,0.0,0,4.6926689,0.0,0.43474001,74.286659,4.6977038,395.5032,-9.2616568
4344,4344,179.1428,9.0191393,5.3074541,0.0,0,4.6699867,0.0,0.43644506,74.236923,4.6757722,395.85477,-9.2621918
4355,4355,179.145,9.0316248,5.334753,0.0,0,4.647305,0.0,0.43980962,74.106575,4.6558952,396.2063,-9.2613668
4366,4366,179.1472,9.0503368,5.3587747,0.0,0,4.6246228,0.0,0.4416087,74.109573,4.6298761,396.55786,-9.261384
4377,4377,179.1494,9.0820761,5.3757048,0.0,0,4.6019411,0.0,0.44397691,74.206039,4.6097841,396.90939,-9.2611742
4388,4388,179.1516,9.0901413,5.3958282,0.0,0,4.5792584,0.0,0.44548512,74.232063,4.5899467,397.25555,-9.2619982
4399,4399,179.1538,9.1103935,5.4206491,0.0,0,4.5565767,0.0,0.44876096,74.069908,4.5674162,397.60016,-9.262228
4410,4410,179.156,9.1360807,5.4443212,0.0,0,4.5340271,0.0,0.45042527,74.115417,4.5424471,397.94476,-9.2625675
4421,4421,179.1582,9.1603031,5.4630594,0.0,0,4.5124488,0.0,0.4531734,74.146957,4.5201788,398.28937,-9.2623806
4432,4432,179.1604,9.1916151,5.4861774,0.0,0,4.4908714,0.0,0.45492867,74.284904,4.5002561,398.62637,-9.2615356
4443,4443,179.1626,9.2292604,5.5089746,0.0,0,4.4692936,0.0,0.4581334,74.302246,4.4742303,398.93759,-9.2615652
4454,4454,179.1648,9.2530289,5.5352302,0.0,0,4.4477158,0.0,0.45998031,74.358711,4.4512587,399.24884,-9.2617588
4465,4465,179.167,9.294075,5.5529404,0.0,0,4.4261384,0.0,0.46272182,74.409424,4.4320865,399.56006,-9.2619658
4476,4476,179.1692,9.3093786,5.5758238,0.0,0,4.404561,0.0,0.46435678,74.47583,4.4087501,399.87131,-9.2614641
4487,4487,179.1714,9.322011,5.599473,0.0,0,4.3829832,0.0,0.46777534,74.375549,4.3860993,400.10129,-9.2621841
4498,4498,179.1736,9.3214264,5.6281242,0.0,0,4.3614058,0.0,0.46974564,74.194427,4.3622437,400.2933,-9.2615843
4509,4509,179.1758,9.3257408,5.6433411,0.0,0,4.339828,0.0,0.4723995,74.069595,4.3420649,400.48535,-9.261097
4520,4520,179.178,9.3203812,5.6658092,0.0,0,4.3182507,0.0,0.4738321,73.871117,4.3194051,400.6774,-9.2622929
4531,4531,179.1802,9.339118,5.6851015,0.0,0,4.2966728,0.0,0.4768652,73.814186,4.2992353,400.86673,-9.262537
4542,4542,179.1824,9.3711338,5.7111435,0.0,0,4.275095,0.0,0.47862929,73.882881,4.2782226,401.03891,-9.2624187
4553,4553,179.1846,9.4079952,5.7278056,0.0,0,4.2535176,0.0,0.48154822,74.015678,4.2552276,401.21109,-9.2609415
4564,4564,179.1868,9.4323616,5.7525969,0.0,0,4.2319398,0.0,0.48316637,74.084648,4.2360063,401.38324,-9.2617617
4575,4575,179.189,9.4341164,5.7692537,0.0,0,4.2103624,0.0,0.48606893,73.916557,4.2160287,401.55542,-9.2617846
4586,4586,179.1912,9.4456739,5.7962155,0.0,0,4.1887846,0.0,0.48770827,73.842339,4.1981091,401.83325,-9.2622795
4597,4597,179.1934,9.490139,5.8100066,0.0,0,4.1672072,0.0,0.49034894,74.036301,4.1766963,402.1842,-9.2616835
4608,4608,179.1956,9.542614,5.8369527,0.0,0,4.1456294,0.0,0.4923709,74.249344,4.155323,402.53519,-9.262454
4619,4619,179.1978,9.5888424,5.8561535,0.0,0,4.124052,0.0,0.4956041,74.337334,4.1320782,402.88614,-9.2625046
4630,4630,179.2,9.6227617,5.8846841,0.0,0,4.1024742,0.0,0.49734694,74.502045,4.1090393,403.21814,-9.2617064
4641,4641,179.2022,9.6507406,5.8998742,0.0,0,4.0808969,0.0,0.50032091,74.57489,4.0852938,403.15195,-9.2615604
4652,4652,179.2044,9.674571,5.9285698,0.0,0,4.059319,0.0,0.50241047,74.503502,4.0639229,403.08572,-9.2618675
4663,4663,179.2066,9.6780319,5.9454269,0.0,0,4.0381556,0.0,0.50528789,74.324936,4.0402279,403.0195,-9.2593374
4674,4674,179.2088,9.6555614,5.97368,0.0,0,4.0176339,0.0,0.50719404,74.106491,4.0160756,402.95328,-9.2608213
4685,4685,179.211,9.649044,5.9860301,0.0,0,3.9971123,0.0,0.50972873,73.749321,3.9995227,402.85065,-9.2603073
4696,4696,179.2132,9.6840487,6.0109754,0.0,0,3.9765906,0.0,0.51159638,73.946793,3.9769897,402.71158,-9.2609911
4707,4707,179.2154,9.7414913,6.0255995,0.0,0,3.956069,0.0,0.5142324,74.157188,3.9567969,402.57251,-9.2625027
4718,4718,179.2176,9.7716227,6.0556526,0.0,0,3.9355476,0.0,0.51629704,74.197189,3.9373477,402.43347,-9.2618589
4729,4729,179.2198,9.7617712,6.0682545,0.0,0,3.9150259,0.0,0.51891029,73.973808,3.913029,402.2944,-9.2617683
4740,4740,179.222,9.7520361,6.0918922,0.0,0,3.8945043,0.0,0.52073473,73.776093,3.8976667,402.38922,-9.2614374
4751,4751,179.2242,9.780592,6.1075034,0.0,0,3.8739827,0.0,0.52342498,73.754997,3.8788433,402.49515,-9.260663
4762,4762,179.2264,9.8019981,6.1357713,0.0,0,3.853461,0.0,0.52537,73.821671,3.8576303,402.6011,-9.2615032
4773,4773,179.2286,9.8447418,6.1459479,0.0,0,3.8329396,0.0,0.52763093,73.988976,3.8400381,402.70706,-9.2612238
4784,4784,179.2308,9.8793631,6.1712251,0.0,0,3.812418,0.0,0.52961445,74.048561,3.8175008,402.6044,-9.2607965
4795,4795,179.233,9.9324598,6.1891036,0.0,0,3.7918961,0.0,0.53265774,74.183006,3.7990413,402.20047,-9.2617874
4806,4806,179.2352,9.9826689,6.219974,0.0,0,3.7713747,0.0,0.53500211,74.407898,3.7751422,401.79651,-9.2619114
4817,4817,179.2374,10.031612,6.2304869,0.0,0,3.7508531,0.0,0.53723556,74.623131,3.7536454,401.39258,-9.2610664
4828,4828,179.2396,10.049581,6.256844,0.0,0,3.7303314,0.0,0.53945303,74.588783,3.7328453,400.98862,-9.2604589
4839,4839,179.2418,10.073235,6.2738519,0.0,0,3.7098098,0.0,0.54213983,74.571671,3.7098851,400.138,-9.260623
4850,4850,179.244,10.075112,6.3064795,0.0,0,3.6892881,0.0,0.54481024,74.448158,3.6925859,399.21689,-9.2608957
4861,4861,179.2462,10.093738,6.3179007,0.0,0,3.6687665,0.0,0.54699188,74.402443,3.6694903,398.29575,-9.2608833
4872,4872,179.2484,10.106704,6.3417988,0.0,0,3.6482451,0.0,0.54921377,74.378593,3.6469967,397.37463,-9.2606773
4883,4883,179.2506,10.137028,6.3586173,0.0,0,3.6277235,0.0,0.55171174,74.270599,3.6250665,396.56516,-9.2607384
4894,4894,179.2528,10.164913,6.3867221,0.0,0,3.6072018,0.0,0.55430406,74.348083,3.6045997,395.99493,-9.2610712
4905,4905,179.255,10.212828,6.4000611,0.0,0,3.5866802,0.0,0.55656326,74.513367,3.5882146,395.42471,-9.2601986
4916,4916,179.2572,10.232736,6.4257164,0.0,0,3.5668228,0.0,0.55898994,74.473824,3.5667338,394.85449,-9.2605906
4927,4927,179.2594,10.245841,6.4407444,0.0,0,3.5472999,0.0,0.56127757,74.431488,3.5472019,394.28427,-9.2610016
4938,4938,179.2616,10.272915,6.4698648,0.0,0,3.527777,0.0,0.56404179,74.402351,3.5259995,394.19568,-9.2623873
4949,4949,179.2638,10.287908,6.4803424,0.0,0,3.5082545,0.0,0.56586635,74.395874,3.5048616,394.24878,-9.2617369
4960,4960,179.266,10.293745,6.5050163,0.0,0,3.4887314,0.0,0.56836015,74.248116,3.4837978,394.30188,-9.2602501
4971,4971,179.2682,10.28257,6.5198021,0.0,0,3.4692085,0.0,0.57041556,74.044174,3.4652057,394.35498,-9.2609835
4982,4982,179.2704,10.303195,6.5454779,0.0,0,3.4496861,0.0,0.5730297,73.960365,3.4486139,394.50452,-9.2626047
4993,4993,179.2726,10.330868,6.5601568,0.0,0,3.4301629,0.0,0.57519007,74.014145,3.4286785,394.98203,-9.2609978
5004,5004,179.2748,10.383376,6.5805264,0.0,0,3.4106405,0.0,0.57740211,74.211464,3.4070299,395.45953,-9.2598209
5015,5015,179.277,10.39649,6.5948691,0.0,0,3.3911176,0.0,0.57918507,74.149979,3.3923945,395.93704,-9.2601166
5026,5026,179.2792,10.440364,6.620729,0.0,0,3.3715944,0.0,0.58213753,74.289505,3.3722324,396.41452,-9.2601118
5037,5037,179.2814,10.476554,6.6340752,0.0,0,3.352072,0.0,0.58382863,74.390503,3.3532681,396.73389,-9.2601519
5048,5048,179.2836,10.524809,6.6556778,0.0,0,3.3325491,0.0,0.58647895,74.580742,3.3306248,396.97943,-9.2606268
5059,5059,179.2858,10.548816,6.673717,0.0,0,3.313026,0.0,0.58854407,74.568024,3.3140199,397.22495,-9.2615328
5070,5070,179.288,10.57018,6.6989398,0.0,0,3.2935035,0.0,0.59172934,74.502373,3.2933004,397.47049,-9.2609463
5081,5081,179.2902,10.612082,6.7147608,0.0,0,3.2739804,0.0,0.59343678,74.638283,3.2717061,397.66089,-9.2599802
5092,5092,179.2924,10.67064,6.7358084,0.0,0,3.254458,0.0,0.59619021,74.82093,3.250958,397.50189,-9.2611513
5103,5103,179.2946,10.694901,6.751781,0.0,0,3.234935,0.0,0.59787166,74.866661,3.2332814,397.3429,-9.262392
5114,5114,179.2968,10.725232,6.7770987,0.0,0,3.2154119,0.0,0.60131913,74.872162,3.2133245,397.18393,-9.2616138
5125,5125,179.299,10.757668,6.7961702,0.0,0,3.1958895,0.0,0.60315752,74.900398,3.1943235,397.02493,-9.259449
5136,5136,179.3012,10.797872,6.8148146,0.0,0,3.1763666,0.0,0.60588807,75.027237,3.1755757,396.71286,-9.2601061
5147,5147,179.3034,10.821296,6.833643,0.0,0,3.1568439,0.0,0.60781121,75.09407,3.1560585,396.2948,-9.2608376
5158,5158,179.3056,10.832993,6.8589802,0.0,0,3.137321,0.0,0.61132795,74.827393,3.1340187,395.87671,-9.2616711
5169,5169,179.3078,10.871672,6.8752065,0.0,0,3.1186893,0.0,0.61275929,74.969963,3.1142318,395.45865,-9.2609577
5180,5180,179.31,10.888596,6.8937869,0.0,0,3.1001165,0.0,0.61576152,74.852066,3.0967612,395.04269,-9.2600441
5191,5191,179.3122,10.898136,6.9136138,0.0,0,3.0815444,0.0,0.61744946,74.842262,3.0789888,394.67108,-9.26089
5202,5202,179.3144,10.912449,6.9334612,0.0,0,3.0629718,0.0,0.62064928,74.688858,3.0596075,394.29947,-9.2621031
5213,5213,179.3166,10.942578,6.95154,0.0,0,3.0443995,0.0,0.62203288,74.798698,3.0409784,393.92786,-9.2609386
5224,5224,179.3188,10.971556,6.9668574,0.0,0,3.0258269,0.0,0.62488729,74.726913,3.0221565,393.55624,-9.2606859
5235,5235,179.321,10.989462,6.9857125,0.0,0,3.0072546,0.0,0.62630367,74.875732,3.0061252,393.22443,-9.2610703
5246,5246,179.3232,11.027869,7.006144,0.0,0,2.9886825,0.0,0.62987196,74.822311,2.9884312,392.93243,-9.261508
5257,5257,179.3254,11.073677,7.0267382,0.0,0,2.9701097,0.0,0.63129544,74.979485,2.9677174,392.64047,-9.260994
5268,5268,179.3276,11.123276,7.0405984,0.0,0,2.9515376,0.0,0.63422364,75.105293,2.9486737,392.34848,-9.2616167
5279,5279,179.3298,11.186092,7.0616136,0.0,0,2.932965,0.0,0.63587326,75.404884,2.9306242,392.05649,-9.2610607
5290,5290,179.332,11.225527,7.0824132,0.0,0,2.9143927,0.0,0.63952929,75.428383,2.9091809,391.53012,-9.2601233
5301,5301,179.3342,11.243909,7.1057701,0.0,0,2.8958201,0.0,0.64127868,75.37928,2.885391,390.99261,-9.2600298
5312,5312,179.3364,11.257265,7.1183634,0.0,0,2.8772478,0.0,0.64395112,75.266945,2.86939,390.45511,-9.2607279
5323,5323,179.3386,11.268432,7.1389289,0.0,0,2.8586755,0.0,0.64545989,75.272072,2.8558297,389.9176,-9.2612648
5334,5334,179.3408,11.285877,7.1550579,0.0,0,2.8401029,0.0,0.64881366,75.076164,2.8345551,389.44254,-9.2609758
5345,5345,179.343,11.30062,7.1771679,0.0,0,2.8215306,0.0,0.6503343,75.089798,2.8163216,389.05765,-9.2608089
5356,5356,179.3452,11.325753,7.1901951,0.0,0,2.8029583,0.0,0.6532194,75.041313,2.7989283,388.67276,-9.2616901
5367,5367,179.3474,11.357627,7.2101264,0.0,0,2.7843859,0.0,0.65458965,75.107727,2.7816679,388.28787,-9.2614183
5378,5378,179.3496,11.411554,7.2248759,0.0,0,2.7658136,0.0,0.65779024,75.200401,2.7619755,387.90298,-9.2610521
5389,5389,179.3518,11.461822,7.2477603,0.0,0,2.747241,0.0,0.65931821,75.418396,2.7458823,387.54102,-9.2615194
5400,5400,179.354,11.494107,7.2609878,0.0,0,2.7286685,0.0,0.66244316,75.493111,2.7284384,387.18268,-9.2601833
5411,5411,179.3562,11.535577,7.2825689,0.0,0,2.7102869,0.0,0.66396195,75.651428,2.7097239,386.82434,-9.2600994
5422,5422,179.3584,11.58946,7.2974772,0.0,0,2.692621,0.0,0.66727632,75.739792,2.6915953,386.466,-9.2598562
5433,5433,179.3606,11.66291,7.3248825,0.0,0,2.6749551,0.0,0.66920495,76.018188,2.6677549,386.12454,-9.2611217
5444,5444,179.3628,11.688825,7.3356009,0.0,0,2.657289,0.0,0.67206788,75.984245,2.6516213,385.81931,-9.2614403
5455,5455,179.365,11.712446,7.3609877,0.0,0,2.6396229,0.0,0.67407936,75.990166,2.6356781,385.51404,-9.2606506
5466,5466,179.3672,11.760901,7.3742857,0.0,0,2.6219571,0.0,0.67724681,76.062523,2.6139257,385.20877,-9.2600479
5477,5477,179.3694,11.801216,7.3999672,0.0,0,2.604291,0.0,0.67898107,76.156235,2.5957568,384.9035,-9.2599545
5488,5488,179.3716,11.832232,7.4103842,0.0,0,2.5866251,0.0,0.68192297,76.173744,2.5779319,385.03412,-9.2613297
5499,5499,179.3738,11.851089,7.4337816,0.0,0,2.568959,0.0,0.68364847,76.209,2.5603182,385.29291,-9.260747
5510,5510,179.376,11.847971,7.4480534,0.0,0,2.5512929,0.0,0.68705261,75.913345,2.5430117,385.55173,-9.2601433
5521,5521,179.3782,11.831541,7.473321,0.0,0,2.533627,0.0,0.68864352,75.658386,2.525214,385.81052,-9.2608995
5532,5532,179.3804,11.83711,7.4799271,0.0,0,2.5159609,0.0,0.69112086,75.496582,2.5085542,386.05875,-9.2610083
5543,5543,179.3826,11.897439,7.5035009,0.0,0,2.4982951,0.0,0.69310564,75.744606,2.4927397,386.27112,-9.2618256
5554,5554,179.3848,11.938521,7.5157218,0.0,0,2.480629,0.0,0.69590926,75.71788,2.4743607,386.48349,-9.2610741
5565,5565,179.387,11.992495,7.5422091,0.0,0,2.4629631,0.0,0.69792688,75.939018,2.4569654,386.69583,-9.2615252
5576,5576,179.3892,12.009663,7.5472355,0.0,0,2.445297,0.0,0.70013303,75.921066,2.4386489,386.9082,-9.2620792
5587,5587,179.3914,12.041641,7.5697827,0.0,0,2.4276309,0.0,0.70199579,76.011528,2.426055,387.1839,-9.2608242
5598,5598,179.3936,12.065094,7.5813608,0.0,0,2.409965,0.0,0.70479149,75.929321,2.4086256,387.48914,-9.2614889
5609,5609,179.3958,12.123751,7.6083345,0.0,0,2.3922989,0.0,0.70684612,76.146637,2.3913624,387.7944,-9.2612343
5620,5620,179.398,12.157645,7.6160998,0.0,0,2.3746328,0.0,0.70918852,76.185738,2.373884,388.09964,-9.2619572
5631,5631,179.4002,12.240728,7.6395493,0.0,0,2.356967,0.0,0.71126235,76.526024,2.3554764,388.45016,-9.2605801
5642,5642,179.4024,12.309714,7.6506333,0.0,0,2.3393009,0.0,0.71395183,76.670715,2.3337719,389.08719,-9.2600079
5653,5653,179.4046,12.400922,7.6777315,0.0,0,2.3216348,0.0,0.7164126,77.067688,2.3166349,389.72424,-9.2597237
5664,5664,179.4068,12.468085,7.6884899,0.0,0,2.3043852,0.0,0.71920359,77.288857,2.2987406,390.3613,-9.2601423
5675,5675,179.409,12.465185,7.7148585,0.0,0,2.2875817,0.0,0.72176033,77.133171,2.282624,390.99835,-9.2604885
5686,5686,179.4112,12.458158,7.7270794,0.0,0,2.2707779,0.0,0.72436875,76.881302,2.2635581,391.53738,-9.2610197
5697,5697,179.4134,12.461529,7.7546272,0.0,0,2.2539747,0.0,0.72699261,76.701874,2.2441368,392.00854,-9.2604914
5708,5708,179.4156,12.468163,7.7613478,0.0,0,2.2371707,0.0,0.72891921,76.58419,2.23084,392.47968,-9.2616119
5719,5719,179.4178,12.495659,7.7822051,0.0,0,2.2203674,0.0,0.73109955,76.592163,2.2140508,392.95084,-9.2614002
5730,5730,179.42,12.55372,7.7951536,0.0,0,2.2035637,0.0,0.73358333,76.727943,2.1969841,393.42319,-9.2611876
5741,5741,179.4222,12.617393,7.8209567,0.0,0,2.1867602,0.0,0.73630494,76.921295,2.1775053,393.9209,-9.2597256
5752,5752,179.4244,12.640841,7.8303905,0.0,0,2.1699564,0.0,0.73846459,76.947289,2.1593406,394.41858,-9.2602968
5763,5763,179.4266,12.690279,7.8494983,0.0,0,2.1531529,0.0,0.74058926,77.053238,2.1476095,394.91629,-9.2600574
5774,5774,179.4288,12.693313,7.8591104,0.0,0,2.1363492,0.0,0.74240607,76.924118,2.1270626,395.414,-9.2615261
5785,5785,179.431,12.715607,7.8853579,0.0,0,2.1195457,0.0,0.74555266,76.794922,2.1105342,395.74579,-9.2606544
5796,5796,179.4332,12.719495,7.8956575,0.0,0,2.102742,0.0,0.74759078,76.703522,2.0982382,395.91168,-9.2604952
5807,5807,179.4354,12.78576,7.9163795,0.0,0,2.0859385,0.0,0.75006092,76.922371,2.0827646,396.07758,-9.2605295
5818,5818,179.4376,12.840834,7.9263554,0.0,0,2.069135,0.0,0.75176364,77.060959,2.064544,396.2435,-9.2616148
5829,5829,179.4398,12.894042,7.9509826,0.0,0,2.0523314,0.0,0.75492239,77.162292,2.0485935,396.40939,-9.2608271
5840,5840,179.442,12.94694,7.9610276,0.0,0,2.0355277,0.0,0.75659186,77.364861,2.0314527,396.34726,-9.2595663
5851,5851,179.4442,13.012325,7.9806647,0.0,0,2.0187242,0.0,0.7592752,77.519142,2.0193598,396.27426,-9.2600746
5862,5862,179.4464,13.088065,7.99299,0.0,0,2.0019205,0.0,0.76101565,77.836014,1.9991513,396.20126,-9.2595396
5873,5873,179.4486,13.110785,8.0157957,0.0,0,1.985117,0.0,0.7642442,77.753891,1.9863193,396.12827,-9.2609358
5884,5884,179.4508,13.156276,8.027791,0.0,0,1.9683133,0.0,0.76595551,77.886238,1.9695264,396.22067,-9.2603464
5895,5895,179.453,13.210764,8.048377,0.0,0,1.9515098,0.0,0.76908898,77.946365,1.9500506,396.55197,-9.2609596
5906,5906,179.4552,13.276462,8.0651178,0.0,0,1.9347062,0.0,0.77129054,78.11879,1.9320883,396.88324,-9.2611189
5917,5917,179.4574,13.351627,8.0877209,0.0,0,1.918521,0.0,0.77482671,78.297768,1.9122459,397.21454,-9.260458
5928,5928,179.4596,13.420025,8.1002474,0.0,0,1.9025358,0.0,0.77624053,78.634087,1.8988501,397.54584,-9.2603207
5939,5939,179.4618,13.458126,8.1174383,0.0,0,1.8865505,0.0,0.77931732,78.612015,1.8804485,397.63687,-9.2598886
5950,5950,179.464,13.480882,8.1340427,0.0,0,1.8705654,0.0,0.78115278,78.571472,1.8617511,397.68994,-9.2600307
5961,5961,179.4662,13.513644,8.1583319,0.0,0,1.8545802,0.0,0.78532016,78.463821,1.8447112,397.74304,-9.2616405
5972,5972,179.4684,13.508287,8.1719046,0.0,0,1.838595,0.0,0.78652674,78.363823,1.8278028,397.79614,-9.2603111
5983,5983,179.4706,13.497604,8.1854658,0.0,0,1.8226099,0.0,0.7892471,78.092377,1.8108927,397.55377,-9.2597008
5994,5994,179.4728,13.495711,8.2005329,0.0,0,1.8066247,0.0,0.79076892,77.972778,1.796581,396.67834,-9.260519
6005,6005,179.475,13.546718,8.2185678,0.0,0,1.7906394,0.0,0.79427135,77.940826,1.7772393,395.80289,-9.2602892
6016,6016,179.4772,13.599686,8.235466,0.0,0,1.7746543,0.0,0.79573071,78.137032,1.7686667,394.92743,-9.260313
6027,6027,179.4794,13.656214,8.2474794,0.0,0,1.758669,0.0,0.7984761,78.218147,1.7519753,394.052,-9.2597427
6038,6038,179.4816,13.708851,8.2595062,0.0,0,1.7426839,0.0,0.79933912,78.460777,1.7340006,393.78125,-9.2609863
6049,6049,179.4838,13.74748,8.2769804,0.0,0,1.7266986,0.0,0.80308992,78.399261,1.7179097,393.68835,-9.2620611
6060,6060,179.486,13.756429,8.2928591,0.0,0,1.7107134,0.0,0.80422211,78.367889,1.7052199,393.59543,-9.2601986
6071,6071,179.4882,13.77348,8.3082905,0.0,0,1.6947283,0.0,0.80773443,78.202461,1.6929153,393.50253,-9.2602444
6082,6082,179.4904,13.83595,8.3226986,0.0,0,1.678743,0.0,0.80873078,78.454033,1.6746905,393.49863,-9.258934
6093,6093,179.4926,13.898092,8.3357611,0.0,0,1.6627578,0.0,0.81202745,78.558876,1.6594238,393.79724,-9.2600965
6104,6104,179.4948,14.004269,8.3545618,0.0,0,1.6467726,0.0,0.81325024,79.031944,1.6428535,394.09586,-9.2595358
6115,6115,179.497,14.096911,8.3658123,0.0,0,1.6307874,0.0,0.81658006,79.270721,1.6266439,394.39447,-9.2594519
6126,6126,179.4992,14.203622,8.3866844,0.0,0,1.6148022,0.0,0.81831264,79.787994,1.6136287,394.69308,-9.2598066
6137,6137,179.5014,14.28428,8.4021616,0.0,0,1.5988171,0.0,0.82200402,79.899963,1.5918236,394.4216,-9.2595196
6148,6148,179.5036,14.33555,8.4235773,0.0,0,1.5828317,0.0,0.82361007,80.132576,1.5762529,393.88409,-9.2613983
6159,6159,179.5058,14.347569,8.4359045,0.0,0,1.5668756,0.0,0.82719231,79.907341,1.5584316,393.34659,-9.2610292
6170,6170,179.508,14.347269,8.4550247,0.0,0,1.5516622,0.0,0.82854843,79.809074,1.5447223,392.80905,-9.2595282
6181,6181,179.5102,14.373178,8.4691191,0.0,0,1.5364559,0.0,0.83240235,79.606079,1.5256006,392.26431,-9.2602005
6192,6192,179.5124,14.420194,8.4890747,0.0,0,1.5212495,0.0,0.83349693,79.777153,1.5124419,391.67371,-9.2604294
6203,6203,179.5146,14.487013,8.4977455,0.0,0,1.506043,0.0,0.83672875,79.86097,1.4967119,391.0831,-9.259408
6214,6214,179.5168,14.51954,8.5166349,0.0,0,1.4908366,0.0,0.83810645,79.954742,1.4827292,390.49249,-9.2594051
6225,6225,179.519,14.571408,8.5305185,0.0,0,1.4756303,0.0,0.84192783,79.94397,1.4669298,389.90189,-9.2605562
6236,6236,179.5212,14.617962,8.550868,0.0,0,1.4604239,0.0,0.84293866,80.144447,1.4484055,389.8681,-9.2622156
6247,6247,179.5234,14.646236,8.5555124,0.0,0,1.4452175,0.0,0.84572816,80.04863,1.437512,390.21982,-9.2607222
6258,6258,179.5256,14.655521,8.577529,0.0,0,1.430011,0.0,0.84735548,79.9618,1.4208504,390.57153,-9.2594185
6269,6269,179.5278,14.701619,8.5894985,0.0,0,1.4148048,0.0,0.85105067,79.892838,1.4081792,390.92325,-9.2598839
6280,6280,179.53,14.782812,8.6118135,0.0,0,1.3995984,0.0,0.85246342,80.240417,1.3927153,391.28491,-9.2609367
6291,6291,179.5322,14.839593,8.6160507,0.0,0,1.3843919,0.0,0.85517007,80.356209,1.3794086,391.85559,-9.2610636
6302,6302,179.5344,14.910429,8.6392918,0.0,0,1.3691854,0.0,0.85705864,80.548927,1.3633821,392.4263,-9.2607298
6313,6313,179.5366,14.972502,8.6478262,0.0,0,1.3539791,0.0,0.86022586,80.66256,1.3466902,392.99698,-9.2603502
6324,6324,179.5388,15.029399,8.6703529,0.0,0,1.3387728,0.0,0.86166066,80.835442,1.3315433,393.56769,-9.2598858
6335,6335,179.541,15.054188,8.6763048,0.0,0,1.3235664,0.0,0.86470228,80.77211,1.3172021,393.80658,-9.2594872
6346,6346,179.5432,15.111382,8.6981993,0.0,0,1.30836,0.0,0.86649275,80.917877,1.3024931,393.71365,-9.2598953
6357,6357,179.5454,15.141973,8.7087479,0.0,0,1.2931535,0.0,0.86986625,80.781296,1.2843009,393.62076,-9.2586575
6368,6368,179.5476,15.226449,8.7343225,0.0,0,1.2779471,0.0,0.8718949,81.086113,1.2688318,393.52786,-9.259656
6379,6379,179.5498,15.312747,8.7367382,0.0,0,1.2627407,0.0,0.87421262,81.300613,1.2546912,393.43494,-9.2578526
6390,6390,179.552,15.390991,8.75735,0.0,0,1.2475343,0.0,0.87601358,81.58934,1.2404709,392.84796,-9.2588902
6401,6401,179.5542,15.453255,8.7643528,0.0,0,1.2323278,0.0,0.87869656,81.756218,1.2260033,392.23746,-9.260808
6412,6412,179.5564,15.525558,8.7910891,0.0,0,1.2173454,0.0,0.88098741,81.888573,1.2122318,391.62695,-9.2601452
6423,6423,179.5586,15.546917,8.7981691,0.0,0,1.2028826,0.0,0.88412249,81.800377,1.1926677,391.01645,-9.2599354
6434,6434,179.5608,15.569554,8.8189764,0.0,0,1.1884197,0.0,0.88588035,81.747047,1.1758076,390.00385,-9.2600965
6445,6445,179.563,15.584599,8.8272572,0.0,0,1.173957,0.0,0.88872051,81.586266,1.161605,388.4104,-9.2598085
6456,6456,179.5652,15.631186,8.8510847,0.0,0,1.1594943,0.0,0.89086235,81.664253,1.1524863,386.81696,-9.2596512
6467,6467,179.5674,15.668199,8.8539581,0.0,0,1.1450313,0.0,0.89287138,81.725136,1.1372256,385.22351,-9.2600756
6478,6478,179.5696,15.736451,8.873373,0.0,0,1.1305685,0.0,0.89487696,81.90049,1.1186427,383.63007,-9.2593355
6489,6489,179.5718,15.802385,8.8801775,0.0,0,1.1161058,0.0,0.89730304,81.985916,1.1093118,382.51813,-9.2599001
6500,6500,179.574,15.864965,8.9040604,0.0,0,1.101643,0.0,0.89962673,82.169334,1.0951761,381.48224,-9.2597351
6511,6511,179.5762,15.938073,8.9107561,0.0,0,1.0871801,0.0,0.90189362,82.372398,1.0810699,380.44632,-9.2597075
6522,6522,179.5784,15.979591,8.9301186,0.0,0,1.0727174,0.0,0.90421426,82.38295,1.0648621,379.4104,-9.2593632
6533,6533,179.5806,16.027653,8.9381027,0.0,0,1.0582546,0.0,0.9065944,82.427933,1.0514265,378.66388,-9.2606401
6544,6544,179.5828,16.078943,8.9610205,0.0,0,1.0437918,0.0,0.90905362,82.486588,1.0402448,378.53754,-9.2613707
6555,6555,179.585,16.120852,8.9661837,0.0,0,1.0293289,0.0,0.91104639,82.506477,1.0221013,378.41116,-9.2594814
6566,6566,179.5872,16.209312,8.9874802,0.0,0,1.0148661,0.0,0.91384518,82.739143,1.0095731,378.28479,-9.2593613
6577,6577,179.5894,16.256145,8.9957724,0.0,0,1.0004034,0.0,0.91587496,82.825043,0.9946273,378.15842,-9.2586298
6588,6588,179.5916,16.336039,9.0173149,0.0,0,0.98594052,0.0,0.91877687,82.999374,0.98181766,378.13998,-9.2598019
6599,6599,179.5938,16.386675,9.0236473,0.0,0,0.97147781,0.0,0.9204666,83.090889,0.96628428,378.15329,-9.2590141
6610,6610,179.596,16.428968,9.0403328,0.0,0,0.95701498,0.0,0.92276132,83.11554,0.95062172,378.1666,-9.2609062
6621,6621,179.5982,16.477715,9.0489798,0.0,0,0.94255221,0.0,0.92460269,83.251427,0.94067299,378.1799,-9.259346
6632,6632,179.6004,16.573174,9.0705185,0.0,0,0.92808938,0.0,0.92766941,83.426109,0.92602211,378.33521,-9.2601147
6643,6643,179.6026,16.661413,9.0777197,0.0,0,0.91362655,0.0,0.92944205,83.735222,0.91074419,378.97336,-9.259305
6654,6654,179.6048,16.800745,9.0976191,0.0,0,0.89916378,0.0,0.93249977,84.138458,0.89089018,379.61151,-9.2585526
6665,6665,179.607,16.913439,9.1086292,0.0,0,0.88510746,0.0,0.93461436,84.536354,0.87968051,380.24966,-9.2597303
6676,6676,179.6092,16.994884,9.1305456,0.0,0,0.87135309,0.0,0.93812829,84.675278,0.86532766,380.88782,-9.2605457
6687,6687,179.6114,17.039402,9.1380377,0.0,0,0.8575986,0.0,0.93956232,84.814598,0.84809518,381.54376,-9.2606497
6698,6698,179.6136,17.082769,9.155962,0.0,0,0.84384423,0.0,0.94269556,84.725677,0.83530402,382.20801,-9.2584209
6709,6709,179.6158,17.143021,9.1684618,0.0,0,0.83008987,0.0,0.94466794,84.878113,0.81927711,382.87228,-9.2589083
6720,6720,179.618,17.193306,9.188158,0.0,0,0.81633544,0.0,0.94819957,84.801071,0.80516857,383.53656,-9.2599497
6731,6731,179.6202,17.242373,9.1995296,0.0,0,0.80258107,0.0,0.94979995,84.914955,0.79352909,384.11929,-9.2594843
6742,6742,179.6224,17.302956,9.2139339,0.0,0,0.7888267,0.0,0.95289129,84.931969,0.77883041,384.18564,-9.2595224
6753,6753,179.6246,17.3251,9.2253714,0.0,0,0.77507228,0.0,0.9543193,84.977898,0.76403427,384.25198,-9.2593784
6764,6764,179.6268,17.393038,9.2443447,0.0,0,0.76131791,0.0,0.95824111,84.941925,0.75135511,384.31836,-9.2600985
6775,6775,179.629,17.430391,9.2524738,0.0,0,0.74756348,0.0,0.95896298,85.070938,0.73839438,384.3847,-9.2599602
6786,6786,179.6312,17.45648,9.2654428,0.0,0,0.73380905,0.0,0.96195239,84.951553,0.72463739,384.42361,-9.2588215
6797,6797,179.6334,17.489378,9.2769613,0.0,0,0.72005463,0.0,0.96314317,85.035805,0.71375149,384.44351,-9.2593288
6808,6808,179.6356,17.549343,9.2932987,0.0,0,0.70630032,0.0,0.96692556,84.988075,0.69826555,384.46341,-9.2604713
6819,6819,179.6378,17.620129,9.3044767,0.0,0,0.69254589,0.0,0.9677605,85.253525,0.68507075,384.48334,-9.2585917
6830,6830,179.64,17.682825,9.314846,0.0,0,0.67879146,0.0,0.97072512,85.275055,0.66929644,384.51379,-9.2587767
6841,6841,179.6422,17.77367,9.3288736,0.0,0,0.6650371,0.0,0.97202122,85.572166,0.65865642,384.76596,-9.2578688
6852,6852,179.6444,17.84762,9.3444452,0.0,0,0.65128267,0.0,0.97601306,85.599289,0.6480549,385.01813,-9.2601185
6863,6863,179.6466,17.973944,9.3593464,0.0,0,0.6375283,0.0,0.9771589,86.111427,0.63235742,385.27029,-9.2586155
6874,6874,179.6488,18.052326,9.3686638,0.0,0,0.62377387,0.0,0.98027575,86.223099,0.61668396,385.52246,-9.2593021
6885,6885,179.651,18.111368,9.3830833,0.0,0,0.61001945,0.0,0.98145765,86.420464,0.60598487,385.76801,-9.2590866
6896,6896,179.6532,18.203421,9.39711,0.0,0,0.59626508,0.0,0.98553103,86.500511,0.59135062,386.0069,-9.2591352
6907,6907,179.6554,18.29104,9.4120703,0.0,0,0.58251071,0.0,0.98643446,86.852509,0.57762927,386.24579,-9.2592983
6918,6918,179.6576,18.377762,9.4223118,0.0,0,0.56931871,0.0,0.99016082,86.887978,0.55892342,386.48468,-9.2593699
6929,6929,179.6598,18.479597,9.4395609,0.0,0,0.5562287,0.0,0.99153239,87.264328,0.54645187,386.72357,-9.2593098
6940,6940,179.662,18.557596,9.4498606,0.0,0,0.54313874,0.0,0.99507242,87.347237,0.53580105,387.32986,-9.2583656
6951,6951,179.6642,18.623491,9.4664469,0.0,0,0.53004873,0.0,0.99612093,87.554985,0.51868439,387.95364,-9.2577791