File: clean data/testID_0148.csv
level_0,index,Time(sec),Force(kN),Jaw(mm),PowAngle(deg),Power(W),Pram,PTemp,Strain,Stress(MPa),Stroke(mm),TC1(C),wedge(mm)
2126,2126,165.3749,0.57495081,0.014701289,0.0,0,9.9308634,0.0,0.00090365671,7.1489954,10.035402,359.84253,-9.2862787
2137,2137,165.3771,2.0331635,0.031476632,0.0,0,9.8978634,0.0,0.0021159935,25.588261,10.002107,359.99554,-9.2855921
2148,2148,165.3793,3.3464844,0.044721525,0.0,0,9.8648634,0.0,0.0029356608,42.201771,9.9684057,360.14859,-9.2849827
2159,2159,165.3815,4.3084388,0.069443271,0.0,0,9.8318634,0.0,0.0046689678,54.386963,9.9360752,360.30164,-9.2842789
2170,2170,165.3837,4.9375539,0.096749075,0.0,0,9.7988634,0.0,0.0063758772,62.346695,9.9013996,360.45468,-9.2831411
2181,2181,165.3859,5.3726606,0.12956376,0.0,0,9.7658634,0.0,0.0087081864,67.830338,9.8628883,360.75519,-9.28298
2192,2192,165.3881,5.7220311,0.16149327,0.0,0,9.7328634,0.0,0.010772077,72.036873,9.8259106,361.06128,-9.2827873
2203,2203,165.3903,5.9898653,0.19922617,0.0,0,9.6998634,0.0,0.013309855,75.23114,9.7905846,361.36737,-9.283412
2214,2214,165.3925,6.1957097,0.22876933,0.0,0,9.6668634,0.0,0.015230163,77.625031,9.7554026,361.67343,-9.283082
2225,2225,165.3947,6.3585138,0.25998586,0.0,0,9.6338634,0.0,0.017527753,79.540573,9.7232704,361.93597,-9.2830172
2236,2236,165.3969,6.4753418,0.29194948,0.0,0,9.6008635,0.0,0.019537155,80.824844,9.6894789,362.13559,-9.2826633
2247,2247,165.3991,6.5998445,0.32752585,0.0,0,9.5678635,0.0,0.022220585,82.22921,9.6526747,362.33521,-9.2834558
2258,2258,165.4013,6.6997628,0.35852352,0.0,0,9.5348635,0.0,0.023996001,83.286179,9.6202459,362.53482,-9.2835541
2269,2269,165.4035,6.7952271,0.3882226,0.0,0,9.5018635,0.0,0.026337389,84.146309,9.5909472,362.73444,-9.2833061
2280,2280,165.4057,6.8963475,0.42098439,0.0,0,9.4691811,0.0,0.028328616,85.313034,9.5556717,362.88855,-9.2828436
2291,2291,165.4079,6.9709744,0.45588747,0.0,0,9.4369907,0.0,0.031015174,86.005058,9.5203753,363.03494,-9.2817841
2302,2302,165.4101,7.0390921,0.49008188,0.0,0,9.4048004,0.0,0.033040188,86.804565,9.4848385,363.18134,-9.2836161
2313,2313,165.4123,7.0813127,0.51989633,0.0,0,9.3726101,0.0,0.035344198,87.009399,9.4521646,363.3277,-9.2834101
2324,2324,165.4145,7.1214547,0.55142075,0.0,0,9.3404198,0.0,0.03729482,87.425987,9.4169235,363.46811,-9.283062
2335,2335,165.4167,7.1483669,0.58553499,0.0,0,9.3082294,0.0,0.039992884,87.499748,9.3862534,363.59451,-9.284133
2346,2346,165.4189,7.1892676,0.61893022,0.0,0,9.2760391,0.0,0.041913014,87.761314,9.3541689,363.72095,-9.2842474
2357,2357,165.4211,7.2266941,0.64580709,0.0,0,9.2438488,0.0,0.044154383,88.015312,9.3195295,363.84738,-9.2842369
2368,2368,165.4233,7.2834849,0.67892241,0.0,0,9.2116575,0.0,0.046088759,88.473221,9.2865,363.97382,-9.2839928
2379,2379,165.4255,7.3464193,0.71151167,0.0,0,9.1794672,0.0,0.048818316,89.037048,9.254571,364.08038,-9.2841387
2390,2390,165.4277,7.3846488,0.74717802,0.0,0,9.1472769,0.0,0.050776199,89.389267,9.2219896,364.18021,-9.2843246
2401,2401,165.4299,7.413496,0.77379394,0.0,0,9.1150866,0.0,0.053142875,89.451363,9.1886034,364.28,-9.2841883
2412,2412,165.4321,7.4184632,0.80761236,0.0,0,9.0828962,0.0,0.05506834,89.441322,9.1549969,364.37982,-9.2847452
2423,2423,165.4343,7.4363151,0.83874732,0.0,0,9.0507059,0.0,0.057809129,89.376144,9.1254396,364.48343,-9.2857571
2434,2434,165.4365,7.4637938,0.87414521,0.0,0,9.0185156,0.0,0.059763826,89.549118,9.0923223,364.60321,-9.2846899
2445,2445,165.4387,7.5225949,0.90057021,0.0,0,8.9863253,0.0,0.062115274,89.882515,9.0627213,364.72299,-9.2829046
2456,2456,165.4409,7.5631118,0.93439126,0.0,0,8.9541349,0.0,0.064059459,90.322037,9.0290279,364.84274,-9.2832623
2467,2467,165.4431,7.6068058,0.96756518,0.0,0,8.9219446,0.0,0.066899061,90.630699,8.991931,364.96252,-9.2841034
2478,2478,165.4453,7.640604,1.0043671,0.0,0,8.8897533,0.0,0.06894546,90.81237,8.9574871,365.06958,-9.2848368
2489,2489,165.4475,7.668057,1.0295688,0.0,0,8.857563,0.0,0.071350746,90.906952,8.9272108,365.1694,-9.2840405
2500,2500,165.4497,7.6769052,1.0656044,0.0,0,8.8253727,0.0,0.073475733,90.854584,8.892478,365.2692,-9.2842293
2511,2511,165.4519,7.6803007,1.093338,0.0,0,8.7931824,0.0,0.076004289,90.721191,8.8610106,365.36899,-9.2841511
2522,2522,165.4541,7.7004733,1.129753,0.0,0,8.7609921,0.0,0.077907935,90.768669,8.8310003,365.4639,-9.2843628
2533,2533,165.4563,7.744175,1.1566222,0.0,0,8.7298489,0.0,0.080438785,90.922646,8.7945528,365.50381,-9.2830954
2544,2544,165.4585,7.7922072,1.1902412,0.0,0,8.6992331,0.0,0.08244615,91.342392,8.7623711,365.54376,-9.2845726
2555,2555,165.4607,7.8336744,1.2204559,0.0,0,8.6686182,0.0,0.085090272,91.588638,8.7316046,365.58368,-9.2851887
2566,2566,165.4629,7.8611956,1.2573223,0.0,0,8.6380024,0.0,0.087093152,91.72805,8.7001104,365.62363,-9.2843237
2577,2577,165.4651,7.8785501,1.2818856,0.0,0,8.6073875,0.0,0.089546807,91.78656,8.6681004,365.59335,-9.2838516
2588,2588,165.4673,7.8877859,1.3141433,0.0,0,8.5767736,0.0,0.09146446,91.682533,8.638155,365.50021,-9.2835093
2599,2599,165.4695,7.9078746,1.3431345,0.0,0,8.5461569,0.0,0.094119951,91.690727,8.607317,365.40704,-9.2822371
2610,2610,165.4717,7.9114757,1.3813664,0.0,0,8.515542,0.0,0.096155383,91.529808,8.5743179,365.3139,-9.2837763
2621,2621,165.4739,7.9412694,1.4052434,0.0,0,8.4849262,0.0,0.098561727,91.616188,8.542717,365.22073,-9.2836466
2632,2632,165.4761,7.9686041,1.4383799,0.0,0,8.4543123,0.0,0.10063181,91.766426,8.5123224,365.26999,-9.2848148
2643,2643,165.4783,8.0193615,1.4667293,0.0,0,8.4236965,0.0,0.10316853,92.021385,8.4830103,365.32321,-9.2853737
2654,2654,165.4805,8.0397081,1.5023081,0.0,0,8.3930817,0.0,0.10516401,92.18898,8.4521294,365.37646,-9.2845278
2665,2665,165.4827,8.0764093,1.5250107,0.0,0,8.3624659,0.0,0.10744815,92.317337,8.4206457,365.42969,-9.284482
2676,2676,165.4849,8.1032314,1.5591751,0.0,0,8.331852,0.0,0.10953645,92.496178,8.3902693,365.49405,-9.284874
2687,2687,165.4871,8.1219301,1.5889492,0.0,0,8.3012362,0.0,0.1122106,92.41745,8.35495,365.57391,-9.2851038
2698,2698,165.4893,8.1157484,1.62736,0.0,0,8.2706213,0.0,0.11451801,92.133858,8.321106,365.65375,-9.2836275
2709,2709,165.4915,8.1360483,1.6513762,0.0,0,8.2400064,0.0,0.11679994,92.145134,8.2933769,365.73361,-9.2843151
2720,2720,165.4937,8.1591234,1.6822282,0.0,0,8.2093916,0.0,0.11877653,92.173096,8.2647285,365.81345,-9.2848454
2731,2731,165.4959,8.1793261,1.7081075,0.0,0,8.1787748,0.0,0.12104894,92.267784,8.2338848,365.76688,-9.2849684
2742,2742,165.4981,8.2222614,1.7427789,0.0,0,8.14816,0.0,0.12327806,92.510574,8.2026386,365.70032,-9.28407
2753,2753,165.5003,8.244976,1.7655984,0.0,0,8.1175451,0.0,0.12536116,92.630867,8.1764698,365.63379,-9.2827835
2764,2764,165.5025,8.2777805,1.7990448,0.0,0,8.0869303,0.0,0.12759286,92.728065,8.1443224,365.56723,-9.2847519
2775,2775,165.5047,8.3186636,1.8291618,0.0,0,8.0563145,0.0,0.13010737,93.026772,8.1129036,365.43283,-9.2844486
2786,2786,165.5069,8.333868,1.8667636,0.0,0,8.0270939,0.0,0.13265963,93.013557,8.0790901,365.14673,-9.2835436
2797,2797,165.5091,8.333786,1.8900509,0.0,0,7.9979653,0.0,0.13475198,92.781937,8.0494719,364.8606,-9.283267
2808,2808,165.5113,8.350235,1.9215767,0.0,0,7.9688373,0.0,0.13697366,92.643318,8.0176735,364.57449,-9.283102
2819,2819,165.5135,8.379425,1.94787,0.0,0,7.9397097,0.0,0.13920045,92.792786,7.9847698,364.28836,-9.2833395
2830,2830,165.5157,8.4075413,1.9832865,0.0,0,7.9105816,0.0,0.14162514,92.794441,7.9593754,363.98718,-9.2829838
2841,2841,165.5179,8.4401865,2.0081699,0.0,0,7.881453,0.0,0.14380826,93.009331,7.9287324,363.68109,-9.285512
2852,2852,165.5201,8.4521141,2.0396671,0.0,0,7.8523254,0.0,0.14603734,93.092461,7.902101,363.37503,-9.2858295
2863,2863,165.5223,8.4686537,2.0622571,0.0,0,7.8231974,0.0,0.14792693,93.044037,7.8705535,363.06894,-9.2844877
2874,2874,165.5245,8.4827204,2.0974076,0.0,0,7.7940698,0.0,0.15042298,92.89949,7.8418717,362.83206,-9.2840157
2885,2885,165.5267,8.4995956,2.1204004,0.0,0,7.7649412,0.0,0.15241033,92.967796,7.8149161,362.87198,-9.2844648
2896,2896,165.5289,8.5060816,2.151284,0.0,0,7.7358131,0.0,0.1547464,92.756775,7.7842202,362.9119,-9.2846956
2907,2907,165.5311,8.554637,2.1767499,0.0,0,7.7066855,0.0,0.15681307,93.189545,7.7544951,362.95184,-9.2857389
2918,2918,165.5333,8.5940008,2.2135453,0.0,0,7.6775575,0.0,0.15958083,93.332085,7.723649,362.99176,-9.2851686
2929,2929,165.5355,8.6244564,2.23844,0.0,0,7.6484294,0.0,0.16162221,93.344994,7.6942449,363.07034,-9.283308
2940,2940,165.5377,8.6427574,2.2690322,0.0,0,7.6193013,0.0,0.16403522,93.380981,7.666409,363.17017,-9.2827282
2951,2951,165.5399,8.6808577,2.2936261,0.0,0,7.5901732,0.0,0.16584773,93.609428,7.6334848,363.26996,-9.2844133
2962,2962,165.5421,8.6896057,2.3274856,0.0,0,7.5610456,0.0,0.16861241,93.483459,7.605103,363.36978,-9.284585
2973,2973,165.5443,8.6907415,2.3517447,0.0,0,7.5319176,0.0,0.17049956,93.354797,7.579567,363.46112,-9.2848749
2984,2984,165.5465,8.706461,2.3811219,0.0,0,7.5027895,0.0,0.17288023,93.278198,7.5472569,363.46777,-9.2857122
2995,2995,165.5487,8.7395468,2.4103835,0.0,0,7.4736614,0.0,0.17505708,93.36055,7.5187702,363.4744,-9.2857857
3006,3006,165.5509,8.7803421,2.44348,0.0,0,7.4445333,0.0,0.17786348,93.615112,7.4915061,363.48105,-9.2856226
3017,3017,165.5531,8.8367281,2.4716945,0.0,0,7.4154053,0.0,0.17982887,93.945877,7.4632559,363.4877,-9.2845383
3028,3028,165.5553,8.8619814,2.4987319,0.0,0,7.3865771,0.0,0.18230703,94.024918,7.4292226,363.36945,-9.2836571
3039,3039,165.5575,8.8848143,2.5291524,0.0,0,7.3588748,0.0,0.18444036,94.068695,7.3978958,363.14322,-9.2834663
3050,3050,165.5597,8.9041948,2.5644619,0.0,0,7.3311725,0.0,0.18758965,94.068275,7.368639,362.91696,-9.2836847
3061,3061,165.5619,8.9090929,2.5916328,0.0,0,7.3034697,0.0,0.18945286,93.893166,7.3384771,362.69073,-9.284503
3072,3072,165.5641,8.9081402,2.6162136,0.0,0,7.2757673,0.0,0.19179806,93.558929,7.3066611,362.46451,-9.2854977
3083,3083,165.5663,8.9109173,2.6417511,0.0,0,7.248065,0.0,0.19353166,93.482391,7.2815971,362.30362,-9.2847958
3094,3094,165.5685,8.9291544,2.6742404,0.0,0,7.2203627,0.0,0.19649443,93.331512,7.2540517,362.14392,-9.2853308
3105,3105,165.5707,8.9761629,2.7013652,0.0,0,7.1926603,0.0,0.19826013,93.705383,7.2244897,361.98422,-9.2840195
3116,3116,165.5729,9.0179815,2.7255878,0.0,0,7.1649575,0.0,0.20065998,93.926003,7.194881,361.82455,-9.2844496
3127,3127,165.5751,9.0278072,2.7523549,0.0,0,7.1372557,0.0,0.20244409,93.92955,7.1690388,361.69046,-9.2840872
3138,3138,165.5773,9.0258808,2.7806921,0.0,0,7.1095533,0.0,0.20526555,93.687866,7.145473,361.59064,-9.2838173
3149,3149,165.5795,9.0543594,2.8100889,0.0,0,7.0818505,0.0,0.2071369,93.720627,7.1140485,361.49081,-9.2841034
3160,3160,165.5817,9.057415,2.8337736,0.0,0,7.0541482,0.0,0.20958777,93.495033,7.0835123,361.39102,-9.2828102
3171,3171,165.5839,9.0792465,2.8615484,0.0,0,7.0264459,0.0,0.21132521,93.594589,7.0579081,361.2912,-9.283536
3182,3182,165.5861,9.0992966,2.8882916,0.0,0,6.9987435,0.0,0.21416619,93.528603,7.0346122,361.15076,-9.2842999
3193,3193,165.5883,9.1433334,2.9176242,0.0,0,6.9710412,0.0,0.21599461,93.740067,7.0026364,361.00436,-9.2844238
3204,3204,165.5905,9.1805019,2.9403121,0.0,0,6.9433384,0.0,0.21846899,93.902901,6.9782362,360.85797,-9.2855253
3215,3215,165.5927,9.2139311,2.9695098,0.0,0,6.9156365,0.0,0.22030711,94.157257,6.9487534,360.71161,-9.2836161
3226,3226,165.5949,9.2226677,2.9985905,0.0,0,6.8879337,0.0,0.22339256,93.986519,6.9204884,360.58215,-9.283391
3237,3237,165.5971,9.2437782,3.0291569,0.0,0,6.8602314,0.0,0.22515666,93.953735,6.8915758,360.48898,-9.2834263
3248,3248,165.5993,9.2656364,3.0520442,0.0,0,6.8325291,0.0,0.22776319,93.936546,6.867239,360.39584,-9.2843542
3259,3259,165.6015,9.26437,3.0819123,0.0,0,6.8048267,0.0,0.22968429,93.8032,6.8364062,360.30267,-9.2832556
3270,3270,165.6037,9.2887497,3.1054175,0.0,0,6.7771239,0.0,0.23227108,93.743446,6.8112593,360.20953,-9.2833433
3281,3281,165.6059,9.3210001,3.1335068,0.0,0,6.750072,0.0,0.23390217,93.933647,6.7807407,360.1062,-9.2834406
3292,3292,165.6081,9.3609877,3.1565096,0.0,0,6.7237158,0.0,0.23661385,94.133774,6.7580175,359.99973,-9.2849197
3303,3303,165.6103,9.3931551,3.1888354,0.0,0,6.69736,0.0,0.23865156,94.191162,6.7294621,359.89328,-9.2850351
3314,3314,165.6125,9.4187832,3.2132659,0.0,0,6.6710038,0.0,0.24145389,94.203033,6.7014303,359.7868,-9.2840443
3325,3325,165.6147,9.4263811,3.2455857,0.0,0,6.6446481,0.0,0.24328178,94.03392,6.6726952,359.71097,-9.2837496
3336,3336,165.6169,9.438406,3.2656643,0.0,0,6.6182923,0.0,0.24587999,94.034409,6.6476703,359.75089,-9.283783
3347,3347,165.6191,9.4704552,3.2957213,0.0,0,6.5919356,0.0,0.2477383,94.121529,6.6224303,359.7908,-9.284318
3358,3358,165.6213,9.4797678,3.3187196,0.0,0,6.5655799,0.0,0.25044912,94.010239,6.5916858,359.83075,-9.2836504
3369,3369,165.6235,9.5104313,3.352478,0.0,0,6.5392241,0.0,0.25245738,94.014404,6.5665483,359.87067,-9.2849283
3380,3380,165.6257,9.5298367,3.3730726,0.0,0,6.5128679,0.0,0.25507593,94.114441,6.5383458,359.95413,-9.2844315
3391,3391,165.6279,9.5587177,3.4022014,0.0,0,6.4865122,0.0,0.25691509,94.107986,6.5158229,360.06061,-9.2842569
3402,3402,165.6301,9.597146,3.4262183,0.0,0,6.460156,0.0,0.25962576,94.189919,6.4829001,360.16705,-9.2828646
3413,3413,165.6323,9.6122856,3.4583032,0.0,0,6.4338002,0.0,0.26158521,94.202377,6.4621325,360.2735,-9.2828407
3424,3424,165.6345,9.6367588,3.477021,0.0,0,6.407444,0.0,0.26401579,94.232964,6.4339714,360.38397,-9.2823906
3435,3435,165.6367,9.6565886,3.506829,0.0,0,6.3810883,0.0,0.26607114,94.26947,6.4102697,360.53036,-9.2835875
3446,3446,165.6389,9.6968966,3.531235,0.0,0,6.354732,0.0,0.26874271,94.390739,6.3762956,360.67676,-9.2850189
3457,3457,165.6411,9.7014542,3.5654094,0.0,0,6.3283763,0.0,0.27091202,94.223228,6.3510046,360.82315,-9.2851343
3468,3468,165.6433,9.7163763,3.5831525,0.0,0,6.3020205,0.0,0.273238,94.094421,6.3285427,360.96954,-9.2850723
3479,3479,165.6455,9.7403498,3.6128561,0.0,0,6.2756648,0.0,0.2753309,94.132393,6.2970495,361.14496,-9.2844725
3490,3490,165.6477,9.7570667,3.6343954,0.0,0,6.2493086,0.0,0.27776912,94.045784,6.2723126,361.34457,-9.2838392
3501,3501,165.6499,9.7836151,3.6666632,0.0,0,6.2229524,0.0,0.27988553,94.205521,6.2510505,361.54419,-9.2836561
3512,3512,165.6521,9.7979507,3.6823206,0.0,0,6.1965966,0.0,0.28194338,94.124695,6.22543,361.7438,-9.2833328
3523,3523,165.6543,9.8299103,3.7118604,0.0,0,6.1702404,0.0,0.28401342,94.174866,6.1977143,361.94342,-9.2827873
3534,3534,165.6565,9.8596249,3.7350569,0.0,0,6.1448588,0.0,0.28663504,94.240349,6.1705642,362.14963,-9.2838478
3545,3545,165.6587,9.9057178,3.7713611,0.0,0,6.119792,0.0,0.28919438,94.412155,6.1468873,362.3559,-9.2839174
3556,3556,165.6609,9.94559,3.7915716,0.0,0,6.0947251,0.0,0.29161978,94.594009,6.1157722,362.56216,-9.2835379
3567,3567,165.6631,9.9736786,3.8226264,0.0,0,6.0696583,0.0,0.29391205,94.630806,6.088264,362.76843,-9.2845716
3578,3578,165.6653,9.9807444,3.841469,0.0,0,6.0445914,0.0,0.2960946,94.500526,6.0615797,362.78598,-9.2841663
3589,3589,165.6675,9.995429,3.8754079,0.0,0,6.0195251,0.0,0.29858807,94.420761,6.0385027,362.55975,-9.2850618
3600,3600,165.6697,9.997798,3.8950496,0.0,0,5.9944577,0.0,0.30080229,94.210274,6.0111318,362.33353,-9.2842369
3611,3611,165.6719,10.008831,3.9233632,0.0,0,5.9693913,0.0,0.30298299,94.142059,5.9855752,362.10727,-9.2841425
3622,3622,165.6741,10.016756,3.9414053,0.0,0,5.944324,0.0,0.30499023,94.01265,5.9628878,361.88104,-9.2844133
3633,3633,165.6763,10.035301,3.9727857,0.0,0,5.9192576,0.0,0.30740777,93.921707,5.9385829,361.32037,-9.2831745
3644,3644,165.6785,10.064776,3.9912436,0.0,0,5.8941908,0.0,0.30950773,94.022499,5.9118333,360.71484,-9.2841368
3655,3655,165.6807,10.103301,4.0189695,0.0,0,5.8691239,0.0,0.31175858,94.099335,5.8882232,360.10934,-9.2838802
3666,3666,165.6829,10.125038,4.0406833,0.0,0,5.8440571,0.0,0.31386381,94.170242,5.8645802,359.50385,-9.284174
3677,3677,165.6851,10.154938,4.0710526,0.0,0,5.8189898,0.0,0.3163718,94.217361,5.8402147,359.02246,-9.2838249
3688,3688,165.6873,10.207183,4.0901809,0.0,0,5.7939234,0.0,0.3184216,94.457977,5.8137274,358.79623,-9.2842731
3699,3699,165.6895,10.217124,4.1170216,0.0,0,5.7688565,0.0,0.32075825,94.379585,5.7889671,358.56998,-9.2842321
3710,3710,165.6917,10.22693,4.1398435,0.0,0,5.7437897,0.0,0.32293403,94.256325,5.7622647,358.34375,-9.2850847
3721,3721,165.6939,10.258855,4.1712847,0.0,0,5.7187228,0.0,0.32566482,94.323746,5.7368107,358.11752,-9.2843351
3732,3732,165.6961,10.289573,4.1918883,0.0,0,5.693656,0.0,0.32771274,94.378242,5.7099319,358.00955,-9.2841339
3743,3743,165.6983,10.328758,4.2182894,0.0,0,5.6685896,0.0,0.33021513,94.50293,5.6830587,357.93637,-9.2852573
3754,3754,165.7005,10.346999,4.2427158,0.0,0,5.6435223,0.0,0.33244348,94.500435,5.6629338,357.86316,-9.2847338
3765,3765,165.7027,10.399688,4.2742162,0.0,0,5.6184554,0.0,0.33543259,94.656395,5.6331353,357.78998,-9.2834969
3776,3776,165.7049,10.43596,4.2955704,0.0,0,5.5934343,0.0,0.33732778,94.809563,5.6052771,357.75018,-9.283411
3787,3787,165.7071,10.439773,4.3207617,0.0,0,5.5695753,0.0,0.33969378,94.65625,5.5798712,357.83002,-9.2830677
3798,3798,165.7093,10.421871,4.3425474,0.0,0,5.5457277,0.0,0.34167007,94.343399,5.5581851,357.90988,-9.2842321
3809,3809,165.7115,10.416674,4.3705039,0.0,0,5.5218797,0.0,0.3445192,93.997269,5.5369215,357.98972,-9.2838888
3820,3820,165.7137,10.421821,4.3932962,0.0,0,5.4980316,0.0,0.34633023,93.87088,5.5126581,358.06958,-9.2830915
3831,3831,165.7159,10.443652,4.4181638,0.0,0,5.4741836,0.0,0.34903175,93.799339,5.4886522,358.29956,-9.2849169
3842,3842,165.7181,10.49976,4.4380608,0.0,0,5.4503355,0.0,0.35056168,94.182373,5.4641385,358.60565,-9.2842112
3853,3853,165.7203,10.547466,4.4650817,0.0,0,5.4264879,0.0,0.35347167,94.311256,5.4386954,358.91171,-9.284483
3864,3864,165.7225,10.590684,4.4867864,0.0,0,5.4026399,0.0,0.35514274,94.442291,5.4158239,359.2178,-9.2842512
3875,3875,165.7247,10.590322,4.5096297,0.0,0,5.3787913,0.0,0.3577489,94.314392,5.3914056,359.53113,-9.2842722
3886,3886,165.7269,10.611768,4.5334024,0.0,0,5.3549438,0.0,0.35960555,94.264717,5.3678966,359.90375,-9.2835102
3897,3897,165.7291,10.59284,4.5579977,0.0,0,5.3310957,0.0,0.36251262,93.883698,5.344851,360.27637,-9.2835608
3908,3908,165.7313,10.625329,4.5843048,0.0,0,5.3072476,0.0,0.3643682,94.002266,5.3195381,360.64896,-9.2836494
3919,3919,165.7335,10.658792,4.6064634,0.0,0,5.2833996,0.0,0.36710885,93.95237,5.2995896,361.02158,-9.2836752
3930,3930,165.7357,10.714588,4.6296449,0.0,0,5.2595515,0.0,0.36876464,94.283783,5.2771454,361.42001,-9.2834597
3941,3941,165.7379,10.764142,4.6565056,0.0,0,5.2357039,0.0,0.37200254,94.377037,5.2455845,361.83923,-9.2845945
3952,3952,165.7401,10.76917,4.6817775,0.0,0,5.2118554,0.0,0.37374115,94.357635,5.2256365,362.25842,-9.2827711
3963,3963,165.7423,10.786312,4.7002311,0.0,0,5.1880078,0.0,0.3763136,94.346603,5.2027001,362.67764,-9.2831669
3974,3974,165.7445,10.805213,4.7247825,0.0,0,5.1641598,0.0,0.37789595,94.238167,5.179204,363.09683,-9.2837629
3985,3985,165.7467,10.812235,4.7477455,0.0,0,5.1403117,0.0,0.38091448,94.098816,5.1532431,363.1767,-9.2831802
3996,3996,165.7489,10.818263,4.7756343,0.0,0,5.1164637,0.0,0.38284561,94.018494,5.1312361,363.25653,-9.2846212
4007,4007,165.7511,10.873289,4.7940502,0.0,0,5.0926156,0.0,0.38548294,94.165779,5.1062431,363.3364,-9.2834082
4018,4018,165.7533,10.937346,4.819838,0.0,0,5.0687675,0.0,0.38727608,94.498512,5.0813189,363.41623,-9.2840338
4029,4029,165.7555,10.987373,4.845221,0.0,0,5.0452709,0.0,0.39053249,94.639687,5.0577931,362.95068,-9.2832794
4040,4040,165.7577,10.998261,4.87392,0.0,0,5.0225892,0.0,0.39244685,94.561096,5.0318384,361.80621,-9.2844858
4051,4051,165.7599,11.051366,4.8934536,0.0,0,4.9999065,0.0,0.39525735,94.684021,5.0077162,360.66174,-9.284338
4062,4062,165.7621,11.036261,4.9198689,0.0,0,4.9772248,0.0,0.39706165,94.437294,4.9848495,359.51727,-9.2851448
4073,4073,165.7643,11.049582,4.9413123,0.0,0,4.9545431,0.0,0.40007296,94.278984,4.9604506,358.37277,-9.2847424
4084,4084,165.7665,11.026454,4.968286,0.0,0,4.9318609,0.0,0.40168321,93.975517,4.9406052,357.34094,-9.2841082
4095,4095,165.7687,11.01967,4.9827967,0.0,0,4.9091787,0.0,0.40424052,93.642982,4.9177427,356.32291,-9.2836199
4106,4106,165.7709,11.029584,5.0067129,0.0,0,4.886497,0.0,0.40580109,93.59008,4.8924661,355.30487,-9.2840376
4117,4117,165.7731,11.06758,5.0253487,0.0,0,4.8638148,0.0,0.40848505,93.601036,4.872581,354.2868,-9.2845697
4128,4128,165.7753,11.082136,5.0527363,0.0,0,4.8411331,0.0,0.4101041,93.644264,4.8553085,353.67612,-9.2828732
4139,4139,165.7775,11.1531,5.0673718,0.0,0,4.8184505,0.0,0.41270006,93.943161,4.8326559,353.86908,-9.2837267
4150,4150,165.7797,11.22254,5.0938573,0.0,0,4.7957687,0.0,0.41444436,94.371979,4.8094473,354.06204,-9.2849627
4161,4161,165.7819,11.285444,5.1144862,0.0,0,4.773087,0.0,0.41740581,94.628395,4.7851081,354.255,-9.2848053
4172,4172,165.7841,11.318409,5.1492586,0.0,0,4.7504048,0.0,0.41975585,94.752853,4.7604671,354.44794,-9.2848034
4183,4183,165.7863,11.344716,5.1659899,0.0,0,4.7277226,0.0,0.4225781,94.695999,4.7347317,354.6149,-9.2835054
4194,4194,165.7885,11.345519,5.1952271,0.0,0,4.7050409,0.0,0.42470452,94.497406,4.7067838,354.7746,-9.2835054
4205,4205,165.7907,11.36836,5.2142606,0.0,0,4.6823587,0.0,0.42758268,94.344612,4.6879373,354.9343,-9.2848644
4216,4216,165.7929,11.393535,5.2447319,0.0,0,4.659677,0.0,0.42963344,94.386063,4.6648355,355.09399,-9.2851229
4227,4227,165.7951,11.417788,5.2576404,0.0,0,4.6369944,0.0,0.43201402,94.361542,4.6400943,355.23102,-9.2846909
4238,4238,165.7973,11.425529,5.2839489,0.0,0,4.6143126,0.0,0.43383402,94.27964,4.6173677,355.29089,-9.2840433
4249,4249,165.7995,11.459594,5.3012276,0.0,0,4.5916309,0.0,0.4365913,94.314873,4.5990901,355.35077,-9.2840061
4260,4260,165.8017,11.475434,5.3326159,0.0,0,4.5689487,0.0,0.43871325,94.253738,4.5754104,355.41068,-9.2843771
4271,4271,165.8039,11.494205,5.3461585,0.0,0,4.546267,0.0,0.44109082,94.148483,4.5515389,355.47055,-9.2841854
4282,4282,165.8061,11.524096,5.3717141,0.0,0,4.5242186,0.0,0.44292885,94.179131,4.5316401,355.58862,-9.2843962
4293,4293,165.8083,11.538933,5.3892956,0.0,0,4.5026407,0.0,0.44573104,94.107613,4.5102897,355.73502,-9.2842999
4304,4304,165.8105,11.587167,5.4212971,0.0,0,4.4810629,0.0,0.44796789,94.226486,4.4872394,355.88138,-9.2838144
4315,4315,165.8127,11.629268,5.4323916,0.0,0,4.4594855,0.0,0.45000446,94.348518,4.465713,356.02777,-9.2835827
4326,4326,165.8149,11.644436,5.4589329,0.0,0,4.4379077,0.0,0.45209992,94.343369,4.4436283,356.16394,-9.2846355
4337,4337,165.8171,11.673061,5.4769421,0.0,0,4.4163303,0.0,0.45476255,94.325134,4.421865,356.22382,-9.2843361
4348,4348,165.8193,11.705509,5.5060253,0.0,0,4.3947525,0.0,0.45697829,94.352966,4.4000778,356.28372,-9.2830515
4359,4359,165.8215,11.723426,5.5196099,0.0,0,4.3731751,0.0,0.45912471,94.292137,4.3747816,356.3436,-9.2836523
4370,4370,165.8237,11.727291,5.5463276,0.0,0,4.3515973,0.0,0.4613224,94.123779,4.3592482,356.4035,-9.2846012
4381,4381,165.8259,11.755134,5.5640411,0.0,0,4.33002,0.0,0.4637852,94.109833,4.3362908,356.50089,-9.284483
4392,4392,165.8281,11.809344,5.5958185,0.0,0,4.3084426,0.0,0.46634433,94.266304,4.3122435,356.62732,-9.2861443
4403,4403,165.8303,11.847323,5.6079516,0.0,0,4.2868648,0.0,0.46842605,94.401085,4.2906265,356.75372,-9.2855844
4414,4414,165.8325,11.883762,5.631484,0.0,0,4.2652874,0.0,0.47040144,94.52179,4.2722998,356.88016,-9.2843113
4425,4425,165.8347,11.888659,5.646771,0.0,0,4.2437096,0.0,0.47257021,94.441383,4.2469845,357.00052,-9.2837038
4436,4436,165.8369,11.929978,5.6783442,0.0,0,4.2221322,0.0,0.47529164,94.463158,4.2300887,356.46155,-9.2843218
4447,4447,165.8391,11.959095,5.6943789,0.0,0,4.2005544,0.0,0.4776395,94.48127,4.207675,355.92258,-9.2834826
4458,4458,165.8413,11.999428,5.7194581,0.0,0,4.178977,0.0,0.47990251,94.576286,4.1879296,355.38361,-9.2850885
4469,4469,165.8435,12.030169,5.7373199,0.0,0,4.1573992,0.0,0.48211333,94.531769,4.1622715,354.84464,-9.2843266
4480,4480,165.8457,12.068369,5.7668271,0.0,0,4.1358213,0.0,0.48490506,94.552109,4.1377983,354.17557,-9.2842855
4491,4491,165.8479,12.12202,5.7817907,0.0,0,4.114244,0.0,0.48699224,94.806358,4.1186829,353.35037,-9.2840977
4502,4502,165.8501,12.157685,5.8079801,0.0,0,4.0926666,0.0,0.48959085,94.856873,4.0996284,352.52518,-9.2837839
4513,4513,165.8523,12.199483,5.826674,0.0,0,4.0710883,0.0,0.49175763,95.051414,4.0743518,351.69995,-9.2848616
4524,4524,165.8545,12.220095,5.8534136,0.0,0,4.0495114,0.0,0.49444541,94.884575,4.0535512,350.87476,-9.2830582
4535,4535,165.8567,12.213706,5.8687263,0.0,0,4.0288277,0.0,0.49635074,94.635933,4.0317035,350.97787,-9.2843494
4546,4546,165.8589,12.244986,5.8956547,0.0,0,4.008306,0.0,0.49917743,94.642693,4.0070558,351.18414,-9.2851028
4557,4557,165.8611,12.254414,5.91363,0.0,0,3.9877841,0.0,0.50117093,94.499458,3.9871817,351.39041,-9.2858095
4568,4568,165.8633,12.285651,5.9384832,0.0,0,3.9672625,0.0,0.50389224,94.500999,3.9671619,351.59668,-9.2855902
4579,4579,165.8655,12.332673,5.9542751,0.0,0,3.9467409,0.0,0.50567687,94.656349,3.9478416,351.86044,-9.2851534
4590,4590,165.8677,12.387526,5.9761119,0.0,0,3.9262192,0.0,0.50812328,94.800255,3.9246891,352.23322,-9.2841349
4601,4601,165.8699,12.396095,5.9933162,0.0,0,3.9056978,0.0,0.51004487,94.828049,3.9033618,352.60596,-9.2835989
4612,4612,165.8721,12.402396,6.0210838,0.0,0,3.8851764,0.0,0.51328462,94.525253,3.8868129,352.9787,-9.2841702
4623,4623,165.8743,12.410221,6.036243,0.0,0,3.8646545,0.0,0.51464069,94.476227,3.8679926,353.35144,-9.2833042
4634,4634,165.8765,12.44368,6.056694,0.0,0,3.8441329,0.0,0.51717156,94.466187,3.8441412,353.59253,-9.2851305
4645,4645,165.8787,12.4867,6.074357,0.0,0,3.8236115,0.0,0.51887208,94.679581,3.8262861,353.7988,-9.2843704
4656,4656,165.8809,12.526032,6.1003447,0.0,0,3.8030899,0.0,0.52227116,94.61322,3.8085823,354.00507,-9.2855883
4667,4667,165.8831,12.567568,6.1176553,0.0,0,3.7825682,0.0,0.52372748,94.696022,3.7859681,354.21133,-9.2850628
4678,4678,165.8853,12.623102,6.1392889,0.0,0,3.7620466,0.0,0.52668977,94.838333,3.7656305,354.43805,-9.2842312
4689,4689,165.8875,12.665701,6.1578374,0.0,0,3.7415249,0.0,0.52820849,95.017563,3.7439845,354.7308,-9.2842627
4700,4700,165.8897,12.689961,6.1815348,0.0,0,3.7210035,0.0,0.5314784,95.022034,3.724457,355.02359,-9.284111
4711,4711,165.8919,12.716897,6.2011828,0.0,0,3.7004819,0.0,0.53291368,94.9561,3.7048655,355.31635,-9.2842474
4722,4722,165.8941,12.726219,6.2200966,0.0,0,3.67996,0.0,0.53582621,94.830544,3.6862285,355.60913,-9.2839918
4733,4733,165.8963,12.794854,6.2408333,0.0,0,3.6594386,0.0,0.53756052,95.166122,3.6648357,355.90189,-9.2836046
4744,4744,165.8985,12.845159,6.2632589,0.0,0,3.638917,0.0,0.54092836,95.253662,3.6410301,356.19464,-9.2831926
4755,4755,165.9007,12.888805,6.2869306,0.0,0,3.6183956,0.0,0.54266256,95.326637,3.618983,356.48743,-9.2823639
4766,4766,165.9029,12.924536,6.303844,0.0,0,3.5978739,0.0,0.54552931,95.334023,3.5974226,356.78018,-9.2840557
4777,4777,165.9051,12.979627,6.3262739,0.0,0,3.577472,0.0,0.54724926,95.599503,3.5765548,357.06195,-9.2843456
4788,4788,165.9073,13.033889,6.3492117,0.0,0,3.5579486,0.0,0.55084145,95.587532,3.555145,357.26825,-9.2846174
4799,4799,165.9095,13.051025,6.3695302,0.0,0,3.5384259,0.0,0.55214995,95.679924,3.5365365,357.47452,-9.2841463
4810,4810,165.9117,13.049497,6.385797,0.0,0,3.518903,0.0,0.55514371,95.338867,3.5141492,357.68079,-9.284236
4821,4821,165.9139,13.039309,6.409987,0.0,0,3.4993801,0.0,0.55693954,95.160149,3.4942453,357.88708,-9.2832413
4832,4832,165.9161,13.055621,6.4282331,0.0,0,3.4798574,0.0,0.56011093,94.986847,3.4777164,358.04764,-9.2845097
4843,4843,165.9183,13.071371,6.4495773,0.0,0,3.4603345,0.0,0.56138325,94.93512,3.4587791,358.17404,-9.283742
4854,4854,165.9205,13.147193,6.462018,0.0,0,3.4408119,0.0,0.5641377,95.19709,3.4373984,358.30048,-9.2833204
4865,4865,165.9227,13.186218,6.4851003,0.0,0,3.4212892,0.0,0.5657348,95.28064,3.4203291,358.42691,-9.283885
4876,4876,165.9249,13.231045,6.5011792,0.0,0,3.4017661,0.0,0.5688144,95.374397,3.4009988,358.55295,-9.2848644
4887,4887,165.9271,13.289713,6.5260477,0.0,0,3.3822436,0.0,0.57036352,95.631874,3.3815913,358.65942,-9.2851505
4898,4898,165.9293,13.306035,6.538959,0.0,0,3.3627205,0.0,0.57323396,95.524918,3.3622384,358.76587,-9.2839613
4909,4909,165.9315,13.334245,6.5628271,0.0,0,3.3431976,0.0,0.57473779,95.55175,3.344233,358.87234,-9.2844362
4920,4920,165.9337,13.366134,6.5789804,0.0,0,3.3236752,0.0,0.57801193,95.448799,3.3180966,358.97879,-9.2846689
4931,4931,165.9359,13.404355,6.6076822,0.0,0,3.304152,0.0,0.579925,95.559807,3.3009388,359.11917,-9.2852182
4942,4942,165.9381,13.427286,6.6179171,0.0,0,3.2846293,0.0,0.58260071,95.453697,3.2844291,359.29883,-9.284236
4953,4953,165.9403,13.458197,6.6400213,0.0,0,3.2651067,0.0,0.58401233,95.557884,3.2677608,359.47849,-9.2839336
4964,4964,165.9425,13.487417,6.6550341,0.0,0,3.2455838,0.0,0.58716315,95.442139,3.2462263,359.65814,-9.283556
4975,4975,165.9447,13.542906,6.6815796,0.0,0,3.2260611,0.0,0.58874488,95.723511,3.2287896,359.8378,-9.284236
4986,4986,165.9469,13.587168,6.6914425,0.0,0,3.2065382,0.0,0.59141403,95.792221,3.2112401,360.07794,-9.2836828
4997,4997,165.9491,13.65177,6.7148166,0.0,0,3.1870155,0.0,0.59303111,96.054344,3.1883998,360.32413,-9.2836504
5008,5008,165.9513,13.732493,6.73105,0.0,0,3.1674926,0.0,0.59618878,96.285446,3.1689391,360.57034,-9.2845364
5019,5019,165.9535,13.796285,6.76122,0.0,0,3.1479697,0.0,0.59834135,96.533211,3.1500521,360.81653,-9.2842827
5030,5030,165.9557,13.835757,6.7734699,0.0,0,3.1288195,0.0,0.60124511,96.567955,3.1283052,361.03204,-9.2827711
5041,5041,165.9579,13.87855,6.7983007,0.0,0,3.1102469,0.0,0.60314131,96.691833,3.1095166,361.19174,-9.2832127
5052,5052,165.9601,13.910272,6.8118501,0.0,0,3.0916746,0.0,0.60604024,96.568192,3.08866,361.35144,-9.2841158
5063,5063,165.9623,13.952972,6.8438473,0.0,0,3.0731022,0.0,0.60846061,96.671959,3.069803,361.51114,-9.2840652
5074,5074,165.9645,13.968612,6.8530989,0.0,0,3.0545297,0.0,0.61094725,96.558304,3.0515387,361.67081,-9.2831974
5085,5085,165.9667,13.989458,6.8762493,0.0,0,3.0359576,0.0,0.61270785,96.521271,3.0286586,361.80389,-9.2842264
5096,5096,165.9689,14.003892,6.8898602,0.0,0,3.017385,0.0,0.61553717,96.377678,3.0112488,361.93033,-9.2835789
5107,5107,165.9711,14.031026,6.917027,0.0,0,2.9988127,0.0,0.61754805,96.311783,2.992785,362.05673,-9.2832527
5118,5118,165.9733,14.080088,6.9270072,0.0,0,2.9802401,0.0,0.61995602,96.397293,2.9789679,362.18317,-9.2849321
5129,5129,165.9755,14.1497,6.9500251,0.0,0,2.9616678,0.0,0.6220243,96.702927,2.9575989,362.29654,-9.2850142
5140,5140,165.9777,14.196946,6.9651885,0.0,0,2.9430954,0.0,0.62476623,96.767174,2.9388924,362.36972,-9.2842455
5151,5151,165.9799,14.225216,6.995718,0.0,0,2.9245229,0.0,0.62730289,96.743439,2.9185004,362.44293,-9.28333
5162,5162,165.9821,14.237255,7.0023217,0.0,0,2.9059508,0.0,0.62940443,96.633621,2.9029045,362.51611,-9.284255
5173,5173,165.9843,14.249525,7.0232463,0.0,0,2.8873782,0.0,0.63109016,96.528183,2.8846157,362.58932,-9.2844505
5184,5184,165.9865,14.266111,7.0353241,0.0,0,2.8688059,0.0,0.63345903,96.478554,2.868803,362.65503,-9.28409
5195,5195,165.9887,14.304301,7.063406,0.0,0,2.8502333,0.0,0.63601136,96.412827,2.8510685,362.71741,-9.2836351
5206,5206,165.9909,14.356582,7.0737491,0.0,0,2.831661,0.0,0.63828987,96.539307,2.8305838,362.77979,-9.2830381
5217,5217,165.9931,14.42908,7.0955386,0.0,0,2.8130884,0.0,0.64025092,96.798149,2.8143656,362.84216,-9.2844858
5228,5228,165.9953,14.495328,7.1075521,0.0,0,2.7945161,0.0,0.64237595,97.022896,2.7937458,362.90588,-9.2848654
5239,5239,165.9975,14.575379,7.1336627,0.0,0,2.7759438,0.0,0.6449545,97.302139,2.7780449,362.97241,-9.2843838
5250,5250,165.9997,14.631983,7.1470098,0.0,0,2.7573714,0.0,0.64735824,97.528961,2.7598443,363.03894,-9.2835989
5261,5261,166.0019,14.681974,7.1704783,0.0,0,2.7387993,0.0,0.6498574,97.581551,2.7380369,363.10547,-9.2823353
5272,5272,166.0041,14.722088,7.1849055,0.0,0,2.7202265,0.0,0.65219134,97.701942,2.7220206,363.17203,-9.2832651
5283,5283,166.0063,14.752492,7.2123899,0.0,0,2.7022569,0.0,0.65509182,97.602425,2.6999896,363.142,-9.2830715
5294,5294,166.0085,14.791524,7.2255192,0.0,0,2.6845908,0.0,0.65744877,97.600319,2.6820436,363.08212,-9.2828016
5305,5305,166.0107,14.824998,7.246438,0.0,0,2.6669247,0.0,0.65971035,97.563339,2.6625724,363.02225,-9.2831001
5316,5316,166.0129,14.898647,7.2605519,0.0,0,2.6492589,0.0,0.66181147,97.804665,2.6425169,362.96234,-9.2833242
5327,5327,166.0151,14.955673,7.2849412,0.0,0,2.631593,0.0,0.6647287,97.985619,2.6284411,362.90247,-9.2842922
5338,5338,166.0173,14.973043,7.2987385,0.0,0,2.6139269,0.0,0.66673154,97.856552,2.6080704,362.84259,-9.2844725
5349,5349,166.0195,15.005933,7.3176532,0.0,0,2.5962608,0.0,0.66907877,97.852966,2.5926962,362.78268,-9.285264
5360,5360,166.0217,15.017973,7.3285122,0.0,0,2.5785949,0.0,0.67052817,97.823952,2.5744479,362.72281,-9.2846375
5371,5371,166.0239,15.031557,7.353528,0.0,0,2.5609288,0.0,0.67383504,97.593437,2.5568674,362.66293,-9.2838154
5382,5382,166.0261,15.062133,7.367949,0.0,0,2.543263,0.0,0.67563653,97.594742,2.5381372,362.66403,-9.2836199
5393,5393,166.0283,15.104538,7.3849673,0.0,0,2.5255969,0.0,0.67790627,97.649521,2.5217271,362.6973,-9.2835093
5404,5404,166.0305,15.175874,7.3993831,0.0,0,2.5079308,0.0,0.67969555,97.89917,2.5050731,362.73056,-9.2836237
5415,5415,166.0327,15.251874,7.4240165,0.0,0,2.4902649,0.0,0.68326324,98.05983,2.4856584,362.76382,-9.2853727
5426,5426,166.0349,15.347054,7.4379849,0.0,0,2.4725988,0.0,0.68483484,98.417297,2.4681695,362.79111,-9.2842121
5437,5437,166.0371,15.398056,7.4555688,0.0,0,2.4549327,0.0,0.68731344,98.587944,2.4503143,362.7645,-9.2835064
5448,5448,166.0393,15.451263,7.4715476,0.0,0,2.4372668,0.0,0.68905193,98.791969,2.4350588,362.73788,-9.2835302
5459,5459,166.0415,15.497051,7.4949789,0.0,0,2.4196007,0.0,0.69270635,98.710426,2.4157026,362.71127,-9.2834883
5470,5470,166.0437,15.53239,7.5113268,0.0,0,2.4019349,0.0,0.69432437,98.844719,2.3969529,362.68463,-9.2834253
5481,5481,166.0459,15.580855,7.5284925,0.0,0,2.3842688,0.0,0.69724578,98.757912,2.3783674,362.58545,-9.2839317
5492,5492,166.0481,15.64096,7.5463414,0.0,0,2.3666029,0.0,0.69905788,98.982758,2.3593211,362.42575,-9.2822514
5503,5503,166.0503,15.68294,7.568181,0.0,0,2.3489368,0.0,0.7027182,98.87513,2.3405418,362.26605,-9.284194
5514,5514,166.0525,15.716165,7.5831089,0.0,0,2.3312709,0.0,0.70370001,98.976532,2.3253617,362.10635,-9.2840195
5525,5525,166.0547,15.722055,7.595614,0.0,0,2.3136048,0.0,0.70653754,98.768791,2.3099458,361.94669,-9.2834816
5536,5536,166.0569,15.763435,7.6142731,0.0,0,2.2967472,0.0,0.70807743,98.889915,2.2934473,361.60236,-9.2831497
5547,5547,166.0591,15.805612,7.6341171,0.0,0,2.2799437,0.0,0.71167701,98.789932,2.2753639,361.25635,-9.2825632
5558,5558,166.0613,15.87384,7.6525383,0.0,0,2.26314,0.0,0.7131325,99.039848,2.25896,360.91034,-9.2835655
5569,5569,166.0635,15.923407,7.6646829,0.0,0,2.2463365,0.0,0.7157948,99.10096,2.2433333,360.56436,-9.2849369
5580,5580,166.0657,15.981152,7.6812606,0.0,0,2.229533,0.0,0.71707064,99.336685,2.2267938,360.16028,-9.2849302
5591,5591,166.0679,16.052412,7.7002864,0.0,0,2.2127295,0.0,0.72083563,99.410583,2.2061977,359.68118,-9.2851267
5602,5602,166.0701,16.124989,7.7209353,0.0,0,2.1959257,0.0,0.72242719,99.651535,2.1904097,359.20212,-9.2852211
5613,5613,166.0723,16.185514,7.7351923,0.0,0,2.1791222,0.0,0.72555357,99.732841,2.1720073,358.72302,-9.2842741
5624,5624,166.0745,16.223448,7.7503343,0.0,0,2.1623185,0.0,0.72654796,99.913155,2.1576273,358.24393,-9.2842636
5635,5635,166.0767,16.245974,7.765626,0.0,0,2.145515,0.0,0.72997528,99.637711,2.1398821,358.06998,-9.283246
5646,5646,166.0789,16.295557,7.7866082,0.0,0,2.1287112,0.0,0.7314139,99.861282,2.1255734,357.93689,-9.2820959
5657,5657,166.0811,16.348471,7.8012967,0.0,0,2.1119077,0.0,0.73483092,99.80452,2.1075602,357.80383,-9.2838058
5668,5668,166.0833,16.402086,7.8204417,0.0,0,2.095104,0.0,0.73601311,100.02782,2.0907304,357.67075,-9.2833042
5679,5679,166.0855,16.453468,7.8322835,0.0,0,2.0783007,0.0,0.7392652,100.00853,2.0739765,357.44186,-9.2833605
5690,5690,166.0877,16.508816,7.8542862,0.0,0,2.061497,0.0,0.74061882,100.1609,2.0564394,357.01602,-9.2829151
5701,5701,166.0899,16.571754,7.8627601,0.0,0,2.0446935,0.0,0.74351394,100.28755,2.0403838,356.59015,-9.2829161
5712,5712,166.0921,16.632452,7.8853736,0.0,0,2.0278897,0.0,0.74512756,100.5403,2.0237052,356.16431,-9.2821951
5723,5723,166.0943,16.681082,7.8994923,0.0,0,2.0110862,0.0,0.74872416,100.45486,2.0079327,355.73846,-9.2826424
5734,5734,166.0965,16.743849,7.9206095,0.0,0,1.9942826,0.0,0.74981135,100.72491,1.9934274,355.01437,-9.2829189
5745,5745,166.0987,16.848063,7.9318719,0.0,0,1.977479,0.0,0.75319916,100.97164,1.9739428,354.20258,-9.2834778
5756,5756,166.1009,16.916462,7.9527783,0.0,0,1.9606754,0.0,0.75466001,101.26065,1.9578488,353.39081,-9.2818441
5767,5767,166.1031,17.006996,7.9666705,0.0,0,1.9438719,0.0,0.75819725,101.46482,1.9398116,352.57901,-9.2833624
5778,5778,166.1053,17.092495,7.991581,0.0,0,1.9272404,0.0,0.75995272,101.78239,1.9229528,351.86591,-9.2821074
5789,5789,166.1075,17.183916,8.0032673,0.0,0,1.911255,0.0,0.76341724,101.92059,1.9024934,351.50635,-9.2816677
5800,5800,166.1097,17.220764,8.0263157,0.0,0,1.8952699,0.0,0.76517683,102.00092,1.8873073,351.14679,-9.2827883
5811,5811,166.1119,17.251654,8.0398455,0.0,0,1.8792846,0.0,0.76876312,101.86269,1.8690691,350.78726,-9.2822247
5822,5822,166.1141,17.280088,8.0673628,0.0,0,1.8632994,0.0,0.77076751,101.77218,1.8526291,350.4277,-9.282752
5833,5833,166.1163,17.303333,8.0714788,0.0,0,1.8473142,0.0,0.77303624,101.71058,1.8340294,350.45691,-9.2836809
5844,5844,166.1185,17.334894,8.0936165,0.0,0,1.8313291,0.0,0.77495748,101.67709,1.8179832,350.68317,-9.2825413
5855,5855,166.1207,17.367453,8.1062193,0.0,0,1.8153439,0.0,0.77826589,101.54839,1.8051429,350.90939,-9.2833567
5866,5866,166.1229,17.403675,8.1287823,0.0,0,1.7993586,0.0,0.77966291,101.588,1.7891327,351.13565,-9.2830391
5877,5877,166.1251,17.452579,8.131732,0.0,0,1.7833734,0.0,0.78199124,101.63258,1.7741247,351.37933,-9.282712
5888,5888,166.1273,17.520945,8.1537619,0.0,0,1.7673882,0.0,0.78368187,101.83421,1.7579471,351.7655,-9.2823906
5899,5899,166.1295,17.567593,8.1635647,0.0,0,1.751403,0.0,0.78661191,101.91191,1.7428341,352.15167,-9.2828445
5910,5910,166.1317,17.619184,8.1871376,0.0,0,1.7354178,0.0,0.78820509,102.01126,1.7285373,352.53784,-9.2833462
5921,5921,166.1339,17.6658,8.1926346,0.0,0,1.7194326,0.0,0.79085046,101.9902,1.7125074,352.92398,-9.2833338
5932,5932,166.1361,17.716448,8.2147789,0.0,0,1.7034475,0.0,0.79275334,102.11871,1.6991553,353.14767,-9.2820902
5943,5943,166.1383,17.816542,8.2237034,0.0,0,1.6874622,0.0,0.79543829,102.35723,1.6805159,353.24081,-9.283659
5954,5954,166.1405,17.892738,8.2495127,0.0,0,1.6714771,0.0,0.79760313,102.61292,1.6648328,353.33398,-9.2837763
5965,5965,166.1427,17.972,8.2556562,0.0,0,1.6554918,0.0,0.79994202,102.77976,1.6500357,353.42712,-9.283494
5976,5976,166.1449,18.038099,8.2754421,0.0,0,1.6395066,0.0,0.80161726,103.02615,1.6365374,353.52029,-9.2839375
5987,5987,166.1471,18.12825,8.2854395,0.0,0,1.6235213,0.0,0.80439538,103.24879,1.6192734,353.40051,-9.2824965
5998,5998,166.1493,18.181471,8.3112965,0.0,0,1.6075362,0.0,0.8068943,103.32155,1.6020694,353.28076,-9.2843399
6009,6009,166.1515,18.255642,8.3183804,0.0,0,1.5915509,0.0,0.80909377,103.48622,1.5865326,353.16098,-9.2841005
6020,6020,166.1537,18.303255,8.3391352,0.0,0,1.5755658,0.0,0.81135845,103.53321,1.5738051,353.0412,-9.2836866
6031,6031,166.1559,18.36779,8.3477945,0.0,0,1.5599567,0.0,0.81364036,103.65678,1.5578337,352.88586,-9.2837086
6042,6042,166.1581,18.469948,8.3750687,0.0,0,1.5447503,0.0,0.81659603,103.90093,1.5384814,352.68625,-9.2841406
6053,6053,166.1603,18.569553,8.3842859,0.0,0,1.5295439,0.0,0.81903189,104.20354,1.5211594,352.48663,-9.2837801
6064,6064,166.1625,18.642824,8.4055433,0.0,0,1.5143375,0.0,0.8214311,104.39679,1.5061103,352.28702,-9.28335
6075,6075,166.1647,18.693504,8.4146814,0.0,0,1.4991311,0.0,0.82348943,104.44703,1.493129,352.0874,-9.2828836
6086,6086,166.1669,18.719233,8.4395285,0.0,0,1.4839247,0.0,0.82649457,104.30847,1.476408,352.38571,-9.2831364
6097,6097,166.1691,18.739059,8.4460621,0.0,0,1.4687183,0.0,0.82828814,104.26508,1.4571415,352.74503,-9.2835827
6108,6108,166.1713,18.753168,8.4660864,0.0,0,1.4535118,0.0,0.83078957,104.04223,1.4477197,353.10434,-9.2828941
6119,6119,166.1735,18.80389,8.4740944,0.0,0,1.4383055,0.0,0.83237833,104.18132,1.4347314,353.46365,-9.2829294
6130,6130,166.1757,18.90093,8.4959354,0.0,0,1.423099,0.0,0.83528644,104.36588,1.4202096,353.88116,-9.2814083
6141,6141,166.1779,19.00304,8.5028648,0.0,0,1.4078927,0.0,0.83688849,104.76304,1.4039598,354.41348,-9.2829409
6152,6152,166.1801,19.131039,8.5241632,0.0,0,1.3926864,0.0,0.83978319,105.18271,1.3884938,354.9458,-9.2829008
6163,6163,166.1823,19.227325,8.5340395,0.0,0,1.3774799,0.0,0.84140033,105.51257,1.3711755,355.47809,-9.282733
6174,6174,166.1845,19.315746,8.5579491,0.0,0,1.3622735,0.0,0.844926,105.64762,1.3527067,356.01041,-9.2825584
6185,6185,166.1867,19.373562,8.5674419,0.0,0,1.3470671,0.0,0.84673423,105.7885,1.3397453,356.33463,-9.2828102
6196,6196,166.1889,19.387936,8.5881948,0.0,0,1.3318607,0.0,0.84999156,105.55832,1.3245026,356.6008,-9.2825594
6207,6207,166.1911,19.392952,8.5965071,0.0,0,1.3166543,0.0,0.85109937,105.43613,1.3114988,356.86694,-9.2834892
6218,6218,166.1933,19.455881,8.6157112,0.0,0,1.3014479,0.0,0.85419565,105.39663,1.2966858,357.13312,-9.2827835
6229,6229,166.1955,19.55188,8.6250429,0.0,0,1.2862415,0.0,0.85547811,105.81972,1.2779956,356.9025,-9.2841682
6240,6240,166.1977,19.643143,8.6420345,0.0,0,1.2710352,0.0,0.85854834,105.9642,1.2658076,354.98279,-9.283514
6251,6251,166.1999,19.722826,8.654891,0.0,0,1.2558287,0.0,0.86004424,106.26862,1.2502253,353.06308,-9.2843981
6262,6262,166.2021,19.812,8.6748171,0.0,0,1.2406223,0.0,0.86373752,106.29173,1.2330428,351.14337,-9.2839279
6273,6273,166.2043,19.887392,8.6872511,0.0,0,1.2254159,0.0,0.86510611,106.63648,1.2210554,349.22369,-9.2819738
6284,6284,166.2065,19.984636,8.7032394,0.0,0,1.2107713,0.0,0.86832929,106.75946,1.2021322,347.41199,-9.2829084
6295,6295,166.2087,20.067463,8.7180252,0.0,0,1.1963085,0.0,0.86984551,107.08649,1.1877404,345.65283,-9.2833481
6306,6306,166.2109,20.128731,8.7370758,0.0,0,1.1818458,0.0,0.87372327,106.96693,1.1746427,343.89368,-9.2834759
6317,6317,166.2131,20.190382,8.7471352,0.0,0,1.167383,0.0,0.87442935,107.21031,1.1579856,342.13452,-9.2827387
6328,6328,166.2153,20.238041,8.7608786,0.0,0,1.1529201,0.0,0.87762237,107.11131,1.144001,340.5383,-9.2832947
6339,6339,166.2175,20.279984,8.7769642,0.0,0,1.1384574,0.0,0.87924367,107.17047,1.1259086,340.15802,-9.2821779
6350,6350,166.2197,20.326584,8.793294,0.0,0,1.1239946,0.0,0.88312316,107.02322,1.1116917,339.77777,-9.2816753
6361,6361,166.2219,20.373125,8.8069992,0.0,0,1.1095318,0.0,0.88393116,107.15588,1.1004338,339.39749,-9.2825909
6372,6372,166.2241,20.433456,8.8154755,0.0,0,1.0950689,0.0,0.88665527,107.19687,1.0881574,339.01721,-9.2826967
6383,6383,166.2263,20.488243,8.829421,0.0,0,1.0806062,0.0,0.88761097,107.41457,1.0718501,338.41879,-9.2826462
6394,6394,166.2285,20.583096,8.847312,0.0,0,1.0661434,0.0,0.8919251,107.41759,1.0608091,337.65152,-9.2818899
6405,6405,166.2307,20.686056,8.8631678,0.0,0,1.0516806,0.0,0.89282668,107.83287,1.0439563,336.88425,-9.2822542
6416,6416,166.2329,20.828331,8.8700209,0.0,0,1.0372177,0.0,0.8955847,108.27513,1.0314611,336.117,-9.2827034
6427,6427,166.2351,20.910028,8.8846483,0.0,0,1.022755,0.0,0.89650166,108.62801,1.0166126,335.35577,-9.2830105
6438,6438,166.2373,20.998484,8.9029779,0.0,0,1.0082921,0.0,0.90119082,108.55589,1.0006647,335.25555,-9.2815056
6449,6449,166.2395,21.080187,8.9212952,0.0,0,0.99382937,0.0,0.90232706,108.86406,0.98657483,335.15536,-9.282341
6460,6460,166.2417,21.144825,8.9275322,0.0,0,0.97936654,0.0,0.90509576,108.91776,0.97042608,335.05515,-9.281373
6471,6471,166.2439,21.183723,8.9444036,0.0,0,0.96490371,0.0,0.90618336,109.01306,0.95689833,334.95493,-9.2821579
6482,6482,166.2461,21.247578,8.9548817,0.0,0,0.95044094,0.0,0.9098478,108.93343,0.94320309,335.00946,-9.2836723
6493,6493,166.2483,21.285168,8.9741716,0.0,0,0.93597806,0.0,0.9109239,108.98047,0.92707527,335.24966,-9.2828875
6504,6504,166.2505,21.354342,8.9818745,0.0,0,0.92151535,0.0,0.91420841,108.94027,0.91624093,335.4899,-9.2813959
6515,6515,166.2527,21.47699,9.000432,0.0,0,0.90705252,0.0,0.91536707,109.49464,0.90103817,335.7301,-9.2821531
6526,6526,166.2549,21.621504,9.0125322,0.0,0,0.89261615,0.0,0.91933423,109.77091,0.88870424,335.97034,-9.2818899
6537,6537,166.2571,21.723768,9.0327053,0.0,0,0.87885547,0.0,0.92060572,110.136,0.87258023,336.34274,-9.2829275
6548,6548,166.2593,21.795055,9.0400515,0.0,0,0.86510104,0.0,0.92409819,110.12711,0.85921049,336.72983,-9.2833042
6559,6559,166.2615,21.877754,9.0591869,0.0,0,0.85134661,0.0,0.92515332,110.45352,0.84643227,337.11691,-9.2820511
6570,6570,166.2637,21.939095,9.0667667,0.0,0,0.83759224,0.0,0.9284693,110.38583,0.82943499,337.504,-9.2822809
6581,6581,166.2659,22.00799,9.0865126,0.0,0,0.82383782,0.0,0.92948037,110.57457,0.81567997,337.86569,-9.2822371
6592,6592,166.2681,22.092112,9.0946436,0.0,0,0.81008345,0.0,0.93328404,110.59924,0.8025201,338.17926,-9.2815762
6603,6603,166.2703,22.188269,9.1156645,0.0,0,0.79632908,0.0,0.93482751,110.93143,0.79117435,338.4928,-9.2834806
6614,6614,166.2725,22.312513,9.1244497,0.0,0,0.78257465,0.0,0.9384163,111.14796,0.77344233,338.80637,-9.2832527
6625,6625,166.2747,22.428799,9.1479979,0.0,0,0.76882023,0.0,0.93976229,111.56364,0.75826377,339.11993,-9.2827053
6636,6636,166.2769,22.485537,9.1496611,0.0,0,0.7550658,0.0,0.94245046,111.58941,0.74400485,339.68149,-9.2819805
6647,6647,166.2791,22.519789,9.1705685,0.0,0,0.74131143,0.0,0.94428867,111.5423,0.73281956,340.30862,-9.2824144
6658,6658,166.2813,22.557255,9.1765041,0.0,0,0.72755706,0.0,0.94736296,111.39588,0.71775442,340.93573,-9.2827024
6669,6669,166.2835,22.614143,9.19946,0.0,0,0.71380264,0.0,0.94870585,111.51368,0.70262837,341.56287,-9.2824812
6680,6680,166.2857,22.682217,9.2044868,0.0,0,0.70004821,0.0,0.95178443,111.5204,0.69347674,342.21838,-9.2825165
6691,6691,166.2879,22.780352,9.2245445,0.0,0,0.68629384,0.0,0.95363432,111.74654,0.6777916,342.96561,-9.2824841
6702,6702,166.2901,22.88866,9.228878,0.0,0,0.67253947,0.0,0.95619529,111.94592,0.66302669,343.71283,-9.2824078
6713,6713,166.2923,23.012396,9.2506924,0.0,0,0.65878505,0.0,0.95769763,112.41212,0.65500683,344.46002,-9.2820606
6724,6724,166.2945,23.100397,9.2553988,0.0,0,0.64503068,0.0,0.96058887,112.54854,0.63848191,345.20724,-9.2817316
6735,6735,166.2967,23.194094,9.2732468,0.0,0,0.63127625,0.0,0.96207643,112.86816,0.62507159,345.74979,-9.2826347
6746,6746,166.2989,23.284,9.2799854,0.0,0,0.61752182,0.0,0.96506149,112.93755,0.60881871,346.19678,-9.2818565
6757,6757,166.3011,23.392397,9.3058662,0.0,0,0.60376745,0.0,0.96752572,113.17393,0.59550697,346.64377,-9.2825785
6768,6768,166.3033,23.479218,9.3097878,0.0,0,0.59001309,0.0,0.97002357,113.35146,0.58445108,347.09079,-9.2820911
6779,6779,166.3055,23.633522,9.3285351,0.0,0,0.57645869,0.0,0.97186995,113.7856,0.56640804,347.53015,-9.2826138
6790,6790,166.3077,23.763988,9.3342533,0.0,0,0.56336868,0.0,0.97457027,114.11288,0.5515883,347.91708,-9.2816639
6801,6801,166.3099,23.880379,9.3595791,0.0,0,0.55027872,0.0,0.9770633,114.41638,0.53765607,348.30405,-9.2826366
6812,6812,166.3121,23.942005,9.3627729,0.0,0,0.53718871,0.0,0.97925806,114.5067,0.524593,348.69101,-9.2821207
6821,6821,166.3139,23.961594,9.3760042,0.0,0,0.52647871,0.0,0.98086756,114.43485,0.51060814,349.0076,-9.2822037