File: clean data/testID_0251.csv
index,Time(sec),Force(kN),Jaw(mm),PowAngle(deg),Power(W),Pram,PTemp,Strain,Stress(MPa),Stroke(mm),TC1(C),wedge(mm)
2421,195.3733,1.6672465,0.016859381,0.0,0,9.948863,0.0,0.0008772919,20.911812,10.051572,451.96997,-9.2366142
2431,195.3753,2.793308,0.020524835,0.0,0,9.9188633,0.0,0.001315355,35.330627,10.019825,452.51492,-9.2350073
2441,195.3773,3.6562252,0.036177307,0.0,0,9.8888636,0.0,0.0024724542,46.319447,9.9887075,453.05988,-9.2342815
2451,195.3793,3.9501963,0.065386601,0.0,0,9.8588629,0.0,0.0045807757,50.002357,9.9569979,453.74097,-9.2332773
2461,195.3813,4.1366625,0.099419571,0.0,0,9.8288631,0.0,0.0066187587,52.342571,9.924633,454.83047,-9.2326698
2471,195.3833,4.2714071,0.13545167,0.0,0,9.7988634,0.0,0.0088703409,53.809536,9.8895855,455.91998,-9.2324991
2481,195.3853,4.3571801,0.1630947,0.0,0,9.7688637,0.0,0.010739395,54.933746,9.8529415,457.00949,-9.2339582
2491,195.3873,4.4276152,0.1933178,0.0,0,9.7388639,0.0,0.012973137,55.648273,9.8240547,458.099,-9.2342291
2501,195.3893,4.4697456,0.2207749,0.0,0,9.7088633,0.0,0.015020463,56.072075,9.7936592,459.10611,-9.2332726
2511,195.3913,4.5142546,0.25037396,0.0,0,9.6788635,0.0,0.016918708,56.442631,9.7624245,459.86594,-9.2323561
2521,195.3933,4.5517745,0.28289142,0.0,0,9.6488638,0.0,0.018960705,56.823559,9.7334614,460.62579,-9.2323141
2531,195.3953,4.5868788,0.30741349,0.0,0,9.6188631,0.0,0.020542786,57.165337,9.704504,461.38562,-9.2324562
2541,195.3973,4.6062212,0.33676621,0.0,0,9.5888634,0.0,0.022540862,57.395123,9.6761866,462.14545,-9.234004
2551,195.3993,4.6535597,0.36180678,0.0,0,9.5588636,0.0,0.024469463,57.777374,9.6465549,462.81702,-9.2331476
2561,195.4013,4.7048979,0.39584634,0.0,0,9.5288639,0.0,0.026908237,58.285347,9.6116905,463.22369,-9.2335234
2571,195.4033,4.7163539,0.42902929,0.0,0,9.4988632,0.0,0.029142622,58.231922,9.5788546,463.63037,-9.2336683
2581,195.4053,4.7355242,0.45910168,0.0,0,9.4691811,0.0,0.030994572,58.399654,9.5496769,464.03705,-9.2334661
2591,195.4073,4.7399893,0.49339628,0.0,0,9.4399176,0.0,0.033130892,58.284084,9.5172091,464.44373,-9.233037
2601,195.4093,4.7494426,0.51774448,0.0,0,9.4106531,0.0,0.035034034,58.394958,9.4916897,464.8175,-9.2336607
2611,195.4113,4.7663755,0.54757833,0.0,0,9.3813896,0.0,0.037230302,58.417568,9.4604378,465.09259,-9.2328243
2621,195.4133,4.7795205,0.57598096,0.0,0,9.3521252,0.0,0.039313618,58.526699,9.4298077,465.36768,-9.2333679
2631,195.4153,4.7872553,0.60477149,0.0,0,9.3228617,0.0,0.041219238,58.550377,9.4040575,465.64279,-9.2339334
2641,195.4173,4.8137145,0.6376906,0.0,0,9.2935972,0.0,0.043258764,58.702747,9.3711548,465.91788,-9.2349377
2651,195.4193,4.8177094,0.6619361,0.0,0,9.2643328,0.0,0.044915229,58.748867,9.3464613,466.17206,-9.2343855
2661,195.4213,4.8322167,0.69095719,0.0,0,9.2350683,0.0,0.04706021,58.634247,9.3141661,466.36343,-9.234333
2671,195.4233,4.86903,0.71615911,0.0,0,9.2058048,0.0,0.049111333,58.946404,9.2833405,466.55481,-9.2336969
2681,195.4253,4.8919044,0.74804759,0.0,0,9.1765404,0.0,0.05130668,59.149525,9.2549429,466.74619,-9.2330828
2691,195.4273,4.9150195,0.78494287,0.0,0,9.1472769,0.0,0.053603001,59.214134,9.2237167,466.93759,-9.2333984
2701,195.4293,4.9256339,0.81052083,0.0,0,9.1180134,0.0,0.055400375,59.242367,9.1931086,467.10504,-9.2334681
2711,195.4313,4.9285741,0.84233904,0.0,0,9.0887489,0.0,0.057550464,59.275944,9.15903,467.20071,-9.2348795
2721,195.4333,4.9421482,0.86872655,0.0,0,9.0594854,0.0,0.059661098,59.274887,9.1298666,467.29642,-9.2348433
2731,195.4353,4.9427781,0.89663178,0.0,0,9.030221,0.0,0.061854724,59.17276,9.0970726,467.39209,-9.2347212
2741,195.4373,4.9411926,0.9300167,0.0,0,9.0009575,0.0,0.064140365,59.058285,9.0702972,467.48776,-9.2348385
2751,195.4393,4.9375286,0.95576876,0.0,0,8.971693,0.0,0.065755956,58.856556,9.0410252,467.573,-9.2341948
2761,195.4413,4.950511,0.98587239,0.0,0,8.9424286,0.0,0.067612477,58.931488,9.0122929,467.62683,-9.233777
2771,195.4433,4.9631457,1.0084145,0.0,0,8.9131651,0.0,0.069509387,58.967693,8.9859457,467.68066,-9.2340555
2781,195.4453,4.984663,1.0382805,0.0,0,8.8839006,0.0,0.07180994,59.079418,8.9559278,467.73447,-9.2351313
2791,195.4473,5.0174985,1.0671901,0.0,0,8.8546362,0.0,0.074016877,59.403469,8.9254837,467.7883,-9.233449
2801,195.4493,5.034667,1.0971001,0.0,0,8.8253727,0.0,0.075979464,59.463589,8.8907166,467.8526,-9.2339983
2811,195.4513,5.0399499,1.1322223,0.0,0,8.7961092,0.0,0.078200243,59.457153,8.8656416,467.94827,-9.2337551
2821,195.4533,5.0509248,1.1592294,0.0,0,8.7668447,0.0,0.080185898,59.379765,8.8334856,468.04398,-9.234127
2831,195.4553,5.0518069,1.186206,0.0,0,8.7381983,0.0,0.082292423,59.225719,8.8071651,468.13965,-9.2350245
2841,195.4573,5.0619345,1.2113043,0.0,0,8.7103662,0.0,0.084364407,59.187309,8.7761831,468.23532,-9.2340899
2851,195.4593,5.0813875,1.2457906,0.0,0,8.6825333,0.0,0.086850159,59.336681,8.7450027,468.32056,-9.2329359
2861,195.4613,5.0685043,1.2795863,0.0,0,8.6547022,0.0,0.089086227,59.072224,8.7151632,468.37439,-9.2335625
2871,195.4633,5.0731153,1.3011608,0.0,0,8.6268702,0.0,0.090607032,59.077522,8.6876726,468.42822,-9.2357521
2881,195.4653,5.0769053,1.3313895,0.0,0,8.5990381,0.0,0.09274438,58.921284,8.6589613,468.48203,-9.2339487
2891,195.4673,5.0671992,1.3552148,0.0,0,8.5712061,0.0,0.094729796,58.781261,8.6299181,468.53586,-9.234292
2901,195.4693,5.0833721,1.3816745,0.0,0,8.5433741,0.0,0.096743003,58.812237,8.6054993,468.42972,-9.2334929
2911,195.4713,5.0827775,1.412141,0.0,0,8.515542,0.0,0.098941088,58.668709,8.5772095,467.84363,-9.2332621
2921,195.4733,5.1033621,1.4378148,0.0,0,8.48771,0.0,0.10068974,58.921024,8.549942,467.25754,-9.2342682
2931,195.4753,5.1168833,1.4704316,0.0,0,8.459878,0.0,0.10272925,58.796139,8.520484,466.67145,-9.2335796
2941,195.4773,5.1362286,1.4927478,0.0,0,8.4320459,0.0,0.10465237,58.924622,8.4908104,466.08536,-9.2349157
2951,195.4793,5.129076,1.5200331,0.0,0,8.4042158,0.0,0.10690795,58.769917,8.4639368,465.50525,-9.2336617
2961,195.4813,5.1649218,1.5480037,0.0,0,8.3763819,0.0,0.10915512,59.126225,8.4352875,464.94308,-9.2333994
2971,195.4833,5.1679378,1.5769686,0.0,0,8.3485498,0.0,0.11111022,58.870731,8.4033375,464.38092,-9.2326527
2981,195.4853,5.1920428,1.6112554,0.0,0,8.3207188,0.0,0.11343896,59.041004,8.3735657,463.81876,-9.2326899
2991,195.4873,5.1927185,1.6360346,0.0,0,8.2928858,0.0,0.11526024,58.949776,8.3480577,463.25659,-9.2336416
3001,195.4893,5.1792703,1.6630536,0.0,0,8.2650547,0.0,0.11736838,58.682381,8.3191891,462.87234,-9.2342167
3011,195.4913,5.1802115,1.6886541,0.0,0,8.2372227,0.0,0.11963474,58.57803,8.2938557,463.02185,-9.234313
3021,195.4933,5.2028675,1.7171326,0.0,0,8.2093916,0.0,0.12177832,58.680676,8.2613392,463.17136,-9.2336941
3031,195.4953,5.2012691,1.7481718,0.0,0,8.1815586,0.0,0.12390351,58.563877,8.2355318,463.32086,-9.2334843
3041,195.4973,5.2132378,1.7715176,0.0,0,8.1537266,0.0,0.12554616,58.56451,8.2123747,463.4704,-9.2339678
3051,195.4993,5.2352204,1.8018529,0.0,0,8.1258955,0.0,0.12768644,58.689392,8.1824846,463.63037,-9.2340431
3061,195.5013,5.2480493,1.8260562,0.0,0,8.0980625,0.0,0.1297469,58.67189,8.1547718,463.82175,-9.2345715
3071,195.5033,5.2692499,1.8541584,0.0,0,8.0702305,0.0,0.1322118,58.776417,8.1233492,464.01312,-9.2330503
3081,195.5053,5.2715893,1.8856502,0.0,0,8.0429821,0.0,0.13450666,58.674942,8.0934105,464.2045,-9.2324276
3091,195.5073,5.2708302,1.9129243,0.0,0,8.0165014,0.0,0.13629295,58.612701,8.0683756,464.39587,-9.2341309
3101,195.5093,5.2833128,1.944376,0.0,0,7.9900212,0.0,0.13841674,58.603676,8.0377169,464.57413,-9.2340565
3111,195.5113,5.2865658,1.9666656,0.0,0,7.9635415,0.0,0.1403868,58.516708,8.0136423,464.71307,-9.2346153
3121,195.5133,5.3115759,1.995386,0.0,0,7.9370618,0.0,0.14282784,58.672958,7.9817266,464.85202,-9.2324343
3131,195.5153,5.2996626,2.0214279,0.0,0,7.9105816,0.0,0.14504598,58.461548,7.9521523,464.99097,-9.2340269
3141,195.5173,5.2930608,2.0483079,0.0,0,7.8841014,0.0,0.14685902,58.231312,7.926374,465.12991,-9.2332029
3151,195.5193,5.2832913,2.0777466,0.0,0,7.8576217,0.0,0.14887193,58.005119,7.9055924,465.26126,-9.2342739
3161,195.5213,5.2833405,2.0985096,0.0,0,7.831141,0.0,0.15043005,57.811897,7.8748226,465.37488,-9.2339993
3171,195.5233,5.2823353,2.1225126,0.0,0,7.8046613,0.0,0.15239273,57.747932,7.8525238,465.48849,-9.2342291
3181,195.5253,5.3048177,2.1441514,0.0,0,7.7781816,0.0,0.15443054,57.932926,7.8282909,465.60214,-9.234395
3191,195.5273,5.3548265,2.1704321,0.0,0,7.7517014,0.0,0.15654062,58.261204,7.8005667,465.71576,-9.2329731
3201,195.5293,5.3579154,2.2026956,0.0,0,7.7252216,0.0,0.15880643,58.193485,7.7756081,465.84195,-9.232728
3211,195.5313,5.3816676,2.2268364,0.0,0,7.6987414,0.0,0.16054177,58.297417,7.7480764,465.99744,-9.2342405
3221,195.5333,5.4084883,2.2555542,0.0,0,7.6722617,0.0,0.16264023,58.453327,7.7199383,466.15292,-9.2341299
3231,195.5353,5.4269643,2.276942,0.0,0,7.6457815,0.0,0.16456276,58.573395,7.6897731,466.30841,-9.2332478
3241,195.5373,5.4314079,2.3054326,0.0,0,7.6193013,0.0,0.16707614,58.525661,7.6648245,466.4639,-9.2326612
3251,195.5393,5.4473791,2.3344338,0.0,0,7.5928211,0.0,0.16931885,58.618881,7.635375,466.54944,-9.2322178
3261,195.5413,5.4616976,2.3601036,0.0,0,7.5663414,0.0,0.17111704,58.530045,7.6105752,466.47168,-9.233511
3271,195.5433,5.4673815,2.3920469,0.0,0,7.5398612,0.0,0.17329369,58.561291,7.5840087,466.39395,-9.233882
3281,195.5453,5.4716034,2.4133177,0.0,0,7.5133815,0.0,0.17526653,58.531235,7.5550475,466.31619,-9.2332764
3291,195.5473,5.4914865,2.4399283,0.0,0,7.4869013,0.0,0.17764631,58.551117,7.5281968,466.23843,-9.2331133
3301,195.5493,5.5113487,2.4673328,0.0,0,7.4604211,0.0,0.17996587,58.600285,7.497838,466.03333,-9.2322321
3311,195.5513,5.5123968,2.4938648,0.0,0,7.4339414,0.0,0.18187924,58.440578,7.4751263,465.53094,-9.2327557
3321,195.5533,5.5208745,2.5243239,0.0,0,7.4074612,0.0,0.1840163,58.459255,7.448452,465.02859,-9.2339869
3331,195.5553,5.5148892,2.5471199,0.0,0,7.3815403,0.0,0.18581362,58.321278,7.4224472,464.52625,-9.2332535
3341,195.5573,5.5210061,2.5729601,0.0,0,7.3563566,0.0,0.18804578,58.224998,7.3956189,464.0239,-9.2325621
3351,195.5593,5.5263724,2.5925813,0.0,0,7.3311725,0.0,0.18992372,58.141327,7.3673105,463.57178,-9.2327662
3361,195.5613,5.528347,2.6192627,0.0,0,7.3059883,0.0,0.19212808,58.1623,7.3467479,463.23685,-9.233552
3371,195.5633,5.5411687,2.6492386,0.0,0,7.2808042,0.0,0.19437809,58.034698,7.318068,462.90195,-9.234271
3381,195.5653,5.5566716,2.6732955,0.0,0,7.2556205,0.0,0.19607541,58.131393,7.2932138,462.56702,-9.2340384
3391,195.5673,5.5739741,2.7001021,0.0,0,7.2304363,0.0,0.19809066,58.14798,7.2665057,462.23212,-9.233717
3401,195.5693,5.5810318,2.7184663,0.0,0,7.2052522,0.0,0.1999747,58.190136,7.2422781,462.01202,-9.2329206
3411,195.5713,5.6017766,2.7457263,0.0,0,7.1800685,0.0,0.20239706,58.172421,7.2187581,462.05988,-9.2326498
3421,195.5733,5.6066279,2.7719696,0.0,0,7.1548843,0.0,0.2046043,58.317089,7.1917171,462.10773,-9.2339134
3431,195.5753,5.6162634,2.7994344,0.0,0,7.1297007,0.0,0.20651643,58.190456,7.1669145,462.15558,-9.2342911
3441,195.5773,5.6126809,2.8272207,0.0,0,7.104516,0.0,0.20844617,58.015522,7.1435461,462.20343,-9.23347
3451,195.5793,5.6446691,2.8489296,0.0,0,7.0793324,0.0,0.21033847,58.175972,7.1126518,462.25842,-9.2321444
3461,195.5813,5.6648626,2.8742909,0.0,0,7.0541482,0.0,0.21281803,58.366947,7.0908136,462.3302,-9.2326841
3471,195.5833,5.6894073,2.8992865,0.0,0,7.028964,0.0,0.21508779,58.437229,7.0582376,462.40198,-9.2336245
3481,195.5853,5.6980262,2.9261248,0.0,0,7.0037804,0.0,0.21720657,58.366943,7.0362129,462.47372,-9.2335186
3491,195.5873,5.6816158,2.9580007,0.0,0,6.9785962,0.0,0.21947132,58.080093,7.0102143,462.5455,-9.2338057
3501,195.5893,5.6714892,2.9785833,0.0,0,6.9534125,0.0,0.2210875,57.942013,6.9868798,462.62085,-9.2342091
3511,195.5913,5.6771922,3.0050097,0.0,0,6.9282284,0.0,0.22333948,57.854244,6.962491,462.70459,-9.2333422
3521,195.5933,5.6936283,3.0263159,0.0,0,6.9030442,0.0,0.22541681,57.865135,6.9370313,462.7883,-9.2325583
3531,195.5953,5.7049737,3.0503714,0.0,0,6.8778601,0.0,0.2277112,57.828236,6.9078908,462.87204,-9.2327938
3541,195.5973,5.7224917,3.0796342,0.0,0,6.8526764,0.0,0.22992294,57.869522,6.8814001,462.95575,-9.2340078
3551,195.5993,5.7220445,3.1039486,0.0,0,6.8274922,0.0,0.23169179,57.775082,6.8595777,463.06641,-9.2334805
3561,195.6013,5.7240372,3.1303024,0.0,0,6.8023081,0.0,0.23372559,57.723793,6.8334599,463.23984,-9.2331867
3571,195.6033,5.7271805,3.1474266,0.0,0,6.7771239,0.0,0.23540266,57.631165,6.8099108,463.41327,-9.233284
3581,195.6053,5.7507486,3.1737301,0.0,0,6.7524676,0.0,0.23792188,57.738674,6.7835984,463.5867,-9.2332878
3591,195.6073,5.7733378,3.2023556,0.0,0,6.728508,0.0,0.24040885,57.895088,6.7581697,463.76013,-9.2336435
3601,195.6093,5.7746062,3.2266271,0.0,0,6.7045479,0.0,0.24220176,57.79705,6.736465,463.92459,-9.2342834
3611,195.6113,5.7839265,3.2566211,0.0,0,6.6805878,0.0,0.24438089,57.728539,6.7072225,464.06812,-9.232769
3621,195.6133,5.7796102,3.2769141,0.0,0,6.6566281,0.0,0.24619567,57.440521,6.6822839,464.21164,-9.2337656
3631,195.6153,5.7961001,3.2984388,0.0,0,6.632668,0.0,0.24841824,57.59911,6.6565552,464.35519,-9.2340012
3641,195.6173,5.7787108,3.3243129,0.0,0,6.6087079,0.0,0.25082326,57.329403,6.6322646,464.49872,-9.232749
3651,195.6193,5.8003631,3.3495023,0.0,0,6.5847478,0.0,0.25282854,57.361404,6.6082544,464.63864,-9.2341566
3661,195.6213,5.7996101,3.3758378,0.0,0,6.5607882,0.0,0.25474602,57.240196,6.5840964,464.77023,-9.2345295
3671,195.6233,5.7794733,3.3955123,0.0,0,6.536828,0.0,0.25634825,56.956421,6.5582919,464.90179,-9.2344837
3681,195.6253,5.7811403,3.42118,0.0,0,6.5128679,0.0,0.25857309,56.906094,6.5367827,465.03339,-9.2327433
3691,195.6273,5.7763247,3.4387088,0.0,0,6.4889083,0.0,0.26039323,56.721745,6.5171781,465.16495,-9.2327309
3701,195.6293,5.8056669,3.460181,0.0,0,6.4649482,0.0,0.26257753,56.84457,6.4918499,465.31625,-9.2327394
3711,195.6313,5.8249235,3.4865162,0.0,0,6.4409881,0.0,0.26463595,56.944801,6.4706025,465.51361,-9.2344933
3721,195.6333,5.843513,3.511214,0.0,0,6.417028,0.0,0.26652405,57.042282,6.4437675,465.71097,-9.2339582
3731,195.6353,5.8581767,3.537117,0.0,0,6.3930678,0.0,0.26845267,57.008453,6.4248004,465.90833,-9.2328157
3741,195.6373,5.8913455,3.5533824,0.0,0,6.3691082,0.0,0.27021289,57.21365,6.4015346,466.10568,-9.2327709
3751,195.6393,5.9225655,3.5771132,0.0,0,6.3451481,0.0,0.27266032,57.390553,6.3732653,466.28152,-9.2321186
3761,195.6413,5.9410295,3.6050406,0.0,0,6.3211884,0.0,0.2752139,57.4072,6.3492656,466.4071,-9.2343607
3771,195.6433,5.938468,3.6318653,0.0,0,6.2972283,0.0,0.27724907,57.30484,6.3225937,466.53268,-9.2343836
3781,195.6453,5.9410729,3.6585169,0.0,0,6.2732687,0.0,0.27910069,57.207722,6.3015637,466.65826,-9.232563
3791,195.6473,5.9456697,3.677367,0.0,0,6.2493086,0.0,0.28091735,57.183762,6.2751255,466.78384,-9.2321491
3801,195.6493,5.9547997,3.7010276,0.0,0,6.2253485,0.0,0.28338072,56.987988,6.2501049,466.88074,-9.2329903
3811,195.6513,5.9745817,3.7243552,0.0,0,6.2013884,0.0,0.285698,57.154888,6.2250395,466.91064,-9.2329922
3821,195.6533,5.9964347,3.7477994,0.0,0,6.1774282,0.0,0.28772339,57.215702,6.2005968,466.94055,-9.2321339
3831,195.6553,5.9941931,3.7767615,0.0,0,6.1539736,0.0,0.28990939,57.097469,6.1797991,466.97046,-9.2336226
3841,195.6573,6.0183787,3.7979634,0.0,0,6.1311855,0.0,0.29171622,57.199707,6.1512275,467.00037,-9.2331133
3851,195.6593,6.024282,3.8238707,0.0,0,6.1083975,0.0,0.29395172,57.13166,6.1316233,467.06256,-9.2332506
3861,195.6613,6.026403,3.8433526,0.0,0,6.0856099,0.0,0.29608652,57.080917,6.1087747,467.2001,-9.2326946
3871,195.6633,6.0580778,3.8664906,0.0,0,6.0628219,0.0,0.29836607,57.195229,6.0842266,467.33768,-9.2341061
3881,195.6653,6.0590687,3.8942142,0.0,0,6.0400338,0.0,0.3007814,57.075069,6.0568299,467.47522,-9.2334404
3891,195.6673,6.053669,3.9160166,0.0,0,6.0172458,0.0,0.30235186,56.861465,6.0344462,467.61276,-9.2336683
3901,195.6693,6.055016,3.9416056,0.0,0,5.9944577,0.0,0.30429101,56.815125,6.0141821,467.75571,-9.2328892
3911,195.6713,6.0754533,3.9585295,0.0,0,5.9716697,0.0,0.30620292,56.930355,5.9908633,467.91119,-9.2327805
3921,195.6733,6.0958614,3.9814558,0.0,0,5.9488816,0.0,0.30864543,57.043793,5.9671869,468.06668,-9.2328997
3931,195.6753,6.1014977,4.0077772,0.0,0,5.9260936,0.0,0.31121793,56.916618,5.9428926,468.22217,-9.2324514
3941,195.6773,6.0871773,4.0285587,0.0,0,5.903306,0.0,0.31276575,56.682175,5.9224715,468.37766,-9.2339048
3951,195.6793,6.1063385,4.0536385,0.0,0,5.880518,0.0,0.31465265,56.797501,5.9012823,468.46677,-9.2337084
3961,195.6813,6.1133914,4.0728483,0.0,0,5.8577299,0.0,0.31643099,56.751999,5.8804474,468.401,-9.233387
3971,195.6833,6.1438951,4.0943489,0.0,0,5.8349419,0.0,0.31874752,56.806332,5.8536272,468.33521,-9.2329283
3981,195.6853,6.1551323,4.1139541,0.0,0,5.8121538,0.0,0.32093945,56.797028,5.8311424,468.26944,-9.2340221
3991,195.6873,6.18188,4.1396222,0.0,0,5.7893653,0.0,0.32314491,57.017208,5.8105645,468.20364,-9.2345219
4001,195.6893,6.210813,4.167367,0.0,0,5.7665777,0.0,0.32539162,57.064606,5.7867208,468.15759,-9.2341099
4011,195.6913,6.2253561,4.1865807,0.0,0,5.7437897,0.0,0.32698599,57.183193,5.7598071,468.15759,-9.2318659
4021,195.6933,6.2277489,4.21173,0.0,0,5.7210021,0.0,0.32925847,57.055355,5.7375102,468.15759,-9.2319756
4031,195.6953,6.2296162,4.2323136,0.0,0,5.6982141,0.0,0.33148876,56.929047,5.7134204,468.15759,-9.2328672
4041,195.6973,6.2136803,4.2544017,0.0,0,5.675426,0.0,0.33381724,56.664127,5.6910882,468.15759,-9.2332392
4051,195.6993,6.1828647,4.2778745,0.0,0,5.652638,0.0,0.33603394,56.271584,5.6728544,468.18988,-9.2330122
4061,195.7013,6.2088037,4.2977815,0.0,0,5.6298494,0.0,0.33751097,56.458481,5.6485372,468.29755,-9.2332172
4071,195.7033,6.2430916,4.3246212,0.0,0,5.6070614,0.0,0.33955979,56.596748,5.6286135,468.40518,-9.2336226
4081,195.7053,6.2973061,4.3408475,0.0,0,5.5847516,0.0,0.34141126,57.015522,5.6041908,468.51282,-9.2337999
4091,195.7073,6.3088803,4.3635831,0.0,0,5.5630717,0.0,0.34395874,56.919228,5.5794106,468.62048,-9.2333488
4101,195.7093,6.3075242,4.3886671,0.0,0,5.5413914,0.0,0.34656271,56.829395,5.5555043,468.69583,-9.2325764
4111,195.7113,6.2958646,4.4120836,0.0,0,5.519712,0.0,0.34839702,56.573162,5.5317454,468.69583,-9.2331915
4121,195.7133,6.2984886,4.4397187,0.0,0,5.4980316,0.0,0.35054535,56.488621,5.513123,468.69583,-9.2337637
4131,195.7153,6.2943449,4.4528379,0.0,0,5.4763517,0.0,0.35192487,56.429714,5.4886928,468.69583,-9.2319984
4141,195.7173,6.3077431,4.4757729,0.0,0,5.4546719,0.0,0.35427523,56.372849,5.4692235,468.69583,-9.2327337
4151,195.7193,6.3336024,4.4974909,0.0,0,5.4329915,0.0,0.35672751,56.431488,5.4445648,468.66174,-9.2334213
4161,195.7213,6.3471541,4.5185795,0.0,0,5.4113116,0.0,0.35868609,56.508701,5.4229374,468.54813,-9.2338104
4171,195.7233,6.3639283,4.5463276,0.0,0,5.3896313,0.0,0.36100265,56.43877,5.4033837,468.43448,-9.2355013
4181,195.7253,6.3738394,4.5666747,0.0,0,5.3679519,0.0,0.36277509,56.475311,5.3807731,468.32086,-9.2330618
4191,195.7273,6.3856535,4.5907578,0.0,0,5.346272,0.0,0.36489528,56.50946,5.3571119,468.20721,-9.232233
4201,195.7293,6.3832765,4.608757,0.0,0,5.3245916,0.0,0.36719632,56.302368,5.333046,468.06668,-9.2327318
4211,195.7313,6.374742,4.629952,0.0,0,5.3029118,0.0,0.36949208,56.136223,5.3089881,467.86334,-9.2338676
4221,195.7333,6.3616252,4.6528826,0.0,0,5.2812319,0.0,0.37171233,55.913952,5.290946,467.66003,-9.233737
4231,195.7353,6.3535204,4.6740417,0.0,0,5.2595515,0.0,0.37323424,55.666435,5.274622,467.4567,-9.2344007
4241,195.7373,6.3595581,4.6965928,0.0,0,5.2378716,0.0,0.37499058,55.656925,5.2529211,467.25336,-9.2339296
4251,195.7393,6.3864131,4.7110085,0.0,0,5.2161918,0.0,0.37683848,55.756042,5.2327566,467.09845,-9.2328148
4261,195.7413,6.422235,4.7336469,0.0,0,5.1945119,0.0,0.3793323,55.949089,5.2101274,467.05658,-9.2325306
4271,195.7433,6.4234385,4.753417,0.0,0,5.172832,0.0,0.38149157,55.836952,5.1901178,467.01471,-9.2328587
4281,195.7453,6.4658136,4.7761421,0.0,0,5.1511517,0.0,0.3834056,56.094101,5.1658902,466.97284,-9.2339783
4291,195.7473,6.4737234,4.8054442,0.0,0,5.1294718,0.0,0.38583899,56.06366,5.1463594,466.93097,-9.2342815
4301,195.7493,6.4681425,4.8217683,0.0,0,5.1077919,0.0,0.38746762,55.927654,5.1255188,466.96268,-9.2340784
4311,195.7513,6.493804,4.8416605,0.0,0,5.0861115,0.0,0.38962811,55.985355,5.1019278,467.16602,-9.2321548
4321,195.7533,6.5263023,4.8623948,0.0,0,5.0644317,0.0,0.39222023,56.141151,5.0742965,467.36935,-9.2325563
4331,195.7553,6.5611372,4.8870811,0.0,0,5.0432091,0.0,0.3945162,56.246639,5.0517945,467.57269,-9.2338362
4341,195.7573,6.579978,4.9156389,0.0,0,5.0225892,0.0,0.39699557,56.298553,5.0336132,467.77603,-9.2333736
4351,195.7593,6.5916672,4.9357839,0.0,0,5.0019689,0.0,0.39865986,56.265556,5.012455,467.95425,-9.2332878
4361,195.7613,6.5937572,4.9572501,0.0,0,4.9813485,0.0,0.40079427,56.224098,4.9879217,468.07385,-9.2339134
4371,195.7633,6.5751023,4.9747696,0.0,0,4.9607286,0.0,0.40294906,55.982014,4.9674478,468.19348,-9.2340717
4381,195.7653,6.5591764,4.997633,0.0,0,4.9401088,0.0,0.4056499,55.646496,4.9433823,468.31308,-9.2333994
4391,195.7673,6.5623298,5.0207319,0.0,0,4.9194889,0.0,0.40789044,55.593708,4.92693,468.43268,-9.2337599
4401,195.7693,6.5542512,5.0394955,0.0,0,4.898869,0.0,0.40943557,55.442711,4.9065099,468.15033,-9.2335463
4411,195.7713,6.5607657,5.0654168,0.0,0,4.8782492,0.0,0.41135034,55.3092,4.8873806,466.93002,-9.2341137
4421,195.7733,6.5797453,5.0778303,0.0,0,4.8576288,0.0,0.41302136,55.423035,4.861526,465.70969,-9.2336588
4431,195.7753,6.5667133,5.0969353,0.0,0,4.8370085,0.0,0.41538182,55.173519,4.8450575,464.48938,-9.233017
4441,195.7773,6.5773282,5.1150775,0.0,0,4.8163886,0.0,0.4175171,55.227329,4.8288321,463.26907,-9.2337294
4451,195.7793,6.5886822,5.1331906,0.0,0,4.7957687,0.0,0.41905627,55.183041,4.8105245,461.84573,-9.2359695
4461,195.7813,6.6175942,5.1591353,0.0,0,4.7751489,0.0,0.42118254,55.273975,4.787848,459.9487,-9.2337227
4471,195.7833,6.6289201,5.1742878,0.0,0,4.754529,0.0,0.42261067,55.289669,4.7709708,458.05167,-9.2329149
4481,195.7853,6.6669817,5.1946564,0.0,0,4.7339091,0.0,0.42493215,55.484734,4.7493186,456.1546,-9.2336063
4491,195.7873,6.7061505,5.212563,0.0,0,4.7132888,0.0,0.42717075,55.704987,4.7283778,454.25757,-9.2333879
4501,195.7893,6.7564945,5.2339087,0.0,0,4.6926689,0.0,0.4294717,55.95966,4.7049761,452.6799,-9.2342539
4511,195.7913,6.7762198,5.2632866,0.0,0,4.6720486,0.0,0.43214968,56.013577,4.6865449,451.8475,-9.2337627
4521,195.7933,6.7830896,5.2811813,0.0,0,4.6514287,0.0,0.43367586,55.998165,4.6651936,451.01511,-9.2335987
4531,195.7953,6.8163896,5.3039012,0.0,0,4.6308088,0.0,0.43592644,56.093689,4.6436143,450.18271,-9.2333155
4541,195.7973,6.8323002,5.3228765,0.0,0,4.610189,0.0,0.43827602,56.107517,4.6204238,449.35028,-9.2336273
4551,195.7993,6.8448706,5.3438373,0.0,0,4.5895686,0.0,0.44075948,56.079403,4.597928,448.78558,-9.2334414
4561,195.8013,6.8524141,5.3654733,0.0,0,4.5689487,0.0,0.44306988,55.957253,4.5744948,448.84546,-9.2337608
4571,195.8033,6.8449059,5.3890109,0.0,0,4.5483289,0.0,0.44509888,55.837902,4.5547395,448.90536,-9.2345133
4581,195.8053,6.8491073,5.4162951,0.0,0,4.5281415,0.0,0.44738904,55.746437,4.5332189,448.96524,-9.2349482
4591,195.8073,6.8744373,5.4281049,0.0,0,4.5085258,0.0,0.44883263,55.896996,4.5120621,449.02512,-9.234683
4601,195.8093,6.8712564,5.4484835,0.0,0,4.4889092,0.0,0.45143032,55.753765,4.4928102,449.2485,-9.2340651
4611,195.8113,6.8720074,5.4698172,0.0,0,4.4692936,0.0,0.45403832,55.551521,4.4722967,449.85333,-9.2337914
4621,195.8133,6.8894782,5.489974,0.0,0,4.4496775,0.0,0.45587134,55.594101,4.4516826,450.45819,-9.2341671
4631,195.8153,6.8860712,5.5137963,0.0,0,4.4300613,0.0,0.45779926,55.453316,4.4329848,451.06302,-9.2338724
4641,195.8173,6.8878307,5.5311484,0.0,0,4.4104452,0.0,0.45968598,55.399742,4.4111824,451.66785,-9.2342653
4651,195.8193,6.8864093,5.5506978,0.0,0,4.3908296,0.0,0.46182495,55.238209,4.3938017,452.29605,-9.2340832
4661,195.8213,6.899158,5.5637074,0.0,0,4.3712134,0.0,0.46372464,55.282139,4.3706493,452.97873,-9.2337132
4671,195.8233,6.9158659,5.5832639,0.0,0,4.3515973,0.0,0.46599817,55.207493,4.3536282,453.66141,-9.2342834
4681,195.8253,6.8888845,5.6095252,0.0,0,4.3319817,0.0,0.46844909,54.932095,4.3375611,454.34412,-9.2330227
4691,195.8273,6.9314613,5.6261477,0.0,0,4.3123655,0.0,0.46978244,55.224972,4.3183994,455.02679,-9.2335501
4701,195.8293,6.9539542,5.644598,0.0,0,4.2927494,0.0,0.47158781,55.200123,4.2994089,455.62863,-9.2331724
4711,195.8313,6.9956169,5.660327,0.0,0,4.2731338,0.0,0.47371781,55.462597,4.2778544,456.04184,-9.2335653
4721,195.8333,7.0138478,5.6795321,0.0,0,4.2535176,0.0,0.47618672,55.453041,4.2588544,456.45505,-9.2336235
4731,195.8353,7.0311918,5.7026572,0.0,0,4.2339015,0.0,0.4787246,55.494488,4.2400532,456.86823,-9.2343073
4741,195.8373,7.0304904,5.7224298,0.0,0,4.2142854,0.0,0.48041877,55.377346,4.2239585,457.28143,-9.2349062
4751,195.8393,7.0338593,5.7455454,0.0,0,4.1946697,0.0,0.48226374,55.333843,4.2029266,457.62817,-9.2341967
4761,195.8413,7.0513601,5.7596278,0.0,0,4.1750536,0.0,0.48411268,55.344345,4.1822777,457.81976,-9.233779
4771,195.8433,7.0589743,5.7795439,0.0,0,4.1554375,0.0,0.48668399,55.268726,4.1631904,458.01138,-9.2327023
4781,195.8453,7.0877452,5.7980342,0.0,0,4.1358213,0.0,0.48918509,55.325882,4.1434302,458.203,-9.2328157
4791,195.8473,7.1142426,5.8197017,0.0,0,4.1162057,0.0,0.49115399,55.395473,4.1254387,458.39462,-9.234437
4801,195.8493,7.1509538,5.8462491,0.0,0,4.0965896,0.0,0.49353543,55.574535,4.1024384,458.57361,-9.2337046
4811,195.8513,7.1517682,5.8617878,0.0,0,4.0769739,0.0,0.49516094,55.524342,4.0814795,458.72318,-9.2342901
4821,195.8533,7.1764293,5.8827763,0.0,0,4.0573578,0.0,0.49756706,55.582344,4.0627456,458.87274,-9.2330523
4831,195.8553,7.1784654,5.8982525,0.0,0,4.0381556,0.0,0.49989516,55.442463,4.0412159,459.02231,-9.2341223
4841,195.8573,7.1902733,5.9187407,0.0,0,4.0194993,0.0,0.50226581,55.436871,4.0209231,459.17184,-9.2349615
4851,195.8593,7.1997066,5.9448953,0.0,0,4.0008435,0.0,0.50487298,55.338806,4.0008736,459.38599,-9.2348309
4861,195.8613,7.2057099,5.9637527,0.0,0,3.9821873,0.0,0.50645393,55.344933,3.9797599,459.75079,-9.233901
4871,195.8633,7.2142811,5.984602,0.0,0,3.9635313,0.0,0.50852346,55.275154,3.9608727,460.11563,-9.2327623
4881,195.8653,7.2089925,5.997818,0.0,0,3.9448752,0.0,0.5104965,55.08411,3.9402719,460.48044,-9.2336235
4891,195.8673,7.1701646,6.0182953,0.0,0,3.9262192,0.0,0.51322246,54.67268,3.9231002,460.84525,-9.2353125
4901,195.8693,7.1426048,6.0353017,0.0,0,3.9075632,0.0,0.51527685,54.353901,3.9050043,461.21185,-9.2350082
4911,195.8713,7.1416912,6.0525975,0.0,0,3.8889074,0.0,0.51668984,54.273186,3.8925347,461.58264,-9.2342272
4921,195.8733,7.1584797,6.0750089,0.0,0,3.8702514,0.0,0.51852137,54.273235,3.8739536,461.95343,-9.2350206
4931,195.8753,7.2391305,6.0882459,0.0,0,3.8515954,0.0,0.52025801,54.745457,3.8551459,462.32422,-9.2348614
4941,195.8773,7.2520814,6.104794,0.0,0,3.8329396,0.0,0.52251679,54.771366,3.8387759,462.69501,-9.2330456
4951,195.8793,7.3102136,6.1214423,0.0,0,3.8142834,0.0,0.52498555,55.075951,3.8160918,463.04248,-9.2343111
4961,195.8813,7.3689198,6.1423988,0.0,0,3.7956276,0.0,0.52710974,55.317307,3.8015354,463.33551,-9.2342405
4971,195.8833,7.3699846,6.1692638,0.0,0,3.7769713,0.0,0.52955371,55.272663,3.7786155,463.62857,-9.2338924
4981,195.8853,7.3812447,6.1846008,0.0,0,3.7583156,0.0,0.53116089,55.219959,3.7590108,463.92163,-9.2341452
4991,195.8873,7.3851185,6.2063708,0.0,0,3.7396593,0.0,0.53362131,55.122711,3.7401245,464.21466,-9.2343187
5001,195.8893,7.3978519,6.2208176,0.0,0,3.7210035,0.0,0.5359512,55.11763,3.7208903,464.51489,-9.2339764
5011,195.8913,7.4106073,6.2391987,0.0,0,3.7023473,0.0,0.53818375,55.077587,3.7029517,464.83185,-9.2325096
5021,195.8933,7.4350705,6.2634726,0.0,0,3.6836913,0.0,0.54086339,55.113628,3.6838512,465.14883,-9.2338676
5031,195.8953,7.4396062,6.2820511,0.0,0,3.6650355,0.0,0.54239982,55.069885,3.6611907,465.46579,-9.2343988
5041,195.8973,7.4521365,6.3027778,0.0,0,3.6463795,0.0,0.54437596,55.068306,3.6474011,465.78278,-9.2337885
5051,195.8993,7.4561887,6.3166552,0.0,0,3.6277235,0.0,0.54648829,54.966171,3.6257241,466.06744,-9.2335348
5061,195.9013,7.4459596,6.3336053,0.0,0,3.6090674,0.0,0.54885858,54.69598,3.6087816,466.27673,-9.2338476
5071,195.9033,7.4450293,6.3487539,0.0,0,3.5904114,0.0,0.55095214,54.619095,3.5905707,466.48605,-9.2336578
5081,195.9053,7.4427662,6.3686576,0.0,0,3.5721471,0.0,0.55278683,54.546135,3.5737231,466.69537,-9.2340555
5091,195.9073,7.5059781,6.3924699,0.0,0,3.554399,0.0,0.55468535,54.837322,3.5555282,466.90469,-9.2342949
5101,195.9093,7.5387664,6.4043779,0.0,0,3.5366509,0.0,0.55622023,55.018044,3.5374315,467.09607,-9.2356482
5111,195.9113,7.5990233,6.4230814,0.0,0,3.518903,0.0,0.55900651,55.277153,3.5174496,467.24557,-9.233489
5121,195.9133,7.6311035,6.4408846,0.0,0,3.5011549,0.0,0.56157076,55.382008,3.5025675,467.39508,-9.2327442
5131,195.9153,7.6641679,6.4596648,0.0,0,3.483407,0.0,0.56360686,55.45639,3.4843466,467.54459,-9.2336693
5141,195.9173,7.6735425,6.4849792,0.0,0,3.4656589,0.0,0.56600153,55.433479,3.4655926,467.69412,-9.2331762
5151,195.9193,7.6802711,6.5009117,0.0,0,3.4479113,0.0,0.56766325,55.466412,3.4439168,467.84363,-9.2337618
5161,195.9213,7.7032704,6.5212917,0.0,0,3.4301629,0.0,0.57008302,55.450222,3.4269042,467.99313,-9.2335043
5171,195.9233,7.7015996,6.5340123,0.0,0,3.412415,0.0,0.57216436,55.362865,3.4074249,468.14264,-9.2333193
5181,195.9253,7.6896787,6.5522995,0.0,0,3.3946671,0.0,0.57470322,55.125778,3.3897109,468.29214,-9.2331228
5191,195.9273,7.6862164,6.5745187,0.0,0,3.376919,0.0,0.57701981,54.90181,3.3711483,468.44168,-9.2328148
5201,195.9293,7.7006688,6.5898209,0.0,0,3.3591712,0.0,0.57826346,55.023144,3.3581395,468.5553,-9.2336407
5211,195.9313,7.6948471,6.6095295,0.0,0,3.3414228,0.0,0.5802213,54.839283,3.3423789,468.58521,-9.2339878
5221,195.9333,7.7259216,6.6216254,0.0,0,3.3236752,0.0,0.58226097,54.913094,3.3224492,468.61511,-9.2337198
5231,195.9353,7.7193441,6.639801,0.0,0,3.3059268,0.0,0.58487487,54.800209,3.3014174,468.64499,-9.2331343
5241,195.9373,7.7441988,6.6538424,0.0,0,3.2881792,0.0,0.58680493,54.839539,3.2890866,468.6749,-9.2312288
5251,195.9393,7.7767959,6.6728196,0.0,0,3.270431,0.0,0.58860183,54.933331,3.2729247,468.57922,-9.2328148
5261,195.9413,7.8081341,6.6967649,0.0,0,3.2526829,0.0,0.59083939,55.105762,3.2562678,468.19049,-9.2347555
5271,195.9433,7.8497286,6.709291,0.0,0,3.234935,0.0,0.59236038,55.300861,3.2327008,467.80176,-9.2341795
5281,195.9453,7.92273,6.7241335,0.0,0,3.2171869,0.0,0.59468937,55.681358,3.2156413,467.41302,-9.2341814
5291,195.9473,7.9505405,6.7433829,0.0,0,3.199439,0.0,0.59759796,55.707409,3.2007203,467.02429,-9.2329769
5301,195.9493,7.9660559,6.7632313,0.0,0,3.1816909,0.0,0.59988701,55.658672,3.1834185,466.58353,-9.2333241
5311,195.9513,7.9855628,6.7889209,0.0,0,3.1639431,0.0,0.60223281,55.643139,3.1619217,466.02136,-9.2353983
5321,195.9533,7.9992661,6.8011999,0.0,0,3.1461952,0.0,0.60353041,55.711422,3.1450126,465.4592,-9.2333975
5331,195.9553,7.9916911,6.822885,0.0,0,3.1288195,0.0,0.60624468,55.516098,3.1252043,464.89703,-9.2332525
5341,195.9573,7.9813905,6.8365645,0.0,0,3.1119354,0.0,0.6085965,55.379887,3.1070645,464.33487,-9.233799
5351,195.9593,7.9533725,6.8547111,0.0,0,3.0950513,0.0,0.61114341,54.972782,3.0891025,463.89468,-9.2335043
5361,195.9613,7.9727654,6.873394,0.0,0,3.0781677,0.0,0.61334229,55.019531,3.0734127,463.7392,-9.2343807
5371,195.9633,7.9572997,6.8877258,0.0,0,3.0612833,0.0,0.61435139,54.884132,3.0560207,463.58371,-9.2343445
5381,195.9653,8.017333,6.9106855,0.0,0,3.0443995,0.0,0.61667991,55.129395,3.0425477,463.42822,-9.2344599
5391,195.9673,8.0505915,6.919529,0.0,0,3.0275152,0.0,0.61836857,55.235168,3.0194492,463.27274,-9.2335739
5401,195.9693,8.0826883,6.9365144,0.0,0,3.0106313,0.0,0.62104428,55.330925,3.0068207,463.16208,-9.2339058
5411,195.9713,8.0771961,6.9533267,0.0,0,2.9937477,0.0,0.62338531,55.153965,2.9907064,463.1561,-9.2342873
5421,195.9733,8.0955496,6.9723763,0.0,0,2.9768634,0.0,0.62531734,55.155533,2.9758263,463.15012,-9.2345619
5431,195.9753,8.0995054,6.9957781,0.0,0,2.9599793,0.0,0.62744397,55.136551,2.9547465,463.14413,-9.2349043
5441,195.9773,8.1058874,7.0056877,0.0,0,2.9430954,0.0,0.62878734,55.091911,2.9366908,463.13815,-9.2340775
5451,195.9793,8.1084461,7.0225239,0.0,0,2.9262114,0.0,0.63133025,54.957161,2.9217069,463.15372,-9.2330828
5461,195.9813,8.1262255,7.0362716,0.0,0,2.9093275,0.0,0.63367641,54.890881,2.9048667,463.21948,-9.2341862
5471,195.9833,8.1481218,7.0537643,0.0,0,2.8924434,0.0,0.6357339,54.970497,2.8892252,463.28528,-9.2342882
5481,195.9853,8.1946592,7.0751643,0.0,0,2.8755593,0.0,0.63802379,55.117954,2.87164,463.35104,-9.2345438
5491,195.9873,8.2232342,7.0915914,0.0,0,2.8586755,0.0,0.63969302,55.205929,2.8583591,463.41684,-9.2335901
5501,195.9893,8.2376909,7.1081281,0.0,0,2.8417914,0.0,0.6416871,55.282394,2.8425572,463.56876,-9.2346973
5511,195.9913,8.2764797,7.1194415,0.0,0,2.8249075,0.0,0.64369464,55.359428,2.8229833,463.9216,-9.2323494
5521,195.9933,8.3019772,7.1372466,0.0,0,2.8080232,0.0,0.64655447,55.414726,2.8046741,464.27448,-9.2349968
5531,195.9953,8.3306103,7.1606536,0.0,0,2.7911394,0.0,0.64933902,55.399696,2.7873397,464.62732,-9.2359266
5541,195.9973,8.3647633,7.1782007,0.0,0,2.7742555,0.0,0.65094405,55.602077,2.7771497,464.98016,-9.2340288
5551,195.9993,8.3845873,7.1995616,0.0,0,2.7573714,0.0,0.65299737,55.576019,2.7548292,465.32227,-9.233427
5561,196.0013,8.4108057,7.2101479,0.0,0,2.7404876,0.0,0.65496898,55.629517,2.7364917,465.63922,-9.2330828
5571,196.0033,8.3969908,7.2276802,0.0,0,2.7236035,0.0,0.65775108,55.387501,2.7179563,465.95618,-9.2332716
5581,196.0053,8.3824558,7.245513,0.0,0,2.7070749,0.0,0.66041625,55.190052,2.7036991,466.27313,-9.2352009
5591,196.0073,8.4103136,7.2609878,0.0,0,2.6910148,0.0,0.66184384,55.228519,2.6886053,466.59012,-9.2328606
5601,196.0093,8.4249763,7.2846918,0.0,0,2.6749549,0.0,0.66419691,55.225426,2.6700256,466.85684,-9.232173
5611,196.0113,8.4426374,7.297296,0.0,0,2.658895,0.0,0.66579288,55.237415,2.6543374,467.00635,-9.2330151
5621,196.0133,8.4960394,7.3092847,0.0,0,2.6428349,0.0,0.66792959,55.43198,2.6399083,467.15585,-9.23454
5631,196.0153,8.5020218,7.32267,0.0,0,2.626775,0.0,0.67036873,55.375561,2.6207297,467.30536,-9.2344532
5641,196.0173,8.5266247,7.3407421,0.0,0,2.6107149,0.0,0.67267102,55.370884,2.6057167,467.4549,-9.235178
5651,196.0193,8.5523481,7.3630009,0.0,0,2.5946548,0.0,0.67510796,55.406742,2.5904965,467.56671,-9.2340498
5661,196.0213,8.5823574,7.3766127,0.0,0,2.5785949,0.0,0.67632169,55.518143,2.5732052,467.59064,-9.2336979
5671,196.0233,8.5839901,7.3954511,0.0,0,2.5625348,0.0,0.67878532,55.490234,2.5562544,467.61456,-9.2329226
5681,196.0253,8.6054955,7.4072714,0.0,0,2.5464747,0.0,0.68081445,55.511692,2.5412145,467.63849,-9.2319994
5691,196.0273,8.624651,7.4208202,0.0,0,2.5304148,0.0,0.68330419,55.455647,2.5263386,467.66238,-9.2323895
5701,196.0293,8.6124516,7.4412484,0.0,0,2.5143549,0.0,0.68587458,55.225941,2.5110571,467.68991,-9.2339735
5711,196.0313,8.6210728,7.4564586,0.0,0,2.4982948,0.0,0.68714398,55.174747,2.4949408,467.7258,-9.2351122
5721,196.0333,8.6574354,7.4772196,0.0,0,2.482235,0.0,0.68928951,55.315918,2.477562,467.76169,-9.2344809
5731,196.0353,8.7169542,7.4877653,0.0,0,2.4661748,0.0,0.69114518,55.55619,2.4626203,467.79758,-9.2330198
5741,196.0373,8.751586,7.4990778,0.0,0,2.4501147,0.0,0.69336933,55.662388,2.4448817,467.83347,-9.2323303
5751,196.0393,8.7824316,7.5142279,0.0,0,2.4340549,0.0,0.69569308,55.767212,2.429656,467.90164,-9.2344437
5761,196.0413,8.8293438,7.5343242,0.0,0,2.4179947,0.0,0.69789088,55.965279,2.4165907,468.04517,-9.2335443
5771,196.0433,8.868576,7.5550494,0.0,0,2.4019349,0.0,0.69995219,56.052494,2.3998127,468.18869,-9.2337017
5781,196.0453,8.9007502,7.5684299,0.0,0,2.3858747,0.0,0.70169055,56.196053,2.3823311,468.33224,-9.2327223
5791,196.0473,8.9311371,7.5841608,0.0,0,2.3698149,0.0,0.70415139,56.217861,2.3609092,468.47577,-9.2319145
5801,196.0493,8.9410353,7.5968595,0.0,0,2.3537548,0.0,0.70671159,56.129253,2.3479793,468.465,-9.2339602
5811,196.0513,8.9418268,7.6154327,0.0,0,2.3376949,0.0,0.70939475,56.000351,2.333322,468.09421,-9.2338533
5821,196.0533,8.9595814,7.6380858,0.0,0,2.3216348,0.0,0.71181226,55.981037,2.3150287,467.72342,-9.2336884
5831,196.0553,9.008522,7.6500893,0.0,0,2.3059127,0.0,0.71284711,56.196896,2.3000345,467.3526,-9.2331495
5841,196.0573,9.0486393,7.6669164,0.0,0,2.2906368,0.0,0.71500456,56.34127,2.2860298,466.98181,-9.233037
5851,196.0593,9.0743122,7.6787748,0.0,0,2.2753608,0.0,0.71724159,56.379395,2.2692521,466.02023,-9.2333965
5861,196.0613,9.0816336,7.6953921,0.0,0,2.2600849,0.0,0.72008413,56.270924,2.2512286,463.68011,-9.2342043
5871,196.0633,9.0738401,7.7139869,0.0,0,2.2448089,0.0,0.72266656,56.067696,2.2380726,461.34,-9.2346621
5881,196.0653,9.0871744,7.7298703,0.0,0,2.229533,0.0,0.7241354,56.082779,2.2205064,458.99988,-9.2328262
5891,196.0673,9.1339264,7.7491136,0.0,0,2.214257,0.0,0.72607738,56.256081,2.2039101,456.65979,-9.2335443
5901,196.0693,9.1558094,7.7589912,0.0,0,2.198981,0.0,0.7277984,56.277401,2.1890552,453.97751,-9.2328939
5911,196.0713,9.160594,7.7723136,0.0,0,2.1837049,0.0,0.73028362,56.179989,2.1741438,450.49686,-9.2327604
5921,196.0733,9.1668606,7.7876916,0.0,0,2.1684289,0.0,0.73304939,56.110023,2.1614671,447.01617,-9.2336121
5931,196.0753,9.1707754,7.803864,0.0,0,2.1531529,0.0,0.73481315,56.042152,2.1465225,443.53552,-9.2336369
5941,196.0773,9.1950073,7.8255501,0.0,0,2.1378767,0.0,0.73702937,56.051605,2.1295466,440.05487,-9.2336559
5951,196.0793,9.2073488,7.8360128,0.0,0,2.1226008,0.0,0.7383042,56.041393,2.1181192,436.94351,-9.2340727
5961,196.0813,9.2328768,7.8487186,0.0,0,2.1073248,0.0,0.74033785,56.096073,2.1027217,434.69382,-9.23452
5971,196.0833,9.2649031,7.8610811,0.0,0,2.0920489,0.0,0.74297881,56.155174,2.0887241,432.44415,-9.2339134
5981,196.0853,9.3043156,7.8756599,0.0,0,2.0767729,0.0,0.74524486,56.230827,2.0736611,430.19449,-9.2336168
5991,196.0873,9.34793,7.8972888,0.0,0,2.061497,0.0,0.74757266,56.354092,2.0599582,427.94479,-9.23489
6001,196.0893,9.4055672,7.9102883,0.0,0,2.046221,0.0,0.74894047,56.642715,2.0439973,426.44919,-9.2337828
6011,196.0913,9.4405222,7.9278393,0.0,0,2.0309451,0.0,0.75119728,56.730366,2.0268543,426.7131,-9.233593
6021,196.0933,9.4595842,7.939611,0.0,0,2.0156689,0.0,0.75351143,56.734303,2.0101957,426.97699,-9.2328005
6031,196.0953,9.4952459,7.9546986,0.0,0,2.0003929,0.0,0.75627643,56.774296,1.9932547,427.24091,-9.2340221
6041,196.0973,9.5078964,7.9721708,0.0,0,1.985117,0.0,0.75880337,56.715374,1.9783006,427.50482,-9.2344379
6051,196.0993,9.5245638,7.9888611,0.0,0,1.969841,0.0,0.7604664,56.762753,1.96178,428.03348,-9.2335396
6061,196.1013,9.5440483,8.0109806,0.0,0,1.954565,0.0,0.76273984,56.693138,1.9455297,429.1799,-9.2329369
6071,196.1033,9.5384512,8.0169611,0.0,0,1.939289,0.0,0.76402497,56.597794,1.9345087,430.32635,-9.2321911
6081,196.1053,9.5546026,8.0330009,0.0,0,1.9243339,0.0,0.7670548,56.551785,1.9174159,431.47278,-9.2322311
6091,196.1073,9.5870886,8.0467281,0.0,0,1.9098018,0.0,0.76969165,56.565289,1.8999734,432.6192,-9.2334929
6101,196.1093,9.6164818,8.0616875,0.0,0,1.8952699,0.0,0.77132434,56.68948,1.8873935,433.52789,-9.2357349
6111,196.1113,9.6365242,8.0833874,0.0,0,1.8807379,0.0,0.7736178,56.607685,1.8728496,433.88174,-9.2340336
6121,196.1133,9.6786232,8.0961657,0.0,0,1.8662058,0.0,0.77532071,56.726196,1.8551921,434.23563,-9.2325735
6131,196.1153,9.6948137,8.1060181,0.0,0,1.8516738,0.0,0.77699924,56.790173,1.8434395,434.58948,-9.2331982
6141,196.1173,9.718935,8.1164637,0.0,0,1.8371419,0.0,0.77951646,56.781803,1.8292645,434.94336,-9.2338772
6151,196.1193,9.7357912,8.1358299,0.0,0,1.8226099,0.0,0.7824806,56.695686,1.8131049,435.23425,-9.2338209
6161,196.1213,9.7469759,8.154644,0.0,0,1.8080778,0.0,0.78461105,56.663445,1.7964151,435.3782,-9.234272
6171,196.1233,9.767539,8.1670666,0.0,0,1.7935458,0.0,0.78584242,56.700768,1.7829632,435.52216,-9.2330809
6181,196.1253,9.7974434,8.1824751,0.0,0,1.7790139,0.0,0.78774524,56.7486,1.7705288,435.66608,-9.2320366
6191,196.1273,9.8364229,8.193018,0.0,0,1.7644818,0.0,0.78992319,56.8176,1.7575225,435.81003,-9.2318668
6201,196.1293,9.8485165,8.2078123,0.0,0,1.7499498,0.0,0.79291272,56.73296,1.740523,436.06375,-9.2329836
6211,196.1313,9.8753376,8.2222385,0.0,0,1.7354178,0.0,0.79508907,56.743607,1.7305418,436.57355,-9.2349033
6221,196.1333,9.8922281,8.2387342,0.0,0,1.7208858,0.0,0.79676145,56.754303,1.7143563,437.08337,-9.2345629
6231,196.1353,9.9237766,8.2587776,0.0,0,1.7063538,0.0,0.79877049,56.82032,1.7004027,437.59317,-9.2354422
6241,196.1373,9.9455242,8.2653437,0.0,0,1.6918218,0.0,0.8001377,56.888004,1.6869339,438.103,-9.233943
6251,196.1393,9.9983788,8.2782335,0.0,0,1.6772897,0.0,0.80277777,57.002281,1.6720948,438.80515,-9.2339144
6261,196.1413,10.046802,8.2904081,0.0,0,1.6627578,0.0,0.80539453,57.176414,1.6631763,439.95609,-9.2331409
6271,196.1433,10.083127,8.3062019,0.0,0,1.6482258,0.0,0.807284,57.282467,1.6487789,441.10699,-9.2327223
6281,196.1453,10.168821,8.3278666,0.0,0,1.6336937,0.0,0.80977678,57.612061,1.63068,442.25793,-9.233551
6291,196.1473,10.232633,8.3395958,0.0,0,1.6191618,0.0,0.8111096,57.86269,1.6153171,443.40884,-9.2341928
6301,196.1493,10.295936,8.3561697,0.0,0,1.6046298,0.0,0.81389099,58.080566,1.5947931,444.50565,-9.2325554
6311,196.1513,10.317365,8.3660641,0.0,0,1.5900977,0.0,0.81634766,58.059631,1.5853291,445.47617,-9.2333546
6321,196.1533,10.358461,8.3810425,0.0,0,1.5755658,0.0,0.81893104,58.14019,1.5713866,446.44669,-9.2342167
6331,196.1553,10.385527,8.4038029,0.0,0,1.561339,0.0,0.82184595,58.110405,1.5553904,447.41718,-9.2347193
6341,196.1573,10.418889,8.4180689,0.0,0,1.547515,0.0,0.82324678,58.187244,1.5377918,448.3877,-9.2332582
6351,196.1593,10.457058,8.4357414,0.0,0,1.5336912,0.0,0.82549524,58.276421,1.5203203,449.26108,-9.2325373
6361,196.1613,10.458387,8.4425087,0.0,0,1.5198671,0.0,0.8273288,58.193352,1.5106709,449.90784,-9.2329702
6371,196.1633,10.486892,8.4583578,0.0,0,1.506043,0.0,0.83050895,58.18959,1.4965074,450.5546,-9.2336597
6381,196.1653,10.512316,8.4747219,0.0,0,1.4922191,0.0,0.83311373,58.134556,1.4799322,451.20135,-9.2334661
6391,196.1673,10.538235,8.4897194,0.0,0,1.478395,0.0,0.83473575,58.212196,1.4647882,451.84811,-9.2333145
6401,196.1693,10.552843,8.5112019,0.0,0,1.4645711,0.0,0.8370921,58.173107,1.451244,452.45535,-9.2334776
6411,196.1713,10.561245,8.5178347,0.0,0,1.4507471,0.0,0.83829552,58.17757,1.4382063,452.97034,-9.233634
6421,196.1733,10.576053,8.5300083,0.0,0,1.4369231,0.0,0.84107697,58.040955,1.4210892,453.48535,-9.2339382
6431,196.1753,10.590058,8.541564,0.0,0,1.423099,0.0,0.84347546,57.969288,1.4087112,454.00034,-9.2354507
6441,196.1773,10.596731,8.5556669,0.0,0,1.4092751,0.0,0.84544337,57.941956,1.3982265,454.51535,-9.2348747
6451,196.1793,10.607655,8.5753307,0.0,0,1.3954511,0.0,0.84741491,57.846397,1.3871436,454.96747,-9.2322598
6461,196.1813,10.619831,8.5824528,0.0,0,1.3816271,0.0,0.84823835,57.890064,1.3699358,455.27289,-9.232914
6471,196.1833,10.635167,8.5972939,0.0,0,1.3678031,0.0,0.85084116,57.844357,1.3572611,455.57831,-9.23419
6481,196.1853,10.687127,8.6066523,0.0,0,1.3539791,0.0,0.85315675,57.985592,1.3431088,455.88373,-9.234148
6491,196.1873,10.74791,8.6187811,0.0,0,1.3401551,0.0,0.85551941,58.157692,1.3335905,456.18915,-9.2329865
6501,196.1893,10.813242,8.6353464,0.0,0,1.3263311,0.0,0.85763615,58.346645,1.3174025,456.41913,-9.233139
6511,196.1913,10.88143,8.6505108,0.0,0,1.3125072,0.0,0.85922045,58.637997,1.3069587,456.47302,-9.2340727
6521,196.1933,10.947446,8.6668587,0.0,0,1.2986832,0.0,0.86135733,58.91132,1.2911863,456.52692,-9.2339382
6531,196.1953,11.023636,8.6765671,0.0,0,1.2848592,0.0,0.86367953,59.202393,1.2773254,456.58081,-9.2341404
6541,196.1973,11.081645,8.6880903,0.0,0,1.2710352,0.0,0.86612362,59.352558,1.2639443,456.6347,-9.234272
6551,196.1993,11.132056,8.7039843,0.0,0,1.2572112,0.0,0.86890519,59.455837,1.246963,456.67783,-9.2327738
6561,196.2013,11.15005,8.7229128,0.0,0,1.2433872,0.0,0.87130606,59.421192,1.2323687,456.69577,-9.2332821
6571,196.2033,11.153026,8.7406588,0.0,0,1.2295632,0.0,0.8730948,59.32703,1.2187108,456.71375,-9.2332373
6581,196.2053,11.155187,8.7481441,0.0,0,1.2160306,0.0,0.87446934,59.260201,1.203665,456.73172,-9.2326431
6591,196.2073,11.164638,8.7618437,0.0,0,1.2028826,0.0,0.87743634,59.100418,1.1865557,456.74969,-9.2336006
6601,196.2093,11.134443,8.7730799,0.0,0,1.1897346,0.0,0.88008589,58.812382,1.1788709,456.82693,-9.2336664
6611,196.2113,11.113203,8.7872019,0.0,0,1.1765865,0.0,0.88193327,58.620785,1.1664549,457.04251,-9.2328644
6621,196.2133,11.148637,8.8053122,0.0,0,1.1634386,0.0,0.88398618,58.605011,1.1535012,457.25812,-9.2327557
6631,196.2153,11.155569,8.8142948,0.0,0,1.1502906,0.0,0.88523412,58.627403,1.1417139,457.47369,-9.2330666
6641,196.2173,11.197699,8.8274231,0.0,0,1.1371425,0.0,0.88731533,58.718781,1.128986,457.68927,-9.2325811
6651,196.2193,11.224758,8.8328238,0.0,0,1.1239946,0.0,0.88920194,58.749088,1.1185474,457.91022,-9.2334452
6661,196.2213,11.288047,8.8468399,0.0,0,1.1108466,0.0,0.89190239,58.936024,1.1086555,458.14365,-9.2341347
6671,196.2233,11.330907,8.8664646,0.0,0,1.0976987,0.0,0.8947171,58.987545,1.0950266,458.37708,-9.2333193
6681,196.2253,11.408986,8.8775129,0.0,0,1.0845505,0.0,0.89553368,59.319256,1.0774539,458.6105,-9.2332449
6691,196.2273,11.474559,8.8963566,0.0,0,1.0714027,0.0,0.89790726,59.541187,1.0686669,458.84393,-9.2333202
6701,196.2293,11.548594,8.9029551,0.0,0,1.0582546,0.0,0.89992577,59.772583,1.0537283,459.0181,-9.2342024
6711,196.2313,11.583173,8.9140091,0.0,0,1.0451066,0.0,0.90239185,59.852802,1.0407232,459.05402,-9.2345085
6721,196.2333,11.633905,8.9292316,0.0,0,1.0319586,0.0,0.90556985,59.917645,1.0284986,459.0899,-9.2341604
6731,196.2353,11.691357,8.9448853,0.0,0,1.0188106,0.0,0.90746772,60.052616,1.010149,459.12582,-9.2323647
6741,196.2373,11.698835,8.9632196,0.0,0,1.0056624,0.0,0.90916985,59.990536,0.99627274,459.16171,-9.2335281
6751,196.2393,11.748317,8.9728374,0.0,0,0.99251461,0.0,0.91101182,60.175293,0.98044604,459.16354,-9.2337418
6761,196.2413,11.757883,8.9851618,0.0,0,0.97936654,0.0,0.91360021,60.070396,0.96872401,459.08578,-9.2335501
6771,196.2433,11.754282,8.995244,0.0,0,0.96621853,0.0,0.91641772,59.830841,0.9560973,459.00806,-9.2340336
6781,196.2453,11.740275,9.008626,0.0,0,0.95307052,0.0,0.91854912,59.689747,0.94357741,458.9303,-9.2335148
6791,196.2473,11.7703,9.0275755,0.0,0,0.93992251,0.0,0.92067409,59.650272,0.93007219,458.85254,-9.2327557
6801,196.2493,11.786296,9.0394897,0.0,0,0.92677456,0.0,0.92204392,59.653072,0.91952091,458.82324,-9.2327423
6811,196.2513,11.809004,9.049758,0.0,0,0.91362649,0.0,0.92383659,59.671265,0.90494734,458.90698,-9.2333393
6821,196.2533,11.836934,9.0562487,0.0,0,0.90047848,0.0,0.9259299,59.692249,0.8944779,458.99069,-9.2334862
6831,196.2553,11.871802,9.0707512,0.0,0,0.88760823,0.0,0.92898291,59.694878,0.88381577,459.07443,-9.2335625
6841,196.2573,11.920458,9.0850687,0.0,0,0.87510419,0.0,0.93112379,59.802708,0.86817467,459.15814,-9.2329216
6851,196.2593,11.968899,9.0985136,0.0,0,0.86260027,0.0,0.93240947,59.958729,0.8579945,459.23651,-9.2327127
6861,196.2613,12.066872,9.1126375,0.0,0,0.85009623,0.0,0.93404621,60.360832,0.8434093,459.30231,-9.232295
6871,196.2633,12.153611,9.1217108,0.0,0,0.83759224,0.0,0.93644136,60.677017,0.82871163,459.36807,-9.2330408
6881,196.2653,12.238916,9.1329031,0.0,0,0.8250882,0.0,0.93912184,60.921604,0.81638062,459.43387,-9.2343082
6891,196.2673,12.293507,9.145998,0.0,0,0.81258422,0.0,0.9418695,61.029877,0.80092287,459.49966,-9.2334023
6901,196.2693,12.343756,9.1614037,0.0,0,0.80008024,0.0,0.94375783,61.132397,0.78964174,459.57443,-9.2328262
6911,196.2713,12.377945,9.1819725,0.0,0,0.78757626,0.0,0.94620484,61.150082,0.77502435,459.6701,-9.2333908
6921,196.2733,12.378467,9.190836,0.0,0,0.77507222,0.0,0.94778383,61.062679,0.76118249,459.76578,-9.2339983
6931,196.2753,12.376245,9.2028246,0.0,0,0.76256824,0.0,0.95041752,60.917549,0.7484048,459.86148,-9.2332163
6941,196.2773,12.374378,9.2093487,0.0,0,0.75006425,0.0,0.95271879,60.77935,0.73487991,459.95715,-9.2339754
6951,196.2793,12.396686,9.2239895,0.0,0,0.73756021,0.0,0.95505548,60.707047,0.72346604,460.09412,-9.2330627
6961,196.2813,12.386074,9.242363,0.0,0,0.72505623,0.0,0.95725322,60.53764,0.71453458,460.32736,-9.2332716
6971,196.2833,12.373276,9.2496281,0.0,0,0.71255219,0.0,0.95806956,60.395977,0.70089775,460.56058,-9.2321968
6981,196.2853,12.401471,9.2615576,0.0,0,0.70004821,0.0,0.96008795,60.461941,0.69228452,460.79382,-9.2328091
6991,196.2873,12.429905,9.2666044,0.0,0,0.68754423,0.0,0.96175861,60.478439,0.68196809,461.02707,-9.2336588
7001,196.2893,12.506968,9.2755289,0.0,0,0.67504025,0.0,0.96420324,60.688721,0.67131919,461.25314,-9.2330284
7011,196.2913,12.590618,9.2938433,0.0,0,0.66253626,0.0,0.96711624,60.914116,0.65800852,461.46243,-9.2324276
7021,196.2933,12.71557,9.3061075,0.0,0,0.65003228,0.0,0.9683612,61.408237,0.64378786,461.67175,-9.2325516
7031,196.2953,12.802816,9.3222351,0.0,0,0.63752824,0.0,0.9702248,61.765659,0.6335535,461.88107,-9.23351
7041,196.2973,12.888474,9.3259115,0.0,0,0.62502426,0.0,0.97168976,62.074062,0.61979169,462.09039,-9.2348118
7051,196.2993,12.944714,9.3394156,0.0,0,0.61252022,0.0,0.97494048,62.154247,0.60572064,462.10049,-9.2341509
7061,196.3013,13.002368,9.3524857,0.0,0,0.60001624,0.0,0.97778076,62.230103,0.59383518,461.64578,-9.2329893
7071,196.3033,13.040554,9.3666382,0.0,0,0.58751225,0.0,0.97960037,62.308128,0.58127397,461.19107,-9.2325068
7081,196.3053,13.076484,9.3848457,0.0,0,0.57526869,0.0,0.98175168,62.356236,0.57048261,460.73639,-9.2317057
7091,196.3073,13.121447,9.3929834,0.0,0,0.56336868,0.0,0.98310828,62.483974,0.55230963,460.28168,-9.2330036
7100,196.3091,13.126506,9.4062166,0.0,0,0.55265868,0.0,0.98567688,62.35099,0.54663676,459.76947,-9.2340193