File: clean data/testID_0103.csv
level_0,index,Time(sec),Force(kN),Jaw(mm),PowAngle(deg),Power(W),Pram,PTemp,Strain,Stress(MPa),Stroke(mm),TC1(C),wedge(mm)
2438,2438,212.0104,0.4725692,0.0070835822,0.0,0,9.0629702,0.0,0.00036544981,5.713079,10.105952,499.75995,-9.2067614
2439,2439,212.0106,1.0566946,0.01340494,0.0,0,9.0337057,0.0,0.00071984075,11.281008,10.071126,499.75458,-9.2060452
2440,2440,212.0108,2.5432918,0.030056106,0.0,0,9.0044422,0.0,0.0019177262,27.981102,10.041296,499.74921,-9.2057352
2441,2441,212.011,4.0792856,0.058698788,0.0,0,8.9751778,0.0,0.0034473673,48.165688,10.019416,499.74387,-9.2057219
2442,2442,212.0112,4.8786778,0.084568255,0.0,0,8.9459143,0.0,0.005226647,60.34988,9.9995356,499.73849,-9.2059555
2443,2443,212.0114,5.092155,0.10089868,0.0,0,8.9166498,0.0,0.0067359982,64.106506,9.9724855,499.73312,-9.2052641
2444,2444,212.0116,5.1482954,0.1311112,0.0,0,8.8873854,0.0,0.0083051575,64.855583,9.9388418,499.72778,-9.2044973
2445,2445,212.0118,5.2511535,0.18666089,0.0,0,8.8581219,0.0,0.011525791,65.865982,9.9009237,499.72241,-9.2040939
2446,2446,212.012,5.1636424,0.25221205,0.0,0,8.8288574,0.0,0.016196633,65.10968,9.8616896,499.71704,-9.2033472
2447,2447,212.0122,4.9400764,0.31324086,0.0,0,8.7995939,0.0,0.020377705,62.202251,9.821104,499.7117,-9.2030134
2448,2448,212.0124,4.9870477,0.34935769,0.0,0,8.7703295,0.0,0.022982394,61.675472,9.7761412,499.70633,-9.2029953
2449,2449,212.0126,5.3097544,0.36794463,0.0,0,8.7416534,0.0,0.024729501,65.193893,9.7276964,499.70096,-9.2028742
2450,2450,212.0128,5.4148521,0.41139579,0.0,0,8.7136869,0.0,0.027243216,67.081985,9.6811743,499.70181,-9.2027149
2451,2451,212.013,5.3653798,0.47381395,0.0,0,8.6858492,0.0,0.030989362,66.36348,9.6390476,499.71194,-9.2019758
2452,2452,212.0132,5.4947228,0.51447225,0.0,0,8.6580172,0.0,0.034487735,67.17247,9.5988617,499.72205,-9.201273
2453,2453,212.0134,5.6761522,0.53262621,0.0,0,8.6301851,0.0,0.036201715,69.376137,9.5600491,499.73218,-9.2018042
2454,2454,212.0136,5.5976152,0.54124486,0.0,0,8.6023531,0.0,0.036443599,69.14447,9.5222206,499.74231,-9.2021923
2455,2455,212.0138,5.2752252,0.55473733,0.0,0,8.5745211,0.0,0.037354954,65.517845,9.489172,499.75244,-9.2021437
2456,2456,212.014,5.1388612,0.59963447,0.0,0,8.546689,0.0,0.040251561,62.892391,9.459753,499.76257,-9.2033434
2457,2457,212.0142,5.4025249,0.65211582,0.0,0,8.518857,0.0,0.043566074,64.958969,9.4293404,499.77271,-9.2045717
2458,2458,212.0144,5.7846127,0.67257106,0.0,0,8.491025,0.0,0.045600768,69.436615,9.398241,499.78281,-9.2047844
2459,2459,212.0146,5.9618883,0.68505532,0.0,0,8.4631929,0.0,0.046762571,72.139763,9.3679247,499.79294,-9.2046852
2460,2460,212.0148,5.9502978,0.71511906,0.0,0,8.4353609,0.0,0.048198402,72.341438,9.3356476,499.80307,-9.2037802
2461,2461,212.015,5.8926678,0.76002282,0.0,0,8.4075289,0.0,0.05117863,71.451088,9.2999735,499.8132,-9.2024374
2462,2462,212.0152,5.8395581,0.82269824,0.0,0,8.3796968,0.0,0.055798735,70.486938,9.2624359,499.82333,-9.2016373
2463,2463,212.0154,5.7536039,0.88012016,0.0,0,8.3518648,0.0,0.059651911,69.220512,9.2217588,499.83347,-9.2007446
2464,2464,212.0156,5.673728,0.90854192,0.0,0,8.3240328,0.0,0.061885908,67.994217,9.1813841,499.84357,-9.2011585
2465,2465,212.0158,5.6873407,0.93718028,0.0,0,8.2962008,0.0,0.064240091,67.753342,9.1404266,499.8537,-9.2024364
2466,2466,212.016,5.7691913,0.98106867,0.0,0,8.2683687,0.0,0.066947266,68.476395,9.0982447,499.86383,-9.2020893
2467,2467,212.0162,5.865593,1.0190105,0.0,0,8.2405367,0.0,0.069574237,69.452049,9.0572758,499.87396,-9.2021351
2468,2468,212.0164,5.9213204,1.0509939,0.0,0,8.2127056,0.0,0.072396919,70.059647,9.0189619,499.88409,-9.2028522
2469,2469,212.0166,5.9326892,1.077778,0.0,0,8.1848736,0.0,0.074348643,70.193581,8.9840384,499.89423,-9.203455
2470,2470,212.0168,5.9000335,1.0981982,0.0,0,8.1570406,0.0,0.075507119,69.782288,8.9494629,499.90433,-9.203496
2471,2471,212.017,5.8220925,1.130326,0.0,0,8.1292095,0.0,0.077942751,68.749321,8.9148626,499.91446,-9.2030649
2472,2472,212.0172,5.7466974,1.1721607,0.0,0,8.1013775,0.0,0.080921881,67.543373,8.8837128,499.92459,-9.2030334
2473,2473,212.0174,5.7652998,1.2027912,0.0,0,8.0735445,0.0,0.08300738,67.342064,8.8537846,499.93472,-9.2029276
2474,2474,212.0176,5.9218812,1.2251778,0.0,0,8.0462675,0.0,0.085023046,68.790337,8.82271,499.94485,-9.2028399
2475,2475,212.0178,6.1157813,1.2519544,0.0,0,8.0196619,0.0,0.086936682,70.993164,8.7896271,499.95499,-9.2023964
2476,2476,212.018,6.2236495,1.2865323,0.0,0,7.993176,0.0,0.088848233,72.412979,8.7575388,499.96509,-9.2018499
2477,2477,212.0182,6.2096353,1.3297033,0.0,0,7.9666953,0.0,0.092071272,72.226387,8.7269449,499.97522,-9.2020826
2478,2478,212.0184,6.1327844,1.3727781,0.0,0,7.9402156,0.0,0.095578589,71.157265,8.6932831,499.98535,-9.2021399
2479,2479,212.0186,6.0623465,1.4082981,0.0,0,7.9137354,0.0,0.097945616,70.164246,8.6586876,499.99548,-9.2019567
2480,2480,212.0188,6.0157313,1.4402562,0.0,0,7.8872552,0.0,0.10040329,69.415306,8.6215553,500.00562,-9.2030735
2481,2481,212.019,6.0002828,1.4744928,0.0,0,7.860775,0.0,0.10326216,68.881447,8.5869322,500.01575,-9.2042017
2482,2482,212.0192,6.0367436,1.5127048,0.0,0,7.8342953,0.0,0.1057264,68.979645,8.5510054,500.02588,-9.2040844
2483,2483,212.0194,6.0993629,1.544847,0.0,0,7.8078156,0.0,0.10813419,69.519615,8.5149565,500.03598,-9.203495
2484,2484,212.0196,6.1434975,1.5661248,0.0,0,7.7813349,0.0,0.11023033,69.940544,8.4837227,500.04611,-9.2032576
2485,2485,212.0198,6.1705904,1.5909114,0.0,0,7.7548552,0.0,0.11167132,70.156136,8.451314,500.05624,-9.2030983
2486,2486,212.02,6.164762,1.6203341,0.0,0,7.728375,0.0,0.11359967,70.05645,8.4172468,500.06638,-9.2033453
2487,2487,212.0202,6.1286039,1.6498052,0.0,0,7.7018952,0.0,0.11628244,69.590904,8.3854818,500.07651,-9.2026653
2488,2488,212.0204,6.0944381,1.6864605,0.0,0,7.675415,0.0,0.11880224,69.006393,8.3565989,500.08664,-9.2021465
2489,2489,212.0206,6.0913458,1.7166781,0.0,0,7.6489348,0.0,0.12089083,68.732071,8.3280916,500.09674,-9.2025414
2490,2490,212.0208,6.1569505,1.7329818,0.0,0,7.6224551,0.0,0.12264155,69.226051,8.3005724,500.10687,-9.2025824
2491,2491,212.021,6.2567992,1.758019,0.0,0,7.5959754,0.0,0.12432055,70.235649,8.2746077,500.117,-9.2025843
2492,2492,212.0212,6.3100166,1.791091,0.0,0,7.5694952,0.0,0.12634842,70.823959,8.2468891,500.12714,-9.2026081
2493,2493,212.0214,6.304575,1.8197103,0.0,0,7.543015,0.0,0.12895392,70.608055,8.2170944,500.13727,-9.2026844
2494,2494,212.0216,6.3060493,1.8560394,0.0,0,7.5165353,0.0,0.13171789,70.369019,8.1887064,500.1474,-9.2030869
2495,2495,212.0218,6.3390226,1.8922777,0.0,0,7.4900556,0.0,0.13404875,70.530914,8.1565161,500.1575,-9.2038336
2496,2496,212.022,6.3496923,1.9141854,0.0,0,7.4635754,0.0,0.13614795,70.597534,8.1218691,500.16763,-9.2039242
2497,2497,212.0222,6.3137269,1.9449438,0.0,0,7.4370952,0.0,0.13854313,70.091194,8.0902414,500.17776,-9.2039423
2498,2498,212.0224,6.2858539,1.9826905,0.0,0,7.410615,0.0,0.14090249,69.512138,8.0602179,500.1879,-9.203516
2499,2499,212.0226,6.3062687,2.0061891,0.0,0,7.384666,0.0,0.14309907,69.456863,8.0296402,500.19803,-9.2029476
2500,2500,212.0228,6.3428946,2.0327444,0.0,0,7.3593607,0.0,0.14546423,69.67292,8.0006504,500.20493,-9.2026014
2501,2501,212.023,6.3512492,2.0621889,0.0,0,7.3341718,0.0,0.1472439,69.779533,7.9710627,500.20435,-9.202445
2502,2502,212.0232,6.3388028,2.0808105,0.0,0,7.3089876,0.0,0.14886282,69.562202,7.9423285,500.20374,-9.2021608
2503,2503,212.0234,6.3309355,2.1098728,0.0,0,7.2838035,0.0,0.15144184,69.269432,7.9151778,500.20316,-9.2021685
2504,2504,212.0236,6.3351431,2.1463337,0.0,0,7.2586198,0.0,0.15371753,69.174347,7.8867698,500.20255,-9.2027063
2505,2505,212.0238,6.3508816,2.1662276,0.0,0,7.2334356,0.0,0.15535478,69.208717,7.8589911,500.20197,-9.2028532
2506,2506,212.024,6.3812127,2.1851137,0.0,0,7.2082515,0.0,0.15737078,69.292419,7.8318701,500.20135,-9.2034101
2507,2507,212.0242,6.4299445,2.2111621,0.0,0,7.1830673,0.0,0.15903448,69.625015,7.8069992,500.20074,-9.2034359
2508,2508,212.0244,6.4747534,2.2339833,0.0,0,7.1578832,0.0,0.16060781,70.07518,7.7804484,500.20016,-9.203021
2509,2509,212.0246,6.4940252,2.2651563,0.0,0,7.132699,0.0,0.16339983,70.222427,7.7539115,500.19955,-9.2029314
2510,2510,212.0248,6.4896398,2.3025424,0.0,0,7.1075149,0.0,0.16615562,70.064583,7.7276382,500.19897,-9.2034492
2511,2511,212.025,6.4780617,2.3278503,0.0,0,7.0823312,0.0,0.16796887,69.770699,7.7001448,500.19836,-9.2035856
2512,2512,212.0252,6.4694529,2.352294,0.0,0,7.0571475,0.0,0.17031023,69.467682,7.6732774,500.19778,-9.2031393
2513,2513,212.0254,6.4719319,2.3833554,0.0,0,7.0319633,0.0,0.17270707,69.320656,7.6459899,500.19717,-9.2033634
2514,2514,212.0256,6.4937205,2.4085639,0.0,0,7.0067787,0.0,0.1743841,69.357735,7.6180797,500.19659,-9.20333
2515,2515,212.0258,6.5282135,2.4322522,0.0,0,6.981595,0.0,0.17666531,69.530342,7.5900731,500.19598,-9.2031898
2516,2516,212.026,6.5578241,2.4578571,0.0,0,6.9564114,0.0,0.17878227,69.726151,7.5623465,500.1954,-9.2033205
2517,2517,212.0262,6.570961,2.4794564,0.0,0,6.9312272,0.0,0.18006203,69.838661,7.5372796,500.19479,-9.2026424
2518,2518,212.0264,6.5585389,2.5026982,0.0,0,6.9060431,0.0,0.18217984,69.629303,7.5106478,500.19421,-9.2023211
2519,2519,212.0266,6.5263867,2.5312779,0.0,0,6.8808589,0.0,0.18464185,69.194054,7.4831605,500.1936,-9.2028379
2520,2520,212.0268,6.5130801,2.55885,0.0,0,6.8556757,0.0,0.18642291,68.853859,7.4597301,500.19302,-9.2028713
2521,2521,212.027,6.524075,2.581387,0.0,0,6.8304915,0.0,0.18844914,68.744965,7.4338932,500.19241,-9.2028732
2522,2522,212.0272,6.5641642,2.6014457,0.0,0,6.8053074,0.0,0.19040541,68.991455,7.408515,500.19183,-9.2034178
2523,2523,212.0274,6.6191354,2.6257188,0.0,0,6.7801232,0.0,0.19182299,69.458893,7.3858957,500.19122,-9.2034473
2524,2524,212.0276,6.6551137,2.6521831,0.0,0,6.7554412,0.0,0.19390997,69.716934,7.3598533,500.19064,-9.2029123
2525,2525,212.0278,6.6716695,2.6772013,0.0,0,6.7313666,0.0,0.1964507,69.701454,7.3337483,500.19003,-9.2028818
2526,2526,212.028,6.6682487,2.7055585,0.0,0,6.7074018,0.0,0.19843484,69.614906,7.3096447,500.18945,-9.2027845
2527,2527,212.0282,6.6527038,2.7308981,0.0,0,6.6834412,0.0,0.20039281,69.342735,7.2830939,500.18884,-9.2028236
2528,2528,212.0284,6.6433306,2.7514334,0.0,0,6.6594815,0.0,0.20256141,69.048309,7.2585311,500.18826,-9.2029867
2529,2529,212.0286,6.6546426,2.7792273,0.0,0,6.6355214,0.0,0.20448399,68.993057,7.2354422,500.18765,-9.2039757
2530,2530,212.0288,6.6634874,2.8064914,0.0,0,6.6115613,0.0,0.2064822,68.976768,7.2097945,500.18707,-9.2044144
2531,2531,212.029,6.676888,2.8248286,0.0,0,6.5876012,0.0,0.20860282,68.963417,7.185236,500.18646,-9.204071
2532,2532,212.0292,6.7089672,2.8491092,0.0,0,6.5636415,0.0,0.21035731,69.112602,7.1629667,500.18585,-9.2041492
2533,2533,212.0294,6.7393517,2.8760476,0.0,0,6.5396814,0.0,0.21206744,69.382484,7.1372871,500.18527,-9.2042131
2534,2534,212.0296,6.7598281,2.8954711,0.0,0,6.5157218,0.0,0.21423613,69.449142,7.1105123,500.18466,-9.2035589
2535,2535,212.0298,6.7508073,2.924217,0.0,0,6.4917617,0.0,0.21653163,69.202034,7.0837326,500.18408,-9.2028055
2536,2536,212.03,6.7441993,2.9553802,0.0,0,6.467802,0.0,0.21854271,68.996017,7.0589695,500.18347,-9.2025404
2537,2537,212.0302,6.7658596,2.9726315,0.0,0,6.4438419,0.0,0.22049163,69.013878,7.0369668,500.18289,-9.2019949
2538,2538,212.0304,6.7989278,2.9967992,0.0,0,6.4198813,0.0,0.2225814,69.166451,7.014791,500.18228,-9.202837
2539,2539,212.0306,6.8237009,3.0265937,0.0,0,6.3959212,0.0,0.22450148,69.321701,6.9897919,500.1817,-9.2035761
2540,2540,212.0308,6.8281536,3.0439966,0.0,0,6.3719611,0.0,0.2263988,69.337814,6.9643402,500.18109,-9.2039185
2541,2541,212.031,6.8301725,3.0691335,0.0,0,6.3480015,0.0,0.2287233,69.159325,6.9376674,500.18051,-9.2043524
2542,2542,212.0312,6.8337288,3.1004207,0.0,0,6.3240414,0.0,0.23070115,68.992882,6.910984,500.1799,-9.2042303
2543,2543,212.0314,6.8491182,3.1180775,0.0,0,6.3000817,0.0,0.23248997,69.064522,6.8879199,500.17932,-9.2041187
2544,2544,212.0316,6.8672771,3.1417484,0.0,0,6.2761216,0.0,0.23495948,69.156082,6.8613558,500.17871,-9.2032557
2545,2545,212.0318,6.8730602,3.1725018,0.0,0,6.252162,0.0,0.23702852,69.062683,6.8356729,500.17813,-9.2024689
2546,2546,212.032,6.8786259,3.1897352,0.0,0,6.2282019,0.0,0.23859499,68.999443,6.8125114,500.17752,-9.20189
2547,2547,212.0322,6.9014726,3.211338,0.0,0,6.2042418,0.0,0.24091433,69.02195,6.7876248,500.17694,-9.20193
2548,2548,212.0324,6.9243221,3.241889,0.0,0,6.1802816,0.0,0.24298431,69.062485,6.7631526,500.17633,-9.2019148
2549,2549,212.0326,6.9237905,3.261327,0.0,0,6.1568022,0.0,0.24449565,68.985146,6.7398386,500.17575,-9.2019835
2550,2550,212.0328,6.912209,3.2850058,0.0,0,6.1339045,0.0,0.24697252,68.655312,6.7165661,515.14587,-9.2032242
2551,2551,212.033,6.9011021,3.3155963,0.0,0,6.1111116,0.0,0.24931426,68.38868,6.6925831,589.98547,-9.2041492
2552,2552,212.0332,6.9095306,3.334692,0.0,0,6.0883236,0.0,0.25077283,68.401947,6.66856,664.82513,-9.2038336
2553,2553,212.0334,6.9591846,3.3548934,0.0,0,6.0655355,0.0,0.25303125,68.67923,6.6446166,739.66473,-9.2038336
2554,2554,212.0336,7.0061021,3.3821096,0.0,0,6.042748,0.0,0.25523382,68.949791,6.621398,814.50433,-9.2044029
2555,2555,212.0338,7.0291886,3.4033208,0.0,0,6.0199599,0.0,0.25662068,69.148178,6.5962505,889.34399,-9.2044706
2556,2556,212.034,7.0431247,3.4247193,0.0,0,5.9971714,0.0,0.25889328,69.22332,6.5729346,964.18353,-9.2038126
2557,2557,212.0342,7.0464063,3.451654,0.0,0,5.9743834,0.0,0.26126263,69.092934,6.5518489,1039.0232,-9.2033386
2558,2558,212.0344,7.0362992,3.4740176,0.0,0,5.9515953,0.0,0.26272523,68.872673,6.5260749,1113.8628,-9.2032175
2559,2559,212.0346,7.0288186,3.4960411,0.0,0,5.9288073,0.0,0.26502874,68.708817,6.4992471,1188.7024,-9.2025938
2560,2560,212.0348,7.0398579,3.5227478,0.0,0,5.9060197,0.0,0.26757717,68.612488,6.4749904,1263.542,-9.2019882
2561,2561,212.035,7.0504942,3.5468547,0.0,0,5.8832316,0.0,0.26917848,68.524483,6.4530463,1338.3816,-9.201643
2562,2562,212.0352,7.0648351,3.5686636,0.0,0,5.8604436,0.0,0.27131373,68.526489,6.4298577,1413.2213,-9.2022333
2563,2563,212.0354,7.0926399,3.5915828,0.0,0,5.8376555,0.0,0.27364388,68.644524,6.4045358,1488.0609,-9.2028513
2564,2564,212.0356,7.1211457,3.6159265,0.0,0,5.814867,0.0,0.27523556,68.809151,6.3813162,1562.9005,-9.2029085
2565,2565,212.0358,7.1408486,3.6386487,0.0,0,5.792079,0.0,0.27727914,68.923088,6.3577628,1637.7401,-9.2029228
2566,2566,212.036,7.1468663,3.6600974,0.0,0,5.7692914,0.0,0.27970415,68.890671,6.3344746,1712.5798,-9.2035084
2567,2567,212.0362,7.1318717,3.685627,0.0,0,5.7465034,0.0,0.28145158,68.648651,6.3135924,1787.4193,-9.204258
2568,2568,212.0364,7.1147676,3.7084193,0.0,0,5.7237153,0.0,0.28339502,68.332741,6.2880487,1862.2589,-9.2037239
2569,2569,212.0366,7.1225181,3.7265186,0.0,0,5.7009273,0.0,0.28568631,68.213577,6.2621293,1937.0986,-9.2029638
2570,2570,212.0368,7.1464667,3.7522054,0.0,0,5.6781397,0.0,0.28740948,68.324478,6.241015,2011.9382,-9.2028713
2571,2571,212.037,7.164228,3.7774615,0.0,0,5.6553516,0.0,0.28928685,68.369034,6.2148619,2086.7778,-9.2026672
2572,2572,212.0372,7.181313,3.7947488,0.0,0,5.6325636,0.0,0.29155919,68.415199,6.1911731,2161.6174,-9.2026587
2573,2573,212.0374,7.2079816,3.8206153,0.0,0,5.6097751,0.0,0.29356065,68.435966,6.1718102,2236.457,-9.2027054
2574,2574,212.0376,7.2366543,3.8466096,0.0,0,5.5874414,0.0,0.29551926,68.488632,6.1483517,2311.2966,-9.2027082
2575,2575,212.0378,7.2522025,3.8631704,0.0,0,5.5656581,0.0,0.29769742,68.59465,6.1256413,2386.1362,-9.2028465
2576,2576,212.038,7.2511282,3.8897433,0.0,0,5.5439734,0.0,0.29984692,68.467621,6.1021132,2460.9758,-9.2028961
2577,2577,212.0382,7.2467971,3.9186182,0.0,0,5.5222936,0.0,0.3018969,68.261116,6.0785761,2535.8154,-9.2034454
2578,2578,212.0384,7.2534413,3.9359343,0.0,0,5.5006132,0.0,0.30405316,68.178078,6.0555549,2610.6553,-9.203516
2579,2579,212.0386,7.2661328,3.960408,0.0,0,5.4789333,0.0,0.30631712,68.111267,6.0326858,2685.4949,-9.2029886
2580,2580,212.0388,7.2799129,3.9888277,0.0,0,5.457253,0.0,0.30824822,68.116707,6.0084171,2760.3342,-9.2027206
2581,2581,212.039,7.297523,4.0048709,0.0,0,5.4355731,0.0,0.31016284,68.147461,5.9853473,2835.1741,-9.2029734
2582,2582,212.0392,7.3231211,4.0287542,0.0,0,5.4138932,0.0,0.31259647,68.183113,5.9626808,2910.0137,-9.2031384
2583,2583,212.0394,7.3575559,4.0577393,0.0,0,5.3922133,0.0,0.31460086,68.302399,5.9391613,2984.8533,-9.2028284
2584,2584,212.0396,7.3845177,4.072825,0.0,0,5.370533,0.0,0.31638226,68.403183,5.9156456,3059.6929,-9.2022467
2585,2585,212.0398,7.3990846,4.0955853,0.0,0,5.3488531,0.0,0.31882948,68.360031,5.8924928,3134.5325,-9.2022734
2586,2586,212.04,7.4069223,4.1250286,0.0,0,5.3271732,0.0,0.32082221,68.312599,5.8686323,3209.3721,-9.2028465
2587,2587,212.0402,7.4099627,4.1415157,0.0,0,5.3054934,0.0,0.32252955,68.309288,5.8461709,3284.2117,-9.2035151
2588,2588,212.0404,7.4127316,4.1649508,0.0,0,5.283813,0.0,0.32522652,68.147774,5.8229804,3359.0513,-9.20362
2589,2589,212.0406,7.4155073,4.1957474,0.0,0,5.2621331,0.0,0.3274661,68.004875,5.79913,3433.8909,-9.2030277
2590,2590,212.0408,7.4299603,4.2133894,0.0,0,5.2404532,0.0,0.32906517,68.044434,5.7776022,3508.7307,-9.203516
2591,2591,212.041,7.4498086,4.2346406,0.0,0,5.2187734,0.0,0.33160412,68.047523,5.754807,3583.5701,-9.2036963
2592,2592,212.0412,7.4742193,4.2635498,0.0,0,5.1970935,0.0,0.33385602,68.105331,5.7303677,3658.4097,-9.2036209
2593,2593,212.0414,7.503263,4.2825489,0.0,0,5.1754136,0.0,0.33542532,68.219383,5.7067332,3733.2495,-9.204134
2594,2594,212.0416,7.5213585,4.3039522,0.0,0,5.1537333,0.0,0.33802864,68.228104,5.6832142,3808.0889,-9.2036839
2595,2595,212.0418,7.5288029,4.3320603,0.0,0,5.1320534,0.0,0.34047827,68.211311,5.6567039,3882.9287,-9.2029428
2596,2596,212.042,7.5315199,4.3519917,0.0,0,5.110373,0.0,0.34191501,68.12851,5.6321931,3957.7683,-9.2028828
2597,2597,212.0422,7.5328307,4.3727508,0.0,0,5.0886931,0.0,0.34436709,67.983749,5.6117606,4032.6077,-9.2028742
2598,2598,212.0424,7.5403953,4.4002895,0.0,0,5.0670133,0.0,0.34697756,67.888603,5.5901046,4107.4478,-9.2024441
2599,2599,212.0426,7.5529065,4.4221988,0.0,0,5.0457678,0.0,0.34856725,67.865387,5.5679903,4182.2871,-9.202426
2600,2600,212.0428,7.5627894,4.4424706,0.0,0,5.0250483,0.0,0.35092929,67.840767,5.544641,4257.1284,-9.2026634
2601,2601,212.043,7.5843315,4.4671855,0.0,0,5.0044241,0.0,0.35342982,67.81736,5.5206976,4331.9858,-9.2026758
2602,2602,212.0432,7.6182213,4.490056,0.0,0,4.9838037,0.0,0.35498881,67.917137,5.5000534,4406.8433,-9.2031317
2603,2603,212.0434,7.6444097,4.5116115,0.0,0,4.9631839,0.0,0.35733336,68.0923,5.4775033,4481.7012,-9.2038469
2604,2604,212.0436,7.6578388,4.534678,0.0,0,4.9425635,0.0,0.35992017,68.112297,5.4538689,4556.5586,-9.2038021
2605,2605,212.0438,7.6613908,4.5581889,0.0,0,4.9219437,0.0,0.3615236,68.011742,5.4301543,4631.416,-9.2038364
2606,2606,212.044,7.6643558,4.5790162,0.0,0,4.9013238,0.0,0.36366835,67.879044,5.4075708,4706.2734,-9.2035894
2607,2607,212.0442,7.6705751,4.5993109,0.0,0,4.8807039,0.0,0.36624172,67.763779,5.3859353,4781.1309,-9.2031145
2608,2608,212.0444,7.6825323,4.625113,0.0,0,4.8600836,0.0,0.3680408,67.719704,5.3620381,4855.9883,-9.202877
2609,2609,212.0446,7.6959887,4.6486192,0.0,0,4.8394637,0.0,0.37020233,67.622757,5.3372707,4930.8457,-9.2025957
2610,2610,212.0448,7.7045541,4.6678839,0.0,0,4.8188438,0.0,0.37281811,67.548042,5.3148942,5005.7031,-9.2028503
2611,2611,212.045,7.7265191,4.6945815,0.0,0,4.798224,0.0,0.37486523,67.60553,5.2929125,5080.5605,-9.2023306
2612,2612,212.0452,7.7572613,4.7187276,0.0,0,4.7776036,0.0,0.37694725,67.709686,5.2694287,5155.4185,-9.2023239
2613,2613,212.0454,7.7844467,4.7357736,0.0,0,4.7569838,0.0,0.37934583,67.777267,5.2485209,5230.2759,-9.2024708
2614,2614,212.0456,7.7983823,4.761209,0.0,0,4.7363639,0.0,0.38143301,67.757278,5.2267332,5305.1333,-9.2024622
2615,2615,212.0458,7.799921,4.7852883,0.0,0,4.7157435,0.0,0.38338298,67.667641,5.2030573,5379.9907,-9.2026806
2616,2616,212.046,7.8042083,4.8004365,0.0,0,4.6951237,0.0,0.38565844,67.564957,5.1798115,5454.8481,-9.2026348
2617,2617,212.0462,7.8111773,4.8253989,0.0,0,4.6745038,0.0,0.3878217,67.478607,5.154305,5529.7056,-9.2022429
2618,2618,212.0464,7.8230381,4.8520207,0.0,0,4.6538839,0.0,0.38978219,67.398148,5.1312122,5604.563,-9.2027988
2619,2619,212.0466,7.8418097,4.8662024,0.0,0,4.6332641,0.0,0.3919495,67.38916,5.111063,5679.4204,-9.2031517
2620,2620,212.0468,7.8659225,4.8904295,0.0,0,4.6126437,0.0,0.39428625,67.4496,5.0905843,5754.2783,-9.202651
2621,2621,212.047,7.8859429,4.9192076,0.0,0,4.5920234,0.0,0.39632526,67.496651,5.069222,5829.1357,-9.2034798
2622,2622,212.0472,7.9001832,4.9334245,0.0,0,4.5714035,0.0,0.39840266,67.498283,5.0467134,5903.9932,-9.2033443
2623,2623,212.0474,7.9154325,4.9563556,0.0,0,4.5507836,0.0,0.40094799,67.510757,5.02281,5978.8506,-9.2021055
2624,2624,212.0476,7.9308147,4.9854817,0.0,0,4.5305758,0.0,0.40301478,67.50882,5.0017972,6053.708,-9.2015228
2625,2625,212.0478,7.9428115,4.9998779,0.0,0,4.5108657,0.0,0.40497193,67.443184,4.9827075,6128.5654,-9.2013998
2626,2626,212.048,7.9485545,5.0216861,0.0,0,4.4912457,0.0,0.40763584,67.298737,4.9621334,6203.4229,-9.2013464
2627,2627,212.0482,7.9545002,5.0501437,0.0,0,4.4716296,0.0,0.40968364,67.206551,4.9410338,6278.2803,-9.2019014
2628,2628,212.0484,7.9643154,5.0641484,0.0,0,4.4520135,0.0,0.41137081,67.155434,4.9183726,6353.1382,-9.202673
2629,2629,212.0486,7.9796004,5.0849895,0.0,0,4.4323974,0.0,0.41403934,67.106972,4.8953953,6427.9956,-9.2030382
2630,2630,212.0488,7.9973583,5.114161,0.0,0,4.4127812,0.0,0.41621432,67.13018,4.8740067,6502.853,-9.2025423
2631,2631,212.049,8.0178862,5.1299448,0.0,0,4.3931651,0.0,0.4178305,67.204079,4.8522263,6577.7104,-9.2020798
2632,2632,212.0492,8.0336084,5.1498532,0.0,0,4.3735495,0.0,0.42051253,67.266113,4.8298626,6652.5679,-9.2023048
2633,2633,212.0494,8.0542173,5.1785045,0.0,0,4.3539338,0.0,0.42283845,67.211525,4.8090811,6727.4253,-9.2022915
2634,2634,212.0496,8.0727797,5.1950231,0.0,0,4.3343177,0.0,0.42441109,67.14962,4.7858391,6802.2827,-9.201828
2635,2635,212.0498,8.0834045,5.2140036,0.0,0,4.3147016,0.0,0.42708078,67.11039,4.7631612,6877.1401,-9.2013979
2636,2636,212.05,8.0940924,5.2423635,0.0,0,4.2950859,0.0,0.42957523,67.031998,4.7426028,6951.998,-9.2020988
2637,2637,212.0502,8.0992498,5.2612939,0.0,0,4.2754693,0.0,0.431077,66.950912,4.7222219,7026.855,-9.2028542
2638,2638,212.0504,8.1063709,5.2788172,0.0,0,4.2558532,0.0,0.43363312,66.839622,4.7018585,7101.7129,-9.2028208
2639,2639,212.0506,8.1161633,5.303391,0.0,0,4.236237,0.0,0.43612173,66.750343,4.6807494,7176.5703,-9.2027283
2640,2640,212.0508,8.1296053,5.3222046,0.0,0,4.2166214,0.0,0.43744954,66.7743,4.6602445,7251.4277,-9.2027998
2641,2641,212.051,8.1461821,5.3402743,0.0,0,4.1970053,0.0,0.43988571,66.799545,4.6397171,7326.2852,-9.20294
2642,2642,212.0512,8.1655598,5.3644934,0.0,0,4.1773891,0.0,0.44252917,66.813858,4.6179671,7401.1426,-9.2029572
2643,2643,212.0514,8.1946564,5.3855848,0.0,0,4.1577735,0.0,0.44395015,66.932602,4.5958982,7476.0,-9.2028999
2644,2644,212.0516,8.2199154,5.4036789,0.0,0,4.1381574,0.0,0.44626549,66.945618,4.5758004,7550.8574,-9.202323
2645,2645,212.0518,8.2323713,5.42488,0.0,0,4.1185412,0.0,0.44891435,66.879997,4.5571017,7625.7153,-9.2023239
2646,2646,212.052,8.2380676,5.4464264,0.0,0,4.0989256,0.0,0.45038351,66.852257,4.5375891,7700.5728,-9.2034197
2647,2647,212.0522,8.2436132,5.4656682,0.0,0,4.0793095,0.0,0.45260257,66.730164,4.5181026,7775.4302,-9.2033386
2648,2648,212.0524,8.2505436,5.4855232,0.0,0,4.0596933,0.0,0.45535946,66.593567,4.4992752,7850.2876,-9.2026005
2649,2649,212.0526,8.2612896,5.5086474,0.0,0,4.0404716,0.0,0.45707455,66.573311,4.4764786,7925.145,-9.2021017
2650,2650,212.0528,8.273901,5.5288391,0.0,0,4.0217257,0.0,0.45912543,66.528831,4.4536495,8000.0,-9.2016993
2651,2651,212.053,8.2969656,5.545475,0.0,0,4.0030656,0.0,0.4616816,66.515114,4.4338946,8000.0,-9.2022171
2652,2652,212.0532,8.3347816,5.5683851,0.0,0,3.9844091,0.0,0.46344399,66.693779,4.4118123,8000.0,-9.2023621
2653,2653,212.0534,8.3675146,5.5900531,0.0,0,3.9657531,0.0,0.46544152,66.839096,4.3905277,8000.0,-9.2016497
2654,2654,212.0536,8.3869581,5.606606,0.0,0,3.9470971,0.0,0.46810785,66.847275,4.3720517,8000.0,-9.2020779
2655,2655,212.0538,8.3886223,5.6303234,0.0,0,3.928441,0.0,0.47008651,66.787323,4.3530874,8000.0,-9.2028198
2656,2656,212.054,8.3840799,5.6523533,0.0,0,3.9097853,0.0,0.47197458,66.66452,4.3338737,8000.0,-9.2026997
2657,2657,212.0542,8.3871984,5.6654563,0.0,0,3.8911293,0.0,0.47442186,66.505554,4.3134336,8000.0,-9.2022429
2658,2658,212.0544,8.3950224,5.6888638,0.0,0,3.8724732,0.0,0.47656497,66.38575,4.2919817,8000.0,-9.2016668
2659,2659,212.0546,8.4107056,5.7135425,0.0,0,3.8538172,0.0,0.47853008,66.36113,4.271338,8000.0,-9.2021027
2660,2660,212.0548,8.431509,5.7261591,0.0,0,3.8351612,0.0,0.48080423,66.360817,4.2519445,8000.0,-9.2022409
2661,2661,212.055,8.4606915,5.7484417,0.0,0,3.8165052,0.0,0.48301107,66.396225,4.2320333,8000.0,-9.2017946
2662,2662,212.0552,8.5002651,5.7731824,0.0,0,3.7978492,0.0,0.48484585,66.550224,4.2110186,8000.0,-9.2019424
2663,2663,212.0554,8.5290499,5.7841396,0.0,0,3.7791932,0.0,0.48693556,66.664612,4.1909113,8000.0,-9.2021723
2664,2664,212.0556,8.5393305,5.8056583,0.0,0,3.7605371,0.0,0.48943993,66.64595,4.1696534,8000.0,-9.2018423
2665,2665,212.0558,8.5484428,5.8332787,0.0,0,3.7418811,0.0,0.49145743,66.621529,4.1489096,8000.0,-9.2014637
2666,2666,212.056,8.5574551,5.844923,0.0,0,3.7232251,0.0,0.49332109,66.535561,4.1303883,8000.0,-9.2017355
2667,2667,212.0562,8.5643845,5.8641582,0.0,0,3.7045693,0.0,0.49579579,66.361679,4.11058,8000.0,-9.2014875
2668,2668,212.0564,8.5658703,5.89184,0.0,0,3.6859133,0.0,0.49782476,66.263466,4.0907912,8000.0,-9.2018719
2669,2669,212.0566,8.5784655,5.9046621,0.0,0,3.6672573,0.0,0.49969411,66.21093,4.0718169,8000.0,-9.2028961
2670,2670,212.0568,8.6080093,5.9241962,0.0,0,3.6486013,0.0,0.50259316,66.288864,4.0517893,8000.0,-9.203021
2671,2671,212.057,8.6407795,5.9520264,0.0,0,3.629945,0.0,0.5047192,66.502914,4.0305753,8000.0,-9.2029591
2672,2672,212.0572,8.6702061,5.9643402,0.0,0,3.611289,0.0,0.50624198,66.584778,4.0116963,8000.0,-9.2024174
2673,2673,212.0574,8.6944733,5.9822931,0.0,0,3.5926332,0.0,0.50898874,66.500877,3.9920287,8000.0,-9.201601
2674,2674,212.0576,8.7135315,6.0099397,0.0,0,3.5743496,0.0,0.51123548,66.464516,3.9714572,8000.0,-9.2016106
2675,2675,212.0578,8.7215834,6.0239763,0.0,0,3.5565164,0.0,0.51272517,66.453682,3.9537201,8000.0,-9.2011433
2676,2676,212.058,8.730278,6.0406737,0.0,0,3.5387647,0.0,0.51543349,66.310326,3.9343626,8000.0,-9.200819
2677,2677,212.0582,8.7375488,6.0663114,0.0,0,3.5210166,0.0,0.51775223,66.226662,3.9124043,8000.0,-9.2006521
2678,2678,212.0584,8.7493067,6.0819497,0.0,0,3.5032687,0.0,0.51908576,66.252991,3.8921587,8000.0,-9.2001486
2679,2679,212.0586,8.769948,6.0993118,0.0,0,3.4855206,0.0,0.52184618,66.211578,3.8735535,8000.0,-9.2001753
2680,2680,212.0588,8.7965841,6.1244192,0.0,0,3.4677725,0.0,0.5244661,66.219627,3.8544984,8000.0,-9.2009754
2681,2681,212.059,8.8308802,6.1415496,0.0,0,3.4500246,0.0,0.52577889,66.383499,3.8367257,8000.0,-9.2022476
2682,2682,212.0592,8.8641968,6.1570139,0.0,0,3.4322767,0.0,0.52828252,66.449249,3.8172102,8000.0,-9.2026262
2683,2683,212.0594,8.8856392,6.1796856,0.0,0,3.4145288,0.0,0.53092611,66.429459,3.79723,8000.0,-9.2027082
2684,2684,212.0596,8.8949108,6.19839,0.0,0,3.3967807,0.0,0.53225416,66.454506,3.7797644,8000.0,-9.2027216
2685,2685,212.0598,8.8939228,6.2147779,0.0,0,3.3790326,0.0,0.53464532,66.336258,3.7609446,8000.0,-9.2021179
2686,2686,212.06,8.8986473,6.236599,0.0,0,3.3612847,0.0,0.53740436,66.21521,3.7409112,8000.0,-9.2020864
2687,2687,212.0602,8.9112015,6.2565851,0.0,0,3.3435366,0.0,0.53889316,66.207458,3.7229509,8000.0,-9.2019157
2688,2688,212.0604,8.9260836,6.2732668,0.0,0,3.3257885,0.0,0.54117113,66.124023,3.7030396,8000.0,-9.2011023
2689,2689,212.0606,8.9435167,6.2924309,0.0,0,3.3080406,0.0,0.54395485,66.051796,3.6838012,8000.0,-9.2010736
2690,2690,212.0608,8.9717188,6.31392,0.0,0,3.2902927,0.0,0.54559612,66.158524,3.6658142,8000.0,-9.2012177
2691,2691,212.061,9.0116587,6.3312945,0.0,0,3.2725446,0.0,0.54770321,66.290611,3.6480732,8000.0,-9.2010574
2692,2692,212.0612,9.0491781,6.3471899,0.0,0,3.2547965,0.0,0.55036646,66.376938,3.6294041,8000.0,-9.2012892
2693,2693,212.0614,9.078229,6.3685832,0.0,0,3.2370486,0.0,0.55201894,66.438843,3.6090255,8000.0,-9.2014647
2694,2694,212.0616,9.0888252,6.387239,0.0,0,3.2193005,0.0,0.55399626,66.38446,3.5913041,8000.0,-9.2015352
2695,2695,212.0618,9.0864258,6.4018402,0.0,0,3.2015524,0.0,0.55668819,66.257828,3.5735793,8000.0,-9.2015438
2696,2696,212.062,9.0949774,6.4243236,0.0,0,3.1838045,0.0,0.55867177,66.204826,3.553246,8000.0,-9.2018585
2697,2697,212.0622,9.1122732,6.444664,0.0,0,3.1660566,0.0,0.56063259,66.209625,3.5336862,8000.0,-9.2019644
2698,2698,212.0624,9.1286373,6.4570842,0.0,0,3.1483085,0.0,0.56315798,66.158577,3.5142159,8000.0,-9.2017269
2699,2699,212.0626,9.1429043,6.478992,0.0,0,3.1309149,0.0,0.56520951,66.130943,3.4965436,8000.0,-9.2016115
2700,2700,212.0628,9.1708479,6.5012984,0.0,0,3.1139498,0.0,0.56704068,66.223587,3.4807091,8000.0,-9.2015142
2701,2701,212.063,9.2079,6.5123553,0.0,0,3.0970623,0.0,0.56943625,66.306961,3.4635038,8000.0,-9.201519
2702,2702,212.0632,9.2445736,6.5334973,0.0,0,3.0801783,0.0,0.57177407,66.38427,3.4452467,8000.0,-9.201292
2703,2703,212.0634,9.2718382,6.5584564,0.0,0,3.0632942,0.0,0.57369316,66.44754,3.4233589,8000.0,-9.2009993
2704,2704,212.0636,9.2773991,6.5702944,0.0,0,3.0464103,0.0,0.57597357,66.358887,3.405437,8000.0,-9.2003078
2705,2705,212.0638,9.2727108,6.5905881,0.0,0,3.0295262,0.0,0.57852554,66.199242,3.3900335,8000.0,-9.2004929
2706,2706,212.064,9.2800531,6.6151323,0.0,0,3.0126421,0.0,0.5804798,66.138039,3.3724418,8000.0,-9.2017012
2707,2707,212.0642,9.2995348,6.6246643,0.0,0,2.9957583,0.0,0.58246785,66.121033,3.3537054,8000.0,-9.2016716
2708,2708,212.0644,9.3240223,6.6432185,0.0,0,2.9788742,0.0,0.58503622,66.077446,3.3343215,8000.0,-9.2019033
2709,2709,212.0646,9.3543615,6.6690831,0.0,0,2.9619904,0.0,0.58694571,66.131569,3.3160863,8000.0,-9.2021141
2710,2710,212.0648,9.3788023,6.6786776,0.0,0,2.9451063,0.0,0.58864665,66.248337,3.2967441,8000.0,-9.2021379
2711,2711,212.065,9.4067917,6.696209,0.0,0,2.9282222,0.0,0.5914706,66.275551,3.2780433,8000.0,-9.2020893
2712,2712,212.0652,9.4421024,6.723011,0.0,0,2.9113381,0.0,0.59364325,66.32122,3.2587891,8000.0,-9.2013149
2713,2713,212.0654,9.4671574,6.7344565,0.0,0,2.894454,0.0,0.59526223,66.411957,3.2401803,8000.0,-9.2005339
2714,2714,212.0656,9.4813566,6.7511892,0.0,0,2.8775702,0.0,0.59819865,66.332245,3.2233343,8000.0,-9.1995134
2715,2715,212.0658,9.4925604,6.7773919,0.0,0,2.8606861,0.0,0.6004687,66.253128,3.2056034,8000.0,-9.1994801
2716,2716,212.066,9.5059605,6.7904091,0.0,0,2.8438022,0.0,0.60184026,66.23497,3.186929,8000.0,-9.2001009
2717,2717,212.0662,9.5255079,6.8058095,0.0,0,2.8269181,0.0,0.60465282,66.164169,3.1708786,8000.0,-9.200284
2718,2718,212.0664,9.5487499,6.8306785,0.0,0,2.810034,0.0,0.6070832,66.209381,3.1524448,8000.0,-9.2007256
2719,2719,212.0666,9.5733337,6.844511,0.0,0,2.7931502,0.0,0.60835868,66.311577,3.1330523,8000.0,-9.2011566
2720,2720,212.0668,9.6007452,6.8594441,0.0,0,2.7762663,0.0,0.61117148,66.303932,3.1155608,8000.0,-9.2012043
2721,2721,212.067,9.6378231,6.8834724,0.0,0,2.7593822,0.0,0.61384887,66.373123,3.0956111,8000.0,-9.2018881
2722,2722,212.0672,9.6644716,6.8987575,0.0,0,2.7424982,0.0,0.61503744,66.517387,3.0768273,8000.0,-9.2018032
2723,2723,212.0674,9.676713,6.9136596,0.0,0,2.7256143,0.0,0.61764479,66.448425,3.0609112,8000.0,-9.2012768
2724,2724,212.0676,9.6985083,6.935431,0.0,0,2.7090681,0.0,0.62040997,66.389435,3.0441308,8000.0,-9.2006769
2725,2725,212.0678,9.7212124,6.9517183,0.0,0,2.6929309,0.0,0.62168986,66.439789,3.0268421,8000.0,-9.2004995
2726,2726,212.068,9.7358627,6.9667053,0.0,0,2.6768675,0.0,0.62422419,66.368141,3.0099165,8000.0,-9.2007856
2727,2727,212.0682,9.7453203,6.9865603,0.0,0,2.6608074,0.0,0.6270777,66.27359,2.9924257,8000.0,-9.2003126
2728,2728,212.0684,9.7590513,7.0038586,0.0,0,2.6447473,0.0,0.62827545,66.282219,2.9736836,8000.0,-9.200408
2729,2729,212.0686,9.7852678,7.0182085,0.0,0,2.6286871,0.0,0.63043773,66.287575,2.9552476,8000.0,-9.2006092
2730,2730,212.0688,9.8154078,7.0357432,0.0,0,2.6126273,0.0,0.63324463,66.306976,2.9380407,8000.0,-9.2007532
2731,2731,212.069,9.8447924,7.0557857,0.0,0,2.5965672,0.0,0.63469774,66.382996,2.9197249,8000.0,-9.2012081
2732,2732,212.0692,9.8701973,7.0725555,0.0,0,2.580507,0.0,0.6370275,66.395744,2.9047017,8000.0,-9.2011786
2733,2733,212.0694,9.8984404,7.0882812,0.0,0,2.5644472,0.0,0.64001554,66.399269,2.8891199,8000.0,-9.2013035
2734,2734,212.0696,9.9189329,7.1090155,0.0,0,2.5483871,0.0,0.64161527,66.432289,2.8707089,8000.0,-9.2008953
2735,2735,212.0698,9.9308672,7.1263161,0.0,0,2.5323269,0.0,0.64366663,66.391106,2.8528416,8000.0,-9.2005901
2736,2736,212.07,9.9413099,7.1386414,0.0,0,2.5162671,0.0,0.64644963,66.283554,2.8352017,8000.0,-9.2007694
2737,2737,212.0702,9.9542551,7.1590323,0.0,0,2.5002072,0.0,0.64819449,66.250237,2.8169491,8000.0,-9.2001715
2738,2738,212.0704,9.9736881,7.1763906,0.0,0,2.4841471,0.0,0.64991486,66.291336,2.8006644,8000.0,-9.1997452
2739,2739,212.0706,9.9981155,7.1859269,0.0,0,2.4680872,0.0,0.65237582,66.298851,2.7874105,8000.0,-9.1995792
2740,2740,212.0708,10.032598,7.2057562,0.0,0,2.4520271,0.0,0.65428203,66.340118,2.7737222,8000.0,-9.2001867
2741,2741,212.071,10.065802,7.2250257,0.0,0,2.4359672,0.0,0.65595132,66.424797,2.757581,8000.0,-9.2010851
2742,2742,212.0712,10.092726,7.2345114,0.0,0,2.4199073,0.0,0.65841007,66.476578,2.7402308,8000.0,-9.2012568
2743,2743,212.0714,10.122582,7.2551465,0.0,0,2.4038472,0.0,0.66075039,66.542763,2.7222049,8000.0,-9.2010355
2744,2744,212.0716,10.142598,7.2775507,0.0,0,2.3877871,0.0,0.6626721,66.542969,2.7044792,8000.0,-9.2016039
2745,2745,212.0718,10.153223,7.2874484,0.0,0,2.3717272,0.0,0.66515774,66.454742,2.687171,8000.0,-9.202261
2746,2746,212.072,10.16581,7.3078914,0.0,0,2.3556671,0.0,0.66776633,66.390381,2.6714518,8000.0,-9.2016897
2747,2747,212.0722,10.180394,7.3315706,0.0,0,2.339607,0.0,0.66966373,66.37751,2.653502,8000.0,-9.20119
2748,2748,212.0724,10.202296,7.339622,0.0,0,2.3235471,0.0,0.67170745,66.35791,2.6361287,8000.0,-9.2011642
2749,2749,212.0726,10.235102,7.3564782,0.0,0,2.3078086,0.0,0.67424297,66.361076,2.622277,8000.0,-9.2009907
2750,2750,212.0728,10.272723,7.3782458,0.0,0,2.2924592,0.0,0.67585337,66.480087,2.6071844,8000.0,-9.2002792
2751,2751,212.073,10.309638,7.3839993,0.0,0,2.2771802,0.0,0.67735988,66.650688,2.5919154,8000.0,-9.19979
2752,2752,212.0732,10.33964,7.3995252,0.0,0,2.261904,0.0,0.68003476,66.698799,2.5753977,8000.0,-9.1997557
2753,2753,212.0734,10.36778,7.4239922,0.0,0,2.2466278,0.0,0.68197274,66.726021,2.557811,8000.0,-9.1998243
2754,2754,212.0736,10.394526,7.4331055,0.0,0,2.2313521,0.0,0.68358749,66.774612,2.5400259,8000.0,-9.1998396
2755,2755,212.0738,10.410763,7.4488401,0.0,0,2.2160761,0.0,0.68659651,66.699387,2.5245836,8000.0,-9.2001085
2756,2756,212.074,10.420355,7.4740081,0.0,0,2.2008002,0.0,0.68881822,66.641731,2.5089405,8000.0,-9.2008266
2757,2757,212.0742,10.43412,7.4845481,0.0,0,2.185524,0.0,0.69028372,66.626846,2.490063,8000.0,-9.2011976
2758,2758,212.0744,10.456245,7.4995403,0.0,0,2.170248,0.0,0.69336289,66.54937,2.4742324,8000.0,-9.2011957
2759,2759,212.0746,10.486858,7.5243082,0.0,0,2.1549721,0.0,0.69578183,66.58387,2.4597843,8000.0,-9.2009783
2760,2760,212.0748,10.530662,7.5358028,0.0,0,2.1396961,0.0,0.69691348,66.739883,2.444041,8000.0,-9.2002869
2761,2761,212.075,10.577702,7.5486526,0.0,0,2.1244199,0.0,0.69978094,66.819801,2.4266977,8000.0,-9.199791
2762,2762,212.0752,10.618981,7.5716147,0.0,0,2.109144,0.0,0.70238638,66.915176,2.4100833,8000.0,-9.1997461
2763,2763,212.0754,10.649955,7.5849495,0.0,0,2.093868,0.0,0.70343202,67.036369,2.3939419,8000.0,-9.1997433
2764,2764,212.0756,10.664952,7.5962238,0.0,0,2.0785921,0.0,0.70605171,66.970749,2.378058,8000.0,-9.199749
2765,2765,212.0758,10.677254,7.6161671,0.0,0,2.0633161,0.0,0.70872837,66.894554,2.3636312,8000.0,-9.1999102
2766,2766,212.076,10.691197,7.6308808,0.0,0,2.0480402,0.0,0.70974702,66.914146,2.3472054,8000.0,-9.2004776
2767,2767,212.0762,10.713674,7.6429458,0.0,0,2.0327642,0.0,0.7121982,66.85778,2.3304224,8000.0,-9.2009039
2768,2768,212.0764,10.75083,7.661788,0.0,0,2.0174882,0.0,0.71500725,66.890663,2.3136039,8000.0,-9.2004528
2769,2769,212.0766,10.785779,7.6784,0.0,0,2.002212,0.0,0.71625066,67.035568,2.2976782,8000.0,-9.1999292
2770,2770,212.0768,10.821474,7.69174,0.0,0,1.986936,0.0,0.7187714,67.097443,2.2812169,8000.0,-9.1998158
2771,2771,212.077,10.866795,7.7092485,0.0,0,1.9716599,0.0,0.72183782,67.172157,2.2651718,8000.0,-9.1997471
2772,2772,212.0772,10.904275,7.7276011,0.0,0,1.9563839,0.0,0.72314483,67.301971,2.250941,8000.0,-9.1996946
2773,2773,212.0774,10.9195,7.7416201,0.0,0,1.941108,0.0,0.7252925,67.272308,2.2356551,8000.0,-9.199544
2774,2774,212.0776,10.930991,7.7559175,0.0,0,1.9261372,0.0,0.72824293,67.154907,2.2207255,8000.0,-9.1991377
2775,2775,212.0778,10.94818,7.7750754,0.0,0,1.9115354,0.0,0.72977626,67.096306,2.2054312,8000.0,-9.1992712
2776,2776,212.078,10.965559,7.7906365,0.0,0,1.8970003,0.0,0.73179799,67.081696,2.1903343,8000.0,-9.1997004
2777,2777,212.0782,10.995164,7.8034172,0.0,0,1.8824683,0.0,0.73470134,67.112762,2.1742463,8000.0,-9.1996231
2778,2778,212.0784,11.038403,7.8231993,0.0,0,1.8679363,0.0,0.73657864,67.228188,2.157073,8000.0,-9.1999588
2779,2779,212.0786,11.080938,7.8385878,0.0,0,1.8534042,0.0,0.73843437,67.370949,2.1435931,8000.0,-9.2006607
2780,2780,212.0788,11.120457,7.8481832,0.0,0,1.8388723,0.0,0.7410928,67.43988,2.128278,8000.0,-9.1998377
2781,2781,212.079,11.160212,7.8676672,0.0,0,1.8243402,0.0,0.74302381,67.556213,2.1106935,8000.0,-9.1991997
2782,2782,212.0792,11.197751,7.884378,0.0,0,1.8098083,0.0,0.74469012,67.661072,2.0936954,8000.0,-9.199708
2783,2783,212.0794,11.222618,7.8924627,0.0,0,1.7952763,0.0,0.74719697,67.65274,2.0768442,8000.0,-9.199688
2784,2784,212.0796,11.24269,7.9128375,0.0,0,1.7807442,0.0,0.74951172,67.603302,2.0609617,8000.0,-9.1996098
2785,2785,212.0798,11.263338,7.9337401,0.0,0,1.7662122,0.0,0.75131965,67.599823,2.0459988,8000.0,-9.1996603
2786,2786,212.08,11.288804,7.9409876,0.0,0,1.7516803,0.0,0.75368804,67.61853,2.0317891,8000.0,-9.2002745
2787,2787,212.0802,11.320409,7.9586453,0.0,0,1.7371483,0.0,0.75616419,67.643356,2.0172172,8000.0,-9.2003002
2788,2788,212.0804,11.357611,7.9802513,0.0,0,1.7226163,0.0,0.75791478,67.742897,2.0025079,8000.0,-9.2002983
2789,2789,212.0806,11.405564,7.9872856,0.0,0,1.7080842,0.0,0.76010364,67.83297,1.9866788,8000.0,-9.2002859
2790,2790,212.0808,11.45241,8.0044565,0.0,0,1.6935523,0.0,0.76286441,67.935211,1.9700402,8000.0,-9.1991358
2791,2791,212.081,11.49277,8.0278349,0.0,0,1.6790203,0.0,0.76476246,68.074974,1.9559517,8000.0,-9.1988955
2792,2792,212.0812,11.523875,8.0352135,0.0,0,1.6644882,0.0,0.76666975,68.184227,1.941535,8000.0,-9.1994572
2793,2793,212.0814,11.546026,8.0516891,0.0,0,1.6499562,0.0,0.76970673,68.13633,1.9241691,8000.0,-9.1991482
2794,2794,212.0816,11.566121,8.0763474,0.0,0,1.6354243,0.0,0.77184623,68.058891,1.9070652,8000.0,-9.1984529
2795,2795,212.0818,11.589446,8.0836554,0.0,0,1.6208922,0.0,0.77351266,68.062859,1.8897183,8000.0,-9.198904
2796,2796,212.082,11.621678,8.0975428,0.0,0,1.6063603,0.0,0.77655131,68.042152,1.8742914,8000.0,-9.1996546
2797,2797,212.0822,11.661035,8.1214495,0.0,0,1.5918282,0.0,0.77861226,68.095955,1.8627858,8000.0,-9.1997614
2798,2798,212.0824,11.704868,8.1291866,0.0,0,1.5772963,0.0,0.77987915,68.250832,1.8480229,8000.0,-9.1998425
2799,2799,212.0826,11.747054,8.1415386,0.0,0,1.5630547,0.0,0.78291148,68.294998,1.8310809,8000.0,-9.1998177
2800,2800,212.0828,11.78815,8.1654301,0.0,0,1.5491643,0.0,0.78526753,68.368233,1.814976,8000.0,-9.1990089
2801,2801,212.083,11.830303,8.1753712,0.0,0,1.5353372,0.0,0.78644508,68.534592,1.7979646,8000.0,-9.1982441
2802,2802,212.0832,11.861491,8.1871281,0.0,0,1.5215131,0.0,0.78943664,68.505264,1.784328,8000.0,-9.1989403
2803,2803,212.0834,11.878654,8.2101231,0.0,0,1.5076891,0.0,0.79200363,68.476738,1.7704294,8000.0,-9.1996231
2804,2804,212.0836,11.903441,8.221921,0.0,0,1.4938651,0.0,0.7931031,68.555557,1.7539979,8000.0,-9.2001925
2805,2805,212.0838,11.931651,8.2323627,0.0,0,1.4800411,0.0,0.79600698,68.516083,1.7387387,8000.0,-9.2003784
2806,2806,212.084,11.966452,8.2533045,0.0,0,1.4662172,0.0,0.79893708,68.515427,1.7227004,8000.0,-9.199831
2807,2807,212.0842,12.009953,8.267745,0.0,0,1.4523932,0.0,0.80004394,68.660217,1.7056631,8000.0,-9.199729
2808,2808,212.0844,12.050278,8.2786589,0.0,0,1.4385692,0.0,0.80267918,68.735352,1.6917166,8000.0,-9.1995449
2809,2809,212.0846,12.094145,8.2977638,0.0,0,1.4247452,0.0,0.80570531,68.781738,1.6789478,8000.0,-9.1988201
2810,2810,212.0848,12.145257,8.3133039,0.0,0,1.4109212,0.0,0.80687183,68.931023,1.663053,8000.0,-9.1982412
2811,2811,212.085,12.184479,8.324152,0.0,0,1.3970972,0.0,0.80931711,68.97966,1.6481187,8000.0,-9.1982327
2812,2812,212.0852,12.215972,8.3413906,0.0,0,1.3832732,0.0,0.81234568,68.960091,1.6336608,8000.0,-9.198308
2813,2813,212.0854,12.244679,8.3584766,0.0,0,1.3694493,0.0,0.81357604,69.052299,1.6202365,8000.0,-9.1984539
2814,2814,212.0856,12.275125,8.3710518,0.0,0,1.3556252,0.0,0.81601608,69.086624,1.60753,8000.0,-9.1988039
2815,2815,212.0858,12.306096,8.3861275,0.0,0,1.3418012,0.0,0.81925917,69.031647,1.5919473,8000.0,-9.1996441
2816,2816,212.086,12.335645,8.4050484,0.0,0,1.3279773,0.0,0.82080853,69.067665,1.5756183,8000.0,-9.200058
2817,2817,212.0862,12.376691,8.4193192,0.0,0,1.3141533,0.0,0.82305855,69.128189,1.5614038,8000.0,-9.1998558
2818,2818,212.0864,12.416865,8.4304686,0.0,0,1.3003292,0.0,0.82606936,69.165169,1.5481281,8000.0,-9.1997995
2819,2819,212.0866,12.461595,8.4487715,0.0,0,1.2865052,0.0,0.82765156,69.312065,1.5348008,8000.0,-9.1997519
2820,2820,212.0868,12.508839,8.4634981,0.0,0,1.2726812,0.0,0.82955658,69.43631,1.5200189,8000.0,-9.1997805
2821,2821,212.087,12.54988,8.4721098,0.0,0,1.2588573,0.0,0.83241403,69.456963,1.5050451,8000.0,-9.1993542
2822,2822,212.0872,12.584617,8.4908495,0.0,0,1.2450333,0.0,0.83424699,69.509796,1.4903903,8000.0,-9.198741
2823,2823,212.0874,12.614825,8.5068274,0.0,0,1.2312093,0.0,0.83597761,69.580719,1.4753309,8000.0,-9.1985922
2824,2824,212.0876,12.644112,8.5137634,0.0,0,1.2176626,0.0,0.8387202,69.576088,1.4604037,8000.0,-9.1983995
2825,2825,212.0878,12.680877,8.5326195,0.0,0,1.2044512,0.0,0.84100759,69.602379,1.4442174,8000.0,-9.1980658
2826,2826,212.088,12.721663,8.5511904,0.0,0,1.1913005,0.0,0.84277809,69.685081,1.4276426,8000.0,-9.1980505
2827,2827,212.0882,12.754277,8.557848,0.0,0,1.1781523,0.0,0.84538966,69.699059,1.4146936,8000.0,-9.1987324
2828,2828,212.0884,12.798261,8.5761318,0.0,0,1.1650044,0.0,0.84798723,69.749153,1.4030639,8000.0,-9.1985712
2829,2829,212.0886,12.856313,8.5975475,0.0,0,1.1518563,0.0,0.84982544,69.922989,1.3879954,8000.0,-9.1983223
2830,2830,212.0888,12.909996,8.603982,0.0,0,1.1387082,0.0,0.85220468,70.063652,1.371492,8000.0,-9.1991167
2831,2831,212.089,12.964649,8.6199856,0.0,0,1.1255603,0.0,0.85505438,70.152481,1.3538188,8000.0,-9.1992388
2832,2832,212.0892,13.004155,8.6418772,0.0,0,1.1124123,0.0,0.85697567,70.245872,1.3395976,8000.0,-9.1992626
2833,2833,212.0894,13.028857,8.6473961,0.0,0,1.0992643,0.0,0.85891694,70.242432,1.3282453,8000.0,-9.1996469
2834,2834,212.0896,13.06116,8.6622124,0.0,0,1.0861163,0.0,0.8619023,70.19178,1.3143488,8000.0,-9.1995668
2835,2835,212.0898,13.096085,8.6850662,0.0,0,1.0729682,0.0,0.863868,70.251892,1.2980314,8000.0,-9.1987057
2836,2836,212.09,13.129577,8.6903296,0.0,0,1.0598202,0.0,0.86544847,70.291992,1.2829251,8000.0,-9.1981106
2837,2837,212.0902,13.167581,8.7035942,0.0,0,1.0466722,0.0,0.86862522,70.26561,1.2685158,8000.0,-9.1979313
2838,2838,212.0904,13.213064,8.7261896,0.0,0,1.0335243,0.0,0.87069792,70.376617,1.2558731,8000.0,-9.1979399
2839,2839,212.0906,13.263273,8.7323351,0.0,0,1.0203762,0.0,0.8718127,70.554329,1.2418565,8000.0,-9.1981478
2840,2840,212.0908,13.315412,8.7436485,0.0,0,1.0072283,0.0,0.87483323,70.612091,1.2263802,8000.0,-9.1981497
2841,2841,212.091,13.363367,8.7664766,0.0,0,0.99408025,0.0,0.87717032,70.720512,1.2105161,8000.0,-9.1985865
2842,2842,212.0912,13.399643,8.7759466,0.0,0,0.98093224,0.0,0.87851989,70.845299,1.1946406,8000.0,-9.1986246
2843,2843,212.0914,13.432805,8.7872219,0.0,0,0.96778423,0.0,0.88182092,70.7715,1.1822027,8000.0,-9.1985388
2844,2844,212.0916,13.468719,8.8098993,0.0,0,0.95463622,0.0,0.88450718,70.77565,1.1682801,8000.0,-9.1992159
2845,2845,212.0918,13.503934,8.8214502,0.0,0,0.94148827,0.0,0.88569868,70.891747,1.1538868,8000.0,-9.1991129
2846,2846,212.092,13.54055,8.8315754,0.0,0,0.92834032,0.0,0.88883209,70.842628,1.1412357,8000.0,-9.1984653
2847,2847,212.0922,13.589578,8.8513565,0.0,0,0.91519231,0.0,0.89169526,70.850616,1.1263399,8000.0,-9.1985159
2848,2848,212.0924,13.636314,8.8633223,0.0,0,0.9020443,0.0,0.8925792,71.052162,1.1106577,8000.0,-9.1979389
2849,2849,212.0926,13.686646,8.8730154,0.0,0,0.88916039,0.0,0.89534217,71.138962,1.0982953,8000.0,-9.1971025
2850,2850,212.0928,13.742298,8.8905668,0.0,0,0.87659597,0.0,0.89830452,71.2164,1.0855559,8000.0,-9.1975212
2851,2851,212.093,13.792936,8.9032059,0.0,0,0.86408937,0.0,0.89903098,71.42067,1.0711925,8000.0,-9.1977568
2852,2852,212.0932,13.831293,8.9122152,0.0,0,0.85158527,0.0,0.90150321,71.43689,1.0569425,8000.0,-9.1976671
2853,2853,212.0934,13.862214,8.9282351,0.0,0,0.83908123,0.0,0.9046917,71.406044,1.0439678,8000.0,-9.1980047
2854,2854,212.0936,13.89594,8.9434481,0.0,0,0.82657719,0.0,0.90574288,71.508087,1.0325415,8000.0,-9.1982117
2855,2855,212.0938,13.926364,8.9534454,0.0,0,0.8140732,0.0,0.90809435,71.474541,1.0182314,8000.0,-9.1981955
2856,2856,212.094,13.963023,8.96702,0.0,0,0.80156928,0.0,0.91128904,71.398193,1.0047791,8000.0,-9.1980419
2857,2857,212.0942,14.012547,8.9828987,0.0,0,0.78906524,0.0,0.91251636,71.53801,0.99168104,8000.0,-9.1987324
2858,2858,212.0944,14.071726,8.9944468,0.0,0,0.77656126,0.0,0.91464913,71.690651,0.97705811,8000.0,-9.1993647
2859,2859,212.0946,14.129798,9.0065975,0.0,0,0.76405728,0.0,0.91793513,71.784775,0.96587241,8000.0,-9.1987095
2860,2860,212.0948,14.184097,9.0249681,0.0,0,0.75155324,0.0,0.91955179,71.974716,0.9538306,8000.0,-9.1982183
2861,2861,212.095,14.23765,9.0380802,0.0,0,0.73904926,0.0,0.92165345,72.060425,0.93687814,8000.0,-9.1982279
2862,2862,212.0952,14.277586,9.0470123,0.0,0,0.72654527,0.0,0.92483324,72.047943,0.92142427,8000.0,-9.1981916
2863,2863,212.0954,14.30591,9.0657444,0.0,0,0.71404123,0.0,0.92666447,72.10498,0.9070915,8000.0,-9.1979322
2864,2864,212.0956,14.335748,9.0803328,0.0,0,0.70153725,0.0,0.9284271,72.119934,0.89404351,8000.0,-9.1974163
2865,2865,212.0958,14.376508,9.0855379,0.0,0,0.68903327,0.0,0.93123925,72.078278,0.88301587,8000.0,-9.1971264
2866,2866,212.096,14.431465,9.1025343,0.0,0,0.67652929,0.0,0.93326646,72.155464,0.86951762,8000.0,-9.197197
2867,2867,212.0962,14.478898,9.1189117,0.0,0,0.66402531,0.0,0.93477577,72.305435,0.85900229,8000.0,-9.1976709
2868,2868,212.0964,14.527196,9.1233959,0.0,0,0.65152127,0.0,0.93736404,72.390015,0.84704822,8000.0,-9.197628
2869,2869,212.0966,14.590359,9.1397696,0.0,0,0.63901722,0.0,0.93974179,72.506134,0.82982767,8000.0,-9.1976242
2870,2870,212.0968,14.657951,9.158618,0.0,0,0.62651324,0.0,0.94138712,72.708199,0.81578648,8000.0,-9.1978464
2871,2871,212.097,14.710027,9.1631336,0.0,0,0.61400926,0.0,0.94379455,72.83651,0.80260652,8000.0,-9.1978436
2872,2872,212.0972,14.743566,9.1775093,0.0,0,0.60150528,0.0,0.94645631,72.829636,0.78836364,8000.0,-9.1986761
2873,2873,212.0974,14.777763,9.1971807,0.0,0,0.58900124,0.0,0.94809735,72.872864,0.77671659,8000.0,-9.1987381
2874,2874,212.0976,14.8076,9.2021151,0.0,0,0.57674497,0.0,0.950158,72.893486,0.76628625,8000.0,-9.1982088
2875,2875,212.0978,14.845856,9.2164803,0.0,0,0.56478834,0.0,0.95336074,72.847046,0.75140107,8000.0,-9.1976519
2876,2876,212.098,14.903085,9.2379904,0.0,0,0.55288589,0.0,0.95525062,72.933815,0.73509306,8000.0,-9.1973352
2877,2877,212.0982,14.961686,9.2422476,0.0,0,0.54098582,0.0,0.95686865,73.092461,0.72280335,8000.0,-9.1975079
2878,2878,212.0984,15.018167,9.2541599,0.0,0,0.52908581,0.0,0.96008223,73.145309,0.70891035,8000.0,-9.1977186
2879,2879,212.0986,15.080745,9.2749033,0.0,0,0.51718581,0.0,0.96206993,73.303421,0.69510716,8000.0,-9.1980686
2880,2880,212.0988,15.143286,9.2793493,0.0,0,0.5052858,0.0,0.96338278,73.510902,0.68427694,8000.0,-9.1979027
2881,2881,212.099,15.187884,9.2907705,0.0,0,0.49338579,0.0,0.9666698,73.482811,0.67317641,8000.0,-9.1971626
2882,2882,212.0992,15.226962,9.3130188,0.0,0,0.48148578,0.0,0.96892846,73.514275,0.65817308,8000.0,-9.1966562
2883,2883,212.0994,15.263016,9.3203554,0.0,0,0.46958581,0.0,0.97002512,73.60952,0.64430207,8000.0,-9.1966486
2884,2884,212.0996,15.301616,9.3303728,0.0,0,0.4576858,0.0,0.97338951,73.561592,0.63431245,8000.0,-9.196846
2885,2885,212.0998,15.346191,9.3512554,0.0,0,0.44578579,0.0,0.9759416,73.599045,0.61985695,8000.0,-9.1969099
2886,2886,212.1,15.393768,9.3592625,0.0,0,0.43388578,0.0,0.97671586,73.752052,0.60348535,8000.0,-9.1967659
2887,2887,212.1002,15.455866,9.3669052,0.0,0,0.42198581,0.0,0.97985882,73.804016,0.59131646,8000.0,-9.1968813
2888,2888,212.1004,15.525205,9.3843193,0.0,0,0.4100858,0.0,0.98246521,73.943344,0.58021778,8000.0,-9.1974106
2889,2889,212.1006,15.593877,9.3933563,0.0,0,0.39818579,0.0,0.98278701,74.239388,0.56925625,8000.0,-9.1972666