File: clean data/testID_0236.csv
level_0,index,Time(sec),Force(kN),Jaw(mm),PowAngle(deg),Power(W),Pram,PTemp,Strain,Stress(MPa),Stroke(mm),TC1(C),wedge(mm)
2445,2445,212.0118,0.70389217,0.011962463,0.0,0,8.8581161,0.0,0.00080489944,8.2614326,9.8100958,501.08188,-9.2068434
2446,2446,212.012,1.2825747,0.034157272,0.0,0,8.8288527,0.0,0.0017088151,14.583608,9.7698717,501.11057,-9.2062025
2447,2447,212.0122,2.163986,0.059185009,0.0,0,8.7995882,0.0,0.0034809269,25.125647,9.7375298,501.13928,-9.2056255
2448,2448,212.0124,3.0803142,0.09115877,0.0,0,8.7703247,0.0,0.005830552,36.685364,9.7061024,501.168,-9.2061262
2449,2449,212.0126,3.7425082,0.12066802,0.0,0,8.7416477,0.0,0.0075095003,45.826794,9.6720066,501.19669,-9.2060614
2450,2450,212.0128,4.0046949,0.14339809,0.0,0,8.7136822,0.0,0.0090828463,50.044853,9.6358805,501.2254,-9.2052736
2451,2451,212.013,4.0468197,0.19573368,0.0,0,8.6858435,0.0,0.01251808,50.829185,9.5952435,501.25412,-9.2050848
2452,2452,212.0132,3.9923186,0.27530363,0.0,0,8.6580114,0.0,0.017342255,50.140202,9.5507774,501.28284,-9.2051277
2453,2453,212.0134,3.8969779,0.34260505,0.0,0,8.6301794,0.0,0.022113526,48.842308,9.4988499,501.31152,-9.205162
2454,2454,212.0136,3.8210878,0.39784864,0.0,0,8.6023474,0.0,0.026403839,47.492477,9.4435091,501.34024,-9.2051497
2455,2455,212.0138,3.80494,0.44836617,0.0,0,8.5745163,0.0,0.029587615,46.968403,9.3899622,501.36896,-9.2051964
2456,2456,212.014,3.8486729,0.49279919,0.0,0,8.5466833,0.0,0.032514591,47.335251,9.3360367,501.39767,-9.2052107
2457,2457,212.0142,3.9518137,0.54422194,0.0,0,8.5188513,0.0,0.036405038,48.18055,9.2853775,501.42636,-9.2051878
2458,2458,212.0144,4.1770358,0.59085035,0.0,0,8.4910202,0.0,0.039619461,50.364666,9.2419691,501.45508,-9.2040625
2459,2459,212.0146,4.3458142,0.60987884,0.0,0,8.4631872,0.0,0.041070979,52.782871,9.2018929,501.4838,-9.2037773
2460,2460,212.0148,4.2709537,0.62306011,0.0,0,8.4353552,0.0,0.04237454,52.469063,9.1643095,501.51248,-9.2041454
2461,2461,212.015,4.065166,0.65013742,0.0,0,8.4075241,0.0,0.044038944,50.006596,9.126811,501.5412,-9.2036848
2462,2462,212.0152,3.9076223,0.68147421,0.0,0,8.3796911,0.0,0.045881152,47.815079,9.0900164,501.56992,-9.2041426
2463,2463,212.0154,3.8822653,0.71130341,0.0,0,8.3518591,0.0,0.048308752,47.066387,9.0554819,501.59863,-9.2048664
2464,2464,212.0156,3.9785082,0.73325872,0.0,0,8.324028,0.0,0.049999673,47.942673,9.023201,501.62732,-9.2050457
2465,2465,212.0158,4.1332788,0.74728644,0.0,0,8.296196,0.0,0.050694905,49.616951,8.9939003,501.65604,-9.2050247
2466,2466,212.016,4.3443217,0.77297872,0.0,0,8.268364,0.0,0.052556928,51.964676,8.9634037,501.67468,-9.2043943
2467,2467,212.0162,4.5384731,0.81803364,0.0,0,8.2405319,0.0,0.055625904,54.27713,8.9307165,501.68665,-9.2032223
2468,2468,212.0164,4.5298176,0.86730379,0.0,0,8.2126999,0.0,0.058723643,54.553673,8.895586,501.69861,-9.2024488
2469,2469,212.0166,4.3593755,0.9122141,0.0,0,8.1848679,0.0,0.06214026,52.593937,8.8591576,501.71057,-9.2028265
2470,2470,212.0168,4.266427,0.9489491,0.0,0,8.1570358,0.0,0.065069877,51.037079,8.8229828,501.72253,-9.2036152
2471,2471,212.017,4.2865639,0.98153418,0.0,0,8.1292038,0.0,0.06705045,50.9767,8.7860165,501.7345,-9.2037039
2472,2472,212.0172,4.289124,1.0204111,0.0,0,8.1013718,0.0,0.069743633,50.948566,8.7488508,501.74646,-9.2044029
2473,2473,212.0174,4.2390447,1.0617988,0.0,0,8.0735397,0.0,0.073018752,50.320885,8.712225,501.75842,-9.2051268
2474,2474,212.0176,4.2233405,1.099571,0.0,0,8.0462627,0.0,0.075507805,49.839485,8.6785889,501.77039,-9.2051668
2475,2475,212.0178,4.3469105,1.1265113,0.0,0,8.0196571,0.0,0.077553563,50.856861,8.644805,501.78235,-9.2051487
2476,2476,212.018,4.5103917,1.1443008,0.0,0,7.9931707,0.0,0.079341114,52.729218,8.6096077,501.79431,-9.2040243
2477,2477,212.0182,4.5245714,1.172526,0.0,0,7.9666901,0.0,0.080930486,53.265354,8.5780077,501.80627,-9.2026062
2478,2478,212.0184,4.3818164,1.2083062,0.0,0,7.9402103,0.0,0.083214201,51.731689,8.5502663,501.81824,-9.2023802
2479,2479,212.0186,4.2571316,1.237882,0.0,0,7.9137306,0.0,0.085872538,50.002243,8.5227251,501.8302,-9.2035332
2480,2480,212.0188,4.28403,1.2657642,0.0,0,7.8872504,0.0,0.08784093,49.917755,8.4952002,501.84216,-9.2041779
2481,2481,212.019,4.4171367,1.288114,0.0,0,7.8607702,0.0,0.089265496,51.140419,8.4672794,501.85413,-9.2043848
2482,2482,212.0192,4.5451837,1.3058175,0.0,0,7.8342905,0.0,0.090912707,52.54092,8.4393282,501.86609,-9.2050409
2483,2483,212.0194,4.5945773,1.3382673,0.0,0,7.8078103,0.0,0.093020916,53.221397,8.4138327,501.87805,-9.2046776
2484,2484,212.0196,4.5865283,1.3750155,0.0,0,7.7813301,0.0,0.095349781,53.137688,8.3860941,501.89001,-9.2039633
2485,2485,212.0198,4.5576525,1.3975751,0.0,0,7.7548499,0.0,0.097586431,52.746643,8.3567677,501.90198,-9.2037277
2486,2486,212.02,4.5215988,1.4272388,0.0,0,7.7283702,0.0,0.099725701,52.277645,8.3285055,501.91394,-9.2035131
2487,2487,212.0202,4.5011992,1.4644612,0.0,0,7.70189,0.0,0.10187296,51.871689,8.2990646,501.9259,-9.2027302
2488,2488,212.0204,4.4815497,1.4910991,0.0,0,7.6754098,0.0,0.10422342,51.470528,8.267312,501.93787,-9.2023411
2489,2489,212.0206,4.4667449,1.5202125,0.0,0,7.6489296,0.0,0.10665977,51.12125,8.2390032,501.9498,-9.2025681
2490,2490,212.0208,4.4926033,1.5465125,0.0,0,7.6224499,0.0,0.10826987,51.257099,8.2109013,501.96176,-9.2028656
2491,2491,212.021,4.5424066,1.5570456,0.0,0,7.5959702,0.0,0.10937048,51.713745,8.1817083,501.97372,-9.2038403
2492,2492,212.0212,4.5706477,1.5785086,0.0,0,7.56949,0.0,0.11109645,51.976467,8.1556473,501.98569,-9.2043362
2493,2493,212.0214,4.5489569,1.6114656,0.0,0,7.5430098,0.0,0.11299264,51.785442,8.1292582,501.99765,-9.2045126
2494,2494,212.0216,4.5029783,1.6326107,0.0,0,7.51653,0.0,0.1148096,51.256561,8.1037416,502.00961,-9.2049141
2495,2495,212.0218,4.4926457,1.6543568,0.0,0,7.4900503,0.0,0.11684057,50.854149,8.0794353,502.02158,-9.2049303
2496,2496,212.022,4.5347452,1.6772426,0.0,0,7.4635701,0.0,0.11811861,51.157665,8.0547934,502.03354,-9.2043943
2497,2497,212.0222,4.6077957,1.6897445,0.0,0,7.4370899,0.0,0.11907364,51.945431,8.0301304,502.0455,-9.2042303
2498,2498,212.0224,4.6735272,1.7125586,0.0,0,7.4106097,0.0,0.12109267,52.615307,8.0068331,502.05746,-9.2041321
2499,2499,212.0226,4.7201219,1.7456037,0.0,0,7.3846612,0.0,0.1231578,53.085365,7.9846311,502.06943,-9.2029533
2500,2500,212.0228,4.7504759,1.7677323,0.0,0,7.3593564,0.0,0.12480067,53.386154,7.9614358,502.08139,-9.2022238
2501,2501,212.023,4.7557735,1.7917222,0.0,0,7.3341675,0.0,0.12705985,53.362469,7.9360089,502.09335,-9.2027721
2502,2502,212.0232,4.7254953,1.8225329,0.0,0,7.3089833,0.0,0.1291517,52.94162,7.909739,502.10532,-9.2042503
2503,2503,212.0234,4.6645875,1.8488985,0.0,0,7.2837992,0.0,0.1308302,52.293461,7.8832064,502.11728,-9.2045555
2504,2504,212.0236,4.6320357,1.8787102,0.0,0,7.258615,0.0,0.13345648,51.762085,7.8577309,502.12924,-9.2045746
2505,2505,212.0238,4.6515846,1.909871,0.0,0,7.2334309,0.0,0.13584737,51.652882,7.8331323,502.1412,-9.2047024
2506,2506,212.024,4.6946511,1.9287583,0.0,0,7.2082467,0.0,0.13706782,51.990997,7.8077564,502.15317,-9.2040195
2507,2507,212.0242,4.7380195,1.9462199,0.0,0,7.1830626,0.0,0.13881186,52.50658,7.7819819,502.16513,-9.2033195
2508,2508,212.0244,4.7619882,1.9711094,0.0,0,7.1578784,0.0,0.14071539,52.779518,7.7576685,502.17709,-9.2033968
2509,2509,212.0246,4.7614875,1.9955289,0.0,0,7.1326947,0.0,0.14210683,52.690853,7.7345209,502.18906,-9.2035913
2510,2510,212.0248,4.7372599,2.0193539,0.0,0,7.1075106,0.0,0.14425983,52.315468,7.7078133,502.20102,-9.2040405
2511,2511,212.025,4.7090826,2.0421839,0.0,0,7.0823264,0.0,0.14628565,51.874535,7.681715,502.21298,-9.2041702
2512,2512,212.0252,4.7067747,2.0610893,0.0,0,7.0571427,0.0,0.14735743,51.695133,7.6607838,502.22495,-9.2037735
2513,2513,212.0254,4.7467828,2.0816073,0.0,0,7.0319586,0.0,0.14904173,51.914986,7.6404266,502.23691,-9.203804
2514,2514,212.0256,4.8034964,2.1062422,0.0,0,7.0067744,0.0,0.15118636,52.409096,7.6207342,502.24887,-9.2036715
2515,2515,212.0258,4.8544993,2.1322422,0.0,0,6.9815903,0.0,0.15280253,52.952328,7.5978894,502.26083,-9.2037039
2516,2516,212.026,4.897615,2.1557806,0.0,0,6.9564066,0.0,0.15472412,53.338642,7.5735087,502.22546,-9.2036877
2517,2517,212.0262,4.9109073,2.1772027,0.0,0,6.9312229,0.0,0.15681089,53.414066,7.5516315,502.16983,-9.2033119
2518,2518,212.0264,4.9018173,2.205229,0.0,0,6.9060383,0.0,0.15845057,53.288063,7.5283341,502.1142,-9.2033482
2519,2519,212.0266,4.8893294,2.2335839,0.0,0,6.8808546,0.0,0.16052693,53.026638,7.5027905,502.05859,-9.2037363
2520,2520,212.0268,4.8697495,2.254487,0.0,0,6.8556709,0.0,0.16279596,52.699692,7.4770403,502.00296,-9.2043934
2521,2521,212.027,4.8590384,2.278049,0.0,0,6.8304873,0.0,0.16435947,52.490433,7.4546075,501.94733,-9.2045622
2522,2522,212.0272,4.883523,2.299907,0.0,0,6.8053026,0.0,0.16588572,52.609409,7.4334126,501.89172,-9.2041197
2523,2523,212.0274,4.9261732,2.317333,0.0,0,6.7801185,0.0,0.16779517,52.987701,7.4091563,501.83609,-9.2040358
2524,2524,212.0276,4.9557123,2.3450408,0.0,0,6.7554369,0.0,0.16964832,53.252087,7.3830347,501.78046,-9.2039461
2525,2525,212.0278,4.9615822,2.3729856,0.0,0,6.7313623,0.0,0.17151824,53.219238,7.358386,501.72485,-9.203867
2526,2526,212.028,4.9486203,2.3896177,0.0,0,6.7073975,0.0,0.17344809,52.987457,7.3354535,501.66922,-9.2037258
2527,2527,212.0282,4.9551606,2.4127662,0.0,0,6.6834369,0.0,0.17516258,52.956989,7.3138752,501.61359,-9.2037497
2528,2528,212.0284,4.9868708,2.4387119,0.0,0,6.6594772,0.0,0.17673305,53.109585,7.2913442,501.55798,-9.2031584
2529,2529,212.0286,5.0058761,2.455097,0.0,0,6.6355171,0.0,0.17855249,53.210278,7.2677746,501.50235,-9.2030478
2530,2530,212.0288,5.0060925,2.4805779,0.0,0,6.611557,0.0,0.18053247,53.15881,7.2437034,501.44675,-9.2041149
2531,2531,212.029,5.0194454,2.5089803,0.0,0,6.5875969,0.0,0.18220848,53.22813,7.2199235,501.39111,-9.2041788
2532,2532,212.0292,5.0602984,2.5239732,0.0,0,6.5636373,0.0,0.18389083,53.522766,7.1971722,501.33548,-9.2038059
2533,2533,212.0294,5.0871472,2.5482821,0.0,0,6.5396771,0.0,0.18604802,53.750168,7.1705942,501.27988,-9.2043095
2534,2534,212.0296,5.0843563,2.5808766,0.0,0,6.5157175,0.0,0.18802229,53.734184,7.1447659,501.22424,-9.2043219
2535,2535,212.0298,5.0775523,2.6003699,0.0,0,6.4917574,0.0,0.18989179,53.492802,7.1198654,501.16861,-9.2037878
2536,2536,212.03,5.0794835,2.6244137,0.0,0,6.4677978,0.0,0.19220403,53.35305,7.0943246,501.11301,-9.2036409
2537,2537,212.0302,5.1099172,2.6531961,0.0,0,6.4438376,0.0,0.19396585,53.557106,7.0717988,501.05737,-9.2035437
2538,2538,212.0304,5.1572609,2.6687098,0.0,0,6.4198771,0.0,0.19541346,53.924931,7.0484362,501.00174,-9.2028875
2539,2539,212.0306,5.1960487,2.6915903,0.0,0,6.3959169,0.0,0.19769391,54.222893,7.0229244,500.94614,-9.2027769
2540,2540,212.0308,5.2077904,2.7230659,0.0,0,6.3719568,0.0,0.19972645,54.348953,6.9987607,500.8905,-9.2035608
2541,2541,212.031,5.1910191,2.7419031,0.0,0,6.3479972,0.0,0.20131622,54.099903,6.975841,500.83487,-9.2045097
2542,2542,212.0312,5.1745725,2.7636893,0.0,0,6.3240371,0.0,0.20354496,53.730839,6.9526544,500.77927,-9.2048655
2543,2543,212.0314,5.1814771,2.7921433,0.0,0,6.3000774,0.0,0.20544155,53.696999,6.9278212,500.72363,-9.2048779
2544,2544,212.0316,5.2138886,2.8119578,0.0,0,6.2761173,0.0,0.20692424,53.920029,6.9036636,500.668,-9.2040205
2545,2545,212.0318,5.2464385,2.8359451,0.0,0,6.2521577,0.0,0.20936412,54.169197,6.8802304,500.6124,-9.2030792
2546,2546,212.032,5.280756,2.8656924,0.0,0,6.2281976,0.0,0.21159923,54.397461,6.8538008,500.55676,-9.2032299
2547,2547,212.0322,5.3160005,2.8856633,0.0,0,6.2042375,0.0,0.21302091,54.594097,6.828866,500.50116,-9.2021275
2548,2548,212.0324,5.3416886,2.906956,0.0,0,6.1802773,0.0,0.21527225,54.775341,6.8059888,500.44553,-9.2009258
2549,2549,212.0326,5.3537574,2.9362142,0.0,0,6.1567979,0.0,0.21757461,54.818249,6.785346,500.38989,-9.2011127
2550,2550,212.0328,5.3407736,2.960149,0.0,0,6.1339006,0.0,0.21914555,54.598816,6.7630582,500.33429,-9.2017269
2551,2551,212.033,5.3142247,2.9833701,0.0,0,6.1111078,0.0,0.22146992,54.23877,6.7362504,500.27866,-9.2027893
2552,2552,212.0332,5.3033381,3.0105131,0.0,0,6.0883193,0.0,0.22383365,53.994286,6.710412,500.22302,-9.2042599
2553,2553,212.0334,5.3228364,3.0334342,0.0,0,6.0655317,0.0,0.22533593,54.052982,6.6855702,500.16742,-9.2055998
2554,2554,212.0336,5.3660169,3.0559464,0.0,0,6.0427437,0.0,0.22747803,54.328255,6.6595469,500.11179,-9.2053299
2555,2555,212.0338,5.4069934,3.0820899,0.0,0,6.0199556,0.0,0.22983873,54.606071,6.6361103,500.05615,-9.2047567
2556,2556,212.034,5.4296446,3.1065526,0.0,0,5.9971676,0.0,0.23143977,54.799976,6.6124129,500.00055,-9.2050714
2557,2557,212.0342,5.4536033,3.1283579,0.0,0,5.9743791,0.0,0.23348966,54.934303,6.5864177,499.94492,-9.2044096
2558,2558,212.0344,5.4689679,3.1510468,0.0,0,5.951591,0.0,0.23573755,54.998337,6.5622602,499.88928,-9.2038317
2559,2559,212.0346,5.4666686,3.1765437,0.0,0,5.9288034,0.0,0.237334,54.894978,6.5374928,499.83368,-9.2034197
2560,2560,212.0348,5.4590263,3.2012227,0.0,0,5.9060159,0.0,0.23946407,54.68716,6.5130582,499.77805,-9.2030401
2561,2561,212.035,5.4589558,3.2243125,0.0,0,5.8832278,0.0,0.24197005,54.551064,6.4907494,499.72244,-9.2033119
2562,2562,212.0352,5.4789524,3.2524178,0.0,0,5.8604393,0.0,0.24384309,54.638325,6.4662232,499.66681,-9.2034969
2563,2563,212.0354,5.5051379,3.278424,0.0,0,5.8376513,0.0,0.24589738,54.85083,6.4423604,499.61118,-9.203537
2564,2564,212.0356,5.535027,3.2989571,0.0,0,5.8148632,0.0,0.24832365,54.986629,6.4181657,499.55557,-9.2040176
2565,2565,212.0358,5.5622034,3.3267827,0.0,0,5.7920747,0.0,0.25029683,55.129791,6.3911676,499.49994,-9.2048054
2566,2566,212.036,5.5899725,3.3535819,0.0,0,5.7692871,0.0,0.25231802,55.282921,6.3667321,499.45389,-9.205101
2567,2567,212.0362,5.6056604,3.3727365,0.0,0,5.7464995,0.0,0.25467411,55.248722,6.3418431,499.41022,-9.2050762
2568,2568,212.0364,5.6015878,3.3999069,0.0,0,5.723711,0.0,0.25665614,55.0826,6.3159957,499.36658,-9.204627
2569,2569,212.0366,5.5941091,3.4272671,0.0,0,5.7009234,0.0,0.25849953,54.969311,6.2928085,499.32291,-9.204113
2570,2570,212.0368,5.6007781,3.445008,0.0,0,5.6781354,0.0,0.26076448,54.932865,6.2679801,499.27924,-9.203867
2571,2571,212.037,5.6214819,3.471827,0.0,0,5.6553473,0.0,0.26301533,54.938721,6.2440372,499.23557,-9.2030783
2572,2572,212.0372,5.634377,3.5005057,0.0,0,5.6325593,0.0,0.26486316,55.065533,6.2197781,499.19193,-9.2023506
2573,2573,212.0374,5.6565461,3.5164363,0.0,0,5.6097713,0.0,0.26686078,55.155247,6.1931767,499.14825,-9.2028713
2574,2574,212.0376,5.6769152,3.5406508,0.0,0,5.5874376,0.0,0.26906192,55.139568,6.1691017,499.10458,-9.2038355
2575,2575,212.0378,5.697401,3.5701516,0.0,0,5.5656543,0.0,0.27096105,55.191612,6.145988,499.06094,-9.2046251
2576,2576,212.038,5.7298675,3.5879002,0.0,0,5.5439696,0.0,0.27299574,55.329784,6.123529,499.01727,-9.2049599
2577,2577,212.0382,5.7504597,3.6133487,0.0,0,5.5222898,0.0,0.27544737,55.48035,6.1001134,498.9736,-9.2044811
2578,2578,212.0384,5.756115,3.6434965,0.0,0,5.5006094,0.0,0.27744004,55.496841,6.0745163,498.92996,-9.2044611
2579,2579,212.0386,5.7578993,3.6602364,0.0,0,5.4789295,0.0,0.27926844,55.378136,6.0480018,498.88629,-9.2044306
2580,2580,212.0388,5.7656207,3.6852591,0.0,0,5.4572492,0.0,0.28183115,55.303989,6.0222259,498.84262,-9.2045908
2581,2581,212.039,5.778728,3.7173607,0.0,0,5.4355693,0.0,0.28400266,55.350822,5.9996786,498.79895,-9.2043867
2582,2582,212.0392,5.7928967,3.7345607,0.0,0,5.4138894,0.0,0.28575456,55.420116,5.9776344,498.75531,-9.2035627
2583,2583,212.0394,5.8053522,3.7564752,0.0,0,5.3922095,0.0,0.28821468,55.395378,5.9507837,498.71164,-9.2035046
2584,2584,212.0396,5.8186555,3.7868929,0.0,0,5.3705292,0.0,0.29029012,55.389221,5.9258442,498.66797,-9.2032557
2585,2585,212.0398,5.844346,3.8066449,0.0,0,5.3488493,0.0,0.29204383,55.563011,5.9027395,498.62433,-9.2030926
2586,2586,212.04,5.8759284,3.8311815,0.0,0,5.3271694,0.0,0.29480821,55.727352,5.8785381,498.58066,-9.2039366
2587,2587,212.0402,5.8984818,3.8626831,0.0,0,5.3054895,0.0,0.29719919,55.760727,5.8559489,498.53699,-9.2041311
2588,2588,212.0404,5.9040384,3.8813658,0.0,0,5.2838092,0.0,0.29873124,55.695892,5.8311987,498.49335,-9.2034407
2589,2589,212.0406,5.900156,3.9022796,0.0,0,5.2621293,0.0,0.30117387,55.592152,5.8066745,498.44968,-9.2034254
2590,2590,212.0408,5.9023213,3.9312861,0.0,0,5.2404494,0.0,0.30349767,55.531544,5.7853332,498.40601,-9.2035904
2591,2591,212.041,5.9136314,3.9516006,0.0,0,5.2187696,0.0,0.3049731,55.488422,5.7607503,498.36234,-9.203928
2592,2592,212.0412,5.9321647,3.9722567,0.0,0,5.1970897,0.0,0.3074086,55.452908,5.7360654,498.3187,-9.2045298
2593,2593,212.0414,5.9562101,3.9985514,0.0,0,5.1754098,0.0,0.30979994,55.550743,5.7133002,498.27502,-9.2042828
2594,2594,212.0416,5.987329,4.0189033,0.0,0,5.1537294,0.0,0.3111842,55.771587,5.6898952,498.23135,-9.2036839
2595,2595,212.0418,6.0128794,4.0401239,0.0,0,5.1320496,0.0,0.31355652,55.882038,5.6653929,498.18771,-9.2030249
2596,2596,212.042,6.0266385,4.0667324,0.0,0,5.1103692,0.0,0.31612143,55.877113,5.6398039,498.14404,-9.2025328
2597,2597,212.0422,6.0403056,4.0900464,0.0,0,5.0886893,0.0,0.31769904,55.926907,5.6167707,498.10037,-9.2023602
2598,2598,212.0424,6.0489879,4.111639,0.0,0,5.0670094,0.0,0.32003549,55.907761,5.592989,498.05673,-9.2015781
2599,2599,212.0426,6.0564833,4.1359839,0.0,0,5.045764,0.0,0.32257038,55.840996,5.5695238,498.01306,-9.2015257
2600,2600,212.0428,6.0678773,4.1605539,0.0,0,5.0250449,0.0,0.32421073,55.866325,5.5488496,497.96939,-9.2020588
2601,2601,212.043,6.0753775,4.1828938,0.0,0,5.0044203,0.0,0.32645518,55.846405,5.5250664,497.92572,-9.2022486
2602,2602,212.0432,6.0842018,4.2056131,0.0,0,4.9838004,0.0,0.32899177,55.744381,5.4993644,497.88208,-9.2031126
2603,2603,212.0434,6.1060886,4.2306294,0.0,0,4.9631801,0.0,0.33070219,55.785389,5.4759846,497.83841,-9.2042818
2604,2604,212.0436,6.1351013,4.2531347,0.0,0,4.9425602,0.0,0.33282858,55.962852,5.4532986,497.79474,-9.2049246
2605,2605,212.0438,6.1579528,4.2737074,0.0,0,4.9219403,0.0,0.33533517,56.08622,5.4288416,497.7511,-9.2044525
2606,2606,212.044,6.1761088,4.2998075,0.0,0,4.9013205,0.0,0.33718041,56.093525,5.404882,497.70743,-9.2038717
2607,2607,212.0442,6.1839857,4.3224559,0.0,0,4.8807001,0.0,0.33924061,56.043121,5.3847103,497.66376,-9.2036467
2608,2608,212.0444,6.1990533,4.3398361,0.0,0,4.8600802,0.0,0.34163344,56.092239,5.3637576,497.62012,-9.2028246
2609,2609,212.0446,6.2052522,4.3649197,0.0,0,4.8394604,0.0,0.34343949,56.046188,5.3418741,497.57645,-9.2027292
2610,2610,212.0448,6.2014408,4.3878284,0.0,0,4.8188405,0.0,0.34526262,55.912159,5.3180137,497.53278,-9.2028093
2611,2611,212.045,6.214467,4.4035668,0.0,0,4.7982202,0.0,0.34754723,55.885597,5.2949395,497.48911,-9.2023678
2612,2612,212.0452,6.2403297,4.4296761,0.0,0,4.7776003,0.0,0.34966394,56.018932,5.2749634,497.44547,-9.202199
2613,2613,212.0454,6.2649002,4.4560103,0.0,0,4.7569804,0.0,0.35162863,56.136776,5.2534652,497.40179,-9.2021027
2614,2614,212.0456,6.2807755,4.4712944,0.0,0,4.7363601,0.0,0.35384127,56.098927,5.2280774,497.35812,-9.2023211
2615,2615,212.0458,6.2996702,4.4961863,0.0,0,4.7157402,0.0,0.35605964,56.096813,5.2040057,497.31448,-9.2029896
2616,2616,212.046,6.3181481,4.5240207,0.0,0,4.6951203,0.0,0.35799485,56.187843,5.1839747,497.34512,-9.2040653
2617,2617,212.0462,6.3283434,4.5396419,0.0,0,4.6745005,0.0,0.360194,56.229023,5.1635203,497.384,-9.2046671
2618,2618,212.0464,6.3423305,4.5642428,0.0,0,4.6538806,0.0,0.36265224,56.228466,5.1408701,497.42288,-9.204649
2619,2619,212.0466,6.3554282,4.5927458,0.0,0,4.6332603,0.0,0.36458969,56.213799,5.115571,497.46176,-9.2043858
2620,2620,212.0468,6.3591256,4.6067457,0.0,0,4.6126399,0.0,0.36650729,56.118587,5.0944629,497.50064,-9.2038364
2621,2621,212.047,6.3727365,4.6297331,0.0,0,4.59202,0.0,0.36899456,56.109158,5.0743008,497.53949,-9.2033014
2622,2622,212.0472,6.3873281,4.6591063,0.0,0,4.5714002,0.0,0.37101793,56.155666,5.0514579,497.57837,-9.2026854
2623,2623,212.0474,6.4044533,4.6732812,0.0,0,4.5507803,0.0,0.37283626,56.197937,5.0310159,497.61725,-9.2027817
2624,2624,212.0476,6.4249201,4.6947522,0.0,0,4.5305719,0.0,0.37538648,56.218891,5.0103617,497.65613,-9.2026491
2625,2625,212.0478,6.4423213,4.723155,0.0,0,4.5108619,0.0,0.37738341,56.238125,4.989368,497.69501,-9.2021027
2626,2626,212.048,6.4651566,4.7370009,0.0,0,4.4912419,0.0,0.37899143,56.335373,4.9664011,497.73389,-9.2030325
2627,2627,212.0482,6.4892178,4.7574115,0.0,0,4.4716258,0.0,0.38156345,56.384521,4.9418297,497.77277,-9.2036896
2628,2628,212.0484,6.4974523,4.7865586,0.0,0,4.4520097,0.0,0.38368899,56.347324,4.9211965,497.81165,-9.2034969
2629,2629,212.0486,6.4952464,4.8026409,0.0,0,4.432394,0.0,0.38529131,56.26078,4.9019079,497.85052,-9.203598
2630,2630,212.0488,6.5012641,4.8224506,0.0,0,4.4127779,0.0,0.38791561,56.154507,4.8785901,497.8894,-9.2041845
2631,2631,212.049,6.5141053,4.8511381,0.0,0,4.3931618,0.0,0.39018387,56.114887,4.8579245,497.92828,-9.2049561
2632,2632,212.0492,6.5240612,4.8685064,0.0,0,4.3735461,0.0,0.39165366,56.101608,4.83743,497.96713,-9.2048702
2633,2633,212.0494,6.5401416,4.8880148,0.0,0,4.35393,0.0,0.39420313,56.075752,4.8150468,498.00601,-9.2041759
2634,2634,212.0496,6.5673413,4.915133,0.0,0,4.3343139,0.0,0.39662024,56.1325,4.7973371,498.04489,-9.2036781
2635,2635,212.0498,6.5983319,4.9329767,0.0,0,4.3146982,0.0,0.39802557,56.333832,4.7762041,498.08377,-9.2042971
2636,2636,212.05,6.6270027,4.9505615,0.0,0,4.2950821,0.0,0.40045366,56.496655,4.752955,498.12265,-9.204339
2637,2637,212.0502,6.6402092,4.9754643,0.0,0,4.275466,0.0,0.40285873,56.507343,4.7321467,498.16153,-9.2036066
2638,2638,212.0504,6.6483097,4.9953742,0.0,0,4.2558494,0.0,0.40422371,56.529366,4.7112303,498.20041,-9.2035046
2639,2639,212.0506,6.6557899,5.0134935,0.0,0,4.2362337,0.0,0.40658394,56.416622,4.687499,498.23929,-9.2028341
2640,2640,212.0508,6.658742,5.0370975,0.0,0,4.2166176,0.0,0.40912431,56.258232,4.6667442,498.27817,-9.2021646
2641,2641,212.051,6.6608853,5.0572414,0.0,0,4.1970015,0.0,0.41055182,56.225433,4.6474242,498.31705,-9.2026291
2642,2642,212.0512,6.6689925,5.0755563,0.0,0,4.1773858,0.0,0.41279376,56.213463,4.6261621,498.35593,-9.202611
2643,2643,212.0514,6.6955533,5.0982947,0.0,0,4.1577697,0.0,0.41533321,56.291214,4.6055627,498.39478,-9.2028456
2644,2644,212.0516,6.7362452,5.1206822,0.0,0,4.1381536,0.0,0.41681808,56.520096,4.5835481,498.43365,-9.2028589
2645,2645,212.0518,6.7687693,5.1391768,0.0,0,4.1185379,0.0,0.41899422,56.68898,4.5615773,498.47253,-9.2034283
2646,2646,212.052,6.7893453,5.1583862,0.0,0,4.0989218,0.0,0.42156228,56.698841,4.5418401,498.51141,-9.204196
2647,2647,212.0522,6.8035216,5.1819439,0.0,0,4.0793056,0.0,0.42312846,56.715729,4.5226736,498.55029,-9.2036228
2648,2648,212.0524,6.8001695,5.2024341,0.0,0,4.05969,0.0,0.42517358,56.572937,4.5027933,498.58917,-9.2035437
2649,2649,212.0526,6.798667,5.2204452,0.0,0,4.0404677,0.0,0.42781177,56.395012,4.4810686,498.62805,-9.2029705
2650,2650,212.0528,6.8063083,5.2449284,0.0,0,4.0217218,0.0,0.42966577,56.383667,4.459321,498.66693,-9.2022839
2651,2651,212.053,6.8251805,5.266305,0.0,0,4.0030622,0.0,0.43168095,56.388065,4.4388514,498.70581,-9.2020893
2652,2652,212.0532,6.8525944,5.2816548,0.0,0,3.9844058,0.0,0.43415123,56.465363,4.420064,498.74469,-9.201993
2653,2653,212.0534,6.8782077,5.3066216,0.0,0,3.9657497,0.0,0.4360927,56.599613,4.3999906,498.78357,-9.2021523
2654,2654,212.0536,6.8988142,5.3292537,0.0,0,3.9470937,0.0,0.43800765,56.646191,4.3790584,498.82242,-9.2029066
2655,2655,212.0538,6.9227338,5.3433533,0.0,0,3.9284377,0.0,0.44041631,56.676159,4.3583837,498.8613,-9.2035236
2656,2656,212.054,6.9423642,5.3678021,0.0,0,3.9097817,0.0,0.44256732,56.705242,4.3344464,498.90018,-9.2035818
2657,2657,212.0542,6.9438634,5.3915987,0.0,0,3.8911257,0.0,0.44442528,56.652912,4.3130612,498.93906,-9.2031584
2658,2658,212.0544,6.9447446,5.404501,0.0,0,3.8724699,0.0,0.4466272,56.557644,4.2940116,498.97794,-9.2029982
2659,2659,212.0546,6.9499354,5.4273124,0.0,0,3.8538139,0.0,0.44878221,56.441135,4.2745752,499.01682,-9.2034054
2660,2660,212.0548,6.9603801,5.4518738,0.0,0,3.8351576,0.0,0.45059553,56.412224,4.2555275,499.05569,-9.2029085
2661,2661,212.055,6.9814234,5.4631138,0.0,0,3.8165019,0.0,0.45265615,56.479858,4.2362642,499.09457,-9.2023087
2662,2662,212.0552,7.0082321,5.4849415,0.0,0,3.7978458,0.0,0.45500994,56.527615,4.2151437,499.13345,-9.2022085
2663,2663,212.0554,7.0323782,5.5112991,0.0,0,3.7791896,0.0,0.45685425,56.614872,4.1967406,499.17233,-9.202322
2664,2664,212.0556,7.0605888,5.5224252,0.0,0,3.7605336,0.0,0.45875806,56.740845,4.1778522,499.21121,-9.2032108
2665,2665,212.0558,7.0825629,5.5424385,0.0,0,3.7418776,0.0,0.46125504,56.788631,4.1575422,499.25006,-9.2036819
2666,2666,212.056,7.0943804,5.5695024,0.0,0,3.7232218,0.0,0.46316242,56.83297,4.1386538,499.29373,-9.203558
2667,2667,212.0562,7.104815,5.5813656,0.0,0,3.7045658,0.0,0.46491462,56.8274,4.1184025,499.3374,-9.2033997
2668,2668,212.0564,7.1134892,5.601212,0.0,0,3.6859097,0.0,0.46756327,56.715229,4.0963297,499.38107,-9.203229
2669,2669,212.0566,7.1117835,5.6289964,0.0,0,3.6672537,0.0,0.4696207,56.600311,4.0746431,499.42471,-9.2026691
2670,2670,212.0568,7.1216464,5.6422954,0.0,0,3.6485977,0.0,0.47126949,56.578728,4.0558929,499.46838,-9.2020693
2671,2671,212.057,7.1418548,5.6611366,0.0,0,3.6299417,0.0,0.47398198,56.571598,4.0371265,499.51205,-9.2023144
2672,2672,212.0572,7.1560555,5.687377,0.0,0,3.6112857,0.0,0.47600892,56.553543,4.0182333,499.55569,-9.2030687
2673,2673,212.0574,7.1766672,5.700573,0.0,0,3.5926297,0.0,0.4773657,56.63847,3.9995565,499.59937,-9.2035217
2674,2674,212.0576,7.2070136,5.7178726,0.0,0,3.5743463,0.0,0.47998831,56.732578,3.9799347,499.64304,-9.2035294
2675,2675,212.0578,7.2322783,5.7442336,0.0,0,3.5565133,0.0,0.48220876,56.826252,3.9611008,499.68668,-9.2035866
2676,2676,212.058,7.2530546,5.7595048,0.0,0,3.5387616,0.0,0.48354718,56.905048,3.9418576,499.73035,-9.2035093
2677,2677,212.0582,7.2623992,5.7771859,0.0,0,3.5210135,0.0,0.48619655,56.816982,3.9226458,499.77402,-9.2031927
2678,2678,212.0584,7.262526,5.8029881,0.0,0,3.5032654,0.0,0.48868281,56.678528,3.9038858,499.81766,-9.2028418
2679,2679,212.0586,7.267344,5.8188181,0.0,0,3.4855173,0.0,0.48995316,56.654911,3.8852546,499.86133,-9.2025909
2680,2680,212.0588,7.2857766,5.8351531,0.0,0,3.4677694,0.0,0.49255127,56.668705,3.8674798,499.905,-9.2023211
2681,2681,212.059,7.3038001,5.859035,0.0,0,3.4500215,0.0,0.49515015,56.67226,3.8489618,499.94864,-9.2021713
2682,2682,212.0592,7.3167739,5.8767495,0.0,0,3.4322736,0.0,0.49636883,56.683281,3.8277662,499.99231,-9.2030048
2683,2683,212.0594,7.3480067,5.8919706,0.0,0,3.4145255,0.0,0.49871454,56.737324,3.8087013,500.03598,-9.2037315
2684,2684,212.0596,7.3772669,5.9132152,0.0,0,3.3967774,0.0,0.50121772,56.852585,3.7919261,500.07962,-9.2041454
2685,2685,212.0598,7.3994765,5.9329114,0.0,0,3.3790293,0.0,0.50251633,56.976444,3.7725933,500.12329,-9.2042122
2686,2686,212.06,7.4119282,5.9502378,0.0,0,3.3612814,0.0,0.50489169,56.977486,3.7543352,500.16696,-9.2038269
2687,2687,212.0602,7.4124875,5.971086,0.0,0,3.3435335,0.0,0.50766701,56.832813,3.7368755,500.2106,-9.2038269
2688,2688,212.0604,7.4089789,5.9926457,0.0,0,3.3257854,0.0,0.50920588,56.709583,3.7187181,500.25427,-9.2035837
2689,2689,212.0606,7.4193759,6.0105634,0.0,0,3.3080375,0.0,0.51148731,56.665718,3.6990809,500.29794,-9.2028036
2690,2690,212.0608,7.4389658,6.028141,0.0,0,3.2902894,0.0,0.51421607,56.645168,3.6785023,500.34161,-9.2021265
2691,2691,212.061,7.4532609,6.0501356,0.0,0,3.2725413,0.0,0.51581633,56.661446,3.6596091,500.38525,-9.2021084
2692,2692,212.0612,7.4819298,6.0687513,0.0,0,3.2547932,0.0,0.51780176,56.722828,3.6414673,500.42892,-9.202117
2693,2693,212.0614,7.5160675,6.0839729,0.0,0,3.2370453,0.0,0.52029318,56.847725,3.6226079,500.4726,-9.2020788
2694,2694,212.0616,7.5421772,6.1056552,0.0,0,3.2192974,0.0,0.52203178,56.975616,3.6035595,500.51624,-9.2024975
2695,2695,212.0618,7.5621634,6.1240215,0.0,0,3.2015493,0.0,0.5239445,56.983959,3.5846689,500.55991,-9.2032566
2696,2696,212.062,7.5730562,6.137742,0.0,0,3.1838014,0.0,0.52642882,56.922596,3.5653512,500.60358,-9.2034063
2697,2697,212.0622,7.5806293,6.16115,0.0,0,3.1660533,0.0,0.52840829,56.902496,3.5477746,500.64722,-9.2033873
2698,2698,212.0624,7.5816097,6.1817675,0.0,0,3.1483054,0.0,0.53028888,56.831623,3.5293357,500.69089,-9.2026148
2699,2699,212.0626,7.5820284,6.1930184,0.0,0,3.1309118,0.0,0.53268874,56.682846,3.5097065,500.73456,-9.2023821
2700,2700,212.0628,7.5979691,6.2151999,0.0,0,3.1139467,0.0,0.53479904,56.654755,3.4914277,500.7782,-9.2026091
2701,2701,212.063,7.6313133,6.2381287,0.0,0,3.0970592,0.0,0.53650683,56.80228,3.4719434,500.82187,-9.2020302
2702,2702,212.0632,7.6597719,6.2489886,0.0,0,3.0801752,0.0,0.53875989,56.882515,3.4538684,500.86554,-9.2027149
2703,2703,212.0634,7.6820178,6.2699456,0.0,0,3.0632911,0.0,0.54105431,56.933498,3.4363568,500.90918,-9.2034998
2704,2704,212.0636,7.7084093,6.2945585,0.0,0,3.0464072,0.0,0.54285526,56.997025,3.4171958,500.95285,-9.2028036
2705,2705,212.0638,7.72544,6.3051338,0.0,0,3.0295231,0.0,0.54502046,56.993019,3.3992093,500.99652,-9.2015438
2706,2706,212.064,7.7302856,6.3242764,0.0,0,3.012639,0.0,0.54748029,56.928059,3.3816018,501.04016,-9.2014866
2707,2707,212.0642,7.7398715,6.3491001,0.0,0,2.9957552,0.0,0.54928678,56.887882,3.3632572,501.08383,-9.2020941
2708,2708,212.0644,7.7546058,6.3591847,0.0,0,2.9788711,0.0,0.55114168,56.840897,3.3447704,501.1275,-9.2021198
2709,2709,212.0646,7.7680421,6.3782821,0.0,0,2.9619873,0.0,0.55383998,56.776943,3.3265779,501.17114,-9.2021065
2710,2710,212.0648,7.7835646,6.4045339,0.0,0,2.9451032,0.0,0.55583054,56.80658,3.30809,501.21481,-9.2021036
2711,2711,212.065,7.7985797,6.415381,0.0,0,2.9282191,0.0,0.55755436,56.835987,3.2889321,501.25848,-9.2020397
2712,2712,212.0652,7.8197093,6.4333243,0.0,0,2.911335,0.0,0.56030154,56.847752,3.2716799,501.30215,-9.2020264
2713,2713,212.0654,7.8534064,6.4589458,0.0,0,2.8944509,0.0,0.56225657,56.912785,3.2540016,501.34579,-9.2020264
2714,2714,212.0656,7.8808031,6.4696326,0.0,0,2.8775671,0.0,0.56369293,57.01403,3.2357101,501.38947,-9.2020483
2715,2715,212.0658,7.8982673,6.4852138,0.0,0,2.860683,0.0,0.56638032,57.043839,3.2182462,501.42239,-9.2020493
2716,2716,212.066,7.908247,6.5100293,0.0,0,2.8437991,0.0,0.56850922,57.029827,3.2004521,501.35898,-9.202199
2717,2717,212.0662,7.9104223,6.5218887,0.0,0,2.826915,0.0,0.5698095,57.001442,3.1823657,501.29559,-9.202817
2718,2718,212.0664,7.9246702,6.537015,0.0,0,2.8100309,0.0,0.57248145,56.922909,3.1641278,501.23218,-9.202692
2719,2719,212.0666,7.9503102,6.5625744,0.0,0,2.7931471,0.0,0.57495308,56.938568,3.1468718,501.16879,-9.2014904
2720,2720,212.0668,7.9629416,6.5774145,0.0,0,2.7762632,0.0,0.57625717,56.986572,3.1291804,501.10538,-9.2006674
2721,2721,212.067,7.9713898,6.5926447,0.0,0,2.7593791,0.0,0.57895237,56.909622,3.1100519,501.04199,-9.2011309
2722,2722,212.0672,7.9927454,6.6174064,0.0,0,2.7424951,0.0,0.58160073,56.924553,3.0938013,500.97861,-9.2021046
2723,2723,212.0674,8.0207376,6.6347332,0.0,0,2.7256112,0.0,0.58291489,57.062809,3.0795457,500.91519,-9.2023849
2724,2724,212.0676,8.0494862,6.6493263,0.0,0,2.7090652,0.0,0.58556306,57.0826,3.0628879,500.85181,-9.2022057
2725,2725,212.0678,8.0764704,6.6712923,0.0,0,2.6929281,0.0,0.5883168,57.104027,3.0437412,500.78839,-9.2021484
2726,2726,212.068,8.0940342,6.688715,0.0,0,2.6768646,0.0,0.58955944,57.141411,3.0259764,500.72501,-9.201993
2727,2727,212.0682,8.095706,6.702774,0.0,0,2.6608045,0.0,0.59186453,57.044651,3.0085216,500.66159,-9.2018833
2728,2728,212.0684,8.1006279,6.7216554,0.0,0,2.6447444,0.0,0.59443831,56.979561,2.9916973,500.59821,-9.2018757
2729,2729,212.0686,8.1157026,6.7383504,0.0,0,2.6286843,0.0,0.59553754,56.903858,2.9759095,500.53479,-9.2024546
2730,2730,212.0688,8.1317234,6.7524047,0.0,0,2.6126244,0.0,0.59773904,56.84782,2.9575379,500.47141,-9.2026386
2731,2731,212.069,8.1496038,6.769794,0.0,0,2.5965643,0.0,0.60042691,56.887249,2.9399548,500.40802,-9.2025118
2732,2732,212.0692,8.166008,6.7886052,0.0,0,2.5805042,0.0,0.60167474,56.963749,2.9219639,500.3446,-9.203228
2733,2733,212.0694,8.1950426,6.8043823,0.0,0,2.5644443,0.0,0.60383713,57.015488,2.9039209,500.28122,-9.2028332
2734,2734,212.0696,8.2380724,6.8211823,0.0,0,2.5483842,0.0,0.6068424,57.059425,2.8866594,500.2178,-9.2020893
2735,2735,212.0698,8.2651806,6.8437905,0.0,0,2.5323241,0.0,0.60859877,57.188889,2.8728085,500.15442,-9.2018881
2736,2736,212.07,8.2751722,6.8631859,0.0,0,2.5162642,0.0,0.61078417,57.185555,2.8568201,500.091,-9.2018633
2737,2737,212.0702,8.2803774,6.8778601,0.0,0,2.5002043,0.0,0.6136772,57.09758,2.8367591,500.02762,-9.202014
2738,2738,212.0704,8.289794,6.8986382,0.0,0,2.4841442,0.0,0.61550671,57.107689,2.8190107,499.96423,-9.2020378
2739,2739,212.0706,8.3048019,6.9169617,0.0,0,2.4680843,0.0,0.61746418,57.066143,2.801502,499.90082,-9.2027826
2740,2740,212.0708,8.3231077,6.9293232,0.0,0,2.4520242,0.0,0.62010598,56.986828,2.782928,499.83743,-9.2035179
2741,2741,212.071,8.3438911,6.9501309,0.0,0,2.4359643,0.0,0.62198251,57.006371,2.764658,499.77402,-9.2033453
2742,2742,212.0712,8.3756695,6.9686966,0.0,0,2.4199045,0.0,0.62365347,57.088242,2.7471542,499.71063,-9.2027903
2743,2743,212.0714,8.4150333,6.9784193,0.0,0,2.4038444,0.0,0.62600309,57.188034,2.7299192,499.64722,-9.2024145
2744,2744,212.0716,8.4385653,6.9984703,0.0,0,2.3877842,0.0,0.6280793,57.260208,2.7145245,499.58383,-9.2023945
2745,2745,212.0718,8.4506884,7.0200586,0.0,0,2.3717244,0.0,0.62987006,57.262608,2.6981156,499.52045,-9.2019358
2746,2746,212.072,8.4620066,7.0306134,0.0,0,2.3556643,0.0,0.63234705,57.221783,2.6810267,499.45703,-9.2019167
2747,2747,212.0722,8.4661722,7.0513864,0.0,0,2.3396041,0.0,0.63488758,57.122601,2.6635833,499.39365,-9.2016563
2748,2748,212.0724,8.4661388,7.0759344,0.0,0,2.3235443,0.0,0.6367712,57.017075,2.6444709,499.33023,-9.2016459
2749,2749,212.0726,8.4766636,7.0848813,0.0,0,2.307806,0.0,0.63897574,56.961765,2.627779,499.26685,-9.2022715
2750,2750,212.0728,8.5011301,7.1026917,0.0,0,2.2924564,0.0,0.64156866,56.928661,2.6102755,499.20343,-9.202137
2751,2751,212.073,8.530757,7.1275768,0.0,0,2.2771773,0.0,0.64342618,56.993095,2.590883,499.14005,-9.202301
2752,2752,212.0732,8.5581551,7.1365876,0.0,0,2.2619011,0.0,0.6453287,57.117168,2.5756938,499.07663,-9.2028513
2753,2753,212.0734,8.5907087,7.1524434,0.0,0,2.2466252,0.0,0.64806169,57.148403,2.5601807,499.01324,-9.2030277
2754,2754,212.0736,8.618248,7.1762285,0.0,0,2.2313492,0.0,0.64990979,57.227669,2.5423298,498.94986,-9.2025223
2755,2755,212.0738,8.6315842,7.1854105,0.0,0,2.2160735,0.0,0.65145218,57.276592,2.5270007,498.88644,-9.2020788
2756,2756,212.074,8.6359129,7.2012424,0.0,0,2.2007973,0.0,0.65430295,57.14463,2.5122135,498.82306,-9.2020369
2757,2757,212.0742,8.6377888,7.2268071,0.0,0,2.1855214,0.0,0.65633279,57.086395,2.4939663,498.75964,-9.2019758
2758,2758,212.0744,8.6533146,7.2369967,0.0,0,2.1702452,0.0,0.65777445,57.08802,2.4762735,498.69626,-9.2017078
2759,2759,212.0746,8.6736393,7.251585,0.0,0,2.1549692,0.0,0.66079146,57.032043,2.45945,498.63284,-9.2017441
2760,2760,212.0748,8.698431,7.2761798,0.0,0,2.1396933,0.0,0.66309875,57.061378,2.4415488,498.56946,-9.2020569
2761,2761,212.075,8.7288942,7.2879229,0.0,0,2.1244173,0.0,0.66445023,57.140671,2.4254413,498.50607,-9.2020817
2762,2762,212.0752,8.756649,7.3019972,0.0,0,2.1091413,0.0,0.66723728,57.168171,2.4130833,498.44266,-9.2013321
2763,2763,212.0754,8.7921038,7.3251448,0.0,0,2.0938654,0.0,0.66957045,57.234726,2.3989587,498.37927,-9.2012529
2764,2764,212.0756,8.8205671,7.3382163,0.0,0,2.0785894,0.0,0.67084748,57.355652,2.3815873,498.31586,-9.2017765
2765,2765,212.0758,8.8273344,7.3520651,0.0,0,2.0633135,0.0,0.67370504,57.305225,2.3642755,498.22668,-9.2011175
2766,2766,212.076,8.8274775,7.3748779,0.0,0,2.0480375,0.0,0.67635167,57.152496,2.3466227,498.03464,-9.2012682
2767,2767,212.0762,8.8307343,7.3893785,0.0,0,2.0327616,0.0,0.6774528,57.098804,2.3273668,497.84259,-9.2018042
2768,2768,212.0764,8.8394594,7.4021831,0.0,0,2.0174854,0.0,0.68010813,57.033447,2.3093004,497.65054,-9.2011166
2769,2769,212.0766,8.8612137,7.4231057,0.0,0,2.0022092,0.0,0.68291831,56.983936,2.2929122,497.4585,-9.2012768
2770,2770,212.0768,8.8933849,7.4391375,0.0,0,1.9869331,0.0,0.68399084,57.080219,2.2746289,497.26645,-9.2020245
2771,2771,212.077,8.9183407,7.4513516,0.0,0,1.9716572,0.0,0.6863839,57.157368,2.2592211,497.0744,-9.2020636
2772,2772,212.0772,8.9417934,7.4700274,0.0,0,1.9563811,0.0,0.6893,57.139683,2.2450705,496.88239,-9.2018824
2773,2773,212.0774,8.9726391,7.4874935,0.0,0,1.9411051,0.0,0.6905266,57.203358,2.2287385,496.69034,-9.2018576
2774,2774,212.0776,8.9981833,7.5004478,0.0,0,1.9261345,0.0,0.69276208,57.250584,2.2142336,496.49829,-9.2020149
2775,2775,212.0778,9.0170584,7.5167923,0.0,0,1.9115326,0.0,0.69564581,57.225925,2.1977718,496.30624,-9.2025785
2776,2776,212.078,9.0223837,7.5354819,0.0,0,1.8969977,0.0,0.69698644,57.197529,2.1796417,496.1142,-9.2026005
2777,2777,212.0782,9.0246325,7.5497398,0.0,0,1.8824656,0.0,0.69913995,57.088589,2.1631608,495.92215,-9.2021303
2778,2778,212.0784,9.0475969,7.5644774,0.0,0,1.8679335,0.0,0.70212501,56.996792,2.145757,495.7301,-9.202075
2779,2779,212.0786,9.0736246,7.5846124,0.0,0,1.8534015,0.0,0.70371717,57.085926,2.1320395,495.53806,-9.2019653
2780,2780,212.0788,9.0998011,7.6003828,0.0,0,1.8388696,0.0,0.70569927,57.180489,2.1180453,495.34601,-9.2019148
2781,2781,212.079,9.1242123,7.612402,0.0,0,1.8243376,0.0,0.7085278,57.173801,2.101284,495.15396,-9.2018795
2782,2782,212.0792,9.1524734,7.6322603,0.0,0,1.8098055,0.0,0.71023983,57.246159,2.086283,494.96191,-9.2019091
2783,2783,212.0794,9.1849461,7.6492891,0.0,0,1.7952735,0.0,0.71218914,57.364304,2.0697634,494.76987,-9.2019377
2784,2784,212.0796,9.206563,7.6595321,0.0,0,1.7807416,0.0,0.71504813,57.358315,2.0551395,494.57782,-9.2018976
2785,2785,212.0798,9.2132702,7.680408,0.0,0,1.7662096,0.0,0.71706593,57.222912,2.0403764,494.38577,-9.2019415
2786,2786,212.08,9.2135839,7.6990376,0.0,0,1.7516776,0.0,0.7188133,57.127945,2.0261471,494.19373,-9.2019405
2787,2787,212.0802,9.216527,7.7074981,0.0,0,1.7371455,0.0,0.72142345,57.038113,2.0129077,494.00168,-9.2019434
2788,2788,212.0804,9.2236748,7.7271023,0.0,0,1.7226136,0.0,0.72375315,56.9431,1.9956694,493.80963,-9.202034
2789,2789,212.0806,9.2448664,7.7472787,0.0,0,1.7080816,0.0,0.72545183,56.979698,1.978792,493.61758,-9.2020388
2790,2790,212.0808,9.2816172,7.7553453,0.0,0,1.6935496,0.0,0.72767502,57.066162,1.9621149,493.42554,-9.2018433
2791,2791,212.081,9.3175459,7.7735577,0.0,0,1.6790177,0.0,0.73004657,57.114956,1.9471576,493.23349,-9.2019854
2792,2792,212.0812,9.3460579,7.7950068,0.0,0,1.6644856,0.0,0.73180228,57.197083,1.9329875,493.04144,-9.2021818
2793,2793,212.0814,9.3720798,7.801898,0.0,0,1.6499536,0.0,0.73389173,57.207489,1.9170934,492.8494,-9.2020407
2794,2794,212.0816,9.3948517,7.8188429,0.0,0,1.6354215,0.0,0.73663169,57.163521,1.8998902,492.65735,-9.2021132
2795,2795,212.0818,9.4149122,7.8424983,0.0,0,1.6208895,0.0,0.7386325,57.204319,1.884527,492.4653,-9.2020388
2796,2796,212.082,9.4230118,7.8502526,0.0,0,1.6063576,0.0,0.74050522,57.150188,1.8687606,492.27325,-9.2021084
2797,2797,212.0822,9.4341593,7.8663096,0.0,0,1.5918256,0.0,0.7434724,57.069229,1.8512453,492.08121,-9.2021885
2798,2798,212.0824,9.4555979,7.8901587,0.0,0,1.5772935,0.0,0.74542791,57.110741,1.8368355,491.88916,-9.2020302
2799,2799,212.0826,9.4765558,7.8977761,0.0,0,1.5630522,0.0,0.74690926,57.16172,1.8248329,491.69711,-9.2017546
2800,2800,212.0828,9.5012789,7.9121518,0.0,0,1.5491617,0.0,0.74997634,57.146683,1.8094981,491.50507,-9.201746
2801,2801,212.083,9.5262556,7.9359016,0.0,0,1.5353347,0.0,0.75208604,57.178429,1.7927859,491.31305,-9.2013254
2802,2802,212.0832,9.5505495,7.9441915,0.0,0,1.5215106,0.0,0.75335473,57.257595,1.7779266,491.121,-9.2012854
2803,2803,212.0834,9.5751657,7.956255,0.0,0,1.5076866,0.0,0.75625557,57.237331,1.7631581,490.92896,-9.201437
2804,2804,212.0836,9.5956869,7.9796634,0.0,0,1.4938626,0.0,0.75841671,57.230408,1.7451169,490.73691,-9.201478
2805,2805,212.0838,9.6080751,7.9893942,0.0,0,1.4800386,0.0,0.7595191,57.223297,1.7291431,490.54486,-9.2020121
2806,2806,212.084,9.6169538,8.0007219,0.0,0,1.4662145,0.0,0.76254541,57.126072,1.7165998,490.35281,-9.201992
2807,2807,212.0842,9.6288528,8.0235691,0.0,0,1.4523906,0.0,0.76511019,57.075829,1.7010918,490.16077,-9.2021122
2808,2808,212.0844,9.6471424,8.0354719,0.0,0,1.4385666,0.0,0.76616031,57.079113,1.6865908,489.96872,-9.202117
2809,2809,212.0846,9.6742563,8.0471458,0.0,0,1.4247426,0.0,0.76904064,57.052067,1.671284,489.77667,-9.2025328
2810,2810,212.0848,9.6998644,8.0691566,0.0,0,1.4109187,0.0,0.77192515,57.069614,1.6551576,489.58463,-9.2022943
2811,2811,212.085,9.7298737,8.0834198,0.0,0,1.3970947,0.0,0.77301913,57.176964,1.641516,489.39258,-9.2015982
2812,2812,212.0852,9.7634659,8.0948238,0.0,0,1.3832707,0.0,0.77567178,57.196968,1.6263651,489.20053,-9.2017908
2813,2813,212.0854,9.7890177,8.1136866,0.0,0,1.3694466,0.0,0.77856481,57.211052,1.6107889,489.00848,-9.2017918
2814,2814,212.0856,9.8138552,8.1282425,0.0,0,1.3556226,0.0,0.77950191,57.33152,1.5967709,488.81644,-9.2007866
2815,2815,212.0858,9.8338327,8.1393023,0.0,0,1.3417987,0.0,0.78198379,57.274475,1.5822064,488.63516,-9.2001562
2816,2816,212.086,9.8435755,8.1552362,0.0,0,1.3279747,0.0,0.78487164,57.132206,1.5681119,488.47897,-9.2010565
2817,2817,212.0862,9.8576689,8.1705151,0.0,0,1.3141507,0.0,0.78587723,57.166664,1.5521512,488.32278,-9.2016315
2818,2818,212.0864,9.879508,8.1820478,0.0,0,1.3003267,0.0,0.78809232,57.192455,1.5365564,488.1666,-9.2011099
2819,2819,212.0866,9.9051943,8.1968412,0.0,0,1.2865027,0.0,0.79096228,57.196796,1.5236763,488.01041,-9.2007599
2820,2820,212.0868,9.9291477,8.2143354,0.0,0,1.2726787,0.0,0.79225761,57.255924,1.5111275,487.85425,-9.2010031
2821,2821,212.087,9.9585161,8.2276449,0.0,0,1.2588546,0.0,0.79447567,57.279419,1.4956852,487.69806,-9.2010069
2822,2822,212.0872,9.9903212,8.2413797,0.0,0,1.2450306,0.0,0.79762578,57.280045,1.4796824,487.54187,-9.2007275
2823,2823,212.0874,10.012538,8.260725,0.0,0,1.2312068,0.0,0.79923654,57.328892,1.4666802,487.38568,-9.2010927
2824,2824,212.0876,10.026729,8.2749519,0.0,0,1.2176601,0.0,0.80124372,57.306831,1.4541095,487.22949,-9.2010984
2825,2825,212.0878,10.042408,8.2856197,0.0,0,1.2044488,0.0,0.80426866,57.205303,1.438524,487.0733,-9.200676
2826,2826,212.088,10.057078,8.3052816,0.0,0,1.1912981,0.0,0.80607659,57.188747,1.4248991,486.91711,-9.201335
2827,2827,212.0882,10.071136,8.3204021,0.0,0,1.1781499,0.0,0.80777591,57.208698,1.4115416,486.76093,-9.2017546
2828,2828,212.0884,10.091084,8.3275681,0.0,0,1.165002,0.0,0.8104431,57.155499,1.396644,486.60477,-9.201231
2829,2829,212.0886,10.109376,8.3448887,0.0,0,1.1518539,0.0,0.812392,57.123383,1.3823025,486.44858,-9.2007761
2830,2830,212.0888,10.132001,8.3613272,0.0,0,1.1387058,0.0,0.81386596,57.147041,1.3666073,486.29239,-9.2000713
2831,2831,212.089,10.166443,8.3673105,0.0,0,1.1255579,0.0,0.8162142,57.156563,1.3526235,486.1362,-9.200078
2832,2832,212.0892,10.201784,8.3838568,0.0,0,1.1124099,0.0,0.81841969,57.231476,1.3392409,485.98001,-9.2006102
2833,2833,212.0894,10.229846,8.4033098,0.0,0,1.0992619,0.0,0.82008457,57.33128,1.3242908,485.82382,-9.2004814
2834,2834,212.0896,10.257632,8.4092569,0.0,0,1.0861139,0.0,0.82238948,57.366997,1.3082106,485.66763,-9.2004299
2835,2835,212.0898,10.276566,8.426671,0.0,0,1.0729659,0.0,0.82499164,57.304695,1.2924497,485.51144,-9.2011147
2836,2836,212.09,10.29068,8.4484797,0.0,0,1.0598178,0.0,0.82686448,57.2752,1.2797973,485.35529,-9.2019377
2837,2837,212.0902,10.309725,8.4540091,0.0,0,1.0466698,0.0,0.8290695,57.300041,1.26715,485.1991,-9.2019911
2838,2838,212.0904,10.328049,8.4695177,0.0,0,1.0335219,0.0,0.83186477,57.241432,1.25121,485.04291,-9.2020159
2839,2839,212.0906,10.349352,8.4917994,0.0,0,1.0203738,0.0,0.83361083,57.237839,1.2348739,484.88672,-9.2020588
2840,2840,212.0908,10.378357,8.4976416,0.0,0,1.0072259,0.0,0.83531129,57.288834,1.2224272,484.73053,-9.2013092
2841,2841,212.091,10.415118,8.510973,0.0,0,0.9940778,0.0,0.8382681,57.327232,1.2091559,484.57434,-9.200531
2842,2842,212.0912,10.452432,8.5329895,0.0,0,0.98092979,0.0,0.84014779,57.395664,1.1940018,484.41815,-9.2006502
2843,2843,212.0914,10.483572,8.538867,0.0,0,0.96778184,0.0,0.84152341,57.475388,1.1812811,484.26196,-9.2006102
2844,2844,212.0916,10.507616,8.5516996,0.0,0,0.95463383,0.0,0.84470934,57.429348,1.1669101,484.1058,-9.2009649
2845,2845,212.0918,10.512852,8.5741682,0.0,0,0.94148582,0.0,0.84675306,57.359425,1.1535712,483.94962,-9.2010336
2846,2846,212.092,10.515306,8.5815601,0.0,0,0.92833787,0.0,0.8479268,57.333099,1.1398399,483.79343,-9.2007084
2847,2847,212.0922,10.534019,8.5935478,0.0,0,0.91518986,0.0,0.85107285,57.229649,1.1253737,483.63724,-9.2012768
2848,2848,212.0924,10.552951,8.6156101,0.0,0,0.90204185,0.0,0.85337967,57.232281,1.1107247,483.48105,-9.2015085
2849,2849,212.0926,10.571198,8.6237497,0.0,0,0.88915813,0.0,0.85447085,57.275948,1.0963587,483.32486,-9.2016153
2850,2850,212.0928,10.601987,8.6342392,0.0,0,0.87659371,0.0,0.85759956,57.247635,1.0838684,483.16867,-9.2019577
2851,2851,212.093,10.642798,8.6553345,0.0,0,0.86408705,0.0,0.86007285,57.307209,1.0702001,483.01248,-9.2019997
2852,2852,212.0932,10.684377,8.6657181,0.0,0,0.85158294,0.0,0.86086506,57.451889,1.0566212,482.85632,-9.201684
2853,2853,212.0934,10.710295,8.6757584,0.0,0,0.83907896,0.0,0.86376905,57.456512,1.0430733,482.70013,-9.2016802
2854,2854,212.0936,10.720778,8.6950254,0.0,0,0.82657492,0.0,0.86655414,57.393044,1.0307856,482.54395,-9.2013435
2855,2855,212.0938,10.726612,8.7073183,0.0,0,0.81407094,0.0,0.86741632,57.391003,1.0193367,482.38776,-9.2006245
2856,2856,212.094,10.735043,8.7167692,0.0,0,0.80156696,0.0,0.87011957,57.266033,1.0038257,482.23157,-9.201107
2857,2857,212.0942,10.756697,8.7345171,0.0,0,0.78906298,0.0,0.87315327,57.171936,0.98966324,482.07538,-9.2011623
2858,2858,212.0944,10.786724,8.7488356,0.0,0,0.776559,0.0,0.87419462,57.279888,0.97747213,481.91919,-9.2014246
2859,2859,212.0946,10.821868,8.7582722,0.0,0,0.76405495,0.0,0.87668157,57.29076,0.96148169,481.763,-9.2022905
2860,2860,212.0948,10.859126,8.7733421,0.0,0,0.75155091,0.0,0.87958694,57.31654,0.94729561,481.60681,-9.2022142
2861,2861,212.095,10.895864,8.7880354,0.0,0,0.73904693,0.0,0.88048178,57.474155,0.93649954,481.45065,-9.2025976
2862,2862,212.0952,10.934608,8.7978678,0.0,0,0.72654295,0.0,0.88269174,57.508785,0.92203104,481.29446,-9.2025919
2863,2863,212.0954,10.963499,8.8104544,0.0,0,0.71403897,0.0,0.8857066,57.504585,0.90855134,481.13828,-9.2019176
2864,2864,212.0956,10.973207,8.8267717,0.0,0,0.70153493,0.0,0.88681173,57.533016,0.89633507,480.98209,-9.2013149
2865,2865,212.0958,10.974577,8.8392801,0.0,0,0.68903095,0.0,0.88896555,57.44062,0.88214546,480.89874,-9.2006645
2866,2866,212.096,10.983575,8.8507862,0.0,0,0.67652696,0.0,0.89213544,57.284924,0.871306,480.92447,-9.2004099
2867,2867,212.0962,11.009159,8.8686171,0.0,0,0.66402298,0.0,0.89370084,57.307678,0.85873324,480.95023,-9.2003946
2868,2868,212.0964,11.037493,8.8819847,0.0,0,0.651519,0.0,0.89571363,57.347836,0.84571612,480.97595,-9.2010469
2869,2869,212.0966,11.062564,8.8904867,0.0,0,0.63901496,0.0,0.89871317,57.30822,0.8328529,481.00168,-9.2013235
2870,2870,212.0968,11.098602,8.9088144,0.0,0,0.62651092,0.0,0.90059841,57.412193,0.81776971,481.02744,-9.2006807
2871,2871,212.097,11.139974,8.9234352,0.0,0,0.61400694,0.0,0.90238237,57.52005,0.80283672,481.05316,-9.2005634
2872,2872,212.0972,11.163664,8.9298182,0.0,0,0.60150295,0.0,0.90517813,57.463955,0.78997648,481.07892,-9.2006941
2873,2873,212.0974,11.173114,8.9480219,0.0,0,0.58899897,0.0,0.90720803,57.439625,0.77888685,481.10464,-9.2005453
2874,2874,212.0976,11.183661,8.9630585,0.0,0,0.57674277,0.0,0.90866333,57.425804,0.76483279,481.1304,-9.2002125
2875,2875,212.0978,11.205499,8.9658861,0.0,0,0.5647862,0.0,0.91098833,57.361103,0.75083899,481.15613,-9.1999292
2876,2876,212.098,11.227909,8.9812698,0.0,0,0.55288374,0.0,0.91306317,57.330093,0.74007958,481.18188,-9.1999722
2877,2877,212.0982,11.248479,8.9984713,0.0,0,0.54098368,0.0,0.91452938,57.344288,0.72721446,481.20761,-9.2001839
2878,2878,212.0984,11.274736,9.0017385,0.0,0,0.52908367,0.0,0.91666114,57.364155,0.71413207,481.23334,-9.2003241
2879,2879,212.0986,11.312044,9.0166521,0.0,0,0.5171836,0.0,0.9190715,57.417747,0.70064229,481.25909,-9.2010765
2880,2880,212.0988,11.353132,9.0373306,0.0,0,0.50528359,0.0,0.92078632,57.520256,0.68670177,481.28482,-9.201932
2881,2881,212.099,11.386419,9.0414953,0.0,0,0.49338362,0.0,0.92304951,57.583736,0.67299551,481.31058,-9.2018509
2882,2882,212.0992,11.412438,9.0558681,0.0,0,0.48148361,0.0,0.92614126,57.526928,0.65918589,481.3363,-9.2009659
2883,2883,212.0994,11.4297,9.0788565,0.0,0,0.46958363,0.0,0.92798841,57.502365,0.64772063,481.36206,-9.2003613
2884,2884,212.0996,11.450694,9.0837603,0.0,0,0.45768362,0.0,0.92973602,57.503319,0.6361739,481.38779,-9.2003889
2885,2885,212.0998,11.465053,9.0963049,0.0,0,0.44578362,0.0,0.93297118,57.393337,0.62365824,481.41354,-9.2003412
2886,2886,212.1,11.478447,9.1175089,0.0,0,0.43388361,0.0,0.93491852,57.384548,0.61141205,481.43927,-9.2003794
2887,2887,212.1002,11.501142,9.1215506,0.0,0,0.42198363,0.0,0.93608743,57.421432,0.59749031,481.465,-9.2001114
2888,2888,212.1004,11.53162,9.1316843,0.0,0,0.41008362,0.0,0.9391163,57.396343,0.58425987,481.49075,-9.1999397