File: clean data/testID_0105.csv
level_0,index,Time(sec),Force(kN),Jaw(mm),PowAngle(deg),Power(W),Pram,PTemp,Strain,Stress(MPa),Stroke(mm),TC1(C),wedge(mm)
2262,2262,178.7098,1.3446161,0.023126272,0.0,0,9.9218636,0.0,0.0014041978,16.765459,10.017121,400.12747,-9.2656975
2273,2273,178.712,2.5857844,0.030623376,0.0,0,9.8888636,0.0,0.0022382999,32.609283,9.9836283,400.14072,-9.2645664
2284,2284,178.7142,3.8869066,0.054021928,0.0,0,9.8558636,0.0,0.0033332673,49.097805,9.9578571,400.17953,-9.2641716
2295,2295,178.7164,4.9626589,0.067940891,0.0,0,9.8228636,0.0,0.0046566403,62.694283,9.9216089,400.30536,-9.2630529
2306,2306,178.7186,5.5105643,0.097425215,0.0,0,9.7898636,0.0,0.0064124824,69.578392,9.8890772,400.43118,-9.2635221
2317,2317,178.7208,5.8891978,0.12782896,0.0,0,9.7568636,0.0,0.0087447474,74.297737,9.8574495,400.55698,-9.2625818
2328,2328,178.723,6.1862016,0.16929704,0.0,0,9.7238636,0.0,0.011068443,77.805122,9.8202877,400.6828,-9.2625237
2339,2339,178.7252,6.4085975,0.19769305,0.0,0,9.6908636,0.0,0.013395259,80.481514,9.779727,400.82669,-9.2630835
2350,2350,178.7274,6.5668116,0.23297505,0.0,0,9.6578636,0.0,0.015472078,82.341354,9.7409773,400.979,-9.261405
2361,2361,178.7296,6.6821318,0.26351681,0.0,0,9.6248636,0.0,0.017883837,83.597656,9.7065725,401.13132,-9.2616901
2372,2372,178.7318,6.7852783,0.3025181,0.0,0,9.5918636,0.0,0.020136401,84.636497,9.6765232,401.28363,-9.2620993
2383,2383,178.734,6.8862762,0.32962844,0.0,0,9.5588636,0.0,0.022303496,85.646538,9.6385946,401.42511,-9.2616711
2394,2394,178.7362,6.9637976,0.36329606,0.0,0,9.5258636,0.0,0.024384568,86.553978,9.60676,401.49796,-9.2613745
2405,2405,178.7384,7.0352378,0.39243588,0.0,0,9.4928637,0.0,0.026673174,87.173683,9.5727396,401.5708,-9.2614422
2416,2416,178.7406,7.1096807,0.43056166,0.0,0,9.4604025,0.0,0.028870989,88.001587,9.5393829,401.64365,-9.2625828
2427,2427,178.7428,7.1557188,0.45889321,0.0,0,9.4282112,0.0,0.031101726,88.291679,9.5047331,401.71649,-9.2628956
2438,2438,178.745,7.1916862,0.4921703,0.0,0,9.3960209,0.0,0.033236165,88.552208,9.4746933,401.77368,-9.2630625
2449,2449,178.7472,7.2223554,0.51994914,0.0,0,9.3638315,0.0,0.035338961,88.72187,9.4434118,401.82001,-9.2625608
2460,2460,178.7494,7.2745109,0.55995208,0.0,0,9.3316412,0.0,0.037823979,89.154297,9.4080992,401.86636,-9.2630787
2471,2471,178.7516,7.3145242,0.58783299,0.0,0,9.2994499,0.0,0.040026676,89.404892,9.3739157,401.91272,-9.2624702
2482,2482,178.7538,7.3664236,0.62171769,0.0,0,9.2672586,0.0,0.042239945,89.895432,9.3419304,401.95999,-9.2638092
2493,2493,178.756,7.4197164,0.65001917,0.0,0,9.2350683,0.0,0.044367325,90.306648,9.308856,402.02618,-9.2634811
2504,2504,178.7582,7.4386415,0.68720931,0.0,0,9.202879,0.0,0.046715006,90.283005,9.2739134,402.09241,-9.262949
2515,2515,178.7604,7.4668202,0.71440697,0.0,0,9.1706886,0.0,0.048800502,90.537659,9.2446527,402.15863,-9.2621574
2526,2526,178.7626,7.4979162,0.74906129,0.0,0,9.1384983,0.0,0.051126432,90.695976,9.2125721,402.22485,-9.2628832
2537,2537,178.7648,7.5181761,0.77760994,0.0,0,9.106307,0.0,0.053193498,90.85746,9.1793642,402.26788,-9.2636814
2548,2548,178.767,7.5490599,0.81482297,0.0,0,9.0741167,0.0,0.055752166,90.910706,9.1417761,402.28775,-9.2643557
2559,2559,178.7692,7.5823903,0.84367967,0.0,0,9.0419264,0.0,0.057850577,91.141655,9.1084471,402.30762,-9.2643738
2570,2570,178.7714,7.6132584,0.87616497,0.0,0,9.009737,0.0,0.060132153,91.173225,9.0784655,402.32748,-9.2645931
2581,2581,178.7736,7.6505656,0.90491086,0.0,0,8.9775457,0.0,0.062143471,91.551971,9.0489693,402.34735,-9.2636585
2592,2592,178.7758,7.6900363,0.9431327,0.0,0,8.9453554,0.0,0.064925648,91.67289,9.0121164,402.26608,-9.2631426
2603,2603,178.778,7.7220154,0.97221452,0.0,0,8.9131651,0.0,0.066926926,92.013809,8.9778605,402.18002,-9.2641888
2614,2614,178.7802,7.7468863,1.0042571,0.0,0,8.8809748,0.0,0.069295146,92.002434,8.9476795,402.09393,-9.2643557
2625,2625,178.7824,7.7785068,1.0342917,0.0,0,8.8487844,0.0,0.071388401,92.212944,8.9122887,402.00784,-9.2642574
2636,2636,178.7846,7.7939248,1.0708168,0.0,0,8.8165941,0.0,0.074056581,92.145126,8.8784838,401.95697,-9.2653389
2647,2647,178.7868,7.8022428,1.1008334,0.0,0,8.7844028,0.0,0.076083034,92.023399,8.8447723,401.95697,-9.2642326
2658,2658,178.789,7.8243971,1.1319399,0.0,0,8.7522125,0.0,0.078560196,92.113342,8.8131027,401.95697,-9.2642241
2669,2669,178.7912,7.8476877,1.1619837,0.0,0,8.7214985,0.0,0.080524266,92.152649,8.7808418,401.95697,-9.2639999
2680,2680,178.7934,7.8783784,1.1958624,0.0,0,8.6908836,0.0,0.083179437,92.275093,8.7515125,401.95697,-9.262742
2691,2691,178.7956,7.9091034,1.2252514,0.0,0,8.6602697,0.0,0.08504042,92.541664,8.7160692,401.99701,-9.2640285
2702,2702,178.7978,7.9151621,1.2532598,0.0,0,8.629653,0.0,0.087292738,92.382164,8.6863899,402.04337,-9.2642031
2713,2713,178.8,7.9353662,1.2827302,0.0,0,8.5990381,0.0,0.089295417,92.41687,8.6580076,402.08972,-9.263442
2724,2724,178.8022,7.9395571,1.3143739,0.0,0,8.5684223,0.0,0.091786459,92.218391,8.6252947,402.13605,-9.2642212
2735,2735,178.8044,7.9694719,1.3457857,0.0,0,8.5378084,0.0,0.093812376,92.350922,8.5965624,402.19928,-9.2638292
2746,2746,178.8066,7.975544,1.3730867,0.0,0,8.5071926,0.0,0.096071191,92.317963,8.5652933,402.29858,-9.263339
2757,2757,178.8088,8.0172558,1.4048574,0.0,0,8.4765778,0.0,0.09811376,92.463081,8.5374947,402.39792,-9.2631016
2768,2768,178.811,8.045023,1.4361881,0.0,0,8.445962,0.0,0.10079105,92.563133,8.5026226,402.49725,-9.2641306
2779,2779,178.8132,8.0985966,1.4666067,0.0,0,8.4153471,0.0,0.1026217,93.044174,8.4736776,402.59656,-9.2648573
2790,2790,178.8154,8.1160612,1.4926009,0.0,0,8.3847322,0.0,0.10496769,93.036911,8.4411116,402.7522,-9.2630024
2801,2801,178.8176,8.135354,1.5264891,0.0,0,8.3541164,0.0,0.10707024,93.09726,8.4100237,402.92438,-9.2622728
2812,2812,178.8198,8.1561489,1.5588491,0.0,0,8.3235025,0.0,0.10990813,93.003632,8.3793812,403.09653,-9.2635708
2823,2823,178.822,8.16471,1.5911243,0.0,0,8.2928858,0.0,0.11182656,92.948021,8.3471308,403.26871,-9.2635717
2834,2834,178.8242,8.1744499,1.6155289,0.0,0,8.2622709,0.0,0.11414389,92.902771,8.3180847,403.42734,-9.2627325
2845,2845,178.8264,8.1910248,1.6468023,0.0,0,8.2316561,0.0,0.11608383,92.848793,8.2849646,403.53992,-9.2634096
2856,2856,178.8286,8.2254047,1.6783333,0.0,0,8.2010412,0.0,0.11888504,93.018311,8.2550812,403.6525,-9.2641716
2867,2867,178.8308,8.2720232,1.7103481,0.0,0,8.1704264,0.0,0.12075357,93.217255,8.2265368,403.76508,-9.2640648
2878,2878,178.833,8.2970495,1.73675,0.0,0,8.1398106,0.0,0.12323938,93.352341,8.1982279,403.87762,-9.2628241
2889,2889,178.8352,8.3337841,1.7698307,0.0,0,8.1091957,0.0,0.1252858,93.663971,8.1624517,403.92249,-9.2634792
2900,2900,178.8374,8.3545713,1.8004732,0.0,0,8.0785799,0.0,0.1281215,93.659431,8.1299572,403.93573,-9.2637224
2911,2911,178.8396,8.3681364,1.8368173,0.0,0,8.0482779,0.0,0.13026434,93.483444,8.1011381,403.94897,-9.2641191
2922,2922,178.8418,8.3893642,1.8633766,0.0,0,8.0191498,0.0,0.13285087,93.490738,8.0622339,403.96222,-9.2633333
2933,2933,178.844,8.4029789,1.8975661,0.0,0,7.9900212,0.0,0.13494126,93.445755,8.0326052,403.9556,-9.263607
2944,2944,178.8462,8.3957443,1.9241139,0.0,0,7.9608936,0.0,0.13760062,93.214996,8.0058966,403.82315,-9.2633781
2955,2955,178.8484,8.4143496,1.9588125,0.0,0,7.9317656,0.0,0.13947423,93.142349,7.9750676,403.6907,-9.2635756
2966,2966,178.8506,8.4390745,1.9798256,0.0,0,7.9026375,0.0,0.14179854,93.226532,7.9432192,403.55826,-9.2645016
2977,2977,178.8528,8.4661779,2.011152,0.0,0,7.8735094,0.0,0.1437275,93.319099,7.9154897,403.42581,-9.2642269
2988,2988,178.855,8.468214,2.0381393,0.0,0,7.8443813,0.0,0.14628617,93.11924,7.8844042,403.37949,-9.2636442
2999,2999,178.8572,8.4862347,2.0717998,0.0,0,7.8152533,0.0,0.1482008,93.223137,7.8608074,403.39273,-9.2641964
3010,3010,178.8594,8.4953642,2.0948699,0.0,0,7.7861252,0.0,0.15063754,93.044121,7.8270645,403.40598,-9.2642097
3021,3021,178.8616,8.5268621,2.1255617,0.0,0,7.7569971,0.0,0.15256922,93.231171,7.7940016,403.41922,-9.2634411
3032,3032,178.8638,8.54737,2.1528492,0.0,0,7.7278695,0.0,0.15528089,93.185989,7.7692461,403.41293,-9.2641764
3043,3043,178.866,8.5589304,2.1878731,0.0,0,7.6987414,0.0,0.15721251,93.078087,7.7404542,402.99573,-9.2634344
3054,3054,178.8682,8.5937996,2.2090802,0.0,0,7.6696134,0.0,0.1595667,93.229347,7.7114253,402.57852,-9.2633648
3065,3065,178.8704,8.6188421,2.2392662,0.0,0,7.6404853,0.0,0.16151582,93.444237,7.6803122,402.16135,-9.2630796
3076,3076,178.8726,8.6128044,2.2646136,0.0,0,7.6113577,0.0,0.16392533,93.144241,7.6529431,401.74414,-9.2630386
3087,3087,178.8748,8.6238565,2.2994847,0.0,0,7.5822296,0.0,0.16596852,93.017494,7.6263075,401.39648,-9.2634678
3098,3098,178.877,8.6541243,2.3203681,0.0,0,7.5531015,0.0,0.16829842,93.121239,7.5980172,401.11835,-9.2645779
3109,3109,178.8792,8.6719971,2.3504336,0.0,0,7.523973,0.0,0.17023055,93.141983,7.5677881,400.84024,-9.2646408
3120,3120,178.8814,8.7259073,2.37762,0.0,0,7.4948454,0.0,0.17279053,93.412659,7.5393481,400.5621,-9.2641535
3131,3131,178.8836,8.765605,2.4133518,0.0,0,7.4657173,0.0,0.17502075,93.708687,7.5070319,400.28397,-9.2628336
3142,3142,178.8858,8.7838898,2.4378805,0.0,0,7.4365897,0.0,0.17750855,93.675354,7.4779634,400.61267,-9.2631769
3153,3153,178.888,8.806838,2.4701848,0.0,0,7.4074612,0.0,0.17978764,93.676811,7.4497466,400.97025,-9.2628164
3164,3164,178.8902,8.8346128,2.4945188,0.0,0,7.3790221,0.0,0.18206084,93.716995,7.4157419,401.32785,-9.2624884
3175,3175,178.8924,8.8566685,2.5321875,0.0,0,7.3513193,0.0,0.18454759,93.711807,7.385622,401.68542,-9.2629375
3186,3186,178.8946,8.852891,2.5545869,0.0,0,7.323617,0.0,0.18680236,93.511086,7.3577671,401.978,-9.2635002
3197,3197,178.8968,8.8563089,2.5855935,0.0,0,7.2959146,0.0,0.18897596,93.331535,7.3311067,402.17667,-9.263917
3208,3208,178.899,8.8587456,2.6105759,0.0,0,7.2682123,0.0,0.19130345,93.147186,7.3010926,402.37534,-9.263381
3219,3219,178.9012,8.8798008,2.6436505,0.0,0,7.24051,0.0,0.19360222,93.17852,7.2716527,402.57401,-9.2640686
3230,3230,178.9034,8.8814182,2.6648576,0.0,0,7.2128077,0.0,0.19576824,92.948624,7.2479382,402.77264,-9.2629128
3241,3241,178.9056,8.9086494,2.6929812,0.0,0,7.1851048,0.0,0.19775653,93.014343,7.2210279,402.93701,-9.2640953
3252,3252,178.9078,8.9560614,2.7176673,0.0,0,7.157403,0.0,0.20001239,93.355316,7.1916342,403.09595,-9.2634239
3263,3263,178.91,8.9764919,2.7529044,0.0,0,7.1297007,0.0,0.20251328,93.310989,7.1630735,403.25485,-9.2630587
3274,3274,178.9122,8.9676428,2.7732325,0.0,0,7.1019974,0.0,0.20452824,93.163719,7.1404066,403.41379,-9.2638788
3285,3285,178.9144,8.9810448,2.8011465,0.0,0,7.0742955,0.0,0.20664203,92.938377,7.1092801,403.55588,-9.2639341
3296,3296,178.9166,9.005847,2.8265076,0.0,0,7.0465932,0.0,0.20879863,93.059998,7.0812106,403.66183,-9.2628565
3307,3307,178.9188,9.0135641,2.8605888,0.0,0,7.0188909,0.0,0.21140671,92.873474,7.0526838,403.76779,-9.2636776
3318,3318,178.921,9.042985,2.881279,0.0,0,6.991188,0.0,0.21334794,93.029289,7.0309324,403.87375,-9.2627144
3329,3329,178.9232,9.0944366,2.9099731,0.0,0,6.9634857,0.0,0.21563844,93.288422,7.0002971,403.97971,-9.2627144
3340,3340,178.9254,9.1320782,2.9365375,0.0,0,6.9357834,0.0,0.21785802,93.581978,6.9719219,404.08054,-9.2642307
3351,3351,178.9276,9.1608286,2.9710221,0.0,0,6.9080811,0.0,0.22067584,93.522408,6.9427896,404.17987,-9.2647696
3362,3362,178.9298,9.1762581,2.9933197,0.0,0,6.8803787,0.0,0.22255372,93.566963,6.9160972,404.27917,-9.2643375
3373,3373,178.932,9.1805477,3.0221646,0.0,0,6.8526764,0.0,0.22501275,93.370346,6.8844919,404.37851,-9.2630911
3384,3384,178.9342,9.1936255,3.0477519,0.0,0,6.8249741,0.0,0.22713971,93.308418,6.8576398,404.47031,-9.2611179
3395,3395,178.9364,9.2093544,3.080569,0.0,0,6.7972713,0.0,0.22986166,93.250786,6.8287215,404.53653,-9.2626219
3406,3406,178.9386,9.2428675,3.1047168,0.0,0,6.7695689,0.0,0.23175347,93.392319,6.8015509,404.60275,-9.2627764
3417,3417,178.9408,9.2715607,3.1323328,0.0,0,6.7428842,0.0,0.23432045,93.372887,6.7728696,404.66898,-9.2636662
3428,3428,178.943,9.2928944,3.1595774,0.0,0,6.7165279,0.0,0.23639314,93.39727,6.7410135,404.73523,-9.2645807
3439,3439,178.9452,9.3155832,3.1926196,0.0,0,6.6901722,0.0,0.2393479,93.406464,6.7140846,404.17383,-9.2645149
3450,3450,178.9474,9.3245497,3.215555,0.0,0,6.663816,0.0,0.24111885,93.286095,6.6885366,403.31952,-9.2635489
3461,3461,178.9496,9.3132153,3.2407393,0.0,0,6.6374598,0.0,0.24346121,93.032219,6.659297,402.46524,-9.2646112
3472,3472,178.9518,9.3205023,3.2657733,0.0,0,6.611104,0.0,0.24537642,92.836731,6.6347857,401.61096,-9.2629251
3483,3483,178.954,9.3280849,3.293818,0.0,0,6.5847478,0.0,0.24803014,92.679802,6.6086397,400.78918,-9.2617903
3494,3494,178.9562,9.3397427,3.3171546,0.0,0,6.558392,0.0,0.24968094,92.653358,6.5838237,400.17334,-9.2621784
3505,3505,178.9584,9.3376427,3.3422322,0.0,0,6.5320363,0.0,0.25217751,92.361862,6.5599442,399.5575,-9.2627754
3516,3516,178.9606,9.365346,3.3666515,0.0,0,6.5056801,0.0,0.2539731,92.429039,6.5335479,398.94165,-9.2629261
3527,3527,178.9628,9.4087296,3.394099,0.0,0,6.4793239,0.0,0.2566953,92.674744,6.5112634,398.32578,-9.2627115
3538,3538,178.965,9.4393501,3.419158,0.0,0,6.4529681,0.0,0.25840974,92.822571,6.4838181,398.35953,-9.2630033
3549,3549,178.9672,9.47363,3.4403179,0.0,0,6.4266124,0.0,0.26066476,92.95118,6.4566712,398.84299,-9.2632055
3560,3560,178.9694,9.5043669,3.4687755,0.0,0,6.4002562,0.0,0.26269794,93.122383,6.4320474,399.32642,-9.2645779
3571,3571,178.9716,9.5298815,3.4984276,0.0,0,6.3738999,0.0,0.26585665,93.110825,6.4018073,399.80988,-9.2636957
3582,3582,178.9738,9.560688,3.5274704,0.0,0,6.3475442,0.0,0.26774248,93.126717,6.3729439,400.2879,-9.2621794
3593,3593,178.976,9.5847073,3.5517399,0.0,0,6.3211884,0.0,0.27038348,93.115303,6.3458786,400.6521,-9.2636251
3604,3604,178.9782,9.5837221,3.5802047,0.0,0,6.2948327,0.0,0.27231678,92.982178,6.3184223,401.01633,-9.263711
3615,3615,178.9804,9.6070385,3.6060231,0.0,0,6.2684765,0.0,0.27523828,92.834541,6.2898235,401.38052,-9.2639685
3626,3626,178.9826,9.6323271,3.6346221,0.0,0,6.2421203,0.0,0.27704364,92.94841,6.2646351,401.74475,-9.2637062
3637,3637,178.9848,9.6458502,3.6562157,0.0,0,6.2157645,0.0,0.27967897,92.910461,6.2382088,402.05597,-9.2634697
3648,3648,178.987,9.6632862,3.6837239,0.0,0,6.1894083,0.0,0.2814675,92.872978,6.2133303,402.31424,-9.2634525
3659,3659,178.9892,9.6700621,3.7092919,0.0,0,6.1631007,0.0,0.28440136,92.628632,6.1852965,402.57251,-9.2618818
3670,3670,178.9914,9.6718407,3.7384932,0.0,0,6.1380219,0.0,0.28622678,92.491554,6.1604075,402.83078,-9.2626772
3681,3681,178.9936,9.7098351,3.7590692,0.0,0,6.1129556,0.0,0.28883213,92.610168,6.1371045,403.08902,-9.262722
3692,3692,178.9958,9.7444496,3.7872615,0.0,0,6.0878887,0.0,0.29068533,92.763374,6.1076455,403.35361,-9.262702
3703,3703,178.998,9.7699556,3.8115816,0.0,0,6.0628219,0.0,0.29362199,92.739395,6.084095,403.6185,-9.2627954
3714,3714,179.0002,9.7984467,3.8431509,0.0,0,6.037755,0.0,0.29549617,92.781464,6.0562086,403.88336,-9.2630634
3725,3725,179.0024,9.7981329,3.8606908,0.0,0,6.0126886,0.0,0.29794773,92.632408,6.0306826,404.14825,-9.2620373
3736,3736,179.0046,9.8009415,3.889925,0.0,0,5.9876213,0.0,0.29987335,92.452393,6.0075717,404.39417,-9.2621679
3747,3747,179.0068,9.7973604,3.911639,0.0,0,5.9625545,0.0,0.30254012,92.192886,5.9791722,404.6127,-9.2611589
3758,3758,179.009,9.8298588,3.9434085,0.0,0,5.9374876,0.0,0.30448574,92.355064,5.9553761,404.83124,-9.2621069
3769,3769,179.0112,9.8504791,3.9605241,0.0,0,5.9124212,0.0,0.30691653,92.300179,5.9307423,405.04977,-9.2628994
3780,3780,179.0134,9.8803349,3.9881618,0.0,0,5.8873544,0.0,0.30872276,92.406113,5.9056706,405.26831,-9.2630253
3791,3791,179.0156,9.9166193,4.0116091,0.0,0,5.8622875,0.0,0.31157413,92.433411,5.8795834,405.51541,-9.2625046
3802,3802,179.0178,9.9390116,4.0437317,0.0,0,5.8372207,0.0,0.3135795,92.416054,5.8583207,405.76706,-9.2623186
3813,3813,179.02,9.9514952,4.0592308,0.0,0,5.8121538,0.0,0.3158389,92.340805,5.8306661,406.01868,-9.2641382
3824,3824,179.0222,9.9749985,4.0875387,0.0,0,5.787087,0.0,0.31785521,92.455055,5.8054276,406.27032,-9.2632256
3835,3835,179.0244,9.9964991,4.110745,0.0,0,5.7620201,0.0,0.32072434,92.338112,5.7795649,406.33234,-9.2637148
3846,3846,179.0266,10.000218,4.1438456,0.0,0,5.7369533,0.0,0.32280603,92.253937,5.7538319,405.98798,-9.2627125
3857,3857,179.0288,10.034819,4.1613626,0.0,0,5.7118864,0.0,0.32524878,92.302139,5.7295151,405.64365,-9.2626657
3868,3868,179.031,10.056453,4.1895747,0.0,0,5.6868196,0.0,0.32728291,92.301132,5.699677,405.29929,-9.2638388
3879,3879,179.0332,10.081784,4.2123194,0.0,0,5.6617532,0.0,0.33002412,92.309929,5.6778016,404.95493,-9.2623281
3890,3890,179.0354,10.11924,4.245779,0.0,0,5.6366854,0.0,0.33226815,92.40593,5.652247,404.40079,-9.2624388
3901,3901,179.0376,10.144719,4.261826,0.0,0,5.6116195,0.0,0.33444467,92.369705,5.6260266,403.78494,-9.2634077
3912,3912,179.0398,10.149597,4.2882175,0.0,0,5.5869198,0.0,0.33635768,92.30323,5.5982571,403.16907,-9.2636452
3923,3923,179.042,10.15425,4.3093214,0.0,0,5.5630717,0.0,0.33908212,92.195717,5.5741196,402.55322,-9.2636213
3934,3934,179.0442,10.156735,4.3408189,0.0,0,5.5392232,0.0,0.34120151,91.82962,5.5508294,402.11798,-9.2639256
3945,3945,179.0464,10.159376,4.3596635,0.0,0,5.5153751,0.0,0.34356827,91.711136,5.5301323,402.29678,-9.2640181
3956,3956,179.0486,10.172286,4.3852105,0.0,0,5.4915276,0.0,0.34558529,91.690575,5.5039372,402.47559,-9.2636471
3967,3967,179.0508,10.214072,4.4035969,0.0,0,5.4676795,0.0,0.3478063,91.791313,5.4794683,402.65439,-9.2639084
3978,3978,179.053,10.251933,4.4349127,0.0,0,5.4438314,0.0,0.35013732,91.907494,5.4563289,402.83319,-9.2641869
3989,3989,179.0552,10.283216,4.4522805,0.0,0,5.4199839,0.0,0.35234833,92.046997,5.433248,403.24677,-9.2633619
4000,4000,179.0574,10.294078,4.4797015,0.0,0,5.3961358,0.0,0.35446519,91.936028,5.4091463,403.7699,-9.2633629
4011,4011,179.0596,10.288054,4.4988494,0.0,0,5.3722878,0.0,0.35675976,91.614296,5.383554,404.29306,-9.2609425
4022,4022,179.0618,10.30257,4.5288115,0.0,0,5.3484397,0.0,0.35908088,91.576416,5.3597088,404.81619,-9.2624178
4033,4033,179.064,10.32781,4.5462446,0.0,0,5.3245916,0.0,0.36120015,91.632591,5.3400502,405.31766,-9.2613955
4044,4044,179.0662,10.323216,4.570622,0.0,0,5.3007436,0.0,0.36323476,91.451317,5.312099,405.68188,-9.2625856
4055,4055,179.0684,10.382717,4.5911698,0.0,0,5.276896,0.0,0.36548311,91.688568,5.2939701,406.04611,-9.2623777
4066,4066,179.0706,10.415636,4.6224637,0.0,0,5.2530475,0.0,0.36815867,91.703026,5.2678571,406.41031,-9.2633142
4077,4077,179.0728,10.461094,4.6407166,0.0,0,5.2291994,0.0,0.37026438,91.979027,5.2454329,406.77454,-9.2626276
4088,4088,179.075,10.493264,4.665719,0.0,0,5.2053518,0.0,0.37247506,92.014267,5.2198811,406.95093,-9.2634125
4099,4099,179.0772,10.513895,4.6877608,0.0,0,5.1815038,0.0,0.37465632,92.073082,5.1965361,406.99725,-9.2626514
4110,4110,179.0794,10.526345,4.7171221,0.0,0,5.1576557,0.0,0.37741172,91.892532,5.172946,407.04361,-9.2626114
4121,4121,179.0816,10.560481,4.7362709,0.0,0,5.1338077,0.0,0.37940824,92.008148,5.1438766,407.08997,-9.2622576
4132,4132,179.0838,10.578435,4.7629275,0.0,0,5.1099596,0.0,0.38206917,91.918022,5.1234355,407.12698,-9.2614136
4143,4143,179.086,10.603765,4.7860441,0.0,0,5.0861115,0.0,0.38430861,91.935501,5.0981836,406.96805,-9.2623243
4154,4154,179.0882,10.617708,4.8153439,0.0,0,5.062264,0.0,0.38709852,91.755547,5.0693626,406.80914,-9.2628746
4165,4165,179.0904,10.650583,4.834074,0.0,0,5.0390849,0.0,0.38893628,91.895294,5.0476437,406.65021,-9.2646742
4176,4176,179.0926,10.662995,4.8595009,0.0,0,5.0164027,0.0,0.39156744,91.795387,5.0275927,406.49127,-9.2635441
4187,4187,179.0948,10.687179,4.8804817,0.0,0,4.993721,0.0,0.39353231,91.851624,5.000514,406.38864,-9.2623844
4198,4198,179.097,10.719198,4.9102798,0.0,0,4.9710388,0.0,0.39657122,91.762444,4.9774523,406.34229,-9.2616587
4209,4209,179.0992,10.722791,4.9309554,0.0,0,4.9483566,0.0,0.39848801,91.653358,4.9540911,406.29593,-9.2618093
4220,4220,179.1014,10.729991,4.9544725,0.0,0,4.9256749,0.0,0.40101606,91.459915,4.9339604,406.24957,-9.2627411
4231,4231,179.1036,10.736201,4.9739051,0.0,0,4.9029927,0.0,0.40263906,91.383743,4.9077282,406.20322,-9.2626657
4242,4242,179.1058,10.74277,4.9990511,0.0,0,4.880311,0.0,0.40557382,91.189613,4.8855591,406.24536,-9.263422
4253,4253,179.108,10.779254,5.0227413,0.0,0,4.8576288,0.0,0.40753126,91.276337,4.8652849,406.29172,-9.2630835
4264,4264,179.1102,10.798272,5.0425687,0.0,0,4.8349466,0.0,0.4098959,91.229767,4.8411651,406.33807,-9.2628698
4275,4275,179.1124,10.81954,5.0625238,0.0,0,4.8122649,0.0,0.41147989,91.243248,4.8189993,406.3844,-9.2630577
4286,4286,179.1146,10.846322,5.0882511,0.0,0,4.7895827,0.0,0.41459092,91.235176,4.7992983,406.45514,-9.2623158
4297,4297,179.1168,10.878745,5.1092257,0.0,0,4.766901,0.0,0.41615129,91.248009,4.7749529,406.5611,-9.2630949
4308,4308,179.119,10.872534,5.1294503,0.0,0,4.7442188,0.0,0.41872743,91.06546,4.7504873,406.66702,-9.2625294
4319,4319,179.1212,10.895391,5.1529422,0.0,0,4.7215366,0.0,0.42050424,91.079613,4.7318411,406.77298,-9.2630663
4330,4330,179.1234,10.91531,5.1754098,0.0,0,4.6988549,0.0,0.42345738,91.007263,4.7084131,406.87894,-9.2629194
4341,4341,179.1256,10.947696,5.1981297,0.0,0,4.6761732,0.0,0.42507449,91.107384,4.6878228,406.87622,-9.2636051
4352,4352,179.1278,10.993275,5.2179461,0.0,0,4.6534905,0.0,0.42773017,91.195023,4.6622868,406.85635,-9.2629185
4363,4363,179.13,11.057676,5.2417498,0.0,0,4.6308088,0.0,0.42956442,91.632904,4.6404691,406.83649,-9.2635689
4374,4374,179.1322,11.108098,5.2644024,0.0,0,4.6081266,0.0,0.43259233,91.743553,4.6163273,406.81665,-9.2626534
4385,4385,179.1344,11.12822,5.2921963,0.0,0,4.5854449,0.0,0.43469447,91.766762,4.5887408,405.6123,-9.2621994
4396,4396,179.1366,11.137115,5.3121681,0.0,0,4.5627627,0.0,0.43745193,91.527657,4.5692315,401.86984,-9.2626629
4407,4407,179.1388,11.133091,5.3378468,0.0,0,4.5400805,0.0,0.43928427,91.39698,4.547452,398.12738,-9.2627048
4418,4418,179.141,11.157782,5.3586378,0.0,0,4.5183334,0.0,0.44241294,91.293297,4.524549,394.38492,-9.2634716
4429,4429,179.1432,11.17082,5.3840709,0.0,0,4.4967556,0.0,0.44411862,91.28878,4.49931,390.64249,-9.2626534
4440,4440,179.1454,11.199903,5.4022827,0.0,0,4.4751782,0.0,0.44694677,91.200363,4.4772663,387.87576,-9.2634363
4451,4451,179.1476,11.231404,5.4282331,0.0,0,4.4536009,0.0,0.44876748,91.293762,4.4572086,385.39603,-9.2637138
4462,4462,179.1498,11.25894,5.4463439,0.0,0,4.432023,0.0,0.45162937,91.189629,4.4376397,382.91629,-9.2639217
4473,4473,179.152,11.277987,5.4733424,0.0,0,4.4104452,0.0,0.45340264,91.282829,4.4112949,380.43655,-9.2629156
4484,4484,179.1542,11.287444,5.4864011,0.0,0,4.3888679,0.0,0.45583013,91.06073,4.3893008,378.9115,-9.2625227
4495,4495,179.1564,11.268003,5.5140524,0.0,0,4.36729,0.0,0.45778418,90.810623,4.3674207,380.63232,-9.2627726
4506,4506,179.1586,11.274183,5.5333576,0.0,0,4.3457127,0.0,0.46073663,90.577133,4.3499866,382.35315,-9.2628946
4517,4517,179.1608,11.300573,5.5573497,0.0,0,4.3241353,0.0,0.46224225,90.621735,4.3281527,384.07397,-9.2641802
4528,4528,179.163,11.329165,5.5710807,0.0,0,4.3025579,0.0,0.46456021,90.651657,4.3086696,385.7948,-9.263237
4539,4539,179.1652,11.371084,5.5932446,0.0,0,4.2809801,0.0,0.46622652,90.777496,4.2866693,386.30612,-9.2642574
4550,4550,179.1674,11.446535,5.6127772,0.0,0,4.2594023,0.0,0.46925303,91.087906,4.2652617,386.25302,-9.2641277
4561,4561,179.1696,11.475856,5.64152,0.0,0,4.2378249,0.0,0.47107205,91.171959,4.2428842,386.19995,-9.2642117
4572,4572,179.1718,11.509158,5.6563296,0.0,0,4.2162471,0.0,0.47372699,91.264183,4.2228751,386.14685,-9.2636404
4583,4583,179.174,11.51782,5.6805987,0.0,0,4.1946697,0.0,0.47550777,91.118019,4.2008638,386.05847,-9.2632685
4594,4594,179.1762,11.571559,5.6977372,0.0,0,4.1730919,0.0,0.4783482,91.262444,4.176425,385.74658,-9.2639761
4605,4605,179.1784,11.566602,5.7283802,0.0,0,4.1515145,0.0,0.48024583,91.072121,4.1586185,385.43469,-9.2634792
4616,4616,179.1806,11.621088,5.743186,0.0,0,4.1299367,0.0,0.48317102,91.277794,4.134748,385.1228,-9.2628012
4627,4627,179.1828,11.631546,5.7698922,0.0,0,4.1083593,0.0,0.48518443,91.112869,4.1134882,384.81091,-9.263011
4638,4638,179.185,11.633566,5.7865229,0.0,0,4.0867815,0.0,0.48787925,90.956429,4.0892396,385.25974,-9.2634144
4649,4649,179.1872,11.675569,5.8137751,0.0,0,4.0652041,0.0,0.48968339,91.107002,4.068398,386.23523,-9.2640915
4660,4660,179.1894,11.736034,5.8268952,0.0,0,4.0437527,0.0,0.49224219,91.357452,4.0489845,387.21072,-9.2641516
4671,4671,179.1916,11.748963,5.8528633,0.0,0,4.0232306,0.0,0.49426451,91.259956,4.0287485,388.18622,-9.263073
4682,4682,179.1938,11.764655,5.8695235,0.0,0,4.0027089,0.0,0.49690989,91.179695,4.0068016,389.17197,-9.2633419
4693,4693,179.196,11.772509,5.8992629,0.0,0,3.9821873,0.0,0.49915275,90.995819,3.9897299,390.37308,-9.2635221
4704,4704,179.1982,11.825972,5.9131103,0.0,0,3.9616656,0.0,0.50161469,91.142059,3.9631922,391.57419,-9.2641964
4715,4715,179.2004,11.856427,5.9390006,0.0,0,3.9411442,0.0,0.50366056,91.199089,3.9380772,392.7753,-9.2642326
4726,4726,179.2026,11.888589,5.9568229,0.0,0,3.9206226,0.0,0.50638509,91.212822,3.9201822,393.97641,-9.2639761
4737,4737,179.2048,11.918829,5.9863887,0.0,0,3.9001009,0.0,0.50888979,91.193153,3.9022574,394.96494,-9.2638712
4748,4748,179.207,11.951979,5.9985743,0.0,0,3.8795795,0.0,0.51098776,91.348976,3.8837199,395.74088,-9.2626438
4759,4759,179.2092,11.994942,6.0233603,0.0,0,3.8590579,0.0,0.51310748,91.416214,3.8586755,396.51682,-9.2627163
4770,4770,179.2114,12.016494,6.0404177,0.0,0,3.8385363,0.0,0.51562321,91.351723,3.8383384,397.29276,-9.2633276
4781,4781,179.2136,12.02682,6.0682755,0.0,0,3.8180146,0.0,0.51803631,91.225983,3.8183932,398.06866,-9.2632561
4792,4792,179.2158,12.080377,6.0823736,0.0,0,3.797493,0.0,0.5203312,91.318901,3.792845,398.40741,-9.2641907
4803,4803,179.218,12.080151,6.1092229,0.0,0,3.7769713,0.0,0.52285177,91.151901,3.7735267,398.72531,-9.2634802
4814,4814,179.2202,12.105314,6.1252913,0.0,0,3.7564499,0.0,0.52497709,91.169403,3.7539439,399.04321,-9.2628584
4825,4825,179.2224,12.097508,6.1524415,0.0,0,3.7359283,0.0,0.52756083,90.846725,3.7312415,399.36111,-9.2635174
4836,4836,179.2246,12.120368,6.1637096,0.0,0,3.7154067,0.0,0.52934349,90.846519,3.7151153,399.61938,-9.26264
4847,4847,179.2268,12.136999,6.1874075,0.0,0,3.694885,0.0,0.53162444,90.820274,3.6966259,399.79156,-9.2632141
4858,4858,179.229,12.17,6.2018991,0.0,0,3.6743636,0.0,0.53365105,90.831863,3.678839,399.96371,-9.2618895
4869,4869,179.2312,12.202417,6.2276068,0.0,0,3.6538417,0.0,0.5361774,90.839142,3.6598117,400.13589,-9.2631712
4880,4880,179.2334,12.24838,6.2402463,0.0,0,3.6333201,0.0,0.53797805,91.085556,3.6380534,400.30807,-9.2633848
4891,4891,179.2356,12.312799,6.2648163,0.0,0,3.6127987,0.0,0.54052019,91.319138,3.6175816,400.60605,-9.2634296
4902,4902,179.2378,12.364481,6.280159,0.0,0,3.5922771,0.0,0.54249978,91.469772,3.5981376,400.92392,-9.2629442
4913,4913,179.24,12.405549,6.3088994,0.0,0,3.5721471,0.0,0.54565668,91.486458,3.5712166,401.24179,-9.2631569
4924,4924,179.2422,12.476577,6.3247185,0.0,0,3.5526242,0.0,0.5475387,91.859917,3.5523233,401.55963,-9.2620649
4935,4935,179.2444,12.529242,6.3500113,0.0,0,3.5331016,0.0,0.55052274,92.035896,3.5318692,401.90491,-9.2623539
4946,4946,179.2466,12.580364,6.3705254,0.0,0,3.5135787,0.0,0.5527221,92.129852,3.5126092,402.30884,-9.2639685
4957,4957,179.2488,12.563863,6.3959103,0.0,0,3.4940557,0.0,0.55579233,91.803833,3.4908204,402.71277,-9.2630339
4968,4968,179.251,12.525798,6.4104066,0.0,0,3.4745328,0.0,0.55740058,91.385262,3.4738147,403.1167,-9.2637482
4979,4979,179.2532,12.502077,6.43153,0.0,0,3.4550104,0.0,0.55999678,90.989044,3.4510589,403.52066,-9.2628098
4990,4990,179.2554,12.52637,6.445765,0.0,0,3.4354873,0.0,0.56153613,90.95401,3.4320831,403.81714,-9.2632303
5001,5001,179.2576,12.541948,6.4699731,0.0,0,3.4159648,0.0,0.5646137,90.833534,3.4156322,404.08203,-9.2624311
5012,5012,179.2598,12.585361,6.4852705,0.0,0,3.3964417,0.0,0.56613517,90.963081,3.3974273,404.34689,-9.262455
5023,5023,179.262,12.638618,6.5044127,0.0,0,3.376919,0.0,0.56868607,91.119095,3.3803444,404.61179,-9.2632885
5034,5034,179.2642,12.729184,6.5219908,0.0,0,3.3573964,0.0,0.57023954,91.604401,3.3597872,404.86612,-9.2620707
5045,5045,179.2664,12.798101,6.546196,0.0,0,3.3378732,0.0,0.57366794,91.813187,3.3377395,405.08466,-9.262166
5056,5056,179.2686,12.826591,6.5638351,0.0,0,3.3183508,0.0,0.57511693,91.926521,3.3168693,405.30319,-9.2618427
5067,5067,179.2708,12.839919,6.5830946,0.0,0,3.2988276,0.0,0.578004,91.730995,3.2995696,405.52173,-9.2632895
5078,5078,179.273,12.853247,6.6024966,0.0,0,3.2793047,0.0,0.57987934,91.644005,3.2786088,405.74026,-9.2624636
5089,5089,179.2752,12.866093,6.6233315,0.0,0,3.2597823,0.0,0.58303165,91.432686,3.2608824,405.97232,-9.2625694
5100,5100,179.2774,12.882684,6.6426563,0.0,0,3.2402592,0.0,0.58450896,91.394157,3.2410402,406.21072,-9.2618856
5111,5111,179.2796,12.920066,6.6569581,0.0,0,3.2207365,0.0,0.58691484,91.493675,3.2217431,406.44913,-9.2631693
5122,5122,179.2818,13.004359,6.6768584,0.0,0,3.2012138,0.0,0.5885188,91.943848,3.2053926,406.68753,-9.2628002
5133,5133,179.284,13.059443,6.697186,0.0,0,3.1816909,0.0,0.591932,92.010643,3.1814406,406.91327,-9.263917
5144,5144,179.2862,13.102364,6.7192202,0.0,0,3.1621683,0.0,0.59357685,92.147995,3.1632504,407.05896,-9.2642488
5155,5155,179.2884,13.158603,6.7366819,0.0,0,3.1426454,0.0,0.59671921,92.252953,3.142545,407.20465,-9.263113
5166,5166,179.2906,13.182079,6.7570906,0.0,0,3.1237545,0.0,0.59822792,92.322021,3.1208756,407.35031,-9.2626133
5177,5177,179.2928,13.205068,6.7774911,0.0,0,3.1051819,0.0,0.6017803,92.125946,3.1031716,407.496,-9.2616682
5188,5188,179.295,13.246244,6.8014622,0.0,0,3.0866094,0.0,0.60343003,92.252449,3.0830224,407.58691,-9.2627115
5199,5199,179.2972,13.293794,6.8166161,0.0,0,3.0680368,0.0,0.60648692,92.276802,3.0633242,407.63989,-9.2619476
5210,5210,179.2994,13.296707,6.8386145,0.0,0,3.0494645,0.0,0.60800713,92.153687,3.0448258,407.69284,-9.2628841
5221,5221,179.3016,13.328161,6.8538437,0.0,0,3.0308924,0.0,0.61095691,92.101036,3.0264595,407.74582,-9.2632456
5232,5232,179.3038,13.316954,6.8746624,0.0,0,3.0123198,0.0,0.61241645,91.885719,3.0076392,407.79156,-9.263134
5243,5243,179.306,13.322732,6.8869658,0.0,0,2.9937477,0.0,0.61517674,91.696777,2.9900134,407.68564,-9.2622547
5254,5254,179.3082,13.346361,6.9101734,0.0,0,2.9751751,0.0,0.61679071,91.712151,2.9741435,407.57968,-9.2628555
5265,5265,179.3104,13.406271,6.9246821,0.0,0,2.9566026,0.0,0.61994362,91.8395,2.9542274,407.47372,-9.2626562
5276,5276,179.3126,13.473352,6.9485373,0.0,0,2.93803,0.0,0.62134564,92.136253,2.9372001,407.3678,-9.2638016
5287,5287,179.3148,13.55379,6.9610715,0.0,0,2.9194577,0.0,0.62429523,92.414848,2.9178195,407.22211,-9.2640228
5298,5298,179.317,13.61448,6.9831252,0.0,0,2.9008856,0.0,0.62581885,92.719276,2.9000385,407.03668,-9.2635088
5309,5309,179.3192,13.644744,6.9988089,0.0,0,2.882313,0.0,0.62902188,92.622269,2.8812044,406.85126,-9.2623768
5320,5320,179.3214,13.669651,7.0248156,0.0,0,2.8637407,0.0,0.63082612,92.646645,2.8622241,406.66583,-9.263401
5331,5331,179.3236,13.72136,7.0354753,0.0,0,2.8451684,0.0,0.63358337,92.719543,2.8436768,406.48041,-9.2625055
5342,5342,179.3258,13.758523,7.058105,0.0,0,2.8265958,0.0,0.63526976,92.846336,2.8243351,406.3519,-9.2623968
5353,5353,179.328,13.78274,7.0730467,0.0,0,2.8080232,0.0,0.63845521,92.659637,2.8043857,406.22607,-9.263442
5364,5364,179.3302,13.808972,7.099915,0.0,0,2.7894509,0.0,0.64023644,92.69912,2.7895546,406.10025,-9.2620134
5375,5375,179.3324,13.877034,7.1075006,0.0,0,2.7708786,0.0,0.64273983,92.841446,2.7716472,405.97443,-9.2635527
5386,5386,179.3346,13.962159,7.132163,0.0,0,2.7523062,0.0,0.64470756,93.262596,2.7515202,405.91635,-9.262908
5397,5397,179.3368,14.024635,7.1495724,0.0,0,2.7337339,0.0,0.64809352,93.352928,2.7301798,405.95609,-9.2620573
5408,5408,179.339,14.030117,7.1763511,0.0,0,2.7151613,0.0,0.65011215,93.264984,2.7106254,405.99582,-9.2624416
5419,5419,179.3412,14.04341,7.1841655,0.0,0,2.697439,0.0,0.6524632,93.174759,2.6988657,406.03555,-9.2615223
5430,5430,179.3434,14.062039,7.2071195,0.0,0,2.6797729,0.0,0.65432578,93.057884,2.6784091,406.07526,-9.262063
5441,5441,179.3456,14.10705,7.2211266,0.0,0,2.6621068,0.0,0.65730453,93.090675,2.6561987,406.2637,-9.2635517
5452,5452,179.3478,14.149599,7.2489853,0.0,0,2.6444409,0.0,0.65937757,93.199814,2.6399634,406.47559,-9.2639856
5463,5463,179.35,14.197131,7.2570763,0.0,0,2.626775,0.0,0.66175646,93.264481,2.6229348,406.6875,-9.262702
5474,5474,179.3522,14.232842,7.2798438,0.0,0,2.6091087,0.0,0.66383302,93.252182,2.6035023,406.89941,-9.2633924
5485,5485,179.3544,14.2794,7.2931414,0.0,0,2.5914428,0.0,0.66648978,93.320709,2.5838602,407.08392,-9.2622433
5496,5496,179.3566,14.32582,7.3206778,0.0,0,2.573777,0.0,0.66877162,93.468956,2.5659955,407.20975,-9.2636948
5507,5507,179.3588,14.359139,7.3281889,0.0,0,2.5561109,0.0,0.67101645,93.502007,2.5508535,407.33554,-9.2637796
5518,5518,179.361,14.36561,7.3542261,0.0,0,2.538445,0.0,0.67342001,93.245491,2.5312893,407.46136,-9.2626266
5529,5529,179.3632,14.383306,7.3654842,0.0,0,2.5207789,0.0,0.67577875,93.202141,2.5138524,407.58719,-9.2626543
5540,5540,179.3654,14.404302,7.3889136,0.0,0,2.5031128,0.0,0.67784917,93.145401,2.4965827,407.66183,-9.2625656
5551,5551,179.3676,14.451022,7.4003816,0.0,0,2.4854469,0.0,0.68028092,93.178398,2.480247,407.72144,-9.2627459
5562,5562,179.3698,14.506956,7.4190335,0.0,0,2.4677808,0.0,0.6819697,93.408043,2.4644618,407.78107,-9.2641754
5573,5573,179.372,14.578313,7.4316883,0.0,0,2.4501147,0.0,0.68436116,93.553917,2.4476087,407.84067,-9.2636757
5584,5584,179.3742,14.655276,7.4590321,0.0,0,2.4324489,0.0,0.68722647,93.851791,2.4290969,407.41068,-9.2627535
5595,5595,179.3764,14.716671,7.4677262,0.0,0,2.4147828,0.0,0.68920958,94.093269,2.4119277,405.31613,-9.2626448
5606,5606,179.3786,14.749017,7.4893913,0.0,0,2.3971167,0.0,0.69144452,94.054695,2.3906977,403.22159,-9.2628717
5617,5617,179.3808,14.797653,7.5028439,0.0,0,2.3794508,0.0,0.69383055,94.133713,2.3755858,401.12701,-9.2623882
5628,5628,179.383,14.863375,7.5288401,0.0,0,2.3617849,0.0,0.69658566,94.286453,2.3585999,399.03247,-9.2625666
5639,5639,179.3852,14.919921,7.5406051,0.0,0,2.3441188,0.0,0.69875902,94.454582,2.3355627,396.79745,-9.2626047
5650,5650,179.3874,14.951096,7.5620279,0.0,0,2.3264527,0.0,0.70125097,94.361671,2.3192174,394.49686,-9.2618895
5661,5661,179.3896,15.006842,7.5762653,0.0,0,2.3089681,0.0,0.70344937,94.507454,2.3033514,392.19629,-9.2639065
5672,5672,179.3918,15.043313,7.601491,0.0,0,2.2921643,0.0,0.70654076,94.48349,2.2846551,389.89569,-9.2633429
5683,5683,179.394,15.068253,7.6107845,0.0,0,2.2753608,0.0,0.7081399,94.501221,2.2692971,387.71234,-9.2629051
5694,5694,179.3962,15.070314,7.6309733,0.0,0,2.2585571,0.0,0.71069348,94.296501,2.2532029,387.99106,-9.2623043
5705,5705,179.3984,15.07558,7.642045,0.0,0,2.2417536,0.0,0.71228671,94.153931,2.2349503,388.26978,-9.2619219
5716,5716,179.4006,15.108685,7.6657014,0.0,0,2.2249501,0.0,0.71536583,94.103378,2.2194767,388.54849,-9.2624826
5727,5727,179.4028,15.187349,7.6772671,0.0,0,2.2081466,0.0,0.71710813,94.407524,2.2017281,388.82721,-9.2628469
5738,5738,179.405,15.235818,7.6968131,0.0,0,2.1913428,0.0,0.71970963,94.444695,2.1878102,389.46756,-9.2632132
5749,5749,179.4072,15.295539,7.7104263,0.0,0,2.1745393,0.0,0.72154993,94.649811,2.1673739,390.4696,-9.2627831
5760,5760,179.4094,15.362798,7.7321329,0.0,0,2.1577358,0.0,0.72476673,94.733009,2.1528594,391.47162,-9.2610188
5771,5771,179.4116,15.385156,7.7449064,0.0,0,2.1409321,0.0,0.72617477,94.814636,2.135227,392.47366,-9.2617073
5782,5782,179.4138,15.4528,7.7608509,0.0,0,2.1241283,0.0,0.7286461,94.923553,2.1192703,393.47568,-9.2616758
5793,5793,179.416,15.489612,7.776845,0.0,0,2.1073248,0.0,0.73050714,95.003601,2.1053512,394.26846,-9.260994
5804,5804,179.4182,15.54845,7.8001485,0.0,0,2.0905213,0.0,0.73424476,95.005394,2.0863311,395.05124,-9.2616091
5815,5815,179.4204,15.596093,7.812192,0.0,0,2.0737178,0.0,0.73531544,95.180931,2.0686495,395.83405,-9.2621956
5826,5826,179.4226,15.667548,7.826489,0.0,0,2.0569141,0.0,0.73785913,95.351357,2.054929,396.61685,-9.2620268
5837,5837,179.4248,15.731548,7.8437762,0.0,0,2.0401106,0.0,0.73973793,95.573013,2.035346,397.28,-9.262373
5848,5848,179.427,15.824543,7.8648772,0.0,0,2.0233071,0.0,0.74329865,95.803238,2.0144367,397.77032,-9.2620001
5859,5859,179.4292,15.89063,7.8812089,0.0,0,2.0065033,0.0,0.74481016,96.051628,1.9988106,398.26062,-9.2616863
5870,5870,179.4314,15.946567,7.8959265,0.0,0,1.9896998,0.0,0.74779224,96.114708,1.9827116,398.75095,-9.2623043
5881,5881,179.4336,15.961927,7.9140797,0.0,0,1.9728961,0.0,0.74941403,96.081085,1.9662237,399.24127,-9.2619228
5892,5892,179.4358,15.956738,7.9342542,0.0,0,1.9560926,0.0,0.75320941,95.712761,1.9495,399.7771,-9.2632637
5903,5903,179.438,15.968811,7.9487,0.0,0,1.939289,0.0,0.75415921,95.656425,1.9342487,400.3201,-9.2634096
5914,5914,179.4402,16.031391,7.9606628,0.0,0,1.9228806,0.0,0.75700772,95.749977,1.9191518,400.86313,-9.2632427
5925,5925,179.4424,16.085522,7.9781475,0.0,0,1.9068955,0.0,0.75846374,95.913223,1.9016505,401.40613,-9.2624483
5936,5936,179.4446,16.167801,7.9939351,0.0,0,1.8909101,0.0,0.76191789,96.06163,1.8843691,401.91754,-9.2611589
5947,5947,179.4468,16.258017,8.0153408,0.0,0,1.874925,0.0,0.76371652,96.436043,1.870302,402.36121,-9.2608976
5958,5958,179.449,16.370281,8.025547,0.0,0,1.8589398,0.0,0.76642084,96.841446,1.8512033,402.8049,-9.2618361
5969,5969,179.4512,16.428402,8.0461159,0.0,0,1.8429546,0.0,0.7680679,97.058182,1.8316003,403.24857,-9.2616291
5980,5980,179.4534,16.458252,8.0626717,0.0,0,1.8269695,0.0,0.7717914,96.845573,1.8172666,403.69226,-9.2626581
5991,5991,179.4556,16.451681,8.0803766,0.0,0,1.8109843,0.0,0.77295262,96.698387,1.7985682,403.32233,-9.2627058
6002,6002,179.4578,16.467966,8.0913973,0.0,0,1.794999,0.0,0.77594787,96.495735,1.7856669,402.7131,-9.2619762
6013,6013,179.46,16.456396,8.1107054,0.0,0,1.7790139,0.0,0.77742964,96.275757,1.7682346,402.10388,-9.2622604
6024,6024,179.4622,16.482954,8.1236353,0.0,0,1.7630286,0.0,0.78090602,96.102043,1.7523386,401.49463,-9.2631483
6035,6035,179.4644,16.513851,8.1435099,0.0,0,1.7470435,0.0,0.78202569,96.222542,1.7429768,400.66229,-9.2620335
6046,6046,179.4666,16.581766,8.1522636,0.0,0,1.7310582,0.0,0.78479028,96.351578,1.7243911,399.07132,-9.262311
6057,6057,179.4688,16.681469,8.1694937,0.0,0,1.715073,0.0,0.78598028,96.762894,1.7135209,397.48035,-9.2607431
6068,6068,179.471,16.773903,8.1824284,0.0,0,1.6990879,0.0,0.78940588,96.984726,1.6958321,395.88937,-9.2619047
6079,6079,179.4732,16.836527,8.2059851,0.0,0,1.6831026,0.0,0.79094708,97.195793,1.6811854,394.2984,-9.2613306
6090,6090,179.4754,16.928394,8.2135649,0.0,0,1.6671174,0.0,0.79384923,97.465294,1.6634899,393.89603,-9.2619848
6101,6101,179.4776,17.036039,8.236227,0.0,0,1.6511322,0.0,0.79571342,97.85836,1.6531843,394.04834,-9.2616177
6112,6112,179.4798,17.150309,8.2500792,0.0,0,1.635147,0.0,0.79937238,98.136055,1.6312,394.20065,-9.2624712
6123,6123,179.482,17.251684,8.2737713,0.0,0,1.6191618,0.0,0.80098981,98.61937,1.6080905,394.35297,-9.2626524
6134,6134,179.4842,17.315807,8.2804022,0.0,0,1.6031766,0.0,0.80378592,98.69796,1.5931957,394.6301,-9.2626696
6145,6145,179.4864,17.358034,8.3024712,0.0,0,1.5871913,0.0,0.8056674,98.711723,1.5814259,395.69794,-9.2620907
6156,6156,179.4886,17.396332,8.3163242,0.0,0,1.5712062,0.0,0.80923647,98.630707,1.5629952,396.76575,-9.2625656
6167,6167,179.4908,17.402328,8.3429689,0.0,0,1.5558095,0.0,0.81125796,98.451622,1.544359,397.83359,-9.2633028
6178,6178,179.493,17.391468,8.348896,0.0,0,1.540603,0.0,0.81387591,98.122414,1.5315888,398.9014,-9.2610893
6189,6189,179.4952,17.405973,8.3656893,0.0,0,1.5253967,0.0,0.81516653,98.077377,1.5139495,399.45172,-9.260561
6200,6200,179.4974,17.429394,8.3763332,0.0,0,1.5101904,0.0,0.81830287,97.901581,1.5009074,399.64377,-9.2618856
6211,6211,179.4996,17.490747,8.3994446,0.0,0,1.4949839,0.0,0.82003653,98.050133,1.4880162,399.83582,-9.2627296
6222,6222,179.5018,17.582396,8.4046125,0.0,0,1.4797776,0.0,0.82246679,98.342575,1.4729787,400.02783,-9.261445
6233,6233,179.504,17.663643,8.4257736,0.0,0,1.4645711,0.0,0.82415342,98.651581,1.4572594,400.22198,-9.2618723
6244,6244,179.5062,17.74811,8.4344149,0.0,0,1.4493648,0.0,0.82708603,98.803864,1.4429735,400.46039,-9.2623959
6255,6255,179.5084,17.817657,8.459239,0.0,0,1.4341583,0.0,0.82914054,98.985039,1.42182,400.69876,-9.2616777
6266,6266,179.5106,17.884417,8.4628,0.0,0,1.418952,0.0,0.83118993,99.150505,1.4119086,400.93716,-9.2609425
6277,6277,179.5128,17.922445,8.4845171,0.0,0,1.4037454,0.0,0.83338279,99.181549,1.3964523,401.17554,-9.2611494
6288,6288,179.515,17.955872,8.4963322,0.0,0,1.3885391,0.0,0.83638126,99.065132,1.3800803,401.25171,-9.2621231
6299,6299,179.5172,18.035767,8.5206203,0.0,0,1.3733326,0.0,0.83864057,99.229347,1.3646566,401.16562,-9.2619829
6310,6310,179.5194,18.095074,8.5258532,0.0,0,1.3581263,0.0,0.84079474,99.320869,1.3470895,401.07953,-9.2625999
6321,6321,179.5216,18.160492,8.5458136,0.0,0,1.3429198,0.0,0.84278035,99.519691,1.3353913,400.99344,-9.2625847
6332,6332,179.5238,18.207682,8.5549955,0.0,0,1.3277135,0.0,0.84521621,99.554947,1.3249519,400.90735,-9.2609024
6343,6343,179.526,18.25115,8.5780277,0.0,0,1.3125072,0.0,0.84758455,99.525528,1.3016045,400.3027,-9.2624149
6354,6354,179.5282,18.334801,8.5834484,0.0,0,1.2973008,0.0,0.84960562,99.840744,1.2910142,399.67337,-9.2625351
6365,6365,179.5304,18.418753,8.6048326,0.0,0,1.2820944,0.0,0.85214275,100.05454,1.2763424,399.04401,-9.2617874
6376,6376,179.5326,18.469542,8.6142397,0.0,0,1.2668879,0.0,0.85439962,100.03955,1.2631207,398.41467,-9.2623825
6387,6387,179.5348,18.524372,8.6373711,0.0,0,1.2516814,0.0,0.856947,100.1153,1.2489202,398.08612,-9.2616749
6398,6398,179.537,18.621449,8.6430321,0.0,0,1.2364751,0.0,0.85881072,100.40115,1.2324337,398.19208,-9.2614183
6409,6409,179.5392,18.733746,8.6639957,0.0,0,1.2212964,0.0,0.86146885,100.77064,1.2167125,398.29803,-9.2624683
6420,6420,179.5414,18.816298,8.6749163,0.0,0,1.206827,0.0,0.86378658,100.9663,1.198662,398.40399,-9.2612314
6431,6431,179.5436,18.888554,8.6966896,0.0,0,1.1923642,0.0,0.86660451,101.09805,1.1837089,398.50998,-9.261775
6442,6442,179.5458,18.928904,8.7025614,0.0,0,1.1779014,0.0,0.86814082,101.18648,1.1721852,397.58453,-9.2608871
6453,6453,179.548,19.011053,8.7238197,0.0,0,1.1634386,0.0,0.87128282,101.29147,1.157397,396.49622,-9.2618132
6464,6464,179.5502,19.068415,8.7332935,0.0,0,1.1489758,0.0,0.87298477,101.39397,1.1399347,395.40793,-9.2628784
6475,6475,179.5524,19.120804,8.7556391,0.0,0,1.134513,0.0,0.8762387,101.35316,1.1243062,394.31961,-9.2622166
6486,6486,179.5546,19.150837,8.7669401,0.0,0,1.1200502,0.0,0.87817806,101.29546,1.1107255,393.18091,-9.2613659
6497,6497,179.5568,19.231058,8.7832489,0.0,0,1.1055874,0.0,0.88082403,101.4759,1.0978117,391.93423,-9.2615242
6508,6508,179.559,19.306637,8.7924051,0.0,0,1.0911245,0.0,0.88229012,101.75892,1.0841371,390.68753,-9.2609625
6519,6519,179.5612,19.403421,8.8124075,0.0,0,1.0766618,0.0,0.8854146,101.84534,1.0674224,389.44086,-9.2618818
6530,6530,179.5634,19.449034,8.822011,0.0,0,1.0621989,0.0,0.88687766,102.01598,1.0561105,388.19418,-9.2615967
6541,6541,179.5656,19.497015,8.8393297,0.0,0,1.0477362,0.0,0.88996089,101.91352,1.0427585,388.13644,-9.2618866
6552,6552,179.5678,19.542065,8.8488817,0.0,0,1.0332733,0.0,0.89119899,102.06808,1.0272095,388.42844,-9.2614613
6563,6563,179.57,19.602055,8.8677177,0.0,0,1.0188106,0.0,0.89480996,102.01999,1.0109676,388.7204,-9.2605686
6574,6574,179.5722,19.64883,8.8780127,0.0,0,1.0043477,0.0,0.89580786,102.13409,0.99706596,389.01239,-9.2601337
6585,6585,179.5744,19.724566,8.8924236,0.0,0,0.98988497,0.0,0.89887536,102.15763,0.98304713,389.14902,-9.2609596
6596,6596,179.5766,19.81637,8.9037285,0.0,0,0.97542214,0.0,0.90009165,102.54281,0.97042292,388.75751,-9.2616558
6607,6607,179.5788,19.927244,8.9230108,0.0,0,0.96095932,0.0,0.90373063,102.73244,0.9573999,388.366,-9.2611456
6618,6618,179.581,20.020544,8.9353266,0.0,0,0.94649649,0.0,0.90501392,103.12378,0.9397217,387.97446,-9.2606192
6629,6629,179.5832,20.113983,8.9475021,0.0,0,0.93203378,0.0,0.90794927,103.24564,0.92516297,387.58295,-9.2592869
6640,6640,179.5854,20.182167,8.961071,0.0,0,0.91757095,0.0,0.90930337,103.52982,0.9119063,387.15976,-9.2618752
6651,6651,179.5876,20.245211,8.981266,0.0,0,0.90310812,0.0,0.91378963,103.39333,0.89774126,386.72177,-9.2610474
6662,6662,179.5898,20.313244,8.9952812,0.0,0,0.88885862,0.0,0.91480953,103.61169,0.88001287,386.28378,-9.2605429
6673,6673,179.592,20.37109,9.0038967,0.0,0,0.87510419,0.0,0.91749227,103.63049,0.86514473,385.84583,-9.262723
6684,6684,179.5942,20.466413,9.0185432,0.0,0,0.86134988,0.0,0.91876352,103.93797,0.85370827,385.57251,-9.261323
6695,6695,179.5964,20.56459,9.0350037,0.0,0,0.84759539,0.0,0.92265218,104.0885,0.83952934,386.34232,-9.2620001
6706,6706,179.5986,20.631552,9.0503187,0.0,0,0.83384103,0.0,0.92385513,104.25163,0.82214439,387.11209,-9.2623396
6717,6717,179.6008,20.679293,9.0587282,0.0,0,0.82008666,0.0,0.92674738,104.21054,0.8111034,387.88187,-9.2623768
6728,6728,179.603,20.719898,9.0729408,0.0,0,0.80633223,0.0,0.92773402,104.33801,0.79704058,388.65164,-9.261199
6739,6739,179.6052,20.760567,9.0872164,0.0,0,0.79257786,0.0,0.93171382,104.11047,0.78379542,389.65277,-9.2611179
6750,6750,179.6074,20.803698,9.1034575,0.0,0,0.77882344,0.0,0.93279803,104.23983,0.7668907,390.81406,-9.2613468
6761,6761,179.6096,20.876768,9.1101589,0.0,0,0.76506907,0.0,0.93565297,104.30034,0.75244802,391.97537,-9.2611217
6772,6772,179.6118,20.957277,9.126689,0.0,0,0.75131464,0.0,0.93668461,104.5735,0.74405837,393.13666,-9.2611732
6783,6783,179.614,21.06846,9.1409578,0.0,0,0.73756021,0.0,0.941073,104.65841,0.73088133,394.26389,-9.2610941
6794,6794,179.6162,21.158947,9.1570368,0.0,0,0.72380584,0.0,0.94170648,105.04754,0.71470648,394.67529,-9.2603111
6805,6805,179.6184,21.249117,9.1611767,0.0,0,0.71005148,0.0,0.94440776,105.21059,0.70430392,395.08673,-9.2616053
6816,6816,179.6206,21.300097,9.1796169,0.0,0,0.69629705,0.0,0.94588327,105.32516,0.68897003,395.49817,-9.2610931
6827,6827,179.6228,21.345921,9.1915789,0.0,0,0.68254262,0.0,0.9498105,105.15562,0.67903894,395.90958,-9.2617168
6838,6838,179.625,21.4508,9.2110329,0.0,0,0.66878825,0.0,0.95090228,105.51918,0.66302657,396.14847,-9.2594519
6849,6849,179.6272,21.5361,9.2143002,0.0,0,0.65503383,0.0,0.9535839,105.67545,0.64966756,396.21484,-9.2599192
6860,6860,179.6294,21.632318,9.2329216,0.0,0,0.64127946,0.0,0.95505619,105.98254,0.63580608,396.28119,-9.261795
6871,6871,179.6316,21.745066,9.2421007,0.0,0,0.62752503,0.0,0.95845968,106.15212,0.62419462,396.34756,-9.2605438
6882,6882,179.6338,21.872561,9.262042,0.0,0,0.61377066,0.0,0.95967376,106.63316,0.60627586,396.41391,-9.2606802
6893,6893,179.636,21.966433,9.2658777,0.0,0,0.60001624,0.0,0.96258849,106.81919,0.59549659,395.53012,-9.2603979
6904,6904,179.6382,22.08264,9.2868042,0.0,0,0.58626187,0.0,0.96423048,107.19398,0.57934523,394.6011,-9.259654
6915,6915,179.6404,22.150749,9.2953634,0.0,0,0.57288873,0.0,0.96760643,107.22202,0.56451267,393.67206,-9.2598801
6926,6926,179.6426,22.249199,9.3169308,0.0,0,0.55979866,0.0,0.96937197,107.44643,0.55326426,392.74301,-9.2609148
6937,6937,179.6448,22.303165,9.3231955,0.0,0,0.5467087,0.0,0.97259015,107.38705,0.54278523,391.99857,-9.2607088
6942,6942,179.6458,22.364,9.3306627,0.0,0,0.54075873,0.0,0.97208476,107.74463,0.53215873,391.7814,-9.2603016