File: clean data/testID_0239.csv
level_0,index,Time(sec),Force(kN),Jaw(mm),PowAngle(deg),Power(W),Pram,PTemp,Strain,Stress(MPa),Stroke(mm),TC1(C),wedge(mm)
2172,2172,165.3851,1.146695,0.031263251,0.0,0,9.7928638,0.0,0.0018609747,14.273595,9.8791504,360.20932,-9.2892771
2183,2183,165.3873,1.8517172,0.040396981,0.0,0,9.7598639,0.0,0.0029114704,23.288429,9.8500481,360.20264,-9.2886248
2194,2194,165.3895,2.000464,0.039025903,0.0,0,9.7268629,0.0,0.0023974127,25.451149,9.8241682,360.19598,-9.2866697
2205,2205,165.3917,2.8359523,0.04983725,0.0,0,9.6938639,0.0,0.0034994369,35.746937,9.7954092,360.18933,-9.2874832
2216,2216,165.3939,3.6033387,0.073337778,0.0,0,9.6608629,0.0,0.0046880399,45.41721,9.7605858,360.32327,-9.2853384
2227,2227,165.3961,4.0033441,0.10692762,0.0,0,9.6278639,0.0,0.0073535736,50.573936,9.7242975,360.50995,-9.2864332
2238,2238,165.3983,4.2678585,0.14660946,0.0,0,9.5948629,0.0,0.0095221382,53.838631,9.688611,360.69666,-9.2864313
2249,2249,165.4005,4.3130913,0.17947237,0.0,0,9.5618639,0.0,0.012169868,54.400421,9.6494217,360.88333,-9.2854156
2260,2260,165.4027,3.8277233,0.22574715,0.0,0,9.5288639,0.0,0.014993646,48.088806,9.6094427,361.09427,-9.2859612
2271,2271,165.4049,2.9843588,0.26630515,0.0,0,9.4958639,0.0,0.018107696,37.555096,9.5688515,361.41428,-9.2862911
2282,2282,165.4071,3.2302706,0.30609691,0.0,0,9.4633293,0.0,0.020265386,40.097816,9.531846,361.73431,-9.2869568
2293,2293,165.4093,3.750761,0.32736745,0.0,0,9.431138,0.0,0.022271592,46.506847,9.5016584,362.05432,-9.2871056
2304,2304,165.4115,4.1653385,0.35255688,0.0,0,9.3989477,0.0,0.023635983,51.707382,9.4745522,362.37436,-9.2855272
2315,2315,165.4137,4.4356947,0.37596005,0.0,0,9.3667564,0.0,0.025625832,54.938557,9.4467916,362.64346,-9.2864885
2326,2326,165.4159,4.3437424,0.41210106,0.0,0,9.3345671,0.0,0.027457412,53.976242,9.4152527,362.88348,-9.2845898
2337,2337,165.4181,3.6889079,0.44376433,0.0,0,9.3023767,0.0,0.030222144,45.925304,9.3811026,363.1235,-9.2848673
2348,2348,165.4203,3.1324751,0.49197286,0.0,0,9.2701855,0.0,0.033204686,38.49342,9.3392124,363.36353,-9.286025
2359,2359,165.4225,3.6697919,0.51500994,0.0,0,9.2379951,0.0,0.035144608,44.977402,9.3130646,363.62897,-9.2861309
2370,2370,165.4247,4.1683197,0.54573977,0.0,0,9.2058048,0.0,0.036682066,50.982517,9.2834702,364.14862,-9.2865391
2381,2381,165.4269,4.6210837,0.56630898,0.0,0,9.1736145,0.0,0.038653243,56.482582,9.2538977,364.66827,-9.2851791
2392,2392,165.4291,4.8644214,0.59896469,0.0,0,9.1414251,0.0,0.040537942,59.336586,9.2197495,365.18793,-9.2858229
2403,2403,165.4313,5.0244031,0.6306563,0.0,0,9.1092339,0.0,0.043130305,61.273586,9.187026,365.70758,-9.2865152
2414,2414,165.4335,5.1314325,0.67007059,0.0,0,9.0770426,0.0,0.045445189,62.481342,9.1511469,366.33588,-9.2865314
2425,2425,165.4357,5.2437286,0.69706166,0.0,0,9.0448523,0.0,0.047722898,63.562099,9.1219301,367.05475,-9.2861156
2436,2436,165.4379,5.3325415,0.73165762,0.0,0,9.0126629,0.0,0.049819805,64.557465,9.0825615,367.77359,-9.2854185
2447,2447,165.4401,5.4311905,0.76094383,0.0,0,8.9804716,0.0,0.052262265,65.645348,9.0543699,368.49246,-9.28512
2458,2458,165.4423,5.5138965,0.80121744,0.0,0,8.9482822,0.0,0.054594975,66.445358,9.014699,369.2113,-9.2853832
2469,2469,165.4445,5.5833211,0.82749003,0.0,0,8.916091,0.0,0.056840159,67.092033,8.9815216,370.00943,-9.2850409
2480,2480,165.4467,5.6627655,0.8609845,0.0,0,8.8839006,0.0,0.058938831,67.915489,8.9527597,370.80756,-9.2851524
2491,2491,165.4489,5.7208748,0.88838935,0.0,0,8.8517103,0.0,0.06116249,68.545341,8.9211464,371.60565,-9.2849264
2502,2502,165.4511,5.7696528,0.9265061,0.0,0,8.819521,0.0,0.063530892,68.977577,8.8858957,372.40378,-9.2835665
2513,2513,165.4533,5.8034477,0.95255625,0.0,0,8.7873297,0.0,0.065694362,69.215309,8.8506165,373.14749,-9.2846355
2524,2524,165.4555,5.8293071,0.98723876,0.0,0,8.7551394,0.0,0.067886911,69.297852,8.8217125,373.8259,-9.2863388
2535,2535,165.4577,5.8747129,1.015362,0.0,0,8.7242823,0.0,0.070175104,69.77565,8.7924232,374.5043,-9.286128
2546,2546,165.4599,5.923131,1.0536735,0.0,0,8.6936674,0.0,0.07267148,70.159149,8.7565145,375.18271,-9.285923
2557,2557,165.4621,5.978622,1.0802162,0.0,0,8.6630526,0.0,0.07486096,70.570183,8.7237434,375.86111,-9.2851238
2568,2568,165.4643,6.0233326,1.1143289,0.0,0,8.6324368,0.0,0.077099375,70.86673,8.6920624,376.26138,-9.2855787
2579,2579,165.4665,6.049346,1.1418926,0.0,0,8.6018219,0.0,0.079176612,71.155937,8.663228,376.63385,-9.2857103
2590,2590,165.4687,6.0749035,1.1790687,0.0,0,8.5712061,0.0,0.081759401,71.295883,8.6304131,377.00632,-9.2856178
2601,2601,165.4709,6.080822,1.203146,0.0,0,8.5405912,0.0,0.083590791,71.217857,8.6029119,377.37875,-9.2859468
2612,2612,165.4731,6.0917172,1.2343776,0.0,0,8.5099754,0.0,0.085769661,71.212051,8.5739737,377.68832,-9.2860804
2623,2623,165.4753,6.1236529,1.2613076,0.0,0,8.4793606,0.0,0.087857954,71.450691,8.5403118,377.88785,-9.2858715
2634,2634,165.4775,6.1629395,1.2965374,0.0,0,8.4487457,0.0,0.090332404,71.650459,8.5152702,378.08737,-9.286274
2645,2645,165.4797,6.2147293,1.3241129,0.0,0,8.4181299,0.0,0.092425078,72.100731,8.482172,378.2869,-9.2867975
2656,2656,165.4819,6.2668452,1.3587967,0.0,0,8.3875151,0.0,0.09488485,72.540359,8.4461632,378.48642,-9.2865582
2667,2667,165.4841,6.3034267,1.3889378,0.0,0,8.3568993,0.0,0.097090058,72.829979,8.4105883,378.60977,-9.2856951
2678,2678,165.4863,6.3293643,1.4260716,0.0,0,8.3262854,0.0,0.099833474,72.986992,8.3817778,378.71619,-9.2859774
2689,2689,165.4885,6.3378644,1.4528859,0.0,0,8.2956686,0.0,0.10184142,72.954079,8.348876,378.8226,-9.2850294
2700,2700,165.4907,6.3586679,1.4849818,0.0,0,8.2650547,0.0,0.1041963,72.965576,8.3154774,378.92902,-9.2864628
2711,2711,165.4929,6.3562179,1.5133908,0.0,0,8.2344389,0.0,0.10624851,72.827682,8.2868538,379.03906,-9.2859621
2722,2722,165.4951,6.3910933,1.5472977,0.0,0,8.203825,0.0,0.10893481,73.038857,8.2539682,379.15878,-9.2856169
2733,2733,165.4973,6.4138789,1.5755528,0.0,0,8.1732092,0.0,0.1108628,73.074722,8.2213869,379.2785,-9.28652
2744,2744,165.4995,6.4535065,1.6045856,0.0,0,8.1425943,0.0,0.11309833,73.316216,8.1915207,379.39822,-9.2867136
2755,2755,165.5017,6.47505,1.6329638,0.0,0,8.1119785,0.0,0.11508397,73.443779,8.1653099,379.51794,-9.2867889
2766,2766,165.5039,6.5018392,1.6654351,0.0,0,8.0813627,0.0,0.117818,73.610916,8.1328735,379.61346,-9.2863741
2777,2777,165.5061,6.5410824,1.6955265,0.0,0,8.0509262,0.0,0.11971918,73.852928,8.1054115,379.69995,-9.2859383
2788,2788,165.5083,6.5556655,1.7220771,0.0,0,8.0217981,0.0,0.12202472,73.747635,8.0713406,379.78641,-9.285903
2799,2799,165.5105,6.5519238,1.7490028,0.0,0,7.9926691,0.0,0.12385768,73.734459,8.0418348,379.87286,-9.2867022
2810,2810,165.5127,6.5602536,1.7811918,0.0,0,7.9635415,0.0,0.12654813,73.588104,8.0155554,379.94965,-9.2866373
2821,2821,165.5149,6.5954089,1.8099786,0.0,0,7.9344139,0.0,0.12838052,73.857216,7.9860954,379.98291,-9.2863646
2832,2832,165.5171,6.6493759,1.8385425,0.0,0,7.9052858,0.0,0.13092117,74.21167,7.9556308,380.01617,-9.2857504
2843,2843,165.5193,6.691411,1.8690729,0.0,0,7.8761578,0.0,0.13292825,74.561577,7.923193,380.04944,-9.2854109
2854,2854,165.5215,6.722827,1.901261,0.0,0,7.8470297,0.0,0.13572225,74.716148,7.8890905,380.0827,-9.2854614
2865,2865,165.5237,6.7375007,1.9325434,0.0,0,7.8179016,0.0,0.13760597,74.721718,7.8646283,380.13287,-9.2859125
2876,2876,165.5259,6.7376733,1.9582123,0.0,0,7.7887735,0.0,0.14000495,74.676842,7.8329821,380.19275,-9.2859097
2887,2887,165.5281,6.757103,1.9871699,0.0,0,7.7596455,0.0,0.14187339,74.709351,7.8007421,380.25259,-9.2862978
2898,2898,165.5303,6.7728658,2.018187,0.0,0,7.7305174,0.0,0.1447286,74.620605,7.7736845,380.31247,-9.2849998
2909,2909,165.5325,6.7773485,2.0492985,0.0,0,7.7013893,0.0,0.14656156,74.54924,7.743258,380.37231,-9.2857571
2920,2920,165.5347,6.8133707,2.0718491,0.0,0,7.6722617,0.0,0.14887658,74.749474,7.7149844,380.43219,-9.285779
2931,2931,165.5369,6.8441191,2.1013753,0.0,0,7.6431332,0.0,0.15066582,74.84256,7.6845622,380.49203,-9.2865038
2942,2942,165.5391,6.8743873,2.130636,0.0,0,7.6140056,0.0,0.15338178,75.090637,7.658452,380.55188,-9.2866573
2953,2953,165.5413,6.8937688,2.1620626,0.0,0,7.5848775,0.0,0.15531428,75.248459,7.6313696,380.61176,-9.2868271
2964,2964,165.5435,6.9236455,2.1838999,0.0,0,7.5557494,0.0,0.157547,75.356186,7.6023693,380.60266,-9.2869921
2975,2975,165.5457,6.9509263,2.2136209,0.0,0,7.5266213,0.0,0.15937248,75.403778,7.5755072,380.53616,-9.2857418
2986,2986,165.5479,6.9786124,2.2435517,0.0,0,7.4974933,0.0,0.16232331,75.602867,7.5458946,380.46964,-9.2857485
2997,2997,165.5501,6.9997611,2.2789948,0.0,0,7.4683657,0.0,0.16440257,75.669525,7.5162892,380.40314,-9.2847204
3008,3008,165.5523,7.0290046,2.3015234,0.0,0,7.4392376,0.0,0.16678129,75.724785,7.4821448,380.33661,-9.2840948
3019,3019,165.5545,7.0878863,2.3340893,0.0,0,7.410109,0.0,0.16884774,76.146461,7.4514189,380.21024,-9.2851276
3030,3030,165.5567,7.1103878,2.3623807,0.0,0,7.3815403,0.0,0.17167652,76.213371,7.4203515,380.08386,-9.2863054
3041,3041,165.5589,7.1240315,2.397917,0.0,0,7.353838,0.0,0.17378989,76.17231,7.3958592,379.95749,-9.2852135
3052,3052,165.5611,7.1386337,2.4195421,0.0,0,7.3261356,0.0,0.17612001,76.184639,7.3644428,379.83115,-9.2863483
3063,3063,165.5633,7.1602273,2.4494298,0.0,0,7.2984333,0.0,0.17803332,76.300598,7.3346028,379.5264,-9.2858801
3074,3074,165.5655,7.1746793,2.4761467,0.0,0,7.270731,0.0,0.18073429,76.143806,7.3049626,379.00763,-9.2854404
3085,3085,165.5677,7.1862445,2.5106337,0.0,0,7.2430286,0.0,0.18279824,76.143898,7.2773323,378.48886,-9.286499
3096,3096,165.5699,7.1605811,2.5299952,0.0,0,7.2153258,0.0,0.18497266,75.853477,7.2541342,377.97009,-9.2870274
3107,3107,165.5721,7.2052622,2.5574608,0.0,0,7.1876235,0.0,0.1866484,76.10199,7.2249761,377.45129,-9.2872162
3118,3118,165.5743,7.2516317,2.5831754,0.0,0,7.1599212,0.0,0.18930691,76.390999,7.1953883,376.58185,-9.2850819
3129,3129,165.5765,7.2893777,2.6186459,0.0,0,7.1322188,0.0,0.19145043,76.615738,7.1697145,375.67731,-9.2841558
3140,3140,165.5787,7.3107991,2.6389396,0.0,0,7.104516,0.0,0.19370314,76.784592,7.1429462,374.77277,-9.2845898
3151,3151,165.5809,7.3257451,2.667201,0.0,0,7.0768137,0.0,0.19563544,76.756119,7.1119976,373.86823,-9.2855787
3162,3162,165.5831,7.3453655,2.6938,0.0,0,7.0491114,0.0,0.19824921,76.716972,7.086504,373.15717,-9.2862034
3173,3173,165.5853,7.3531122,2.7283206,0.0,0,7.021409,0.0,0.20039292,76.658699,7.0560741,372.7847,-9.28652
3184,3184,165.5875,7.3834248,2.748348,0.0,0,6.9937067,0.0,0.20260087,76.767944,7.0304322,372.41226,-9.2861614
3195,3195,165.5897,7.4035563,2.7783902,0.0,0,6.9660039,0.0,0.20459838,76.806427,7.0008445,372.03979,-9.2865191
3206,3206,165.5919,7.4580994,2.8031969,0.0,0,6.938302,0.0,0.20711268,77.127953,6.9733319,371.66736,-9.2864838
3217,3217,165.5941,7.4997773,2.8381386,0.0,0,6.9105997,0.0,0.20937803,77.392616,6.9470587,371.70303,-9.2858973
3228,3228,165.5963,7.5231462,2.8598783,0.0,0,6.8828974,0.0,0.21175051,77.542252,6.9177575,371.82941,-9.2854185
3239,3239,165.5985,7.5504594,2.8916109,0.0,0,6.8551946,0.0,0.21399175,77.623596,6.88799,371.95578,-9.2850752
3250,3250,165.6007,7.5676789,2.9165497,0.0,0,6.8274922,0.0,0.21642846,77.621559,6.8577151,372.08212,-9.2851086
3261,3261,165.6029,7.5816331,2.950227,0.0,0,6.7997894,0.0,0.21868195,77.552536,6.8323226,372.20306,-9.2862711
3272,3272,165.6051,7.5824795,2.9716325,0.0,0,6.7720871,0.0,0.22099005,77.402237,6.8056703,372.30948,-9.2862968
3283,3283,165.6073,7.6165762,3.0033219,0.0,0,6.7452798,0.0,0.22327344,77.522949,6.7765074,372.41589,-9.2851667
3294,3294,165.6095,7.6461115,3.0267122,0.0,0,6.718924,0.0,0.22545256,77.678558,6.7469449,372.52231,-9.2844133
3305,3305,165.6117,7.6820674,3.0599217,0.0,0,6.6925678,0.0,0.22784482,77.792732,6.7202048,372.62872,-9.2853489
3316,3316,165.6139,7.7071681,3.0791836,0.0,0,6.6662121,0.0,0.22983834,78.00119,6.6962514,372.64807,-9.2866774
3327,3327,165.6161,7.7216516,3.1082168,0.0,0,6.6398559,0.0,0.23206416,78.003502,6.6669765,372.63477,-9.2865238
3338,3338,165.6183,7.7422833,3.1317697,0.0,0,6.6135001,0.0,0.2342488,77.93956,6.6415453,372.62146,-9.2857695
3349,3349,165.6205,7.7603436,3.1644921,0.0,0,6.5871439,0.0,0.23669228,78.024796,6.6145773,372.60818,-9.2847586
3360,3360,165.6227,7.7757492,3.1847453,0.0,0,6.5607882,0.0,0.23866194,77.983894,6.5888681,372.58035,-9.28543
3371,3371,165.6249,7.7872791,3.2130842,0.0,0,6.5344319,0.0,0.24099579,77.859207,6.5614672,372.48724,-9.2867346
3382,3382,165.6271,7.8123794,3.2365263,0.0,0,6.5080762,0.0,0.24315102,77.958412,6.5352912,372.3941,-9.286808
3393,3393,165.6293,7.8548179,3.2686172,0.0,0,6.48172,0.0,0.24565463,78.118591,6.5101748,372.30099,-9.2863331
3404,3404,165.6315,7.8989091,3.2904613,0.0,0,6.4553642,0.0,0.24758655,78.463844,6.4845357,372.20789,-9.2851143
3415,3415,165.6337,7.936563,3.3175223,0.0,0,6.4290085,0.0,0.24985148,78.659019,6.4577603,372.15286,-9.2851563
3426,3426,165.6359,7.9525065,3.3409498,0.0,0,6.4026518,0.0,0.25194305,78.673447,6.4318471,372.1196,-9.2853689
3437,3437,165.6381,7.9527931,3.3723562,0.0,0,6.376296,0.0,0.25458854,78.521461,6.4068561,372.08636,-9.2856035
3448,3448,165.6403,7.992146,3.394927,0.0,0,6.3499398,0.0,0.25653291,78.741066,6.3792009,372.0531,-9.2863169
3459,3459,165.6425,8.0259333,3.4255431,0.0,0,6.3235841,0.0,0.25924069,78.842278,6.3527188,372.0253,-9.2854099
3470,3470,165.6447,8.0450096,3.450177,0.0,0,6.2972283,0.0,0.26123378,78.835266,6.3212204,372.05191,-9.2856159
3481,3481,165.6469,8.0678997,3.4810498,0.0,0,6.2708726,0.0,0.264002,78.908592,6.293838,372.07852,-9.2862186
3492,3492,165.6491,8.114006,3.5040264,0.0,0,6.2445164,0.0,0.26583821,79.251259,6.2707915,372.1051,-9.285347
3503,3503,165.6513,8.1475563,3.5291977,0.0,0,6.2181602,0.0,0.2683855,79.31311,6.2422028,372.13171,-9.2858572
3514,3514,165.6535,8.1652269,3.5522776,0.0,0,6.1918044,0.0,0.27019545,79.331749,6.2159486,372.09665,-9.2854519
3525,3525,165.6557,8.1906185,3.5833797,0.0,0,6.1654482,0.0,0.27307197,79.33741,6.1906347,372.01016,-9.2853909
3536,3536,165.6579,8.1908226,3.608479,0.0,0,6.1403008,0.0,0.27497813,79.276093,6.168725,371.92371,-9.2857018
3547,3547,165.6601,8.2158298,3.6341317,0.0,0,6.1152344,0.0,0.27755073,79.300415,6.1405072,371.83725,-9.2859526
3558,3558,165.6623,8.2393789,3.658277,0.0,0,6.0901675,0.0,0.27927434,79.323692,6.1129112,371.75079,-9.2870588
3569,3569,165.6645,8.2702532,3.6862764,0.0,0,6.0651007,0.0,0.2821795,79.354454,6.0884695,371.60446,-9.2864161
3580,3580,165.6667,8.308445,3.7109365,0.0,0,6.0400338,0.0,0.28396705,79.565819,6.0601797,371.45816,-9.2852068
3591,3591,165.6689,8.3414583,3.7349067,0.0,0,6.014967,0.0,0.28646737,79.692871,6.0354414,371.31183,-9.2845802
3602,3602,165.6711,8.3553686,3.7573054,0.0,0,5.9899006,0.0,0.2881268,79.751419,6.0142088,371.1655,-9.2851372
3613,3613,165.6733,8.3752327,3.7854662,0.0,0,5.9648333,0.0,0.29110458,79.760727,5.9833794,371.07361,-9.2858181
3624,3624,165.6755,8.3903685,3.8117056,0.0,0,5.9397664,0.0,0.2928538,79.721779,5.9619641,371.047,-9.2855015
3635,3635,165.6777,8.4209003,3.8331587,0.0,0,5.9147,0.0,0.29536313,79.840218,5.9354329,371.02039,-9.284297
3646,3646,165.6799,8.4568224,3.8611107,0.0,0,5.8896332,0.0,0.29726133,79.907509,5.9073091,370.99377,-9.2856321
3657,3657,165.6821,8.4776516,3.8880694,0.0,0,5.8645663,0.0,0.30029613,79.871117,5.8826909,370.96716,-9.2870693
3668,3668,165.6843,8.489871,3.9124222,0.0,0,5.8394995,0.0,0.30189562,79.917198,5.8580375,370.84381,-9.2862415
3679,3679,165.6865,8.5268574,3.9314504,0.0,0,5.8144326,0.0,0.3041943,80.124023,5.8332109,370.71082,-9.2851057
3690,3690,165.6887,8.5520201,3.9575224,0.0,0,5.7893653,0.0,0.30600664,80.161209,5.8086262,370.57779,-9.2849302
3701,3701,165.6909,8.5557556,3.9830749,0.0,0,5.7642989,0.0,0.30898428,79.944847,5.7867718,370.44476,-9.2848711
3712,3712,165.6931,8.5739431,4.0085731,0.0,0,5.7392321,0.0,0.3105565,80.085236,5.764678,370.30688,-9.2857151
3723,3723,165.6953,8.608367,4.0300336,0.0,0,5.7141652,0.0,0.31317416,80.176559,5.7392864,370.16058,-9.2853231
3734,3734,165.6975,8.6612368,4.0577049,0.0,0,5.6890984,0.0,0.31502959,80.485474,5.7128487,370.01425,-9.2838974
3745,3745,165.6997,8.7230844,4.0811367,0.0,0,5.6640315,0.0,0.31794068,80.781158,5.6876745,369.86792,-9.2832346
3756,3756,165.7019,8.7710838,4.1126761,0.0,0,5.6389647,0.0,0.31999928,81.074585,5.6563921,369.72162,-9.2848549
3767,3767,165.7041,8.8014164,4.1346197,0.0,0,5.6138978,0.0,0.3228564,81.099991,5.6293616,369.65692,-9.2854824
3778,3778,165.7063,8.8212204,4.164609,0.0,0,5.589088,0.0,0.32479376,81.21051,5.6054034,369.61035,-9.2864084
3789,3789,165.7085,8.8381948,4.1872706,0.0,0,5.5652399,0.0,0.32776093,81.159615,5.5785947,369.56381,-9.2858458
3800,3800,165.7107,8.8566389,4.2165999,0.0,0,5.5413914,0.0,0.32945982,81.138023,5.5548449,369.51724,-9.2846498
3811,3811,165.7129,8.8494196,4.2325091,0.0,0,5.5175438,0.0,0.33186549,80.84211,5.5332303,369.23636,-9.2848167
3822,3822,165.7151,8.8543959,4.2591438,0.0,0,5.4936957,0.0,0.33367038,80.720375,5.5086579,368.33051,-9.2859879
3833,3833,165.7173,8.860919,4.2789979,0.0,0,5.4698477,0.0,0.33629736,80.564003,5.485343,367.42468,-9.2859364
3844,3844,165.7195,8.9105377,4.3088751,0.0,0,5.4459996,0.0,0.33805221,80.892784,5.461616,366.51886,-9.2860565
3855,3855,165.7217,8.9463844,4.3260794,0.0,0,5.4221516,0.0,0.34051317,81.041199,5.4415693,365.61301,-9.2854729
3866,3866,165.7239,8.9727888,4.3497081,0.0,0,5.3983035,0.0,0.34212255,81.126938,5.4119687,364.63922,-9.2842922
3877,3877,165.7261,9.0042171,4.369092,0.0,0,5.3744559,0.0,0.34477881,81.216217,5.3888683,363.63998,-9.2852249
3888,3888,165.7283,9.0300503,4.4016881,0.0,0,5.3506079,0.0,0.34682333,81.319763,5.3694615,362.64075,-9.2856321
3899,3899,165.7305,9.0606289,4.4169111,0.0,0,5.3267598,0.0,0.34916067,81.345978,5.3501735,361.64148,-9.2867918
3910,3910,165.7327,9.1087456,4.4470639,0.0,0,5.3029118,0.0,0.35142833,81.623993,5.3198419,360.81665,-9.2862806
3921,3921,165.7349,9.1657343,4.4698815,0.0,0,5.2790637,0.0,0.35422617,81.830589,5.2956529,360.77664,-9.2843437
3932,3932,165.7371,9.1717587,4.5027876,0.0,0,5.2552156,0.0,0.35638314,81.752602,5.2681179,360.73663,-9.2853718
3943,3943,165.7393,9.2213707,4.5177102,0.0,0,5.2313676,0.0,0.35865536,82.026062,5.2445927,360.69662,-9.2852936
3954,3954,165.7415,9.241066,4.5475483,0.0,0,5.20752,0.0,0.3609269,82.030678,5.2212248,360.65665,-9.2859221
3965,3965,165.7437,9.2744637,4.5685616,0.0,0,5.1836715,0.0,0.3635999,82.058441,5.196959,360.65057,-9.2850161
3976,3976,165.7459,9.2847328,4.6002469,0.0,0,5.1598234,0.0,0.36587018,82.037582,5.1681499,360.66391,-9.2858295
3987,3987,165.7481,9.3125734,4.6150274,0.0,0,5.1359754,0.0,0.36793223,82.116707,5.1475682,360.67725,-9.2856255
3998,3998,165.7503,9.3218966,4.6431675,0.0,0,5.1121278,0.0,0.37012431,81.979309,5.1270008,360.69058,-9.2862587
4009,4009,165.7525,9.3432178,4.6613383,0.0,0,5.0882797,0.0,0.37241414,81.930687,5.0995598,360.69299,-9.2859001
4020,4020,165.7547,9.3736372,4.6935639,0.0,0,5.0644317,0.0,0.37487304,82.044456,5.0781822,360.58633,-9.2853966
4031,4031,165.7569,9.419899,4.7105179,0.0,0,5.0411468,0.0,0.3771461,82.302879,5.0554237,360.47964,-9.2856522
4042,4042,165.7591,9.4891205,4.7389183,0.0,0,5.0184646,0.0,0.37939489,82.602341,5.029706,360.37296,-9.2848825
4053,4053,165.7613,9.5081949,4.7571554,0.0,0,4.9957829,0.0,0.38167167,82.617439,5.005074,360.2663,-9.2848959
4064,4064,165.7635,9.5494089,4.7910061,0.0,0,4.9731011,0.0,0.38440245,82.769402,4.980319,360.12689,-9.2862072
4075,4075,165.7657,9.5784006,4.8079824,0.0,0,4.9504189,0.0,0.38664424,82.873795,4.9575744,359.96021,-9.2851944
4086,4086,165.7679,9.5801096,4.8345013,0.0,0,4.9277368,0.0,0.38882014,82.743629,4.9344044,359.79352,-9.2844896
4097,4097,165.7701,9.5730057,4.8531842,0.0,0,4.9050546,0.0,0.39103973,82.467468,4.908546,359.62686,-9.2849131
4108,4108,165.7723,9.5589685,4.8807082,0.0,0,4.8823729,0.0,0.39338458,82.163872,4.889658,359.46017,-9.2864571
4119,4119,165.7745,9.588048,4.8953896,0.0,0,4.8596911,0.0,0.39517537,82.236755,4.8694582,359.42685,-9.2849884
4130,4130,165.7767,9.6409349,4.9196668,0.0,0,4.8370085,0.0,0.39724764,82.501022,4.849412,359.39349,-9.284874
4141,4141,165.7789,9.6941681,4.9383488,0.0,0,4.8143268,0.0,0.39932919,82.748825,4.8237224,359.36017,-9.2846117
4152,4152,165.7811,9.7228613,4.9674678,0.0,0,4.7916451,0.0,0.4020175,82.865631,4.7999082,359.32684,-9.2844706
4163,4163,165.7833,9.7721567,4.9847827,0.0,0,4.7689629,0.0,0.40398404,83.065788,4.7778268,358.85696,-9.2853365
4174,4174,165.7855,9.8233166,5.0109081,0.0,0,4.7462807,0.0,0.40654364,83.287758,4.7570586,357.86328,-9.2846375
4185,4185,165.7877,9.8328018,5.0313516,0.0,0,4.7235985,0.0,0.40854919,83.236259,4.7317171,356.8696,-9.2855406
4196,4196,165.7899,9.8504438,5.060626,0.0,0,4.7009168,0.0,0.41151091,83.12796,4.7055678,355.87592,-9.2853985
4207,4207,165.7921,9.8842583,5.0803761,0.0,0,4.6782351,0.0,0.41356364,83.246994,4.68328,354.88223,-9.2863054
4218,4218,165.7943,9.9203005,5.1049562,0.0,0,4.6555529,0.0,0.41595259,83.292351,4.6620922,353.94336,-9.2863836
4229,4229,165.7965,9.9636707,5.1227298,0.0,0,4.6328707,0.0,0.4176884,83.450096,4.6404614,353.00995,-9.2853336
4240,4240,165.7987,9.9809561,5.1506252,0.0,0,4.610189,0.0,0.42070043,83.453117,4.6174726,352.07654,-9.2856245
4251,4251,165.8009,9.9998608,5.1706448,0.0,0,4.5875068,0.0,0.4225482,83.479713,4.5937848,351.14313,-9.2839584
4262,4262,165.8031,10.016915,5.1937256,0.0,0,4.5648251,0.0,0.42508301,83.401947,4.5726895,350.74319,-9.284111
4273,4273,165.8053,10.0509,5.2125216,0.0,0,4.5421429,0.0,0.42677334,83.528038,4.5481811,351.27682,-9.2846422
4284,4284,165.8075,10.091476,5.2381821,0.0,0,4.5202951,0.0,0.42978105,83.584312,4.5298734,351.81049,-9.2848358
4295,4295,165.8097,10.106236,5.2589126,0.0,0,4.4987173,0.0,0.43139893,83.580879,4.5068955,352.34412,-9.2850132
4306,4306,165.8119,10.1673,5.2811251,0.0,0,4.4771399,0.0,0.43415809,83.859825,4.4856706,352.87778,-9.2849951
4317,4317,165.8141,10.203752,5.3041701,0.0,0,4.4555626,0.0,0.43612891,83.94194,4.4601588,353.073,-9.2844248
4328,4328,165.8163,10.234144,5.3279967,0.0,0,4.4339848,0.0,0.4390229,83.952217,4.4370484,353.19299,-9.2852087
4339,4339,165.8185,10.248049,5.3476448,0.0,0,4.4124074,0.0,0.44050637,83.994438,4.4204831,353.31302,-9.2849541
4350,4350,165.8207,10.273176,5.3685665,0.0,0,4.3908296,0.0,0.44320679,83.968163,4.4006586,353.43301,-9.2856207
4361,4361,165.8229,10.298343,5.3880935,0.0,0,4.3692517,0.0,0.44473094,84.078156,4.3773041,353.43665,-9.28617
4372,4372,165.8251,10.335806,5.4132476,0.0,0,4.3476744,0.0,0.44801107,84.085503,4.351593,353.12994,-9.2842674
4383,4383,165.8273,10.366772,5.4368124,0.0,0,4.326097,0.0,0.44967243,84.269981,4.3298755,352.82324,-9.2843246
4394,4394,165.8295,10.38475,5.4559879,0.0,0,4.3045192,0.0,0.45244011,84.116295,4.3105097,352.51657,-9.2850561
4405,4405,165.8317,10.43752,5.4790931,0.0,0,4.2829418,0.0,0.45420843,84.407005,4.2926803,352.20987,-9.2853394
4416,4416,165.8339,10.492621,5.5001683,0.0,0,4.261364,0.0,0.45726773,84.53492,4.2629862,352.10199,-9.285593
4427,4427,165.8361,10.529247,5.5240464,0.0,0,4.2397861,0.0,0.45894679,84.715889,4.2422285,352.06863,-9.2845345
4438,4438,165.8383,10.541631,5.5412607,0.0,0,4.2182088,0.0,0.46141633,84.643112,4.2226801,352.03531,-9.2833405
4449,4449,165.8405,10.573321,5.5663385,0.0,0,4.196631,0.0,0.46328571,84.685616,4.2040782,352.00198,-9.2844372
4460,4460,165.8427,10.597599,5.5887017,0.0,0,4.1750536,0.0,0.46661803,84.619392,4.18082,352.0329,-9.2855787
4471,4471,165.8449,10.616167,5.6141548,0.0,0,4.1534758,0.0,0.46828645,84.678337,4.1579361,352.35291,-9.2849798
4482,4482,165.8471,10.638526,5.6293859,0.0,0,4.1318984,0.0,0.47087365,84.597549,4.1346254,352.67294,-9.2846556
4493,4493,165.8493,10.662723,5.6536937,0.0,0,4.1103206,0.0,0.47255355,84.640717,4.112258,352.99298,-9.2846756
4504,4504,165.8515,10.700939,5.6715627,0.0,0,4.0887432,0.0,0.47540924,84.638779,4.0939898,353.31302,-9.2850657
4515,4515,165.8537,10.772354,5.6989212,0.0,0,4.0671659,0.0,0.47731629,85.025223,4.0729656,353.67123,-9.2843227
4526,4526,165.8559,10.829341,5.7151146,0.0,0,4.0456276,0.0,0.48003304,85.344353,4.0532351,354.05124,-9.2848377
4537,4537,165.8581,10.838884,5.7410908,0.0,0,4.0250959,0.0,0.48201248,85.294724,4.0283709,354.43127,-9.2841625
4548,4548,165.8603,10.88082,5.7589111,0.0,0,4.0045748,0.0,0.48490027,85.299606,4.003696,354.81131,-9.2848501
4559,4559,165.8625,10.898305,5.7866678,0.0,0,3.9840529,0.0,0.48670164,85.223221,3.9851415,355.18347,-9.2849646
4570,4570,165.8647,10.923606,5.8017488,0.0,0,3.9635313,0.0,0.48958921,85.283379,3.9650087,355.47684,-9.2842913
4581,4581,165.8669,10.955599,5.828361,0.0,0,3.9430099,0.0,0.4915674,85.349731,3.9429691,355.77017,-9.2851915
4592,4592,165.8691,11.008451,5.8456631,0.0,0,3.9224882,0.0,0.49437776,85.476143,3.9205623,356.06354,-9.2840118
4603,4603,165.8713,11.024614,5.8745985,0.0,0,3.9019666,0.0,0.49626738,85.45536,3.8986878,356.3569,-9.2849092
4614,4614,165.8735,11.050912,5.8868132,0.0,0,3.8814449,0.0,0.49876112,85.401314,3.8794498,356.69754,-9.2845917
4625,4625,165.8757,11.06639,5.9102936,0.0,0,3.8609233,0.0,0.50046355,85.438904,3.8602841,357.07755,-9.2851152
4636,4636,165.8779,11.066594,5.9254556,0.0,0,3.8404016,0.0,0.50319344,85.148155,3.8384295,357.45758,-9.2861814
4647,4647,165.8801,11.086639,5.9538279,0.0,0,3.8198802,0.0,0.50507241,85.207588,3.818716,357.83762,-9.2836561
4658,4658,165.8823,11.12886,5.9641976,0.0,0,3.7993586,0.0,0.50730467,85.349731,3.8029139,358.21765,-9.2844124
4669,4669,165.8845,11.156184,5.9899993,0.0,0,3.778837,0.0,0.50920886,85.399551,3.7806423,358.41766,-9.2842646
4680,4680,165.8867,11.19467,6.005775,0.0,0,3.7583156,0.0,0.51201069,85.424477,3.7596774,358.61768,-9.2848148
4691,4691,165.8889,11.24524,6.0330396,0.0,0,3.7377939,0.0,0.5138247,85.639603,3.7407689,358.81769,-9.2843456
4702,4702,165.8911,11.304667,6.0452223,0.0,0,3.7172723,0.0,0.51619035,85.855988,3.7231123,359.0177,-9.2834044
4713,4713,165.8933,11.376958,6.0700445,0.0,0,3.6967506,0.0,0.51824993,86.245018,3.7021565,359.13287,-9.2838888
4724,4724,165.8955,11.41495,6.086585,0.0,0,3.676229,0.0,0.52100879,86.312943,3.6809299,359.14621,-9.2839718
4735,4735,165.8977,11.431736,6.1179338,0.0,0,3.6557074,0.0,0.52333188,86.234291,3.6573792,359.15952,-9.2834444
4746,4746,165.8999,11.444686,6.1317034,0.0,0,3.635186,0.0,0.52587092,86.15564,3.6401293,359.17285,-9.2849321
4757,4757,165.9021,11.46339,6.1570377,0.0,0,3.6146641,0.0,0.52801144,86.066902,3.6166396,359.18619,-9.2851954
4768,4768,165.9043,11.50474,6.1712251,0.0,0,3.5941427,0.0,0.53046829,86.170395,3.593863,358.73889,-9.2838583
4779,4779,165.9065,11.556755,6.2013884,0.0,0,3.5739219,0.0,0.53293222,86.294006,3.5730848,358.24551,-9.2853775
4790,4790,165.9087,11.601002,6.2141848,0.0,0,3.554399,0.0,0.5352155,86.534454,3.5538568,357.75217,-9.2850142
4801,4801,165.9109,11.633328,6.2391596,0.0,0,3.5348763,0.0,0.5373767,86.568352,3.5344145,357.25879,-9.2858315
4812,4812,165.9131,11.665335,6.2536931,0.0,0,3.5153534,0.0,0.53982937,86.564865,3.5141382,356.70236,-9.2845955
4823,4823,165.9153,11.715993,6.2831278,0.0,0,3.4958305,0.0,0.54233509,86.695724,3.4897866,356.03564,-9.2846718
4834,4834,165.9175,11.707159,6.2965174,0.0,0,3.4763079,0.0,0.54456747,86.479568,3.4724238,355.36893,-9.2829504
4845,4845,165.9197,11.708306,6.3195295,0.0,0,3.4567852,0.0,0.54658943,86.251724,3.4554572,354.70221,-9.285037
4856,4856,165.9219,11.730653,6.3319883,0.0,0,3.4372621,0.0,0.54858416,86.291634,3.4378116,354.03546,-9.2854977
4867,4867,165.9241,11.740425,6.3591962,0.0,0,3.4177396,0.0,0.55116278,86.126816,3.4165184,353.69604,-9.2848377
4878,4878,165.9263,11.791593,6.3697119,0.0,0,3.3982165,0.0,0.55300885,86.347267,3.3950727,353.42935,-9.2850437
4889,4889,165.9285,11.83456,6.3922529,0.0,0,3.3786941,0.0,0.5551936,86.54203,3.3788013,353.16266,-9.2845631
4900,4900,165.9307,11.881453,6.4087873,0.0,0,3.3591712,0.0,0.557423,86.59845,3.3599188,352.896,-9.2848301
4911,4911,165.9329,11.91637,6.4335318,0.0,0,3.339648,0.0,0.5599544,86.663017,3.3426948,352.60922,-9.2851152
4922,4922,165.9351,11.946605,6.4450107,0.0,0,3.3201256,0.0,0.56158477,86.752403,3.3239763,352.26898,-9.2859535
4933,4933,165.9373,11.979115,6.4676681,0.0,0,3.3006024,0.0,0.56410271,86.85041,3.3051364,351.92871,-9.2850037
4944,4944,165.9395,12.058579,6.4851322,0.0,0,3.2810795,0.0,0.56624573,87.11496,3.2835689,351.58844,-9.2845068
4955,4955,165.9417,12.116138,6.5134578,0.0,0,3.2615571,0.0,0.56935459,87.27903,3.2616205,351.2482,-9.2835751
4966,4966,165.9439,12.179232,6.5279822,0.0,0,3.242034,0.0,0.57132852,87.521843,3.2406065,350.6015,-9.2848444
4977,4977,165.9461,12.238965,6.5507536,0.0,0,3.2225113,0.0,0.57400572,87.791603,3.220897,349.8399,-9.2833729
4988,4988,165.9483,12.280245,6.5702081,0.0,0,3.2029886,0.0,0.57617712,87.878593,3.1993959,349.07831,-9.2842531
4999,4999,165.9505,12.304831,6.5976262,0.0,0,3.1834657,0.0,0.57949209,87.776779,3.1785715,348.31671,-9.2841558
5010,5010,165.9527,12.307662,6.6115823,0.0,0,3.1639431,0.0,0.58103538,87.632301,3.1570251,347.60971,-9.2840891
5021,5021,165.9549,12.29973,6.631259,0.0,0,3.1444204,0.0,0.58376628,87.394501,3.1447988,347.14844,-9.2839603
5032,5032,165.9571,12.30853,6.6493535,0.0,0,3.1254427,0.0,0.58554178,87.270355,3.1259565,346.68719,-9.284276
5043,5043,165.9593,12.354486,6.6735616,0.0,0,3.1068702,0.0,0.58879393,87.281769,3.1044099,346.22592,-9.2845955
5054,5054,165.9615,12.397362,6.6882524,0.0,0,3.0882978,0.0,0.59010118,87.468826,3.0880353,345.76465,-9.2836409
5065,5065,165.9637,12.433089,6.706625,0.0,0,3.0697253,0.0,0.59262913,87.466942,3.0701134,345.58841,-9.2850056
5076,5076,165.9659,12.493628,6.7248569,0.0,0,3.0511529,0.0,0.59455371,87.806129,3.0513315,345.57507,-9.2849607
5087,5087,165.9681,12.546602,6.7483487,0.0,0,3.0325809,0.0,0.59793895,87.837723,3.0330019,345.56171,-9.2848721
5098,5098,165.9703,12.609631,6.7655644,0.0,0,3.0140083,0.0,0.5992552,88.160027,3.0130038,345.54834,-9.2848597
5109,5109,165.9725,12.625214,6.7842016,0.0,0,2.995436,0.0,0.60230947,88.106537,2.9921439,345.4967,-9.2845688
5120,5120,165.9747,12.620201,6.8023109,0.0,0,2.9768634,0.0,0.60389721,87.835922,2.9720488,345.06216,-9.2837639
5131,5131,165.9769,12.627974,6.8233142,0.0,0,2.9582911,0.0,0.60719997,87.552193,2.9552281,344.62766,-9.2849102
5142,5142,165.9791,12.662932,6.8419495,0.0,0,2.9397185,0.0,0.60859603,87.692184,2.9362028,344.19312,-9.2847233
5153,5153,165.9813,12.684672,6.8584623,0.0,0,2.9211462,0.0,0.61136901,87.661232,2.9204233,343.75861,-9.284317
5164,5164,165.9835,12.750515,6.8763337,0.0,0,2.9025741,0.0,0.61277395,87.935547,2.9020798,343.07248,-9.2835569
5175,5175,165.9857,12.81029,6.8940377,0.0,0,2.8840015,0.0,0.61595887,88.125458,2.882266,342.1767,-9.2849369
5186,5186,165.9879,12.876543,6.9137826,0.0,0,2.8654292,0.0,0.61734724,88.475075,2.8670044,341.28094,-9.2858877
5197,5197,165.9901,12.909562,6.9302101,0.0,0,2.8468566,0.0,0.62027341,88.407578,2.8474545,340.38516,-9.2861891
5208,5208,165.9923,12.929353,6.9514427,0.0,0,2.8282843,0.0,0.62199903,88.368958,2.8265307,339.48938,-9.2849102
5219,5219,165.9945,12.942279,6.9678268,0.0,0,2.8097117,0.0,0.62514663,88.229301,2.8068242,338.80753,-9.2834349
5230,5230,165.9967,12.97523,6.9910793,0.0,0,2.7911394,0.0,0.62692636,88.283531,2.7893362,338.12567,-9.2844772
5241,5241,165.9989,13.04895,7.0049443,0.0,0,2.772567,0.0,0.62979072,88.457825,2.7718923,337.44379,-9.2845621
5252,5252,166.0011,13.088954,7.0259027,0.0,0,2.7539945,0.0,0.63129956,88.633537,2.7534363,336.76193,-9.2845707
5263,5263,166.0033,13.148547,7.043201,0.0,0,2.7354224,0.0,0.63461447,88.699387,2.7337079,336.17697,-9.2845764
5274,5274,166.0055,13.208853,7.0678625,0.0,0,2.7168498,0.0,0.63640052,89.006447,2.7149091,335.70828,-9.2833481
5285,5285,166.0077,13.276311,7.0806537,0.0,0,2.6990449,0.0,0.63938659,89.228546,2.6933014,335.23962,-9.283618
5296,5296,166.0099,13.316273,7.104876,0.0,0,2.6813788,0.0,0.64125317,89.32003,2.6779656,334.77094,-9.2855387
5307,5307,166.0121,13.332335,7.1221666,0.0,0,2.663713,0.0,0.6446563,89.087204,2.6518967,334.30225,-9.2851095
5318,5318,166.0143,13.345382,7.1484976,0.0,0,2.6460469,0.0,0.64645982,89.003922,2.6370833,334.12567,-9.2849646
5329,5329,166.0165,13.37548,7.1565385,0.0,0,2.6283808,0.0,0.64900231,88.964943,2.6213996,333.9783,-9.2836323
5340,5340,166.0187,13.392932,7.1803865,0.0,0,2.6107149,0.0,0.65072817,88.925194,2.601054,333.83096,-9.283515
5351,5351,166.0209,13.432853,7.1950831,0.0,0,2.5930488,0.0,0.65396476,88.874168,2.5836496,333.68359,-9.2843599
5362,5362,166.0231,13.458768,7.2194996,0.0,0,2.5753827,0.0,0.65547818,88.929291,2.569314,333.41183,-9.2851496
5373,5373,166.0253,13.476954,7.2279739,0.0,0,2.5577168,0.0,0.65809077,88.889969,2.5511153,332.92239,-9.2855711
5384,5384,166.0275,13.501369,7.2486119,0.0,0,2.540051,0.0,0.65969813,88.913422,2.5362511,332.43292,-9.2844725
5395,5395,166.0297,13.529811,7.2611775,0.0,0,2.5223849,0.0,0.66251242,88.852501,2.5152364,331.94348,-9.2843237
5406,5406,166.0319,13.556782,7.2858171,0.0,0,2.5047188,0.0,0.66412359,88.834396,2.499934,331.45404,-9.2843647
5417,5417,166.0341,13.613194,7.2935286,0.0,0,2.4870529,0.0,0.66663629,89.000389,2.4842117,330.85489,-9.2863522
5428,5428,166.0363,13.672597,7.315321,0.0,0,2.4693868,0.0,0.66830236,89.181015,2.4683714,330.23132,-9.2855129
5439,5439,166.0385,13.744277,7.326663,0.0,0,2.451721,0.0,0.67103821,89.45752,2.4479198,329.60779,-9.2851419
5450,5450,166.0407,13.802677,7.3549666,0.0,0,2.4340549,0.0,0.67318088,89.608604,2.4313147,328.98425,-9.2845726
5461,5461,166.0429,13.858584,7.363493,0.0,0,2.4163888,0.0,0.67581773,89.748795,2.4143257,328.48322,-9.2843723
5472,5472,166.0451,13.898561,7.3868194,0.0,0,2.3987229,0.0,0.67758173,89.906677,2.3957593,328.3089,-9.2848234
5483,5483,166.0473,13.94287,7.4005013,0.0,0,2.3810568,0.0,0.68064129,89.927284,2.3803949,328.13458,-9.2862701
5494,5494,166.0495,13.982403,7.4284315,0.0,0,2.3633907,0.0,0.68289948,89.951614,2.3582218,327.96027,-9.2844563
5505,5505,166.0517,14.002517,7.4395413,0.0,0,2.3457248,0.0,0.68562198,89.775078,2.3413293,327.78595,-9.284585
5516,5516,166.0539,14.039265,7.4597507,0.0,0,2.3280587,0.0,0.68742996,89.847878,2.3244991,327.43121,-9.2840948
5527,5527,166.0561,14.086155,7.4710622,0.0,0,2.3104959,0.0,0.68994874,89.920967,2.3058155,327.00882,-9.2846985
5538,5538,166.0583,14.13437,7.4996967,0.0,0,2.2936921,0.0,0.69236147,90.051079,2.290005,326.58643,-9.2851906
5549,5549,166.0605,14.165879,7.5067139,0.0,0,2.2768884,0.0,0.69447476,90.007561,2.2708426,326.164,-9.2846985
5560,5560,166.0627,14.216677,7.5291371,0.0,0,2.2600849,0.0,0.69660997,90.178635,2.2548776,325.78915,-9.2842159
5571,5571,166.0649,14.244981,7.5404768,0.0,0,2.2432811,0.0,0.69890529,90.153358,2.237108,325.62823,-9.2840967
5582,5582,166.0671,14.28685,7.5655928,0.0,0,2.2264779,0.0,0.70143443,90.205208,2.2224388,325.46732,-9.2841301
5593,5593,166.0693,14.309352,7.5770726,0.0,0,2.2096741,0.0,0.70378023,90.136299,2.2025132,325.3064,-9.2843685
5604,5604,166.0715,14.361897,7.59935,0.0,0,2.1928706,0.0,0.70612353,90.218513,2.1848147,325.14548,-9.2848816
5615,5615,166.0737,14.42245,7.6111217,0.0,0,2.1760669,0.0,0.70824999,90.440384,2.1659012,325.06992,-9.2843647
5626,5626,166.0759,14.490091,7.637691,0.0,0,2.1592634,0.0,0.71122968,90.574203,2.1501334,325.04309,-9.2843409
5637,5637,166.0781,14.525892,7.6470757,0.0,0,2.1424596,0.0,0.71310258,90.619461,2.1365573,325.01627,-9.2835894
5648,5648,166.0803,14.561498,7.6662321,0.0,0,2.1256561,0.0,0.71531665,90.669739,2.1208401,324.98947,-9.2852488
5659,5659,166.0825,14.588065,7.6797924,0.0,0,2.1088524,0.0,0.71739519,90.625244,2.1023302,324.97971,-9.2846394
5670,5670,166.0847,14.59578,7.7036376,0.0,0,2.0920489,0.0,0.72023237,90.489594,2.0869932,325.14063,-9.2848253
5681,5681,166.0869,14.599854,7.7111893,0.0,0,2.0752454,0.0,0.7218504,90.362213,2.0694098,325.30154,-9.28473
5692,5692,166.0891,14.629919,7.7294979,0.0,0,2.0584419,0.0,0.72420108,90.312927,2.053479,325.46246,-9.2841816
5703,5703,166.0913,14.693607,7.7428417,0.0,0,2.0416381,0.0,0.72610807,90.455528,2.040349,325.62335,-9.2840595
5714,5714,166.0935,14.786127,7.766932,0.0,0,2.0248346,0.0,0.7292071,90.774178,2.0237734,325.68552,-9.28512
5725,5725,166.0957,14.895425,7.7809401,0.0,0,2.0080309,0.0,0.73126918,91.25695,2.0095739,325.66541,-9.2844133
5736,5736,166.0979,14.973287,7.8008142,0.0,0,1.9912274,0.0,0.73411787,91.470161,1.987686,325.64529,-9.2840528
5747,5747,166.1001,15.023183,7.8130293,0.0,0,1.9744238,0.0,0.73571938,91.654312,1.9713534,325.62518,-9.2845011
5758,5758,166.1023,15.048571,7.838871,0.0,0,1.9576201,0.0,0.73943919,91.471901,1.954605,325.60507,-9.2841072
5769,5769,166.1045,15.099463,7.8550043,0.0,0,1.9408166,0.0,0.7414549,91.637077,1.9344463,325.16257,-9.285059
5780,5780,166.1067,15.138361,7.8731837,0.0,0,1.9243339,0.0,0.74437261,91.567932,1.9160864,324.72003,-9.2842674
5791,5791,166.1089,15.16955,7.8868265,0.0,0,1.9083487,0.0,0.74592173,91.610855,1.8958223,324.27753,-9.2847452
5802,5802,166.1111,15.201747,7.9069972,0.0,0,1.8923634,0.0,0.74915254,91.484131,1.8822906,323.83499,-9.286418
5813,5813,166.1133,15.227197,7.9197779,0.0,0,1.8763782,0.0,0.75048339,91.557976,1.8683405,323.38333,-9.2856808
5824,5824,166.1155,15.246895,7.9359446,0.0,0,1.860393,0.0,0.75322753,91.380264,1.8514297,322.92072,-9.2853756
5835,5835,166.1177,15.260667,7.9508576,0.0,0,1.8444078,0.0,0.75481284,91.349625,1.8342342,322.4581,-9.2847357
5846,5846,166.1199,15.296537,7.9701481,0.0,0,1.8284227,0.0,0.75822484,91.269394,1.8188869,321.99545,-9.2845392
5857,5857,166.1221,15.339808,7.9835815,0.0,0,1.8124374,0.0,0.7593227,91.414581,1.8051833,321.53284,-9.2860613
5868,5868,166.1243,15.391424,7.9989586,0.0,0,1.7964523,0.0,0.76224345,91.429176,1.7925998,321.25916,-9.2847166
5879,5879,166.1265,15.433355,8.0155468,0.0,0,1.780467,0.0,0.76395369,91.492958,1.7697853,321.00439,-9.2857237
5890,5890,166.1287,15.509514,8.0345383,0.0,0,1.7644818,0.0,0.76751322,91.648453,1.7582477,320.7496,-9.2839556
5901,5901,166.1309,15.597083,8.0513287,0.0,0,1.7484967,0.0,0.768902,92.015923,1.7410901,320.49484,-9.2839842
5912,5912,166.1331,15.686307,8.0641508,0.0,0,1.7325114,0.0,0.77181327,92.257851,1.7259659,320.35953,-9.2837067
5923,5923,166.1353,15.727606,8.0832548,0.0,0,1.7165262,0.0,0.77358872,92.351448,1.7060329,320.43329,-9.2842131
5934,5934,166.1375,15.742333,8.1004782,0.0,0,1.700541,0.0,0.77707273,92.152473,1.6942965,320.50702,-9.2859907
5945,5945,166.1397,15.785921,8.117568,0.0,0,1.6845558,0.0,0.77842623,92.232239,1.679364,320.58078,-9.2843008
5956,5956,166.1419,15.819961,8.1291609,0.0,0,1.6685706,0.0,0.78139907,92.222206,1.6577433,320.65454,-9.2835159
5967,5967,166.1441,15.853518,8.1458435,0.0,0,1.6525854,0.0,0.78255683,92.307709,1.642833,320.66245,-9.2840977
5978,5978,166.1463,15.883104,8.1599731,0.0,0,1.6366003,0.0,0.78605008,92.13205,1.628499,320.65573,-9.284399
5989,5989,166.1485,15.918827,8.1815844,0.0,0,1.620615,0.0,0.78750044,92.213593,1.6131539,320.64905,-9.2839308
6000,6000,166.1507,15.96744,8.1909275,0.0,0,1.6046298,0.0,0.79059178,92.187027,1.5977031,320.64233,-9.2848434
6011,6011,166.1529,16.035637,8.209547,0.0,0,1.5886445,0.0,0.79177564,92.455048,1.5834557,320.63379,-9.2830219
6022,6022,166.1551,16.073307,8.2223177,0.0,0,1.5726594,0.0,0.79521394,92.411423,1.5661713,320.62039,-9.2835197
6033,6033,166.1573,16.07822,8.2415524,0.0,0,1.5571918,0.0,0.79629201,92.353622,1.5535442,320.60696,-9.2847881
6044,6044,166.1595,16.109102,8.248951,0.0,0,1.5419855,0.0,0.79921335,92.214722,1.5386628,320.59357,-9.285408
6055,6055,166.1617,16.193666,8.2705517,0.0,0,1.5267792,0.0,0.80080885,92.516434,1.5217813,320.58017,-9.2843447
6066,6066,166.1639,16.270079,8.2841787,0.0,0,1.5115727,0.0,0.80423129,92.711708,1.5063767,320.54236,-9.2845812
6077,6077,166.1661,16.349096,8.3062048,0.0,0,1.4963663,0.0,0.80588377,92.96138,1.4882491,320.49542,-9.283309
6088,6088,166.1683,16.415417,8.3136339,0.0,0,1.4811599,0.0,0.8087858,93.097893,1.4753828,320.44849,-9.2825413
6099,6099,166.1705,16.486315,8.3339481,0.0,0,1.4659536,0.0,0.81012136,93.358681,1.46078,320.40155,-9.2833929
6110,6110,166.1727,16.54495,8.3458586,0.0,0,1.4507471,0.0,0.81366724,93.390709,1.4433136,320.34,-9.2847261
6121,6121,166.1749,16.565886,8.3680468,0.0,0,1.4355407,0.0,0.81506497,93.354515,1.4268976,320.21259,-9.2846689
6132,6132,166.1771,16.575562,8.3765106,0.0,0,1.4203343,0.0,0.81836879,93.145172,1.4131666,320.08517,-9.2834082
6143,6143,166.1793,16.609728,8.3996925,0.0,0,1.4051279,0.0,0.82026094,93.117477,1.3939732,319.95776,-9.2822733
6154,6154,166.1815,16.651001,8.411026,0.0,0,1.3899214,0.0,0.82348675,93.086708,1.3839194,319.83035,-9.2835655
6165,6165,166.1837,16.704786,8.4338646,0.0,0,1.3747151,0.0,0.82486796,93.231865,1.3682671,319.81815,-9.2834129
6176,6176,166.1859,16.794472,8.4393578,0.0,0,1.3595088,0.0,0.8277995,93.458138,1.3512771,319.8718,-9.2837124
6187,6187,166.1881,16.88245,8.4606695,0.0,0,1.3443023,0.0,0.82949537,93.737038,1.3350434,319.92545,-9.284277
6198,6198,166.1903,16.927376,8.4714727,0.0,0,1.3290958,0.0,0.83274174,93.731514,1.315609,319.97906,-9.2848272
6209,6209,166.1925,16.972937,8.4964113,0.0,0,1.3138895,0.0,0.83467776,93.805649,1.3068122,320.02783,-9.2846584
6220,6220,166.1947,16.993933,8.5008879,0.0,0,1.2986832,0.0,0.83708608,93.662941,1.2893922,320.02783,-9.284524
6231,6231,166.1969,17.013832,8.5210209,0.0,0,1.2834768,0.0,0.83869928,93.628899,1.2724124,320.02783,-9.2836685
6242,6242,166.1991,17.047228,8.5302382,0.0,0,1.2682704,0.0,0.84172505,93.56665,1.2563641,320.02783,-9.2841692
6253,6253,166.2013,17.109171,8.5547199,0.0,0,1.2530639,0.0,0.84375036,93.668091,1.2432926,320.02783,-9.2835732
6264,6264,166.2035,17.17391,8.5586147,0.0,0,1.2378575,0.0,0.84599876,93.780327,1.2284113,319.9473,-9.2837105
6275,6275,166.2057,17.237886,8.5811205,0.0,0,1.2226511,0.0,0.84805417,93.987259,1.2151891,319.79965,-9.2834444
6286,6286,166.2079,17.299747,8.5919161,0.0,0,1.2081418,0.0,0.85121638,94.01474,1.1990389,319.65204,-9.2832165
6297,6297,166.2101,17.336273,8.6152525,0.0,0,1.193679,0.0,0.85337698,94.020699,1.1834806,319.50439,-9.2833776
6308,6308,166.2123,17.350233,8.6210527,0.0,0,1.1792163,0.0,0.85552049,93.897285,1.1666188,319.35675,-9.2833748
6319,6319,166.2145,17.353991,8.6398602,0.0,0,1.1647533,0.0,0.85744458,93.734665,1.1527557,319.30966,-9.2834778
6330,6330,166.2167,17.376776,8.6462173,0.0,0,1.1502906,0.0,0.85956711,93.689095,1.1419297,319.26254,-9.2840776
6341,6341,166.2189,17.445913,8.6702461,0.0,0,1.1358278,0.0,0.86211222,93.787285,1.1264958,319.21545,-9.2848749
6352,6352,166.2211,17.532257,8.6775494,0.0,0,1.121365,0.0,0.86447674,94.021729,1.1097345,319.16837,-9.2840147
6363,6363,166.2233,17.598553,8.6962061,0.0,0,1.1069021,0.0,0.86641103,94.194115,1.0983609,319.05484,-9.2834015
6374,6374,166.2255,17.662233,8.7048016,0.0,0,1.0924393,0.0,0.86866772,94.347305,1.0859401,318.8616,-9.283411
6385,6385,166.2277,17.71575,8.7270603,0.0,0,1.0779766,0.0,0.87118363,94.395721,1.0722184,318.66837,-9.2839355
6396,6396,166.2299,17.744976,8.7327785,0.0,0,1.0635136,0.0,0.87308866,94.395599,1.0537902,318.47513,-9.284277
6407,6407,166.2321,17.771088,8.7514906,0.0,0,1.0490509,0.0,0.87528247,94.308159,1.0436614,318.30234,-9.2851124
6418,6418,166.2343,17.784943,8.7599411,0.0,0,1.0345882,0.0,0.87720239,94.193604,1.0289567,318.22162,-9.2832851
6429,6429,166.2365,17.818329,8.7843161,0.0,0,1.0201254,0.0,0.8805263,94.032578,1.0124756,318.14087,-9.2830162
6440,6440,166.2387,17.889851,8.7917519,0.0,0,1.0056624,0.0,0.88248014,94.217026,1.0013703,318.06015,-9.282733
6451,6451,166.2409,17.976402,8.8080215,0.0,0,0.99119979,0.0,0.88445163,94.479462,0.98460233,317.9794,-9.2827606
6462,6462,166.2431,18.050308,8.8157921,0.0,0,0.97673696,0.0,0.88621771,94.706245,0.97228664,317.96289,-9.283123
6473,6473,166.2453,18.109833,8.841465,0.0,0,0.96227413,0.0,0.88995111,94.687157,0.95521623,317.98306,-9.2834578
6484,6484,166.2475,18.172722,8.8507471,0.0,0,0.94781131,0.0,0.89174265,94.885986,0.94336367,318.00323,-9.2841835
6495,6495,166.2497,18.224705,8.8662128,0.0,0,0.93334854,0.0,0.89422023,94.880135,0.92757374,318.02344,-9.2847528
6506,6506,166.2519,18.258797,8.8737364,0.0,0,0.91888577,0.0,0.89550406,94.97361,0.91498852,318.02954,-9.2847471
6517,6517,166.2541,18.309053,8.8982277,0.0,0,0.90442294,0.0,0.89934218,94.846382,0.90164977,317.89499,-9.2835312
6528,6528,166.2563,18.349743,8.9075556,0.0,0,0.89010906,0.0,0.90095389,94.876251,0.88312989,317.76044,-9.2829847
6539,6539,166.2585,18.449516,8.922657,0.0,0,0.87635463,0.0,0.90349501,95.143997,0.86972249,317.62589,-9.2827721
6550,6550,166.2607,18.536371,8.9347839,0.0,0,0.86260027,0.0,0.90530908,95.471466,0.85686326,317.49133,-9.2832184
6561,6561,166.2629,18.583914,8.9567347,0.0,0,0.84884584,0.0,0.90928018,95.327301,0.8421405,317.34946,-9.2839212
6572,6572,166.2651,18.637207,8.9674835,0.0,0,0.83509147,0.0,0.91052949,95.449684,0.82508332,317.20142,-9.2827282
6583,6583,166.2673,18.674496,8.9817724,0.0,0,0.82133704,0.0,0.91350567,95.385742,0.81004041,317.05341,-9.2833843
6594,6594,166.2695,18.668238,8.9934835,0.0,0,0.80758262,0.0,0.91489738,95.226593,0.79789627,316.9054,-9.2843027
6605,6605,166.2717,18.684605,9.0099745,0.0,0,0.79382825,0.0,0.91832185,94.971733,0.78612608,316.75739,-9.2832603
6616,6616,166.2739,18.739021,9.023881,0.0,0,0.78007382,0.0,0.91963482,95.062683,0.76950848,316.48828,-9.2840023
6627,6627,166.2761,18.79707,9.0355873,0.0,0,0.76631945,0.0,0.92258382,95.099174,0.75847775,316.21918,-9.2842884
6638,6638,166.2783,18.878553,9.0503731,0.0,0,0.75256503,0.0,0.92421943,95.384758,0.74421918,315.95007,-9.2838507
6649,6649,166.2805,18.933907,9.0667257,0.0,0,0.73881066,0.0,0.92799741,95.307274,0.72964972,315.68097,-9.2828283
6660,6660,166.2827,18.99651,9.0785608,0.0,0,0.72505623,0.0,0.92883581,95.539078,0.7137599,315.44855,-9.2835083
6671,6671,166.2849,19.021263,9.0873594,0.0,0,0.7113018,0.0,0.93155527,95.39537,0.69977403,315.26016,-9.2830067
6682,6682,166.2871,19.068661,9.101757,0.0,0,0.69754744,0.0,0.93280697,95.542671,0.69011277,315.07181,-9.2828255
6693,6693,166.2893,19.105532,9.117425,0.0,0,0.68379307,0.0,0.93683434,95.301849,0.67243272,314.88342,-9.2823515
6704,6704,166.2915,19.151566,9.1348715,0.0,0,0.67003864,0.0,0.93809432,95.44754,0.66169703,314.69504,-9.2822142
6715,6715,166.2937,19.232082,9.1460896,0.0,0,0.65628421,0.0,0.94159943,95.496696,0.64905787,314.65344,-9.2845154
6726,6726,166.2959,19.327124,9.1589584,0.0,0,0.64252985,0.0,0.94226152,95.879433,0.6372866,314.62656,-9.2828627
6737,6737,166.2981,19.399075,9.1710243,0.0,0,0.62877542,0.0,0.94614398,95.933823,0.62090796,314.59964,-9.2832632
6748,6748,166.3003,19.486399,9.1894426,0.0,0,0.61502105,0.0,0.94734335,96.210869,0.60194027,314.57272,-9.2827663
6759,6759,166.3025,19.535149,9.1991873,0.0,0,0.60126662,0.0,0.95086735,96.137917,0.59030777,314.56293,-9.283843
6770,6770,166.3047,19.57786,9.217411,0.0,0,0.58751225,0.0,0.95231646,96.192139,0.57826525,314.58313,-9.2845259
6781,6781,166.3069,19.601034,9.2288666,0.0,0,0.57407868,0.0,0.95606011,95.938805,0.56349766,314.6033,-9.2845974
6792,6792,166.3091,19.606396,9.2454414,0.0,0,0.56098866,0.0,0.95685035,95.918129,0.55194461,314.62347,-9.2834692
6803,6803,166.3113,19.642044,9.2512512,0.0,0,0.54789871,0.0,0.95994306,95.760529,0.53801495,314.64368,-9.2829676
6814,6814,166.3135,19.689577,9.269392,0.0,0,0.53480875,0.0,0.96126074,95.833984,0.52473557,314.80145,-9.2830019
6816,6816,166.3139,19.734648,9.2734919,0.0,0,0.53242874,0.0,0.96328413,95.876831,0.52346641,314.83572,-9.2838898