File: clean data/testID_0108.csv
level_0,index,Time(sec),Force(kN),Jaw(mm),PowAngle(deg),Power(W),Pram,PTemp,Strain,Stress(MPa),Stroke(mm),TC1(C),wedge(mm)
2573,2573,212.0395,1.5032609,0.024933085,0.0,0,9.9878626,0.0,0.001658633,18.875874,10.091065,503.27466,-9.2072754
2584,2584,212.0417,2.8827794,0.034557782,0.0,0,9.9548635,0.0,0.002359292,36.339233,10.062728,503.30219,-9.206768
2595,2595,212.0439,3.5929933,0.053752482,0.0,0,9.9218636,0.0,0.0035574697,45.553799,10.032225,503.37454,-9.2058048
2606,2606,212.0461,3.7698679,0.095269941,0.0,0,9.8888636,0.0,0.0064289914,47.732098,9.9927683,503.4469,-9.2058115
2617,2617,212.0483,3.8679388,0.13341179,0.0,0,9.8558636,0.0,0.0087621072,48.784386,9.9523945,503.51926,-9.2047062
2628,2628,212.0505,3.9536548,0.16739613,0.0,0,9.8228636,0.0,0.011189918,49.795773,9.9125586,503.59164,-9.204834
2639,2639,212.0527,4.0023174,0.20448573,0.0,0,9.7898636,0.0,0.013587153,50.130154,9.875227,503.72058,-9.2045383
2650,2650,212.0549,4.0389032,0.23898533,0.0,0,9.7568636,0.0,0.016266443,50.545406,9.8393469,503.86533,-9.2057476
2661,2661,212.0571,4.0506039,0.27489668,0.0,0,9.7238636,0.0,0.018238684,50.786827,9.8072453,504.01007,-9.2051897
2672,2672,212.0593,4.0732226,0.30211997,0.0,0,9.6908636,0.0,0.020494057,50.707001,9.7709198,504.15479,-9.2054634
2683,2683,212.0615,4.0793762,0.33544281,0.0,0,9.6578636,0.0,0.022432443,50.744366,9.7375393,504.28015,-9.2048931
2694,2694,212.0637,4.0800352,0.36393458,0.0,0,9.6248636,0.0,0.024751548,50.685818,9.7065716,504.34595,-9.2060623
2705,2705,212.0659,4.0784612,0.3999849,0.0,0,9.5918636,0.0,0.026720641,50.58971,9.6798143,504.41174,-9.2059298
2716,2716,212.0681,4.1029181,0.42672262,0.0,0,9.5588636,0.0,0.029037606,50.673405,9.6434002,504.47751,-9.2055397
2727,2727,212.0703,4.1340809,0.46041912,0.0,0,9.5258636,0.0,0.030984908,51.096905,9.6093779,504.5433,-9.2068129
2738,2738,212.0725,4.176692,0.49239913,0.0,0,9.4928637,0.0,0.033594668,51.377426,9.5743437,504.55777,-9.2059202
2749,2749,212.0747,4.2138538,0.53419393,0.0,0,9.4604025,0.0,0.035918243,51.710175,9.5398197,504.55121,-9.206707
2760,2760,212.0769,4.2244811,0.56159407,0.0,0,9.4282112,0.0,0.038304687,51.812866,9.501687,504.54465,-9.2058039
2771,2771,212.0791,4.2336192,0.5991897,0.0,0,9.3960209,0.0,0.04059545,51.654308,9.474535,504.53806,-9.2058764
2782,2782,212.0813,4.2326074,0.63036746,0.0,0,9.3638315,0.0,0.043015048,51.683826,9.4347944,504.5383,-9.2058144
2793,2793,212.0835,4.2218361,0.6683597,0.0,0,9.3316412,0.0,0.045310296,51.445145,9.4042892,504.57117,-9.2063961
2804,2804,212.0857,4.1835408,0.69272,0.0,0,9.2994499,0.0,0.047310296,50.862846,9.3695889,504.60406,-9.2057543
2815,2815,212.0879,4.1838651,0.72578591,0.0,0,9.2672586,0.0,0.049488205,50.691505,9.3390646,504.63693,-9.2066708
2826,2826,212.0901,4.2037053,0.75310957,0.0,0,9.2350683,0.0,0.051533863,50.787994,9.3134499,504.6698,-9.2072086
2837,2837,212.0923,4.2485738,0.78834581,0.0,0,9.202879,0.0,0.053880125,51.056602,9.2796841,504.71524,-9.2063284
2848,2848,212.0945,4.2937517,0.81522906,0.0,0,9.1706886,0.0,0.055831451,51.615074,9.2465611,504.76785,-9.207345
2859,2859,212.0967,4.3081436,0.84910566,0.0,0,9.1384983,0.0,0.058280721,51.755135,9.2142582,504.82047,-9.2060165
2870,2870,212.0989,4.3279891,0.8807168,0.0,0,9.106307,0.0,0.060445357,51.917126,9.1795502,504.87308,-9.2061176
2881,2881,212.1011,4.3434587,0.9199326,0.0,0,9.0741167,0.0,0.06328959,51.965702,9.144434,504.92239,-9.2064495
2892,2892,212.1033,4.333569,0.95192772,0.0,0,9.0419264,0.0,0.065425396,51.875271,9.107687,504.94211,-9.2073069
2903,2903,212.1055,4.3204293,0.98188156,0.0,0,9.009737,0.0,0.06774471,51.432098,9.0771074,504.96182,-9.2072134
2914,2914,212.1077,4.290225,1.0112643,0.0,0,8.9775457,0.0,0.069663063,50.868664,9.0422535,504.98157,-9.2057714
2925,2925,212.1099,4.2966218,1.0448542,0.0,0,8.9453554,0.0,0.072338209,50.932796,9.0128679,505.00128,-9.2062168
2936,2936,212.1121,4.3297272,1.0755072,0.0,0,8.9131651,0.0,0.07417509,51.055897,8.9874496,505.00247,-9.2051287
2947,2947,212.1143,4.370913,1.1006439,0.0,0,8.8809748,0.0,0.076309755,51.513851,8.9492235,504.98932,-9.2054367
2958,2958,212.1165,4.3961225,1.132678,0.0,0,8.8487844,0.0,0.078315496,51.823261,8.9214964,504.97617,-9.2061586
2969,2969,212.1187,4.4079442,1.1647326,0.0,0,8.8165941,0.0,0.08104264,51.760712,8.8866444,504.96301,-9.2050104
2980,2980,212.1209,4.4347615,1.2026649,0.0,0,8.7844028,0.0,0.083272971,51.968781,8.855916,504.95273,-9.2064857
2991,2991,212.1231,4.4656968,1.2315528,0.0,0,8.7522125,0.0,0.085868657,52.198582,8.8194132,505.0448,-9.2068768
3002,3002,212.1253,4.4302826,1.2674845,0.0,0,8.7214985,0.0,0.088065319,51.657925,8.7822809,505.13687,-9.205843
3013,3013,212.1275,4.437211,1.2968345,0.0,0,8.6908836,0.0,0.090663701,51.583752,8.7517967,505.22894,-9.206255
3024,3024,212.1297,4.4488926,1.3345574,0.0,0,8.6602697,0.0,0.092812397,51.613991,8.7209921,505.32098,-9.2055798
3035,3035,212.1319,4.4675708,1.3583572,0.0,0,8.629653,0.0,0.095042482,51.71225,8.6870975,505.4324,-9.2054434
3046,3046,212.1341,4.4654837,1.3918368,0.0,0,8.5990381,0.0,0.097200103,51.567589,8.6589174,505.56393,-9.2058239
3057,3057,212.1363,4.4702764,1.418348,0.0,0,8.5684223,0.0,0.099544734,51.518101,8.6250715,505.69543,-9.204648
3068,3068,212.1385,4.4691758,1.4561393,0.0,0,8.5378084,0.0,0.10184298,51.385845,8.5945234,505.82693,-9.2053728
3079,3079,212.1407,4.4664259,1.4791775,0.0,0,8.5071926,0.0,0.10388489,51.244591,8.567647,505.95844,-9.2049503
3090,3090,212.1429,4.4555774,1.50761,0.0,0,8.4765778,0.0,0.10584276,51.043217,8.5373096,506.01465,-9.2053232
3101,3101,212.1451,4.4627247,1.5338188,0.0,0,8.445962,0.0,0.1079013,51.128563,8.508688,506.06723,-9.207181
3112,3112,212.1473,4.5024085,1.5706751,0.0,0,8.4153471,0.0,0.11051609,51.257572,8.4804335,506.11984,-9.2068701
3123,3123,212.1495,4.5613341,1.5968457,0.0,0,8.3847322,0.0,0.11254221,51.903683,8.4475899,506.17245,-9.2044153
3134,3134,212.1517,4.6017346,1.629837,0.0,0,8.3541164,0.0,0.11500955,52.233974,8.4120789,506.21957,-9.2048044
3145,3145,212.1539,4.6048784,1.6597706,0.0,0,8.3235025,0.0,0.11722918,52.125706,8.3828154,506.259,-9.2062817
3156,3156,212.1561,4.6098781,1.6975584,0.0,0,8.2928858,0.0,0.12012222,52.099239,8.3541317,506.29846,-9.2052908
3167,3167,212.1583,4.6047626,1.7266216,0.0,0,8.2622709,0.0,0.12209813,51.985558,8.317831,506.33792,-9.2053223
3178,3178,212.1605,4.6279063,1.7560521,0.0,0,8.2316561,0.0,0.12457525,51.975208,8.2826166,506.37735,-9.2055855
3189,3189,212.1627,4.6409292,1.7900442,0.0,0,8.2010412,0.0,0.12689696,51.982212,8.2550507,506.4458,-9.2058954
3200,3200,212.1649,4.6404538,1.8250866,0.0,0,8.1704264,0.0,0.12985727,51.898533,8.2206669,506.51813,-9.2058048
3211,3211,212.1671,4.6413679,1.8575243,0.0,0,8.1398106,0.0,0.13184197,51.668224,8.1903763,506.59045,-9.2066154
3222,3222,212.1693,4.6639786,1.8831799,0.0,0,8.1091957,0.0,0.13430555,51.861271,8.1592789,506.66281,-9.2056093
3233,3233,212.1715,4.6644626,1.9137313,0.0,0,8.0785799,0.0,0.13626529,51.829437,8.1275654,506.74875,-9.2061157
3244,3244,212.1737,4.6639357,1.9433352,0.0,0,8.0482779,0.0,0.1389723,51.658272,8.0954018,506.86053,-9.2048998
3255,3255,212.1759,4.6614428,1.9774524,0.0,0,8.0191498,0.0,0.14091207,51.554676,8.0666838,506.97232,-9.2050219
3266,3266,212.1781,4.6723118,2.0029104,0.0,0,7.9900212,0.0,0.14358468,51.571865,8.0353699,507.08411,-9.2051868
3277,3277,212.1803,4.6827054,2.033416,0.0,0,7.9608936,0.0,0.14541337,51.614006,8.0097008,507.19589,-9.2064428
3288,3288,212.1825,4.6910734,2.0607057,0.0,0,7.9317656,0.0,0.14802592,51.471855,7.9767933,507.26511,-9.2057714
3299,3299,212.1847,4.6984825,2.0973315,0.0,0,7.9026375,0.0,0.15016596,51.495686,7.9417281,507.32431,-9.2058611
3310,3310,212.1869,4.7075701,2.1196465,0.0,0,7.8735094,0.0,0.15258944,51.513313,7.9143519,507.38348,-9.2052794
3321,3321,212.1891,4.713232,2.1492386,0.0,0,7.8443813,0.0,0.1544416,51.425278,7.8856001,507.44269,-9.2050819
3332,3332,212.1913,4.7109604,2.1735721,0.0,0,7.8152533,0.0,0.15685992,51.341206,7.8592911,507.48929,-9.206624
3343,3343,212.1935,4.7178712,2.2081015,0.0,0,7.7861252,0.0,0.15891176,51.198627,7.8294926,507.50244,-9.206171
3354,3354,212.1957,4.7285609,2.2309711,0.0,0,7.7569971,0.0,0.16114099,51.277531,7.8020201,507.51559,-9.2056923
3365,3365,212.1979,4.739058,2.2606304,0.0,0,7.7278695,0.0,0.16318309,51.198036,7.7742782,507.52875,-9.2058668
3376,3376,212.2001,4.7420149,2.286366,0.0,0,7.6987414,0.0,0.16544674,51.161438,7.7434239,507.54187,-9.2049961
3387,3387,212.2023,4.7470241,2.3201973,0.0,0,7.6696134,0.0,0.16786036,51.082458,7.7149186,507.58408,-9.2062197
3398,3398,212.2045,4.7792697,2.3437436,0.0,0,7.6404853,0.0,0.16998696,51.344334,7.6863222,507.63669,-9.2057018
3409,3409,212.2067,4.8057265,2.3754392,0.0,0,7.6113577,0.0,0.17233178,51.489311,7.6566086,507.6893,-9.2051926
3420,3420,212.2089,4.8508844,2.4025426,0.0,0,7.5822296,0.0,0.17448786,51.844437,7.6275063,507.74191,-9.2063036
3431,3431,212.2111,4.8480315,2.4363198,0.0,0,7.5531015,0.0,0.17722856,51.799496,7.5986729,507.78793,-9.2071466
3442,3442,212.2133,4.8524771,2.4626935,0.0,0,7.523973,0.0,0.1792181,51.692776,7.56988,507.80768,-9.2065125
3453,3453,212.2155,4.8532047,2.4916501,0.0,0,7.4948454,0.0,0.18175562,51.594299,7.5375643,507.82739,-9.2061996
3464,3464,212.2177,4.8592029,2.5209332,0.0,0,7.4657173,0.0,0.18380731,51.510761,7.506608,507.84711,-9.2066336
3475,3475,212.2199,4.8776174,2.5515349,0.0,0,7.4365897,0.0,0.18661122,51.402039,7.4767065,507.86685,-9.2067261
3486,3486,212.2221,4.8757873,2.5823586,0.0,0,7.4074612,0.0,0.18870725,51.374111,7.4471908,507.90839,-9.2068014
3497,3497,212.2243,4.8816123,2.6060681,0.0,0,7.3790221,0.0,0.19095655,51.253895,7.4202833,507.961,-9.2059469
3508,3508,212.2265,4.9107728,2.6337297,0.0,0,7.3513193,0.0,0.19282231,51.452324,7.3890195,508.01361,-9.2064857
3519,3519,212.2287,4.9349942,2.664423,0.0,0,7.323617,0.0,0.19585453,51.574142,7.3645196,508.06622,-9.206933
3530,3530,212.2309,4.9330134,2.6956446,0.0,0,7.2959146,0.0,0.19777942,51.56789,7.3288779,508.12466,-9.2048435
3541,3541,212.2331,4.9164052,2.7200754,0.0,0,7.2682123,0.0,0.20033066,51.215717,7.303328,508.2233,-9.2049532
3552,3552,212.2353,4.9008203,2.748836,0.0,0,7.24051,0.0,0.20217204,50.969868,7.2742262,508.32196,-9.2054052
3563,3563,212.2375,4.9075532,2.7728293,0.0,0,7.2128077,0.0,0.20475046,50.93314,7.2504101,508.42059,-9.2049532
3574,3574,212.2397,4.9241896,2.8076437,0.0,0,7.1851048,0.0,0.20679644,50.910732,7.218688,508.51923,-9.2056932
3585,3585,212.2419,4.9377427,2.827559,0.0,0,7.157403,0.0,0.2091293,50.987278,7.1945238,508.31479,-9.2058525
3596,3596,212.2441,4.9826827,2.8578875,0.0,0,7.1297007,0.0,0.21113674,51.426929,7.1701088,507.90051,-9.205801
3607,3607,212.2463,5.0047784,2.8812118,0.0,0,7.1019974,0.0,0.21357487,51.46365,7.1408067,507.48624,-9.2043753
3618,3618,212.2485,5.0337315,2.9158053,0.0,0,7.0742955,0.0,0.21573789,51.609287,7.1070485,507.07199,-9.2041969
3629,3629,212.2507,5.0241327,2.9379487,0.0,0,7.0465932,0.0,0.21816894,51.415092,7.0832911,506.65771,-9.2055874
3640,3640,212.2529,5.0233779,2.9705389,0.0,0,7.0188909,0.0,0.22040778,51.354755,7.0543132,506.24347,-9.2058096
3651,3651,212.2551,5.0229335,2.9957664,0.0,0,6.991188,0.0,0.22301416,51.137486,7.028326,505.82919,-9.2058144
3662,3662,212.2573,5.0362768,3.0318489,0.0,0,6.9634857,0.0,0.22553343,51.181499,6.9973822,505.41495,-9.2049952
3673,3673,212.2595,5.0577741,3.0510066,0.0,0,6.9357834,0.0,0.22745544,51.325176,6.9669075,505.00067,-9.2062206
3684,3684,212.2617,5.0719562,3.0804722,0.0,0,6.9080811,0.0,0.22981112,51.263035,6.9414883,504.73633,-9.2055826
3695,3695,212.2639,5.0757565,3.1059513,0.0,0,6.8803787,0.0,0.2319767,51.218761,6.911284,504.61133,-9.2061958
3706,3706,212.2661,5.1010761,3.1376054,0.0,0,6.8526764,0.0,0.23458828,51.349396,6.8851876,504.48633,-9.2058315
3717,3717,212.2683,5.0970926,3.1615906,0.0,0,6.8249741,0.0,0.23667559,51.184715,6.8580265,504.36133,-9.2070589
3728,3728,212.2705,5.0959959,3.190099,0.0,0,6.7972713,0.0,0.23915699,51.099537,6.8318129,504.23633,-9.2059755
3739,3739,212.2727,5.0975094,3.2148852,0.0,0,6.7695689,0.0,0.24106792,50.9888,6.8045688,503.35559,-9.2058964
3750,3750,212.2749,5.1248827,3.2451284,0.0,0,6.7428842,0.0,0.24391171,51.02177,6.7752819,502.46085,-9.2045984
3761,3761,212.2771,5.1291394,3.2727911,0.0,0,6.7165279,0.0,0.24598132,51.140835,6.7447238,501.56613,-9.2048912
3772,3772,212.2793,5.1392884,3.2976351,0.0,0,6.6901722,0.0,0.24830973,51.050892,6.7187839,500.67139,-9.2046919
3783,3783,212.2815,5.1430111,3.3235111,0.0,0,6.663816,0.0,0.25019041,50.964241,6.6919532,499.83234,-9.2057543
3794,3794,212.2837,5.160727,3.3499608,0.0,0,6.6374598,0.0,0.25296804,51.052711,6.6642685,499.06259,-9.2064934
3805,3805,212.2859,5.1945562,3.3807588,0.0,0,6.611104,0.0,0.25492817,51.310875,6.6375914,498.29285,-9.2056675
3816,3816,212.2881,5.1927409,3.4016607,0.0,0,6.5847478,0.0,0.25752291,51.141491,6.6092997,497.5231,-9.2053089
3827,3827,212.2903,5.1881056,3.4311917,0.0,0,6.558392,0.0,0.259368,50.949825,6.5847502,496.75336,-9.2054148
3838,3838,212.2925,5.1649833,3.4551449,0.0,0,6.5320363,0.0,0.26213405,50.534809,6.5542383,496.80301,-9.2069578
3849,3849,212.2947,5.1796455,3.4861987,0.0,0,6.5056801,0.0,0.26402548,50.660789,6.5304127,496.93457,-9.2051105
3860,3860,212.2969,5.2162004,3.5041473,0.0,0,6.4793239,0.0,0.2664367,50.869564,6.5051475,497.06616,-9.2041025
3871,3871,212.2991,5.2277107,3.5340297,0.0,0,6.4529681,0.0,0.26835021,50.82608,6.4769726,497.19772,-9.2048779
3882,3882,212.3013,5.2360401,3.5566645,0.0,0,6.4266124,0.0,0.2708959,50.880829,6.4536338,497.37592,-9.2057133
3893,3893,212.3035,5.2788739,3.5928481,0.0,0,6.4002562,0.0,0.27326429,51.139969,6.4310389,497.63251,-9.205246
3904,3904,212.3057,5.2774081,3.6100688,0.0,0,6.3738999,0.0,0.27549961,51.056515,6.4000368,497.8891,-9.2046652
3915,3915,212.3079,5.2980852,3.6390316,0.0,0,6.3475442,0.0,0.27765176,51.087097,6.3735209,498.14566,-9.2050629
3926,3926,212.3101,5.2822943,3.6619663,0.0,0,6.3211884,0.0,0.28010759,50.879631,6.3470502,498.40225,-9.2063913
3937,3937,212.3123,5.2810736,3.6979842,0.0,0,6.2948327,0.0,0.28277054,50.639301,6.3189993,498.62033,-9.2065582
3948,3948,212.3145,5.2939939,3.7170584,0.0,0,6.2684765,0.0,0.28483671,50.627575,6.2914305,498.83087,-9.2066565
3959,3959,212.3167,5.3164625,3.743742,0.0,0,6.2421203,0.0,0.28694841,50.856323,6.268281,499.04138,-9.2074022
3970,3970,212.3189,5.3489532,3.7680855,0.0,0,6.2157645,0.0,0.28933564,50.988613,6.2376928,499.25192,-9.2064972
3981,3981,212.3211,5.3639417,3.8034067,0.0,0,6.1894083,0.0,0.29226375,51.034317,6.21384,499.48416,-9.2035475
3992,3992,212.3233,5.3581791,3.8227608,0.0,0,6.1631007,0.0,0.29414845,50.817955,6.1845503,499.76706,-9.2043428
4003,4003,212.3255,5.3452749,3.8460402,0.0,0,6.1380219,0.0,0.29628658,50.623005,6.1620154,500.04996,-9.2047081
4014,4014,212.3277,5.369729,3.8703079,0.0,0,6.1129556,0.0,0.29839987,50.738106,6.1364431,500.33286,-9.2060862
4025,4025,212.3299,5.3643785,3.9018161,0.0,0,6.0878887,0.0,0.30143493,50.573364,6.1080089,500.61575,-9.2057705
4036,4036,212.3321,5.3643274,3.9254947,0.0,0,6.0628219,0.0,0.30313456,50.418751,6.0859666,500.758,-9.2052069
4047,4047,212.3343,5.3959455,3.9501011,0.0,0,6.037755,0.0,0.30580592,50.585468,6.0563831,500.85666,-9.2051916
4058,4058,212.3365,5.4080625,3.9759789,0.0,0,6.0126886,0.0,0.30776334,50.572502,6.0349588,500.95535,-9.2058935
4069,4069,212.3387,5.4117966,4.0011158,0.0,0,5.9876213,0.0,0.31048983,50.54327,6.0092244,501.05405,-9.2064829
4080,4080,212.3409,5.4200873,4.0267973,0.0,0,5.9625545,0.0,0.31214145,50.550598,5.9810266,501.14825,-9.2061653
4091,4091,212.3431,5.4419131,4.0490232,0.0,0,5.9374876,0.0,0.31488153,50.644901,5.9592729,501.2272,-9.2065048
4102,4102,212.3453,5.4438701,4.077795,0.0,0,5.9124212,0.0,0.31688467,50.461624,5.9320636,501.30615,-9.2068768
4113,4113,212.3475,5.4446149,4.0983663,0.0,0,5.8873544,0.0,0.3195495,50.388412,5.9086647,501.3851,-9.2049503
4124,4124,212.3497,5.4391665,4.1275735,0.0,0,5.8622875,0.0,0.32129079,50.240704,5.8846202,501.46402,-9.2057104
4135,4135,212.3519,5.4508371,4.1456966,0.0,0,5.8372207,0.0,0.32383266,50.165905,5.8590012,501.72934,-9.2049437
4146,4146,212.3541,5.4710183,4.1751199,0.0,0,5.8121538,0.0,0.3258456,50.240883,5.8312898,502.07803,-9.204812
4157,4157,212.3563,5.5068364,4.1961598,0.0,0,5.787087,0.0,0.32848066,50.477188,5.8075542,502.42673,-9.2056656
4168,4168,212.3585,5.5271702,4.2283888,0.0,0,5.7620201,0.0,0.33059996,50.609409,5.7846017,502.77542,-9.2056837
4179,4179,212.3607,5.5291071,4.2470775,0.0,0,5.7369533,0.0,0.3331424,50.459297,5.7586198,503.12817,-9.2058535
4190,4190,212.3629,5.5667825,4.2751374,0.0,0,5.7118864,0.0,0.33522311,50.624786,5.733439,503.50311,-9.2049303
4201,4201,212.3651,5.5713353,4.2988319,0.0,0,5.6868196,0.0,0.337989,50.608665,5.7043209,503.87805,-9.2056637
4212,4212,212.3673,5.5555344,4.3315487,0.0,0,5.6617532,0.0,0.34037688,50.392117,5.6798816,504.25302,-9.2059813
4223,4223,212.3695,5.5724177,4.349093,0.0,0,5.6366854,0.0,0.34254974,50.391315,5.6561246,504.62796,-9.2052956
4234,4234,212.3717,5.5872831,4.3763475,0.0,0,5.6116195,0.0,0.34476134,50.303768,5.626822,504.94186,-9.2060375
4245,4245,212.3739,5.6173544,4.4000669,0.0,0,5.5869198,0.0,0.34731585,50.50716,5.6054492,505.21808,-9.2054329
4256,4256,212.3761,5.6296725,4.4326248,0.0,0,5.5630717,0.0,0.35001713,50.518963,5.573554,505.49426,-9.2048788
4267,4267,212.3783,5.6341424,4.4507351,0.0,0,5.5392232,0.0,0.3520551,50.470486,5.5509882,505.77048,-9.2052259
4278,4278,212.3805,5.6302338,4.4754839,0.0,0,5.5153751,0.0,0.35439172,50.304619,5.5288815,506.03647,-9.206459
4289,4289,212.3827,5.5978036,4.4977818,0.0,0,5.4915276,0.0,0.35645378,49.968719,5.5038209,506.18768,-9.2065058
4300,4300,212.3849,5.5784469,4.5267744,0.0,0,5.4676795,0.0,0.35933429,49.592545,5.4804716,506.33893,-9.2060509
4311,4311,212.3871,5.5769892,4.5457392,0.0,0,5.4438314,0.0,0.36077851,49.50528,5.4577117,506.49017,-9.2050228
4322,4322,212.3893,5.5961733,4.5659375,0.0,0,5.4199839,0.0,0.36304283,49.518597,5.4356937,506.64139,-9.2051821
4333,4333,212.3915,5.6454983,4.5890465,0.0,0,5.3961358,0.0,0.36495861,49.890064,5.4113994,506.71014,-9.2061834
4344,4344,212.3937,5.6872296,4.6153908,0.0,0,5.3722878,0.0,0.36800542,50.100353,5.3888383,506.71014,-9.205658
4355,4355,212.3959,5.7074213,4.6399212,0.0,0,5.3484397,0.0,0.36965492,50.255188,5.3656545,506.71014,-9.2060013
4366,4366,212.3981,5.7320457,4.6608939,0.0,0,5.3245916,0.0,0.37232995,50.287033,5.3368235,506.71014,-9.2049541
4377,4377,212.4003,5.7397232,4.6881342,0.0,0,5.3007436,0.0,0.3743321,50.300423,5.3144655,506.70966,-9.2050619
4388,4388,212.4025,5.7419429,4.7123446,0.0,0,5.276896,0.0,0.37755826,50.155312,5.2910109,506.65704,-9.2053623
4399,4399,212.4047,5.7312789,4.7406654,0.0,0,5.2530475,0.0,0.37930337,49.894863,5.2657714,506.60446,-9.2054987
4410,4410,212.4069,5.744772,4.7568789,0.0,0,5.2291994,0.0,0.38189995,49.951897,5.2399192,506.55185,-9.2049694
4421,4421,212.4091,5.7663016,4.7844157,0.0,0,5.2053518,0.0,0.38372931,49.974525,5.2187805,506.49924,-9.2042027
4432,4432,212.4113,5.7937994,4.8088408,0.0,0,5.1815038,0.0,0.3869195,50.108028,5.1929412,506.50879,-9.2037821
4443,4443,212.4135,5.8133068,4.8387122,0.0,0,5.1576557,0.0,0.38891852,50.17432,5.1676836,506.58771,-9.2050123
4454,4454,212.4157,5.8034964,4.8545799,0.0,0,5.1338077,0.0,0.39136353,49.949173,5.1453395,506.66663,-9.2055292
4465,4465,212.4179,5.8079853,4.8801236,0.0,0,5.1099596,0.0,0.39321673,49.930168,5.124105,506.74554,-9.206255
4476,4476,212.4201,5.8099184,4.8983684,0.0,0,5.0861115,0.0,0.39580396,49.855473,5.0988894,506.82443,-9.2054062
4487,4487,212.4223,5.8379607,4.9339099,0.0,0,5.062264,0.0,0.39837947,49.964794,5.0714664,507.00803,-9.2056274
4498,4498,212.4245,5.8141251,4.9488821,0.0,0,5.0390849,0.0,0.4006061,49.63686,5.0514174,507.19873,-9.2049704
4509,4509,212.4267,5.8272109,4.9743285,0.0,0,5.0164027,0.0,0.4026331,49.605827,5.0295091,507.3894,-9.2058907
4520,4520,212.4289,5.8510337,4.9936743,0.0,0,4.993721,0.0,0.40493125,49.629673,5.0084882,507.58011,-9.2055864
4531,4531,212.4311,5.8769608,5.0250902,0.0,0,4.9710388,0.0,0.40757221,49.728325,4.9869514,507.45773,-9.2053366
4542,4542,212.4333,5.9149218,5.0414681,0.0,0,4.9483566,0.0,0.40968791,50.060764,4.9602652,506.86575,-9.2059679
4553,4553,212.4355,5.9165292,5.06636,0.0,0,4.9256749,0.0,0.41206717,49.919399,4.9400744,506.2738,-9.2061157
4564,4564,212.4377,5.8930449,5.0852299,0.0,0,4.9029927,0.0,0.41397521,49.660976,4.9133339,505.68182,-9.2056141
4575,4575,212.4399,5.8960247,5.1145282,0.0,0,4.880311,0.0,0.41692406,49.480919,4.8911176,505.08987,-9.2049398
4586,4586,212.4421,5.9161859,5.1340804,0.0,0,4.8576288,0.0,0.41888627,49.585552,4.8682346,502.74185,-9.2040815
4597,4597,212.4443,5.9206972,5.1557765,0.0,0,4.8349466,0.0,0.42124271,49.453239,4.8466687,500.11658,-9.203722
4608,4608,212.4465,5.9297428,5.178328,0.0,0,4.8122649,0.0,0.42323679,49.462162,4.8240895,497.4913,-9.2049465
4619,4619,212.4487,5.9839463,5.2041006,0.0,0,4.7895827,0.0,0.42632985,49.680233,4.7995872,494.86603,-9.205471
4630,4630,212.4509,6.0276999,5.2279038,0.0,0,4.766901,0.0,0.42806864,50.00042,4.7773733,492.55728,-9.2059593
4641,4641,212.4531,6.0451503,5.2481704,0.0,0,4.7442188,0.0,0.43087265,49.995094,4.7525349,490.89914,-9.2055569
4652,4652,212.4553,6.0528092,5.273912,0.0,0,4.7215366,0.0,0.4328478,49.98381,4.7294827,489.241,-9.2045307
4663,4663,212.4575,6.0044303,5.296349,0.0,0,4.6988549,0.0,0.43596584,49.43119,4.7019238,487.58282,-9.204977
4674,4674,212.4597,5.9767327,5.3204708,0.0,0,4.6761732,0.0,0.43750441,49.194786,4.6829667,485.92468,-9.2066326
4685,4685,212.4619,5.9850478,5.3339,0.0,0,4.6534905,0.0,0.43987557,49.061016,4.6631851,486.01025,-9.2061214
4696,4696,212.4641,6.0193338,5.3605804,0.0,0,4.6308088,0.0,0.44180873,49.239727,4.6432023,486.55673,-9.2047625
4707,4707,212.4663,6.0860224,5.3818412,0.0,0,4.6081266,0.0,0.44480428,49.725372,4.6185346,487.10324,-9.2046099
4718,4718,212.4685,6.113915,5.4102254,0.0,0,4.5854449,0.0,0.44673598,49.78896,4.5920229,487.64975,-9.2043924
4729,4729,212.4707,6.1413031,5.4262834,0.0,0,4.5627627,0.0,0.44948941,49.840054,4.572401,488.12753,-9.2046461
4740,4740,212.4729,6.1507578,5.4534783,0.0,0,4.5400805,0.0,0.45150292,49.88332,4.5529819,488.40408,-9.205801
4751,4751,212.4751,6.1648402,5.4727473,0.0,0,4.5183334,0.0,0.45438397,49.849365,4.5298333,488.68063,-9.2052803
4762,4762,212.4773,6.1657281,5.5050917,0.0,0,4.4967556,0.0,0.45676738,49.761719,4.5023627,488.95718,-9.2051964
4773,4773,212.4795,6.1757636,5.5204716,0.0,0,4.4751782,0.0,0.45925215,49.624405,4.4784746,489.23373,-9.2061338
4784,4784,212.4817,6.1787319,5.5465069,0.0,0,4.4536009,0.0,0.46137619,49.623787,4.4564834,489.51013,-9.2064304
4795,4795,212.4839,6.1521873,5.5631032,0.0,0,4.432023,0.0,0.46371546,49.225735,4.435493,489.78647,-9.2064772
4806,4806,212.4861,6.1597733,5.5951123,0.0,0,4.4104452,0.0,0.4664492,49.21172,4.412169,490.06277,-9.2053747
4817,4817,212.4883,6.1692615,5.6086407,0.0,0,4.3888679,0.0,0.46838161,49.132183,4.3896022,490.33911,-9.2054214
4828,4828,212.4905,6.1823153,5.6296349,0.0,0,4.36729,0.0,0.47041914,49.198582,4.3703685,490.67285,-9.2060537
4839,4839,212.4927,6.1815414,5.6479239,0.0,0,4.3457127,0.0,0.47240764,49.080257,4.349195,491.26495,-9.206502
4850,4850,212.4949,6.1950798,5.6761436,0.0,0,4.3241353,0.0,0.47540796,49.030025,4.3295426,491.85709,-9.207098
4861,4861,212.4971,6.1888752,5.6919408,0.0,0,4.3025579,0.0,0.47707683,48.911362,4.3090992,492.44919,-9.2067766
4872,4872,212.4993,6.2362323,5.7133884,0.0,0,4.2809801,0.0,0.47943735,49.121708,4.2874298,493.04129,-9.2062683
4883,4883,212.5015,6.2696319,5.7320876,0.0,0,4.2594023,0.0,0.48129171,49.34988,4.2663803,493.70984,-9.2047768
4894,4894,212.5037,6.2978191,5.7585888,0.0,0,4.2378249,0.0,0.48451334,49.344978,4.2402291,494.42038,-9.2048492
4905,4905,212.5059,6.3077626,5.7801003,0.0,0,4.2162471,0.0,0.48628178,49.397953,4.2218671,495.13092,-9.2054348
4916,4916,212.5081,6.3638887,5.7992926,0.0,0,4.1946697,0.0,0.48907956,49.642902,4.2021194,495.84146,-9.2051506
4927,4927,212.5103,6.3821049,5.8227096,0.0,0,4.1730919,0.0,0.49088714,49.702579,4.1779599,496.54626,-9.2053375
4938,4938,212.5125,6.3754749,5.8455215,0.0,0,4.1515145,0.0,0.49420789,49.582439,4.1509428,497.20416,-9.2054119
4949,4949,212.5147,6.3638368,5.8687091,0.0,0,4.1299367,0.0,0.49594611,49.395073,4.1327186,497.86209,-9.2059565
4960,4960,212.5169,6.3789706,5.887804,0.0,0,4.1083593,0.0,0.49890667,49.295555,4.112679,498.51999,-9.2055035
4971,4971,212.5191,6.3909807,5.9127512,0.0,0,4.0867815,0.0,0.50073856,49.276455,4.0893826,499.17789,-9.2047625
4982,4982,212.5213,6.3986945,5.9284973,0.0,0,4.0652041,0.0,0.50348479,49.178333,4.0697579,498.31677,-9.2051926
4993,4993,212.5235,6.4149089,5.9551158,0.0,0,4.0437527,0.0,0.50515288,49.305885,4.0479703,496.32248,-9.2052174
5004,5004,212.5257,6.4448757,5.9724712,0.0,0,4.0232306,0.0,0.50824487,49.340675,4.0268755,494.32822,-9.2049532
5015,5015,212.5279,6.4646335,5.9991083,0.0,0,4.0027089,0.0,0.51028907,49.371292,4.0065308,492.33392,-9.2050991
5026,5026,212.5301,6.4880834,6.0153341,0.0,0,3.9821873,0.0,0.51302314,49.406036,3.9837017,490.34442,-9.2050724
5037,5037,212.5323,6.4710555,6.0437093,0.0,0,3.9616656,0.0,0.51499903,49.248932,3.9609814,488.48206,-9.2053757
5048,5048,212.5345,6.4800825,6.0569544,0.0,0,3.9411442,0.0,0.51754493,49.144375,3.9416301,486.61966,-9.2056694
5059,5059,212.5367,6.4618964,6.0805354,0.0,0,3.9206226,0.0,0.51944149,48.976173,3.9221394,484.75729,-9.2062731
5070,5070,212.5389,6.4854212,6.0953741,0.0,0,3.9001009,0.0,0.52190906,49.020645,3.9034929,482.8949,-9.2068863
5081,5081,212.5411,6.4930964,6.1259379,0.0,0,3.8795795,0.0,0.52438384,48.924091,3.8869913,482.35223,-9.206953
5092,5092,212.5433,6.5089984,6.1360402,0.0,0,3.8590579,0.0,0.52626121,48.943176,3.8663149,483.12921,-9.2060356
5103,5103,212.5455,6.5485034,6.1588387,0.0,0,3.8385363,0.0,0.52839845,49.141483,3.8460693,483.90619,-9.2070541
5114,5114,212.5477,6.6050739,6.1766076,0.0,0,3.8180146,0.0,0.53065592,49.46632,3.8200994,484.68317,-9.2067051
5125,5125,212.5499,6.6094227,6.2055216,0.0,0,3.797493,0.0,0.53367418,49.342842,3.8019524,485.46014,-9.2061872
5136,5136,212.5521,6.6469707,6.2212491,0.0,0,3.7769713,0.0,0.53571242,49.523891,3.7783806,486.38281,-9.2055807
5147,5147,212.5543,6.662601,6.2445173,0.0,0,3.7564499,0.0,0.53834587,49.49794,3.7578321,487.31097,-9.2051334
5158,5158,212.5565,6.675808,6.2643461,0.0,0,3.7359283,0.0,0.54034591,49.456169,3.7377894,488.23914,-9.2057352
5169,5169,212.5587,6.6885796,6.2905455,0.0,0,3.7154067,0.0,0.54381102,49.43708,3.7176154,489.1673,-9.2055435
5180,5180,212.5609,6.6780548,6.3098578,0.0,0,3.694885,0.0,0.54555625,49.323513,3.6972158,490.11496,-9.205739
5191,5191,212.5631,6.6702356,6.3282657,0.0,0,3.6743636,0.0,0.54826021,49.058739,3.6757758,491.08884,-9.20648
5202,5202,212.5653,6.6859751,6.3475666,0.0,0,3.6538417,0.0,0.54986638,49.116379,3.658196,492.06271,-9.206727
5213,5213,212.5675,6.7299681,6.3696122,0.0,0,3.6333201,0.0,0.55321115,49.26593,3.6363537,493.03659,-9.2037783
5224,5224,212.5697,6.7300224,6.3933029,0.0,0,3.6127987,0.0,0.5548588,49.179352,3.6161401,494.01047,-9.2043571
5235,5235,212.5719,6.7071314,6.407856,0.0,0,3.5922771,0.0,0.55765021,48.908714,3.5950274,494.87869,-9.2049398
5246,5246,212.5741,6.7016745,6.4274645,0.0,0,3.5721471,0.0,0.55891401,48.776901,3.5791178,495.73398,-9.2052498
5257,5257,212.5763,6.75144,6.4453259,0.0,0,3.5526242,0.0,0.56210428,48.994305,3.5544612,496.58926,-9.2058525
5268,5268,212.5785,6.8213444,6.4726663,0.0,0,3.5331016,0.0,0.56397575,49.358524,3.5349865,497.44455,-9.2058325
5279,5279,212.5807,6.8863926,6.4866538,0.0,0,3.5135787,0.0,0.5668574,49.72599,3.5140989,498.17621,-9.2051411
5290,5290,212.5829,6.8851323,6.5102749,0.0,0,3.4940557,0.0,0.56864238,49.665234,3.4956203,498.68277,-9.2044106
5301,5301,212.5851,6.8993726,6.5260386,0.0,0,3.4745328,0.0,0.57168263,49.592979,3.4729373,499.18936,-9.2061729
5312,5312,212.5873,6.8944116,6.5569496,0.0,0,3.4550104,0.0,0.57389879,49.480839,3.4540703,499.69592,-9.2070713
5323,5323,212.5895,6.8785272,6.5691791,0.0,0,3.4354873,0.0,0.57663155,49.185226,3.4321764,500.20251,-9.206377
5334,5334,212.5917,6.8702946,6.594595,0.0,0,3.4159648,0.0,0.57869935,49.0658,3.4135616,500.40088,-9.2057486
5345,5345,212.5939,6.8884525,6.6079478,0.0,0,3.3964417,0.0,0.58127803,49.016258,3.3940175,500.53076,-9.2071829
5356,5356,212.5961,6.8986392,6.6351876,0.0,0,3.376919,0.0,0.58347464,48.969753,3.3749301,500.66064,-9.2078476
5367,5367,212.5983,6.9076233,6.6456137,0.0,0,3.3573964,0.0,0.58554417,48.923138,3.3584125,500.79053,-9.2062521
5378,5378,212.6005,6.925509,6.6675177,0.0,0,3.3378732,0.0,0.58756447,48.948853,3.3380587,500.74661,-9.2057114
5389,5389,212.6027,6.9671907,6.6828547,0.0,0,3.3183508,0.0,0.58992153,49.17767,3.3174558,500.62161,-9.2060919
5400,5400,212.6049,7.0044026,6.7111616,0.0,0,3.2988276,0.0,0.59276795,49.308033,3.2997341,500.49661,-9.2070808
5411,5411,212.6071,7.0355692,6.723732,0.0,0,3.2793047,0.0,0.59466344,49.428146,3.2781749,500.37161,-9.2072945
5422,5422,212.6093,7.0521026,6.7457833,0.0,0,3.2597823,0.0,0.59727466,49.390594,3.2582717,500.3002,-9.2058191
5433,5433,212.6115,7.0735078,6.7652206,0.0,0,3.2402592,0.0,0.5994789,49.425919,3.2379858,500.54364,-9.2063169
5444,5444,212.6137,7.1310706,6.7916379,0.0,0,3.2207365,0.0,0.60287392,49.668701,3.2189839,500.78708,-9.2064505
5455,5455,212.6159,7.1460514,6.8093524,0.0,0,3.2012138,0.0,0.60477877,49.677742,3.1981246,501.03049,-9.2057343
5466,5466,212.6181,7.1664128,6.8264842,0.0,0,3.1816909,0.0,0.60729975,49.626648,3.1765285,501.27393,-9.2049503
5477,5477,212.6203,7.1947541,6.846549,0.0,0,3.1621683,0.0,0.60917675,49.784245,3.1589632,501.6055,-9.205184
5488,5488,212.6225,7.1628428,6.8695931,0.0,0,3.1426454,0.0,0.61287564,49.441494,3.1391139,501.99365,-9.2044201
5499,5499,212.6247,7.1533318,6.8893442,0.0,0,3.1237545,0.0,0.61436039,49.306248,3.1204884,502.38184,-9.2055302
5510,5510,212.6269,7.161613,6.9038606,0.0,0,3.1051819,0.0,0.61705601,49.200871,3.0995741,502.76999,-9.206131
5521,5521,212.6291,7.190093,6.9247937,0.0,0,3.0866094,0.0,0.61873645,49.333603,3.0836725,503.12561,-9.2059402
5532,5532,212.6313,7.1812248,6.9418402,0.0,0,3.0680368,0.0,0.62195677,49.087193,3.0634634,503.06641,-9.2054482
5543,5543,212.6335,7.1987205,6.9644055,0.0,0,3.0494645,0.0,0.62352401,49.114399,3.0442572,503.0072,-9.2057943
5554,5554,212.6357,7.2320261,6.9750662,0.0,0,3.0308924,0.0,0.62599391,49.212605,3.023716,502.948,-9.2055407
5565,5565,212.6379,7.2814345,6.9993067,0.0,0,3.0123198,0.0,0.6280039,49.551815,3.0043004,502.88879,-9.2060308
5576,5576,212.6401,7.2813168,7.0158482,0.0,0,2.9937477,0.0,0.6312449,49.345562,2.9878905,502.72723,-9.2065945
5587,5587,212.6423,7.268847,7.0418148,0.0,0,2.9751751,0.0,0.6328634,49.205181,2.9723933,502.47723,-9.2065182
5598,5598,212.6445,7.2606206,7.0494556,0.0,0,2.9566026,0.0,0.63539302,49.009701,2.9529738,502.22723,-9.2068329
5609,5609,212.6467,7.2991023,7.0710249,0.0,0,2.93803,0.0,0.63696176,49.145279,2.9344759,501.9772,-9.2058296
5620,5620,212.6489,7.3191433,7.0852427,0.0,0,2.9194577,0.0,0.63995427,49.126595,2.9173632,501.7272,-9.2054605
5631,5631,212.6511,7.3591409,7.1123691,0.0,0,2.9008856,0.0,0.6421712,49.298473,2.8981972,501.50351,-9.2062912
5642,5642,212.6533,7.4284377,7.1231184,0.0,0,2.882313,0.0,0.64459872,49.592411,2.8813744,501.27982,-9.2063074
5653,5653,212.6555,7.4457431,7.1460209,0.0,0,2.8637407,0.0,0.64672226,49.63549,2.863414,501.05612,-9.2048073
5664,5664,212.6577,7.4745431,7.1606393,0.0,0,2.8451684,0.0,0.6492666,49.733406,2.845964,500.83246,-9.2048149
5675,5675,212.6599,7.4787822,7.1892524,0.0,0,2.8265958,0.0,0.65216392,49.643181,2.8216455,500.79788,-9.2048731
5686,5686,212.6621,7.465282,7.1997299,0.0,0,2.8080232,0.0,0.65402561,49.468529,2.8049712,500.98209,-9.205595
5697,5697,212.6643,7.4678397,7.219882,0.0,0,2.7894509,0.0,0.65635765,49.340061,2.789896,501.16629,-9.205822
5708,5708,212.6665,7.5002875,7.2329435,0.0,0,2.7708786,0.0,0.6581679,49.452515,2.7741489,501.35052,-9.206111
5719,5719,212.6687,7.5333176,7.2605557,0.0,0,2.7523062,0.0,0.66174561,49.484619,2.7529457,501.53473,-9.2061014
5730,5730,212.6709,7.5887465,7.2740736,0.0,0,2.7337339,0.0,0.66329986,49.738956,2.7351406,501.90195,-9.2050667
5741,5741,212.6731,7.6334958,7.2911692,0.0,0,2.7151613,0.0,0.66585642,49.939362,2.7168686,502.28354,-9.2051449
5752,5752,212.6753,7.6647348,7.3088317,0.0,0,2.697439,0.0,0.66775292,50.04015,2.6996331,502.66513,-9.2052546
5763,5763,212.6775,7.6797628,7.3339429,0.0,0,2.6797729,0.0,0.67162228,50.02644,2.6796172,503.04672,-9.2058535
5774,5774,212.6797,7.7072463,7.3505845,0.0,0,2.6621068,0.0,0.67284662,50.095604,2.6610901,503.39487,-9.2047939
5785,5785,212.6819,7.7448807,7.3672895,0.0,0,2.6444409,0.0,0.67596614,50.183411,2.6394575,503.69089,-9.2044268
5796,5796,212.6841,7.7407274,7.3885226,0.0,0,2.626775,0.0,0.67790926,50.031307,2.6185169,503.98691,-9.2048416
5807,5807,212.6863,7.7830381,7.4100561,0.0,0,2.6091087,0.0,0.68182147,50.1353,2.6035881,504.28293,-9.2056141
5818,5818,212.6885,7.7661343,7.4322939,0.0,0,2.5914428,0.0,0.68345249,49.948921,2.5823233,504.57895,-9.2063084
5829,5829,212.6907,7.7595968,7.4428506,0.0,0,2.573777,0.0,0.68608135,49.755768,2.5640271,504.63324,-9.2052803
5840,5840,212.6929,7.75631,7.4616313,0.0,0,2.5561109,0.0,0.68748873,49.638725,2.5470498,504.64639,-9.2039642
5851,5851,212.6951,7.7468762,7.4774814,0.0,0,2.538445,0.0,0.69088912,49.424915,2.5301893,504.65955,-9.2054396
5862,5862,212.6973,7.7134438,7.502243,0.0,0,2.5207789,0.0,0.69246185,49.130348,2.5143032,504.6727,-9.2061977
5873,5873,212.6995,7.7358899,7.5074725,0.0,0,2.5031128,0.0,0.6947192,49.210056,2.4998176,504.70679,-9.2057705
5884,5884,212.7017,7.7925434,7.528307,0.0,0,2.4854469,0.0,0.69629323,49.436806,2.4812973,504.78568,-9.2054911
5895,5895,212.7039,7.8392591,7.540554,0.0,0,2.4677808,0.0,0.69917685,49.635441,2.4666805,504.86459,-9.2056971
5906,5906,212.7061,7.9211955,7.568346,0.0,0,2.4501147,0.0,0.70150453,49.946785,2.4454203,504.94348,-9.2051163
5917,5917,212.7083,7.9699306,7.576839,0.0,0,2.4324489,0.0,0.70401043,50.198658,2.4255431,505.0224,-9.2053299
5928,5928,212.7105,8.0229292,7.6013379,0.0,0,2.4147828,0.0,0.70637286,50.366226,2.4100065,505.16302,-9.2054501
5939,5939,212.7127,8.0456123,7.6151137,0.0,0,2.3971167,0.0,0.70899487,50.385841,2.3925893,505.32086,-9.2059145
5950,5950,212.7149,8.0444183,7.6406822,0.0,0,2.3794508,0.0,0.71164447,50.275909,2.3735423,505.47867,-9.2064104
5961,5961,212.7171,7.9817662,7.6508594,0.0,0,2.3617849,0.0,0.71360391,49.794136,2.3565717,505.63651,-9.2052546
5972,5972,212.7193,7.9896059,7.670331,0.0,0,2.3441188,0.0,0.71588182,49.745014,2.3414874,505.76047,-9.2059879
5983,5983,212.7215,8.0076666,7.6814928,0.0,0,2.3264527,0.0,0.71772057,49.774593,2.3283551,505.78018,-9.2057848
5994,5994,212.7237,8.0575666,7.7072973,0.0,0,2.3089681,0.0,0.72110194,49.879997,2.310179,505.7999,-9.2051754
6005,6005,212.7259,8.1147032,7.7195067,0.0,0,2.2921643,0.0,0.7227124,50.202076,2.2920682,505.81964,-9.2057705
6016,6016,212.7281,8.1837301,7.738204,0.0,0,2.2753608,0.0,0.72551799,50.412228,2.273335,505.83936,-9.2056389
6027,6027,212.7303,8.2320433,7.7515106,0.0,0,2.2585571,0.0,0.72700721,50.627693,2.2558024,505.29465,-9.2052927
6038,6038,212.7325,8.2973824,7.7765527,0.0,0,2.2417536,0.0,0.73101419,50.859863,2.2376509,504.5184,-9.2058458
6049,6049,212.7347,8.3349247,7.7922792,0.0,0,2.2249501,0.0,0.73245412,51.021542,2.2189071,503.74213,-9.2055197
6060,6060,212.7369,8.3349771,7.8082633,0.0,0,2.2081466,0.0,0.73543894,50.904633,2.2004514,502.96585,-9.2042933
6071,6071,212.7391,8.3363113,7.8291554,0.0,0,2.1913428,0.0,0.73747414,50.760239,2.1797049,502.18506,-9.2058754
6082,6082,212.7413,8.3255606,7.848711,0.0,0,2.1745393,0.0,0.74137372,50.509094,2.1613092,501.38251,-9.2055035
6093,6093,212.7435,8.31915,7.8661156,0.0,0,2.1577358,0.0,0.74248785,50.367901,2.148757,500.57993,-9.2059784
6104,6104,212.7457,8.3062687,7.8783951,0.0,0,2.1409321,0.0,0.74558878,50.155144,2.1319911,499.77737,-9.2063179
6115,6115,212.7479,8.3264284,7.8987913,0.0,0,2.1241283,0.0,0.7470715,50.210747,2.1140714,498.97482,-9.204875
6126,6126,212.7501,8.3882666,7.9108777,0.0,0,2.1073248,0.0,0.75018567,50.406502,2.0952718,498.27271,-9.2048931
6137,6137,212.7523,8.4237261,7.9339728,0.0,0,2.0905213,0.0,0.75172228,50.55978,2.081809,497.62796,-9.2057734
6148,6148,212.7545,8.4324923,7.942987,0.0,0,2.0737178,0.0,0.75471944,50.465843,2.0674417,496.98318,-9.2068615
6159,6159,212.7567,8.4260721,7.9623122,0.0,0,2.0569141,0.0,0.7561118,50.384796,2.0524614,496.33844,-9.2068605
6170,6170,212.7589,8.4527798,7.9757361,0.0,0,2.0401106,0.0,0.75946891,50.360088,2.0322926,495.69635,-9.2055988
6181,6181,212.7611,8.5096016,8.0017548,0.0,0,2.0233071,0.0,0.7613737,50.564613,2.0173328,495.07791,-9.2043972
6192,6192,212.7633,8.57374,8.0079193,0.0,0,2.0065033,0.0,0.76374722,50.837116,1.9971744,494.45947,-9.2053757
6203,6203,212.7655,8.6172514,8.0304756,0.0,0,1.9896998,0.0,0.76599145,50.987328,1.982293,493.84106,-9.2058516
6214,6214,212.7677,8.664546,8.0437183,0.0,0,1.9728961,0.0,0.76882708,51.121925,1.9622891,493.22263,-9.2059336
6225,6225,212.7699,8.6922903,8.0682383,0.0,0,1.9560926,0.0,0.77139723,51.163609,1.9480391,492.98615,-9.2060013
6236,6236,212.7721,8.6963634,8.0773668,0.0,0,1.939289,0.0,0.77372551,51.070053,1.9295564,493.04535,-9.2049608
6247,6247,212.7743,8.6805429,8.0976906,0.0,0,1.9228806,0.0,0.77604532,50.895535,1.9146576,493.10455,-9.2047615
6258,6258,212.7765,8.6406965,8.1088886,0.0,0,1.9068955,0.0,0.77794397,50.536751,1.9011396,493.16379,-9.2055073
6269,6269,212.7787,8.6612082,8.130724,0.0,0,1.8909101,0.0,0.78066987,50.52507,1.8851658,493.22137,-9.205759
6280,6280,212.7809,8.7078047,8.1406078,0.0,0,1.874925,0.0,0.78249431,50.714027,1.8695664,493.22137,-9.2047615
6291,6291,212.7831,8.7646866,8.1600838,0.0,0,1.8589398,0.0,0.7852419,50.877148,1.8491337,493.22137,-9.2058973
6302,6302,212.7853,8.803442,8.1722879,0.0,0,1.8429546,0.0,0.78683954,51.022083,1.8367372,493.22137,-9.2056522
6313,6313,212.7875,8.8371687,8.1901054,0.0,0,1.8269695,0.0,0.78994024,51.073334,1.8226118,493.22137,-9.2062035
6324,6324,212.7897,8.8782845,8.2059736,0.0,0,1.8109843,0.0,0.79156858,51.257175,1.8068116,493.55405,-9.205822
6335,6335,212.7919,8.9120398,8.2226295,0.0,0,1.794999,0.0,0.79480928,51.212143,1.7906585,494.23169,-9.2062531
6346,6346,212.7941,8.9509659,8.2394543,0.0,0,1.7790139,0.0,0.79645598,51.36105,1.7727257,494.90933,-9.2055798
6357,6357,212.7963,8.944562,8.2557192,0.0,0,1.7630286,0.0,0.79993707,51.248592,1.7555313,495.58698,-9.2054005
6368,6368,212.7985,8.9809074,8.273221,0.0,0,1.7470435,0.0,0.80120879,51.304844,1.7414166,496.26462,-9.2052412
6379,6379,212.8007,9.0509176,8.2838974,0.0,0,1.7310582,0.0,0.80421627,51.511135,1.7264888,496.98621,-9.2058792
6390,6390,212.8029,9.1175776,8.3038473,0.0,0,1.715073,0.0,0.80574262,51.814419,1.7067072,497.7099,-9.2055159
6401,6401,212.8051,9.1298532,8.3178749,0.0,0,1.6990879,0.0,0.80945903,51.741432,1.6939085,498.43359,-9.2051687
6412,6412,212.8073,9.1366081,8.3414507,0.0,0,1.6831026,0.0,0.81118745,51.682163,1.6764648,499.15732,-9.2055168
6423,6423,212.8095,9.1599474,8.3498611,0.0,0,1.6671174,0.0,0.81426966,51.643017,1.6593453,499.49033,-9.2064943
6434,6434,212.8117,9.1706114,8.36868,0.0,0,1.6511322,0.0,0.81555367,51.712605,1.648823,499.27979,-9.2068157
6445,6445,212.8139,9.2064991,8.3806276,0.0,0,1.635147,0.0,0.81886977,51.683281,1.6333294,499.06924,-9.2050991
6456,6456,212.8161,9.2553368,8.4063158,0.0,0,1.6191618,0.0,0.82089162,51.851177,1.6134213,498.8587,-9.2048645
6467,6467,212.8183,9.3162346,8.4125996,0.0,0,1.6031766,0.0,0.82357794,52.04092,1.5998937,498.64816,-9.2053099
6478,6478,212.8205,9.3970661,8.4351521,0.0,0,1.5871913,0.0,0.82571763,52.390598,1.5842211,498.40283,-9.2035456
6489,6489,212.8227,9.4419842,8.4474316,0.0,0,1.5712062,0.0,0.82898253,52.46386,1.5650491,498.15283,-9.2052441
6500,6500,212.8249,9.4614801,8.4743366,0.0,0,1.5558095,0.0,0.83145672,52.428768,1.549125,497.90283,-9.2054977
6511,6511,212.8271,9.4801292,8.481473,0.0,0,1.540603,0.0,0.83387142,52.454006,1.5308113,497.65283,-9.2058067
6522,6522,212.8293,9.5092192,8.50105,0.0,0,1.5253967,0.0,0.83601606,52.488232,1.5162722,497.53467,-9.2049904
6533,6533,212.8315,9.4879093,8.5118828,0.0,0,1.5101904,0.0,0.83821702,52.285645,1.4987004,497.66623,-9.2046471
6544,6544,212.8337,9.484026,8.5345392,0.0,0,1.4949839,0.0,0.8412292,52.068928,1.4817437,497.79782,-9.2056408
6555,6555,212.8359,9.4782104,8.5425129,0.0,0,1.4797776,0.0,0.84299165,51.947086,1.4703494,497.92941,-9.2052698
6566,6566,212.8381,9.4826469,8.5635262,0.0,0,1.4645711,0.0,0.84604847,51.78529,1.4578656,498.061,-9.2049627
6577,6577,212.8403,9.5222845,8.5733938,0.0,0,1.4493648,0.0,0.84734833,51.906876,1.4414372,498.32565,-9.2044325
6588,6588,212.8425,9.5501795,8.593317,0.0,0,1.4341583,0.0,0.85082948,51.944427,1.4272796,498.6217,-9.2063036
6599,6599,212.8447,9.5694742,8.6040344,0.0,0,1.418952,0.0,0.85202718,51.999809,1.4115514,498.91776,-9.2061892
6610,6610,212.8469,9.6001282,8.616787,0.0,0,1.4037454,0.0,0.85473192,52.0084,1.4008052,499.21384,-9.2044191
6621,6621,212.8491,9.6523428,8.6302462,0.0,0,1.3885391,0.0,0.85592681,52.197041,1.3847404,499.50092,-9.2062721
6632,6632,212.8513,9.6605768,8.6480722,0.0,0,1.3733326,0.0,0.85984635,52.100639,1.3672134,499.76407,-9.2055969
6643,6643,212.8535,9.7032433,8.6637754,0.0,0,1.3581263,0.0,0.86104679,52.237385,1.3549516,500.02722,-9.205265
6654,6654,212.8557,9.7699194,8.6719656,0.0,0,1.3429198,0.0,0.86356825,52.459976,1.3407378,500.29037,-9.2050238
6665,6665,212.8579,9.8516397,8.6883173,0.0,0,1.3277135,0.0,0.86490476,52.801067,1.3263336,500.55356,-9.2051659
6676,6676,212.8601,9.9469347,8.7034588,0.0,0,1.3125072,0.0,0.86890584,53.113804,1.3094406,500.72952,-9.204217
6687,6687,212.8623,10.025908,8.7257547,0.0,0,1.2973008,0.0,0.8706215,53.440331,1.2921647,500.87427,-9.2043123
6698,6698,212.8645,10.090894,8.7365532,0.0,0,1.2820944,0.0,0.87421399,53.62328,1.2749436,501.01901,-9.2049131
6709,6709,212.8667,10.132711,8.7594128,0.0,0,1.2668879,0.0,0.87617368,53.708557,1.2569767,501.16376,-9.2053461
6720,6720,212.8689,10.13926,8.7699156,0.0,0,1.2516814,0.0,0.87958866,53.6087,1.2437091,501.3006,-9.2047024
6731,6731,212.8711,10.1623,8.7937727,0.0,0,1.2364751,0.0,0.88138455,53.598225,1.2246062,501.40585,-9.204689
6742,6742,212.8733,10.165805,8.8008451,0.0,0,1.2212964,0.0,0.8845014,53.456593,1.2068226,501.51111,-9.2057743
6753,6753,212.8755,10.177362,8.8229866,0.0,0,1.206827,0.0,0.88648552,53.382748,1.1933647,501.61636,-9.205616
6764,6764,212.8777,10.178179,8.8299608,0.0,0,1.1923642,0.0,0.88916481,53.240463,1.180275,501.72162,-9.2041426
6775,6775,212.8799,10.206824,8.8546886,0.0,0,1.1779014,0.0,0.89145494,53.303596,1.1669039,501.81378,-9.2052355
6786,6786,212.8821,10.218409,8.8576336,0.0,0,1.1634386,0.0,0.8935377,53.255371,1.1518844,501.89932,-9.2052803
6797,6797,212.8843,10.25384,8.8783226,0.0,0,1.1489758,0.0,0.89563876,53.294128,1.1372694,501.98483,-9.2047186
6808,6808,212.8865,10.26041,8.8873062,0.0,0,1.134513,0.0,0.89796042,53.254726,1.1252542,502.07037,-9.2042551
6819,6819,212.8887,10.28449,8.9106655,0.0,0,1.1200502,0.0,0.90103942,53.197479,1.1108146,502.1601,-9.2048559
6830,6830,212.8909,10.281754,8.9151554,0.0,0,1.1055874,0.0,0.90239286,53.091061,1.1005641,502.27853,-9.2058744
6841,6841,212.8931,10.341621,8.9327459,0.0,0,1.0911245,0.0,0.90503734,53.260105,1.0843849,502.39694,-9.2043934
6852,6852,212.8953,10.421848,8.9434862,0.0,0,1.0766618,0.0,0.90688688,53.58913,1.0699663,502.51538,-9.2046614
6863,6863,212.8975,10.524686,8.9636478,0.0,0,1.0621989,0.0,0.91012895,53.884243,1.051675,502.63379,-9.2050438
6874,6874,212.8997,10.594478,8.9732208,0.0,0,1.0477362,0.0,0.91147244,54.217773,1.0404905,502.76001,-9.2064123
6885,6885,212.9019,10.618114,8.989006,0.0,0,1.0332733,0.0,0.91476142,54.202023,1.0276985,502.89157,-9.2066002
6896,6896,212.9041,10.638655,9.0017414,0.0,0,1.0188106,0.0,0.91619754,54.195126,1.0135758,503.02313,-9.204915
6907,6907,212.9063,10.664877,9.0210457,0.0,0,1.0043477,0.0,0.9203853,54.09127,0.99478203,503.15472,-9.2048283
6918,6918,212.9085,10.717823,9.0322733,0.0,0,0.98988497,0.0,0.9210093,54.335751,0.97827715,503.22061,-9.2036085
6929,6929,212.9107,10.766855,9.0443687,0.0,0,0.97542214,0.0,0.92431182,54.365639,0.96617931,502.14825,-9.2044048
6940,6940,212.9129,10.815463,9.0621281,0.0,0,0.96095932,0.0,0.92598754,54.516174,0.95403463,501.07587,-9.204215
6951,6951,212.9151,10.847297,9.0771427,0.0,0,0.94649649,0.0,0.93014634,54.462284,0.9361912,500.00348,-9.2048445
6962,6962,212.9173,10.854738,9.0941019,0.0,0,0.93203378,0.0,0.93099123,54.457138,0.92181033,498.93109,-9.2046299
6973,6973,212.9195,10.85516,9.0995579,0.0,0,0.91757095,0.0,0.93403572,54.340839,0.9103266,497.5416,-9.2043419
6984,6984,212.9217,10.888695,9.1189184,0.0,0,0.90310812,0.0,0.93554932,54.420723,0.89668405,495.85727,-9.2049799
6995,6995,212.9239,10.919813,9.1310215,0.0,0,0.88885862,0.0,0.93937033,54.357361,0.88245463,494.17294,-9.2058144
7006,7006,212.9261,10.970877,9.1504688,0.0,0,0.87510419,0.0,0.94033712,54.543106,0.86994582,492.48859,-9.2060757
7017,7017,212.9283,11.010698,9.152585,0.0,0,0.86134988,0.0,0.94287336,54.6255,0.85641384,490.80426,-9.2036695
7028,7028,212.9305,11.08098,9.1740484,0.0,0,0.84759539,0.0,0.94489789,54.793499,0.83909398,489.9465,-9.2035894
7039,7039,212.9327,11.160882,9.1824455,0.0,0,0.83384103,0.0,0.94803011,55.010876,0.82621491,489.10406,-9.2050505
7050,7050,212.9349,11.212749,9.205965,0.0,0,0.82008666,0.0,0.95023471,55.179359,0.8125307,488.26163,-9.2075844
7061,7061,212.9371,11.23123,9.2107992,0.0,0,0.80633223,0.0,0.95278913,55.148941,0.79698682,487.41919,-9.2052698
7072,7072,212.9393,11.233422,9.2300615,0.0,0,0.79257786,0.0,0.95475227,55.040974,0.78416955,486.66458,-9.2058315
7083,7083,212.9415,11.261692,9.2353296,0.0,0,0.77882344,0.0,0.95688266,55.109558,0.76982725,486.01929,-9.2059669
7094,7094,212.9437,11.289397,9.259222,0.0,0,0.76506907,0.0,0.95969623,55.083328,0.75968838,485.37402,-9.2064362
7105,7105,212.9459,11.324334,9.2635555,0.0,0,0.75131464,0.0,0.9616487,55.145649,0.74653524,484.72873,-9.206502
7116,7116,212.9481,11.380217,9.2827034,0.0,0,0.73756021,0.0,0.96454668,55.269077,0.73165154,484.08344,-9.2054863
7127,7127,212.9503,11.482162,9.2924681,0.0,0,0.72380584,0.0,0.96623552,55.590893,0.71384847,483.7554,-9.2056618
7138,7138,212.9525,11.583049,9.3141098,0.0,0,0.71005148,0.0,0.9698773,55.928341,0.70051849,483.45911,-9.205472
7149,7149,212.9547,11.67038,9.3219948,0.0,0,0.69629705,0.0,0.97125286,56.236042,0.68752563,483.16281,-9.2050629
7160,7160,212.9569,11.69187,9.337678,0.0,0,0.68254262,0.0,0.97441906,56.166489,0.6718514,482.86649,-9.2044706
7171,7171,212.9591,11.686991,9.3491402,0.0,0,0.66878825,0.0,0.97595417,56.050323,0.65491444,482.8696,-9.2051277
7182,7182,212.9613,11.679386,9.365984,0.0,0,0.65503383,0.0,0.97960573,55.835693,0.64561987,483.37662,-9.2041998
7193,7193,212.9635,11.661846,9.3776503,0.0,0,0.64127946,0.0,0.98073334,55.728046,0.63060123,483.88361,-9.2051935
7204,7204,212.9657,11.67142,9.3885098,0.0,0,0.62752503,0.0,0.98381174,55.548473,0.61731911,484.39063,-9.2056398
7215,7215,212.9679,11.710498,9.4017811,0.0,0,0.61377066,0.0,0.98482448,55.686428,0.60350424,484.89761,-9.206502
7226,7226,212.9701,11.774253,9.414197,0.0,0,0.60001624,0.0,0.98870051,55.759369,0.595092,485.50928,-9.2064533
7237,7237,212.9723,11.851154,9.4318275,0.0,0,0.58626187,0.0,0.98982871,56.06934,0.58186781,486.14139,-9.2046003
7248,7248,212.9745,11.971193,9.437583,0.0,0,0.57288873,0.0,0.9928785,56.436001,0.56474942,486.7735,-9.2052116
7257,7257,212.9763,11.997413,9.448534,0.0,0,0.56217867,0.0,0.99477589,56.432476,0.55695629,487.29071,-9.2051296