File: clean data/testID_0090.csv
level_0,index,Time(sec),Force(kN),Jaw(mm),PowAngle(deg),Power(W),Pram,PTemp,Strain,Stress(MPa),Stroke(mm),TC1(C),wedge(mm)
1773,1773,145.3439,0.61086512,0.022253707,0.0,0,9.0337057,0.0,0.0012959043,7.1973481,10.060526,300.04007,-9.3222084
1775,1775,145.3443,2.9380569,0.042984761,0.0,0,8.9751778,0.0,0.0027747089,32.642303,9.9988832,300.06088,-9.3228559
1777,1777,145.3447,6.6552596,0.092790104,0.0,0,8.9166498,0.0,0.0058010304,80.485298,9.9530554,300.38354,-9.3217001
1779,1779,145.3451,8.0073338,0.13379441,0.0,0,8.8581219,0.0,0.008526477,100.12811,9.8918419,300.70624,-9.3189363
1781,1781,145.3455,8.5133009,0.23569873,0.0,0,8.7995939,0.0,0.015114989,106.17402,9.8185444,301.0289,-9.3162355
1783,1783,145.3459,8.9622698,0.3123163,0.0,0,8.7416534,0.0,0.02060017,111.14706,9.741312,301.35156,-9.317049
1785,1785,145.3463,9.5588198,0.37091962,0.0,0,8.6858492,0.0,0.024611507,118.09812,9.6607122,301.67422,-9.3168945
1787,1787,145.3467,10.25097,0.46217868,0.0,0,8.6301851,0.0,0.030897733,125.46857,9.5855131,301.99692,-9.3157272
1789,1789,145.3471,10.535151,0.48014617,0.0,0,8.5745211,0.0,0.032262933,130.04643,9.515564,302.31958,-9.314292
1791,1791,145.3475,10.229103,0.55796361,0.0,0,8.518857,0.0,0.03746568,125.36609,9.4521208,302.64224,-9.3149147
1793,1793,145.3479,10.81319,0.63012481,0.0,0,8.4631929,0.0,0.042512625,131.13239,9.3885603,302.96494,-9.3157415
1795,1795,145.3483,11.161323,0.66442603,0.0,0,8.4075289,0.0,0.04485409,135.68205,9.325696,303.2876,-9.3145981
1797,1797,145.3487,11.270274,0.76579297,0.0,0,8.3518648,0.0,0.051980492,136.24609,9.253005,303.61026,-9.313942
1799,1799,145.3491,11.195334,0.84642589,0.0,0,8.2962008,0.0,0.057347823,134.50011,9.1743107,303.93295,-9.3148031
1801,1801,145.3495,11.456161,0.91605902,0.0,0,8.2405367,0.0,0.062494997,136.63274,9.0956783,304.25562,-9.3132162
1803,1803,145.3499,11.670343,0.98129123,0.0,0,8.1848736,0.0,0.067516766,138.73383,9.0217438,304.57828,-9.3135395
1805,1805,145.3503,11.874211,1.0291084,0.0,0,8.1292095,0.0,0.070371591,140.6442,8.9563379,304.90097,-9.3142757
1807,1807,145.3507,11.830881,1.090099,0.0,0,8.0735445,0.0,0.075095065,139.83061,8.8948078,305.22363,-9.3137798
1809,1809,145.3511,11.952358,1.1456987,0.0,0,8.0196619,0.0,0.079079859,140.16135,8.8342104,305.5463,-9.3142281
1811,1811,145.3515,12.357093,1.2106072,0.0,0,7.9666953,0.0,0.083364092,144.40381,8.7750778,305.86896,-9.3137484
1813,1813,145.3519,12.284344,1.2819679,0.0,0,7.9137354,0.0,0.089035913,143.31081,8.7082663,306.19165,-9.3138819
1815,1815,145.3523,12.295153,1.3480507,0.0,0,7.860775,0.0,0.093553849,142.38394,8.6409988,306.51431,-9.3124008
1817,1817,145.3527,12.392362,1.4215606,0.0,0,7.8078156,0.0,0.098958038,142.87474,8.5705442,306.83698,-9.3130941
1819,1819,145.3531,12.612325,1.4688697,0.0,0,7.7548552,0.0,0.10304337,144.51956,8.5052919,307.15967,-9.3135815
1821,1821,145.3535,12.764504,1.5154175,0.0,0,7.7018952,0.0,0.10593809,146.25975,8.440012,307.48233,-9.3142719
1823,1823,145.3539,12.68294,1.5897269,0.0,0,7.6489348,0.0,0.1116371,144.39545,8.3818417,307.80499,-9.3149862
1825,1825,145.3543,12.876218,1.6383066,0.0,0,7.5959754,0.0,0.11547262,145.75278,8.324131,308.14493,-9.3133678
1827,1827,145.3547,13.033123,1.6949979,0.0,0,7.543015,0.0,0.11920121,147.21278,8.2635279,308.64005,-9.3130074
1829,1829,145.3551,13.110426,1.7673215,0.0,0,7.4900556,0.0,0.12513086,147.21298,8.2043982,309.13516,-9.3125286
1831,1831,145.3555,13.17999,1.8208286,0.0,0,7.4370952,0.0,0.12898688,147.43932,8.1433163,309.63028,-9.3126774
1833,1833,145.3559,13.191334,1.8892295,0.0,0,7.384666,0.0,0.13389729,146.76366,8.0750484,310.1254,-9.313509
1835,1835,145.3563,13.356185,1.9415871,0.0,0,7.3341718,0.0,0.13857831,147.84882,8.014905,310.62051,-9.3133497
1837,1837,145.3567,13.430509,1.9904085,0.0,0,7.2838035,0.0,0.14171349,148.35881,7.9600163,311.11566,-9.3118801
1839,1839,145.3571,13.525922,2.054374,0.0,0,7.2334356,0.0,0.14688683,148.68451,7.897438,311.61078,-9.3123255
1841,1841,145.3575,13.578757,2.0986619,0.0,0,7.1830673,0.0,0.15075147,148.63535,7.841949,312.1059,-9.3127403
1843,1843,145.3579,13.714948,2.1559637,0.0,0,7.132699,0.0,0.15430325,149.39125,7.7893205,312.60101,-9.313489
1845,1845,145.3583,13.812078,2.2120728,0.0,0,7.0823312,0.0,0.15922366,150.00893,7.7289157,313.09613,-9.3134336
1847,1847,145.3587,13.832365,2.2660656,0.0,0,7.0319633,0.0,0.16343464,149.47537,7.6729755,313.59125,-9.3132124
1849,1849,145.3591,13.907258,2.3319254,0.0,0,6.981595,0.0,0.16811186,149.5408,7.6166487,314.08636,-9.3119087
1851,1851,145.3595,14.021179,2.3754575,0.0,0,6.9312272,0.0,0.17238358,150.11342,7.5604167,314.58148,-9.3126392
1853,1853,145.3599,14.101214,2.4229026,0.0,0,6.8808589,0.0,0.17566423,150.57648,7.5090804,315.07663,-9.313179
1855,1855,145.3603,14.115678,2.4850171,0.0,0,6.8304915,0.0,0.18052384,149.99718,7.4575486,315.57175,-9.3145037
1857,1857,145.3607,14.223774,2.5217049,0.0,0,6.7801232,0.0,0.18407288,150.44394,7.4016023,316.06686,-9.3139954
1859,1859,145.3611,14.339737,2.5734785,0.0,0,6.7313666,0.0,0.18749569,151.30714,7.3515244,316.56198,-9.3127871
1861,1861,145.3615,14.399947,2.6297998,0.0,0,6.6834412,0.0,0.19228624,151.28926,7.2999873,317.0571,-9.3127241
1863,1863,145.3619,14.426359,2.6754298,0.0,0,6.6355214,0.0,0.19623941,150.9635,7.2463083,317.55222,-9.3140469
1865,1865,145.3623,14.478617,2.7340937,0.0,0,6.5876012,0.0,0.20048943,150.68201,7.1939883,318.04733,-9.3149977
1867,1867,145.3627,14.59604,2.7799661,0.0,0,6.5396814,0.0,0.20487507,151.21472,7.1468816,318.54248,-9.3145113
1869,1869,145.3631,14.701094,2.8261092,0.0,0,6.4917617,0.0,0.20842269,151.86685,7.0975089,319.0376,-9.3138304
1871,1871,145.3635,14.72404,2.8795781,0.0,0,6.4438419,0.0,0.21249045,151.57097,7.0488415,319.53271,-9.3141346
1873,1873,145.3639,14.792687,2.9193625,0.0,0,6.3959212,0.0,0.21645832,151.63977,7.0011873,320.02783,-9.3133059
1875,1875,145.3643,14.864172,2.9682879,0.0,0,6.3480015,0.0,0.21990979,151.9124,6.9517016,320.47693,-9.3143387
1877,1877,145.3647,14.967531,3.0185997,0.0,0,6.3000817,0.0,0.22419491,152.13501,6.9027138,320.66528,-9.3134184
1879,1879,145.3651,15.03805,3.0659132,0.0,0,6.252162,0.0,0.22859053,152.27945,6.8506808,320.85361,-9.3137255
1881,1881,145.3655,15.062582,3.1248779,0.0,0,6.2042418,0.0,0.2328185,151.87735,6.8031282,321.04196,-9.3131037
1883,1883,145.3659,15.136979,3.1662657,0.0,0,6.1568022,0.0,0.2367665,152.01723,6.7514668,321.23032,-9.312892
1885,1885,145.3663,15.210172,3.2105045,0.0,0,6.1111116,0.0,0.24065016,152.14038,6.7028298,321.41867,-9.3129396
1887,1887,145.3667,15.297267,3.26598,0.0,0,6.0655355,0.0,0.24452113,152.41692,6.6538663,321.60699,-9.3138618
1889,1889,145.3671,15.382064,3.301702,0.0,0,6.0199599,0.0,0.2484253,152.69238,6.6056933,321.79535,-9.3140268
1891,1891,145.3675,15.437905,3.3509395,0.0,0,5.9743834,0.0,0.25239673,152.68094,6.5570989,321.9837,-9.312974
1893,1893,145.3679,15.498919,3.4058094,0.0,0,5.9288073,0.0,0.25674355,152.57214,6.5076284,322.17206,-9.3123074
1895,1895,145.3683,15.557017,3.4465764,0.0,0,5.8832316,0.0,0.2610344,152.46385,6.4599023,322.36038,-9.3121672
1897,1897,145.3687,15.642801,3.4967725,0.0,0,5.8376555,0.0,0.26481095,152.69968,6.4148331,322.54874,-9.3132133
1899,1899,145.3691,15.729438,3.5463948,0.0,0,5.792079,0.0,0.26916787,152.95985,6.3639426,322.73709,-9.3138571
1901,1901,145.3695,15.777966,3.5867352,0.0,0,5.7465034,0.0,0.27318203,152.79889,6.3159771,322.92545,-9.3143005
1903,1903,145.3699,15.815597,3.6353714,0.0,0,5.7009273,0.0,0.27684695,152.67023,6.2680306,323.11377,-9.3132982
1905,1905,145.3703,15.890111,3.6839013,0.0,0,5.6553516,0.0,0.2814998,152.64377,6.2221637,323.30212,-9.3137903
1907,1907,145.3707,15.981729,3.7281618,0.0,0,5.6097751,0.0,0.28544992,152.91093,6.1745768,323.49048,-9.3135719
1909,1909,145.3711,16.048195,3.7748098,0.0,0,5.5656581,0.0,0.28914499,152.95865,6.1316123,323.67883,-9.3142672
1911,1911,145.3715,16.086927,3.8202217,0.0,0,5.5222936,0.0,0.29388642,152.68863,6.0848513,323.86716,-9.3136253
1913,1913,145.3719,16.141073,3.8651314,0.0,0,5.4789333,0.0,0.29753214,152.5508,6.0386987,324.05551,-9.3140354
1915,1915,145.3723,16.215288,3.9092338,0.0,0,5.4355731,0.0,0.30136275,152.67004,5.9921942,324.24387,-9.3139791
1917,1917,145.3727,16.310936,3.9541645,0.0,0,5.3922133,0.0,0.30609876,152.81241,5.9473042,324.43222,-9.3131981
1919,1919,145.3731,16.369804,4.0034041,0.0,0,5.3488531,0.0,0.30979484,152.7755,5.9019556,324.62054,-9.3142452
1921,1921,145.3735,16.433275,4.0497093,0.0,0,5.3054934,0.0,0.31425819,152.73874,5.8547459,324.8089,-9.3136635
1923,1923,145.3739,16.499094,4.0922346,0.0,0,5.2621331,0.0,0.31863204,152.6064,5.8070045,324.99725,-9.3135023
1925,1925,145.3743,16.562378,4.1429734,0.0,0,5.2187734,0.0,0.3223142,152.64159,5.7617874,325.17017,-9.3135881
1927,1927,145.3747,16.637972,4.1839762,0.0,0,5.1754136,0.0,0.32677782,152.75258,5.7178574,325.28131,-9.3130264
1929,1929,145.3751,16.697144,4.2254486,0.0,0,5.1320534,0.0,0.3305929,152.68443,5.6715398,325.39246,-9.313426
1931,1931,145.3755,16.761812,4.2786627,0.0,0,5.0886931,0.0,0.33475718,152.67039,5.6254106,325.50363,-9.3138428
1933,1933,145.3759,16.814171,4.3166652,0.0,0,5.0457678,0.0,0.33930394,152.46689,5.5795255,325.61478,-9.3143206
1935,1935,145.3763,16.896296,4.3595848,0.0,0,5.0044241,0.0,0.34285647,152.6377,5.5344906,325.72592,-9.3143024
1937,1937,145.3767,16.98348,4.4113007,0.0,0,4.9631839,0.0,0.34749493,152.74298,5.4852142,325.8371,-9.3133469
1939,1939,145.3771,17.054787,4.4490695,0.0,0,4.9219437,0.0,0.35184938,152.66393,5.4426327,325.94824,-9.3133287
1941,1941,145.3775,17.111698,4.4969587,0.0,0,4.8807039,0.0,0.35562813,152.57559,5.3965125,326.05939,-9.3140306
1943,1943,145.3779,17.161655,4.5474458,0.0,0,4.8394637,0.0,0.36069676,152.32651,5.3527937,326.17056,-9.3150644
1945,1945,145.3783,17.236933,4.5822606,0.0,0,4.798224,0.0,0.36446133,152.39981,5.3093085,326.28171,-9.3146706
1947,1947,145.3787,17.335892,4.6292634,0.0,0,4.7569838,0.0,0.36819699,152.64705,5.2651601,326.39288,-9.3136177
1949,1949,145.3791,17.397284,4.6749887,0.0,0,4.7157435,0.0,0.37327158,152.48837,5.2223506,326.50403,-9.3135071
1951,1951,145.3795,17.451921,4.7144308,0.0,0,4.6745038,0.0,0.37701347,152.35899,5.1768384,326.61517,-9.3139553
1953,1953,145.3799,17.513329,4.7631812,0.0,0,4.6332641,0.0,0.38125503,152.20988,5.1345496,326.72635,-9.3135624
1955,1955,145.3803,17.584312,4.8049536,0.0,0,4.5920234,0.0,0.38622126,152.09351,5.0900741,326.83749,-9.3133802
1957,1957,145.3807,17.681122,4.8491316,0.0,0,4.5507836,0.0,0.38986096,152.37927,5.0449142,326.94864,-9.3133154
1959,1959,145.3811,17.738611,4.8934326,0.0,0,4.5108657,0.0,0.394283,152.2438,5.0047336,327.05981,-9.3138065
1961,1961,145.3815,17.794636,4.9293265,0.0,0,4.4716296,0.0,0.39862603,152.07736,4.9606795,327.17096,-9.313344
1963,1963,145.3819,17.848995,4.976418,0.0,0,4.4323974,0.0,0.40226889,151.95078,4.9170799,327.2821,-9.3130093
1965,1965,145.3823,17.940113,5.0172191,0.0,0,4.3931651,0.0,0.40680033,151.99652,4.8746457,327.39328,-9.3137712
1967,1967,145.3827,18.037621,5.0570302,0.0,0,4.3539338,0.0,0.41123551,152.23021,4.8302073,327.50443,-9.3140116
1969,1969,145.3831,18.095604,5.1099572,0.0,0,4.3147016,0.0,0.41545209,152.05176,4.78584,327.6156,-9.3130074
1971,1971,145.3835,18.157501,5.1456923,0.0,0,4.2754693,0.0,0.4200494,151.8494,4.7456069,327.72675,-9.31287
1973,1973,145.3839,18.212862,5.1844835,0.0,0,4.236237,0.0,0.42374551,151.74261,4.7028298,327.83789,-9.3141785
1975,1975,145.3843,18.305122,5.2340279,0.0,0,4.1970053,0.0,0.42815119,151.81343,4.6636877,327.94202,-9.314292
1977,1977,145.3847,18.412056,5.2654915,0.0,0,4.1577735,0.0,0.4325453,152.03238,4.619462,328.02509,-9.3140068
1979,1979,145.3851,18.460478,5.3088388,0.0,0,4.1185412,0.0,0.43613142,151.96814,4.5795889,328.10815,-9.3140163
1981,1981,145.3855,18.520802,5.3568306,0.0,0,4.0793095,0.0,0.44102633,151.66151,4.5379968,328.19122,-9.3131113
1983,1983,145.3859,18.599485,5.3889256,0.0,0,4.0404716,0.0,0.44520614,151.65292,4.496531,328.27426,-9.31388
1985,1985,145.3863,18.684124,5.4341326,0.0,0,4.0030656,0.0,0.44894689,151.79094,4.4553084,328.35733,-9.3142824
1987,1987,145.3867,18.788708,5.4776754,0.0,0,3.9657531,0.0,0.45413214,151.87292,4.4162083,328.4404,-9.3150167
1989,1989,145.3871,18.848352,5.5134735,0.0,0,3.928441,0.0,0.45803627,151.7364,4.3743463,328.52347,-9.3134775
1991,1991,145.3875,18.902895,5.5582418,0.0,0,3.8911293,0.0,0.46200103,151.57028,4.3338203,328.60651,-9.3129349
1993,1993,145.3879,18.990305,5.598804,0.0,0,3.8538172,0.0,0.46720243,151.43945,4.2923021,328.68958,-9.3127222
1995,1995,145.3883,19.088324,5.6375265,0.0,0,3.8165052,0.0,0.47091246,151.72539,4.2485418,328.77264,-9.3147993
1997,1997,145.3887,19.178185,5.6789336,0.0,0,3.7791932,0.0,0.4750495,151.80429,4.2095628,328.85568,-9.3141708
1999,1999,145.3891,19.253622,5.7145824,0.0,0,3.7418811,0.0,0.47981727,151.71275,4.1676006,328.93875,-9.314642
2001,2001,145.3895,19.310822,5.7563257,0.0,0,3.7045693,0.0,0.48337969,151.58543,4.1264806,329.02182,-9.3141298
2003,2003,145.3899,19.400904,5.7984672,0.0,0,3.6672573,0.0,0.48811474,151.59659,4.0847359,329.10489,-9.3127499
2005,2005,145.3903,19.506369,5.8347917,0.0,0,3.629945,0.0,0.49282154,151.65117,4.0451045,329.18793,-9.3115368
2007,2007,145.3907,19.591402,5.8843331,0.0,0,3.5926332,0.0,0.49701211,151.70605,4.0047026,329.271,-9.3118963
2009,2009,145.3911,19.665802,5.9195666,0.0,0,3.5565164,0.0,0.50170022,151.53143,3.9644458,329.35406,-9.3127871
2011,2011,145.3915,19.729729,5.9551287,0.0,0,3.5210166,0.0,0.50565571,151.4368,3.9254029,329.43713,-9.3142252
2013,2013,145.3919,19.82312,6.0019984,0.0,0,3.4855206,0.0,0.50997496,151.51189,3.8859284,329.52017,-9.3136721
2015,2015,145.3923,19.922913,6.0343976,0.0,0,3.4500246,0.0,0.51463842,151.55534,3.8457348,329.60324,-9.3131666
2017,2017,145.3927,20.008425,6.0744324,0.0,0,3.4145288,0.0,0.51863015,151.56369,3.8072245,329.68631,-9.311533
2019,2019,145.3931,20.084383,6.1218629,0.0,0,3.3790326,0.0,0.52359366,151.43723,3.7673168,329.76935,-9.3118305
2021,2021,145.3935,20.151785,6.152144,0.0,0,3.3435366,0.0,0.52800471,151.2254,3.7316015,329.85242,-9.3123446
2023,2023,145.3939,20.240463,6.1906261,0.0,0,3.3080406,0.0,0.53146285,151.38403,3.6908257,329.93549,-9.3128824
2025,2025,145.3943,20.355806,6.2322311,0.0,0,3.2725446,0.0,0.53637683,151.4736,3.651845,330.00607,-9.3123865
2027,2027,145.3947,20.441868,6.2621088,0.0,0,3.2370486,0.0,0.54041147,151.5459,3.6174474,330.04761,-9.3120661
2029,2029,145.3951,20.530678,6.3062181,0.0,0,3.2015524,0.0,0.54437482,151.58124,3.576472,330.08914,-9.3132782
2031,2031,145.3955,20.609528,6.3492918,0.0,0,3.1660566,0.0,0.55016887,151.34624,3.5387909,330.13068,-9.3131399
2033,2033,145.3959,20.678427,6.3811636,0.0,0,3.1309149,0.0,0.55384743,151.27303,3.4989789,330.17221,-9.3129587
2035,2035,145.3963,20.802906,6.4206886,0.0,0,3.0970623,0.0,0.55782336,151.58621,3.4669309,330.21371,-9.3134289
2037,2037,145.3967,20.91589,6.4538798,0.0,0,3.0632942,0.0,0.56280881,151.60234,3.4286988,330.25525,-9.3129015
2039,2039,145.3971,20.985411,6.4883804,0.0,0,3.0295262,0.0,0.5660606,151.66467,3.3911889,330.29678,-9.3127756
2041,2041,145.3975,21.050737,6.5295334,0.0,0,2.9957583,0.0,0.57066876,151.44972,3.3541577,330.33832,-9.3130703
2043,2043,145.3979,21.149956,6.5639224,0.0,0,2.9619904,0.0,0.57579368,151.34615,3.3151255,330.37985,-9.3133097
2045,2045,145.3983,21.259893,6.6055107,0.0,0,2.9282222,0.0,0.57950741,151.49806,3.2826457,330.42139,-9.311862
2047,2047,145.3987,21.369598,6.6402955,0.0,0,2.894454,0.0,0.58424532,151.59502,3.2447791,330.46292,-9.3116951
2049,2049,145.3991,21.440163,6.6700454,0.0,0,2.8606861,0.0,0.58837473,151.50177,3.2069347,330.50443,-9.3123522
2051,2051,145.3995,21.512491,6.7139044,0.0,0,2.8269181,0.0,0.59222847,151.48483,3.1714664,330.54596,-9.3127241
2053,2053,145.3999,21.609741,6.7434015,0.0,0,2.7931502,0.0,0.59700131,151.39314,3.1346216,330.58749,-9.3127136
2055,2055,145.4003,21.734165,6.7761941,0.0,0,2.7593822,0.0,0.60068476,151.67006,3.0979326,330.62903,-9.3119602
2057,2057,145.4007,21.842743,6.8201618,0.0,0,2.7256143,0.0,0.60521257,151.76282,3.0617714,330.67056,-9.3115473
2059,2059,145.4011,21.913198,6.8470964,0.0,0,2.6929309,0.0,0.60994786,151.54741,3.0272281,330.7121,-9.3118677
2061,2061,145.4015,21.999187,6.8831148,0.0,0,2.6608074,0.0,0.61345708,151.59091,2.9932768,330.7536,-9.3116312
2063,2063,145.4019,22.101341,6.9232616,0.0,0,2.6286871,0.0,0.61816561,151.56293,2.9563715,330.79514,-9.311408
2065,2065,145.4023,22.224648,6.9473214,0.0,0,2.5965672,0.0,0.62225497,151.80133,2.9233031,330.83667,-9.3111906
2067,2067,145.4027,22.322613,6.9844737,0.0,0,2.5644472,0.0,0.62564856,152.01642,2.8905988,330.8782,-9.3110762
2069,2069,145.4031,22.406118,7.0193853,0.0,0,2.5323269,0.0,0.63071829,151.76775,2.8565171,330.91974,-9.3117476
2071,2071,145.4035,22.483368,7.0465355,0.0,0,2.5002072,0.0,0.63451982,151.73515,2.8241622,330.96127,-9.3115864
2073,2073,145.4039,22.602186,7.0860014,0.0,0,2.4680872,0.0,0.63836527,151.88712,2.7938275,331.00278,-9.311717
2075,2075,145.4043,22.728346,7.1181884,0.0,0,2.4359672,0.0,0.64352524,151.97145,2.7607918,331.03662,-9.3119116
2077,2077,145.4047,22.826372,7.147831,0.0,0,2.4038472,0.0,0.64691198,152.18234,2.7273648,331.05618,-9.3118849
2079,2079,145.4051,22.902945,7.1837616,0.0,0,2.3717272,0.0,0.6510281,152.05629,2.6941333,331.07571,-9.3111582
2081,2081,145.4055,22.993046,7.213007,0.0,0,2.339607,0.0,0.65599561,151.89455,2.6603124,331.09525,-9.3112888
2083,2083,145.4059,23.118366,7.2479858,0.0,0,2.3078086,0.0,0.65919143,152.15562,2.6302412,331.11481,-9.3114386
2085,2085,145.4063,23.251406,7.2801809,0.0,0,2.2771802,0.0,0.66362101,152.35324,2.5976067,331.13434,-9.3121872
2087,2087,145.4067,23.343931,7.3056693,0.0,0,2.2466278,0.0,0.66788292,152.34363,2.5632572,331.1539,-9.3112173
2089,2089,145.4071,23.430647,7.3459063,0.0,0,2.2160761,0.0,0.67162079,152.28242,2.5327568,331.17343,-9.3104506
2091,2091,145.4075,23.511658,7.3734961,0.0,0,2.185524,0.0,0.6762861,152.19698,2.501956,331.19299,-9.3111372
2093,2093,145.4079,23.645679,7.4017911,0.0,0,2.1549721,0.0,0.68010169,152.40668,2.4701946,331.21252,-9.3117762
2095,2095,145.4083,23.790745,7.4415736,0.0,0,2.1244199,0.0,0.68391252,152.72873,2.4356287,331.23209,-9.3121319
2097,2097,145.4087,23.875681,7.4626575,0.0,0,2.093868,0.0,0.68836939,152.67427,2.4070101,331.25162,-9.3109884
2099,2099,145.4091,23.971579,7.4938397,0.0,0,2.0633161,0.0,0.69181418,152.74561,2.3758385,331.27115,-9.3111553
2101,2101,145.4095,24.085094,7.5338964,0.0,0,2.0327642,0.0,0.69674134,152.68622,2.3417382,331.29071,-9.3112526
2103,2103,145.4099,24.219076,7.5554743,0.0,0,2.002212,0.0,0.70089084,152.88335,2.3114059,331.31024,-9.3111763
2105,2105,145.4103,24.347452,7.5888748,0.0,0,1.9716599,0.0,0.70416427,153.24614,2.2839856,331.3298,-9.3110161
2107,2107,145.4107,24.455805,7.6246247,0.0,0,1.941108,0.0,0.70930618,153.0865,2.2501478,331.34933,-9.3096962
2109,2109,145.4111,24.549862,7.6464858,0.0,0,1.9115354,0.0,0.71300513,153.17024,2.2198322,331.3689,-9.3106823
2111,2111,145.4115,24.675648,7.6811795,0.0,0,1.8824683,0.0,0.71650988,153.39389,2.1916423,331.38843,-9.3111353
2113,2113,145.4119,24.811068,7.7126384,0.0,0,1.8534042,0.0,0.72184759,153.39658,2.1585889,331.40799,-9.311183
2115,2115,145.4123,24.941141,7.73804,0.0,0,1.8243402,0.0,0.72530115,153.70026,2.1273303,331.42752,-9.3104868
2117,2117,145.4127,25.05372,7.7715821,0.0,0,1.7952763,0.0,0.72905135,153.83691,2.0986116,331.44705,-9.3108597
2119,2119,145.4131,25.155981,7.7991624,0.0,0,1.7662122,0.0,0.73419541,153.64684,2.0669508,331.46661,-9.3101768
2121,2121,145.4135,25.27614,7.8295903,0.0,0,1.7371483,0.0,0.73746538,153.86374,2.0391445,331.48615,-9.3096113
2123,2123,145.4139,25.402847,7.8613968,0.0,0,1.7080842,0.0,0.74178421,153.98157,2.0113704,331.50571,-9.3094425
2125,2125,145.4143,25.55154,7.8840976,0.0,0,1.6790203,0.0,0.74610537,154.20622,1.9784207,331.50668,-9.309763
2127,2127,145.4147,25.666288,7.9176521,0.0,0,1.6499562,0.0,0.74941134,154.38174,1.9510739,331.4798,-9.3103523
2129,2129,145.4151,25.795961,7.946106,0.0,0,1.6208922,0.0,0.75407839,154.45677,1.9161623,331.45294,-9.3092613
2131,2131,145.4155,25.910282,7.972033,0.0,0,1.5918282,0.0,0.75847447,154.45348,1.889932,331.42606,-9.3094683
2133,2133,145.4159,26.060547,8.0109091,0.0,0,1.5630547,0.0,0.76221955,154.73477,1.859512,331.3992,-9.3093052
2135,2135,145.4163,26.202269,8.0339499,0.0,0,1.5353372,0.0,0.76701081,154.8817,1.8297977,331.37231,-9.3096428
2137,2137,145.4167,26.332573,8.0588198,0.0,0,1.5076891,0.0,0.77036774,155.09656,1.8019881,331.34543,-9.3101978
2139,2139,145.4171,26.437662,8.095089,0.0,0,1.4800411,0.0,0.77446556,155.05685,1.7737843,331.31857,-9.3100386
2141,2141,145.4175,26.575588,8.1142435,0.0,0,1.4523932,0.0,0.77895927,155.16287,1.7464812,331.29169,-9.3105421
2143,2143,145.4179,26.730961,8.1442394,0.0,0,1.4247452,0.0,0.78221047,155.58,1.7127818,331.26483,-9.3105679
2145,2145,145.4183,26.874857,8.181695,0.0,0,1.3970972,0.0,0.78742069,155.65215,1.6885613,331.23795,-9.3096619
2147,2147,145.4187,27.001776,8.1998453,0.0,0,1.3694493,0.0,0.79152274,155.76138,1.6620973,331.21109,-9.3093462
2149,2149,145.4191,27.125252,8.2304554,0.0,0,1.3418012,0.0,0.79465282,155.95265,1.6342403,331.1842,-9.3094645
2151,2151,145.4195,27.258429,8.2631931,0.0,0,1.3141533,0.0,0.80019611,155.82729,1.6070256,331.15732,-9.3097076
2153,2153,145.4199,27.419804,8.2845573,0.0,0,1.2865052,0.0,0.80393958,156.17624,1.5790112,331.13046,-9.3095894
2155,2155,145.4203,27.585869,8.3164616,0.0,0,1.2588573,0.0,0.80732089,156.64008,1.5491827,331.10358,-9.309824
2157,2157,145.4207,27.710468,8.3432837,0.0,0,1.2312093,0.0,0.81261098,156.52979,1.5193661,331.07672,-9.3101521
2159,2159,145.4211,27.844374,8.3673935,0.0,0,1.2044512,0.0,0.8157919,156.75916,1.4955655,331.04984,-9.3097248
2161,2161,145.4215,27.984735,8.3992605,0.0,0,1.1781523,0.0,0.81984961,156.86266,1.4662662,331.02298,-9.3080692
2163,2163,145.4219,28.164179,8.4225454,0.0,0,1.1518563,0.0,0.82498133,157.06859,1.4371156,330.99609,-9.3078346
2165,2165,145.4223,28.338392,8.4524155,0.0,0,1.1255603,0.0,0.82816654,157.52974,1.4102912,330.96924,-9.3089371
2167,2167,145.4227,28.462252,8.4835272,0.0,0,1.0992643,0.0,0.83293056,157.50478,1.3792254,330.94235,-9.3094988
2169,2169,145.4231,28.593075,8.505661,0.0,0,1.0729682,0.0,0.83769053,157.44936,1.3534335,330.91547,-9.3088942
2171,2171,145.4235,28.751705,8.5382071,0.0,0,1.0466722,0.0,0.84093416,157.80544,1.326046,330.88861,-9.3074465
2173,2173,145.4239,28.936842,8.5597811,0.0,0,1.0203762,0.0,0.84528285,158.11864,1.2981108,330.86172,-9.3081646
2175,2175,145.4243,29.105654,8.5798674,0.0,0,0.99408025,0.0,0.84875816,158.49879,1.2688926,330.77658,-9.3085852
2177,2177,145.4247,29.23303,8.6179705,0.0,0,0.96778423,0.0,0.85290855,158.55757,1.2415696,330.62024,-9.308527
2179,2179,145.4251,29.367275,8.6392012,0.0,0,0.94148827,0.0,0.85809827,158.4576,1.2145725,330.4639,-9.3083229
2181,2181,145.4255,29.532391,8.6662331,0.0,0,0.91519231,0.0,0.86175734,158.76898,1.1898168,330.30756,-9.3077898
2183,2183,145.4259,29.734274,8.7014399,0.0,0,0.88916039,0.0,0.86632454,159.11426,1.1626128,330.15118,-9.3079605
2185,2185,145.4263,29.905035,8.7163496,0.0,0,0.86408937,0.0,0.87067193,159.3342,1.1367759,329.99484,-9.3065434
2187,2187,145.4267,30.044388,8.7414446,0.0,0,0.83908123,0.0,0.87318367,159.67249,1.109113,329.8385,-9.3076849
2189,2189,145.4271,30.190258,8.7727623,0.0,0,0.8140732,0.0,0.8782475,159.60176,1.0838171,329.68213,-9.3080587
2191,2191,145.4275,30.366869,8.7894754,0.0,0,0.78906524,0.0,0.88233358,159.89517,1.0589896,329.52579,-9.308898
2193,2193,145.4279,30.563448,8.8219395,0.0,0,0.76405728,0.0,0.88571095,160.39568,1.031634,329.36945,-9.3078871
2195,2195,145.4283,30.733727,8.8511496,0.0,0,0.73904926,0.0,0.89181828,160.32448,1.0044681,329.2131,-9.3078299
2197,2197,145.4287,30.889923,8.8705883,0.0,0,0.71404123,0.0,0.89499599,160.61519,0.97879028,329.05673,-9.3071337
2199,2199,145.4291,31.058556,8.9000378,0.0,0,0.68903327,0.0,0.89860713,160.86301,0.95332152,328.90039,-9.3072815
2201,2201,145.4295,31.258928,8.9216166,0.0,0,0.66402531,0.0,0.90384728,161.10944,0.92906284,328.74405,-9.3069429
2203,2203,145.4299,31.462002,8.946022,0.0,0,0.63901722,0.0,0.90667033,161.71103,0.89847553,328.58768,-9.3078356
2205,2205,145.4303,31.640102,8.9746914,0.0,0,0.61400926,0.0,0.91108364,161.89633,0.87947226,328.43134,-9.3080559
2207,2207,145.4307,31.817797,8.9964752,0.0,0,0.58900124,0.0,0.91638005,161.95445,0.84907323,328.27499,-9.3075323
2209,2209,145.4311,31.996197,9.0269871,0.0,0,0.56478834,0.0,0.91962153,162.32742,0.82270473,328.11865,-9.3071127
2211,2211,145.4315,32.190605,9.0504532,0.0,0,0.54098582,0.0,0.92434281,162.56575,0.79370528,327.96228,-9.3067799
2213,2213,145.4319,32.406757,9.0691023,0.0,0,0.51718581,0.0,0.9283812,162.96994,0.7696681,327.80594,-9.3060675
2215,2215,145.4323,32.59845,9.1029882,0.0,0,0.49338579,0.0,0.93213552,163.33243,0.74231553,327.6496,-9.3056479
2217,2217,145.4327,32.776138,9.1237917,0.0,0,0.46958581,0.0,0.93711215,163.35167,0.71582717,327.49323,-9.3069658
2219,2219,145.4331,32.970879,9.1487017,0.0,0,0.44578579,0.0,0.94132137,163.67923,0.68973494,327.33688,-9.3073015
2221,2221,145.4335,33.191391,9.1833439,0.0,0,0.42198581,0.0,0.94562513,163.99678,0.6661014,327.18054,-9.3065472
2223,2223,145.4339,33.421585,9.1981344,0.0,0,0.39818579,0.0,0.95037079,164.40277,0.6370073,327.0242,-9.3063669
2225,2225,145.4343,33.619335,9.2215843,0.0,0,0.37438577,0.0,0.95330834,164.93411,0.61242968,326.92343,-9.3062067
2227,2227,145.4347,33.81662,9.2547808,0.0,0,0.35058579,0.0,0.95847374,165.01987,0.5866164,326.87823,-9.3059034
2229,2229,145.4351,34.002846,9.2692032,0.0,0,0.3267858,0.0,0.96280456,165.25536,0.56215948,326.83304,-9.3055992
2231,2231,145.4355,34.230679,9.2981834,0.0,0,0.30298579,0.0,0.96601111,165.7939,0.53899622,326.78784,-9.3060932
2233,2233,145.4359,34.467178,9.3281679,0.0,0,0.27942529,0.0,0.97212446,165.87808,0.51264584,326.74265,-9.3048468