File: clean data/testID_0243.csv
level_0,index,Time(sec),Force(kN),Jaw(mm),PowAngle(deg),Power(W),Pram,PTemp,Strain,Stress(MPa),Stroke(mm),TC1(C),wedge(mm)
2246,2246,178.7052,1.4996816,0.0081808716,0.0,0,9.9698629,0.0,0.00061489915,18.750771,10.06811,400.58441,-9.2638531
2257,2257,178.7074,2.7633476,0.013025139,0.0,0,9.9368629,0.0,0.00089297787,34.669178,10.037214,400.81,-9.2635088
2268,2268,178.7096,4.3373241,0.028784808,0.0,0,9.903863,0.0,0.001965438,54.797882,10.010743,401.03561,-9.2627983
2279,2279,178.7118,5.3614273,0.048996992,0.0,0,9.870863,0.0,0.003108782,67.928864,9.9807405,401.60046,-9.2607069
2290,2290,178.714,5.6729536,0.082298547,0.0,0,9.837863,0.0,0.0055187461,71.736259,9.9392757,404.69571,-9.2614918
2301,2301,178.7162,5.8119302,0.11890351,0.0,0,9.804863,0.0,0.0078465138,73.336433,9.9039478,407.79099,-9.2609282
2312,2312,178.7184,5.9132261,0.16024694,0.0,0,9.771863,0.0,0.010822993,74.445221,9.8627739,410.88626,-9.26019
2323,2323,178.7206,5.9530172,0.19806321,0.0,0,9.738863,0.0,0.013119508,74.724258,9.8235455,413.98154,-9.2596197
2334,2334,178.7228,5.9565806,0.23070754,0.0,0,9.705863,0.0,0.015545019,74.574242,9.785881,417.06091,-9.2604065
2345,2345,178.725,5.9360394,0.262079,0.0,0,9.6728621,0.0,0.017465269,74.313858,9.7511606,420.12888,-9.260746
2356,2356,178.7272,5.9478025,0.29675901,0.0,0,9.639863,0.0,0.020090934,74.168915,9.7182817,423.19687,-9.2602129
2367,2367,178.7294,5.9382868,0.32900316,0.0,0,9.606863,0.0,0.021879114,73.947098,9.689127,426.26483,-9.2610188
2378,2378,178.7316,5.9432278,0.35561395,0.0,0,9.573863,0.0,0.02412284,73.871254,9.6557312,429.2092,-9.2609997
2389,2389,178.7338,5.9794064,0.38888714,0.0,0,9.540863,0.0,0.02600028,74.167732,9.622263,429.55957,-9.2617655
2400,2400,178.736,6.026854,0.4198828,0.0,0,9.507863,0.0,0.028625138,74.510826,9.593976,429.90994,-9.2616673
2411,2411,178.7382,6.0514822,0.45494053,0.0,0,9.4750338,0.0,0.030515822,74.691551,9.5608683,430.26031,-9.2606897
2422,2422,178.7404,6.070684,0.48275828,0.0,0,9.4428425,0.0,0.032865554,74.684624,9.5235205,430.61069,-9.2611284
2433,2433,178.7426,6.0805206,0.51803368,0.0,0,9.4106531,0.0,0.03497351,74.761925,9.4941893,430.90384,-9.2614803
2444,2444,178.7448,6.0925307,0.54908329,0.0,0,9.3784628,0.0,0.037535034,74.697861,9.4549522,431.14185,-9.262105
2455,2455,178.747,6.1151271,0.58669633,0.0,0,9.3462715,0.0,0.039528295,74.933266,9.4271708,431.37982,-9.2634697
2466,2466,178.7492,6.1263037,0.61445349,0.0,0,9.3140821,0.0,0.041965306,74.799995,9.3957586,431.61783,-9.2610826
2477,2477,178.7514,6.129837,0.64988017,0.0,0,9.2818909,0.0,0.044082399,74.692528,9.3602428,431.85583,-9.2605486
2488,2488,178.7536,6.1638069,0.68157035,0.0,0,9.2497005,0.0,0.046763241,74.797607,9.3242521,432.00378,-9.2620735
2499,2499,178.7558,6.1872692,0.72245455,0.0,0,9.2175102,0.0,0.048968975,74.835442,9.2875433,432.1492,-9.2625227
2510,2510,178.758,6.1903024,0.74609053,0.0,0,9.1853199,0.0,0.051151644,74.870232,9.2591734,432.29465,-9.2629128
2521,2521,178.7602,6.1786366,0.7776528,0.0,0,9.1531296,0.0,0.053031351,74.569405,9.2270937,432.44006,-9.2624102
2532,2532,178.7624,6.2082381,0.80411029,0.0,0,9.1209383,0.0,0.055307288,74.776741,9.1978416,432.55664,-9.2628393
2543,2543,178.7646,6.2113523,0.8412143,0.0,0,9.088748,0.0,0.057474785,74.719894,9.1655798,432.63599,-9.2610226
2554,2554,178.7668,6.2363391,0.86876839,0.0,0,9.0565586,0.0,0.059725888,74.695824,9.13342,432.7153,-9.2606115
2565,2565,178.769,6.2413049,0.90238184,0.0,0,9.0243683,0.0,0.061854403,74.70723,9.1035452,432.79465,-9.2617521
2576,2576,178.7712,6.2987213,0.9336617,0.0,0,8.992178,0.0,0.06442266,75.167938,9.0657196,432.87396,-9.2626209
2587,2587,178.7734,6.317348,0.97270387,0.0,0,8.9599867,0.0,0.06679409,75.221802,9.0292988,432.9176,-9.2623711
2598,2598,178.7756,6.3572531,1.0006241,0.0,0,8.9277964,0.0,0.069090322,75.522758,8.9933023,432.95728,-9.2618923
2609,2609,178.7778,6.3692183,1.0350511,0.0,0,8.895606,0.0,0.071476191,75.486267,8.9617414,432.99692,-9.2619286
2620,2620,178.78,6.3649054,1.0654356,0.0,0,8.8634157,0.0,0.073697366,75.279411,8.9313574,433.03659,-9.2610188
2631,2631,178.7822,6.3611093,1.1032677,0.0,0,8.8312254,0.0,0.076252855,74.979202,8.8982382,433.06183,-9.2612543
2642,2642,178.7844,6.3656936,1.1298287,0.0,0,8.7990341,0.0,0.078254186,75.043144,8.8627892,433.06183,-9.2618923
2653,2653,178.7866,6.3629727,1.1601961,0.0,0,8.7668438,0.0,0.080508232,74.753326,8.8325863,433.06183,-9.26192
2664,2664,178.7888,6.3705139,1.1888582,0.0,0,8.7354145,0.0,0.08252693,74.72612,8.8030052,433.06183,-9.2621517
2675,2675,178.791,6.3956223,1.2258945,0.0,0,8.7047997,0.0,0.085262708,74.712296,8.7714272,433.06183,-9.2629862
2686,2686,178.7932,6.4559422,1.2550234,0.0,0,8.6741838,0.0,0.087271675,75.3368,8.7429781,433.06183,-9.2625837
2697,2697,178.7954,6.490881,1.2848586,0.0,0,8.643569,0.0,0.089569442,75.573555,8.707037,433.06183,-9.2617998
2708,2708,178.7976,6.4839196,1.3161461,0.0,0,8.6129532,0.0,0.091710418,75.347954,8.6738434,433.06183,-9.2611942
2719,2719,178.7998,6.4847865,1.3488469,0.0,0,8.5823383,0.0,0.094415739,75.173248,8.6412983,433.06183,-9.2625303
2730,2730,178.802,6.4933786,1.3816599,0.0,0,8.5517225,0.0,0.096373647,75.017197,8.6087246,433.07336,-9.2626705
2741,2741,178.8042,6.5047731,1.4097323,0.0,0,8.5211077,0.0,0.098762266,75.026199,8.5779943,433.11304,-9.2633581
2752,2752,178.8064,6.521409,1.440043,0.0,0,8.4904919,0.0,0.10072475,75.163353,8.5464211,433.15271,-9.2623053
2763,2763,178.8086,6.5319848,1.4727644,0.0,0,8.459878,0.0,0.10353188,74.980354,8.5154095,433.19235,-9.2616262
2774,2774,178.8108,6.5327959,1.5047771,0.0,0,8.4292622,0.0,0.10542952,74.848457,8.4834957,433.23203,-9.262248
2785,2785,178.813,6.5528021,1.5297246,0.0,0,8.3986473,0.0,0.10768194,74.902786,8.4564486,433.28168,-9.2620192
2796,2796,178.8152,6.5836287,1.5594921,0.0,0,8.3680325,0.0,0.10947168,75.11377,8.4231577,433.33456,-9.2623358
2807,2807,178.8174,6.5827994,1.5893409,0.0,0,8.3374176,0.0,0.11218148,74.971619,8.395484,433.38745,-9.2607975
2818,2818,178.8196,6.6190457,1.6217135,0.0,0,8.3068018,0.0,0.11408452,75.30616,8.3647261,433.44034,-9.261096
2829,2829,178.8218,6.6537204,1.6473895,0.0,0,8.2761879,0.0,0.11657357,75.421471,8.3355732,433.49036,-9.2622004
2840,2840,178.824,6.6646056,1.6822867,0.0,0,8.2455711,0.0,0.11868693,75.360214,8.3057213,433.53,-9.2614384
2851,2851,178.8262,6.6885986,1.7139523,0.0,0,8.2149563,0.0,0.12162105,75.398201,8.2707548,433.56967,-9.2635441
2862,2862,178.8284,6.6762857,1.7508353,0.0,0,8.1843414,0.0,0.12367247,75.148064,8.2375288,433.60934,-9.2620325
2873,2873,178.8306,6.7070231,1.7736951,0.0,0,8.1537256,0.0,0.12607625,75.223717,8.2080278,433.64899,-9.2611561
2884,2884,178.8328,6.7425804,1.8049499,0.0,0,8.1231108,0.0,0.12802099,75.483788,8.1788139,433.69769,-9.2614794
2895,2895,178.835,6.7755284,1.8344994,0.0,0,8.092495,0.0,0.13072163,75.707451,8.1449099,433.75058,-9.2614346
2906,2906,178.8372,6.7783284,1.8728911,0.0,0,8.0618811,0.0,0.13300738,75.537956,8.115591,433.80347,-9.2628736
2917,2917,178.8394,6.7665277,1.8963462,0.0,0,8.0323896,0.0,0.13536873,75.280006,8.0819063,433.85635,-9.2622118
2928,2928,178.8416,6.7826104,1.9297925,0.0,0,8.0032616,0.0,0.13748765,75.242935,8.049118,433.90347,-9.2624912
2939,2939,178.8438,6.7755194,1.9579792,0.0,0,7.974133,0.0,0.14015576,75.019386,8.0219059,433.91669,-9.2627068
2950,2950,178.846,6.7700157,1.9912467,0.0,0,7.9450049,0.0,0.1421141,74.743767,7.9922357,433.9299,-9.2632771
2961,2961,178.8482,6.7928991,2.0130985,0.0,0,7.9158769,0.0,0.14428218,74.861473,7.9647436,433.94315,-9.2630453
2972,2972,178.8504,6.8281989,2.0443046,0.0,0,7.8867493,0.0,0.14630571,75.019974,7.934341,433.95636,-9.2632504
2983,2983,178.8526,6.8622856,2.0687673,0.0,0,7.8576212,0.0,0.14854866,75.295853,7.9041557,433.97763,-9.2623558
2994,2994,178.8548,6.8825569,2.1064041,0.0,0,7.8284931,0.0,0.15105025,75.349365,7.874927,434.00406,-9.2615471
3005,3005,178.857,6.8791561,2.1306131,0.0,0,7.799365,0.0,0.15326084,75.126534,7.844944,434.03052,-9.2612543
3016,3016,178.8592,6.8842325,2.1610761,0.0,0,7.7702374,0.0,0.15542142,75.041412,7.817347,434.05695,-9.2633419
3027,3027,178.8614,6.9062309,2.1881285,0.0,0,7.7411094,0.0,0.15771095,75.062546,7.7870693,434.08774,-9.2621555
3038,3038,178.8636,6.9146318,2.2214704,0.0,0,7.7119808,0.0,0.16020286,75.032028,7.752377,434.17368,-9.2621794
3049,3049,178.8658,6.9428582,2.2446232,0.0,0,7.6828527,0.0,0.1621149,75.09642,7.7247,434.25961,-9.261096
3060,3060,178.868,6.9444318,2.2744734,0.0,0,7.6537251,0.0,0.16439657,75.114288,7.6955132,434.34555,-9.2618017
3071,3071,178.8702,6.9811702,2.3011274,0.0,0,7.6245971,0.0,0.16652355,75.189941,7.6707945,434.43149,-9.2610598
3082,3082,178.8724,7.0079985,2.33764,0.0,0,7.595469,0.0,0.1694206,75.326355,7.639545,434.49969,-9.2615385
3093,3093,178.8746,7.0142717,2.3631685,0.0,0,7.5663409,0.0,0.1712479,75.332886,7.6085238,434.55258,-9.2625208
3104,3104,178.8768,7.0019026,2.3887682,0.0,0,7.5372128,0.0,0.17354383,74.977509,7.5816545,434.60547,-9.2631693
3115,3115,178.879,7.0273166,2.4165564,0.0,0,7.5080848,0.0,0.17548908,74.999969,7.5482635,434.65836,-9.2616806
3126,3126,178.8812,7.0351744,2.4465461,0.0,0,7.4789567,0.0,0.17818443,74.921745,7.5244565,434.71124,-9.2614565
3137,3137,178.8834,7.0623574,2.4762948,0.0,0,7.4498286,0.0,0.18020554,75.060074,7.4922991,434.77075,-9.2609348
3148,3148,178.8856,7.0854058,2.5024645,0.0,0,7.420701,0.0,0.18266574,75.189018,7.4632907,434.83023,-9.2615671
3159,3159,178.8878,7.1379609,2.5334432,0.0,0,7.3916259,0.0,0.18477829,75.393173,7.4321523,434.88974,-9.2607622
3170,3170,178.89,7.1420989,2.5624855,0.0,0,7.3639112,0.0,0.18756625,75.402039,7.4046102,434.94922,-9.262435
3181,3181,178.8922,7.1642284,2.5937791,0.0,0,7.3362088,0.0,0.18949586,75.473282,7.3739567,435.01486,-9.2616062
3192,3192,178.8944,7.1654758,2.6180902,0.0,0,7.3085065,0.0,0.19204621,75.295303,7.3472605,435.08759,-9.2616262
3203,3203,178.8966,7.1572728,2.6491094,0.0,0,7.2808037,0.0,0.1940089,75.04866,7.3165517,435.16031,-9.2613277
3214,3214,178.8988,7.1519399,2.6758268,0.0,0,7.2531013,0.0,0.19678625,74.756668,7.2872505,435.23303,-9.2593088
3225,3225,178.901,7.178082,2.7068646,0.0,0,7.225399,0.0,0.19865106,74.931168,7.2609882,435.30576,-9.2617302
3236,3236,178.9032,7.1851516,2.7288265,0.0,0,7.1976972,0.0,0.20106313,74.82016,7.2353292,435.34781,-9.2615643
3247,3247,178.9054,7.221736,2.7595413,0.0,0,7.1699939,0.0,0.20309822,75.062454,7.2048116,435.38748,-9.2624655
3258,3258,178.9076,7.2423949,2.7840657,0.0,0,7.1422915,0.0,0.20564172,75.105301,7.1777196,435.42715,-9.2632093
3269,3269,178.9098,7.2723889,2.8192618,0.0,0,7.1145892,0.0,0.20773697,75.277412,7.1490097,435.4668,-9.2608032
3280,3280,178.912,7.2841897,2.8414931,0.0,0,7.0868874,0.0,0.21032467,75.19429,7.1203666,435.50388,-9.260726
3291,3291,178.9142,7.2959628,2.8708956,0.0,0,7.0591846,0.0,0.21212476,75.126511,7.0914168,435.53693,-9.2607918
3302,3302,178.9164,7.2802467,2.8944571,0.0,0,7.0314822,0.0,0.21477252,74.770576,7.0649204,435.56998,-9.2613888
3313,3313,178.9186,7.2862115,2.9313233,0.0,0,7.0037799,0.0,0.21696076,74.667595,7.0373244,435.60303,-9.2615223
3324,3324,178.9208,7.3073497,2.9501023,0.0,0,6.9760776,0.0,0.21925178,74.740692,7.0103292,435.63611,-9.2616215
3335,3335,178.923,7.3381996,2.9815581,0.0,0,6.9483747,0.0,0.22134449,74.889809,6.9798021,435.6748,-9.2618265
3346,3346,178.9252,7.3645921,3.0021341,0.0,0,6.9206724,0.0,0.22359473,74.936241,6.9536471,435.71445,-9.2617607
3357,3357,178.9274,7.4095078,3.0398083,0.0,0,6.8929706,0.0,0.22606769,75.237305,6.9275851,435.75412,-9.2607756
3368,3368,178.9296,7.4162688,3.061065,0.0,0,6.8652678,0.0,0.2284331,75.204521,6.8974409,435.79379,-9.2599897
3379,3379,178.9318,7.4388204,3.0895665,0.0,0,6.8375654,0.0,0.23041904,75.206726,6.8683572,435.82715,-9.2609386
3390,3390,178.934,7.438045,3.1137698,0.0,0,6.8098631,0.0,0.23281156,75.021095,6.8431444,435.84698,-9.2621355
3401,3401,178.9362,7.4312997,3.1487157,0.0,0,6.7821608,0.0,0.23529296,74.738266,6.8153071,435.86682,-9.262022
3412,3412,178.9384,7.4468889,3.1704273,0.0,0,6.7548633,0.0,0.2375638,74.791771,6.7872972,435.88663,-9.263072
3423,3423,178.9406,7.5036411,3.2018886,0.0,0,6.7285075,0.0,0.23993406,75.104866,6.7556071,435.90646,-9.2613182
3434,3434,178.9428,7.5318809,3.2247443,0.0,0,6.7021518,0.0,0.24211106,75.175186,6.7274346,435.92114,-9.2619066
3445,3445,178.945,7.5445175,3.2599294,0.0,0,6.6757956,0.0,0.24489069,75.243378,6.6998205,435.93436,-9.2605705
3456,3456,178.9472,7.5615788,3.2819357,0.0,0,6.6494393,0.0,0.24687773,75.225746,6.6755123,435.94757,-9.2594795
3467,3467,178.9494,7.5736299,3.3093891,0.0,0,6.6230836,0.0,0.24921714,75.138489,6.6448088,435.96078,-9.2598333
3478,3478,178.9516,7.5623717,3.3329861,0.0,0,6.5967274,0.0,0.25123224,74.852264,6.6172123,435.98212,-9.2601213
3489,3489,178.9538,7.5491152,3.3659866,0.0,0,6.5703716,0.0,0.25406867,74.551773,6.5919833,436.02841,-9.2604828
3500,3500,178.956,7.536612,3.3868046,0.0,0,6.5440154,0.0,0.25573596,74.306328,6.5655026,436.07468,-9.2621031
3511,3511,178.9582,7.5425816,3.4104602,0.0,0,6.5176597,0.0,0.25807047,74.181503,6.5428548,436.12094,-9.2621536
3522,3522,178.9604,7.5695119,3.4336121,0.0,0,6.4913034,0.0,0.25978285,74.300308,6.5160179,436.16724,-9.2617903
3533,3533,178.9626,7.5951562,3.4607842,0.0,0,6.4649477,0.0,0.26249424,74.396454,6.4925342,436.2182,-9.2622557
3544,3544,178.9648,7.6376595,3.4855783,0.0,0,6.4385915,0.0,0.26420814,74.671898,6.468215,436.27109,-9.2627964
3555,3555,178.967,7.6970081,3.511622,0.0,0,6.4122357,0.0,0.26684791,74.991959,6.4340448,436.32397,-9.2615137
3566,3566,178.9692,7.709239,3.5387771,0.0,0,6.3858795,0.0,0.26882157,75.005096,6.4149399,436.37683,-9.2617016
3577,3577,178.9714,7.7169032,3.566632,0.0,0,6.3595233,0.0,0.27174726,74.88488,6.3868356,436.42746,-9.2619495
3588,3588,178.9736,7.7242723,3.5951252,0.0,0,6.3331676,0.0,0.27360603,74.791611,6.3598456,436.4671,-9.2610111
3599,3599,178.9758,7.7477765,3.6163187,0.0,0,6.3068118,0.0,0.27611554,74.851479,6.3298588,436.50677,-9.2618685
3610,3610,178.978,7.7478738,3.6454237,0.0,0,6.2804561,0.0,0.27818817,74.760574,6.3036871,436.54645,-9.2615528
3621,3621,178.9802,7.7676611,3.6720581,0.0,0,6.2540998,0.0,0.28115061,74.636742,6.2806697,436.58609,-9.2614803
3632,3632,178.9824,7.7870708,3.7017584,0.0,0,6.2277441,0.0,0.28287888,74.739571,6.2515941,436.61734,-9.2617159
3643,3643,178.9846,7.8115072,3.7205248,0.0,0,6.2013879,0.0,0.28538954,74.811485,6.228723,436.6438,-9.2607355
3654,3654,178.9868,7.8686328,3.7500713,0.0,0,6.1750321,0.0,0.28732005,75.18924,6.1965852,436.67026,-9.2604542
3665,3665,178.989,7.8628759,3.7741218,0.0,0,6.1494155,0.0,0.29011816,75.000259,6.1737118,436.69669,-9.2599726
3676,3676,178.9912,7.8701262,3.8075354,0.0,0,6.1243486,0.0,0.29228696,74.831757,6.1469417,436.72049,-9.2619514
3687,3687,178.9934,7.8563457,3.8256936,0.0,0,6.0992823,0.0,0.29474127,74.53215,6.1225233,436.72049,-9.2609634
3698,3698,178.9956,7.8853674,3.8536348,0.0,0,6.0742154,0.0,0.29666609,74.598228,6.094614,436.72049,-9.2611074
3709,3709,178.9978,7.91399,3.8765137,0.0,0,6.0491486,0.0,0.29938456,74.622467,6.0673575,436.72049,-9.2613201
3720,3720,179.0,7.949738,3.9091167,0.0,0,6.0240817,0.0,0.30137989,74.886925,6.0464625,436.72049,-9.2607412
3731,3731,179.0022,7.9720869,3.9276009,0.0,0,5.9990149,0.0,0.30398634,74.887077,6.0125165,436.73538,-9.2604733
3742,3742,179.0044,7.9620504,3.957902,0.0,0,5.973948,0.0,0.30607957,74.690407,5.9909167,436.76184,-9.2608728
3753,3753,179.0066,7.9911947,3.9790113,0.0,0,5.9488811,0.0,0.30855569,74.733078,5.9678712,436.7883,-9.2621632
3764,3764,179.0088,7.9851761,4.0113525,0.0,0,5.9238143,0.0,0.31069905,74.543961,5.940877,436.81473,-9.2623587
3775,3775,179.011,7.9796538,4.0280232,0.0,0,5.8987479,0.0,0.31292206,74.266754,5.913466,436.84171,-9.2612133
3786,3786,179.0132,7.9914174,4.055408,0.0,0,5.8736811,0.0,0.31497791,74.277275,5.8908148,436.888,-9.2618809
3797,3797,179.0154,8.0082769,4.0748887,0.0,0,5.8486142,0.0,0.3171685,74.231522,5.8676696,436.93427,-9.2612219
3808,3808,179.0176,8.0436745,4.1071029,0.0,0,5.8235474,0.0,0.31964427,74.409615,5.8445697,436.98056,-9.2632971
3819,3819,179.0198,8.0827742,4.1252313,0.0,0,5.7984805,0.0,0.32174265,74.558273,5.8193445,437.02682,-9.2616405
3830,3830,179.022,8.1537046,4.1541653,0.0,0,5.7734137,0.0,0.32411888,75.059364,5.789886,437.06012,-9.2610188
3841,3841,179.0242,8.1462402,4.1751194,0.0,0,5.7483468,0.0,0.32630101,74.799767,5.7636256,437.07996,-9.2603445
3852,3852,179.0264,8.1659718,4.2075067,0.0,0,5.72328,0.0,0.32896143,74.846848,5.7393928,437.09979,-9.2607574
3863,3863,179.0286,8.1621819,4.2279425,0.0,0,5.6982136,0.0,0.33114386,74.637321,5.7137361,437.11963,-9.26122
3874,3874,179.0308,8.1553726,4.2546558,0.0,0,5.6731462,0.0,0.33355895,74.398155,5.6889844,437.13943,-9.2604065
3885,3885,179.033,8.178319,4.2763362,0.0,0,5.6480799,0.0,0.33555442,74.390373,5.6635981,437.14667,-9.2604132
3896,3896,179.0352,8.2399511,4.3078251,0.0,0,5.623013,0.0,0.33854449,74.751717,5.6398826,437.15329,-9.2607985
3907,3907,179.0374,8.2579222,4.3290114,0.0,0,5.5979457,0.0,0.34038627,74.810791,5.6134634,437.15988,-9.2599382
3918,3918,179.0396,8.3029766,4.3544984,0.0,0,5.5739112,0.0,0.34295142,75.016182,5.586731,437.1665,-9.2611923
3929,3929,179.0418,8.28053,4.3790202,0.0,0,5.5500631,0.0,0.34499988,74.582298,5.5652404,437.17313,-9.261857
3940,3940,179.044,8.2884016,4.4063101,0.0,0,5.5262156,0.0,0.34797591,74.468788,5.5383997,437.17972,-9.2619629
3951,3951,179.0462,8.2878809,4.428905,0.0,0,5.5023675,0.0,0.34970143,74.386787,5.5113692,437.18631,-9.2606363
3962,3962,179.0484,8.2967844,4.4489231,0.0,0,5.4785194,0.0,0.35193938,74.306305,5.4907293,437.19293,-9.2620926
3973,3973,179.0506,8.3022709,4.4723592,0.0,0,5.4546714,0.0,0.3537744,74.238579,5.4692783,437.19952,-9.261817
3984,3984,179.0528,8.3580713,4.4990344,0.0,0,5.4308233,0.0,0.35687107,74.401314,5.4407077,437.21198,-9.2621164
3995,3995,179.055,8.3970604,4.526217,0.0,0,5.4069753,0.0,0.35877922,74.6007,5.4177461,437.22522,-9.2620564
4006,4006,179.0572,8.4106855,4.5454578,0.0,0,5.3831272,0.0,0.36129928,74.578247,5.3935485,437.23843,-9.2606993
4017,4017,179.0594,8.4213228,4.5695391,0.0,0,5.3592792,0.0,0.36282459,74.572731,5.3723392,437.25165,-9.2600594
4028,4028,179.0616,8.4092817,4.5906157,0.0,0,5.3354311,0.0,0.36577353,74.298096,5.3447247,437.26718,-9.2613468
4039,4039,179.0638,8.4078913,4.619947,0.0,0,5.3115835,0.0,0.3677606,74.175049,5.3240156,437.28699,-9.2617331
4050,4050,179.066,8.4454746,4.6389823,0.0,0,5.287735,0.0,0.37031308,74.261902,5.2977076,437.30682,-9.2625551
4061,4061,179.0682,8.4597921,4.6638918,0.0,0,5.2638869,0.0,0.37203339,74.24424,5.2782192,437.32666,-9.2620316
4072,4072,179.0704,8.470005,4.6827121,0.0,0,5.2400393,0.0,0.37472484,74.213089,5.2541494,437.3465,-9.2624283
4083,4083,179.0726,8.4947205,4.7127795,0.0,0,5.2161913,0.0,0.3765063,74.214935,5.2327085,437.37167,-9.2622766
4094,4094,179.0748,8.5481491,4.727756,0.0,0,5.1923432,0.0,0.37902862,74.460571,5.2093797,437.3981,-9.2612848
4105,4105,179.077,8.6074333,4.7570972,0.0,0,5.1684952,0.0,0.38109335,74.848755,5.1845913,437.42456,-9.2612934
4116,4116,179.0792,8.6701412,4.7786288,0.0,0,5.1446471,0.0,0.38394189,75.237854,5.1586094,437.45099,-9.2605343
4127,4127,179.0814,8.676446,4.8103929,0.0,0,5.1207991,0.0,0.38607565,75.107574,5.1313782,437.47522,-9.262023
4138,4138,179.0836,8.6760807,4.8273587,0.0,0,5.096951,0.0,0.38878298,74.9188,5.1045442,437.49353,-9.2614174
4149,4149,179.0858,8.6876497,4.8561149,0.0,0,5.073103,0.0,0.39087728,74.786148,5.082109,437.51187,-9.2613096
4160,4160,179.088,8.6788292,4.8765435,0.0,0,5.0493946,0.0,0.39362815,74.607758,5.0601377,437.53018,-9.2605667
4171,4171,179.0902,8.7025146,4.9085951,0.0,0,5.0267124,0.0,0.39588422,74.512383,5.0308638,437.54852,-9.2606459
4182,4182,179.0924,8.7215958,4.925169,0.0,0,5.0040302,0.0,0.39827034,74.519241,5.0109081,437.56018,-9.2600489
4193,4193,179.0946,8.7493238,4.9510751,0.0,0,4.981348,0.0,0.40034574,74.648361,4.9915838,437.56018,-9.2606707
4204,4204,179.0968,8.8002911,4.9693851,0.0,0,4.9586663,0.0,0.40265551,74.924034,4.9691896,437.56018,-9.2605162
4215,4215,179.099,8.8157959,5.0006704,0.0,0,4.9359846,0.0,0.40520549,74.89325,4.9405503,437.56018,-9.2611132
4226,4226,179.1012,8.8090248,5.0153084,0.0,0,4.9133024,0.0,0.40715271,74.603951,4.9180598,437.56018,-9.2604637
4237,4237,179.1034,8.8035736,5.0430799,0.0,0,4.8906202,0.0,0.40960476,74.411629,4.8950825,437.54926,-9.2617149
4248,4248,179.1056,8.794446,5.0626936,0.0,0,4.8679385,0.0,0.41181594,74.188148,4.8775434,437.53601,-9.2626915
4259,4259,179.1078,8.7917538,5.089704,0.0,0,4.8452563,0.0,0.4142206,73.984253,4.8558717,437.5228,-9.2615528
4270,4270,179.11,8.8143921,5.1027455,0.0,0,4.8225746,0.0,0.41587391,74.025124,4.8280029,437.50958,-9.261735
4281,4281,179.1122,8.897378,5.1279531,0.0,0,4.7998919,0.0,0.41828212,74.491737,4.8077331,437.43481,-9.259634
4292,4292,179.1144,8.9491673,5.1478863,0.0,0,4.7772102,0.0,0.42022264,74.805374,4.7869749,437.21005,-9.2606802
4303,4303,179.1166,8.9843302,5.1760483,0.0,0,4.7545285,0.0,0.42320198,74.840439,4.7640505,436.98529,-9.2624264
4314,4314,179.1188,8.9893408,5.1950912,0.0,0,4.7318463,0.0,0.42503953,74.784302,4.7388921,436.76053,-9.2621689
4325,4325,179.121,8.9955797,5.218678,0.0,0,4.7091641,0.0,0.42773253,74.67141,4.7165403,436.53577,-9.2604208
4336,4336,179.1232,9.0086918,5.2388773,0.0,0,4.6864824,0.0,0.42943895,74.637611,4.6953564,436.17133,-9.2611046
4347,4347,179.1254,9.0471382,5.2646952,0.0,0,4.6638002,0.0,0.43254396,74.731071,4.6722198,435.76144,-9.2615252
4358,4358,179.1276,9.0754461,5.2889705,0.0,0,4.6411185,0.0,0.4344376,74.846245,4.6506243,435.35159,-9.260726
4369,4369,179.1298,9.0989838,5.3091221,0.0,0,4.6184363,0.0,0.43704075,74.812126,4.625103,434.94171,-9.2611094
4380,4380,179.132,9.1271582,5.3323345,0.0,0,4.5957541,0.0,0.43894309,74.926575,4.6043401,434.58377,-9.2614918
4391,4391,179.1342,9.1933041,5.3572283,0.0,0,4.5730724,0.0,0.44218582,75.170021,4.5799441,434.4119,-9.2609501
4402,4402,179.1364,9.2115364,5.3801761,0.0,0,4.5503902,0.0,0.44379708,75.212486,4.5571079,434.24002,-9.2616215
4413,4413,179.1386,9.2204113,5.4000392,0.0,0,4.528141,0.0,0.44668257,75.174057,4.5341196,434.06812,-9.2618771
4424,4424,179.1408,9.1939878,5.4233394,0.0,0,4.5065637,0.0,0.44825131,74.801529,4.5114665,433.89624,-9.2609406
4435,4435,179.143,9.2120028,5.4443073,0.0,0,4.4849858,0.0,0.45133215,74.729584,4.4898334,433.87762,-9.2599239
4446,4446,179.1452,9.2170916,5.4699211,0.0,0,4.4634085,0.0,0.45306271,74.52681,4.4697533,433.93051,-9.260047
4457,4457,179.1474,9.2634459,5.4854665,0.0,0,4.4418306,0.0,0.45567706,74.742638,4.4479012,433.9834,-9.2610798
4468,4468,179.1496,9.2962523,5.5103869,0.0,0,4.4202533,0.0,0.45733333,74.894455,4.4281774,434.03629,-9.2597857
4479,4479,179.1518,9.3481092,5.5300703,0.0,0,4.3986754,0.0,0.46039236,75.134163,4.4059348,434.09109,-9.2601252
4490,4490,179.154,9.3881483,5.5589452,0.0,0,4.3770976,0.0,0.46235746,75.297928,4.3800726,434.1572,-9.2609529
4501,4501,179.1562,9.4101028,5.5740514,0.0,0,4.3555202,0.0,0.46501189,75.27459,4.3596725,434.2233,-9.2611217
4512,4512,179.1584,9.407752,5.5993705,0.0,0,4.3339429,0.0,0.46678153,75.083206,4.3383489,434.2894,-9.2607479
4523,4523,179.1606,9.4025517,5.6175475,0.0,0,4.3123651,0.0,0.46974334,74.874458,4.3156753,434.3555,-9.2622738
4534,4534,179.1628,9.3835497,5.644989,0.0,0,4.2907877,0.0,0.47157046,74.563774,4.2931185,434.4498,-9.2632799
4545,4545,179.165,9.4240255,5.6553326,0.0,0,4.2692099,0.0,0.47375926,74.680138,4.2734733,434.56219,-9.2616663
4556,4556,179.1672,9.4804859,5.6805873,0.0,0,4.247632,0.0,0.47558954,75.002769,4.2529535,434.67459,-9.2609034
4567,4567,179.1694,9.5435276,5.6992502,0.0,0,4.2260542,0.0,0.47848198,75.220833,4.2314563,434.78696,-9.2613573
4578,4578,179.1716,9.5807562,5.7301416,0.0,0,4.2044768,0.0,0.48062932,75.404556,4.2116981,434.89886,-9.2623358
4589,4589,179.1738,9.6285954,5.7422981,0.0,0,4.1828995,0.0,0.48292679,75.65889,4.1892943,435.00464,-9.2607069
4600,4600,179.176,9.6270094,5.7685757,0.0,0,4.1613216,0.0,0.48509106,75.478958,4.1683412,435.11041,-9.2607212
4611,4611,179.1782,9.6375933,5.7863851,0.0,0,4.1397443,0.0,0.48763618,75.377159,4.1430936,435.21616,-9.2601089
4622,4622,179.1804,9.6550941,5.8160391,0.0,0,4.1181669,0.0,0.4900806,75.305779,4.1233044,435.32193,-9.2608223
4633,4633,179.1826,9.6934271,5.8303838,0.0,0,4.0965891,0.0,0.49237284,75.441566,4.1012521,435.39224,-9.2613287
4644,4644,179.1848,9.7192688,5.854322,0.0,0,4.0750117,0.0,0.49452069,75.445038,4.0812168,435.43192,-9.2601347
4655,4655,179.187,9.7806787,5.8715477,0.0,0,4.0534339,0.0,0.4966839,75.740555,4.0623665,435.47159,-9.2613611
4666,4666,179.1892,9.8390961,5.9000816,0.0,0,4.0325584,0.0,0.4995226,76.016357,4.037395,435.51126,-9.2611599
4677,4677,179.1914,9.8889971,5.9185729,0.0,0,4.0120368,0.0,0.50172502,76.278236,4.014452,435.55093,-9.2603598
4688,4688,179.1936,9.8940334,5.9429688,0.0,0,3.9915152,0.0,0.50433284,76.123917,3.9916985,435.54431,-9.2604904
4699,4699,179.1958,9.892067,5.9619875,0.0,0,3.9709935,0.0,0.50657034,75.941071,3.9730289,435.53772,-9.2600384
4710,4710,179.198,9.8886833,5.9896679,0.0,0,3.9504721,0.0,0.50960243,75.647102,3.9518869,435.5311,-9.2612066
4721,4721,179.2002,9.8815155,6.0061021,0.0,0,3.9299502,0.0,0.51134908,75.467361,3.9303482,435.52448,-9.2603903
4732,4732,179.2024,9.9245338,6.0234241,0.0,0,3.9094286,0.0,0.5135389,75.610748,3.9106052,435.5148,-9.2607775
4743,4743,179.2046,9.9835978,6.0419073,0.0,0,3.8889072,0.0,0.51534164,75.911995,3.8844638,435.50159,-9.2614908
4754,4754,179.2068,10.023025,6.0682435,0.0,0,3.8683856,0.0,0.51861668,75.923035,3.8696296,435.48837,-9.261323
4765,4765,179.209,10.025447,6.087925,0.0,0,3.8478639,0.0,0.52028304,75.847572,3.8511887,435.47516,-9.2607851
4776,4776,179.2112,10.05104,6.1042833,0.0,0,3.8273423,0.0,0.5226227,75.878311,3.8292806,435.46191,-9.2598
4787,4787,179.2134,10.081509,6.1248579,0.0,0,3.8068206,0.0,0.52435237,75.99691,3.8065431,435.60196,-9.2606649
4798,4798,179.2156,10.106507,6.1443233,0.0,0,3.7862992,0.0,0.52740657,75.93644,3.7883596,435.754,-9.2612658
4809,4809,179.2178,10.129212,6.1683478,0.0,0,3.7657776,0.0,0.52927876,75.963211,3.7705584,435.90604,-9.2619848
4820,4820,179.22,10.184488,6.1869779,0.0,0,3.7452559,0.0,0.53221458,76.131744,3.7502472,436.05807,-9.2625437
4831,4831,179.2222,10.242025,6.2088952,0.0,0,3.7247343,0.0,0.53382617,76.428467,3.7262747,436.22565,-9.2603006
4842,4842,179.2244,10.295855,6.2275467,0.0,0,3.7042127,0.0,0.53683519,76.568047,3.7025645,436.41736,-9.25945
4853,4853,179.2266,10.336349,6.2523913,0.0,0,3.683691,0.0,0.53869504,76.750015,3.6837473,436.60907,-9.2613087
4864,4864,179.2288,10.35979,6.2697306,0.0,0,3.6631694,0.0,0.54179728,76.725754,3.6603658,436.80078,-9.2612286
4875,4875,179.231,10.390019,6.2956309,0.0,0,3.642648,0.0,0.54360616,76.768074,3.6409223,436.99249,-9.2618961
4886,4886,179.2332,10.413625,6.3098927,0.0,0,3.6221263,0.0,0.54649556,76.831665,3.620095,437.07687,-9.2599287
4897,4897,179.2354,10.441691,6.3384585,0.0,0,3.6016047,0.0,0.54834223,76.814507,3.6001682,437.14297,-9.2592516
4908,4908,179.2376,10.466901,6.3526092,0.0,0,3.5810831,0.0,0.55130696,76.78466,3.5769665,437.20911,-9.2605534
4919,4919,179.2398,10.478119,6.3763885,0.0,0,3.5614979,0.0,0.55310667,76.743156,3.5580752,437.27521,-9.2603807
4930,4930,179.242,10.499723,6.3917427,0.0,0,3.541975,0.0,0.55604964,76.688919,3.5398498,437.32028,-9.2617455
4941,4941,179.2442,10.493323,6.4192805,0.0,0,3.5224524,0.0,0.55774593,76.443336,3.5186343,437.32028,-9.259819
4952,4952,179.2464,10.522127,6.4307003,0.0,0,3.5029294,0.0,0.56037128,76.50666,3.5053651,437.32028,-9.2593546
4963,4963,179.2486,10.546422,6.4528418,0.0,0,3.4834068,0.0,0.56199342,76.477829,3.4820158,437.32028,-9.2578001
4974,4974,179.2508,10.596211,6.4655633,0.0,0,3.4638839,0.0,0.56447983,76.740852,3.4662359,437.32028,-9.2597284
4985,4985,179.253,10.612025,6.4943819,0.0,0,3.4443612,0.0,0.56676155,76.649269,3.4470458,437.27893,-9.2618952
4996,4996,179.2552,10.644918,6.5041847,0.0,0,3.4248383,0.0,0.56899881,76.71627,3.4304211,437.22604,-9.2614174
5007,5007,179.2574,10.710915,6.5307498,0.0,0,3.4053154,0.0,0.57126075,76.954681,3.4049835,437.17316,-9.2607279
5018,5018,179.2596,10.793177,6.5446,0.0,0,3.385793,0.0,0.57351458,77.419594,3.3857784,437.1203,-9.2607403
5029,5029,179.2618,10.836349,6.5719976,0.0,0,3.3662698,0.0,0.57600385,77.511818,3.3648164,437.07388,-9.2607422
5040,5040,179.264,10.846029,6.5857415,0.0,0,3.3467469,0.0,0.57830119,77.447647,3.3452661,437.04745,-9.2604856
5051,5051,179.2662,10.859619,6.6081023,0.0,0,3.3272245,0.0,0.58051485,77.382607,3.3269773,437.021,-9.2607145
5062,5062,179.2684,10.906021,6.6221943,0.0,0,3.3077013,0.0,0.58254135,77.557571,3.3069177,436.99457,-9.2613888
5073,5073,179.2706,10.911873,6.6479754,0.0,0,3.2881789,0.0,0.58534855,77.374542,3.2879944,436.96811,-9.2609797
5084,5084,179.2728,10.945444,6.6625428,0.0,0,3.268656,0.0,0.58739978,77.435181,3.268657,436.93228,-9.2599554
5095,5095,179.275,10.988214,6.6848278,0.0,0,3.2491331,0.0,0.58989102,77.56311,3.2493787,436.89264,-9.2611446
5106,5106,179.2772,11.06321,6.7010708,0.0,0,3.2296104,0.0,0.59186304,77.914696,3.2293851,436.85297,-9.2609892
5117,5117,179.2794,11.142419,6.7261629,0.0,0,3.2100873,0.0,0.59499598,78.22776,3.2125149,436.81329,-9.2607355
5128,5128,179.2816,11.215973,6.7447462,0.0,0,3.1905646,0.0,0.5970875,78.574478,3.1878748,436.77249,-9.2603273
5139,5139,179.2838,11.202108,6.7643733,0.0,0,3.171042,0.0,0.59968507,78.289772,3.1675777,436.72623,-9.2607374
5150,5150,179.286,11.230767,6.7831202,0.0,0,3.1515191,0.0,0.60170585,78.324722,3.1501615,436.67993,-9.2607698
5161,5161,179.2882,11.218655,6.8066874,0.0,0,3.1321959,0.0,0.60489863,78.032578,3.131366,436.63367,-9.2619114
5172,5172,179.2904,11.267171,6.8227601,0.0,0,3.1136236,0.0,0.60624456,78.287849,3.1117041,436.58737,-9.2605124
5183,5183,179.2926,11.278401,6.8382182,0.0,0,3.0950511,0.0,0.6088478,78.098259,3.0861697,436.57056,-9.2608347
5194,5194,179.2948,11.335388,6.8587313,0.0,0,3.076479,0.0,0.61076301,78.366165,3.0675619,436.57056,-9.2610159
5205,5205,179.297,11.315711,6.8792148,0.0,0,3.0579064,0.0,0.61413825,77.990807,3.0577455,436.57056,-9.2601166
5216,5216,179.2992,11.357258,6.8991146,0.0,0,3.0393341,0.0,0.61548626,78.097824,3.0391819,436.57056,-9.2600126
5227,5227,179.3014,11.393684,6.9124618,0.0,0,3.0207615,0.0,0.61814398,78.17598,3.0178108,436.57254,-9.2598219
5238,5238,179.3036,11.442311,6.9315848,0.0,0,3.0021892,0.0,0.61951596,78.382118,3.0024023,436.59238,-9.2587624
5249,5249,179.3058,11.477993,6.9477873,0.0,0,2.9836168,0.0,0.62274557,78.409035,2.9853866,436.61221,-9.2597589
5260,5260,179.308,11.567675,6.9705963,0.0,0,2.9650443,0.0,0.62427944,78.888313,2.964499,436.63205,-9.2610226
5271,5271,179.3102,11.569329,6.9834709,0.0,0,2.9464722,0.0,0.62715328,78.714005,2.944371,436.65186,-9.2609377
5282,5282,179.3124,11.584563,7.0069828,0.0,0,2.9278994,0.0,0.6289348,78.622856,2.9304738,436.68289,-9.260251
5293,5293,179.3146,11.623057,7.0189247,0.0,0,2.909327,0.0,0.63168854,78.737709,2.909631,436.72253,-9.2602844
5304,5304,179.3168,11.705343,7.0438366,0.0,0,2.8907547,0.0,0.63321859,79.10923,2.8894675,436.76221,-9.259181
5315,5315,179.319,11.832002,7.0573297,0.0,0,2.8721824,0.0,0.63647121,79.654945,2.8717632,436.80188,-9.2607975
5326,5326,179.3212,11.906079,7.0803041,0.0,0,2.8536098,0.0,0.63819706,80.043152,2.8537867,436.84082,-9.2607822
5337,5337,179.3234,11.913836,7.0946326,0.0,0,2.8350375,0.0,0.64117575,79.869408,2.8361752,436.85403,-9.260519
5348,5348,179.3256,11.950578,7.1252308,0.0,0,2.8164649,0.0,0.64349592,79.956932,2.8142505,436.86728,-9.26085
5359,5359,179.3278,11.97846,7.1356831,0.0,0,2.7978928,0.0,0.64630318,79.943283,2.7923837,436.88049,-9.258873
5370,5370,179.33,12.005522,7.1592503,0.0,0,2.7793205,0.0,0.64819074,79.943527,2.7781088,436.89371,-9.260437
5381,5381,179.3322,12.043504,7.1723099,0.0,0,2.7607477,0.0,0.65100497,79.968414,2.7554178,436.89722,-9.2619286
5392,5392,179.3344,12.080822,7.2014723,0.0,0,2.7421756,0.0,0.65332973,80.022247,2.7418089,436.89059,-9.2614098
5403,5403,179.3366,12.137948,7.2106614,0.0,0,2.723603,0.0,0.65566975,80.163429,2.7196903,436.88397,-9.2604647
5414,5414,179.3388,12.203904,7.2324777,0.0,0,2.7054687,0.0,0.65764952,80.502769,2.7004819,436.87738,-9.2591801
5425,5425,179.341,12.228559,7.2455945,0.0,0,2.6878026,0.0,0.66025907,80.478065,2.6822469,436.87076,-9.2597771
5436,5436,179.3432,12.233862,7.2741866,0.0,0,2.6701367,0.0,0.66284996,80.263496,2.6677477,436.90201,-9.259963
5447,5447,179.3454,12.225308,7.2815919,0.0,0,2.6524706,0.0,0.66481918,80.069221,2.646533,436.93506,-9.260457
5458,5458,179.3476,12.274958,7.3062944,0.0,0,2.6348047,0.0,0.66736275,80.240761,2.6300676,436.96811,-9.2606516
5469,5469,179.3498,12.347266,7.3181214,0.0,0,2.6171386,0.0,0.66926163,80.489197,2.6147716,437.00116,-9.2605038
5480,5480,179.352,12.417366,7.3434806,0.0,0,2.5994725,0.0,0.67212504,80.66452,2.5954769,437.02869,-9.2602291
5491,5491,179.3542,12.447495,7.3550382,0.0,0,2.5818067,0.0,0.67410803,80.720352,2.5745361,437.04852,-9.2609377
5502,5502,179.3564,12.486697,7.3763742,0.0,0,2.5641406,0.0,0.6766932,80.76725,2.5611687,437.06833,-9.2602453
5513,5513,179.3586,12.550295,7.3900971,0.0,0,2.5464745,0.0,0.67859602,81.049614,2.5434744,437.08817,-9.258894
5524,5524,179.3608,12.565224,7.4142995,0.0,0,2.5288086,0.0,0.68180227,80.92234,2.5255218,437.108,-9.2597952
5535,5535,179.363,12.592062,7.4266539,0.0,0,2.5111427,0.0,0.6832518,80.989647,2.5038874,437.08704,-9.2604523
5546,5546,179.3652,12.60052,7.4440489,0.0,0,2.4934766,0.0,0.68582356,80.803246,2.4902031,437.06061,-9.2593651
5557,5557,179.3674,12.641909,7.4590731,0.0,0,2.4758105,0.0,0.68747669,80.955498,2.4735515,437.03415,-9.2603683
5568,5568,179.3696,12.69908,7.4796185,0.0,0,2.4581447,0.0,0.69081855,81.019081,2.4554007,437.00772,-9.2595901
5579,5579,179.3718,12.824136,7.4968457,0.0,0,2.4404786,0.0,0.69221383,81.654243,2.4343929,436.98584,-9.2605209
5590,5590,179.374,12.880348,7.5112882,0.0,0,2.4228127,0.0,0.69490439,81.861427,2.418328,436.97263,-9.2610321
5601,5601,179.3762,12.941926,7.5305843,0.0,0,2.4051466,0.0,0.69672322,82.118469,2.4008858,436.95941,-9.2602272
5612,5612,179.3784,13.019752,7.5532784,0.0,0,2.3874805,0.0,0.70072579,82.211617,2.3852255,436.94617,-9.2608528
5623,5623,179.3806,13.042817,7.5720639,0.0,0,2.3698146,0.0,0.70222867,82.333679,2.3644307,436.93295,-9.2589417
5634,5634,179.3828,13.072278,7.5848389,0.0,0,2.3521485,0.0,0.7050845,82.276215,2.3448274,436.93576,-9.2588482
5645,5645,179.385,13.108113,7.6042628,0.0,0,2.3344824,0.0,0.70647991,82.379295,2.3274901,436.94238,-9.2593393
5656,5656,179.3872,13.145702,7.6188879,0.0,0,2.3168166,0.0,0.70991391,82.248596,2.3140521,436.94901,-9.2596779
5667,5667,179.3894,13.205558,7.64149,0.0,0,2.2998021,0.0,0.71132439,82.525848,2.2939346,436.9556,-9.2594919
5678,5678,179.3916,13.29579,7.6532307,0.0,0,2.2829986,0.0,0.71444666,82.830223,2.278496,436.92075,-9.2586746
5689,5689,179.3938,13.356514,7.675036,0.0,0,2.2661951,0.0,0.71614051,83.101143,2.2589226,436.7753,-9.259428
5700,5700,179.396,13.391079,7.6901979,0.0,0,2.2493913,0.0,0.71956027,82.993935,2.2413538,436.62988,-9.260026
5711,5711,179.3982,13.424818,7.7150917,0.0,0,2.2325881,0.0,0.72117162,83.089882,2.2243292,436.48444,-9.2589149
5722,5722,179.4004,13.410462,7.7220445,0.0,0,2.2157843,0.0,0.72400266,82.808647,2.2078316,436.33899,-9.2608776
5733,5733,179.4026,13.443519,7.7419872,0.0,0,2.1989808,0.0,0.72524315,82.932663,2.1930048,436.18384,-9.2607803
5744,5744,179.4048,13.504797,7.7549868,0.0,0,2.1821771,0.0,0.72850895,82.96627,2.1748338,436.02518,-9.2599344
5755,5755,179.407,13.590824,7.7812681,0.0,0,2.1653736,0.0,0.73043001,83.344933,2.1565397,435.86652,-9.2588224
5766,5766,179.4092,13.650285,7.790123,0.0,0,2.1485698,0.0,0.73330051,83.407394,2.1400108,435.70786,-9.2583208
5777,5777,179.4114,13.712776,7.8109684,0.0,0,2.1317663,0.0,0.73489267,83.714783,2.1225622,435.5307,-9.2596064
5788,5788,179.4136,13.759039,7.8207932,0.0,0,2.1149626,0.0,0.73758531,83.741829,2.1043606,435.27948,-9.2601519
5799,5799,179.4158,13.820859,7.8480229,0.0,0,2.0981591,0.0,0.73983622,83.959557,2.0895138,435.02826,-9.2596102
5810,5810,179.418,13.847045,7.8558192,0.0,0,2.0813556,0.0,0.74216473,83.946983,2.0745542,434.77704,-9.260004
5821,5821,179.4202,13.87333,7.8750491,0.0,0,2.0645521,0.0,0.74392635,83.977272,2.0571687,434.52585,-9.260623
5832,5832,179.4224,13.866746,7.8852329,0.0,0,2.0477483,0.0,0.74634957,83.75946,2.0424817,434.26584,-9.2599392
5843,5843,179.4246,13.879563,7.9137688,0.0,0,2.0309448,0.0,0.74917954,83.476212,2.0259149,434.0014,-9.2608662
5854,5854,179.4268,13.947927,7.9203157,0.0,0,2.0141411,0.0,0.75098288,83.788185,2.0126438,433.73697,-9.2615681
5865,5865,179.429,14.070088,7.9373779,0.0,0,1.9973376,0.0,0.75295359,84.335869,1.9957246,433.47253,-9.2602606
5876,5876,179.4312,14.184453,7.9478116,0.0,0,1.980534,0.0,0.7549057,84.857101,1.9751222,433.21317,-9.259779
5887,5887,179.4334,14.249253,7.9755864,0.0,0,1.9637303,0.0,0.75831455,84.979912,1.960134,432.9884,-9.2599468
5898,5898,179.4356,14.305059,7.9854946,0.0,0,1.9469268,0.0,0.7602194,85.208595,1.9489633,432.76364,-9.2599363
5909,5909,179.4378,14.38038,8.0058155,0.0,0,1.9301536,0.0,0.7628215,85.419281,1.9308716,432.53888,-9.2597389
5920,5920,179.44,14.461304,8.0183964,0.0,0,1.9141612,0.0,0.76477349,85.707451,1.9116598,432.31412,-9.2610588
5931,5931,179.4422,14.546861,8.0412445,0.0,0,1.898176,0.0,0.76795399,85.919601,1.8912797,432.30029,-9.2608023
5942,5942,179.4444,14.613638,8.0534,0.0,0,1.8821908,0.0,0.76953322,86.156815,1.8777425,432.4325,-9.2592726
5953,5953,179.4466,14.695355,8.0726957,0.0,0,1.8662056,0.0,0.77269149,86.337273,1.8600752,432.56473,-9.2602568
5964,5964,179.4488,14.718406,8.0876389,0.0,0,1.8502204,0.0,0.77458924,86.336967,1.8416657,432.69693,-9.2606659
5975,5975,179.451,14.745263,8.1097584,0.0,0,1.8342352,0.0,0.77826798,86.158302,1.8212178,432.83563,-9.2596264
5986,5986,179.4532,14.744765,8.1227131,0.0,0,1.8182499,0.0,0.77935362,86.111588,1.8049983,433.08685,-9.2590208
5997,5997,179.4554,14.767865,8.1367378,0.0,0,1.8022648,0.0,0.78207719,86.071861,1.7956773,433.33807,-9.2602615
6008,6008,179.4576,14.80168,8.1514559,0.0,0,1.7862796,0.0,0.78359169,86.081245,1.7791166,433.58926,-9.2607946
6019,6019,179.4598,14.863857,8.1702347,0.0,0,1.7702944,0.0,0.78729504,86.126343,1.7616097,433.84048,-9.2602606
6030,6030,179.462,14.945642,8.1863585,0.0,0,1.7543092,0.0,0.78838456,86.493347,1.7483282,433.7594,-9.2606039
6041,6041,179.4642,15.014568,8.1962976,0.0,0,1.7383239,0.0,0.79111928,86.616577,1.7324994,433.36935,-9.2598162
6052,6052,179.4664,15.136003,8.2138205,0.0,0,1.7223388,0.0,0.79245657,87.183998,1.7139952,432.97934,-9.2604885
6063,6063,179.4686,15.237872,8.2295561,0.0,0,1.7063535,0.0,0.79614979,87.507057,1.699859,432.58929,-9.2611094
6074,6074,179.4708,15.290237,8.2511053,0.0,0,1.6903684,0.0,0.79767573,87.670021,1.6846751,432.19925,-9.2600756
6085,6085,179.473,15.40437,8.2617474,0.0,0,1.6743832,0.0,0.80085617,88.047035,1.6699651,431.84167,-9.2595119
6096,6096,179.4752,15.503725,8.2821312,0.0,0,1.658398,0.0,0.80241877,88.49028,1.6524823,431.48468,-9.2594547
6107,6107,179.4774,15.568976,8.2960281,0.0,0,1.6424128,0.0,0.80623871,88.512352,1.6345655,431.12769,-9.259923
6118,6118,179.4796,15.576749,8.3179798,0.0,0,1.6264275,0.0,0.80746454,88.474052,1.6124715,430.77072,-9.2607574
6129,6129,179.4818,15.619819,8.3281498,0.0,0,1.6104424,0.0,0.81090492,88.378807,1.6023377,430.48441,-9.2592516
6140,6140,179.484,15.657578,8.3478661,0.0,0,1.5944571,0.0,0.81239426,88.447083,1.5849828,430.28607,-9.2588768
6151,6151,179.4862,15.722228,8.3591356,0.0,0,1.5784719,0.0,0.81560165,88.496704,1.5679666,430.08777,-9.2580519
6162,6162,179.4884,15.751423,8.3822651,0.0,0,1.5627213,0.0,0.81711751,88.565033,1.5565964,429.88943,-9.2594423
6173,6173,179.4906,15.803671,8.3868313,0.0,0,1.5475148,0.0,0.81975341,88.614403,1.5421281,429.69113,-9.261343
6184,6184,179.4928,15.854818,8.4080782,0.0,0,1.5323085,0.0,0.82157707,88.782547,1.5282795,429.12564,-9.2606735
6195,6195,179.495,15.903261,8.4165421,0.0,0,1.517102,0.0,0.82441515,88.790901,1.5111682,428.52347,-9.2602901
6206,6206,179.4972,15.966146,8.4412966,0.0,0,1.5018957,0.0,0.82636929,88.989746,1.4937946,427.9213,-9.2592382
6217,6217,179.4994,16.042154,8.4457598,0.0,0,1.4866892,0.0,0.82858849,89.200577,1.4801198,427.31912,-9.2591801
6228,6228,179.5016,16.136419,8.4664555,0.0,0,1.4714829,0.0,0.83055699,89.520599,1.4650698,426.73907,-9.2594252
6239,6239,179.5038,16.252954,8.4767666,0.0,0,1.4562764,0.0,0.83324862,89.918213,1.4491357,426.19623,-9.2591486
6250,6250,179.506,16.385874,8.5022755,0.0,0,1.4410701,0.0,0.83577895,90.426994,1.4336855,425.65338,-9.2602053
6261,6261,179.5082,16.464489,8.5083332,0.0,0,1.4258636,0.0,0.83788723,90.679825,1.4178499,425.11053,-9.2584915
6272,6272,179.5104,16.504669,8.5291557,0.0,0,1.4106573,0.0,0.84042543,90.717354,1.3997076,424.56769,-9.2576828
6283,6283,179.5126,16.565315,8.540513,0.0,0,1.3954508,0.0,0.84263903,90.845253,1.3836166,424.27948,-9.259284
6294,6294,179.5148,16.608896,8.5630579,0.0,0,1.3802445,0.0,0.84549618,90.821968,1.3677267,424.04108,-9.2594061
6305,6305,179.517,16.636934,8.5715981,0.0,0,1.3650382,0.0,0.84756386,90.742302,1.3563945,423.80267,-9.2606716
6316,6316,179.5192,16.711033,8.5884981,0.0,0,1.3498316,0.0,0.84985757,90.957703,1.3393917,423.56424,-9.2591248
6327,6327,179.5214,16.798937,8.5973759,0.0,0,1.3346252,0.0,0.85126787,91.271248,1.3253329,423.41327,-9.2590904
6338,6338,179.5236,16.863663,8.6222439,0.0,0,1.3194188,0.0,0.85519111,91.300842,1.3083612,423.46625,-9.2583265
6349,6349,179.5258,16.922697,8.6313543,0.0,0,1.3042125,0.0,0.85654306,91.480751,1.2978079,423.51923,-9.2578974
6360,6360,179.528,16.982183,8.6453648,0.0,0,1.2890061,0.0,0.85910165,91.56945,1.2796141,423.5722,-9.2577887
6371,6371,179.5302,17.085655,8.6589422,0.0,0,1.2737997,0.0,0.86062294,91.995018,1.2653773,423.62518,-9.2583923
6382,6382,179.5324,17.173042,8.6770802,0.0,0,1.2585933,0.0,0.86419731,92.18631,1.2498301,423.73883,-9.2600632
6393,6393,179.5346,17.247105,8.6888285,0.0,0,1.243387,0.0,0.86531705,92.436867,1.2344962,423.87128,-9.2605629
6404,6404,179.5368,17.331135,8.7057123,0.0,0,1.2281805,0.0,0.86875594,92.533302,1.2216325,424.00372,-9.2603588
6415,6415,179.539,17.435028,8.7215233,0.0,0,1.2134007,0.0,0.87042725,92.944679,1.2062981,424.13617,-9.2591991
6426,6426,179.5412,17.581385,8.7382765,0.0,0,1.198938,0.0,0.87420022,93.322403,1.1891129,424.21143,-9.2591572
6437,6437,179.5434,17.679859,8.7526693,0.0,0,1.1844752,0.0,0.87506777,93.821701,1.1771715,424.09222,-9.2593632
6448,6448,179.5456,17.720804,8.762578,0.0,0,1.1700124,0.0,0.87811267,93.792564,1.1589794,423.97302,-9.2595253
6459,6459,179.5478,17.750277,8.7821512,0.0,0,1.1555496,0.0,0.87990612,93.771355,1.1452998,423.85382,-9.2601595
6470,6470,179.55,17.780621,8.797864,0.0,0,1.1410867,0.0,0.88391781,93.57724,1.1331058,423.73462,-9.2587366
6481,6481,179.5522,17.845924,8.8139954,0.0,0,1.126624,0.0,0.88475233,93.843307,1.1193979,423.67032,-9.2588625
6492,6492,179.5544,17.933308,8.8195772,0.0,0,1.1121612,0.0,0.88740623,94.04895,1.1024381,423.63058,-9.2591877
6503,6503,179.5566,18.014156,8.835804,0.0,0,1.0976985,0.0,0.88841629,94.295723,1.085928,423.59085,-9.258646
6514,6514,179.5588,18.081926,8.846405,0.0,0,1.0832355,0.0,0.89198661,94.345543,1.0752454,423.55112,-9.2584877
6525,6525,179.561,18.188784,8.8686228,0.0,0,1.0687727,0.0,0.89352584,94.745239,1.0619965,423.51956,-9.2583361
6536,6536,179.5632,18.256348,8.87784,0.0,0,1.05431,0.0,0.89709264,94.783867,1.0464231,423.53281,-9.2583084
6547,6547,179.5654,18.331549,8.8975716,0.0,0,1.0398471,0.0,0.89844471,95.051575,1.0285226,423.54605,-9.2571115
6558,6558,179.5676,18.380142,8.9038067,0.0,0,1.0253843,0.0,0.9014309,95.016121,1.0179915,423.5593,-9.2573681
6569,6569,179.5698,18.440308,8.9252939,0.0,0,1.0109215,0.0,0.90264684,95.201889,1.0065818,423.57254,-9.2583904
6580,6580,179.572,18.554472,8.9306154,0.0,0,0.99645877,0.0,0.90565228,95.499809,0.98848593,423.61035,-9.2575912
6591,6591,179.5742,18.663275,8.9514132,0.0,0,0.98199582,0.0,0.90746021,95.89991,0.97152656,423.66333,-9.2586918
6602,6602,179.5764,18.810516,8.959321,0.0,0,0.96753311,0.0,0.91056299,96.32888,0.95835382,423.71631,-9.2580862
6613,6613,179.5786,18.986807,8.9845657,0.0,0,0.95307028,0.0,0.9126721,97.020126,0.94324964,423.76929,-9.2586479
6624,6624,179.5808,19.125387,8.990818,0.0,0,0.93860745,0.0,0.91552126,97.434929,0.93013096,423.81577,-9.2589302
6635,6635,179.583,19.214401,9.0088558,0.0,0,0.92414463,0.0,0.91704744,97.753853,0.91326892,423.78928,-9.2587128
6646,6646,179.5852,19.238131,9.0173512,0.0,0,0.90968192,0.0,0.91981882,97.653107,0.89875501,423.76279,-9.2588396
6657,6657,179.5874,19.248487,9.0406456,0.0,0,0.89521909,0.0,0.92233241,97.506104,0.88549125,423.7363,-9.2584181
6668,6668,179.5896,19.220676,9.0477467,0.0,0,0.88135606,0.0,0.92468441,97.047424,0.86960411,423.70981,-9.2580509
6679,6679,179.5918,19.215935,9.0640984,0.0,0,0.86760163,0.0,0.92654377,96.827728,0.85852349,423.58582,-9.2575941
6690,6690,179.594,19.274933,9.0704794,0.0,0,0.85384727,0.0,0.92823571,96.992188,0.84549642,423.38049,-9.2592239
6701,6701,179.5962,19.371336,9.0906849,0.0,0,0.84009284,0.0,0.93111765,97.209007,0.83379948,423.1752,-9.2585449
6712,6712,179.5984,19.574421,9.0954266,0.0,0,0.82633847,0.0,0.93243033,98.064384,0.82072783,422.96991,-9.2585497
6723,6723,179.6006,19.719299,9.1127863,0.0,0,0.81258404,0.0,0.9352777,98.51445,0.80409175,422.76569,-9.259347
6734,6734,179.6028,19.845083,9.1248055,0.0,0,0.79882962,0.0,0.93711996,99.005318,0.79472554,422.67963,-9.2593079
6745,6745,179.605,19.94763,9.1428013,0.0,0,0.78507525,0.0,0.94017953,99.231277,0.78074121,422.59354,-9.2589426
6756,6756,179.6072,20.070032,9.1512518,0.0,0,0.77132082,0.0,0.94175935,99.667366,0.76246488,422.50745,-9.2574692
6767,6767,179.6094,20.162893,9.1669807,0.0,0,0.75756639,0.0,0.9446286,99.775505,0.74588555,422.42136,-9.2567577
6778,6778,179.6116,20.229218,9.1774588,0.0,0,0.74381202,0.0,0.94601214,99.993103,0.73350787,422.48557,-9.2589493
6789,6789,179.6138,20.322939,9.1984358,0.0,0,0.7300576,0.0,0.95023054,100.04481,0.7199325,422.71735,-9.2591887
6800,6800,179.616,20.403555,9.2088203,0.0,0,0.71630323,0.0,0.95120257,100.32045,0.70549756,422.94913,-9.256835
6811,6811,179.6182,20.522608,9.2215767,0.0,0,0.7025488,0.0,0.95431721,100.57256,0.69201273,423.18091,-9.2573099
6822,6822,179.6204,20.606827,9.233716,0.0,0,0.68879443,0.0,0.95544302,100.90562,0.67939907,423.41269,-9.2576637
6833,6833,179.6226,20.682814,9.247345,0.0,0,0.67504007,0.0,0.95906395,100.94514,0.66766614,423.64447,-9.2582827
6844,6844,179.6248,20.730555,9.2619972,0.0,0,0.66128564,0.0,0.9601475,101.05979,0.65108019,423.87625,-9.2580204
6855,6855,179.627,20.807888,9.2710133,0.0,0,0.64753121,0.0,0.96307057,101.12537,0.64006412,424.10803,-9.2584467
6866,6866,179.6292,20.899401,9.2862291,0.0,0,0.63377684,0.0,0.96419442,101.45683,0.62988794,424.33981,-9.2578306
6877,6877,179.6314,21.060041,9.297163,0.0,0,0.62002248,0.0,0.96810633,101.81853,0.61406487,424.46829,-9.2570477
6888,6888,179.6336,21.195759,9.3171635,0.0,0,0.60626805,0.0,0.9694792,102.33093,0.59790921,424.4418,-9.2575626
6899,6899,179.6358,21.312372,9.3236818,0.0,0,0.59251362,0.0,0.97272384,102.54255,0.58596319,424.41531,-9.2573385
6910,6910,179.638,21.415108,9.3408899,0.0,0,0.57883877,0.0,0.97394735,102.97996,0.57489264,424.38879,-9.2582226
6921,6921,179.6402,21.579716,9.3499165,0.0,0,0.56574845,0.0,0.97747785,103.37988,0.56007081,424.3623,-9.2576199
6930,6930,179.642,21.759493,9.3588133,0.0,0,0.55503851,0.0,0.97874594,104.09789,0.54660636,424.36774,-9.2570019