File: clean data/testID_0225.csv
level_0,index,Time(sec),Force(kN),Jaw(mm),PowAngle(deg),Power(W),Pram,PTemp,Strain,Stress(MPa),Stroke(mm),TC1(C),wedge(mm)
2273,2273,195.3708,0.97324574,0.016061632,0.0,0,9.0337067,0.0,0.00098967191,10.504492,10.04669,450.48422,-9.2352991
2275,2275,195.3712,3.7059598,0.056394789,0.0,0,8.9751787,0.0,0.0035084269,43.681156,9.9842701,450.54291,-9.2330761
2277,2277,195.3716,4.7467775,0.11168208,0.0,0,8.9166508,0.0,0.0068850811,59.39444,9.9258327,450.60159,-9.2317162
2279,2279,195.372,5.2532496,0.19204994,0.0,0,8.8581219,0.0,0.012161179,65.497734,9.8482323,450.66028,-9.2300024
2281,2281,195.3724,4.9212365,0.34054971,0.0,0,8.7995939,0.0,0.022047775,61.969707,9.7565346,450.71896,-9.2304382
2283,2283,195.3728,5.2044559,0.43693036,0.0,0,8.7416534,0.0,0.028718673,63.74128,9.6464634,450.77765,-9.2322655
2285,2285,195.3732,5.3153162,0.53561926,0.0,0,8.6858492,0.0,0.035918076,65.273598,9.5444374,450.83633,-9.2304668
2287,2287,195.3736,5.8122778,0.58323342,0.0,0,8.6301851,0.0,0.03942354,70.686958,9.4571514,450.89502,-9.228816
2289,2289,195.374,5.2819934,0.62224162,0.0,0,8.574522,0.0,0.041838147,65.457146,9.3854856,450.9537,-9.2290678
2291,2291,195.3744,5.4529786,0.68978649,0.0,0,8.518857,0.0,0.046924062,65.393456,9.3262854,451.01239,-9.2314377
2293,2293,195.3748,5.8692532,0.73174119,0.0,0,8.4631929,0.0,0.049398039,70.952713,9.268508,451.07108,-9.2320452
2295,2295,195.3752,6.1166072,0.8307181,0.0,0,8.4075298,0.0,0.056239478,73.346321,9.1988783,451.12976,-9.2307549
2297,2297,195.3756,5.7932854,0.92960674,0.0,0,8.3518648,0.0,0.063540816,69.926094,9.1152868,451.18845,-9.2304535
2299,2299,195.376,5.6509981,1.013189,0.0,0,8.2962017,0.0,0.069101006,66.850311,9.0283813,451.24716,-9.2305336
2301,2301,195.3764,5.8387475,1.097658,0.0,0,8.2405376,0.0,0.075779177,68.989342,8.9459677,451.30585,-9.2312613
2303,2303,195.3768,5.8686008,1.1321645,0.0,0,8.1848736,0.0,0.07824216,68.79911,8.8737288,451.36453,-9.2316246
2305,2305,195.3772,5.9923592,1.1845907,0.0,0,8.1292095,0.0,0.081634618,70.593071,8.8097582,451.42322,-9.2313576
2307,2307,195.3776,5.7593179,1.2421379,0.0,0,8.0735455,0.0,0.08644855,67.157837,8.7563257,451.4819,-9.2307405
2309,2309,195.378,6.2036457,1.2876143,0.0,0,8.0196619,0.0,0.089076266,71.721092,8.7046995,451.54059,-9.2307215
2311,2311,195.3784,6.1565814,1.3678813,0.0,0,7.9666953,0.0,0.094996929,71.450035,8.6410942,451.59927,-9.2312412
2313,2313,195.3788,6.1421461,1.4389641,0.0,0,7.9137359,0.0,0.10067181,70.671898,8.5743132,451.65796,-9.2306366
2315,2315,195.3792,6.0137491,1.5170045,0.0,0,7.8607755,0.0,0.10565709,69.035446,8.5081415,451.65402,-9.2307253
2317,2317,195.3796,6.0751023,1.5689433,0.0,0,7.8078156,0.0,0.11034707,69.036926,8.442215,451.46231,-9.2307425
2319,2319,195.38,6.1379709,1.5974965,0.0,0,7.7548552,0.0,0.11238472,69.916161,8.3825808,451.2706,-9.2308254
2321,2321,195.3804,6.1189899,1.6641331,0.0,0,7.7018952,0.0,0.11670977,69.332016,8.3303499,451.07889,-9.2307539
2323,2323,195.3808,6.1273851,1.7031139,0.0,0,7.6489348,0.0,0.12063814,69.110802,8.2821198,450.88715,-9.2296963
2325,2325,195.3812,6.3190928,1.7474198,0.0,0,7.5959754,0.0,0.12335142,70.877831,8.2321262,450.69543,-9.230093
2327,2327,195.3816,6.3659911,1.8201605,0.0,0,7.543015,0.0,0.12871502,71.38176,8.1755123,450.50372,-9.2300034
2329,2329,195.382,6.299715,1.8676531,0.0,0,7.4900556,0.0,0.13277021,70.242996,8.118392,450.31201,-9.2299223
2331,2331,195.3824,6.2454042,1.9348708,0.0,0,7.4370952,0.0,0.13730781,69.463135,8.0604544,450.1203,-9.2301884
2333,2333,195.3828,6.265871,1.9870802,0.0,0,7.3846664,0.0,0.14187227,69.059898,8.0041552,449.92856,-9.2305546
2335,2335,195.3832,6.4142408,2.021193,0.0,0,7.3341722,0.0,0.14451444,70.693855,7.9505577,449.73685,-9.2300644
2337,2337,195.3836,6.3051348,2.0803194,0.0,0,7.2838039,0.0,0.14860728,69.251953,7.9019542,449.54514,-9.2292852
2339,2339,195.384,6.3331389,2.1194739,0.0,0,7.2334356,0.0,0.15238246,69.266022,7.8559151,449.35342,-9.2292452
2341,2341,195.3844,6.4028711,2.1661026,0.0,0,7.1830673,0.0,0.15552874,69.67205,7.8078685,449.16171,-9.230402
2343,2343,195.3848,6.5741105,2.2223959,0.0,0,7.1326995,0.0,0.15976079,71.170959,7.7618728,448.96997,-9.2305756
2345,2345,195.3852,6.5216413,2.2711396,0.0,0,7.0823312,0.0,0.16411944,70.639816,7.7061739,448.77826,-9.2300587
2347,2347,195.3856,6.4552565,2.335243,0.0,0,7.0319633,0.0,0.1685752,69.498703,7.6556897,448.58655,-9.2298079
2349,2349,195.386,6.4915862,2.3739588,0.0,0,6.981595,0.0,0.17196643,69.525703,7.6052613,448.39484,-9.2294083
2351,2351,195.3864,6.5842729,2.4158969,0.0,0,6.9312277,0.0,0.17553401,70.305984,7.5540895,448.20313,-9.2292738
2353,2353,195.3868,6.5944571,2.4732161,0.0,0,6.8808594,0.0,0.17938066,70.169891,7.5032396,448.01138,-9.2305984
2355,2355,195.3872,6.5804911,2.5067394,0.0,0,6.830492,0.0,0.18267296,69.791016,7.4587421,447.81967,-9.2315893
2357,2357,195.3876,6.6356158,2.5559847,0.0,0,6.7801232,0.0,0.18648435,70.091476,7.4120922,447.62796,-9.2313194
2359,2359,195.388,6.7079215,2.6131303,0.0,0,6.7313671,0.0,0.19055066,70.558746,7.3613062,447.43625,-9.2288389
2361,2361,195.3884,6.7121658,2.6577852,0.0,0,6.6834416,0.0,0.19488257,70.225037,7.3133564,447.24454,-9.2291126
2363,2363,195.3888,6.6966124,2.7132719,0.0,0,6.6355219,0.0,0.19905703,69.792259,7.2642345,447.0528,-9.2305202
2365,2365,195.3892,6.7628746,2.7608922,0.0,0,6.5876017,0.0,0.20276688,70.239563,7.2135868,446.76782,-9.2313919
2367,2367,195.3896,6.8041239,2.801306,0.0,0,6.5396819,0.0,0.20668481,70.48774,7.1650643,446.20303,-9.2307253
2369,2369,195.39,6.7809358,2.8489521,0.0,0,6.4917622,0.0,0.21010877,70.042648,7.1149735,445.63824,-9.2298918
2371,2371,195.3904,6.8202004,2.8994637,0.0,0,6.4438419,0.0,0.21430293,70.078987,7.0716815,445.07346,-9.2300339
2373,2373,195.3908,6.8963165,2.9447312,0.0,0,6.3959212,0.0,0.21840484,70.45343,7.0242705,444.50867,-9.2298222
2375,2375,195.3912,6.9506845,2.9956014,0.0,0,6.3480015,0.0,0.22201286,70.831909,6.9754248,443.94388,-9.2305365
2377,2377,195.3916,6.929287,3.04843,0.0,0,6.3000817,0.0,0.22700593,70.407028,6.9260502,443.37909,-9.2307224
2379,2379,195.392,6.8992991,3.0948532,0.0,0,6.252162,0.0,0.23081312,69.779633,6.8755708,442.8143,-9.2309599
2381,2381,195.3924,6.9858594,3.1411116,0.0,0,6.2042422,0.0,0.23425466,70.325226,6.8280873,442.24951,-9.2296391
2383,2383,195.3928,7.0469699,3.1871576,0.0,0,6.1568027,0.0,0.238841,70.601875,6.7775817,441.68472,-9.228898
2385,2385,195.3932,7.0611081,3.2318227,0.0,0,6.1111121,0.0,0.24206662,70.591148,6.7274184,441.11993,-9.2290869
2387,2387,195.3936,7.0694647,3.2819197,0.0,0,6.065536,0.0,0.24636029,70.397873,6.6808286,440.55515,-9.2299442
2389,2389,195.394,7.1145554,3.3282847,0.0,0,6.0199599,0.0,0.25091457,70.430298,6.6350112,439.99039,-9.2320471
2391,2391,195.3944,7.1793094,3.3831527,0.0,0,5.9743834,0.0,0.2546812,70.80587,6.583509,439.4256,-9.2321396
2393,2393,195.3948,7.1958718,3.4323432,0.0,0,5.9288077,0.0,0.25944716,70.69001,6.5335345,438.86081,-9.2314529
2395,2395,195.3952,7.1910644,3.4759943,0.0,0,5.8832321,0.0,0.26344526,70.332848,6.48599,438.29602,-9.2296095
2397,2397,195.3956,7.2210627,3.5311551,0.0,0,5.8376555,0.0,0.26748887,70.309647,6.434741,437.73123,-9.2290897
2399,2399,195.396,7.2396765,3.5730391,0.0,0,5.792079,0.0,0.27193934,70.21537,6.3904643,437.16644,-9.2297745
2401,2401,195.3964,7.2947116,3.6167748,0.0,0,5.7465038,0.0,0.27549571,70.459465,6.3379235,436.60165,-9.2303953
2403,2403,195.3968,7.3197732,3.6719482,0.0,0,5.7009277,0.0,0.27997065,70.427406,6.2906218,436.03687,-9.231164
2405,2405,195.3972,7.3613338,3.711102,0.0,0,5.6553516,0.0,0.28426644,70.517731,6.2439227,435.47208,-9.2314119
2407,2407,195.3976,7.3812485,3.7619438,0.0,0,5.6097755,0.0,0.28803104,70.460487,6.1975174,434.90729,-9.2301416
2409,2409,195.398,7.3974166,3.8173587,0.0,0,5.5656581,0.0,0.29312512,70.186829,6.1484137,434.3425,-9.2299824
2411,2411,195.3984,7.4349608,3.8554518,0.0,0,5.5222936,0.0,0.29706439,70.322189,6.1028237,433.77771,-9.2313795
2413,2413,195.3988,7.4924836,3.9088175,0.0,0,5.4789333,0.0,0.30103669,70.559921,6.0552206,433.21295,-9.2306414
2415,2415,195.3992,7.5283208,3.9555168,0.0,0,5.4355736,0.0,0.30596903,70.473312,6.0066867,432.69843,-9.2305098
2417,2417,195.3996,7.5343919,3.9974873,0.0,0,5.3922133,0.0,0.30962801,70.352806,5.9600334,432.33478,-9.2307377
2419,2419,195.4,7.5446982,4.050612,0.0,0,5.3488536,0.0,0.31397283,70.118126,5.9144173,431.9711,-9.2299967
2421,2421,195.4004,7.5986109,4.0941014,0.0,0,5.3054934,0.0,0.31879014,70.250298,5.8638415,431.60745,-9.2297735
2423,2423,195.4008,7.6552749,4.1436257,0.0,0,5.2621331,0.0,0.32259101,70.533211,5.820241,431.24377,-9.2303963
2425,2425,195.4012,7.6754012,4.1914139,0.0,0,5.2187734,0.0,0.32702577,70.454552,5.7709932,430.88013,-9.2306614
2427,2427,195.4016,7.6959171,4.2328682,0.0,0,5.1754136,0.0,0.33160907,70.322533,5.724103,430.51645,-9.2306614
2429,2429,195.402,7.7044086,4.2871838,0.0,0,5.1320534,0.0,0.33569664,70.131371,5.6762042,430.1528,-9.230587
2431,2431,195.4024,7.769732,4.3299341,0.0,0,5.0886931,0.0,0.34021428,70.436401,5.62848,429.78912,-9.2299509
2433,2433,195.4028,7.817987,4.3729854,0.0,0,5.0457683,0.0,0.34457055,70.550186,5.5822549,429.42548,-9.2294979
2435,2435,195.4032,7.8182325,4.4266701,0.0,0,5.0044241,0.0,0.34868878,70.256866,5.5343151,429.0618,-9.2291098
2437,2437,195.4036,7.8332157,4.4655056,0.0,0,4.9631839,0.0,0.35321438,70.01049,5.4893064,428.69815,-9.2304287
2439,2439,195.404,7.8592863,4.5112081,0.0,0,4.9219441,0.0,0.35736087,70.002876,5.4411359,428.33447,-9.2307339
2441,2441,195.4044,7.9241185,4.5641775,0.0,0,4.8807039,0.0,0.36179972,70.19223,5.3950324,427.97083,-9.2297049
2443,2443,195.4048,7.9638371,4.6012001,0.0,0,4.8394642,0.0,0.36636859,70.21405,5.3497758,427.60715,-9.2298794
2445,2445,195.4052,7.9701476,4.648068,0.0,0,4.798224,0.0,0.37022996,70.059319,5.3050923,427.2435,-9.2289219
2447,2447,195.4056,7.997952,4.7004037,0.0,0,4.7569842,0.0,0.37516323,69.991768,5.2604904,426.87982,-9.2295618
2449,2449,195.406,8.0340347,4.7365088,0.0,0,4.715744,0.0,0.37950477,69.936508,5.2151871,426.51617,-9.2293968
2451,2451,195.4064,8.0917721,4.7860527,0.0,0,4.6745043,0.0,0.38338244,70.163483,5.1675491,426.1525,-9.2298489
2453,2453,195.4068,8.1306648,4.8329439,0.0,0,4.6332641,0.0,0.38864702,70.126228,5.125339,425.78885,-9.2300797
2455,2455,195.4072,8.1441851,4.8754144,0.0,0,4.5920238,0.0,0.39286655,70.011063,5.078485,425.42517,-9.2304707
2457,2457,195.4076,8.1514931,4.9231172,0.0,0,4.5507841,0.0,0.39699644,69.795311,5.0346932,425.06152,-9.2299185
2459,2459,195.408,8.1916819,4.9648037,0.0,0,4.5108657,0.0,0.40201712,69.763992,4.9918227,424.69785,-9.2284861
2461,2461,195.4084,8.2476501,5.004848,0.0,0,4.4716296,0.0,0.40550226,69.945564,4.9477754,424.33417,-9.2292147
2463,2463,195.4088,8.291501,5.051425,0.0,0,4.4323978,0.0,0.40985456,70.040337,4.9065394,423.97052,-9.2293158
2465,2465,195.4092,8.294735,5.0955229,0.0,0,4.3931656,0.0,0.41518328,69.755051,4.8627529,423.62204,-9.2300186
2467,2467,195.4096,8.3162012,5.14501,0.0,0,4.3539338,0.0,0.41927445,69.573402,4.8170762,423.31912,-9.2306519
2469,2469,195.41,8.3606014,5.1868496,0.0,0,4.314702,0.0,0.4238005,69.571426,4.7759714,423.0162,-9.2299023
2471,2471,195.4104,8.4218035,5.2213264,0.0,0,4.2754698,0.0,0.427955,69.821701,4.7296567,422.71326,-9.2280741
2473,2473,195.4108,8.4570532,5.2707863,0.0,0,4.2362375,0.0,0.4318321,69.860603,4.6881347,422.41034,-9.2294626
2475,2475,195.4112,8.4546776,5.3092136,0.0,0,4.1970053,0.0,0.43672708,69.597099,4.6467886,422.10742,-9.2316723
2477,2477,195.4116,8.4785233,5.3507338,0.0,0,4.1577735,0.0,0.44075304,69.489914,4.6039314,421.80447,-9.2313499
2479,2479,195.412,8.5181656,5.4025211,0.0,0,4.1185417,0.0,0.44543111,69.473824,4.5613885,421.50156,-9.2295485
2481,2481,195.4124,8.5820055,5.4359565,0.0,0,4.0793095,0.0,0.45010018,69.602768,4.5186009,421.19864,-9.22855
2483,2483,195.4128,8.6077261,5.4770126,0.0,0,4.0404716,0.0,0.45371604,69.691978,4.4804397,420.89572,-9.2282658
2485,2485,195.4132,8.6173601,5.5228157,0.0,0,4.0030656,0.0,0.45845294,69.376808,4.4355407,420.59277,-9.2295656
2487,2487,195.4136,8.6743555,5.5525999,0.0,0,3.9657533,0.0,0.46246257,69.49472,4.3930974,420.28986,-9.2313414
2489,2489,195.414,8.7248707,5.5986419,0.0,0,3.9284413,0.0,0.46633649,69.644272,4.3507504,419.98694,-9.2313242
2491,2491,195.4144,8.7706213,5.6468163,0.0,0,3.8911293,0.0,0.47189528,69.617409,4.3122306,419.68399,-9.2298698
2493,2493,195.4148,8.7957726,5.6834373,0.0,0,3.8538175,0.0,0.47615817,69.545158,4.2702146,419.38107,-9.2291021
2495,2495,195.4152,8.8139629,5.7264724,0.0,0,3.8165054,0.0,0.48003069,69.428467,4.2301764,419.07816,-9.2287979
2497,2497,195.4156,8.8477516,5.7626491,0.0,0,3.7791932,0.0,0.48482624,69.351898,4.1896329,418.77524,-9.2294207
2499,2499,195.416,8.8851652,5.79808,0.0,0,3.7418811,0.0,0.4882268,69.388458,4.1512427,418.47229,-9.2294884
2501,2501,195.4164,8.9394302,5.8399692,0.0,0,3.7045693,0.0,0.49233404,69.505783,4.111465,418.16937,-9.2291508
2503,2503,195.4168,8.9848881,5.8787174,0.0,0,3.6672573,0.0,0.49759555,69.51355,4.0718732,417.86646,-9.2294025
2505,2505,195.4172,9.0188751,5.9239097,0.0,0,3.6299453,0.0,0.50160581,69.521187,4.0329237,417.56351,-9.2287588
2507,2507,195.4176,9.0338449,5.9641891,0.0,0,3.5926332,0.0,0.50628722,69.283974,3.991673,417.26059,-9.2278576
2509,2509,195.418,9.0767469,5.995616,0.0,0,3.5565166,0.0,0.51055491,69.306953,3.9513953,416.95767,-9.2298098
2511,2511,195.4184,9.1349068,6.0397868,0.0,0,3.5210168,0.0,0.5141288,69.513321,3.9165437,416.65475,-9.2302914
2513,2513,195.4188,9.1612663,6.0733547,0.0,0,3.4855206,0.0,0.5188337,69.416954,3.8781254,416.35181,-9.2285538
2515,2515,195.4192,9.1802139,6.1120381,0.0,0,3.4500248,0.0,0.52301759,69.308556,3.8395667,415.97778,-9.2287245
2517,2517,195.4196,9.212821,6.1602368,0.0,0,3.4145288,0.0,0.52752393,69.210098,3.8017535,415.39041,-9.2288246
2519,2519,195.42,9.2659044,6.1906967,0.0,0,3.3790326,0.0,0.53226966,69.231812,3.7628961,414.80307,-9.2300472
2521,2521,195.4204,9.3366785,6.2260652,0.0,0,3.3435369,0.0,0.53568196,69.540421,3.7244916,414.21573,-9.2304468
2523,2523,195.4208,9.3764954,6.2711921,0.0,0,3.3080409,0.0,0.54040837,69.488197,3.6880441,413.62839,-9.2293196
2525,2525,195.4212,9.3845558,6.2992969,0.0,0,3.2725446,0.0,0.54485345,69.301643,3.6502109,413.04102,-9.2291956
2527,2527,195.4216,9.4233522,6.3397326,0.0,0,3.2370486,0.0,0.54845941,69.291565,3.6122441,412.45367,-9.2275715
2529,2529,195.422,9.4917889,6.383471,0.0,0,3.2015526,0.0,0.55380666,69.408897,3.5756865,411.86633,-9.2291632
2531,2531,195.4224,9.5553322,6.4132304,0.0,0,3.1660566,0.0,0.55793434,69.596222,3.5386992,411.27899,-9.2316389
2533,2533,195.4228,9.5711918,6.4548454,0.0,0,3.1309152,0.0,0.56164593,69.485222,3.5023234,410.69162,-9.2306757
2535,2535,195.4232,9.5988512,6.4927001,0.0,0,3.0970623,0.0,0.567123,69.314255,3.4645615,410.10428,-9.2297697
2537,2537,195.4236,9.6275845,6.5244021,0.0,0,3.0632944,0.0,0.57052439,69.283508,3.4295654,409.51694,-9.2280226
2539,2539,195.424,9.6986427,6.5626583,0.0,0,3.0295265,0.0,0.57451874,69.439735,3.3926785,408.92957,-9.2278843
2541,2541,195.4244,9.7732582,6.5968447,0.0,0,2.9957583,0.0,0.57962894,69.668312,3.3554764,408.34222,-9.2294979
2543,2543,195.4248,9.7950287,6.6364803,0.0,0,2.9619906,0.0,0.58342516,69.615067,3.3212726,407.75488,-9.2302971
2545,2545,195.4252,9.8254805,6.6730986,0.0,0,2.9282222,0.0,0.58791786,69.444229,3.2854939,407.16754,-9.2298498
2547,2547,195.4256,9.867939,6.7033854,0.0,0,2.8944542,0.0,0.5925923,69.412399,3.2480333,406.58017,-9.2292252
2549,2549,195.426,9.9621744,6.7451835,0.0,0,2.8606863,0.0,0.59614283,69.795151,3.2098987,405.99283,-9.2283602
2551,2551,195.4264,10.01977,6.7771864,0.0,0,2.8269184,0.0,0.60081148,69.994041,3.1772149,405.40549,-9.2269201
2553,2553,195.4268,10.035036,6.8094282,0.0,0,2.7931502,0.0,0.60499394,69.774117,3.1397133,404.81812,-9.2285748
2555,2555,195.4272,10.067598,6.8532095,0.0,0,2.7593822,0.0,0.60917902,69.718964,3.1060181,404.23077,-9.2298594
2557,2557,195.4276,10.128069,6.8826461,0.0,0,2.7256143,0.0,0.61407548,69.689278,3.0693932,403.64343,-9.2298765
2559,2559,195.428,10.206252,6.9180536,0.0,0,2.6929309,0.0,0.61789149,70.002716,3.0357671,403.05609,-9.2285738
2561,2561,195.4284,10.243876,6.9618716,0.0,0,2.6608074,0.0,0.62272972,69.967575,3.0009911,402.46872,-9.2277279
2563,2563,195.4288,10.277359,6.9858079,0.0,0,2.6286874,0.0,0.62711304,69.90551,2.9631975,401.88138,-9.2279482
2565,2565,195.4292,10.339047,7.0214739,0.0,0,2.5965672,0.0,0.63040841,69.974503,2.9292712,401.23392,-9.2292089
2567,2567,195.4296,10.387691,7.0620346,0.0,0,2.5644474,0.0,0.63558954,69.999496,2.8932939,400.40616,-9.2297134
2569,2569,195.43,10.454832,7.0888505,0.0,0,2.5323272,0.0,0.639817,70.190926,2.8611488,399.57843,-9.2282896
2571,2571,195.4304,10.518934,7.1304755,0.0,0,2.5002072,0.0,0.64387751,70.305618,2.8249106,398.75067,-9.2277508
2573,2573,195.4308,10.54828,7.1659536,0.0,0,2.4680872,0.0,0.64946759,70.105621,2.7952449,397.92291,-9.2275438
2575,2575,195.4312,10.593,7.1947622,0.0,0,2.4359674,0.0,0.65311646,70.152069,2.76001,397.09515,-9.2286215
2577,2577,195.4316,10.648533,7.2315731,0.0,0,2.4038472,0.0,0.65701491,70.256897,2.7269511,396.26743,-9.229105
2579,2579,195.432,10.711381,7.262857,0.0,0,2.3717272,0.0,0.66235453,70.293961,2.6944447,395.43967,-9.2297058
2581,2581,195.4324,10.776308,7.2977848,0.0,0,2.3396072,0.0,0.66588742,70.45356,2.6579127,394.61191,-9.2298794
2583,2583,195.4328,10.830354,7.3344574,0.0,0,2.3078089,0.0,0.67046034,70.511955,2.6249182,393.78415,-9.228816
2585,2585,195.4332,10.878772,7.3623366,0.0,0,2.2771804,0.0,0.67540967,70.464523,2.591949,392.95642,-9.2271137
2587,2587,195.4336,10.944199,7.4019179,0.0,0,2.246628,0.0,0.67912638,70.634262,2.5577023,392.12866,-9.2275372
2589,2589,195.434,11.04521,7.4332619,0.0,0,2.2160764,0.0,0.68395466,70.890961,2.5250704,391.3009,-9.2282619
2591,2591,195.4344,11.097885,7.4632835,0.0,0,2.1855242,0.0,0.6884892,70.956009,2.4902384,390.47314,-9.2289257
2593,2593,195.4348,11.145644,7.508348,0.0,0,2.1549723,0.0,0.69281465,70.933037,2.4571197,389.64539,-9.2289267
2595,2595,195.4352,11.185271,7.5336523,0.0,0,2.1244202,0.0,0.69765151,70.876213,2.4267533,388.81766,-9.2295618
2597,2597,195.4356,11.247218,7.5636353,0.0,0,2.0938683,0.0,0.7012648,70.96891,2.3897421,387.9899,-9.2284613
2599,2599,195.436,11.333837,7.6041613,0.0,0,2.0633163,0.0,0.70581162,71.167206,2.3576066,387.16214,-9.22824
2601,2601,195.4364,11.389899,7.6278152,0.0,0,2.0327644,0.0,0.71067715,71.283005,2.3231838,386.33438,-9.2269125
2603,2603,195.4368,11.439535,7.662076,0.0,0,2.0022123,0.0,0.71434927,71.271042,2.2914839,385.50665,-9.2280798
2605,2605,195.4372,11.482309,7.7036791,0.0,0,1.9716601,0.0,0.71976703,71.204346,2.2602794,384.67889,-9.2284212
2607,2607,195.4376,11.558291,7.7268004,0.0,0,1.9411081,0.0,0.72418278,71.291031,2.2272961,383.85114,-9.2291002
2609,2609,195.438,11.650622,7.7643714,0.0,0,1.9115355,0.0,0.72787535,71.567894,2.1922736,383.02338,-9.2273779
2611,2611,195.4384,11.710131,7.798068,0.0,0,1.8824685,0.0,0.73354155,71.578453,2.1642156,382.19565,-9.22721
2613,2613,195.4388,11.765305,7.8217468,0.0,0,1.8534043,0.0,0.73704833,71.627708,2.1318088,381.36789,-9.2263603
2615,2615,195.4392,11.799253,7.85532,0.0,0,1.8243403,0.0,0.74062693,71.613449,2.1009262,380.69611,-9.2275076
2617,2617,195.4396,11.884483,7.8867779,0.0,0,1.7952764,0.0,0.74629569,71.689407,2.0669644,380.49222,-9.2272081
2619,2619,195.44,11.977612,7.9191165,0.0,0,1.7662123,0.0,0.75016499,71.961441,2.0362463,380.2883,-9.2281313
2621,2621,195.4404,12.044823,7.9553404,0.0,0,1.7371484,0.0,0.75465775,72.066856,2.0039322,380.08441,-9.2277317
2623,2623,195.4408,12.084088,7.9815273,0.0,0,1.7080843,0.0,0.75999022,71.926804,1.9767953,379.88049,-9.227294
2625,2625,195.4412,12.142344,8.0153847,0.0,0,1.6790204,0.0,0.76333547,71.978065,1.9447641,379.67661,-9.2276478
2627,2627,195.4416,12.223965,8.043787,0.0,0,1.6499563,0.0,0.76799273,72.161057,1.9108773,379.47269,-9.2285757
2629,2629,195.442,12.326986,8.0690174,0.0,0,1.6208923,0.0,0.7723701,72.429794,1.8805631,379.26877,-9.2267647
2631,2631,195.4424,12.378989,8.1108685,0.0,0,1.5918283,0.0,0.77654576,72.466293,1.849725,379.06488,-9.2269163
2633,2633,195.4428,12.416338,8.1368332,0.0,0,1.5630548,0.0,0.78175169,72.362854,1.821198,378.86096,-9.2281265
2635,2635,195.4432,12.472758,8.1639519,0.0,0,1.5353373,0.0,0.78578097,72.358749,1.7935674,378.65707,-9.2285604
2637,2637,195.4436,12.566058,8.2013588,0.0,0,1.5076892,0.0,0.78990388,72.582123,1.76262,378.45316,-9.2294788
2639,2639,195.444,12.682091,8.2201347,0.0,0,1.4800413,0.0,0.79451501,72.85009,1.7339396,378.24927,-9.2281332
2641,2641,195.4444,12.734166,8.2489653,0.0,0,1.4523933,0.0,0.7977519,73.015709,1.7049284,378.04535,-9.2269316
2643,2643,195.4448,12.78581,8.2892427,0.0,0,1.4247453,0.0,0.80326402,72.893425,1.676397,377.84146,-9.2266788
2645,2645,195.4452,12.859205,8.3107996,0.0,0,1.3970973,0.0,0.80808175,72.98539,1.6465757,377.63754,-9.2275429
2647,2647,195.4456,12.957296,8.347024,0.0,0,1.3694494,0.0,0.81181419,73.215317,1.6174086,377.43362,-9.2278461
2649,2649,195.446,13.065598,8.3793736,0.0,0,1.3418013,0.0,0.81743389,73.362106,1.5867201,377.22974,-9.2282352
2651,2651,195.4464,13.1163,8.3979845,0.0,0,1.3141534,0.0,0.82093227,73.472679,1.5587851,377.02582,-9.2272968
2653,2653,195.4468,13.174959,8.4305124,0.0,0,1.2865053,0.0,0.82439977,73.495323,1.5284139,376.82193,-9.2263422
2655,2655,195.4472,13.258632,8.4570856,0.0,0,1.2588574,0.0,0.83005762,73.560417,1.4999102,376.61801,-9.2270136
2657,2657,195.4476,13.369788,8.4835548,0.0,0,1.2312094,0.0,0.83345103,73.933456,1.4704896,376.41412,-9.2276726
2659,2659,195.448,13.472381,8.5202799,0.0,0,1.2044513,0.0,0.83811295,74.124176,1.4453052,376.21021,-9.2275667
2661,2661,195.4484,13.537268,8.545372,0.0,0,1.1781524,0.0,0.84372652,74.079506,1.4118478,376.00629,-9.2274227
2663,2663,195.4488,13.605412,8.5777473,0.0,0,1.1518564,0.0,0.84719783,74.230865,1.3841228,375.8024,-9.226922
2665,2665,195.4492,13.698549,8.6056519,0.0,0,1.1255604,0.0,0.85198134,74.368675,1.3566006,375.36176,-9.2261953
2667,2667,195.4496,13.821474,8.6235456,0.0,0,1.0992644,0.0,0.85610318,74.705719,1.3293951,374.21097,-9.2255907
2669,2669,195.45,13.924172,8.6584997,0.0,0,1.0729684,0.0,0.85953063,74.988838,1.3003088,373.06018,-9.2257614
2671,2671,195.4504,14.001307,8.6848202,0.0,0,1.0466723,0.0,0.8651098,75.004868,1.2682185,371.90942,-9.2264929
2673,2673,195.4508,14.065159,8.7114544,0.0,0,1.0203763,0.0,0.86940378,75.06884,1.2441168,370.75864,-9.2274332
2675,2675,195.4512,14.162603,8.7525024,0.0,0,0.99408036,0.0,0.87407637,75.197609,1.2130671,369.60788,-9.2274714
2677,2677,195.4516,14.266776,8.7725945,0.0,0,0.96778435,0.0,0.87945968,75.34346,1.1871637,368.45709,-9.2262812
2679,2679,195.452,14.375839,8.7992487,0.0,0,0.94148839,0.0,0.88280445,75.650772,1.1596433,367.30634,-9.225522
2681,2681,195.4524,14.453681,8.8325396,0.0,0,0.91519243,0.0,0.88761592,75.744576,1.1306428,366.15555,-9.2257099
2683,2683,195.4528,14.541494,8.8465452,0.0,0,0.88916051,0.0,0.89165157,75.859749,1.1063951,365.00476,-9.2267647
2685,2685,195.4532,14.623458,8.8793354,0.0,0,0.86408949,0.0,0.89503735,76.05941,1.0769707,363.854,-9.2267075
2687,2687,195.4536,14.742367,8.9138899,0.0,0,0.83908135,0.0,0.90135795,76.163338,1.0528531,362.70322,-9.2259436
2689,2689,195.454,14.843307,8.9338284,0.0,0,0.81407332,0.0,0.90564144,76.367088,1.0222393,361.55246,-9.2252893
2691,2691,195.4544,14.93129,8.9671373,0.0,0,0.78906536,0.0,0.90948367,76.536072,0.99514091,360.40167,-9.2254639
2693,2693,195.4548,15.006716,8.9918127,0.0,0,0.7640574,0.0,0.91506433,76.433266,0.96874976,359.25092,-9.2272243
2695,2695,195.4552,15.104689,9.0109682,0.0,0,0.73904938,0.0,0.91784358,76.773155,0.9418118,358.10013,-9.226799
2697,2697,195.4556,15.233847,9.0413618,0.0,0,0.71404135,0.0,0.92198753,77.076706,0.91100758,356.94937,-9.2255688
2699,2699,195.456,15.348356,9.0661182,0.0,0,0.68903339,0.0,0.92807245,77.197021,0.88548338,355.79858,-9.2245522
2701,2701,195.4564,15.436524,9.0965557,0.0,0,0.66402543,0.0,0.93151551,77.336746,0.86028689,354.6478,-9.2249174
2703,2703,195.4568,15.52166,9.1264772,0.0,0,0.63901734,0.0,0.93678361,77.382668,0.83284324,353.49704,-9.2259626
2705,2705,195.4572,15.630112,9.1438522,0.0,0,0.61400938,0.0,0.94138902,77.583542,0.80631828,352.34625,-9.2266092
2707,2707,195.4576,15.753504,9.1756706,0.0,0,0.58900136,0.0,0.94453073,77.918915,0.77959692,351.1955,-9.2258253
2709,2709,195.458,15.875312,9.198637,0.0,0,0.56478846,0.0,0.94979554,78.069397,0.7558524,350.04471,-9.2245703
2711,2711,195.4584,15.959885,9.2193203,0.0,0,0.54098594,0.0,0.95394015,78.219276,0.7294699,348.89395,-9.2248096
2713,2713,195.4588,16.052465,9.2549305,0.0,0,0.51718587,0.0,0.9577617,78.365837,0.70199305,347.74316,-9.224721
2715,2715,195.4592,16.160265,9.272357,0.0,0,0.49338591,0.0,0.96309209,78.461647,0.6772396,346.72,-9.2255058
2717,2717,195.4596,16.304983,9.2972164,0.0,0,0.4695859,0.0,0.96664375,78.875214,0.65162867,346.07959,-9.2265062
2719,2719,195.46,16.42469,9.3334818,0.0,0,0.44578591,0.0,0.97190374,79.051247,0.62529117,345.43918,-9.2259865
2721,2721,195.4604,16.516027,9.3491306,0.0,0,0.42198589,0.0,0.97697234,79.151176,0.59895819,344.79877,-9.225235
2723,2723,195.4608,16.61013,9.3775654,0.0,0,0.39818591,0.0,0.9799881,79.321709,0.57214373,344.15839,-9.2246065
2725,2725,195.4612,16.741905,9.4067516,0.0,0,0.37438589,0.0,0.98566073,79.508514,0.55068338,343.51797,-9.2242603
2727,2727,195.4616,16.890516,9.4197674,0.0,0,0.35058588,0.0,0.98936421,79.888878,0.52661186,342.87756,-9.2235956