File: clean data/testID_0223.csv
index,Time(sec),Force(kN),Jaw(mm),PowAngle(deg),Power(W),Pram,PTemp,Strain,Stress(MPa),Stroke(mm),TC1(C),wedge(mm)
2271,195.3433,0.53808212,0.023003131,0.0,0,9.1214981,0.0,0.0011911517,5.2821069,10.190772,442.62314,-9.2364435
2272,195.3435,1.6732585,0.040515061,0.0,0,9.0922337,0.0,0.0024561482,17.836102,10.156445,443.47937,-9.2359285
2273,195.3437,2.9471552,0.070051119,0.0,0,9.0629702,0.0,0.0044442257,34.414829,10.126882,444.33557,-9.2357473
2274,195.3439,3.6795566,0.092502668,0.0,0,9.0337057,0.0,0.0057297447,45.169537,10.099983,445.1918,-9.2351265
2275,195.3441,3.9157958,0.11295089,0.0,0,9.0044422,0.0,0.0073149581,49.088188,10.069965,446.04803,-9.2338543
2276,195.3443,3.9527512,0.149487,0.0,0,8.9751778,0.0,0.0097149331,49.765354,10.032652,446.90424,-9.2327232
2277,195.3445,4.0308995,0.20845537,0.0,0,8.9459143,0.0,0.012986213,50.388252,9.9911985,447.76047,-9.2318411
2278,195.3447,3.9966018,0.28035074,0.0,0,8.9166498,0.0,0.017877381,50.190266,9.9497156,448.61667,-9.2312956
2279,195.3449,3.795567,0.34851047,0.0,0,8.8873854,0.0,0.02289384,47.770378,9.8994322,449.4729,-9.2318153
2280,195.3451,3.6651831,0.4075847,0.0,0,8.8581219,0.0,0.026638845,45.536224,9.8431435,450.3291,-9.2326984
2281,195.3453,3.751761,0.46555987,0.0,0,8.8288574,0.0,0.030627679,46.018795,9.7873688,451.18533,-9.2329836
2282,195.3455,3.8335185,0.52660346,0.0,0,8.7995939,0.0,0.035137028,47.061253,9.7305651,452.04153,-9.2329779
2283,195.3457,3.9022474,0.58297896,0.0,0,8.7703295,0.0,0.038851116,47.644329,9.6737509,452.89777,-9.232933
2284,195.3459,4.0928454,0.61973393,0.0,0,8.7416534,0.0,0.041611593,49.515835,9.6192608,453.754,-9.2329292
2285,195.3461,4.1873999,0.64076245,0.0,0,8.7136869,0.0,0.043636069,51.04781,9.5700827,454.6102,-9.2322149
2286,195.3463,4.0264239,0.67120236,0.0,0,8.6858492,0.0,0.045328811,49.670181,9.5248203,455.46643,-9.2313004
2287,195.3465,3.8156857,0.70896846,0.0,0,8.6580172,0.0,0.047682073,46.905891,9.4858274,456.32263,-9.2311373
2288,195.3467,3.8355746,0.73916739,0.0,0,8.6301851,0.0,0.050389785,46.231697,9.4522572,457.17886,-9.2313337
2289,195.3469,4.0382037,0.76763099,0.0,0,8.6023531,0.0,0.052235454,48.233143,9.4173584,458.03506,-9.2319708
2290,195.3471,4.1741624,0.79120094,0.0,0,8.5745211,0.0,0.053615443,50.164265,9.3808804,458.8913,-9.2318497
2291,195.3473,4.2500935,0.8153773,0.0,0,8.546689,0.0,0.055686954,51.084164,9.3450251,459.74753,-9.2313318
2292,195.3475,4.4051857,0.86340916,0.0,0,8.518857,0.0,0.05867485,52.547596,9.3076105,460.60373,-9.2314644
2293,195.3477,4.5150309,0.92018133,0.0,0,8.491025,0.0,0.062259398,53.951809,9.2677746,461.45996,-9.2320089
2294,195.3479,4.3636994,0.96506381,0.0,0,8.4631929,0.0,0.065992735,52.629375,9.225996,462.31616,-9.2326088
2295,195.3481,4.1119585,1.0147116,0.0,0,8.4353609,0.0,0.069458239,49.450623,9.1833467,463.17239,-9.232378
2296,195.3483,4.0846844,1.0679557,0.0,0,8.4075289,0.0,0.072742358,48.223675,9.1378613,464.02859,-9.2323265
2297,195.3485,4.2090845,1.1104475,0.0,0,8.3796968,0.0,0.076280206,49.304989,9.0908175,464.88483,-9.2326832
2298,195.3487,4.2166419,1.1567881,0.0,0,8.3518648,0.0,0.07980606,49.683846,9.0448332,465.74103,-9.2321596
2299,195.3489,4.1165328,1.1992936,0.0,0,8.3240328,0.0,0.082470246,48.496243,9.0024357,466.59726,-9.2313051
2300,195.3491,4.1312957,1.2185338,0.0,0,8.2962008,0.0,0.084381081,48.174171,8.9606962,467.45349,-9.2316751
2301,195.3493,4.278389,1.2423898,0.0,0,8.2683687,0.0,0.086338788,49.582504,8.9215584,468.30969,-9.2321558
2302,195.3495,4.3185263,1.2776678,0.0,0,8.2405367,0.0,0.088220254,50.31823,8.8877506,469.16592,-9.2323046
2303,195.3497,4.1606755,1.3016747,0.0,0,8.2127056,0.0,0.090237565,48.790718,8.8561363,470.02213,-9.2325411
2304,195.3499,4.0400147,1.3298379,0.0,0,8.1848736,0.0,0.092733383,46.976715,8.8250866,470.87836,-9.2325563
2305,195.3501,4.1582966,1.3599935,0.0,0,8.1570406,0.0,0.094464064,47.662994,8.7946138,471.73456,-9.2339573
2306,195.3503,4.3952293,1.3751118,0.0,0,8.1292095,0.0,0.095685571,50.300884,8.7655773,472.59079,-9.2348442
2307,195.3505,4.5198264,1.4015435,0.0,0,8.1013775,0.0,0.097919755,52.015026,8.7361803,473.44699,-9.2342796
2308,195.3507,4.5010972,1.4433342,0.0,0,8.0735445,0.0,0.10045289,51.957298,8.7067299,474.30322,-9.2335062
2309,195.3509,4.4636512,1.4769769,0.0,0,8.0462675,0.0,0.10289956,51.315876,8.6768703,475.15945,-9.2332602
2310,195.3511,4.4638319,1.515126,0.0,0,8.0196619,0.0,0.10617044,51.011456,8.6452913,476.01566,-9.2325048
2311,195.3513,4.4414854,1.5618449,0.0,0,7.993176,0.0,0.10924427,50.762543,8.6115046,476.87189,-9.2309246
2312,195.3515,4.3506336,1.6000491,0.0,0,7.9666953,0.0,0.11187975,49.777275,8.5752745,477.72809,-9.2305088
2313,195.3517,4.267015,1.6406739,0.0,0,7.9402156,0.0,0.11544084,48.551434,8.5398254,478.58432,-9.2306604
2314,195.3519,4.2694368,1.6824106,0.0,0,7.9137354,0.0,0.11848508,48.217945,8.5025978,479.44052,-9.2309475
2315,195.3521,4.3332238,1.7055316,0.0,0,7.8872552,0.0,0.12003762,48.71917,8.4667044,480.29675,-9.2312126
2316,195.3523,4.3799782,1.7238551,0.0,0,7.860775,0.0,0.12196571,49.211613,8.4341297,481.15295,-9.231946
2317,195.3525,4.3679543,1.7517215,0.0,0,7.8342953,0.0,0.12399304,49.212334,8.4039316,482.00919,-9.2325726
2318,195.3527,4.3316412,1.7782401,0.0,0,7.8078156,0.0,0.12550622,48.769417,8.3741865,482.86542,-9.2331676
2319,195.3529,4.2986689,1.8029898,0.0,0,7.7813349,0.0,0.12778465,48.259663,8.3461332,483.72162,-9.2337408
2320,195.3531,4.2675238,1.8272611,0.0,0,7.7548552,0.0,0.12981735,47.836464,8.3201885,484.60916,-9.2339439
2321,195.3533,4.2745905,1.8438874,0.0,0,7.728375,0.0,0.13069741,47.759254,8.2941856,485.52798,-9.2334042
2322,195.3535,4.3573718,1.861618,0.0,0,7.7018952,0.0,0.1322272,48.372597,8.2714252,486.44684,-9.2319555
2323,195.3537,4.4722075,1.8877317,0.0,0,7.675415,0.0,0.13435987,49.572147,8.2472086,487.36566,-9.2317371
2324,195.3539,4.5452433,1.9161515,0.0,0,7.6489348,0.0,0.1360447,50.50536,8.222086,488.28452,-9.2322636
2325,195.3541,4.5552421,1.9425626,0.0,0,7.6224551,0.0,0.13825928,50.548733,8.1979504,489.20334,-9.2316952
2326,195.3543,4.5494814,1.9695895,0.0,0,7.5959754,0.0,0.14071421,50.284378,8.1719007,490.12216,-9.231638
2327,195.3545,4.5489411,2.0008929,0.0,0,7.5694952,0.0,0.14252675,50.181744,8.1420088,491.04102,-9.2316093
2328,195.3547,4.5088906,2.032006,0.0,0,7.543015,0.0,0.14490207,49.79063,8.1129522,491.95984,-9.2315197
2329,195.3549,4.4221931,2.0609493,0.0,0,7.5165353,0.0,0.14769946,48.795681,8.0847483,492.87869,-9.2325277
2330,195.3551,4.3798823,2.090435,0.0,0,7.4900556,0.0,0.14962597,48.086746,8.0565948,493.79752,-9.233119
2331,195.3553,4.4251661,2.11291,0.0,0,7.4635754,0.0,0.1512918,48.327782,8.0308084,494.71637,-9.2329493
2332,195.3555,4.4836283,2.1302426,0.0,0,7.4370952,0.0,0.15321444,48.886436,8.0040512,495.63519,-9.2328987
2333,195.3557,4.4902806,2.1577163,0.0,0,7.410615,0.0,0.15490438,48.961685,7.9754262,496.55402,-9.2328024
2334,195.3559,4.4578557,2.1851122,0.0,0,7.384666,0.0,0.15678687,48.602665,7.9497318,497.47287,-9.2325687
2335,195.3561,4.4396496,2.2031233,0.0,0,7.3593607,0.0,0.15886679,48.268475,7.9282284,498.39169,-9.2325544
2336,195.3563,4.440865,2.2261431,0.0,0,7.3341718,0.0,0.16036206,48.20681,7.9049296,499.31055,-9.232482
2337,195.3565,4.4530454,2.2482378,0.0,0,7.3089876,0.0,0.1616604,48.262947,7.8795762,500.22937,-9.2318239
2338,195.3567,4.4637389,2.2633464,0.0,0,7.2838035,0.0,0.1634675,48.227104,7.8569393,501.14822,-9.231245
2339,195.3569,4.5011306,2.2887988,0.0,0,7.2586198,0.0,0.16527463,48.500706,7.8345094,502.06705,-9.2312717
2340,195.3571,4.5746298,2.3158188,0.0,0,7.2334356,0.0,0.16685976,49.124737,7.8122582,502.9859,-9.2320518
2341,195.3573,4.620347,2.3309379,0.0,0,7.2082515,0.0,0.16868782,49.606541,7.7901626,503.90472,-9.2328138
2342,195.3575,4.6151905,2.3566179,0.0,0,7.1830673,0.0,0.17071794,49.60223,7.7660556,504.82355,-9.2326746
2343,195.3577,4.5891829,2.3902743,0.0,0,7.1578832,0.0,0.17267072,49.204578,7.7417479,505.7424,-9.2325487
2344,195.3579,4.579689,2.4105403,0.0,0,7.132699,0.0,0.17478518,48.925022,7.7201252,506.66122,-9.2323742
2345,195.3581,4.580399,2.4362977,0.0,0,7.1075149,0.0,0.17710431,48.829399,7.696805,507.58008,-9.2318935
2346,195.3583,4.5772953,2.4649501,0.0,0,7.0823312,0.0,0.17875575,48.714237,7.6711907,508.4989,-9.2313919
2347,195.3585,4.5933595,2.4778457,0.0,0,7.0571475,0.0,0.18017347,48.729446,7.6476302,509.41776,-9.2312288
2348,195.3587,4.6181021,2.5009558,0.0,0,7.0319633,0.0,0.18227714,48.902508,7.6240597,510.33658,-9.2311602
2349,195.3589,4.6233678,2.5324211,0.0,0,7.0067787,0.0,0.18416037,48.907986,7.6000972,511.25543,-9.2314892
2350,195.3591,4.5953121,2.5478995,0.0,0,6.981595,0.0,0.18574187,48.619186,7.5764823,512.17426,-9.2321024
2351,195.3593,4.5507479,2.5675941,0.0,0,6.9564114,0.0,0.18780306,48.13961,7.5540671,513.09308,-9.2319193
2352,195.3595,4.5418601,2.593776,0.0,0,6.9312272,0.0,0.18927872,47.846935,7.5334544,514.0119,-9.232028
2353,195.3597,4.5850983,2.6078856,0.0,0,6.9060431,0.0,0.19045556,48.115459,7.5118842,514.93079,-9.2325811
2354,195.3599,4.6419172,2.6281621,0.0,0,6.8808589,0.0,0.19261272,48.623814,7.4886079,515.84961,-9.2325754
2355,195.3601,4.6797004,2.6575313,0.0,0,6.8556757,0.0,0.19449997,49.01646,7.4649692,516.76843,-9.2329826
2356,195.3603,4.7047958,2.6748517,0.0,0,6.8304915,0.0,0.19583136,49.160995,7.4423237,517.68726,-9.2328777
2357,195.3605,4.7189488,2.6944456,0.0,0,6.8053074,0.0,0.19796266,49.204105,7.4200382,518.60614,-9.2317219
2358,195.3607,4.71661,2.7245932,0.0,0,6.7801232,0.0,0.20005161,49.177338,7.3993034,519.52496,-9.2310162
2359,195.3609,4.6962681,2.7473757,0.0,0,6.7554412,0.0,0.20161387,48.891548,7.3765121,520.44379,-9.2310915
2360,195.3611,4.6647267,2.769855,0.0,0,6.7313666,0.0,0.20401295,48.514111,7.3527098,521.36261,-9.2319126
2361,195.3613,4.6594224,2.7977211,0.0,0,6.7074018,0.0,0.2061692,48.334293,7.3292146,522.28143,-9.2323074
2362,195.3615,4.6883917,2.81636,0.0,0,6.6834412,0.0,0.20731996,48.452217,7.3039503,523.20032,-9.2325907
2363,195.3617,4.7293348,2.8351626,0.0,0,6.6594815,0.0,0.20938301,48.751698,7.2821379,524.11914,-9.2329445
2364,195.3619,4.7726178,2.8627439,0.0,0,6.6355214,0.0,0.21157156,49.058678,7.2610726,525.03796,-9.2326984
2365,195.3621,4.7931366,2.8851917,0.0,0,6.6115613,0.0,0.21287155,49.262032,7.238183,525.95679,-9.2333212
2366,195.3623,4.7814384,2.9045622,0.0,0,6.5876012,0.0,0.21495615,49.137295,7.2152772,526.87561,-9.233551
2367,195.3625,4.7604504,2.9281161,0.0,0,6.5636415,0.0,0.21713057,48.800938,7.1945128,527.79449,-9.2332735
2368,195.3627,4.7493567,2.9496489,0.0,0,6.5396814,0.0,0.21838795,48.617855,7.1705909,528.71332,-9.2329025
2369,195.3629,4.7560153,2.9703417,0.0,0,6.5157218,0.0,0.22034334,48.590267,7.1438093,529.63214,-9.2323914
2370,195.3631,4.7793198,2.9950786,0.0,0,6.4917617,0.0,0.22266677,48.698021,7.1211324,530.10944,-9.2318344
2371,195.3633,4.8128748,3.0194073,0.0,0,6.467802,0.0,0.22413908,48.973957,7.0988474,530.1452,-9.2316856
2372,195.3635,4.8493876,3.0405412,0.0,0,6.4438419,0.0,0.22605625,49.198917,7.0763078,530.18103,-9.2316704
2373,195.3637,4.8844213,3.0631349,0.0,0,6.4198813,0.0,0.22840863,49.433563,7.0539265,530.2168,-9.2317142
2374,195.3639,4.9074073,3.0908513,0.0,0,6.3959212,0.0,0.23009808,49.653458,7.0305333,530.25256,-9.2320709
2375,195.3641,4.8951621,3.1163862,0.0,0,6.3719611,0.0,0.23223042,49.469967,7.007586,530.28833,-9.2323942
2376,195.3643,4.8666601,3.1383581,0.0,0,6.3480015,0.0,0.23472348,49.128204,6.9839468,530.3241,-9.2334986
2377,195.3645,4.8613191,3.164449,0.0,0,6.3240414,0.0,0.23639724,48.92704,6.9595037,530.35992,-9.234004
2378,195.3647,4.8750672,3.1873412,0.0,0,6.3000817,0.0,0.23816428,48.883053,6.9357462,530.39569,-9.2334366
2379,195.3649,4.8953376,3.2052994,0.0,0,6.2761216,0.0,0.24037753,48.99519,6.9115753,530.43146,-9.2325382
2380,195.3651,4.9149814,3.232794,0.0,0,6.252162,0.0,0.2422585,49.078754,6.8868184,530.46722,-9.2315378
2381,195.3653,4.929038,3.2580361,0.0,0,6.2282019,0.0,0.24412704,49.103569,6.8636751,530.50299,-9.2309399
2382,195.3655,4.9413033,3.2730284,0.0,0,6.2042418,0.0,0.24621478,49.171494,6.8411312,530.53882,-9.2309732
2383,195.3657,4.9558678,3.2987697,0.0,0,6.1802816,0.0,0.24802278,49.245728,6.8174543,530.57458,-9.2310591
2384,195.3659,4.9683681,3.3262618,0.0,0,6.1568022,0.0,0.24981607,49.239925,6.7920833,530.61035,-9.2311182
2385,195.3661,4.977869,3.3433545,0.0,0,6.1339045,0.0,0.25204098,49.209103,6.7679658,530.64612,-9.2322302
2386,195.3663,4.9986639,3.371026,0.0,0,6.1111116,0.0,0.25426716,49.295219,6.743628,530.68188,-9.2329683
2387,195.3665,5.017242,3.4003747,0.0,0,6.0883236,0.0,0.25612634,49.399349,6.7185402,530.71771,-9.2327814
2388,195.3667,5.0284047,3.4166327,0.0,0,6.0655355,0.0,0.25819126,49.422596,6.6957397,530.75348,-9.23351
2389,195.3669,5.0410905,3.4441788,0.0,0,6.042748,0.0,0.26063338,49.405258,6.6732092,530.78925,-9.2333965
2390,195.3671,5.0473299,3.4770432,0.0,0,6.0199599,0.0,0.26272812,49.375919,6.6473384,530.82501,-9.2325811
2391,195.3673,5.0492191,3.4939356,0.0,0,5.9971714,0.0,0.26480612,49.336773,6.6182117,530.86078,-9.2323341
2392,195.3675,5.0614486,3.5180168,0.0,0,5.9743834,0.0,0.26721719,49.299381,6.5956502,530.89661,-9.2318058
2393,195.3677,5.0749102,3.5493214,0.0,0,5.9515953,0.0,0.26913202,49.328663,6.574245,530.93237,-9.2315788
2394,195.3679,5.0934472,3.566323,0.0,0,5.9288073,0.0,0.27101293,49.439484,6.5453157,530.96814,-9.2315664
2395,195.3681,5.1145945,3.5910809,0.0,0,5.9060197,0.0,0.2736325,49.447861,6.5194459,531.00391,-9.2313766
2396,195.3683,5.1215806,3.6234016,0.0,0,5.8832316,0.0,0.27571899,49.401096,6.4962707,531.03967,-9.2318096
2397,195.3685,5.1239238,3.6398551,0.0,0,5.8604436,0.0,0.27740595,49.375256,6.4715557,531.0755,-9.2324257
2398,195.3687,5.1274242,3.6632724,0.0,0,5.8376555,0.0,0.28003368,49.366779,6.4480076,531.11127,-9.2333422
2399,195.3689,5.1280208,3.6967416,0.0,0,5.814867,0.0,0.28224781,49.281235,6.4239879,531.14703,-9.23351
2400,195.3691,5.1321588,3.7157149,0.0,0,5.792079,0.0,0.28398433,49.173901,6.4002395,531.1828,-9.2327795
2401,195.3693,5.1415596,3.7381194,0.0,0,5.7692914,0.0,0.28665906,49.109798,6.3755221,531.21857,-9.2325544
2402,195.3695,5.1647768,3.7689002,0.0,0,5.7465034,0.0,0.28882718,49.209888,6.3494172,531.25439,-9.2325172
2403,195.3697,5.1911836,3.7874811,0.0,0,5.7237153,0.0,0.29027513,49.450405,6.3256159,531.29016,-9.2318354
2404,195.3699,5.2112942,3.8088458,0.0,0,5.7009273,0.0,0.29281428,49.57732,6.3012762,531.32593,-9.2310133
2405,195.3701,5.225471,3.8402758,0.0,0,5.6781397,0.0,0.2952542,49.584675,6.277113,531.36169,-9.2308941
2406,195.3703,5.2269397,3.862385,0.0,0,5.6553516,0.0,0.2968677,49.492157,6.2540364,531.39746,-9.2309666
2407,195.3705,5.2240744,3.8838773,0.0,0,5.6325636,0.0,0.29943472,49.355843,6.230948,531.43329,-9.2310486
2408,195.3707,5.2282295,3.913358,0.0,0,5.6097751,0.0,0.30194509,49.254215,6.2047448,531.46906,-9.2312174
2409,195.3709,5.2379103,3.9361665,0.0,0,5.5874414,0.0,0.30356747,49.260132,6.1787395,531.50482,-9.2317657
2410,195.3711,5.2502728,3.9577901,0.0,0,5.5656581,0.0,0.30610257,49.228065,6.1562457,531.54059,-9.2323704
2411,195.3713,5.2663102,3.9860361,0.0,0,5.5439734,0.0,0.30872506,49.196259,6.1319776,531.57635,-9.2326241
2412,195.3715,5.2888913,4.0102754,0.0,0,5.5222936,0.0,0.31031382,49.277393,6.1068745,531.61218,-9.2329493
2413,195.3717,5.3168864,4.0316339,0.0,0,5.5006132,0.0,0.31267276,49.437637,6.0818114,531.64795,-9.2324247
2414,195.3719,5.3248816,4.0570312,0.0,0,5.4789333,0.0,0.31527963,49.466705,6.0583653,531.68372,-9.23209
2415,195.3721,5.3283315,4.0818911,0.0,0,5.457253,0.0,0.31686789,49.43462,6.0356598,531.71948,-9.2324228
2416,195.3723,5.3406372,4.1042161,0.0,0,5.4355731,0.0,0.31918749,49.414337,6.0098338,531.75525,-9.232399
2417,195.3725,5.3475881,4.128108,0.0,0,5.4138932,0.0,0.32185313,49.326275,5.9858398,531.79108,-9.232398
2418,195.3727,5.3484468,4.1534395,0.0,0,5.3922133,0.0,0.32344401,49.267159,5.9627357,531.82684,-9.2324295
2419,195.3729,5.356493,4.1758022,0.0,0,5.370533,0.0,0.32564473,49.264328,5.9379301,531.86261,-9.2326345
2420,195.3731,5.3705792,4.1986971,0.0,0,5.3488531,0.0,0.3284314,49.266819,5.9134254,531.85547,-9.2326508
2421,195.3733,5.3829894,4.2275538,0.0,0,5.3271732,0.0,0.33035165,49.247849,5.8884811,531.80536,-9.232461
2422,195.3735,5.3991628,4.2525249,0.0,0,5.3054934,0.0,0.3326112,49.269802,5.8648634,531.75525,-9.2328672
2423,195.3737,5.4287438,4.2735868,0.0,0,5.283813,0.0,0.33543402,49.378517,5.841279,531.7052,-9.23277
2424,195.3739,5.4564118,4.3026829,0.0,0,5.2621331,0.0,0.33754963,49.526413,5.81497,531.65509,-9.2323122
2425,195.3741,5.4708591,4.3296041,0.0,0,5.2404532,0.0,0.33972278,49.558983,5.7895298,531.60498,-9.2325554
2426,195.3743,5.4663181,4.3495288,0.0,0,5.2187734,0.0,0.34244478,49.409031,5.7661672,531.55493,-9.2321844
2427,195.3745,5.4595799,4.3775916,0.0,0,5.1970935,0.0,0.34469175,49.228947,5.7425189,531.50482,-9.2321253
2428,195.3747,5.4649124,4.4043379,0.0,0,5.1754136,0.0,0.3467083,49.1311,5.7192965,531.45471,-9.2323895
2429,195.3749,5.4693103,4.4214787,0.0,0,5.1537333,0.0,0.34917697,49.086609,5.6918859,531.40466,-9.2326002
2430,195.3751,5.478766,4.4488831,0.0,0,5.1320534,0.0,0.35153955,49.059029,5.664443,531.35455,-9.2327366
2431,195.3753,5.4863033,4.4775686,0.0,0,5.110373,0.0,0.35355943,49.014812,5.6411428,531.30444,-9.2326632
2432,195.3755,5.497148,4.4929681,0.0,0,5.0886931,0.0,0.35580385,49.025723,5.6170273,531.25433,-9.2326593
2433,195.3757,5.5204163,4.5173988,0.0,0,5.0670133,0.0,0.35811007,49.124935,5.5919185,531.20428,-9.2320509
2434,195.3759,5.5417428,4.5463467,0.0,0,5.0457678,0.0,0.36005828,49.207241,5.5675774,531.15417,-9.2319918
2435,195.3761,5.5587916,4.5624647,0.0,0,5.0250483,0.0,0.36232382,49.22139,5.5437584,531.10406,-9.2318525
2436,195.3763,5.5561242,4.5875144,0.0,0,5.0044241,0.0,0.3649604,49.084808,5.518959,531.05402,-9.2311726
2437,195.3765,5.5384364,4.618113,0.0,0,4.9838037,0.0,0.36698762,48.905441,5.4951453,531.00391,-9.2316027
2438,195.3767,5.5405159,4.6333141,0.0,0,4.9631839,0.0,0.36906371,48.804775,5.4726624,530.9538,-9.2321405
2439,195.3769,5.5565867,4.6580467,0.0,0,4.9425635,0.0,0.37189156,48.796005,5.4502368,530.90375,-9.2323761
2440,195.3771,5.5743413,4.6898232,0.0,0,4.9219437,0.0,0.37401372,48.852024,5.4263234,530.85364,-9.2325211
2441,195.3773,5.5979581,4.7047591,0.0,0,4.9013238,0.0,0.37585703,48.943138,5.4027462,530.80353,-9.2325268
2442,195.3775,5.6207089,4.7269745,0.0,0,4.8807039,0.0,0.37864095,48.95993,5.3816895,530.75348,-9.232336
2443,195.3777,5.6424365,4.7573624,0.0,0,4.8600836,0.0,0.38074905,49.049152,5.3574886,530.70337,-9.2317505
2444,195.3779,5.6666913,4.7737894,0.0,0,4.8394637,0.0,0.38247195,49.187557,5.3320837,530.65326,-9.2319794
2445,195.3781,5.6782413,4.796308,0.0,0,4.8188438,0.0,0.38527885,49.137367,5.3086767,530.60321,-9.2325325
2446,195.3783,5.671555,4.8276987,0.0,0,4.798224,0.0,0.38759169,49.039814,5.2867169,530.5531,-9.2319584
2447,195.3785,5.6628733,4.8457584,0.0,0,4.7776036,0.0,0.38935584,48.90097,5.2657433,530.50299,-9.2317581
2448,195.3787,5.6635637,4.8675017,0.0,0,4.7569838,0.0,0.39223599,48.705162,5.2432275,530.45294,-9.2316132
2449,195.3789,5.6766119,4.8982148,0.0,0,4.7363639,0.0,0.39467403,48.66132,5.2178431,530.40283,-9.231492
2450,195.3791,5.6980524,4.9168978,0.0,0,4.7157435,0.0,0.39628002,48.777557,5.1927919,530.35272,-9.2315025
2451,195.3793,5.7158055,4.9370394,0.0,0,4.6951237,0.0,0.39911357,48.818211,5.1716909,530.30267,-9.2313528
2452,195.3795,5.7366276,4.9672689,0.0,0,4.6745038,0.0,0.40176398,48.86655,5.1488013,530.25256,-9.2320757
2453,195.3797,5.7633977,4.988061,0.0,0,4.6538839,0.0,0.40329343,49.005409,5.1239171,530.20245,-9.2323065
2454,195.3799,5.770679,5.0062671,0.0,0,4.6332641,0.0,0.40590057,48.923656,5.1018548,530.1524,-9.2322397
2455,195.3801,5.7584252,5.0332494,0.0,0,4.6126437,0.0,0.40856934,48.698681,5.0804543,530.10229,-9.2319565
2456,195.3803,5.7524338,5.0556326,0.0,0,4.5920234,0.0,0.4100824,48.620884,5.0593553,530.05219,-9.2313347
2457,195.3805,5.7547774,5.0744281,0.0,0,4.5714035,0.0,0.41258642,48.5112,5.0370922,530.00208,-9.2316732
2458,195.3807,5.7627192,5.0979099,0.0,0,4.5507836,0.0,0.4152624,48.477673,5.0130286,529.95203,-9.2321749
2459,195.3809,5.776638,5.1187472,0.0,0,4.5305758,0.0,0.41663355,48.527023,4.9920526,529.90192,-9.2321835
2460,195.3811,5.7948241,5.1374106,0.0,0,4.5108657,0.0,0.41889656,48.497913,4.9715652,529.85181,-9.2315636
2461,195.3813,5.8116341,5.161098,0.0,0,4.4912457,0.0,0.42171463,48.543205,4.9502206,529.80176,-9.2315922
2462,195.3815,5.8282723,5.1854362,0.0,0,4.4716296,0.0,0.42328644,48.60154,4.9286551,529.75165,-9.231679
2463,195.3817,5.8392577,5.2056627,0.0,0,4.4520135,0.0,0.42556211,48.528435,4.9056549,529.70154,-9.2310915
2464,195.3819,5.8427286,5.226542,0.0,0,4.4323974,0.0,0.42845383,48.46463,4.8825617,529.65149,-9.2313738
2465,195.3821,5.8499188,5.2517643,0.0,0,4.4127812,0.0,0.43015999,48.460052,4.8619919,529.60138,-9.2320719
2466,195.3823,5.8599796,5.2739606,0.0,0,4.3931651,0.0,0.43239558,48.378773,4.8402343,529.55127,-9.231823
2467,195.3825,5.8637891,5.2930217,0.0,0,4.3735495,0.0,0.43526572,48.260807,4.818604,529.50122,-9.2311258
2468,195.3827,5.8647213,5.3180466,0.0,0,4.3539338,0.0,0.43712091,48.17627,4.7984242,529.45111,-9.2317419
2469,195.3829,5.880301,5.3385482,0.0,0,4.3343177,0.0,0.43905535,48.192268,4.7763476,529.401,-9.2319632
2470,195.3831,5.9009562,5.3527865,0.0,0,4.3147016,0.0,0.44159055,48.245956,4.7555237,529.25189,-9.2313766
2471,195.3833,5.9152875,5.3777714,0.0,0,4.2950859,0.0,0.44358224,48.266159,4.7345915,529.00378,-9.2311726
2472,195.3835,5.9353571,5.4006653,0.0,0,4.2754693,0.0,0.44547352,48.327106,4.7112422,528.75568,-9.2318115
2473,195.3837,5.9475126,5.41432,0.0,0,4.2558532,0.0,0.44792661,48.346546,4.6909771,528.50751,-9.2324162
2474,195.3839,5.9526472,5.439187,0.0,0,4.236237,0.0,0.4500334,48.327744,4.6722627,528.2594,-9.23242
2475,195.3841,5.9599972,5.4636159,0.0,0,4.2166214,0.0,0.45182914,48.302395,4.6511517,528.01123,-9.2325296
2476,195.3843,5.9603972,5.4768038,0.0,0,4.1970053,0.0,0.45420814,48.198032,4.6313448,527.76312,-9.2323294
2477,195.3845,5.9603853,5.5008435,0.0,0,4.1773891,0.0,0.45653945,48.02877,4.6100597,527.51501,-9.2322111
2478,195.3847,5.9665632,5.5268183,0.0,0,4.1577735,0.0,0.45840195,47.982632,4.5886102,527.26685,-9.2331171
2479,195.3849,5.9777231,5.5387869,0.0,0,4.1381574,0.0,0.46059942,47.978363,4.5683637,527.01874,-9.2331362
2480,195.3851,5.9994922,5.5611358,0.0,0,4.1185412,0.0,0.46303418,47.972462,4.5480032,526.77063,-9.2324162
2481,195.3853,6.0222063,5.5886645,0.0,0,4.0989256,0.0,0.46496451,48.074596,4.5273595,526.52246,-9.232234
2482,195.3855,6.0412798,5.6007624,0.0,0,4.0793095,0.0,0.46708691,48.166698,4.5055566,526.27435,-9.2321396
2483,195.3857,6.055687,5.622416,0.0,0,4.0596933,0.0,0.46979198,48.199829,4.4848342,526.02625,-9.2323065
2484,195.3859,6.0677342,5.6508384,0.0,0,4.0404716,0.0,0.47167799,48.248062,4.4639955,525.77808,-9.2319069
2485,195.3861,6.0800099,5.6630025,0.0,0,4.0217257,0.0,0.47349522,48.192966,4.444591,525.52997,-9.2320414
2486,195.3863,6.0845609,5.6837096,0.0,0,4.0030656,0.0,0.4763366,48.027554,4.4235978,525.2818,-9.232585
2487,195.3865,6.0851393,5.7132792,0.0,0,3.9844091,0.0,0.47838509,47.946709,4.4019136,525.03369,-9.2324562
2488,195.3867,6.0872464,5.7259583,0.0,0,3.9657531,0.0,0.48009306,47.921749,4.3837895,524.78558,-9.2321253
2489,195.3869,6.1012912,5.743679,0.0,0,3.9470971,0.0,0.48288336,47.906258,4.3646488,524.53741,-9.2319756
2490,195.3871,6.1177549,5.7711682,0.0,0,3.928441,0.0,0.48490164,47.941235,4.3455935,524.28931,-9.2316999
2491,195.3873,6.1302929,5.7837591,0.0,0,3.9097853,0.0,0.48628089,48.010902,4.3258371,524.0412,-9.2312269
2492,195.3875,6.1451383,5.8013153,0.0,0,3.8911293,0.0,0.48907447,48.016331,4.3052344,523.79303,-9.231741
2493,195.3877,6.1610799,5.8292818,0.0,0,3.8724732,0.0,0.49140984,48.006508,4.2862415,523.54492,-9.2317867
2494,195.3879,6.1713896,5.8431516,0.0,0,3.8538172,0.0,0.49271145,48.014893,4.2652626,523.29681,-9.2314701
2495,195.3881,6.172164,5.8590856,0.0,0,3.8351612,0.0,0.49537709,47.912289,4.2438483,523.04865,-9.2321796
2496,195.3883,6.176054,5.8857884,0.0,0,3.8165052,0.0,0.49778596,47.812817,4.2238455,522.80054,-9.2332764
2497,195.3885,6.1853294,5.901557,0.0,0,3.7978492,0.0,0.49902794,47.805504,4.2059665,522.55243,-9.2334938
2498,195.3887,6.1955328,5.9166083,0.0,0,3.7791932,0.0,0.50161821,47.782764,4.1873479,522.30426,-9.2330122
2499,195.3889,6.2126741,5.9417276,0.0,0,3.7605371,0.0,0.50418127,47.778027,4.165401,522.05615,-9.2332134
2500,195.3891,6.2298141,5.9596071,0.0,0,3.7418811,0.0,0.50543761,47.817982,4.1469874,521.80798,-9.2326393
2501,195.3893,6.2492447,5.9750643,0.0,0,3.7232251,0.0,0.50791252,47.805927,4.1285696,521.55988,-9.2320576
2502,195.3895,6.27496,5.9990659,0.0,0,3.7045693,0.0,0.51059341,47.870888,4.1094484,521.31177,-9.2319393
2503,195.3897,6.2973189,6.0196171,0.0,0,3.6859133,0.0,0.51199442,48.015087,4.0922832,521.0636,-9.2310658
2504,195.3899,6.3108106,6.0358386,0.0,0,3.6672573,0.0,0.51449758,47.983818,4.0735245,520.81549,-9.2306852
2505,195.3901,6.3126311,6.0573845,0.0,0,3.6486013,0.0,0.51725084,47.898914,4.0529561,520.56738,-9.2314911
2506,195.3903,6.3114491,6.077424,0.0,0,3.629945,0.0,0.51854944,47.863998,4.0340915,520.31921,-9.2316179
2507,195.3905,6.3248334,6.0926871,0.0,0,3.611289,0.0,0.52071357,47.794006,4.0127554,520.07111,-9.2310934
2508,195.3907,6.3345175,6.1115189,0.0,0,3.5926332,0.0,0.52341402,47.723839,3.9921069,519.823,-9.2317657
2509,195.3909,6.3374033,6.1325741,0.0,0,3.5743496,0.0,0.524827,47.72694,3.9742548,519.57483,-9.2325773
2510,195.3911,6.3509445,6.1486626,0.0,0,3.5565164,0.0,0.52683944,47.7197,3.955955,519.32672,-9.2325974
2511,195.3913,6.3820658,6.1649132,0.0,0,3.5387647,0.0,0.52961618,47.772465,3.939517,519.07855,-9.2318583
2512,195.3915,6.4099579,6.1875544,0.0,0,3.5210166,0.0,0.53127879,47.907207,3.9202318,518.83044,-9.2312956
2513,195.3917,6.4181023,6.2061152,0.0,0,3.5032687,0.0,0.53315574,47.890545,3.8996484,518.58234,-9.2309694
2514,195.3919,6.4257569,6.2210674,0.0,0,3.4855206,0.0,0.53590661,47.829273,3.8817973,518.33417,-9.230792
2515,195.3921,6.4313579,6.2448773,0.0,0,3.4677725,0.0,0.53782964,47.814579,3.8643084,518.08606,-9.2310457
2516,195.3923,6.4377036,6.2651095,0.0,0,3.4500246,0.0,0.53973627,47.758545,3.8452876,517.83795,-9.2310543
2517,195.3925,6.4498215,6.2783141,0.0,0,3.4322767,0.0,0.54251128,47.701431,3.8259027,517.58978,-9.2311478
2518,195.3927,6.4555559,6.3018179,0.0,0,3.4145288,0.0,0.54457742,47.679859,3.8071754,517.34167,-9.231863
2519,195.3929,6.4713383,6.3227196,0.0,0,3.3967807,0.0,0.54628032,47.689423,3.7887175,517.09357,-9.2317991
2520,195.3931,6.4995999,6.33394,0.0,0,3.3790326,0.0,0.54868478,47.711487,3.7700274,516.78424,-9.2320137
2521,195.3933,6.5238562,6.3562918,0.0,0,3.3612847,0.0,0.55085278,47.830078,3.7521458,516.4137,-9.2327538
2522,195.3935,6.5511174,6.3792458,0.0,0,3.3435366,0.0,0.55260813,47.964478,3.7335041,516.04321,-9.2324352
2523,195.3937,6.5703411,6.3899875,0.0,0,3.3257885,0.0,0.55499834,47.977325,3.7138612,515.67267,-9.2316904
2524,195.3939,6.5794816,6.4115691,0.0,0,3.3080406,0.0,0.55746037,47.961773,3.6950994,515.30219,-9.2310619
2525,195.3941,6.5866752,6.4365158,0.0,0,3.2902927,0.0,0.55922741,47.93681,3.6753716,514.93164,-9.2310743
2526,195.3943,6.5847998,6.4461727,0.0,0,3.2725446,0.0,0.56142533,47.834229,3.6567709,514.56116,-9.2311077
2527,195.3945,6.5846071,6.466795,0.0,0,3.2547965,0.0,0.56421,47.701332,3.6392131,514.19061,-9.231143
2528,195.3947,6.5966053,6.4938526,0.0,0,3.2370486,0.0,0.56616688,47.673206,3.6206808,513.82013,-9.2313414
2529,195.3949,6.613524,6.5038247,0.0,0,3.2193005,0.0,0.56807709,47.660458,3.600589,513.44965,-9.2320166
2530,195.3951,6.6339703,6.5214605,0.0,0,3.2015524,0.0,0.57072729,47.715099,3.5833192,513.0791,-9.2318811
2531,195.3953,6.6654344,6.5478253,0.0,0,3.1838045,0.0,0.57258958,47.883102,3.56868,512.70862,-9.231823
2532,195.3955,6.6913152,6.558012,0.0,0,3.1660566,0.0,0.57432222,47.974632,3.5500665,512.33807,-9.2317848
2533,195.3957,6.7035918,6.5751963,0.0,0,3.1483085,0.0,0.57718498,47.946873,3.5314043,511.96756,-9.2312908
2534,195.3959,6.7134514,6.6022739,0.0,0,3.1309149,0.0,0.57922781,47.90118,3.5150428,511.59705,-9.2317972
2535,195.3961,6.7137465,6.6132779,0.0,0,3.1139498,0.0,0.58065891,47.841743,3.4978247,511.22656,-9.2323465
2536,195.3963,6.7185507,6.6287279,0.0,0,3.0970623,0.0,0.58342987,47.703083,3.4773724,510.85605,-9.232233
2537,195.3965,6.7372446,6.6549687,0.0,0,3.0801783,0.0,0.58562964,47.685329,3.4578772,510.48553,-9.2321949
2538,195.3967,6.7510481,6.6680188,0.0,0,3.0632942,0.0,0.58708239,47.771107,3.4399352,510.11502,-9.2322121
2539,195.3969,6.7746243,6.6833262,0.0,0,3.0464103,0.0,0.58997446,47.790592,3.423075,509.74451,-9.2315235
2540,195.3971,6.8070273,6.7097659,0.0,0,3.0295262,0.0,0.59239417,47.869007,3.4051199,509.37399,-9.2318068
2541,195.3973,6.8288498,6.7237244,0.0,0,3.0126421,0.0,0.59365207,48.040794,3.3858631,509.00348,-9.2317886
2542,195.3975,6.8543487,6.7384367,0.0,0,2.9957583,0.0,0.59653461,48.105583,3.3688395,508.63297,-9.2310772
2543,195.3977,6.8790135,6.764595,0.0,0,2.9788742,0.0,0.59928894,48.098232,3.351892,508.26245,-9.2317734
2544,195.3979,6.8852892,6.781023,0.0,0,2.9619904,0.0,0.6005829,48.061344,3.3353722,507.89194,-9.2325239
2545,195.3981,6.8851547,6.795187,0.0,0,2.9451063,0.0,0.60334802,47.926384,3.3177798,507.52142,-9.232605
2546,195.3983,6.894022,6.8183661,0.0,0,2.9282222,0.0,0.60610217,47.876846,3.2974873,507.15091,-9.2323418
2547,195.3985,6.9142604,6.8350158,0.0,0,2.9113381,0.0,0.60720724,47.939636,3.2770793,506.78043,-9.2317905
2548,195.3987,6.9360242,6.8481283,0.0,0,2.894454,0.0,0.60973769,47.92205,3.258323,506.40991,-9.2312975
2549,195.3989,6.9534211,6.8699446,0.0,0,2.8775702,0.0,0.61263746,47.921867,3.2403257,506.0394,-9.2310705
2550,195.3991,6.9797597,6.888772,0.0,0,2.8606861,0.0,0.6138283,48.037659,3.221374,505.66888,-9.2310495
2551,195.3993,7.0109463,6.9029284,0.0,0,2.8438022,0.0,0.61617249,48.138031,3.2040293,505.29837,-9.2306843
2552,195.3995,7.0338979,6.9230967,0.0,0,2.8269181,0.0,0.6192559,48.194309,3.1874077,504.92786,-9.2306671
2553,195.3997,7.0489316,6.9435191,0.0,0,2.810034,0.0,0.62071592,48.24662,3.1693234,504.55734,-9.2310305
2554,195.3999,7.0532608,6.9585414,0.0,0,2.7931502,0.0,0.62295365,48.173347,3.1519883,504.18683,-9.2312012
2555,195.4001,7.0478854,6.9759574,0.0,0,2.7762663,0.0,0.62594467,48.008331,3.1355631,503.81631,-9.2317495
2556,195.4003,7.0556426,6.9977279,0.0,0,2.7593822,0.0,0.62750375,48.003582,3.1179099,503.4458,-9.2319307
2557,195.4005,7.0742741,7.0139046,0.0,0,2.7424982,0.0,0.62960577,47.995998,3.0999279,503.07529,-9.2315636
2558,195.4007,7.0948577,7.0283527,0.0,0,2.7256143,0.0,0.63247502,47.929863,3.0800881,502.70477,-9.2312498
2559,195.4009,7.1270671,7.0508838,0.0,0,2.7090681,0.0,0.63417381,48.018253,3.0613563,502.33426,-9.2316189
2560,195.4011,7.159831,7.0683527,0.0,0,2.6929309,0.0,0.6361264,48.184452,3.0455151,501.96378,-9.2316971
2561,195.4013,7.1849656,7.0803103,0.0,0,2.6768675,0.0,0.63899332,48.239662,3.0275006,501.59326,-9.2312298
2562,195.4015,7.2050428,7.1030121,0.0,0,2.6608074,0.0,0.64103627,48.257732,3.0086398,501.22275,-9.2311325
2563,195.4017,7.2176619,7.1220613,0.0,0,2.6447473,0.0,0.64295596,48.27832,2.9882309,500.85223,-9.2309694
2564,195.4019,7.2216802,7.1331315,0.0,0,2.6286871,0.0,0.6457029,48.220608,2.970381,500.48172,-9.2309551
2565,195.4021,7.2301564,7.1558013,0.0,0,2.6126273,0.0,0.64788365,48.137737,2.9553211,500.11121,-9.2306929
2566,195.4023,7.2497659,7.1768308,0.0,0,2.5965672,0.0,0.64969182,48.117893,2.9369671,499.74069,-9.23069
2567,195.4025,7.2631221,7.1863489,0.0,0,2.580507,0.0,0.65226543,48.123032,2.9210806,499.37018,-9.2310343
2568,195.4027,7.2811952,7.2071853,0.0,0,2.5644472,0.0,0.65464586,48.13979,2.9036248,498.99966,-9.2311888
2569,195.4029,7.316834,7.23035,0.0,0,2.5483871,0.0,0.65640587,48.261433,2.8839438,498.62915,-9.2311182
2570,195.4031,7.3534279,7.2399912,0.0,0,2.5323269,0.0,0.65878588,48.365112,2.8679073,498.39557,-9.2309732
2571,195.4033,7.379498,7.260097,0.0,0,2.5162671,0.0,0.66147822,48.431576,2.8514235,498.29886,-9.2310371
2572,195.4035,7.3917923,7.2848682,0.0,0,2.5002072,0.0,0.66336799,48.495052,2.8352363,498.20218,-9.2309618
2573,195.4037,7.3930864,7.2929516,0.0,0,2.4841471,0.0,0.66560853,48.411945,2.818572,498.1055,-9.2309437
2574,195.4039,7.4019709,7.3114858,0.0,0,2.4680872,0.0,0.66850859,48.309887,2.7993681,498.00879,-9.2315788
2575,195.4041,7.4262958,7.3385663,0.0,0,2.4520271,0.0,0.67045563,48.328903,2.7800491,497.91211,-9.2316751
2576,195.4043,7.4501915,7.347599,0.0,0,2.4359672,0.0,0.67242557,48.389759,2.7652776,497.81543,-9.2312756
2577,195.4045,7.4644346,7.3631086,0.0,0,2.4199073,0.0,0.6753968,48.39761,2.7486806,497.71872,-9.2312107
2578,195.4047,7.483191,7.387382,0.0,0,2.4038472,0.0,0.67727536,48.405411,2.7306974,497.62204,-9.2310276
2579,195.4049,7.5153079,7.3965225,0.0,0,2.3877871,0.0,0.67878073,48.48698,2.715827,497.52536,-9.230648
2580,195.4051,7.546742,7.4130797,0.0,0,2.3717272,0.0,0.68185669,48.537235,2.6987975,497.42865,-9.2306519
2581,195.4053,7.5695982,7.4399457,0.0,0,2.3556671,0.0,0.68410683,48.607548,2.680413,497.33197,-9.2309475
2582,195.4055,7.5864592,7.4503207,0.0,0,2.339607,0.0,0.685574,48.647514,2.6625896,497.23526,-9.2316551
2583,195.4057,7.6008186,7.4656096,0.0,0,2.3235471,0.0,0.68873215,48.599033,2.6441939,497.13858,-9.2319155
2584,195.4059,7.6099014,7.4917526,0.0,0,2.3078086,0.0,0.69115812,48.564659,2.6272056,497.0419,-9.2311659
2585,195.4061,7.622026,7.5026603,0.0,0,2.2924592,0.0,0.69242108,48.549377,2.6125233,496.94519,-9.2310295
2586,195.4063,7.6478024,7.5164719,0.0,0,2.2771802,0.0,0.69557732,48.527916,2.5976939,496.84851,-9.2317066
2587,195.4065,7.6695175,7.5418096,0.0,0,2.261904,0.0,0.6982426,48.551739,2.5797513,496.75183,-9.2316914
2588,195.4067,7.6857777,7.5553918,0.0,0,2.2466278,0.0,0.69939446,48.628613,2.5623527,496.65512,-9.230793
2589,195.4069,7.7124686,7.5678706,0.0,0,2.2313521,0.0,0.70234859,48.637573,2.5461047,496.55844,-9.2303829
2590,195.4071,7.7442999,7.5900497,0.0,0,2.2160761,0.0,0.70509505,48.668968,2.5286212,496.46176,-9.2302017
2591,195.4073,7.7686701,7.6044617,0.0,0,2.2008002,0.0,0.70603341,48.782608,2.5110564,496.36505,-9.2304459
2592,195.4075,7.7854567,7.6165028,0.0,0,2.185524,0.0,0.70872056,48.792473,2.4930902,496.26837,-9.2309504
2593,195.4077,7.7990947,7.638073,0.0,0,2.170248,0.0,0.71176481,48.718498,2.4760642,496.17166,-9.2310867
2594,195.4079,7.8088431,7.6555777,0.0,0,2.1549721,0.0,0.71296346,48.710735,2.4597857,496.07498,-9.2309351
2595,195.4081,7.818996,7.6691527,0.0,0,2.1396961,0.0,0.71570885,48.685707,2.4419639,495.9783,-9.2309418
2596,195.4083,7.8330083,7.689168,0.0,0,2.1244199,0.0,0.71890086,48.629501,2.42608,495.88159,-9.2311182
2597,195.4085,7.8565931,7.7069693,0.0,0,2.109144,0.0,0.72007686,48.676559,2.4094713,495.78491,-9.23176
2598,195.4087,7.8831677,7.7196627,0.0,0,2.093868,0.0,0.72239691,48.694431,2.3913131,495.68823,-9.2323914
2599,195.4089,7.9094853,7.7363915,0.0,0,2.0785921,0.0,0.72547281,48.728897,2.376333,495.59152,-9.2323179
2600,195.4091,7.9396672,7.7548504,0.0,0,2.0633161,0.0,0.72674024,48.850487,2.3612802,495.49484,-9.2316494
2601,195.4093,7.969451,7.767931,0.0,0,2.0480402,0.0,0.72884881,48.904095,2.3455031,495.39816,-9.2310114
2602,195.4095,7.9949813,7.7823677,0.0,0,2.0327642,0.0,0.73189741,48.92485,2.3291683,495.30145,-9.2305889
2603,195.4097,8.0140791,7.8022456,0.0,0,2.0174882,0.0,0.73337299,48.996536,2.3111007,495.20477,-9.2304506
2604,195.4099,8.0313568,7.8165078,0.0,0,2.002212,0.0,0.73539174,48.999577,2.2975831,495.10809,-9.2304716
2605,195.4101,8.0507126,7.8283749,0.0,0,1.986936,0.0,0.73853058,48.945648,2.281265,495.01138,-9.2302828
2606,195.4103,8.0658817,7.8503437,0.0,0,1.9716599,0.0,0.74027485,48.971317,2.2610409,494.9147,-9.2303476
2607,195.4105,8.080718,7.8680735,0.0,0,1.9563839,0.0,0.74220639,48.973629,2.2485545,494.81799,-9.2307997
2608,195.4107,8.1036587,7.8790369,0.0,0,1.941108,0.0,0.74542928,48.93494,2.2347417,494.72131,-9.2311592
2609,195.4109,8.1342735,7.9013653,0.0,0,1.9261371,0.0,0.74770331,49.003414,2.215946,494.62463,-9.2317848
2610,195.4111,8.1659698,7.9196815,0.0,0,1.9115354,0.0,0.7494899,49.109329,2.1984835,494.52792,-9.2319355
2611,195.4113,8.1912508,7.9283819,0.0,0,1.8970003,0.0,0.75228018,49.140316,2.183275,494.43124,-9.2312565
2612,195.4115,8.2162447,7.9486279,0.0,0,1.8824683,0.0,0.75465685,49.184425,2.1668832,494.33456,-9.2312136
2613,195.4117,8.2398329,7.9679055,0.0,0,1.8679363,0.0,0.75629246,49.235813,2.1497259,494.23785,-9.2317448
2614,195.4119,8.2572403,7.9742899,0.0,0,1.8534042,0.0,0.75864941,49.219055,2.1354442,494.14117,-9.2315903
2615,195.4121,8.2711735,7.9921565,0.0,0,1.8388723,0.0,0.76106852,49.231407,2.1207695,494.04449,-9.2303867
2616,195.4123,8.2893391,8.0130005,0.0,0,1.8243402,0.0,0.76259369,49.26931,2.1039875,493.94778,-9.2299061
2617,195.4125,8.3109808,8.0185995,0.0,0,1.8098083,0.0,0.76458961,49.254726,2.0883622,493.8511,-9.230092
2618,195.4127,8.3375769,8.0362053,0.0,0,1.7952763,0.0,0.76734644,49.254547,2.0735965,493.75439,-9.2299118
2619,195.4129,8.3800821,8.0607815,0.0,0,1.7807442,0.0,0.76935267,49.360474,2.0573888,493.65771,-9.2299948
2620,195.4131,8.4242077,8.0687227,0.0,0,1.7662122,0.0,0.77162224,49.503181,2.0416791,493.43961,-9.2303429
2621,195.4133,8.4479551,8.0864735,0.0,0,1.7516803,0.0,0.77487695,49.542641,2.0263262,493.1001,-9.2312565
2622,195.4135,8.4664869,8.1121025,0.0,0,1.7371483,0.0,0.77698958,49.574562,2.0087442,492.76059,-9.2316389
2623,195.4137,8.4897022,8.1194563,0.0,0,1.7226163,0.0,0.7787565,49.603886,1.9940166,492.42108,-9.2311153
2624,195.4139,8.5086098,8.1341467,0.0,0,1.7080842,0.0,0.78195679,49.569382,1.9808044,492.08157,-9.2307539
2625,195.4141,8.5220137,8.1583738,0.0,0,1.6935523,0.0,0.78404218,49.540462,1.9646528,491.74207,-9.2304716
2626,195.4143,8.5368814,8.1656885,0.0,0,1.6790203,0.0,0.78530824,49.536064,1.9487498,491.40256,-9.2303762
2627,195.4145,8.5626326,8.1785154,0.0,0,1.6644882,0.0,0.78834981,49.500801,1.9334711,491.06305,-9.2303553
2628,195.4147,8.6016483,8.2023954,0.0,0,1.6499562,0.0,0.79046535,49.576653,1.9167728,490.72354,-9.2306957
2629,195.4149,8.6387215,8.2110758,0.0,0,1.6354243,0.0,0.79156625,49.759884,1.9006931,490.38403,-9.2306499
2630,195.4151,8.6701555,8.2235909,0.0,0,1.6208922,0.0,0.79484063,49.823101,1.8849682,490.04453,-9.2303057
2631,195.4153,8.6988668,8.2475386,0.0,0,1.6063603,0.0,0.79739302,49.882839,1.8724,489.70502,-9.2302151
2632,195.4155,8.7214975,8.258462,0.0,0,1.5918282,0.0,0.79856831,49.984661,1.8575778,489.36551,-9.2302351
2633,195.4157,8.7385759,8.270133,0.0,0,1.5772963,0.0,0.80185169,49.914612,1.8398726,489.026,-9.2302885
2634,195.4159,8.7476492,8.2937078,0.0,0,1.5630547,0.0,0.80475092,49.798347,1.8258029,488.68649,-9.2303715
2635,195.4161,8.7619495,8.3075047,0.0,0,1.5491643,0.0,0.80580544,49.83614,1.8130428,488.34698,-9.2304754
2636,195.4163,8.7863264,8.3187275,0.0,0,1.5353372,0.0,0.80884039,49.839695,1.7984151,488.00748,-9.2304068
2637,195.4165,8.82267,8.3397818,0.0,0,1.5215131,0.0,0.81191725,49.846207,1.7821121,487.66797,-9.2304106
2638,195.4167,8.8682137,8.3532629,0.0,0,1.5076891,0.0,0.81276047,50.012245,1.7649995,487.32846,-9.2304859
2639,195.4169,8.9093781,8.3631964,0.0,0,1.4938651,0.0,0.81540084,50.119164,1.7476462,486.98895,-9.2303076
2640,195.4171,8.9459972,8.3824005,0.0,0,1.4800411,0.0,0.81849641,50.198509,1.7333782,486.64941,-9.2300978
2641,195.4173,8.9762096,8.3971491,0.0,0,1.4662172,0.0,0.81937027,50.351368,1.7190777,486.30991,-9.2301559
2642,195.4175,8.9980154,8.4069271,0.0,0,1.4523932,0.0,0.8218658,50.356583,1.7049527,485.9704,-9.2302122
2643,195.4177,9.011569,8.4246902,0.0,0,1.4385692,0.0,0.82516265,50.262638,1.6925778,485.63089,-9.2297449
2644,195.4179,9.021965,8.4432688,0.0,0,1.4247452,0.0,0.82641107,50.258568,1.6780181,485.29138,-9.229846
2645,195.4181,9.0479879,8.4555998,0.0,0,1.4109212,0.0,0.82890701,50.25444,1.6631298,484.95187,-9.2303467
2646,195.4183,9.079092,8.4709282,0.0,0,1.3970972,0.0,0.83239144,50.245251,1.6478393,484.61237,-9.2302923
2647,195.4185,9.1083956,8.4900913,0.0,0,1.3832732,0.0,0.83377999,50.366516,1.6322883,484.27286,-9.2305593
2648,195.4187,9.14534,8.5029898,0.0,0,1.3694493,0.0,0.83586115,50.453362,1.6160277,483.93335,-9.23141
2649,195.4189,9.1852856,8.5154257,0.0,0,1.3556252,0.0,0.83919317,50.481731,1.600269,483.59384,-9.2315426
2650,195.4191,9.2208786,8.5356169,0.0,0,1.3418012,0.0,0.84089166,50.600124,1.585999,483.25433,-9.231061
2651,195.4193,9.2412806,8.5495815,0.0,0,1.3279773,0.0,0.84282547,50.643879,1.5733404,482.91483,-9.2305784
2652,195.4195,9.266223,8.5587673,0.0,0,1.3141533,0.0,0.84594733,50.593254,1.5596197,482.57532,-9.2302065
2653,195.4197,9.2882318,8.5782604,0.0,0,1.3003292,0.0,0.84780627,50.586735,1.5442318,482.23581,-9.2301884
2654,195.4199,9.3018513,8.592762,0.0,0,1.2865052,0.0,0.849392,50.60857,1.5287678,481.8963,-9.230134
2655,195.4201,9.3275881,8.5989809,0.0,0,1.2726812,0.0,0.85220695,50.63052,1.5132468,481.55679,-9.2296648
2656,195.4203,9.3591413,8.617733,0.0,0,1.2588573,0.0,0.85426605,50.71352,1.5003593,481.21729,-9.2296772
2657,195.4205,9.3971224,8.6350126,0.0,0,1.2450333,0.0,0.85582048,50.791805,1.486581,480.87778,-9.2301512
2658,195.4207,9.4409428,8.6416702,0.0,0,1.2312093,0.0,0.85875291,50.854542,1.4709854,480.53827,-9.2302217
2659,195.4209,9.4838305,8.6616793,0.0,0,1.2176626,0.0,0.86147434,50.975784,1.454845,480.19876,-9.230711
2660,195.4211,9.5208235,8.6829233,0.0,0,1.2044512,0.0,0.86323905,51.078098,1.4407965,479.85925,-9.2312307
2661,195.4213,9.5472918,8.6898937,0.0,0,1.1913005,0.0,0.86584276,51.111137,1.4262878,479.51974,-9.2309418
2662,195.4215,9.559371,8.708087,0.0,0,1.1781523,0.0,0.86873138,51.085064,1.4105935,479.18024,-9.2304258
2663,195.4217,9.5795832,8.7299595,0.0,0,1.1650044,0.0,0.8705501,51.083611,1.3941976,478.84073,-9.2303028
2664,195.4219,9.6123571,8.7353802,0.0,0,1.1518563,0.0,0.8728646,51.085537,1.3797724,478.50122,-9.2302752
2665,195.4221,9.6427155,8.751276,0.0,0,1.1387082,0.0,0.87602741,51.070278,1.3669615,478.16171,-9.2303619
2666,195.4223,9.6737719,8.7732286,0.0,0,1.1255603,0.0,0.87771624,51.131161,1.3532084,477.82217,-9.2303629
2667,195.4225,9.7131596,8.776473,0.0,0,1.1124123,0.0,0.87921041,51.241673,1.3394423,477.48267,-9.2302895
2668,195.4227,9.7552938,8.7891273,0.0,0,1.0992643,0.0,0.8821407,51.327408,1.3242151,477.14316,-9.2302656
2669,195.4229,9.7963448,8.8115549,0.0,0,1.0861163,0.0,0.8839336,51.475502,1.3091923,476.80365,-9.2299337
2670,195.4231,9.8320055,8.816823,0.0,0,1.0729682,0.0,0.8854149,51.596699,1.2944239,476.40076,-9.2298651
2671,195.4233,9.8552017,8.8295374,0.0,0,1.0598202,0.0,0.88881576,51.574146,1.2818229,475.93445,-9.2304382
2672,195.4235,9.8796978,8.8538971,0.0,0,1.0466722,0.0,0.89099914,51.552555,1.268905,475.46814,-9.230257
2673,195.4237,9.9019709,8.8616295,0.0,0,1.0335243,0.0,0.89241105,51.567844,1.2543879,475.00186,-9.2299852
2674,195.4239,9.9224596,8.8734722,0.0,0,1.0203762,0.0,0.89593673,51.535736,1.2409396,474.53555,-9.2302561
2675,195.4241,9.9504042,8.8979845,0.0,0,1.0072283,0.0,0.89850152,51.555382,1.2270232,474.06924,-9.2297115
2676,195.4243,9.9890003,8.9072628,0.0,0,0.99408025,0.0,0.89971972,51.681156,1.2122651,473.60294,-9.2290401
2677,195.4245,10.032646,8.9179373,0.0,0,0.98093224,0.0,0.90302312,51.714844,1.1968555,473.13666,-9.229022
2678,195.4247,10.073904,8.9405441,0.0,0,0.96778423,0.0,0.90576416,51.789616,1.1837337,472.67035,-9.2295704
2679,195.4249,10.118435,8.9498262,0.0,0,0.95463622,0.0,0.90661699,51.969646,1.1702079,472.20404,-9.2298708
2680,195.4251,10.15736,8.9577007,0.0,0,0.94148827,0.0,0.90969443,52.023941,1.155383,471.73773,-9.2293968
2681,195.4253,10.186554,8.9777117,0.0,0,0.92834032,0.0,0.91252345,52.048843,1.143231,471.27145,-9.2293634
2682,195.4255,10.210925,8.988287,0.0,0,0.91519231,0.0,0.91301984,52.137211,1.1308274,470.80515,-9.2297907
2683,195.4257,10.236503,8.9955187,0.0,0,0.9020443,0.0,0.91579539,52.108818,1.1153227,470.33884,-9.2296057
2684,195.4259,10.270962,9.0144844,0.0,0,0.88916039,0.0,0.91893381,52.121651,1.1012806,469.87253,-9.2292824
2685,195.4261,10.304211,9.0287619,0.0,0,0.87659597,0.0,0.9198243,52.258831,1.0880473,469.40622,-9.2297487
2686,195.4263,10.339419,9.0389853,0.0,0,0.86408937,0.0,0.92270696,52.248405,1.0728803,468.93994,-9.2296867
2687,195.4265,10.377609,9.0580235,0.0,0,0.85158527,0.0,0.92623341,52.245167,1.0579866,468.47363,-9.2291479
2688,195.4267,10.418383,9.0746469,0.0,0,0.83908123,0.0,0.92743689,52.424465,1.0448543,468.00732,-9.2289343
2689,195.4269,10.468451,9.0852661,0.0,0,0.82657719,0.0,0.93013561,52.527145,1.0337726,467.54102,-9.228714
2690,195.4271,10.507616,9.1002846,0.0,0,0.8140732,0.0,0.93362409,52.504604,1.0212796,467.07474,-9.228858
2691,195.4273,10.527536,9.1169186,0.0,0,0.80156928,0.0,0.93476123,52.565762,1.0070109,466.60843,-9.2288666
2692,195.4275,10.553082,9.1270828,0.0,0,0.78906524,0.0,0.93691808,52.590244,0.99297315,466.14212,-9.2288523
2693,195.4277,10.581187,9.1380892,0.0,0,0.77656126,0.0,0.94027781,52.549648,0.97851324,465.67581,-9.2296219
2694,195.4279,10.60374,9.1547899,0.0,0,0.76405728,0.0,0.94140702,52.623608,0.96420455,465.20953,-9.2302971
2695,195.4281,10.640386,9.1650972,0.0,0,0.75155324,0.0,0.94305241,52.71682,0.94933486,464.74323,-9.2303762
2696,195.4283,10.681059,9.1731482,0.0,0,0.73904926,0.0,0.9462893,52.730251,0.93575162,464.27692,-9.2300072
2697,195.4285,10.711407,9.1910591,0.0,0,0.72654527,0.0,0.9478544,52.815056,0.92406505,463.81061,-9.2297459
2698,195.4287,10.754296,9.204011,0.0,0,0.71404123,0.0,0.94954836,52.973572,0.91103286,463.34433,-9.2291851
2699,195.4289,10.804654,9.2112522,0.0,0,0.70153725,0.0,0.95277947,53.037235,0.89855534,462.87802,-9.2285061
2700,195.4291,10.840262,9.2305355,0.0,0,0.68903327,0.0,0.95488477,53.096302,0.88636357,462.41171,-9.2286091
2701,195.4293,10.869679,9.2458572,0.0,0,0.67652929,0.0,0.95663303,53.166447,0.87083304,461.9454,-9.2286901
2702,195.4295,10.900504,9.2519522,0.0,0,0.66402531,0.0,0.95984137,53.135189,0.85718888,461.47913,-9.2287064
2703,195.4297,10.935608,9.2716179,0.0,0,0.65152127,0.0,0.96240091,53.13921,0.84606063,461.01282,-9.2292461
2704,195.4299,10.968774,9.2895451,0.0,0,0.63901722,0.0,0.9640975,53.197998,0.83302838,460.54651,-9.2297478
2705,195.4301,11.001134,9.294035,0.0,0,0.62651324,0.0,0.96692908,53.210217,0.81985748,460.0802,-9.2299719
2706,195.4303,11.042345,9.3104315,0.0,0,0.61400926,0.0,0.96950835,53.26358,0.80516374,459.61392,-9.2302427
2707,195.4305,11.087423,9.328454,0.0,0,0.60150528,0.0,0.97086799,53.403183,0.79270351,459.14761,-9.2306271
2708,195.4307,11.137081,9.3307076,0.0,0,0.58900124,0.0,0.97302908,53.543648,0.78092319,458.6813,-9.230649
2709,195.4309,11.182816,9.3447752,0.0,0,0.57674497,0.0,0.97578537,53.635151,0.76890135,458.215,-9.2300177
2710,195.4311,11.220767,9.3648834,0.0,0,0.56478834,0.0,0.97719014,53.734035,0.75804019,457.74869,-9.2299862
2711,195.4313,11.258284,9.367341,0.0,0,0.55288589,0.0,0.9791556,53.799393,0.74490756,457.28241,-9.2300892
2712,195.4315,11.294568,9.3804522,0.0,0,0.54098582,0.0,0.9823792,53.810135,0.73016846,456.8161,-9.2293091
2713,195.4317,11.328863,9.4024601,0.0,0,0.52908581,0.0,0.98414928,53.860802,0.71629488,456.34979,-9.228693
2714,195.4319,11.359538,9.4067631,0.0,0,0.51718581,0.0,0.98585415,53.919601,0.70374101,455.88348,-9.2287416
2715,195.4321,11.392035,9.4195557,0.0,0,0.5052858,0.0,0.98930025,53.909172,0.69033283,455.41721,-9.2290668
2716,195.4323,11.428472,9.4418383,0.0,0,0.49338579,0.0,0.99130428,53.992729,0.67854601,454.9509,-9.2292337
2717,195.4325,11.479212,9.4459753,0.0,0,0.48148578,0.0,0.99262482,54.144722,0.66349375,454.48459,-9.2292986
2718,195.4327,11.541626,9.4573193,0.0,0,0.46958581,0.0,0.99627072,54.207134,0.64847094,454.01828,-9.2298393
2719,195.4329,11.594104,9.4800825,0.0,0,0.4576858,0.0,0.99853063,54.329884,0.63791007,453.552,-9.2299385
2720,195.4331,11.64015,9.4854956,0.0,0,0.44578579,0.0,0.99950099,54.494633,0.62459177,453.35983,-9.2293987
2721,195.4333,11.682402,9.4943876,0.0,0,0.43388578,0.0,1.0029991,54.524281,0.61252445,453.44177,-9.22896
2722,195.4335,11.714697,9.5169048,0.0,0,0.42198581,0.0,1.0056689,54.538765,0.60102373,453.52374,-9.2291288
2723,195.4337,11.740182,9.525198,0.0,0,0.4100858,0.0,1.0066348,54.610062,0.5884394,453.60568,-9.2292881