File: clean data/testID_0217.csv
level_0,index,Time(sec),Force(kN),Jaw(mm),PowAngle(deg),Power(W),Pram,PTemp,Strain,Stress(MPa),Stroke(mm),TC1(C),wedge(mm)
2106,2106,178.6805,0.51967883,0.08861585,0.0,0,9.0337067,0.0,0.0056831776,5.6517372,10.072257,418.41046,-9.2663441
2108,2108,178.6809,2.4400666,0.14440204,0.0,0,8.9751787,0.0,0.009101118,27.675737,10.015002,418.45853,-9.2651472
2110,2110,178.6813,4.185832,0.19058514,0.0,0,8.9166508,0.0,0.012509638,51.361862,9.9457531,418.50659,-9.2636518
2112,2112,178.6817,4.6893988,0.30356744,0.0,0,8.8581219,0.0,0.019551851,57.830204,9.8685207,418.55466,-9.2617617
2114,2114,178.6821,5.505754,0.4002634,0.0,0,8.7995939,0.0,0.026359132,67.636078,9.7814188,418.60272,-9.2607803
2116,2116,178.6825,5.3780508,0.48847213,0.0,0,8.7416534,0.0,0.032555275,66.48941,9.6915588,418.65079,-9.2613373
2118,2118,178.6829,5.8330102,0.56956351,0.0,0,8.6858492,0.0,0.038182959,70.577942,9.6017962,418.69885,-9.2617025
2120,2120,178.6833,5.8983402,0.61462039,0.0,0,8.6301851,0.0,0.041449085,72.576164,9.5233908,418.74692,-9.261219
2122,2122,178.6837,5.935883,0.68907017,0.0,0,8.574522,0.0,0.046654709,71.613678,9.4569521,418.79498,-9.261466
2124,2124,178.6841,6.1837997,0.74358809,0.0,0,8.518857,0.0,0.050281718,74.970634,9.3910828,418.84305,-9.2600727
2126,2126,178.6845,6.2240129,0.81228179,0.0,0,8.4631929,0.0,0.055264365,74.563995,9.3273354,418.89111,-9.2593193
2128,2128,178.6849,6.3932252,0.89640701,0.0,0,8.4075298,0.0,0.061062019,76.835335,9.2514973,418.93918,-9.2601318
2130,2130,178.6853,6.2087364,0.97297394,0.0,0,8.3518648,0.0,0.066319183,73.843124,9.1686602,418.98724,-9.2613478
2132,2132,178.6857,6.5155182,1.0599877,0.0,0,8.2962017,0.0,0.072943389,77.069641,9.0883341,419.03531,-9.2612715
2134,2134,178.6861,6.2778358,1.1280553,0.0,0,8.2405376,0.0,0.077663437,73.887787,9.0128584,419.08337,-9.2607794
2136,2136,178.6865,6.63271,1.1783168,0.0,0,8.1848736,0.0,0.081277952,77.587486,8.9382343,419.13144,-9.261404
2138,2138,178.6869,6.4551959,1.2388998,0.0,0,8.1292095,0.0,0.086146779,75.576317,8.8777628,419.1795,-9.2606735
2140,2140,178.6873,6.6990042,1.2947155,0.0,0,8.0735455,0.0,0.08956749,77.706833,8.8162432,419.14285,-9.2609787
2142,2142,178.6877,6.6193037,1.3737572,0.0,0,8.0196619,0.0,0.095434532,76.717216,8.7535419,419.07797,-9.2605467
2144,2144,178.6881,6.8189044,1.4471858,0.0,0,7.9666953,0.0,0.1011708,78.154503,8.6836329,419.01309,-9.26052
2146,2146,178.6885,6.6973701,1.5218172,0.0,0,7.9137359,0.0,0.10594823,76.822197,8.614624,418.94818,-9.2612467
2148,2148,178.6889,6.7394357,1.5892435,0.0,0,7.8607755,0.0,0.11169395,76.52845,8.540493,418.8833,-9.2609491
2150,2150,178.6893,6.7243171,1.6390767,0.0,0,7.8078156,0.0,0.11541937,76.389389,8.4772635,418.81842,-9.2615643
2152,2152,178.6897,6.8280578,1.7023611,0.0,0,7.7548552,0.0,0.11965862,76.951057,8.4149294,418.75351,-9.2615461
2154,2154,178.6901,6.8383546,1.7554585,0.0,0,7.7018952,0.0,0.12435542,77.004883,8.3614702,418.68863,-9.2605858
2156,2156,178.6905,6.9852648,1.8038378,0.0,0,7.6489348,0.0,0.12754782,78.023918,8.3043365,418.62375,-9.2600346
2158,2158,178.6909,6.9915547,1.8764365,0.0,0,7.5959754,0.0,0.13297349,78.065567,8.2457199,418.55884,-9.2609739
2160,2160,178.6913,6.9976783,1.9259424,0.0,0,7.543015,0.0,0.13727511,77.479477,8.1874924,418.49396,-9.2612944
2162,2162,178.6917,7.0742936,1.9899566,0.0,0,7.4900556,0.0,0.14156581,78.298943,8.1245384,418.42908,-9.261013
2164,2164,178.6921,7.0179644,2.054369,0.0,0,7.4370952,0.0,0.14705119,77.080383,8.059907,418.36417,-9.2599411
2166,2166,178.6925,7.1251135,2.0980601,0.0,0,7.3846664,0.0,0.15040576,78.031532,8.0062399,418.29929,-9.2586432
2168,2168,178.6929,7.07723,2.1574104,0.0,0,7.3341722,0.0,0.15459044,77.190872,7.9488387,418.23441,-9.2593441
2170,2170,178.6933,7.1428542,2.2044964,0.0,0,7.2838039,0.0,0.15893833,77.454788,7.8960524,418.16949,-9.2616587
2172,2172,178.6937,7.1869802,2.2534783,0.0,0,7.2334356,0.0,0.16236182,77.764763,7.8430071,418.10461,-9.2622814
2174,2174,178.6941,7.2579174,2.3132885,0.0,0,7.1830673,0.0,0.16694714,78.076111,7.7908397,418.03973,-9.2606173
2176,2176,178.6945,7.3052802,2.3603992,0.0,0,7.1326995,0.0,0.17116548,78.319283,7.7328801,417.97482,-9.2600269
2178,2178,178.6949,7.2914352,2.4237857,0.0,0,7.0823312,0.0,0.17549376,77.925262,7.6792841,417.90994,-9.2595825
2180,2180,178.6953,7.2791948,2.477021,0.0,0,7.0319633,0.0,0.18009529,77.484207,7.6284308,417.84506,-9.2605553
2182,2182,178.6957,7.3410735,2.5190542,0.0,0,6.981595,0.0,0.1837773,77.762207,7.573535,417.78015,-9.2607832
2184,2184,178.6961,7.3737268,2.5768178,0.0,0,6.9312277,0.0,0.18769942,77.758377,7.5207081,417.71527,-9.2610445
2186,2186,178.6965,7.3976865,2.6162336,0.0,0,6.8808594,0.0,0.19139582,77.710526,7.4741583,417.65039,-9.2612762
2188,2188,178.6969,7.4306636,2.6645226,0.0,0,6.830492,0.0,0.19530627,77.777344,7.4223104,417.58551,-9.2613268
2190,2190,178.6973,7.4326115,2.7262359,0.0,0,6.7801232,0.0,0.19969259,77.518959,7.3733702,417.4187,-9.2617311
2192,2192,178.6977,7.4792647,2.7674546,0.0,0,6.7313671,0.0,0.20380224,77.629402,7.3214326,417.21793,-9.2619619
2194,2194,178.6981,7.5147123,2.8196485,0.0,0,6.6834416,0.0,0.20770423,77.80867,7.2747922,417.01718,-9.2621021
2196,2196,178.6985,7.5411305,2.8695607,0.0,0,6.6355219,0.0,0.21170683,77.659737,7.2263107,416.81641,-9.2610769
2198,2198,178.6989,7.5792794,2.9076247,0.0,0,6.5876017,0.0,0.21542306,77.728165,7.1773815,416.61566,-9.2611523
2200,2200,178.6993,7.5684409,2.9568353,0.0,0,6.5396819,0.0,0.21895763,77.458237,7.1296773,416.41489,-9.2616196
2202,2202,178.6997,7.6239853,3.0067844,0.0,0,6.4917622,0.0,0.22317116,77.613846,7.0812621,416.21414,-9.2623606
2204,2204,178.7001,7.6926823,3.0512593,0.0,0,6.4438419,0.0,0.22726536,78.037903,7.0372047,416.01337,-9.2625017
2206,2206,178.7005,7.70014,3.1013119,0.0,0,6.3959212,0.0,0.23093493,77.854599,6.9858203,415.81259,-9.2617798
2208,2208,178.7009,7.7304907,3.1515901,0.0,0,6.3480015,0.0,0.2356983,77.757401,6.942914,415.61185,-9.2607765
2210,2210,178.7013,7.7299767,3.1960971,0.0,0,6.3000817,0.0,0.23936887,77.565971,6.8937531,415.41107,-9.2604914
2212,2212,178.7017,7.7677417,3.24297,0.0,0,6.252162,0.0,0.24283262,77.553818,6.8408809,415.21033,-9.2608089
2214,2214,178.7021,7.8478765,3.2908921,0.0,0,6.2042422,0.0,0.24764676,77.929398,6.7940483,415.00955,-9.2612104
2216,2216,178.7025,7.8476691,3.3373499,0.0,0,6.1568027,0.0,0.25115249,77.791634,6.7431645,414.80881,-9.2618303
2218,2218,178.7029,7.8777022,3.385622,0.0,0,6.1111121,0.0,0.25519711,77.720131,6.69525,414.60803,-9.2625017
2220,2220,178.7033,7.8940392,3.4293723,0.0,0,6.065536,0.0,0.2596719,77.523819,6.649044,414.40729,-9.2608957
2222,2222,178.7037,7.9648547,3.4801056,0.0,0,6.0199599,0.0,0.2632291,77.844749,6.5999346,414.20651,-9.260354
2224,2224,178.7041,8.0232315,3.526989,0.0,0,5.9743834,0.0,0.267656,78.096191,6.554862,414.00574,-9.2603712
2226,2226,178.7045,8.0301523,3.5701106,0.0,0,5.9288077,0.0,0.27173024,78.010406,6.5036979,413.80499,-9.2613382
2228,2228,178.7049,8.0300274,3.6265118,0.0,0,5.8832321,0.0,0.27577263,77.607925,6.4584713,413.60422,-9.2620869
2230,2230,178.7053,8.0658503,3.6725705,0.0,0,5.8376555,0.0,0.28056726,77.501778,6.4102621,413.40347,-9.2621889
2232,2232,178.7057,8.1357651,3.7161429,0.0,0,5.792079,0.0,0.28433755,77.875328,6.3596492,413.2027,-9.2610359
2234,2234,178.7061,8.1644678,3.7705543,0.0,0,5.7465038,0.0,0.2886067,77.903572,6.3165712,413.00195,-9.2607079
2236,2236,178.7065,8.1874838,3.8067441,0.0,0,5.7009277,0.0,0.29275402,77.736862,6.2719722,412.80118,-9.2600174
2238,2238,178.7069,8.2040749,3.8526785,0.0,0,5.6553516,0.0,0.2962504,77.595963,6.2229204,412.6004,-9.2609968
2240,2240,178.7073,8.2524185,3.9083276,0.0,0,5.6097755,0.0,0.30116582,77.615921,6.1763105,412.45456,-9.2622919
2242,2242,178.7077,8.2909508,3.9466965,0.0,0,5.5656581,0.0,0.3052482,77.820747,6.1314912,412.32703,-9.262475
2244,2244,178.7081,8.3372965,3.9967864,0.0,0,5.5222936,0.0,0.30904248,77.917107,6.0859871,412.19949,-9.2624702
2246,2246,178.7085,8.3512249,4.0490394,0.0,0,5.4789333,0.0,0.31422976,77.634064,6.035686,412.07193,-9.261344
2248,2248,178.7089,8.363493,4.0887456,0.0,0,5.4355736,0.0,0.31804001,77.492249,5.9886971,411.9444,-9.2607346
2250,2250,178.7093,8.4028234,4.1376276,0.0,0,5.3922133,0.0,0.32203272,77.52623,5.9450569,411.81683,-9.2615757
2252,2252,178.7097,8.4713526,4.1828871,0.0,0,5.3488536,0.0,0.3269245,77.743568,5.8976617,411.6893,-9.2620411
2254,2254,178.7101,8.5003395,4.2281771,0.0,0,5.3054934,0.0,0.33075544,77.726112,5.8518524,411.56177,-9.2625265
2256,2256,178.7105,8.5219202,4.2772746,0.0,0,5.2621331,0.0,0.33504611,77.61692,5.8048496,411.4342,-9.2622395
2258,2258,178.7109,8.552968,4.3185973,0.0,0,5.2187734,0.0,0.33963478,77.50309,5.7574415,411.30667,-9.2611933
2260,2260,178.7113,8.584301,4.3673625,0.0,0,5.1754136,0.0,0.3434501,77.51078,5.7116466,411.17911,-9.2621756
2262,2262,178.7117,8.6564503,4.4139872,0.0,0,5.1320534,0.0,0.3480157,77.723793,5.6674538,411.05157,-9.2627478
2264,2264,178.7121,8.6770906,4.4558582,0.0,0,5.0886931,0.0,0.35262179,77.68425,5.6211743,410.92404,-9.2617159
2266,2266,178.7125,8.7056484,4.5094781,0.0,0,5.0457683,0.0,0.35665923,77.598915,5.572165,410.79648,-9.2624264
2268,2268,178.7129,8.7297306,4.5512547,0.0,0,5.0044241,0.0,0.36131015,77.423988,5.5250664,410.66895,-9.2608929
2270,2270,178.7133,8.7719822,4.5940018,0.0,0,4.9631839,0.0,0.36547986,77.486389,5.4815998,410.54138,-9.2615976
2272,2272,178.7137,8.8039656,4.6462417,0.0,0,4.9219441,0.0,0.3695654,77.449181,5.4344635,410.41385,-9.2623205
2274,2274,178.7141,8.8505907,4.6824188,0.0,0,4.8807039,0.0,0.3741442,77.482475,5.3901772,410.28632,-9.2622366
2276,2276,178.7145,8.8659277,4.7270355,0.0,0,4.8394642,0.0,0.37805504,77.412521,5.3424158,410.15875,-9.2618933
2278,2278,178.7149,8.9078817,4.7812438,0.0,0,4.798224,0.0,0.38285324,77.259544,5.2967696,410.03122,-9.2610502
2280,2280,178.7153,8.9414387,4.8185019,0.0,0,4.7569842,0.0,0.38752267,77.248451,5.252573,409.90366,-9.260849
2282,2282,178.7157,8.9967794,4.8663964,0.0,0,4.715744,0.0,0.3914502,77.430199,5.20608,409.77612,-9.2600164
2284,2284,178.7161,9.0308599,4.9156432,0.0,0,4.6745043,0.0,0.39644662,77.375,5.167079,409.64859,-9.2610016
2286,2286,178.7165,9.0700035,4.9518304,0.0,0,4.6332641,0.0,0.40063635,77.366989,5.1210103,409.52103,-9.2623196
2288,2288,178.7169,9.0694733,4.9991555,0.0,0,4.5920238,0.0,0.40455216,77.069481,5.0779686,409.39349,-9.2624979
2290,2290,178.7173,9.1192865,5.0444093,0.0,0,4.5507841,0.0,0.40970045,77.002029,5.0351725,409.07516,-9.2614021
2292,2292,178.7177,9.1721001,5.0841932,0.0,0,4.5108657,0.0,0.4136591,77.197853,4.9881916,408.69324,-9.2593241
2294,2294,178.7181,9.2184706,5.1306853,0.0,0,4.4716296,0.0,0.41774768,77.247299,4.9455428,408.31134,-9.2609158
2296,2296,178.7185,9.2466564,5.1735649,0.0,0,4.4323978,0.0,0.42308035,77.097336,4.9034858,407.92941,-9.261466
2298,2298,178.7189,9.2536058,5.2172918,0.0,0,4.3931656,0.0,0.42689073,76.923927,4.8608599,407.54752,-9.2619562
2300,2300,178.7193,9.2989206,5.2642989,0.0,0,4.3539338,0.0,0.43147343,76.868179,4.8159523,407.16559,-9.2619781
2302,2302,178.7197,9.3739157,5.3033791,0.0,0,4.314702,0.0,0.43640304,77.091042,4.7720046,406.78369,-9.2601423
2304,2304,178.7201,9.4086456,5.3494434,0.0,0,4.2754698,0.0,0.44029084,77.142288,4.7282753,406.40176,-9.2599154
2306,2306,178.7205,9.4154005,5.3926282,0.0,0,4.2362375,0.0,0.44495389,76.849152,4.685832,406.01987,-9.2609482
2308,2308,178.7209,9.4397707,5.4288273,0.0,0,4.1970053,0.0,0.44934392,76.650536,4.6438751,405.63794,-9.2623291
2310,2310,178.7213,9.4842634,5.47964,0.0,0,4.1577735,0.0,0.45352027,76.73188,4.603755,405.25604,-9.2630901
2312,2312,178.7217,9.5676289,5.5166726,0.0,0,4.1185417,0.0,0.45827964,76.970352,4.5594025,404.87411,-9.2614899
2314,2314,178.7221,9.5934248,5.5561481,0.0,0,4.0793095,0.0,0.46239054,76.914795,4.5144849,404.49222,-9.2603645
2316,2316,178.7225,9.6020994,5.6087141,0.0,0,4.0404716,0.0,0.46714434,76.629601,4.4752121,404.11029,-9.2605972
2318,2318,178.7229,9.6294184,5.6431236,0.0,0,4.0030656,0.0,0.4719584,76.478645,4.4300828,403.72836,-9.2604246
2320,2320,178.7233,9.6981821,5.6856823,0.0,0,3.9657533,0.0,0.4758912,76.651344,4.3895602,403.34647,-9.2621117
2322,2322,178.7237,9.7658138,5.7356277,0.0,0,3.9284413,0.0,0.48092589,76.844307,4.3495131,402.96454,-9.2627792
2324,2324,178.7241,9.7877569,5.7670135,0.0,0,3.8911293,0.0,0.48537573,76.66523,4.3084989,402.58264,-9.262825
2326,2326,178.7245,9.7998133,5.8099046,0.0,0,3.8538175,0.0,0.48910823,76.486313,4.2658772,402.20071,-9.2608309
2328,2328,178.7249,9.8479738,5.8550024,0.0,0,3.8165054,0.0,0.49441484,76.4496,4.2238646,401.81882,-9.2601156
2330,2330,178.7253,9.9098167,5.8871632,0.0,0,3.7791932,0.0,0.49836648,76.567398,4.1837001,401.43689,-9.2598
2332,2332,178.7257,9.9619246,5.9325132,0.0,0,3.7418811,0.0,0.50233805,76.732948,4.1420851,401.05499,-9.2612791
2334,2334,178.7261,9.9976997,5.9738369,0.0,0,3.7045693,0.0,0.50785786,76.599762,4.100071,400.67307,-9.2614565
2336,2336,178.7265,10.015317,6.0108275,0.0,0,3.6672573,0.0,0.51173675,76.424896,4.0634284,400.29117,-9.2612324
2338,2338,178.7269,10.065932,6.0554147,0.0,0,3.6299453,0.0,0.51618403,76.454185,4.0210042,399.90924,-9.2609959
2340,2340,178.7273,10.118465,6.0919642,0.0,0,3.5926332,0.0,0.52131021,76.461906,3.9829581,399.42682,-9.2596712
2342,2342,178.7277,10.17335,6.1320863,0.0,0,3.5565166,0.0,0.52489728,76.604385,3.9418001,398.91089,-9.2594538
2344,2344,178.7281,10.212866,6.1713419,0.0,0,3.5210168,0.0,0.52934009,76.566193,3.9074452,398.39496,-9.2601624
2346,2346,178.7285,10.234207,6.2011876,0.0,0,3.4855206,0.0,0.533701,76.468948,3.867115,397.87903,-9.2612638
2348,2348,178.7289,10.254303,6.2466297,0.0,0,3.4500248,0.0,0.5375669,76.27388,3.8265433,397.36307,-9.2610722
2350,2350,178.7293,10.32477,6.2856331,0.0,0,3.4145288,0.0,0.54271287,76.349106,3.7873921,396.84714,-9.2601509
2352,2352,178.7297,10.396858,6.3214359,0.0,0,3.3790326,0.0,0.54719394,76.566551,3.7514658,396.33121,-9.2597761
2354,2354,178.7301,10.425697,6.3684864,0.0,0,3.3435369,0.0,0.55137253,76.502632,3.7119074,395.81528,-9.2598133
2356,2356,178.7305,10.447896,6.3985777,0.0,0,3.3080409,0.0,0.55611992,76.244606,3.6744521,395.29935,-9.261302
2358,2358,178.7309,10.497022,6.4333,0.0,0,3.2725446,0.0,0.55975759,76.273598,3.635541,394.78342,-9.2614822
2360,2360,178.7313,10.591583,6.4802127,0.0,0,3.2370486,0.0,0.5644666,76.549583,3.5990672,394.26749,-9.2617807
2362,2362,178.7317,10.639441,6.5071216,0.0,0,3.2015526,0.0,0.56901789,76.648224,3.5659504,393.75156,-9.2601824
2364,2364,178.7321,10.641374,6.5441675,0.0,0,3.1660566,0.0,0.57249272,76.441612,3.5254879,393.23563,-9.2584381
2366,2366,178.7325,10.682551,6.5892444,0.0,0,3.1309152,0.0,0.57770878,76.349983,3.4924815,392.71967,-9.260108
2368,2368,178.7329,10.733263,6.6170669,0.0,0,3.0970623,0.0,0.58201009,76.337547,3.4567285,392.20374,-9.2609444
2370,2370,178.7333,10.803064,6.6584454,0.0,0,3.0632944,0.0,0.58566445,76.500893,3.4202237,391.68781,-9.2619333
2372,2372,178.7337,10.853657,6.6976681,0.0,0,3.0295265,0.0,0.59121197,76.467529,3.3847861,391.17188,-9.2608566
2374,2374,178.7341,10.886652,6.7252393,0.0,0,2.9957583,0.0,0.59477258,76.443916,3.3514471,390.65594,-9.2596169
2376,2376,178.7345,10.925397,6.7646403,0.0,0,2.9619906,0.0,0.59859169,76.433578,3.3129463,390.14001,-9.2606745
2378,2378,178.7349,10.982137,6.7997069,0.0,0,2.9282222,0.0,0.60398102,76.385223,3.2769814,389.62408,-9.2614231
2380,2380,178.7353,11.050849,6.8338337,0.0,0,2.8944542,0.0,0.60761923,76.542137,3.2413003,389.10815,-9.2602739
2382,2382,178.7357,11.112262,6.8738279,0.0,0,2.8606863,0.0,0.61204797,76.646042,3.2057219,388.59219,-9.2601738
2384,2384,178.7361,11.159074,6.9059329,0.0,0,2.8269184,0.0,0.61720163,76.618561,3.167372,388.07626,-9.2601004
2386,2386,178.7365,11.189348,6.9431295,0.0,0,2.7931502,0.0,0.6207568,76.571465,3.1323047,387.56033,-9.2604637
2388,2388,178.7369,11.242358,6.9785781,0.0,0,2.7593822,0.0,0.62543803,76.600029,3.0954955,387.0444,-9.2604818
2390,2390,178.7373,11.30593,7.007966,0.0,0,2.7256143,0.0,0.62994796,76.639175,3.0628762,386.89825,-9.2589493
2392,2392,178.7377,11.391037,7.0506649,0.0,0,2.6929309,0.0,0.63373375,76.917992,3.0238674,386.87531,-9.2597218
2394,2394,178.7381,11.427786,7.0826349,0.0,0,2.6608074,0.0,0.63879383,76.795692,2.9935544,386.85239,-9.2591438
2396,2396,178.7385,11.463223,7.1153069,0.0,0,2.6286874,0.0,0.64306962,76.663841,2.9559197,386.82947,-9.2585325
2398,2398,178.7389,11.523005,7.1584167,0.0,0,2.5965672,0.0,0.64730668,76.742104,2.9214244,386.80655,-9.259593
2400,2400,178.7393,11.605714,7.1818233,0.0,0,2.5644474,0.0,0.65179038,76.933876,2.8886573,386.78363,-9.259902
2402,2402,178.7397,11.67415,7.2133255,0.0,0,2.5323272,0.0,0.65516114,77.178513,2.8536944,386.76068,-9.2603378
2404,2404,178.7401,11.716876,7.2566628,0.0,0,2.5002072,0.0,0.66017449,77.025703,2.8208566,386.73776,-9.2589035
2406,2406,178.7405,11.738619,7.283534,0.0,0,2.4680872,0.0,0.66492468,76.865944,2.7889733,386.71484,-9.2589111
2408,2408,178.7409,11.81721,7.3199706,0.0,0,2.4359674,0.0,0.6686247,77.042854,2.7583671,386.69193,-9.2578468
2410,2410,178.7413,11.903653,7.3591232,0.0,0,2.4038472,0.0,0.67382842,77.193367,2.7224541,386.66901,-9.2592745
2412,2412,178.7417,11.956381,7.3837719,0.0,0,2.3717272,0.0,0.67790788,77.290512,2.6874449,386.64606,-9.2595797
2414,2414,178.7421,12.007607,7.4216566,0.0,0,2.3396072,0.0,0.68157142,77.303902,2.6590025,386.62314,-9.2597818
2416,2416,178.7425,12.047421,7.4545341,0.0,0,2.3078089,0.0,0.68713969,77.133522,2.6229105,386.60022,-9.2591791
2418,2418,178.7429,12.123562,7.4817672,0.0,0,2.2771804,0.0,0.69066024,77.330917,2.5935457,386.5773,-9.2593889
2420,2420,178.7433,12.215752,7.52003,0.0,0,2.246628,0.0,0.69468552,77.596931,2.5563023,386.55438,-9.2597923
2422,2422,178.7437,12.281517,7.5522103,0.0,0,2.2160764,0.0,0.70037758,77.651451,2.5241227,386.53143,-9.2588692
2424,2424,178.7441,12.320703,7.5851269,0.0,0,2.1855242,0.0,0.70399511,77.578888,2.4917006,386.50851,-9.2591839
2426,2426,178.7445,12.370668,7.6204491,0.0,0,2.1549723,0.0,0.70853758,77.558899,2.4603887,386.4856,-9.2600355
2428,2428,178.7449,12.450147,7.6474771,0.0,0,2.1244202,0.0,0.71340913,77.563721,2.4269834,386.46268,-9.2592258
2430,2430,178.7453,12.545426,7.6845045,0.0,0,2.0938683,0.0,0.71695888,77.926018,2.3914065,386.43976,-9.2593842
2432,2432,178.7457,12.610987,7.7145572,0.0,0,2.0633163,0.0,0.72164649,78.002159,2.3610542,386.41681,-9.2595625
2434,2434,178.7461,12.644293,7.7421579,0.0,0,2.0327644,0.0,0.72619313,77.869461,2.3314409,386.39389,-9.2591209
2436,2436,178.7465,12.705379,7.784936,0.0,0,2.0022123,0.0,0.73039371,77.904625,2.2987077,386.37097,-9.2598982
2438,2438,178.7469,12.799901,7.8096704,0.0,0,1.9716601,0.0,0.73530608,78.060654,2.2623143,386.34805,-9.2602873
2440,2440,178.7473,12.892008,7.8380141,0.0,0,1.9411081,0.0,0.73900169,78.371384,2.2336941,386.41922,-9.2581787
2442,2442,178.7477,12.948703,7.8811026,0.0,0,1.9115355,0.0,0.74380815,78.274582,2.2037668,386.52179,-9.2585135
2444,2444,178.7481,12.998781,7.9030743,0.0,0,1.8824685,0.0,0.74873137,78.162567,2.170017,386.62436,-9.258316
2446,2446,178.7485,13.065115,7.93434,0.0,0,1.8534043,0.0,0.75207084,78.361115,2.1381674,386.7269,-9.2576427
2448,2448,178.7489,13.161261,7.9733305,0.0,0,1.8243403,0.0,0.75732768,78.526733,2.1081781,386.82947,-9.2594156
2450,2450,178.7493,13.253427,7.9971099,0.0,0,1.7952764,0.0,0.76212257,78.724411,2.0767796,386.93201,-9.2590179
2452,2452,178.7497,13.30677,8.0308332,0.0,0,1.7662123,0.0,0.76547122,78.774208,2.0447538,387.03458,-9.2587423
2454,2454,178.7501,13.373762,8.0665483,0.0,0,1.7371484,0.0,0.77127647,78.682808,2.0139167,387.13712,-9.2585163
2456,2456,178.7505,13.46372,8.0880756,0.0,0,1.7080843,0.0,0.77507573,78.925781,1.982134,387.23969,-9.2582102
2458,2458,178.7509,13.557029,8.1241236,0.0,0,1.6790204,0.0,0.7787618,79.163551,1.9499251,387.34222,-9.2576437
2460,2460,178.7513,13.660748,8.156456,0.0,0,1.6499563,0.0,0.78478765,79.286087,1.9189719,387.44479,-9.2575932
2462,2462,178.7517,13.723526,8.1841068,0.0,0,1.6208923,0.0,0.78853977,79.393784,1.887609,387.54733,-9.258194
2464,2464,178.7521,13.788443,8.2200165,0.0,0,1.5918283,0.0,0.79300177,79.39637,1.8591064,387.6499,-9.2578325
2466,2466,178.7525,13.855434,8.2461348,0.0,0,1.5630548,0.0,0.79843217,79.369041,1.8288084,387.75244,-9.2572794
2468,2468,178.7529,13.953197,8.2755489,0.0,0,1.5353373,0.0,0.80153769,79.656105,1.7967548,387.85501,-9.2577124
2470,2470,178.7533,14.041981,8.3071594,0.0,0,1.5076892,0.0,0.80617994,79.778534,1.7683746,387.95755,-9.2582054
2472,2472,178.7537,14.121049,8.3316498,0.0,0,1.4800413,0.0,0.81111372,79.805687,1.7401414,388.06012,-9.2586632
2474,2474,178.7541,14.191121,8.3693476,0.0,0,1.4523933,0.0,0.81503224,79.952591,1.7079769,388.16266,-9.2576704
2476,2476,178.7545,14.270516,8.3971138,0.0,0,1.4247453,0.0,0.82024056,79.972107,1.6830614,388.26523,-9.2580853
2478,2478,178.7549,14.374121,8.4211044,0.0,0,1.3970973,0.0,0.82430905,80.175415,1.6515993,388.36777,-9.2576351
2480,2480,178.7553,14.479262,8.4598179,0.0,0,1.3694494,0.0,0.82846862,80.523453,1.6228454,388.47034,-9.2568378
2482,2482,178.7557,14.573158,8.4821901,0.0,0,1.3418013,0.0,0.83365053,80.55571,1.5937924,388.57288,-9.2563906
2484,2484,178.7561,14.64381,8.5110989,0.0,0,1.3141534,0.0,0.83749306,80.62043,1.5652263,388.67545,-9.2584658
2486,2486,178.7565,14.731501,8.5518122,0.0,0,1.2865053,0.0,0.84278232,80.706863,1.534511,388.77798,-9.2581997
2488,2488,178.7569,14.838902,8.5711622,0.0,0,1.2588574,0.0,0.84771502,80.874245,1.5066137,388.88055,-9.2583599
2490,2490,178.7573,14.954123,8.6015434,0.0,0,1.2312094,0.0,0.85115361,81.191719,1.4767783,388.53912,-9.2572803
2492,2492,178.7577,15.033211,8.6374741,0.0,0,1.2044513,0.0,0.85664445,81.213211,1.4468832,388.04974,-9.2561321
2494,2494,178.7581,15.09803,8.6534576,0.0,0,1.1781524,0.0,0.86060673,81.270782,1.4187469,387.56033,-9.2570639
2496,2496,178.7585,15.192729,8.6851683,0.0,0,1.1518564,0.0,0.86384749,81.485046,1.3871728,387.07095,-9.2572603
2498,2498,178.7589,15.318749,8.7172623,0.0,0,1.1255604,0.0,0.8700853,81.619995,1.3595266,386.58154,-9.2580414
2500,2500,178.7593,15.438147,8.7409296,0.0,0,1.0992644,0.0,0.87404633,81.972908,1.3302155,386.09216,-9.2577095
2502,2502,178.7597,15.512555,8.7760963,0.0,0,1.0729684,0.0,0.87846708,82.03212,1.3007674,385.60278,-9.2560873
2504,2504,178.7601,15.605341,8.8039799,0.0,0,1.0466723,0.0,0.88449454,82.003288,1.2740415,385.11337,-9.2565432
2506,2506,178.7605,15.70281,8.8291588,0.0,0,1.0203763,0.0,0.88782805,82.22377,1.2452872,384.62399,-9.2575417
2508,2508,178.7609,15.81925,8.8585939,0.0,0,0.99408036,0.0,0.89197052,82.51236,1.2188141,384.13458,-9.2569237
2510,2510,178.7613,15.938731,8.878643,0.0,0,0.96778435,0.0,0.89683896,82.720947,1.1898583,383.6452,-9.2568188
2512,2512,178.7617,16.024702,8.9090109,0.0,0,0.94148839,0.0,0.90004313,82.937309,1.1621108,383.15579,-9.2567215
2514,2514,178.7621,16.107916,8.9400148,0.0,0,0.91519243,0.0,0.90566713,82.890816,1.1353559,382.66641,-9.2564726
2516,2516,178.7625,16.225307,8.9651031,0.0,0,0.88916051,0.0,0.9110617,82.994865,1.1065456,382.17703,-9.2567959
2518,2518,178.7629,16.347252,9.0019836,0.0,0,0.86408949,0.0,0.91512102,83.315193,1.0786912,381.68762,-9.2569733
2520,2520,178.7633,16.476631,9.0235434,0.0,0,0.83908135,0.0,0.92020541,83.510399,1.0509396,381.19824,-9.2554283
2522,2522,178.7637,16.564888,9.0462942,0.0,0,0.81407332,0.0,0.92398912,83.699463,1.0229113,380.70883,-9.2556038
2524,2524,178.7641,16.64126,9.0816183,0.0,0,0.78906536,0.0,0.92818207,83.708488,0.99603695,380.21945,-9.256484
2526,2526,178.7645,16.761559,9.0982628,0.0,0,0.7640574,0.0,0.93318743,83.834175,0.96706855,379.73004,-9.2567654
2528,2528,178.7649,16.894917,9.1235962,0.0,0,0.73904938,0.0,0.93660617,84.270386,0.94276482,379.24066,-9.2562399
2530,2530,178.7653,17.021528,9.1619501,0.0,0,0.71404135,0.0,0.94228399,84.40097,0.91521651,378.75125,-9.2565908
2532,2532,178.7657,17.109041,9.1812801,0.0,0,0.68903339,0.0,0.94745922,84.391968,0.88839346,378.26187,-9.2569532
2534,2534,178.7661,17.209839,9.2108135,0.0,0,0.66402543,0.0,0.95088208,84.602684,0.8623274,377.77249,-9.2555637
2536,2536,178.7665,17.342762,9.2395525,0.0,0,0.63901734,0.0,0.95643675,84.756798,0.83708423,377.28308,-9.2553234
2538,2538,178.7669,17.4841,9.2547951,0.0,0,0.61400938,0.0,0.96005833,85.175674,0.8088237,376.7937,-9.2565575
2540,2540,178.7673,17.598738,9.2859392,0.0,0,0.58900136,0.0,0.9637028,85.425591,0.78096759,376.5473,-9.2559919
2542,2542,178.7677,17.692646,9.3137608,0.0,0,0.56478846,0.0,0.97007447,85.340073,0.75747895,376.3819,-9.2559919
2544,2544,178.7681,17.796988,9.3357201,0.0,0,0.54098594,0.0,0.97368294,85.536171,0.72863603,376.21649,-9.2562027
2546,2546,178.7685,17.932396,9.3673134,0.0,0,0.51718587,0.0,0.97789472,85.818069,0.70254642,376.05109,-9.2558374
2548,2548,178.7689,18.085608,9.3887596,0.0,0,0.49338591,0.0,0.98396009,85.996422,0.67594069,375.88568,-9.2558079
2550,2550,178.7693,18.199274,9.4140902,0.0,0,0.4695859,0.0,0.9869957,86.307999,0.65346503,375.72028,-9.2558298
2552,2552,178.7697,18.314384,9.4412899,0.0,0,0.44578591,0.0,0.99174058,86.397415,0.62537587,375.55487,-9.2567472
2554,2554,178.7701,18.430136,9.4615183,0.0,0,0.42198589,0.0,0.99708372,86.492226,0.60146683,375.38947,-9.2557459
2556,2556,178.7705,18.560343,9.4929867,0.0,0,0.39818591,0.0,1.0005599,86.823654,0.57662362,375.22406,-9.2549839
2558,2558,178.7709,18.705296,9.5170488,0.0,0,0.37438589,0.0,1.006018,87.02816,0.55221093,375.05865,-9.2545481