File: clean data/testID_0106.csv
level_0,index,Time(sec),Force(kN),Jaw(mm),PowAngle(deg),Power(W),Pram,PTemp,Strain,Stress(MPa),Stroke(mm),TC1(C),wedge(mm)
2433,2433,195.3759,0.98692948,0.013530915,0.0,0,9.9098625,0.0,0.0010770118,12.376468,10.006399,449.37097,-9.2360516
2444,2444,195.3781,2.4009566,0.023641886,0.0,0,9.8768635,0.0,0.0014593382,30.250053,9.9797392,449.4039,-9.2354002
2455,2455,195.3803,3.6929367,0.031440325,0.0,0,9.8438625,0.0,0.0022162227,46.739613,9.9506083,449.43683,-9.2336149
2466,2466,195.3825,4.3184228,0.065434381,0.0,0,9.8108635,0.0,0.0041200393,54.683136,9.9168911,449.49133,-9.2313099
2477,2477,195.3847,4.6462641,0.096712135,0.0,0,9.7778625,0.0,0.0064873351,58.781437,9.8764439,449.57697,-9.2315798
2488,2488,195.3869,4.8416538,0.13305624,0.0,0,9.7448626,0.0,0.0088257529,60.993984,9.8375607,449.6626,-9.2313223
2499,2499,195.3891,4.9767551,0.16624404,0.0,0,9.7118626,0.0,0.01111236,62.650311,9.798975,449.74823,-9.2315578
2510,2510,195.3913,5.077857,0.20744589,0.0,0,9.6788635,0.0,0.013874955,63.782207,9.7630739,449.83383,-9.2334986
2521,2521,195.3935,5.1521831,0.23834836,0.0,0,9.6458626,0.0,0.015938483,64.528748,9.7275286,449.93088,-9.2325363
2532,2532,195.3957,5.2200975,0.2707229,0.0,0,9.6128626,0.0,0.01825304,65.241928,9.691144,450.02966,-9.2318983
2543,2543,195.3979,5.2588778,0.30274856,0.0,0,9.5798626,0.0,0.020312447,65.617683,9.6594944,450.12848,-9.2310362
2554,2554,195.4001,5.3010464,0.33699486,0.0,0,9.5468636,0.0,0.022766242,65.922798,9.6248827,450.22729,-9.2315245
2565,2565,195.4023,5.3097982,0.36413106,0.0,0,9.5138626,0.0,0.024370406,66.082054,9.5973482,450.31354,-9.2318525
2576,2576,195.4045,5.3719096,0.39315122,0.0,0,9.4808931,0.0,0.026624279,66.574333,9.5638056,450.37283,-9.2325191
2587,2587,195.4067,5.3877425,0.42478767,0.0,0,9.4486961,0.0,0.028575385,66.720917,9.5327568,450.4321,-9.2323999
2598,2598,195.4089,5.4379759,0.4590123,0.0,0,9.4165049,0.0,0.031299237,67.094879,9.4995184,450.49139,-9.2339191
2609,2609,195.4111,5.4625678,0.49684379,0.0,0,9.3843145,0.0,0.033413153,67.246872,9.4661779,450.55069,-9.2332125
2620,2620,195.4133,5.4873309,0.52639621,0.0,0,9.3521242,0.0,0.035883438,67.439339,9.4330816,450.60995,-9.2336903
2631,2631,195.4155,5.5526366,0.56104887,0.0,0,9.3199339,0.0,0.03794774,67.933708,9.3957815,450.66925,-9.2343178
2642,2642,195.4177,5.5619583,0.59403503,0.0,0,9.2877445,0.0,0.040626444,67.92704,9.3590527,450.72852,-9.2326384
2653,2653,195.4199,5.5670366,0.63095224,0.0,0,9.2555532,0.0,0.042620633,67.941353,9.3313847,450.78781,-9.2336369
2664,2664,195.4221,5.5749159,0.65668124,0.0,0,9.2233629,0.0,0.044888873,67.885979,9.3012352,450.84711,-9.2328348
2675,2675,195.4243,5.5893097,0.68991643,0.0,0,9.1911726,0.0,0.046907362,67.97229,9.2658949,450.90637,-9.2343521
2686,2686,195.4265,5.5995369,0.71833569,0.0,0,9.1589823,0.0,0.049274523,67.918419,9.2323647,450.96567,-9.234334
2697,2697,195.4287,5.5993309,0.75704205,0.0,0,9.126792,0.0,0.051451314,67.758209,9.2008991,451.02496,-9.2343054
2708,2708,195.4309,5.6307058,0.78262556,0.0,0,9.0946016,0.0,0.053741436,67.85466,9.1697054,451.08426,-9.2340784
2719,2719,195.4331,5.6659198,0.81584603,0.0,0,9.0624104,0.0,0.055802789,68.073715,9.1355534,451.14355,-9.2336512
2730,2730,195.4353,5.6986175,0.84387636,0.0,0,9.03022,0.0,0.058019485,68.486038,9.1011505,451.20285,-9.2353945
2741,2741,195.4375,5.7336159,0.88309336,0.0,0,8.9980307,0.0,0.060487777,68.732712,9.0682507,451.26212,-9.234067
2752,2752,195.4397,5.7475495,0.9110533,0.0,0,8.9658394,0.0,0.062713735,68.732018,9.0395136,451.32141,-9.232995
2763,2763,195.4419,5.7696629,0.94657516,0.0,0,8.93365,0.0,0.065133922,68.820526,9.0040493,451.38251,-9.2318792
2774,2774,195.4441,5.776577,0.9763763,0.0,0,8.9014587,0.0,0.067274056,68.880653,8.9701777,451.45496,-9.2336235
2785,2785,195.4463,5.7514758,1.0115095,0.0,0,8.8692684,0.0,0.069682568,68.301819,8.9375267,451.5274,-9.2343378
2796,2796,195.4485,5.763,1.0388213,0.0,0,8.8370781,0.0,0.07172256,68.3498,8.9068546,451.59988,-9.2332563
2807,2807,195.4507,5.8049922,1.0711329,0.0,0,8.8048878,0.0,0.074144095,68.58075,8.8734283,451.67233,-9.233532
2818,2818,195.4529,5.8458204,1.1013086,0.0,0,8.7726974,0.0,0.076145239,68.962418,8.8421154,451.56573,-9.2327957
2829,2829,195.4551,5.897892,1.1376979,0.0,0,8.7409811,0.0,0.07895866,69.426781,8.8067093,451.33517,-9.2321444
2840,2840,195.4573,5.9191327,1.1686802,0.0,0,8.7103653,0.0,0.080933459,69.46579,8.7725687,451.10461,-9.2334757
2851,2851,195.4595,5.9105706,1.2007625,0.0,0,8.6797504,0.0,0.083528049,69.213737,8.7398672,450.87405,-9.2335978
2862,2862,195.4617,5.9147444,1.2319784,0.0,0,8.6491356,0.0,0.085412584,69.170219,8.7090273,450.63391,-9.2340984
2873,2873,195.4639,5.9125118,1.2616954,0.0,0,8.6185198,0.0,0.088025898,68.886894,8.67659,450.19257,-9.2341356
2884,2884,195.4661,5.9113274,1.2963324,0.0,0,8.5879049,0.0,0.090100795,68.800133,8.6442204,449.75119,-9.233717
2895,2895,195.4683,5.9189715,1.3235377,0.0,0,8.5572891,0.0,0.092531599,68.718681,8.6132002,449.30984,-9.2346134
2906,2906,195.4705,5.9490037,1.3543373,0.0,0,8.5266743,0.0,0.094358481,68.901382,8.5858536,448.8685,-9.2346315
2917,2917,195.4727,5.9697447,1.3822849,0.0,0,8.4960594,0.0,0.096910052,68.977432,8.5561399,448.6709,-9.2339706
2928,2928,195.4749,6.0081258,1.41803,0.0,0,8.4654446,0.0,0.098851882,69.31263,8.5189209,448.71698,-9.2330484
2939,2939,195.4771,6.0201688,1.4419696,0.0,0,8.4348288,0.0,0.10126302,69.322678,8.489994,448.76309,-9.2337437
2950,2950,195.4793,6.0115891,1.4727489,0.0,0,8.4042149,0.0,0.10312352,69.021149,8.4636326,448.8092,-9.23353
2961,2961,195.4815,6.0192232,1.4999102,0.0,0,8.3735981,0.0,0.10557602,68.975555,8.4317341,448.85532,-9.2335033
2972,2972,195.4837,6.0314279,1.5343442,0.0,0,8.3429832,0.0,0.10753952,68.942383,8.4004908,449.20328,-9.2324781
2983,2983,195.4859,6.0425825,1.5587164,0.0,0,8.3123684,0.0,0.10985765,68.899658,8.3738251,449.56558,-9.2333279
2994,2994,195.4881,6.0931802,1.5907729,0.0,0,8.2817526,0.0,0.11194735,69.316444,8.3432732,449.92789,-9.2346163
3005,3005,195.4903,6.134552,1.6188271,0.0,0,8.2511387,0.0,0.11426836,69.588982,8.314662,450.29019,-9.2338428
3016,3016,195.4925,6.1937962,1.657901,0.0,0,8.2205219,0.0,0.11687514,70.125862,8.2800779,450.5932,-9.2340107
3027,3027,195.4947,6.2076216,1.6877128,0.0,0,8.189908,0.0,0.11939452,70.096329,8.2442656,450.81058,-9.2335224
3038,3038,195.4969,6.1982932,1.7211361,0.0,0,8.1592922,0.0,0.12178343,69.866318,8.2155037,451.02798,-9.2338009
3049,3049,195.4991,6.209548,1.7473046,0.0,0,8.1286774,0.0,0.12382673,69.857338,8.1780739,451.24536,-9.2330751
3060,3060,195.5013,6.2271433,1.7844989,0.0,0,8.0980616,0.0,0.12652069,69.794212,8.1491137,451.46274,-9.2342958
3071,3071,195.5035,6.2502017,1.8133203,0.0,0,8.0674467,0.0,0.12880953,69.944595,8.1207533,451.57202,-9.2341442
3082,3082,195.5057,6.2233109,1.8433287,0.0,0,8.0376854,0.0,0.1312118,69.471573,8.0843582,451.66425,-9.2347565
3093,3093,195.5079,6.2530241,1.8740155,0.0,0,8.0085573,0.0,0.13336925,69.629074,8.0543251,451.75647,-9.2341042
3104,3104,195.5101,6.2769461,1.9071862,0.0,0,7.9794288,0.0,0.13608745,69.695793,8.0256062,451.84869,-9.2336302
3115,3115,195.5123,6.306088,1.9350824,0.0,0,7.9503012,0.0,0.13791934,69.914108,7.994061,451.9472,-9.2325211
3126,3126,195.5145,6.3058014,1.961704,0.0,0,7.9211731,0.0,0.14022365,69.775307,7.9653759,452.05917,-9.2341118
3137,3137,195.5167,6.2989354,1.9903084,0.0,0,7.892045,0.0,0.14212537,69.55632,7.9362798,452.17117,-9.234704
3148,3148,195.5189,6.299489,2.019933,0.0,0,7.8629169,0.0,0.14481942,69.453491,7.9054923,452.28317,-9.2336588
3159,3159,195.5211,6.324687,2.0499635,0.0,0,7.8337889,0.0,0.14664069,69.57428,7.8793454,452.39514,-9.2341814
3170,3170,195.5233,6.3388195,2.0745234,0.0,0,7.8046608,0.0,0.14907059,69.455177,7.8509493,452.4715,-9.2345505
3181,3181,195.5255,6.3547125,2.1048479,0.0,0,7.7755327,0.0,0.15093637,69.512077,7.819612,452.53738,-9.2356863
3192,3192,195.5277,6.3688803,2.1321633,0.0,0,7.7464046,0.0,0.153586,69.44706,7.7877727,452.60324,-9.234189
3203,3203,195.5299,6.4021511,2.1660862,0.0,0,7.7172766,0.0,0.15558146,69.711578,7.7621827,452.66913,-9.2328558
3214,3214,195.5321,6.4292111,2.1872034,0.0,0,7.6881485,0.0,0.1578647,69.804848,7.732214,452.70956,-9.2333002
3225,3225,195.5343,6.4390097,2.2182491,0.0,0,7.6590204,0.0,0.15981208,69.894485,7.7034116,452.66345,-9.2331076
3236,3236,195.5365,6.4436297,2.2429426,0.0,0,7.6298928,0.0,0.1622164,69.805061,7.6761231,452.61734,-9.2349634
3247,3247,195.5387,6.4649439,2.2796812,0.0,0,7.6007648,0.0,0.16449776,69.793404,7.6498833,452.57123,-9.2335873
3258,3258,195.5409,6.5032492,2.3023851,0.0,0,7.5716362,0.0,0.16681169,70.061134,7.6139436,452.52512,-9.2349501
3269,3269,195.5431,6.5154929,2.3350625,0.0,0,7.5425086,0.0,0.16901241,70.101021,7.5883026,452.49246,-9.2324858
3280,3280,195.5453,6.5135942,2.3590615,0.0,0,7.513381,0.0,0.17134674,69.841354,7.5580482,452.46613,-9.2329741
3291,3291,195.5475,6.5331445,2.3958213,0.0,0,7.4842525,0.0,0.17374043,69.953072,7.5243883,452.43976,-9.2333183
3302,3302,195.5497,6.5499506,2.4163902,0.0,0,7.4551244,0.0,0.17583731,69.885818,7.4975262,452.41342,-9.2329817
3313,3313,195.5519,6.5900083,2.4488554,0.0,0,7.4259968,0.0,0.17808601,70.283562,7.4687467,452.40234,-9.2330465
3324,3324,195.5541,6.5961432,2.4753001,0.0,0,7.3968687,0.0,0.1804024,70.152435,7.4419718,452.48798,-9.2335014
3335,3335,195.5563,6.6084552,2.5100086,0.0,0,7.3689475,0.0,0.18295734,70.134689,7.4095554,452.57361,-9.2338076
3346,3346,195.5585,6.6119924,2.533556,0.0,0,7.3412447,0.0,0.18501408,69.933151,7.3817124,452.65924,-9.2353554
3357,3357,195.5607,6.6366301,2.5637701,0.0,0,7.3135428,0.0,0.18745136,70.057793,7.3573837,452.74487,-9.2330475
3368,3368,195.5629,6.6491437,2.5906646,0.0,0,7.2858405,0.0,0.18954685,69.996201,7.3224335,452.80716,-9.2327919
3379,3379,195.5651,6.6809344,2.6240602,0.0,0,7.2581377,0.0,0.19234549,70.175285,7.2924209,452.85327,-9.2340431
3390,3390,195.5673,6.6919241,2.6501091,0.0,0,7.2304354,0.0,0.1942919,70.150581,7.2655983,452.89938,-9.2333994
3401,3401,195.5695,6.6919689,2.6759193,0.0,0,7.202733,0.0,0.19660692,69.945549,7.2384548,452.9455,-9.2329082
3412,3412,195.5717,6.6955085,2.70263,0.0,0,7.1750312,0.0,0.19843315,69.981163,7.2111564,452.98172,-9.2344246
3423,3423,195.5739,6.6938529,2.7308204,0.0,0,7.1473279,0.0,0.20120496,69.747437,7.1860652,452.81046,-9.2344065
3434,3434,195.5761,6.7053871,2.7590103,0.0,0,7.119626,0.0,0.20294552,69.666054,7.1574364,452.63916,-9.234271
3445,3445,195.5783,6.7304268,2.7820644,0.0,0,7.0919237,0.0,0.20532189,69.778366,7.1313996,452.4679,-9.2339249
3456,3456,195.5805,6.755815,2.8111589,0.0,0,7.0642214,0.0,0.20726,69.965683,7.1015506,452.29663,-9.2329512
3467,3467,195.5827,6.7724609,2.8383291,0.0,0,7.0365181,0.0,0.21008644,69.831421,7.0735497,452.17807,-9.2329769
3478,3478,195.5849,6.8017955,2.8717122,0.0,0,7.0088162,0.0,0.21203971,70.01281,7.0447488,452.11218,-9.2329397
3489,3489,195.5871,6.8297734,2.8931618,0.0,0,6.9811139,0.0,0.21457192,70.118607,7.0205178,452.0463,-9.2326279
3500,3500,195.5893,6.8418126,2.9221547,0.0,0,6.9534116,0.0,0.21635753,70.203026,6.9898372,451.98044,-9.2349043
3511,3511,195.5915,6.8760905,2.9460628,0.0,0,6.9257088,0.0,0.21899961,70.307861,6.9628568,451.91455,-9.2340441
3522,3522,195.5937,6.8676515,2.9812551,0.0,0,6.8980069,0.0,0.2211816,70.134689,6.9349318,452.09393,-9.2338686
3533,3533,195.5959,6.8796506,3.0040009,0.0,0,6.8703046,0.0,0.22373079,70.106194,6.9054866,452.28494,-9.2335901
3544,3544,195.5981,6.8973374,3.0351868,0.0,0,6.8426018,0.0,0.22579259,70.074593,6.8762736,452.47598,-9.2341185
3555,3555,195.6003,6.9034972,3.058722,0.0,0,6.8148994,0.0,0.22831738,69.942863,6.8445816,452.66702,-9.2339468
3566,3566,195.6025,6.9357142,3.0952892,0.0,0,6.7871971,0.0,0.23075853,70.029335,6.8220348,452.78531,-9.2338772
3577,3577,195.6047,6.9585743,3.1138046,0.0,0,6.7596555,0.0,0.23282593,70.29184,6.7912116,452.79846,-9.2334757
3588,3588,195.6069,6.9715533,3.1448431,0.0,0,6.7332993,0.0,0.23511432,70.111847,6.7646375,452.81165,-9.2335043
3599,3599,195.6091,6.9942951,3.170419,0.0,0,6.7069435,0.0,0.23745468,70.176819,6.7374554,452.82483,-9.2325659
3610,3610,195.6113,6.9737124,3.2023358,0.0,0,6.6805868,0.0,0.23993973,69.940956,6.710535,452.83798,-9.2327833
3621,3621,195.6135,6.9748282,3.2225389,0.0,0,6.6542315,0.0,0.24185725,69.762627,6.6792254,452.69186,-9.2340736
3632,3632,195.6157,6.966188,3.2489359,0.0,0,6.6278753,0.0,0.24407123,69.498627,6.6557822,452.5206,-9.2337894
3643,3643,195.6179,6.9932361,3.2743602,0.0,0,6.6015191,0.0,0.2462422,69.596176,6.6287861,452.34933,-9.2339258
3654,3654,195.6201,7.0361595,3.306025,0.0,0,6.5751634,0.0,0.24912323,69.780937,6.6048212,452.17804,-9.2333202
3665,3665,195.6223,7.0619764,3.3298571,0.0,0,6.5488071,0.0,0.25081456,69.953957,6.5751691,452.0466,-9.2336836
3676,3676,195.6245,7.0668058,3.3536675,0.0,0,6.5224514,0.0,0.25318143,69.734055,6.551784,452.00049,-9.2337122
3687,3687,195.6267,7.0605245,3.3772743,0.0,0,6.4960952,0.0,0.25489742,69.557167,6.526175,451.95438,-9.2336655
3698,3698,195.6289,7.101222,3.4046166,0.0,0,6.4697394,0.0,0.257664,69.866539,6.4982228,451.90826,-9.2319918
3709,3709,195.6311,7.1173897,3.4341822,0.0,0,6.4433832,0.0,0.25965711,69.950241,6.4711127,451.86215,-9.2320232
3720,3720,195.6333,7.1273022,3.4580262,0.0,0,6.4170275,0.0,0.26231205,69.839081,6.4440498,451.86188,-9.2328415
3731,3731,195.6355,7.1508365,3.4865999,0.0,0,6.3906713,0.0,0.26420626,69.90889,6.417944,451.87503,-9.2332964
3742,3742,195.6377,7.1810832,3.5127697,0.0,0,6.3643155,0.0,0.26714858,69.980125,6.3911319,451.88821,-9.2337608
3753,3753,195.6399,7.2244806,3.5461874,0.0,0,6.3379593,0.0,0.26934662,70.230118,6.3604484,451.90137,-9.2329226
3764,3764,195.6421,7.2273784,3.5681541,0.0,0,6.3116031,0.0,0.2718865,70.022385,6.3350801,451.93552,-9.2339802
3775,3775,195.6443,7.2340798,3.5946984,0.0,0,6.2852473,0.0,0.27365336,70.056488,6.3045244,452.04092,-9.234828
3786,3786,195.6465,7.2293606,3.6189239,0.0,0,6.2588916,0.0,0.2764729,69.863045,6.2805042,452.1463,-9.2343216
3797,3797,195.6487,7.2196007,3.6520045,0.0,0,6.2325358,0.0,0.27849191,69.576073,6.2558608,452.25171,-9.234726
3808,3808,195.6509,7.2215543,3.6692834,0.0,0,6.2061796,0.0,0.28084558,69.455078,6.2291098,452.35709,-9.2333698
3819,3819,195.6531,7.2250743,3.697829,0.0,0,6.1798239,0.0,0.28277206,69.376106,6.2037144,452.53436,-9.2328358
3830,3830,195.6553,7.2539845,3.7210925,0.0,0,6.1539731,0.0,0.28542453,69.43335,6.1779838,452.74515,-9.2325716
3841,3841,195.6575,7.272861,3.75418,0.0,0,6.1289063,0.0,0.28774649,69.382935,6.1516628,452.95596,-9.2345123
3852,3852,195.6597,7.2978024,3.7715106,0.0,0,6.1038394,0.0,0.28979841,69.471001,6.128088,453.16678,-9.2343597
3863,3863,195.6619,7.3277502,3.7985179,0.0,0,6.0787725,0.0,0.29178214,69.677849,6.1030388,453.3623,-9.2332964
3874,3874,195.6641,7.3587646,3.820663,0.0,0,6.0537057,0.0,0.29414642,69.836693,6.0748587,453.46109,-9.2332821
3885,3885,195.6663,7.3774066,3.8530889,0.0,0,6.0286393,0.0,0.29662648,69.829353,6.0483789,453.55991,-9.232729
3896,3896,195.6685,7.3788061,3.8747196,0.0,0,6.0035725,0.0,0.29885417,69.695358,6.0249634,453.65872,-9.2311983
3907,3907,195.6707,7.3789849,3.9019089,0.0,0,5.9785056,0.0,0.30123454,69.512169,5.9979239,453.75754,-9.2329741
3918,3918,195.6729,7.3807163,3.9265862,0.0,0,5.9534388,0.0,0.30342525,69.32402,5.9714518,453.77069,-9.2327375
3929,3929,195.6751,7.3763614,3.9552238,0.0,0,5.9283714,0.0,0.30611822,69.220741,5.9478593,453.72458,-9.2325344
3940,3940,195.6773,7.4135551,3.9755001,0.0,0,5.9033051,0.0,0.30781305,69.339203,5.9188728,453.67847,-9.2311659
3951,3951,195.6795,7.401372,3.9996507,0.0,0,5.8782382,0.0,0.31014788,69.051994,5.8978028,453.63235,-9.2321062
3962,3962,195.6817,7.4294348,4.0233183,0.0,0,5.8531713,0.0,0.31205735,69.34465,5.8762021,453.59119,-9.232851
3973,3973,195.6839,7.4805083,4.0489116,0.0,0,5.8281045,0.0,0.31477866,69.526413,5.8504844,453.65359,-9.2339163
3984,3984,195.6861,7.4937673,4.0761824,0.0,0,5.8030376,0.0,0.31668794,69.499435,5.8236737,453.716,-9.2325058
3995,3995,195.6883,7.5227399,4.0974054,0.0,0,5.7779708,0.0,0.31926912,69.649323,5.7959852,453.77841,-9.232728
4006,4006,195.6905,7.5249643,4.1259546,0.0,0,5.7529044,0.0,0.32136777,69.485634,5.7722111,453.84079,-9.2331066
4017,4017,195.6927,7.519875,4.1493568,0.0,0,5.7278376,0.0,0.32416156,69.260841,5.7487292,453.94406,-9.2325478
4028,4028,195.6949,7.5563836,4.1789465,0.0,0,5.7027707,0.0,0.32613212,69.341339,5.721776,454.06262,-9.2331705
4039,4039,195.6971,7.5957241,4.1994009,0.0,0,5.6777039,0.0,0.32878807,69.550499,5.6942892,454.18121,-9.2331543
4050,4050,195.6993,7.603591,4.2270737,0.0,0,5.652637,0.0,0.33069319,69.589775,5.6705894,454.29977,-9.2323761
4061,4061,195.7015,7.6253438,4.24896,0.0,0,5.6275702,0.0,0.33346251,69.612053,5.6461353,454.41116,-9.2318649
4072,4072,195.7037,7.6407485,4.2831321,0.0,0,5.6025033,0.0,0.335619,69.558922,5.6161604,454.4902,-9.2321939
4083,4083,195.7059,7.632494,4.2994089,0.0,0,5.5782466,0.0,0.33812234,69.286072,5.5936041,454.56927,-9.2335806
4094,4094,195.7081,7.6206498,4.3264065,0.0,0,5.554399,0.0,0.33998859,69.114601,5.5712051,454.64832,-9.2342443
4105,4105,195.7103,7.6094966,4.3464565,0.0,0,5.530551,0.0,0.34250966,68.784645,5.5449991,454.72736,-9.2328453
4116,4116,195.7125,7.6350236,4.3779702,0.0,0,5.5067029,0.0,0.34473419,68.825424,5.5224614,454.78964,-9.2332058
4127,4127,195.7147,7.6649289,4.393662,0.0,0,5.4828548,0.0,0.34682882,69.011314,5.4988527,454.84235,-9.2341795
4138,4138,195.7169,7.7117596,4.421402,0.0,0,5.4590068,0.0,0.34904784,69.287689,5.4715328,454.89502,-9.2342348
4149,4149,195.7191,7.7231865,4.4409046,0.0,0,5.4351592,0.0,0.35130033,69.189369,5.4499183,454.94772,-9.2337694
4160,4160,195.7213,7.7378473,4.4737625,0.0,0,5.4113111,0.0,0.3537496,69.15757,5.4225936,454.98785,-9.2327232
4171,4171,195.7235,7.7555861,4.4919686,0.0,0,5.3874626,0.0,0.35599592,69.157837,5.3997808,454.90222,-9.2328329
4182,4182,195.7257,7.7477593,4.517303,0.0,0,5.3636146,0.0,0.35821003,68.933044,5.3772521,454.81659,-9.233016
4193,4193,195.7279,7.7292309,4.5368633,0.0,0,5.339767,0.0,0.36020964,68.66571,5.3528838,454.73096,-9.233161
4204,4204,195.7301,7.7244029,4.566103,0.0,0,5.3159189,0.0,0.3630811,68.338638,5.3257194,454.64529,-9.2335539
4215,4215,195.7323,7.7509108,4.5853429,0.0,0,5.2920713,0.0,0.36466381,68.506317,5.3070569,454.57764,-9.2336569
4226,4226,195.7345,7.8109703,4.6068301,0.0,0,5.2682228,0.0,0.36693433,68.887367,5.2837706,454.52493,-9.2323656
4237,4237,195.7367,7.8645954,4.6300049,0.0,0,5.2443748,0.0,0.36886957,69.22007,5.25915,454.47226,-9.2330723
4248,4248,195.7389,7.9075313,4.6563535,0.0,0,5.2205272,0.0,0.37195504,69.389656,5.2365866,454.41956,-9.2329159
4259,4259,195.7411,7.8983889,4.6815095,0.0,0,5.1966791,0.0,0.37374493,69.232079,5.2115283,454.36685,-9.232481
4270,4270,195.7433,7.9200907,4.7045531,0.0,0,5.1728311,0.0,0.37649122,69.228287,5.188982,454.42615,-9.232873
4281,4281,195.7455,7.9368916,4.7299519,0.0,0,5.148983,0.0,0.37840101,69.274521,5.1627154,454.48544,-9.2322159
4292,4292,195.7477,7.9254127,4.7539425,0.0,0,5.1251349,0.0,0.38147208,68.925087,5.1355734,454.54474,-9.2325878
4303,4303,195.7499,7.9385018,4.7806253,0.0,0,5.1012869,0.0,0.38322526,68.885971,5.1172385,454.604,-9.2317028
4314,4314,195.7521,7.9370451,4.7977476,0.0,0,5.0774393,0.0,0.38580883,68.673164,5.0926266,454.66629,-9.2329082
4325,4325,195.7543,8.0069418,4.823915,0.0,0,5.0535913,0.0,0.38764071,69.152908,5.0640364,454.73218,-9.2331228
4336,4336,195.7565,8.0892801,4.8477755,0.0,0,5.0308361,0.0,0.39088273,69.700714,5.042573,454.79803,-9.2342482
4347,4347,195.7587,8.0738964,4.8819628,0.0,0,5.0081544,0.0,0.39306289,69.441208,5.0156078,454.86389,-9.2324896
4358,4358,195.7609,8.0473738,4.8961625,0.0,0,4.9854722,0.0,0.39560521,69.016296,4.991344,454.92978,-9.2319384
4369,4369,195.7631,8.0199385,4.9222059,0.0,0,4.96279,0.0,0.3974309,68.639458,4.9715548,455.04355,-9.2318058
4380,4380,195.7653,8.0326767,4.9404993,0.0,0,4.9401083,0.0,0.39988109,68.574707,4.9487519,455.16214,-9.2315369
4391,4391,195.7675,8.0277939,4.969367,0.0,0,4.9174266,0.0,0.4018915,68.427643,4.9267144,455.2807,-9.2328463
4402,4402,195.7697,8.0522308,4.9830637,0.0,0,4.8947439,0.0,0.40416387,68.460098,4.9054179,455.39929,-9.2336435
4413,4413,195.7719,8.0790701,5.0098104,0.0,0,4.8720622,0.0,0.40620279,68.517914,4.8833442,455.51065,-9.233242
4424,4424,195.7741,8.0876904,5.0279827,0.0,0,4.84938,0.0,0.40842795,68.420288,4.8611364,455.60947,-9.2339096
4435,4435,195.7763,8.137167,5.0568891,0.0,0,4.8266983,0.0,0.41085866,68.726395,4.8400273,455.70828,-9.2336884
4446,4446,195.7785,8.1610956,5.0751786,0.0,0,4.8040166,0.0,0.41305143,68.730064,4.8156486,455.8071,-9.2330122
4457,4457,195.7807,8.1906118,5.09863,0.0,0,4.7813339,0.0,0.41528171,68.793861,4.794713,455.90588,-9.2328186
4468,4468,195.7829,8.2068672,5.1180954,0.0,0,4.7586522,0.0,0.41735971,68.914589,4.7682924,455.94543,-9.2315426
4479,4479,195.7851,8.2425194,5.1510439,0.0,0,4.73597,0.0,0.42064282,68.839645,4.7454681,455.97177,-9.233119
4490,4490,195.7873,8.2552252,5.1707397,0.0,0,4.7132883,0.0,0.42258716,68.823822,4.7246928,455.99814,-9.2330036
4501,4501,195.7895,8.2674742,5.1930761,0.0,0,4.6906061,0.0,0.42492554,68.801758,4.6978121,456.02448,-9.2320347
4512,4512,195.7917,8.3047333,5.214036,0.0,0,4.6679239,0.0,0.42693302,69.019691,4.6749196,456.05441,-9.2323799
4523,4523,195.7939,8.3472328,5.2393937,0.0,0,4.6452422,0.0,0.42984831,69.095886,4.6522179,456.09393,-9.2327127
4534,4534,195.7961,8.3567123,5.2634044,0.0,0,4.6225605,0.0,0.43172351,69.05529,4.6334634,456.13345,-9.2323818
4545,4545,195.7983,8.342371,5.2844877,0.0,0,4.5998783,0.0,0.43458718,68.857513,4.6069217,456.17297,-9.2327652
4556,4556,195.8005,8.3332605,5.3073854,0.0,0,4.5771961,0.0,0.43638018,68.641006,4.5843596,456.21249,-9.2315931
4567,4567,195.8027,8.3470507,5.330987,0.0,0,4.5545144,0.0,0.43941933,68.466026,4.5619755,456.27118,-9.232872
4578,4578,195.8049,8.3824291,5.3550076,0.0,0,4.532064,0.0,0.44105089,68.703766,4.5415335,456.33707,-9.2328272
4589,4589,195.8071,8.394412,5.3722906,0.0,0,4.5104866,0.0,0.443773,68.512581,4.5158162,456.40292,-9.2330933
4600,4600,195.8093,8.4125748,5.3961725,0.0,0,4.4889088,0.0,0.44540283,68.551903,4.4965081,456.46881,-9.2328224
4611,4611,195.8115,8.4417286,5.414124,0.0,0,4.4673309,0.0,0.44830987,68.633553,4.4713244,456.23877,-9.2326288
4622,4622,195.8137,8.463233,5.4442272,0.0,0,4.4457536,0.0,0.45019674,68.684929,4.4513817,454.6774,-9.2321043
4633,4633,195.8159,8.4901943,5.4582891,0.0,0,4.4241762,0.0,0.45290288,68.727943,4.4309368,453.116,-9.2323542
4644,4644,195.8181,8.4617691,5.4859796,0.0,0,4.4025984,0.0,0.45483163,68.401176,4.4080296,451.5546,-9.2335835
4655,4655,195.8203,8.4568596,5.5020967,0.0,0,4.381021,0.0,0.45749024,68.153389,4.384016,449.99323,-9.2337885
4666,4666,195.8225,8.4651747,5.5293384,0.0,0,4.3594432,0.0,0.45921633,68.126884,4.3655624,448.39407,-9.2332563
4677,4677,195.8247,8.5039177,5.5434051,0.0,0,4.3378654,0.0,0.46164912,68.271141,4.3415895,446.77335,-9.2316046
4688,4688,195.8269,8.5419292,5.5683012,0.0,0,4.316288,0.0,0.46357417,68.301552,4.3227944,445.15262,-9.2335339
4699,4699,195.8291,8.5747166,5.584321,0.0,0,4.2947102,0.0,0.46594286,68.517433,4.3023462,443.53189,-9.2331371
4710,4710,195.8313,8.6023693,5.6147733,0.0,0,4.2731328,0.0,0.4685533,68.617935,4.2789016,442.10947,-9.2337093
4721,4721,195.8335,8.627985,5.6294332,0.0,0,4.2515554,0.0,0.47075009,68.642235,4.2589579,442.66959,-9.2332554
4732,4732,195.8357,8.6337032,5.6535044,0.0,0,4.2299776,0.0,0.47293702,68.577072,4.2341442,443.22971,-9.2329168
4743,4743,195.8379,8.6374598,5.6715569,0.0,0,4.2084002,0.0,0.47497648,68.457863,4.2127757,443.78983,-9.2327147
4754,4754,195.8401,8.6472845,5.6983676,0.0,0,4.1868224,0.0,0.47769219,68.331017,4.1947637,444.34998,-9.233882
4765,4765,195.8423,8.6918859,5.7168798,0.0,0,4.1652451,0.0,0.47975355,68.472305,4.1730609,445.05023,-9.2332029
4776,4776,195.8445,8.7544231,5.7414403,0.0,0,4.1436672,0.0,0.48259157,68.716339,4.1514173,445.86731,-9.2330284
4787,4787,195.8467,8.8159065,5.7612,0.0,0,4.1220899,0.0,0.48440635,69.133621,4.1264744,446.68436,-9.2312078
4798,4798,195.8489,8.8435001,5.7872558,0.0,0,4.100512,0.0,0.48765343,69.196289,4.1025391,447.50143,-9.232975
4809,4809,195.8511,8.8412533,5.8104634,0.0,0,4.0789347,0.0,0.48955926,68.977638,4.0800228,448.31845,-9.2330418
4820,4820,195.8533,8.8214645,5.828546,0.0,0,4.0573568,0.0,0.49226615,68.662613,4.0623446,447.53403,-9.2332096
4831,4831,195.8555,8.8316956,5.8488035,0.0,0,4.0362892,0.0,0.49382746,68.641029,4.0414429,446.7496,-9.2326107
4842,4842,195.8577,8.8488007,5.8709302,0.0,0,4.0157681,0.0,0.4970074,68.543259,4.0160804,445.96515,-9.2334862
4853,4853,195.8599,8.8822908,5.8954921,0.0,0,3.9952462,0.0,0.49874777,68.651871,3.996974,445.18073,-9.2332888
4864,4864,195.8621,8.904089,5.912818,0.0,0,3.9747248,0.0,0.50165373,68.633614,3.9746065,444.2735,-9.2319422
4875,4875,195.8643,8.9321346,5.9381309,0.0,0,3.9542031,0.0,0.50341266,68.757393,3.954169,443.2189,-9.2318211
4886,4886,195.8665,8.9360247,5.9542756,0.0,0,3.9336815,0.0,0.50625074,68.583717,3.9333131,442.16434,-9.2314491
4897,4897,195.8687,8.937355,5.9804468,0.0,0,3.9131598,0.0,0.50793087,68.496704,3.9133277,441.10974,-9.2320499
4908,4908,195.8709,8.9637451,5.9947186,0.0,0,3.8926382,0.0,0.51070774,68.489906,3.8931348,440.05518,-9.2318306
4919,4919,195.8731,8.943387,6.0202193,0.0,0,3.8721166,0.0,0.5126161,68.270279,3.8780191,440.30716,-9.231925
4930,4930,195.8753,8.9701681,6.0345383,0.0,0,3.8515949,0.0,0.51522106,68.206215,3.8562722,440.68976,-9.2329807
4941,4941,195.8775,9.0000391,6.0626302,0.0,0,3.8310735,0.0,0.51713264,68.298737,3.8361919,441.07239,-9.2330923
4952,4952,195.8797,9.0415316,6.0762148,0.0,0,3.8105519,0.0,0.51966697,68.439735,3.8142323,441.45499,-9.2325506
4963,4963,195.8819,9.0852385,6.10116,0.0,0,3.79003,0.0,0.5216549,68.641647,3.794467,441.96219,-9.2323313
4974,4974,195.8841,9.1186829,6.1157632,0.0,0,3.7695086,0.0,0.52414882,68.67189,3.772465,442.68741,-9.2315235
4985,4985,195.8863,9.1201038,6.1444659,0.0,0,3.748987,0.0,0.52658081,68.532417,3.7494428,443.4126,-9.2316427
4996,4996,195.8885,9.161253,6.1574221,0.0,0,3.7284656,0.0,0.52865791,68.753464,3.7313638,444.13782,-9.2326021
5007,5007,195.8907,9.2164135,6.1833024,0.0,0,3.7079437,0.0,0.53112495,69.004425,3.7119913,444.86304,-9.2322178
5018,5018,195.8929,9.2337389,6.2001686,0.0,0,3.687422,0.0,0.5334239,68.966904,3.685308,445.4584,-9.2317276
5029,5029,195.8951,9.2390976,6.2280855,0.0,0,3.6669006,0.0,0.53624964,68.850044,3.6694601,446.0249,-9.2319403
5040,5040,195.8973,9.2223043,6.2444148,0.0,0,3.646379,0.0,0.53820658,68.575142,3.65114,446.5914,-9.233593
5051,5051,195.8995,9.2515793,6.2648082,0.0,0,3.6258574,0.0,0.5406732,68.544037,3.6270137,447.15793,-9.2339239
5062,5062,195.9017,9.2816401,6.2828622,0.0,0,3.6053357,0.0,0.54255968,68.670418,3.6062794,447.68491,-9.2328091
5073,5073,195.9039,9.328618,6.3075781,0.0,0,3.5848141,0.0,0.54578936,68.772339,3.5846181,448.10648,-9.2321634
5084,5084,195.9061,9.3483219,6.3263669,0.0,0,3.5650475,0.0,0.54742104,68.835419,3.5669146,448.52808,-9.2320652
5095,5095,195.9083,9.3810015,6.3431005,0.0,0,3.5455248,0.0,0.54998267,68.915123,3.544462,448.94965,-9.2334747
5106,5106,195.9105,9.3805342,6.3640223,0.0,0,3.5260017,0.0,0.55164403,68.866417,3.5264938,449.37125,-9.2321091
5117,5117,195.9127,9.4063807,6.3859487,0.0,0,3.506479,0.0,0.55509979,68.77916,3.5075274,449.66827,-9.2320786
5128,5128,195.9149,9.4095135,6.4102311,0.0,0,3.4869561,0.0,0.55683666,68.674225,3.4853294,449.91858,-9.23139
5139,5139,195.9171,9.4204035,6.4231434,0.0,0,3.4674332,0.0,0.55947238,68.472321,3.4688289,450.16891,-9.2317219
5150,5150,195.9193,9.4754457,6.4448419,0.0,0,3.4479108,0.0,0.56093454,68.751717,3.4478457,450.41922,-9.2334423
5161,5161,195.9215,9.526186,6.4607368,0.0,0,3.4283876,0.0,0.56397867,69.021011,3.4307795,450.64917,-9.2332497
5172,5172,195.9237,9.5802488,6.4889464,0.0,0,3.408865,0.0,0.56599259,69.300659,3.4105241,450.78751,-9.2331276
5183,5183,195.9259,9.5802145,6.5025811,0.0,0,3.3893423,0.0,0.56884724,69.053581,3.3862121,450.92587,-9.2325163
5194,5194,195.9281,9.5843687,6.5266304,0.0,0,3.3698192,0.0,0.57059264,68.965302,3.3689086,451.06421,-9.2327576
5205,5205,195.9303,9.571249,6.5417509,0.0,0,3.3502967,0.0,0.57351643,68.73999,3.3527641,451.20255,-9.2329473
5216,5216,195.9325,9.5880356,6.5686255,0.0,0,3.3307738,0.0,0.57530528,68.712929,3.3323073,451.3241,-9.2331266
5227,5227,195.9347,9.6214123,6.5782022,0.0,0,3.3112507,0.0,0.57753038,68.734581,3.3083501,451.4361,-9.2333612
5238,5238,195.9369,9.6742725,6.6025105,0.0,0,3.2917283,0.0,0.57974404,68.972153,3.2882631,451.54807,-9.2326517
5249,5249,195.9391,9.7333469,6.6173296,0.0,0,3.2722051,0.0,0.58233619,69.203842,3.2684863,451.66003,-9.2312775
5260,5260,195.9413,9.8065882,6.6481762,0.0,0,3.2526824,0.0,0.58497983,69.592873,3.2495735,451.78162,-9.2311287
5271,5271,195.9435,9.8587742,6.6618848,0.0,0,3.2331598,0.0,0.58749026,69.752594,3.2293167,451.99899,-9.2322111
5282,5282,195.9457,9.8392181,6.6854424,0.0,0,3.2136366,0.0,0.58987683,69.406525,3.209306,452.21637,-9.2322063
5293,5293,195.9479,9.8131847,6.6997962,0.0,0,3.1941142,0.0,0.59186172,69.114441,3.1902163,452.43375,-9.2313328
5304,5304,195.9501,9.7935066,6.7266641,0.0,0,3.1745913,0.0,0.59476542,68.7892,3.1714849,452.65112,-9.2322531
5315,5315,195.9523,9.7933559,6.7401013,0.0,0,3.1550684,0.0,0.5966357,68.656769,3.1520307,452.84335,-9.2334223
5326,5326,195.9545,9.8043509,6.7582788,0.0,0,3.135581,0.0,0.59881258,68.552895,3.1347618,453.01465,-9.2327785
5337,5337,195.9567,9.8678408,6.7750182,0.0,0,3.1170001,0.0,0.60065049,68.873405,3.117214,453.18591,-9.2316313
5348,5348,195.9589,9.9366388,6.7970033,0.0,0,3.0984275,0.0,0.60371375,69.127586,3.0967605,453.35718,-9.2320232
5359,5359,195.9611,9.9870052,6.8137226,0.0,0,3.0798554,0.0,0.605281,69.413727,3.0773847,453.52844,-9.2318697
5370,5370,195.9633,10.009733,6.8303452,0.0,0,3.0612829,0.0,0.60788101,69.403496,3.0606425,453.06073,-9.2312098
5381,5381,195.9655,10.011492,6.8485451,0.0,0,3.0427105,0.0,0.60942209,69.305954,3.0412743,452.59302,-9.2327995
5392,5392,195.9677,10.027782,6.8723001,0.0,0,3.0241382,0.0,0.61325884,69.168037,3.0176044,452.12534,-9.2327824
5403,5403,195.9699,10.052723,6.8934865,0.0,0,3.0055656,0.0,0.61480987,69.25473,3.0023143,451.65762,-9.2323542
5414,5414,195.9721,10.077695,6.9067187,0.0,0,2.9869936,0.0,0.61739981,69.207794,2.9846818,451.12704,-9.2325754
5425,5425,195.9743,10.11155,6.9264235,0.0,0,2.968421,0.0,0.61879808,69.360825,2.9661522,450.521,-9.2324266
5436,5436,195.9765,10.163968,6.9440579,0.0,0,2.9498487,0.0,0.62221277,69.385498,2.9464021,449.91498,-9.23279
5447,5447,195.9787,10.225983,6.9692416,0.0,0,2.9312761,0.0,0.62401944,69.740257,2.9306886,449.30893,-9.2318621
5458,5458,195.9809,10.251194,6.9816351,0.0,0,2.9127038,0.0,0.62697262,69.714134,2.9071054,448.70291,-9.2321463
5469,5469,195.9831,10.24129,7.0044036,0.0,0,2.8941314,0.0,0.62849241,69.598267,2.8908355,448.68976,-9.2314825
5480,5480,195.9853,10.257142,7.0159941,0.0,0,2.8755589,0.0,0.63123995,69.491081,2.8740351,448.73587,-9.2322302
5491,5491,195.9875,10.264847,7.0431857,0.0,0,2.8569863,0.0,0.63318962,69.378128,2.8566151,448.78198,-9.23176
5502,5502,195.9897,10.278119,7.0535212,0.0,0,2.8384142,0.0,0.63590127,69.329552,2.8389471,448.82809,-9.2310762
5513,5513,195.9919,10.320295,7.0774288,0.0,0,2.8198419,0.0,0.6379267,69.373825,2.8196447,448.93167,-9.231534
5524,5524,195.9941,10.365239,7.0904603,0.0,0,2.8012693,0.0,0.64046985,69.538857,2.8017166,449.13589,-9.2319641
5535,5535,195.9963,10.424366,7.1162229,0.0,0,2.782697,0.0,0.64257646,69.733528,2.7848949,449.34009,-9.2316284
5546,5546,195.9985,10.45592,7.1254349,0.0,0,2.7641246,0.0,0.64474177,69.867523,2.7685688,449.54431,-9.2334175
5557,5557,196.0007,10.493755,7.1476402,0.0,0,2.7455523,0.0,0.64691257,69.955574,2.7485721,449.74854,-9.2323179
5568,5568,196.0029,10.547666,7.1623755,0.0,0,2.7269795,0.0,0.6493789,70.094101,2.7297692,449.88266,-9.2313051
5579,5579,196.0051,10.598902,7.192153,0.0,0,2.7086806,0.0,0.65266007,70.327454,2.7114079,450.00122,-9.2320709
5590,5590,196.0073,10.649716,7.2060208,0.0,0,2.6910145,0.0,0.65475035,70.498016,2.6875701,450.11981,-9.2321301
5601,5601,196.0095,10.674482,7.2257123,0.0,0,2.6733484,0.0,0.6571784,70.449097,2.6718161,450.23837,-9.2316561
5612,5612,196.0117,10.70477,7.2411995,0.0,0,2.6556826,0.0,0.65907538,70.48613,2.6505258,450.37851,-9.2325287
5623,5623,196.0139,10.712388,7.2672801,0.0,0,2.6380165,0.0,0.6627717,70.317986,2.6336775,450.57614,-9.231679
5634,5634,196.0161,10.727743,7.2824116,0.0,0,2.6203504,0.0,0.6642682,70.232178,2.6123857,450.77377,-9.2328329
5645,5645,196.0183,10.714421,7.2989674,0.0,0,2.6026845,0.0,0.66692954,70.038025,2.5957501,450.97137,-9.2326555
5656,5656,196.0205,10.729795,7.3158345,0.0,0,2.5850186,0.0,0.66848832,70.052246,2.5798531,451.16901,-9.2326727
5667,5667,196.0227,10.739198,7.3340292,0.0,0,2.5673525,0.0,0.67156696,69.889336,2.5632155,451.29477,-9.2326698
5678,5678,196.0249,10.777429,7.3509502,0.0,0,2.5496864,0.0,0.67288697,70.044029,2.5451274,451.39359,-9.2321358
5689,5689,196.0271,10.80283,7.3649879,0.0,0,2.5320206,0.0,0.6757654,69.964256,2.5261135,451.49237,-9.2320099
5700,5700,196.0293,10.80789,7.3841805,0.0,0,2.5143545,0.0,0.67729205,69.901901,2.5117269,451.59119,-9.2309332
5711,5711,196.0315,10.838322,7.401597,0.0,0,2.4966886,0.0,0.68071634,69.869995,2.4951808,451.66724,-9.2324886
5722,5722,196.0337,10.898059,7.420897,0.0,0,2.4790225,0.0,0.68186486,70.135826,2.4759762,451.64087,-9.2329359
5733,5733,196.0359,11.010773,7.4316883,0.0,0,2.4613564,0.0,0.68463415,70.682365,2.4617279,451.61453,-9.2326498
5744,5744,196.0381,11.069146,7.4554133,0.0,0,2.4436905,0.0,0.68664348,70.940826,2.4433119,451.58817,-9.2317524
5755,5755,196.0403,11.091721,7.4700947,0.0,0,2.4260244,0.0,0.68985152,70.849617,2.4235806,451.56183,-9.2326689
5766,5766,196.0425,11.079469,7.4956446,0.0,0,2.4083586,0.0,0.69168526,70.660057,2.407588,451.49774,-9.2329922
5777,5777,196.0447,11.11527,7.503912,0.0,0,2.3906925,0.0,0.69427019,70.714577,2.3901248,451.41211,-9.232049
5788,5788,196.0469,11.169363,7.528429,0.0,0,2.3730264,0.0,0.69639534,70.873833,2.3702867,451.32651,-9.2320824
5799,5799,196.0491,11.223613,7.5410852,0.0,0,2.3553605,0.0,0.6992873,71.002266,2.3533955,451.24088,-9.2334566
5810,5810,196.0513,11.273058,7.5666409,0.0,0,2.3376946,0.0,0.70146269,71.110962,2.3348618,451.11151,-9.2330322
5821,5821,196.0535,11.330581,7.5775657,0.0,0,2.3200283,0.0,0.70386922,71.334908,2.3155682,450.54498,-9.2334805
5832,5832,196.0557,11.375534,7.600595,0.0,0,2.3028572,0.0,0.70629734,71.439201,2.3020489,449.97849,-9.2331505
5843,5843,196.0579,11.417224,7.6147738,0.0,0,2.2860537,0.0,0.70879269,71.551567,2.2799761,449.41196,-9.2328053
5854,5854,196.0601,11.399899,7.6395035,0.0,0,2.2692499,0.0,0.71148336,71.241516,2.2626886,448.84546,-9.2321682
5865,5865,196.0623,11.41967,7.6502662,0.0,0,2.2524464,0.0,0.71343893,71.246376,2.2466187,448.2933,-9.2328186
5876,5876,196.0645,11.429253,7.6695619,0.0,0,2.2356429,0.0,0.71598572,71.124634,2.2261946,447.75314,-9.2342157
5887,5887,196.0667,11.438462,7.6833038,0.0,0,2.2188394,0.0,0.71780705,71.010971,2.2109914,447.21298,-9.2339811
5898,5898,196.0689,11.470173,7.7053261,0.0,0,2.2020357,0.0,0.7208941,71.009193,2.1954019,446.67282,-9.2328224
5909,5909,196.0711,11.513564,7.7177076,0.0,0,2.1852322,0.0,0.72228807,71.162491,2.1783085,446.13269,-9.2310057
5920,5920,196.0733,11.551164,7.733819,0.0,0,2.1684284,0.0,0.72507787,71.197289,2.1601353,446.11951,-9.2325687
5931,5931,196.0755,11.598616,7.7506719,0.0,0,2.1516249,0.0,0.72685599,71.434387,2.1460712,446.10632,-9.2324286
5942,5942,196.0777,11.618541,7.7696958,0.0,0,2.1348212,0.0,0.73016387,71.286369,2.1316695,446.09314,-9.231719
5953,5953,196.0799,11.646067,7.78584,0.0,0,2.1180177,0.0,0.73133129,71.396294,2.1168327,446.07999,-9.2330551
5964,5964,196.0821,11.702737,7.7985334,0.0,0,2.1012139,0.0,0.73424208,71.530731,2.0965333,446.18356,-9.2324171
5975,5975,196.0843,11.776802,7.8164568,0.0,0,2.0844107,0.0,0.73565418,71.859055,2.0788906,446.42731,-9.2314186
5986,5986,196.0865,11.836756,7.8323646,0.0,0,2.0676069,0.0,0.73932517,71.92926,2.0643194,446.67105,-9.2326031
5997,5997,196.0887,11.909573,7.8573127,0.0,0,2.0508034,0.0,0.74109799,72.231651,2.0445607,446.91476,-9.2336969
6008,6008,196.0909,11.941067,7.865798,0.0,0,2.0339997,0.0,0.74387491,72.233498,2.0262752,447.15851,-9.2326145
6019,6019,196.0931,11.964385,7.8869057,0.0,0,2.0171962,0.0,0.74543518,72.255882,2.0052116,447.56393,-9.2304354
6030,6030,196.0953,12.004039,7.8997912,0.0,0,2.0003924,0.0,0.74867308,72.397072,1.9939709,447.98553,-9.2313251
6041,6041,196.0975,12.040409,7.926909,0.0,0,1.9835889,0.0,0.7506879,72.359329,1.9764415,448.4071,-9.2318811
6052,6052,196.0997,12.025874,7.9338183,0.0,0,1.9667853,0.0,0.7534591,72.11927,1.9619007,448.8287,-9.2325802
6063,6063,196.1019,12.054418,7.9536276,0.0,0,1.9499818,0.0,0.75501835,72.111389,1.9469534,449.16644,-9.2324772
6074,6074,196.1041,12.096918,7.9648013,0.0,0,1.9331782,0.0,0.7580148,72.133354,1.9287746,449.35748,-9.2317257
6085,6085,196.1063,12.151298,7.9918656,0.0,0,1.9170674,0.0,0.76026875,72.337555,1.9112356,449.54852,-9.2312307
6096,6096,196.1085,12.20866,8.000124,0.0,0,1.9010822,0.0,0.76267862,72.487267,1.8940029,449.73956,-9.2320385
6107,6107,196.1107,12.275961,8.0212746,0.0,0,1.8850969,0.0,0.76471663,72.687904,1.8782331,449.9306,-9.2326164
6118,6118,196.1129,12.310113,8.032032,0.0,0,1.8691118,0.0,0.76701862,72.775536,1.8622895,448.7139,-9.2324858
6129,6129,196.1151,12.341262,8.0562935,0.0,0,1.8531265,0.0,0.76967663,72.763382,1.8427509,447.18442,-9.2323551
6140,6140,196.1173,12.342481,8.0653963,0.0,0,1.8371414,0.0,0.77174258,72.638474,1.8255422,445.65494,-9.2326784
6151,6151,196.1195,12.328203,8.0838118,0.0,0,1.8211561,0.0,0.77411658,72.390038,1.8168993,444.12546,-9.2332211
6162,6162,196.1217,12.353323,8.095562,0.0,0,1.805171,0.0,0.77584499,72.403618,1.8004433,442.70932,-9.2335157
6173,6173,196.1239,12.432041,8.1176844,0.0,0,1.7891858,0.0,0.77907085,72.58033,1.7831415,441.59543,-9.2337646
6184,6184,196.1261,12.483387,8.1299572,0.0,0,1.7732006,0.0,0.78064686,72.804779,1.7692147,440.48157,-9.2323484
6195,6195,196.1283,12.540246,8.1455412,0.0,0,1.7572154,0.0,0.78332138,72.960716,1.7491132,439.36768,-9.2319441
6206,6206,196.1305,12.607709,8.1595659,0.0,0,1.7412302,0.0,0.78476727,73.194572,1.7342261,438.25381,-9.2321625
6217,6217,196.1327,12.601219,8.1783752,0.0,0,1.725245,0.0,0.78845799,72.933998,1.7221662,438.18997,-9.2325611
6228,6228,196.1349,12.644424,8.1934099,0.0,0,1.7092597,0.0,0.7895655,73.145576,1.7057991,438.51984,-9.2322874
6239,6239,196.1371,12.73065,8.2048655,0.0,0,1.6932746,0.0,0.79226714,73.425751,1.6913941,438.84973,-9.2322083
6250,6250,196.1393,12.7897,8.22404,0.0,0,1.6772894,0.0,0.79398334,73.591255,1.6722554,439.1796,-9.231204
6261,6261,196.1415,12.847429,8.2390652,0.0,0,1.6613041,0.0,0.79763049,73.705818,1.6575229,439.51068,-9.2306376
6272,6272,196.1437,12.897927,8.2609301,0.0,0,1.645319,0.0,0.79932266,73.77021,1.6427398,439.84717,-9.2320232
6283,6283,196.1459,12.959698,8.2699585,0.0,0,1.6293337,0.0,0.8022719,73.963295,1.6288216,440.18362,-9.2326326
6294,6294,196.1481,13.090396,8.2944689,0.0,0,1.6133486,0.0,0.80420685,74.505791,1.6108826,440.52011,-9.2330894
6305,6305,196.1503,13.16646,8.3046913,0.0,0,1.5973635,0.0,0.8074525,74.785034,1.5930431,440.8566,-9.2324352
6316,6316,196.1525,13.184896,8.3302135,0.0,0,1.5813781,0.0,0.80917567,74.761597,1.5730349,441.37766,-9.2322836
6327,6327,196.1547,13.182744,8.3386087,0.0,0,1.5654862,0.0,0.8124584,74.526009,1.5564816,442.00415,-9.2322388
6338,6338,196.1569,13.213223,8.3588991,0.0,0,1.5502795,0.0,0.81414974,74.524033,1.5424958,442.63065,-9.2318287
6349,6349,196.1591,13.250439,8.369894,0.0,0,1.5350732,0.0,0.8172462,74.487976,1.5258446,443.25714,-9.232337
6360,6360,196.1613,13.308823,8.3959894,0.0,0,1.5198667,0.0,0.81951731,74.687103,1.5069433,443.86264,-9.2310085
6371,6371,196.1635,13.373472,8.4028091,0.0,0,1.5046602,0.0,0.82196259,74.844315,1.4928511,444.25797,-9.2319841
6382,6382,196.1657,13.399153,8.4238386,0.0,0,1.4894539,0.0,0.82405013,74.852219,1.4759338,444.65329,-9.2320471
6393,6393,196.1679,13.411404,8.4336901,0.0,0,1.4742475,0.0,0.82646102,74.66655,1.4655691,445.04865,-9.2312965
6404,6404,196.1701,13.433217,8.4577999,0.0,0,1.4590411,0.0,0.82912302,74.686287,1.4476388,445.44397,-9.2325287
6415,6415,196.1723,13.455402,8.463479,0.0,0,1.4438348,0.0,0.83093882,74.625389,1.4317697,445.69193,-9.2327862
6426,6426,196.1745,13.450163,8.48382,0.0,0,1.4286283,0.0,0.83360845,74.394798,1.416398,445.81708,-9.2325201
6437,6437,196.1767,13.463646,8.4913139,0.0,0,1.4134219,0.0,0.83497375,74.323448,1.4029355,445.94226,-9.2314043
6448,6448,196.1789,13.508527,8.5137634,0.0,0,1.3982155,0.0,0.83828026,74.368202,1.3920861,446.06741,-9.2320881
6459,6459,196.1811,13.590882,8.5244465,0.0,0,1.3830091,0.0,0.83985186,74.668907,1.3747604,446.19257,-9.2326488
6470,6470,196.1833,13.682201,8.5391865,0.0,0,1.3678027,0.0,0.84241641,75.026314,1.3568577,446.15305,-9.2306776
6481,6481,196.1855,13.754446,8.5509996,0.0,0,1.3525964,0.0,0.84360814,75.355133,1.342398,446.11353,-9.2327986
6492,6492,196.1877,13.806087,8.5693331,0.0,0,1.3373901,0.0,0.84734923,75.310555,1.329639,446.07401,-9.2332296
6503,6503,196.1899,13.84437,8.5839033,0.0,0,1.3221836,0.0,0.848656,75.397179,1.3164364,446.03445,-9.2314768
6514,6514,196.1921,13.893274,8.5960789,0.0,0,1.306977,0.0,0.8516264,75.49514,1.3038064,446.09674,-9.2318716
6525,6525,196.1943,13.93542,8.6117458,0.0,0,1.2917708,0.0,0.85283667,75.669098,1.2849469,446.28119,-9.2313843
6536,6536,196.1965,14.020178,8.6272306,0.0,0,1.2765644,0.0,0.85667384,75.784081,1.2681574,446.46567,-9.2317591
6547,6547,196.1987,14.092655,8.6466742,0.0,0,1.261358,0.0,0.85810268,76.067551,1.2528371,446.65012,-9.2305803
6558,6558,196.2009,14.193331,8.6551142,0.0,0,1.2461516,0.0,0.86125553,76.328156,1.2375755,446.83456,-9.2298193
6569,6569,196.2031,14.273063,8.674818,0.0,0,1.2309451,0.0,0.86268359,76.653488,1.2238232,447.06689,-9.2300558
6580,6580,196.2053,14.338345,8.6889887,0.0,0,1.2160302,0.0,0.86670929,76.731277,1.2067994,447.30405,-9.2311983
6591,6591,196.2075,14.394828,8.7111578,0.0,0,1.2015674,0.0,0.86812145,76.895935,1.1918359,447.5412,-9.2317333
6602,6602,196.2097,14.40893,8.7180567,0.0,0,1.1871046,0.0,0.8710137,76.82811,1.1750609,447.77832,-9.2333288
6613,6613,196.2119,14.398147,8.736701,0.0,0,1.1726419,0.0,0.87273651,76.628204,1.158648,447.96756,-9.2314262
6624,6624,196.2141,14.413626,8.7472887,0.0,0,1.158179,0.0,0.87595785,76.436981,1.1486816,448.07294,-9.2306204
6635,6635,196.2163,14.455728,8.7688141,0.0,0,1.1437161,0.0,0.87749511,76.518372,1.1332102,448.17834,-9.230176
6646,6646,196.2185,14.515732,8.7733746,0.0,0,1.1292534,0.0,0.87991977,76.65416,1.1189753,448.28375,-9.230958
6657,6657,196.2207,14.567365,8.7906637,0.0,0,1.1147907,0.0,0.88143277,76.802383,1.1053299,448.38913,-9.2307196
6668,6668,196.2229,14.619384,8.8013725,0.0,0,1.1003278,0.0,0.88439971,76.86425,1.0949907,448.52148,-9.2313709
6679,6679,196.2251,14.66188,8.8261433,0.0,0,1.0858649,0.0,0.88700229,76.840027,1.0775065,448.65982,-9.2310057
6690,6690,196.2273,14.707812,8.8328323,0.0,0,1.0714023,0.0,0.88906288,77.021042,1.0650994,448.79816,-9.2305775
6701,6701,196.2295,14.785599,8.8503752,0.0,0,1.0569394,0.0,0.89141315,77.22316,1.0471981,448.93646,-9.2302198
6712,6712,196.2317,14.857424,8.8576155,0.0,0,1.0424767,0.0,0.89299309,77.450958,1.0336404,449.09637,-9.2304192
6723,6723,196.2339,14.891782,8.8802414,0.0,0,1.0280137,0.0,0.89639312,77.377678,1.0215287,449.31375,-9.2311602
6734,6734,196.2361,14.955108,8.8920259,0.0,0,1.013551,0.0,0.8983075,77.557487,1.0068953,449.53116,-9.2312498
6745,6745,196.2383,15.028629,8.9054127,0.0,0,0.99908823,0.0,0.90074193,77.721153,0.98865134,449.74854,-9.2304449
6756,6756,196.2405,15.112411,8.9171762,0.0,0,0.98462534,0.0,0.90229172,78.037231,0.97957599,449.96591,-9.2312593
6767,6767,196.2427,15.187669,8.9350033,0.0,0,0.97016257,0.0,0.90595025,78.170471,0.96249324,450.11624,-9.2310343
6778,6778,196.2449,15.257064,8.9489641,0.0,0,0.9556998,0.0,0.90720832,78.45929,0.95024681,450.24139,-9.2300453
6789,6789,196.2471,15.292879,8.9628782,0.0,0,0.94123697,0.0,0.91050756,78.322571,0.93248326,450.36655,-9.2307701
6800,6800,196.2493,15.335523,8.9757423,0.0,0,0.9267742,0.0,0.9115479,78.465225,0.91727865,450.49173,-9.2306585
6811,6811,196.2515,15.389108,8.9888487,0.0,0,0.91231132,0.0,0.91523588,78.477249,0.90467519,450.59171,-9.2307825
6822,6822,196.2537,15.433777,9.0073299,0.0,0,0.89784861,0.0,0.91663301,78.577286,0.89079601,450.57855,-9.2317905
6833,6833,196.2559,15.537818,9.0156412,0.0,0,0.88385671,0.0,0.91980743,78.811577,0.87492013,450.56537,-9.2303391
6844,6844,196.2581,15.648563,9.0363264,0.0,0,0.87010235,0.0,0.92153519,79.273735,0.86508971,450.55219,-9.2308865
6855,6855,196.2603,15.75579,9.0476036,0.0,0,0.85634792,0.0,0.92521226,79.507736,0.84908485,450.539,-9.2305689
6866,6866,196.2625,15.812197,9.0669136,0.0,0,0.84259349,0.0,0.92624795,79.743866,0.8303799,450.5426,-9.2306442
6877,6877,196.2647,15.82312,9.0731487,0.0,0,0.82883912,0.0,0.92952442,79.550575,0.81549698,450.55579,-9.2298241
6888,6888,196.2669,15.819109,9.0893917,0.0,0,0.8150847,0.0,0.93053031,79.478745,0.79992592,450.56897,-9.2296057
6899,6899,196.2691,15.80864,9.0982456,0.0,0,0.80133033,0.0,0.93379402,79.12252,0.78905183,450.58212,-9.2312803
6910,6910,196.2713,15.798408,9.1235561,0.0,0,0.7875759,0.0,0.93581879,78.907867,0.77656448,450.58392,-9.2314777
6921,6921,196.2735,15.82365,9.126338,0.0,0,0.77382153,0.0,0.93830895,78.86161,0.76218849,450.47195,-9.2312412
6932,6932,196.2757,15.898944,9.1440582,0.0,0,0.76006716,0.0,0.93987578,79.043221,0.75119257,450.35995,-9.2313786
6943,6943,196.2779,15.977897,9.1469297,0.0,0,0.74631268,0.0,0.94189698,79.265701,0.74015206,450.24799,-9.2323942
6954,6954,196.2801,16.062984,9.1711187,0.0,0,0.73255831,0.0,0.94447076,79.509613,0.72512549,450.13599,-9.2312727
6965,6965,196.2823,16.171246,9.1750364,0.0,0,0.71880394,0.0,0.9463957,79.890846,0.71360588,450.07791,-9.2306013
6976,6976,196.2845,16.291389,9.1941376,0.0,0,0.70504951,0.0,0.94883692,80.361198,0.70146036,450.06473,-9.2305231
6987,6987,196.2867,16.39835,9.2038803,0.0,0,0.69129509,0.0,0.95104325,80.655983,0.6851269,450.05154,-9.2303972
6998,6998,196.2889,16.470541,9.2235241,0.0,0,0.67754072,0.0,0.95400405,80.771889,0.6674059,450.03839,-9.2307234
7009,7009,196.2911,16.5096,9.2331781,0.0,0,0.66378635,0.0,0.95597178,80.808136,0.65631205,450.02521,-9.230917
7020,7020,196.2933,16.550648,9.2489195,0.0,0,0.65003192,0.0,0.95888865,80.757095,0.64327049,450.17673,-9.2309227
7031,7031,196.2955,16.614651,9.260088,0.0,0,0.6362775,0.0,0.96032375,80.969543,0.62901956,450.32822,-9.2310801
7042,7042,196.2977,16.664713,9.2757568,0.0,0,0.62252313,0.0,0.9636597,80.934082,0.61201453,450.47974,-9.2307272
7053,7053,196.2999,16.707184,9.2863197,0.0,0,0.6087687,0.0,0.96445149,81.113617,0.60119677,450.63123,-9.2308455
7064,7064,196.3021,16.734201,9.297864,0.0,0,0.59501433,0.0,0.96763313,80.961281,0.59032977,450.56714,-9.2318029
7075,7075,196.3043,16.825552,9.3115788,0.0,0,0.58125991,0.0,0.9689039,81.29068,0.57344592,450.24435,-9.2318792
7086,7086,196.3065,16.930931,9.3250647,0.0,0,0.56812829,0.0,0.97276717,81.502037,0.56036586,449.9216,-9.2300987
7097,7097,196.3087,17.089741,9.3423405,0.0,0,0.55503839,0.0,0.97396374,82.121552,0.54973376,449.59882,-9.2289705
7108,7108,196.3109,17.204554,9.3519707,0.0,0,0.54194838,0.0,0.97769576,82.410782,0.53656012,449.27603,-9.2297239
7119,7119,196.3131,17.292362,9.3691044,0.0,0,0.52885836,0.0,0.97884512,82.700172,0.52101171,448.82748,-9.2294579
7120,7120,196.3133,17.309284,9.3667135,0.0,0,0.52766836,0.0,0.97994298,82.686508,0.51850164,448.78558,-9.2296839