File: clean data/testID_0210.csv
level_0,index,Time(sec),Force(kN),Jaw(mm),PowAngle(deg),Power(W),Pram,PTemp,Strain,Stress(MPa),Stroke(mm),TC1(C),wedge(mm)
2104,2104,178.6768,0.61049414,0.011760178,0.0,0,9.0922289,0.0,0.00075608521,7.511507,10.136235,401.35635,-9.2661753
2106,2106,178.6772,2.6825604,0.037596762,0.0,0,9.0337009,0.0,0.0020505609,29.741816,10.06389,402.06439,-9.2660313
2108,2108,178.6776,4.9190598,0.091102093,0.0,0,8.975173,0.0,0.0060632853,60.839813,10.008169,402.7724,-9.2647486
2110,2110,178.678,5.3802195,0.15285027,0.0,0,8.9166451,0.0,0.0094501665,67.250801,9.9410696,403.48041,-9.2628374
2112,2112,178.6784,5.5694075,0.28442165,0.0,0,8.8581161,0.0,0.018084526,70.05912,9.8604889,404.18845,-9.2611713
2114,2114,178.6788,5.4753556,0.38639277,0.0,0,8.7995882,0.0,0.025752578,67.393814,9.7601624,404.89645,-9.2619457
2116,2116,178.6792,5.830924,0.48598829,0.0,0,8.7416477,0.0,0.031855006,71.858955,9.6580725,405.60449,-9.2625999
2118,2118,178.6796,6.0429339,0.56771314,0.0,0,8.6858435,0.0,0.038318068,73.295197,9.5642147,406.3125,-9.2626581
2120,2120,178.68,6.0832963,0.59962863,0.0,0,8.6301794,0.0,0.040553745,75.168861,9.4804745,407.02051,-9.262044
2122,2122,178.6804,5.7190137,0.67962396,0.0,0,8.5745163,0.0,0.04543823,69.197083,9.4178495,407.72855,-9.2607794
2124,2124,178.6808,6.3102093,0.72019964,0.0,0,8.5188513,0.0,0.049159121,75.935265,9.3550224,408.43655,-9.2618427
2126,2126,178.6812,6.4389853,0.78202635,0.0,0,8.4631872,0.0,0.052889433,77.446938,9.292345,409.14459,-9.2600012
2128,2128,178.6816,6.4191933,0.88996387,0.0,0,8.4075241,0.0,0.060239356,77.336967,9.2160625,409.8526,-9.2605877
2130,2130,178.682,6.1281776,0.96926218,0.0,0,8.3518591,0.0,0.066498667,72.902634,9.1314363,410.56061,-9.2616329
2132,2132,178.6824,6.4355359,1.0625273,0.0,0,8.296196,0.0,0.072617307,76.014542,9.0448122,411.26865,-9.2615852
2134,2134,178.6828,6.3185372,1.1330409,0.0,0,8.2405319,0.0,0.07817319,74.412781,8.9653702,411.97665,-9.2612848
2136,2136,178.6832,6.5032377,1.1720114,0.0,0,8.1848679,0.0,0.081167109,76.338074,8.8899698,412.68469,-9.2610111
2138,2138,178.6836,6.1450715,1.2380784,0.0,0,8.1292038,0.0,0.085541785,72.157318,8.8340111,413.3927,-9.2610226
2140,2140,178.684,6.6024728,1.2743134,0.0,0,8.0735397,0.0,0.088792607,76.17794,8.7791758,414.10071,-9.2616396
2142,2142,178.6844,6.7066894,1.3321776,0.0,0,8.0196571,0.0,0.092509158,78.191055,8.7237577,414.80875,-9.2605
2144,2144,178.6848,6.6637454,1.4161541,0.0,0,7.9666901,0.0,0.098422356,76.764297,8.6595898,415.51675,-9.2606277
2146,2146,178.6852,6.5521717,1.4890556,0.0,0,7.9137306,0.0,0.10435778,75.443802,8.5896988,416.22479,-9.2611532
2148,2148,178.6856,6.5397573,1.5670372,0.0,0,7.8607702,0.0,0.10964379,74.402,8.5199881,416.9328,-9.2619076
2150,2150,178.686,6.7133775,1.6105365,0.0,0,7.8078103,0.0,0.11322819,76.245331,8.454669,417.64081,-9.2606773
2152,2152,178.6864,6.6875796,1.6604565,0.0,0,7.7548499,0.0,0.11717325,75.768188,8.3949728,418.17725,-9.260848
2154,2154,178.6868,6.5667357,1.7222358,0.0,0,7.70189,0.0,0.12125597,74.246765,8.3416634,418.71365,-9.2605495
2156,2156,178.6872,6.7020373,1.7549424,0.0,0,7.6489296,0.0,0.12419058,74.943207,8.287756,419.25009,-9.2610941
2158,2158,178.6876,6.910161,1.8113519,0.0,0,7.5959702,0.0,0.12837046,77.363617,8.2352772,419.78653,-9.2617893
2160,2160,178.688,6.8575211,1.8797135,0.0,0,7.5430098,0.0,0.1329589,76.381096,8.1788559,420.32297,-9.2611313
2162,2162,178.6884,6.8894687,1.9386315,0.0,0,7.4900503,0.0,0.13809246,76.560333,8.120018,420.85941,-9.259881
2164,2164,178.6888,6.7594376,2.0017848,0.0,0,7.4370899,0.0,0.14278451,74.734131,8.0563183,421.39584,-9.2600603
2166,2166,178.6892,6.9236722,2.0495155,0.0,0,7.3846612,0.0,0.14628536,76.060707,8.0022879,421.93228,-9.2605486
2168,2168,178.6896,6.8604918,2.0978203,0.0,0,7.3341675,0.0,0.15054922,75.30735,7.9474425,422.46869,-9.2610397
2170,2170,178.69,6.8764896,2.1470191,0.0,0,7.2837992,0.0,0.1539972,74.95237,7.8942566,423.00513,-9.2608013
2172,2172,178.6904,6.9261017,2.1938236,0.0,0,7.2334309,0.0,0.15765087,75.256157,7.8469658,423.54156,-9.2619915
2174,2174,178.6908,7.0490208,2.2407687,0.0,0,7.1830626,0.0,0.16165979,76.23069,7.7966552,424.078,-9.2619886
2176,2176,178.6912,7.0459156,2.2950175,0.0,0,7.1326947,0.0,0.16537115,76.13942,7.7455096,424.61444,-9.2616873
2178,2178,178.6916,7.0173988,2.3544617,0.0,0,7.0823264,0.0,0.17045963,75.41188,7.6941972,425.15088,-9.2610559
2180,2180,178.692,7.0677123,2.4016504,0.0,0,7.0319586,0.0,0.17428353,75.504822,7.6428032,425.68729,-9.2609682
2182,2182,178.6924,7.1659698,2.4491496,0.0,0,6.9815903,0.0,0.17759667,76.222977,7.5871606,426.22372,-9.2605848
2184,2184,178.6928,7.1070962,2.5023139,0.0,0,6.9312229,0.0,0.18245628,75.529907,7.5380836,426.76016,-9.2618208
2186,2186,178.6932,7.0589848,2.5473161,0.0,0,6.8808546,0.0,0.18568453,74.681915,7.4887137,427.2966,-9.2614098
2188,2188,178.6936,7.1613116,2.5951948,0.0,0,6.8304873,0.0,0.18942475,75.286461,7.4407682,427.83304,-9.2604399
2190,2190,178.694,7.2689338,2.6416252,0.0,0,6.7801185,0.0,0.19372456,76.285172,7.3907075,428.36948,-9.2603207
2192,2192,178.6944,7.262022,2.6964619,0.0,0,6.7313623,0.0,0.19739006,76.007088,7.3428059,428.90588,-9.2617264
2194,2194,178.6948,7.2193751,2.749701,0.0,0,6.6834369,0.0,0.20211048,75.171295,7.2921505,429.44232,-9.2631788
2196,2196,178.6952,7.2566223,2.7913134,0.0,0,6.6355171,0.0,0.20580818,75.065445,7.2421627,429.97876,-9.2621403
2198,2198,178.6956,7.3597584,2.8472886,0.0,0,6.5875969,0.0,0.20958348,75.918556,7.1895337,430.5152,-9.2606106
2200,2200,178.696,7.3551893,2.8939521,0.0,0,6.5396771,0.0,0.21412815,75.685425,7.1396093,431.05154,-9.2597504
2202,2202,178.6964,7.3336067,2.9371796,0.0,0,6.4917574,0.0,0.21757756,75.094391,7.0917873,430.75137,-9.2604513
2204,2204,178.6968,7.3758154,2.9929962,0.0,0,6.4438376,0.0,0.22175802,75.13736,7.0415483,430.45123,-9.2619104
2206,2206,178.6972,7.4377441,3.0291564,0.0,0,6.3959169,0.0,0.22553152,75.546738,6.9966598,430.15106,-9.2621374
2208,2208,178.6976,7.4954038,3.0789874,0.0,0,6.3479972,0.0,0.22909789,75.830635,6.9513202,429.85089,-9.2620554
2210,2210,178.698,7.4768591,3.1369374,0.0,0,6.3000774,0.0,0.2340038,75.306358,6.9018779,429.55075,-9.2607679
2212,2212,178.6984,7.5085921,3.1756992,0.0,0,6.2521577,0.0,0.2378929,75.357971,6.8514819,429.25058,-9.2610598
2214,2214,178.6988,7.5533452,3.2282991,0.0,0,6.2042375,0.0,0.24152985,75.518631,6.800714,428.95044,-9.2609482
2216,2216,178.6992,7.5671763,3.2788749,0.0,0,6.1567979,0.0,0.24641025,75.227623,6.7496858,428.65027,-9.2618818
2218,2218,178.6996,7.5924392,3.3187261,0.0,0,6.1111078,0.0,0.24985652,75.254944,6.7038579,428.3501,-9.2619925
2220,2220,178.7,7.6545162,3.369982,0.0,0,6.0655317,0.0,0.25375929,75.536339,6.6547508,428.04996,-9.2611847
2222,2222,178.7004,7.7027202,3.4171367,0.0,0,6.0199556,0.0,0.25840196,75.663216,6.6078243,427.74979,-9.2605982
2224,2224,178.7008,7.7087669,3.4677236,0.0,0,5.9743791,0.0,0.26240894,75.53508,6.5586219,427.44962,-9.2598343
2226,2226,178.7012,7.7066174,3.5200155,0.0,0,5.9288034,0.0,0.26674414,75.151192,6.5092392,427.14948,-9.2620935
2228,2228,178.7016,7.7715421,3.5630474,0.0,0,5.8832278,0.0,0.2712487,75.412537,6.4641647,426.8493,-9.2620392
2230,2230,178.702,7.8102841,3.6153986,0.0,0,5.8376513,0.0,0.27508396,75.46785,6.4140954,426.54913,-9.2617664
2232,2232,178.7024,7.8282666,3.6597013,0.0,0,5.7920747,0.0,0.27931347,75.330826,6.3648319,426.24899,-9.2609291
2234,2234,178.7028,7.8242021,3.703861,0.0,0,5.7464995,0.0,0.28351876,75.013977,6.319479,425.94882,-9.2607288
2236,2236,178.7032,7.862186,3.7568188,0.0,0,5.7009234,0.0,0.28743064,74.996452,6.272593,425.64865,-9.2616749
2238,2238,178.7036,7.9347415,3.7992837,0.0,0,5.6553473,0.0,0.29174924,75.418297,6.2241178,425.34851,-9.26194
2240,2240,178.704,7.9657469,3.8459001,0.0,0,5.6097713,0.0,0.29595283,75.486923,6.1764789,425.04834,-9.2620144
2242,2242,178.7044,7.9674759,3.9011436,0.0,0,5.5656543,0.0,0.30028218,75.053307,6.1295285,424.7482,-9.262084
2244,2244,178.7048,7.998558,3.9419804,0.0,0,5.5222898,0.0,0.30481318,74.994087,6.0828514,424.44803,-9.2609577
2246,2246,178.7052,8.0115175,3.9895132,0.0,0,5.4789295,0.0,0.30874237,74.905106,6.0343118,424.14786,-9.2604208
2248,2248,178.7056,8.0727453,4.0412712,0.0,0,5.4355693,0.0,0.31320801,75.119614,5.9849863,423.84772,-9.2615175
2250,2250,178.706,8.1078243,4.0794439,0.0,0,5.3922095,0.0,0.31746176,75.099411,5.9400101,423.54758,-9.2608261
2252,2252,178.7064,8.1227503,4.1269827,0.0,0,5.3488493,0.0,0.32099804,75.01844,5.8925314,423.60641,-9.2612877
2254,2254,178.7068,8.1412287,4.177351,0.0,0,5.3054895,0.0,0.32598838,74.862801,5.8467054,423.66522,-9.2615576
2256,2256,178.7072,8.1764364,4.2190666,0.0,0,5.2621293,0.0,0.33015126,74.786255,5.7980332,423.72403,-9.2612438
2258,2258,178.7076,8.2270203,4.2692542,0.0,0,5.2187696,0.0,0.3340967,74.931145,5.7535319,423.78287,-9.2605648
2260,2260,178.708,8.2882671,4.3162379,0.0,0,5.1754098,0.0,0.33928895,75.142944,5.7058606,423.84167,-9.2621756
2262,2262,178.7084,8.2896338,4.3597007,0.0,0,5.1320496,0.0,0.34307006,74.958176,5.6603093,423.90048,-9.2620296
2264,2264,178.7088,8.2994719,4.4067802,0.0,0,5.0886893,0.0,0.34710771,74.670341,5.6103988,423.95932,-9.2614908
2266,2266,178.7092,8.3398638,4.4509816,0.0,0,5.045764,0.0,0.3520661,74.640968,5.5672913,424.01813,-9.2612467
2268,2268,178.7096,8.403141,4.4978266,0.0,0,5.0044203,0.0,0.3558735,74.908455,5.5190196,424.07693,-9.2608147
2270,2270,178.71,8.4398518,4.5448136,0.0,0,4.9631801,0.0,0.36037603,74.962822,5.4753509,424.13577,-9.260787
2272,2272,178.7104,8.4359074,4.5866346,0.0,0,4.9219403,0.0,0.36507478,74.547707,5.4269896,424.19458,-9.2615232
2274,2274,178.7108,8.4433098,4.6360989,0.0,0,4.8807001,0.0,0.36883837,74.345818,5.3851194,424.25342,-9.2623358
2276,2276,178.7112,8.4926214,4.6785846,0.0,0,4.8394604,0.0,0.3735598,74.368217,5.3410287,424.31223,-9.2619381
2278,2278,178.7116,8.5782862,4.7193127,0.0,0,4.7982202,0.0,0.37757063,74.883575,5.2949061,424.37103,-9.261487
2280,2280,178.712,8.5860071,4.7737255,0.0,0,4.7569804,0.0,0.38206756,74.637009,5.2493653,424.42987,-9.2604332
2282,2282,178.7124,8.6052523,4.8134742,0.0,0,4.7157402,0.0,0.38685766,74.389786,5.2055883,424.48868,-9.2605782
2284,2284,178.7128,8.6336689,4.858676,0.0,0,4.6745005,0.0,0.39096391,74.282814,5.160789,424.54749,-9.2619066
2286,2286,178.7132,8.6962061,4.9126205,0.0,0,4.6332603,0.0,0.39587083,74.399086,5.1139488,424.60632,-9.2615881
2288,2288,178.7136,8.7477961,4.94766,0.0,0,4.59202,0.0,0.40032077,74.641708,5.0707097,424.66513,-9.2604771
2290,2290,178.714,8.7577763,4.9941521,0.0,0,4.5507803,0.0,0.40411243,74.433189,5.0249128,424.72394,-9.2605314
2292,2292,178.7144,8.7694588,5.0438943,0.0,0,4.5108619,0.0,0.40924537,74.080322,4.9817448,424.78278,-9.2619286
2294,2294,178.7148,8.8064451,5.0814075,0.0,0,4.4716258,0.0,0.41355407,74.125977,4.9342923,424.84158,-9.2614851
2296,2296,178.7152,8.8434601,5.1298728,0.0,0,4.432394,0.0,0.41762376,74.105179,4.8919039,424.90039,-9.2612495
2298,2298,178.7156,8.8971319,5.1745443,0.0,0,4.3931618,0.0,0.42290303,74.219116,4.8476014,424.95923,-9.2610931
2300,2300,178.716,8.9332218,5.2138004,0.0,0,4.35393,0.0,0.42676699,74.198662,4.8016925,425.01807,-9.2597904
2302,2302,178.7164,8.9435225,5.2613235,0.0,0,4.3146982,0.0,0.43105212,74.082619,4.7601261,425.4118,-9.2610388
2304,2304,178.7168,8.9824533,5.3033581,0.0,0,4.275466,0.0,0.43634203,73.907707,4.7137208,425.80554,-9.2609558
2306,2306,178.7172,9.0365257,5.3467894,0.0,0,4.2362337,0.0,0.44015265,74.009377,4.6730375,426.19925,-9.2614965
2308,2308,178.7176,9.0768652,5.3911276,0.0,0,4.1970015,0.0,0.4447239,73.998161,4.6313019,426.59299,-9.2613277
2310,2310,178.718,9.1047096,5.4293699,0.0,0,4.1577697,0.0,0.44951668,73.946037,4.5892396,426.98672,-9.2612085
2312,2312,178.7184,9.1142998,5.4789624,0.0,0,4.1185379,0.0,0.45359254,73.688377,4.5433102,427.38043,-9.2606249
2314,2314,178.7188,9.1460409,5.5194798,0.0,0,4.0793056,0.0,0.45839572,73.589775,4.5021086,427.77417,-9.2605619
2316,2316,178.7192,9.1931391,5.5568171,0.0,0,4.0404677,0.0,0.46275166,73.69339,4.4612942,428.16788,-9.2608299
2318,2318,178.7196,9.2589016,5.6060548,0.0,0,4.0030622,0.0,0.4669131,73.844276,4.4188752,428.56161,-9.2603235
2320,2320,178.72,9.2894011,5.6404939,0.0,0,3.9657497,0.0,0.47150719,73.740685,4.3772063,428.95535,-9.2600327
2322,2322,178.7204,9.3089561,5.6803169,0.0,0,3.9284377,0.0,0.47550514,73.638977,4.3345947,429.34906,-9.2611952
2324,2324,178.7208,9.3517008,5.7303743,0.0,0,3.8911257,0.0,0.48016044,73.650459,4.2917147,429.7428,-9.2614889
2326,2326,178.7212,9.4043951,5.763556,0.0,0,3.8538139,0.0,0.48504567,73.653374,4.250545,430.13654,-9.2620268
2328,2328,178.7216,9.442625,5.8064833,0.0,0,3.8165019,0.0,0.48883724,73.681023,4.2090321,430.53024,-9.2612505
2330,2330,178.722,9.4590712,5.8537812,0.0,0,3.7791896,0.0,0.49396968,73.546478,4.1697669,430.92398,-9.2604876
2332,2332,178.7224,9.4706726,5.8827639,0.0,0,3.7418776,0.0,0.49805409,73.359497,4.1290693,431.31772,-9.2610292
2334,2334,178.7228,9.5133553,5.9229379,0.0,0,3.7045658,0.0,0.50141412,73.348381,4.0902271,431.71143,-9.2606106
2336,2336,178.7232,9.5670214,5.9650874,0.0,0,3.6672537,0.0,0.50668257,73.37336,4.0548463,432.10516,-9.2604685
2338,2338,178.7236,9.6193199,5.9987807,0.0,0,3.6299417,0.0,0.51052606,73.507088,4.0137043,432.49887,-9.2598982
2340,2340,178.724,9.6563883,6.0425367,0.0,0,3.5926297,0.0,0.51460642,73.474083,3.9743724,432.89261,-9.2610006
2342,2342,178.7244,9.6857071,6.0813727,0.0,0,3.5565133,0.0,0.51995111,73.307007,3.9376497,433.28635,-9.2608023
2344,2344,178.7248,9.7103996,6.1182957,0.0,0,3.5210135,0.0,0.52364528,73.166397,3.9000924,433.68005,-9.2614574
2346,2346,178.7252,9.7641306,6.1584363,0.0,0,3.4855173,0.0,0.52773058,73.320328,3.859643,434.07379,-9.2605095
2348,2348,178.7256,9.8241348,6.1922946,0.0,0,3.4500215,0.0,0.53269178,73.363205,3.8201895,434.46753,-9.2606897
2350,2350,178.726,9.8382368,6.2333899,0.0,0,3.4145255,0.0,0.53625339,73.275177,3.783546,434.86124,-9.2602949
2352,2352,178.7264,9.8503933,6.2720513,0.0,0,3.3790293,0.0,0.54098821,72.976723,3.7465646,435.13474,-9.2591677
2354,2354,178.7268,9.8909731,6.3053617,0.0,0,3.3435335,0.0,0.5455215,72.941719,3.7112336,435.40823,-9.2599392
2356,2356,178.7272,9.9560194,6.3484602,0.0,0,3.3080375,0.0,0.54920393,73.183907,3.6747262,435.68173,-9.2616386
2358,2358,178.7276,10.027366,6.3800812,0.0,0,3.2725413,0.0,0.5537613,73.298843,3.6352229,435.95523,-9.2620354
2360,2360,178.728,10.048236,6.4130034,0.0,0,3.2370453,0.0,0.55751663,73.223717,3.5973272,436.22873,-9.2618132
2362,2362,178.7284,10.065885,6.4587793,0.0,0,3.2015493,0.0,0.56183511,73.043404,3.5618818,436.5022,-9.2600374
2364,2364,178.7288,10.108057,6.4869084,0.0,0,3.1660533,0.0,0.56665987,73.00782,3.5271139,436.7757,-9.2595053
2366,2366,178.7292,10.165095,6.5234756,0.0,0,3.1309118,0.0,0.57022673,73.179771,3.4933438,437.04919,-9.2596684
2368,2368,178.7296,10.226372,6.5662665,0.0,0,3.0970592,0.0,0.57493079,73.258469,3.4568691,437.32269,-9.2596769
2370,2370,178.73,10.242381,6.5941043,0.0,0,3.0632911,0.0,0.5794434,73.073189,3.4218328,437.59619,-9.2605658
2372,2372,178.7304,10.267859,6.6344771,0.0,0,3.0295231,0.0,0.58301783,72.943314,3.3861809,437.86969,-9.2602758
2374,2374,178.7308,10.313627,6.673296,0.0,0,2.9957552,0.0,0.5881567,72.878395,3.3495827,438.14319,-9.259532
2376,2376,178.7312,10.384892,6.6984353,0.0,0,2.9619873,0.0,0.59167767,73.135727,3.3168633,438.41669,-9.2597084
2378,2378,178.7316,10.449511,6.7371416,0.0,0,2.9282191,0.0,0.59521115,73.357513,3.2813785,438.69019,-9.261364
2380,2380,178.732,10.460361,6.772203,0.0,0,2.8944509,0.0,0.600559,73.044212,3.2437501,438.96368,-9.2605085
2382,2382,178.7324,10.492384,6.8053803,0.0,0,2.860683,0.0,0.60426551,72.948425,3.2074974,439.23718,-9.2590065
2384,2384,178.7328,10.562507,6.845686,0.0,0,2.826915,0.0,0.60864699,73.125305,3.1745813,439.51068,-9.2594986
2386,2386,178.7332,10.644732,6.8769655,0.0,0,2.7931471,0.0,0.61367166,73.328018,3.1408353,439.78415,-9.2592144
2388,2388,178.7336,10.686996,6.9128327,0.0,0,2.7593791,0.0,0.6170249,73.411118,3.108845,440.05765,-9.2590647
2390,2390,178.734,10.705895,6.9473257,0.0,0,2.7256112,0.0,0.62138921,73.149254,3.0711942,440.33115,-9.2596178
2392,2392,178.7344,10.747238,6.9755116,0.0,0,2.6929281,0.0,0.62586844,73.181885,3.0374289,440.60464,-9.2605915
2394,2394,178.7348,10.826089,7.0167632,0.0,0,2.6608045,0.0,0.62957919,73.370712,3.0029736,440.87814,-9.2606859
2396,2396,178.7352,10.892889,7.0484314,0.0,0,2.6286843,0.0,0.63449168,73.518089,2.9673495,441.15164,-9.2599421
2398,2398,178.7356,10.941062,7.0802484,0.0,0,2.5965643,0.0,0.6386342,73.542976,2.9357147,441.42514,-9.2583189
2400,2400,178.736,10.987467,7.1239824,0.0,0,2.5644443,0.0,0.64289182,73.505859,2.9009106,441.69855,-9.2587624
2402,2402,178.7364,11.024088,7.1507125,0.0,0,2.5323241,0.0,0.6476661,73.434517,2.8673553,441.0029,-9.259779
2404,2404,178.7368,11.088259,7.1830215,0.0,0,2.5002043,0.0,0.65137297,73.540421,2.8331487,440.30728,-9.2603693
2406,2406,178.7372,11.148964,7.2266564,0.0,0,2.4680843,0.0,0.6563006,73.597061,2.8024163,439.61163,-9.2603521
2408,2408,178.7376,11.20703,7.2521939,0.0,0,2.4359643,0.0,0.6608668,73.708618,2.7669284,438.91602,-9.2587528
2410,2410,178.738,11.25148,7.2876225,0.0,0,2.4038444,0.0,0.66437197,73.724586,2.7402091,438.22037,-9.2586155
2412,2412,178.7384,11.312177,7.326272,0.0,0,2.3717244,0.0,0.66967672,73.671463,2.7048976,437.52475,-9.2589045
2414,2414,178.7388,11.376913,7.3511086,0.0,0,2.3396041,0.0,0.67376369,73.800026,2.666599,436.8291,-9.2597837
2416,2416,178.7392,11.469254,7.3891387,0.0,0,2.307806,0.0,0.67748314,74.091141,2.6333141,436.13348,-9.2589903
2418,2418,178.7396,11.522286,7.4242806,0.0,0,2.2771773,0.0,0.68293083,74.033569,2.5998304,435.43784,-9.2590017
2420,2420,178.74,11.564315,7.4540401,0.0,0,2.2466252,0.0,0.68691826,74.03035,2.5673623,434.74219,-9.2589331
2422,2422,178.7404,11.624964,7.4929471,0.0,0,2.2160735,0.0,0.69119686,74.130661,2.5296693,434.04657,-9.2591858
2424,2424,178.7408,11.688154,7.523037,0.0,0,2.1855214,0.0,0.69659972,74.117073,2.4998047,433.35092,-9.2592745
2426,2426,178.7412,11.775213,7.556025,0.0,0,2.1549692,0.0,0.69998628,74.37899,2.4642856,432.6553,-9.2597933
2428,2428,178.7416,11.839449,7.5917153,0.0,0,2.1244173,0.0,0.70459932,74.47451,2.430527,431.95966,-9.2590237
2430,2430,178.742,11.871345,7.6189227,0.0,0,2.0938654,0.0,0.7096566,74.361145,2.3961136,431.26404,-9.259223
2432,2432,178.7424,11.944483,7.658421,0.0,0,2.0633135,0.0,0.71335644,74.492828,2.3636937,430.56839,-9.2597332
2434,2434,178.7428,12.003638,7.691287,0.0,0,2.0327616,0.0,0.71863884,74.46524,2.3302886,429.87277,-9.2592888
2436,2436,178.7432,12.095509,7.7179708,0.0,0,2.0022092,0.0,0.72293222,74.701698,2.2994034,429.17712,-9.2589731
2438,2438,178.7436,12.154454,7.7588367,0.0,0,1.9716572,0.0,0.72686148,74.799561,2.2667382,428.48151,-9.2595062
2440,2440,178.744,12.195148,7.7842965,0.0,0,1.9411051,0.0,0.73188418,74.663696,2.2351387,427.78586,-9.2598352
2442,2442,178.7444,12.257456,7.8157535,0.0,0,1.9115326,0.0,0.73579311,74.747971,2.2041435,427.09024,-9.2598991
2444,2444,178.7448,12.350458,7.8565798,0.0,0,1.8824656,0.0,0.74044943,74.911842,2.1696038,426.39459,-9.2593107
2446,2446,178.7452,12.435919,7.8785796,0.0,0,1.8534015,0.0,0.74538463,75.132477,2.1404533,425.69897,-9.2591763
2448,2448,178.7456,12.494382,7.9144673,0.0,0,1.8243376,0.0,0.74909753,75.214287,2.1078591,425.00333,-9.2573977
2450,2450,178.746,12.540039,7.9531422,0.0,0,1.7952735,0.0,0.75458252,75.013435,2.0758107,424.30765,-9.2577286
2452,2452,178.7464,12.599066,7.9741406,0.0,0,1.7662096,0.0,0.75889581,75.050865,2.0429735,423.25082,-9.259407
2454,2454,178.7468,12.692087,8.0103598,0.0,0,1.7371455,0.0,0.76245731,75.314926,2.0110683,422.19397,-9.2592878
2456,2456,178.7472,12.778681,8.043685,0.0,0,1.7080816,0.0,0.76817691,75.447479,1.9806827,421.13712,-9.2596664
2458,2458,178.7476,12.858668,8.0687637,0.0,0,1.6790177,0.0,0.77209473,75.581032,1.950261,420.08026,-9.2594891
2460,2460,178.748,12.89299,8.1068077,0.0,0,1.6499536,0.0,0.77634478,75.500076,1.918098,419.02341,-9.2583647
2462,2462,178.7484,12.964352,8.1364393,0.0,0,1.6208895,0.0,0.7820797,75.457573,1.8865789,417.96655,-9.2575397
2464,2464,178.7488,13.071069,8.1641655,0.0,0,1.5918256,0.0,0.78539819,75.759232,1.8530312,416.90973,-9.2569571
2466,2466,178.7492,13.167343,8.1984243,0.0,0,1.5630522,0.0,0.78988135,76.043694,1.8240494,415.85287,-9.2581072
2468,2468,178.7496,13.212493,8.2255669,0.0,0,1.5353347,0.0,0.79539335,75.912933,1.7930039,414.79602,-9.2586384
2470,2470,178.75,13.26123,8.2596102,0.0,0,1.5076866,0.0,0.79881966,75.898666,1.7617806,413.73917,-9.259079
2472,2472,178.7504,13.328591,8.2883034,0.0,0,1.4800386,0.0,0.80365449,75.929756,1.7350862,412.68231,-9.2587662
2474,2474,178.7508,13.433444,8.3110275,0.0,0,1.4523906,0.0,0.80808049,76.192459,1.7061009,411.62546,-9.2581959
2476,2476,178.7512,13.529675,8.3517733,0.0,0,1.4247426,0.0,0.81218851,76.414871,1.6786945,410.56863,-9.257514
2478,2478,178.7516,13.586457,8.3779259,0.0,0,1.3970947,0.0,0.8175053,76.328865,1.6496435,409.51178,-9.2578897
2480,2480,178.752,13.638567,8.4046774,0.0,0,1.3694466,0.0,0.82155627,76.314285,1.6192712,408.45493,-9.257349
2482,2482,178.7524,13.725111,8.4440403,0.0,0,1.3417987,0.0,0.82606763,76.418373,1.5885888,407.39807,-9.2587271
2484,2484,178.7528,13.823707,8.4627876,0.0,0,1.3141507,0.0,0.83093184,76.636848,1.5579754,406.34122,-9.258213
2486,2486,178.7532,13.917356,8.4902983,0.0,0,1.2865027,0.0,0.83419752,76.930389,1.5275173,405.28436,-9.2579088
2488,2488,178.7536,13.977541,8.5300102,0.0,0,1.2588546,0.0,0.8396343,76.825272,1.5006387,404.22751,-9.2568741
2490,2490,178.754,14.039523,8.5496216,0.0,0,1.2312068,0.0,0.84442508,76.825836,1.4742371,403.17068,-9.2566938
2492,2492,178.7544,14.140618,8.5813847,0.0,0,1.2044488,0.0,0.84771788,77.072311,1.4431299,402.11383,-9.2579222
2494,2494,178.7548,14.250341,8.6150837,0.0,0,1.1781499,0.0,0.8535623,77.237892,1.4125909,401.05698,-9.2581863
2496,2496,178.7552,14.35632,8.6355381,0.0,0,1.1518539,0.0,0.85747212,77.527512,1.3835541,400.00012,-9.2583284
2498,2498,178.7556,14.427765,8.6708469,0.0,0,1.1255579,0.0,0.86144936,77.603096,1.3526762,398.94327,-9.2582541
2500,2500,178.756,14.49771,8.6976233,0.0,0,1.0992619,0.0,0.867441,77.511925,1.3285744,397.88651,-9.2565184
2502,2502,178.7564,14.605504,8.7222166,0.0,0,1.0729659,0.0,0.87085211,77.782143,1.2969706,397.55746,-9.2572117
2504,2504,178.7568,14.708478,8.755621,0.0,0,1.0466698,0.0,0.87521136,78.031883,1.2687994,397.22839,-9.2584696
2506,2506,178.7572,14.79476,8.7805996,0.0,0,1.0203738,0.0,0.88115537,78.012123,1.2422906,396.89935,-9.2577686
2508,2508,178.7576,14.859364,8.8099146,0.0,0,0.9940778,0.0,0.88423926,78.098343,1.2118925,396.57031,-9.2580156
2510,2510,178.758,14.944463,8.8393373,0.0,0,0.96778184,0.0,0.88908881,78.176292,1.1833922,396.24124,-9.2579346
2512,2512,178.7584,15.052736,8.859684,0.0,0,0.94148582,0.0,0.8939507,78.326454,1.1555014,395.9122,-9.2579174
2514,2514,178.7588,15.165469,8.894763,0.0,0,0.91518986,0.0,0.89758819,78.609116,1.1283228,395.58316,-9.2572861
2516,2516,178.7592,15.273515,8.9196177,0.0,0,0.88915813,0.0,0.90279597,78.752357,1.1022521,395.25409,-9.2588329
2518,2518,178.7596,15.354908,8.9423485,0.0,0,0.86408705,0.0,0.90686256,78.875313,1.0749588,394.92505,-9.2579908
2520,2520,178.76,15.443107,8.9800129,0.0,0,0.83907896,0.0,0.9112162,78.984848,1.0459995,394.59601,-9.2564516
2522,2522,178.7604,15.54974,8.9989071,0.0,0,0.81407094,0.0,0.9164874,79.16317,1.0179199,394.26694,-9.2557917
2524,2524,178.7608,15.673074,9.025032,0.0,0,0.78906298,0.0,0.920012,79.436295,0.98904842,393.9379,-9.2563982
2526,2526,178.7612,15.774035,9.0621824,0.0,0,0.76405495,0.0,0.92527831,79.583969,0.96904075,393.60886,-9.2562351
2528,2528,178.7616,15.866346,9.0783176,0.0,0,0.73904693,0.0,0.93028229,79.619194,0.93958628,393.27979,-9.2573357
2530,2530,178.762,15.95606,9.1069069,0.0,0,0.71403897,0.0,0.93335825,79.786179,0.91415131,392.95074,-9.2576075
2532,2532,178.7624,16.058716,9.1403313,0.0,0,0.68903095,0.0,0.93919283,79.892326,0.88416594,392.6217,-9.257946
2534,2534,178.7628,16.198229,9.1573715,0.0,0,0.66402298,0.0,0.94347513,80.210274,0.85864222,392.29263,-9.255928
2536,2536,178.7632,16.303183,9.1898127,0.0,0,0.63901496,0.0,0.94698405,80.447411,0.83259416,391.96359,-9.2559147
2538,2538,178.7636,16.392519,9.2176485,0.0,0,0.61400694,0.0,0.95325631,80.415298,0.80440509,391.63455,-9.2564087
2540,2540,178.764,16.474976,9.2371788,0.0,0,0.58899897,0.0,0.95660013,80.551872,0.77789342,391.30551,-9.2572565
2542,2542,178.7644,16.592087,9.2680998,0.0,0,0.5647862,0.0,0.96066457,80.778244,0.75109345,390.97644,-9.2570333
2544,2544,178.7648,16.732159,9.2926197,0.0,0,0.54098368,0.0,0.96661502,80.949081,0.72500843,390.6474,-9.2562227
2546,2546,178.7652,16.849232,9.317275,0.0,0,0.5171836,0.0,0.96990329,81.27565,0.69695568,390.31836,-9.2563992
2548,2548,178.7656,16.932138,9.3447485,0.0,0,0.49338362,0.0,0.97444874,81.347694,0.67382795,389.98929,-9.2557011
2550,2550,178.766,17.039831,9.3643417,0.0,0,0.46958363,0.0,0.97972333,81.406593,0.64343768,389.66031,-9.2564888
2552,2552,178.7664,17.161116,9.3963089,0.0,0,0.44578362,0.0,0.98331177,81.677116,0.62060696,390.09406,-9.2563076
2554,2554,178.7668,17.301216,9.4197645,0.0,0,0.42198363,0.0,0.98846608,81.939964,0.5940941,390.52777,-9.2552891
2556,2556,178.7672,17.416494,9.4389973,0.0,0,0.39818361,0.0,0.992706,82.086922,0.56922531,390.96149,-9.2561331
2557,2557,178.7674,17.464094,9.4570475,0.0,0,0.38628361,0.0,0.99519324,82.138885,0.55730021,391.17834,-9.2565756