File: clean data/testID_0096.csv
level_0,index,Time(sec),Force(kN),Jaw(mm),PowAngle(deg),Power(W),Pram,PTemp,Strain,Stress(MPa),Stroke(mm),TC1(C),wedge(mm)
1973,1973,165.3572,1.290753,0.064302467,0.0,0,9.0337067,0.0,0.0044633802,15.20068,10.074853,359.76517,-9.2881994
1975,1975,165.3576,3.5423896,0.11289893,0.0,0,8.9751787,0.0,0.0068540629,41.153778,10.017987,359.73734,-9.2884226
1977,1977,165.358,6.2019796,0.16177548,0.0,0,8.9166508,0.0,0.010688129,75.459419,9.9686346,359.7095,-9.2859001
1979,1979,165.3584,7.1714664,0.22430897,0.0,0,8.8581219,0.0,0.01444017,89.52861,9.8962517,359.6817,-9.2833042
1981,1981,165.3588,7.483191,0.35782665,0.0,0,8.7995939,0.0,0.023059892,92.551857,9.8190498,359.65387,-9.2819605
1983,1983,165.3592,8.0981712,0.40931898,0.0,0,8.7416534,0.0,0.027614817,99.684235,9.7288094,359.62604,-9.2831097
1985,1985,165.3596,8.3834476,0.48863336,0.0,0,8.6858492,0.0,0.032307498,102.93575,9.6391029,359.59821,-9.2832365
1987,1987,165.36,9.0444784,0.56469429,0.0,0,8.6301851,0.0,0.037998635,110.11051,9.5628996,359.57037,-9.2816734
1989,1989,165.3604,8.875041,0.5783186,0.0,0,8.574522,0.0,0.039206333,109.21365,9.4961815,359.54257,-9.2813196
1991,1991,165.3608,8.89818,0.68262321,0.0,0,8.518857,0.0,0.045649342,107.62226,9.4325666,359.51474,-9.2810469
1993,1993,165.3612,9.4066277,0.73971695,0.0,0,8.4631929,0.0,0.050361019,113.4569,9.3653708,359.48691,-9.2804356
1995,1995,165.3616,9.5758314,0.80161852,0.0,0,8.4075298,0.0,0.054353442,115.21299,9.2948303,359.45908,-9.2807398
1997,1997,165.362,9.5950193,0.90934598,0.0,0,8.3518648,0.0,0.061732799,114.94457,9.2179365,359.43127,-9.2808971
1999,1999,165.3624,9.5068579,0.96466047,0.0,0,8.2962017,0.0,0.066286623,113.2124,9.1343842,359.80164,-9.2802296
2001,2001,165.3628,9.7771368,1.0400344,0.0,0,8.2405376,0.0,0.071349569,115.67724,9.0623465,360.19296,-9.280077
2003,2003,165.3632,9.8832855,1.0908804,0.0,0,8.1848736,0.0,0.07503929,116.67997,8.9945431,360.58429,-9.2803011
2005,2005,165.3636,10.010108,1.1401525,0.0,0,8.1292095,0.0,0.078889295,117.62717,8.9314756,360.97559,-9.2808218
2007,2007,165.364,10.004182,1.2169778,0.0,0,8.0735455,0.0,0.083971664,117.09361,8.8691492,361.36691,-9.2801971
2009,2009,165.3644,10.168571,1.273424,0.0,0,8.0196619,0.0,0.08820869,118.14146,8.8088608,361.75824,-9.2801313
2011,2011,165.3648,10.366424,1.3440959,0.0,0,7.9666953,0.0,0.093676671,120.20606,8.740407,362.14957,-9.2807102
2013,2013,165.3652,10.274589,1.4238162,0.0,0,7.9137359,0.0,0.098973349,118.63567,8.6661043,362.54089,-9.2801466
2015,2015,165.3656,10.338812,1.4818609,0.0,0,7.8607755,0.0,0.10357112,118.58012,8.5970497,362.93222,-9.2809391
2017,2017,165.366,10.465469,1.5424914,0.0,0,7.8078156,0.0,0.10830934,119.44135,8.5310249,363.32352,-9.2802114
2019,2019,165.3664,10.556604,1.5996225,0.0,0,7.7548552,0.0,0.11199531,119.95658,8.4684219,363.71484,-9.2798576
2021,2021,165.3668,10.586455,1.6503474,0.0,0,7.7018952,0.0,0.11625234,120.03316,8.4075994,364.10617,-9.2800369
2023,2023,165.3672,10.603165,1.7198461,0.0,0,7.6489348,0.0,0.12136821,119.3872,8.3498573,364.4975,-9.2805977
2025,2025,165.3676,10.793859,1.7767395,0.0,0,7.5959754,0.0,0.1253757,121.07339,8.2894669,364.88882,-9.2804356
2027,2027,165.368,10.835656,1.8324853,0.0,0,7.543015,0.0,0.13002457,121.22511,8.2259102,365.28015,-9.2811127
2029,2029,165.3684,10.85736,1.89906,0.0,0,7.4900556,0.0,0.13483769,120.72337,8.1676683,365.67145,-9.2809629
2031,2031,165.3688,10.889787,1.9554986,0.0,0,7.4370952,0.0,0.13908173,120.66322,8.1045265,366.06277,-9.2804394
2033,2033,165.3692,10.943871,2.0113914,0.0,0,7.3846664,0.0,0.14375988,120.42891,8.0451851,366.4541,-9.280632
2035,2035,165.3696,11.100091,2.0603459,0.0,0,7.3341722,0.0,0.14720473,121.8327,7.9902287,366.84543,-9.2798967
2037,2037,165.37,11.084888,2.1187398,0.0,0,7.2838039,0.0,0.15184772,121.15314,7.9349031,367.23676,-9.2807503
2039,2039,165.3704,11.15228,2.1744521,0.0,0,7.2334356,0.0,0.15637514,121.36151,7.8789883,367.62808,-9.2814846
2041,2041,165.3708,11.187926,2.2245407,0.0,0,7.1830673,0.0,0.15988196,121.37585,7.823669,368.01938,-9.2815609
2043,2043,165.3712,11.327231,2.2835071,0.0,0,7.1326995,0.0,0.16489802,122.11866,7.7621622,368.41071,-9.2804871
2045,2045,165.3716,11.343904,2.3364429,0.0,0,7.0823312,0.0,0.1689734,122.05379,7.7076001,368.80203,-9.2800245
2047,2047,165.372,11.36746,2.3919997,0.0,0,7.0319633,0.0,0.1730734,121.65094,7.6521297,369.19336,-9.2800589
2049,2049,165.3724,11.436023,2.4437084,0.0,0,6.981595,0.0,0.17775685,121.83221,7.5983877,369.6564,-9.2800655
2051,2051,165.3728,11.499314,2.4919996,0.0,0,6.9312277,0.0,0.18109214,122.10035,7.5444603,370.12741,-9.280798
2053,2053,165.3732,11.556383,2.5484681,0.0,0,6.8808594,0.0,0.18561208,122.18513,7.4892621,370.59842,-9.281189
2055,2055,165.3736,11.579003,2.5955095,0.0,0,6.830492,0.0,0.19004707,121.81115,7.4382,371.06943,-9.2812653
2057,2057,165.374,11.67736,2.6474156,0.0,0,6.7801232,0.0,0.19345552,122.38776,7.3871498,371.54044,-9.2813292
2059,2059,165.3744,11.706239,2.6963537,0.0,0,6.7313671,0.0,0.19769515,122.30794,7.3355451,372.01144,-9.2813616
2061,2061,165.3748,11.736458,2.741389,0.0,0,6.6834416,0.0,0.20165938,122.07647,7.2841444,372.48245,-9.280077
2063,2063,165.3752,11.781945,2.7986786,0.0,0,6.6355219,0.0,0.20559509,122.12099,7.2336292,372.95346,-9.2793255
2065,2065,165.3756,11.850798,2.8433046,0.0,0,6.5876017,0.0,0.20998697,122.25741,7.1833744,373.42447,-9.2795105
2067,2067,165.376,11.943276,2.8878348,0.0,0,6.5396819,0.0,0.21345825,122.74342,7.1344318,373.89548,-9.2806644
2069,2069,165.3764,11.955978,2.9491863,0.0,0,6.4917622,0.0,0.21807283,122.36256,7.0833015,374.36646,-9.2816143
2071,2071,165.3768,11.985204,2.9878409,0.0,0,6.4438419,0.0,0.22211502,122.11489,7.0393715,374.83746,-9.2813139
2073,2073,165.3772,12.078274,3.0330751,0.0,0,6.3959212,0.0,0.22532931,122.67781,6.9883709,375.30847,-9.2800331
2075,2075,165.3776,12.147726,3.0894971,0.0,0,6.3480015,0.0,0.22993138,122.8217,6.9367599,375.77948,-9.2789106
2077,2077,165.378,12.186776,3.1266358,0.0,0,6.3000817,0.0,0.23367877,122.77827,6.8878021,376.25049,-9.2797451
2079,2079,165.3784,12.201226,3.1799541,0.0,0,6.252162,0.0,0.23751572,122.46864,6.8386788,376.7215,-9.280715
2081,2081,165.3788,12.235913,3.2301717,0.0,0,6.2042422,0.0,0.24230276,122.24726,6.7898216,377.1925,-9.2816086
2083,2083,165.3792,12.323976,3.2696846,0.0,0,6.1568027,0.0,0.2457179,122.69325,6.7430258,377.66351,-9.2816849
2085,2085,165.3796,12.374175,3.3202202,0.0,0,6.1111121,0.0,0.24948829,122.69908,6.696022,378.13452,-9.2805271
2087,2087,165.38,12.426471,3.363167,0.0,0,6.065536,0.0,0.25388327,122.69454,6.652904,378.60553,-9.2798901
2089,2089,165.3804,12.46352,3.4080496,0.0,0,6.0199599,0.0,0.25738674,122.68491,6.6009035,379.07654,-9.2796078
2091,2091,165.3808,12.497132,3.4587579,0.0,0,5.9743834,0.0,0.26149395,122.46522,6.5561166,379.54755,-9.2807989
2093,2093,165.3812,12.579646,3.5017028,0.0,0,5.9288077,0.0,0.26583374,122.65659,6.5094838,380.01855,-9.2823153
2095,2095,165.3816,12.634194,3.5499969,0.0,0,5.8832321,0.0,0.2694836,122.78818,6.4637485,380.48956,-9.2816362
2097,2097,165.382,12.682039,3.5941353,0.0,0,5.8376555,0.0,0.27347812,122.82574,6.4171376,380.96057,-9.2822151
2099,2099,165.3824,12.717384,3.6360617,0.0,0,5.792079,0.0,0.27767223,122.68225,6.3671803,381.11215,-9.2802525
2101,2101,165.3828,12.756745,3.6891124,0.0,0,5.7465038,0.0,0.28147769,122.55425,6.3243203,381.20737,-9.2806749
2103,2103,165.3832,12.828293,3.7301853,0.0,0,5.7009277,0.0,0.28574005,122.64951,6.2771387,381.30258,-9.2805052
2105,2105,165.3836,12.911274,3.7737582,0.0,0,5.6553516,0.0,0.289606,123.05985,6.2335067,381.3978,-9.2806902
2107,2107,165.384,12.940543,3.8294189,0.0,0,5.6097755,0.0,0.29380408,122.85439,6.1853604,381.49304,-9.2802868
2109,2109,165.3844,12.971205,3.8660734,0.0,0,5.5656581,0.0,0.29796955,122.54817,6.139586,381.58826,-9.2816248
2111,2111,165.3848,13.025525,3.91152,0.0,0,5.5222936,0.0,0.30170214,122.55827,6.0945702,381.68347,-9.2810688
2113,2113,165.3852,13.128508,3.9618154,0.0,0,5.4789333,0.0,0.30591512,122.95802,6.0450339,381.77869,-9.2797461
2115,2115,165.3856,13.177582,4.0000124,0.0,0,5.4355736,0.0,0.31009501,123.01486,5.9988532,381.8739,-9.2799549
2117,2117,165.386,13.202657,4.0497069,0.0,0,5.3922133,0.0,0.31401297,122.7655,5.9519429,381.96912,-9.2811995
2119,2119,165.3864,13.251266,4.1013818,0.0,0,5.3488536,0.0,0.3187173,122.63648,5.9066401,382.06433,-9.280797
2121,2121,165.3868,13.320809,4.14081,0.0,0,5.3054934,0.0,0.32298014,122.71831,5.8609705,382.15955,-9.2807608
2123,2123,165.3872,13.401639,4.188766,0.0,0,5.2621331,0.0,0.3267028,122.97241,5.8190842,382.25479,-9.2806435
2125,2125,165.3876,13.457093,4.2355933,0.0,0,5.2187734,0.0,0.33157575,122.91922,5.7690406,382.35001,-9.2807665
2127,2127,165.388,13.487988,4.2743616,0.0,0,5.1754136,0.0,0.33517161,122.82742,5.7256536,382.44522,-9.2812967
2129,2129,165.3884,13.53882,4.3192921,0.0,0,5.1320534,0.0,0.33888134,122.79861,5.6756878,382.54044,-9.2816591
2131,2131,165.3888,13.617598,4.3653431,0.0,0,5.0886931,0.0,0.34385148,122.88305,5.6324897,382.63565,-9.2815065
2133,2133,165.3892,13.685677,4.4105101,0.0,0,5.0457683,0.0,0.34774923,123.06601,5.5877557,382.73087,-9.2802114
2135,2135,165.3896,13.736419,4.4601545,0.0,0,5.0044241,0.0,0.35218099,122.93194,5.5420809,382.82608,-9.2795391
2137,2137,165.39,13.801488,4.5026813,0.0,0,4.9631839,0.0,0.35700539,122.92473,5.4977293,382.9213,-9.2800169
2139,2139,165.3904,13.853048,4.5490952,0.0,0,4.9219441,0.0,0.36066908,122.89615,5.4512711,383.01654,-9.2808867
2141,2141,165.3908,13.913402,4.592504,0.0,0,4.8807039,0.0,0.36496899,122.92693,5.4046321,383.11176,-9.2822924
2143,2143,165.3912,13.987387,4.6326261,0.0,0,4.8394642,0.0,0.36942902,122.96784,5.3553638,383.20697,-9.2823324
2145,2145,165.3916,14.037731,4.6837354,0.0,0,4.798224,0.0,0.37340203,122.95901,5.3143053,383.30219,-9.2811317
2147,2147,165.392,14.100168,4.7250223,0.0,0,4.7569842,0.0,0.37804511,122.93287,5.2710624,383.3974,-9.2803211
2149,2149,165.3924,14.141006,4.7665935,0.0,0,4.715744,0.0,0.38217881,122.83269,5.2286096,383.09189,-9.2797022
2151,2151,165.3928,14.198903,4.8200507,0.0,0,4.6745043,0.0,0.38656795,122.78233,5.1836557,382.68622,-9.2809095
2153,2153,165.3932,14.284222,4.8577251,0.0,0,4.6332641,0.0,0.39126042,122.91058,5.1381226,382.28055,-9.2819014
2155,2155,165.3936,14.350275,4.9010367,0.0,0,4.5920238,0.0,0.3951627,123.06244,5.0960493,381.87485,-9.2819004
2157,2157,165.394,14.383676,4.9514284,0.0,0,4.5507841,0.0,0.3997725,122.799,5.0497966,381.46918,-9.2815132
2159,2159,165.3944,14.428106,4.986589,0.0,0,4.5108657,0.0,0.40426204,122.58637,5.0066433,381.06351,-9.2806606
2161,2161,165.3948,14.503945,5.0331631,0.0,0,4.4716296,0.0,0.40799746,122.77535,4.963026,380.65784,-9.2795219
2163,2163,165.3952,14.598703,5.0811124,0.0,0,4.4323978,0.0,0.41302767,122.89637,4.9162583,380.25214,-9.2793245
2165,2165,165.3956,14.642795,5.1185374,0.0,0,4.3931656,0.0,0.41735181,122.77294,4.8724432,379.84647,-9.2800112
2167,2167,165.396,14.699836,5.1653872,0.0,0,4.3539338,0.0,0.42122951,122.78026,4.8288369,379.4408,-9.2807484
2169,2169,165.3964,14.756816,5.2111344,0.0,0,4.314702,0.0,0.42655265,122.58006,4.7877293,379.03513,-9.2816381
2171,2171,165.3968,14.825481,5.2482362,0.0,0,4.2754698,0.0,0.43043002,122.65849,4.743825,378.62943,-9.2810116
2173,2173,165.3972,14.902568,5.2924118,0.0,0,4.2362375,0.0,0.43435681,122.75742,4.6987944,378.22375,-9.2809296
2175,2175,165.3976,14.961284,5.3326011,0.0,0,4.1970053,0.0,0.43942517,122.69473,4.6580758,377.81808,-9.279932
2177,2177,165.398,15.008233,5.3739486,0.0,0,4.1577735,0.0,0.44314405,122.66898,4.6162062,377.41241,-9.2798204
2179,2179,165.3984,15.066814,5.4197135,0.0,0,4.1185417,0.0,0.4475233,122.60655,4.5752368,377.00671,-9.2806187
2181,2181,165.3988,15.139338,5.4584117,0.0,0,4.0793095,0.0,0.45251426,122.56537,4.5291176,376.60104,-9.2805786
2183,2183,165.3992,15.215981,5.5034523,0.0,0,4.0404716,0.0,0.45639053,122.71068,4.4887815,376.19537,-9.2808237
2185,2185,165.3996,15.292984,5.5445962,0.0,0,4.0030656,0.0,0.46100548,122.78467,4.4483299,375.7897,-9.2800817
2187,2187,165.4,15.322576,5.579246,0.0,0,3.9657533,0.0,0.46536595,122.50232,4.4090242,375.384,-9.2799473
2189,2189,165.4004,15.383774,5.6270318,0.0,0,3.9284413,0.0,0.46913764,122.50945,4.3645205,374.97833,-9.2799845
2191,2191,165.4008,15.456652,5.6627517,0.0,0,3.8911293,0.0,0.47382098,122.45999,4.3227444,374.57266,-9.2808714
2193,2193,165.4012,15.550588,5.6999998,0.0,0,3.8538175,0.0,0.47779611,122.70137,4.2840261,374.16699,-9.2807961
2195,2195,165.4016,15.62034,5.7511477,0.0,0,3.8165054,0.0,0.48241222,122.68946,4.2437005,373.76129,-9.2810421
2197,2197,165.402,15.659042,5.7828312,0.0,0,3.7791932,0.0,0.48708647,122.51468,4.2024884,373.35562,-9.2799559
2199,2199,165.4024,15.731808,5.8212242,0.0,0,3.7418811,0.0,0.49064943,122.49711,4.1614652,372.95282,-9.2795067
2201,2201,165.4028,15.8082,5.8688478,0.0,0,3.7045693,0.0,0.49545953,122.57219,4.1186128,372.55096,-9.2793951
2203,2203,165.4032,15.899617,5.8989649,0.0,0,3.6672573,0.0,0.49980935,122.70532,4.0827265,372.14911,-9.2806187
2205,2205,165.4036,15.956639,5.9413147,0.0,0,3.6299453,0.0,0.50349873,122.77905,4.0421171,371.74725,-9.2814322
2207,2207,165.404,16.005491,5.9884725,0.0,0,3.5926332,0.0,0.50890231,122.49499,4.0025439,371.3454,-9.2809019
2209,2209,165.4044,16.069273,6.0177436,0.0,0,3.5565166,0.0,0.5128904,122.45473,3.9619591,370.94354,-9.2797937
2211,2211,165.4048,16.170687,6.0610704,0.0,0,3.5210168,0.0,0.51666176,122.70925,3.9243252,370.54169,-9.2787371
2213,2213,165.4052,16.260393,6.1007957,0.0,0,3.4855206,0.0,0.52188629,122.73474,3.8883755,370.13983,-9.2790346
2215,2215,165.4056,16.307491,6.1323814,0.0,0,3.4500248,0.0,0.525446,122.74916,3.8454823,369.73798,-9.2803516
2217,2217,165.406,16.363884,6.1741071,0.0,0,3.4145288,0.0,0.52953547,122.62797,3.8077168,369.33612,-9.2813721
2219,2219,165.4064,16.435768,6.2111816,0.0,0,3.3790326,0.0,0.5346517,122.52228,3.7687554,368.93427,-9.2806435
2221,2221,165.4068,16.530596,6.2505236,0.0,0,3.3435369,0.0,0.53838468,122.80292,3.7327445,368.53241,-9.2804956
2223,2223,165.4072,16.621334,6.2912583,0.0,0,3.3080409,0.0,0.54302692,122.89387,3.6952155,368.13055,-9.2792892
2225,2225,165.4076,16.664352,6.3230233,0.0,0,3.2725446,0.0,0.54766649,122.66114,3.6565373,367.7287,-9.2777367
2227,2227,165.408,16.739586,6.3649178,0.0,0,3.2370486,0.0,0.55132216,122.76926,3.6204693,367.32684,-9.2779188
2229,2229,165.4084,16.828648,6.4011054,0.0,0,3.2015526,0.0,0.55598426,122.8643,3.5814631,366.92499,-9.2806263
2231,2231,165.4088,16.916801,6.43468,0.0,0,3.1660566,0.0,0.56046593,122.91097,3.5429533,366.52313,-9.2803183
2233,2233,165.4092,17.006157,6.4779339,0.0,0,3.1309152,0.0,0.56429738,123.09183,3.5095119,366.12128,-9.2799635
2235,2235,165.4096,17.07091,6.5105791,0.0,0,3.0970623,0.0,0.56904888,123.01719,3.4725864,365.71942,-9.2778387
2237,2237,165.41,17.144646,6.5456877,0.0,0,3.0632944,0.0,0.57303524,123.04501,3.4349511,365.31757,-9.2778921
2239,2239,165.4104,17.224052,6.5896568,0.0,0,3.0295265,0.0,0.57742482,123.04572,3.3985887,364.91571,-9.278966
2241,2241,165.4108,17.311918,6.6179209,0.0,0,2.9957583,0.0,0.5821265,123.16243,3.3604195,364.51385,-9.2789602
2243,2243,165.4112,17.400379,6.6544375,0.0,0,2.9619906,0.0,0.58569825,123.33113,3.3244975,364.112,-9.279213
2245,2245,165.4116,17.480682,6.6973481,0.0,0,2.9282222,0.0,0.59054947,123.22401,3.2880499,363.71014,-9.2801323
2247,2247,165.412,17.551302,6.7237253,0.0,0,2.8944542,0.0,0.59492493,123.19486,3.2526314,363.30829,-9.2793694
2249,2249,165.4124,17.622036,6.7606182,0.0,0,2.8606863,0.0,0.59833759,123.31139,3.2168851,362.9003,-9.2786398
2251,2251,165.4128,17.727793,6.8015065,0.0,0,2.8269184,0.0,0.60344946,123.37183,3.1797142,362.48972,-9.278451
2253,2253,165.4132,17.833755,6.829205,0.0,0,2.7931502,0.0,0.60748005,123.57949,3.1471703,362.0791,-9.2790422
2255,2255,165.4136,17.905516,6.8691368,0.0,0,2.7593822,0.0,0.61137801,123.62924,3.1107202,361.66849,-9.2799911
2257,2257,165.414,17.975054,6.9051738,0.0,0,2.7256143,0.0,0.61683226,123.45628,3.0763154,361.25787,-9.2799749
2259,2259,165.4144,18.052885,6.9363122,0.0,0,2.6929309,0.0,0.62045884,123.55688,3.0418162,360.84726,-9.2788897
2261,2261,165.4148,18.160616,6.9737191,0.0,0,2.6608074,0.0,0.62432808,123.79973,3.0072687,360.43665,-9.2787313
2263,2263,165.4152,18.263145,7.0045233,0.0,0,2.6286874,0.0,0.62951189,123.84007,2.9715569,360.02603,-9.2793341
2265,2265,165.4156,18.334227,7.0402341,0.0,0,2.5965672,0.0,0.63307029,123.91068,2.9347963,359.61542,-9.2792559
2267,2267,165.416,18.419161,7.0768242,0.0,0,2.5644474,0.0,0.63745737,123.919,2.9042244,359.2048,-9.2798843
2269,2269,165.4164,18.518518,7.1051764,0.0,0,2.5323272,0.0,0.64209163,123.96928,2.8690853,358.79422,-9.2799892
2271,2271,165.4168,18.616886,7.1432867,0.0,0,2.5002072,0.0,0.64568621,124.26257,2.8357165,358.38361,-9.278821
2273,2273,165.4172,18.7313,7.1772523,0.0,0,2.4680872,0.0,0.65063173,124.35624,2.8021631,357.97299,-9.2783203
2275,2275,165.4176,18.819736,7.2060819,0.0,0,2.4359674,0.0,0.6549657,124.41809,2.7716084,357.56238,-9.2784624
2277,2277,165.418,18.890671,7.2481365,0.0,0,2.4038472,0.0,0.65880513,124.44735,2.7355142,357.15176,-9.2773104
2279,2279,165.4184,18.99123,7.2734666,0.0,0,2.3717272,0.0,0.66343856,124.47117,2.7026796,356.74115,-9.2784853
2281,2281,165.4188,19.114391,7.3031096,0.0,0,2.3396072,0.0,0.66697812,124.80725,2.6697445,356.33054,-9.2790785
2283,2283,165.4192,19.221823,7.3463883,0.0,0,2.3078089,0.0,0.67149723,125.03017,2.6328309,355.91992,-9.2779312
2285,2285,165.4196,19.298525,7.3727927,0.0,0,2.2771804,0.0,0.67654771,124.91508,2.6025927,355.50931,-9.2778196
2287,2287,165.42,19.387821,7.408103,0.0,0,2.246628,0.0,0.68035233,124.94831,2.5641496,355.09872,-9.277607
2289,2289,165.4204,19.501358,7.4484644,0.0,0,2.2160764,0.0,0.68537319,125.02053,2.5341952,354.68811,-9.2776928
2291,2291,165.4208,19.629601,7.4695516,0.0,0,2.1855242,0.0,0.68939584,125.38934,2.4983115,354.2775,-9.2770615
2293,2293,165.4212,19.74317,7.5038648,0.0,0,2.1549723,0.0,0.69263613,125.64875,2.4689786,353.86688,-9.2776966
2295,2295,165.4216,19.822296,7.5416675,0.0,0,2.1244202,0.0,0.69823641,125.48037,2.4308796,353.45627,-9.2782536
2297,2297,165.422,19.905495,7.5678926,0.0,0,2.0938683,0.0,0.70229375,125.5216,2.4010322,353.04565,-9.2784653
2299,2299,165.4224,20.023121,7.6069565,0.0,0,2.0633163,0.0,0.70627528,125.72665,2.367238,352.84689,-9.2789688
2301,2301,165.4228,20.159447,7.6384497,0.0,0,2.0327644,0.0,0.71189976,125.84831,2.3353288,352.76221,-9.2771225
2303,2303,165.4232,20.261042,7.6650233,0.0,0,2.0022123,0.0,0.71525574,126.0999,2.3060727,352.67752,-9.278203
2305,2305,165.4236,20.353497,7.7002006,0.0,0,1.9716601,0.0,0.71915996,126.19486,2.2717168,352.59283,-9.2778187
2307,2307,165.424,20.458815,7.727375,0.0,0,1.9411081,0.0,0.72434425,126.15047,2.2408559,352.50815,-9.2780504
2309,2309,165.4244,20.590488,7.7604475,0.0,0,1.9115355,0.0,0.72761625,126.54659,2.2111866,352.42346,-9.2784405
2311,2311,165.4248,20.730951,7.796113,0.0,0,1.8824685,0.0,0.73239517,126.76685,2.1769619,352.33878,-9.2778921
2313,2313,165.4252,20.835304,7.8238711,0.0,0,1.8534043,0.0,0.73778021,126.77768,2.1454611,352.25409,-9.277215
2315,2315,165.4256,20.919725,7.8615308,0.0,0,1.8243403,0.0,0.74137914,126.83733,2.1156485,352.1694,-9.2768631
2317,2317,165.426,21.038805,7.8886361,0.0,0,1.7952764,0.0,0.7460072,126.94072,2.0830922,352.08475,-9.2770815
2319,2319,165.4264,21.164389,7.9130211,0.0,0,1.7662123,0.0,0.75004601,127.2077,2.053375,352.00006,-9.2770672
2321,2321,165.4268,21.310917,7.9514322,0.0,0,1.7371484,0.0,0.75382185,127.60798,2.0240099,351.91537,-9.2777185
2323,2323,165.4272,21.414917,7.9779072,0.0,0,1.7080843,0.0,0.75889599,127.64064,1.9902791,351.83069,-9.2783308
2325,2325,165.4276,21.518808,8.007987,0.0,0,1.6790204,0.0,0.76301748,127.72115,1.957968,351.746,-9.2766247
2327,2327,165.428,21.638493,8.0468388,0.0,0,1.6499563,0.0,0.76760209,127.81806,1.9291828,351.66132,-9.2763329
2329,2329,165.4284,21.777481,8.0670128,0.0,0,1.6208923,0.0,0.77216744,127.99774,1.8972074,351.57663,-9.2767057
2331,2331,165.4288,21.926735,8.0973539,0.0,0,1.5918283,0.0,0.77543747,128.50368,1.8654157,351.49194,-9.2773428
2333,2333,165.4292,22.041677,8.1362286,0.0,0,1.5630548,0.0,0.78078294,128.49982,1.8354177,351.40726,-9.276886
2335,2335,165.4296,22.150852,8.1580133,0.0,0,1.5353373,0.0,0.78532559,128.58307,1.8054451,351.32257,-9.2775192
2337,2337,165.43,22.284618,8.191864,0.0,0,1.5076892,0.0,0.7887274,128.88338,1.77193,351.23788,-9.2775478
2339,2339,165.4304,22.442574,8.2247524,0.0,0,1.4800413,0.0,0.79435068,129.04764,1.743623,351.1532,-9.2770729
2341,2341,165.4308,22.579172,8.2463741,0.0,0,1.4523933,0.0,0.79817808,129.34453,1.7128412,351.06851,-9.2767
2343,2343,165.4312,22.697529,8.280673,0.0,0,1.4247453,0.0,0.80191088,129.5365,1.684916,350.98383,-9.2765055
2345,2345,165.4316,22.816734,8.3106947,0.0,0,1.3970973,0.0,0.80781704,129.43748,1.6570125,350.89914,-9.2756453
2347,2347,165.432,22.949684,8.3366365,0.0,0,1.3694494,0.0,0.81123954,129.80066,1.6275347,350.81445,-9.2759781
2349,2349,165.4324,23.097908,8.3698635,0.0,0,1.3418013,0.0,0.81540799,130.03514,1.5977201,351.04944,-9.2759876
2351,2351,165.4328,23.237232,8.3950357,0.0,0,1.3141534,0.0,0.82077765,130.15942,1.5677699,351.49756,-9.27563
2353,2353,165.4332,23.367825,8.4257317,0.0,0,1.2865053,0.0,0.8239454,130.46336,1.5411839,351.94568,-9.2759857
2355,2355,165.4336,23.497263,8.4553137,0.0,0,1.2588574,0.0,0.82872725,130.54277,1.5116792,352.3938,-9.2751102
2357,2357,165.434,23.637415,8.477644,0.0,0,1.2312094,0.0,0.83331889,130.70761,1.4855136,352.84192,-9.2761145
2359,2359,165.4344,23.786758,8.5120916,0.0,0,1.2044513,0.0,0.83682919,131.08589,1.4556755,353.29001,-9.2774687
2361,2361,165.4348,23.946627,8.5389471,0.0,0,1.1781524,0.0,0.84204537,131.29836,1.426772,353.73813,-9.2767382
2363,2363,165.4352,24.104504,8.5635118,0.0,0,1.1518564,0.0,0.8463226,131.5713,1.3972777,354.18625,-9.2750692
2365,2365,165.4356,24.226624,8.6001749,0.0,0,1.1255604,0.0,0.85014665,131.77957,1.3674049,354.63437,-9.2758989
2367,2367,165.436,24.365557,8.6197433,0.0,0,1.0992644,0.0,0.85522729,131.81122,1.3397789,355.08249,-9.2763205
2369,2369,165.4364,24.53631,8.6446085,0.0,0,1.0729684,0.0,0.85849148,132.30508,1.3146571,355.53058,-9.2757568
2371,2371,165.4368,24.708126,8.6811008,0.0,0,1.0466723,0.0,0.86312211,132.65878,1.2850772,355.9787,-9.2753248
2373,2373,165.4372,24.855677,8.7001381,0.0,0,1.0203763,0.0,0.86798602,132.82326,1.2548645,356.42682,-9.275219
2375,2375,165.4376,24.988075,8.727622,0.0,0,0.99408036,0.0,0.87116945,133.06903,1.2288702,356.87494,-9.2744751
2377,2377,165.438,25.14138,8.7632313,0.0,0,0.96778435,0.0,0.87663317,133.10316,1.1978209,357.32306,-9.2751989
2379,2379,165.4384,25.316877,8.7811756,0.0,0,0.94148839,0.0,0.88091153,133.45741,1.1729672,357.77115,-9.2757711
2381,2381,165.4388,25.497572,8.8115854,0.0,0,0.91519243,0.0,0.88408697,134.01149,1.1450762,358.21927,-9.2756014
2383,2383,165.4392,25.65556,8.8399105,0.0,0,0.88916051,0.0,0.88970482,134.07832,1.1173245,358.66739,-9.2747793
2385,2385,165.4396,25.793667,8.8596725,0.0,0,0.86408949,0.0,0.89330357,134.34801,1.0946245,359.11551,-9.2739582
2387,2387,165.44,25.954512,8.8922729,0.0,0,0.83908135,0.0,0.89713728,134.63174,1.0654167,359.5636,-9.2742558
2389,2389,165.4404,26.149664,8.9179249,0.0,0,0.81407332,0.0,0.90305346,134.81509,1.0396154,360.01172,-9.2753057
2391,2391,165.4408,26.324724,8.9413271,0.0,0,0.78906536,0.0,0.90633041,135.33757,1.0105425,360.45984,-9.275445
2393,2393,165.4412,26.470608,8.9700584,0.0,0,0.7640574,0.0,0.91030735,135.57753,0.98469263,360.90796,-9.2739429
2395,2395,165.4416,26.618139,8.9904842,0.0,0,0.73904938,0.0,0.91547734,135.56223,0.95715523,361.35608,-9.2733946
2397,2397,165.442,26.79307,9.0181379,0.0,0,0.71404135,0.0,0.91827625,136.09946,0.92959988,361.80417,-9.2740736
2399,2399,165.4424,26.992371,9.0445881,0.0,0,0.68903339,0.0,0.92302245,136.44331,0.9026078,361.93265,-9.2737598
2401,2401,165.4428,27.165377,9.0646553,0.0,0,0.66402543,0.0,0.92786521,136.69832,0.87816721,361.79956,-9.2738523
2403,2403,165.4432,27.319147,9.099287,0.0,0,0.63901734,0.0,0.93154341,136.97066,0.85102171,361.66647,-9.2739363
2405,2405,165.4436,27.470924,9.1218414,0.0,0,0.61400938,0.0,0.93677747,136.99323,0.82645351,361.53339,-9.2744827
2407,2407,165.444,27.656378,9.1414814,0.0,0,0.58900136,0.0,0.94041502,137.38933,0.80131048,361.40033,-9.2743521
2409,2409,165.4444,27.856716,9.1747551,0.0,0,0.56478846,0.0,0.94410199,137.90883,0.77762097,361.26724,-9.2733078
2411,2411,165.4448,28.040661,9.1890965,0.0,0,0.54098594,0.0,0.94859445,138.2038,0.74832791,361.13416,-9.2722082
2413,2413,165.4452,28.199043,9.2091093,0.0,0,0.51718587,0.0,0.95149738,138.55576,0.72338909,361.0011,-9.2719555
2415,2415,165.4456,28.362587,9.2435865,0.0,0,0.49338591,0.0,0.95630598,138.70128,0.70001084,360.86801,-9.2738209
2417,2417,165.446,28.542299,9.2610626,0.0,0,0.4695859,0.0,0.96125722,138.88835,0.67296177,360.73492,-9.2741966
2419,2419,165.4464,28.739578,9.2885551,0.0,0,0.44578591,0.0,0.96458018,139.36948,0.64848006,360.60184,-9.2740221
2421,2421,165.4468,28.927645,9.3194475,0.0,0,0.42198589,0.0,0.97003734,139.51909,0.6271261,360.46878,-9.2726936
2423,2423,165.4472,29.072201,9.3310852,0.0,0,0.39818591,0.0,0.9736523,139.74529,0.60328382,360.33569,-9.272275
2425,2425,165.4476,29.244085,9.3558874,0.0,0,0.37438589,0.0,0.97619045,140.15485,0.57614607,360.20261,-9.2729731
2427,2427,165.448,29.436218,9.3797626,0.0,0,0.35058588,0.0,0.98164117,140.35728,0.55504751,360.06955,-9.2738028
2429,2429,165.4484,29.639118,9.3964195,0.0,0,0.32678592,0.0,0.98483324,140.85422,0.5334962,359.93646,-9.2731886