File: clean data/testID_0192.csv
level_0,index,Time(sec),Force(kN),Jaw(mm),PowAngle(deg),Power(W),Pram,PTemp,Strain,Stress(MPa),Stroke(mm),TC1(C),wedge(mm)
1801,1801,145.3497,2.4825668,0.036477689,0.0,0,8.2405367,0.0,0.0024729387,31.166643,8.9317865,290.71097,-9.3238096
1802,1802,145.3499,3.1551318,0.044020846,0.0,0,8.2127056,0.0,0.0030348825,37.67981,8.8989058,290.73065,-9.3236322
1803,1803,145.3501,4.7662706,0.066625498,0.0,0,8.1848736,0.0,0.0038730022,55.982059,8.8696165,290.75037,-9.3237638
1804,1804,145.3503,6.3624277,0.081516437,0.0,0,8.1570406,0.0,0.0051583806,76.86425,8.8457565,290.77005,-9.3236027
1805,1805,145.3505,7.1877007,0.10027011,0.0,0,8.1292095,0.0,0.0067721945,89.4011,8.82407,290.78973,-9.3225222
1806,1806,145.3507,7.4759035,0.12040792,0.0,0,8.1013775,0.0,0.0076516205,93.921494,8.8000908,290.80942,-9.3209429
1807,1807,145.3509,7.7460661,0.13476741,0.0,0,8.0735445,0.0,0.0086327558,96.951134,8.7727976,290.8291,-9.3195267
1808,1808,145.3511,8.199667,0.17485969,0.0,0,8.0462675,0.0,0.011418925,102.17748,8.7438173,290.84882,-9.3190041
1809,1809,145.3513,8.3944931,0.23544107,0.0,0,8.0196619,0.0,0.014904689,105.04572,8.714138,290.8685,-9.3192549
1810,1810,145.3515,8.4031124,0.27524793,0.0,0,7.993176,0.0,0.017798102,105.04964,8.6782436,290.88818,-9.3193207
1811,1811,145.3517,8.6807604,0.30091745,0.0,0,7.9666953,0.0,0.020188162,107.26794,8.6395321,290.90787,-9.3192701
1812,1812,145.3519,9.2587013,0.32970521,0.0,0,7.9402156,0.0,0.021742996,113.88977,8.6022997,290.92755,-9.319972
1813,1813,145.3521,9.6717739,0.35826465,0.0,0,7.9137354,0.0,0.02347523,119.51653,8.5649462,290.94727,-9.3205299
1814,1814,145.3523,9.8513241,0.39602461,0.0,0,7.8872552,0.0,0.026476664,121.74694,8.5288973,290.96695,-9.3197212
1815,1815,145.3525,10.138099,0.42947137,0.0,0,7.860775,0.0,0.028700104,124.60214,8.49473,290.98663,-9.3182564
1816,1816,145.3527,10.438529,0.43759471,0.0,0,7.8342953,0.0,0.029227125,128.44617,8.4634018,291.02725,-9.3168459
1817,1817,145.3529,10.437819,0.44899151,0.0,0,7.8078156,0.0,0.03031745,129.17325,8.4329443,291.06787,-9.3158064
1818,1818,145.3531,10.181148,0.48389375,0.0,0,7.7813349,0.0,0.032401875,126.13511,8.4035997,291.10849,-9.3157091
1819,1819,145.3533,10.105109,0.51856279,0.0,0,7.7548552,0.0,0.03447473,124.21782,8.3797112,291.14908,-9.3164949
1820,1820,145.3535,10.378861,0.5401358,0.0,0,7.728375,0.0,0.036576122,126.48732,8.3565741,291.1897,-9.3180122
1821,1821,145.3537,10.738468,0.55053043,0.0,0,7.7018952,0.0,0.037523881,130.80951,8.333704,291.23032,-9.3195076
1822,1822,145.3539,10.935207,0.55617058,0.0,0,7.675415,0.0,0.037408531,133.8222,8.31112,291.27094,-9.3195992
1823,1823,145.3541,10.998145,0.57580948,0.0,0,7.6489348,0.0,0.038860023,134.71677,8.2871742,291.31155,-9.3182821
1824,1824,145.3543,11.049717,0.61166757,0.0,0,7.6224551,0.0,0.041398898,134.88023,8.261796,291.35214,-9.3174591
1825,1825,145.3545,11.058479,0.64407486,0.0,0,7.5959754,0.0,0.043266326,134.88205,8.2373161,291.39276,-9.3174448
1826,1826,145.3547,10.992069,0.6677292,0.0,0,7.5694952,0.0,0.04521966,133.99521,8.2114897,291.43338,-9.3167048
1827,1827,145.3549,10.97205,0.69430661,0.0,0,7.543015,0.0,0.047299579,133.26857,8.1835032,291.474,-9.3166685
1828,1828,145.3551,11.100543,0.72716826,0.0,0,7.5165353,0.0,0.0490379,134.17383,8.1577024,291.51462,-9.3168554
1829,1829,145.3553,11.299562,0.75850999,0.0,0,7.4900556,0.0,0.05133282,136.10738,8.1321259,291.55521,-9.316678
1830,1830,145.3555,11.441849,0.78350562,0.0,0,7.4635754,0.0,0.053628001,137.75435,8.1048422,291.59583,-9.3164845
1831,1831,145.3557,11.501441,0.80645061,0.0,0,7.4370952,0.0,0.054863047,138.55034,8.0750437,291.63644,-9.316124
1832,1832,145.3559,11.552917,0.82843769,0.0,0,7.410615,0.0,0.056325924,138.9379,8.0460539,291.67706,-9.3168087
1833,1833,145.3561,11.599344,0.85490483,0.0,0,7.384666,0.0,0.05860455,139.19452,8.0186501,291.71768,-9.317399
1834,1834,145.3563,11.579365,0.89263338,0.0,0,7.3593607,0.0,0.060808346,138.85643,7.992311,291.75827,-9.317111
1835,1835,145.3565,11.523246,0.92398083,0.0,0,7.3341718,0.0,0.062881969,137.90929,7.9668679,291.79889,-9.317193
1836,1836,145.3567,11.552847,0.93828821,0.0,0,7.3089876,0.0,0.064668328,137.74745,7.939642,291.83951,-9.3175611
1837,1837,145.3569,11.724466,0.95491844,0.0,0,7.2838035,0.0,0.065676115,139.36139,7.9157972,291.88013,-9.3174629
1838,1838,145.3571,11.949723,0.97449529,0.0,0,7.2586198,0.0,0.066692457,141.85004,7.8925624,291.92075,-9.3171568
1839,1839,145.3573,12.048606,0.99174333,0.0,0,7.2334356,0.0,0.068397693,143.18385,7.8677773,291.96133,-9.3164663
1840,1840,145.3575,11.974787,1.0229453,0.0,0,7.2082515,0.0,0.070336126,142.44046,7.8449244,292.00195,-9.3161459
1841,1841,145.3577,11.906099,1.0543208,0.0,0,7.1830673,0.0,0.072156139,141.25056,7.8193865,292.04257,-9.3163033
1842,1842,145.3579,11.931196,1.070798,0.0,0,7.1578832,0.0,0.073954836,141.04588,7.7945008,292.08319,-9.3159552
1843,1843,145.3581,11.98375,1.0955672,0.0,0,7.132699,0.0,0.075721867,141.4431,7.7706494,292.12381,-9.3157454
1844,1844,145.3583,12.008953,1.1261139,0.0,0,7.1075149,0.0,0.077288657,141.5519,7.7451906,292.1644,-9.3159266
1845,1845,145.3585,12.057917,1.1436357,0.0,0,7.0823312,0.0,0.078995809,141.64854,7.7219248,292.20502,-9.3159695
1846,1846,145.3587,12.186725,1.1660304,0.0,0,7.0571475,0.0,0.080844969,142.7108,7.6985159,292.24564,-9.3162794
1847,1847,145.3589,12.339149,1.1924845,0.0,0,7.0319633,0.0,0.082173891,144.3544,7.6743073,292.28625,-9.3158092
1848,1848,145.3591,12.398967,1.2067077,0.0,0,7.0067787,0.0,0.083535723,145.20442,7.6507311,292.32687,-9.3149052
1849,1849,145.3593,12.329142,1.2347974,0.0,0,6.981595,0.0,0.08576154,144.39558,7.6255188,292.36746,-9.3148499
1850,1850,145.3595,12.239284,1.2736987,0.0,0,6.9564114,0.0,0.087915652,142.91806,7.5992632,292.40808,-9.315135
1851,1851,145.3597,12.236259,1.2946113,0.0,0,6.9312272,0.0,0.08979848,142.33861,7.57335,292.4487,-9.31528
1852,1852,145.3599,12.330576,1.316119,0.0,0,6.9060431,0.0,0.091874585,142.97746,7.5469642,292.48932,-9.3159952
1853,1853,145.3601,12.4425,1.3427916,0.0,0,6.8808589,0.0,0.093271405,144.08495,7.5209436,292.52994,-9.3163586
1854,1854,145.3603,12.520357,1.3584496,0.0,0,6.8556757,0.0,0.094437532,144.83691,7.4956665,292.57053,-9.3156843
1855,1855,145.3605,12.586769,1.3825654,0.0,0,6.8304915,0.0,0.096606746,145.23193,7.4699345,292.61115,-9.3153419
1856,1856,145.3607,12.64518,1.4153965,0.0,0,6.8053074,0.0,0.098551609,145.69785,7.4461317,292.65176,-9.3155918
1857,1857,145.3609,12.674997,1.4337835,0.0,0,6.7801232,0.0,0.099881768,145.99069,7.4208961,292.69238,-9.3158579
1858,1858,145.3611,12.664422,1.4545543,0.0,0,6.7554412,0.0,0.10192225,145.65977,7.396688,292.733,-9.3158312
1859,1859,145.3613,12.641831,1.4853636,0.0,0,6.7313666,0.0,0.10382832,145.10838,7.374814,292.77359,-9.3159685
1860,1860,145.3615,12.648794,1.5057923,0.0,0,6.7074018,0.0,0.10513202,144.91826,7.3507009,292.81421,-9.3160057
1861,1861,145.3617,12.70413,1.5250119,0.0,0,6.6834412,0.0,0.10714541,145.25067,7.3244171,292.85483,-9.3151379
1862,1862,145.3619,12.791668,1.5504421,0.0,0,6.6594815,0.0,0.10891149,145.93755,7.3013773,292.89545,-9.3143635
1863,1863,145.3621,12.886406,1.569221,0.0,0,6.6355214,0.0,0.10988743,146.81586,7.2788191,292.93607,-9.3144598
1864,1864,145.3623,12.946718,1.5902971,0.0,0,6.6115613,0.0,0.11189231,147.3278,7.2548938,292.97665,-9.3145189
1865,1865,145.3625,12.967203,1.6212301,0.0,0,6.5876012,0.0,0.11420861,147.29158,7.2309284,293.01199,-9.3150349
1866,1866,145.3627,12.968082,1.6479706,0.0,0,6.5636415,0.0,0.11574826,147.08904,7.2074809,292.99966,-9.3157511
1867,1867,145.3629,12.955447,1.6700954,0.0,0,6.5396814,0.0,0.11782059,146.67821,7.1846218,292.98737,-9.3159971
1868,1868,145.3631,12.965943,1.6944784,0.0,0,6.5157218,0.0,0.11985381,146.40218,7.1618838,292.97507,-9.3159323
1869,1869,145.3633,13.020855,1.7166969,0.0,0,6.4917617,0.0,0.12103384,146.72313,7.1370234,292.96277,-9.3152809
1870,1870,145.3635,13.094968,1.7388039,0.0,0,6.467802,0.0,0.12293939,147.21848,7.1101294,292.95044,-9.3155966
1871,1871,145.3637,13.155764,1.7652448,0.0,0,6.4438419,0.0,0.12520298,147.61229,7.0855665,292.93814,-9.3154221
1872,1872,145.3639,13.200825,1.7919208,0.0,0,6.4198813,0.0,0.12664691,147.99001,7.0619445,292.92584,-9.3148756
1873,1873,145.3641,13.236042,1.8139756,0.0,0,6.3959212,0.0,0.12847187,148.1496,7.0372896,292.91354,-9.3150282
1874,1874,145.3643,13.253077,1.8356723,0.0,0,6.3719611,0.0,0.13059668,148.00763,7.013401,292.90121,-9.3152514
1875,1875,145.3645,13.256978,1.8631359,0.0,0,6.3480015,0.0,0.13207915,147.84343,6.9870729,292.88892,-9.3157148
1876,1876,145.3647,13.276922,1.8874992,0.0,0,6.3240414,0.0,0.13390329,147.76663,6.9602809,292.87662,-9.3152428
1877,1877,145.3649,13.34195,1.9067217,0.0,0,6.3000817,0.0,0.13603058,148.06195,6.9396458,292.86429,-9.3152609
1878,1878,145.3651,13.417122,1.9318308,0.0,0,6.2761216,0.0,0.13745083,148.75262,6.9196901,292.85199,-9.3151474
1879,1879,145.3653,13.466042,1.955018,0.0,0,6.252162,0.0,0.13897698,149.16954,6.894484,292.83969,-9.3151941
1880,1880,145.3655,13.481617,1.9746974,0.0,0,6.2282019,0.0,0.1411349,149.08592,6.8662586,292.82739,-9.3163824
1881,1881,145.3657,13.485689,2.0050585,0.0,0,6.2042418,0.0,0.14306401,148.84554,6.841794,292.81506,-9.3165722
1882,1882,145.3659,13.50796,2.0325928,0.0,0,6.1802816,0.0,0.14484027,148.75073,6.8188262,292.80276,-9.3160315
1883,1883,145.3661,13.528944,2.0492315,0.0,0,6.1568022,0.0,0.14686699,148.68646,6.7953401,292.79047,-9.3158903
1884,1884,145.3663,13.556479,2.075227,0.0,0,6.1339045,0.0,0.14864273,148.70372,6.7712178,292.77817,-9.3162012
1885,1885,145.3665,13.619001,2.1029112,0.0,0,6.1111116,0.0,0.15026399,149.04166,6.7453704,292.76584,-9.3161983
1886,1886,145.3667,13.704355,2.1205425,0.0,0,6.0883236,0.0,0.15227778,149.64369,6.7216454,292.75354,-9.3164387
1887,1887,145.3669,13.765369,2.1482453,0.0,0,6.0655355,0.0,0.15435518,150.07664,6.6977625,292.74124,-9.316577
1888,1888,145.3671,13.779451,2.1781383,0.0,0,6.042748,0.0,0.15609917,150.05431,6.6717095,292.72894,-9.3160114
1889,1889,145.3673,13.767911,2.1940112,0.0,0,6.0199599,0.0,0.15789814,149.70734,6.6474619,292.71661,-9.3162317
1890,1890,145.3675,13.765475,2.2190044,0.0,0,5.9971714,0.0,0.15995215,149.33488,6.6222463,292.70432,-9.3163052
1891,1891,145.3677,13.788204,2.249738,0.0,0,5.9743834,0.0,0.16169216,149.27283,6.5971246,292.69202,-9.3158855
1892,1892,145.3679,13.832566,2.2663476,0.0,0,5.9515953,0.0,0.16341583,149.47066,6.5734019,292.67969,-9.3153124
1893,1893,145.3681,13.892915,2.2902169,0.0,0,5.9288073,0.0,0.16561715,149.73503,6.5494137,292.66739,-9.3153181
1894,1894,145.3683,13.968083,2.3196623,0.0,0,5.9060197,0.0,0.16730115,150.25526,6.5248494,292.65509,-9.3160772
1895,1895,145.3685,14.044729,2.3348911,0.0,0,5.8832316,0.0,0.16876417,150.89075,6.5008473,292.64279,-9.3165808
1896,1896,145.3687,14.088466,2.3585904,0.0,0,5.8604436,0.0,0.17105503,151.1581,6.4747515,292.63046,-9.3164234
1897,1897,145.3689,14.091205,2.3912451,0.0,0,5.8376555,0.0,0.17298627,150.9744,6.4502726,292.61816,-9.315958
1898,1898,145.3691,14.082133,2.4093475,0.0,0,5.814867,0.0,0.17454451,150.60687,6.4266505,292.60587,-9.3159008
1899,1899,145.3693,14.09416,2.4313521,0.0,0,5.792079,0.0,0.1768347,150.30226,6.4025154,292.59357,-9.3159008
1900,1900,145.3695,14.137177,2.4629414,0.0,0,5.7692914,0.0,0.1787641,150.41341,6.3768234,292.58124,-9.3156796
1901,1901,145.3697,14.194774,2.4828827,0.0,0,5.7465034,0.0,0.18026231,150.81601,6.3520942,292.56894,-9.3156528
1902,1902,145.3699,14.253602,2.5059724,0.0,0,5.7237153,0.0,0.1827219,151.06155,6.3306837,292.55664,-9.3158045
1903,1903,145.3701,14.303789,2.5376434,0.0,0,5.7009273,0.0,0.18488513,151.26941,6.3053813,292.54434,-9.3150806
1904,1904,145.3703,14.348279,2.5576019,0.0,0,5.6781397,0.0,0.18622524,151.52623,6.2792268,292.53201,-9.3143616
1905,1905,145.3705,14.383668,2.5785434,0.0,0,5.6553516,0.0,0.18849261,151.57327,6.2559586,292.51971,-9.3144817
1906,1906,145.3707,14.396179,2.6094682,0.0,0,5.6325636,0.0,0.19075954,151.40686,6.2314711,292.50742,-9.3143425
1907,1907,145.3709,14.403796,2.6321211,0.0,0,5.6097751,0.0,0.19220299,151.29091,6.2051997,292.49509,-9.3150082
1908,1908,145.3711,14.426736,2.6528664,0.0,0,5.5874414,0.0,0.19448334,151.15477,6.1804042,292.48279,-9.3158293
1909,1909,145.3713,14.465053,2.6803749,0.0,0,5.5656581,0.0,0.19672,151.11891,6.1582274,292.47049,-9.3157644
1910,1910,145.3715,14.517457,2.7014682,0.0,0,5.5439734,0.0,0.19794323,151.48257,6.1334434,292.45819,-9.3161249
1911,1911,145.3717,14.571746,2.7214601,0.0,0,5.5222936,0.0,0.19999447,151.78467,6.1087132,292.44586,-9.3154802
1912,1912,145.3719,14.614051,2.7483234,0.0,0,5.5006132,0.0,0.20229,151.89752,6.0874262,292.43356,-9.3143625
1913,1913,145.3721,14.647166,2.7715735,0.0,0,5.4789333,0.0,0.2036144,152.09613,6.0618162,292.42126,-9.3142099
1914,1914,145.3723,14.675653,2.7917089,0.0,0,5.457253,0.0,0.20560654,152.09613,6.0377402,292.40897,-9.3135929
1915,1915,145.3725,14.701019,2.81584,0.0,0,5.4355731,0.0,0.20792082,151.95879,6.0161548,292.39886,-9.3138638
1916,1916,145.3727,14.734859,2.8415,0.0,0,5.4138932,0.0,0.209364,152.08209,5.9915299,292.39764,-9.3148317
1917,1917,145.3729,14.781759,2.8650899,0.0,0,5.3922133,0.0,0.21146093,152.28696,5.9653692,292.39639,-9.3153667
1918,1918,145.3731,14.820673,2.888833,0.0,0,5.370533,0.0,0.21394342,152.32738,5.9402871,292.39517,-9.3161163
1919,1919,145.3733,14.848337,2.9156704,0.0,0,5.3488531,0.0,0.21551777,152.37373,5.9171395,292.39395,-9.3161917
1920,1920,145.3735,14.879881,2.9387467,0.0,0,5.3271732,0.0,0.2174948,152.40594,5.8940964,292.3927,-9.3159361
1921,1921,145.3737,14.914112,2.9597802,0.0,0,5.3054934,0.0,0.2199104,152.35832,5.8705535,292.39148,-9.3158073
1922,1922,145.3739,14.947287,2.9889967,0.0,0,5.283813,0.0,0.22165202,152.38779,5.844677,292.39026,-9.3158007
1923,1923,145.3741,14.975871,3.0138891,0.0,0,5.2621331,0.0,0.22356729,152.41339,5.8231063,292.38901,-9.3150663
1924,1924,145.3743,15.018919,3.0321259,0.0,0,5.2404532,0.0,0.22588186,152.46034,5.8006911,292.38779,-9.3136902
1925,1925,145.3745,15.076071,3.0598576,0.0,0,5.2187734,0.0,0.2277192,152.72708,5.7750697,292.38657,-9.3136473
1926,1926,145.3747,15.112818,3.083987,0.0,0,5.1970935,0.0,0.22942451,152.94695,5.7523646,292.38531,-9.3145103
1927,1927,145.3749,15.141438,3.0996523,0.0,0,5.1754136,0.0,0.2315255,152.95351,5.7272177,292.38409,-9.3151274
1928,1928,145.3751,15.172156,3.1274889,0.0,0,5.1537333,0.0,0.23349936,152.91959,5.7024813,292.38287,-9.3154926
1929,1929,145.3753,15.197619,3.155587,0.0,0,5.1320534,0.0,0.23527943,152.88863,5.6804705,292.38162,-9.3157234
1930,1930,145.3755,15.226178,3.1716962,0.0,0,5.110373,0.0,0.2374226,152.82907,5.6570835,292.3804,-9.3164263
1931,1931,145.3757,15.254239,3.1973076,0.0,0,5.0886931,0.0,0.23950022,152.8136,5.6310439,292.37918,-9.3164654
1932,1932,145.3759,15.285346,3.2261791,0.0,0,5.0670133,0.0,0.24119946,152.8663,5.6078911,292.37793,-9.3153906
1933,1933,145.3761,15.337485,3.2422409,0.0,0,5.0457678,0.0,0.24325518,152.98743,5.5858097,292.37671,-9.3148556
1934,1934,145.3763,15.398349,3.2677579,0.0,0,5.0250483,0.0,0.24555185,153.19893,5.5647569,292.37549,-9.3152084
1935,1935,145.3765,15.446127,3.2975428,0.0,0,5.0044241,0.0,0.24734896,153.46259,5.5411353,292.37427,-9.3145771
1936,1936,145.3767,15.477252,3.3119111,0.0,0,4.9838037,0.0,0.24912606,153.56206,5.5153608,292.37302,-9.3140078
1937,1937,145.3769,15.495394,3.335748,0.0,0,4.9631839,0.0,0.25145575,153.41356,5.4915347,292.3718,-9.3144684
1938,1938,145.3771,15.509708,3.3672695,0.0,0,4.9425635,0.0,0.25335246,153.21629,5.4660158,292.37057,-9.3146572
1939,1939,145.3773,15.529305,3.3832884,0.0,0,4.9219437,0.0,0.25509781,153.10753,5.4422951,292.36932,-9.3153925
1940,1940,145.3775,15.568705,3.4055407,0.0,0,4.9013238,0.0,0.25752735,153.13519,5.4205794,292.3681,-9.3157787
1941,1941,145.3777,15.612604,3.4356873,0.0,0,4.8807039,0.0,0.25939333,153.3102,5.398212,292.36688,-9.3156986
1942,1942,145.3779,15.663663,3.4505916,0.0,0,4.8600836,0.0,0.26091462,153.57179,5.3746901,292.36563,-9.3158751
1943,1943,145.3781,15.715383,3.4724822,0.0,0,4.8394637,0.0,0.26339042,153.71027,5.3497272,292.36441,-9.3156233
1944,1944,145.3783,15.749151,3.5039501,0.0,0,4.8188438,0.0,0.26539963,153.7672,5.3267174,292.36319,-9.3156672
1945,1945,145.3785,15.785193,3.5215645,0.0,0,4.798224,0.0,0.26689351,153.84949,5.3035574,292.36194,-9.3153934
1946,1946,145.3787,15.823825,3.5430992,0.0,0,4.7776036,0.0,0.26949498,153.76329,5.2804689,292.36072,-9.3147926
1947,1947,145.3789,15.850226,3.5746112,0.0,0,4.7569838,0.0,0.27172878,153.72385,5.257411,292.3595,-9.3150949
1948,1948,145.3791,15.872759,3.5942862,0.0,0,4.7363639,0.0,0.27313307,153.77884,5.2354755,292.35825,-9.3149052
1949,1949,145.3793,15.901281,3.6130829,0.0,0,4.7157435,0.0,0.27552852,153.63364,5.2114239,292.35703,-9.3145676
1950,1950,145.3795,15.938559,3.6411695,0.0,0,4.6951237,0.0,0.27776149,153.6026,5.186265,292.3558,-9.3147564
1951,1951,145.3797,15.981864,3.6609175,0.0,0,4.6745038,0.0,0.27897501,153.84138,5.1648245,292.35455,-9.3155651
1952,1952,145.3799,16.02907,3.6789958,0.0,0,4.6538839,0.0,0.28123781,153.93622,5.1431603,292.35333,-9.3159304
1953,1953,145.3801,16.072821,3.7059758,0.0,0,4.6332641,0.0,0.28360122,154.05159,5.1213899,292.35211,-9.3152466
1954,1954,145.3803,16.108109,3.727088,0.0,0,4.6126437,0.0,0.2848511,154.19827,5.0982614,292.35086,-9.3148756
1955,1955,145.3805,16.149582,3.7444193,0.0,0,4.5920234,0.0,0.28696549,154.18187,5.0750923,292.34964,-9.315032
1956,1956,145.3807,16.189205,3.7696223,0.0,0,4.5714035,0.0,0.28937873,154.20377,5.0536175,292.34842,-9.3155413
1957,1957,145.3809,16.219311,3.7936528,0.0,0,4.5507836,0.0,0.29082477,154.32326,5.0292273,292.34717,-9.3163671
1958,1958,145.3811,16.244104,3.8135662,0.0,0,4.5305758,0.0,0.29300335,154.25487,5.004838,292.34595,-9.3170023
1959,1959,145.3813,16.275234,3.8373871,0.0,0,4.5108657,0.0,0.29549566,154.1476,4.9854178,292.34473,-9.3170538
1960,1960,145.3815,16.301439,3.8616269,0.0,0,4.4912457,0.0,0.29688111,154.19775,4.9656243,292.34351,-9.3165026
1961,1961,145.3817,16.334776,3.8820829,0.0,0,4.4716296,0.0,0.29898775,154.16685,4.9438009,292.34225,-9.3159218
1962,1962,145.3819,16.383953,3.904038,0.0,0,4.4520135,0.0,0.30157843,154.18742,4.9207726,292.34103,-9.3152142
1963,1963,145.3821,16.432961,3.9291561,0.0,0,4.4323974,0.0,0.30309781,154.44006,4.8992796,292.33981,-9.3149843
1964,1964,145.3823,16.483055,3.9495828,0.0,0,4.4127812,0.0,0.30495974,154.655,4.8769174,292.33856,-9.3147593
1965,1965,145.3825,16.522377,3.9672272,0.0,0,4.3931651,0.0,0.30731565,154.66393,4.85432,292.33975,-9.3143988
1966,1966,145.3827,16.548351,3.992162,0.0,0,4.3735495,0.0,0.30892602,154.68855,4.8332248,292.3465,-9.3148365
1967,1967,145.3829,16.568768,4.0139704,0.0,0,4.3539338,0.0,0.31068066,154.6196,4.8128781,292.35327,-9.3152685
1968,1968,145.3831,16.591175,4.0302134,0.0,0,4.3343177,0.0,0.31302503,154.42096,4.7928658,292.36005,-9.3151398
1969,1969,145.3833,16.625883,4.055553,0.0,0,4.3147016,0.0,0.31481057,154.39063,4.7688909,292.36682,-9.3152494
1970,1970,145.3835,16.660728,4.0778866,0.0,0,4.2950859,0.0,0.3164598,154.52991,4.7456942,292.3736,-9.315259
1971,1971,145.3837,16.697987,4.0913911,0.0,0,4.2754693,0.0,0.31859025,154.52583,4.7251186,292.38034,-9.3145466
1972,1972,145.3839,16.743481,4.1156039,0.0,0,4.2558532,0.0,0.3203761,154.61925,4.7042742,292.38712,-9.3148232
1973,1973,145.3841,16.791883,4.1398721,0.0,0,4.236237,0.0,0.32201001,154.89507,4.6826558,292.39389,-9.3153839
1974,1974,145.3843,16.843161,4.1527338,0.0,0,4.2166214,0.0,0.32413095,155.00943,4.6619754,292.40067,-9.3156776
1975,1975,145.3845,16.885258,4.1767492,0.0,0,4.1970053,0.0,0.32614949,155.08235,4.642858,292.40744,-9.3152866
1976,1976,145.3847,16.908524,4.2036524,0.0,0,4.1773891,0.0,0.32779792,155.1136,4.623939,292.41418,-9.3151283
1977,1977,145.3849,16.92314,4.2167006,0.0,0,4.1577735,0.0,0.32977149,154.96788,4.6026287,292.42096,-9.3146982
1978,1978,145.3851,16.95446,4.2404747,0.0,0,4.1381574,0.0,0.3321746,154.80655,4.5797081,292.42773,-9.313386
1979,1979,145.3853,16.99744,4.2697086,0.0,0,4.1185412,0.0,0.33406982,154.8342,4.5576882,292.43451,-9.3135519
1980,1980,145.3855,17.042311,4.2831631,0.0,0,4.0989256,0.0,0.33589002,154.95085,4.5365653,292.44128,-9.3142519
1981,1981,145.3857,17.087326,4.3045607,0.0,0,4.0793095,0.0,0.33824506,154.9913,4.5164824,292.44803,-9.3149347
1982,1982,145.3859,17.135979,4.3325381,0.0,0,4.0596933,0.0,0.33997825,155.14482,4.4923644,292.4548,-9.315012
1983,1983,145.3861,17.185637,4.3440685,0.0,0,4.0404716,0.0,0.34149855,155.39973,4.4688301,292.46158,-9.3151493
1984,1984,145.3863,17.230183,4.362865,0.0,0,4.0217257,0.0,0.34382293,155.45444,4.4493999,292.46835,-9.3151178
1985,1985,145.3865,17.25975,4.3901815,0.0,0,4.0030656,0.0,0.34551868,155.47418,4.4294095,292.47513,-9.3145838
1986,1986,145.3867,17.276587,4.4023294,0.0,0,3.9844091,0.0,0.34685761,155.46637,4.4087481,292.48187,-9.3151093
1987,1987,145.3869,17.296206,4.4213476,0.0,0,3.9657531,0.0,0.34932354,155.24136,4.3898368,292.48865,-9.3156099
1988,1988,145.3871,17.328869,4.449688,0.0,0,3.9470971,0.0,0.35119766,155.20842,4.3704996,292.49542,-9.3156652
1989,1989,145.3873,17.369772,4.463562,0.0,0,3.928441,0.0,0.35250556,155.34807,4.349237,292.5022,-9.3151121
1990,1990,145.3875,17.411623,4.4828858,0.0,0,3.9097853,0.0,0.3551316,155.31976,4.3291507,292.50897,-9.315237
1991,1991,145.3877,17.460852,4.5125599,0.0,0,3.8911293,0.0,0.35733595,155.43794,4.309906,292.51572,-9.3156118
1992,1992,145.3879,17.511101,4.5286727,0.0,0,3.8724732,0.0,0.35858902,155.72766,4.2909856,292.52249,-9.3156767
1993,1993,145.3881,17.554056,4.5454569,0.0,0,3.8538172,0.0,0.36103222,155.68884,4.2723007,292.52927,-9.3159237
1994,1994,145.3883,17.591276,4.5717702,0.0,0,3.8351612,0.0,0.36322564,155.64816,4.2516122,292.53604,-9.3158894
1995,1995,145.3885,17.62298,4.5878854,0.0,0,3.8165052,0.0,0.36423263,155.84877,4.2326474,292.54282,-9.3156919
1996,1996,145.3887,17.656771,4.6026416,0.0,0,3.7978492,0.0,0.36642984,155.8112,4.2118845,292.54956,-9.3155231
1997,1997,145.3889,17.690037,4.6274462,0.0,0,3.7791932,0.0,0.36876401,155.68681,4.1917691,292.55634,-9.3149567
1998,1998,145.3891,17.721123,4.6467547,0.0,0,3.7605371,0.0,0.36990711,155.76567,4.1722903,292.56311,-9.3147764
1999,1999,145.3893,17.760685,4.6630111,0.0,0,3.7418811,0.0,0.37215331,155.73134,4.1505532,292.56989,-9.3153477
2000,2000,145.3895,17.800972,4.6862326,0.0,0,3.7232251,0.0,0.37454924,155.75861,4.1309557,292.57666,-9.315526
2001,2001,145.3897,17.850296,4.7058926,0.0,0,3.7045693,0.0,0.37564412,156.04961,4.1105647,292.5834,-9.315589
2002,2002,145.3899,17.903778,4.7224598,0.0,0,3.6859133,0.0,0.37778556,156.13333,4.0899997,292.59018,-9.3156672
2003,2003,145.3901,17.947691,4.7446718,0.0,0,3.6672573,0.0,0.38033161,156.15094,4.0731583,292.59695,-9.3157911
2004,2004,145.3903,17.981991,4.7661567,0.0,0,3.6486013,0.0,0.38155955,156.32402,4.0552244,292.60373,-9.3158283
2005,2005,145.3905,18.015764,4.7827053,0.0,0,3.629945,0.0,0.383461,156.31052,4.0343122,292.6105,-9.3156223
2006,2006,145.3907,18.045401,4.8013783,0.0,0,3.611289,0.0,0.38594702,156.1237,4.0156736,292.61728,-9.3156643
2007,2007,145.3909,18.069906,4.8235307,0.0,0,3.5926332,0.0,0.38727951,156.12547,3.9965229,292.62402,-9.3153048
2008,2008,145.3911,18.107126,4.8406801,0.0,0,3.5743496,0.0,0.3890321,156.17238,3.9769917,292.6308,-9.3149738
2009,2009,145.3913,18.148746,4.8563085,0.0,0,3.5565164,0.0,0.39140281,156.1515,3.9572587,292.63757,-9.3148384
2010,2010,145.3915,18.189077,4.8793411,0.0,0,3.5387647,0.0,0.39287007,156.317,3.93821,292.64435,-9.3147621
2011,2011,145.3917,18.237967,4.8979673,0.0,0,3.5210166,0.0,0.39453712,156.47697,3.9193678,292.65112,-9.3147049
2012,2012,145.3919,18.290312,4.9109907,0.0,0,3.5032687,0.0,0.3968896,156.53792,3.9004583,292.65787,-9.3143482
2013,2013,145.3921,18.338614,4.9343357,0.0,0,3.4855206,0.0,0.39853445,156.69266,3.8809938,292.66464,-9.3143368
2014,2014,145.3923,18.380442,4.9548035,0.0,0,3.4677725,0.0,0.40013343,156.81648,3.862823,292.67142,-9.3146038
2015,2015,145.3925,18.411053,4.967309,0.0,0,3.4500246,0.0,0.40247387,156.77727,3.8452444,292.66833,-9.314888
2016,2016,145.3927,18.442244,4.9920864,0.0,0,3.4322767,0.0,0.4044334,156.73862,3.8266597,292.65048,-9.3146544
2017,2017,145.3929,18.480392,5.0156226,0.0,0,3.4145288,0.0,0.406066,156.72008,3.8085525,292.63266,-9.3145733
2018,2018,145.3931,18.527403,5.0265603,0.0,0,3.3967807,0.0,0.40817255,156.74193,3.7924125,292.61481,-9.315115
2019,2019,145.3933,18.573536,5.0484371,0.0,0,3.3790326,0.0,0.41008383,156.8589,3.7705715,292.59695,-9.3150835
2020,2020,145.3935,18.618101,5.0723376,0.0,0,3.3612847,0.0,0.41153964,157.009,3.7473526,292.5791,-9.3144932
2021,2021,145.3937,18.668846,5.0813556,0.0,0,3.3435366,0.0,0.41345969,157.0999,3.7292397,292.56128,-9.3143158
2022,2022,145.3939,18.718481,5.1018763,0.0,0,3.3257885,0.0,0.41561192,157.1819,3.7114623,292.54343,-9.3142843
2023,2023,145.3941,18.773586,5.1277828,0.0,0,3.3080406,0.0,0.4172006,157.40446,3.6944754,292.52557,-9.3142557
2024,2024,145.3943,18.818741,5.1365857,0.0,0,3.2902927,0.0,0.41891277,157.50548,3.6764376,292.50772,-9.3145523
2025,2025,145.3945,18.8515,5.1549654,0.0,0,3.2725446,0.0,0.42119828,157.45531,3.657063,292.4899,-9.3145866
2026,2026,145.3947,18.887444,5.1810532,0.0,0,3.2547965,0.0,0.42281803,157.54646,3.6360886,292.47205,-9.314291
2027,2027,145.3949,18.926573,5.1918511,0.0,0,3.2370486,0.0,0.42440909,157.56007,3.617528,292.45419,-9.3142843
2028,2028,145.3951,18.968145,5.2110052,0.0,0,3.2193005,0.0,0.42696509,157.48459,3.6005583,292.43634,-9.3139009
2029,2029,145.3953,19.008116,5.2381592,0.0,0,3.2015524,0.0,0.42876524,157.5659,3.5813906,292.41852,-9.3140049
2030,2030,145.3955,19.053974,5.2487512,0.0,0,3.1838045,0.0,0.43011379,157.69545,3.5618787,292.40067,-9.3144312
2031,2031,145.3957,19.109007,5.2657852,0.0,0,3.1660566,0.0,0.43259609,157.75829,3.5414553,292.38281,-9.3143387
2032,2032,145.3959,19.164749,5.2932534,0.0,0,3.1483085,0.0,0.43449152,157.9294,3.52197,292.36496,-9.3146162
2033,2033,145.3961,19.219652,5.3052459,0.0,0,3.1309149,0.0,0.43570188,158.15359,3.5041792,292.34714,-9.3152027
2034,2034,145.3963,19.268835,5.3210106,0.0,0,3.1139498,0.0,0.43822467,158.15515,3.4872191,292.32928,-9.3145351
2035,2035,145.3965,19.305563,5.3469477,0.0,0,3.0970623,0.0,0.4402214,158.20711,3.4712899,292.31143,-9.3144436
2036,2036,145.3967,19.337513,5.3603806,0.0,0,3.0801783,0.0,0.4413203,158.30194,3.4551671,292.29358,-9.3146982
2037,2037,145.3969,19.37977,5.3757906,0.0,0,3.0632942,0.0,0.44386828,158.18205,3.4358203,292.27576,-9.3142147
2038,2038,145.3971,19.42248,5.4013042,0.0,0,3.0464103,0.0,0.4461011,158.19342,3.41467,292.2579,-9.3141356
2039,2039,145.3973,19.463833,5.4162202,0.0,0,3.0295262,0.0,0.447054,158.45662,3.3964112,292.24005,-9.3139706
2040,2040,145.3975,19.508436,5.4296312,0.0,0,3.0126421,0.0,0.44936764,158.46696,3.3791399,292.2222,-9.3135815
2041,2041,145.3977,19.560425,5.4529772,0.0,0,2.9957583,0.0,0.45172581,158.49837,3.3611267,292.20438,-9.312995
2042,2042,145.3979,19.618355,5.4698563,0.0,0,2.9788742,0.0,0.45266697,158.78963,3.3450806,292.18652,-9.3128738
2043,2043,145.3981,19.678801,5.484416,0.0,0,2.9619904,0.0,0.45494759,158.88383,3.3283706,292.16867,-9.3135719
2044,2044,145.3983,19.736683,5.5068793,0.0,0,2.9451063,0.0,0.45750967,158.93309,3.3090384,292.15082,-9.3137407
2045,2045,145.3985,19.776186,5.5254889,0.0,0,2.9282222,0.0,0.45864064,159.08266,3.2905645,292.133,-9.3137627
2046,2046,145.3987,19.802795,5.5402513,0.0,0,2.9113381,0.0,0.46081719,158.97218,3.2738681,292.11514,-9.3143101
2047,2047,145.3989,19.837542,5.5605469,0.0,0,2.894454,0.0,0.46332085,158.86224,3.2552547,292.09729,-9.315012
2048,2048,145.3991,19.8806,5.5796442,0.0,0,2.8775702,0.0,0.46436426,159.06256,3.236851,292.07944,-9.315815
2049,2049,145.3993,19.93218,5.5942111,0.0,0,2.8606861,0.0,0.4663147,159.1588,3.2201953,292.06161,-9.3153267
2050,2050,145.3995,19.995007,5.6116352,0.0,0,2.8438022,0.0,0.46886745,159.20909,3.2016742,292.04376,-9.3148909
2051,2051,145.3997,20.05201,5.6327868,0.0,0,2.8269181,0.0,0.47006208,159.49576,3.1819832,292.02591,-9.3147125
2052,2052,145.3999,20.111082,5.6491408,0.0,0,2.810034,0.0,0.47186306,159.68541,3.1636863,292.00806,-9.314353
2053,2053,145.4001,20.17506,5.6640501,0.0,0,2.7931502,0.0,0.4744691,159.73035,3.1462092,291.99023,-9.3141699
2054,2054,145.4003,20.222532,5.6858506,0.0,0,2.7762663,0.0,0.47592619,159.90076,3.1276903,291.97238,-9.3134155
2055,2055,145.4005,20.25498,5.702909,0.0,0,2.7593822,0.0,0.4775987,159.90962,3.1108212,291.95453,-9.3133402
2056,2056,145.4007,20.297846,5.7157912,0.0,0,2.7424982,0.0,0.48005077,159.83644,3.0935242,291.93668,-9.3134947
2057,2057,145.4009,20.341015,5.7386079,0.0,0,2.7256143,0.0,0.48169494,159.94606,3.0748742,291.91885,-9.3135586
2058,2058,145.4011,20.388615,5.7578998,0.0,0,2.7090681,0.0,0.48336202,160.07594,3.0567737,291.901,-9.3143339
2059,2059,145.4013,20.445751,5.7694445,0.0,0,2.6929309,0.0,0.48578048,160.08206,3.0390563,291.88315,-9.3144436
2060,2060,145.4015,20.505112,5.7922359,0.0,0,2.6768675,0.0,0.48770049,160.19247,3.0205731,291.8653,-9.3142729
2061,2061,145.4017,20.571737,5.8136683,0.0,0,2.6608074,0.0,0.48928452,160.43848,3.0031617,291.84747,-9.3143425
2062,2062,145.4019,20.638453,5.8238688,0.0,0,2.6447473,0.0,0.49148983,160.60202,2.985409,291.82962,-9.3143368
2063,2063,145.4021,20.696363,5.8451066,0.0,0,2.6286871,0.0,0.49356982,160.7556,2.966465,291.81177,-9.3137741
2064,2064,145.4023,20.739685,5.8673816,0.0,0,2.6126273,0.0,0.4950524,160.89586,2.9486513,291.79391,-9.3136663
2065,2065,145.4025,20.785408,5.8756251,0.0,0,2.5965672,0.0,0.4969646,160.89529,2.93189,291.80255,-9.3142223
2066,2066,145.4027,20.824289,5.8948159,0.0,0,2.580507,0.0,0.49913135,160.85008,2.9142799,291.83762,-9.3141994
2067,2067,145.4029,20.864895,5.9185772,0.0,0,2.5644472,0.0,0.50064403,160.9644,2.8963385,291.87268,-9.3138008
2068,2068,145.4031,20.920706,5.9265251,0.0,0,2.5483871,0.0,0.50251395,161.04845,2.8803346,291.90778,-9.3133717
2069,2069,145.4033,20.979113,5.9446478,0.0,0,2.5323269,0.0,0.50493395,161.07698,2.8639216,291.94284,-9.3143406
2070,2070,145.4035,21.038206,5.9706802,0.0,0,2.5162671,0.0,0.50646031,161.28281,2.8455462,291.97791,-9.3149252
2071,2071,145.4037,21.096634,5.9794526,0.0,0,2.5002072,0.0,0.50801313,161.46654,2.8285577,292.013,-9.3141966
2072,2072,145.4039,21.160364,5.9958272,0.0,0,2.4841471,0.0,0.51058167,161.54608,2.8121481,292.04807,-9.3136244
2073,2073,145.4041,21.220264,6.0217576,0.0,0,2.4680872,0.0,0.51229054,161.76239,2.7939396,292.08313,-9.3130465
2074,2074,145.4043,21.266989,6.0315561,0.0,0,2.4520271,0.0,0.51368588,161.93408,2.7765315,292.11823,-9.3129015
2075,2075,145.4045,21.306368,6.0471854,0.0,0,2.4359672,0.0,0.5163759,161.81212,2.7596114,292.15329,-9.3128662
2076,2076,145.4047,21.34996,6.0731316,0.0,0,2.4199073,0.0,0.51825619,161.83109,2.7421889,292.18835,-9.3127689
2077,2077,145.4049,21.399868,6.0840068,0.0,0,2.4038472,0.0,0.51950407,161.97034,2.7264795,292.22345,-9.3127642
2078,2078,145.4051,21.448725,6.098732,0.0,0,2.3877871,0.0,0.52218449,161.88849,2.7100637,292.25851,-9.3137817
2079,2079,145.4053,21.500225,6.1244326,0.0,0,2.3717272,0.0,0.52415389,162.00383,2.6936679,292.29358,-9.3145161
2080,2080,145.4055,21.56613,6.1358247,0.0,0,2.3556671,0.0,0.52509731,162.34888,2.6763968,292.32867,-9.3141232
2081,2081,145.4057,21.639553,6.1480103,0.0,0,2.339607,0.0,0.52755946,162.45958,2.659488,292.36374,-9.3136301
2082,2082,145.4059,21.711954,6.1722417,0.0,0,2.3235471,0.0,0.52980971,162.62155,2.6442559,292.3988,-9.3130074
2083,2083,145.4061,21.776543,6.185504,0.0,0,2.3078086,0.0,0.53075272,162.97464,2.6257093,292.43387,-9.3127661
2084,2084,145.4063,21.815367,6.197401,0.0,0,2.2924592,0.0,0.53311825,162.94139,2.6079214,292.46896,-9.3120375
2085,2085,145.4065,21.850073,6.219924,0.0,0,2.2771802,0.0,0.53548032,162.83385,2.5906456,292.50403,-9.311532
2086,2086,145.4067,21.895527,6.2345362,0.0,0,2.261904,0.0,0.53624344,163.00092,2.5732508,292.53909,-9.3115549
2087,2087,145.4069,21.944422,6.2465882,0.0,0,2.2466278,0.0,0.53846598,162.98308,2.5588748,292.57419,-9.3119516
2088,2088,145.4071,22.00564,6.2681589,0.0,0,2.2313521,0.0,0.54116064,162.9884,2.542887,292.60925,-9.3126764
2089,2089,145.4073,22.070923,6.2858024,0.0,0,2.2160761,0.0,0.54225057,163.29053,2.5274453,292.64432,-9.3133335
2090,2090,145.4075,22.143494,6.2985377,0.0,0,2.2008002,0.0,0.54436964,163.47375,2.5107512,292.67941,-9.3134909
2091,2091,145.4077,22.217344,6.3165722,0.0,0,2.185524,0.0,0.54685187,163.63005,2.4913862,292.71448,-9.3136854
2092,2092,145.4079,22.280754,6.334095,0.0,0,2.170248,0.0,0.54778987,163.95534,2.4759579,292.74954,-9.3136616
2093,2093,145.4081,22.336349,6.3474455,0.0,0,2.1549721,0.0,0.54978359,164.04001,2.4629416,292.78464,-9.3134508
2094,2094,145.4083,22.379421,6.3637066,0.0,0,2.1396961,0.0,0.55244154,163.94588,2.4473603,292.8197,-9.3133183
2095,2095,145.4085,22.414816,6.3825245,0.0,0,2.1244199,0.0,0.55357295,164.01497,2.4296331,292.85477,-9.3120613
2096,2096,145.4087,22.462877,6.3961458,0.0,0,2.109144,0.0,0.5553298,164.07079,2.4121983,292.88986,-9.3112812
2097,2097,145.4089,22.525499,6.4090662,0.0,0,2.093868,0.0,0.55783468,164.14565,2.3958583,292.92493,-9.3117771
2098,2098,145.4091,22.59446,6.4284492,0.0,0,2.0785921,0.0,0.55900306,164.4451,2.3812613,292.95999,-9.3125229
2099,2099,145.4093,22.659889,6.4431791,0.0,0,2.0633161,0.0,0.56052607,164.64386,2.3653743,292.99509,-9.3127556
2100,2100,145.4095,22.721794,6.4547257,0.0,0,2.0480402,0.0,0.56310266,164.66278,2.3473704,293.03015,-9.313323
2101,2101,145.4097,22.794044,6.4773026,0.0,0,2.0327642,0.0,0.56484133,164.89398,2.3302031,293.06522,-9.3140507
2102,2102,145.4099,22.862522,6.4954929,0.0,0,2.0174882,0.0,0.56642944,165.16917,2.3147905,293.10031,-9.313695
2103,2103,145.4101,22.923281,6.5047812,0.0,0,2.002212,0.0,0.56891489,165.24423,2.2992463,293.13538,-9.3130636
2104,2104,145.4103,22.974319,6.5252395,0.0,0,1.986936,0.0,0.57071608,165.23431,2.2823095,293.17044,-9.3128672
2105,2105,145.4105,23.012203,6.5437732,0.0,0,1.9716599,0.0,0.57206273,165.25278,2.2667933,293.20551,-9.3127127
2106,2106,145.4107,23.061981,6.5512557,0.0,0,1.9563839,0.0,0.5742771,165.26515,2.2523375,293.2406,-9.311965
2107,2107,145.4109,23.128363,6.5701642,0.0,0,1.941108,0.0,0.57611412,165.3858,2.2370818,293.27567,-9.3113041
2108,2108,145.4111,23.198467,6.5904894,0.0,0,1.9261372,0.0,0.57741213,165.67473,2.2214911,293.31073,-9.3120165
2109,2109,145.4113,23.265402,6.5962043,0.0,0,1.9115354,0.0,0.57936633,165.84708,2.2022576,293.34583,-9.3127375
2110,2110,145.4115,23.330942,6.6126823,0.0,0,1.8970003,0.0,0.58141279,165.96193,2.1847155,293.38089,-9.3134556
2111,2111,145.4117,23.403013,6.6349325,0.0,0,1.8824683,0.0,0.58273965,166.24065,2.1710565,293.41595,-9.3140774
2112,2112,145.4119,23.469328,6.6417799,0.0,0,1.8679363,0.0,0.58450526,166.43033,2.1581604,293.45105,-9.3134022
2113,2113,145.4121,23.526793,6.6598883,0.0,0,1.8534042,0.0,0.58708918,166.45171,2.1441374,293.48611,-9.3126621
2114,2114,145.4123,23.580498,6.6852217,0.0,0,1.8388723,0.0,0.58882189,166.52524,2.128315,293.52118,-9.3120546
2115,2115,145.4125,23.635223,6.6921287,0.0,0,1.8243402,0.0,0.59045285,166.62096,2.111237,293.4678,-9.3119392
2116,2116,145.4127,23.692503,6.7080774,0.0,0,1.8098083,0.0,0.59309101,166.60542,2.0951884,293.35547,-9.3124008
2117,2117,145.4129,23.754311,6.732655,0.0,0,1.7952763,0.0,0.59471953,166.7494,2.0807734,293.2431,-9.31217
2118,2118,145.4131,23.822702,6.7380772,0.0,0,1.7807442,0.0,0.59587336,167.01787,2.0667088,293.13077,-9.3120756
2119,2119,145.4133,23.894115,6.7507839,0.0,0,1.7662122,0.0,0.59840024,167.06808,2.0509338,293.01843,-9.3125296
2120,2120,145.4135,23.973005,6.7751107,0.0,0,1.7516803,0.0,0.6000061,167.34126,2.0359857,292.9061,-9.312602
2121,2121,145.4137,24.045235,6.782445,0.0,0,1.7371483,0.0,0.60097516,167.72598,2.0221727,292.79373,-9.3126059
2122,2122,145.4139,24.109034,6.7943306,0.0,0,1.7226163,0.0,0.60365695,167.72346,2.0064535,292.6814,-9.3127403
2123,2123,145.4141,24.176147,6.818234,0.0,0,1.7080842,0.0,0.60555387,167.8405,1.9911385,292.56906,-9.3128204
2124,2124,145.4143,24.23407,6.8275299,0.0,0,1.6935523,0.0,0.60636985,168.1573,1.9753281,292.4567,-9.3126612
2125,2125,145.4145,24.288719,6.8393927,0.0,0,1.6790203,0.0,0.60891342,168.15736,1.9587114,292.34436,-9.3125744
2126,2126,145.4147,24.352579,6.863234,0.0,0,1.6644882,0.0,0.61118406,168.18811,1.9432889,292.23203,-9.3127499
2127,2127,145.4149,24.417953,6.874989,0.0,0,1.6499562,0.0,0.6120342,168.47603,1.9279573,292.11969,-9.3125963
2128,2128,145.4151,24.484035,6.8858767,0.0,0,1.6354243,0.0,0.61452633,168.50348,1.9128344,292.00732,-9.3119659
2129,2129,145.4153,24.551014,6.9083238,0.0,0,1.6208922,0.0,0.61700618,168.56181,1.898708,291.89499,-9.3119688
2130,2130,145.4155,24.625103,6.9222455,0.0,0,1.6063603,0.0,0.61777735,168.94788,1.8858714,291.78265,-9.3118525
2131,2131,145.4157,24.707211,6.9322505,0.0,0,1.5918282,0.0,0.62009937,169.09496,1.8698453,291.67029,-9.311924
2132,2132,145.4159,24.780943,6.95155,0.0,0,1.5772963,0.0,0.62265217,169.19942,1.8528162,291.55795,-9.3125124
2133,2133,145.4161,24.850794,6.9666815,0.0,0,1.5630547,0.0,0.62345755,169.56924,1.8370229,291.44562,-9.3122721
2134,2134,145.4163,24.911606,6.9773355,0.0,0,1.5491643,0.0,0.62558562,169.62511,1.8206577,291.33328,-9.3118839
2135,2135,145.4165,24.966602,6.9941311,0.0,0,1.5353372,0.0,0.62810957,169.61522,1.8072488,291.22092,-9.3117189
2136,2136,145.4167,25.028376,7.0099435,0.0,0,1.5215131,0.0,0.62887764,169.90924,1.792513,291.10858,-9.3111162
2137,2137,145.4169,25.094318,7.0205936,0.0,0,1.5076891,0.0,0.63081998,169.96437,1.7780724,290.99625,-9.3107738
2138,2138,145.4171,25.161085,7.0349212,0.0,0,1.4938651,0.0,0.63346338,169.98759,1.7666515,290.88388,-9.3105536
2139,2139,145.4173,25.240421,7.0521493,0.0,0,1.4800411,0.0,0.63437587,170.35632,1.7517375,290.77155,-9.3098431
2140,2140,145.4175,25.327978,7.0638561,0.0,0,1.4662172,0.0,0.6360569,170.6013,1.7355106,290.65921,-9.3096304
2141,2141,145.4177,25.409836,7.0767512,0.0,0,1.4523932,0.0,0.63875002,170.67584,1.7191367,290.54688,-9.3096218
2142,2142,145.4179,25.486856,7.0964098,0.0,0,1.4385692,0.0,0.64003634,170.99266,1.7044088,290.43451,-9.3104687
2143,2143,145.4181,25.552198,7.1105456,0.0,0,1.4247452,0.0,0.64166129,171.1835,1.6909137,290.32217,-9.3107033
2144,2144,145.4183,25.612551,7.1215992,0.0,0,1.4109212,0.0,0.64435911,171.09476,1.6754223,290.20984,-9.3106365
2145,2145,145.4185,25.675388,7.1418695,0.0,0,1.3970972,0.0,0.6459465,171.25439,1.6601274,290.09747,-9.3118677
2146,2146,145.4187,25.74123,7.1577735,0.0,0,1.3832732,0.0,0.64751208,171.41943,1.6448562,289.98514,-9.3119669
2147,2147,145.4189,25.815825,7.1660209,0.0,0,1.3694493,0.0,0.64998817,171.47153,1.6322001,289.8728,-9.3112984
2148,2148,145.4191,25.89432,7.1849375,0.0,0,1.3556252,0.0,0.6516571,171.73859,1.6187769,289.76047,-9.3112383
2149,2149,145.4193,25.973305,7.201344,0.0,0,1.3418012,0.0,0.65293932,172.00813,1.6045411,289.6481,-9.311223
2150,2150,145.4195,26.056376,7.2069392,0.0,0,1.3279773,0.0,0.65510499,172.1906,1.5901604,289.53577,-9.310729
2151,2151,145.4197,26.141645,7.2247601,0.0,0,1.3141533,0.0,0.65702444,172.47951,1.5737493,289.42343,-9.3099613
2152,2152,145.4199,26.22538,7.243082,0.0,0,1.3003292,0.0,0.65828329,172.81502,1.5587161,289.31107,-9.30968
2153,2153,145.4201,26.29221,7.2468948,0.0,0,1.2865052,0.0,0.6601668,172.95398,1.546455,289.19873,-9.3095427
2154,2154,145.4203,26.358683,7.2633576,0.0,0,1.2726812,0.0,0.66224372,172.9985,1.5324863,289.0864,-9.3089466
2155,2155,145.4205,26.421673,7.285089,0.0,0,1.2588573,0.0,0.66355121,173.1635,1.5169389,288.97406,-9.3083591
2156,2156,145.4207,26.487076,7.289639,0.0,0,1.2450333,0.0,0.66527832,173.32581,1.5028187,288.86169,-9.309103
2157,2157,145.4209,26.570074,7.304718,0.0,0,1.2312093,0.0,0.66760278,173.42072,1.4905422,288.74936,-9.3103704
2158,2158,145.4211,26.648968,7.3278127,0.0,0,1.2176626,0.0,0.66900504,173.68214,1.4767783,288.63702,-9.3109684
2159,2159,145.4213,26.728148,7.3327279,0.0,0,1.2044512,0.0,0.67063272,173.89734,1.4618322,288.52469,-9.3106365
2160,2160,145.4215,26.814266,7.347343,0.0,0,1.1913005,0.0,0.67339408,173.94469,1.4465985,288.41232,-9.3104343
2161,2161,145.4217,26.894331,7.3716841,0.0,0,1.1781523,0.0,0.67504889,174.23386,1.4346976,288.29999,-9.3109818
2162,2162,145.4219,26.970781,7.3771863,0.0,0,1.1650044,0.0,0.67634398,174.52484,1.4217845,288.18765,-9.3111925
2163,2163,145.4221,27.046434,7.3891196,0.0,0,1.1518563,0.0,0.6789996,174.53485,1.405531,288.07529,-9.3110008
2164,2164,145.4223,27.110336,7.4117136,0.0,0,1.1387082,0.0,0.68060958,174.68768,1.3916696,287.96295,-9.3108788
2165,2165,145.4225,27.169682,7.4168506,0.0,0,1.1255603,0.0,0.68142045,174.92871,1.3766438,287.73837,-9.3106518
2166,2166,145.4227,27.238449,7.4261589,0.0,0,1.1124123,0.0,0.68386197,174.9334,1.3623757,287.46573,-9.3107452
2167,2167,145.4229,27.323248,7.4480591,0.0,0,1.0992643,0.0,0.68552697,175.14517,1.3493208,287.19308,-9.3103685
2168,2168,145.4231,27.409414,7.4554687,0.0,0,1.0861163,0.0,0.68623722,175.55974,1.3375469,286.92041,-9.3101778
2169,2169,145.4233,27.492699,7.4656544,0.0,0,1.0729682,0.0,0.68899965,175.61449,1.3250914,286.64777,-9.3102837
2170,2170,145.4235,27.586609,7.4884171,0.0,0,1.0598202,0.0,0.6911884,175.82306,1.3102479,286.37512,-9.3097544
2171,2171,145.4237,27.676857,7.4983191,0.0,0,1.0466722,0.0,0.69184697,176.34717,1.2960747,286.10245,-9.3096008
2172,2172,145.4239,27.758785,7.5073819,0.0,0,1.0335243,0.0,0.6943984,176.45956,1.2828447,285.8298,-9.309618
2173,2173,145.4241,27.828285,7.5280848,0.0,0,1.0203762,0.0,0.69685525,176.46335,1.2696414,285.55716,-9.3097219
2174,2174,145.4243,27.890532,7.5403614,0.0,0,1.0072283,0.0,0.69744289,176.74878,1.255043,285.28452,-9.3095284
2175,2175,145.4245,27.971703,7.5496812,0.0,0,0.99408025,0.0,0.69976676,176.8084,1.2424719,285.01184,-9.3093338
2176,2176,145.4247,28.058441,7.5685592,0.0,0,0.98093224,0.0,0.70245796,176.88635,1.231357,284.7392,-9.3094778
2177,2177,145.4249,28.142511,7.581768,0.0,0,0.96778423,0.0,0.70304447,177.33047,1.2165277,284.46655,-9.3104229
2178,2178,145.4251,28.230684,7.5901632,0.0,0,0.95463622,0.0,0.70504624,177.48907,1.2006863,284.19388,-9.3110027
2179,2179,145.4253,28.323967,7.6064935,0.0,0,0.94148827,0.0,0.70769358,177.59871,1.1855177,283.92123,-9.3108339
2180,2180,145.4255,28.424025,7.6210365,0.0,0,0.92834032,0.0,0.70833236,178.11761,1.1735247,283.64859,-9.3106756
2181,2181,145.4257,28.512674,7.6300325,0.0,0,0.91519231,0.0,0.71021527,178.35625,1.1633222,283.37592,-9.3108196
2182,2182,145.4259,28.587214,7.6441178,0.0,0,0.9020443,0.0,0.71297282,178.35208,1.1496371,283.10327,-9.3108969
2183,2183,145.4261,28.658781,7.6609569,0.0,0,0.88916039,0.0,0.71386135,178.62036,1.1362802,282.83063,-9.3096256
2184,2184,145.4263,28.726765,7.6722183,0.0,0,0.87659597,0.0,0.71574354,178.68089,1.1225964,282.55795,-9.3089533
2185,2185,145.4265,28.794189,7.6840181,0.0,0,0.86408937,0.0,0.71858126,178.62454,1.10805,282.28531,-9.3093815
2186,2186,145.4267,28.875467,7.7012987,0.0,0,0.85158527,0.0,0.71960294,178.96501,1.0940022,282.01266,-9.3094788
2187,2187,145.4269,28.97138,7.7118182,0.0,0,0.83908123,0.0,0.72097039,179.28653,1.0812809,281.74002,-9.309248
2188,2188,145.4271,29.068316,7.7186213,0.0,0,0.82657719,0.0,0.72337884,179.45145,1.070761,281.46735,-9.3097429
2189,2189,145.4273,29.168402,7.7352939,0.0,0,0.8140732,0.0,0.72445333,179.87917,1.0562927,281.1947,-9.30933
2190,2190,145.4275,29.263338,7.7482381,0.0,0,0.80156928,0.0,0.72566688,180.26381,1.0430056,280.92206,-9.308857
2191,2191,145.4277,29.3512,7.7538166,0.0,0,0.78906524,0.0,0.72810847,180.3667,1.0303553,280.64938,-9.3093643
2192,2192,145.4279,29.431013,7.7713609,0.0,0,0.77656126,0.0,0.72965747,180.56555,1.0162299,280.37674,-9.3091402
2193,2193,145.4281,29.503143,7.7877412,0.0,0,0.76405728,0.0,0.73093569,180.76292,1.00468,280.1041,-9.3091927
2194,2194,145.4283,29.583607,7.7932734,0.0,0,0.75155324,0.0,0.73334002,180.77116,0.99216479,279.83142,-9.3094225
2195,2195,145.4285,29.665163,7.8114223,0.0,0,0.73904926,0.0,0.73544109,180.86841,0.97863734,279.55878,-9.3090487
2196,2196,145.4287,29.74869,7.829484,0.0,0,0.72654527,0.0,0.73672104,181.16096,0.96496284,279.28613,-9.3083115
2197,2197,145.4289,29.841114,7.8333511,0.0,0,0.71404123,0.0,0.73877776,181.32521,0.95174092,279.01346,-9.3075371
2198,2198,145.4291,29.935215,7.8495774,0.0,0,0.70153725,0.0,0.74089712,181.5119,0.93871605,278.74081,-9.3067884
2199,2199,145.4293,30.030533,7.8684597,0.0,0,0.68903327,0.0,0.74197453,181.92537,0.92310208,278.46817,-9.307291
2200,2200,145.4295,30.126099,7.8699222,0.0,0,0.67652929,0.0,0.74370021,182.22675,0.90997654,278.19553,-9.3079357
2201,2201,145.4297,30.217625,7.883173,0.0,0,0.66402531,0.0,0.74593633,182.39308,0.89965004,277.92285,-9.3082495
2202,2202,145.4299,30.301065,7.9037271,0.0,0,0.65152127,0.0,0.74707747,182.65089,0.88719624,277.65021,-9.3084526
2203,2203,145.4301,30.374365,7.9058142,0.0,0,0.63901722,0.0,0.74847233,182.85202,0.87552053,277.37756,-9.3089161
2204,2204,145.4303,30.445625,7.9176879,0.0,0,0.62651324,0.0,0.75092477,182.86133,0.86314487,277.10489,-9.3095131
2205,2205,145.4305,30.532154,7.9392691,0.0,0,0.61400926,0.0,0.75223345,183.09862,0.85033315,276.83224,-9.3095455
2206,2206,145.4307,30.629934,7.9427299,0.0,0,0.60150528,0.0,0.75340629,183.44203,0.83743638,276.5596,-9.3094854
2207,2207,145.4309,30.723892,7.9542727,0.0,0,0.58900124,0.0,0.75621235,183.51343,0.82424635,276.28693,-9.3085842
2208,2208,145.4311,30.824076,7.976727,0.0,0,0.57674497,0.0,0.75778037,183.78107,0.81326932,276.01428,-9.3078976
2209,2209,145.4313,30.92625,7.9812326,0.0,0,0.56478834,0.0,0.75864094,184.21529,0.80086344,275.74164,-9.3076925
2210,2210,145.4315,31.02058,7.9908867,0.0,0,0.55288589,0.0,0.76132423,184.34764,0.78853923,275.46896,-9.3074245
2211,2211,145.4317,31.111082,8.0124578,0.0,0,0.54098582,0.0,0.76304114,184.58549,0.77605963,275.19632,-9.3075542
2212,2212,145.4319,31.192259,8.0175257,0.0,0,0.52908581,0.0,0.76366651,184.97617,0.76300377,274.92368,-9.3084097
2213,2213,145.4321,31.275185,8.0245352,0.0,0,0.51718581,0.0,0.76620525,185.01526,0.75046396,274.65103,-9.3089752
2214,2214,145.4323,31.361372,8.0454235,0.0,0,0.5052858,0.0,0.76818681,185.12305,0.73726845,274.37836,-9.3086309
2215,2215,145.4325,31.450979,8.0530434,0.0,0,0.49338579,0.0,0.76862627,185.57237,0.72647643,274.24661,-9.308857
2216,2216,145.4327,31.5508,8.0595179,0.0,0,0.48148578,0.0,0.77114546,185.70343,0.71528494,274.15009,-9.3087006
2217,2217,145.4329,31.646837,8.0797052,0.0,0,0.46958581,0.0,0.77357048,185.81467,0.7018041,274.05359,-9.3079262
2218,2218,145.4331,31.745649,8.0907278,0.0,0,0.4576858,0.0,0.77397752,186.30406,0.68885458,273.95706,-9.3078928
2219,2219,145.4333,31.856426,8.0979433,0.0,0,0.44578579,0.0,0.77639103,186.47046,0.67674553,273.86053,-9.308073
2220,2220,145.4335,31.955397,8.1162691,0.0,0,0.43388578,0.0,0.77903455,186.59451,0.66521186,273.76401,-9.3078814
2221,2221,145.4337,32.044525,8.1285362,0.0,0,0.42198581,0.0,0.77945322,187.03326,0.65288138,273.66748,-9.3071318
2222,2222,145.4339,32.131805,8.1347246,0.0,0,0.4100858,0.0,0.78149503,187.14815,0.64165568,273.57095,-9.3067503
2223,2223,145.4341,32.213142,8.1496878,0.0,0,0.39818579,0.0,0.78414357,187.1692,0.63091457,273.47443,-9.3069344
2224,2224,145.4343,32.304874,8.1630268,0.0,0,0.38628578,0.0,0.78465903,187.59261,0.61717671,273.3779,-9.306879
2225,2225,145.4345,32.401672,8.1701889,0.0,0,0.37438577,0.0,0.78644776,187.81917,0.60511041,273.28137,-9.3074198
2226,2226,145.4347,32.498096,8.1827126,0.0,0,0.36248577,0.0,0.78916115,187.86995,0.59356523,273.18484,-9.3078461
2227,2227,145.4349,32.598785,8.1973276,0.0,0,0.35058579,0.0,0.78983986,188.29671,0.57972533,273.08832,-9.3077421
2228,2228,145.4351,32.699593,8.2053576,0.0,0,0.33868581,0.0,0.79137522,188.6116,0.56723231,272.99179,-9.3079481
2229,2229,145.4353,32.805935,8.2140732,0.0,0,0.3267858,0.0,0.79395574,188.75452,0.55627453,272.89526,-9.3080778
2230,2230,145.4355,32.921661,8.2290506,0.0,0,0.3148858,0.0,0.79460818,189.24266,0.54572105,272.79877,-9.30793
2231,2231,145.4357,33.027691,8.2387257,0.0,0,0.30298579,0.0,0.79598302,189.58884,0.53486073,272.70224,-9.3079033
2232,2232,145.4359,33.116756,8.2456799,0.0,0,0.29108578,0.0,0.79867029,189.63138,0.52185088,272.60571,-9.3077879
2233,2233,145.4361,33.206917,8.2633429,0.0,0,0.27942529,0.0,0.79973716,189.91081,0.51021516,272.50919,-9.3077888
2234,2234,145.4363,33.303261,8.2766123,0.0,0,0.26805454,0.0,0.80120963,190.14366,0.50001246,272.41266,-9.3080502
2235,2235,145.4365,33.399982,8.2830925,0.0,0,0.25673616,0.0,0.80407447,190.16798,0.48868525,272.31613,-9.3079119
2236,2236,145.4367,33.503559,8.3014898,0.0,0,0.24542005,0.0,0.80570781,190.46753,0.4758929,272.2196,-9.3071642
2237,2237,145.4369,33.604958,8.3157253,0.0,0,0.23410405,0.0,0.80696476,190.82053,0.46405873,272.12308,-9.3065977
2238,2238,145.4371,33.706921,8.318593,0.0,0,0.22278805,0.0,0.8093763,190.97478,0.45247763,272.02655,-9.3066254