File: clean data/testID_0153.csv
level_0,index,Time(sec),Force(kN),Jaw(mm),PowAngle(deg),Power(W),Pram,PTemp,Strain,Stress(MPa),Stroke(mm),TC1(C),wedge(mm)
2417,2417,195.3756,0.78101623,0.089998186,0.0,0,9.9578638,0.0,0.0061041191,9.5234032,10.061954,450.31116,-9.2351866
2428,2428,195.3778,2.0295196,0.10275571,0.0,0,9.9248638,0.0,0.0067676231,25.401196,10.031487,450.52856,-9.2348862
2439,2439,195.38,3.2612076,0.11629266,0.0,0,9.8918638,0.0,0.0078655137,40.992039,9.9986124,450.74594,-9.2321777
2450,2450,195.3822,3.825968,0.14424485,0.0,0,9.8588629,0.0,0.0095583303,48.109425,9.9618502,450.99356,-9.2319803
2461,2461,195.3844,4.0564275,0.18435101,0.0,0,9.8258638,0.0,0.012486132,51.039375,9.9193726,451.87625,-9.2319078
2472,2472,195.3866,4.2210817,0.22135821,0.0,0,9.7928638,0.0,0.014658134,52.898319,9.8809767,452.75897,-9.2319479
2483,2483,195.3888,4.325469,0.254078,0.0,0,9.7598639,0.0,0.017121216,54.177135,9.8451605,453.64166,-9.2330198
2494,2494,195.391,4.3788481,0.28697076,0.0,0,9.7268629,0.0,0.019208902,54.781433,9.807023,454.52435,-9.2322006
2505,2505,195.3932,4.4443274,0.32179329,0.0,0,9.6938639,0.0,0.021822397,55.355206,9.7774029,455.36093,-9.233017
2516,2516,195.3954,4.4879026,0.35449874,0.0,0,9.6608629,0.0,0.023713177,55.809586,9.7472715,456.15134,-9.2325821
2527,2527,195.3976,4.5504274,0.38176191,0.0,0,9.6278639,0.0,0.025843216,56.419662,9.716218,456.94177,-9.2327414
2538,2538,195.3998,4.6070337,0.41433394,0.0,0,9.5948629,0.0,0.027817897,57.010056,9.680789,457.73218,-9.2321405
2549,2549,195.402,4.6436849,0.45000941,0.0,0,9.5618639,0.0,0.030567784,57.341003,9.6462641,458.52261,-9.232151
2560,2560,195.4042,4.6662183,0.48556104,0.0,0,9.5288639,0.0,0.032599565,57.475937,9.6140747,458.71561,-9.2331829
2571,2571,195.4064,4.6730299,0.51360482,0.0,0,9.4958639,0.0,0.034972452,57.5271,9.5801039,458.88013,-9.2330971
2582,2582,195.4086,4.6832218,0.54734135,0.0,0,9.4633293,0.0,0.036907412,57.537956,9.5461054,459.04468,-9.2337732
2593,2593,195.4108,4.7102971,0.57983685,0.0,0,9.431138,0.0,0.039575532,57.66893,9.5113583,459.20923,-9.2334204
2604,2604,195.413,4.7215309,0.61640835,0.0,0,9.3989477,0.0,0.041675963,57.774296,9.4812174,459.08011,-9.2337685
2615,2615,195.4152,4.7573214,0.64399123,0.0,0,9.3667564,0.0,0.044039935,57.949806,9.4485035,458.52682,-9.233387
2626,2626,195.4174,4.7727876,0.67804152,0.0,0,9.3345671,0.0,0.046025798,58.059158,9.4159012,457.97357,-9.233264
2637,2637,195.4196,4.7971163,0.70975381,0.0,0,9.3023767,0.0,0.048698779,58.089748,9.3773756,457.42029,-9.2324762
2648,2648,195.4218,4.799263,0.74540555,0.0,0,9.2701855,0.0,0.050670173,58.085136,9.3443489,456.867,-9.2327671
2659,2659,195.424,4.8254938,0.7734974,0.0,0,9.2379951,0.0,0.053186983,58.309879,9.3111057,456.23416,-9.2335072
2670,2670,195.4262,4.8334422,0.80923295,0.0,0,9.2058048,0.0,0.055192843,58.218376,9.2778578,455.58871,-9.2329493
2681,2681,195.4284,4.8389282,0.84168142,0.0,0,9.1736145,0.0,0.057941206,58.086067,9.2430048,454.9433,-9.2340527
2692,2692,195.4306,4.8373003,0.87882352,0.0,0,9.1414251,0.0,0.059997708,57.970798,9.2116346,454.29788,-9.2341518
2703,2703,195.4328,4.8413067,0.90382212,0.0,0,9.1092339,0.0,0.062363155,57.899883,9.1794157,453.91022,-9.2334881
2714,2714,195.435,4.8698497,0.9366259,0.0,0,9.0770426,0.0,0.064223506,58.064129,9.1469469,454.07489,-9.2337809
2725,2725,195.4372,4.8821445,0.96257603,0.0,0,9.0448523,0.0,0.066582844,58.171852,9.1188269,454.23959,-9.2348776
2736,2736,195.4394,4.8968081,0.99966753,0.0,0,9.0126629,0.0,0.068575114,58.274689,9.0875988,454.40427,-9.2337637
2747,2747,195.4416,4.8947721,1.0258329,0.0,0,8.9804716,0.0,0.071036503,57.967831,9.0552607,454.56897,-9.2324944
2758,2758,195.4438,4.9166102,1.06032,0.0,0,8.9482822,0.0,0.073077083,58.163181,9.02596,454.93216,-9.2321377
2769,2769,195.446,4.9381599,1.0877566,0.0,0,8.916091,0.0,0.075564913,58.286217,8.9879618,455.35376,-9.2330542
2780,2780,195.4482,4.9527926,1.127732,0.0,0,8.8839006,0.0,0.077753797,58.362614,8.9542799,455.77533,-9.2333832
2791,2791,195.4504,4.9662519,1.1535022,0.0,0,8.8517103,0.0,0.080191478,58.276737,8.9227552,456.19693,-9.2326746
2802,2802,195.4526,4.9929504,1.1885788,0.0,0,8.819521,0.0,0.082313262,58.531258,8.8903379,456.57062,-9.232914
2813,2813,195.4548,5.0236259,1.2191885,0.0,0,8.7873297,0.0,0.085029051,58.717819,8.856473,456.7814,-9.2334213
2824,2824,195.457,5.0351777,1.2590997,0.0,0,8.7551394,0.0,0.087297946,58.778233,8.8216743,456.99222,-9.2343082
2835,2835,195.4592,5.0390315,1.2851478,0.0,0,8.7242823,0.0,0.089797787,58.745983,8.7897902,457.203,-9.2332239
2846,2846,195.4614,5.0309196,1.3199127,0.0,0,8.6936674,0.0,0.091905661,58.415897,8.7555513,457.41379,-9.2306881
2857,2857,195.4636,5.0159678,1.3479465,0.0,0,8.6630526,0.0,0.094410583,58.141041,8.7222195,457.53925,-9.2324638
2868,2868,195.4658,5.0260048,1.3855578,0.0,0,8.6324368,0.0,0.096563287,58.085712,8.6913824,457.62488,-9.2329378
2879,2879,195.468,5.0475779,1.4096026,0.0,0,8.6018219,0.0,0.098868951,58.159901,8.6627665,457.71051,-9.232585
2890,2890,195.4702,5.072897,1.4436145,0.0,0,8.5712061,0.0,0.1009681,58.255344,8.6326437,457.79617,-9.2340269
2901,2901,195.4724,5.1006346,1.4721389,0.0,0,8.5405912,0.0,0.10355633,58.54557,8.5986032,457.87372,-9.2335901
2912,2912,195.4746,5.1178775,1.5105404,0.0,0,8.5099754,0.0,0.10581621,58.575123,8.5678215,457.90005,-9.2336359
2923,2923,195.4768,5.108448,1.5331422,0.0,0,8.4793606,0.0,0.10802627,58.273781,8.5365601,457.92639,-9.2328529
2934,2934,195.479,5.103085,1.5665064,0.0,0,8.4487457,0.0,0.11010487,58.236038,8.5068407,457.95276,-9.2328291
2945,2945,195.4812,5.0998693,1.5925744,0.0,0,8.4181299,0.0,0.11245197,58.0877,8.4751816,457.9791,-9.2330551
2956,2956,195.4834,5.1176095,1.6324645,0.0,0,8.3875151,0.0,0.11491349,58.029217,8.439436,457.86142,-9.2320719
2967,2967,195.4856,5.1040897,1.6547678,0.0,0,8.3568993,0.0,0.11703887,57.785107,8.4143448,457.64404,-9.2320185
2978,2978,195.4878,5.1324224,1.6869738,0.0,0,8.3262854,0.0,0.11919799,58.068314,8.384881,457.42664,-9.2315989
2989,2989,195.49,5.1700015,1.7132515,0.0,0,8.2956686,0.0,0.12142675,58.370056,8.3540039,457.20926,-9.2324543
3000,3000,195.4922,5.1960201,1.7505227,0.0,0,8.2650547,0.0,0.12380003,58.394077,8.320838,456.99878,-9.2329788
3011,3011,195.4944,5.1930718,1.7734591,0.0,0,8.2344389,0.0,0.12585321,58.316345,8.294486,456.93289,-9.2334757
3022,3022,195.4966,5.1859765,1.8042623,0.0,0,8.203825,0.0,0.1280047,58.12587,8.2632999,456.86703,-9.2326403
3033,3033,195.4988,5.1985502,1.8324821,0.0,0,8.1732092,0.0,0.13042897,58.100155,8.2308989,456.80118,-9.2326479
3044,3044,195.501,5.2223921,1.8701663,0.0,0,8.1425943,0.0,0.13291284,58.177143,8.2016306,456.73529,-9.2322741
3055,3055,195.5032,5.2429676,1.8950887,0.0,0,8.1119785,0.0,0.13511981,58.278629,8.1715488,456.70895,-9.2330418
3066,3066,195.5054,5.2686362,1.9299909,0.0,0,8.0813627,0.0,0.13763086,58.461567,8.1352167,456.72214,-9.2332048
3077,3077,195.5076,5.2780833,1.9578669,0.0,0,8.0509262,0.0,0.13982837,58.47327,8.1022911,456.73532,-9.2329941
3088,3088,195.5098,5.3049574,1.9964658,0.0,0,8.0217981,0.0,0.14265683,58.525623,8.0741739,456.7485,-9.232686
3099,3099,195.512,5.3028202,2.0205138,0.0,0,7.9926691,0.0,0.14467312,58.410179,8.040144,456.76166,-9.2333803
3110,3110,195.5142,5.3095288,2.0529284,0.0,0,7.9635415,0.0,0.14707145,58.358242,8.0107183,456.71194,-9.2321253
3121,3121,195.5164,5.2934346,2.0777218,0.0,0,7.9344139,0.0,0.14912331,58.068947,7.9758778,456.65924,-9.2326717
3132,3132,195.5186,5.2772202,2.1137509,0.0,0,7.9052858,0.0,0.15177661,57.742039,7.9513745,456.60654,-9.2325344
3143,3143,195.5208,5.2839756,2.1370459,0.0,0,7.8761578,0.0,0.15365133,57.629486,7.9244781,456.55383,-9.232399
3154,3154,195.523,5.3201885,2.1657426,0.0,0,7.8470297,0.0,0.15590723,57.846317,7.8949356,456.58469,-9.2337351
3165,3165,195.5252,5.3379011,2.1934075,0.0,0,7.8179016,0.0,0.15805539,58.059193,7.8625793,456.73621,-9.2334166
3176,3176,195.5274,5.3641143,2.2266436,0.0,0,7.7887735,0.0,0.16066204,58.125332,7.8361254,456.88773,-9.2333517
3187,3187,195.5296,5.383985,2.2519014,0.0,0,7.7596455,0.0,0.16259614,58.224949,7.8052659,457.03922,-9.2321939
3198,3198,195.5318,5.3974767,2.2816203,0.0,0,7.7305174,0.0,0.1650416,58.279549,7.7736802,457.19073,-9.2320061
3209,3209,195.534,5.391068,2.3107269,0.0,0,7.7013893,0.0,0.16719295,58.108086,7.7457433,457.38208,-9.2322159
3220,3220,195.5362,5.3852024,2.342921,0.0,0,7.6722617,0.0,0.16990645,57.917866,7.716526,457.57968,-9.2330599
3231,3231,195.5384,5.3830566,2.3686779,0.0,0,7.6431332,0.0,0.17172337,57.704536,7.6928954,457.77731,-9.2342291
3242,3242,195.5406,5.4284635,2.397742,0.0,0,7.6140056,0.0,0.17420581,58.092335,7.6563287,457.97495,-9.23314
3253,3253,195.5428,5.4635949,2.4268615,0.0,0,7.5848775,0.0,0.17633462,58.252949,7.6242204,458.14111,-9.2334423
3264,3264,195.545,5.4811587,2.4625504,0.0,0,7.5557494,0.0,0.17942531,58.27486,7.5962524,458.23993,-9.2323093
3275,3275,195.5472,5.4802074,2.4900551,0.0,0,7.5266213,0.0,0.18130115,58.202633,7.5648313,458.33871,-9.2333107
3286,3286,195.5494,5.4724736,2.5169613,0.0,0,7.4974933,0.0,0.18377116,57.939781,7.5398669,458.43753,-9.2322922
3297,3297,195.5516,5.4708695,2.5431142,0.0,0,7.4683657,0.0,0.18559711,57.893394,7.5089679,458.53632,-9.2327948
3308,3308,195.5538,5.4589114,2.5715835,0.0,0,7.4392376,0.0,0.18830147,57.65572,7.4829178,458.6554,-9.2329369
3319,3319,195.556,5.4741135,2.600117,0.0,0,7.410109,0.0,0.19012356,57.639565,7.4552751,458.78043,-9.2334719
3330,3330,195.5582,5.5067549,2.6287584,0.0,0,7.3815403,0.0,0.192782,57.754288,7.4224296,458.90543,-9.2322206
3341,3341,195.5604,5.5643034,2.657999,0.0,0,7.353838,0.0,0.19480319,58.343117,7.3957424,459.03046,-9.2321234
3352,3352,195.5626,5.5874033,2.6896899,0.0,0,7.3261356,0.0,0.19773233,58.377453,7.3610883,459.16296,-9.2333555
3363,3363,195.5648,5.5926056,2.7196615,0.0,0,7.2984333,0.0,0.19972828,58.25071,7.3331175,459.32083,-9.2333117
3374,3374,195.567,5.5835466,2.7444015,0.0,0,7.270731,0.0,0.20223659,58.059242,7.3035045,459.47873,-9.2319498
3385,3385,195.5692,5.5668087,2.7739453,0.0,0,7.2430286,0.0,0.20421343,57.788059,7.2748966,459.6366,-9.2321262
3396,3396,195.5714,5.571249,2.8026726,0.0,0,7.2153258,0.0,0.20713156,57.685131,7.2499285,459.79449,-9.2329388
3407,3407,195.5736,5.5558772,2.8315248,0.0,0,7.1876235,0.0,0.20883684,57.466953,7.222014,459.9165,-9.2335939
3418,3418,195.5758,5.5463634,2.8518319,0.0,0,7.1599212,0.0,0.21110129,57.199825,7.195766,460.02176,-9.2332487
3429,3429,195.578,5.5662894,2.8788929,0.0,0,7.1322188,0.0,0.21282493,57.268528,7.1700463,460.12698,-9.2327328
3440,3440,195.5802,5.6099563,2.9064016,0.0,0,7.104516,0.0,0.21568981,57.513363,7.1430354,460.23224,-9.2319593
3451,3451,195.5824,5.6338878,2.9360628,0.0,0,7.0768137,0.0,0.21740623,57.752159,7.1161952,460.31955,-9.2319498
3462,3462,195.5846,5.6625428,2.9590681,0.0,0,7.0491114,0.0,0.2199925,57.792229,7.0843778,460.29324,-9.2318716
3473,3473,195.5868,5.6859422,2.9896367,0.0,0,7.021409,0.0,0.22194791,57.911526,7.0590334,460.26694,-9.2320423
3484,3484,195.589,5.6980748,3.0160718,0.0,0,6.9937067,0.0,0.22476266,57.939983,7.0274315,460.24063,-9.2320576
3495,3495,195.5912,5.6930165,3.048629,0.0,0,6.9660039,0.0,0.2268012,57.771915,7.0027194,460.21432,-9.2319117
3506,3506,195.5934,5.6873579,3.0702143,0.0,0,6.938302,0.0,0.22936377,57.6227,6.9714317,459.93512,-9.2317772
3517,3517,195.5956,5.7017889,3.1015959,0.0,0,6.9105997,0.0,0.23131762,57.574326,6.9463329,459.48087,-9.2319698
3528,3528,195.5978,5.7166057,3.1258702,0.0,0,6.8828974,0.0,0.23406702,57.564468,6.9164505,459.02661,-9.2332373
3539,3539,195.6,5.7518544,3.1607172,0.0,0,6.8551946,0.0,0.23607185,57.836685,6.8900285,458.57233,-9.232604
3550,3550,195.6022,5.7654552,3.1806624,0.0,0,6.8274922,0.0,0.23856111,57.840652,6.8581176,458.1055,-9.2312803
3561,3561,195.6044,5.7863188,3.2110059,0.0,0,6.7997894,0.0,0.24055694,57.844646,6.8283691,457.37448,-9.2326584
3572,3572,195.6066,5.7935634,3.2370713,0.0,0,6.7720871,0.0,0.24340032,57.851871,6.8025365,456.64349,-9.2339592
3583,3583,195.6088,5.7975631,3.2714026,0.0,0,6.7452798,0.0,0.24550016,57.743015,6.7749939,455.91248,-9.2321053
3594,3594,195.611,5.8020592,3.2928917,0.0,0,6.718924,0.0,0.24813387,57.600418,6.7467017,455.18149,-9.2318821
3605,3605,195.6132,5.7968845,3.3227077,0.0,0,6.6925678,0.0,0.25006732,57.48642,6.7228041,454.61835,-9.2317715
3616,3616,195.6154,5.8067861,3.3459003,0.0,0,6.6662121,0.0,0.25276977,57.418625,6.6960659,454.22311,-9.2325554
3627,3627,195.6176,5.8365741,3.3813336,0.0,0,6.6398559,0.0,0.25495046,57.53006,6.6694102,453.82788,-9.23176
3638,3638,195.6198,5.8723168,3.4015622,0.0,0,6.6135001,0.0,0.25747988,57.702095,6.6372309,453.43265,-9.2319107
3649,3649,195.622,5.8593249,3.4305165,0.0,0,6.5871439,0.0,0.25934643,57.602612,6.6089916,453.03741,-9.2325201
3660,3660,195.6242,5.8558998,3.4538774,0.0,0,6.5607882,0.0,0.26203188,57.385132,6.5857205,453.09491,-9.2325821
3671,3671,195.6264,5.8570213,3.4875119,0.0,0,6.5344319,0.0,0.26402706,57.300343,6.5606523,453.17395,-9.2327728
3682,3682,195.6286,5.8916793,3.5045035,0.0,0,6.5080762,0.0,0.2663756,57.444321,6.5319595,453.25299,-9.2316628
3693,3693,195.6308,5.8947515,3.5335667,0.0,0,6.48172,0.0,0.26830575,57.435574,6.5070505,453.33203,-9.2325325
3704,3704,195.633,5.8900652,3.5570974,0.0,0,6.4553642,0.0,0.27101943,57.162369,6.476336,453.40518,-9.2331543
3715,3715,195.6352,5.8998394,3.5910032,0.0,0,6.4290085,0.0,0.27322659,57.121681,6.4517636,453.46976,-9.2319603
3726,3726,195.6374,5.9168377,3.6086395,0.0,0,6.4026518,0.0,0.27536073,57.164864,6.4281225,453.53433,-9.2330141
3737,3737,195.6396,5.9648461,3.6364503,0.0,0,6.376296,0.0,0.27736893,57.51601,6.4030061,453.59891,-9.2325678
3748,3748,195.6418,5.96662,3.6579058,0.0,0,6.3499398,0.0,0.27984673,57.445915,6.3769946,453.66348,-9.2322378
3759,3759,195.644,5.9500442,3.6919155,0.0,0,6.3235841,0.0,0.28213069,57.152008,6.3554277,453.61707,-9.2319956
3770,3770,195.6462,5.9908581,3.7122495,0.0,0,6.2972283,0.0,0.28447288,57.399811,6.3256855,453.53802,-9.2332811
3781,3781,195.6484,6.0154152,3.7408409,0.0,0,6.2708726,0.0,0.28661814,57.48315,6.2987981,453.45898,-9.2335901
3792,3792,195.6506,5.9995308,3.762686,0.0,0,6.2445164,0.0,0.28909475,57.231865,6.270432,453.37994,-9.2340555
3803,3803,195.6528,6.0159364,3.7984581,0.0,0,6.2181602,0.0,0.29162535,57.243774,6.247189,453.35178,-9.2324543
3814,3814,195.655,6.0522895,3.8174467,0.0,0,6.1918044,0.0,0.29395512,57.422958,6.2184248,453.4967,-9.2321424
3825,3825,195.6572,6.0716176,3.8452291,0.0,0,6.1654482,0.0,0.29597613,57.541847,6.1926389,453.64163,-9.232049
3836,3836,195.6594,6.0826464,3.8672383,0.0,0,6.1403008,0.0,0.2983304,57.438087,6.165585,453.78656,-9.2325287
3847,3847,195.6616,6.0873847,3.9004123,0.0,0,6.1152344,0.0,0.30083805,57.346428,6.1406579,453.93149,-9.2319269
3858,3858,195.6638,6.1028175,3.919992,0.0,0,6.0901675,0.0,0.30312392,57.434357,6.1145277,453.94168,-9.23314
3869,3869,195.666,6.1395879,3.9517965,0.0,0,6.0651007,0.0,0.30561179,57.626762,6.085773,453.88898,-9.2332268
3880,3880,195.6682,6.1581597,3.9757502,0.0,0,6.0400338,0.0,0.30809179,57.622887,6.0598207,453.83627,-9.2336197
3891,3891,195.6704,6.1430864,4.0108109,0.0,0,6.014967,0.0,0.31078047,57.288231,6.0294347,453.78357,-9.2335443
3902,3902,195.6726,6.1415877,4.0293908,0.0,0,5.9899006,0.0,0.31293225,57.120464,6.0058484,453.68958,-9.2323103
3913,3913,195.6748,6.1429973,4.0569592,0.0,0,5.9648333,0.0,0.31522694,57.075344,5.9791536,453.33383,-9.2324171
3924,3924,195.677,6.1484232,4.0769405,0.0,0,5.9397664,0.0,0.3172377,56.964508,5.9552135,452.97812,-9.2326097
3935,3935,195.6792,6.1470299,4.1084828,0.0,0,5.9147,0.0,0.31979185,56.854843,5.9342918,452.62241,-9.2326946
3946,3946,195.6814,6.1461411,4.1250825,0.0,0,5.8896332,0.0,0.32162338,56.678822,5.9090748,452.26666,-9.2328882
3957,3957,195.6836,6.160234,4.1492901,0.0,0,5.8645663,0.0,0.32379785,56.732292,5.8814206,452.0394,-9.2321377
3968,3968,195.6858,6.1678214,4.1713834,0.0,0,5.8394995,0.0,0.32587975,56.683746,5.8589478,451.90109,-9.2324715
3979,3979,195.688,6.1957769,4.2032847,0.0,0,5.8144326,0.0,0.3286415,56.779781,5.8368759,451.76276,-9.2331505
3990,3990,195.6902,6.2197752,4.2214384,0.0,0,5.7893653,0.0,0.3304598,56.881996,5.8102274,451.62442,-9.2341385
4001,4001,195.6924,6.2547741,4.2473731,0.0,0,5.7642989,0.0,0.33290374,57.098862,5.7876296,451.49896,-9.2326012
4012,4012,195.6946,6.2961292,4.268609,0.0,0,5.7392321,0.0,0.3348034,57.346828,5.761539,451.64389,-9.2318335
4023,4023,195.6968,6.3285332,4.3030777,0.0,0,5.7141652,0.0,0.33805311,57.483715,5.7353621,451.78882,-9.2318478
4034,4034,195.699,6.3338966,4.3239617,0.0,0,5.6890984,0.0,0.33998612,57.468357,5.7081265,451.93375,-9.2320004
4045,4045,195.7012,6.3219781,4.3497472,0.0,0,5.6640315,0.0,0.34254745,57.186878,5.6806135,452.07867,-9.2319803
4056,4056,195.7034,6.3036799,4.3736124,0.0,0,5.6389647,0.0,0.34453085,56.877594,5.6579523,452.27298,-9.2316561
4067,4067,195.7056,6.3130894,4.4007244,0.0,0,5.6138978,0.0,0.34742093,56.867134,5.6351213,452.51672,-9.2323685
4078,4078,195.7078,6.3628321,4.4240909,0.0,0,5.589088,0.0,0.34923983,57.075001,5.6042633,452.76044,-9.2326813
4089,4089,195.71,6.4055586,4.4498143,0.0,0,5.5652399,0.0,0.35201603,57.33625,5.5786834,453.00418,-9.2328634
4100,4100,195.7122,6.4309626,4.4751973,0.0,0,5.5413914,0.0,0.35410297,57.530563,5.5559201,453.24789,-9.2327795
4111,4111,195.7144,6.4108906,4.5054178,0.0,0,5.5175438,0.0,0.3573404,57.121811,5.5278039,453.42874,-9.2312403
4122,4122,195.7166,6.3949394,4.5269284,0.0,0,5.4936957,0.0,0.35894844,56.913437,5.5052094,453.60663,-9.2331924
4133,4133,195.7188,6.3942461,4.5471768,0.0,0,5.4698477,0.0,0.36133233,56.656811,5.4817615,453.78448,-9.2324848
4144,4144,195.721,6.3942137,4.5706997,0.0,0,5.4459996,0.0,0.36319545,56.633011,5.4598498,453.96234,-9.2332392
4155,4155,195.7232,6.3964214,4.5957713,0.0,0,5.4221516,0.0,0.36611253,56.551476,5.4375167,454.04318,-9.2329979
4166,4166,195.7254,6.4096832,4.6196823,0.0,0,5.3983035,0.0,0.36783734,56.47303,5.414536,453.98389,-9.2322369
4177,4177,195.7276,6.4109359,4.6390362,0.0,0,5.3744559,0.0,0.37022382,56.396202,5.3884721,453.92462,-9.2330732
4188,4188,195.7298,6.4537411,4.6619797,0.0,0,5.3506079,0.0,0.37190554,56.700382,5.369441,453.86533,-9.2319603
4199,4199,195.732,6.4849291,4.6875858,0.0,0,5.3267598,0.0,0.3750098,56.702999,5.3446393,453.80603,-9.2318935
4210,4210,195.7342,6.5049796,4.712842,0.0,0,5.3029118,0.0,0.37671453,56.843285,5.3234448,453.75812,-9.2319174
4221,4221,195.7364,6.5158033,4.732029,0.0,0,5.2790637,0.0,0.37922621,56.720333,5.2951818,453.71201,-9.2320824
4232,4232,195.7386,6.5477986,4.7565455,0.0,0,5.2552156,0.0,0.38094473,56.943836,5.2746592,453.66589,-9.2316933
4243,4243,195.7408,6.5958328,4.7839618,0.0,0,5.2313676,0.0,0.38443634,57.199215,5.2498126,453.61978,-9.2332973
4254,4254,195.743,6.6042948,4.8147383,0.0,0,5.20752,0.0,0.38670266,57.096519,5.2205191,453.6575,-9.2315941
4265,4265,195.7452,6.6299767,4.8355641,0.0,0,5.1836715,0.0,0.38949591,57.216408,5.1954966,453.87491,-9.2317858
4276,4276,195.7474,6.6569443,4.8622012,0.0,0,5.1598234,0.0,0.3914026,57.288857,5.1707516,454.09229,-9.2325068
4287,4287,195.7496,6.6370349,4.8855805,0.0,0,5.1359754,0.0,0.39446124,56.958523,5.1474996,454.30966,-9.2330723
4298,4298,195.7518,6.650023,4.9138794,0.0,0,5.1121278,0.0,0.39632452,56.90715,5.1215153,454.52704,-9.231967
4309,4309,195.754,6.6438971,4.9320755,0.0,0,5.0882797,0.0,0.39909047,56.789692,5.0970731,454.69861,-9.2325125
4320,4320,195.7562,6.6174173,4.9546719,0.0,0,5.0644317,0.0,0.40054372,56.505039,5.076705,454.85669,-9.2333117
4331,4331,195.7584,6.6136813,4.9751048,0.0,0,5.0411468,0.0,0.40339452,56.277634,5.0553532,455.0148,-9.2318554
4342,4342,195.7606,6.6396065,5.0046239,0.0,0,5.0184646,0.0,0.40530202,56.354191,5.029398,455.17288,-9.2314053
4353,4353,195.7628,6.6782217,5.0226679,0.0,0,4.9957829,0.0,0.40821287,56.599934,5.0080223,455.31152,-9.2310276
4364,4364,195.765,6.7281804,5.049026,0.0,0,4.9731011,0.0,0.40989465,56.894451,4.9816694,455.38397,-9.2317286
4375,4375,195.7672,6.7507515,5.070075,0.0,0,4.9504189,0.0,0.41294807,56.858826,4.9591432,455.45645,-9.2322226
4386,4386,195.7694,6.7500138,5.0996614,0.0,0,4.9277368,0.0,0.41479552,56.741623,4.9357295,455.52893,-9.2320709
4397,4397,195.7716,6.7323318,5.1136003,0.0,0,4.9050546,0.0,0.41730779,56.496326,4.9123349,455.60138,-9.2320919
4408,4408,195.7738,6.7347388,5.1385183,0.0,0,4.8823729,0.0,0.41899192,56.426849,4.8923907,455.73224,-9.2320004
4419,4419,195.776,6.7391906,5.1593881,0.0,0,4.8596911,0.0,0.42204118,56.292248,4.8708997,455.89035,-9.2319098
4430,4430,195.7782,6.7921491,5.1905699,0.0,0,4.8370085,0.0,0.42404032,56.577885,4.8467379,456.04843,-9.2321625
4441,4441,195.7804,6.8208895,5.2071009,0.0,0,4.8143268,0.0,0.42685872,56.66991,4.8202448,456.20654,-9.2318583
4452,4452,195.7826,6.8399348,5.2361174,0.0,0,4.7916451,0.0,0.42892945,56.7626,4.7993836,456.36642,-9.231492
4463,4463,195.7848,6.8702941,5.2547102,0.0,0,4.7689629,0.0,0.43171513,56.748589,4.7759767,456.53769,-9.2320013
4474,4474,195.787,6.8859162,5.2853971,0.0,0,4.7462807,0.0,0.43375722,56.820488,4.749136,456.70898,-9.2319517
4485,4485,195.7892,6.8729186,5.3005877,0.0,0,4.7235985,0.0,0.4363561,56.497398,4.7270036,456.88025,-9.2313976
4496,4496,195.7914,6.8564749,5.3263416,0.0,0,4.7009168,0.0,0.43817055,56.356216,4.7063384,457.05151,-9.2316427
4507,4507,195.7936,6.8160019,5.3415303,0.0,0,4.6782351,0.0,0.44068137,55.897224,4.6878633,457.10602,-9.2317076
4518,4518,195.7958,6.814671,5.3696976,0.0,0,4.6555529,0.0,0.44244304,55.774303,4.6677055,457.07965,-9.230875
4529,4529,195.798,6.8389363,5.3817816,0.0,0,4.6328707,0.0,0.4447175,55.759972,4.6451049,457.05331,-9.2313843
4540,4540,195.8002,6.9181066,5.4078584,0.0,0,4.610189,0.0,0.4467361,56.341892,4.6215897,457.02695,-9.2330303
4551,4551,195.8024,6.967217,5.4279513,0.0,0,4.5875068,0.0,0.44975293,56.503605,4.5995779,456.9949,-9.2326918
4562,4562,195.8046,7.0056825,5.4595389,0.0,0,4.5648251,0.0,0.45194384,56.799595,4.5788302,456.84341,-9.2312622
4573,4573,195.8068,7.0465121,5.4756565,0.0,0,4.5421429,0.0,0.4545756,56.936676,4.5497713,456.69189,-9.2320499
4584,4584,195.809,7.0500665,5.5025554,0.0,0,4.5202951,0.0,0.45673749,56.841549,4.5277166,456.54037,-9.2310534
4595,4595,195.8112,7.0383353,5.5198889,0.0,0,4.4987173,0.0,0.45928106,56.663261,4.5059237,456.38885,-9.2305498
4606,4606,195.8134,7.0274615,5.5511723,0.0,0,4.4771399,0.0,0.46157941,56.369141,4.4818258,456.28018,-9.2324581
4617,4617,195.8156,7.0341873,5.5678039,0.0,0,4.4555626,0.0,0.4642505,56.257813,4.4596944,456.21429,-9.2306242
4628,4628,195.8178,7.0503535,5.592165,0.0,0,4.4339848,0.0,0.46611398,56.323715,4.4386215,456.14841,-9.2316484
4639,4639,195.82,7.0964985,5.6092367,0.0,0,4.4124074,0.0,0.46873713,56.492546,4.4155746,456.08255,-9.2325048
4650,4650,195.8222,7.1091971,5.6403508,0.0,0,4.3908296,0.0,0.47120595,56.499168,4.3937707,456.01666,-9.2313566
4661,4661,195.8244,7.1114774,5.6550212,0.0,0,4.3692517,0.0,0.47339025,56.387337,4.3727078,455.85019,-9.2320337
4672,4672,195.8266,7.1308565,5.6794481,0.0,0,4.3476744,0.0,0.47550225,56.455856,4.3531246,455.67892,-9.231101
4683,4683,195.8288,7.1344376,5.6959076,0.0,0,4.326097,0.0,0.47793785,56.350811,4.3286729,455.50766,-9.2307959
4694,4694,195.831,7.1516995,5.7249331,0.0,0,4.3045192,0.0,0.48035979,56.330303,4.3065925,455.33636,-9.2330427
4705,4705,195.8332,7.1556325,5.7392564,0.0,0,4.2829418,0.0,0.4825592,56.255665,4.2872615,455.1058,-9.2313156
4716,4716,195.8354,7.1777782,5.7676234,0.0,0,4.261364,0.0,0.48514032,56.235241,4.2633958,454.78964,-9.2318211
4727,4727,195.8376,7.184113,5.7843838,0.0,0,4.2397861,0.0,0.48733974,56.164925,4.2465825,454.47345,-9.2320719
4738,4738,195.8398,7.2203903,5.8137712,0.0,0,4.2182088,0.0,0.49004728,56.225315,4.2181516,454.15726,-9.2314434
4749,4749,195.842,7.2286367,5.8283701,0.0,0,4.196631,0.0,0.49206948,56.27459,4.2052755,453.84106,-9.2318926
4760,4760,195.8442,7.2528491,5.8513956,0.0,0,4.1750536,0.0,0.49424297,56.368221,4.1800666,453.50781,-9.2330561
4771,4771,195.8464,7.2946577,5.8698845,0.0,0,4.1534758,0.0,0.4964999,56.555515,4.1592312,453.17184,-9.2322111
4782,4782,195.8486,7.3409266,5.8992791,0.0,0,4.1318984,0.0,0.49942696,56.74474,4.1386666,452.83588,-9.2319632
4793,4793,195.8508,7.345243,5.9169011,0.0,0,4.1103206,0.0,0.50166982,56.6441,4.1145635,452.49994,-9.231451
4804,4804,195.853,7.3469849,5.9405532,0.0,0,4.0887432,0.0,0.50411701,56.454212,4.0891294,452.24152,-9.2316647
4815,4815,195.8552,7.3771458,5.9603252,0.0,0,4.0671659,0.0,0.50635558,56.5588,4.0710497,452.14932,-9.2312317
4826,4826,195.8574,7.3842683,5.9880714,0.0,0,4.0456276,0.0,0.50946575,56.417503,4.0452433,452.0571,-9.2320414
4837,4837,195.8596,7.4020176,6.0065012,0.0,0,4.0250959,0.0,0.51142627,56.463615,4.0261278,451.96487,-9.2311573
4848,4848,195.8618,7.4104195,6.0275335,0.0,0,4.0045748,0.0,0.51388055,56.439335,4.0054364,451.87265,-9.2305079
4859,4859,195.864,7.4207129,6.0463996,0.0,0,3.9840529,0.0,0.51593417,56.38752,3.9862621,452.07056,-9.2321539
4870,4870,195.8662,7.4283338,6.0744362,0.0,0,3.9635313,0.0,0.51912636,56.284916,3.9625804,452.35382,-9.232193
4881,4881,195.8684,7.4371009,6.0891023,0.0,0,3.9430099,0.0,0.52064383,56.297173,3.9427326,452.63708,-9.2320127
4892,4892,195.8706,7.4367132,6.108748,0.0,0,3.9224882,0.0,0.52302599,56.163181,3.9176915,452.92035,-9.2317381
4903,4903,195.8728,7.4429841,6.1270518,0.0,0,3.9019666,0.0,0.52497309,56.065475,3.9009531,453.13025,-9.2306976
4914,4914,195.875,7.4768314,6.1536636,0.0,0,3.8814449,0.0,0.52822888,56.088783,3.8810449,453.0907,-9.2319155
4925,4925,195.8772,7.5030661,6.1726327,0.0,0,3.8609233,0.0,0.52987891,56.212311,3.8600063,453.05118,-9.2311163
4936,4936,195.8794,7.5196967,6.1907563,0.0,0,3.8404016,0.0,0.53242278,56.241222,3.841177,453.01166,-9.2321386
4947,4947,195.8816,7.5305796,6.2084618,0.0,0,3.8198802,0.0,0.534105,56.221313,3.8209352,452.97211,-9.2315779
4958,4958,195.8838,7.5427237,6.2341561,0.0,0,3.7993586,0.0,0.53739965,56.104481,3.7986212,452.29932,-9.2312536
4969,4969,195.886,7.5833087,6.2527514,0.0,0,3.778837,0.0,0.53896439,56.370968,3.7835817,451.33096,-9.2313719
4980,4980,195.8882,7.6069655,6.2710147,0.0,0,3.7583156,0.0,0.54167229,56.365963,3.7612476,450.36264,-9.2316761
4991,4991,195.8904,7.6197414,6.2909541,0.0,0,3.7377939,0.0,0.54325205,56.433376,3.7375195,449.39432,-9.2320366
5002,5002,195.8926,7.6358643,6.3170595,0.0,0,3.7172723,0.0,0.5469293,56.261894,3.7173476,448.47897,-9.2319727
5013,5013,195.8948,7.6741228,6.3373513,0.0,0,3.6967506,0.0,0.54858375,56.422993,3.6970811,447.89929,-9.2324762
5024,5024,195.897,7.7055874,6.3536348,0.0,0,3.676229,0.0,0.55105472,56.517078,3.6782594,447.31961,-9.2313805
5035,5035,195.8992,7.7347598,6.373167,0.0,0,3.6557074,0.0,0.55273026,56.600277,3.6556952,446.73993,-9.2324972
5046,5046,195.9014,7.752183,6.3993268,0.0,0,3.635186,0.0,0.55667394,56.595032,3.6372695,446.16025,-9.2321024
5057,5057,195.9036,7.7687125,6.4220881,0.0,0,3.6146641,0.0,0.55818713,56.604393,3.6141279,446.06711,-9.2324657
5068,5068,195.9058,7.7626338,6.4348707,0.0,0,3.5941427,0.0,0.56077188,56.430431,3.596859,446.31085,-9.2324142
5079,5079,195.908,7.7656507,6.4574637,0.0,0,3.5739219,0.0,0.56252426,56.332745,3.5774775,446.55457,-9.2319155
5090,5090,195.9102,7.7923985,6.4796324,0.0,0,3.554399,0.0,0.56618291,56.306316,3.5532165,446.79831,-9.2318974
5101,5101,195.9124,7.8012314,6.5012226,0.0,0,3.5348763,0.0,0.567581,56.280365,3.5350494,447.03873,-9.2316427
5112,5112,195.9146,7.819417,6.5150552,0.0,0,3.5153534,0.0,0.57018232,56.269779,3.5176356,447.20999,-9.2313166
5123,5123,195.9168,7.8380756,6.5353379,0.0,0,3.4958305,0.0,0.57164741,56.330101,3.4984851,447.38126,-9.2317562
5134,5134,195.919,7.8725877,6.5529685,0.0,0,3.4763079,0.0,0.57483852,56.408913,3.4746552,447.55255,-9.2318296
5145,5145,195.9212,7.9019237,6.57866,0.0,0,3.4567852,0.0,0.57672167,56.481255,3.4574451,447.72382,-9.2312012
5156,5156,195.9234,7.9094315,6.5943103,0.0,0,3.4372621,0.0,0.57964116,56.391827,3.4382963,448.03342,-9.2311392
5167,5167,195.9256,7.9227815,6.614512,0.0,0,3.4177396,0.0,0.58096796,56.379623,3.4172549,448.48135,-9.2311525
5178,5178,195.9278,7.9404597,6.6348867,0.0,0,3.3982165,0.0,0.58460277,56.391289,3.3974731,448.92929,-9.2316008
5189,5189,195.93,7.9603634,6.660533,0.0,0,3.3786941,0.0,0.58637887,56.403519,3.3780999,449.37723,-9.2320356
5200,5200,195.9322,8.007514,6.6720104,0.0,0,3.3591712,0.0,0.58898532,56.554329,3.3597789,449.82516,-9.2330198
5211,5211,195.9344,8.041153,6.6933413,0.0,0,3.339648,0.0,0.59040886,56.657063,3.3413923,450.33597,-9.2324066
5222,5222,195.9366,8.0535965,6.7105269,0.0,0,3.3201256,0.0,0.59382528,56.629551,3.3180223,450.84979,-9.2311497
5233,5233,195.9388,8.0588932,6.7390056,0.0,0,3.3006024,0.0,0.59561086,56.574501,3.301405,451.36359,-9.2317667
5244,5244,195.941,8.0445328,6.7489219,0.0,0,3.2810795,0.0,0.59831434,56.353077,3.2819152,451.87741,-9.2312937
5255,5255,195.9432,8.0547962,6.7705641,0.0,0,3.2615571,0.0,0.5997901,56.319572,3.2651131,452.28073,-9.2319155
5266,5266,195.9454,8.116169,6.7882953,0.0,0,3.242034,0.0,0.60303569,56.607105,3.2433724,452.52448,-9.2316332
5277,5277,195.9476,8.1756163,6.8173466,0.0,0,3.2225113,0.0,0.60512376,56.839153,3.2228892,452.76822,-9.2309971
5288,5288,195.9498,8.2081861,6.8276887,0.0,0,3.2029886,0.0,0.6079579,56.865566,3.2031736,453.01193,-9.2307758
5299,5299,195.952,8.2179499,6.8532557,0.0,0,3.1834657,0.0,0.60977632,56.844387,3.1845779,453.25568,-9.2316446
5310,5310,195.9542,8.2586527,6.8693681,0.0,0,3.1639431,0.0,0.613074,56.969368,3.1639433,453.43112,-9.2313147
5321,5321,195.9564,8.3086042,6.8958235,0.0,0,3.1444204,0.0,0.61484063,57.185211,3.143172,453.59583,-9.231926
5332,5332,195.9586,8.3082228,6.9047685,0.0,0,3.1254427,0.0,0.61744088,57.067272,3.1236908,453.7605,-9.2315025
5343,5343,195.9608,8.3135691,6.9310141,0.0,0,3.1068702,0.0,0.61957592,56.988865,3.1021008,453.9252,-9.2312384
5354,5354,195.963,8.3255863,6.9466119,0.0,0,3.0882978,0.0,0.62265855,56.894238,3.0853438,454.06891,-9.2309036
5365,5365,195.9652,8.332592,6.9775171,0.0,0,3.0697253,0.0,0.62503272,56.746159,3.0667279,454.16772,-9.2312765
5376,5376,195.9674,8.3710022,6.9870162,0.0,0,3.0511529,0.0,0.62754965,56.876396,3.0478752,454.26654,-9.2325687
5387,5387,195.9696,8.4035845,7.0084605,0.0,0,3.0325809,0.0,0.62919217,56.950874,3.0294795,454.36536,-9.2317553
5398,5398,195.9718,8.4065266,7.0228019,0.0,0,3.0140083,0.0,0.63204497,56.884796,3.0082908,454.46417,-9.2314787
5409,5409,195.974,8.3900404,7.0488253,0.0,0,2.995436,0.0,0.63392836,56.650986,2.9906402,454.45099,-9.2327471
5420,5420,195.9762,8.3719797,7.0572114,0.0,0,2.9768634,0.0,0.63628137,56.46022,2.9765844,454.40488,-9.230998
5431,5431,195.9784,8.3900604,7.0801306,0.0,0,2.9582911,0.0,0.63833863,56.424213,2.9576614,454.3588,-9.232398
5442,5442,195.9806,8.4454918,7.0944376,0.0,0,2.9397185,0.0,0.64100528,56.633461,2.9378431,454.31268,-9.2317028
5453,5453,195.9828,8.4893103,7.1225214,0.0,0,2.9211462,0.0,0.64337516,56.811111,2.9192197,454.26355,-9.2298517
5464,5464,195.985,8.5211992,7.1314235,0.0,0,2.9025741,0.0,0.64554298,56.862766,2.8999977,454.20428,-9.2314854
5475,5475,195.9872,8.5774679,7.1538181,0.0,0,2.8840015,0.0,0.64764029,57.132587,2.8836246,454.14499,-9.2320108
5486,5486,195.9894,8.6206636,7.1677032,0.0,0,2.8654292,0.0,0.65023118,57.25058,2.8619444,454.08569,-9.2316093
5497,5497,195.9916,8.6555758,7.1967983,0.0,0,2.8468566,0.0,0.65279758,57.399841,2.8443561,454.0264,-9.2315903
5508,5508,195.9938,8.6809444,7.2079153,0.0,0,2.8282843,0.0,0.65521353,57.433594,2.8257799,453.98059,-9.2324743
5519,5519,195.996,8.7075291,7.2323256,0.0,0,2.8097117,0.0,0.6576249,57.464043,2.8059516,453.94107,-9.2319641
5530,5530,195.9982,8.7000971,7.2457476,0.0,0,2.7911394,0.0,0.66015792,57.246876,2.7877195,453.90155,-9.2334604
5541,5541,196.0004,8.7231007,7.271317,0.0,0,2.772567,0.0,0.66253835,57.220852,2.7673886,453.86203,-9.2327995
5552,5552,196.0026,8.7663422,7.2843761,0.0,0,2.7539945,0.0,0.66511363,57.398087,2.7505932,453.81531,-9.232934
5563,5563,196.0048,8.7965374,7.3076987,0.0,0,2.7354224,0.0,0.66759104,57.454735,2.7325127,453.72308,-9.2332859
5574,5574,196.007,8.8352795,7.3225422,0.0,0,2.7168498,0.0,0.6699968,57.56369,2.7127719,453.63086,-9.2316294
5585,5585,196.0092,8.8448782,7.3500409,0.0,0,2.6990449,0.0,0.67287213,57.463638,2.6928186,453.53864,-9.2332506
5596,5596,196.0114,8.8633738,7.3606734,0.0,0,2.6813788,0.0,0.6748153,57.47982,2.67572,453.44641,-9.2318172
5607,5607,196.0136,8.8702965,7.3817797,0.0,0,2.663713,0.0,0.6773017,57.384827,2.6564896,453.47876,-9.2322159
5618,5618,196.0158,8.8886309,7.3950791,0.0,0,2.6460469,0.0,0.67943895,57.370865,2.6373558,453.59732,-9.2322102
5629,5629,196.018,8.8932762,7.4220376,0.0,0,2.6283808,0.0,0.68252617,57.209442,2.6205912,453.71591,-9.2320757
5640,5640,196.0202,8.9109793,7.4329114,0.0,0,2.6107149,0.0,0.68436563,57.221024,2.6030016,453.83447,-9.2320108
5651,5651,196.0224,8.895462,7.4530106,0.0,0,2.5930488,0.0,0.6867373,56.974068,2.5873506,453.96112,-9.2318754
5662,5662,196.0246,8.9142599,7.4663367,0.0,0,2.5753827,0.0,0.6886397,56.986214,2.5708323,454.25757,-9.2307367
5673,5673,196.0268,8.9660473,7.488205,0.0,0,2.5577168,0.0,0.69143754,57.145187,2.5545447,454.55399,-9.2299881
5684,5684,196.029,9.0608349,7.4996185,0.0,0,2.540051,0.0,0.69312859,57.696854,2.5395868,454.85043,-9.2318745
5695,5695,196.0312,9.1119862,7.5218177,0.0,0,2.5223849,0.0,0.6960876,57.835163,2.5152578,455.14685,-9.2316484
5706,5706,196.0334,9.1275806,7.5374722,0.0,0,2.5047188,0.0,0.69797033,57.844387,2.5002644,455.40378,-9.2303791
5717,5717,196.0356,9.124507,7.5615907,0.0,0,2.4870529,0.0,0.70148933,57.603516,2.4818039,455.62115,-9.230258
5728,5728,196.0378,9.1217585,7.5736938,0.0,0,2.4693868,0.0,0.70286506,57.482334,2.4654753,455.83853,-9.2303638
5739,5739,196.04,9.1535187,7.5923405,0.0,0,2.451721,0.0,0.70564365,57.529579,2.4456308,456.05591,-9.2298241
5750,5750,196.0422,9.189641,7.6066933,0.0,0,2.4340549,0.0,0.70727837,57.702698,2.4286442,456.27328,-9.2318001
5761,5761,196.0444,9.2173252,7.6291633,0.0,0,2.4163888,0.0,0.71072835,57.654675,2.4155753,456.44037,-9.2319555
5772,5772,196.0466,9.2726049,7.6454754,0.0,0,2.3987229,0.0,0.71235812,57.907509,2.3957806,456.60504,-9.2322311
5783,5783,196.0488,9.3048372,7.6627898,0.0,0,2.3810568,0.0,0.71528667,57.896297,2.378139,456.76974,-9.2314234
5794,5794,196.051,9.336772,7.6765013,0.0,0,2.3633907,0.0,0.71674687,58.079231,2.3595939,456.93442,-9.2323465
5805,5805,196.0532,9.3572598,7.6992269,0.0,0,2.3457248,0.0,0.72036493,57.993553,2.3416369,457.08023,-9.2317247
5816,5816,196.0554,9.4029465,7.7179542,0.0,0,2.3280587,0.0,0.72222906,58.168503,2.3236327,457.19882,-9.2311668
5827,5827,196.0576,9.4181404,7.7334733,0.0,0,2.3104959,0.0,0.7250607,58.05619,2.30603,457.31738,-9.2313366
5838,5838,196.0598,9.4865217,7.7497282,0.0,0,2.2936921,0.0,0.72659141,58.396832,2.286304,457.43594,-9.2294893
5849,5849,196.062,9.5378189,7.7711282,0.0,0,2.2768884,0.0,0.73045987,58.457436,2.2680452,457.5545,-9.2299585
5860,5860,196.0642,9.545784,7.7891307,0.0,0,2.2600849,0.0,0.73188043,58.502892,2.249469,457.62189,-9.2302046
5871,5871,196.0664,9.5369034,7.8051815,0.0,0,2.2432811,0.0,0.73511243,58.22496,2.2317696,457.68115,-9.2313318
5882,5882,196.0686,9.5241709,7.8221555,0.0,0,2.2264779,0.0,0.73662692,58.096817,2.2188647,457.74045,-9.2319345
5893,5893,196.0708,9.5156803,7.8390703,0.0,0,2.2096741,0.0,0.73998654,57.838165,2.2034044,457.79971,-9.2312136
5904,5904,196.073,9.515646,7.8579025,0.0,0,2.1928706,0.0,0.74151641,57.713253,2.1889691,457.65781,-9.2303629
5915,5915,196.0752,9.5431719,7.8713655,0.0,0,2.1760669,0.0,0.74425453,57.73447,2.1713736,457.08472,-9.2302122
5926,5926,196.0774,9.59202,7.8845997,0.0,0,2.1592634,0.0,0.74506801,57.881577,2.1548619,456.5116,-9.2308855
5937,5937,196.0796,9.6657162,7.9003501,0.0,0,2.1424596,0.0,0.74867582,58.168316,2.1380713,455.93851,-9.2311134
5948,5948,196.0818,9.7203131,7.9210277,0.0,0,2.1256561,0.0,0.75023174,58.460361,2.1197736,455.36542,-9.2311659
5959,5959,196.084,9.7594166,7.9332995,0.0,0,2.1088524,0.0,0.75324064,58.520489,2.1020327,453.31003,-9.2305059
5970,5970,196.0862,9.7867117,7.9514446,0.0,0,2.0920489,0.0,0.7545867,58.60318,2.0868216,450.81863,-9.2302914
5981,5981,196.0884,9.8125219,7.9688473,0.0,0,2.0752454,0.0,0.75841308,58.535061,2.0680566,448.32724,-9.2309628
5992,5992,196.0906,9.8259716,7.9878631,0.0,0,2.0584419,0.0,0.75963777,58.558712,2.0579166,445.83588,-9.2310753
6003,6003,196.0928,9.8664837,8.0003815,0.0,0,2.0416381,0.0,0.76283318,58.584473,2.0376036,443.3353,-9.2312984
6014,6014,196.095,9.9341755,8.0209761,0.0,0,2.0248346,0.0,0.76437068,58.909019,2.0192871,440.80338,-9.2319508
6025,6025,196.0972,9.9963303,8.0359964,0.0,0,2.0080309,0.0,0.76806927,59.074768,2.0046163,438.27148,-9.2317238
6036,6036,196.0994,10.071749,8.0608568,0.0,0,1.9912274,0.0,0.76993966,59.396297,1.9870741,435.73959,-9.2302523
6047,6047,196.1016,10.091407,8.0714674,0.0,0,1.9744238,0.0,0.77322453,59.300663,1.9718825,433.2077,-9.2298203
6058,6058,196.1038,10.098513,8.0908842,0.0,0,1.9576201,0.0,0.77459168,59.315929,1.9539305,431.90277,-9.2312117
6069,6069,196.106,10.135428,8.1039133,0.0,0,1.9408166,0.0,0.7780025,59.251339,1.9356027,431.17044,-9.2303734
6080,6080,196.1082,10.15204,8.1287241,0.0,0,1.9243339,0.0,0.77973998,59.291832,1.91748,430.43811,-9.2302895
6091,6091,196.1104,10.145761,8.1399069,0.0,0,1.9083487,0.0,0.78317869,59.066006,1.9020081,429.70578,-9.2312336
6102,6102,196.1126,10.170153,8.1604671,0.0,0,1.8923634,0.0,0.78453338,59.066254,1.8851738,429.1156,-9.2325125
6113,6113,196.1148,10.205193,8.173625,0.0,0,1.8763782,0.0,0.78818172,59.100227,1.868431,429.42566,-9.2325506
6124,6124,196.117,10.252006,8.1971111,0.0,0,1.860393,0.0,0.78959507,59.244133,1.8533213,429.73575,-9.2318602
6135,6135,196.1192,10.30886,8.2013302,0.0,0,1.8444078,0.0,0.7922169,59.40136,1.8362406,430.04584,-9.2303886
6146,6146,196.1214,10.352094,8.2258272,0.0,0,1.8284227,0.0,0.7941547,59.560635,1.8208334,430.35593,-9.2309237
6157,6157,196.1236,10.382114,8.2379227,0.0,0,1.8124374,0.0,0.79765218,59.566422,1.8050923,431.00909,-9.2295523
6168,6168,196.1258,10.402308,8.2636337,0.0,0,1.7964523,0.0,0.79954392,59.545906,1.788167,431.89978,-9.2302046
6179,6179,196.128,10.416262,8.2736893,0.0,0,1.780467,0.0,0.80275428,59.441521,1.7700125,432.79044,-9.2293415
6190,6190,196.1302,10.406625,8.2925816,0.0,0,1.7644818,0.0,0.80418855,59.329453,1.7561525,433.68112,-9.2306013
6201,6201,196.1324,10.427997,8.3023119,0.0,0,1.7484967,0.0,0.8071748,59.235104,1.7386725,434.573,-9.2315245
6212,6212,196.1346,10.464276,8.3288097,0.0,0,1.7325114,0.0,0.80919045,59.293209,1.7258917,435.49005,-9.2313042
6223,6223,196.1368,10.490487,8.3330717,0.0,0,1.7165262,0.0,0.8116734,59.290649,1.7108818,436.4071,-9.2308359
6234,6234,196.139,10.502309,8.352457,0.0,0,1.700541,0.0,0.81326044,59.350689,1.6947817,437.32419,-9.2312794
6245,6245,196.1412,10.551042,8.3628569,0.0,0,1.6845558,0.0,0.81621552,59.394722,1.6804461,438.24124,-9.2319565
6256,6256,196.1434,10.581018,8.3860989,0.0,0,1.6685706,0.0,0.81783754,59.514378,1.6620224,438.99997,-9.2319212
6267,6267,196.1456,10.612428,8.3898916,0.0,0,1.6525854,0.0,0.82011181,59.502895,1.6515598,439.60034,-9.2320795
6278,6278,196.1478,10.67638,8.4141331,0.0,0,1.6366003,0.0,0.82241118,59.73349,1.6337521,440.20071,-9.2325392
6289,6289,196.15,10.735647,8.4253597,0.0,0,1.620615,0.0,0.82551938,59.890579,1.6180581,440.80109,-9.2309923
6300,6300,196.1522,10.851021,8.4507008,0.0,0,1.6046298,0.0,0.82783282,60.344681,1.6020929,441.40149,-9.2295809
6311,6311,196.1544,10.92506,8.4565296,0.0,0,1.5886445,0.0,0.83016688,60.593552,1.5842286,441.76874,-9.2307453
6322,6322,196.1566,10.972638,8.4801121,0.0,0,1.5726594,0.0,0.83243656,60.798771,1.5655789,442.12491,-9.2322245
6333,6333,196.1588,11.015999,8.491334,0.0,0,1.5571918,0.0,0.83551705,60.816109,1.5475293,442.48108,-9.2325697
6344,6344,196.161,11.035826,8.5169392,0.0,0,1.5419855,0.0,0.8381635,60.798809,1.5326197,442.83725,-9.2329197
6355,6355,196.1632,11.055624,8.5228119,0.0,0,1.5267792,0.0,0.84031928,60.729244,1.5139313,443.12326,-9.2323112
6366,6366,196.1654,11.0639,8.5455904,0.0,0,1.5115727,0.0,0.84301955,60.616077,1.4989896,443.30789,-9.2301235
6377,6377,196.1676,11.038129,8.5576296,0.0,0,1.4963663,0.0,0.84561694,60.344242,1.4857908,443.49255,-9.2313747
6388,6388,196.1698,11.051008,8.5829649,0.0,0,1.4811599,0.0,0.84832418,60.24641,1.470896,443.67719,-9.2305698
6399,6399,196.172,11.05406,8.5872879,0.0,0,1.4659536,0.0,0.85013008,60.16885,1.4543833,443.86182,-9.2326746
6410,6410,196.1742,11.079127,8.6068401,0.0,0,1.4507471,0.0,0.85232753,60.125721,1.4372629,443.79593,-9.2314053
6421,6421,196.1764,11.08602,8.6144915,0.0,0,1.4355407,0.0,0.85435975,60.076385,1.4263371,443.69046,-9.2311592
6432,6432,196.1786,11.115293,8.6383152,0.0,0,1.4203343,0.0,0.85721022,60.078011,1.4164973,443.58502,-9.2318497
6443,6443,196.1808,11.185771,8.6447315,0.0,0,1.4051279,0.0,0.85902375,60.306023,1.4030173,443.47955,-9.231514
6454,6454,196.183,11.260958,8.6629686,0.0,0,1.3899214,0.0,0.8613804,60.553738,1.3855135,443.3468,-9.2296886
6465,6465,196.1852,11.352389,8.6722307,0.0,0,1.3747151,0.0,0.86320752,60.965733,1.3699703,443.15558,-9.2304039
6476,6476,196.1874,11.471836,8.6981077,0.0,0,1.3595088,0.0,0.86695606,61.384182,1.3543996,442.96432,-9.230422
6487,6487,196.1896,11.564661,8.7075939,0.0,0,1.3443023,0.0,0.86878687,61.717079,1.3380222,442.7731,-9.2304888
6498,6498,196.1918,11.604013,8.7276211,0.0,0,1.3290958,0.0,0.87172222,61.8018,1.3201041,442.58185,-9.2315178
6509,6509,196.194,11.632297,8.7394733,0.0,0,1.3138895,0.0,0.87382549,61.794102,1.3041307,441.90112,-9.230814
6520,6520,196.1962,11.631636,8.7617683,0.0,0,1.2986832,0.0,0.87731981,61.612877,1.2843547,441.07642,-9.2305689
6531,6531,196.1984,11.615404,8.7712269,0.0,0,1.2834768,0.0,0.87872106,61.395424,1.2739085,440.25171,-9.2316027
6542,6542,196.2006,11.593932,8.7893524,0.0,0,1.2682704,0.0,0.88171381,61.134415,1.2602265,439.427,-9.2315092
6553,6553,196.2028,11.573911,8.8004646,0.0,0,1.2530639,0.0,0.88348579,60.942013,1.2454604,438.50934,-9.2311525
6564,6564,196.205,11.618559,8.8205948,0.0,0,1.2378575,0.0,0.88687676,60.902206,1.2315804,437.2756,-9.2311935
6575,6575,196.2072,11.700109,8.8275795,0.0,0,1.2226511,0.0,0.88784736,61.262901,1.2160051,436.04187,-9.2306223
6586,6586,196.2094,11.778816,8.8437109,0.0,0,1.2081418,0.0,0.89069986,61.497768,1.2015697,434.80814,-9.2312794
6597,6597,196.2116,11.853141,8.8543634,0.0,0,1.193679,0.0,0.89205611,61.794353,1.1885852,433.57437,-9.2313461
6608,6608,196.2138,11.93422,8.874095,0.0,0,1.1792163,0.0,0.89571583,62.07098,1.1708601,432.66,-9.2316103
6619,6619,196.216,11.977342,8.8867006,0.0,0,1.1647533,0.0,0.89722651,62.180893,1.1586111,431.89468,-9.2304802
6630,6630,196.2182,12.027025,8.9021673,0.0,0,1.1502906,0.0,0.90045995,62.225796,1.1371254,431.12936,-9.2303038
6641,6641,196.2204,12.058121,8.9178114,0.0,0,1.1358278,0.0,0.90236336,62.277195,1.1258092,430.36404,-9.2295713
6652,6652,196.2226,12.070436,8.9361296,0.0,0,1.121365,0.0,0.90611446,62.140026,1.1107123,429.70575,-9.2298136
6663,6663,196.2248,12.07167,8.9464264,0.0,0,1.1069021,0.0,0.90680295,62.063763,1.0965229,429.72556,-9.2302313
6674,6674,196.227,12.124014,8.9596939,0.0,0,1.0924393,0.0,0.91000122,62.143951,1.0797033,429.74536,-9.2304564
6685,6685,196.2292,12.146555,8.9727974,0.0,0,1.0779766,0.0,0.91124964,62.208435,1.0675277,429.76514,-9.2301064
6696,6696,196.2314,12.18706,8.9896917,0.0,0,1.0635136,0.0,0.91526151,62.141739,1.0567577,429.78494,-9.2297792
6707,6707,196.2336,12.215725,9.0035019,0.0,0,1.0490509,0.0,0.91613352,62.243629,1.0391167,430.11661,-9.2294083
6718,6718,196.2358,12.241652,9.0151167,0.0,0,1.0345882,0.0,0.91932291,62.214916,1.0285189,430.66422,-9.2301779
6729,6729,196.238,12.253675,9.0305138,0.0,0,1.0201254,0.0,0.92061824,62.158001,1.0160254,431.21182,-9.2303858
6740,6740,196.2402,12.306672,9.044404,0.0,0,1.0056624,0.0,0.92441744,62.148838,0.9999392,431.75943,-9.2313271
6751,6751,196.2424,12.388182,9.0573807,0.0,0,0.99119979,0.0,0.92522103,62.499092,0.98471606,432.30643,-9.2315702
6762,6762,196.2446,12.468025,9.0694132,0.0,0,0.97673696,0.0,0.92862648,62.682354,0.96990943,432.84082,-9.230937
6773,6773,196.2468,12.566237,9.0850449,0.0,0,0.96227413,0.0,0.9296115,63.110584,0.95850229,433.37524,-9.2305269
6784,6784,196.249,12.653204,9.0994492,0.0,0,0.94781131,0.0,0.93381542,63.314995,0.94300407,433.90964,-9.2301779
6795,6795,196.2512,12.734218,9.1172247,0.0,0,0.93334854,0.0,0.93510944,63.630642,0.92369586,434.44403,-9.2292023
6806,6806,196.2534,12.786757,9.127902,0.0,0,0.91888577,0.0,0.93863612,63.679913,0.90881866,434.63208,-9.2304087
6817,6817,196.2556,12.81096,9.1457024,0.0,0,0.90442294,0.0,0.93993926,63.756725,0.89647734,434.47372,-9.2316036
6828,6828,196.2578,12.867869,9.1585913,0.0,0,0.89010906,0.0,0.94409007,63.696915,0.88162166,434.3154,-9.2313557
6839,6839,196.26,12.924175,9.1791668,0.0,0,0.87635463,0.0,0.94544417,63.934669,0.86395156,434.15704,-9.2299843
6850,6850,196.2622,12.976319,9.1857805,0.0,0,0.86260027,0.0,0.94874078,63.917221,0.85358393,433.99872,-9.2289572
6861,6861,196.2644,13.025281,9.2039633,0.0,0,0.84884584,0.0,0.95003635,64.118057,0.83710366,433.43103,-9.2292786
6872,6872,196.2666,13.056387,9.2168827,0.0,0,0.83509147,0.0,0.9541266,64.004211,0.82498455,432.84384,-9.230588
6883,6883,196.2688,13.040366,9.2347012,0.0,0,0.82133704,0.0,0.95503312,63.889027,0.81064695,432.25665,-9.231143
6894,6894,196.271,13.049836,9.2421865,0.0,0,0.80758262,0.0,0.95853138,63.705933,0.79837543,431.66946,-9.2316771
6905,6905,196.2732,13.051068,9.2607718,0.0,0,0.79382825,0.0,0.95979309,63.625137,0.78333241,431.20911,-9.2305727
6916,6916,196.2754,13.075683,9.2694073,0.0,0,0.78007382,0.0,0.96332717,63.585304,0.77196735,430.93201,-9.2303972
6927,6927,196.2776,13.149756,9.2848177,0.0,0,0.76631945,0.0,0.96378636,63.835316,0.75826901,430.65491,-9.2311335
6938,6938,196.2798,13.239851,9.2915096,0.0,0,0.75256503,0.0,0.96709275,64.064499,0.7426818,430.37781,-9.2306633
6949,6949,196.282,13.319056,9.3126354,0.0,0,0.73881066,0.0,0.96889383,64.317734,0.7317329,430.10071,-9.2306862
6960,6960,196.2842,13.380721,9.3225965,0.0,0,0.72505623,0.0,0.97273993,64.350845,0.71854371,430.21106,-9.2303534
6971,6971,196.2864,13.450042,9.3420486,0.0,0,0.7113018,0.0,0.97367275,64.636749,0.7053383,430.3826,-9.2303257
6982,6982,196.2886,13.48909,9.3465738,0.0,0,0.69754744,0.0,0.97688752,64.665611,0.68504757,430.55414,-9.2303696
6993,6993,196.2908,13.51917,9.366662,0.0,0,0.68379307,0.0,0.978486,64.697479,0.67681825,430.72568,-9.2304783
7004,7004,196.293,13.560575,9.3755646,0.0,0,0.67003864,0.0,0.9820888,64.699348,0.66175205,430.9812,-9.2304249
7015,7015,196.2952,13.65032,9.3985519,0.0,0,0.65628421,0.0,0.98338723,64.960625,0.64885676,431.41663,-9.2306299
7026,7026,196.2974,13.719703,9.4016027,0.0,0,0.64252985,0.0,0.98652768,65.127586,0.63254321,431.85208,-9.2285242
7037,7037,196.2996,13.826171,9.4224005,0.0,0,0.62877542,0.0,0.98836815,65.499702,0.62112147,432.28754,-9.2276106
7048,7048,196.3018,13.879653,9.4320726,0.0,0,0.61502105,0.0,0.99217767,65.5158,0.60643822,432.72296,-9.2295446
7059,7059,196.304,13.87046,9.4554901,0.0,0,0.60126662,0.0,0.99398357,65.359917,0.58943278,433.2298,-9.2310209
7070,7070,196.3062,13.881129,9.4568863,0.0,0,0.58751225,0.0,0.99635488,65.250275,0.57785749,433.7576,-9.2308531
7081,7081,196.3084,13.852574,9.4730711,0.0,0,0.57407868,0.0,0.99765021,65.074081,0.56743181,434.2854,-9.2304783
7092,7092,196.3106,13.864014,9.4792595,0.0,0,0.56098866,0.0,1.0006342,64.941109,0.55523002,434.8132,-9.2304668
7103,7103,196.3128,13.928333,9.5040751,0.0,0,0.54789871,0.0,1.0028744,65.032043,0.5425511,435.33502,-9.2300863
7114,7114,196.315,14.034506,9.5071993,0.0,0,0.53480875,0.0,1.0053961,65.376144,0.52819532,435.83643,-9.2294397
7125,7125,196.3172,14.162365,9.52351,0.0,0,0.52171868,0.0,1.0067046,65.851784,0.51691055,436.33786,-9.2289619
7127,7127,196.3176,14.206944,9.5227938,0.0,0,0.51933873,0.0,1.0085571,65.973106,0.51338744,436.42902,-9.2303286