File: clean data/testID_0156.csv
level_0,index,Time(sec),Force(kN),Jaw(mm),PowAngle(deg),Power(W),Pram,PTemp,Strain,Stress(MPa),Stroke(mm),TC1(C),wedge(mm)
2565,2565,212.0374,0.653575,0.025910508,0.0,0,10.011864,0.0,0.0017786307,7.9997139,10.113722,498.93652,-9.2068853
2576,2576,212.0396,1.7865927,0.041086115,0.0,0,9.9788637,0.0,0.0026533811,22.440722,10.087641,498.96942,-9.2058382
2587,2587,212.0418,2.9093533,0.051420856,0.0,0,9.9458637,0.0,0.0034904953,36.776268,10.058281,499.00232,-9.206214
2598,2598,212.044,3.2944329,0.084914528,0.0,0,9.9128637,0.0,0.0055087176,41.590538,10.018871,499.65237,-9.206109
2609,2609,212.0462,3.4938607,0.11789052,0.0,0,9.8798637,0.0,0.0079342974,44.022785,9.9810972,500.53384,-9.2060757
2620,2620,212.0484,3.604532,0.15799764,0.0,0,9.8468628,0.0,0.01045629,45.393169,9.9409723,501.41531,-9.2066355
2631,2631,212.0506,3.6720874,0.18999872,0.0,0,9.8138638,0.0,0.012801085,46.09708,9.9027691,502.29675,-9.2054262
2642,2642,212.0528,3.7146108,0.23259515,0.0,0,9.7808638,0.0,0.015456033,46.616776,9.866848,503.18073,-9.2043524
2653,2653,212.055,3.7468772,0.26184759,0.0,0,9.7478638,0.0,0.01762611,46.848812,9.8296413,504.07532,-9.2056675
2664,2664,212.0572,3.7529519,0.29418728,0.0,0,9.7148628,0.0,0.019797256,46.935974,9.802103,504.96991,-9.2067814
2675,2675,212.0594,3.7516932,0.3239128,0.0,0,9.6818638,0.0,0.02181533,46.783985,9.7650433,505.8645,-9.2064123
2686,2686,212.0616,3.7739892,0.35916272,0.0,0,9.6488638,0.0,0.024106553,46.849274,9.7396584,506.75909,-9.2054186
2697,2697,212.0638,3.8287966,0.38588095,0.0,0,9.6158638,0.0,0.026028566,47.471592,9.7057524,507.13699,-9.2058353
2708,2708,212.066,3.857152,0.41819873,0.0,0,9.5828629,0.0,0.02821395,47.696629,9.6745148,507.24219,-9.2069864
2719,2719,212.0682,3.8759353,0.44802102,0.0,0,9.5498638,0.0,0.030278575,47.884735,9.638689,507.34741,-9.2064714
2730,2730,212.0704,3.9204555,0.48966771,0.0,0,9.5168638,0.0,0.033188365,48.367088,9.6029615,507.45261,-9.2062845
2741,2741,212.0726,3.9311316,0.52261955,0.0,0,9.4838638,0.0,0.035412919,48.316559,9.56744,507.55392,-9.205411
2752,2752,212.0748,3.928045,0.55866802,0.0,0,9.451623,0.0,0.038018975,48.16576,9.5297365,507.62625,-9.2062349
2763,2763,212.077,3.9234476,0.58848894,0.0,0,9.4194326,0.0,0.03999598,47.982632,9.4923019,507.69858,-9.2073231
2774,2774,212.0792,3.9110837,0.62634957,0.0,0,9.3872423,0.0,0.042725034,47.738289,9.4624538,507.7709,-9.2067442
2785,2785,212.0814,3.9163406,0.65646571,0.0,0,9.355051,0.0,0.044685572,47.655403,9.4308434,507.84323,-9.2077713
2796,2796,212.0836,3.933207,0.68703556,0.0,0,9.3228617,0.0,0.046828847,47.634212,9.3957863,507.93088,-9.2081308
2807,2807,212.0858,3.9469202,0.71325076,0.0,0,9.2906713,0.0,0.048642673,47.82674,9.3656569,508.02951,-9.2080755
2818,2818,212.088,3.9358976,0.74696916,0.0,0,9.258481,0.0,0.051171917,47.768448,9.33671,508.12814,-9.2064304
2829,2829,212.0902,3.9566009,0.77688557,0.0,0,9.2262897,0.0,0.053078484,47.80172,9.3046312,508.22678,-9.2060738
2840,2840,212.0924,3.9960601,0.80820942,0.0,0,9.1940994,0.0,0.055408686,48.110085,9.273406,508.3248,-9.2061701
2851,2851,212.0946,3.9954515,0.84122527,0.0,0,9.1619081,0.0,0.05756481,48.042229,9.2404318,508.41028,-9.2075415
2862,2862,212.0968,3.9939363,0.87767339,0.0,0,9.1297188,0.0,0.060404185,47.872925,9.2030993,508.49579,-9.2076015
2873,2873,212.099,3.9954922,0.90817058,0.0,0,9.0975285,0.0,0.062242102,47.750061,9.1668634,508.58127,-9.2069302
2884,2884,212.1012,4.0356121,0.93762445,0.0,0,9.0653381,0.0,0.064635962,48.091972,9.1361275,508.66675,-9.2073612
2895,2895,212.1034,4.0626507,0.97043324,0.0,0,9.0331469,0.0,0.066740006,48.364113,9.1059704,508.74554,-9.2069607
2906,2906,212.1056,4.0877881,1.0065593,0.0,0,9.0009575,0.0,0.069593892,48.583172,9.0732937,508.81787,-9.2075777
2917,2917,212.1078,4.073997,1.0406934,0.0,0,8.9687662,0.0,0.071594439,48.293941,9.0374117,508.8902,-9.2076311
2928,2928,212.11,4.0642037,1.0706022,0.0,0,8.9365768,0.0,0.074114993,48.078293,9.0013618,508.96252,-9.2071934
2939,2939,212.1122,4.0610218,1.1018109,0.0,0,8.9043856,0.0,0.076126449,47.969379,8.9726906,509.03485,-9.206707
2950,2950,212.1144,4.0559382,1.133665,0.0,0,8.8721952,0.0,0.078771628,47.723133,8.9415464,509.10721,-9.2070761
2961,2961,212.1166,4.0458207,1.1652792,0.0,0,8.8400049,0.0,0.080656536,47.521862,8.9070463,509.17953,-9.2074604
2972,2972,212.1188,4.0730424,1.192475,0.0,0,8.8078146,0.0,0.08296486,47.731541,8.8801203,509.25186,-9.2070742
2983,2983,212.121,4.132596,1.2247126,0.0,0,8.7756243,0.0,0.084954694,48.322521,8.8442783,509.32419,-9.2067747
2994,2994,212.1232,4.1585455,1.261023,0.0,0,8.7437658,0.0,0.088045381,48.51313,8.8089914,509.36209,-9.2061481
3005,3005,212.1254,4.1696458,1.2959443,0.0,0,8.7131491,0.0,0.090050958,48.522694,8.7747583,509.35553,-9.206707
3016,3016,212.1276,4.1227307,1.3240908,0.0,0,8.6825333,0.0,0.092517458,47.957165,8.7460651,509.34894,-9.2065487
3027,3027,212.1298,4.1230941,1.3538697,0.0,0,8.6519194,0.0,0.094325617,47.815411,8.7152576,509.34238,-9.2062483
3038,3038,212.132,4.1186309,1.3859956,0.0,0,8.6213045,0.0,0.097210556,47.593262,8.6829014,509.33582,-9.2065639
3049,3049,212.1342,4.1108289,1.4183681,0.0,0,8.5906887,0.0,0.098992407,47.354736,8.6512289,509.34106,-9.2066383
3060,3060,212.1364,4.1383576,1.4425818,0.0,0,8.5600729,0.0,0.10136584,47.589291,8.6233034,509.34763,-9.2060738
3071,3071,212.1386,4.1745157,1.4746954,0.0,0,8.529459,0.0,0.1032392,47.837963,8.5908356,509.35419,-9.2062168
3082,3082,212.1408,4.2023664,1.5054059,0.0,0,8.4988432,0.0,0.10603966,48.032864,8.5584774,509.36075,-9.2060776
3093,3093,212.143,4.214819,1.5417609,0.0,0,8.4682283,0.0,0.10814176,48.138256,8.5285597,509.3721,-9.2073603
3104,3104,212.1452,4.2081304,1.567049,0.0,0,8.4376125,0.0,0.11055433,48.036499,8.5004988,509.39185,-9.2053452
3115,3115,212.1474,4.1911526,1.5984162,0.0,0,8.4069986,0.0,0.11240637,47.773415,8.4651165,509.41156,-9.2065439
3126,3126,212.1496,4.2164149,1.6291802,0.0,0,8.3763819,0.0,0.11521687,47.845985,8.4376736,509.4313,-9.2065945
3137,3137,212.1518,4.2227726,1.6674162,0.0,0,8.345767,0.0,0.1174141,47.837101,8.4051495,509.45102,-9.205965
3148,3148,212.154,4.2180338,1.6914674,0.0,0,8.3151522,0.0,0.11986384,47.61153,8.3707638,509.39459,-9.2068338
3159,3159,212.1562,4.2499967,1.7252556,0.0,0,8.2845373,0.0,0.12185643,47.887684,8.3370094,509.32227,-9.2073956
3170,3170,212.1584,4.2712841,1.7522898,0.0,0,8.2539225,0.0,0.12444893,48.001091,8.3088818,509.24994,-9.2060719
3181,3181,212.1606,4.2888823,1.7879759,0.0,0,8.2233057,0.0,0.12650506,48.102737,8.2780628,509.17764,-9.2054977
3192,3192,212.1628,4.2903509,1.8138516,0.0,0,8.1926918,0.0,0.12913796,48.066883,8.243001,509.02496,-9.2062473
3203,3203,212.165,4.273128,1.8482726,0.0,0,8.162076,0.0,0.13123189,47.75478,8.212903,508.67645,-9.2064743
3214,3214,212.1672,4.2566714,1.8756217,0.0,0,8.1314611,0.0,0.13391615,47.393696,8.1817427,508.32794,-9.2065649
3225,3225,212.1694,4.2756085,1.9102963,0.0,0,8.1008453,0.0,0.135777,47.515743,8.1548271,507.97943,-9.2069597
3236,3236,212.1716,4.2902064,1.9335723,0.0,0,8.0702305,0.0,0.13824943,47.504734,8.1222401,507.63092,-9.2076588
3247,3247,212.1738,4.3034625,1.9677876,0.0,0,8.0403337,0.0,0.14042282,47.654167,8.0887766,507.28738,-9.2083015
3258,3258,212.176,4.3308167,1.9938097,0.0,0,8.0112057,0.0,0.14297117,47.803181,8.0599556,506.94543,-9.2060909
3269,3269,212.1782,4.3526034,2.0323281,0.0,0,7.9820776,0.0,0.14517024,47.869499,8.0303478,506.60352,-9.2062035
3280,3280,212.1804,4.3343425,2.0566764,0.0,0,7.95295,0.0,0.14762726,47.585262,7.9972582,506.2616,-9.2060919
3291,3291,212.1826,4.325438,2.0868943,0.0,0,7.9238219,0.0,0.14958273,47.459217,7.9695902,505.97849,-9.2061138
3302,3302,212.1848,4.3274384,2.1105666,0.0,0,7.8946939,0.0,0.15189438,47.334103,7.944171,505.90616,-9.2062988
3313,3313,212.187,4.3146353,2.1473114,0.0,0,7.8655658,0.0,0.1541533,47.024227,7.9083328,505.8338,-9.2064142
3324,3324,212.1892,4.3301873,2.1685646,0.0,0,7.8364377,0.0,0.15638161,47.13546,7.883604,505.76147,-9.2071829
3335,3335,212.1914,4.3336062,2.199168,0.0,0,7.8073092,0.0,0.1583664,47.080807,7.8520899,505.68915,-9.2071095
3346,3346,212.1936,4.3532982,2.224113,0.0,0,7.7781816,0.0,0.16072191,47.17625,7.8276887,505.36115,-9.2070379
3357,3357,212.1958,4.375145,2.2601247,0.0,0,7.7490535,0.0,0.16299251,47.305256,7.7948704,504.91385,-9.2067318
3368,3368,212.198,4.4076357,2.2824342,0.0,0,7.7199254,0.0,0.16519544,47.575729,7.7691917,504.46655,-9.205615
3379,3379,212.2002,4.4291301,2.3138378,0.0,0,7.6907973,0.0,0.16732089,47.747742,7.7384915,504.01926,-9.2058735
3390,3390,212.2024,4.4129415,2.3387864,0.0,0,7.6616693,0.0,0.16965945,47.492268,7.7060318,503.51166,-9.2054548
3401,3401,212.2046,4.4253411,2.3764615,0.0,0,7.6325412,0.0,0.17221624,47.452236,7.6763029,502.64987,-9.2062149
3412,3412,212.2068,4.4228482,2.3997068,0.0,0,7.6034136,0.0,0.17451933,47.309677,7.6451249,501.78809,-9.2055502
3423,3423,212.209,4.4325538,2.4336338,0.0,0,7.574285,0.0,0.17687054,47.256786,7.6147676,500.92627,-9.2059526
3434,3434,212.2112,4.4419069,2.4579134,0.0,0,7.5451574,0.0,0.17911053,47.195194,7.5896292,500.06448,-9.2061167
3445,3445,212.2134,4.4568806,2.4936967,0.0,0,7.5160294,0.0,0.18154027,47.349533,7.5589976,499.55127,-9.2056894
3456,3456,212.2156,4.4828963,2.51612,0.0,0,7.4869013,0.0,0.18370275,47.489388,7.5311112,499.26178,-9.2062302
3467,3467,212.2178,4.5063577,2.5479689,0.0,0,7.4577727,0.0,0.18603724,47.619816,7.5018191,498.97232,-9.2068253
3478,3478,212.22,4.5122452,2.5725911,0.0,0,7.4286451,0.0,0.18825045,47.534019,7.469317,498.68283,-9.2062521
3489,3489,212.2222,4.5043902,2.6101096,0.0,0,7.3995175,0.0,0.19088809,47.3116,7.4417353,498.43451,-9.2068272
3500,3500,212.2244,4.5074415,2.6344228,0.0,0,7.3714666,0.0,0.1932026,47.303642,7.4090986,498.71082,-9.2058496
3511,3511,212.2266,4.5209274,2.6652734,0.0,0,7.3437643,0.0,0.19549809,47.400993,7.3813949,498.98715,-9.2068224
3522,3522,212.2288,4.5347929,2.691134,0.0,0,7.316062,0.0,0.19779408,47.369865,7.3515658,499.26346,-9.2065973
3533,3533,212.231,4.5300279,2.7270532,0.0,0,7.2883596,0.0,0.20048791,47.25491,7.3227153,499.53979,-9.2062941
3544,3544,212.2332,4.5477581,2.7491982,0.0,0,7.2606573,0.0,0.20249927,47.250584,7.2961125,499.84082,-9.2046595
3555,3555,212.2354,4.5493293,2.7789223,0.0,0,7.232955,0.0,0.20485125,47.281116,7.2664933,500.16318,-9.2053127
3566,3566,212.2376,4.5481477,2.8029718,0.0,0,7.2052522,0.0,0.206862,47.136925,7.2382121,500.48557,-9.2060127
3577,3577,212.2398,4.5255704,2.8368578,0.0,0,7.1775503,0.0,0.20954542,46.728279,7.2118549,500.80795,-9.2055874
3588,3588,212.242,4.5222869,2.85798,0.0,0,7.1498475,0.0,0.21130405,46.590435,7.185833,501.13031,-9.2064371
3599,3599,212.2442,4.535387,2.8864706,0.0,0,7.1221447,0.0,0.21379532,46.626026,7.1556787,501.354,-9.2061882
3610,3610,212.2464,4.544764,2.9106386,0.0,0,7.0944424,0.0,0.21571295,46.611629,7.1256928,501.57767,-9.2060909
3621,3621,212.2486,4.5744767,2.9412553,0.0,0,7.0667405,0.0,0.21822645,46.828869,7.1027603,501.80136,-9.2073421
3632,3632,212.2508,4.6124287,2.9648893,0.0,0,7.0390377,0.0,0.22009858,47.144096,7.074286,502.02505,-9.2061539
3643,3643,212.253,4.6352506,2.9929972,0.0,0,7.0113349,0.0,0.22260749,47.211853,7.0432348,502.18161,-9.2070456
3654,3654,212.2552,4.6541786,3.018548,0.0,0,6.983633,0.0,0.22462586,47.340076,7.0171852,502.26059,-9.2073574
3665,3665,212.2574,4.6484613,3.0527034,0.0,0,6.9559307,0.0,0.22765146,47.187767,6.9900136,502.33954,-9.2068253
3676,3676,212.2596,4.6410947,3.0787048,0.0,0,6.9282284,0.0,0.22963625,47.003166,6.9603777,502.41849,-9.2065697
3687,3687,212.2618,4.6323395,3.1069281,0.0,0,6.9005256,0.0,0.23218639,46.753887,6.9305954,502.49744,-9.2062788
3698,3698,212.264,4.6262321,3.1316755,0.0,0,6.8728237,0.0,0.23399451,46.57856,6.9056745,502.69839,-9.2063589
3709,3709,212.2662,4.6729913,3.1622226,0.0,0,6.8451209,0.0,0.23687643,46.92696,6.8790193,502.90891,-9.2073965
3720,3720,212.2684,4.6964989,3.1889513,0.0,0,6.8174186,0.0,0.23872343,47.13131,6.8490319,503.11945,-9.2062769
3731,3731,212.2706,4.7157445,3.2157328,0.0,0,6.7897158,0.0,0.24141142,47.174488,6.8180418,503.32996,-9.2061176
3742,3742,212.2728,4.7200494,3.2440281,0.0,0,6.762064,0.0,0.24345501,47.129234,6.7922688,503.45819,-9.2073021
3753,3753,212.275,4.726788,3.2747607,0.0,0,6.7356958,0.0,0.24657172,47.072464,6.7633672,503.45819,-9.2058916
3764,3764,212.2772,4.7256527,3.3027353,0.0,0,6.7093401,0.0,0.24838248,46.939911,6.737226,503.45819,-9.2059259
3775,3775,212.2794,4.7071962,3.3257835,0.0,0,6.6829839,0.0,0.25083885,46.650204,6.7068143,503.45819,-9.2073269
3786,3786,212.2816,4.6947246,3.3527145,0.0,0,6.6566281,0.0,0.25271106,46.48093,6.6817422,503.45819,-9.2055321
3797,3797,212.2838,4.7156754,3.3791497,0.0,0,6.6302719,0.0,0.25552666,46.413128,6.6526232,502.94095,-9.2052317
3808,3808,212.286,4.7348676,3.4064581,0.0,0,6.6039157,0.0,0.25723654,46.582783,6.6266937,502.33569,-9.2060795
3819,3819,212.2882,4.7231588,3.4292333,0.0,0,6.5775599,0.0,0.25974506,46.377834,6.6052938,501.73041,-9.2058916
3830,3830,212.2904,4.7372174,3.452997,0.0,0,6.5512042,0.0,0.2613574,46.36132,6.5817394,501.12515,-9.2073498
3841,3841,212.2926,4.7515283,3.4797032,0.0,0,6.524848,0.0,0.26421866,46.394787,6.5537415,500.39426,-9.20683
3852,3852,212.2948,4.7649937,3.5086787,0.0,0,6.4984918,0.0,0.26617709,46.479401,6.5279255,499.39426,-9.2062349
3863,3863,212.297,4.7686667,3.5300863,0.0,0,6.472136,0.0,0.26863307,46.408863,6.500001,498.39423,-9.2062349
3874,3874,212.2992,4.775929,3.5572741,0.0,0,6.4457798,0.0,0.27034053,46.421711,6.478941,497.39423,-9.2062969
3885,3885,212.3014,4.7952585,3.5827589,0.0,0,6.4194241,0.0,0.27319998,46.441776,6.4476662,496.3942,-9.2063169
3896,3896,212.3036,4.8296642,3.6108196,0.0,0,6.3930678,0.0,0.27497733,46.603394,6.4243655,495.54849,-9.206089
3907,3907,212.3058,4.8718834,3.6364567,0.0,0,6.3667121,0.0,0.27800253,46.962463,6.3954763,494.74585,-9.2055464
3918,3918,212.308,4.8802519,3.6681771,0.0,0,6.3403563,0.0,0.28005254,46.992252,6.368535,493.94321,-9.2057581
3929,3929,212.3102,4.8878117,3.6946132,0.0,0,6.3140001,0.0,0.28316224,46.929436,6.337883,493.14053,-9.2063923
3940,3940,212.3124,4.8807263,3.7239642,0.0,0,6.2876444,0.0,0.2849108,46.750713,6.3111577,492.46225,-9.2058201
3951,3951,212.3146,4.8754039,3.7437658,0.0,0,6.2612886,0.0,0.28744,46.618355,6.2808876,492.1662,-9.2062111
3962,3962,212.3168,4.8838477,3.7751181,0.0,0,6.2349324,0.0,0.28955913,46.483898,6.2569404,491.87012,-9.2060995
3973,3973,212.319,4.8783031,3.8003089,0.0,0,6.2085767,0.0,0.29255274,46.319111,6.2317533,491.57407,-9.2052898
3984,3984,212.3212,4.8962021,3.8331439,0.0,0,6.1822205,0.0,0.29460561,46.43399,6.2024899,491.27802,-9.2059307
3995,3995,212.3234,4.9082904,3.8505013,0.0,0,6.1562529,0.0,0.29698965,46.287376,6.1779413,491.24789,-9.2057924
4006,4006,212.3256,4.9157896,3.8782718,0.0,0,6.1311855,0.0,0.29881933,46.382599,6.1505303,491.32684,-9.2068367
4017,4017,212.3278,4.9138641,3.9021208,0.0,0,6.1061187,0.0,0.30163732,46.242783,6.1285563,491.40579,-9.2062559
4028,4028,212.33,4.9272184,3.9333694,0.0,0,6.0810523,0.0,0.30355611,46.380978,6.1035271,491.48474,-9.2060118
4039,4039,212.3322,4.9526992,3.9519587,0.0,0,6.0559855,0.0,0.30621317,46.445667,6.072835,491.61368,-9.2060776
4050,4050,212.3344,4.9254985,3.9807472,0.0,0,6.0309186,0.0,0.30812511,46.115929,6.0492415,491.98212,-9.2062283
4061,4061,212.3366,4.9294691,4.0033722,0.0,0,6.0058517,0.0,0.31091219,46.024742,6.0264859,492.35056,-9.2061033
4072,4072,212.3388,4.9509711,4.0357666,0.0,0,5.9807849,0.0,0.31289294,46.101768,5.998383,492.71896,-9.2058201
4083,4083,212.341,4.9579415,4.0539155,0.0,0,5.9557185,0.0,0.31534219,46.027042,5.9720192,493.0874,-9.2062054
4094,4094,212.3432,4.9819832,4.0813336,0.0,0,5.9306512,0.0,0.31719187,46.148148,5.9482341,493.51025,-9.205678
4105,4105,212.3454,4.9767017,4.1012325,0.0,0,5.9055848,0.0,0.31986892,46.011806,5.9264464,493.9642,-9.206624
4116,4116,212.3476,4.9933009,4.1336303,0.0,0,5.880518,0.0,0.32174841,46.077328,5.9035006,494.41815,-9.206131
4127,4127,212.3498,5.0169554,4.1502271,0.0,0,5.8554511,0.0,0.32422599,46.137383,5.8742938,494.8721,-9.2058964
4138,4138,212.352,5.0405226,4.1798511,0.0,0,5.8303843,0.0,0.32627144,46.324852,5.8473506,495.32541,-9.2060375
4149,4149,212.3542,5.0625448,4.202354,0.0,0,5.8053174,0.0,0.3291713,46.358002,5.8218656,495.7728,-9.2066212
4160,4160,212.3564,5.0664182,4.2382054,0.0,0,5.7802501,0.0,0.33153597,46.304783,5.7930822,496.22015,-9.2058458
4171,4171,212.3586,5.0722246,4.2539544,0.0,0,5.7551837,0.0,0.3338623,46.134815,5.7699776,496.66754,-9.2053175
4182,4182,212.3608,5.0766869,4.2844801,0.0,0,5.7301168,0.0,0.33599085,46.164917,5.7417498,497.1149,-9.2055788
4193,4193,212.363,5.084796,4.3075686,0.0,0,5.7050505,0.0,0.33891064,46.135075,5.7180948,497.56598,-9.2053576
4204,4204,212.3652,5.0760846,4.3380666,0.0,0,5.6799831,0.0,0.34099907,45.923828,5.6927962,498.01996,-9.2061319
4215,4215,212.3674,5.0487642,4.3515086,0.0,0,5.6549168,0.0,0.34292933,45.682171,5.6678753,498.47391,-9.206049
4226,4226,212.3696,5.055038,4.3803043,0.0,0,5.6298494,0.0,0.34503728,45.54324,5.6459618,498.92786,-9.2062492
4237,4237,212.3718,5.0476418,4.3991766,0.0,0,5.6047826,0.0,0.34749293,45.357525,5.6241875,499.38022,-9.2060709
4248,4248,212.374,5.0524049,4.4330344,0.0,0,5.5804157,0.0,0.34984893,45.344467,5.5969191,499.77496,-9.2048969
4259,4259,212.3762,5.0953045,4.4464898,0.0,0,5.5565677,0.0,0.35179707,45.633419,5.5753655,500.16968,-9.2057686
4270,4270,212.3784,5.1508069,4.475019,0.0,0,5.5327196,0.0,0.35398948,45.970497,5.5543318,500.56442,-9.2074442
4281,4281,212.3806,5.1768036,4.4955053,0.0,0,5.5088716,0.0,0.35643786,46.132797,5.5286932,500.95917,-9.207304
4292,4292,212.3828,5.2016954,4.5298538,0.0,0,5.4850235,0.0,0.35913256,46.312519,5.5026259,501.35068,-9.2041903
4303,4303,212.385,5.222332,4.5478921,0.0,0,5.4611754,0.0,0.36140612,46.377949,5.4755459,501.73886,-9.2047291
4314,4314,212.3872,5.2196279,4.5786705,0.0,0,5.4373279,0.0,0.36400571,46.255463,5.4480338,502.12701,-9.2053175
4325,4325,212.3894,5.2068138,4.6007562,0.0,0,5.4134793,0.0,0.3665013,45.959873,5.4210877,502.5152,-9.2060728
4336,4336,212.3916,5.1820192,4.6349654,0.0,0,5.3896313,0.0,0.3692165,45.682682,5.3987398,502.90335,-9.2062197
4347,4347,212.3938,5.1760206,4.6485729,0.0,0,5.3657837,0.0,0.37099788,45.49791,5.3743877,503.25381,-9.2062445
4358,4358,212.396,5.1729679,4.6725788,0.0,0,5.3419356,0.0,0.37315854,45.314857,5.3515549,503.60245,-9.2054806
4369,4369,212.3982,5.1819191,4.6931887,0.0,0,5.3180876,0.0,0.37530759,45.34359,5.3308325,503.95111,-9.2052155
4380,4380,212.4004,5.2012234,4.7237082,0.0,0,5.2942395,0.0,0.37794945,45.431507,5.3103476,504.29977,-9.2051725
4391,4391,212.4026,5.2207785,4.7393489,0.0,0,5.2703915,0.0,0.37974826,45.427807,5.2833166,504.62088,-9.2050676
4402,4402,212.4048,5.2592988,4.7653766,0.0,0,5.2465439,0.0,0.38212767,45.638725,5.2617493,504.90369,-9.2063112
4413,4413,212.407,5.2752962,4.7859392,0.0,0,5.2226958,0.0,0.38434508,45.726288,5.240356,505.18646,-9.2061806
4424,4424,212.4092,5.2937465,4.8178525,0.0,0,5.1988478,0.0,0.38718656,45.796398,5.2122679,505.46924,-9.2062283
4435,4435,212.4114,5.2947111,4.8377748,0.0,0,5.1749997,0.0,0.38939729,45.634552,5.1900344,505.75204,-9.2060413
4446,4446,212.4136,5.3022828,4.8647509,0.0,0,5.1511517,0.0,0.39195707,45.537273,5.1635318,505.97101,-9.204505
4457,4457,212.4158,5.3294053,4.8845596,0.0,0,5.1273036,0.0,0.39392033,45.802589,5.1406736,506.18143,-9.2047501
4468,4468,212.418,5.3660865,4.9150343,0.0,0,5.1034555,0.0,0.39693058,45.934116,5.1133022,506.39185,-9.2044487
4479,4479,212.4202,5.3526297,4.9341779,0.0,0,5.079608,0.0,0.39886212,45.757568,5.0902319,506.60226,-9.2053652
4490,4490,212.4224,5.361834,4.9610353,0.0,0,5.0557599,0.0,0.40155578,45.699589,5.0684109,506.80814,-9.2058115
4501,4501,212.4246,5.3394427,4.9810638,0.0,0,5.0328989,0.0,0.40356484,45.469879,5.0408387,507.0054,-9.2051582
4512,4512,212.4268,5.3296294,5.0085788,0.0,0,5.0102167,0.0,0.40641466,45.203453,5.0200858,507.20267,-9.2059002
4523,4523,212.429,5.3346634,5.0288877,0.0,0,4.987535,0.0,0.40815529,45.160843,5.000113,507.39993,-9.2052298
4534,4534,212.4312,5.3724885,5.051568,0.0,0,4.9648528,0.0,0.41070488,45.303299,4.9785972,507.5972,-9.2062187
4545,4545,212.4334,5.3720584,5.0718713,0.0,0,4.9421706,0.0,0.41254112,45.244537,4.9545617,507.80511,-9.2058935
4556,4556,212.4356,5.4041147,5.0991182,0.0,0,4.9194889,0.0,0.41563872,45.347874,4.9290872,508.01553,-9.206254
4567,4567,212.4378,5.4229937,5.1212082,0.0,0,4.8968072,0.0,0.41743723,45.463699,4.9054174,508.22595,-9.2057781
4578,4578,212.44,5.4230437,5.141602,0.0,0,4.8741245,0.0,0.41989759,45.426163,4.8844342,508.43637,-9.2045116
4589,4589,212.4422,5.419682,5.1635842,0.0,0,4.8514428,0.0,0.42172807,45.285007,4.8632951,508.6217,-9.2058678
4600,4600,212.4444,5.4231963,5.1907701,0.0,0,4.8287606,0.0,0.42489976,45.12941,4.8387222,508.74005,-9.2066574
4611,4611,212.4466,5.4492083,5.2140174,0.0,0,4.8060789,0.0,0.42665631,45.284901,4.8141127,508.85843,-9.205987
4622,4622,212.4488,5.4649062,5.2337918,0.0,0,4.7833967,0.0,0.42935786,45.267208,4.7933078,508.97678,-9.2062626
4633,4633,212.451,5.4750829,5.2572012,0.0,0,4.7607145,0.0,0.43119007,45.267323,4.7686124,509.09515,-9.2060757
4644,4644,212.4532,5.5076857,5.282392,0.0,0,4.7380328,0.0,0.43442208,45.358685,4.7450118,509.12634,-9.2059412
4655,4655,212.4554,5.499661,5.3054438,0.0,0,4.7153511,0.0,0.43611699,45.261173,4.7223492,509.12634,-9.2054157
4666,4666,212.4576,5.5093536,5.3227015,0.0,0,4.6926689,0.0,0.43856892,45.259876,4.7013292,509.12634,-9.2061071
4677,4677,212.4598,5.4972806,5.3477306,0.0,0,4.6699867,0.0,0.44043252,45.060879,4.6787128,509.12634,-9.2061157
4688,4688,212.462,5.5006385,5.3705473,0.0,0,4.647305,0.0,0.44361553,44.912216,4.6545868,509.08688,-9.2061062
4699,4699,212.4642,5.5177479,5.3915515,0.0,0,4.6246228,0.0,0.44498175,45.014137,4.6382995,508.88962,-9.2068729
4710,4710,212.4664,5.5718961,5.4120617,0.0,0,4.6019411,0.0,0.44785467,45.361324,4.6108499,508.69235,-9.2066345
4721,4721,212.4686,5.5733471,5.4377828,0.0,0,4.5792584,0.0,0.44981664,45.223141,4.5876703,508.49506,-9.2060757
4732,4732,212.4708,5.5855742,5.4603362,0.0,0,4.5565767,0.0,0.45299789,45.226536,4.5685878,508.29779,-9.2058249
4743,4743,212.473,5.6145349,5.4881802,0.0,0,4.5340271,0.0,0.4549062,45.341137,4.5449338,507.85614,-9.2065611
4754,4754,212.4752,5.6345463,5.5040836,0.0,0,4.5124488,0.0,0.45761457,45.430557,4.5185823,507.29059,-9.2065134
4765,4765,212.4774,5.6325812,5.5285106,0.0,0,4.4908714,0.0,0.45934215,45.29789,4.4963031,506.72504,-9.2058048
4776,4776,212.4796,5.6230569,5.550693,0.0,0,4.4692936,0.0,0.462556,45.082474,4.4745302,506.15952,-9.2056522
4787,4787,212.4818,5.615593,5.5775323,0.0,0,4.4477158,0.0,0.46435824,45.003345,4.4548368,505.62579,-9.2057934
4798,4798,212.484,5.6325727,5.5931826,0.0,0,4.4261384,0.0,0.46710551,44.947647,4.4292178,505.31015,-9.2050152
4809,4809,212.4862,5.6455283,5.6189647,0.0,0,4.404561,0.0,0.46879372,44.970001,4.4063187,504.99451,-9.2053604
4820,4820,212.4884,5.6480398,5.6365237,0.0,0,4.3829832,0.0,0.47178522,44.909248,4.3873444,504.67889,-9.2053814
4831,4831,212.4906,5.6607661,5.6657386,0.0,0,4.3614058,0.0,0.47369796,44.807285,4.3676891,504.36325,-9.2060699
4842,4842,212.4928,5.6811328,5.6781197,0.0,0,4.339828,0.0,0.47623518,44.831448,4.3438721,502.63187,-9.2051468
4853,4853,212.495,5.7180495,5.7021747,0.0,0,4.3182507,0.0,0.47768503,45.118923,4.324554,499.92038,-9.2059965
4864,4864,212.4972,5.7164669,5.7224965,0.0,0,4.2966728,0.0,0.48097166,45.036297,4.300549,497.20889,-9.2061634
4875,4875,212.4994,5.7262497,5.7506266,0.0,0,4.275095,0.0,0.48272774,45.00349,4.2781749,494.49741,-9.2068195
4886,4886,212.5016,5.7469916,5.7653475,0.0,0,4.2535176,0.0,0.48563305,45.016708,4.2585487,491.76617,-9.2069521
4897,4897,212.5038,5.7628074,5.7915444,0.0,0,4.2319398,0.0,0.48746672,45.099159,4.2377849,488.6926,-9.2063932
4908,4908,212.506,5.7837558,5.8096905,0.0,0,4.2103624,0.0,0.49055478,45.119736,4.2181034,485.61905,-9.2057848
4919,4919,212.5082,5.8052225,5.8403463,0.0,0,4.1887846,0.0,0.4926587,45.16642,4.1918654,482.5455,-9.2045221
4930,4930,212.5104,5.8199663,5.8545866,0.0,0,4.1672072,0.0,0.49532244,45.140079,4.1715107,479.47195,-9.2047968
4941,4941,212.5126,5.8526983,5.8813291,0.0,0,4.1456294,0.0,0.49730009,45.336636,4.1503897,477.53027,-9.2051868
4952,4952,212.5148,5.8343692,5.8995156,0.0,0,4.124052,0.0,0.50029922,45.073792,4.1288762,476.64102,-9.2045431
4963,4963,212.517,5.8453279,5.9288058,0.0,0,4.1024742,0.0,0.50217396,45.05127,4.1055179,475.75177,-9.2053394
4974,4974,212.5192,5.844316,5.9393535,0.0,0,4.0808969,0.0,0.50470167,44.909058,4.0840001,474.86255,-9.2059565
4985,4985,212.5214,5.8401299,5.9659362,0.0,0,4.059319,0.0,0.5066151,44.793343,4.0629301,473.9733,-9.2060146
4996,4996,212.5236,5.8851714,5.9835558,0.0,0,4.0381556,0.0,0.50954288,45.043926,4.0420203,473.80197,-9.2062168
5007,5007,212.5258,5.9120927,6.0135374,0.0,0,4.0176339,0.0,0.51167935,45.095692,4.0181322,473.64392,-9.205617
5018,5018,212.528,5.9113464,6.0274949,0.0,0,3.9971123,0.0,0.5143075,45.040165,3.9996097,473.4859,-9.2053423
5029,5029,212.5302,5.9197178,6.0526452,0.0,0,3.9765906,0.0,0.51623183,45.033653,3.9790509,473.32788,-9.205863
5040,5040,212.5324,5.8987947,6.0657516,0.0,0,3.956069,0.0,0.51866704,44.679607,3.9585924,473.67743,-9.2074966
5051,5051,212.5346,5.9038992,6.0965548,0.0,0,3.9355476,0.0,0.52100122,44.655022,3.9365103,474.65887,-9.2068291
5062,5062,212.5368,5.9138722,6.1099782,0.0,0,3.9150259,0.0,0.52350157,44.605095,3.9186656,475.64029,-9.2060261
5073,5073,212.539,5.9169812,6.1340976,0.0,0,3.8945043,0.0,0.52534819,44.54697,3.8985355,476.62173,-9.2055731
5084,5084,212.5412,5.9804201,6.1472144,0.0,0,3.8739827,0.0,0.52782708,44.861561,3.8762202,477.60318,-9.2051163
5095,5095,212.5434,6.0021405,6.177422,0.0,0,3.853461,0.0,0.53019965,44.978729,3.8535469,477.99167,-9.2046623
5106,5106,212.5456,6.031208,6.1912665,0.0,0,3.8329396,0.0,0.5326221,45.065689,3.8332157,478.32089,-9.2067928
5117,5117,212.5478,6.0292792,6.2180543,0.0,0,3.812418,0.0,0.53492957,44.961586,3.8148503,478.65012,-9.205905
5128,5128,212.55,6.03654,6.2318749,0.0,0,3.7918961,0.0,0.5372346,44.909294,3.7954557,478.97934,-9.2060747
5139,5139,212.5522,6.0420465,6.26124,0.0,0,3.7713747,0.0,0.53984916,44.875355,3.7748594,479.45828,-9.2059774
5150,5150,212.5544,6.0318475,6.2727909,0.0,0,3.7508531,0.0,0.54181021,44.723881,3.7544022,480.18915,-9.2054329
5161,5161,212.5566,6.0673933,6.2992697,0.0,0,3.7303314,0.0,0.54437077,44.844845,3.7330248,480.92004,-9.2052298
5172,5172,212.5588,6.1108351,6.3164606,0.0,0,3.7098098,0.0,0.54681849,45.001419,3.710412,481.65094,-9.2061081
5183,5183,212.561,6.1527367,6.3473697,0.0,0,3.6892881,0.0,0.54968172,45.190609,3.6869769,482.38181,-9.20397
5194,5194,212.5632,6.1712074,6.3606691,0.0,0,3.6687665,0.0,0.55191344,45.310837,3.6673608,483.74582,-9.2046719
5205,5205,212.5654,6.1919813,6.3842573,0.0,0,3.6482451,0.0,0.55420572,45.293308,3.6459861,485.23367,-9.2060556
5216,5216,212.5676,6.1859627,6.399425,0.0,0,3.6277235,0.0,0.55629885,45.095589,3.6265464,486.72156,-9.2065172
5227,5227,212.5698,6.184052,6.4292789,0.0,0,3.6072018,0.0,0.55937451,45.054218,3.6059103,488.20941,-9.2060747
5238,5238,212.572,6.1804533,6.4411187,0.0,0,3.5866802,0.0,0.5611797,44.883629,3.5843904,489.53323,-9.2060747
5249,5249,212.5742,6.1627092,6.4658456,0.0,0,3.5668228,0.0,0.5639168,44.689102,3.5646217,490.47427,-9.2058802
5260,5260,212.5764,6.1680136,6.4829001,0.0,0,3.5472999,0.0,0.56608289,44.572807,3.5450029,491.41531,-9.2060289
5271,5271,212.5786,6.1890764,6.5089178,0.0,0,3.527777,0.0,0.56891751,44.609875,3.5272443,492.35638,-9.2060642
5282,5282,212.5808,6.209507,6.5197167,0.0,0,3.5082545,0.0,0.57034564,44.696136,3.503686,493.29742,-9.2050371
5293,5293,212.583,6.2535896,6.5416899,0.0,0,3.4887314,0.0,0.57285649,44.895149,3.4862175,493.8866,-9.2047901
5304,5304,212.5852,6.243906,6.5586762,0.0,0,3.4692085,0.0,0.57485026,44.727844,3.4678395,494.36685,-9.2045059
5315,5315,212.5874,6.2484179,6.5841079,0.0,0,3.4496861,0.0,0.57784516,44.65226,3.4498684,494.84711,-9.2058945
5326,5326,212.5896,6.2629442,6.5966125,0.0,0,3.4301629,0.0,0.57942045,44.62973,3.4297082,495.32739,-9.2060881
5337,5337,212.5918,6.2819648,6.6169572,0.0,0,3.4106405,0.0,0.58177865,44.698997,3.4127393,495.7254,-9.2062006
5348,5348,212.594,6.3045115,6.6346097,0.0,0,3.3911176,0.0,0.58389223,44.793648,3.3918867,495.84384,-9.2057352
5359,5359,212.5962,6.3583884,6.6636739,0.0,0,3.3715944,0.0,0.58743989,45.043198,3.3713636,495.96225,-9.2060652
5370,5370,212.5984,6.4074097,6.6787534,0.0,0,3.352072,0.0,0.58909881,45.24678,3.3513973,496.08069,-9.2057438
5381,5381,212.6006,6.463028,6.7004285,0.0,0,3.3325491,0.0,0.59202194,45.528431,3.3296597,496.19913,-9.2053385
5392,5392,212.6028,6.4690075,6.7200327,0.0,0,3.313026,0.0,0.59410423,45.49633,3.3096144,496.29025,-9.2054501
5403,5403,212.605,6.4538488,6.7455006,0.0,0,3.2935035,0.0,0.59738272,45.231487,3.288774,496.36923,-9.2056065
5414,5414,212.6072,6.4322329,6.7604241,0.0,0,3.2739804,0.0,0.59879124,45.012383,3.2712855,496.44818,-9.2042961
5425,5425,212.6094,6.4421639,6.779582,0.0,0,3.254458,0.0,0.60159665,44.922348,3.252557,496.52713,-9.2058239
5436,5436,212.6116,6.4367208,6.7970228,0.0,0,3.234935,0.0,0.60332292,44.845543,3.2313399,496.45151,-9.2064104
5447,5447,212.6138,6.4380898,6.8204708,0.0,0,3.2154119,0.0,0.60669565,44.66346,3.213551,495.5303,-9.2061119
5458,5458,212.616,6.4441891,6.83952,0.0,0,3.1958895,0.0,0.60824472,44.687466,3.1927998,494.6091,-9.20609
5469,5469,212.6182,6.5042434,6.8540158,0.0,0,3.1763666,0.0,0.61081028,44.933125,3.1791527,493.68793,-9.2060032
5480,5480,212.6204,6.5603309,6.8729076,0.0,0,3.1568439,0.0,0.61245435,45.269176,3.1564412,492.76672,-9.2053871
5491,5491,212.6226,6.6086383,6.8977165,0.0,0,3.137321,0.0,0.61634195,45.42086,3.1341202,491.72754,-9.2045832
5502,5502,212.6248,6.6337404,6.9185305,0.0,0,3.1186893,0.0,0.61792523,45.540974,3.1174061,490.61545,-9.2044344
5513,5513,212.627,6.6461759,6.9349494,0.0,0,3.1001165,0.0,0.62077749,45.533939,3.100637,489.50336,-9.2046652
5524,5524,212.6292,6.6612911,6.9544249,0.0,0,3.0815444,0.0,0.62243503,45.506668,3.0758376,488.39127,-9.2041636
5535,5535,212.6314,6.6597652,6.9793134,0.0,0,3.0629718,0.0,0.6265583,45.309013,3.0558095,487.39496,-9.2052927
5546,5546,212.6336,6.6502433,7.0024295,0.0,0,3.0443995,0.0,0.62827003,45.169254,3.0379417,487.69772,-9.2057066
5557,5557,212.6358,6.6587358,7.0146093,0.0,0,3.0258269,0.0,0.63093716,45.0769,3.0186136,488.00046,-9.2050571
5568,5568,212.638,6.6686926,7.0316892,0.0,0,3.0072546,0.0,0.63203782,45.077301,3.0008435,488.30322,-9.2046824
5579,5579,212.6402,6.6379032,7.0499601,0.0,0,2.9886825,0.0,0.63545835,44.786774,2.9829056,488.60599,-9.2056704
5590,5590,212.6424,6.6421967,7.0732689,0.0,0,2.9701097,0.0,0.63712162,44.694572,2.9646423,489.11334,-9.2054939
5601,5601,212.6446,6.6441793,7.0838652,0.0,0,2.9515376,0.0,0.63961512,44.64732,2.9469278,489.79123,-9.2054234
5612,5612,212.6468,6.6728654,7.1047969,0.0,0,2.932965,0.0,0.64115542,44.735485,2.9291451,490.46909,-9.2060719
5623,5623,212.649,6.7100754,7.1207995,0.0,0,2.9143927,0.0,0.64442348,44.854996,2.9128013,491.14697,-9.2059736
5634,5634,212.6512,6.7226224,7.1419935,0.0,0,2.8958201,0.0,0.64580321,44.918247,2.8975422,491.82394,-9.2054644
5645,5645,212.6534,6.7571082,7.1528759,0.0,0,2.8772478,0.0,0.64844918,44.977829,2.8783371,492.40289,-9.2055359
5656,5656,212.6556,6.8242412,7.1760383,0.0,0,2.8586755,0.0,0.6501894,45.354351,2.8618484,492.98184,-9.2057152
5667,5667,212.6578,6.8884926,7.1944942,0.0,0,2.8401029,0.0,0.65384531,45.649609,2.8400872,493.56079,-9.2045488
5678,5678,212.66,6.908761,7.2203994,0.0,0,2.8215306,0.0,0.65560192,45.672501,2.8215275,494.13974,-9.204565
5689,5689,212.6622,6.9229417,7.2323174,0.0,0,2.8029583,0.0,0.65873098,45.650116,2.7989569,494.83066,-9.2054167
5700,5700,212.6644,6.9466853,7.2542405,0.0,0,2.7843859,0.0,0.66026556,45.719791,2.7823818,495.64648,-9.2061462
5711,5711,212.6666,6.9303331,7.2692823,0.0,0,2.7658136,0.0,0.66369563,45.450085,2.7602522,496.46228,-9.2062216
5722,5722,212.6688,6.9396338,7.2978282,0.0,0,2.747241,0.0,0.66566145,45.434196,2.7420702,497.27808,-9.2055607
5733,5733,212.671,6.9545636,7.308311,0.0,0,2.7286685,0.0,0.66855878,45.398849,2.7227755,498.09387,-9.2047548
5744,5744,212.6732,6.9934244,7.3306966,0.0,0,2.7102869,0.0,0.67018574,45.496326,2.7064512,498.70023,-9.2058525
5755,5755,212.6754,7.0234833,7.3449149,0.0,0,2.692621,0.0,0.67354441,45.554249,2.6916335,499.29236,-9.2059994
5766,5766,212.6776,7.0389862,7.3726072,0.0,0,2.6749549,0.0,0.67529672,45.663239,2.6676722,499.88446,-9.2048416
5777,5777,212.6798,7.0260634,7.3812556,0.0,0,2.6572888,0.0,0.67811573,45.412525,2.6520572,500.47659,-9.2055359
5788,5788,212.682,7.0453753,7.404871,0.0,0,2.6396229,0.0,0.67985308,45.44508,2.6321242,499.33585,-9.2053766
5799,5799,212.6842,7.0502787,7.4142447,0.0,0,2.6219568,0.0,0.68255627,45.373966,2.6172354,495.59595,-9.2057762
5810,5810,212.6864,7.0713267,7.4418449,0.0,0,2.6042907,0.0,0.68456042,45.421726,2.5982492,491.85605,-9.2055626
5821,5821,212.6886,7.0949674,7.4524422,0.0,0,2.5866249,0.0,0.68742251,45.431026,2.5798981,488.11615,-9.2058964
5832,5832,212.6908,7.1275764,7.476141,0.0,0,2.568959,0.0,0.6893276,45.490448,2.564225,484.37625,-9.2058153
5843,5843,212.693,7.1588192,7.4874125,0.0,0,2.5512927,0.0,0.69218719,45.567665,2.5477269,480.57391,-9.2054682
5854,5854,212.6952,7.2011566,7.5139937,0.0,0,2.5336268,0.0,0.69417238,45.82402,2.527225,476.76169,-9.2055616
5865,5865,212.6974,7.2352648,7.5232849,0.0,0,2.5159609,0.0,0.69688749,45.944344,2.5118966,472.94949,-9.205821
5876,5876,212.6996,7.2313075,7.5478969,0.0,0,2.4982948,0.0,0.69894665,45.774773,2.4968278,469.1373,-9.2061005
5887,5887,212.7018,7.2305307,7.560462,0.0,0,2.480629,0.0,0.70205557,45.650539,2.4745319,466.91571,-9.2067966
5898,5898,212.704,7.2675672,7.5887036,0.0,0,2.4629629,0.0,0.70415515,45.802216,2.4559371,467.96353,-9.2053385
5909,5909,212.7062,7.2908945,7.594975,0.0,0,2.4452968,0.0,0.70649141,45.777008,2.4381437,469.01138,-9.2057037
5920,5920,212.7084,7.2973313,7.6186676,0.0,0,2.4276309,0.0,0.70866942,45.748119,2.4208961,470.05923,-9.205492
5931,5931,212.7106,7.3114457,7.631938,0.0,0,2.4099648,0.0,0.71153247,45.664379,2.4010427,471.10709,-9.2061024
5942,5942,212.7128,7.3414974,7.6592298,0.0,0,2.3922987,0.0,0.71383369,45.707958,2.3859897,472.6236,-9.2060461
5953,5953,212.715,7.3359337,7.6678405,0.0,0,2.3746328,0.0,0.716236,45.622223,2.3680904,474.26404,-9.2052116
5964,5964,212.7172,7.3481851,7.6871781,0.0,0,2.3569667,0.0,0.71787572,45.682907,2.3505232,475.90445,-9.2051125
5975,5975,212.7194,7.3586283,7.6955209,0.0,0,2.3393009,0.0,0.72019577,45.641079,2.3338294,477.54486,-9.2047987
5986,5986,212.7216,7.408257,7.7242813,0.0,0,2.3216348,0.0,0.7228694,45.787254,2.3183031,479.10794,-9.2056026
5997,5997,212.7238,7.4435472,7.7352619,0.0,0,2.3043852,0.0,0.72539657,45.891006,2.301132,480.44461,-9.205987
6008,6008,212.726,7.4828343,7.7584109,0.0,0,2.2875817,0.0,0.72771817,46.014172,2.2817054,481.78125,-9.2053785
6019,6019,212.7282,7.499846,7.7680759,0.0,0,2.2707779,0.0,0.7299155,46.007515,2.2678382,483.11792,-9.2059288
6030,6030,212.7304,7.5128827,7.7953863,0.0,0,2.2539747,0.0,0.73287678,45.994671,2.2487342,484.45456,-9.207077
6041,6041,212.7326,7.5525417,7.8048449,0.0,0,2.2371707,0.0,0.73501313,46.111515,2.2311773,485.5405,-9.2071943
6052,6052,212.7348,7.5897307,7.8260846,0.0,0,2.2203674,0.0,0.73726934,46.200039,2.2145669,486.52805,-9.2072792
6063,6063,212.737,7.6026235,7.8379831,0.0,0,2.2035637,0.0,0.7393989,46.204166,2.2000482,487.51559,-9.2062197
6074,6074,212.7392,7.6032004,7.8618679,0.0,0,2.1867602,0.0,0.7421279,46.112709,2.1819649,488.50317,-9.2069273
6085,6085,212.7414,7.6097646,7.8714514,0.0,0,2.1699564,0.0,0.74419749,46.045776,2.1638513,489.25894,-9.2063904
6096,6096,212.7436,7.6550484,7.8943591,0.0,0,2.1531529,0.0,0.74693412,46.169407,2.1461213,488.97186,-9.2068014
6107,6107,212.7458,7.697762,7.9072328,0.0,0,2.1363492,0.0,0.7490688,46.320934,2.1292768,488.68478,-9.205164
6118,6118,212.748,7.7390008,7.9325552,0.0,0,2.1195457,0.0,0.75217068,46.410473,2.1110754,488.39767,-9.2066631
6129,6129,212.7502,7.7601466,7.9432459,0.0,0,2.102742,0.0,0.75422627,46.447964,2.0926907,488.1106,-9.2064409
6140,6140,212.7524,7.7782502,7.9636216,0.0,0,2.0859385,0.0,0.75692111,46.436668,2.077651,486.60693,-9.2052689
6151,6151,212.7546,7.7713485,7.974968,0.0,0,2.069135,0.0,0.75854653,46.330864,2.0632832,483.88666,-9.2056332
6162,6162,212.7568,7.8061051,7.9968371,0.0,0,2.0523314,0.0,0.76164961,46.392521,2.0454347,481.16641,-9.2045641
6173,6173,212.759,7.8259292,8.0097637,0.0,0,2.0355277,0.0,0.76359683,46.403706,2.0291309,478.44614,-9.2051716
6184,6184,212.7612,7.8414431,8.0308619,0.0,0,2.0187242,0.0,0.76663804,46.391479,2.0103073,475.72589,-9.2063179
6195,6195,212.7634,7.8715806,8.0444431,0.0,0,2.0019205,0.0,0.7684297,46.465569,1.9978943,473.78619,-9.2067928
6206,6206,212.7656,7.8977132,8.0673151,0.0,0,1.985117,0.0,0.7718516,46.433769,1.978526,471.87598,-9.2061062
6217,6217,212.7678,7.9166875,8.0798731,0.0,0,1.9683133,0.0,0.77340776,46.545132,1.9649886,469.96576,-9.2060194
6228,6228,212.77,7.9547863,8.0952406,0.0,0,1.9515098,0.0,0.77583081,46.633083,1.9495634,468.05554,-9.2053308
6239,6239,212.7722,8.0204725,8.1081047,0.0,0,1.9347062,0.0,0.77734751,46.922565,1.9313836,467.38672,-9.2059441
6250,6250,212.7744,8.0469217,8.1331158,0.0,0,1.918521,0.0,0.7815128,46.899963,1.9170241,468.38196,-9.2054949
6261,6261,212.7766,8.0734482,8.1475563,0.0,0,1.9025358,0.0,0.78313118,47.019707,1.8976108,469.3772,-9.2052116
6272,6272,212.7788,8.10777,8.1644297,0.0,0,1.8865505,0.0,0.78615987,47.008102,1.8802717,470.37241,-9.2058716
6283,6283,212.781,8.1494398,8.1803532,0.0,0,1.8705654,0.0,0.78782564,47.188759,1.8628438,471.36765,-9.2054081
6294,6294,212.7832,8.1530256,8.2015343,0.0,0,1.8545802,0.0,0.7917046,47.015591,1.8451563,472.6149,-9.2050591
6305,6305,212.7854,8.1529942,8.2195463,0.0,0,1.838595,0.0,0.79337025,46.986607,1.8320994,473.89301,-9.2055006
6316,6316,212.7876,8.1353331,8.2311764,0.0,0,1.8226099,0.0,0.79606116,46.743118,1.8145713,475.17111,-9.2063198
6327,6327,212.7898,8.1215792,8.2443466,0.0,0,1.8066247,0.0,0.79737628,46.561806,1.7968823,476.44922,-9.2066698
6338,6338,212.792,8.1242714,8.2642241,0.0,0,1.7906394,0.0,0.8011272,46.433857,1.7803253,477.58936,-9.2064972
6349,6349,212.7942,8.1534548,8.2805405,0.0,0,1.7746543,0.0,0.80241525,46.565239,1.7703723,478.47827,-9.2056246
6360,6360,212.7964,8.1862507,8.2915287,0.0,0,1.758669,0.0,0.80494457,46.619202,1.7520361,479.36719,-9.2047091
6371,6371,212.7986,8.2067671,8.3052692,0.0,0,1.7426839,0.0,0.80624473,46.656654,1.735078,480.2561,-9.2047968
6382,6382,212.8008,8.2696419,8.322958,0.0,0,1.7266986,0.0,0.81001687,46.858231,1.721599,481.14502,-9.2055521
6393,6393,212.803,8.3178768,8.3404589,0.0,0,1.7107134,0.0,0.81129843,47.053726,1.7059882,481.86154,-9.2055216
6404,6404,212.8052,8.3563509,8.3512669,0.0,0,1.6947283,0.0,0.81415939,47.119804,1.6930923,482.53973,-9.2062244
6415,6415,212.8074,8.4078245,8.3687105,0.0,0,1.678743,0.0,0.81557608,47.356335,1.6740904,483.21793,-9.2064381
6426,6426,212.8096,8.4415169,8.3852501,0.0,0,1.6627578,0.0,0.81950021,47.384541,1.661303,483.89612,-9.2065611
6437,6437,212.8118,8.4707823,8.4035349,0.0,0,1.6467726,0.0,0.82068801,47.473366,1.6454884,484.45743,-9.2053823
6448,6448,212.814,8.5059948,8.4150906,0.0,0,1.6307874,0.0,0.82404757,47.521248,1.6245321,484.72083,-9.2047091
6459,6459,212.8162,8.5463524,8.4355354,0.0,0,1.6148022,0.0,0.82571554,47.642857,1.6067548,484.98419,-9.2057934
6470,6470,212.8184,8.5667229,8.4503088,0.0,0,1.5988171,0.0,0.8294329,47.573822,1.5924715,485.24759,-9.207593
6481,6481,212.8206,8.5899239,8.4714231,0.0,0,1.5828317,0.0,0.83098233,47.620117,1.5779335,485.51096,-9.2061787
6492,6492,212.8228,8.6182442,8.4799204,0.0,0,1.5668756,0.0,0.83398521,47.638252,1.5607182,485.60745,-9.2047672
6503,6503,212.825,8.6424828,8.5001526,0.0,0,1.5516622,0.0,0.83553994,47.705257,1.5463268,485.64694,-9.205349
6514,6514,212.8272,8.6562672,8.5142021,0.0,0,1.5364559,0.0,0.83930594,47.640778,1.5293024,485.68646,-9.204545
6525,6525,212.8294,8.6873121,8.5347071,0.0,0,1.5212495,0.0,0.84061271,47.700562,1.5137676,485.72595,-9.2046633
6536,6536,212.8316,8.6725349,8.5414362,0.0,0,1.506043,0.0,0.84352791,47.525909,1.5009724,485.80127,-9.2050705
6547,6547,212.8338,8.6663752,8.5602684,0.0,0,1.4908366,0.0,0.8446703,47.412159,1.4842924,486.01196,-9.2051325
6558,6558,212.836,8.711134,8.5708199,0.0,0,1.4756303,0.0,0.84826934,47.463024,1.4731804,486.22269,-9.2051592
6569,6569,212.8382,8.7822161,8.5954123,0.0,0,1.4604239,0.0,0.84979761,47.795399,1.4553614,486.43341,-9.2060328
6580,6580,212.8404,8.8543959,8.6008863,0.0,0,1.4452175,0.0,0.85280269,48.04826,1.4405432,486.6441,-9.2057819
6591,6591,212.8426,8.9195242,8.6231108,0.0,0,1.430011,0.0,0.85457069,48.336636,1.4245385,486.9567,-9.2058926
6602,6602,212.8448,8.9747219,8.6376247,0.0,0,1.4148048,0.0,0.85861331,48.373749,1.4062485,487.31882,-9.206027
6613,6613,212.847,8.9916506,8.6610718,0.0,0,1.3995984,0.0,0.86019552,48.428623,1.3895382,487.68094,-9.2047014
6624,6624,212.8492,9.0390129,8.666338,0.0,0,1.3843919,0.0,0.86299652,48.548496,1.3760407,488.04309,-9.2051392
6635,6635,212.8514,9.0290279,8.6866913,0.0,0,1.3691854,0.0,0.86469585,48.468891,1.3606596,488.46622,-9.2052069
6646,6646,212.8536,9.016943,8.6971455,0.0,0,1.3539791,0.0,0.86799318,48.212093,1.3427289,489.2756,-9.2060347
6657,6657,212.8558,9.0429344,8.7223549,0.0,0,1.3387728,0.0,0.86985976,48.271732,1.3289304,490.08502,-9.2060528
6668,6668,212.858,9.0686626,8.7272272,0.0,0,1.3235664,0.0,0.87275952,48.24493,1.3131069,490.89441,-9.2061081
6679,6679,212.8602,9.0904446,8.7478647,0.0,0,1.30836,0.0,0.87444782,48.285851,1.3012483,491.70383,-9.2049589
6690,6690,212.8624,9.1118145,8.7575617,0.0,0,1.2931535,0.0,0.87786865,48.214985,1.2837034,492.57233,-9.2072382
6701,6701,212.8646,9.1260824,8.7819424,0.0,0,1.2779471,0.0,0.87941092,48.220654,1.2709656,493.48022,-9.2059813
6712,6712,212.8668,9.1441698,8.7863674,0.0,0,1.2627407,0.0,0.88206518,48.230797,1.2566791,494.38812,-9.2058868
6723,6723,212.869,9.1797867,8.8053617,0.0,0,1.2475343,0.0,0.88353699,48.283428,1.2394464,495.29605,-9.2045155
6734,6734,212.8712,9.2509136,8.8134155,0.0,0,1.2323278,0.0,0.88668221,48.517109,1.22701,496.18051,-9.2052536
6745,6745,212.8734,9.3190556,8.8401384,0.0,0,1.2173454,0.0,0.88888294,48.763165,1.2107539,496.72,-9.2067928
6756,6756,212.8756,9.3943319,8.8460016,0.0,0,1.2028826,0.0,0.89164352,49.091206,1.1964918,497.25946,-9.2054186
6767,6767,212.8778,9.4523916,8.867075,0.0,0,1.1884197,0.0,0.89359242,49.186085,1.1802217,497.79895,-9.2046099
6778,6778,212.88,9.4701109,8.8764038,0.0,0,1.173957,0.0,0.89679039,49.175636,1.1618471,498.33844,-9.203886
6789,6789,212.8822,9.4878044,8.9014063,0.0,0,1.1594943,0.0,0.89885783,49.165596,1.1476339,498.77039,-9.2054787
6800,6800,212.8844,9.4681969,8.9067888,0.0,0,1.1450313,0.0,0.90154761,48.950108,1.1340735,499.10593,-9.2062283
6811,6811,212.8866,9.4586887,8.9271231,0.0,0,1.1305685,0.0,0.9035666,48.763416,1.1195163,499.44147,-9.2064295
6822,6822,212.8888,9.4625378,8.9339514,0.0,0,1.1161058,0.0,0.90613163,48.704529,1.1063623,499.77698,-9.2060537
6833,6833,212.891,9.4810801,8.9571886,0.0,0,1.101643,0.0,0.90832162,48.684845,1.0916616,500.11252,-9.2060757
6844,6844,212.8932,9.547471,8.9629002,0.0,0,1.0871801,0.0,0.91068739,48.864525,1.07978,500.435,-9.2050848
6855,6855,212.8954,9.6135302,8.9830761,0.0,0,1.0727174,0.0,0.91293645,49.11338,1.0630387,500.75739,-9.2060146
6866,6866,212.8976,9.6627159,8.9902611,0.0,0,1.0582546,0.0,0.91512084,49.288914,1.0498424,501.07974,-9.2052345
6877,6877,212.8998,9.6907749,9.0128307,0.0,0,1.0437918,0.0,0.91759413,49.317013,1.03417,501.40213,-9.2060499
6888,6888,212.902,9.7204885,9.0172863,0.0,0,1.0293289,0.0,0.91963339,49.341259,1.0218363,501.60489,-9.2052975
6899,6899,212.9042,9.7574167,9.0375729,0.0,0,1.0148661,0.0,0.92215258,49.382576,1.0074289,501.66409,-9.2060394
6910,6910,212.9064,9.7677526,9.0464058,0.0,0,1.0004034,0.0,0.92442334,49.317703,0.99361056,501.7233,-9.2049894
6921,6921,212.9086,9.7945223,9.0702591,0.0,0,0.98594052,0.0,0.92751634,49.33326,0.98098052,501.7825,-9.2060137
6932,6932,212.9108,9.8203907,9.0767059,0.0,0,0.97147775,0.0,0.92946583,49.343002,0.96462375,501.84171,-9.206068
6943,6943,212.913,9.8773756,9.0926905,0.0,0,0.95701498,0.0,0.93155015,49.506187,0.95147759,501.68347,-9.2053413
6954,6954,212.9152,9.9393196,9.1015368,0.0,0,0.94255215,0.0,0.93362045,49.760754,0.93601906,501.50583,-9.2064781
6965,6965,212.9174,10.009271,9.124404,0.0,0,0.92808938,0.0,0.93693143,49.984402,0.92305881,501.32822,-9.2058573
6976,6976,212.9196,10.059694,9.13276,0.0,0,0.91362649,0.0,0.93886578,50.113991,0.90389007,501.15057,-9.2056141
6987,6987,212.9218,10.102166,9.1488724,0.0,0,0.89916372,0.0,0.94125682,50.176792,0.89199203,501.14124,-9.2057161
6998,6998,212.924,10.120982,9.159399,0.0,0,0.88510746,0.0,0.9432056,50.204922,0.88320065,501.40442,-9.2060337
7009,7009,212.9262,10.158744,9.1803865,0.0,0,0.87135303,0.0,0.94654405,50.173878,0.86621588,501.66757,-9.2060699
7020,7020,212.9284,10.217156,9.1891098,0.0,0,0.8575986,0.0,0.94843495,50.389275,0.85172188,501.93073,-9.2060242
7031,7031,212.9306,10.268561,9.2044544,0.0,0,0.84384423,0.0,0.95099163,50.538773,0.83590579,502.19388,-9.2042913
7042,7042,212.9328,10.319426,9.2160664,0.0,0,0.83008987,0.0,0.9527992,50.6604,0.82449621,499.435,-9.2046175
7053,7053,212.935,10.384231,9.2379293,0.0,0,0.81633544,0.0,0.95678747,50.750336,0.80817151,496.12366,-9.2060795
7064,7064,212.9372,10.418436,9.2502756,0.0,0,0.80258107,0.0,0.95890087,50.843266,0.79572684,492.81232,-9.2060766
7075,7075,212.9394,10.425081,9.2648993,0.0,0,0.78882664,0.0,0.96153408,50.75705,0.78162777,489.50098,-9.2060995
7086,7086,212.9416,10.452003,9.2739534,0.0,0,0.77507222,0.0,0.96286196,50.790367,0.76523423,486.37506,-9.2059269
7097,7097,212.9438,10.464725,9.2956038,0.0,0,0.76131785,0.0,0.96699667,50.655365,0.75077713,483.66354,-9.2058916
7108,7108,212.946,10.460067,9.3039217,0.0,0,0.74756342,0.0,0.96797514,50.588383,0.74002159,480.95203,-9.2057066
7119,7119,212.9482,10.50075,9.3169394,0.0,0,0.73380905,0.0,0.97089612,50.628124,0.72579277,478.24054,-9.2051458
7130,7130,212.9504,10.550247,9.3291149,0.0,0,0.72005463,0.0,0.97226143,50.767551,0.71059054,475.52902,-9.2050314
7141,7141,212.9526,10.617768,9.34904,0.0,0,0.70630026,0.0,0.97647846,50.892334,0.69781774,475.97134,-9.2045097
7152,7152,212.9548,10.690701,9.3577242,0.0,0,0.69254583,0.0,0.97730333,51.194481,0.68512392,477.34131,-9.2043161
7163,7163,212.957,10.722166,9.3695765,0.0,0,0.67879146,0.0,0.98027027,51.234745,0.67225617,478.71127,-9.2053452
7174,7174,212.9592,10.748096,9.3857403,0.0,0,0.66503704,0.0,0.98219091,51.239929,0.65492642,480.08121,-9.2057533
7185,7185,212.9614,10.763445,9.4006863,0.0,0,0.65128267,0.0,0.98609483,51.115936,0.64066523,481.30325,-9.2063761
7196,7196,212.9636,10.789247,9.4129181,0.0,0,0.63752824,0.0,0.98676986,51.200905,0.63038665,482.0473,-9.2067785
7207,7207,212.9658,10.838562,9.424427,0.0,0,0.62377387,0.0,0.99013311,51.232582,0.61500025,482.79135,-9.2054892
7218,7218,212.968,10.913395,9.4381704,0.0,0,0.61001945,0.0,0.99145818,51.541435,0.60054618,483.5354,-9.2054768
7229,7229,212.9702,10.976205,9.4541311,0.0,0,0.59626502,0.0,0.99573267,51.616367,0.59028244,484.27945,-9.205966
7240,7240,212.9724,11.032231,9.4683123,0.0,0,0.58251065,0.0,0.99656302,51.844238,0.57319701,484.42896,-9.2053471
7251,7251,212.9746,11.058698,9.4778414,0.0,0,0.56931865,0.0,0.99993008,51.803272,0.56151491,484.32358,-9.204566
7258,7258,212.976,11.068287,9.4935989,0.0,0,0.56098866,0.0,1.0012065,51.774067,0.55214804,484.25656,-9.2057304