File: clean data/testID_0109.csv
level_0,index,Time(sec),Force(kN),Jaw(mm),PowAngle(deg),Power(W),Pram,PTemp,Strain,Stress(MPa),Stroke(mm),TC1(C),wedge(mm)
2594,2594,212.0416,0.92335021,0.0062282006,0.0,0,9.9248629,0.0,0.00052954041,11.521043,10.021506,498.79282,-9.205267
2605,2605,212.0438,2.2917936,0.016016832,0.0,0,9.8918629,0.0,0.00094148528,28.852787,9.9918919,498.80237,-9.2049255
2616,2616,212.046,3.5753326,0.029477824,0.0,0,9.8588629,0.0,0.0021707781,45.156197,9.9593773,498.80237,-9.2048922
2627,2627,212.0482,3.924989,0.065704875,0.0,0,9.8258629,0.0,0.0041704378,49.787918,9.9268866,498.80237,-9.2030191
2638,2638,212.0504,4.0799637,0.097033791,0.0,0,9.7928629,0.0,0.0066733146,51.582359,9.8898077,498.80237,-9.2037621
2649,2649,212.0526,4.1698618,0.13584024,0.0,0,9.7598629,0.0,0.0088037178,52.578941,9.8461456,498.80237,-9.2034044
2660,2660,212.0548,4.2271328,0.16877078,0.0,0,9.7268629,0.0,0.01154595,53.286316,9.8106518,498.76361,-9.2044563
2671,2671,212.057,4.2808714,0.20677376,0.0,0,9.6938629,0.0,0.013589152,53.837788,9.7781534,498.711,-9.2036161
2682,2682,212.0592,4.3264556,0.23615122,0.0,0,9.6608629,0.0,0.015965305,54.181442,9.7423439,498.65836,-9.2015696
2693,2693,212.0614,4.3395448,0.27048784,0.0,0,9.6278629,0.0,0.01805016,54.243668,9.7058105,498.60574,-9.2020025
2704,2704,212.0636,4.3784256,0.29933906,0.0,0,9.5948629,0.0,0.020365508,54.589096,9.6725912,498.54257,-9.2040157
2715,2715,212.0658,4.4041305,0.33911651,0.0,0,9.5618629,0.0,0.022562837,54.819065,9.6449537,498.43732,-9.2058239
2726,2726,212.068,4.4204583,0.36492825,0.0,0,9.528863,0.0,0.024698058,54.907646,9.6134043,498.33206,-9.205493
2737,2737,212.0702,4.4285574,0.3979606,0.0,0,9.495863,0.0,0.026824046,54.917137,9.5740957,498.22678,-9.2045736
2748,2748,212.0724,4.4369349,0.42759785,0.0,0,9.4633284,0.0,0.028969465,54.912704,9.5456152,498.12152,-9.2044315
2759,2759,212.0746,4.4381571,0.46672606,0.0,0,9.4311371,0.0,0.031352453,54.756126,9.5096512,497.99005,-9.2046061
2770,2770,212.0768,4.4427238,0.49320918,0.0,0,9.3989468,0.0,0.033448633,54.735271,9.4792929,497.84531,-9.2048645
2781,2781,212.079,4.4431581,0.52362776,0.0,0,9.3667564,0.0,0.035369236,54.529583,9.4476709,497.70056,-9.20432
2792,2792,212.0812,4.5049543,0.55249763,0.0,0,9.3345661,0.0,0.037581082,55.298534,9.4158144,497.55582,-9.2043915
2803,2803,212.0834,4.5578508,0.59351349,0.0,0,9.3023758,0.0,0.040310383,55.702827,9.3849888,497.42868,-9.2031746
2814,2814,212.0856,4.6014962,0.62331271,0.0,0,9.2701855,0.0,0.042409554,56.024265,9.3492212,497.42209,-9.2035103
2825,2825,212.0878,4.5737672,0.65759403,0.0,0,9.2379951,0.0,0.044799153,55.771122,9.312171,497.4155,-9.2032003
2836,2836,212.09,4.5379276,0.68889797,0.0,0,9.2058048,0.0,0.046938796,55.189903,9.2775097,497.40894,-9.2043133
2847,2847,212.0922,4.5361128,0.72471982,0.0,0,9.1736135,0.0,0.049613189,55.104389,9.2465944,497.40234,-9.2042847
2858,2858,212.0944,4.5464001,0.75565881,0.0,0,9.1414242,0.0,0.051497102,54.995865,9.2121582,497.42297,-9.2045574
2869,2869,212.0966,4.5652008,0.7832613,0.0,0,9.1092339,0.0,0.053714424,55.029499,9.1802998,497.46246,-9.2046242
2880,2880,212.0988,4.6024041,0.8152867,0.0,0,9.0770426,0.0,0.05569521,55.355587,9.1485491,497.50195,-9.2058172
2891,2891,212.101,4.6285419,0.8492462,0.0,0,9.0448523,0.0,0.058447968,55.465679,9.1177406,497.54141,-9.2045469
2902,2902,212.1032,4.6640468,0.88441992,0.0,0,9.0126619,0.0,0.06050333,55.869881,9.0824623,497.57513,-9.2036695
2913,2913,212.1054,4.6765585,0.91486204,0.0,0,8.9804716,0.0,0.06308265,55.963428,9.0484896,497.50934,-9.2035637
2924,2924,212.1076,4.6625938,0.94960052,0.0,0,8.9482813,0.0,0.065145209,55.654942,9.0156164,497.44354,-9.2036724
2935,2935,212.1098,4.649394,0.98043919,0.0,0,8.916091,0.0,0.067821451,55.408897,8.9805479,497.37778,-9.2031984
2946,2946,212.112,4.6427336,1.0174782,0.0,0,8.8839006,0.0,0.069893584,55.080345,8.9471779,497.31198,-9.2050571
2957,2957,212.1142,4.6684079,1.0434548,0.0,0,8.8517094,0.0,0.072310895,55.204468,8.9166241,497.19162,-9.2045717
2968,2968,212.1164,4.6693444,1.0747737,0.0,0,8.81952,0.0,0.074183449,55.135563,8.8832264,497.02057,-9.2045593
2979,2979,212.1186,4.6899652,1.1042756,0.0,0,8.7873297,0.0,0.076677725,55.254463,8.8502941,496.84955,-9.2035322
2990,2990,212.1208,4.7070928,1.1426102,0.0,0,8.7551384,0.0,0.078868285,55.321339,8.8182335,496.6785,-9.2052822
3001,3001,212.123,4.7239385,1.1670635,0.0,0,8.7242813,0.0,0.081111103,55.451782,8.7905111,496.50745,-9.2045898
3012,3012,212.1252,4.7255683,1.1998497,0.0,0,8.6936665,0.0,0.083214082,55.475578,8.7570763,496.49786,-9.2037468
3023,3023,212.1274,4.7557888,1.2278507,0.0,0,8.6630516,0.0,0.085514493,55.65501,8.7275352,496.4913,-9.2046738
3034,3034,212.1296,4.7428236,1.2650288,0.0,0,8.6324358,0.0,0.087908208,55.376217,8.6927252,496.48471,-9.2043123
3045,3045,212.1318,4.7424059,1.292869,0.0,0,8.6018209,0.0,0.090235204,55.05051,8.6623592,496.47815,-9.2038889
3056,3056,212.134,4.7370076,1.324838,0.0,0,8.5712051,0.0,0.092387944,55.002773,8.6279154,496.59174,-9.2045593
3067,3067,212.1362,4.7887135,1.3534622,0.0,0,8.5405903,0.0,0.094571896,55.432537,8.5997305,496.85489,-9.2040262
3078,3078,212.1384,4.8144188,1.3890877,0.0,0,8.5099754,0.0,0.097040154,55.551201,8.5651388,497.11804,-9.2034521
3089,3089,212.1406,4.8247223,1.416063,0.0,0,8.4793596,0.0,0.099178024,55.633942,8.5343056,497.3812,-9.2033567
3100,3100,212.1428,4.8270102,1.4477518,0.0,0,8.4487448,0.0,0.10146119,55.531528,8.5023785,497.64435,-9.2037058
3111,3111,212.145,4.83603,1.4761816,0.0,0,8.418129,0.0,0.10349183,55.470657,8.4739141,497.77594,-9.20397
3122,3122,212.1472,4.8074121,1.5096012,0.0,0,8.3875151,0.0,0.10617135,55.061169,8.4421072,497.89435,-9.2045813
3133,3133,212.1494,4.8114314,1.5392584,0.0,0,8.3568993,0.0,0.10809445,55.144165,8.4139795,498.01279,-9.2050896
3144,3144,212.1516,4.8302474,1.566808,0.0,0,8.3262844,0.0,0.11043794,54.978279,8.3794975,498.1312,-9.2055073
3155,3155,212.1538,4.8408875,1.5968205,0.0,0,8.2956686,0.0,0.11236732,54.978565,8.3516445,498.18094,-9.2045097
3166,3166,212.156,4.8699489,1.6266619,0.0,0,8.2650537,0.0,0.1149591,55.170601,8.3265829,498.11517,-9.2048988
3177,3177,212.1582,4.8930516,1.6587924,0.0,0,8.2344389,0.0,0.11691658,55.452442,8.2933445,498.04938,-9.2046623
3188,3188,212.1604,4.9206133,1.6855307,0.0,0,8.203824,0.0,0.11940487,55.7155,8.2643919,497.98358,-9.2037687
3199,3199,212.1626,4.9565659,1.7192745,0.0,0,8.1732082,0.0,0.12147559,55.789055,8.2275028,497.91782,-9.2033768
3210,3210,212.1648,4.9481158,1.7493639,0.0,0,8.1425934,0.0,0.12425021,55.747803,8.199399,497.87402,-9.2031059
3221,3221,212.167,4.959578,1.7866013,0.0,0,8.1119785,0.0,0.12642607,55.662075,8.1690893,497.83456,-9.2036228
3232,3232,212.1692,4.9522858,1.8126212,0.0,0,8.0813618,0.0,0.12900101,55.422478,8.133626,497.79507,-9.2039165
3243,3243,212.1714,4.9765959,1.8457789,0.0,0,8.0509262,0.0,0.13105384,55.582481,8.1002703,497.75558,-9.2045937
3254,3254,212.1736,5.0020828,1.8749666,0.0,0,8.0217972,0.0,0.13380395,55.637451,8.0699425,497.74771,-9.2044611
3265,3265,212.1758,4.996449,1.9122056,0.0,0,7.9926682,0.0,0.13595743,55.555653,8.0358715,497.81351,-9.2050056
3276,3276,212.178,4.9774418,1.9349704,0.0,0,7.963541,0.0,0.13824898,55.199375,8.0082884,497.8793,-9.2049704
3287,3287,212.1802,4.9933524,1.9662391,0.0,0,7.9344134,0.0,0.14030167,55.24057,7.9788942,497.9451,-9.2052269
3298,3298,212.1824,5.0116611,1.9913617,0.0,0,7.9052849,0.0,0.14267264,55.345531,7.9513988,498.01089,-9.2049656
3309,3309,212.1846,5.0142941,2.0278821,0.0,0,7.8761568,0.0,0.14494778,55.410789,7.9209485,498.12692,-9.2037077
3320,3320,212.1868,4.9958067,2.0500321,0.0,0,7.8470292,0.0,0.1470775,54.952583,7.8915687,498.25848,-9.2046509
3331,3331,212.189,5.00737,2.081212,0.0,0,7.8179011,0.0,0.14921357,54.897324,7.8599339,498.39005,-9.2014551
3342,3342,212.1912,5.0205951,2.105557,0.0,0,7.7887726,0.0,0.15128055,54.897934,7.8321605,498.52164,-9.2031708
3353,3353,212.1934,5.0649242,2.1403725,0.0,0,7.7596445,0.0,0.15383731,55.264477,7.806251,498.6586,-9.2032309
3364,3364,212.1956,5.0749464,2.1666784,0.0,0,7.7305169,0.0,0.15598564,55.295502,7.7729306,498.81393,-9.2044611
3375,3375,212.1978,5.1049705,2.1953278,0.0,0,7.7013888,0.0,0.15826854,55.474174,7.7411823,498.96927,-9.2034903
3386,3386,212.2,5.0789862,2.2219102,0.0,0,7.6722608,0.0,0.16025968,55.150368,7.7160978,499.12457,-9.2039537
3397,3397,212.2022,5.094924,2.2530613,0.0,0,7.6431322,0.0,0.16283438,55.232342,7.6873007,499.27991,-9.2035656
3408,3408,212.2044,5.1076479,2.2815418,0.0,0,7.6140046,0.0,0.16486058,55.190495,7.6557989,499.26675,-9.2046394
3419,3419,212.2066,5.1126623,2.3084221,0.0,0,7.5848765,0.0,0.16720179,55.086098,7.6280837,499.2536,-9.2047729
3430,3430,212.2088,5.1351004,2.3376291,0.0,0,7.5557485,0.0,0.16925272,55.174763,7.5989218,499.24042,-9.2030678
3441,3441,212.211,5.1635032,2.3688095,0.0,0,7.5266209,0.0,0.1721438,55.349007,7.5696135,499.22726,-9.2039795
3452,3452,212.2132,5.1659656,2.3981783,0.0,0,7.4974923,0.0,0.17393401,55.222431,7.537137,499.23242,-9.2026186
3463,3463,212.2154,5.1834698,2.4213636,0.0,0,7.4683647,0.0,0.17624785,55.298038,7.5117478,499.25873,-9.2030582
3474,3474,212.2176,5.1982188,2.4520214,0.0,0,7.4392366,0.0,0.17827559,55.373249,7.4843969,499.28506,-9.2028236
3485,3485,212.2198,5.2266021,2.4825101,0.0,0,7.4101086,0.0,0.18115319,55.522491,7.4541278,499.31137,-9.2043695
3496,3496,212.222,5.2191372,2.51526,0.0,0,7.3815393,0.0,0.18312591,55.356144,7.4213028,499.33768,-9.2039499
3507,3507,212.2242,5.2148404,2.5381773,0.0,0,7.3538375,0.0,0.18566173,55.12344,7.3950548,499.4494,-9.2043619
3518,3518,212.2264,5.1988974,2.5696266,0.0,0,7.3261347,0.0,0.18758516,54.926132,7.3645387,499.56784,-9.2037201
3529,3529,212.2286,5.2148542,2.5954437,0.0,0,7.2984324,0.0,0.1902874,54.869759,7.3347626,499.68625,-9.2031384
3540,3540,212.2308,5.2519579,2.628402,0.0,0,7.27073,0.0,0.19223681,55.116272,7.310143,499.80469,-9.2030725
3551,3551,212.233,5.2561059,2.6481907,0.0,0,7.2430277,0.0,0.19450298,55.122314,7.2757611,499.9231,-9.2041216
3562,3562,212.2352,5.2672219,2.6793201,0.0,0,7.2153249,0.0,0.19650358,55.065018,7.2513843,500.0415,-9.2046041
3573,3573,212.2374,5.2584844,2.7022955,0.0,0,7.1876225,0.0,0.19892481,54.912556,7.2267437,500.15994,-9.2043238
3584,3584,212.2396,5.2754741,2.7393258,0.0,0,7.1599207,0.0,0.20129262,54.93858,7.1988153,500.27835,-9.2034645
3595,3595,212.2418,5.2847157,2.7606685,0.0,0,7.1322184,0.0,0.20350146,54.88245,7.1667795,500.39679,-9.2038193
3606,3606,212.244,5.2973361,2.7915673,0.0,0,7.1045151,0.0,0.20569152,54.947811,7.1451735,500.52646,-9.2033043
3617,3617,212.2462,5.3051572,2.8149247,0.0,0,7.0768127,0.0,0.20790446,54.835964,7.1140633,500.65805,-9.2042723
3628,3628,212.2484,5.3305387,2.8490033,0.0,0,7.0491109,0.0,0.21042199,54.988823,7.08671,500.78961,-9.2046146
3639,3639,212.2506,5.373662,2.8712873,0.0,0,7.0214081,0.0,0.2125068,55.288708,7.0549202,500.9212,-9.2043066
3650,3650,212.2528,5.3819728,2.9019434,0.0,0,6.9937057,0.0,0.21498521,55.272438,7.0291076,501.02768,-9.2035208
3661,3661,212.255,5.3758016,2.9278934,0.0,0,6.9660034,0.0,0.21707901,55.088081,6.9982677,501.08029,-9.2027893
3672,3672,212.2572,5.3883524,2.9603422,0.0,0,6.9383011,0.0,0.21986707,55.143471,6.9716263,501.13293,-9.205204
3683,3683,212.2594,5.3868413,2.9835224,0.0,0,6.9105988,0.0,0.22163482,55.007923,6.9433227,501.18555,-9.2048683
3694,3694,212.2616,5.3868332,3.0110269,0.0,0,6.8828964,0.0,0.22414444,54.82135,6.9157214,501.23819,-9.2048635
3705,3705,212.2638,5.3824382,3.0395315,0.0,0,6.8551941,0.0,0.22625995,54.627228,6.8868852,501.31653,-9.2047634
3716,3716,212.266,5.4135642,3.0701129,0.0,0,6.8274918,0.0,0.22924104,54.789581,6.8551035,501.40207,-9.2047834
3727,3727,212.2682,5.4269791,3.0957589,0.0,0,6.799789,0.0,0.23089889,54.741745,6.8301725,501.48758,-9.2057438
3738,3738,212.2704,5.4621329,3.1213453,0.0,0,6.7720866,0.0,0.2335145,55.053928,6.8046803,501.57309,-9.2043972
3749,3749,212.2726,5.4657078,3.1513736,0.0,0,6.7452793,0.0,0.23553976,54.891945,6.7741747,501.66025,-9.2039042
3760,3760,212.2748,5.4577746,3.1784387,0.0,0,6.7189231,0.0,0.23843065,54.791302,6.7499652,501.75235,-9.2036705
3771,3771,212.277,5.4686794,3.2076561,0.0,0,6.6925673,0.0,0.24018045,54.728481,6.720767,501.84445,-9.2037115
3782,3782,212.2792,5.4231853,3.227102,0.0,0,6.6662111,0.0,0.24252459,54.239349,6.6938896,501.93658,-9.2038431
3793,3793,212.2814,5.4240012,3.2542624,0.0,0,6.6398554,0.0,0.24424721,54.06678,6.6631112,502.02869,-9.2045822
3804,3804,212.2836,5.4143929,3.277884,0.0,0,6.6134992,0.0,0.2469891,53.859455,6.6447644,502.06949,-9.2045412
3815,3815,212.2858,5.4709306,3.3100173,0.0,0,6.5871429,0.0,0.24884503,54.26545,6.6189651,502.0892,-9.2033043
3826,3826,212.288,5.5132222,3.3284874,0.0,0,6.5607872,0.0,0.25116763,54.570057,6.5908613,502.10895,-9.2031746
3837,3837,212.2902,5.5593929,3.3573611,0.0,0,6.5344315,0.0,0.2531696,54.939541,6.56179,502.12869,-9.2031898
3848,3848,212.2924,5.5684409,3.3811464,0.0,0,6.5080752,0.0,0.25576192,54.942856,6.5353131,502.14047,-9.2048168
3859,3859,212.2946,5.5581689,3.4162853,0.0,0,6.4817195,0.0,0.25803405,54.640297,6.5124407,502.11417,-9.20469
3870,3870,212.2968,5.5771337,3.4387171,0.0,0,6.4553633,0.0,0.26061735,54.747391,6.4840956,502.08783,-9.2035465
3881,3881,212.299,5.5891356,3.4695888,0.0,0,6.4290075,0.0,0.26283428,54.668011,6.4498415,502.06152,-9.2039986
3892,3892,212.3012,5.6023827,3.4906454,0.0,0,6.4026513,0.0,0.26505363,54.621086,6.4243507,502.03522,-9.2040977
3903,3903,212.3034,5.5932975,3.5225842,0.0,0,6.3762951,0.0,0.2673912,54.52821,6.400456,502.034,-9.2046413
3914,3914,212.3056,5.6111698,3.545337,0.0,0,6.3499393,0.0,0.26981825,54.553818,6.3729525,502.04718,-9.2029343
3925,3925,212.3078,5.6283169,3.5750265,0.0,0,6.3235831,0.0,0.27215073,54.467209,6.3441372,502.06033,-9.2037239
3936,3936,212.31,5.6344275,3.5988879,0.0,0,6.2972279,0.0,0.27437147,54.53426,6.3200793,502.07349,-9.2023687
3947,3947,212.3122,5.6074085,3.6291332,0.0,0,6.2708716,0.0,0.27691555,54.189724,6.2925239,502.09061,-9.2031145
3958,3958,212.3144,5.5916853,3.6477973,0.0,0,6.2445159,0.0,0.27853674,53.874599,6.2712603,502.14322,-9.2035551
3969,3969,212.3166,5.6221824,3.6731617,0.0,0,6.2181597,0.0,0.28092262,54.034451,6.243701,502.19586,-9.2051172
3980,3980,212.3188,5.6385331,3.6993937,0.0,0,6.1918035,0.0,0.28301758,54.146992,6.2192245,502.2485,-9.2046404
3991,3991,212.321,5.639648,3.7277219,0.0,0,6.1654477,0.0,0.28589866,53.951691,6.1944299,502.30112,-9.2032738
4002,4002,212.3232,5.6786003,3.7534373,0.0,0,6.1403003,0.0,0.28768069,54.182896,6.164145,502.3649,-9.2036829
4013,4013,212.3254,5.7234154,3.7756872,0.0,0,6.1152334,0.0,0.29017341,54.445637,6.140666,502.43726,-9.204339
4024,4024,212.3276,5.7544055,3.803889,0.0,0,6.090167,0.0,0.29215467,54.704952,6.1123166,502.50964,-9.2051077
4035,4035,212.3298,5.7720127,3.8317993,0.0,0,6.0650997,0.0,0.29524672,54.699577,6.0881824,502.582,-9.2044468
4046,4046,212.332,5.7724414,3.8618088,0.0,0,6.0400333,0.0,0.29722103,54.623497,6.0564551,502.65439,-9.2038422
4057,4057,212.3342,5.7536964,3.881974,0.0,0,6.0149665,0.0,0.29979083,54.259644,6.0335422,502.72675,-9.2036657
4068,4068,212.3364,5.7354593,3.9116504,0.0,0,5.9898996,0.0,0.30178782,54.053738,6.0073676,502.7991,-9.2044306
4079,4079,212.3386,5.7338433,3.9328892,0.0,0,5.9648328,0.0,0.30448315,53.835197,5.9811625,502.87149,-9.2036581
4090,4090,212.3408,5.7201104,3.9633319,0.0,0,5.9397659,0.0,0.30623558,53.547573,5.9577637,502.94385,-9.2035704
4101,4101,212.343,5.7466569,3.9808347,0.0,0,5.9146991,0.0,0.30877802,53.621449,5.934761,502.21518,-9.201745
4112,4112,212.3452,5.7553873,4.005651,0.0,0,5.8896322,0.0,0.31032076,53.748337,5.9067359,500.65588,-9.2034502
4123,4123,212.3474,5.7759342,4.024672,0.0,0,5.8645654,0.0,0.31278774,53.827824,5.8855419,499.09662,-9.204874
4134,4134,212.3496,5.8200364,4.057035,0.0,0,5.839499,0.0,0.3149361,54.074158,5.8609738,497.53732,-9.2052164
4145,4145,212.3518,5.8289657,4.0765705,0.0,0,5.8144317,0.0,0.31737137,53.972511,5.8363838,495.97803,-9.2051392
4156,4156,212.354,5.8313656,4.1055036,0.0,0,5.7893648,0.0,0.31952122,53.948868,5.8118567,494.89609,-9.2051687
4167,4167,212.3562,5.8604918,4.1250362,0.0,0,5.7642984,0.0,0.32183644,54.072113,5.7840948,493.83685,-9.2045393
4178,4178,212.3584,5.8816886,4.1598744,0.0,0,5.7392311,0.0,0.32447466,54.106567,5.7583647,492.77762,-9.2035036
4189,4189,212.3606,5.8746233,4.1778765,0.0,0,5.7141647,0.0,0.32656473,53.94146,5.7354875,491.71838,-9.203126
4200,4200,212.3628,5.9010873,4.2056441,0.0,0,5.6890979,0.0,0.32893333,53.984062,5.7076311,491.41309,-9.2035351
4211,4211,212.365,5.9464669,4.2298908,0.0,0,5.664031,0.0,0.33126718,54.309719,5.6821918,492.15656,-9.2031517
4222,4222,212.3672,5.9614172,4.2616024,0.0,0,5.6389642,0.0,0.33417723,54.377037,5.6537929,492.90002,-9.2023563
4233,4233,212.3694,5.9554758,4.2831912,0.0,0,5.6138973,0.0,0.33621848,54.247196,5.6291699,493.64352,-9.2039232
4244,4244,212.3716,5.9655075,4.309792,0.0,0,5.589087,0.0,0.33869705,54.176979,5.6073503,494.38699,-9.2041216
4255,4255,212.3738,5.9381218,4.3320575,0.0,0,5.565239,0.0,0.34066722,53.804134,5.5792208,494.60831,-9.204175
4266,4266,212.376,5.9067426,4.360703,0.0,0,5.5413909,0.0,0.34369001,53.390297,5.5532746,494.75961,-9.2032833
4277,4277,212.3782,5.9268069,4.383656,0.0,0,5.5175428,0.0,0.34537399,53.396046,5.5307255,494.91095,-9.2036095
4288,4288,212.3804,5.941628,4.403811,0.0,0,5.4936948,0.0,0.347673,53.41433,5.5079541,495.06226,-9.2019987
4299,4299,212.3826,5.9501071,4.4258299,0.0,0,5.4698472,0.0,0.34936714,53.355103,5.4808974,494.34259,-9.2032156
4310,4310,212.3848,5.9982615,4.4502201,0.0,0,5.4459991,0.0,0.3523269,53.631229,5.4602766,491.97272,-9.2034855
4321,4321,212.387,6.0268722,4.4775019,0.0,0,5.4221511,0.0,0.35410491,53.900124,5.4357843,489.60284,-9.2030401
4332,4332,212.3892,6.0260267,4.4954629,0.0,0,5.398303,0.0,0.35658714,53.774647,5.4118657,487.233,-9.2024651
4343,4343,212.3914,6.0298314,4.5236573,0.0,0,5.374455,0.0,0.35843918,53.670757,5.3869734,484.86313,-9.2020464
4354,4354,212.3936,5.9948592,4.5444875,0.0,0,5.3506069,0.0,0.36136174,53.205135,5.3651099,483.23911,-9.2029915
4365,4365,212.3958,6.0034828,4.5738201,0.0,0,5.3267589,0.0,0.36317131,53.130077,5.3419394,481.79102,-9.2031889
4376,4376,212.398,6.038301,4.5880637,0.0,0,5.3029108,0.0,0.36544627,53.344593,5.316524,480.34293,-9.203743
4387,4387,212.4002,6.0995398,4.614614,0.0,0,5.2790627,0.0,0.36731374,53.75103,5.2945232,478.89484,-9.2026081
4398,4398,212.4024,6.1160946,4.637867,0.0,0,5.2552152,0.0,0.37034225,53.785889,5.2732248,478.24762,-9.2024231
4409,4409,212.4046,6.1296148,4.6692057,0.0,0,5.2313666,0.0,0.37229225,53.847301,5.250628,479.73572,-9.2029095
4420,4420,212.4068,6.1155806,4.6847153,0.0,0,5.2075191,0.0,0.37469974,53.535385,5.2230482,481.22382,-9.2026072
4431,4431,212.409,6.1127667,4.7107205,0.0,0,5.183671,0.0,0.37667459,53.40789,5.1999245,482.71191,-9.2017498
4442,4442,212.4112,6.126687,4.7318382,0.0,0,5.1598229,0.0,0.37931415,53.380814,5.1781955,484.20001,-9.2025814
4453,4453,212.4134,6.1704311,4.7639537,0.0,0,5.1359749,0.0,0.3816371,53.620003,5.1501451,485.33405,-9.2024384
4464,4464,212.4156,6.2069597,4.781703,0.0,0,5.1121268,0.0,0.38403642,53.781597,5.124485,486.34134,-9.2031326
4475,4475,212.4178,6.2046876,4.8096142,0.0,0,5.0882792,0.0,0.38647455,53.635147,5.1034198,487.34863,-9.2026854
4486,4486,212.42,6.2161632,4.8293643,0.0,0,5.0644312,0.0,0.38865963,53.658062,5.0761709,488.3559,-9.2029486
4497,4497,212.4222,6.2202744,4.8603344,0.0,0,5.0411463,0.0,0.39140162,53.554829,5.0528812,489.27625,-9.2033157
4508,4508,212.4244,6.2287674,4.8759999,0.0,0,5.0184641,0.0,0.39317203,53.477592,5.0300961,489.84879,-9.2036877
4519,4519,212.4266,6.2124362,4.9010797,0.0,0,4.9957824,0.0,0.39563227,53.328846,5.0114441,490.42133,-9.2044458
4530,4530,212.4288,6.2154489,4.9217191,0.0,0,4.9731002,0.0,0.39753312,53.237175,4.9907207,490.99387,-9.202898
4541,4541,212.431,6.2446613,4.9512415,0.0,0,4.950418,0.0,0.40068415,53.208385,4.9618106,491.56641,-9.2032785
4552,4552,212.4332,6.272047,4.9717278,0.0,0,4.9277363,0.0,0.40242389,53.438545,4.9383712,491.96417,-9.2031975
4563,4563,212.4354,6.2819867,4.9938579,0.0,0,4.9050541,0.0,0.4049648,53.341557,4.9143271,492.27341,-9.2029724
4574,4574,212.4376,6.3029895,5.0153174,0.0,0,4.8823724,0.0,0.40674749,53.424454,4.8950958,492.58261,-9.2039299
4585,4585,212.4398,6.3174901,5.0388031,0.0,0,4.8596902,0.0,0.40962917,53.408482,4.8701625,492.89182,-9.2027435
4596,4596,212.442,6.325273,5.0646811,0.0,0,4.837008,0.0,0.41151723,53.316734,4.8484817,493.2002,-9.2027855
4607,4607,212.4442,6.3302164,5.0843449,0.0,0,4.8143263,0.0,0.41423804,53.335625,4.8244271,493.50284,-9.2028675
4618,4618,212.4464,6.3246503,5.1093464,0.0,0,4.7916441,0.0,0.41599816,53.136845,4.8027086,493.80548,-9.2022581
4629,4629,212.4486,6.346293,5.1291814,0.0,0,4.7689624,0.0,0.41893956,53.188187,4.7773862,494.10812,-9.2021275
4640,4640,212.4508,6.3685069,5.1578088,0.0,0,4.7462802,0.0,0.4206906,53.222233,4.755506,494.41074,-9.2030849
4651,4651,212.453,6.4052067,5.1736598,0.0,0,4.723598,0.0,0.42336842,53.432297,4.7344818,494.71729,-9.2031593
4662,4662,212.4552,6.4397979,5.2010174,0.0,0,4.7009163,0.0,0.42544493,53.621784,4.7062111,495.02649,-9.2028265
4673,4673,212.4574,6.4698176,5.2212515,0.0,0,4.6782346,0.0,0.42831069,53.669514,4.6826477,495.33569,-9.2030258
4684,4684,212.4596,6.4602032,5.250042,0.0,0,4.6555519,0.0,0.43015191,53.518826,4.6611576,495.64493,-9.2032843
4695,4695,212.4618,6.467063,5.2670355,0.0,0,4.6328702,0.0,0.43292874,53.410278,4.6414218,495.95377,-9.2043657
4706,4706,212.464,6.4632564,5.2940726,0.0,0,4.610188,0.0,0.43494737,53.340618,4.6146684,496.25641,-9.2030993
4717,4717,212.4662,6.449285,5.3129511,0.0,0,4.5875063,0.0,0.43763536,53.020355,4.5920196,496.55905,-9.2022753
4728,4728,212.4684,6.4356813,5.3422651,0.0,0,4.5648246,0.0,0.43985665,52.793793,4.5724783,496.86166,-9.2030134
4739,4739,212.4706,6.4667826,5.3559208,0.0,0,4.5421419,0.0,0.44198516,52.919064,4.5534596,497.16431,-9.20257
4750,4750,212.4728,6.5321493,5.3821597,0.0,0,4.5202942,0.0,0.44423419,53.263996,4.5292487,497.4465,-9.2037334
4761,4761,212.475,6.5743885,5.4017954,0.0,0,4.4987168,0.0,0.44657561,53.562634,4.5049725,497.70966,-9.2040854
4772,4772,212.4772,6.5982437,5.4315557,0.0,0,4.4771395,0.0,0.4492453,53.598812,4.4800186,497.97281,-9.202405
4783,4783,212.4794,6.6079841,5.4469604,0.0,0,4.4555616,0.0,0.45122308,53.552467,4.4592605,498.23596,-9.2020483
4794,4794,212.4816,6.5687151,5.471118,0.0,0,4.4339843,0.0,0.45372304,53.179562,4.4354801,498.49911,-9.2022762
4805,4805,212.4838,6.5694046,5.4924746,0.0,0,4.4124064,0.0,0.45594639,52.998093,4.415894,498.168,-9.2035685
4816,4816,212.486,6.5506635,5.5184236,0.0,0,4.3908291,0.0,0.45874989,52.723473,4.3946476,497.8259,-9.2031784
4827,4827,212.4882,6.5609779,5.5375175,0.0,0,4.3692513,0.0,0.46044305,52.741589,4.3722873,497.4838,-9.2029324
4838,4838,212.4904,6.595119,5.5559478,0.0,0,4.3476739,0.0,0.46282306,52.873821,4.3488173,497.14166,-9.2030315
4849,4849,212.4926,6.6303639,5.5773559,0.0,0,4.3260961,0.0,0.46465105,53.029686,4.3300147,496.78784,-9.2032099
4860,4860,212.4948,6.6737509,5.6005535,0.0,0,4.3045187,0.0,0.46765614,53.218822,4.3086128,496.41943,-9.2026186
4871,4871,212.497,6.6682158,5.6219034,0.0,0,4.2829409,0.0,0.46925312,53.111019,4.2887764,496.05099,-9.2031097
4882,4882,212.4992,6.6769228,5.6400256,0.0,0,4.261363,0.0,0.47193727,53.012409,4.2647576,495.68259,-9.2022324
4893,4893,212.5014,6.6735325,5.6640687,0.0,0,4.2397857,0.0,0.47372776,52.947266,4.2454848,495.31415,-9.2028933
4904,4904,212.5036,6.6854382,5.6847029,0.0,0,4.2182078,0.0,0.47690636,52.838776,4.2211566,495.50198,-9.203578
4915,4915,212.5058,6.6808276,5.7101398,0.0,0,4.1966305,0.0,0.47851214,52.714256,4.2016888,495.74539,-9.204277
4926,4926,212.508,6.6789837,5.7246599,0.0,0,4.1750526,0.0,0.48114708,52.509766,4.1821356,495.98883,-9.2035799
4937,4937,212.5102,6.7229128,5.7483034,0.0,0,4.1534753,0.0,0.48274618,52.814457,4.1618776,496.23227,-9.2022791
4948,4948,212.5124,6.7841849,5.765553,0.0,0,4.1318974,0.0,0.48561555,53.096954,4.1410851,496.35062,-9.2015209
4959,4959,212.5146,6.8308468,5.7959733,0.0,0,4.1103201,0.0,0.48773929,53.407921,4.1161752,496.25851,-9.2026405
4970,4970,212.5168,6.8707743,5.8101239,0.0,0,4.0887423,0.0,0.49034438,53.537083,4.097456,496.16638,-9.2033205
4981,4981,212.519,6.8588204,5.8346729,0.0,0,4.0671649,0.0,0.49212348,53.460072,4.0741835,496.07428,-9.2038708
4992,4992,212.5212,6.8719773,5.8525643,0.0,0,4.0456271,0.0,0.4950653,53.400562,4.0505452,495.98218,-9.2030029
5003,5003,212.5234,6.8860316,5.883831,0.0,0,4.0250955,0.0,0.49746481,53.30127,4.0285048,495.97812,-9.2019272
5014,5014,212.5256,6.8844953,5.8981562,0.0,0,4.0045743,0.0,0.49984974,53.177319,4.0063252,495.99127,-9.2017937
5025,5025,212.5278,6.8953376,5.9247069,0.0,0,3.9840524,0.0,0.50219846,53.098549,3.9846635,496.00443,-9.2022171
5036,5036,212.53,6.8922796,5.9415898,0.0,0,3.9635308,0.0,0.50461459,52.935368,3.9607024,496.01758,-9.2022371
5047,5047,212.5322,6.9188552,5.9709373,0.0,0,3.9430094,0.0,0.5073207,53.004139,3.9426057,496.16891,-9.2018719
5058,5058,212.5344,6.9114261,5.9849186,0.0,0,3.9224877,0.0,0.50919563,52.897354,3.9222584,496.64261,-9.2031298
5069,5069,212.5366,6.9206824,6.0049539,0.0,0,3.9019661,0.0,0.51132578,52.889462,3.9032001,497.1163,-9.2019529
5080,5080,212.5388,6.8912492,6.0208116,0.0,0,3.8814445,0.0,0.51318598,52.555313,3.8873472,497.59,-9.2044401
5091,5091,212.541,6.9132919,6.0450273,0.0,0,3.8609228,0.0,0.51580083,52.585815,3.8691509,498.06369,-9.2041807
5102,5102,212.5432,6.952188,6.0622354,0.0,0,3.8404012,0.0,0.5176602,52.817707,3.8481772,498.42181,-9.2038174
5113,5113,212.5454,7.018723,6.0863528,0.0,0,3.8198798,0.0,0.52053171,53.003849,3.8286898,498.7442,-9.202734
5124,5124,212.5476,7.0636668,6.1039276,0.0,0,3.7993581,0.0,0.52220809,53.287781,3.8038878,499.06659,-9.2028561
5135,5135,212.5498,7.0934997,6.1285286,0.0,0,3.7788365,0.0,0.52546078,53.373844,3.7834594,499.38895,-9.201457
5146,5146,212.552,7.1129994,6.1505995,0.0,0,3.7583151,0.0,0.52718627,53.466316,3.7604442,499.68442,-9.2021894
5157,5157,212.5542,7.125968,6.1685314,0.0,0,3.7377934,0.0,0.5300681,53.417881,3.7393405,499.88837,-9.2017689
5168,5168,212.5564,7.148953,6.1910968,0.0,0,3.7172718,0.0,0.53185189,53.500511,3.7179167,500.09232,-9.2037334
5179,5179,212.5586,7.1675386,6.2118144,0.0,0,3.6967502,0.0,0.53515464,53.483067,3.697232,500.29626,-9.2031031
5190,5190,212.5608,7.1629777,6.237309,0.0,0,3.6762285,0.0,0.53693807,53.33337,3.6751134,500.50021,-9.202919
5201,5201,212.563,7.1509204,6.2541761,0.0,0,3.6557069,0.0,0.53995663,53.050598,3.6498461,500.59052,-9.203373
5212,5212,212.5652,7.1646433,6.278367,0.0,0,3.6351855,0.0,0.54164249,53.01852,3.6330919,500.62997,-9.2020845
5223,5223,212.5674,7.1677895,6.2943397,0.0,0,3.6146636,0.0,0.5446018,52.870461,3.614207,500.66946,-9.2019806
5234,5234,212.5696,7.1965737,6.3201642,0.0,0,3.5941422,0.0,0.54627264,53.072601,3.5947039,500.70892,-9.2029295
5245,5245,212.5718,7.2127547,6.3312054,0.0,0,3.5739214,0.0,0.54888588,53.036095,3.5731549,500.74536,-9.2025013
5256,5256,212.574,7.2042928,6.354569,0.0,0,3.5543985,0.0,0.55059534,52.860447,3.5545042,500.76511,-9.2028742
5267,5267,212.5762,7.1941552,6.3709416,0.0,0,3.5348759,0.0,0.55348104,52.702251,3.5384991,500.78485,-9.2027864
5278,5278,212.5784,7.2165251,6.4004197,0.0,0,3.515353,0.0,0.55565864,52.648453,3.5167482,500.80457,-9.2030888
5289,5289,212.5806,7.2315149,6.4061222,0.0,0,3.4958301,0.0,0.5573985,52.752014,3.4987652,500.82431,-9.2030363
5300,5300,212.5828,7.2635965,6.4284439,0.0,0,3.4763074,0.0,0.55921292,52.916748,3.4803405,500.86438,-9.2030067
5311,5311,212.585,7.3270035,6.4459972,0.0,0,3.4567847,0.0,0.5619356,53.188217,3.4615943,500.91702,-9.2030888
5322,5322,212.5872,7.3879356,6.475359,0.0,0,3.4372616,0.0,0.56461692,53.509148,3.4420428,500.96967,-9.2030735
5333,5333,212.5894,7.4436331,6.4895039,0.0,0,3.4177392,0.0,0.56698173,53.774155,3.4197729,501.02228,-9.203351
5344,5344,212.5916,7.4746165,6.5140629,0.0,0,3.398216,0.0,0.56946957,53.868473,3.3978164,501.07062,-9.2026691
5355,5355,212.5938,7.4636264,6.5323615,0.0,0,3.3786936,0.0,0.57184488,53.616356,3.3776495,501.07062,-9.2020435
5366,5366,212.596,7.4595203,6.5583034,0.0,0,3.3591707,0.0,0.57476449,53.517437,3.3547046,501.07062,-9.2029867
5377,5377,212.5982,7.4701061,6.5738339,0.0,0,3.3396475,0.0,0.57662475,53.375835,3.3338215,501.07062,-9.2021828
5388,5388,212.6004,7.4650278,6.5947351,0.0,0,3.3201251,0.0,0.5792318,53.227135,3.3193324,501.07062,-9.2021751
5399,5399,212.6026,7.4608226,6.6103101,0.0,0,3.300602,0.0,0.58090639,53.095226,3.2947755,501.11011,-9.2024698
5410,5410,212.6048,7.4578605,6.6339164,0.0,0,3.2810791,0.0,0.58407986,52.899654,3.2755196,501.18246,-9.2032804
5421,5421,212.607,7.4423966,6.6515722,0.0,0,3.2615566,0.0,0.58563805,52.754803,3.2583799,501.25485,-9.2033825
5432,5432,212.6092,7.5112872,6.6667109,0.0,0,3.2420335,0.0,0.58814049,53.173393,3.2442534,501.32721,-9.2031422
5443,5443,212.6114,7.5738716,6.6855855,0.0,0,3.2225108,0.0,0.58954376,53.395504,3.2255478,501.39893,-9.203001
5454,5454,212.6136,7.6173148,6.7075257,0.0,0,3.2029881,0.0,0.59314764,53.626823,3.20293,501.39893,-9.2025242
5465,5465,212.6158,7.6298075,6.7289386,0.0,0,3.1834652,0.0,0.59457713,53.592327,3.1829565,501.39893,-9.2024231
5476,5476,212.618,7.6529918,6.744442,0.0,0,3.1639426,0.0,0.59771061,53.574131,3.1624172,501.39893,-9.2025385
5487,5487,212.6202,7.6981173,6.7705479,0.0,0,3.1444199,0.0,0.59973156,53.78204,3.1432559,501.39893,-9.2024822
5498,5498,212.6224,7.7390652,6.7882562,0.0,0,3.1254423,0.0,0.60321045,53.871075,3.1225984,501.40204,-9.2016678
5509,5509,212.6246,7.767808,6.8157701,0.0,0,3.1068697,0.0,0.60497248,54.009796,3.100847,501.4086,-9.2020321
5520,5520,212.6268,7.7870011,6.8271832,0.0,0,3.0882974,0.0,0.60775673,54.01646,3.0825467,501.41519,-9.2017899
5531,5531,212.629,7.7586675,6.8499365,0.0,0,3.0697248,0.0,0.60942721,53.709988,3.0611262,501.42175,-9.2021933
5542,5542,212.6312,7.6828241,6.8627267,0.0,0,3.0511525,0.0,0.61230034,53.110771,3.0481038,501.42831,-9.2036123
5553,5553,212.6334,7.6130795,6.889257,0.0,0,3.0325804,0.0,0.61405927,52.478069,3.028487,501.53964,-9.2036934
5564,5564,212.6356,7.6219683,6.8960385,0.0,0,3.0140078,0.0,0.61624932,52.378143,3.0139174,501.65805,-9.2024698
5575,5575,212.6378,7.6807046,6.9177256,0.0,0,2.9954355,0.0,0.61802131,52.687885,2.99279,501.77646,-9.2030172
5586,5586,212.64,7.7563701,6.9283285,0.0,0,2.9768629,0.0,0.62021005,53.079041,2.9776466,501.8949,-9.2017584
5597,5597,212.6422,7.8239894,6.9569564,0.0,0,2.9582906,0.0,0.62273735,53.379566,2.9611795,501.97385,-9.203187
5608,5608,212.6444,7.8791037,6.965189,0.0,0,2.939718,0.0,0.62457412,53.6576,2.9400773,501.99359,-9.2016764
5619,5619,212.6466,7.9466476,6.9893513,0.0,0,2.9211457,0.0,0.62706721,53.998375,2.9207942,502.01331,-9.2020426
5630,5630,212.6488,7.994473,7.0052915,0.0,0,2.9025736,0.0,0.6294018,54.3009,2.9021707,502.03305,-9.2028084
5641,5641,212.651,8.0071936,7.0344315,0.0,0,2.884001,0.0,0.63285154,54.121841,2.8826404,502.0528,-9.2023983
5652,5652,212.6532,7.9673276,7.0463686,0.0,0,2.8654287,0.0,0.63439292,53.794308,2.8650239,501.89639,-9.2023907
5663,5663,212.6554,7.9796567,7.0671272,0.0,0,2.8468561,0.0,0.63703603,53.701855,2.8464189,501.71216,-9.2023249
5674,5674,212.6576,8.0288563,7.0830517,0.0,0,2.8282838,0.0,0.63896567,53.936691,2.8253143,501.52795,-9.2019119
5685,5685,212.6598,8.0917292,7.1078758,0.0,0,2.8097112,0.0,0.64237988,54.201691,2.8084986,501.34375,-9.201478
5696,5696,212.662,8.1237602,7.1256013,0.0,0,2.7911389,0.0,0.64398885,54.344406,2.7857571,501.08417,-9.2015171
5707,5707,212.6642,8.1448326,7.14433,0.0,0,2.7725666,0.0,0.64709222,54.377972,2.7699454,500.66968,-9.2026691
5718,5718,212.6664,8.1277313,7.1612449,0.0,0,2.753994,0.0,0.64863116,54.112682,2.754236,500.25522,-9.2034349
5729,5729,212.6686,8.1770573,7.1819606,0.0,0,2.7354219,0.0,0.6521399,54.212757,2.7333374,499.84073,-9.2034397
5740,5740,212.6708,8.1689587,7.203526,0.0,0,2.7168493,0.0,0.65381491,54.129116,2.7135489,499.42624,-9.2026749
5751,5751,212.673,8.168416,7.2164955,0.0,0,2.6990447,0.0,0.65650821,53.945129,2.6963882,499.33438,-9.2023954
5762,5762,212.6752,8.1713085,7.2382755,0.0,0,2.6813786,0.0,0.65818876,53.873169,2.6782548,499.32782,-9.2035961
5773,5773,212.6774,8.2261982,7.2542982,0.0,0,2.6637125,0.0,0.6616298,54.033848,2.6603501,499.32123,-9.2026901
5784,5784,212.6796,8.2775993,7.2769165,0.0,0,2.6460466,0.0,0.66308063,54.327877,2.6405187,499.31467,-9.2022171
5795,5795,212.6818,8.3289938,7.2890573,0.0,0,2.6283805,0.0,0.6660223,54.490601,2.6210783,499.29468,-9.2020063
5806,5806,212.684,8.3261747,7.3120084,0.0,0,2.6107144,0.0,0.66767067,54.351723,2.6023407,499.23547,-9.2021685
5817,5817,212.6862,8.2861032,7.3261418,0.0,0,2.5930486,0.0,0.67095435,53.940311,2.5872974,499.17624,-9.204463
5828,5828,212.6884,8.2525864,7.3492465,0.0,0,2.5753825,0.0,0.67242151,53.707188,2.5697274,499.11703,-9.204113
5839,5839,212.6906,8.2552109,7.3573785,0.0,0,2.5577166,0.0,0.6748575,53.552376,2.5539532,499.05783,-9.2031546
5850,5850,212.6928,8.2698231,7.3772511,0.0,0,2.5400505,0.0,0.676507,53.53315,2.5365646,498.65842,-9.2022591
5861,5861,212.695,8.3647451,7.3912253,0.0,0,2.5223844,0.0,0.67925578,53.908001,2.5213735,498.12552,-9.2022629
5872,5872,212.6972,8.4398451,7.4169526,0.0,0,2.5047185,0.0,0.68147916,54.313183,2.5028238,497.59262,-9.2029448
5883,5883,212.6994,8.4941263,7.4250484,0.0,0,2.4870527,0.0,0.68359542,54.587635,2.485878,497.05972,-9.2025795
5894,5894,212.7016,8.5222492,7.4491916,0.0,0,2.4693866,0.0,0.68608212,54.626595,2.4665465,496.62134,-9.2024221
5905,5905,212.7038,8.5546045,7.4636393,0.0,0,2.4517205,0.0,0.68852729,54.667545,2.444303,496.60815,-9.2033243
5916,5916,212.706,8.5558901,7.4877667,0.0,0,2.4340546,0.0,0.69115567,54.570015,2.4317057,496.595,-9.2017241
5927,5927,212.7082,8.5493116,7.4983311,0.0,0,2.4163885,0.0,0.69296676,54.474064,2.4153664,496.58185,-9.2020836
5938,5938,212.7104,8.5746803,7.5199342,0.0,0,2.3987224,0.0,0.69579685,54.433453,2.3901846,496.5687,-9.202487
5949,5949,212.7126,8.6123133,7.5370536,0.0,0,2.3810565,0.0,0.6980803,54.539772,2.3741021,496.71689,-9.2017193
5960,5960,212.7148,8.6703434,7.5597315,0.0,0,2.3633904,0.0,0.7013157,54.713505,2.3582783,496.95374,-9.2023668
5971,5971,212.717,8.7277174,7.5727048,0.0,0,2.3457243,0.0,0.70246911,55.063023,2.3383477,497.19058,-9.2020388
5982,5982,212.7192,8.7537975,7.5891209,0.0,0,2.3280585,0.0,0.70542163,55.05724,2.3184555,497.42743,-9.2029238
5993,5993,212.7214,8.7625742,7.6102843,0.0,0,2.3104956,0.0,0.70750844,55.013264,2.3068929,497.62909,-9.2029152
6004,6004,212.7236,8.7700691,7.6283503,0.0,0,2.2936916,0.0,0.7109322,54.868725,2.2855074,497.54355,-9.202693
6015,6015,212.7258,8.776968,7.6468525,0.0,0,2.2768879,0.0,0.71243817,54.772072,2.273145,497.45804,-9.203125
6026,6026,212.728,8.7923355,7.66008,0.0,0,2.2600844,0.0,0.71509945,54.753151,2.2538099,497.3725,-9.2026682
6037,6037,212.7302,8.8145752,7.6802144,0.0,0,2.2432809,0.0,0.71677619,54.791775,2.2382884,497.28696,-9.2022209
6048,6048,212.7324,8.8430147,7.6922669,0.0,0,2.2264774,0.0,0.71988976,54.782719,2.2209284,497.2655,-9.2041245
6059,6059,212.7346,8.8748016,7.7157755,0.0,0,2.2096736,0.0,0.72157723,54.892395,2.2024677,497.29181,-9.2016964
6070,6070,212.7368,8.9139004,7.7266355,0.0,0,2.1928701,0.0,0.72451085,54.964794,2.1846671,497.31815,-9.2002516
6081,6081,212.739,8.9271469,7.74506,0.0,0,2.1760664,0.0,0.7255348,54.999542,2.1690056,497.34445,-9.2016611
6092,6092,212.7412,8.9442825,7.7572346,0.0,0,2.1592631,0.0,0.72889435,54.948402,2.1567626,497.37939,-9.2019148
6103,6103,212.7434,8.9949799,7.7828574,0.0,0,2.1424592,0.0,0.73068947,55.171989,2.1390665,497.64255,-9.2034998
6114,6114,212.7456,9.0290089,7.7912378,0.0,0,2.1256557,0.0,0.73338485,55.202408,2.1205039,497.90573,-9.2032232
6125,6125,212.7478,9.0997105,7.8161159,0.0,0,2.1088521,0.0,0.73562866,55.526382,2.1035917,498.16888,-9.202754
6136,6136,212.75,9.1554852,7.8286729,0.0,0,2.0920484,0.0,0.73844773,55.668869,2.0837665,498.43207,-9.2020159
6147,6147,212.7522,9.2162857,7.8565884,0.0,0,2.0752449,0.0,0.74110436,55.823082,2.0640962,498.66562,-9.2026587
6158,6158,212.7544,9.2366142,7.8656845,0.0,0,2.0584414,0.0,0.7435196,55.903065,2.0478609,498.86957,-9.2030134
6169,6169,212.7566,9.2177782,7.8884301,0.0,0,2.0416377,0.0,0.74596763,55.737469,2.0319324,499.07352,-9.2022305
6180,6180,212.7588,9.1967287,7.898777,0.0,0,2.0248342,0.0,0.7479701,55.43272,2.0138321,499.27747,-9.2009163
6191,6191,212.761,9.1925125,7.9231582,0.0,0,2.0080307,0.0,0.75072032,55.241108,1.9947091,499.48141,-9.2014427
6202,6202,212.7632,9.1748028,7.9310188,0.0,0,1.9912269,0.0,0.75242603,55.092052,1.978804,499.52689,-9.2013617
6213,6213,212.7654,9.1572475,7.9517446,0.0,0,1.9744233,0.0,0.75514883,54.791893,1.9700702,499.56635,-9.2027493
6224,6224,212.7676,9.1802473,7.9622126,0.0,0,1.9576197,0.0,0.75666404,54.817451,1.9535028,499.60583,-9.2033224
6235,6235,212.7698,9.2558022,7.9830666,0.0,0,1.9408162,0.0,0.75984216,55.133423,1.9397101,499.64529,-9.2033691
6246,6246,212.772,9.3157206,7.9924898,0.0,0,1.9243335,0.0,0.7609778,55.397045,1.9219981,498.89178,-9.2027588
6257,6257,212.7742,9.4337015,8.0106897,0.0,0,1.9083482,0.0,0.76391137,55.919579,1.9022759,497.07541,-9.2013264
6268,6268,212.7764,9.4977369,8.0285559,0.0,0,1.892363,0.0,0.76599437,56.198593,1.8874211,495.25903,-9.203516
6279,6279,212.7786,9.5295477,8.0475588,0.0,0,1.8763778,0.0,0.76939929,56.206558,1.8698006,493.44266,-9.2047958
6290,6290,212.7808,9.5175514,8.0631819,0.0,0,1.8603926,0.0,0.77064621,56.101974,1.8516308,491.62628,-9.2020426
6301,6301,212.783,9.5503416,8.0752478,0.0,0,1.8444074,0.0,0.77345681,56.106853,1.8335539,490.39655,-9.2008209
6312,6312,212.7852,9.5663538,8.0929375,0.0,0,1.8284222,0.0,0.77488238,56.114723,1.8197509,489.23862,-9.2009993
6323,6323,212.7874,9.5918274,8.1113567,0.0,0,1.8124371,0.0,0.77882969,56.006485,1.8031971,488.08069,-9.2019701
6334,6334,212.7896,9.5972033,8.132082,0.0,0,1.7964518,0.0,0.78022987,56.015057,1.787547,486.92276,-9.2023458
6345,6345,212.7918,9.6689835,8.1411209,0.0,0,1.7804666,0.0,0.7832852,56.26247,1.7740574,486.50916,-9.2029982
6356,6356,212.794,9.7269974,8.16047,0.0,0,1.7644814,0.0,0.78468418,56.493504,1.7560029,487.45053,-9.2009859
6367,6367,212.7962,9.7711153,8.1747017,0.0,0,1.7484962,0.0,0.78834689,56.583847,1.7379797,488.39188,-9.2020378
6378,6378,212.7984,9.784914,8.1997728,0.0,0,1.732511,0.0,0.78993309,56.581036,1.7232314,489.33322,-9.2016525
6389,6389,212.8006,9.785696,8.2042017,0.0,0,1.7165258,0.0,0.79252756,56.383556,1.7059958,490.27457,-9.2027426
6400,6400,212.8028,9.8113804,8.2228756,0.0,0,1.7005407,0.0,0.7939719,56.460728,1.6952164,490.54263,-9.2017698
6411,6411,212.805,9.8254843,8.2376232,0.0,0,1.6845553,0.0,0.79739398,56.309952,1.678351,490.66107,-9.2009125
6422,6422,212.8072,9.8723497,8.2637644,0.0,0,1.6685703,0.0,0.79961008,56.492901,1.6634868,490.77951,-9.201292
6433,6433,212.8094,9.9453421,8.2708731,0.0,0,1.6525849,0.0,0.8021428,56.75182,1.646538,490.89795,-9.2015924
6444,6444,212.8116,10.013314,8.2901134,0.0,0,1.6365998,0.0,0.80399323,57.007164,1.6292048,490.97928,-9.2018719
6455,6455,212.8138,10.069501,8.3008928,0.0,0,1.6206145,0.0,0.80657041,57.215992,1.6141407,490.96613,-9.2020035
6466,6466,212.816,10.097206,8.3269939,0.0,0,1.6046293,0.0,0.80935144,57.245705,1.5975571,490.95297,-9.2025871
6477,6477,212.8182,10.091887,8.3355913,0.0,0,1.588644,0.0,0.811625,57.111938,1.5796198,490.93982,-9.2014294
6488,6488,212.8204,10.102017,8.3560715,0.0,0,1.572659,0.0,0.81416643,56.983768,1.5638524,490.92667,-9.2007542
6499,6499,212.8226,10.119317,8.3670406,0.0,0,1.5571915,0.0,0.81604713,57.009979,1.5520991,491.17343,-9.2036114
6510,6510,212.8248,10.146274,8.3883648,0.0,0,1.5419852,0.0,0.81909931,56.936756,1.5357056,491.50897,-9.20292
6521,6521,212.827,10.204457,8.3985405,0.0,0,1.5267788,0.0,0.8206892,57.165596,1.5175256,491.84451,-9.2014046
6532,6532,212.8292,10.306284,8.4168081,0.0,0,1.5115724,0.0,0.82378286,57.570179,1.5018817,492.18002,-9.2012997
6543,6543,212.8314,10.373042,8.430666,0.0,0,1.4963659,0.0,0.82519037,57.856094,1.4887151,492.50317,-9.2006693
6554,6554,212.8336,10.398084,8.4515982,0.0,0,1.4811596,0.0,0.82916355,57.785522,1.4737698,492.77951,-9.2014036
6565,6565,212.8358,10.400745,8.4650221,0.0,0,1.4659532,0.0,0.83034104,57.716553,1.4575963,493.05585,-9.2018642
6576,6576,212.838,10.370771,8.4757414,0.0,0,1.4507468,0.0,0.83291507,57.426971,1.4412707,493.33215,-9.2019691
6587,6587,212.8402,10.383955,8.4902744,0.0,0,1.4355403,0.0,0.83414078,57.419861,1.4249845,493.60849,-9.201087
6598,6598,212.8424,10.399159,8.5070114,0.0,0,1.420334,0.0,0.83817911,57.269081,1.4088968,493.88037,-9.2011662
6609,6609,212.8446,10.420047,8.5262222,0.0,0,1.4051275,0.0,0.83937204,57.282948,1.3957765,494.15012,-9.2012615
6620,6620,212.8468,10.458097,8.5346842,0.0,0,1.3899211,0.0,0.84241879,57.323689,1.3850235,494.41986,-9.2017517
6631,6631,212.849,10.5165,8.5526857,0.0,0,1.3747147,0.0,0.84370345,57.60387,1.3690418,494.68961,-9.2008038
6642,6642,212.8512,10.579045,8.5630655,0.0,0,1.3595084,0.0,0.84697491,57.718727,1.3512677,494.94766,-9.2008038
6653,6653,212.8534,10.609206,8.5859079,0.0,0,1.3443019,0.0,0.84839672,57.822334,1.3378094,495.13187,-9.2004118
6664,6664,212.8556,10.663476,8.5926027,0.0,0,1.3290955,0.0,0.85153109,57.925072,1.3233392,495.31607,-9.2000952
6675,6675,212.8578,10.702929,8.6119452,0.0,0,1.3138891,0.0,0.85294437,58.076382,1.3077427,495.50031,-9.2013464
6686,6686,212.86,10.753894,8.6222067,0.0,0,1.2986828,0.0,0.85607225,58.151173,1.2899765,495.68451,-9.201417
6697,6697,212.8622,10.842184,8.6496201,0.0,0,1.2834765,0.0,0.85832804,58.497044,1.2761375,495.78976,-9.1998777
6708,6708,212.8644,10.922079,8.6541309,0.0,0,1.26827,0.0,0.86100024,58.744633,1.2608781,495.84241,-9.2016096
6719,6719,212.8666,10.951778,8.6717224,0.0,0,1.2530636,0.0,0.86252445,58.892654,1.2432014,495.89502,-9.2022486
6730,6730,212.8688,10.983099,8.6811686,0.0,0,1.2378571,0.0,0.86516285,58.855759,1.2311014,495.94766,-9.2013493
6741,6741,212.871,11.008505,8.7088509,0.0,0,1.2226508,0.0,0.86814058,58.881157,1.2150755,495.98648,-9.2006044
6752,6752,212.8732,11.049597,8.7159824,0.0,0,1.2081414,0.0,0.87063062,58.894867,1.2013377,495.82199,-9.2005682
6763,6763,212.8754,11.051234,8.7335176,0.0,0,1.1936786,0.0,0.87265879,58.808487,1.182875,495.65753,-9.2009525
6774,6774,212.8776,11.044899,8.744628,0.0,0,1.1792159,0.0,0.87476116,58.659882,1.1720079,495.49304,-9.2017889
6785,6785,212.8798,11.043596,8.7665176,0.0,0,1.164753,0.0,0.87782544,58.450581,1.1594678,495.32858,-9.201827
6796,6796,212.882,11.09486,8.7746563,0.0,0,1.1502903,0.0,0.87942576,58.612667,1.1441624,494.81369,-9.2023745
6807,6807,212.8842,11.151023,8.791275,0.0,0,1.1358274,0.0,0.88222319,58.713898,1.1270138,493.98465,-9.2011595
6818,6818,212.8864,11.223538,8.7997684,0.0,0,1.1213646,0.0,0.88316208,59.092815,1.114923,493.15564,-9.1999636
6829,6829,212.8886,11.292626,8.8207569,0.0,0,1.1069018,0.0,0.88715494,59.203739,1.1035572,492.32663,-9.2006912
6840,6840,212.8908,11.355197,8.8348064,0.0,0,1.0924389,0.0,0.88872385,59.437542,1.0884649,491.49759,-9.2012005
6851,6851,212.893,11.416531,8.8464193,0.0,0,1.0779762,0.0,0.89143002,59.647285,1.0714006,489.54614,-9.2011652
6862,6862,212.8952,11.456942,8.8579988,0.0,0,1.0635133,0.0,0.89232391,59.805683,1.056965,487.58441,-9.2002535
6873,6873,212.8974,11.476554,8.877737,0.0,0,1.0490506,0.0,0.89686626,59.618031,1.042807,485.62271,-9.1996431
6884,6884,212.8996,11.483673,8.8942995,0.0,0,1.0345879,0.0,0.89803267,59.570339,1.0274057,483.66098,-9.2007332
6895,6895,212.9018,11.537768,8.9009037,0.0,0,1.020125,0.0,0.90074301,59.650948,1.0122088,481.74982,-9.2008781
6906,6906,212.904,11.595913,8.9180384,0.0,0,1.0056621,0.0,0.90201938,59.87458,0.99645174,479.89929,-9.2007046
6917,6917,212.9062,11.656396,8.9309282,0.0,0,0.99119943,0.0,0.90586942,60.022648,0.98198694,478.0488,-9.2003059
6928,6928,212.9084,11.745727,8.953661,0.0,0,0.97673661,0.0,0.90748441,60.34441,0.96668106,476.19827,-9.2003965
6939,6939,212.9106,11.778665,8.9621,0.0,0,0.96227378,0.0,0.91097128,60.338799,0.95616263,474.34778,-9.2017183
6950,6950,212.9128,11.791136,8.9819374,0.0,0,0.94781095,0.0,0.91237509,60.287106,0.93959862,474.13596,-9.2012863
6961,6961,212.915,11.801041,8.9881573,0.0,0,0.93334818,0.0,0.91541857,60.147255,0.92227936,474.07013,-9.2022238
6972,6972,212.9172,11.825428,9.0111351,0.0,0,0.91888541,0.0,0.91704804,60.168861,0.90842563,474.00427,-9.2016792
6983,6983,212.9194,11.858088,9.0165949,0.0,0,0.90442258,0.0,0.9197892,60.156204,0.896465,473.93845,-9.200676
6994,6994,212.9216,11.934054,9.0370131,0.0,0,0.8901087,0.0,0.92180341,60.424412,0.88295549,474.2951,-9.1998978
7005,7005,212.9238,11.99153,9.0426378,0.0,0,0.87635428,0.0,0.92415571,60.539261,0.8693459,475.33569,-9.2011147
7016,7016,212.926,12.041213,9.0661526,0.0,0,0.86259991,0.0,0.92639428,60.714993,0.85688263,476.37631,-9.2017927
7027,7027,212.9282,12.116125,9.0701208,0.0,0,0.84884548,0.0,0.92868251,60.939434,0.84299284,477.41693,-9.1997814
7038,7038,212.9304,12.192355,9.0925112,0.0,0,0.83509111,0.0,0.93132514,61.139759,0.8266232,478.45755,-9.199892
7049,7049,212.9326,12.195975,9.1012306,0.0,0,0.82133675,0.0,0.93361235,61.08205,0.80917937,479.35876,-9.1997089
7060,7060,212.9348,12.204115,9.121542,0.0,0,0.80758232,0.0,0.936167,60.935856,0.79789084,480.2345,-9.2012968
7071,7071,212.937,12.230613,9.1269855,0.0,0,0.79382795,0.0,0.93778843,60.964161,0.78589213,481.11023,-9.200326
7082,7082,212.9392,12.255287,9.1431799,0.0,0,0.78007352,0.0,0.94060451,60.904797,0.77090889,481.98596,-9.1997557
7093,7093,212.9414,12.303889,9.1555872,0.0,0,0.7663191,0.0,0.94236851,61.039631,0.75224268,482.7742,-9.200778
7104,7104,212.9436,12.338304,9.1748934,0.0,0,0.75256473,0.0,0.94614822,60.958111,0.7466324,483.36679,-9.2001886
7115,7115,212.9458,12.367084,9.1830177,0.0,0,0.7388103,0.0,0.94673902,61.100182,0.73218274,483.95941,-9.2005062
7126,7126,212.948,12.403158,9.1943312,0.0,0,0.72505593,0.0,0.94958013,61.117828,0.72078574,484.55203,-9.201313
7137,7137,212.9502,12.4745,9.2052584,0.0,0,0.71130151,0.0,0.95056748,61.391834,0.70647091,485.14462,-9.2005615
7148,7148,212.9524,12.569342,9.2202921,0.0,0,0.69754714,0.0,0.95429695,61.645844,0.69120085,485.59985,-9.2008743
7159,7159,212.9546,12.669078,9.238101,0.0,0,0.68379271,0.0,0.95593578,62.020626,0.67595321,486.01468,-9.2007761
7170,7170,212.9568,12.784081,9.2476158,0.0,0,0.67003828,0.0,0.95912594,62.35051,0.66167891,486.4295,-9.2015839
7181,7181,212.959,12.888486,9.2647886,0.0,0,0.65628392,0.0,0.96050155,62.766953,0.64274639,486.84433,-9.201827
7192,7192,212.9612,12.924958,9.276967,0.0,0,0.64252955,0.0,0.96455491,62.731396,0.63244039,487.1969,-9.2009487
7203,7203,212.9634,12.944808,9.2979431,0.0,0,0.62877512,0.0,0.96599478,62.749645,0.61883533,487.34833,-9.2006807
7214,7214,212.9656,12.95214,9.3030214,0.0,0,0.61502075,0.0,0.96916378,62.587639,0.6041503,487.49979,-9.1999264
7225,7225,212.9678,12.974999,9.3205862,0.0,0,0.60126632,0.0,0.97018296,62.612606,0.58840317,487.65121,-9.200593
7236,7236,212.97,12.986487,9.3276043,0.0,0,0.5875119,0.0,0.9736619,62.518108,0.58191848,487.80264,-9.2025576
7247,7247,212.9722,13.019823,9.3514576,0.0,0,0.57407832,0.0,0.9754082,62.514107,0.56351107,488.03702,-9.2018404
7258,7258,212.9744,13.069921,9.3556347,0.0,0,0.56098837,0.0,0.97844946,62.573448,0.55112493,488.30688,-9.2017746
7261,7261,212.975,13.158429,9.3584337,0.0,0,0.55741835,0.0,0.97864503,62.916828,0.54617631,488.38049,-9.2005606